File: examples/dan-msc-case-studies/CS3/data/01 raw data/baron_test_020.csv
Time(sec),Force(kN),Jaw(mm),PowAngle(deg),Power(W),Pram,PTemp,Strain,Stress(MPa),Stroke(mm),TC1(C),wedge(mm)
0.0,0.61532545,0.18053517,0.0,0,11.076097,0.0012268908,0.012110384,7.7325215,11.076823,28.486238,-9.1173172
1.3,0.55038851,-0.0018957013,0.0,0,11.076097,3.8159168,-0.00012207319,7.0081053,11.076953,28.477343,-9.4827719
2.6,0.52394557,-0.0017375599,0.0,0,11.076097,7.7159162,-0.00013651796,6.6797056,11.076152,28.500456,-9.4798012
3.9,0.50900954,-0.0018324917,0.0,0,11.076097,11.615913,-0.00014204973,6.4763937,11.07587,28.452581,-9.4778137
5.2,0.49093056,-0.0019834405,0.0,0,11.076097,15.515913,-0.00012075387,6.2496614,11.076695,28.466391,-9.4749489
6.5,0.47779226,-0.001911836,0.0,0,11.076097,19.415911,-0.00011089947,6.0731611,11.07625,28.410992,-9.4733229
7.8,0.4702073,-0.0014236977,0.0,0,11.076097,23.315914,-9.413292e-05,5.9904642,11.076277,28.402525,-9.4709749
9.1,0.45743099,-0.0016322862,0.0,0,11.076097,27.215912,-0.00011280346,5.8248463,11.076612,28.362917,-9.4685659
10.4,0.45962939,-0.0011461679,15.664853,0,11.076097,31.115908,-0.00010411558,5.8446541,11.076305,28.347143,-9.4667006
11.7,0.44857767,-0.0014689884,32.167202,0,11.076097,35.015911,-8.6923435e-05,5.7055039,11.076044,28.912666,-9.464077
13.0,0.45113266,-0.0024992607,40.506332,0,11.076097,38.915909,-0.00014819857,5.7294264,11.076315,31.087269,-9.4619932
14.3,0.46445638,-0.004389232,45.753288,0,11.076097,42.815899,-0.00029437055,5.9114294,11.076145,34.481979,-9.4594469
15.6,0.48228106,-0.0073567317,48.811333,0,11.076097,46.7159,-0.00048074781,6.1433001,11.076365,39.031372,-9.4578857
16.9,0.49107292,-0.010963737,50.437908,0,11.076097,50.615902,-0.00075165665,6.26021,11.076558,44.549721,-9.4554062
18.2,0.4945212,-0.014618103,50.82275,0,11.076097,54.515907,-0.00098546746,6.3015265,11.075971,50.480186,-9.4529123
19.5,0.50484848,-0.018514045,50.455364,0,11.076097,58.415909,-0.0012158576,6.4332571,11.07557,56.296543,-9.4510689
20.8,0.5113892,-0.022198873,49.648766,0,11.076097,62.31591,-0.0014770782,6.5136328,11.075452,61.92057,-9.448946
22.1,0.5203625,-0.025339577,48.768135,0,11.076097,66.215904,-0.0016856722,6.6325059,11.076263,66.990921,-9.4464989
23.4,0.51234525,-0.028040089,47.955326,0,11.076097,70.115898,-0.0018733175,6.5321903,11.076595,71.348251,-9.4445639
24.7,0.51365602,-0.030358689,47.054447,0,11.076097,74.0159,-0.0020351154,6.5611458,11.076026,75.414551,-9.442626
26.0,0.51491606,-0.033242624,46.582207,0,11.076097,77.915901,-0.0022153063,6.5743647,11.075887,79.042892,-9.4404221
27.3,0.51831609,-0.035493564,46.86816,0,11.076097,81.81591,-0.002336775,6.6178546,11.076848,82.316429,-9.4379883
28.6,0.51447004,-0.037824169,47.127495,0,11.076097,85.715904,-0.0025156906,6.5668836,11.07548,85.626472,-9.4361076
29.9,0.51642823,-0.039875414,47.955318,0,11.076097,89.615891,-0.0026490737,6.5881691,11.075956,88.955795,-9.4337816
31.2,0.52539998,-0.042521108,48.787552,0,11.076097,93.515892,-0.0028472524,6.7075644,11.076099,92.450081,-9.4318228
32.5,0.52500391,-0.045097172,49.229733,0,11.076097,97.415894,-0.0030137114,6.7045345,11.075723,96.255432,-9.4297743
33.8,0.51746809,-0.047938917,50.004532,0,11.076097,101.3159,-0.0031738463,6.6101651,11.076462,100.0187,-9.4270821
35.1,0.5263781,-0.050749004,50.438229,0,11.076097,105.2159,-0.0033727,6.7100472,11.076546,103.94987,-9.4254961
36.4,0.53350848,-0.053797811,50.82275,0,11.076097,109.11591,-0.0035707979,6.8238511,11.07583,107.96344,-9.4231958
37.7,0.5330779,-0.056691609,51.05299,0,11.076097,113.01591,-0.0037925169,6.8178973,11.076155,112.06217,-9.4207582
39.0,0.53032935,-0.05981781,51.196285,0,11.076097,116.91589,-0.0039920709,6.7872849,11.076169,116.15347,-9.4185429
40.3,0.52934802,-0.062920757,51.37838,0,11.076097,120.8159,-0.0041766749,6.766326,11.076127,120.13176,-9.4165506
41.6,0.53546387,-0.066031992,51.56982,0,11.076097,124.71589,-0.0043794187,6.8460879,11.076227,124.11338,-9.4141045
42.9,0.54144317,-0.068918809,51.932369,0,11.076097,128.61601,-0.0045805299,6.9275842,11.076643,127.93758,-9.4124918
44.2,0.55712998,-0.071755297,51.950378,0,11.076097,132.51588,-0.0047766278,7.1302633,11.075841,131.89003,-9.4104166
45.5,0.55419934,-0.075056829,52.283936,0,11.076097,136.41589,-0.0050124153,7.0836568,11.076003,135.77396,-9.408102
46.8,0.55860913,-0.078045532,52.635494,0,11.076097,140.31589,-0.0051892772,7.1517324,11.076187,139.64861,-9.4060783
48.1,0.56143433,-0.080512069,52.894253,0,11.076097,144.21588,-0.0053335805,7.1913509,11.075756,143.47066,-9.4036951
49.4,0.564053,-0.083321907,52.976986,0,11.076097,148.11588,-0.0055435305,7.219439,11.076378,147.37799,-9.4018764
50.7,0.55053765,-0.086585261,53.31665,0,11.076097,152.01587,-0.0057483721,7.0460439,11.075914,151.27615,-9.3994474
52.0,0.55572087,-0.089690618,53.657223,0,11.076097,155.91586,-0.0059817415,7.1250324,11.075364,155.07074,-9.3974495
53.3,0.56497139,-0.092789002,53.975826,0,11.076097,159.81589,-0.0061776619,7.2328477,11.075906,158.95476,-9.3954496
54.6,0.55989432,-0.096053973,54.305416,0,11.076097,163.71588,-0.0063552922,7.1698852,11.0766,162.85663,-9.3932371
55.9,0.57139713,-0.099071912,54.622601,0,11.076097,167.61588,-0.0065869666,7.3180785,11.074954,166.76762,-9.391283
57.2,0.56859255,-0.10247789,54.765232,0,11.076097,171.51588,-0.0068043959,7.282918,11.075666,170.7281,-9.3887253
58.5,0.58303094,-0.10522661,54.931637,0,11.076097,175.41588,-0.0070008747,7.4649701,11.075104,174.78647,-9.3869009
59.8,0.58084923,-0.10862017,55.228401,0,11.076097,179.31589,-0.0072261496,7.4576678,11.075787,178.66385,-9.38486
61.1,0.58195966,-0.11145894,55.239254,0,11.076097,183.21588,-0.0073934477,7.4740062,11.076371,182.63142,-9.3824549
62.4,0.58527887,-0.11449331,55.516468,0,11.076097,187.11588,-0.0076028821,7.5248146,11.076007,186.56248,-9.3804054
63.7,0.57643694,-0.11772249,55.535885,0,11.076097,191.01587,-0.007809862,7.3900647,11.076761,190.5071,-9.378087
65.0,0.5690155,-0.12120645,55.794434,0,11.076097,194.91586,-0.00806389,7.2956028,11.077223,194.45502,-9.3758068
66.3,0.57813561,-0.1240769,55.75972,0,11.076097,198.81587,-0.0082576945,7.4316959,11.075554,198.39026,-9.3741417
67.6,0.57179093,-0.12800993,55.843506,0,11.076097,202.71587,-0.0084830746,7.3404179,11.076125,202.43901,-9.3715391
68.9,0.57449549,-0.13104172,55.994541,0,11.076097,206.61589,-0.0086849285,7.3710246,11.075316,206.15486,-9.3694124
70.2,0.58063209,-0.13389991,56.129955,0,11.076097,210.51588,-0.0088758059,7.4539552,11.076026,209.99516,-9.3676968
71.5,0.58283693,-0.13739397,56.425777,0,11.076097,214.41586,-0.0091294935,7.4755054,11.075852,213.78377,-9.3654385
72.8,0.57836646,-0.14041293,56.711422,0,11.076097,218.31586,-0.0093385205,7.4358034,11.076749,217.63113,-9.3635025
74.1,0.58976543,-0.14472561,56.986084,0,11.076097,222.21587,-0.0095901052,7.5754724,11.076096,221.37582,-9.3611879
75.4,0.58109742,-0.1481882,57.143867,0,11.076097,226.11586,-0.0098122312,7.4761982,11.075434,225.36423,-9.3588753
76.7,0.58716774,-0.15108587,57.260738,0,11.076097,230.01587,-0.010020247,7.5473547,11.07596,229.27119,-9.3568316
78.0,0.59531379,-0.15370902,57.535397,0,11.076097,233.91588,-0.010196544,7.6621032,11.076155,233.29169,-9.3546991
79.3,0.59059852,-0.15715571,57.76981,0,11.076097,237.81587,-0.010448457,7.6028214,11.075642,237.10231,-9.3524733
80.6,0.58856332,-0.16078463,57.810741,0,11.076097,241.71585,-0.010670875,7.563592,11.075607,241.00668,-9.3504114
81.9,0.58768243,-0.16435026,58.073727,0,11.076097,245.61588,-0.010873259,7.5671616,11.07644,244.88115,-9.3481741
83.2,0.59160608,-0.16783036,58.337399,0,11.076097,249.51585,-0.01113112,7.6044574,11.075646,248.75603,-9.3458509
84.5,0.59352922,-0.17131689,58.59008,0,11.076097,253.41586,-0.011354057,7.6475611,11.075876,252.62578,-9.3441639
85.8,0.59274387,-0.17490648,58.654518,0,11.076097,257.3161,-0.011604866,7.6523018,11.07657,256.62341,-9.3420753
87.1,0.58509994,-0.1785951,58.853752,0,11.076097,261.21613,-0.011846252,7.5416484,11.076821,260.54065,-9.3396206
88.4,0.59006226,-0.18218111,59.106438,0,11.076097,265.11584,-0.012048987,7.6046939,11.076546,264.38419,-9.3376589
89.7,0.58486468,-0.18604556,59.165714,0,11.076097,269.01587,-0.01232799,7.5455289,11.076561,268.34824,-9.3356037
91.0,0.5891239,-0.18935642,59.348137,0,11.076097,272.91586,-0.012536057,7.5968423,11.075695,272.31326,-9.3330908
92.3,0.58884585,-0.19274141,59.507286,0,11.076097,276.81586,-0.012794899,7.5825114,11.075695,276.18823,-9.3312588
93.6,0.58467919,-0.1963878,59.600826,0,11.076097,280.71582,-0.0130234,7.533401,11.076052,280.12256,-9.3290091
94.9,0.59271348,-0.20030712,59.842525,0,11.076097,284.61581,-0.013246556,7.6456671,11.076344,283.95547,-9.3269463
96.2,0.59375471,-0.20367374,60.078022,0,11.076097,288.51584,-0.013491655,7.6643138,11.075343,287.79849,-9.3252325
97.5,0.57576758,-0.20754792,60.12561,0,11.076097,292.41583,-0.013734224,7.4326291,11.076581,291.74918,-9.3226099
98.8,0.58410817,-0.21074143,60.314934,0,11.076097,296.31586,-0.013964511,7.5344276,11.075776,295.64029,-9.3204355
100.1,0.5902763,-0.21415946,60.55645,0,11.076097,300.21588,-0.014187884,7.6206956,11.075792,299.51733,-9.3182888
101.4,0.58360714,-0.21800765,60.556793,0,11.076097,304.11584,-0.014409089,7.5190368,11.076283,303.47443,-9.316185
102.7,0.58124906,-0.22143684,60.787346,0,11.076097,308.01584,-0.014649475,7.5196061,11.076279,307.23492,-9.3137197
104.0,0.5949254,-0.22533983,61.018063,0,11.076097,311.91583,-0.014903544,7.6974626,11.076439,311.13986,-9.3118877
105.3,0.58397174,-0.22897245,61.23777,0,11.076097,315.81583,-0.015174537,7.5468378,11.076347,315.02319,-9.3097563
106.6,0.5956955,-0.23272078,61.438126,0,11.076097,319.71582,-0.015405532,7.6957512,11.076294,318.95776,-9.307642
107.9,0.57753223,-0.23664792,61.568542,0,11.076097,323.61584,-0.015627634,7.4632049,11.077057,322.74329,-9.3051615
109.2,0.5932492,-0.24031657,61.801258,0,11.076097,327.51584,-0.015888669,7.6709766,11.076509,326.6178,-9.303257
110.5,0.59659731,-0.24405171,62.000477,0,11.076097,331.41586,-0.016128438,7.7113376,11.076265,330.49265,-9.3012342
111.8,0.59229141,-0.2479568,62.122879,0,11.076097,335.31586,-0.016415263,7.6759439,11.07721,334.40668,-9.2992897
113.1,0.59292972,-0.25196728,62.533512,0,11.076097,339.21585,-0.016667044,7.6618705,11.075649,338.12909,-9.2967319
114.4,0.59117228,-0.25631157,62.753899,0,11.076097,343.11584,-0.016923673,7.6413865,11.076124,342.00018,-9.2950125
115.7,0.59063232,-0.26046827,62.962639,0,11.076097,347.01581,-0.017214542,7.6637406,11.077388,345.96115,-9.2925014
117.0,0.59306329,-0.26449722,63.165359,0,11.076097,350.9158,-0.017470254,7.6767368,11.076218,349.95447,-9.2907143
118.3,0.57731539,-0.26873231,63.171383,0,11.076097,354.81583,-0.017781304,7.4812369,11.07604,354.07111,-9.2881651
119.6,0.58635545,-0.27264902,63.264832,0,11.076097,358.71585,-0.018026926,7.5800076,11.076352,358.11154,-9.2864342
120.9,0.59403765,-0.27624509,63.215786,0,11.076097,362.61588,-0.018231107,7.6851411,11.076004,362.30276,-9.2841597
122.2,0.59617925,-0.27997041,63.238926,0,11.076097,366.51587,-0.018495528,7.7137833,11.076447,366.38019,-9.2822227
123.5,0.58980799,-0.28394154,63.249916,0,11.076097,370.41583,-0.018749494,7.6360102,11.075925,370.289,-9.2800169
124.8,0.59372288,-0.2881352,63.350601,0,11.076097,374.31583,-0.019043736,7.6852026,11.076375,374.15402,-9.2777729
126.1,0.593804,-0.29279694,63.367653,0,11.076097,378.21582,-0.019325135,7.6989708,11.075934,378.10614,-9.2755041
127.4,0.60022575,-0.29669619,63.368359,0,11.076097,382.11581,-0.019559769,7.7904868,11.07645,382.01608,-9.2736759
128.7,0.59922791,-0.30060813,63.436222,0,11.076097,386.01581,-0.01983704,7.7840662,11.076296,385.71304,-9.2712746
130.0,0.59936607,-0.30482894,63.577873,0,11.076097,389.91583,-0.020119131,7.7736392,11.075477,389.51654,-9.2692442
131.3,0.60351598,-0.30882981,63.775608,0,11.076097,393.81583,-0.020397682,7.837213,11.076827,393.22043,-9.2672434
132.6,0.60377449,-0.31280822,63.940044,0,11.076097,397.71585,-0.020637143,7.8518019,11.076745,396.98511,-9.2651272
133.9,0.60467088,-0.31689143,64.171135,0,11.076097,401.61581,-0.020893091,7.8570971,11.07625,400.66333,-9.2630434
135.2,0.60590804,-0.32068849,64.357903,0,11.076097,405.51581,-0.021146623,7.8722339,11.076483,404.42557,-9.2607746
136.5,0.60239565,-0.3246572,64.648605,0,11.076097,409.41583,-0.021420959,7.8274732,11.076112,408.32974,-9.2582607
137.8,0.60168052,-0.32871205,64.90686,0,11.076097,413.3158,-0.021693889,7.8265672,11.077055,412.20209,-9.2562809
139.1,0.60275108,-0.33292136,65.013214,0,11.076097,417.21579,-0.021932172,7.842876,11.07589,416.21313,-9.2540941
140.4,0.60053664,-0.33680424,65.115959,0,11.076097,421.11581,-0.022188678,7.8123312,11.075325,420.23398,-9.2519131
141.7,0.598243,-0.34065527,65.302727,0,11.076097,425.01584,-0.022447262,7.7742658,11.076987,424.17993,-9.2499743
143.0,0.60150421,-0.3444308,65.312965,0,11.076097,428.91583,-0.022722043,7.8283048,11.077041,428.3558,-9.2481756
144.3,0.58954912,-0.34937617,65.478508,0,11.076097,432.81586,-0.023032652,7.6782546,11.076314,432.18439,-9.2457943
145.6,0.59057933,-0.35428441,65.541748,0,11.076097,436.71582,-0.023323778,7.7029328,11.075191,436.2005,-9.2434282
146.9,0.59790123,-0.35898086,65.480202,0,11.076097,440.61578,-0.02365165,7.7985806,11.075649,440.34903,-9.241744
148.2,0.59374905,-0.36333978,65.478523,0,11.076097,444.51578,-0.023929726,7.7502613,11.075504,444.41962,-9.2392359
149.5,0.59773201,-0.36735201,65.478523,0,11.076097,448.4158,-0.024209097,7.7971826,11.076615,448.38544,-9.2372627
150.8,0.5932973,-0.37196833,65.478523,0,11.076097,452.3158,-0.024487901,7.7501802,11.07647,452.29398,-9.2351513
152.1,0.60109574,-0.37626013,65.478523,0,11.076097,456.21582,-0.024762627,7.8584628,11.07558,456.21521,-9.2326889
153.4,0.59926862,-0.38024065,65.541451,0,11.076097,460.11584,-0.025027664,7.8185005,11.076449,459.98334,-9.2310495
154.7,0.59512514,-0.38410982,65.665276,0,11.076097,464.01584,-0.02529262,7.7676373,11.076368,463.64285,-9.2287092
156.0,0.60322946,-0.38810939,65.841057,0,11.076097,467.9158,-0.025560347,7.8845634,11.076286,467.30673,-9.2264481
157.3,0.60659724,-0.39266303,66.016838,0,11.076097,471.81583,-0.025822196,7.9333034,11.07592,471.0824,-9.2246523
158.6,0.60604721,-0.39727616,66.218819,0,11.076097,475.71579,-0.026147213,7.922318,11.075821,474.85211,-9.2220097
159.9,0.60403293,-0.40226129,66.440796,0,11.076097,479.61581,-0.026452459,7.8986068,11.075648,478.65991,-9.2198391
161.2,0.61150581,-0.40777645,66.544182,0,11.076097,483.51584,-0.026843788,7.9910488,11.075803,482.77911,-9.2179766
162.5,0.61498535,-0.41349792,66.544182,0,11.076097,487.41583,-0.027201667,8.0573902,11.076657,486.87396,-9.2159519
163.8,0.61044216,-0.41804934,66.56749,0,11.076097,491.31583,-0.027463742,7.9847045,11.075716,490.90128,-9.2136049
165.1,0.60544145,-0.42178717,66.544197,0,11.076097,495.21585,-0.027728841,7.91292,11.075739,495.02203,-9.2110996
166.4,0.59077442,-0.42578343,66.540741,0,11.076097,499.11584,-0.027992209,7.7203279,11.076284,499.26019,-9.209198
167.7,0.58827507,-0.43064895,65.116386,0,11.076097,499.99884,-0.028315462,7.7017736,11.076186,503.33038,-9.2087612
169.0,0.59192717,-0.43341953,62.609283,0,11.076097,499.99884,-0.028486606,7.7459803,11.076642,506.91275,-9.208375
170.3,0.59052306,-0.43455684,59.676579,0,11.076097,499.99884,-0.028541755,7.7283125,11.074716,509.2327,-9.2085924
171.6,0.56160218,-0.43415403,56.475925,0,11.076097,499.99884,-0.028523061,7.3549418,11.07657,510.21503,-9.2086191
172.9,0.55676425,-0.43286061,53.659641,0,11.076097,499.99884,-0.028465422,7.3074889,11.0762,509.84299,-9.2087984
174.2,0.53886271,-0.43173122,51.569843,0,11.076097,499.99884,-0.028391607,7.0547748,11.075902,508.2406,-9.2084856
175.5,0.51470053,-0.42907467,50.443985,0,11.076097,499.99884,-0.028181037,6.749609,11.075878,505.93961,-9.2087412
176.8,0.48960257,-0.42645863,51.071999,0,11.076097,499.99884,-0.028033279,6.4132295,11.076843,502.96198,-9.2083988
178.1,0.4857001,-0.42490754,52.4221,0,11.076097,499.99884,-0.027927712,6.3557577,11.076711,500.22784,-9.2086468
179.4,0.47309792,-0.42417321,54.289612,0,11.076097,499.99884,-0.027903214,6.1868248,11.076404,497.99719,-9.2087555
180.7,0.45500085,-0.42405954,56.070175,0,11.076097,499.99884,-0.027883617,5.9541869,11.076015,496.48199,-9.2085991
182.0,0.44637778,-0.42436206,57.524967,0,11.076097,499.99884,-0.027886495,5.8478069,11.076186,495.88303,-9.2085371
183.3,0.42902544,-0.42657614,58.701801,0,11.076097,499.99884,-0.028039148,5.6142588,11.076436,495.71848,-9.2086277
184.6,0.39722946,-0.42812082,59.600758,0,11.076097,499.99884,-0.028141186,5.1963496,11.076383,496.03549,-9.2086458
185.9,0.36681041,-0.4301495,60.309669,0,11.076097,499.99884,-0.028291976,4.8257098,11.076329,496.62607,-9.2086449
187.2,0.36205575,-0.43203977,60.556637,0,11.076097,499.99884,-0.028379686,4.7403717,11.075831,497.3815,-9.2084303
188.5,0.3541826,-0.43419623,60.787319,0,11.076097,499.99884,-0.028528536,4.63557,11.076765,498.23373,-9.2083263
189.8,0.35767204,-0.43560162,60.568363,0,11.076097,499.99884,-0.028618572,4.6928358,11.076612,499.12213,-9.208456
191.1,0.36261705,-0.4370068,60.314949,0,11.076097,499.99884,-0.028741432,4.7592053,11.075962,500.05798,-9.2084513
192.4,0.3648136,-0.43982264,59.842541,0,11.076097,499.99884,-0.028905082,4.7749715,11.076086,500.82733,-9.2082977
193.7,0.34852695,-0.43933746,59.197296,0,11.076097,499.99884,-0.028844992,4.5729022,11.076344,501.43329,-9.2084036
195.0,0.33528164,-0.44086447,58.590881,0,11.076097,499.99884,-0.028958419,4.3964906,11.076253,501.71246,-9.2082109
196.3,0.34134355,-0.44085711,58.08186,0,11.076097,499.99884,-0.028964061,4.4735765,11.075696,501.83215,-9.2082863
197.6,0.34602043,-0.44104508,57.810066,0,11.076097,499.99884,-0.028999234,4.5436397,11.075876,501.67361,-9.2084122
198.9,0.34239936,-0.44092596,57.476036,0,11.076097,499.99884,-0.028966619,4.4908943,11.075858,501.45422,-9.2082062
200.2,0.33701739,-0.44233701,57.260746,0,11.076097,499.99884,-0.02905757,4.4198513,11.076186,501.09665,-9.2083359
201.5,0.3297877,-0.44122243,57.282093,0,11.076097,499.99884,-0.0289745,4.3031883,11.075404,500.55914,-9.2081556
202.8,0.31780905,-0.44210234,57.531879,0,11.076097,499.99884,-0.029066693,4.1644921,11.075634,500.19965,-9.2083874
204.1,0.32677525,-0.44212273,57.762257,0,11.076097,499.99884,-0.029053494,4.2836995,11.076714,499.74661,-9.2082882
205.4,0.33332238,-0.44196907,58.014912,0,11.076097,499.99884,-0.029011184,4.3664966,11.076063,499.44284,-9.2079744
206.7,0.35250235,-0.44399408,58.249546,0,11.076097,499.99884,-0.029179076,4.6004171,11.076112,499.28839,-9.2080784
208.0,0.3291913,-0.44386533,58.406033,0,11.076097,499.99884,-0.029167358,4.3231225,11.076248,499.25546,-9.2083025
209.3,0.34291369,-0.44492459,58.59008,0,11.076097,499.99884,-0.029250132,4.4949265,11.076612,499.37555,-9.2077541
210.6,0.3482115,-0.44529262,58.59008,0,11.076097,499.99884,-0.029246589,4.579864,11.076394,499.50687,-9.2080479
211.8982,0.34862095,0.022358671,58.59008,0,11.076097,499.99884,0.0015097714,4.4330187,11.076485,499.79269,-9.2080536
211.9507,0.32816729,0.02792473,58.590088,0,11.076099,8.225476e-14,0.0018110544,4.2243223,11.079329,499.81784,-9.207819
211.9533,0.35127231,0.029134845,58.590088,0,11.076099,1.5390809e-31,0.0017148713,4.3820577,11.076213,499.84106,-9.2072296
211.9559,0.34942356,0.027595842,58.590088,0,11.076099,0.0,0.0016471279,4.5061054,11.076107,499.86429,-9.208519
211.9585,0.33035469,0.028009832,51.573257,0,11.076099,0.0,0.0017458919,4.2191091,11.077234,499.88037,-9.2091913
211.9611,0.30679339,0.027443303,36.370239,0,11.076099,0.0,0.0018491258,4.0192294,11.076528,499.88812,-9.2090588
211.9637,0.354608,0.025867796,21.167223,0,11.076099,0.0,0.001825739,4.5017099,11.079348,499.89587,-9.2078409
211.9663,0.33887929,0.028705793,5.9642067,0,11.076099,0.0,0.0021276036,4.2643595,11.078259,499.90359,-9.2082043
211.9689,0.33639354,0.026255915,0.0,0,11.076099,0.0,0.0018896528,4.2743549,11.077049,499.85489,-9.2080317
211.9715,0.3342312,0.032246951,0.0,0,11.076099,0.0,0.0019900349,4.3423767,11.078532,499.76971,-9.2082176
211.9741,0.32408637,0.02733827,0.0,0,11.076099,0.0,0.0016659328,4.1802373,11.077991,499.68451,-9.2082472
211.9767,0.32289803,0.028922185,0.0,0,11.076099,0.0,0.0017414776,4.071372,11.076046,499.59933,-9.2075224
211.9793,0.31727365,0.02481357,0.0,0,11.076099,0.0,0.0015980093,4.0511723,11.077076,499.60754,-9.2080498
211.9819,0.30950093,0.025313536,0.0,0,11.076099,0.0,0.0017794877,3.9822168,11.07584,499.64627,-9.2090836
211.9845,0.31228161,0.024678463,0.0,0,11.076099,0.0,0.0019316676,3.8664751,11.07583,499.685,-9.2089529
211.9871,0.30987257,0.02560645,0.0,0,11.076099,0.0,0.0018575036,3.9842231,11.076299,499.72369,-9.20751
211.9897,0.3037312,0.030631255,0.0,0,11.076099,0.0,0.0020481204,3.7968879,11.076468,499.72757,-9.2071829
211.9923,0.29441297,0.027611235,0.0,0,11.076099,0.0,0.0017578085,3.5903528,11.076777,499.72757,-9.2088127
211.9949,0.30220553,0.03091751,0.0,0,11.076099,0.0,0.0017501307,3.8035722,11.078863,499.72757,-9.207756
211.9975,0.30112031,0.026549535,0.0,0,11.076099,0.0,0.0015833162,3.7967553,11.079069,499.72757,-9.2071362
212.0001,0.28709543,0.026310461,0.0,0,10.826062,0.0,0.0016952771,3.600224,11.076748,499.72757,-9.2067318
212.0027,0.31229538,0.025009647,0.0,0,10.435007,0.0,0.001721543,4.1041574,11.069752,499.72757,-9.207201
212.0053,0.29490516,0.024723545,0.0,0,10.043953,0.0,0.0018016211,3.8340127,11.002419,499.72757,-9.2070799
212.0079,0.30821544,0.027274493,0.0,0,9.6528978,0.0,0.0019950047,3.9378479,10.750991,499.72757,-9.2073917
212.0105,0.32544646,0.027193764,0.0,0,9.2678175,0.0,0.0019017353,4.0901828,10.366846,499.72757,-9.2077436
212.0131,5.0119348,0.20092191,0.0,0,8.8873854,0.0,0.012515948,62.901878,9.9472523,499.72757,-9.2043638
212.0157,5.5190983,0.70121884,0.0,0,8.518857,0.0,0.047349997,66.119385,9.4404774,499.72757,-9.2034607
212.0183,5.7545738,1.1473036,0.0,0,8.1570406,0.0,0.078886956,67.754761,8.9580603,499.56769,-9.2035036
212.0209,5.9937973,1.5904887,0.0,0,7.8078156,0.0,0.11165852,68.248009,8.5221128,499.09528,-9.2035837
212.0235,6.1785502,1.9722152,0.0,0,7.4635754,0.0,0.1406159,68.375031,8.1296415,498.62289,-9.2046385
212.0261,6.4408078,2.3227217,0.0,0,7.132699,0.0,0.16810267,69.320183,7.7596288,498.15051,-9.2052212
212.0287,6.5090408,2.6646996,0.0,0,6.8053074,0.0,0.1953849,68.071632,7.4068165,497.55801,-9.2049007
212.0313,6.6179013,2.9943349,0.0,0,6.4917617,0.0,0.2223078,67.522034,7.0815063,496.8378,-9.2046394
212.0339,6.8430662,3.2969241,0.0,0,6.1802816,0.0,0.24766849,67.959412,6.762538,496.11761,-9.2041979
212.0365,6.9886122,3.6072056,0.0,0,5.8832316,0.0,0.2741572,67.577049,6.4530582,495.3974,-9.2041168
212.0391,7.1325741,3.9009819,0.0,0,5.5874414,0.0,0.30051532,67.227104,6.1521015,494.64297,-9.2054873
212.0417,7.3442864,4.1974688,0.0,0,5.3054934,0.0,0.32783785,67.242966,5.8529167,493.86856,-9.2042933
212.0443,7.5283518,4.4926186,0.0,0,5.0250483,0.0,0.35588941,67.125778,5.5481057,493.09415,-9.2034397
212.0469,7.6942482,4.7886844,0.0,0,4.7569838,0.0,0.38448659,66.676392,5.2503314,492.31973,-9.20432
212.0495,7.9103179,5.0824299,0.0,0,4.4912457,0.0,0.41355214,66.451462,4.9598947,489.76242,-9.2047043
212.0521,8.0773039,5.3635192,0.0,0,4.236237,0.0,0.44197875,66.103653,4.6760883,486.69321,-9.2045088
212.0547,8.2582264,5.6371236,0.0,0,3.9844091,0.0,0.47047234,65.601913,4.4059978,483.62396,-9.2037249
212.0573,8.4674931,5.8879862,0.0,0,3.7418811,0.0,0.49760437,65.51162,4.1445999,480.55475,-9.2037525
212.0599,8.6869764,6.13696,0.0,0,3.5032687,0.0,0.52530831,65.385323,3.8949146,476.84717,-9.2034435
212.0625,8.8999615,6.3773308,0.0,0,3.2725446,0.0,0.55319971,65.145203,3.653682,473.0864,-9.204937
212.0651,9.1557007,6.6170545,0.0,0,3.0464103,0.0,0.58190745,65.092133,3.4146338,469.32559,-9.2031002
212.0677,9.4657898,6.8524804,0.0,0,2.8269181,0.0,0.61054373,65.441582,3.1740718,465.84775,-9.2021303
212.0703,9.7159233,7.0818505,0.0,0,2.6126273,0.0,0.63888496,65.286179,2.9485013,466.17365,-9.2006474
212.0729,10.015528,7.3108711,0.0,0,2.4038472,0.0,0.66763729,65.414932,2.7278521,466.49954,-9.2023735
212.0755,10.386334,7.527513,0.0,0,2.2008002,0.0,0.69590718,65.866684,2.506376,466.82541,-9.2019939
212.0781,10.715569,7.7445784,0.0,0,2.002212,0.0,0.72505814,66.054375,2.2926505,467.10953,-9.2018528
212.0807,11.091918,7.9472733,0.0,0,1.8098083,0.0,0.75383079,66.386429,2.0833948,467.24142,-9.2024345
212.0833,11.523119,8.1477661,0.0,0,1.6208922,0.0,0.7832498,66.979187,1.8819863,467.37332,-9.201602
212.0859,11.917556,8.3405581,0.0,0,1.4385692,0.0,0.81242734,67.317451,1.6850755,467.50522,-9.2017736
212.0885,12.36493,8.5315542,0.0,0,1.2588573,0.0,0.84156811,67.794525,1.4976299,466.51447,-9.1997519
212.0911,12.891022,8.7222023,0.0,0,1.0861163,0.0,0.87109202,68.646057,1.3105533,463.54126,-9.1997232
212.0937,13.395241,8.9026279,0.0,0,0.91519231,0.0,0.89953876,69.3246,1.1268736,460.56805,-9.2014647
212.0963,13.956091,9.0800772,0.0,0,0.75155324,0.0,0.92831683,70.134682,0.95105845,457.59482,-9.2003412
212.0989,14.557865,9.2467833,0.0,0,0.58900124,0.0,0.95700097,71.138657,0.77731836,456.21384,-9.1987638
212.1015,15.20374,9.4095507,0.0,0,0.43388578,0.0,0.98612231,72.122536,0.60783082,456.37677,-9.1990471
212.1041,12.849319,9.4490108,0.0,0,0.27942529,0.0,0.99430573,60.846703,0.49516562,456.5397,-9.2020617
212.1067,11.236812,9.4608603,0.0,0,0.13226004,0.0,0.99702954,52.815201,0.43438414,456.70264,-9.2035732
212.1093,10.483504,9.4742813,0.0,0,-0.014479335,0.0,0.99959433,49.151653,0.3931163,459.28595,-9.2034693
212.1119,10.118946,9.4796047,0.0,0,-0.15794852,0.0,1.0000032,47.431015,0.36000577,463.15063,-9.2040215
212.1145,10.140246,9.489356,0.0,0,-0.30141655,0.0,1.0007647,47.422791,0.31547576,467.01535,-9.2045803
212.1171,10.499681,9.4904156,0.0,0,-0.44488451,0.0,1.0007153,49.075603,0.24371295,470.88004,-9.2037077
212.1197,10.678413,9.4986906,0.0,0,-0.5883525,0.0,1.0018868,49.918392,0.17045967,474.13437,-9.2022257
212.1223,10.634803,9.4998837,0.0,0,-0.73182052,0.0,1.0029011,49.678619,0.10086802,477.23611,-9.2026291
212.1249,10.44298,9.5062571,0.0,0,-0.87528849,0.0,1.0046866,48.677761,0.049127579,480.33783,-9.2035084
212.1275,10.148457,9.5087643,0.0,0,-1.0187565,0.0,1.0059078,47.278744,0.008668459,483.43958,-9.2055235
212.1301,9.7190104,9.5111513,0.0,0,-0.91974235,499.99997,1.0062726,45.298565,-0.01024947,485.30746,-9.2049913
212.1327,9.2249756,9.5174999,0.0,0,-0.42304912,500.0,1.0067775,42.980312,-0.014075171,487.10513,-9.2054348
212.1353,8.7694902,9.5170231,0.0,0,0.073644437,500.0,1.0060626,40.875072,-0.011614322,488.90283,-9.2059736
212.1379,8.3608894,9.519268,0.4347274,0,0.57033831,500.0,1.0056261,38.958672,-0.0015151382,490.66681,-9.2051878
212.1405,8.1001205,9.5144224,5.1441565,0,1.0670315,500.0,1.0051069,37.755852,0.0029604416,492.0997,-9.206151
212.1431,7.6703415,9.5152359,9.8535852,0,1.5637254,500.0,1.0058228,35.78566,0.011203052,493.53256,-9.2064257
212.1457,6.0764432,9.5061808,14.563014,0,2.0604191,500.0,1.0049078,28.50499,0.092448339,494.96545,-9.2060957
212.1483,2.8981471,9.4904499,18.149414,0,2.5571125,500.0,1.0026387,13.799445,0.28886995,496.29303,-9.2085333
212.1509,-0.24492189,9.4537687,18.149414,0,3.0538061,500.0,0.99609554,-1.1373795,0.59435874,497.28427,-9.2125072
212.1535,0.064729594,9.4037046,18.149414,0,3.5504997,500.0,0.98631608,0.21458104,1.2314593,498.27554,-9.2121267
212.1561,-0.014767175,9.3874998,18.149414,0,4.0471931,500.0,0.98238987,-0.0098031238,2.0572619,499.26678,-9.2106276
212.1587,-0.13425556,9.3678589,16.338085,0,4.5438867,500.0,0.97893941,-0.55266714,2.8447483,500.11212,-9.2113705
212.1613,0.069545813,9.3739023,11.628656,0,5.0405807,500.0,0.97983038,0.25240594,3.4737306,500.72391,-9.2102365
212.1639,-0.12772498,9.3941965,6.9192281,0,5.5372739,500.0,0.98391122,-0.55290896,3.9663675,501.33569,-9.210743
212.1665,0.0734469,9.4093809,2.2097983,0,6.0339675,500.0,0.98755044,0.31627524,4.4246778,501.94748,-9.2095652
212.1691,0.013989902,9.437396,0.0,0,6.5306616,500.0,0.99294156,0.10989526,4.8960161,502.39899,-9.208787
212.1717,-0.075676978,9.4756269,0.0,0,7.0273547,500.0,0.99960095,-0.34566939,5.378253,502.70874,-9.2111168
212.1743,0.13170134,9.4860477,0.0,0,7.5240488,500.0,1.0009491,0.65995669,5.8877387,503.01849,-9.2095156
212.1769,-0.22353677,9.4887352,0.0,0,8.0207424,500.0,1.0006711,-1.0295918,6.3984056,503.32828,-9.2096395
212.1795,0.2293534,9.488246,0.0,0,8.5174351,500.0,0.99971205,1.0399395,6.9257054,503.60132,-9.2087164
212.1821,-0.16303991,9.4849014,0.0,0,9.0141287,500.0,0.99985933,-0.75898719,7.4360895,503.85684,-9.2090311
212.1847,0.15691124,9.4861565,0.0,0,9.5108232,500.0,1.0006982,0.70806837,7.9633021,504.11237,-9.209506
212.1873,-0.14869425,9.4833317,0.0,0,10.007517,500.0,1.0011348,-0.75264269,8.4649458,504.36789,-9.2079048
212.1899,0.097686671,9.4797516,0.0,0,10.50421,500.0,1.0005814,0.45203179,8.9859734,504.61063,-9.2072067
212.1925,-0.13284233,9.4862785,0.0,0,11.000903,500.0,1.0016755,-0.54672873,9.4932375,504.85062,-9.2061119
212.1951,0.005270212,9.4867725,0.0,0,11.497598,500.0,1.0011414,-0.032402258,10.001192,505.09064,-9.2077274
212.1977,-0.014738092,9.4912863,0.0,0,11.99429,500.0,1.0008203,0.047164842,10.521722,505.33063,-9.2078428
212.2003,-0.10407361,9.4875145,0.0,0,12.490984,500.0,1.0000447,-0.51985162,11.025622,505.48056,-9.2073736
212.2029,0.14658734,9.4858713,0.0,0,12.987678,500.0,0.99985844,0.69846362,11.533047,505.62762,-9.2068424
212.2055,-0.16255625,9.4837656,0.0,0,13.484371,500.0,1.0002526,-0.7932176,12.020813,505.77469,-9.2069016
212.2081,0.099869229,9.4798431,0.0,0,13.981066,500.0,1.0002753,0.50102687,12.521543,505.92175,-9.2062626
212.2107,-0.070181042,9.4820766,0.0,0,14.477758,500.0,1.0012988,-0.34791702,13.025267,506.06882,-9.206583
212.2133,0.081865914,9.4823771,0.0,0,14.974452,500.0,1.000663,0.36679149,13.545087,506.21588,-9.2061529
212.2159,-0.094315924,9.4898939,0.0,0,15.471146,500.0,1.0011381,-0.37400764,14.063643,506.36292,-9.206974
212.2185,0.018815467,9.4850035,0.0,0,15.967839,500.0,1.0000296,-0.00062216434,14.581965,506.50595,-9.2078829
212.2211,-0.032972127,9.4874916,0.0,0,16.464533,500.0,0.9997673,-0.094898447,15.090266,506.63754,-9.2063522
212.2237,0.018464942,9.4825239,0.0,0,16.961227,500.0,0.99956882,0.058176313,15.58187,506.7691,-9.206358
212.2263,0.0019512561,9.4824266,0.0,0,17.45792,500.0,1.0002828,0.026498873,16.077286,506.9007,-9.2062416
212.2289,-0.071820781,9.4815474,0.0,0,17.954613,500.0,1.0009118,-0.32429287,16.564035,507.01019,-9.2062769
212.2315,0.13002098,9.4817486,0.0,0,18.0,500.0,1.0009899,0.58765298,17.055641,507.08759,-9.2075891
212.2341,-0.14945425,9.4891787,0.0,0,18.0,500.0,1.0020567,-0.73952538,17.51506,507.16498,-9.2079039
212.2367,0.0803032,9.4852104,0.0,0,18.0,500.0,1.0005169,0.4210822,17.92325,507.24237,-9.2066355
212.2393,-0.054156929,9.4945469,0.0,0,18.0,500.0,1.0012894,-0.28966513,18.233324,507.30264,-9.2094307
212.2419,0.011257131,9.4922628,0.0,0,18.0,500.0,1.0008914,0.087453127,18.434118,507.34906,-9.2130117
212.2445,0.018623559,9.4973106,0.0,0,18.0,500.0,1.0021472,0.064537317,18.483181,507.39551,-9.2176428
212.2471,0.015522053,9.5013418,0.0,0,18.0,500.0,1.0036846,0.13607837,18.406172,507.44196,-9.2254705
212.2497,0.27102911,9.5110979,0.0,0,18.0,500.0,1.0061504,1.2361383,18.269445,507.51007,-9.2384539
212.2523,0.13606201,9.5111666,0.0,0,18.0,500.0,1.0062717,0.60880589,18.152962,507.58746,-9.2561178
212.2549,0.15008095,9.509326,0.0,0,18.0,500.0,1.0054781,0.82904214,18.076685,507.66486,-9.2742043
212.2575,0.12158149,9.5168352,0.0,0,18.0,500.0,1.0059141,0.56668431,18.057217,507.74228,-9.2970982
212.2601,0.12744075,9.5118799,0.0,0,18.0,500.0,1.0047011,0.55244648,18.058298,507.81311,-9.3192339
212.2627,0.14372045,9.5122929,0.0,0,18.0,500.0,1.0044625,0.69006807,18.075092,507.88278,-9.3430042
212.2653,0.091714084,9.5073709,0.0,0,18.0,500.0,1.0042148,0.45442468,18.099747,507.95245,-9.3653727
212.2679,0.12675622,9.5089102,0.0,0,18.0,500.0,1.0051621,0.581352,18.118683,508.02209,-9.3867817
212.2705,0.15063499,9.5072889,0.0,0,18.0,500.0,1.0055628,0.70318925,18.134666,508.03799,-9.4061003
212.2731,0.10317503,9.5072193,0.0,0,18.0,500.0,1.0056089,0.47195506,18.145449,508.05347,-9.4250536
212.2757,0.12408698,9.5127621,0.0,0,18.0,500.0,1.0060791,0.5789507,18.146473,508.06894,-9.4436998
212.2783,0.15735607,9.5108185,0.0,0,18.0,500.0,1.0047839,0.74553818,18.146547,508.08014,-9.4637442
212.2809,0.13094184,9.5146084,0.0,0,18.0,500.0,1.0048324,0.59560192,18.143391,508.06467,-9.4843531
212.2835,0.11944038,9.508769,0.0,0,18.0,500.0,1.0039873,0.52068818,18.139139,508.04919,-9.5029173
212.2861,0.16773631,9.5080395,0.0,0,18.0,500.0,1.0043132,0.80223787,18.134756,508.03372,-9.523077
212.2887,0.13523816,9.5031929,0.0,0,18.0,500.0,1.0042638,0.67443442,18.137938,508.01382,-9.5400829
212.2913,0.12780601,9.5050659,0.0,0,18.0,500.0,1.0051194,0.58187032,18.129042,507.98288,-9.5617228
212.2939,0.18600032,9.508647,0.0,0,18.0,500.0,1.0057837,0.85922265,18.127264,507.9519,-9.5811357
212.2965,0.13033991,9.5096292,0.0,0,18.0,500.0,1.0053476,0.61388749,18.128754,507.92096,-9.6020203
212.2991,0.1378067,9.5163927,0.0,0,18.0,500.0,1.0056564,0.62150908,18.124666,507.90009,-9.6206799
212.3017,0.17300777,9.5120621,0.0,0,18.0,500.0,1.0047525,0.80406165,18.120445,507.89258,-9.6391745
212.3043,0.15526977,9.5136337,0.0,0,18.0,500.0,1.0047973,0.74210477,18.118261,507.88507,-9.6584034
212.3069,0.11498265,9.5083857,0.0,0,18.0,500.0,1.0045043,0.53682619,18.118111,507.87756,-9.679204
212.3095,0.18106918,9.508812,0.0,0,18.0,500.0,1.0052147,0.81873375,18.119501,507.88065,-9.6983986
212.3121,0.14555024,9.50774,0.0,0,18.0,500.0,1.0058963,0.71924853,18.11344,507.89612,-9.7195816
212.3147,0.11335881,9.5082026,0.0,0,18.0,500.0,1.0057056,0.55716741,18.111177,507.91162,-9.7396135
212.3173,0.17330776,9.5129204,0.0,0,18.0,500.0,1.0058514,0.81586361,18.111246,507.92709,-9.7591248
212.3199,0.15045816,9.5085592,0.0,0,18.0,500.0,1.0044218,0.72331154,18.111135,507.93787,-9.778594
212.3225,0.11961559,9.5140896,0.0,0,18.0,500.0,1.004701,0.57094389,18.110155,507.94562,-9.7981195
212.3251,0.16843197,9.5093098,0.0,0,18.0,500.0,1.0042813,0.74926466,18.109165,507.95334,-9.818655
212.3277,0.16499056,9.5068283,0.0,0,18.0,500.0,1.0043921,0.8006987,18.109217,507.96109,-9.8367405
212.3303,0.11075331,9.5051994,0.0,0,18.0,500.0,1.0048876,0.54373878,18.108547,507.95132,-9.8582649
212.3329,0.13872537,9.5051832,0.0,0,18.0,500.0,1.0053761,0.65133721,18.106876,507.93582,-9.8786383
212.3355,0.14984639,9.5071373,0.0,0,18.0,500.0,1.0054698,0.73828143,18.105976,507.92035,-9.8973312
212.3381,0.1179274,9.508853,0.0,0,18.0,500.0,1.0049816,0.55389869,18.10214,507.90488,-9.917695
212.3407,0.13418335,9.5153971,0.0,0,18.0,500.0,1.0052601,0.60710263,18.10437,507.8685,-9.9371824
212.3433,0.17783327,9.5104752,0.0,0,18.0,500.0,1.0042703,0.81094605,18.100042,507.8298,-9.9562407
212.3459,0.11502659,9.5113153,0.0,0,18.0,500.0,1.0045831,0.53682202,18.097408,507.79111,-9.9767504
212.3485,0.14604488,9.5085945,0.0,0,18.0,500.0,1.0047617,0.62689298,18.097055,507.75418,-9.9960108
212.3511,0.17659736,9.506938,0.0,0,18.0,500.0,1.0049744,0.82772857,18.096071,507.75418,-10.015581
212.3537,0.10852571,9.5089951,0.0,0,18.0,500.0,1.0061297,0.51590395,18.100929,507.75418,-10.036523
212.3563,0.12068031,9.5099277,0.0,0,18.0,500.0,1.0058352,0.5341925,18.100574,507.75418,-10.056322
212.3589,0.18974651,9.5157804,0.0,0,18.0,500.0,1.0059739,0.87208378,18.094021,507.75119,-10.075271
212.3615,0.13920204,9.5120258,0.0,0,18.0,500.0,1.004846,0.65729874,18.093098,507.73572,-10.094452
212.3641,0.13445437,9.5152664,0.0,0,18.0,500.0,1.004922,0.62523693,18.093006,507.72025,-10.115164
212.3667,0.18670391,9.5091791,0.0,0,18.0,500.0,1.0043886,0.86872613,18.091398,507.70477,-10.134264
212.3693,0.14638707,9.5060015,0.0,0,18.0,500.0,1.0045253,0.68747842,18.092283,507.68405,-10.152818
212.3719,0.14244989,9.5053196,0.0,0,18.0,500.0,1.0051322,0.65362024,18.093166,507.65308,-10.173992
212.3745,0.19301614,9.5042858,0.0,0,18.0,500.0,1.0050558,0.84822601,18.091734,507.6221,-10.192278
212.3771,0.1568266,9.5101089,0.0,0,18.0,500.0,1.0058801,0.72988641,18.091002,507.59116,-10.211561
212.3797,0.14610572,9.5119143,0.0,0,18.0,500.0,1.0055282,0.6900056,18.088377,507.56018,-10.232012
212.3823,0.17193508,9.5156422,0.0,0,18.0,500.0,1.0051014,0.77052104,18.087978,507.52924,-10.251349
212.3849,0.17178813,9.5114746,0.0,0,18.0,500.0,1.0042595,0.8170706,18.088257,507.49826,-10.27083
212.3875,0.12128741,9.5124922,0.0,0,18.0,500.0,1.0047978,0.56211406,18.091019,507.46732,-10.291453
212.3901,0.1885232,9.5090332,0.0,0,18.0,500.0,1.0051911,0.84697551,18.087851,507.44122,-10.310111
212.3927,0.17134956,9.5079517,0.0,0,18.0,500.0,1.005641,0.81082183,18.085096,507.418,-10.330215
212.3953,0.13824742,9.5122757,0.0,0,18.0,500.0,1.0066615,0.64441574,18.084738,507.39481,-10.35029
212.3979,0.17508005,9.5117331,0.0,0,18.0,500.0,1.0059092,0.80251294,18.086895,507.37158,-10.370236
212.4005,0.17510574,9.5176868,0.0,0,18.0,500.0,1.0060185,0.788001,18.078831,507.34235,-10.390451
212.4031,0.13027143,9.5153599,0.0,0,18.0,500.0,1.005487,0.63165301,18.07847,507.31137,-10.410309
212.4057,0.1620014,9.5166426,0.0,0,18.0,500.0,1.0052599,0.73751187,18.07774,507.28043,-10.428267
212.4083,0.18433265,9.5109816,0.0,0,18.0,500.0,1.0048774,0.85751879,18.076946,507.24945,-10.44924
212.4109,0.12851889,9.51126,0.0,0,18.0,500.0,1.0055695,0.6000008,18.084503,507.21133,-10.469093
212.4135,0.1538429,9.5090084,0.0,0,18.0,500.0,1.0059851,0.67910433,18.080246,507.17264,-10.489704
212.4161,0.17675641,9.5078993,0.0,0,18.0,500.0,1.0057895,0.84614402,18.074409,507.13394,-10.508393
212.4187,0.13793543,9.512558,0.0,0,18.0,500.0,1.0061107,0.66638863,18.074314,507.09686,-10.528572
212.4213,0.14232533,9.5143385,0.0,0,18.0,500.0,1.0056366,0.61875099,18.074102,507.08139,-10.549643
212.4239,0.17841442,9.518116,0.0,0,18.0,500.0,1.0054665,0.85515773,18.074879,507.06589,-10.567643
212.4265,0.14039403,9.5132017,0.0,0,18.0,500.0,1.0046606,0.67460221,18.074881,507.05042,-10.587693
212.4291,0.15529181,9.5133247,0.0,0,18.0,500.0,1.0053378,0.65334839,18.075281,507.03659,-10.608348
212.4317,0.18853951,9.5079823,0.0,0,18.0,500.0,1.0051807,0.88861549,18.076351,507.02887,-10.626607
212.4343,0.13946635,9.5069332,0.0,0,18.0,500.0,1.0054027,0.66978675,18.074699,507.02112,-10.646915
212.4369,0.14745361,9.5108538,0.0,0,18.0,500.0,1.0061716,0.6834687,18.07168,507.01337,-10.666984
212.4395,0.19607332,9.5124073,0.0,0,18.0,500.0,1.005861,0.91124189,18.070805,506.99722,-10.685484
212.4421,0.1588884,9.5186119,0.0,0,18.0,500.0,1.0059865,0.72997952,18.069378,506.96628,-10.705768
212.4447,0.14074491,9.5155497,0.0,0,18.0,500.0,1.0054473,0.64018553,18.069376,506.93533,-10.727452
212.4473,0.19373499,9.5165377,0.0,0,18.0,500.0,1.0053442,0.89191264,18.06905,506.90436,-10.745951
212.4499,0.1807607,9.5112467,0.0,0,18.0,500.0,1.0052347,0.80941433,18.067707,506.86948,-10.765498
212.4525,0.15160875,9.5107832,0.0,0,18.0,500.0,1.0057837,0.70482928,18.061138,506.83078,-10.786061
212.4551,0.18424472,9.5098639,0.0,0,18.0,500.0,1.0062917,0.86083078,18.061741,506.79208,-10.804571
212.4577,0.16889131,9.5115252,0.0,0,18.0,500.0,1.0063158,0.82326227,18.067337,506.75339,-10.823303
212.4603,0.15410772,9.5180998,0.0,0,18.0,500.0,1.0068283,0.67900479,18.059095,506.71469,-10.842466
212.4629,0.19506171,9.517108,0.0,0,18.0,500.0,1.005944,0.90071493,18.061073,506.67596,-10.862504
212.4655,0.18293843,9.5197916,0.0,0,18.0,500.0,1.0056159,0.88426191,18.063227,506.63727,-10.880902
212.4681,0.13872759,9.514883,0.0,0,18.0,500.0,1.005034,0.68102509,18.060101,506.59857,-10.901322
212.4707,0.18778512,9.5147638,0.0,0,18.0,500.0,1.0058403,0.80845952,18.05834,506.54129,-10.922902
212.4733,0.17878243,9.5100269,0.0,0,18.0,500.0,1.005826,0.88027203,18.061964,506.47937,-10.94173
212.4759,0.15031376,9.5099707,0.0,0,18.0,500.0,1.0060693,0.70379168,18.062386,506.41745,-10.961996
212.4785,0.17575626,9.5120544,0.0,0,18.0,500.0,1.0063726,0.77324611,18.057308,506.35553,-10.983657
212.4811,0.18133716,9.5129004,0.0,0,18.0,500.0,1.0057894,0.86012018,18.057915,506.31558,-11.001734
212.4837,0.15668374,9.5183554,0.0,0,18.0,500.0,1.0056731,0.73450309,18.060505,506.27689,-11.021819
212.4863,0.1667262,9.5134706,0.0,0,18.0,500.0,1.0049028,0.72758895,18.05835,506.23819,-11.040492
212.4889,0.19290827,9.5140514,0.0,0,18.0,500.0,1.0051051,0.92003757,18.059206,506.20163,-11.060442
212.4915,0.14090396,9.5095892,0.0,0,18.0,500.0,1.0050768,0.66073644,18.060007,506.18616,-11.081369
212.4941,0.16278093,9.5108662,0.0,0,18.0,500.0,1.0056673,0.70036906,18.0571,506.17068,-11.099904
212.4967,0.19453955,9.5104342,0.0,0,18.0,500.0,1.0063398,0.9048211,18.055508,506.15518,-11.119052
212.4993,0.1576771,9.5116415,0.0,0,18.0,500.0,1.0061899,0.75884807,18.057053,506.13788,-11.139937
212.5019,0.15529829,9.5190659,0.0,0,18.0,500.0,1.0067093,0.71198273,18.055929,506.11462,-11.160623
212.5045,0.19371967,9.5162296,0.0,0,18.0,500.0,1.0057259,0.88928843,18.057182,506.0914,-11.179418
212.5071,0.16237077,9.5201683,0.0,0,18.0,500.0,1.0056863,0.79765707,18.057087,506.06818,-11.198492
212.5097,0.15407224,9.5146475,0.0,0,18.0,500.0,1.00525,0.68542123,18.053448,506.03009,-11.218884
212.5123,0.20750007,9.5124645,0.0,0,18.0,500.0,1.0056096,0.94869077,18.052986,505.96817,-11.237704
212.5149,0.1675908,9.5098181,0.0,0,18.0,500.0,1.0059454,0.78830081,18.050577,505.90625,-11.256956
212.5175,0.15764591,9.5106916,0.0,0,18.0,500.0,1.0063865,0.72143137,18.048595,505.84433,-11.275848
212.5201,0.20956472,9.5160923,0.0,0,18.0,500.0,1.0070195,0.94996113,18.050699,505.79474,-11.29645
212.5227,0.17434011,9.515686,0.0,0,18.0,500.0,1.0063071,0.85463566,18.050385,505.75604,-11.31581
212.5253,0.15403427,9.5206194,0.0,0,18.0,500.0,1.0061768,0.73219883,18.052498,505.71735,-11.337276
212.5279,0.20248683,9.5165253,0.0,0,18.0,500.0,1.0052536,0.90630269,18.051224,505.67865,-11.356647
213.229,0.12311598,9.5209274,0.0,0,18.0,1.4427177e-07,1.0070952,0.56473118,18.003839,490.49268,-11.48223
214.529,0.086864963,9.5323067,0.0,0,18.0,2.6994805e-25,1.0092254,0.401788,18.001497,472.04068,-11.482016
215.829,0.071733825,9.5417929,0.0,0,18.0,5.0446745e-43,1.0109602,0.33408162,18.000132,457.20395,-11.482394
217.129,0.068350136,9.5508156,0.0,0,18.0,1.4012985e-45,1.0125419,0.31510413,18.000208,443.55835,-11.482396
218.429,0.059966013,9.559638,0.0,0,18.0,1.4012985e-45,1.014166,0.28044075,17.99931,430.98734,-11.48285
219.729,0.057780046,9.5675077,0.0,0,18.0,1.4012985e-45,1.0157427,0.26975143,18.000427,418.8208,-11.482561
221.029,0.055124305,9.5753813,0.0,0,18.0,1.4012985e-45,1.0171046,0.25020468,18.000368,407.23657,-11.482727
222.329,0.049686156,9.5826845,0.0,0,18.0,1.4012985e-45,1.0184563,0.22550356,17.99934,396.23688,-11.482122
223.629,0.05076541,9.5899391,0.0,0,18.0,1.4012985e-45,1.0197108,0.22757746,17.999634,385.38702,-11.482242
224.929,0.051749893,9.5972519,0.0,0,18.0,1.4012985e-45,1.0212148,0.24200635,18.000523,374.88358,-11.482501
226.229,0.050281383,9.6033344,0.0,0,18.0,1.4012985e-45,1.0222644,0.22930144,18.000786,364.86606,-11.482548
227.529,0.047454868,9.6099195,0.0,0,18.0,1.4012985e-45,1.0235565,0.21827586,17.999985,355.13208,-11.482499
228.829,0.048106365,9.6163673,0.0,0,18.0,1.4012985e-45,1.0246012,0.2204666,18.000378,345.66791,-11.482279
230.129,0.047218747,9.6224747,0.0,0,18.0,1.4012985e-45,1.0258319,0.216039,18.000309,336.36288,-11.482128
231.429,0.047612388,9.6284695,0.0,0,18.0,1.4012985e-45,1.0269507,0.21649492,18.00065,327.1413,-11.482344
232.729,0.044210017,9.6325188,0.0,0,18.0,1.4012985e-45,1.0277194,0.19858862,18.000059,318.1384,-11.482203
234.029,0.04409859,9.6376143,0.0,0,18.0,1.4012985e-45,1.0285884,0.20203876,17.999956,309.71002,-11.482244
235.329,0.041674208,9.6427326,0.0,0,18.0,1.4012985e-45,1.0295691,0.19197646,18.000551,301.36496,-11.482528
236.629,0.044455484,9.6475401,0.0,0,18.0,1.4012985e-45,1.0305601,0.20137939,17.999817,293.03757,-11.482125
237.929,0.041978676,9.6523819,0.0,0,18.0,1.4012985e-45,1.0313923,0.18900032,18.000755,285.30359,-11.482481
239.229,0.041847721,9.6576748,0.0,0,18.0,1.4012985e-45,1.0323814,0.18324481,17.999733,277.74902,-11.482388
240.529,0.04133445,9.6631031,0.0,0,18.0,1.4012985e-45,1.033343,0.18622497,18.000427,270.40134,-11.482621
241.829,0.041967213,9.6671467,0.0,0,18.0,1.4012985e-45,1.0342371,0.18854368,17.999434,263.03265,-11.482516
243.129,0.03994488,9.6719837,0.0,0,18.0,1.4012985e-45,1.0350183,0.18191905,18.00062,256.22147,-11.482426
244.429,0.041003775,9.6760473,0.0,0,18.0,1.4012985e-45,1.0358531,0.18528356,17.999903,249.54463,-11.482535
245.729,0.035456035,9.6807365,0.0,0,18.0,1.4012985e-45,1.0366586,0.15975389,18.000072,242.89526,-11.482632
247.029,0.035445973,9.6843777,0.0,0,18.0,1.4012985e-45,1.0374756,0.16200337,17.999538,236.30603,-11.482175
248.329,0.039749548,9.688653,0.0,0,18.0,1.4012985e-45,1.0382155,0.17863199,17.99992,230.19798,-11.482247
249.629,0.034196835,9.6923294,0.0,0,18.0,1.4012985e-45,1.0389416,0.15375747,17.99938,224.21796,-11.482444
250.929,0.031828701,9.6966333,0.0,0,18.0,1.4012985e-45,1.0396351,0.14529897,18.000563,219.42813,-11.482266
252.229,0.03152582,9.7002945,0.0,0,18.0,1.4012985e-45,1.040431,0.14405748,18.000572,213.64319,-11.482666
253.529,0.033528764,9.7040968,0.0,0,18.0,1.4012985e-45,1.0411425,0.14687236,18.000591,208.44408,-11.482345
254.829,0.034714133,9.7073479,0.0,0,18.0,1.4012985e-45,1.0417798,0.15729453,17.999519,203.24419,-11.482721
256.129,0.030531412,9.7115927,0.0,0,18.0,1.4012985e-45,1.0424809,0.13822766,17.999945,197.84511,-11.482366
257.429,0.03068113,9.7147799,0.0,0,18.0,1.4012985e-45,1.0431058,0.13716385,18.00075,192.81021,-11.482476
258.729,0.029687749,9.7177114,0.0,0,18.0,1.4012985e-45,1.0437425,0.13435413,18.000446,187.76241,-11.48234
260.029,0.031531531,9.7213116,0.0,0,18.0,1.4012985e-45,1.0443884,0.13998534,18.000923,182.85947,-11.482432
261.329,0.029070789,9.7245436,0.0,0,18.0,1.4012985e-45,1.0449686,0.13100833,18.000229,178.24246,-11.48244
262.629,0.027717674,9.72791,0.0,0,18.0,1.4012985e-45,1.0455754,0.12471427,18.000135,173.68935,-11.482459
263.929,0.02550807,9.7301702,0.0,0,18.0,1.4012985e-45,1.0461177,0.11417582,18.000303,169.31789,-11.482387
265.229,0.029139968,9.7333984,0.0,0,18.0,1.4012985e-45,1.0466653,0.13154306,18.000078,165.04828,-11.482414
266.529,0.029184042,9.7361746,0.0,0,18.0,1.4012985e-45,1.0471874,0.12877955,17.999887,160.88608,-11.482367
267.829,0.024533281,9.7391768,0.0,0,18.0,1.4012985e-45,1.047699,0.10750958,18.000568,157.17728,-11.482509
269.129,0.023987904,9.7416239,0.0,0,18.0,1.4012985e-45,1.0483187,0.1065646,18.000347,153.30574,-11.482373
270.429,0.026181689,9.7442169,0.0,0,18.0,1.4012985e-45,1.0486991,0.11865757,17.999517,149.45815,-11.482437
271.729,0.026988531,9.7472763,0.0,0,18.0,1.4012985e-45,1.0493376,0.12433047,17.99967,145.83517,-11.482261
272.529,0.023904046,9.748889,0.0,0,18.0,1.4012985e-45,1.0495882,0.10259532,18.00028,143.60213,-11.482569