File: examples/dan-msc-case-studies/CS3/data/01 raw data/baron_test_065.csv
Time(sec),Force(kN),Jaw(mm),PowAngle(deg),Power(W),Pram,PTemp,Strain,Stress(MPa),Stroke(mm),TC1(C),wedge(mm)
0.0,0.91384333,0.51115668,0.0,0,10.594783,0.0013620723,0.034664843,11.233622,10.594357,25.704758,-9.11656
2.2,0.83149922,-0.0031115497,0.0,0,10.594783,6.5159135,-0.00023078952,10.591159,10.594938,25.682335,-9.4826078
4.4,0.78790724,-0.0034143322,0.0,0,10.594783,13.115914,-0.00020285144,10.030872,10.595011,25.739929,-9.4795094
6.6,0.77192014,-0.0032874262,0.0,0,10.594783,19.715918,-0.000209409,9.8375034,10.594528,25.606052,-9.4759741
8.8,0.7490291,-0.0030665267,0.0,0,10.594783,26.315914,-0.00021865944,9.5280313,10.594386,25.617304,-9.4717922
11.0,0.75694174,-0.0039260127,31.177,0,10.594783,32.915913,-0.00025324739,9.6382084,10.594832,27.497738,-9.4683123
13.2,0.76408499,-0.0089865196,38.550194,0,10.594783,39.515907,-0.00061415473,9.7360687,10.594446,34.54438,-9.4651527
15.4,0.77224165,-0.015018793,39.924313,0,10.594783,46.11591,-0.00099139451,9.8376112,10.594618,43.434849,-9.4613371
17.6,0.77615517,-0.020385077,39.255634,0,10.594783,52.7159,-0.0013571506,9.8776217,10.594467,51.881203,-9.4574347
19.8,0.78806841,-0.024733881,39.243168,0,10.594783,59.315914,-0.0016777314,10.051038,10.594933,59.064056,-9.4537268
22.0,0.78690594,-0.03003698,39.24316,0,10.594783,65.915909,-0.0019717347,10.048764,10.594711,65.730919,-9.4503155
24.2,0.79125106,-0.03407333,39.924313,0,10.594783,72.5159,-0.0022623756,10.094626,10.595019,72.056068,-9.4465761
26.4,0.80067831,-0.039214849,40.572506,0,10.594783,79.115898,-0.0026323779,10.211751,10.594727,78.631874,-9.4431791
28.6,0.80313402,-0.043784816,41.198727,0,10.594783,85.715919,-0.0029075262,10.258408,10.594748,85.17347,-9.4394169
30.8,0.80708784,-0.049416728,41.802975,0,10.594783,92.315926,-0.0033009839,10.309849,10.594851,91.794067,-9.4351931
33.0,0.82209015,-0.05403338,42.396236,0,10.594783,98.915924,-0.0035848366,10.496894,10.594894,98.370338,-9.4318371
35.2,0.83268929,-0.059260052,42.773861,0,10.594783,105.51592,-0.0039479621,10.641268,10.593785,105.08277,-9.4286175
37.4,0.82509524,-0.063802533,42.978512,0,10.594783,112.11592,-0.0042707976,10.549704,10.594863,111.79271,-9.4247713
39.6,0.83892286,-0.068700179,43.527828,0,10.594783,118.71592,-0.0045461105,10.716516,10.594783,118.23118,-9.4212646
41.8,0.84281969,-0.074196048,44.077095,0,10.594783,125.3159,-0.0049238252,10.769944,10.594345,124.87733,-9.4173784
44.0,0.85156447,-0.079595082,44.225807,0,10.594783,131.91591,-0.0053031244,10.90854,10.593739,131.46674,-9.413475
46.2,0.85923952,-0.085084811,44.604488,0,10.594783,138.5159,-0.0056597106,11.008058,10.594519,138.09009,-9.4101381
48.4,0.85315943,-0.090345725,45.12085,0,10.594783,145.11588,-0.0060237856,10.930276,10.595244,144.7258,-9.4070845
50.6,0.87035227,-0.095641479,45.12085,0,10.594783,151.71591,-0.0063372557,11.1471,10.594554,151.36694,-9.4033508
52.8,0.88293642,-0.10112952,45.615231,0,10.594783,158.31592,-0.0067190672,11.31718,10.594675,157.86577,-9.3993959
55.0,0.87741429,-0.10680601,46.109619,0,10.594783,164.91592,-0.0071129198,11.243728,10.595136,164.40831,-9.3956347
57.2,0.88185781,-0.11251706,46.448521,0,10.594783,171.51591,-0.0074580414,11.30954,10.594617,171.14156,-9.3918858
59.4,0.89017373,-0.11833445,46.471909,0,10.594783,178.11592,-0.0078590764,11.423324,10.594678,177.95628,-9.3883677
61.6,0.89850968,-0.12579067,46.582027,0,10.594783,184.71591,-0.0083475811,11.52646,10.595553,184.57367,-9.3848658
63.8,0.89280504,-0.13098371,47.05444,0,10.594783,191.3159,-0.0087026488,11.479725,10.594473,190.97874,-9.3814707
66.0,0.90052146,-0.13650414,47.055122,0,10.594783,197.91589,-0.0090712328,11.564141,10.594886,197.58824,-9.378149
68.2,0.90290749,-0.14321446,47.504883,0,10.594783,204.5159,-0.0094780438,11.621674,10.594682,204.33054,-9.3743219
70.4,0.89619851,-0.14805557,47.504883,0,10.594783,211.11592,-0.0098044593,11.517209,10.594944,210.91008,-9.3706217
72.6,0.90207893,-0.15448414,47.955318,0,10.594783,217.71593,-0.010262183,11.604935,10.593843,217.33331,-9.3664865
74.8,0.90480596,-0.16061589,48.19714,0,10.594783,224.31592,-0.010641038,11.627944,10.596057,224.01277,-9.3629436
77.0,0.91451734,-0.16688165,48.198902,0,10.594783,230.91591,-0.011080626,11.790053,10.594056,230.81012,-9.3590183
79.2,0.91577488,-0.17346218,48.383785,0,10.594783,237.51591,-0.011478961,11.793724,10.593563,237.30884,-9.3556366
81.4,0.90106702,-0.17896254,48.812252,0,10.594783,244.11591,-0.011860367,11.611862,10.594836,243.73463,-9.3520823
83.6,0.91519219,-0.18449603,49.078175,0,10.594783,250.7159,-0.012247327,11.806192,10.594246,250.37686,-9.3486214
85.8,0.92460334,-0.19061157,49.218517,0,10.594783,257.31616,-0.012606851,11.930573,10.594665,257.10709,-9.3453026
88.0,0.91350412,-0.19800094,49.229733,0,10.594783,263.91589,-0.013103788,11.80145,10.5954,263.61453,-9.3413363
90.2,0.90996855,-0.20268996,49.636227,0,10.594783,270.51593,-0.013433781,11.74119,10.594438,270.27814,-9.3375292
92.4,0.91267049,-0.20902206,49.863235,0,10.594783,277.11594,-0.013833781,11.768157,10.594123,276.80856,-9.3339262
94.6,0.92321128,-0.21530871,50.042721,0,10.594783,283.71594,-0.014269764,11.93293,10.59478,283.36868,-9.3299589
96.8,0.92712867,-0.2222462,50.164112,0,10.594783,290.31592,-0.014689639,11.975331,10.594899,290.01453,-9.32656
99.0,0.91996157,-0.2287423,50.438229,0,10.594783,296.91592,-0.015128737,11.908143,10.594904,296.60187,-9.3233519
101.2,0.92468011,-0.23412032,50.671978,0,10.594783,303.5159,-0.015502336,11.974903,10.594993,303.26831,-9.3193922
103.4,0.93039119,-0.24292739,50.82275,0,10.594783,310.11591,-0.01604596,12.040605,10.594807,309.87527,-9.3162098
105.6,0.92043036,-0.24780312,50.822758,0,10.594783,316.71591,-0.016396485,11.908466,10.594304,316.55441,-9.3123007
107.8,0.93133068,-0.25388774,51.079929,0,10.594783,323.31589,-0.016770655,12.060361,10.594489,323.03842,-9.3087454
110.0,0.93399209,-0.26165712,51.196285,0,10.594783,329.91589,-0.017280474,12.104547,10.594453,329.58194,-9.3049078
112.2,0.92426056,-0.26762187,51.233948,0,10.594783,336.51593,-0.017711362,11.98307,10.593981,336.3233,-9.301095
114.4,0.93447518,-0.27657163,51.251945,0,10.594783,343.11591,-0.018255034,12.106109,10.594928,343.01013,-9.297574
116.6,0.93512505,-0.28096455,51.083221,0,10.594783,349.71591,-0.018566791,12.126966,10.594439,350.0658,-9.2940454
118.8,0.92346007,-0.28768399,50.438236,0,10.594783,356.31592,-0.018995369,11.987581,10.594575,357.09399,-9.2909718
121.0,0.062702566,-0.30444732,48.143639,0,10.594783,359.99924,-0.020094933,0.82094002,10.594306,362.34219,-9.2892141
123.2,0.036603007,-0.30286795,45.615238,0,10.594783,359.99924,-0.020017324,0.47741324,10.594884,362.66553,-9.2887125
125.4,0.026554281,-0.30077258,45.176601,0,10.594783,359.99924,-0.019838069,0.35349542,10.59479,361.14468,-9.2882032
127.6,0.026223613,-0.29804763,48.80558,0,10.594783,359.99924,-0.019681983,0.35207528,10.594185,357.78387,-9.2884779
129.8,0.036765199,-0.29849997,52.279575,0,10.594783,359.99924,-0.019696278,0.48803675,10.59526,356.16403,-9.2878809
132.0,0.045660459,-0.29900864,53.920002,0,10.594783,359.99924,-0.019733211,0.60018796,10.594597,356.94498,-9.2878294
134.2,0.055470902,-0.30037251,53.65723,0,10.594783,359.99924,-0.019848749,0.71130949,10.594568,359.04849,-9.2881584
136.4,0.066338122,-0.30283174,52.635632,0,10.594783,359.99924,-0.019976811,0.86137724,10.594016,360.46515,-9.2880793
138.6,0.055346504,-0.30261043,51.636288,0,10.594783,359.99924,-0.019977696,0.72334081,10.59514,361.10657,-9.2881451
140.8,0.062546939,-0.30266786,51.196293,0,10.594783,359.99924,-0.019977091,0.81630492,10.595423,360.82779,-9.2881842
143.0,0.043461051,-0.30331346,51.225311,0,10.594783,359.99924,-0.020014901,0.55791259,10.594289,360.28238,-9.2881012
145.2,0.048732359,-0.30311379,51.196293,0,10.594783,359.99924,-0.020027198,0.63473213,10.594668,360.19739,-9.287591
147.4,0.045100298,-0.30438116,51.424019,0,10.594783,359.99924,-0.020075677,0.58158153,10.595123,359.89365,-9.2872238
149.6,0.042993687,-0.30418572,51.932369,0,10.594783,359.99924,-0.020070627,0.54364908,10.595748,359.3559,-9.2875366
151.8,0.056019396,-0.30454165,52.611267,0,10.594783,359.99924,-0.020106195,0.73839271,10.594444,359.35919,-9.2876711
154.0,0.066637456,-0.30559558,52.283939,0,10.594783,359.99924,-0.020166606,0.88948452,10.594886,359.88818,-9.2878933
156.2,0.072370373,-0.30774733,51.571983,0,10.594783,359.99924,-0.020330608,0.92618865,10.59452,360.5983,-9.287529
158.4,0.049146075,-0.30723512,51.196293,0,10.594783,359.99924,-0.020257588,0.63872933,10.594347,360.70984,-9.2873955
160.6,0.045532878,-0.30751204,50.822758,0,10.594783,359.99924,-0.020281054,0.59259492,10.595074,360.49817,-9.2871037
162.8,0.055852279,-0.30767864,51.180424,0,10.594783,359.99924,-0.020327,0.71981198,10.594678,360.04129,-9.2870092
165.0,0.057919361,-0.307971,51.272842,0,10.594783,359.99924,-0.020307809,0.74829614,10.594188,359.75995,-9.2871952
165.2841,0.1744948,0.0089416048,0.0,0,10.5948,3.8939123000000003e-22,0.00035444743,2.1482375,10.594445,359.81284,-9.2864399
165.2885,0.1633063,0.0055924673,0.0,0,10.5948,0.0,0.00016448618,2.0670445,10.595735,359.71967,-9.285758
165.2929,0.15715861,0.0080245519,0.0,0,10.5948,0.0,0.00034605744,2.0333622,10.594657,359.62653,-9.2882767
165.2973,0.16448018,0.0054390156,0.0,0,10.5948,0.0,0.00014363661,2.0299721,10.594281,359.67883,-9.2869654
165.3017,0.17155153,0.0079401489,0.0,0,10.5948,0.0,0.00023038989,2.2367053,10.595098,359.75867,-9.2874317
165.3061,0.17641003,0.0044584838,0.0,0,10.5948,0.0,0.00020442391,2.2117352,10.595076,359.79352,-9.2865639
165.3105,0.17022732,0.0098364344,0.0,0,10.5948,0.0,0.00033105561,2.1647017,10.594809,359.79352,-9.2883301
165.3149,0.167731,0.0080354018,0.0,0,10.5948,0.0,0.00035733421,2.065388,10.595205,359.7897,-9.2875414
165.3193,0.1861372,0.010019782,0.0,0,10.5948,0.0,0.00036974816,2.3624957,10.595221,359.7764,-9.2859392
165.3237,0.18859896,0.0071430816,0.0,0,10.5948,0.0,0.00030270018,2.3231044,10.594356,359.76321,-9.2866678
165.3281,0.17752391,0.011319327,0.0,0,10.5948,0.0,0.00046557895,2.4121337,10.594555,359.76321,-9.2872057
165.3325,0.18344046,0.0071024015,0.0,0,10.566863,0.0,0.00029738556,2.274713,10.58969,359.76321,-9.2859869
165.3369,0.1930507,0.011800391,0.0,0,10.500864,0.0,0.00057683181,2.4028101,10.592396,359.79242,-9.2869091
165.3413,0.19458006,0.0078322114,0.0,0,10.434863,0.0,0.0003417861,2.4864824,10.572994,359.83234,-9.2861137
165.3457,0.19880712,0.012452659,0.0,0,10.368864,0.0,0.00063779345,2.5681813,10.518131,359.86017,-9.2878914
165.3501,0.18767308,0.0070802253,0.0,0,10.302863,0.0,0.00039148179,2.3974757,10.416495,359.87347,-9.2880039
165.3545,0.18439916,0.010855244,0.0,0,10.236864,0.0,0.00053861458,2.3535178,10.318102,359.87735,-9.2878628
165.3589,0.2041311,0.0082907844,0.0,0,10.170864,0.0,0.00048151196,2.6892366,10.245155,359.83743,-9.2878761
165.3633,0.19292003,0.011711977,0.0,0,10.104864,0.0,0.00065780251,2.5319889,10.194613,359.79752,-9.2860603
165.3677,0.19148883,0.008280633,0.0,0,10.038863,0.0,0.00048022333,2.409656,10.141965,359.78156,-9.2874212
165.3721,0.19062117,0.011163384,0.0,0,9.9728632,0.0,0.00065567996,2.4356177,10.078391,359.76825,-9.2876444
165.3765,1.7413547,0.029941967,0.0,0,9.9068632,0.0,0.0019330219,21.853548,10.010893,359.95383,-9.286191
165.3809,4.0948648,0.062165473,0.0,0,9.8408632,0.0,0.0040298249,51.719944,9.9440765,360.25989,-9.28438
165.3853,5.2603388,0.12181871,0.0,0,9.7748632,0.0,0.0081297746,66.410599,9.8715706,360.67172,-9.2821875
165.3897,5.8973384,0.19044057,0.0,0,9.7088633,0.0,0.012788381,74.044731,9.800272,361.28387,-9.282403
165.3941,6.3311801,0.25239435,0.0,0,9.6428633,0.0,0.016946329,79.35199,9.733942,361.88153,-9.2825651
165.3985,6.589653,0.31964225,0.0,0,9.5768633,0.0,0.021562122,82.071823,9.6634483,362.28076,-9.2815838
165.4029,6.7750669,0.38078934,0.0,0,9.5108633,0.0,0.025684882,84.052147,9.5968781,362.67999,-9.2812729
165.4073,6.9246798,0.44869912,0.0,0,9.4457693,0.0,0.030453956,85.408707,9.5312977,362.99503,-9.282794
165.4117,7.0794759,0.50931334,0.0,0,9.3813896,0.0,0.034546625,87.02948,9.4651976,363.28778,-9.2841673
165.4161,7.1635795,0.57715398,0.0,0,9.317008,0.0,0.039349135,87.654984,9.3959637,363.56006,-9.2828722
165.4205,7.2195168,0.63872224,0.0,0,9.2526274,0.0,0.043611959,87.967537,9.3308687,363.8129,-9.283535
165.4249,7.300149,0.70262432,0.0,0,9.1882467,0.0,0.048118751,88.568779,9.2651825,364.05316,-9.2842703
165.4293,7.3994823,0.76653022,0.0,0,9.1238651,0.0,0.052521639,89.324944,9.198741,364.25278,-9.2840958
165.4337,7.4636712,0.83177006,0.0,0,9.0594854,0.0,0.057186406,89.74353,9.1329756,364.45239,-9.2835016
165.4381,7.5078816,0.89126164,0.0,0,8.9951048,0.0,0.061412271,89.81144,9.0693989,364.69031,-9.2834873
165.4425,7.5816598,0.95891428,0.0,0,8.9307232,0.0,0.066284858,90.353134,8.9986725,364.92987,-9.2851563
165.4469,7.6505971,1.0231184,0.0,0,8.8663425,0.0,0.070807509,90.658325,8.9323826,365.14218,-9.2846756
165.4513,7.7154746,1.0871856,0.0,0,8.8019619,0.0,0.075445458,91.08963,8.8688936,365.34177,-9.2843208
165.4557,7.7377768,1.1475883,0.0,0,8.7381983,0.0,0.079784408,90.97287,8.8034878,365.49295,-9.2848253
165.4601,7.8066859,1.2110916,0.0,0,8.6769676,0.0,0.084441893,91.448524,8.7416954,365.57278,-9.2853031
165.4645,7.8479466,1.2746941,0.0,0,8.615737,0.0,0.089058004,91.374352,8.6770725,365.61877,-9.284483
165.4689,7.9160376,1.3341246,0.0,0,8.5545063,0.0,0.09344779,91.843086,8.6169519,365.43246,-9.2851868
165.4733,7.9556227,1.3972813,0.0,0,8.4932766,0.0,0.097999737,91.891106,8.5535994,365.24615,-9.2843399
165.4777,7.9873018,1.4579988,0.0,0,8.4320459,0.0,0.10252989,91.811775,8.4899244,365.30872,-9.2849474
165.4821,8.0468054,1.5182705,0.0,0,8.3708162,0.0,0.1069121,92.086227,8.4282198,365.41516,-9.2837744
165.4865,8.1278591,1.5800805,0.0,0,8.3095856,0.0,0.1116205,92.485817,8.3654499,365.55212,-9.2836399
165.4909,8.1569796,1.6401074,0.0,0,8.2483559,0.0,0.11599211,92.560982,8.30126,365.71182,-9.2836027
165.4953,8.1646109,1.6996202,0.0,0,8.1871252,0.0,0.12052413,92.116409,8.24401,365.78503,-9.2834072
165.4997,8.2206154,1.7589091,0.0,0,8.1258955,0.0,0.12490971,92.410294,8.1832066,365.65195,-9.2836905
165.5041,8.3062305,1.818978,0.0,0,8.0646648,0.0,0.12951542,92.870193,8.1184998,365.51086,-9.2840376
165.5085,8.3582458,1.8807437,0.0,0,8.0059099,0.0,0.1341482,93.099998,8.0547142,364.93863,-9.2828636
165.5129,8.360404,1.9414653,0.0,0,7.9476533,0.0,0.1387789,92.656296,7.9971266,364.36639,-9.2839088
165.5173,8.3946762,1.9992847,0.0,0,7.8893976,0.0,0.14319023,92.630333,7.9397264,363.76459,-9.2853699
165.5217,8.4673128,2.0534201,0.0,0,7.831141,0.0,0.14728406,92.973854,7.880527,363.1524,-9.2827644
165.5261,8.5176973,2.1121042,0.0,0,7.7728858,0.0,0.15185599,93.215324,7.8203254,362.86108,-9.2858438
165.5305,8.5506783,2.1684473,0.0,0,7.7146292,0.0,0.15621436,93.101845,7.7611589,362.94095,-9.2842188
165.5349,8.5893602,2.2311025,0.0,0,7.6563735,0.0,0.16112705,93.097382,7.7015996,363.04312,-9.2839184
165.5393,8.6691046,2.2844758,0.0,0,7.5981178,0.0,0.16523729,93.503464,7.6433935,363.24274,-9.2844439
165.5437,8.6994038,2.344662,0.0,0,7.5398612,0.0,0.1700063,93.465385,7.5875192,363.44235,-9.2843466
165.5481,8.7486019,2.4006653,0.0,0,7.4816051,0.0,0.17436726,93.580063,7.5277023,363.4726,-9.2849989
165.5525,8.7911358,2.4607761,0.0,0,7.4233494,0.0,0.17912963,93.489594,7.4673023,363.4859,-9.2843208
165.5569,8.8677216,2.5205195,0.0,0,7.3664303,0.0,0.18389781,93.989441,7.4066019,363.2049,-9.2838068
165.5613,8.9217291,2.581001,0.0,0,7.3110256,0.0,0.18866248,94.062271,7.345542,362.75244,-9.2841511
165.5657,8.9367771,2.6353154,0.0,0,7.2556205,0.0,0.19304359,93.774193,7.2902503,362.34717,-9.2832212
165.5701,8.9401979,2.6919994,0.0,0,7.2002158,0.0,0.19765458,93.451553,7.2353396,362.02777,-9.2843437
165.5745,8.9980659,2.744298,0.0,0,7.1448102,0.0,0.20191982,93.639633,7.1787701,361.71768,-9.2848577
165.5789,9.0595551,2.8023427,0.0,0,7.089406,0.0,0.20658903,93.810242,7.1224451,361.51804,-9.2837715
165.5833,9.1017838,2.8531041,0.0,0,7.0340009,0.0,0.21075627,93.835625,7.0678391,361.31842,-9.2850161
165.5877,9.1235504,2.9099264,0.0,0,6.9785962,0.0,0.21548524,93.663597,7.0122824,361.04428,-9.2854357
165.5921,9.1799145,2.9622884,0.0,0,6.9231911,0.0,0.21972962,93.849182,6.9561934,360.75153,-9.2823467
165.5965,9.2525387,3.0215688,0.0,0,6.8677864,0.0,0.2245601,94.073959,6.9017754,360.5144,-9.2840548
165.6009,9.2777319,3.0710704,0.0,0,6.8123817,0.0,0.22875358,94.009964,6.848412,360.32809,-9.2833738
165.6053,9.3153849,3.128298,0.0,0,6.7572598,0.0,0.23354752,93.949921,6.7902203,360.13522,-9.2841921
165.6097,9.3464956,3.1814406,0.0,0,6.7045479,0.0,0.23803718,93.821838,6.7377753,359.9223,-9.2843819
165.6141,9.4179888,3.2375531,0.0,0,6.6518359,0.0,0.24268161,94.071434,6.6816244,359.70938,-9.2828007
165.6185,9.484375,3.288312,0.0,0,6.599124,0.0,0.2471112,94.327873,6.6272278,359.77991,-9.2840042
165.6229,9.5144024,3.3474236,0.0,0,6.5464115,0.0,0.25207978,94.138039,6.5725675,359.85977,-9.2844887
165.6273,9.5258312,3.3948998,0.0,0,6.4937,0.0,0.25620025,93.905273,6.5202937,360.03156,-9.2840567
165.6317,9.6037598,3.4501817,0.0,0,6.4409881,0.0,0.2608203,94.203468,6.4663224,360.24448,-9.2837877
165.6361,9.6696806,3.5005651,0.0,0,6.3882761,0.0,0.26545751,94.433647,6.4144921,360.49042,-9.2846851
165.6405,9.7137737,3.5579138,0.0,0,6.3355641,0.0,0.27024153,94.392715,6.3595357,360.7832,-9.2844038
165.6449,9.7163944,3.6077032,0.0,0,6.2828526,0.0,0.27483854,93.969986,6.3070321,361.09052,-9.2839661
165.6493,9.7566662,3.6590345,0.0,0,6.2301402,0.0,0.27912986,93.901314,6.2576981,361.48975,-9.2836018
165.6537,9.8511753,3.7050641,0.0,0,6.1774282,0.0,0.28340721,94.352936,6.2047977,361.88898,-9.2845049
165.6581,9.8902035,3.7641022,0.0,0,6.1266279,0.0,0.28842008,94.469383,6.1545577,362.29965,-9.2827883
165.6625,9.9612083,3.8141415,0.0,0,6.0764947,0.0,0.29307884,94.624794,6.0955033,362.71219,-9.2832518
165.6669,9.9694958,3.8717253,0.0,0,6.026361,0.0,0.2981683,94.164658,6.0445209,362.62146,-9.2833128
165.6713,10.033403,3.9127951,0.0,0,5.9762278,0.0,0.30195305,94.485176,5.9911819,362.16898,-9.2837038
165.6757,10.047463,3.9683909,0.0,0,5.9260936,0.0,0.30693313,94.209389,5.9462461,361.4855,-9.283453
165.6801,10.093188,4.0144176,0.0,0,5.8759604,0.0,0.31116515,94.180061,5.8924689,360.27448,-9.2839804
165.6845,10.123775,4.064095,0.0,0,5.8258266,0.0,0.31571779,94.027489,5.8494067,359.08417,-9.2835779
165.6889,10.228562,4.1106591,0.0,0,5.7756925,0.0,0.32006767,94.506996,5.7949262,358.63168,-9.285017
165.6933,10.276657,4.1642318,0.0,0,5.7255592,0.0,0.32485357,94.569283,5.7433615,358.17923,-9.2837505
165.6977,10.310082,4.214015,0.0,0,5.675426,0.0,0.32969356,94.371048,5.6919231,357.95633,-9.2842922
165.7021,10.36914,4.2668529,0.0,0,5.6252923,0.0,0.33443284,94.404457,5.6417074,357.80994,-9.2829008
165.7065,10.434371,4.3152232,0.0,0,5.5760794,0.0,0.33921143,94.670952,5.5882468,357.80826,-9.2846451
165.7109,10.447397,4.366015,0.0,0,5.5283837,0.0,0.34388566,94.362396,5.5384507,357.96796,-9.2836142
165.7153,10.436189,4.4114189,0.0,0,5.4806876,0.0,0.34825999,93.872162,5.4959626,358.21609,-9.2843161
165.7197,10.521269,4.458437,0.0,0,5.4329915,0.0,0.35269415,94.115883,5.4468637,358.82825,-9.2840509
165.7241,10.576636,4.5059347,0.0,0,5.3852959,0.0,0.35736266,94.162781,5.3994212,359.4404,-9.2832546
165.7285,10.629618,4.5545144,0.0,0,5.3375998,0.0,0.36195511,94.289581,5.3540306,360.17474,-9.2842855
165.7329,10.659112,4.6011896,0.0,0,5.2899036,0.0,0.3664608,94.104073,5.3044925,360.91995,-9.2830553
165.7373,10.730333,4.6503992,0.0,0,5.2422075,0.0,0.37128919,94.205612,5.2546506,361.72491,-9.2843466
165.7417,10.775126,4.6938958,0.0,0,5.1945119,0.0,0.37548682,94.157883,5.2074242,362.56329,-9.283659
165.7461,10.823696,4.7422643,0.0,0,5.1468158,0.0,0.38033071,94.151245,5.1633072,363.15491,-9.2858524
165.7505,10.874081,4.7869205,0.0,0,5.0991197,0.0,0.38459766,94.246941,5.1146479,363.31461,-9.2843122
165.7549,10.945866,4.8403964,0.0,0,5.0514669,0.0,0.38998464,94.348427,5.0630927,363.26282,-9.2842808
165.7593,11.019271,4.8869009,0.0,0,5.006093,0.0,0.39441729,94.552353,5.0159798,360.97388,-9.2840223
165.7637,11.054027,4.9345822,0.0,0,4.9607286,0.0,0.39929011,94.356705,4.9653773,358.68491,-9.283433
165.7681,11.059486,4.9790998,0.0,0,4.9153652,0.0,0.4036198,93.994614,4.9238377,356.60056,-9.2843227
165.7725,11.029382,5.0226007,0.0,0,4.8700008,0.0,0.40824452,93.421425,4.882266,354.56445,-9.2851229
165.7769,11.114236,5.061502,0.0,0,4.8246369,0.0,0.41205019,93.66964,4.8368931,353.81644,-9.2856483
165.7813,11.268928,5.1084309,0.0,0,4.7792726,0.0,0.41690037,94.497742,4.7947741,354.20236,-9.2845173
165.7857,11.372567,5.1598868,0.0,0,4.7339091,0.0,0.42200398,95.002922,4.7387137,354.57135,-9.2849874
165.7901,11.344372,5.2082753,0.0,0,4.6885448,0.0,0.42711136,94.254753,4.6908231,354.89075,-9.2858381
165.7945,11.388273,5.2528219,0.0,0,4.6431808,0.0,0.43150619,94.115562,4.6486797,355.21014,-9.2844076
165.7989,11.448728,5.2954168,0.0,0,4.5978165,0.0,0.43606812,94.296753,4.6039243,355.33444,-9.283886
165.8033,11.511583,5.3391809,0.0,0,4.552453,0.0,0.44045433,94.334587,4.5574374,355.45422,-9.2843761
165.8077,11.54871,5.3849659,0.0,0,4.5085258,0.0,0.44528559,94.231262,4.5158219,355.69507,-9.2840872
165.8121,11.569296,5.4262676,0.0,0,4.4653702,0.0,0.44947982,94.009041,4.4697647,355.98785,-9.2847309
165.8165,11.670079,5.4691405,0.0,0,4.422215,0.0,0.45396915,94.336311,4.4285827,356.20749,-9.2849979
165.8209,11.736085,5.5141683,0.0,0,4.3790598,0.0,0.45867732,94.407211,4.3825688,356.32727,-9.284893
165.8253,11.759363,5.5582366,0.0,0,4.3359046,0.0,0.46329129,94.215271,4.340682,356.4664,-9.2856417
165.8297,11.801791,5.6001949,0.0,0,4.2927494,0.0,0.46763337,94.099022,4.2983251,356.71924,-9.2834034
165.8341,11.882293,5.6416192,0.0,0,4.2495942,0.0,0.47222233,94.371056,4.2566066,356.97211,-9.2834682
165.8385,11.965619,5.68784,0.0,0,4.206439,0.0,0.47697458,94.589828,4.2161531,356.06958,-9.2837353
165.8429,12.038875,5.7299237,0.0,0,4.1632838,0.0,0.48157546,94.673058,4.1674104,354.99164,-9.2839155
165.8473,12.073978,5.7735515,0.0,0,4.1201291,0.0,0.48631811,94.582504,4.1265497,353.57541,-9.2840738
165.8517,12.178047,5.8194246,0.0,0,4.0769739,0.0,0.4911029,94.880898,4.0804229,351.92502,-9.2851715
165.8561,12.221754,5.8639903,0.0,0,4.0344243,0.0,0.49602956,94.780312,4.0394683,350.92163,-9.2846308
165.8605,12.272222,5.9062586,0.0,0,3.9933808,0.0,0.5004862,94.691399,3.9945252,351.33417,-9.2844572
165.8649,12.3108,5.9479437,0.0,0,3.952338,0.0,0.50520402,94.564735,3.9509597,351.75879,-9.2835388
165.8693,12.357693,5.9894304,0.0,0,3.9112947,0.0,0.50969338,94.480415,3.9090638,352.5043,-9.2857866
165.8737,12.42842,6.0286465,0.0,0,3.8702514,0.0,0.514063,94.626801,3.8735888,353.24979,-9.2858477
165.8781,12.492274,6.0683784,0.0,0,3.8292081,0.0,0.5183751,94.720177,3.8312035,353.74252,-9.2846613
165.8825,12.551517,6.1123219,0.0,0,3.7881651,0.0,0.52318007,94.715256,3.7960751,354.15506,-9.2850199
165.8869,12.628877,6.1500387,0.0,0,3.7471218,0.0,0.52743822,94.857513,3.7497957,354.65097,-9.2840414
165.8913,12.717073,6.1931534,0.0,0,3.7060785,0.0,0.53233939,95.052917,3.7089641,355.23651,-9.2835245
165.8957,12.800814,6.2337866,0.0,0,3.6650355,0.0,0.53691405,95.266975,3.6680546,355.82205,-9.2831373
165.9001,12.884776,6.2801576,0.0,0,3.6239922,0.0,0.54211354,95.405655,3.624939,356.40759,-9.2843256
165.9045,12.93951,6.31915,0.0,0,3.5829492,0.0,0.54664361,95.388657,3.5832038,356.99313,-9.2850018
165.9089,13.040505,6.3632655,0.0,0,3.5437503,0.0,0.5515824,95.569664,3.5405741,357.41827,-9.2827959
165.9133,13.068118,6.4033036,0.0,0,3.5047047,0.0,0.55627149,95.390358,3.5017524,357.83081,-9.2824125
165.9177,13.086699,6.4431553,0.0,0,3.4656589,0.0,0.56086934,95.0672,3.4628041,358.13956,-9.2852345
165.9221,13.152331,6.4810381,0.0,0,3.4266133,0.0,0.56519651,95.172508,3.4252949,358.39243,-9.2844906
165.9265,13.260067,6.5195851,0.0,0,3.387568,0.0,0.56978768,95.455887,3.3854725,358.63037,-9.2845221
165.9309,13.360338,6.5576749,0.0,0,3.3485222,0.0,0.57431686,95.740013,3.3473477,358.84329,-9.2831116
165.9353,13.403185,6.6006689,0.0,0,3.3094764,0.0,0.5792641,95.636269,3.3040383,359.07019,-9.2831097
165.9397,13.437454,6.633677,0.0,0,3.270431,0.0,0.58328325,95.444458,3.2723691,359.4295,-9.2850523
165.9441,13.5037,6.6750903,0.0,0,3.2313855,0.0,0.58801687,95.474495,3.233763,359.78879,-9.2839861
165.9485,13.661595,6.7070265,0.0,0,3.1923399,0.0,0.59201515,96.212013,3.1986084,360.25699,-9.2841244
165.9529,13.79643,6.7553344,0.0,0,3.1532941,0.0,0.59769702,96.66748,3.1540148,360.74939,-9.2831593
165.9573,13.85404,6.79321,0.0,0,3.1153123,0.0,0.60252243,96.581978,3.1142311,361.14819,-9.285099
165.9617,13.924057,6.8376784,0.0,0,3.0781677,0.0,0.60763747,96.589722,3.0764041,361.46759,-9.2836256
165.9661,13.99904,6.8712635,0.0,0,3.0410228,0.0,0.61209226,96.63633,3.037123,361.76941,-9.2842817
165.9705,14.04494,6.9126253,0.0,0,3.0038779,0.0,0.61689705,96.514,3.0012136,362.02228,-9.2835608
165.9749,14.108856,6.9478159,0.0,0,2.966733,0.0,0.62150359,96.466881,2.9636042,362.27512,-9.2841244
165.9793,14.201451,6.9888458,0.0,0,2.9295881,0.0,0.62626547,96.624176,2.9214816,362.42297,-9.2838936
165.9837,14.250784,7.0184755,0.0,0,2.8924434,0.0,0.63041747,96.565849,2.8873196,362.56937,-9.2835655
165.9881,14.341954,7.058641,0.0,0,2.8552985,0.0,0.63520074,96.683769,2.8546891,362.70041,-9.283309
165.9925,14.398577,7.0903125,0.0,0,2.8181539,0.0,0.63954508,96.747513,2.8178537,362.82516,-9.2844419
165.9969,14.52702,7.1298356,0.0,0,2.781009,0.0,0.6442852,97.126816,2.7832384,362.95425,-9.2837076
166.0013,14.65836,7.1665397,0.0,0,2.7438643,0.0,0.6492492,97.48819,2.7433872,363.08734,-9.2831736
166.0057,14.780982,7.2086711,0.0,0,2.7070749,0.0,0.65438175,97.785545,2.7056067,363.15836,-9.2843685
166.0101,14.819392,7.2405038,0.0,0,2.6717427,0.0,0.65882051,97.672058,2.6689463,363.03857,-9.284112
166.0145,14.90596,7.2810726,0.0,0,2.636411,0.0,0.66391748,97.735023,2.6328681,362.91879,-9.2843494
166.0189,14.990535,7.3128037,0.0,0,2.601079,0.0,0.66829598,97.805435,2.5942419,362.79901,-9.2835236
166.0233,15.051063,7.3527918,0.0,0,2.5657468,0.0,0.67339349,97.733391,2.5593281,362.67926,-9.2828922
166.0277,15.12462,7.3814297,0.0,0,2.5304148,0.0,0.6773268,97.823288,2.5260091,362.6882,-9.2828312
166.0321,15.201684,7.4215336,0.0,0,2.4950829,0.0,0.68251836,97.760582,2.4952681,362.75476,-9.2833557
166.0365,15.371956,7.4501872,0.0,0,2.4597509,0.0,0.68648905,98.522499,2.4586289,362.77176,-9.2832937
166.0409,15.502237,7.4914565,0.0,0,2.4244189,0.0,0.69196326,98.807228,2.4209054,362.71851,-9.2833405
166.0453,15.592546,7.5258479,0.0,0,2.389087,0.0,0.69670266,98.900375,2.3830187,362.629,-9.2836142
166.0497,15.651052,7.5632172,0.0,0,2.3537548,0.0,0.70175683,98.764824,2.3458712,362.3096,-9.285718
166.0541,15.689474,7.5937386,0.0,0,2.3184228,0.0,0.70599413,98.590126,2.3130434,361.99023,-9.2839956
166.0585,15.804275,7.6309161,0.0,0,2.2845263,0.0,0.71103305,98.823685,2.2802989,361.35071,-9.2836666
166.0629,15.942767,7.6587915,0.0,0,2.2509191,0.0,0.7147631,99.360435,2.2473767,360.65872,-9.2828331
166.0673,16.028345,7.698668,0.0,0,2.2173121,0.0,0.72036541,99.271156,2.2131634,359.81186,-9.2831945
166.0717,16.130732,7.7273865,0.0,0,2.1837049,0.0,0.72417736,99.58712,2.1780193,358.85367,-9.2820244
166.0761,16.247911,7.7628651,0.0,0,2.1500978,0.0,0.72934431,99.732658,2.145884,358.10626,-9.2827578
166.0805,16.357462,7.7954545,0.0,0,2.1164904,0.0,0.73385811,99.985237,2.1118176,357.84012,-9.2822323
166.0849,16.438391,7.8290462,0.0,0,2.0828834,0.0,0.73854494,100.01801,2.075531,357.55801,-9.2828245
166.0893,16.513189,7.8621883,0.0,0,2.0492761,0.0,0.74325889,99.976913,2.0459657,356.7063,-9.2833328
166.0937,16.675488,7.8938861,0.0,0,2.0156689,0.0,0.74782634,100.48215,2.0120897,355.85458,-9.2828789
166.0981,16.848297,7.9272785,0.0,0,1.9820617,0.0,0.75248581,101.04121,1.9815695,354.42398,-9.2841539
166.1025,16.998667,7.9640646,0.0,0,1.9484546,0.0,0.75786269,101.37678,1.944942,352.80042,-9.2835188
166.1069,17.124323,8.0018177,0.0,0,1.9156146,0.0,0.76316702,101.59282,1.9098485,351.6044,-9.2826357
166.1113,17.233931,8.0361261,0.0,0,1.8836442,0.0,0.76826441,101.80186,1.8736402,350.88531,-9.2830296
166.1157,17.329252,8.0680799,0.0,0,1.8516738,0.0,0.77261358,101.89429,1.8372855,350.3952,-9.2829809
166.1201,17.383232,8.1001997,0.0,0,1.8197033,0.0,0.77739316,101.74733,1.8085122,350.84769,-9.2825184
166.1245,17.412563,8.1285496,0.0,0,1.787733,0.0,0.78143114,101.46368,1.7780827,351.3002,-9.2833004
166.1289,17.525755,8.1581326,0.0,0,1.7557626,0.0,0.78589219,101.71678,1.7448051,352.04636,-9.2824764
166.1333,17.677757,8.1903553,0.0,0,1.7237922,0.0,0.79045987,102.0706,1.7177181,352.81866,-9.2834444
166.1377,17.808659,8.2190418,0.0,0,1.6918218,0.0,0.79473794,102.43352,1.6881764,353.21542,-9.2832766
166.1421,17.924204,8.250474,0.0,0,1.6598514,0.0,0.79937047,102.58273,1.6525345,353.40173,-9.2837858
166.1465,18.070332,8.2830658,0.0,0,1.6278811,0.0,0.80418295,102.92511,1.6248572,353.4332,-9.2833738
166.1509,18.25765,8.3123026,0.0,0,1.5959105,0.0,0.80834717,103.54517,1.59232,353.19363,-9.2835379
166.1553,18.385359,8.3446007,0.0,0,1.564104,0.0,0.81349891,103.76923,1.5590533,352.94031,-9.2836914
166.1597,18.534109,8.3794565,0.0,0,1.5336912,0.0,0.81843162,104.08202,1.5283128,352.54108,-9.2827253
166.1641,18.638186,8.4098215,0.0,0,1.5032783,0.0,0.82310045,104.14491,1.4971049,352.14185,-9.2832308
166.1685,18.747046,8.4401836,0.0,0,1.4728655,0.0,0.8275305,104.31763,1.4656655,352.64703,-9.2827816
166.1729,18.825958,8.4696808,0.0,0,1.4424527,0.0,0.83202523,104.34502,1.44008,353.36566,-9.2816181
166.1773,18.968458,8.5008917,0.0,0,1.4120399,0.0,0.8365587,104.61395,1.4101089,354.26831,-9.2840109
166.1817,19.170069,8.5297947,0.0,0,1.3816271,0.0,0.84116668,105.23182,1.3734553,355.33292,-9.2826958
166.1861,19.354801,8.5638361,0.0,0,1.3512143,0.0,0.84631056,105.68053,1.3452988,356.26205,-9.2825804
166.1905,19.430603,8.5901918,0.0,0,1.3208014,0.0,0.85047364,105.69733,1.3139617,356.79437,-9.2830925
166.1949,19.518137,8.6219721,0.0,0,1.2903887,0.0,0.85531473,105.65346,1.286678,357.32669,-9.2823477
166.1993,19.670155,8.6516571,0.0,0,1.2599759,0.0,0.85991991,105.95473,1.2537507,353.58664,-9.2827511
166.2037,19.852882,8.68291,0.0,0,1.2295632,0.0,0.8646664,106.44167,1.2246665,349.74722,-9.2826357
166.2081,20.095367,8.7120028,0.0,0,1.200253,0.0,0.86921173,107.28837,1.1908623,346.1326,-9.2818747
166.2125,20.186367,8.7418079,0.0,0,1.1713274,0.0,0.87395203,107.28272,1.1614851,342.61429,-9.2825441
166.2169,20.242355,8.7724123,0.0,0,1.1424017,0.0,0.87885362,107.01161,1.1297007,340.26175,-9.2832088
166.2213,20.337648,8.8010254,0.0,0,1.1134762,0.0,0.88325262,107.03462,1.1058718,339.50119,-9.2828703
166.2257,20.500654,8.8267603,0.0,0,1.0845505,0.0,0.88746434,107.41886,1.0789292,338.62805,-9.2827711
166.2301,20.682167,8.8546228,0.0,0,1.055625,0.0,0.89168954,107.94504,1.0492897,337.09351,-9.2826967
166.2345,20.848461,8.884387,0.0,0,1.0266993,0.0,0.89662302,108.27579,1.0183806,335.55899,-9.2836199
166.2389,21.024277,8.9139729,0.0,0,0.99777377,0.0,0.90132642,108.67406,0.98998117,335.18268,-9.2833929
166.2433,21.197468,8.9388714,0.0,0,0.96884811,0.0,0.90549189,109.11259,0.95931607,334.98227,-9.282342
166.2477,21.322126,8.9711027,0.0,0,0.93992251,0.0,0.91063333,109.23032,0.93285269,335.18417,-9.2819653
166.2521,21.421839,8.9971333,0.0,0,0.91099691,0.0,0.91485137,109.23369,0.9036454,335.66461,-9.2817106
166.2565,21.664085,9.0280037,0.0,0,0.88260663,0.0,0.91999775,109.91702,0.88090664,336.23715,-9.282732
166.2609,21.871677,9.0524836,0.0,0,0.85509783,0.0,0.92416871,110.51775,0.84895301,337.01135,-9.281085
166.2653,22.042696,9.0855837,0.0,0,0.82758909,0.0,0.92961466,110.74622,0.81956387,337.78018,-9.2827349
166.2697,22.150993,9.1110153,0.0,0,0.80008024,0.0,0.93407971,110.82629,0.79192919,338.40729,-9.2834587
166.2741,22.362551,9.1408262,0.0,0,0.77257144,0.0,0.93888295,111.33248,0.76071274,339.03439,-9.2812719
166.2785,22.522278,9.1677732,0.0,0,0.74506265,0.0,0.94375479,111.56683,0.7344451,340.13757,-9.2827435
166.2829,22.642653,9.1963921,0.0,0,0.71755385,0.0,0.94823772,111.70095,0.70854437,341.39185,-9.2817812
166.2873,22.760227,9.2186852,0.0,0,0.690045,0.0,0.95242435,111.83288,0.68139666,342.76181,-9.2820568
166.2917,22.930122,9.2472,0.0,0,0.66253626,0.0,0.95697945,112.10779,0.65813327,344.25626,-9.2824974
166.2961,23.168793,9.2700319,0.0,0,0.63502741,0.0,0.96145129,112.79113,0.62763387,345.62787,-9.2819252
166.3005,23.403976,9.3020172,0.0,0,0.60751861,0.0,0.96663916,113.31219,0.6007334,346.52188,-9.2821932
166.3049,23.610699,9.324111,0.0,0,0.58003461,0.0,0.97106069,113.83406,0.57234639,347.41586,-9.2815742
166.3093,23.805357,9.3573313,0.0,0,0.55384868,0.0,0.97640991,114.12358,0.54266244,348.19852,-9.2822475
166.3137,23.947647,9.3784103,0.0,0,0.52766871,0.0,0.98080832,114.34078,0.51411766,348.97241,-9.2825098
166.3181,23.222954,9.396637,0.0,0,0.50148869,0.0,0.98357493,110.615,0.49458295,349.84116,-9.2839632
166.3225,22.379801,9.4001637,0.0,0,0.47530869,0.0,0.98471135,106.45934,0.47980088,350.76093,-9.2824535
166.3269,21.910524,9.4108496,0.0,0,0.44912869,0.0,0.98620647,104.09344,0.46850249,351.59589,-9.2828798
166.3313,21.518663,9.4094906,0.0,0,0.42294869,0.0,0.98639458,102.18939,0.45282471,352.28806,-9.2836399
166.3357,21.029919,9.4159031,0.0,0,0.39676869,0.0,0.98728216,99.787872,0.44523358,352.86841,-9.285059
166.3401,20.59646,9.4147921,0.0,0,0.37058869,0.0,0.98747444,97.732948,0.4375397,352.38895,-9.2849207
166.3445,20.236124,9.4199104,0.0,0,0.34440869,0.0,0.98828793,95.904335,0.42776805,351.90948,-9.2844839
166.3489,20.054485,9.4170055,0.0,0,0.31822872,0.0,0.98810315,95.042351,0.41407156,350.97211,-9.2852125
166.3533,20.03487,9.4224491,0.0,0,0.29204869,0.0,0.98878622,94.903419,0.3953554,349.93301,-9.2842426
166.3577,20.296888,9.4221439,0.0,0,0.26670453,0.0,0.98942828,96.01944,0.36290276,349.24667,-9.2841911
166.3621,20.44075,9.4293995,0.0,0,0.24180932,0.0,0.99035132,96.679886,0.3306582,348.85971,-9.2856102
166.3665,20.495241,9.4274635,0.0,0,0.21691413,0.0,0.99031931,96.911789,0.29271817,348.60995,-9.2825861
166.3709,20.501457,9.4339256,0.0,0,0.19201899,0.0,0.99142385,96.833214,0.2640835,348.74338,-9.2826834
166.3753,20.500618,9.4324903,0.0,0,0.16712378,0.0,0.99135232,96.822128,0.23873663,348.8768,-9.2831249
166.3797,20.458473,9.4389668,0.0,0,0.14222857,0.0,0.99261314,96.528152,0.21098076,349.41821,-9.2833662
166.3841,20.379108,9.4373322,0.0,0,0.11733337,0.0,0.99238896,96.18457,0.18823323,349.96524,-9.2831631
166.3885,20.311209,9.4437542,0.0,0,0.092438169,0.0,0.99363351,95.727119,0.16302782,350.44574,-9.2844896
166.3929,20.261745,9.4430733,0.0,0,0.067542963,0.0,0.99353695,95.504791,0.14091492,350.89893,-9.2852097
166.3973,20.168388,9.4447479,0.0,0,0.04264776,0.0,0.99407762,95.040817,0.11946406,351.31735,-9.2835026
166.4017,20.059948,9.4443789,0.0,0,0.017752562,0.0,0.99378008,94.553581,0.096776836,351.68997,-9.2836666
166.4061,19.964991,9.4480505,0.0,0,-0.0069684293,0.0,0.99483949,94.025391,0.083037026,352.06055,-9.2844744
166.4105,19.895515,9.4458399,0.0,0,-0.03125643,0.0,0.99433839,93.703339,0.064063519,352.41983,-9.2834902
166.4149,19.816198,9.4510994,0.0,0,-0.055544429,0.0,0.99546915,93.196808,0.049286652,352.77914,-9.2837296
166.4193,19.682632,9.4481764,10.580588,0,-0.079832427,0.0,0.9949792,92.6763,0.034808666,353.04504,-9.2836132
166.4237,19.572763,9.4521646,22.641426,0,-0.10412042,0.0,0.99578226,92.064125,0.023583064,353.29791,-9.2829809
166.4281,19.448612,9.4528503,27.46582,0,0.46232122,359.99997,0.99578989,91.473259,0.0103842,353.49487,-9.2838335
166.4325,18.517624,9.4506407,27.46582,0,1.2591794,359.99997,0.99545574,87.215584,0.034133893,353.65457,-9.2842855
166.4369,14.225012,9.4413424,27.090601,0,2.0560369,359.99997,0.99389189,67.272888,0.22786297,353.87009,-9.2882872
166.4413,-0.55098873,9.3467388,25.927938,0,2.8528943,359.99997,0.97769153,-1.9389466,0.61448592,354.20279,-9.2978363
166.4457,0.12117242,9.1228743,24.818115,0,3.6497519,359.99997,0.93844914,0.6529097,1.835712,354.53668,-9.2993679
166.4501,-0.040224638,9.1640415,24.818115,0,4.4466095,359.99997,0.9451623,-0.25602573,3.0264504,354.896,-9.2987547
166.4545,-0.057426937,9.3851099,24.818115,0,5.2434673,359.99997,0.98336875,-0.36726296,3.831393,355.25531,-9.2969923
166.4589,-0.00024988674,9.3458843,23.20603,0,6.0403247,359.99997,0.97694737,-0.16434269,4.5836406,355.53287,-9.2956171
166.4633,1.6246262,9.4025021,21.107445,0,6.837183,359.99997,0.98664182,7.6034093,5.3462205,355.78571,-9.292942
166.4677,0.54566509,9.3875055,20.039063,0,7.6340399,359.99997,0.98413515,2.521039,6.1302662,355.97977,-9.2921295
166.4721,0.38139114,9.3835773,20.039063,0,8.4308987,359.99997,0.98348838,1.8006663,6.9525094,356.11282,-9.2914515
166.4765,0.32962683,9.3859196,19.861794,0,9.2277555,359.99997,0.9838618,1.5615152,7.7783127,356.23453,-9.2897167
166.4809,0.41339386,9.3845987,19.032009,0,10.024614,359.99997,0.98342335,1.9740217,8.6079016,356.31436,-9.2875137
166.4853,0.36668167,9.3858452,18.202225,0,10.821471,359.99997,0.98372191,1.7193688,9.4329357,356.3942,-9.28967
166.4897,0.34769624,9.3872557,18.149414,0,11.618328,359.99997,0.98369372,1.6703949,10.250558,356.47406,-9.2883234
166.4941,0.37166962,9.3835535,18.149414,0,12.415187,359.99997,0.98305738,1.7990755,11.037734,356.55392,-9.2874708
166.4985,0.34789455,9.3839474,17.54528,0,13.212044,359.99997,0.98298538,1.6392488,11.836726,356.6601,-9.2891598
166.5029,0.34770304,9.3886995,16.628656,0,14.008902,359.99997,0.98398113,1.62088,12.611908,356.77985,-9.2881107
166.5073,0.32489404,9.3901901,16.062012,0,14.805759,359.99997,0.98379123,1.5305673,13.389603,356.89963,-9.2890415
166.5117,0.34775114,9.3849163,16.062012,0,15.602618,359.99997,0.9829455,1.6511756,14.189577,357.01938,-9.2872124
166.5161,0.31271735,9.3883724,15.955091,0,16.399475,359.99997,0.98332357,1.4849647,14.992891,357.13361,-9.2855644
166.5205,0.37608007,9.3874865,14.932332,0,17.196333,359.99997,0.9830761,1.7943549,15.805265,357.20013,-9.2873487
166.5249,0.39960894,9.3883209,13.909574,0,17.986996,359.99997,0.98330408,1.8451085,16.59874,357.26666,-9.2881145
166.5293,0.39693344,9.3857212,13.73291,0,18.0,359.99997,0.98269117,1.9178504,17.389692,357.28918,-9.2866936
166.5337,0.40517733,9.3888302,13.73291,0,18.0,359.99997,0.98328066,1.8790427,18.065836,357.30249,-9.2889128
166.5381,0.44815427,9.3892632,13.73291,0,18.0,359.99997,0.98320472,2.1438007,18.461002,357.30115,-9.2933664
166.5425,0.50766283,9.3911715,13.73291,0,18.0,359.99997,0.98335809,2.4231696,18.436203,357.28784,-9.3044357
166.5469,0.49010876,9.3884535,13.73291,0,18.0,359.99997,0.98272455,2.3843699,18.207375,357.30719,-9.3254061
166.5513,0.45344043,9.3905678,13.73291,0,18.0,359.99997,0.98298788,2.1222243,18.055101,357.41367,-9.3553038
166.5557,0.47066793,9.3824558,13.73291,0,18.0,359.99997,0.98163831,2.2168045,18.044333,357.52011,-9.3924608
166.5601,0.46859819,9.3870459,13.73291,0,18.0,359.99997,0.98237276,2.2280998,18.075947,357.54709,-9.4284849
166.5645,0.43197048,9.3840141,13.73291,0,18.0,359.99997,0.98175544,2.0785697,18.121927,357.5737,-9.4647827
166.5689,0.46966061,9.3879642,13.73291,0,18.0,359.99997,0.98223668,2.2442198,18.141829,357.54297,-9.4960794
166.5733,0.48821491,9.3834009,13.73291,0,18.0,359.99997,0.98142099,2.338701,18.141663,357.48975,-9.5285892
166.5777,0.49274093,9.3873777,13.73291,0,18.0,359.99997,0.98187554,2.3460407,18.137766,357.45999,-9.5591526
166.5821,0.50706553,9.3864536,13.73291,0,18.0,359.99997,0.98198748,2.4188213,18.129871,357.45999,-9.5896406
166.5865,0.47389695,9.3897543,13.73291,0,18.0,359.99997,0.9822858,2.2269342,18.125761,357.46869,-9.622901
166.5909,0.46904114,9.3841534,13.73291,0,18.0,359.99997,0.98163193,2.2425001,18.122889,357.52194,-9.6553202
166.5953,0.51770538,9.3906479,13.73291,0,18.0,359.99997,0.98228633,2.4657636,18.112415,357.57516,-9.6868477
166.5997,0.4915773,9.3885489,13.73291,0,18.0,359.99997,0.98229307,2.3235843,18.111444,357.6048,-9.7207479
166.6041,0.47234952,9.3915386,13.73291,0,18.0,359.99997,0.98237807,2.2554305,18.106544,357.63144,-9.7522984
166.6085,0.4733226,9.3881607,13.73291,0,18.0,359.99997,0.9822439,2.2689238,18.106461,357.61752,-9.7846146
166.6129,0.50450462,9.3912611,13.73291,0,18.0,359.99997,0.98215771,2.3778298,18.104708,357.57758,-9.8156891
166.6173,0.49648544,9.3889151,13.73291,0,18.0,359.99997,0.98231739,2.3929853,18.101765,357.5509,-9.8484344
166.6217,0.47261953,9.3914194,13.73291,0,18.0,359.99997,0.98226464,2.3013818,18.100471,357.5509,-9.8821735
166.6261,0.46776927,9.3878565,13.73291,0,18.0,359.99997,0.9821651,2.251909,18.097712,357.55017,-9.9131575
166.6305,0.50207138,9.3903923,13.73291,0,18.0,359.99997,0.98213232,2.3720307,18.097383,357.5369,-9.9438248
166.6349,0.50082725,9.3883286,13.73291,0,18.0,359.99997,0.98226589,2.3881378,18.099745,357.52359,-9.9776564
166.6393,0.47927529,9.394186,13.73291,0,18.0,359.99997,0.9829759,2.2693722,18.09218,357.45856,-10.01018
166.6437,0.46994215,9.3848095,13.73291,0,18.0,359.99997,0.98181641,2.2394137,18.094297,357.37869,-10.042265
166.6481,0.50857872,9.388526,13.73291,0,18.0,359.99997,0.98212475,2.4083991,18.092855,357.32547,-10.073516
166.6525,0.51345932,9.3870573,13.73291,0,18.0,359.99997,0.98226637,2.4389608,18.093533,357.29886,-10.10324
166.6569,0.49723718,9.3915977,13.9607,0,18.0,359.99997,0.98280394,2.3838737,18.087278,357.27817,-10.138379
166.6613,0.49670368,9.3870754,14.983459,0,18.0,359.99997,0.98237586,2.3466315,18.089827,357.27817,-10.168159
166.6657,0.50950515,9.3899517,16.00622,0,18.0,359.99997,0.98262566,2.4202356,18.088181,357.27817,-10.202438
166.6701,0.5253607,9.3878012,16.062012,0,18.0,359.99997,0.98266959,2.5199454,18.086002,357.20267,-10.236474
166.6745,0.50594634,9.3919191,16.062012,0,18.0,359.99997,0.98332292,2.3967741,18.083872,357.1228,-10.267098
166.6789,0.4900566,9.3844709,16.062012,0,18.0,359.99997,0.98233896,2.339242,18.083765,357.07852,-10.30052
166.6833,0.4970668,9.388649,16.062012,0,18.0,359.99997,0.98301977,2.339597,18.077354,357.05191,-10.330734
166.6877,0.54699767,9.3839521,16.062012,0,18.0,359.99997,0.98218763,2.5873139,18.080704,357.05652,-10.363095
166.6921,0.48357356,9.3879452,16.062012,0,18.0,359.99997,0.98311216,2.3123336,18.083378,357.10977,-10.396703
166.6965,0.49484101,9.3849897,16.062012,0,18.0,359.99997,0.98270851,2.3441219,18.07798,357.15393,-10.429969
166.7009,0.49265057,9.3841982,16.062012,0,18.0,359.99997,0.98277628,2.3397038,18.076939,357.12732,-10.460048
166.7053,0.54641068,9.3842802,16.062012,0,18.0,359.99997,0.98273939,2.5787821,18.075872,357.10071,-10.491066
166.7097,0.51800191,9.3860979,16.062012,0,18.0,359.99997,0.98330849,2.4556184,18.076714,357.02954,-10.526487
166.7141,0.50328249,9.3837233,16.062012,0,18.0,359.99997,0.98279673,2.3867402,18.079205,356.94971,-10.558248
166.7185,0.49748015,9.382884,16.574482,0,18.0,359.99997,0.98299694,2.3768985,18.071999,356.8996,-10.589001
166.7229,0.5399633,9.3817091,17.491106,0,18.0,359.99997,0.98256445,2.5483346,18.073772,356.87299,-10.621418
166.7273,0.54936129,9.3843098,18.149414,0,18.0,359.99997,0.98342717,2.6247337,18.068066,356.84262,-10.65404
166.7317,0.51111966,9.3802366,18.149414,0,18.0,359.99997,0.98251867,2.4921772,18.068775,356.8027,-10.685294
166.7361,0.51248831,9.3828354,18.149414,0,18.0,359.99997,0.98339331,2.4356239,18.067385,356.76285,-10.716842
166.7405,0.53755391,9.3806524,18.149414,0,18.0,359.99997,0.98259646,2.5436332,18.067442,356.73624,-10.748375
166.7449,0.55937237,9.3833961,18.149414,0,18.0,359.99997,0.98343587,2.6579485,18.063858,356.70963,-10.781351
166.7493,0.51431245,9.3806734,18.149414,0,18.0,359.99997,0.98282462,2.48104,18.063955,356.66364,-10.814478
166.7537,0.52330917,9.3798504,18.149414,0,18.0,359.99997,0.98281336,2.4873424,18.058001,356.61041,-10.845687
166.7581,0.53156972,9.3774405,18.149414,0,18.0,359.99997,0.98220968,2.5046043,18.059883,356.56317,-10.876296
166.7625,0.57692909,9.3804779,18.149414,0,18.0,359.99997,0.98312587,2.7450023,18.057657,356.52325,-10.911385
166.7669,0.53558969,9.3790178,18.149414,0,18.0,359.99997,0.98262638,2.5289764,18.062677,356.49023,-10.94391
166.7713,0.50139332,9.3791056,18.149414,0,18.0,359.99997,0.98283529,2.4128015,18.059111,356.49023,-10.975961
166.7757,0.54094011,9.3755236,18.149414,0,18.0,359.99997,0.98203158,2.5809352,18.060635,356.49023,-11.007096
166.7801,0.55382109,9.3805981,18.892445,0,18.0,359.99997,0.98299056,2.6467144,18.059359,356.49023,-11.039328
166.7845,0.542642,9.3802099,19.722231,0,18.0,359.99997,0.98289537,2.6285439,18.061296,356.49023,-11.071842
166.7889,0.52160871,9.377408,20.039063,0,18.0,359.99997,0.98252249,2.4906127,18.055811,356.46555,-11.104861
166.7933,0.5300445,9.3759651,20.039063,0,18.0,359.99997,0.982144,2.5016296,18.057854,356.4256,-11.136538
166.7977,0.5650773,9.3778057,20.039063,0,18.0,359.99997,0.98255533,2.6752598,18.05435,356.37662,-11.16881
166.8021,0.58257592,9.3764067,20.039063,0,18.0,359.99997,0.98198634,2.7703397,18.054623,356.31009,-11.202207
166.8065,0.52518791,9.3779984,20.039063,0,18.0,359.99997,0.98236626,2.5071571,18.049429,356.24268,-11.233236
166.8109,0.52069676,9.3759031,20.039063,0,18.0,359.99997,0.98202866,2.4864213,18.053078,356.16284,-11.26296
166.8153,0.56957173,9.3764048,20.039063,0,18.0,359.99997,0.98192632,2.7045262,18.050678,356.08298,-11.296613
166.8197,0.56099164,9.3795576,13.119443,0,18.0,359.99997,0.982243,2.6896827,18.050585,356.02405,-11.329113
166.8241,0.52633208,9.3748341,4.3198552,0,18.0,359.99997,0.98138595,2.5260296,18.047245,355.97083,-11.361226
168.6248,0.48214751,9.3909988,0.0,0,18.0,1.0338233e-22,0.98358178,2.2952585,17.999697,323.62708,-11.480611
170.8248,0.52783495,9.3993664,0.0,0,18.0,1.4012985e-45,0.98524082,2.514128,18.000101,304.81863,-11.482124
173.0248,0.52703696,9.4075098,0.0,0,18.0,1.4012985e-45,0.98668438,2.4995363,17.99999,288.52356,-11.480621
175.2248,0.53862643,9.415638,0.0,0,18.0,1.4012985e-45,0.98806715,2.5533512,17.998905,274.11838,-11.480893
177.4248,0.55923855,9.4228144,0.0,0,18.0,1.4012985e-45,0.98932916,2.649291,18.000338,260.97351,-11.481239
179.6248,0.58721089,9.4295597,0.0,0,18.0,1.4012985e-45,0.99050415,2.7749805,18.000254,248.75029,-11.481977
181.8248,0.58074838,9.4360065,0.0,0,18.0,1.4012985e-45,0.99179882,2.7349155,18.000616,237.33437,-11.481754
184.0248,0.60240513,9.4430189,0.0,0,18.0,1.4012985e-45,0.9930321,2.8472321,17.999723,226.60374,-11.48199
186.2248,0.59969693,9.4500093,0.0,0,18.0,1.4012985e-45,0.99417728,2.8286543,17.999947,216.34143,-11.481
188.4248,0.61971152,9.4558802,0.0,0,18.0,1.4012985e-45,0.99533272,2.9113359,17.999914,206.61198,-11.480852
190.6248,0.63753426,9.4614096,0.0,0,18.0,1.4012985e-45,0.99633914,2.9977806,17.999538,197.48846,-11.481767
192.8248,0.64586008,9.4671097,0.0,0,18.0,1.4012985e-45,0.99736321,3.0369821,17.999357,188.75893,-11.482429
195.0248,0.66067785,9.4724207,0.0,0,18.0,1.4012985e-45,0.99828649,3.1031578,17.999781,180.44685,-11.482403
197.2248,0.65978968,9.4772234,0.0,0,18.0,1.4012985e-45,0.9991135,3.0933263,18.00017,172.70396,-11.481901
199.4248,0.66291624,9.4818869,0.0,0,18.0,1.4012985e-45,1.0000881,3.1054747,17.999355,165.39937,-11.481032
201.6248,0.67236382,9.4864597,0.0,0,18.0,1.4012985e-45,1.0009055,3.1515212,17.999996,158.38707,-11.480569
203.8248,0.69496053,9.4906702,0.0,0,18.0,1.4012985e-45,1.0015471,3.2495525,18.00041,151.95509,-11.481071
206.0248,0.71744412,9.4954109,0.0,0,18.0,1.4012985e-45,1.0024695,3.3511181,17.999645,145.57979,-11.482266
208.2248,0.70829862,9.4991875,0.0,0,18.0,1.4012985e-45,1.003127,3.3126321,17.999653,139.63481,-11.48253
210.4248,0.7322771,9.5030899,0.0,0,18.0,1.4012985e-45,1.0039161,3.4148664,17.99976,133.95462,-11.482784
212.6248,0.74135417,9.5066833,0.0,0,18.0,1.4012985e-45,1.0045048,3.4511998,18.000212,128.46603,-11.483033
214.8248,0.74350727,9.5106497,0.0,0,18.0,1.4012985e-45,1.0051455,3.4597244,18.000397,123.38372,-11.483271
217.0248,0.75344974,9.5139008,0.0,0,18.0,1.4012985e-45,1.005904,3.5110507,17.999878,118.44391,-11.483068
219.2248,0.75957352,9.5169258,0.0,0,18.0,1.4012985e-45,1.0064688,3.5313144,17.999496,113.78062,-11.48326
221.4248,0.75514889,9.5201416,0.0,0,18.0,1.4012985e-45,1.0069348,3.5148747,18.000225,109.41614,-11.482603
223.6248,0.75129968,9.5236435,0.0,0,18.0,1.4012985e-45,1.0075929,3.4975998,18.000324,105.2468,-11.482647
225.8248,0.77160352,9.5266447,0.0,0,18.0,1.4012985e-45,1.0081258,3.5800121,18.000317,101.13792,-11.482509
226.8248,0.77578127,9.5277081,0.0,0,18.0,1.4012985e-45,1.0082533,3.6072488,18.000031,99.50634,-11.482808