File: examples/dan-msc-case-studies/CS3/data/01 raw data/baron_test_151.csv
Time(sec),Force(kN),Jaw(mm),PowAngle(deg),Power(W),Pram,PTemp,Strain,Stress(MPa),Stroke(mm),TC1(C),wedge(mm)
0.0,1.2308328,0.43828326,0.0,0,10.594783,0.001449223,0.029703394,15.209228,10.594929,26.307266,-9.1154633
2.2,1.1061594,0.0070844917,0.0,0,10.594783,6.5159173,0.00049021345,14.087095,10.5949,26.087343,-9.4828529
4.4,1.069326,0.0073909061,0.0,0,10.594783,13.115914,0.00048295909,13.594299,10.594949,26.094904,-9.4795036
6.6,1.0592537,0.0073017338,0.0,0,10.594783,19.715912,0.00051665428,13.460454,10.595092,25.963591,-9.4761868
8.8,1.0397999,0.0076518897,0.0,0,10.594783,26.315912,0.00047861296,13.228183,10.594213,25.984335,-9.4718332
11.0,1.0406085,0.007582501,34.047649,0,10.594783,32.915905,0.00050498545,13.242563,10.5941,26.171663,-9.4683628
13.2,1.0570474,0.0031242217,48.343052,0,10.594783,39.5159,0.00020662461,13.4718,10.59507,28.756399,-9.4646807
15.4,1.0901175,-0.0061462959,55.211292,0,10.594783,46.115906,-0.00040169567,13.886887,10.594537,35.371948,-9.4607544
17.6,1.1418444,-0.01787528,57.262985,0,10.594783,52.715904,-0.0011686005,14.543075,10.594186,45.974522,-9.4569187
19.8,1.16829,-0.029437982,55.246906,0,10.594783,59.315914,-0.0019889735,14.895104,10.595274,59.216534,-9.4531574
22.0,1.1592695,-0.038628813,48.88324,0,10.594783,65.915886,-0.0025902267,14.806346,10.595229,72.033585,-9.4496307
24.2,1.1375082,-0.042556833,38.583939,0,10.594783,72.515884,-0.0028338702,14.527113,10.594564,81.407318,-9.4457893
26.4,1.0935529,-0.042469736,28.663361,0,10.594783,79.115891,-0.0028297736,13.956246,10.594224,86.439842,-9.4414902
28.6,1.067084,-0.042078584,30.867579,0,10.594783,85.715912,-0.0027774067,13.607408,10.594502,87.607674,-9.4381123
30.8,1.0709128,-0.042586613,43.357845,0,10.594783,92.31591,-0.0028568939,13.669864,10.59408,87.388855,-9.4347134
33.0,1.0975024,-0.047864471,52.964153,0,10.594783,98.915909,-0.0031829951,14.038691,10.593821,89.169998,-9.4309044
35.2,1.13644,-0.057980977,58.813644,0,10.594783,105.51591,-0.0038448081,14.533384,10.594975,95.051147,-9.4269867
37.4,1.1797004,-0.070873864,60.556637,0,10.594783,112.11591,-0.0047361129,15.088538,10.594956,105.64564,-9.4229097
39.6,1.1922456,-0.083587974,58.60128,0,10.594783,118.7159,-0.0055588074,15.258312,10.594929,118.97327,-9.4197111
41.8,1.1873814,-0.093162045,53.317348,0,10.594783,125.3159,-0.0061966432,15.220317,10.594986,131.69482,-9.416399
44.0,1.1512119,-0.097589649,44.748764,0,10.594783,131.91586,-0.00648162,14.760778,10.594619,141.37065,-9.4125719
46.2,1.1087352,-0.098107733,37.091179,0,10.594783,138.51587,-0.006503718,14.219804,10.594694,146.38367,-9.4085579
48.4,1.0765991,-0.097416461,38.713669,0,10.594783,145.11589,-0.0064828061,13.786146,10.594543,147.25955,-9.404829
50.6,1.0683869,-0.098004885,47.966766,0,10.594783,151.71588,-0.0065030339,13.678918,10.595047,146.778,-9.4016142
52.8,1.1140867,-0.10410263,56.378536,0,10.594783,158.3159,-0.0068936353,14.279665,10.594604,148.35378,-9.3977938
55.0,1.1592126,-0.11428676,61.444702,0,10.594783,164.91589,-0.0075976825,14.87782,10.59386,154.09048,-9.3937674
57.2,1.1939318,-0.12808874,63.369087,0,10.594783,171.51588,-0.0084961709,15.338093,10.595216,164.1633,-9.3901625
59.4,1.1942062,-0.14242947,62.338326,0,10.594783,178.11588,-0.0094273044,15.346475,10.59454,177.07483,-9.3862867
61.6,1.1898887,-0.15376946,58.370552,0,10.594783,184.71588,-0.010210186,15.295008,10.594676,190.03989,-9.3829155
63.8,1.1867307,-0.16005397,52.088261,0,10.594783,191.31587,-0.010620011,15.271382,10.595593,200.50415,-9.3795509
66.0,1.138994,-0.16195257,45.432621,0,10.594783,197.91588,-0.01073579,14.653728,10.595257,206.8772,-9.3759508
68.2,1.0898527,-0.16147801,43.730503,0,10.594783,204.51587,-0.010719565,14.021221,10.594278,209.02087,-9.3716269
70.4,1.0817931,-0.16137683,49.134842,0,10.594783,211.11588,-0.010717491,13.918252,10.594898,209.07089,-9.3678074
72.6,1.1118318,-0.16620451,55.832348,0,10.594783,217.71588,-0.011026865,14.295967,10.594596,210.13783,-9.364522
74.8,1.1561755,-0.1755531,61.013451,0,10.594783,224.31587,-0.01162753,14.883487,10.5945,214.5144,-9.3610468
77.0,1.1944039,-0.18740642,63.774952,0,10.594783,230.91586,-0.012444845,15.411726,10.594109,222.67087,-9.3574982
79.2,1.1962472,-0.20076787,64.021584,0,10.594783,237.51587,-0.013292082,15.438446,10.595168,233.8318,-9.3535624
81.4,1.1973062,-0.21270753,62.119152,0,10.594783,244.11588,-0.014049293,15.460154,10.594584,245.93362,-9.3497448
83.6,1.1906011,-0.22054304,58.431839,0,10.594783,250.71587,-0.014613005,15.376137,10.594882,256.75632,-9.3456688
85.8,1.1790589,-0.22474781,54.318302,0,10.594783,257.3161,-0.014869244,15.219179,10.594914,264.62769,-9.3428612
88.0,1.1403848,-0.22687788,51.666672,0,10.594783,263.91586,-0.015011149,14.749207,10.595119,269.34125,-9.3392591
90.2,1.1273236,-0.22849989,52.63142,0,10.594783,270.51584,-0.015101044,14.575342,10.594209,271.76215,-9.335516
92.4,1.1281807,-0.2313931,56.117435,0,10.594783,277.11584,-0.015332761,14.581301,10.595289,273.79694,-9.331605
94.6,1.1658207,-0.23810916,59.854897,0,10.594783,283.71582,-0.015734885,15.081137,10.595599,277.46347,-9.3274374
96.8,1.2008425,-0.24773194,62.751556,0,10.594783,290.31589,-0.016360108,15.536933,10.594833,283.49106,-9.3241892
99.0,1.1988646,-0.25895879,63.997105,0,10.594783,296.91586,-0.01712206,15.53915,10.594765,292.06363,-9.321023
101.2,1.1991016,-0.26978585,63.802971,0,10.594783,303.51587,-0.017844141,15.549101,10.594535,302.00415,-9.317337
103.4,1.20002,-0.27970418,62.375542,0,10.594783,310.11584,-0.018471405,15.56424,10.594445,311.92596,-9.3137541
105.6,1.1773046,-0.28755447,60.316315,0,10.594783,316.71585,-0.018955711,15.271866,10.594579,320.61633,-9.3090897
107.8,1.1939662,-0.29256946,58.494724,0,10.594783,323.31583,-0.019329896,15.492687,10.595034,327.33746,-9.3055239
110.0,1.1776997,-0.29679522,57.810066,0,10.594783,329.91583,-0.019620309,15.302773,10.59498,332.38696,-9.3023405
112.2,1.1737643,-0.30130595,58.58086,0,10.594783,336.51581,-0.019893194,15.24832,10.594311,336.50098,-9.2990685
114.4,1.1907512,-0.30721062,60.217789,0,10.594783,343.11584,-0.020240899,15.46273,10.595483,340.72858,-9.2955933
116.6,1.2001314,-0.31413683,62.116077,0,10.594783,349.71582,-0.020736255,15.591046,10.594648,345.91257,-9.2921991
118.8,1.1984652,-0.32303011,63.607716,0,10.594783,356.31589,-0.021327633,15.594083,10.594783,352.28793,-9.2877769
121.0,1.1991463,-0.33279026,64.552177,0,10.594783,362.91586,-0.021928027,15.607163,10.595453,359.7959,-9.2840023
123.2,1.2006871,-0.34249339,64.555672,0,10.594783,369.51584,-0.02255852,15.633628,10.59595,368.23633,-9.2802629
125.4,1.1987473,-0.35172725,63.973614,0,10.594783,376.11584,-0.023183754,15.601232,10.59448,376.65045,-9.2765989
127.6,1.2004272,-0.35933402,62.969032,0,10.594783,382.71582,-0.023701541,15.636163,10.594687,384.58081,-9.2729139
129.8,1.1998441,-0.36572188,62.04147,0,10.594783,389.3158,-0.024080513,15.64362,10.595776,391.63654,-9.2695942
132.0,1.202251,-0.37251526,61.468513,0,10.594783,395.9158,-0.024522334,15.712404,10.594601,397.74957,-9.2662773
134.2,1.2126675,-0.37893784,61.564629,0,10.594783,402.51581,-0.024924653,15.829246,10.594728,403.00568,-9.2627783
136.4,1.2114042,-0.38346842,62.333645,0,10.594783,409.11581,-0.025266314,15.821979,10.595233,408.14557,-9.258543
138.6,1.2125893,-0.38976625,63.365887,0,10.594783,415.71585,-0.025672499,15.838455,10.595247,413.62766,-9.2549009
140.8,1.2112508,-0.39826971,64.171135,0,10.594783,422.31583,-0.026191415,15.840934,10.594674,419.97723,-9.2510386
143.0,1.2104019,-0.40723169,64.742432,0,10.594783,428.91583,-0.026778648,15.84357,10.594173,427.05109,-9.2470608
145.2,1.2055269,-0.41554421,64.745888,0,10.594783,435.51584,-0.027307427,15.766508,10.595714,434.71262,-9.24331
147.4,1.2072793,-0.42251581,64.357918,0,10.594783,442.11584,-0.027793104,15.797114,10.593715,442.6933,-9.2400656
149.6,1.1953368,-0.42768359,63.445732,0,10.594783,448.71585,-0.028131936,15.648987,10.594489,450.40842,-9.2367001
151.8,1.1714269,-0.43160605,62.753914,0,10.594783,455.3158,-0.02836349,15.359084,10.595224,457.1752,-9.2331495
154.0,1.1554698,-0.4346154,62.336433,0,10.594783,461.9158,-0.028554302,15.15081,10.593802,463.32651,-9.2289515
156.2,1.1371609,-0.43749699,62.544895,0,10.594783,468.51581,-0.028724039,14.903584,10.593651,468.79489,-9.2250242
158.4,1.1310539,-0.44010571,63.171349,0,10.594783,475.11581,-0.028926717,14.804772,10.59479,474.01212,-9.221447
160.6,1.1344373,-0.44245586,64.350609,0,10.594783,481.71582,-0.029098617,14.880836,10.594543,479.36481,-9.2182016
162.8,1.1165433,-0.4455792,65.474831,0,10.594783,488.31586,-0.029266171,14.634164,10.594729,485.27905,-9.2146044
165.0,1.0993521,-0.44758978,66.19252,0,10.594783,494.91583,-0.029400691,14.424179,10.593862,492.43399,-9.2112904
167.2,1.0838451,-0.44692427,64.934814,0,10.594783,499.99884,-0.029340502,14.206716,10.593976,501.92853,-9.2076464
169.4,1.0432627,-0.43703729,58.959343,0,10.594783,499.99884,-0.028701568,13.669355,10.59452,510.17795,-9.2068768
171.6,1.0244914,-0.41617927,48.560612,0,10.594783,499.99884,-0.027381355,13.396968,10.594575,515.25934,-9.2075748
173.8,1.0209473,-0.38754711,30.901665,0,10.594783,499.99884,-0.025541553,13.342216,10.595459,515.16058,-9.2077866
176.0,1.0209413,-0.36043501,31.50141,0,10.594783,499.99884,-0.023743382,13.333772,10.594703,505.56686,-9.2080021
178.2,1.0302969,-0.34566247,47.849503,0,10.594783,499.99884,-0.022779016,13.426132,10.594661,493.4342,-9.2075596
180.4,1.0774429,-0.34608895,58.794659,0,10.594783,499.99884,-0.022813311,14.02985,10.594103,486.14001,-9.2070522
182.6,1.1401751,-0.35643744,64.513718,0,10.594783,499.99884,-0.023464046,14.851211,10.593998,485.70584,-9.2069006
184.8,1.1640625,-0.36625257,66.192619,0,10.594783,499.99884,-0.024111843,15.183817,10.595706,491.3504,-9.2068634
187.0,1.1351048,-0.36631644,64.406082,0,10.594783,499.99884,-0.02413165,14.792384,10.594807,499.96808,-9.207365
189.2,1.0716046,-0.35893267,58.659695,0,10.594783,499.99884,-0.023677316,13.940123,10.594702,509.01178,-9.2076817
191.4,1.0226852,-0.34671402,48.868336,0,10.594783,499.99884,-0.022855461,13.308397,10.594711,513.88269,-9.2073689
193.6,1.0249254,-0.32659143,37.265339,0,10.594783,499.99884,-0.021528143,13.334822,10.59525,512.45013,-9.2072687
195.8,1.0297098,-0.30630815,36.307453,0,10.594783,499.99884,-0.020219998,13.381545,10.594318,505.1618,-9.2066708
198.0,1.0312345,-0.29436982,46.648491,0,10.594783,499.99884,-0.019415479,13.399295,10.593998,496.20862,-9.2067375
200.2,1.0605099,-0.2936115,55.514164,0,10.594783,499.99884,-0.019356864,13.767452,10.5952,490.42844,-9.2067556
202.4,1.0990205,-0.29812509,60.908478,0,10.594783,499.99884,-0.019665515,14.269818,10.593566,489.26871,-9.2066689
204.6,1.1367197,-0.30458492,63.104595,0,10.594783,499.99884,-0.020118102,14.757897,10.594234,492.40314,-9.2070398
206.8,1.1422814,-0.30612862,62.121479,0,10.594783,499.99884,-0.020218732,14.846888,10.595469,498.59109,-9.2071209
209.0,1.1019006,-0.30552891,58.524853,0,10.594783,499.99884,-0.020196212,14.31756,10.595114,504.67929,-9.2073517
211.2,1.0445906,-0.29678857,52.047367,0,10.594783,499.99884,-0.019601688,13.547144,10.595229,509.05374,-9.2074556
211.9512,1.0313956,0.00774056,1.9853483,0,10.5948,1.5409876e-16,0.00046754265,13.119922,10.594101,509.72052,-9.2069311
211.9556,1.0117177,0.011935044,0.0,0,10.5948,0.0,0.00066623685,12.91671,10.596309,509.74677,-9.2084026
211.96,1.0172161,0.0076911487,0.0,0,10.5948,0.0,0.00045764583,12.935264,10.594752,509.77301,-9.2061234
211.9644,1.0216494,0.010846332,0.0,0,10.5948,0.0,0.00062724488,13.021483,10.595215,509.78256,-9.207469
211.9688,1.0244043,0.0083518419,0.0,0,10.5948,0.0,0.00046413022,13.026656,10.596437,509.78256,-9.2082014
211.9732,1.0121554,0.011553842,0.0,0,10.5948,0.0,0.00066152227,12.949241,10.593454,509.78256,-9.2081203
211.9776,1.000082,0.007917597,0.0,0,10.5948,0.0,0.00044117047,12.716724,10.594417,509.78256,-9.2077742
211.982,1.0202101,0.011749525,0.0,0,10.5948,0.0,0.00064674678,12.978874,10.595804,509.78256,-9.2066545
211.9864,1.0207286,0.0084469691,0.0,0,10.5948,0.0,0.00050348777,12.856095,10.595971,509.78256,-9.2079945
211.9908,1.0081687,0.011447872,0.0,0,10.5948,0.0,0.00064369058,13.007536,10.597684,509.78256,-9.2086372
211.9952,1.0182464,0.0087059736,0.0,0,10.5948,0.0,0.00049594452,12.829852,10.595317,509.76108,-9.2074251
211.9996,1.0127901,0.012095571,0.0,0,10.578863,0.0,0.00071339734,12.856127,10.596152,509.73483,-9.2067003
212.004,1.0277764,0.010738003,0.0,0,10.512864,0.0,0.00064235181,13.09547,10.593988,509.7229,-9.2074547
212.0084,1.0229375,0.012663907,0.0,0,10.446864,0.0,0.0007219722,13.094422,10.585695,509.7229,-9.2068815
212.0128,1.0191332,0.0090853833,0.0,0,10.380864,0.0,0.00058426237,12.960807,10.53563,509.73364,-9.2090683
212.0172,1.0093818,0.012993115,0.0,0,10.314864,0.0,0.00072424201,12.797758,10.431593,509.77301,-9.2065268
212.0216,1.0250777,0.0075587914,0.0,0,10.248864,0.0,0.00048023998,13.079349,10.331328,509.81238,-9.2078199
212.026,1.0188341,0.013118885,0.0,0,10.182864,0.0,0.00077621639,12.990427,10.25927,509.81238,-9.2071762
212.0304,1.0153459,0.010377409,0.0,0,10.116864,0.0,0.00063384383,12.954934,10.204788,509.81238,-9.2076225
212.0348,1.0145848,0.013043485,0.0,0,10.050864,0.0,0.00074350857,13.017786,10.147344,509.80283,-9.2066612
212.0392,1.0208324,0.011064126,0.0,0,9.9848633,0.0,0.000651896,12.961365,10.084009,509.7897,-9.2079411
212.0436,1.0248914,0.013079253,0.0,0,9.9188633,0.0,0.00077983981,13.046468,10.009449,509.75275,-9.2073383
212.048,1.146101,0.011284518,0.0,0,9.8528633,0.0,0.00071102957,14.575587,9.9416199,509.6871,-9.2072096
212.0524,2.7203057,0.027319711,0.0,0,9.7868633,0.0,0.0016334949,34.287399,9.8822384,509.57852,-9.2058773
212.0568,3.0691252,0.087180883,0.0,0,9.7208633,0.0,0.0057601524,38.869576,9.8157139,509.27667,-9.2055464
212.0612,3.1562858,0.16295153,0.0,0,9.6548634,0.0,0.010655885,39.842396,9.7421217,508.97479,-9.2047043
212.0656,3.1761389,0.22664113,0.0,0,9.5888634,0.0,0.015137761,39.888035,9.6684437,509.55588,-9.2053337
212.07,3.2091713,0.29606813,0.0,0,9.5228634,0.0,0.019764164,40.063171,9.6009283,510.22522,-9.2059345
212.0744,3.2172935,0.35736176,0.0,0,9.4574747,0.0,0.023966406,40.04295,9.5366802,511.75488,-9.2064362
212.0788,3.220711,0.42248878,0.0,0,9.393095,0.0,0.028354332,39.943798,9.4754324,513.77612,-9.2072811
212.0832,3.2448018,0.48366231,0.0,0,9.3287144,0.0,0.032692816,40.016243,9.4088678,515.72577,-9.2071486
212.0876,3.2949395,0.55567014,0.0,0,9.2643328,0.0,0.037488483,40.402721,9.3352451,517.54999,-9.2057104
212.092,3.2923608,0.61600733,0.0,0,9.1999531,0.0,0.041779879,40.305275,9.2749529,519.20477,-9.2058592
212.0964,3.2759831,0.68073523,0.0,0,9.1355715,0.0,0.046254266,39.927162,9.2105074,519.16541,-9.205102
212.1008,3.2759361,0.74035192,0.0,0,9.0711908,0.0,0.050482053,39.764294,9.1452303,519.12604,-9.2058182
212.1052,3.3229868,0.80859613,0.0,0,9.0068102,0.0,0.055218056,40.029793,9.0803499,518.5498,-9.2064495
212.1096,3.3852925,0.87036258,0.0,0,8.9424286,0.0,0.059644736,40.606792,9.0112782,517.85431,-9.2063351
212.114,3.368865,0.93961257,0.0,0,8.8780489,0.0,0.064471319,40.242077,8.9418049,517.65985,-9.2072897
212.1184,3.3493152,0.99937493,0.0,0,8.8136673,0.0,0.068827473,39.831348,8.8774395,517.883,-9.2058687
212.1228,3.3652377,1.0644164,0.0,0,8.7493448,0.0,0.073409922,39.731201,8.8131056,518.20636,-9.2072372
212.1272,3.419735,1.1238492,0.0,0,8.6880999,0.0,0.077780142,40.270947,8.7503033,518.79688,-9.2066231
212.1316,3.4377697,1.1931357,0.0,0,8.6268702,0.0,0.082675278,40.158249,8.686017,519.38745,-9.2069798
212.136,3.4202673,1.251491,0.0,0,8.5656395,0.0,0.087051883,39.911423,8.6197529,519.74176,-9.2073498
212.1404,3.4068794,1.3159612,0.0,0,8.5044088,0.0,0.091558702,39.56805,8.5580406,520.09613,-9.2069759
212.1448,3.4409797,1.3707792,0.0,0,8.4431791,0.0,0.095714241,39.716251,8.5012655,520.19275,-9.2059498
212.1492,3.4693577,1.4318037,0.0,0,8.3819485,0.0,0.10010587,39.941845,8.4408875,520.19275,-9.2059278
212.1536,3.4927528,1.4912952,0.0,0,8.3207188,0.0,0.10459976,40.096783,8.3725386,520.53265,-9.2067051
212.158,3.4929578,1.5582502,0.0,0,8.2594881,0.0,0.10945722,39.843964,8.3139477,521.28046,-9.2065296
212.1624,3.509563,1.616922,0.0,0,8.1982584,0.0,0.11388703,39.835632,8.2525358,522.09741,-9.2061787
212.1668,3.5514579,1.6817435,0.0,0,8.1370277,0.0,0.11869609,40.140797,8.1884327,523.22565,-9.204814
212.1712,3.5386343,1.7385321,0.0,0,8.0757971,0.0,0.12301768,39.939373,8.1253462,524.35388,-9.2055569
212.1756,3.5435836,1.8041862,0.0,0,8.0165014,0.0,0.12795468,39.716228,8.0645075,525.24353,-9.2057953
212.18,3.5350783,1.8591104,0.0,0,7.9582458,0.0,0.13218749,39.546211,8.0055475,526.10938,-9.2055626
212.1844,3.5899272,1.9204915,0.0,0,7.8999891,0.0,0.13675739,39.813931,7.9430065,527.14307,-9.2071409
212.1888,3.5933406,1.9764166,0.0,0,7.8417335,0.0,0.14117087,39.781502,7.8853979,528.27277,-9.2052412
212.1932,3.583792,2.0355096,0.0,0,7.7834773,0.0,0.14560209,39.349052,7.8303938,529.4093,-9.2058964
212.1976,3.5981562,2.0879874,0.0,0,7.7252216,0.0,0.14978912,39.442921,7.772758,530.5769,-9.2049522
212.202,3.6568789,2.1490715,0.0,0,7.666965,0.0,0.15439351,39.920933,7.7111106,531.74451,-9.2066479
212.2064,3.6545775,2.2054567,0.0,0,7.6087093,0.0,0.15886639,39.744457,7.6502242,530.58649,-9.2061892
212.2108,3.6487164,2.2658339,0.0,0,7.5504532,0.0,0.16354752,39.43375,7.5915403,529.19586,-9.205637
212.2152,3.6753273,2.3205433,0.0,0,7.4921975,0.0,0.1679001,39.561344,7.535017,527.73016,-9.2063274
212.2196,3.7262671,2.3819785,0.0,0,7.4339414,0.0,0.1727019,39.905663,7.4756632,526.2215,-9.2053127
212.224,3.7522287,2.4390485,0.0,0,7.3765039,0.0,0.17729588,39.968185,7.4099498,525.47614,-9.2058039
212.2284,3.7177675,2.4996653,0.0,0,7.3210988,0.0,0.18197736,39.506203,7.3535213,526.06647,-9.2060509
212.2328,3.7020791,2.5490341,0.0,0,7.2656941,0.0,0.18614928,39.146763,7.3037472,526.42065,-9.2043905
212.2372,3.7266638,2.6078293,0.0,0,7.210289,0.0,0.19071659,39.134243,7.2481608,524.41315,-9.2060461
212.2416,3.8006365,2.6592002,0.0,0,7.1548843,0.0,0.19495754,39.810501,7.1918974,522.40564,-9.2065001
212.246,3.7780628,2.7171373,0.0,0,7.0994792,0.0,0.19964299,39.443138,7.1336212,519.64661,-9.2054253
212.2504,3.7868707,2.7707531,0.0,0,7.044075,0.0,0.20407368,39.354462,7.0816002,516.72046,-9.206872
212.2548,3.8279827,2.8299963,0.0,0,6.9886694,0.0,0.20879062,39.56749,7.026545,514.64594,-9.2059689
212.2592,3.8661754,2.8821466,0.0,0,6.9332652,0.0,0.21320143,39.702805,6.9663339,513.28094,-9.206192
212.2636,3.8682868,2.9407415,0.0,0,6.8778601,0.0,0.21794792,39.660706,6.9112244,512.12714,-9.2053032
212.268,3.8707142,2.9907715,0.0,0,6.8224554,0.0,0.2222213,39.46991,6.8507814,511.53653,-9.2066669
212.2724,3.8819811,3.0516851,0.0,0,6.7670503,0.0,0.22719121,39.362793,6.7976961,510.94592,-9.2065907
212.2768,3.9200354,3.1041315,0.0,0,6.7141318,0.0,0.2317079,39.48571,6.7392783,511.07718,-9.2040939
212.2812,3.9137793,3.1625674,0.0,0,6.6614199,0.0,0.23648106,39.340927,6.6870313,511.2084,-9.2071152
212.2856,3.887229,3.2090414,0.0,0,6.6087079,0.0,0.24052018,38.906536,6.637475,512.24646,-9.206418
212.29,3.9103172,3.266422,0.0,0,6.5559959,0.0,0.24530821,38.968563,6.5823154,513.62457,-9.2052174
212.2944,3.9419894,3.3134456,0.0,0,6.503284,0.0,0.24946794,39.131992,6.5287662,515.24133,-9.2052956
212.2988,3.9575071,3.3689742,0.0,0,6.450572,0.0,0.25412408,39.035816,6.4773545,517.14447,-9.2050333
212.3032,3.9700916,3.4151263,0.0,0,6.3978601,0.0,0.25814384,39.093262,6.423583,518.97589,-9.2040157
212.3076,3.9787045,3.4717152,0.0,0,6.3451481,0.0,0.26295114,38.955051,6.374783,520.48474,-9.2058401
212.312,4.0225782,3.5213859,0.0,0,6.2924366,0.0,0.26735565,39.203091,6.318687,521.99365,-9.2053061
212.3164,4.0354857,3.5767596,0.0,0,6.2397246,0.0,0.27217394,39.206524,6.268877,523.72894,-9.2051926
212.3208,4.0671105,3.6283741,0.0,0,6.1870127,0.0,0.27681592,39.262783,6.2107086,525.48688,-9.2058153
212.3252,4.0597463,3.6851325,0.0,0,6.1357436,0.0,0.28155398,38.991074,6.1537352,527.04443,-9.2059937
212.3296,4.055604,3.7326403,0.0,0,6.0856099,0.0,0.28591254,38.713047,6.1079073,528.48743,-9.2075129
212.334,4.0748053,3.7858987,0.0,0,6.0354762,0.0,0.2905046,38.77153,6.0542874,529.85419,-9.2049751
212.3384,4.0776272,3.8304787,0.0,0,5.9853425,0.0,0.29469436,38.672344,6.0095286,531.08734,-9.2055693
212.3428,4.0863957,3.8844802,0.0,0,5.9352088,0.0,0.29939109,38.549812,5.9557495,532.27997,-9.2061558
212.3472,4.099144,3.9288931,0.0,0,5.8850756,0.0,0.30353945,38.552536,5.9062366,533.06714,-9.2051334
212.3516,4.1571112,3.9822206,0.0,0,5.8349419,0.0,0.30819276,38.828743,5.8563209,533.85425,-9.2062864
212.356,4.1595755,4.0286736,0.0,0,5.7848082,0.0,0.31255502,38.822746,5.8066125,534.57709,-9.2045307
212.3604,4.1936979,4.0851426,0.0,0,5.7346745,0.0,0.31757459,38.918617,5.7532625,535.28558,-9.2057552
212.3648,4.219214,4.1331797,0.0,0,5.6845412,0.0,0.32211074,38.929581,5.7018261,536.02283,-9.2053194
212.3692,4.2339077,4.1890492,0.0,0,5.634407,0.0,0.3271465,38.869556,5.6466861,536.78387,-9.2047033
212.3736,4.217361,4.2356157,0.0,0,5.5847516,0.0,0.33149856,38.622219,5.5991387,537.50562,-9.2053175
212.378,4.2072415,4.2841101,0.0,0,5.5370555,0.0,0.33603686,38.296818,5.5487494,538.12238,-9.2060413
212.3824,4.2142658,4.3292055,0.0,0,5.4893594,0.0,0.3402994,38.162941,5.5008812,538.73914,-9.2053671
212.3868,4.23596,4.3803864,0.0,0,5.4416633,0.0,0.34503433,38.111977,5.4581385,539.10657,-9.2057514
212.3912,4.2707686,4.4214687,0.0,0,5.3939681,0.0,0.34903619,38.321335,5.4061828,539.474,-9.2034464
212.3956,4.2742257,4.4728279,0.0,0,5.346272,0.0,0.35376388,38.257748,5.3632307,539.73651,-9.2052956
212.4,4.3076591,4.5159674,0.0,0,5.2985759,0.0,0.35794663,38.320976,5.3134184,539.95959,-9.2060184
212.4044,4.3106394,4.5691247,0.0,0,5.2508798,0.0,0.3628054,38.215462,5.2606063,539.30597,-9.2050877
212.4088,4.3794599,4.612638,0.0,0,5.2031837,0.0,0.36716256,38.544842,5.219244,537.60016,-9.2052813
212.4132,4.3671145,4.6643348,0.0,0,5.155488,0.0,0.37208053,38.334839,5.1686502,535.83716,-9.2065344
212.4176,4.3598866,4.7050328,0.0,0,5.1077919,0.0,0.37615606,38.138725,5.1231117,533.81647,-9.2063599
212.422,4.4163237,4.7602654,0.0,0,5.0600958,0.0,0.38137406,38.377956,5.0743852,531.79584,-9.205411
212.4264,4.4723105,4.8054738,0.0,0,5.0143409,0.0,0.38600853,38.76268,5.0197682,531.68365,-9.2041254
212.4308,4.4791822,4.860353,0.0,0,4.968977,0.0,0.39122832,38.551846,4.9784775,531.76239,-9.2055073
212.4352,4.4238381,4.9030828,0.0,0,4.9236126,0.0,0.39555624,37.962444,4.9253683,532.09155,-9.2045956
212.4396,4.3985233,4.9473395,0.0,0,4.8782492,0.0,0.39985254,37.573235,4.8860641,532.56384,-9.2050171
212.444,4.4146314,4.9873548,0.0,0,4.8328848,0.0,0.40401691,37.480244,4.8439941,533.07428,-9.2059183
212.4484,4.483489,5.0321679,0.0,0,4.7875209,0.0,0.40829575,38.001663,4.7960715,533.65149,-9.2041941
212.4528,4.5425472,5.0762048,0.0,0,4.7421565,0.0,0.41281381,38.271339,4.7552285,534.24304,-9.2050991
212.4572,4.5567679,5.1289258,0.0,0,4.6967926,0.0,0.41802981,38.186527,4.7039866,534.97784,-9.2047224
212.4616,4.5832953,5.1706767,0.0,0,4.6514287,0.0,0.42247826,38.223995,4.6580906,535.71259,-9.2049999
212.466,4.5562882,5.2188315,0.0,0,4.6060648,0.0,0.42723563,37.805565,4.6158404,536.46893,-9.2053375
212.4704,4.6089134,5.2606359,0.0,0,4.5607004,0.0,0.43162403,38.120537,4.5698566,537.2301,-9.2039127
212.4748,4.6175308,5.3114109,0.0,0,4.5163722,0.0,0.43654424,38.045124,4.5216112,538.06281,-9.2054558
212.4792,4.6225247,5.3522148,0.0,0,4.4732165,0.0,0.4410643,37.863415,4.4745646,538.95514,-9.2060471
212.4836,4.6490159,5.4008255,0.0,0,4.4300613,0.0,0.44597113,37.924667,4.4294329,539.81885,-9.2035732
212.488,4.6405349,5.4376912,0.0,0,4.3869061,0.0,0.44996816,37.761463,4.3892274,540.6062,-9.2061148
212.4924,4.6321669,5.4820495,0.0,0,4.343751,0.0,0.4544121,37.447563,4.3474765,541.39355,-9.2049942
212.4968,4.7210207,5.5223441,0.0,0,4.3005962,0.0,0.45878065,37.953411,4.3068051,542.04974,-9.2049417
212.5012,4.7430491,5.5697594,0.0,0,4.2574406,0.0,0.46375921,37.964355,4.2584987,542.70587,-9.2056608
212.5056,4.7543807,5.6073108,0.0,0,4.2142854,0.0,0.46788645,37.980316,4.2174411,543.20929,-9.204011
212.51,4.7401462,5.6551123,0.0,0,4.1711302,0.0,0.47280255,37.680317,4.1775746,543.65552,-9.2040997
212.5144,4.7748461,5.694952,0.0,0,4.127975,0.0,0.47722596,37.731842,4.1344929,543.96448,-9.2051582
212.5188,4.8335409,5.7413974,0.0,0,4.0848203,0.0,0.4820109,37.998859,4.0891042,544.10883,-9.2066307
212.5232,4.8747344,5.7835541,0.0,0,4.0418863,0.0,0.48669443,38.202564,4.049808,544.21259,-9.2048254
212.5276,4.8933148,5.8289418,0.0,0,4.0008435,0.0,0.49148026,38.126152,3.9987454,544.13385,-9.2052221
212.532,4.834466,5.8680973,0.0,0,3.9598002,0.0,0.49600145,37.482067,3.9602981,544.05511,-9.2049913
212.5364,4.9148383,5.9129229,0.0,0,3.918757,0.0,0.50067383,37.940788,3.918133,544.14343,-9.2051554
212.5408,4.9118733,5.9496531,0.0,0,3.8777139,0.0,0.50498283,37.782013,3.879442,544.24841,-9.2046938
212.5452,4.947824,5.9946551,0.0,0,3.8366706,0.0,0.50980258,37.841698,3.8406758,544.44531,-9.2057619
212.5496,4.953824,6.0349312,0.0,0,3.7956276,0.0,0.51432484,37.738586,3.7954841,544.69458,-9.204752
212.554,4.9618325,6.0794616,0.0,0,3.7545841,0.0,0.51917082,37.630039,3.758189,544.12317,-9.2042179
212.5584,5.0212936,6.1147985,0.0,0,3.713541,0.0,0.52323914,37.872009,3.7164118,542.11536,-9.2056608
212.5628,5.0509596,6.1604075,0.0,0,3.672498,0.0,0.52826852,37.942337,3.6723008,540.11707,-9.2046957
212.5672,5.052834,6.1978469,0.0,0,3.6314545,0.0,0.53276008,37.755943,3.6312079,538.21423,-9.2054977
212.5716,5.1023488,6.2438178,0.0,0,3.5904114,0.0,0.53779566,37.935982,3.5910223,536.3114,-9.2048588
212.576,5.1571312,6.2795978,0.0,0,3.5508497,0.0,0.5420562,38.168938,3.5483468,535.55756,-9.2051783
212.5804,5.1825776,6.3273587,0.0,0,3.5118039,0.0,0.5473668,38.197029,3.5059631,535.05902,-9.2056732
212.5848,5.1493087,6.3641405,0.0,0,3.4727583,0.0,0.55178553,37.733154,3.462486,534.73218,-9.2044868
212.5892,5.1206126,6.404623,0.0,0,3.4337125,0.0,0.55638784,37.348431,3.4299998,534.5484,-9.2058163
212.5936,5.1776142,6.4405699,0.0,0,3.3946671,0.0,0.56064463,37.573322,3.3888659,534.6438,-9.2036934
212.598,5.2155619,6.4815068,0.0,0,3.3556216,0.0,0.565274,37.719917,3.3545539,535.48358,-9.2057028
212.6024,5.2385449,6.5141358,0.0,0,3.316576,0.0,0.56933522,37.708302,3.3181801,536.32336,-9.205061
212.6068,5.2594876,6.5601468,0.0,0,3.27753,0.0,0.57452577,37.720303,3.2749636,537.08447,-9.2036629
212.6112,5.3110614,6.5950599,0.0,0,3.2384844,0.0,0.57887775,37.925957,3.2377064,537.84564,-9.2046804
212.6156,5.3860412,6.6363306,0.0,0,3.199439,0.0,0.58356237,38.245754,3.2011368,538.37769,-9.2051849
212.62,5.3932786,6.6725435,0.0,0,3.1603935,0.0,0.58811074,38.210098,3.1615365,538.82391,-9.2040081
212.6244,5.3575315,6.7171178,0.0,0,3.122066,0.0,0.5932157,37.739933,3.122658,539.30585,-9.2051048
212.6288,5.37989,6.7494483,0.0,0,3.0849211,0.0,0.59741771,37.678543,3.081408,539.83075,-9.2039185
212.6332,5.4489899,6.7894778,0.0,0,3.0477762,0.0,0.60220087,37.930367,3.0456944,540.38196,-9.2064514
212.6376,5.4565563,6.8239079,0.0,0,3.0106313,0.0,0.60653591,37.896965,3.0104473,541.05121,-9.2047796
212.642,5.4614878,6.8642263,0.0,0,2.9734867,0.0,0.61118603,37.702217,2.9703698,541.72046,-9.204073
212.6464,5.471323,6.8953733,0.0,0,2.9363418,0.0,0.61526251,37.695652,2.9369533,541.66199,-9.2044954
212.6508,5.5810504,6.9376884,0.0,0,2.8991969,0.0,0.62021667,38.219322,2.8978117,541.53076,-9.2038832
212.6552,5.6213813,6.9738312,0.0,0,2.8620524,0.0,0.62490326,38.342937,2.8628683,541.12396,-9.203536
212.6596,5.617846,7.0145631,0.0,0,2.8249075,0.0,0.62982708,38.123856,2.8230126,540.55963,-9.2041454
212.664,5.644206,7.0484943,0.0,0,2.7877626,0.0,0.63437116,38.119026,2.7829907,540.14807,-9.2057867
212.6684,5.706531,7.0896525,0.0,0,2.7506177,0.0,0.6392597,38.296314,2.7520928,540.00372,-9.2051344
212.6728,5.7608047,7.1232691,0.0,0,2.7135069,0.0,0.64376694,38.528786,2.7122707,538.96454,-9.2042189
212.6772,5.7574711,7.1670127,0.0,0,2.6781669,0.0,0.64915574,38.345276,2.6744266,528.97705,-9.2048521
212.6816,5.7967753,7.2000699,0.0,0,2.6428349,0.0,0.65348434,38.33419,2.6346309,518.98956,-9.2050524
212.686,5.8190861,7.240521,0.0,0,2.6075029,0.0,0.65855467,38.332359,2.5984316,509.59302,-9.2052383
212.6904,5.8159704,7.2715988,0.0,0,2.572171,0.0,0.66280335,38.143742,2.5670695,500.32779,-9.2053041
212.6948,5.8424091,7.3080606,0.0,0,2.536839,0.0,0.66725487,38.16637,2.5308282,496.47446,-9.2047596
212.6992,5.8909783,7.3396869,0.0,0,2.501507,0.0,0.67160946,38.329296,2.4966528,497.13107,-9.2044764
212.7036,5.9752731,7.3815989,0.0,0,2.4661748,0.0,0.67675292,38.693008,2.4585724,497.99896,-9.2044802
212.708,6.0124726,7.4136686,0.0,0,2.4308429,0.0,0.68134224,38.742168,2.4224322,499.43033,-9.2052574
212.7124,6.0056157,7.4542742,0.0,0,2.3955109,0.0,0.68650931,38.444901,2.3844271,500.86169,-9.2057276
212.7168,5.9790335,7.481101,0.0,0,2.3601789,0.0,0.69018847,38.216045,2.3525865,503.80249,-9.2039623
212.7212,6.0090013,7.5206051,0.0,0,2.324847,0.0,0.69512689,38.135651,2.3231966,506.74329,-9.2046919
212.7256,6.0989165,7.5471501,0.0,0,2.2906368,0.0,0.6989696,38.549591,2.2909067,509.70258,-9.2049646
212.73,6.2106218,7.5878816,0.0,0,2.2570295,0.0,0.70432895,39.132828,2.2541342,512.66882,-9.2052107
212.7344,6.234395,7.6177192,0.0,0,2.2234225,0.0,0.7085408,39.083347,2.2182829,515.28894,-9.2063265
212.7388,6.2545428,7.6608305,0.0,0,2.1898153,0.0,0.7141211,38.93446,2.1822419,517.49384,-9.205143
212.7432,6.2674546,7.692122,0.0,0,2.156208,0.0,0.71865237,38.910748,2.1461191,519.57697,-9.2030163
212.7476,6.2777691,7.7260036,0.0,0,2.1226008,0.0,0.72308588,38.777042,2.1121547,521.11206,-9.2036915
212.752,6.2773938,7.7565742,0.0,0,2.0889935,0.0,0.72764796,38.618969,2.0823159,522.64716,-9.2035875
212.7564,6.3341255,7.794446,0.0,0,2.0553865,0.0,0.73253036,38.774147,2.051369,524.18213,-9.2038269
212.7608,6.4437809,7.8227839,0.0,0,2.0217793,0.0,0.7367444,39.245846,2.0159135,525.71698,-9.2051659
212.7652,6.5534,7.8613057,0.0,0,1.9881722,0.0,0.74188888,39.727749,1.9818904,526.7677,-9.2036476
212.7696,6.5365133,7.8923006,0.0,0,1.954565,0.0,0.74631178,39.511116,1.9472369,527.54169,-9.2044001
212.774,6.5299788,7.9303732,0.0,0,1.9214275,0.0,0.75148326,39.213219,1.910067,528.31091,-9.2045288
212.7784,6.5399013,7.9598517,0.0,0,1.889457,0.0,0.75607198,39.050552,1.8816411,529.07184,-9.2043543
212.7828,6.5615082,7.9906783,0.0,0,1.8574866,0.0,0.76008159,39.054585,1.8485719,529.88043,-9.2045584
212.7872,6.6511459,8.0209417,0.0,0,1.8255162,0.0,0.76464826,39.37167,1.8203491,531.16608,-9.2044926
212.7916,6.6926823,8.0568638,0.0,0,1.7935458,0.0,0.76960653,39.516544,1.7861731,532.45172,-9.2034121
212.796,6.7346573,8.0863581,0.0,0,1.7615755,0.0,0.77407104,39.490189,1.7545624,533.72675,-9.2042761
212.8004,6.8024325,8.1232347,0.0,0,1.729605,0.0,0.77906239,39.734932,1.7195805,534.99939,-9.2048855
212.8048,6.809866,8.1472015,0.0,0,1.6976346,0.0,0.78301036,39.623375,1.6960921,536.02167,-9.2045403
212.8092,6.8872914,8.1876612,0.0,0,1.6656642,0.0,0.78852701,39.856899,1.6622981,536.83521,-9.2036486
212.8136,6.9519806,8.2133465,0.0,0,1.6336937,0.0,0.79259521,40.058765,1.6295725,535.99554,-9.2058144
212.818,7.0365529,8.2527533,0.0,0,1.6017234,0.0,0.79822814,40.300125,1.594659,530.74719,-9.203846
212.8224,7.1216435,8.2820854,0.0,0,1.5697531,0.0,0.80266178,40.659409,1.5623921,525.49884,-9.203805
212.8268,7.1372132,8.3197699,0.0,0,1.5392207,0.0,0.80818141,40.508717,1.528899,519.89618,-9.2051344
212.8312,7.1195025,8.3495455,0.0,0,1.5088079,0.0,0.81282216,40.233269,1.4928672,514.29352,-9.2043085
212.8356,7.0906076,8.3824129,0.0,0,1.478395,0.0,0.81748062,39.84045,1.4627035,512.86096,-9.2041235
212.84,7.1290298,8.4047909,0.0,0,1.4479822,0.0,0.82121205,39.884232,1.4401304,512.99219,-9.2037363
212.8444,7.1771622,8.4395599,0.0,0,1.4175695,0.0,0.82621515,40.036247,1.4086524,514.06592,-9.2032871
212.8488,7.2589054,8.4636412,0.0,0,1.3871567,0.0,0.830154,40.299572,1.3810778,516.27063,-9.2049961
212.8532,7.3784833,8.4973755,0.0,0,1.3567439,0.0,0.834988,40.741074,1.3499331,518.63513,-9.2041121
212.8576,7.4366155,8.525403,0.0,0,1.3263311,0.0,0.83958387,40.858356,1.3194091,521.71863,-9.2043009
212.862,7.4382997,8.560874,0.0,0,1.2959183,0.0,0.84477305,40.680313,1.2876078,524.80219,-9.2045622
212.8664,7.4637341,8.5842171,0.0,0,1.2655054,0.0,0.84885782,40.658211,1.2575476,526.72833,-9.2048302
212.8708,7.5142541,8.6203413,0.0,0,1.2350928,0.0,0.85405725,40.71928,1.2314039,528.5387,-9.2036295
212.8752,7.6536345,8.6446686,0.0,0,1.2055123,0.0,0.85827321,41.308872,1.2005966,529.23877,-9.2032661
212.8796,7.7185678,8.6801205,0.0,0,1.1765865,0.0,0.86358052,41.476734,1.1653944,529.30438,-9.2050943
212.884,7.7174621,8.7051296,0.0,0,1.1476611,0.0,0.86777997,41.271049,1.1403167,529.15051,-9.2035532
212.8884,7.7280946,8.7375689,0.0,0,1.1187353,0.0,0.87255597,41.091946,1.1092362,528.61267,-9.2029095
212.8928,7.7821326,8.7648907,0.0,0,1.0898098,0.0,0.8772282,41.211826,1.0855278,528.1153,-9.2046995
212.8972,7.9165812,8.7956314,0.0,0,1.0608841,0.0,0.88192564,41.704136,1.0523133,528.0235,-9.2044735
212.9016,7.9739184,8.8205786,0.0,0,1.0319586,0.0,0.88629079,41.859612,1.0212481,527.9317,-9.204134
212.906,8.0258894,8.8574343,0.0,0,1.0030329,0.0,0.89185727,41.884525,0.99645621,528.04376,-9.2036076
212.9104,8.0908051,8.8812332,0.0,0,0.97410738,0.0,0.89621115,42.066601,0.95992345,528.20123,-9.2032118
212.9148,8.1323462,8.9141159,0.0,0,0.94518179,0.0,0.90113974,42.036976,0.93580967,527.85773,-9.2041616
212.9192,8.1804161,8.9362469,0.0,0,0.91625619,0.0,0.90516692,42.109531,0.90464902,527.09686,-9.2037907
212.9236,8.2220182,8.9696178,0.0,0,0.88760829,0.0,0.91027606,42.105976,0.8793686,526.41107,-9.202672
212.928,8.2593679,8.9916992,0.0,0,0.86009949,0.0,0.91433096,42.115623,0.84964114,525.92572,-9.2052784
212.9324,8.3456192,9.0255508,0.0,0,0.83259064,0.0,0.9195776,42.325199,0.82171983,525.44031,-9.2052593
212.9368,8.3979015,9.0472517,0.0,0,0.8050819,0.0,0.92347032,42.483059,0.7945658,526.04382,-9.2033644
212.9412,8.4239178,9.0793066,0.0,0,0.77757305,0.0,0.92859668,42.361439,0.76875371,526.64728,-9.2036114
212.9456,8.5268354,9.1005964,0.0,0,0.75006431,0.0,0.93253475,42.686947,0.73896688,524.38788,-9.2031088
212.95,8.6202183,9.1302357,0.0,0,0.72255546,0.0,0.93739313,42.992535,0.71371818,521.05481,-9.2032833
212.9544,8.649086,9.1548805,0.0,0,0.69504666,0.0,0.94184208,42.949291,0.68623221,517.47125,-9.2037954
212.9588,8.7030029,9.1850204,0.0,0,0.66753787,0.0,0.94669658,42.992016,0.65818769,513.58704,-9.2038803
212.9632,8.7891541,9.2068567,0.0,0,0.64002907,0.0,0.95078385,43.219944,0.63210112,510.25867,-9.2045898
212.9676,8.9348068,9.2384825,0.0,0,0.61252028,0.0,0.95584267,43.70929,0.60118419,509.43176,-9.202755
212.972,8.9859772,9.2618179,0.0,0,0.58501148,0.0,0.96026897,43.790009,0.57576442,508.60489,-9.2034903
212.9764,8.4184618,9.2847137,0.0,0,0.55860871,0.0,0.96385956,40.915924,0.55217385,507.9928,-9.2045317
212.9808,7.8930187,9.2829304,0.0,0,0.53242874,0.0,0.96383864,38.362225,0.53413975,507.40219,-9.2057219
212.9852,7.5068712,9.2850542,0.0,0,0.50624865,0.0,0.96399593,36.472099,0.51889193,507.00369,-9.2059355
212.9896,7.2195706,9.2891369,0.0,0,0.48006868,0.0,0.96510643,34.99633,0.49741766,506.71494,-9.2061176
212.994,7.0343771,9.2969103,0.0,0,0.45388871,0.0,0.9659493,34.110268,0.47847265,506.77936,-9.2057753
212.9984,6.8302798,9.2933245,0.0,0,0.42770869,0.0,0.96588302,33.092854,0.45527527,507.46185,-9.206233
213.0028,6.6069903,9.30369,0.0,0,0.40152872,0.0,0.96719611,31.950893,0.43481663,508.22186,-9.2066059
213.0072,6.427001,9.2993097,0.0,0,0.37534869,0.0,0.96680516,31.102104,0.42134887,509.75751,-9.2060995
213.0116,6.1164641,9.3053532,0.0,0,0.34916872,0.0,0.96746641,29.598719,0.41220847,511.29312,-9.2067728
213.016,5.8538795,9.2996397,0.0,0,0.32298869,0.0,0.96700811,28.400454,0.40819809,512.77502,-9.2080631
213.0204,5.7199473,9.3088484,0.0,0,0.29680869,0.0,0.96813816,27.663668,0.39622009,514.24506,-9.2066755
213.0248,5.7523632,9.3028946,0.0,0,0.27123094,0.0,0.96747071,27.810593,0.37982887,515.45013,-9.2046499
213.0292,6.0679531,9.3123541,0.0,0,0.24633574,0.0,0.96868753,29.316425,0.34965658,516.43451,-9.2048607
213.0336,6.3141394,9.3091869,0.0,0,0.22144052,0.0,0.96859121,30.488029,0.31464759,517.30072,-9.2051306
213.038,6.4604106,9.3149309,0.0,0,0.19654539,0.0,0.96913826,31.174725,0.27673826,517.85199,-9.2049675
213.0424,6.5287237,9.3158293,0.0,0,0.17165019,0.0,0.96968013,31.517128,0.24635734,518.4032,-9.2051497
213.0468,6.542738,9.3232784,0.0,0,0.14675498,0.0,0.97072887,31.552826,0.21764387,518.7182,-9.2043095
213.0512,6.5036569,9.3225899,0.0,0,0.12185977,0.0,0.97076058,31.386997,0.19439414,519.0332,-9.2054758
213.0556,6.4532833,9.3249531,0.0,0,0.096964575,0.0,0.97092569,31.083824,0.16662975,519.49127,-9.2057343
213.06,6.3906441,9.3265619,0.0,0,0.072069377,0.0,0.97164261,30.801949,0.14134985,520.00299,-9.2041874
213.0644,6.3412113,9.3302679,0.0,0,0.047174171,0.0,0.97194004,30.570971,0.12029174,520.63989,-9.204587
213.0688,6.2804093,9.3281736,0.0,0,0.022278972,0.0,0.97191584,30.267622,0.1028589,521.42712,-9.2057619
213.0732,6.2125545,9.3341122,0.0,0,-0.002552415,0.0,0.9727298,29.915373,0.077939011,522.19757,-9.2043056
213.0776,6.1541615,9.3329201,0.0,0,-0.02684042,0.0,0.97261119,29.635132,0.062065806,522.89288,-9.205121
213.082,6.1117091,9.3361616,0.0,0,-0.051128417,0.0,0.97300494,29.397785,0.046038438,523.58813,-9.2036724
213.0864,6.0527134,9.3366327,0.0,0,-0.075416416,0.0,0.97341919,29.101332,0.033501934,524.24768,-9.2043352
213.0908,5.9789786,9.3407822,0.0,0,-0.099704415,0.0,0.97380006,28.772844,0.014568442,524.90369,-9.2048693
213.0952,5.909462,9.3388567,0.0,0,0.31743813,500.0,0.97365606,28.413845,0.0041351677,525.58466,-9.2043533
213.0996,5.5295982,9.3422146,0.0,0,1.1142951,500.0,0.97398788,26.647299,0.0096333707,526.27997,-9.2045021
213.104,2.7014256,9.3280573,0.0,0,1.9111534,500.0,0.97183263,13.166869,0.17797287,526.94659,-9.2067032
213.1084,-0.059212081,9.295783,0.0,0,2.7080107,500.0,0.96614623,-0.31881556,0.52410865,527.56317,-9.2108603
213.1128,0.067239426,9.2945786,0.0,0,3.5048685,500.0,0.96609831,0.1690017,1.6825391,528.16779,-9.2097998
213.1172,-0.14939171,9.301343,0.0,0,4.3017259,500.0,0.96680903,-0.59663397,2.8956513,528.6532,-9.2100964
213.1216,0.031321242,9.2954197,0.0,0,5.0985837,500.0,0.96632475,0.18502612,3.715688,529.13861,-9.2094545
213.126,-0.022734106,9.2994461,0.0,0,5.8954411,500.0,0.96648103,-0.089052722,4.4716072,529.51666,-9.2070837
213.1304,-0.018293589,9.2923708,0.0,0,6.6922989,500.0,0.96568036,-0.078775235,5.2441311,529.87085,-9.2089138
213.1348,0.10284711,9.2984962,0.0,0,7.4891562,500.0,0.96630412,0.57818347,6.0512581,530.19647,-9.2064695
213.1392,-0.059988339,9.2952948,0.0,0,8.2860146,500.0,0.96604186,-0.32959634,6.889154,530.49817,-9.2054529
213.1436,0.031136831,9.2979794,0.0,0,9.0828724,500.0,0.96608543,0.18971856,7.7182803,530.78918,-9.2078066
213.148,-0.0086739818,9.2927332,0.0,0,9.8797302,500.0,0.96573538,-0.10954559,8.5377817,531.05157,-9.2072954
213.1524,0.078853875,9.2988367,0.0,0,10.676588,500.0,0.96612811,0.36981174,9.3659201,531.31396,-9.2069187
213.1568,-0.11058837,9.2908278,0.0,0,11.473445,500.0,0.96537584,-0.49277362,10.174297,531.62885,-9.2068567
213.1612,0.0090379501,9.2942591,0.0,0,12.270303,500.0,0.96569788,0.062495489,10.970948,531.94366,-9.2055702
213.1656,-0.035138637,9.2926016,0.0,0,13.067161,500.0,0.96559179,-0.17828676,11.740568,532.23944,-9.2059708
213.17,0.035580594,9.2970448,0.0,0,13.864018,500.0,0.96587634,0.057482701,12.509382,532.52808,-9.2051735
213.1744,-0.0025894332,9.2911282,0.0,0,14.660876,500.0,0.96538383,0.028999573,13.32388,532.78687,-9.2060928
213.1788,0.020110626,9.2965727,0.0,0,15.457734,500.0,0.96593589,0.030138634,14.130796,533.00989,-9.2043695
213.1832,0.034285534,9.2913857,0.0,0,16.254593,500.0,0.96536744,0.17144193,14.937804,533.22357,-9.2044106
213.1876,-0.077669226,9.2976809,0.0,0,17.051451,500.0,0.96606392,-0.39873114,15.732389,533.3952,-9.2069378
213.192,0.082433552,9.2911558,0.0,0,17.848307,500.0,0.96540147,0.43688232,16.535576,533.56683,-9.2037497
213.1964,-0.14486124,9.2959843,0.0,0,18.0,500.0,0.96593541,-0.68640745,17.3272,533.76715,-9.2040567
213.2008,0.036848299,9.2920389,0.0,0,18.0,500.0,0.96560037,0.22320525,18.020372,533.97705,-9.2067432
213.2052,0.024296956,9.3017559,0.0,0,18.0,500.0,0.96672153,0.11112504,18.437313,534.16193,-9.2121878
213.2096,0.052640039,9.3051424,0.0,0,18.0,500.0,0.96793228,0.1709843,18.443913,534.31934,-9.2224197
213.214,0.22836535,9.3299704,0.0,0,18.0,500.0,0.97176665,1.0401978,18.222046,534.46338,-9.2412767
213.2184,1.0058944,9.3413191,0.0,0,18.0,500.0,0.97432524,4.8663816,18.0672,534.55524,-9.2718534
213.2228,0.90646207,9.3489389,0.0,0,18.0,500.0,0.97515136,4.4298844,18.059568,534.64703,-9.309803
213.2272,0.88886529,9.3428144,0.0,0,18.0,500.0,0.97458059,4.2500658,18.091091,534.81226,-9.3461485
213.2316,0.97077888,9.3473701,0.0,0,18.0,500.0,0.97489959,4.6410527,18.131393,534.98279,-9.3816872
213.236,1.0010728,9.3434,0.0,0,18.0,500.0,0.97457701,4.8083887,18.145571,535.12744,-9.4173508
213.2404,0.94853401,9.350687,0.0,0,18.0,500.0,0.97525668,4.6061573,18.148535,535.25867,-9.4500313
213.2448,0.8922236,9.3406906,0.0,0,18.0,500.0,0.97423989,4.3256063,18.143702,535.39496,-9.4816456
213.2492,0.97372359,9.3481464,0.0,0,18.0,500.0,0.97495526,4.6004519,18.133436,535.53931,-9.5147753
213.2536,1.0198956,9.3437204,0.0,0,18.0,500.0,0.97455692,4.8907843,18.132484,535.67914,-9.54877
213.258,0.97921383,9.3521509,0.0,0,18.0,500.0,0.97563857,4.6955152,18.128557,535.78412,-9.5821705
213.2624,0.91869628,9.3440838,0.0,0,18.0,500.0,0.97466439,4.4310293,18.119509,535.8891,-9.61446
213.2668,0.9370808,9.3504057,0.0,0,18.0,500.0,0.97536117,4.4995866,18.117592,535.98309,-9.6491375
213.2712,1.0229347,9.3447819,0.0,0,18.0,500.0,0.97487515,4.8911948,18.11364,536.07495,-9.683136
213.2756,0.99069774,9.3481197,0.0,0,18.0,500.0,0.97501194,4.8019428,18.114254,536.18915,-9.7155237
213.28,0.92049211,9.34484,0.0,0,18.0,500.0,0.97494096,4.4589825,18.112555,536.32037,-9.7495832
213.2844,0.91316539,9.3478193,0.0,0,18.0,500.0,0.97486925,4.3912625,18.108383,536.43225,-9.7818251
213.2888,1.0200531,9.3417397,0.0,0,18.0,500.0,0.97434914,4.8386812,18.110147,536.49786,-9.816164
213.2932,1.0152055,9.3527327,0.0,0,18.0,500.0,0.97563589,4.8776603,18.102442,536.56256,-9.849
213.2976,0.92650068,9.3433104,0.0,0,18.0,500.0,0.97453326,4.4810266,18.102514,536.58881,-9.8832073
213.302,0.90350008,9.348032,0.0,0,18.0,500.0,0.97498727,4.3185339,18.104496,536.61505,-9.9148836
213.3064,0.99459755,9.3446064,0.0,0,18.0,500.0,0.97478491,4.7116451,18.09996,536.66095,-9.9482899
213.3108,1.0326041,9.347868,0.0,0,18.0,500.0,0.97484475,4.9385099,18.099089,536.7135,-9.9827499
213.3152,0.95386112,9.3434591,0.0,0,18.0,500.0,0.97450989,4.6194186,18.096376,536.77856,-10.015594
213.3196,0.91475558,9.3490953,0.0,0,18.0,500.0,0.97511548,4.4097428,18.095379,536.8573,-10.049343
213.324,0.98617321,9.3456697,0.0,0,18.0,500.0,0.97493118,4.7449493,18.096329,536.93066,-10.082859
213.3284,1.0520098,9.3499804,0.0,0,18.0,500.0,0.97543764,5.0530682,18.091908,536.98315,-10.115074
213.3328,0.97522587,9.3461971,0.0,0,18.0,500.0,0.97485131,4.7038703,18.094927,537.03558,-10.150362
213.3372,0.92684603,9.3497334,0.0,0,18.0,500.0,0.9751634,4.4687228,18.092501,537.11255,-10.183856
213.3416,0.96409076,9.3449793,0.0,0,18.0,500.0,0.97481495,4.6027422,18.086588,537.19128,-10.215626
213.346,1.0532705,9.3468399,0.0,0,18.0,500.0,0.97473639,5.0290122,18.087,537.28735,-10.248936
213.3504,1.0111994,9.3456373,0.0,0,18.0,500.0,0.97485173,4.8657556,18.084776,537.39233,-10.283646
213.3548,0.93930876,9.3501015,0.0,0,18.0,500.0,0.97517639,4.5643005,18.079163,537.47699,-10.316852
213.3592,0.94989008,9.3442326,0.0,0,18.0,500.0,0.97469574,4.5151815,18.082289,537.52954,-10.350889
213.3636,1.0336311,9.351265,0.0,0,18.0,500.0,0.97555453,4.9513836,18.081837,537.57904,-10.383056
213.368,1.0305188,9.3437433,0.0,0,18.0,500.0,0.97458673,4.9824896,18.083387,537.60529,-10.417845
213.3724,0.94582325,9.350626,0.0,0,18.0,500.0,0.9753471,4.5890808,18.077845,537.63153,-10.450038
213.3768,0.94567537,9.3447256,0.0,0,18.0,500.0,0.97467494,4.4656272,18.081564,537.65771,-10.48285
213.3812,1.0312406,9.3479958,0.0,0,18.0,500.0,0.97490698,4.9268894,18.077959,537.68396,-10.517138
213.3856,1.0644721,9.3449173,0.0,0,18.0,500.0,0.97468108,5.1001511,18.077831,537.70276,-10.549581
213.39,0.96927989,9.3483715,0.0,0,18.0,500.0,0.97501993,4.6632633,18.073856,537.71588,-10.58348
213.3944,0.94730395,9.3417273,0.0,0,18.0,500.0,0.97418696,4.5320568,18.0741,537.729,-10.615547
213.3988,1.0144045,9.3480492,0.0,0,18.0,500.0,0.97490191,4.864397,18.068693,537.74213,-10.649872
213.4032,1.0704838,9.3445072,0.0,0,18.0,500.0,0.97470582,5.1018858,18.07061,537.75647,-10.682817
213.4076,1.0099472,9.3509054,0.0,0,18.0,500.0,0.97555995,4.8733125,18.06988,537.82208,-10.71781
213.412,0.94191217,9.3431101,0.0,0,18.0,500.0,0.9743728,4.5307536,18.066059,537.8877,-10.751042
213.4164,1.0269849,9.3521643,0.0,0,18.0,500.0,0.97545421,4.865252,18.064499,537.93365,-10.783606
213.4208,1.0766851,9.3444309,0.0,0,18.0,500.0,0.97462481,5.1607604,18.065626,537.97302,-10.815701
213.4252,1.0271031,9.3514795,0.0,0,18.0,500.0,0.97552407,4.9485621,18.064476,537.99359,-10.849917
213.4296,0.95304614,9.3439579,0.0,0,18.0,500.0,0.97471154,4.589036,18.060909,537.99359,-10.884359
213.434,0.98675305,9.34867,0.0,0,18.0,500.0,0.97516662,4.7067394,18.061411,538.00433,-10.916836
213.4384,1.0724139,9.3453541,0.0,0,18.0,500.0,0.97468954,5.1057048,18.060675,538.05682,-10.949869
213.4428,1.0412269,9.3491926,0.0,0,18.0,500.0,0.97497523,5.0342236,18.060934,538.10931,-10.982512
213.4472,0.95903736,9.3428831,0.0,0,18.0,500.0,0.97439027,4.6450424,18.062998,538.1618,-11.018466
213.4516,0.9640699,9.3499784,0.0,0,18.0,500.0,0.97528011,4.6417661,18.059906,538.21429,-11.051281
213.456,1.0689747,9.3452511,0.0,0,18.0,500.0,0.97466475,5.1252418,18.058786,538.23218,-11.082298
213.4604,1.0676306,9.3480892,0.0,0,18.0,500.0,0.97497255,5.1434183,18.059361,538.23218,-11.118642
213.4648,0.99429339,9.3459358,0.0,0,18.0,500.0,0.97488552,4.8211436,18.056591,538.22205,-11.150496
213.4692,0.94974506,9.3496885,0.0,0,18.0,500.0,0.9750421,4.5525208,18.054537,538.19574,-11.184085
213.4736,1.0517718,9.3447952,0.0,0,18.0,500.0,0.97467524,5.0509801,18.05773,538.16803,-11.219227
213.478,1.0785836,9.3479633,0.0,0,18.0,500.0,0.9749313,5.2037201,18.052696,538.12866,-11.250217
213.4824,1.007766,9.3439617,0.0,0,18.0,500.0,0.97471559,4.8577094,18.055185,538.08929,-11.285303
213.4868,0.95812976,9.3487873,0.0,0,18.0,500.0,0.9751119,4.5870981,18.04804,538.1051,-11.318154
213.4912,1.0239264,9.3423767,0.0,0,18.0,500.0,0.97440046,4.877799,18.052654,538.13135,-11.351362
214.8927,0.87403995,9.3595743,0.0,0,18.0,4.0912098e-17,0.97800797,4.1808953,18.000362,510.83813,-11.480167
217.0927,0.87355632,9.3809404,0.0,0,18.0,1.4012985e-45,0.9818508,4.1616216,18.000193,487.11185,-11.480687
219.2927,0.86934078,9.3997679,0.0,0,18.0,1.4012985e-45,0.98527521,4.1375651,17.999935,464.69016,-11.481111
221.4927,0.8549273,9.4173384,0.0,0,18.0,1.4012985e-45,0.98845088,4.0533161,17.999687,443.21216,-11.479992
223.6927,0.86195177,9.4324713,0.0,0,18.0,1.4012985e-45,0.99112427,4.0756679,18.000835,422.44543,-11.480961
225.8927,0.87206286,9.4468393,0.0,0,18.0,1.4012985e-45,0.993716,4.100677,17.999578,402.1879,-11.481134
228.0927,0.87321329,9.4600554,0.0,0,18.0,1.4012985e-45,0.99603641,4.098022,18.000229,382.61823,-11.481071
230.2927,0.85973454,9.4730024,0.0,0,18.0,1.4012985e-45,0.99835616,4.034049,18.000015,364.11734,-11.480434
232.4927,0.87401158,9.4852238,0.0,0,18.0,1.4012985e-45,1.0005895,4.0979829,18.000994,346.34753,-11.480727
234.6927,0.87716901,9.4971523,0.0,0,18.0,1.4012985e-45,1.0028061,4.0939312,17.999878,329.55399,-11.481112
236.8927,0.89628482,9.5084209,0.0,0,18.0,1.4012985e-45,1.0048867,4.1691833,17.999926,313.2659,-11.481466
239.0927,0.89405179,9.5190001,0.0,0,18.0,1.4012985e-45,1.006852,4.1546488,17.999813,297.98441,-11.480616
241.2927,0.8996498,9.5292435,0.0,0,18.0,1.4012985e-45,1.0087214,4.1900249,18.000111,283.51871,-11.480584
243.4927,0.90202135,9.5382891,0.0,0,18.0,1.4012985e-45,1.0103759,4.1899309,17.999763,269.54395,-11.480542
245.6927,0.91998589,9.5478611,0.0,0,18.0,1.4012985e-45,1.0121102,4.2545862,18.000595,256.31381,-11.481141
247.8927,0.92925197,9.5570831,0.0,0,18.0,1.4012985e-45,1.0138198,4.285368,18.000113,243.85742,-11.481316
250.0927,0.93156612,9.5659742,0.0,0,18.0,1.4012985e-45,1.0154063,4.2889175,17.999559,231.79245,-11.480801
252.2927,0.93608135,9.5742903,0.0,0,18.0,1.4012985e-45,1.0169306,4.3200698,17.998186,220.24603,-11.480478
254.4927,0.93887138,9.5822191,0.0,0,18.0,1.4012985e-45,1.0183809,4.3239541,18.000055,209.49455,-11.48004
256.6927,0.93400526,9.5899315,0.0,0,18.0,1.4012985e-45,1.0198146,4.2810521,17.999865,199.47093,-11.479407
258.8927,0.96500665,9.5964518,0.0,0,18.0,1.4012985e-45,1.0210297,4.4167471,17.998966,189.84479,-11.480779
261.0927,0.9797315,9.6032591,0.0,0,18.0,1.4012985e-45,1.0222883,4.4890256,17.999748,181.037,-11.481129
263.2927,0.96535718,9.6095333,0.0,0,18.0,1.4012985e-45,1.0234717,4.4252272,18.000156,172.46182,-11.481226
265.4927,0.95976132,9.6157846,0.0,0,18.0,1.4012985e-45,1.0246191,4.3945594,17.999931,164.66696,-11.481104
267.6927,0.95388424,9.6219196,0.0,0,18.0,1.4012985e-45,1.0257897,4.3495407,18.000092,157.20049,-11.481125
269.8927,0.9702456,9.6273909,0.0,0,18.0,1.4012985e-45,1.0268582,4.4112444,17.999819,150.22427,-11.480518
272.0927,0.9811933,9.6329737,0.0,0,18.0,1.4012985e-45,1.0279078,4.4664302,17.999846,143.65598,-11.480338
273.4927,0.97149205,9.6358643,0.0,0,18.0,1.4012985e-45,1.0283848,4.4221959,18.00074,139.67249,-11.481004