File: examples/dan-msc-case-studies/CS3/data/01 raw data/baron_test_014.csv
Time(sec),Force(kN),Jaw(mm),PowAngle(deg),Power(W),Pram,PTemp,Strain,Stress(MPa),Stroke(mm),TC1(C),wedge(mm)
0.0,1.2553128,0.44524246,0.0,0,11.076097,4.9676541e-10,0.030114813,15.503716,11.076656,24.681759,-9.11306
1.2,1.1815298,-0.0015542135,0.0,0,11.076097,3.5162148,-0.0001196508,15.04494,11.075186,24.637962,-9.482172
2.4,1.1546052,-0.0020235709,0.0,0,11.076097,7.1162133,-0.00015802958,14.694103,11.076263,24.536131,-9.4796333
3.6,1.1333822,-0.0019454533,0.0,0,11.076097,10.716211,-0.0001217867,14.41453,11.076958,24.428469,-9.4784794
4.8,1.1118742,-0.002024025,0.0,0,11.076097,14.316213,-0.00012886073,14.154968,11.074487,24.386133,-9.4761095
6.0,1.1006587,-0.0022213319,0.0,0,11.076097,17.916216,-0.00014895029,14.018155,11.076023,24.381311,-9.4745445
7.2,1.0816478,-0.0021861878,0.0,0,11.076097,21.516214,-0.00011888958,13.761832,11.076371,24.332376,-9.4720697
8.4,1.0769178,-0.0024096305,0.0,0,11.076097,25.116211,-0.00015356521,13.700514,11.075965,24.328436,-9.4702406
9.6,1.0769497,-0.0013881644,24.650543,0,11.076097,28.716211,-0.00010421373,13.716625,11.075675,24.287172,-9.4678793
10.8,1.0689435,-0.0013963023,37.331482,0,11.076097,32.316212,-0.00012213517,13.60827,11.075191,24.485067,-9.4663773
12.0,1.0954041,-0.0027158663,46.285389,0,11.076097,35.916222,-0.00019158158,13.930945,11.075506,25.109459,-9.4647694
13.2,1.098525,-0.0056683631,52.253159,0,11.076097,39.51622,-0.00036862717,13.980421,11.076167,26.923319,-9.4627934
14.4,1.1217759,-0.010155634,56.412571,0,11.076097,43.116219,-0.00067341287,14.296193,11.075776,30.086542,-9.4606895
15.6,1.1509271,-0.01598403,59.314362,0,11.076097,46.716221,-0.0010644832,14.652597,11.076424,34.431442,-9.4592848
16.8,1.1708443,-0.02217138,60.903412,0,11.076097,50.316223,-0.0014530354,14.926514,11.075981,39.92981,-9.4567509
18.0,1.1877699,-0.028552631,61.468498,0,11.076097,53.916225,-0.0018892569,15.135812,11.075607,46.667152,-9.4547243
19.2,1.2084285,-0.03569489,60.805199,0,11.076097,57.51622,-0.0023868484,15.428054,11.076632,53.982456,-9.4525356
20.4,1.2124319,-0.042081814,59.259773,0,11.076097,61.116219,-0.0028234147,15.476027,11.075891,61.663361,-9.4505587
21.6,1.2243446,-0.046741091,56.517353,0,11.076097,64.716209,-0.0031316199,15.625757,11.075653,69.100143,-9.448781
22.8,1.2217003,-0.051314741,52.689236,0,11.076097,68.3162,-0.003404648,15.601567,11.076896,76.022766,-9.4469948
24.0,1.2166345,-0.054357495,47.570866,0,11.076097,71.916214,-0.0036136508,15.545253,11.075197,81.952744,-9.4448395
25.2,1.1983693,-0.056321278,41.279274,0,11.076097,75.51619,-0.0037473172,15.312679,11.075963,86.473419,-9.4432182
26.4,1.1713498,-0.056479499,34.666466,0,11.076097,79.116219,-0.0037310687,14.963427,11.075894,89.542114,-9.4408369
27.6,1.154864,-0.056437753,29.79571,0,11.076097,82.716209,-0.0037345423,14.776728,11.075986,91.19735,-9.4392786
28.8,1.1303465,-0.055775292,29.668907,0,11.076097,86.316223,-0.0037325781,14.444418,11.075282,91.589272,-9.4373989
30.0,1.1141974,-0.055310737,34.497112,0,11.076097,89.916214,-0.0036977087,14.233577,11.076203,91.246254,-9.4354477
31.2,1.1037661,-0.054598764,41.144009,0,11.076097,93.516228,-0.0036589461,14.103698,11.075698,90.551079,-9.4333858
32.4,1.0991234,-0.055317383,47.820362,0,11.076097,97.116211,-0.0036769791,14.052525,11.076656,90.225121,-9.4312611
33.6,1.1140738,-0.05765523,53.266216,0,11.076097,100.71622,-0.0038231555,14.250398,11.074737,90.64164,-9.4290667
34.8,1.1353221,-0.06123329,57.73526,0,11.076097,104.31622,-0.0040739733,14.527095,11.07593,92.292244,-9.4267874
36.0,1.1614556,-0.066074222,60.917732,0,11.076097,107.91623,-0.0043745637,14.86399,11.075507,95.252937,-9.4249477
37.2,1.1906959,-0.072459348,63.12952,0,11.076097,111.5162,-0.0048068021,15.254952,11.075766,99.58606,-9.4232416
38.4,1.2179369,-0.079717495,64.357483,0,11.076097,115.11623,-0.0052973991,15.59199,11.075813,105.06821,-9.4211216
39.6,1.2306814,-0.085801281,64.785172,0,11.076097,118.71622,-0.0057185395,15.768794,11.077171,111.62311,-9.4193764
40.8,1.2312311,-0.093369171,64.359741,0,11.076097,122.31623,-0.0062222932,15.790076,11.075289,118.93881,-9.4173002
42.0,1.2310265,-0.10012775,63.026699,0,11.076097,125.9162,-0.0066577895,15.775267,11.075781,126.45437,-9.4157763
43.2,1.2373753,-0.10657454,60.988037,0,11.076097,129.51631,-0.0070600715,15.892635,11.075675,133.74843,-9.4138994
44.4,1.2284465,-0.11048952,57.937981,0,11.076097,133.11623,-0.0073382948,15.774991,11.076334,140.59268,-9.4122763
45.6,1.2243186,-0.11462178,54.342026,0,11.076097,136.7162,-0.0075963349,15.711155,11.076143,146.42044,-9.4104176
46.8,1.2104899,-0.11703823,49.922081,0,11.076097,140.31621,-0.0077542267,15.533027,11.076143,151.34587,-9.4082079
48.0,1.1848232,-0.11783927,45.290237,0,11.076097,143.91618,-0.0078271851,15.221986,11.076924,154.83112,-9.4061298
49.2,1.1683772,-0.11765184,41.803589,0,11.076097,147.5162,-0.007824447,15.009693,11.075891,156.96817,-9.4042654
50.4,1.1469488,-0.11730354,40.568722,0,11.076097,151.1162,-0.0078008068,14.732856,11.075036,157.68248,-9.4022865
51.6,1.1246753,-0.11718391,42.378101,0,11.076097,154.71619,-0.0077825477,14.443787,11.075896,157.54469,-9.4003248
52.8,1.1137019,-0.11705193,46.356995,0,11.076097,158.31619,-0.0077596754,14.292768,11.075374,156.96756,-9.3983994
54.0,1.1128825,-0.11749667,51.146416,0,11.076097,161.9162,-0.0078127356,14.278238,11.075925,156.47586,-9.3964272
55.2,1.1128111,-0.11897095,55.716835,0,11.076097,165.5162,-0.0078862617,14.277218,11.074425,156.67212,-9.3938427
56.4,1.1408433,-0.12310456,59.572117,0,11.076097,169.1162,-0.0081518665,14.655476,11.076671,157.7986,-9.3920355
57.6,1.1669192,-0.12768686,62.678967,0,11.076097,172.7162,-0.0084645394,14.998477,11.075442,160.25711,-9.3897686
58.8,1.2047421,-0.13454714,64.869293,0,11.076097,176.31621,-0.0089417361,15.485586,11.075863,164.12775,-9.3884678
60.0,1.2288653,-0.14029998,66.192284,0,11.076097,179.91621,-0.0093345605,15.808728,11.075686,169.33997,-9.3865585
61.2,1.2339556,-0.14825672,66.884598,0,11.076097,183.5162,-0.0098469602,15.869245,11.07621,175.54681,-9.3843889
62.4,1.2341859,-0.15613179,66.710426,0,11.076097,187.11621,-0.010351091,15.880112,11.076336,182.50446,-9.3823824
63.6,1.2409778,-0.16362105,65.88353,0,11.076097,190.7162,-0.01084647,15.991496,11.076032,189.80104,-9.3808384
64.8,1.2374293,-0.1688989,64.38208,0,11.076097,194.31622,-0.011197656,15.959345,11.075423,197.03188,-9.3789759
66.0,1.2327603,-0.1740014,62.077412,0,11.076097,197.9162,-0.011511842,15.875893,11.076127,204.17079,-9.3769379
67.2,1.2167758,-0.17900614,59.133736,0,11.076097,201.5162,-0.011845501,15.68611,11.075778,210.55219,-9.37502
68.4,1.2116473,-0.18150203,55.848454,0,11.076097,205.11621,-0.012025337,15.626462,11.075738,215.67001,-9.3730898
69.6,1.193763,-0.18340701,52.31044,0,11.076097,208.71622,-0.012165902,15.40471,11.076063,219.59348,-9.3712673
70.8,1.1839105,-0.18380144,49.486847,0,11.076097,212.31621,-0.012193184,15.25768,11.075098,222.01817,-9.3692455
72.0,1.1627097,-0.18415052,47.955326,0,11.076097,215.91623,-0.012211044,14.980408,11.076996,223.29097,-9.3676071
73.2,1.1397824,-0.18332483,48.383751,0,11.076097,219.5162,-0.0121371,14.709738,11.076206,223.60269,-9.3655376
74.4,1.1272756,-0.18325621,50.740433,0,11.076097,223.11621,-0.01213422,14.53564,11.076586,223.38248,-9.3635807
75.6,1.1235696,-0.18411183,53.927895,0,11.076097,226.7162,-0.012197175,14.483095,11.07563,223.29271,-9.3615894
76.8,1.1297452,-0.18621798,57.283577,0,11.076097,230.31622,-0.012321551,14.567723,11.076812,223.59766,-9.3598337
78.0,1.1535203,-0.19027306,60.522827,0,11.076097,233.9162,-0.012579447,14.877434,11.07515,224.69215,-9.3576241
79.2,1.1743731,-0.19425486,63.042717,0,11.076097,237.51622,-0.012878655,15.152538,11.075026,227.17383,-9.3556566
80.4,1.2052128,-0.19882779,64.97139,0,11.076097,241.1162,-0.013185294,15.543381,11.075786,230.72366,-9.3537121
81.6,1.2299277,-0.20583934,66.190071,0,11.076097,244.71622,-0.013644556,15.878751,11.076735,235.66713,-9.3514729
82.8,1.2382231,-0.21291573,66.708977,0,11.076097,248.31621,-0.014099088,15.97989,11.075764,241.40561,-9.3494263
84.0,1.2397155,-0.22021046,66.708992,0,11.076097,251.91621,-0.01456703,16.01964,11.075999,247.79037,-9.3473577
85.2,1.2421867,-0.22791624,66.125351,0,11.076097,255.51619,-0.015073147,16.071766,11.074758,254.32224,-9.3453932
86.4,1.2390863,-0.23326872,64.938187,0,11.076097,259.11642,-0.015430765,16.022635,11.075904,261.02063,-9.3435383
87.6,1.2409664,-0.23775814,63.291916,0,11.076097,262.71619,-0.015709894,16.054724,11.074066,267.3577,-9.3412714
88.8,1.2330902,-0.24170169,61.248192,0,11.076097,266.31619,-0.015973056,15.952037,11.074678,272.95453,-9.3395929
90.0,1.2182169,-0.24501382,59.036713,0,11.076097,269.91617,-0.016209299,15.753763,11.07644,277.83743,-9.3377123
91.2,1.2171221,-0.24726206,56.722656,0,11.076097,273.5162,-0.016372716,15.75247,11.076001,281.7926,-9.3362484
92.4,1.192861,-0.24898648,54.935139,0,11.076097,277.11618,-0.016476797,15.436446,11.077469,284.74469,-9.334096
93.6,1.1857511,-0.24976403,53.905949,0,11.076097,280.71619,-0.016518731,15.340788,11.075772,286.76544,-9.3318558
94.8,1.1714536,-0.25039726,53.975372,0,11.076097,284.31619,-0.016533937,15.152896,11.075542,287.96179,-9.3294697
96.0,1.1659181,-0.25185847,54.931446,0,11.076097,287.9162,-0.01664203,15.081851,11.076193,288.80069,-9.3276529
97.2,1.1635114,-0.25351864,56.708447,0,11.076097,291.5162,-0.016759589,15.067533,11.075555,289.73602,-9.3259544
98.4,1.1801665,-0.25638074,58.806175,0,11.076097,295.11621,-0.016932145,15.273066,11.075292,290.90738,-9.3241177
99.6,1.1921289,-0.25998256,60.784927,0,11.076097,298.71622,-0.017161967,15.450648,11.075473,292.72946,-9.3225355
100.8,1.2123152,-0.26397344,62.57505,0,11.076097,302.31619,-0.017442618,15.716385,11.075676,295.38565,-9.3205671
102.0,1.2330897,-0.26796633,63.959625,0,11.076097,305.9162,-0.017701322,15.978209,11.076177,298.92737,-9.3186665
103.2,1.245343,-0.27211916,64.742363,0,11.076097,309.5162,-0.017997259,16.134054,11.076722,303.51068,-9.316884
104.4,1.2364478,-0.27804729,65.115959,0,11.076097,313.11621,-0.018376874,16.046825,11.076216,308.647,-9.314189
105.6,1.2414005,-0.28316149,64.929787,0,11.076097,316.71619,-0.018699929,16.100073,11.07581,314.30438,-9.3123045
106.8,1.2402833,-0.28823268,64.358269,0,11.076097,320.31622,-0.019016119,16.093956,11.075291,320.19354,-9.3102837
108.0,1.2416607,-0.29249999,63.37167,0,11.076097,323.9162,-0.019305561,16.117683,11.077287,325.79425,-9.3084297
109.2,1.2412007,-0.29630968,62.126369,0,11.076097,327.51624,-0.019555235,16.106337,11.07583,331.07346,-9.3066101
110.4,1.2395182,-0.29971558,60.795673,0,11.076097,331.11621,-0.019772006,16.102316,11.075984,335.74579,-9.3047695
111.6,1.235052,-0.30376875,59.502319,0,11.076097,334.71622,-0.020029636,16.045259,11.075878,339.81827,-9.3028002
112.8,1.2225518,-0.30431348,58.513691,0,11.076097,338.31622,-0.02008914,15.862075,11.076177,343.05679,-9.3011627
114.0,1.2085953,-0.30622998,57.858341,0,11.076097,341.91623,-0.020222552,15.697303,11.075329,345.6806,-9.2990732
115.2,1.1983842,-0.30780119,57.881245,0,11.076097,345.5162,-0.020327335,15.564069,11.075677,347.81812,-9.2970963
116.4,1.2030455,-0.30894151,58.483067,0,11.076097,349.11621,-0.020401984,15.642533,11.074958,349.6817,-9.2947664
117.6,1.2075819,-0.31159815,59.381618,0,11.076097,352.71622,-0.020543868,15.684187,11.075859,351.55157,-9.2925377
118.8,1.2031335,-0.31466416,60.551403,0,11.076097,356.31622,-0.020750454,15.627068,11.076212,353.73212,-9.2902832
120.0,1.2310994,-0.31664678,61.685467,0,11.076097,359.9162,-0.020891042,15.994989,11.076418,356.2912,-9.2884817
121.2,1.2449483,-0.32198235,60.795883,0,11.076097,359.99924,-0.021230832,16.186453,11.076603,359.42599,-9.2885571
122.4,1.2439687,-0.32296905,59.11348,0,11.076097,359.99924,-0.02128518,16.186726,11.077218,362.42648,-9.2884979
123.6,1.2356457,-0.32359725,56.744259,0,11.076097,359.99924,-0.021343408,16.064922,11.076442,364.98804,-9.2885122
124.8,1.2232562,-0.32500255,54.021591,0,11.076097,359.99924,-0.02145154,15.911903,11.075445,366.7233,-9.2883577
126.0,1.2161491,-0.32408112,51.254196,0,11.076097,359.99924,-0.021395935,15.814819,11.07642,367.33163,-9.288537
127.2,1.1859722,-0.32321593,49.22987,0,11.076097,359.99924,-0.021330189,15.422703,11.075883,366.85263,-9.2887363
128.4,1.1714777,-0.32141045,47.955326,0,11.076097,359.99924,-0.021206763,15.220813,11.076077,365.40005,-9.2890434
129.6,1.1564305,-0.31932354,47.955147,0,11.076097,359.99924,-0.021058116,15.036987,11.076279,363.2731,-9.288825
130.8,1.1410723,-0.3170228,49.229008,0,11.076097,359.99924,-0.020903673,14.828364,11.076059,360.85938,-9.2885962
132.0,1.1305104,-0.31582776,51.191113,0,11.076097,359.99924,-0.020834526,14.688805,11.07563,358.43106,-9.2883511
133.2,1.1294272,-0.31539026,53.424961,0,11.076097,359.99924,-0.020791432,14.680542,11.075572,356.51907,-9.2880325
134.4,1.1350646,-0.31456357,55.487583,0,11.076097,359.99924,-0.020731557,14.744678,11.076212,355.28891,-9.288249
135.6,1.1511769,-0.31628722,56.980404,0,11.076097,359.99924,-0.020857379,14.971932,11.075727,355.02765,-9.288126
136.8,1.1719133,-0.31674701,58.072414,0,11.076097,359.99924,-0.020904604,15.217596,11.075984,355.31046,-9.2880287
138.0,1.1823381,-0.31918612,58.59008,0,11.076097,359.99924,-0.021070629,15.371547,11.074351,356.21216,-9.2877283
139.2,1.1997813,-0.32076219,58.590099,0,11.076097,359.99924,-0.021171866,15.593816,11.07614,357.64417,-9.2880392
140.4,1.2136163,-0.32423869,58.265682,0,11.076097,359.99924,-0.02138767,15.788531,11.074823,359.19278,-9.2876892
141.6,1.223756,-0.3248316,57.262447,0,11.076097,359.99924,-0.021412706,15.911304,11.075302,360.85013,-9.2880373
142.8,1.2339799,-0.32595116,56.129745,0,11.076097,359.99924,-0.021499373,16.044975,11.075595,362.20685,-9.2879887
144.0,1.2289054,-0.32668883,54.667927,0,11.076097,359.99924,-0.021536639,15.97864,11.076966,363.24289,-9.2883101
145.2,1.219183,-0.32665554,53.317009,0,11.076097,359.99924,-0.021519637,15.854176,11.076057,363.73001,-9.2883425
146.4,1.204771,-0.32632652,52.162933,0,11.076097,359.99924,-0.02149798,15.656367,11.076252,363.69055,-9.2887573
147.6,1.1943558,-0.32619756,51.234802,0,11.076097,359.99924,-0.021507017,15.541422,11.0764,363.10117,-9.2887363
148.8,1.1888373,-0.32648739,51.196293,0,11.076097,359.99924,-0.021532893,15.459584,11.076744,362.07718,-9.2883987
150.0,1.1783155,-0.32469961,51.569801,0,11.076097,359.99924,-0.021435482,15.329106,11.076956,360.87631,-9.2885771
151.2,1.1715058,-0.32406989,52.283901,0,11.076097,359.99924,-0.021393193,15.233825,11.076015,359.68958,-9.2886419
152.4,1.1726457,-0.32404774,53.316422,0,11.076097,359.99924,-0.021375816,15.258739,11.077675,358.677,-9.2886353
153.6,1.0991209,-0.32400903,54.303619,0,11.076097,359.99924,-0.021361545,14.283631,11.075337,358.01807,-9.2883215
154.8,0.97172779,-0.32580572,55.239094,0,11.076097,359.99924,-0.021482827,12.643138,11.07489,357.61172,-9.2883272
156.0,0.88425326,-0.32693002,55.843506,0,11.076097,359.99924,-0.021554826,11.509354,11.076134,357.50565,-9.2880411
157.2,0.83193547,-0.32957798,56.423794,0,11.076097,359.99924,-0.021711037,10.832612,11.075805,357.92673,-9.2881451
158.4,0.80410641,-0.3306646,56.425777,0,11.076097,359.99924,-0.021785798,10.448722,11.07526,358.55533,-9.2877102
159.6,0.79170287,-0.3331165,56.327621,0,11.076097,359.99924,-0.021954305,10.285708,11.075266,359.33832,-9.2876844
160.8,0.77187413,-0.33294046,55.942699,0,11.076097,359.99924,-0.02196471,10.035881,11.076084,360.12097,-9.2874498
162.0,0.77621341,-0.33429405,55.301411,0,11.076097,359.99924,-0.022057097,10.096185,11.075744,360.87396,-9.2872734
163.2,0.77572435,-0.3341234,54.764454,0,11.076097,359.99924,-0.022040799,10.102178,11.075259,361.29214,-9.2874508
164.4,0.76182818,-0.33455449,54.290749,0,11.076097,359.99924,-0.02206267,9.9337902,11.076941,361.47601,-9.2875605
165.2848,0.75629127,0.050420407,53.97583,0,11.076099,2.5665329,0.0034511376,9.4833517,11.074089,361.46976,-9.2870121
165.2872,0.76710111,0.048229244,53.97583,0,11.076099,1.1095114e-16,0.0035297878,9.736105,11.073323,361.49872,-9.2878218
165.2896,0.73977453,0.047712617,50.965237,0,11.076099,4.7964155e-33,0.003249797,9.3628378,11.077975,361.51755,-9.2872267
165.292,0.7437526,0.048863012,38.062645,0,11.076099,0.0,0.0030600373,9.4645672,11.079268,361.50305,-9.2875519
165.2944,0.79128057,0.050971091,25.160057,0,11.076099,0.0,0.0033272526,10.021236,11.0736,361.48859,-9.2863436
165.2968,0.74708945,0.050684299,12.257471,0,11.076099,0.0,0.0035338281,9.4743862,11.076827,361.47409,-9.2876215
165.2992,0.75063348,0.048395552,0.0,0,11.076099,0.0,0.0034539176,9.5364475,11.075742,361.46286,-9.2875624
165.3016,0.74470395,0.048831731,0.0,0,11.076099,0.0,0.0033460255,9.3846006,11.07398,361.51358,-9.2866745
165.304,0.74285585,0.051579885,0.0,0,11.076099,0.0,0.0032551074,9.4515753,11.076993,361.56427,-9.2857523
165.3064,0.76827377,0.054276396,0.0,0,11.076099,0.0,0.0033703716,9.6771965,11.077063,361.61499,-9.2861004
165.3088,0.74994236,0.052444633,0.0,0,11.076099,0.0,0.0035815139,9.4777765,11.074415,361.66568,-9.2866573
165.3112,0.72839856,0.047160216,0.0,0,11.076099,0.0,0.0034019551,9.3324261,11.077418,361.66617,-9.2866964
165.3136,0.74382746,0.047274522,0.0,0,11.076099,0.0,0.0032298693,9.3669214,11.077636,361.65894,-9.287529
165.316,0.75022304,0.049066287,0.0,0,11.076099,0.0,0.0030517194,9.5064573,11.076686,361.6517,-9.2862949
165.3184,0.7443589,0.049297605,0.0,0,11.076099,0.0,0.0031825611,9.4769382,11.079064,361.64444,-9.2864704
165.3208,0.73111898,0.048347175,0.0,0,11.076099,0.0,0.0033164609,9.334219,11.079021,361.62234,-9.2878256
165.3232,0.72017503,0.046956588,0.0,0,11.076099,0.0,0.0034076294,9.0998936,11.076344,361.59338,-9.2877302
165.3256,0.72124636,0.050077029,0.0,0,11.076099,0.0,0.0033756488,9.1480656,11.078053,361.56439,-9.287096
165.328,0.74494976,0.054054812,0.0,0,11.076099,0.0,0.0033574372,9.4157858,11.077153,361.53543,-9.286624
165.3304,0.72664309,0.054796759,0.0,0,11.076099,0.0,0.003430025,9.3156052,11.077679,361.5137,-9.2869539
165.3328,0.71572483,0.051400259,0.0,0,11.076099,0.0,0.0035529037,9.1052103,11.078032,361.49921,-9.287919
165.3352,0.72507286,0.047309589,0.0,0,10.976469,0.0,0.0034359493,9.1803904,11.07809,361.48471,-9.2877617
165.3376,0.74032336,0.046966355,0.0,0,10.615495,0.0,0.0032085006,9.2969151,11.076283,361.47021,-9.2876234
165.34,0.73950708,0.049595032,0.0,0,10.254521,0.0,0.0031110833,9.426652,11.055336,361.46951,-9.2866497
165.3424,0.75202048,0.04946053,0.0,0,9.893548,0.0,0.0032132126,9.4878836,10.92456,361.49847,-9.2876759
165.3448,0.69924927,0.049823936,0.0,0,9.5325737,0.0,0.0033653148,8.8941336,10.641135,361.52747,-9.2874012
165.3472,0.73579562,0.046792854,0.0,0,9.1800261,0.0,0.0033455568,9.1927519,10.256409,361.55643,-9.2868986
165.3496,6.7229505,0.30918843,0.0,0,8.8288584,0.0,0.020063849,84.151077,9.8635693,361.47626,-9.2814722
165.352,8.386982,0.69896841,0.0,0,8.4910259,0.0,0.047362763,101.19714,9.4189634,360.68665,-9.2820787
165.3544,8.7589378,1.1223897,0.0,0,8.1570415,0.0,0.077043749,103.26768,8.9791365,359.897,-9.2806654
165.3568,9.1388035,1.525121,0.0,0,7.8342957,0.0,0.10681283,104.44456,8.5787067,359.10736,-9.281435
165.3592,9.5476151,1.8708706,0.0,0,7.5165353,0.0,0.13306005,106.37283,8.2170954,358.31775,-9.2815485
165.3616,9.8046627,2.1942153,0.0,0,7.2082515,0.0,0.15795602,106.54026,7.8628645,356.69449,-9.2806711
165.364,10.106862,2.5225329,0.0,0,6.9060431,0.0,0.18338875,107.16031,7.5320182,355.02734,-9.2808075
165.3664,10.407001,2.8324649,0.0,0,6.6115613,0.0,0.20866148,107.44173,7.2204781,353.3602,-9.2813616
165.3688,10.695794,3.1291282,0.0,0,6.3240418,0.0,0.23370646,107.79133,6.9153824,351.69305,-9.2814102
165.3712,10.91638,3.4173954,0.0,0,6.042748,0.0,0.25858974,107.33887,6.616704,353.89371,-9.2810841
165.3736,11.161618,3.7032864,0.0,0,5.7692914,0.0,0.28322431,107.01672,6.3260736,357.27151,-9.2809229
165.376,11.407182,3.981745,0.0,0,5.5006137,0.0,0.30769822,106.75767,6.0444727,360.64932,-9.280694
165.3784,11.694283,4.2565913,0.0,0,5.2404532,0.0,0.33290398,106.65578,5.7717237,364.02713,-9.2814112
165.3808,11.964532,4.5254593,0.0,0,4.9838042,0.0,0.35887,106.41537,5.5000639,368.68646,-9.2801714
165.3832,12.192741,4.7856255,0.0,0,4.7363639,0.0,0.38435158,105.68793,5.2303252,374.26117,-9.2810555
165.3856,12.481579,5.0450845,0.0,0,4.4912457,0.0,0.40967751,105.3674,4.9701395,379.83585,-9.2812052
165.388,12.804008,5.3003225,0.0,0,4.2558532,0.0,0.43515661,105.47575,4.7148728,385.41055,-9.2801247
165.3904,13.131282,5.5477295,0.0,0,4.0217257,0.0,0.46091986,105.46592,4.4692316,389.43314,-9.2809458
165.3928,13.43557,5.7862911,0.0,0,3.7978494,0.0,0.4870837,105.10002,4.2258701,391.12756,-9.2800303
165.3952,13.793605,6.0221696,0.0,0,3.5743496,0.0,0.51352495,105.02151,3.9840589,392.82196,-9.2798624
165.3976,14.147762,6.254775,0.0,0,3.3612847,0.0,0.53928512,104.96556,3.749404,394.51639,-9.2810545
165.4,14.55231,6.486578,0.0,0,3.1483088,0.0,0.56547189,105.21246,3.5240905,395.27136,-9.2807522
165.4024,14.961361,6.7110629,0.0,0,2.9451065,0.0,0.59203053,105.31051,3.3030248,392.62979,-9.280653
165.4048,15.345066,6.9239511,0.0,0,2.7424984,0.0,0.61890948,105.19801,3.0889821,389.98825,-9.2791605
165.4072,15.780375,7.1263013,0.0,0,2.5483873,0.0,0.64483225,105.37609,2.8777678,387.34668,-9.2795448
165.4096,16.270931,7.3255172,0.0,0,2.3556671,0.0,0.66993904,105.96704,2.6737642,384.67264,-9.2796106
165.412,16.76399,7.5256443,0.0,0,2.1702483,0.0,0.69551247,106.42287,2.4744031,381.0563,-9.2793531
165.4144,17.28952,7.7203984,0.0,0,1.9869361,0.0,0.72192597,106.91754,2.2846117,377.43994,-9.2794886
165.4168,17.850159,7.9066954,0.0,0,1.8098084,0.0,0.74862355,107.44888,2.0980532,373.82361,-9.2788467
165.4192,18.459988,8.0869513,0.0,0,1.6354244,0.0,0.77509481,108.20545,1.9075637,370.20724,-9.2780247
165.4216,19.119108,8.2691288,0.0,0,1.4662173,0.0,0.80121005,109.17962,1.7240353,368.93353,-9.277524
165.424,19.82266,8.4508476,0.0,0,1.3003293,0.0,0.82753062,110.28143,1.5531269,368.07321,-9.2787113
165.4264,20.497919,8.6275215,0.0,0,1.1387084,0.0,0.85477787,110.98021,1.3754886,367.21289,-9.2778234
165.4288,21.264097,8.7885933,0.0,0,0.98093235,0.0,0.88142198,112.04766,1.2043881,366.35257,-9.2759075
165.4312,22.080095,8.9438391,0.0,0,0.82657731,0.0,0.9077031,113.33057,1.0415989,366.89926,-9.2751522
165.4336,22.941269,9.1012068,0.0,0,0.67652941,0.0,0.93311834,114.78607,0.88273311,368.14951,-9.2755919
165.436,23.813248,9.2549467,0.0,0,0.52908593,0.0,0.958534,116.17542,0.72672755,369.39972,-9.2759762
165.4384,24.702623,9.4033117,0.0,0,0.3862859,0.0,0.98449129,117.44234,0.57293499,370.64993,-9.2744627
165.4408,22.273144,9.433876,0.0,0,0.24542016,0.0,0.99152255,105.51437,0.47963855,372.98846,-9.2752094
165.4432,20.416697,9.4381857,0.0,0,0.10962815,0.0,0.99338591,96.379768,0.43730211,376.49033,-9.2780371
165.4456,19.614943,9.4444504,0.0,0,-0.025516368,0.0,0.99369329,92.487694,0.40692717,379.99222,-9.2799377
165.448,19.312645,9.4567471,0.0,0,-0.15794842,0.0,0.99461859,90.915634,0.36791709,383.49408,-9.280302
165.4504,19.424109,9.4647512,0.0,0,-0.29038045,0.0,0.99571896,91.372162,0.31684998,386.59467,-9.2798672
165.4528,19.606348,9.4704552,0.0,0,-0.42281243,0.0,0.99835795,91.980766,0.24837221,388.75894,-9.2786732
165.4552,19.644979,9.4719601,0.0,0,-0.55524439,0.0,0.99954748,92.091011,0.17664798,390.92319,-9.2791138
165.4576,19.580254,9.4744349,0.0,0,-0.68767637,0.0,0.99912858,91.796593,0.11593685,393.08746,-9.2804184
165.46,19.401558,9.4837103,0.0,0,-0.82010835,0.0,0.99961853,90.925232,0.070623823,395.04129,-9.2802782
165.4624,19.085438,9.4901438,0.0,0,-0.9525404,0.0,1.0006981,89.374977,0.03373298,395.40176,-9.2804708
165.4648,18.657808,9.4905081,0.0,0,-1.0849724,0.0,1.0018237,87.246834,0.006866232,395.76221,-9.280714
165.4672,18.141575,9.4852409,0.0,0,-0.72870702,359.99997,1.0017825,84.857727,-0.0043493421,396.12268,-9.281395
165.4696,17.607191,9.4867897,0.0,0,-0.27022067,359.99997,1.0014637,82.388702,-2.0313708e-05,396.48315,-9.2829142
165.472,17.081833,9.4934149,0.0,0,0.18826568,359.99997,1.0011283,79.946373,0.0026081435,397.13208,-9.2828941
165.4744,16.643539,9.499115,0.0,0,0.64675206,359.99997,1.0018711,77.819153,0.0080634495,397.80164,-9.2835054
165.4768,16.313623,9.4974489,0.0,0,1.1052387,359.99997,1.0029949,76.197678,0.010006797,398.47119,-9.2837372
165.4792,15.799484,9.4913216,0.0,0,1.563725,359.99997,1.0029011,73.841209,0.020618657,399.14075,-9.282999
165.4816,14.124056,9.4864683,0.0,0,2.0222113,359.99997,1.0013168,66.294518,0.082420446,399.92871,-9.2852755
165.484,10.930491,9.4803867,0.0,0,2.4806981,359.99997,0.99893868,51.581818,0.23143251,400.75616,-9.286809
165.4864,5.9567976,9.4620571,0.0,0,2.9391842,359.99997,0.9955883,28.710651,0.47099951,401.58362,-9.2882242
165.4888,0.15555191,9.3706141,0.0,0,3.3976707,359.99997,0.98041576,0.69277471,0.88415247,402.4111,-9.2945023
165.4912,-0.23242655,9.3553715,0.0,0,3.8561573,359.99997,0.97833991,-1.1132724,1.6352853,403.09583,-9.2967892
165.4936,0.023805289,9.4044132,0.0,0,4.3146434,359.99997,0.98627323,0.24072677,2.4290199,403.67145,-9.2948189
165.496,1.9235018,9.4908466,0.0,0,4.7731299,359.99997,1.0008827,9.6238604,3.1061602,404.24707,-9.2937403
165.4984,0.20312618,9.4612761,0.0,0,5.2316165,359.99997,0.99508172,1.0123259,3.6222134,404.82269,-9.2935429
165.5008,0.30321079,9.4696207,0.0,0,5.6901026,359.99997,0.99784499,1.4444966,4.0609488,405.30731,-9.2925253
165.5032,0.41950259,9.4565573,0.0,0,6.1485891,359.99997,0.99673998,2.115629,4.4953551,405.64548,-9.2910843
165.5056,0.44985223,9.4554186,0.0,0,6.6070752,359.99997,0.99576485,2.0949662,4.9354658,405.98367,-9.2908545
165.508,0.44130459,9.4559708,0.0,0,7.0655618,359.99997,0.99447846,2.0396652,5.3839097,406.32187,-9.290391
165.5104,0.35594943,9.461832,0.0,0,7.5240483,359.99997,0.99545473,1.6939023,5.8589897,406.62982,-9.2899361
165.5128,0.43776304,9.4595652,0.0,0,7.9825354,359.99997,0.99606675,2.0604794,6.3437376,406.81689,-9.2893496
165.5152,0.41463748,9.4594402,0.0,0,8.441021,359.99997,0.99711645,1.9494128,6.8274274,407.00397,-9.2886658
165.5176,0.37883836,9.4594345,0.0,0,8.8995075,359.99997,0.99635524,1.7774854,7.2958651,407.19104,-9.2896242
165.52,0.40059289,9.4633884,0.0,0,9.3579931,359.99997,0.99576855,1.8683243,7.7761478,407.37741,-9.2891064
165.5224,0.41294894,9.4664755,0.0,0,9.8164806,359.99997,0.99606192,1.9741132,8.2441387,407.5213,-9.2890024
165.5248,0.38120368,9.4628286,0.0,0,10.274966,359.99997,0.99672765,1.742691,8.7195597,407.66519,-9.2899313
165.5272,0.43068737,9.455287,0.0,0,10.733453,359.99997,0.99633056,2.0207109,9.2005463,407.80911,-9.2894526
165.5296,0.41604713,9.4592123,0.0,0,11.191939,359.99997,0.99650097,1.98575,9.659565,407.953,-9.2882576
165.532,0.3732802,9.4620209,0.0,0,11.650426,359.99997,0.99585027,1.7785453,10.134871,408.10892,-9.287858
165.5344,0.4214724,9.461957,0.0,0,12.108912,359.99997,0.99550694,1.9587736,10.613564,408.26721,-9.2874994
165.5368,0.40708396,9.4613934,0.0,0,12.567399,359.99997,0.99655539,1.9321065,11.077912,408.42551,-9.2874107
165.5392,0.35796368,9.4574022,0.0,0,13.025885,359.99997,0.99666011,1.6784341,11.541319,408.5838,-9.2876205
165.5416,0.43267635,9.4565125,0.0,0,13.484371,359.99997,0.99579436,2.0241749,11.994117,408.72809,-9.2860527
165.544,0.40032312,9.4625273,0.0,0,13.942858,359.99997,0.99580282,1.8836476,12.450365,408.86478,-9.2870998
165.5464,0.38963851,9.4662571,0.0,0,14.401344,359.99997,0.99608302,1.8650713,12.919603,409.0015,-9.2873325
165.5488,0.46769723,9.462244,0.0,0,14.859831,359.99997,0.99674636,2.1840241,13.402759,409.13821,-9.2864504
165.5512,0.40443462,9.4593248,0.0,0,15.318317,359.99997,0.99710995,1.9170491,13.87712,409.27158,-9.2874441
165.5536,0.39577749,9.4580812,0.0,0,15.776803,359.99997,0.99632555,1.8223559,14.3585,409.40106,-9.2871637
165.556,0.43778613,9.4620361,0.0,0,16.235291,359.99997,0.99566853,2.0586386,14.830332,409.53058,-9.2856436
165.5584,0.39715466,9.4667635,0.0,0,16.693775,359.99997,0.9963783,1.8755383,15.29164,409.6601,-9.2861195
165.5608,0.40297532,9.462348,0.0,0,17.152262,359.99997,0.99660599,1.8912233,15.758046,409.76517,-9.2860441
165.5632,0.46273881,9.4561749,0.0,0,17.61075,359.99997,0.99652725,2.1888025,16.21138,409.80832,-9.286437
165.5656,0.36620107,9.459815,0.0,0,17.999975,359.99997,0.9964413,1.73664,16.659395,409.8515,-9.2860432
165.568,0.43074235,9.4645529,0.0,0,18.0,359.99997,0.99599969,1.9930178,17.116993,409.89468,-9.2848654
165.5704,0.42572746,9.4673643,0.0,0,18.0,359.99997,0.99589962,1.9763819,17.53879,409.9364,-9.2856855
165.5728,0.40560243,9.4665537,0.0,0,18.0,359.99997,0.99717116,1.9325475,17.915651,409.96518,-9.2870636
165.5752,0.47058785,9.4626951,0.0,0,18.0,359.99997,0.99764997,2.228395,18.217085,409.99396,-9.28722
165.5776,0.55026543,9.4597225,0.0,0,18.0,359.99997,0.9966656,2.6172094,18.417322,410.02274,-9.2907953
165.58,0.51320767,9.4604177,0.0,0,18.0,359.99997,0.99554938,2.3841736,18.499508,410.05151,-9.2975712
165.5824,0.53994083,9.4633818,0.0,0,18.0,359.99997,0.99583548,2.5582712,18.456667,410.11987,-9.3041906
165.5848,0.49641404,9.4629641,0.0,0,18.0,359.99997,0.99676609,2.3202953,18.329062,410.19183,-9.3129196
165.5872,0.52879637,9.458415,0.0,0,18.0,359.99997,0.99687195,2.4114735,18.203203,410.26379,-9.3245602
165.5896,0.53506726,9.4588146,0.0,0,18.0,359.99997,0.99637502,2.554806,18.107056,410.33572,-9.3389902
165.592,0.56343782,9.4621134,0.0,0,18.0,359.99997,0.99573439,2.6228004,18.051659,410.4024,-9.3571472
165.5944,0.48865363,9.4646082,0.0,0,18.0,359.99997,0.99562144,2.323983,18.04179,410.46716,-9.3776255
165.5968,0.45984608,9.4632902,0.0,0,18.0,359.99997,0.99666351,2.1709857,18.052027,410.53192,-9.3968105
165.5992,0.47647849,9.4555883,0.0,0,18.0,359.99997,0.99631947,2.2027857,18.065908,410.59668,-9.4169483
165.6016,0.5560078,9.4527235,0.0,0,18.0,359.99997,0.99526376,2.5889308,18.08881,410.63373,-9.4355907
165.604,0.52822602,9.4552269,0.0,0,18.0,359.99997,0.99453652,2.4830806,18.107027,410.64813,-9.455409
165.6064,0.48544616,9.4590559,0.0,0,18.0,359.99997,0.99490023,2.2801661,18.126945,410.66254,-9.4731808
165.6088,0.46401563,9.4561119,0.0,0,18.0,359.99997,0.99544728,2.2016349,18.135067,410.67691,-9.48915
165.6112,0.53196728,9.4514303,0.0,0,18.0,359.99997,0.99568051,2.4691772,18.138313,410.68604,-9.506423
165.6136,0.54377234,9.4533396,0.0,0,18.0,359.99997,0.99558693,2.5412567,18.137648,410.68604,-9.5250406
165.616,0.50642788,9.458662,0.0,0,18.0,359.99997,0.9949196,2.417392,18.138348,410.68604,-9.5425243
165.6184,0.48215076,9.4627571,0.0,0,18.0,359.99997,0.99525124,2.2723522,18.13168,410.68604,-9.5600214
165.6208,0.49670061,9.4602079,0.0,0,18.0,359.99997,0.99613142,2.305913,18.130896,410.69131,-9.5752678
165.6232,0.55515277,9.4546471,0.0,0,18.0,359.99997,0.99624187,2.5844092,18.127354,410.72009,-9.5919323
165.6256,0.56342399,9.4544621,0.0,0,18.0,359.99997,0.99563926,2.6548016,18.128477,410.74887,-9.6104212
165.628,0.49238053,9.4561129,0.0,0,18.0,359.99997,0.99476206,2.3522277,18.126917,410.77765,-9.6281013
165.6304,0.48995134,9.4596901,0.0,0,18.0,359.99997,0.99514276,2.2771628,18.11801,410.80643,-9.6463299
165.6328,0.53886282,9.4589939,0.0,0,18.0,359.99997,0.9960674,2.4966354,18.115391,410.78485,-9.6633244
165.6352,0.57718331,9.4575977,0.0,0,18.0,359.99997,0.99668854,2.7344313,18.119158,410.76324,-9.6814861
165.6376,0.52410293,9.4562616,0.0,0,18.0,359.99997,0.99599403,2.5250034,18.113249,410.74167,-9.6998167
165.64,0.48551095,9.4585381,0.0,0,18.0,359.99997,0.99502194,2.306051,18.11157,410.72009,-9.7169313
165.6424,0.50200468,9.4630756,0.0,0,18.0,359.99997,0.99521726,2.3333805,18.112095,410.71613,-9.73386
165.6448,0.56190819,9.4628201,0.0,0,18.0,359.99997,0.99648142,2.6359305,18.111132,410.71613,-9.7500544
165.6472,0.55759716,9.4567919,0.0,0,18.0,359.99997,0.99678582,2.6390047,18.10955,410.71613,-9.7683172
165.6496,0.49934894,9.4560986,0.0,0,18.0,359.99997,0.99619102,2.3815367,18.106979,410.71613,-9.7862797
165.652,0.48041531,9.4585962,0.0,0,18.0,359.99997,0.99515355,2.2734013,18.106934,410.74347,-9.8058949
165.6544,0.52593505,9.4622755,0.0,0,18.0,359.99997,0.99548942,2.4479675,18.102674,410.78665,-9.8220224
165.6568,0.57505673,9.4591799,0.0,0,18.0,359.99997,0.99589628,2.6965625,18.099064,410.8298,-9.8394957
165.6592,0.53558564,9.4551153,0.0,0,18.0,359.99997,0.99621898,2.5270255,18.097046,410.87299,-9.857708
165.6616,0.48443633,9.4526548,0.0,0,18.0,359.99997,0.99546635,2.3070085,18.100279,410.88379,-9.8736267
165.664,0.49231577,9.4577608,0.0,0,18.0,359.99997,0.99489641,2.3103335,18.095491,410.85498,-9.8922844
165.6664,0.53752458,9.4649687,0.0,0,18.0,359.99997,0.99569911,2.527951,18.094501,410.8262,-9.9094582
165.6688,0.56510663,9.4649515,0.0,0,18.0,359.99997,0.99691862,2.6436069,18.095913,410.79742,-9.9268341
165.6712,0.49681374,9.4579868,0.0,0,18.0,359.99997,0.99677348,2.3753884,18.101068,410.76096,-9.9449892
165.6736,0.47251531,9.454402,0.0,0,18.0,359.99997,0.99563402,2.2162802,18.095409,410.7034,-9.9621334
165.676,0.51486665,9.4560308,0.0,0,18.0,359.99997,0.99472868,2.3957188,18.095922,410.64584,-9.97931
165.6784,0.5710963,9.4596472,0.0,0,18.0,359.99997,0.99492359,2.7068708,18.093042,410.58829,-9.9977236
165.6808,0.53438002,9.4586964,0.0,0,18.0,359.99997,0.9958418,2.5019801,18.090714,410.53253,-10.016322
165.6832,0.48383844,9.4543991,0.0,0,18.0,359.99997,0.99615699,2.2737184,18.093817,410.49655,-10.032736
165.6856,0.48737746,9.4549217,0.0,0,18.0,359.99997,0.99582964,2.2740505,18.095272,410.46057,-10.050057
165.688,0.54369539,9.4605627,0.0,0,18.0,359.99997,0.99545497,2.5957744,18.097519,410.42459,-10.064769
165.6904,0.57314813,9.464633,0.0,0,18.0,359.99997,0.99562627,2.7022338,18.095184,410.38861,-10.084811
165.6928,0.50349802,9.4609833,0.0,0,18.0,359.99997,0.99616158,2.4043946,18.095173,410.36557,-10.102386
165.6952,0.4924095,9.4555578,0.0,0,18.0,359.99997,0.99637395,2.3042357,18.09042,410.34399,-10.120068
165.6976,0.51618552,9.4521713,0.0,0,18.0,359.99997,0.99546391,2.4054885,18.092445,410.32242,-10.138392
165.7,0.58356357,9.456871,0.0,0,18.0,359.99997,0.99488586,2.7173254,18.09026,410.30081,-10.155439
165.7024,0.56169558,9.462821,0.0,0,18.0,359.99997,0.99548876,2.6249642,18.082413,410.26892,-10.172725
165.7048,0.49748838,9.4608335,0.0,0,18.0,359.99997,0.9962914,2.3535016,18.084824,410.23297,-10.189175
165.7072,0.50658631,9.4559727,0.0,0,18.0,359.99997,0.99640632,2.3712347,18.085684,410.19699,-10.207274
165.7096,0.56393892,9.4552927,0.0,0,18.0,359.99997,0.99576807,2.6258113,18.084381,410.16101,-10.22442
165.712,0.59760106,9.4598122,0.0,0,18.0,359.99997,0.99543732,2.8164241,18.077869,410.12122,-10.242218
165.7144,0.52119786,9.4643421,0.0,0,18.0,359.99997,0.99561006,2.4997771,18.082575,410.07803,-10.261436
165.7168,0.50387836,9.4629354,0.0,0,18.0,359.99997,0.99629408,2.3596611,18.083416,410.03485,-10.279037
165.7192,0.53198373,9.4560614,0.0,0,18.0,359.99997,0.99632496,2.4658134,18.077658,409.9917,-10.298165
165.7216,0.58882791,9.4537497,0.0,0,18.0,359.99997,0.99576348,2.7582033,18.077755,409.95395,-10.313406
165.724,0.57884508,9.456502,0.0,0,18.0,359.99997,0.99497205,2.8002913,18.077698,409.92624,-10.331804
165.7264,0.50400126,9.4611225,0.0,0,18.0,359.99997,0.99530232,2.3769271,18.078173,409.89856,-10.348907
165.7288,0.50416666,9.460907,0.0,0,18.0,359.99997,0.99636847,2.341109,18.0763,409.87088,-10.366456
165.7312,0.56012219,9.4570322,0.0,0,18.0,359.99997,0.99651074,2.5992069,18.077578,409.8432,-10.382554
165.7336,0.58503336,9.4551411,0.0,0,18.0,359.99997,0.99575537,2.7688806,18.077467,409.79285,-10.400992
165.736,0.54013848,9.45961,0.0,0,18.0,359.99997,0.99536437,2.5952876,18.076435,409.74246,-10.419516
165.7384,0.49751097,9.4637308,0.0,0,18.0,359.99997,0.99543571,2.3053384,18.073582,409.69211,-10.437062
165.7408,0.52706712,9.4645338,0.0,0,18.0,359.99997,0.99665791,2.426893,18.075916,409.64175,-10.453107
165.7432,0.58458292,9.4562216,0.0,0,18.0,359.99997,0.9964177,2.7439919,18.0762,409.60312,-10.471136
165.7456,0.57619596,9.4534111,0.0,0,18.0,359.99997,0.99558914,2.7728438,18.073036,409.56714,-10.489157
165.748,0.5021258,9.4538479,0.0,0,18.0,359.99997,0.99435002,2.3857138,18.07551,409.53116,-10.506327
165.7504,0.50151676,9.4585752,0.0,0,18.0,359.99997,0.99472362,2.349479,18.074265,409.49518,-10.524642
165.7528,0.55767375,9.4577971,0.0,0,18.0,359.99997,0.99563676,2.6149802,18.072166,409.45465,-10.542017
165.7552,0.58172315,9.4563284,0.0,0,18.0,359.99997,0.99628323,2.741467,18.071903,409.41147,-10.559713
165.7576,0.53930581,9.4576864,0.0,0,18.0,359.99997,0.99638712,2.5556827,18.066442,409.36832,-10.576481
165.76,0.4962635,9.4597607,0.0,0,18.0,359.99997,0.99523336,2.3237293,18.06847,409.32513,-10.593678
165.7624,0.51977193,9.4637451,0.0,0,18.0,359.99997,0.99535644,2.3941424,18.068016,409.27548,-10.611681
165.7648,0.58355761,9.4607201,0.0,0,18.0,359.99997,0.9957794,2.7370844,18.067825,409.21793,-10.630031
165.7672,0.59034514,9.4573498,0.0,0,18.0,359.99997,0.99657351,2.7894964,18.067831,409.16037,-10.646018
165.7696,0.52994758,9.4550505,0.0,0,18.0,359.99997,0.99608856,2.5142715,18.067528,409.10281,-10.664561
165.772,0.50184548,9.4569416,0.0,0,18.0,359.99997,0.99507117,2.3595953,18.063457,409.05292,-10.682362
165.7744,0.5600931,9.4613857,0.0,0,18.0,359.99997,0.99527442,2.6019659,18.066761,409.02414,-10.700756
165.7768,0.59766966,9.4591427,0.0,0,18.0,359.99997,0.99579728,2.8290753,18.067608,408.99536,-10.718106
165.7792,0.5715009,9.4582109,0.0,0,18.0,359.99997,0.99675244,2.7442641,18.063141,408.96658,-10.736308
165.7816,0.51147068,9.4555416,0.0,0,18.0,359.99997,0.99591833,2.4005005,18.063915,408.93958,-10.75215
165.784,0.52275079,9.456275,0.0,0,18.0,359.99997,0.99478817,2.4357061,18.067833,408.9324,-10.770061
165.7864,0.59102559,9.4624386,0.0,0,18.0,359.99997,0.99521106,2.7485831,18.068008,408.9252,-10.786306
165.7888,0.60295457,9.4611254,0.0,0,18.0,359.99997,0.99602729,2.8223875,18.06086,408.918,-10.804111
165.7912,0.53798908,9.4566574,0.0,0,18.0,359.99997,0.99669242,2.5751617,18.061516,408.91083,-10.822165
165.7936,0.51409382,9.4558554,0.0,0,18.0,359.99997,0.99619335,2.4258871,18.05965,408.89716,-10.838874
165.796,0.56904918,9.459341,0.0,0,18.0,359.99997,0.99538165,2.6346018,18.061209,408.88275,-10.857172
165.7984,0.60708278,9.4623318,0.0,0,18.0,359.99997,0.99554145,2.8603985,18.063618,408.86838,-10.875916
165.8008,0.57369697,9.4605932,0.0,0,18.0,359.99997,0.99616951,2.7333088,18.058525,408.854,-10.893631
165.8032,0.52857834,9.4533157,0.0,0,18.0,359.99997,0.9958266,2.4934714,18.06216,408.8396,-10.910509
165.8056,0.52602381,9.4490595,0.0,0,18.0,359.99997,0.99484587,2.4095497,18.062796,408.8252,-10.928017
165.808,0.59708953,9.4556055,0.0,0,18.0,359.99997,0.99456459,2.7623553,18.059692,408.81082,-10.945981
165.8104,0.59591341,9.4617252,0.0,0,18.0,359.99997,0.99509513,2.8376403,18.058729,408.79642,-10.964355
165.8128,0.5420301,9.4629202,0.0,0,18.0,359.99997,0.99607289,2.632966,18.059271,408.76669,-10.980161
165.8152,0.51630819,9.4572592,0.0,0,18.0,359.99997,0.99675977,2.4159458,18.05884,408.72351,-10.998458
165.8176,0.55999225,9.4520311,0.0,0,18.0,359.99997,0.99552959,2.6014903,18.056259,408.68033,-11.015817
165.82,0.60334504,9.4539928,0.0,0,18.0,359.99997,0.99454468,2.8274269,18.059528,408.63718,-11.034475
165.8224,0.58628064,9.4595604,0.0,0,18.0,359.99997,0.99500543,2.7850182,18.056299,408.59399,-11.050182
165.8248,0.53087276,9.4594831,0.0,0,18.0,359.99997,0.99580646,2.527508,18.055861,408.55081,-11.067021
165.8272,0.51021314,9.454257,0.0,0,18.0,359.99997,0.99589783,2.3832257,18.05629,408.50766,-11.084131
165.8296,0.58732367,9.4522686,0.0,0,18.0,359.99997,0.99542785,2.7626894,18.055199,408.46448,-11.102713
165.832,0.60379124,9.4595222,0.0,0,18.0,359.99997,0.99543977,2.832314,18.053083,408.42371,-11.122818
165.8344,0.55336225,9.464366,0.0,0,18.0,359.99997,0.99554473,2.620759,18.052599,408.39493,-11.139356
165.8368,0.52559352,9.4623079,0.0,0,18.0,359.99997,0.99612105,2.4758813,18.052094,408.36615,-11.156776
165.8392,0.55492353,9.4560747,0.0,0,18.0,359.99997,0.99637961,2.5614126,18.052153,408.33737,-11.174357
165.8416,0.60080171,9.4532051,0.0,0,18.0,359.99997,0.99576783,2.8127122,18.051151,408.30859,-11.192606
165.844,0.59783345,9.4568729,0.0,0,18.0,359.99997,0.99503857,2.8226326,18.0516,408.24442,-11.211296
165.8464,0.53081578,9.460906,0.0,0,18.0,359.99997,0.99512917,2.5217123,18.053818,408.17966,-11.228868
165.8488,0.52613258,9.4589653,0.0,0,18.0,359.99997,0.9956497,2.4519076,18.045601,408.1149,-11.246037
165.8512,0.59465522,9.4548969,0.0,0,18.0,359.99997,0.9960711,2.7720742,18.046741,408.05014,-11.264732
165.8536,0.61161739,9.4551611,0.0,0,18.0,359.99997,0.99603295,2.883009,18.04767,408.00266,-11.281868
165.856,0.5650636,9.4587164,0.0,0,18.0,359.99997,0.99523908,2.6854661,18.047554,407.9595,-11.297783
165.8584,0.53010112,9.4633961,0.0,0,18.0,359.99997,0.99541879,2.5141795,18.042637,407.91632,-11.315593
165.8608,0.55500847,9.4619503,0.0,0,18.0,359.99997,0.99606878,2.5678442,18.046539,407.87314,-11.332692
165.8632,0.61996835,9.4554672,0.0,0,18.0,359.99997,0.9961428,2.8928981,18.048592,407.84329,-11.350011
166.0651,0.52872878,9.4581194,0.0,0,18.0,0.68381345,0.99571627,2.4876432,18.024546,402.46332,-11.47898
167.2651,0.47982138,9.4674139,0.0,0,18.0,2.9561132e-17,0.99741787,2.2565744,18.000648,382.70715,-11.481403
168.4651,0.45903549,9.4732075,0.0,0,18.0,1.2779232e-33,0.99849886,2.1534345,17.999743,368.47906,-11.480881
169.6651,0.46089283,9.4795322,0.0,0,18.0,1.4012985e-45,0.99960572,2.1665657,18.000324,355.81494,-11.482078
170.8651,0.44479001,9.4858198,0.0,0,18.0,1.4012985e-45,1.0006886,2.0872247,17.999643,344.52692,-11.481833
172.0651,0.43881369,9.4916744,0.0,0,18.0,1.4012985e-45,1.0017289,2.0560045,18.000422,333.83694,-11.481764
173.2651,0.43759984,9.4971828,0.0,0,18.0,1.4012985e-45,1.0027418,2.0495684,17.999979,323.66357,-11.481419
174.4651,0.43073145,9.50212,0.0,0,18.0,1.4012985e-45,1.0037214,2.0136487,18.000334,313.97916,-11.481247
175.6651,0.43073434,9.5072412,0.0,0,18.0,1.4012985e-45,1.0046635,2.0132978,18.001129,304.89389,-11.481245
176.8651,0.44315955,9.511425,0.0,0,18.0,1.4012985e-45,1.0053928,2.0688481,17.999191,295.96954,-11.48185
178.0651,0.43687698,9.5166187,0.0,0,18.0,1.4012985e-45,1.0062995,2.0331607,18.000023,287.23752,-11.482188
179.2651,0.43946809,9.5212841,0.0,0,18.0,1.4012985e-45,1.0072122,2.0469635,18.000589,278.98456,-11.482826
180.4651,0.42552537,9.5255795,0.0,0,18.0,1.4012985e-45,1.0080423,1.9848459,18.000515,271.12601,-11.481864
181.6651,0.43017036,9.5297976,0.0,0,18.0,1.4012985e-45,1.0087671,1.9994135,17.999039,263.50754,-11.481959
182.8651,0.43174633,9.5343685,0.0,0,18.0,1.4012985e-45,1.0095394,2.0099044,17.998686,256.19995,-11.481952
184.0651,0.42811185,9.5381908,0.0,0,18.0,1.4012985e-45,1.0102109,1.986761,17.999662,248.97577,-11.481794
185.2651,0.4307439,9.5425348,0.0,0,18.0,1.4012985e-45,1.010975,2.0008583,17.999901,242.21404,-11.481525
186.4651,0.44231957,9.5460205,0.0,0,18.0,1.4012985e-45,1.0117228,2.0578952,18.000509,235.63499,-11.482083
187.6651,0.44823334,9.5494137,0.0,0,18.0,1.4012985e-45,1.0123863,2.0796549,18.000498,229.17564,-11.482758
188.8651,0.43432808,9.5525236,0.0,0,18.0,1.4012985e-45,1.0128947,2.0116689,17.999985,223.03122,-11.482234
190.0651,0.43092945,9.5561514,0.0,0,18.0,1.4012985e-45,1.0135499,1.9936877,18.001371,217.17064,-11.482767
191.2651,0.43320426,9.5592003,0.0,0,18.0,1.4012985e-45,1.0141177,2.0056055,17.999409,211.21962,-11.482643
192.4651,0.42868447,9.5618048,0.0,0,18.0,1.4012985e-45,1.0146737,1.982716,17.999208,205.28577,-11.482586
193.6651,0.43252617,9.5655231,0.0,0,18.0,1.4012985e-45,1.0153427,1.9991026,17.998856,199.96652,-11.482202
194.8651,0.42550176,9.568881,0.0,0,18.0,1.4012985e-45,1.0158731,1.96233,17.99925,194.61005,-11.482143
196.0651,0.42296195,9.5721178,0.0,0,18.0,1.4012985e-45,1.0164254,1.9578542,17.99935,189.58038,-11.481208
197.2651,0.4201344,9.5752048,0.0,0,18.0,1.4012985e-45,1.0170485,1.9392737,18.000292,184.72504,-11.481627
198.4651,0.4296416,9.5780516,0.0,0,18.0,1.4012985e-45,1.0176189,1.9886289,17.999161,179.94025,-11.481473
199.6651,0.43569809,9.5807219,0.0,0,18.0,1.4012985e-45,1.0181359,2.0076604,18.000639,175.35165,-11.481472
200.8651,0.44042909,9.5840588,0.0,0,18.0,1.4012985e-45,1.0187023,2.0276415,17.999693,170.90311,-11.48199
202.0651,0.43093678,9.5864153,0.0,0,18.0,1.4012985e-45,1.0191423,1.9818012,17.99938,166.38875,-11.482
203.2651,0.42667681,9.5888643,0.0,0,18.0,1.4012985e-45,1.0196402,1.9605273,17.999952,162.18864,-11.481905
204.4651,0.43141925,9.591733,0.0,0,18.0,1.4012985e-45,1.0201645,1.9825453,17.999413,158.18965,-11.481877
205.6651,0.43207964,9.5943775,0.0,0,18.0,1.4012985e-45,1.020636,1.9861202,18.000362,154.0668,-11.482511
206.8651,0.42951289,9.597476,0.0,0,18.0,1.4012985e-45,1.0211476,1.9746788,17.999514,150.19331,-11.482076
208.0651,0.43598732,9.5998363,0.0,0,18.0,1.4012985e-45,1.0215617,1.9990871,18.000135,146.41768,-11.482358
209.2651,0.42405191,9.6021385,0.0,0,18.0,1.4012985e-45,1.0220107,1.9484727,17.999594,142.75629,-11.482377
210.4651,0.42814881,9.6042452,0.0,0,18.0,1.4012985e-45,1.0224735,1.9642727,17.999783,139.22389,-11.48272
211.6651,0.43408674,9.6064301,0.0,0,18.0,1.4012985e-45,1.0228952,1.9948678,17.99946,135.81664,-11.483092
212.8651,0.43352962,9.6088943,0.0,0,18.0,1.4012985e-45,1.0233072,1.9881889,17.999546,132.47015,-11.48272
214.0651,0.42884433,9.6109715,0.0,0,18.0,1.4012985e-45,1.0236404,1.9633127,18.000301,129.22209,-11.482748
215.2651,0.42989364,9.6132345,0.0,0,18.0,1.4012985e-45,1.0241426,1.9699063,17.999706,126.27655,-11.483109
216.4651,0.42662549,9.6153164,0.0,0,18.0,1.4012985e-45,1.0245627,1.952178,17.99964,123.25864,-11.482388
217.6651,0.4254055,9.6171684,0.0,0,18.0,1.4012985e-45,1.024884,1.9437847,18.000076,120.33234,-11.48248
218.8651,0.42102873,9.6192017,0.0,0,18.0,1.4012985e-45,1.0252137,1.9301537,17.999836,117.47057,-11.482232
220.0651,0.42430916,9.6212454,0.0,0,18.0,1.4012985e-45,1.0255601,1.9417058,18.00009,114.66734,-11.482402
221.2651,0.42365631,9.6234579,0.0,0,18.0,1.4012985e-45,1.0259435,1.9408623,18.000187,112.16293,-11.48223
222.4651,0.42259926,9.6252661,0.0,0,18.0,1.4012985e-45,1.0263169,1.9308215,17.999418,109.47565,-11.482089
223.6651,0.42595246,9.626874,0.0,0,18.0,1.4012985e-45,1.0266764,1.9466693,17.99995,107.11035,-11.481722
224.8651,0.42403898,9.6284504,0.0,0,18.0,1.4012985e-45,1.0269771,1.9390342,18.000473,104.6246,-11.481684
225.8651,0.42869115,9.6300278,0.0,0,18.0,1.4012985e-45,1.0271726,1.9527571,17.999884,102.69751,-11.481721