File: examples/dan-msc-case-studies/CS3/data/01 raw data/baron_test_069.csv
Time(sec),Force(kN),Jaw(mm),PowAngle(deg),Power(W),Pram,PTemp,Strain,Stress(MPa),Stroke(mm),TC1(C),wedge(mm)
0.0,0.77975076,0.5180831,0.0,0,10.594783,0.0016185053,0.035438858,9.5809717,10.595401,23.307419,-9.1273193
2.2,0.71058303,-0.0005363964,0.0,0,10.594783,6.5158744,-3.675574e-05,9.0426197,10.594593,23.302485,-9.4919329
4.4,0.68050569,-0.00065806264,0.0,0,10.594783,13.115876,-3.9524373e-05,8.6566629,10.594872,23.202322,-9.488657
6.6,0.64996225,-0.00043073556,0.0,0,10.594783,19.715879,-2.8627772e-05,8.2846146,10.594872,23.223974,-9.4844828
8.8,0.63489944,-0.00054846861,17.926472,0,10.594783,26.315878,-4.1723208e-05,8.0932436,10.59495,23.259748,-9.4802523
11.0,0.64498693,-0.0027604792,36.307945,0,10.594783,32.915874,-0.00019390005,8.2139854,10.59461,26.561209,-9.4770689
13.2,0.66325498,-0.0093998527,41.802906,0,10.594783,39.515869,-0.00061439193,8.4598646,10.594729,34.448326,-9.4735622
15.4,0.66696388,-0.015782047,42.396244,0,10.594783,46.115875,-0.0010834372,8.4939899,10.593904,43.772297,-9.4691601
17.6,0.68667406,-0.022382244,40.628048,0,10.594783,52.715874,-0.001497179,8.7602205,10.595055,52.582336,-9.465024
19.8,0.67904419,-0.026210895,39.92432,0,10.594783,59.315887,-0.0017022145,8.6630592,10.594251,59.678947,-9.4607439
22.0,0.67737484,-0.030490249,40.550926,0,10.594783,65.915871,-0.0020579966,8.6435356,10.594559,65.812675,-9.4568911
24.2,0.69115943,-0.034969673,41.553513,0,10.594783,72.515869,-0.0023123268,8.8168535,10.593449,71.811249,-9.4533854
26.4,0.69592452,-0.03982047,42.396236,0,10.594783,79.115875,-0.0026168518,8.8805161,10.594714,78.353691,-9.4496908
28.6,0.70563859,-0.045382798,42.978512,0,10.594783,85.715881,-0.0030353416,9.0194731,10.594071,85.023743,-9.4458189
30.8,0.71161026,-0.049396604,43.527828,0,10.594783,92.315903,-0.0032810331,9.1061077,10.593769,91.694267,-9.4418116
33.0,0.71155185,-0.054579955,44.077145,0,10.594783,98.915894,-0.0036405125,9.0887194,10.594884,98.329025,-9.4375792
35.2,0.72111213,-0.059927739,44.604488,0,10.594783,105.51589,-0.0039666616,9.2112379,10.594882,104.93559,-9.434041
37.4,0.71807498,-0.065177396,44.793468,0,10.594783,112.11588,-0.0043774736,9.1833324,10.593975,111.66024,-9.4301939
39.6,0.72257972,-0.070724733,45.12085,0,10.594783,118.71588,-0.0046898834,9.2344809,10.594831,118.26051,-9.4258518
41.8,0.73527479,-0.076235898,45.615231,0,10.594783,125.31587,-0.0050392882,9.4023228,10.594831,124.85441,-9.4218645
44.0,0.74058253,-0.082906999,46.109619,0,10.594783,131.91588,-0.0055108042,9.4829464,10.594831,131.3385,-9.4182653
46.2,0.74881619,-0.088216484,46.582027,0,10.594783,138.51585,-0.0059019066,9.5981331,10.593503,138.02548,-9.414629
48.4,0.7527914,-0.093336739,47.054436,0,10.594783,145.11588,-0.0062065539,9.6584463,10.595947,144.60219,-9.4112263
50.6,0.74724102,-0.099735752,47.504883,0,10.594783,151.71588,-0.0065861437,9.5909586,10.595345,151.26598,-9.4069147
52.8,0.74980587,-0.10520834,47.951046,0,10.594783,158.31589,-0.00699468,9.6143026,10.595111,157.6908,-9.4026928
55.0,0.75697261,-0.11125418,48.273331,0,10.594783,164.91588,-0.0074015665,9.7029305,10.594933,164.43163,-9.3994522
57.2,0.7545889,-0.11717692,48.383736,0,10.594783,171.51588,-0.0077830623,9.6954441,10.595321,171.27428,-9.3956203
59.4,0.75846291,-0.12347775,48.383785,0,10.594783,178.11588,-0.0081581883,9.7381382,10.593797,177.85698,-9.3917923
61.6,0.76582766,-0.12900655,48.812252,0,10.594783,184.71588,-0.0085719405,9.8500423,10.595161,184.39157,-9.3876657
63.8,0.75786853,-0.13488843,49.229733,0,10.594783,191.31589,-0.0089750541,9.7320576,10.593967,190.79987,-9.3835382
66.0,0.76166207,-0.14180557,49.636227,0,10.594783,197.91588,-0.009405232,9.8029842,10.594745,197.3116,-9.3804054
68.2,0.76927292,-0.14826399,50.014229,0,10.594783,204.5159,-0.0098018348,9.8792419,10.595201,203.98114,-9.3771019
70.4,0.77164221,-0.15499377,50.438229,0,10.594783,211.11591,-0.010276575,9.9180851,10.595449,210.5428,-9.372839
72.6,0.76687878,-0.16000956,50.438236,0,10.594783,217.7159,-0.010642705,9.8660021,10.594795,217.31966,-9.3688383
74.8,0.75469595,-0.16629958,50.82275,0,10.594783,224.31589,-0.011011216,9.7134447,10.595596,223.99324,-9.3652477
77.0,0.7569108,-0.17221345,51.180679,0,10.594783,230.91589,-0.011416379,9.7508936,10.595521,230.4556,-9.3619213
79.2,0.76320213,-0.17873798,51.196285,0,10.594783,237.51588,-0.011810098,9.8450155,10.59538,237.16953,-9.3574896
81.4,0.76735401,-0.18443514,51.56982,0,10.594783,244.11589,-0.012241775,9.8894682,10.594894,243.71959,-9.3536625
83.6,0.7757259,-0.19137363,51.932369,0,10.594783,250.71588,-0.012700528,10.014915,10.595543,250.23991,-9.349637
85.8,0.77156752,-0.19829227,52.27132,0,10.594783,257.31613,-0.013114209,9.9628439,10.595468,256.87094,-9.3462715
88.0,0.76007777,-0.20426662,52.57674,0,10.594783,263.91592,-0.013523079,9.8195486,10.594555,263.33017,-9.3432617
90.2,0.76755935,-0.21070425,52.965794,0,10.594783,270.51593,-0.013913605,9.9095049,10.594864,269.91922,-9.3385248
92.4,0.77184403,-0.21662186,53.316376,0,10.594783,277.11591,-0.014353747,9.9712601,10.594794,276.48886,-9.3347855
94.6,0.77697915,-0.22339989,53.657223,0,10.594783,283.71588,-0.01480231,10.05043,10.594261,283.0943,-9.330512
96.8,0.77923,-0.23014341,53.657223,0,10.594783,290.31586,-0.015223186,10.079197,10.595878,289.98434,-9.3274603
99.0,0.78229862,-0.23807441,53.739456,0,10.594783,296.91586,-0.015764749,10.135163,10.594917,296.59558,-9.3235083
101.2,0.76256913,-0.2458688,53.975807,0,10.594783,303.51587,-0.016216379,9.8720236,10.594691,303.2562,-9.319746
103.4,0.76876646,-0.25210527,54.05521,0,10.594783,310.11584,-0.016676424,9.9530983,10.594942,309.80298,-9.3152409
105.6,0.77753133,-0.25836471,54.305416,0,10.594783,316.71588,-0.017100783,10.068965,10.594288,316.33273,-9.3125381
107.8,0.78413004,-0.26501182,54.624023,0,10.594783,323.31589,-0.017500091,10.159557,10.594316,322.85751,-9.3083553
110.0,0.78274703,-0.27076855,54.931637,0,10.594783,329.91592,-0.017906899,10.146861,10.594533,329.39725,-9.3044357
112.2,0.77849269,-0.27699125,55.233547,0,10.594783,336.51593,-0.018260594,10.087291,10.594572,336.10281,-9.3013144
114.4,0.76893699,-0.28440225,55.318954,0,10.594783,343.11591,-0.018761767,9.9868126,10.594181,342.72635,-9.2972689
116.6,0.7694962,-0.2921806,55.469341,0,10.594783,349.71591,-0.01931591,9.9995899,10.594951,349.53745,-9.2932081
118.8,0.76656771,-0.29926163,55.360672,0,10.594783,356.31589,-0.019781467,9.954277,10.594421,356.23627,-9.2898417
121.0,0.76372284,-0.30646268,55.378712,0,10.594783,362.91589,-0.020201849,9.9230957,10.595337,362.86142,-9.2864199
123.2,0.76653785,-0.31289515,55.535694,0,10.594783,369.5159,-0.020665918,9.9480572,10.594358,369.35907,-9.2831602
125.4,0.77643991,-0.3205362,55.535885,0,10.594783,376.11591,-0.021115305,10.093306,10.59557,375.86453,-9.2791672
127.6,0.78258175,-0.32859594,55.843506,0,10.594783,382.71591,-0.021626739,10.182397,10.595166,382.45905,-9.2750883
129.8,0.77784997,-0.335639,56.129147,0,10.594783,389.31592,-0.022126932,10.109523,10.595283,388.85861,-9.2712202
132.0,0.78303766,-0.34199312,56.220901,0,10.594783,395.91592,-0.022565696,10.191434,10.594354,395.5939,-9.2673264
134.2,0.77491552,-0.34897152,56.628479,0,10.594783,402.51593,-0.023010906,10.083864,10.594921,401.99631,-9.263464
136.4,0.76795667,-0.35692537,56.711422,0,10.594783,409.11591,-0.023499658,10.012447,10.594454,408.71909,-9.2601595
138.6,0.7674799,-0.36430192,56.986084,0,10.594783,415.71591,-0.024006428,10.015754,10.594727,415.31265,-9.2566137
140.8,0.77335632,-0.37137461,56.71529,0,10.594783,422.31589,-0.024437647,10.10714,10.595427,422.39615,-9.2531738
143.0,0.78046364,-0.37789619,56.138874,0,10.594783,428.91589,-0.024837615,10.198903,10.594562,429.65292,-9.2489128
145.2,0.78634679,-0.38426036,55.84351,0,10.594783,435.51593,-0.025290962,10.283771,10.594643,436.27371,-9.2448349
147.4,0.78461647,-0.39236778,55.856613,0,10.594783,442.11594,-0.02582201,10.247637,10.59412,442.25137,-9.2411079
149.6,0.76703894,-0.39771137,56.129147,0,10.594783,448.71594,-0.026196236,10.025322,10.594705,448.50769,-9.2381086
151.8,0.056103703,-0.40904212,55.535892,0,10.594783,449.9989,-0.026918124,0.74013567,10.595275,450.41205,-9.2378693
154.0,0.056195073,-0.40810126,55.992592,0,10.594783,449.9989,-0.026832577,0.74006975,10.594037,449.71637,-9.2367535
156.2,0.050334867,-0.40915152,56.428196,0,10.594783,449.9989,-0.026915992,0.65224153,10.594585,449.25607,-9.23664
158.4,0.045060862,-0.40939924,56.986084,0,10.594783,449.9989,-0.026938099,0.59559733,10.595299,449.22052,-9.2360058
160.6,0.076935463,-0.40995657,57.031319,0,10.594783,449.9989,-0.02693166,1.0049326,10.595562,449.58884,-9.2367973
162.8,0.087341018,-0.41269654,56.797924,0,10.594783,449.9989,-0.027113482,1.1372956,10.593913,450.09399,-9.237092
165.0,0.071444258,-0.41280603,56.425785,0,10.594783,449.9989,-0.027147256,0.91523093,10.59528,450.56937,-9.2371216
167.2,0.068422303,-0.41371939,56.023582,0,10.594783,449.9989,-0.027223168,0.89162612,10.595108,450.72382,-9.2365561
169.4,0.064327843,-0.41392893,55.84351,0,10.594783,449.9989,-0.027255302,0.85349387,10.59444,450.47787,-9.2356348
171.6,0.064266443,-0.41604,55.851494,0,10.594783,449.9989,-0.027377494,0.83714402,10.594277,450.02173,-9.2353783
173.8,0.073476091,-0.41534817,56.133858,0,10.594783,449.9989,-0.027301315,0.96426189,10.59422,449.71924,-9.2363672
176.0,0.07899981,-0.41639692,56.292683,0,10.594783,449.9989,-0.027375804,1.04442,10.594672,449.80389,-9.2365646
178.2,0.082923189,-0.4188593,56.129154,0,10.594783,449.9989,-0.027549731,1.0952908,10.594234,450.01764,-9.2362137
180.4,0.061023887,-0.41888082,56.129154,0,10.594783,449.9989,-0.027552703,0.79655427,10.594978,449.95581,-9.2358475
182.6,0.077906862,-0.41947025,56.215961,0,10.594783,449.9989,-0.027558561,1.0241534,10.594625,450.00317,-9.2354784
184.8,0.093935177,-0.42115459,56.129154,0,10.594783,449.9989,-0.027657995,1.2243847,10.594777,450.11707,-9.236146
187.0,0.079273999,-0.42175528,56.128704,0,10.594783,449.9989,-0.027707664,1.0321521,10.594259,450.20245,-9.2368116
189.2,0.081396878,-0.42240646,55.722305,0,10.594783,449.9989,-0.027759174,1.0674757,10.594139,450.40994,-9.2370501
191.4,0.072916836,-0.42325458,55.801453,0,10.594783,449.9989,-0.027834522,0.95344687,10.594633,450.15775,-9.2356272
193.6,0.05476483,-0.42371026,56.129078,0,10.594783,449.9989,-0.027881527,0.71442157,10.595098,449.64474,-9.2353449
195.2807,0.19176908,0.013276594,56.425781,0,10.5948,0.13874726,0.0010396934,2.4860373,10.59576,449.3912,-9.2365246
195.2851,0.17959604,0.015797969,47.189892,0,10.5948,1.3840876e-31,0.0012347582,2.3024914,10.597434,449.37625,-9.2362719
195.2895,0.19257039,0.013279716,22.412102,0,10.5948,0.0,0.0011078749,2.5028462,10.595554,449.40256,-9.2355556
195.2939,0.1733886,0.016815489,0.0,0,10.5948,0.0,0.0012624925,2.1851406,10.59504,449.42508,-9.236393
195.2983,0.16087046,0.014173726,0.0,0,10.5948,0.0,0.0011439923,2.0491168,10.595481,449.41193,-9.2369738
195.3027,0.18375072,0.015307738,0.0,0,10.5948,0.0,0.0012133804,2.3510013,10.594159,449.39877,-9.236062
195.3071,0.18454346,0.015247598,0.0,0,10.5948,0.0,0.0013349399,2.3820603,10.592584,449.39639,-9.2360754
195.3115,0.16638705,0.015823975,0.0,0,10.5948,0.0,0.0012067803,2.1178298,10.595348,449.39639,-9.235672
195.3159,0.18489778,0.018860614,0.0,0,10.5948,0.0,0.0014718225,2.2640471,10.595715,449.37506,-9.2352467
195.3203,0.18323129,0.015734294,0.0,0,10.5948,0.0,0.0012367346,2.3222542,10.593265,449.33563,-9.2368479
195.3247,0.19240433,0.016940651,0.0,0,10.5948,0.0,0.0014243847,2.4853692,10.596538,449.31351,-9.2360249
195.3291,0.18885371,0.016338551,0.0,0,10.5948,0.0,0.0013115865,2.4188819,10.596647,449.33981,-9.235589
195.3335,0.18978755,0.01815052,0.0,0,10.545862,0.0,0.0014447899,2.3857195,10.59098,449.36609,-9.2370577
195.3379,0.1929433,0.017083229,0.0,0,10.479862,0.0,0.0013520833,2.5300331,10.590506,449.37943,-9.2356958
195.3423,0.20259881,0.020561738,0.0,0,10.413862,0.0,0.0015642758,2.6266847,10.564108,449.39261,-9.2366228
195.3467,0.19110827,0.016323326,0.0,0,10.347862,0.0,0.0012217718,2.4036095,10.48298,449.37778,-9.2355204
195.3511,0.18626186,0.020299327,0.0,0,10.281862,0.0,0.0015108607,2.4322233,10.382606,449.35147,-9.2354107
195.3555,0.19998856,0.018101947,0.0,0,10.215862,0.0,0.0013098848,2.4600441,10.292343,449.34219,-9.2358713
195.3599,0.20856741,0.021545751,0.0,0,10.149862,0.0,0.0016288034,2.612124,10.226187,449.35535,-9.2360382
195.3643,0.20394272,0.019564213,0.0,0,10.083862,0.0,0.0013792712,2.5896063,10.170548,449.3685,-9.2359581
195.3687,0.2034651,0.020534538,0.0,0,10.017862,0.0,0.0015334089,2.6375566,10.116492,449.38162,-9.2366304
195.3731,1.6803622,0.039031215,0.0,0,9.9518623,0.0,0.0026594729,21.124731,10.055156,449.39478,-9.2351093
195.3775,3.672303,0.07396955,0.0,0,9.8858624,0.0,0.0049831267,46.474506,9.9962883,450.13464,-9.2327967
195.3819,4.1762042,0.14362429,0.0,0,9.8198624,0.0,0.0096162511,52.634163,9.9162378,450.97614,-9.2320023
195.3863,4.3686695,0.21938109,0.0,0,9.7538624,0.0,0.014752929,54.816227,9.8372459,451.99118,-9.2335138
195.3907,4.4706931,0.28477547,0.0,0,9.6878614,0.0,0.01913067,55.825672,9.7716494,453.12195,-9.233511
195.3951,4.5482721,0.3505629,0.0,0,9.6218624,0.0,0.023569344,56.527195,9.7087393,453.9599,-9.233099
195.3995,4.6284618,0.41272324,0.0,0,9.5558624,0.0,0.027855804,57.380409,9.6381054,454.18344,-9.2349672
195.4039,4.6427298,0.4828425,0.0,0,9.4898624,0.0,0.032565072,57.277309,9.5709562,454.392,-9.2346888
195.4083,4.690486,0.54576933,0.0,0,9.4252844,0.0,0.036915146,57.496601,9.5073462,454.28683,-9.2344246
195.4127,4.7308984,0.61470938,0.0,0,9.3609037,0.0,0.041617874,57.658878,9.433814,454.18164,-9.2334995
195.4171,4.7449908,0.67488158,0.0,0,9.2965221,0.0,0.045853656,57.748291,9.3730078,454.14716,-9.2340994
195.4215,4.755826,0.74045056,0.0,0,9.2321415,0.0,0.050404508,57.604321,9.30513,454.134,-9.2333794
195.4259,4.7711711,0.80089176,0.0,0,9.1677608,0.0,0.054689508,57.522274,9.2451534,454.16605,-9.2343025
195.4303,4.8458433,0.86790627,0.0,0,9.1033802,0.0,0.05926054,58.198654,9.177989,454.24493,-9.2345629
195.4347,4.8882322,0.92899984,0.0,0,9.0389996,0.0,0.063714266,58.371418,9.112709,454.37717,-9.2321968
195.4391,4.8973403,0.99943441,0.0,0,8.974618,0.0,0.068576269,58.244316,9.0430593,454.7059,-9.2340841
195.4435,4.8836102,1.0586015,0.0,0,8.9102383,0.0,0.072998501,57.937534,8.9788132,455.03464,-9.2351313
195.4479,4.9249229,1.1283165,0.0,0,8.8458567,0.0,0.077717856,58.011185,8.9129848,455.49878,-9.2336779
195.4523,4.952105,1.1825262,0.0,0,8.7814751,0.0,0.081906959,58.056168,8.8504963,455.97214,-9.2343569
195.4567,4.9855838,1.2515538,0.0,0,8.7187147,0.0,0.086653441,58.277493,8.7854843,456.30679,-9.2330875
195.4611,5.0013695,1.3136972,0.0,0,8.657485,0.0,0.091374733,58.1217,8.7187815,456.56976,-9.2331753
195.4655,4.9769077,1.3788589,0.0,0,8.5962543,0.0,0.095995083,57.579304,8.6581993,456.75742,-9.2327108
195.4699,5.0297217,1.4319855,0.0,0,8.5350246,0.0,0.10009786,57.942677,8.5977716,456.82315,-9.2339916
195.4743,5.0617037,1.494749,0.0,0,8.473794,0.0,0.10466461,58.111584,8.5340366,456.89026,-9.2345076
195.4787,5.0787773,1.5562956,0.0,0,8.4125633,0.0,0.10925627,57.926331,8.4762096,456.96915,-9.2337751
195.4831,5.0959425,1.620362,0.0,0,8.3513317,0.0,0.11402453,57.903641,8.4072266,457.04807,-9.2338428
195.4875,5.1490903,1.6800381,0.0,0,8.290102,0.0,0.11854101,58.09129,8.3448496,457.08344,-9.2324276
195.4919,5.1501865,1.7419199,0.0,0,8.2288713,0.0,0.12315888,57.950962,8.2835321,457.10974,-9.2331333
195.4963,5.1558723,1.7993809,0.0,0,8.1676416,0.0,0.12762213,57.875378,8.2214012,457.17221,-9.2332106
195.5007,5.1612096,1.861478,0.0,0,8.106411,0.0,0.13225883,57.613495,8.1611223,457.26425,-9.2346087
195.5051,5.2544293,1.9176248,0.0,0,8.0456285,0.0,0.13656171,58.28685,8.0995941,457.30606,-9.2343693
195.5095,5.2770267,1.9849889,0.0,0,7.9873724,0.0,0.14178781,58.445419,8.0376978,457.21405,-9.233263
195.5139,5.2486157,2.0425644,0.0,0,7.9291158,0.0,0.14625077,57.759491,7.9703455,457.12201,-9.2338324
195.5183,5.2320814,2.102073,0.0,0,7.8708601,0.0,0.15085277,57.326019,7.9157858,456.59802,-9.2340059
195.5227,5.2993412,2.1573,0.0,0,7.812604,0.0,0.1552366,57.680511,7.8554177,456.07208,-9.2336464
195.5271,5.3227735,2.2165604,0.0,0,7.7543483,0.0,0.15992732,57.827805,7.7982883,455.74445,-9.2336121
195.5315,5.3129883,2.2703698,0.0,0,7.6960926,0.0,0.16411611,57.387405,7.7406487,455.49463,-9.2344933
195.5359,5.3453054,2.3268306,0.0,0,7.6378365,0.0,0.16862297,57.550266,7.6848445,455.37814,-9.2338085
195.5403,5.3856406,2.3837216,0.0,0,7.5795803,0.0,0.17314175,57.642445,7.62361,455.43076,-9.2334061
195.5447,5.4366603,2.4449334,0.0,0,7.5213242,0.0,0.17797749,57.913029,7.5665522,455.47687,-9.2316246
195.5491,5.4516296,2.5009279,0.0,0,7.4630685,0.0,0.18252134,57.893055,7.5068378,455.49002,-9.2328568
195.5535,5.4642382,2.5630789,0.0,0,7.4048119,0.0,0.18752807,57.719345,7.4467731,455.50317,-9.2329493
195.5579,5.4740229,2.6186833,0.0,0,7.3488002,0.0,0.19209985,57.444847,7.3835115,455.79602,-9.233079
195.5623,5.5205917,2.6756725,0.0,0,7.2933955,0.0,0.19663849,57.719215,7.3264146,456.12476,-9.2326422
195.5667,5.5035553,2.7318647,0.0,0,7.2379904,0.0,0.20135126,57.376015,7.2714729,456.52551,-9.2339888
195.5711,5.4894032,2.7849889,0.0,0,7.1825857,0.0,0.20560242,56.958336,7.2176957,456.97256,-9.2336063
195.5755,5.5393991,2.8389623,0.0,0,7.1271806,0.0,0.21012701,57.14119,7.1666207,456.7084,-9.2344246
195.5799,5.6045332,2.8919978,0.0,0,7.0717764,0.0,0.21448167,57.496712,7.1090083,455.01227,-9.2331905
195.5843,5.6260114,2.950767,0.0,0,7.0163713,0.0,0.21944736,57.543121,7.0501361,453.30322,-9.2329988
195.5887,5.6191225,3.0051429,0.0,0,6.9609666,0.0,0.22387017,57.173912,6.9942622,451.37042,-9.234808
195.5931,5.6370006,3.0594409,0.0,0,6.9055619,0.0,0.22846815,57.101925,6.9374809,449.43759,-9.234725
195.5975,5.6673093,3.1122968,0.0,0,6.8501573,0.0,0.23278776,57.181904,6.8856926,449.26263,-9.2345943
195.6019,5.7198219,3.1688342,0.0,0,6.7947516,0.0,0.23768106,57.406757,6.8296103,449.59131,-9.2328882
195.6063,5.7369299,3.2229953,0.0,0,6.7404871,0.0,0.24217108,57.341988,6.7712989,450.14532,-9.2337656
195.6107,5.7472587,3.2822313,0.0,0,6.6877751,0.0,0.24728507,57.136791,6.7161536,450.85535,-9.2330055
195.6151,5.7654719,3.3327076,0.0,0,6.6350627,0.0,0.25153849,57.087124,6.6622353,451.49112,-9.2330036
195.6195,5.8033032,3.3890519,0.0,0,6.5823512,0.0,0.25631079,57.190651,6.6063533,451.96448,-9.2331734
195.6239,5.7870026,3.4382854,0.0,0,6.5296392,0.0,0.26058549,56.806168,6.5546932,452.42969,-9.2342234
195.6283,5.8191676,3.4922271,0.0,0,6.4769273,0.0,0.26528496,56.793743,6.5029473,452.6795,-9.2343302
195.6327,5.8633599,3.542702,0.0,0,6.4242153,0.0,0.2695004,56.982372,6.4539499,452.92932,-9.2337933
195.6371,5.9147487,3.5992119,0.0,0,6.3715034,0.0,0.27457714,57.252808,6.3959422,452.69006,-9.2325296
195.6415,5.920155,3.6519308,0.0,0,6.3187914,0.0,0.27911088,57.054935,6.3410816,452.29562,-9.2319622
195.6459,5.9233251,3.7081068,0.0,0,6.2660789,0.0,0.28407905,56.738766,6.28619,451.7998,-9.23242
195.6503,5.9597497,3.7577746,0.0,0,6.213367,0.0,0.28842908,56.875767,6.2357101,451.19498,-9.2339506
195.6547,5.9833984,3.8126676,0.0,0,6.16081,0.0,0.29330251,56.815926,6.1839409,450.73807,-9.2340765
195.6591,5.9968233,3.8596437,0.0,0,6.1106753,0.0,0.29749826,56.710865,6.1345296,450.85641,-9.2323427
195.6635,6.0052953,3.9168096,0.0,0,6.0605421,0.0,0.30252472,56.527637,6.0797853,450.97473,-9.2332706
195.6679,6.0495839,3.9654312,0.0,0,6.0104084,0.0,0.30694982,56.674187,6.0290565,451.42227,-9.2329426
195.6723,6.0598516,4.0190191,0.0,0,5.9602747,0.0,0.31167716,56.495949,5.9781117,451.89563,-9.2326212
195.6767,6.0810051,4.063436,0.0,0,5.9101415,0.0,0.31576821,56.468838,5.9282212,452.41171,-9.2322769
195.6811,6.0878935,4.1163502,0.0,0,5.8600078,0.0,0.32046726,56.271503,5.8768129,452.95081,-9.2332926
195.6855,6.1250205,4.162796,0.0,0,5.8098741,0.0,0.32490471,56.328754,5.826715,453.55359,-9.2336121
195.6899,6.1724257,4.2178817,0.0,0,5.7597404,0.0,0.32973844,56.539284,5.7801414,454.26361,-9.233202
195.6943,6.2100844,4.2633572,0.0,0,5.7096066,0.0,0.33411625,56.54987,5.7283192,454.97739,-9.2330151
195.6987,6.2118759,4.3194284,0.0,0,5.6594734,0.0,0.33916149,56.418365,5.6751132,455.72684,-9.2332544
195.7031,6.2287097,4.3649273,0.0,0,5.6093397,0.0,0.34360686,56.291435,5.6241622,456.47629,-9.2346306
195.7075,6.29287,4.4199657,0.0,0,5.5609026,0.0,0.34856781,56.54752,5.5729046,457.08591,-9.2325392
195.7119,6.2949567,4.4644632,0.0,0,5.5132065,0.0,0.35300192,56.273521,5.524148,457.6644,-9.2337904
195.7163,6.2484818,4.5139513,0.0,0,5.4655108,0.0,0.35739872,55.686241,5.4822488,458.17169,-9.2339134
195.7207,6.2995677,4.5580401,0.0,0,5.4178147,0.0,0.36178994,55.842472,5.4314446,458.6185,-9.2332706
195.7251,6.3700924,4.608273,0.0,0,5.3701186,0.0,0.36636895,56.255543,5.3799515,459.03754,-9.2322655
195.7295,6.3850317,4.6540985,0.0,0,5.3224225,0.0,0.37101719,56.13018,5.3355584,459.379,-9.2327805
195.7339,6.4156127,4.7032547,0.0,0,5.2747273,0.0,0.37567481,56.190536,5.2892289,459.72046,-9.2336168
195.7383,6.4182343,4.7497077,0.0,0,5.2270308,0.0,0.3803761,55.889381,5.2401328,460.02298,-9.2332563
195.7427,6.4639502,4.8017869,0.0,0,5.1793351,0.0,0.38539124,56.007008,5.1907878,460.32498,-9.2336226
195.7471,6.4895811,4.8440108,0.0,0,5.131639,0.0,0.38956803,56.028664,5.1435962,460.64563,-9.2337217
195.7515,6.4915304,4.8949976,0.0,0,5.0839429,0.0,0.39453188,55.749733,5.0991058,460.97388,-9.2328644
195.7559,6.5261617,4.9364257,0.0,0,5.0370216,0.0,0.39869538,55.800552,5.0484314,461.22845,-9.232337
195.7603,6.5741758,4.9873824,0.0,0,4.9916582,0.0,0.40378642,55.860237,5.0045476,461.38602,-9.2333708
195.7647,6.6226125,5.0316081,0.0,0,4.9462938,0.0,0.40834072,56.051926,4.9584179,461.52734,-9.2335472
195.7691,6.6078033,5.0797768,0.0,0,4.9009299,0.0,0.41309616,55.720753,4.9088731,461.57986,-9.2323942
195.7735,6.6474257,5.122972,0.0,0,4.8555655,0.0,0.41763872,55.732658,4.8642278,461.63242,-9.2331047
195.7779,6.6645122,5.1740041,0.0,0,4.8102021,0.0,0.42274535,55.625832,4.8141451,460.18622,-9.233139
195.7823,6.6753502,5.2142181,0.0,0,4.7648377,0.0,0.42696294,55.445148,4.7709441,458.53036,-9.2331553
195.7867,6.6861501,5.257709,0.0,0,4.7194738,0.0,0.43135315,55.305988,4.7267432,456.40909,-9.2336903
195.7911,6.7004724,5.3019152,0.0,0,4.6741099,0.0,0.43605614,55.258121,4.6912222,453.97754,-9.2337933
195.7955,6.7893252,5.3470984,0.0,0,4.628746,0.0,0.44069195,55.625877,4.6380668,451.63055,-9.2350445
195.7999,6.8265228,5.3920469,0.0,0,4.5833821,0.0,0.44538659,55.649879,4.5954604,449.46109,-9.2322216
195.8043,6.8466883,5.4378004,0.0,0,4.5380177,0.0,0.45038551,55.655293,4.5460901,447.30774,-9.2330608
195.8087,6.8655305,5.4785433,0.0,0,4.4947934,0.0,0.45456269,55.471687,4.5029659,445.49292,-9.2336512
195.8131,6.8960171,5.5265398,0.0,0,4.4516382,0.0,0.45967406,55.429092,4.4579334,443.67813,-9.2322435
195.8175,6.9590516,5.5695567,0.0,0,4.408483,0.0,0.4643665,55.708611,4.4120278,443.18674,-9.234045
195.8219,6.9841256,5.6163363,0.0,0,4.3653278,0.0,0.46933958,55.616013,4.3708,443.0947,-9.2332764
195.8263,6.957128,5.6569376,0.0,0,4.3221726,0.0,0.47370255,55.178761,4.3250628,442.97675,-9.231638
195.8307,6.9894986,5.7013912,0.0,0,4.2790174,0.0,0.47857678,55.181072,4.2825384,442.83188,-9.2323008
195.8351,7.0747652,5.7455201,0.0,0,4.2358623,0.0,0.48338905,55.553299,4.2381968,442.44788,-9.2331142
195.8395,7.1129489,5.7886138,0.0,0,4.1927071,0.0,0.48806712,55.609505,4.197927,441.18384,-9.2324467
195.8439,7.1017938,5.8327589,0.0,0,4.1495519,0.0,0.49293804,55.224491,4.1525674,439.91977,-9.2343454
195.8483,7.1044836,5.8756852,0.0,0,4.1063967,0.0,0.49755242,55.052067,4.1140962,438.23633,-9.2328272
195.8527,7.1743689,5.9182391,0.0,0,4.0632415,0.0,0.50235593,55.258652,4.0677667,436.52438,-9.2336569
195.8571,7.2177453,5.957551,0.0,0,4.0213637,0.0,0.50666744,55.401024,4.0291634,435.68909,-9.2332335
195.8615,7.2759428,6.0032506,0.0,0,3.9803212,0.0,0.51181006,55.481632,3.9844496,435.30719,-9.232523
195.8659,7.289206,6.0483613,0.0,0,3.9392779,0.0,0.51675147,55.408779,3.940475,435.6192,-9.2329702
195.8703,7.3068566,6.0899491,0.0,0,3.8982346,0.0,0.5214268,55.186268,3.8979597,437.0546,-9.23244
195.8747,7.3195233,6.1270943,0.0,0,3.8571913,0.0,0.52559352,55.088451,3.8603253,438.53815,-9.232626
195.8791,7.3492417,6.1675048,0.0,0,3.8161483,0.0,0.53010541,55.091164,3.8198557,440.4339,-9.2331095
195.8835,7.3834214,6.2079811,0.0,0,3.775105,0.0,0.53467536,55.099533,3.7816467,442.32968,-9.2339716
195.8879,7.4453402,6.2490993,0.0,0,3.7340617,0.0,0.53934294,55.220776,3.7376211,443.7348,-9.2328806
195.8923,7.5200882,6.2913132,0.0,0,3.6930187,0.0,0.54418319,55.533016,3.6976461,445.03748,-9.2335587
195.8967,7.5866618,6.3370066,0.0,0,3.6519752,0.0,0.54940033,55.802364,3.6552687,446.04309,-9.2330904
195.9011,7.5952616,6.3784184,0.0,0,3.6109321,0.0,0.55413783,55.566921,3.6098595,446.80573,-9.2327261
195.9055,7.619875,6.4226718,0.0,0,3.5703716,0.0,0.55932307,55.403442,3.571775,447.5719,-9.2331543
195.9099,7.6622858,6.4608603,0.0,0,3.5313258,0.0,0.56360644,55.533749,3.5269666,448.34766,-9.2331839
195.9143,7.6956754,6.5044336,0.0,0,3.4922802,0.0,0.56871867,55.472027,3.4893146,449.12341,-9.2330084
195.9187,7.6837511,6.5420589,0.0,0,3.4532349,0.0,0.57309139,55.126179,3.4487231,449.57193,-9.2344055
195.9231,7.6680322,6.5800633,0.0,0,3.4141889,0.0,0.57746089,54.813171,3.4161966,450.01898,-9.2335901
195.9275,7.7526069,6.6143265,0.0,0,3.3751433,0.0,0.5816828,55.202946,3.3776162,450.21106,-9.233717
195.9319,7.8439145,6.6568012,0.0,0,3.3360977,0.0,0.58654279,55.514107,3.3399878,450.3031,-9.2337675
195.9363,7.9041834,6.6937103,0.0,0,3.2970521,0.0,0.59097207,55.74176,3.2967927,450.38354,-9.2323341
195.9407,7.9213238,6.7363715,0.0,0,3.2580068,0.0,0.59600544,55.583359,3.2600939,450.44928,-9.2338247
195.9451,7.9693489,6.7746587,0.0,0,3.218961,0.0,0.60065097,55.631836,3.2193754,450.47415,-9.2324705
195.9495,8.0365553,6.8153968,0.0,0,3.1799152,0.0,0.60538065,55.873077,3.1803806,450.29007,-9.2327719
195.9539,8.0809221,6.8514695,0.0,0,3.1408699,0.0,0.60988522,55.897255,3.1398239,450.10599,-9.2336493
195.9583,8.0860558,6.8975229,0.0,0,3.1034927,0.0,0.61530137,55.661774,3.1037927,449.43243,-9.2333574
195.9627,8.1397247,6.9304819,0.0,0,3.0663478,0.0,0.61950606,55.757748,3.0678954,448.69614,-9.2323065
195.9671,8.2157154,6.9717069,0.0,0,3.0292032,0.0,0.62449378,56.010376,3.0255666,448.34424,-9.2337074
195.9715,8.2571611,7.0086393,0.0,0,2.9920585,0.0,0.62911981,56.081696,2.9910204,448.23904,-9.2337227
195.9759,8.253562,7.048172,0.0,0,2.9549136,0.0,0.63388211,55.737476,2.9514036,448.1644,-9.2338533
195.9803,8.2955523,7.0811071,0.0,0,2.9177687,0.0,0.6382457,55.780613,2.9160712,448.15125,-9.2322102
195.9847,8.34937,7.1189713,0.0,0,2.8806238,0.0,0.64283085,55.926243,2.8788872,448.12589,-9.2317715
195.9891,8.3926105,7.1542373,0.0,0,2.8434792,0.0,0.64752251,55.940498,2.8423412,447.88922,-9.2329721
195.9935,8.4694347,7.1939063,0.0,0,2.8063343,0.0,0.65219796,56.161728,2.8032689,447.65256,-9.2328176
195.9979,8.5487261,7.2287817,0.0,0,2.7691894,0.0,0.65708762,56.37912,2.7661176,448.09042,-9.2343264
196.0023,8.6121778,7.2711873,0.0,0,2.7320449,0.0,0.66214371,56.592823,2.7280965,448.72156,-9.2338142
196.0067,8.6071978,7.3038979,0.0,0,2.6958323,0.0,0.6666286,56.291344,2.691673,449.53018,-9.2332096
196.0111,8.6231699,7.341651,0.0,0,2.6605003,0.0,0.67148018,56.09742,2.6548324,450.5163,-9.2333717
196.0155,8.6457605,7.3731585,0.0,0,2.6251683,0.0,0.67574316,56.020824,2.6262877,451.47607,-9.2332916
196.0199,8.7551527,7.4106693,0.0,0,2.5898364,0.0,0.68060899,56.386917,2.5873845,452.34387,-9.2322693
196.0243,8.8376369,7.4452176,0.0,0,2.5545044,0.0,0.68521863,56.713051,2.5490813,453.21164,-9.2328978
196.0287,8.8885241,7.480969,0.0,0,2.5191722,0.0,0.68999612,56.753712,2.5127146,453.88055,-9.2341614
196.0331,8.9003019,7.5166211,0.0,0,2.4838402,0.0,0.69478792,56.520252,2.4746604,454.53796,-9.234355
196.0375,8.9494648,7.5551229,0.0,0,2.4485083,0.0,0.69994801,56.519718,2.4437852,455.12509,-9.2329941
196.0419,9.0199718,7.5856175,0.0,0,2.4131763,0.0,0.7041291,56.811295,2.4093378,455.67734,-9.2333269
196.0463,9.0418043,7.6227965,0.0,0,2.3778443,0.0,0.70918727,56.665459,2.3747249,456.07535,-9.2337885
196.0507,9.103281,7.6541114,0.0,0,2.3425124,0.0,0.71367913,56.726273,2.3397369,456.23312,-9.2336483
196.0551,9.2016935,7.6929841,0.0,0,2.3074398,0.0,0.7189256,57.080761,2.3022039,456.39243,-9.2328663
196.0595,9.2901773,7.7248201,0.0,0,2.2738326,0.0,0.72342283,57.402817,2.2676754,456.56335,-9.2335014
196.0639,9.3062687,7.7640257,0.0,0,2.2402256,0.0,0.72891295,57.16098,2.2327495,456.73428,-9.2338037
196.0683,9.3055477,7.7949357,0.0,0,2.2066183,0.0,0.73320878,56.896027,2.1976986,456.60831,-9.2328062
196.0727,9.3590536,7.8297114,0.0,0,2.1730111,0.0,0.73811829,56.947941,2.1637709,456.42422,-9.2332754
196.0771,9.4496861,7.8604898,0.0,0,2.1394038,0.0,0.74242979,57.251377,2.1336198,455.66675,-9.2329159
196.0815,9.5207891,7.8955131,0.0,0,2.1057966,0.0,0.7475099,57.449593,2.0975354,454.45709,-9.2323141
196.0859,9.5233221,7.9245858,0.0,0,2.0721896,0.0,0.75169933,57.202671,2.0648234,452.79895,-9.2330379
196.0903,9.610404,7.9621091,0.0,0,2.0385823,0.0,0.75700533,57.373249,2.034018,449.99808,-9.2329988
196.0947,9.7017756,7.9923368,0.0,0,2.0049751,0.0,0.76148731,57.667606,2.0055504,447.19647,-9.2325792
196.0991,9.8059797,8.0271263,0.0,0,1.9713678,0.0,0.76653677,58.039436,1.9689457,444.23642,-9.2313528
196.1035,9.9049492,8.0641603,0.0,0,1.9377607,0.0,0.7719925,58.272758,1.93239,441.27637,-9.2322359
196.1079,9.9835978,8.0992632,0.0,0,1.9054416,0.0,0.7770344,58.472061,1.898479,439.02292,-9.2334633
196.1123,10.044026,8.1356916,0.0,0,1.8734711,0.0,0.7823875,58.457432,1.861414,437.03442,-9.23248
196.1167,10.041223,8.1687784,0.0,0,1.8415009,0.0,0.78734845,58.191174,1.8311341,435.48447,-9.232954
196.1211,9.9521904,8.1979856,0.0,0,1.8095305,0.0,0.79162973,57.391075,1.7984439,434.47049,-9.2328358
196.1255,10.035729,8.2276249,0.0,0,1.7775601,0.0,0.79594511,57.622021,1.7725891,433.7363,-9.2324467
196.1299,10.175735,8.2582092,0.0,0,1.7455896,0.0,0.80067134,58.130787,1.7401284,434.34207,-9.2327175
196.1343,10.282582,8.2871189,0.0,0,1.7136192,0.0,0.80486768,58.527988,1.7092779,434.94781,-9.2334204
196.1387,10.377301,8.3221054,0.0,0,1.6816489,0.0,0.8102237,58.805519,1.6741934,435.35312,-9.2334194
196.1431,10.427728,8.3548422,0.0,0,1.6496783,0.0,0.81520462,58.744537,1.6405027,435.73499,-9.2321367
196.1475,10.524594,8.3874235,0.0,0,1.617708,0.0,0.81994748,59.002426,1.6085519,436.60535,-9.2323446
196.1519,10.565832,8.4200878,0.0,0,1.5857376,0.0,0.82476848,58.947441,1.580959,437.77737,-9.2321796
196.1563,10.617085,8.4495382,0.0,0,1.5544266,0.0,0.82941496,58.99065,1.5485108,439.23209,-9.2325153
196.1607,10.67633,8.481699,0.0,0,1.5240138,0.0,0.83411068,59.041389,1.5188328,441.23331,-9.2325563
196.1651,10.79465,8.5135355,0.0,0,1.493601,0.0,0.83896393,59.367657,1.4859109,443.19171,-9.2328548
196.1695,10.882825,8.5461178,0.0,0,1.4631881,0.0,0.84382653,59.622253,1.4538565,444.52029,-9.2328959
196.1739,10.952353,8.577981,0.0,0,1.4327753,0.0,0.84875679,59.661304,1.4261242,445.84888,-9.2337217
196.1783,10.975232,8.607935,0.0,0,1.4023625,0.0,0.8533206,59.537872,1.3929125,445.50134,-9.2339268
196.1827,11.076049,8.6388311,0.0,0,1.3719497,0.0,0.858284,59.738171,1.3658839,444.69849,-9.2328281
196.1871,11.227677,8.6684895,0.0,0,1.3415369,0.0,0.8629722,60.356068,1.3336774,443.97638,-9.2330217
196.1915,11.242414,8.7013969,0.0,0,1.3111242,0.0,0.86792445,60.145996,1.3001317,443.33209,-9.232585
196.1959,11.254575,8.7286873,0.0,0,1.2807113,0.0,0.8722434,59.926491,1.2738941,443.1239,-9.2324648
196.2003,11.358633,8.7600908,0.0,0,1.2502985,0.0,0.87706399,60.160423,1.2434373,444.36066,-9.2343235
196.2047,11.514194,8.7895184,0.0,0,1.2199748,0.0,0.88183105,60.722664,1.2110814,445.59741,-9.2323761
196.2091,11.561023,8.8217344,0.0,0,1.1910489,0.0,0.88675994,60.632393,1.1835647,446.40665,-9.2322845
196.2135,11.601648,8.8456526,0.0,0,1.1621233,0.0,0.89064074,60.6133,1.1556047,447.19556,-9.233304
196.2179,11.686049,8.8782654,0.0,0,1.1331977,0.0,0.89557379,60.7509,1.1245871,447.81525,-9.2337494
196.2223,11.831375,8.9051876,0.0,0,1.1042721,0.0,0.90010369,61.222019,1.0958232,448.35434,-9.2328453
196.2267,11.906565,8.937933,0.0,0,1.0753465,0.0,0.90527838,61.337761,1.0650591,448.77246,-9.2320471
196.2311,11.950453,8.9613295,0.0,0,1.0464209,0.0,0.90925276,61.307991,1.0360279,449.00912,-9.2315989
196.2355,12.01998,8.9942923,0.0,0,1.0174953,0.0,0.91442871,61.345345,1.0098733,449.27808,-9.2319555
196.2399,12.113535,9.017374,0.0,0,0.98856962,0.0,0.91849357,61.549225,0.98076642,449.77771,-9.2316904
196.2443,12.217407,9.0503416,0.0,0,0.95964396,0.0,0.92360228,61.770115,0.9525966,450.27734,-9.2316608
196.2487,12.281866,9.0718298,0.0,0,0.93071842,0.0,0.92766809,61.834019,0.92394978,450.37677,-9.2316532
196.2531,12.420766,9.1037683,0.0,0,0.90179276,0.0,0.93252748,62.224586,0.89579064,450.40308,-9.2333288
196.2575,12.537037,9.1274805,0.0,0,0.87385333,0.0,0.93709934,62.481663,0.86968797,450.43686,-9.2324142
196.2619,12.703186,9.1612244,0.0,0,0.84634447,0.0,0.94219726,63.006413,0.8405745,450.47629,-9.2322893
196.2663,12.767942,9.1883717,0.0,0,0.81883568,0.0,0.94729626,63.02034,0.80976784,450.05664,-9.2322378
196.2707,12.850374,9.2196426,0.0,0,0.79132688,0.0,0.95231253,63.13662,0.78092897,448.51801,-9.2330132
196.2751,12.957583,9.2466135,0.0,0,0.76381809,0.0,0.95713902,63.303726,0.75076246,446.95673,-9.2322998
196.2795,12.962579,9.2736464,0.0,0,0.73630929,0.0,0.96181005,63.109528,0.72709364,443.75949,-9.2329168
196.2839,12.982395,9.2952795,0.0,0,0.70880049,0.0,0.96594602,62.923676,0.70051396,440.56229,-9.2331724
196.2883,13.110912,9.3231945,0.0,0,0.6812917,0.0,0.9705959,63.251377,0.6764738,437.70239,-9.2333879
196.2927,13.318765,9.3467913,0.0,0,0.6537829,0.0,0.9748677,63.935631,0.64600962,434.96326,-9.2323475
196.2971,13.509038,9.3770714,0.0,0,0.62627411,0.0,0.98029608,64.515945,0.62141693,433.07056,-9.2322302
196.3015,13.575016,9.4038086,0.0,0,0.59876531,0.0,0.98511994,64.564514,0.58829999,432.17508,-9.232233
196.3059,13.579453,9.4319162,0.0,0,0.57169825,0.0,0.9902007,64.231705,0.56413084,431.62442,-9.2334251
196.3103,13.295475,9.4521923,0.0,0,0.54551822,0.0,0.99394482,62.699844,0.53609937,432.62527,-9.2327738
196.3147,12.346067,9.4602528,0.0,0,0.51933819,0.0,0.9954133,58.131508,0.5206151,433.6261,-9.2330751
196.3191,11.862922,9.463068,0.0,0,0.49315819,0.0,0.99614966,55.811779,0.50751209,434.82944,-9.2341413
196.3235,11.587401,9.4739799,0.0,0,0.46697822,0.0,0.99820262,54.354664,0.49038997,436.05414,-9.2346106
196.3279,11.331155,9.4759064,0.0,0,0.44079819,0.0,0.99875951,53.160721,0.47323743,437.56796,-9.2340546
196.3323,11.008574,9.4791679,0.0,0,0.41461822,0.0,0.99921072,51.650555,0.45105296,439.25357,-9.2345848
196.3367,10.719274,9.4798355,0.0,0,0.38843817,0.0,0.99950784,50.247467,0.42901966,440.93884,-9.2360563
196.3411,10.351689,9.4819307,0.0,0,0.36225817,0.0,1.0001888,48.467728,0.42381656,442.6235,-9.233532
196.3455,10.00906,9.4832401,0.0,0,0.33607817,0.0,1.00046,46.872021,0.41812488,444.31094,-9.2354393
196.3499,9.8430128,9.4848919,0.0,0,0.30989817,0.0,1.0008582,46.083057,0.4046787,446.03372,-9.2351332
196.3543,9.8314095,9.482583,0.0,0,0.2837182,0.0,1.0004987,46.030781,0.38676286,447.75653,-9.2366562
196.3587,10.006591,9.4869757,0.0,0,0.25878283,0.0,1.0014287,46.813625,0.36147064,449.35352,-9.2348137
196.3631,10.237675,9.4867296,0.0,0,0.23388766,0.0,1.001708,47.876209,0.32680944,450.91818,-9.2347679
196.3675,10.399725,9.4937353,0.0,0,0.2089925,0.0,1.0029063,48.544491,0.29195207,452.14215,-9.2333479
196.3719,10.523726,9.4938097,0.0,0,0.18409729,0.0,1.0030326,49.133282,0.25951448,453.04938,-9.2340355
196.3763,10.557055,9.502017,0.0,0,0.1592021,0.0,1.0044351,49.232403,0.23297481,453.85526,-9.2345343
196.3807,10.508981,9.5009136,0.0,0,0.13430689,0.0,1.0044831,49.048981,0.20484067,454.34177,-9.2346745
196.3851,10.449662,9.503787,0.0,0,0.10941169,0.0,1.005128,48.683136,0.17879359,454.82828,-9.2330332
196.3895,10.416069,9.5069466,0.0,0,0.084516473,0.0,1.0056978,48.479351,0.15455875,455.18805,-9.23384
196.3939,10.355885,9.5073891,0.0,0,0.059621278,0.0,1.0057249,48.220215,0.1324216,455.54306,-9.234355
196.3983,10.285198,9.5134716,0.0,0,0.034726076,0.0,1.0069643,47.859901,0.11401018,455.7988,-9.2337885
196.4027,10.203193,9.511775,0.0,0,0.0098308772,0.0,1.0065714,47.478683,0.088159069,456.00919,-9.2333708
196.4071,10.147417,9.5160055,0.0,0,-0.014696904,0.0,1.0074185,47.169739,0.071757823,456.17651,-9.2335634
196.4115,10.084356,9.5141315,0.0,0,-0.038984902,0.0,1.0071893,46.888226,0.057239331,456.28168,-9.2347383
196.4159,9.9818754,9.5172987,0.0,0,-0.063272901,0.0,1.0077317,46.397682,0.042548116,456.38684,-9.2341557
196.4203,9.8712692,9.5213451,0.0,0,-0.0875609,0.0,1.0084281,45.86935,0.025504585,456.49207,-9.2337132
196.4247,9.7863894,9.5219154,0.0,0,-0.080402613,439.72598,1.0083839,45.441822,0.014820044,456.59726,-9.2337551
196.4291,9.6688471,9.5232573,0.0,0,0.71588182,450.0,1.0084682,44.881401,0.0051806164,456.84851,-9.2351723
196.4335,7.9864526,9.5217209,0.0,0,1.5127399,450.0,1.008268,37.277344,0.077933677,457.1246,-9.2353802
196.4379,3.9441273,9.5005074,0.0,0,2.3095984,450.0,1.0043145,18.582434,0.3199555,457.38556,-9.2386312
196.4423,-0.11990297,9.4628849,0.0,0,3.1064556,450.0,0.99724346,-0.43738723,0.88392454,457.63538,-9.2431803
196.4467,0.13560452,9.4774399,0.0,0,3.9033134,450.0,0.99990827,0.56664866,2.2080424,457.85757,-9.2424164
196.4511,-0.18022169,9.4846668,0.0,0,4.7001705,450.0,1.001159,-0.81255633,3.2779486,458.01535,-9.2394915
196.4555,0.0079923458,9.4741116,0.0,0,5.4970284,450.0,0.99898899,0.084188424,4.0593643,458.17285,-9.2394247
196.4599,0.042697895,9.476696,0.0,0,6.2938862,450.0,0.99949121,0.19875512,4.8101053,458.31744,-9.2401333
196.4643,0.025091372,9.4729033,0.0,0,7.0907435,450.0,0.99849856,0.16050054,5.5773387,458.46207,-9.2370033
196.4687,-0.081021592,9.4777431,0.0,0,7.8876014,450.0,0.99928856,-0.35466242,6.374114,458.57727,-9.2372599
196.4731,0.022036176,9.4740677,0.0,0,8.6844587,450.0,0.99871111,0.083602786,7.2076898,458.68243,-9.2376785
196.4775,-0.016657367,9.4736032,0.0,0,9.4813175,450.0,0.99827236,-0.06513676,8.0413542,458.77521,-9.2364817
196.4819,-0.027424727,9.4740734,0.0,0,10.278174,450.0,0.99837899,-0.12344974,8.8652344,458.854,-9.2368221
196.4863,-0.037730079,9.4754505,0.0,0,11.075032,450.0,0.99841511,-0.21654071,9.6794643,458.94028,-9.2366295
196.4907,-0.0027473182,9.4714766,0.0,0,11.87189,450.0,0.99790502,0.0013272306,10.488284,459.0585,-9.2353811
196.4951,-0.019266291,9.4757023,0.0,0,12.668747,450.0,0.99814749,-0.11602193,11.2944,459.1767,-9.2363176
196.4995,-0.027109422,9.4715748,0.0,0,13.465605,450.0,0.99768966,-0.081694752,12.059226,459.23486,-9.2362747
196.5039,0.0089485208,9.4752121,0.0,0,14.262463,450.0,0.99781114,0.064381212,12.834738,459.28738,-9.2345285
196.5083,-0.021753745,9.4731483,0.0,0,15.05932,450.0,0.99768972,-0.15197557,13.640839,459.32318,-9.2339144
196.5127,-0.018133808,9.4757738,0.0,0,15.856178,450.0,0.99772877,-0.093711585,14.435143,459.34946,-9.2343903
196.5171,0.049636625,9.4710646,0.0,0,16.653036,450.0,0.99723864,0.23956208,15.249646,459.3757,-9.2337837
196.5215,-0.036688998,9.4721365,0.0,0,17.449894,450.0,0.9969936,-0.21993499,16.050436,459.40198,-9.2347622
196.5259,-0.04783896,9.4729967,0.0,0,18.0,450.0,0.99756181,-0.2072698,16.838402,459.42932,-9.2339792
196.5303,0.055684097,9.475522,0.0,0,18.0,450.0,0.99746841,0.22756658,17.612383,459.46872,-9.2353783
196.5347,-0.017407659,9.4731874,0.0,0,18.0,450.0,0.99762487,-0.091211982,18.224596,459.50812,-9.2375154
196.5391,0.030223494,9.4861889,0.0,0,18.0,450.0,0.99935776,0.15895113,18.500057,459.55807,-9.2456675
196.5435,0.56098384,9.4960251,0.0,0,18.0,450.0,1.0016028,2.6346388,18.375488,459.6106,-9.2585211
196.5479,0.476062,9.5010042,0.0,0,18.0,450.0,1.0022236,2.21807,18.146189,459.64926,-9.28403
196.5523,0.4918943,9.4949131,0.0,0,18.0,450.0,1.0012025,2.289119,18.044371,459.67551,-9.3172836
196.5567,0.50595009,9.4934883,0.0,0,18.0,450.0,1.0009828,2.3533504,18.053486,459.69849,-9.3552628
196.5611,0.46912548,9.4913445,0.0,0,18.0,450.0,1.0008644,2.2426519,18.100719,459.71161,-9.3941889
196.5655,0.46537748,9.4948835,0.0,0,18.0,450.0,1.0013382,2.1655152,18.134111,459.72473,-9.4286385
196.5699,0.47387251,9.4899235,0.0,0,18.0,450.0,1.0008507,2.2183056,18.144579,459.75064,-9.4603434
196.5743,0.50095189,9.4908972,0.0,0,18.0,450.0,1.0007832,2.3605857,18.138123,459.77692,-9.4928074
196.5787,0.49667555,9.4877005,0.0,0,18.0,450.0,1.0004171,2.3357365,18.1353,459.80319,-9.5258398
196.5831,0.48201191,9.4959173,0.0,0,18.0,450.0,1.0018129,2.2324612,18.127861,459.82944,-9.5593367
196.5875,0.49099731,9.4878693,0.0,0,18.0,450.0,1.0004916,2.2703409,18.122763,459.83374,-9.5914335
196.5919,0.50690132,9.4904928,0.0,0,18.0,450.0,1.0011859,2.3659914,18.120781,459.80746,-9.6245518
196.5963,0.51580137,9.4894047,0.0,0,18.0,450.0,1.0010682,2.4039865,18.11367,459.78882,-9.6593113
196.6007,0.47079244,9.492959,0.0,0,18.0,450.0,1.0018796,2.1965296,18.116932,459.81647,-9.6916628
196.6051,0.47414991,9.4885502,0.0,0,18.0,450.0,1.0011913,2.2027414,18.113415,459.84409,-9.7254858
196.6095,0.50925875,9.4889393,0.0,0,18.0,450.0,1.0014255,2.3595574,18.114363,459.87039,-9.7563772
196.6139,0.51567823,9.4914398,0.0,0,18.0,450.0,1.0017248,2.4310665,18.106134,459.89667,-9.7875414
196.6183,0.48179433,9.4869604,0.0,0,18.0,450.0,1.0012649,2.3123403,18.108181,459.89536,-9.8228836
196.6227,0.48263326,9.4885597,0.0,0,18.0,450.0,1.0016546,2.2598484,18.108995,459.8822,-9.8569937
196.6271,0.48633546,9.486867,0.0,0,18.0,450.0,1.0013647,2.3063359,18.101686,459.85797,-9.8896217
196.6315,0.52332664,9.4882746,0.0,0,18.0,450.0,1.0016713,2.4400218,18.100111,459.81857,-9.9207621
196.6359,0.49177977,9.487462,0.0,0,18.0,450.0,1.0017599,2.3138881,18.099981,459.77728,-9.9553003
196.6403,0.47724921,9.4882326,0.0,0,18.0,450.0,1.0020394,2.1994109,18.099295,459.72476,-9.9894209
196.6447,0.49314696,9.4845715,0.0,0,18.0,450.0,1.0013368,2.2771313,18.098148,459.67224,-10.022488
196.6491,0.53255326,9.4870882,0.0,0,18.0,450.0,1.0019838,2.4619539,18.093348,459.6539,-10.054004
196.6535,0.51040983,9.4872723,0.0,0,18.0,450.0,1.0019796,2.3824263,18.095358,459.64078,-10.088522
196.6579,0.49022797,9.4895792,0.0,0,18.0,450.0,1.0025562,2.3019338,18.087461,459.62766,-10.119109
196.6623,0.50740314,9.4871969,0.0,0,18.0,450.0,1.0020841,2.3704085,18.091049,459.6145,-10.151285
196.6667,0.52837414,9.4871702,0.0,0,18.0,450.0,1.0022807,2.4857593,18.087395,459.6055,-10.184897
196.6711,0.52053809,9.4878168,0.0,0,18.0,450.0,1.0021961,2.4722645,18.087461,459.6055,-10.218534
196.6755,0.50374597,9.488122,0.0,0,18.0,450.0,1.0024332,2.3626537,18.085142,459.60599,-10.250036
196.6799,0.4974781,9.4867563,0.0,0,18.0,450.0,1.0020778,2.3231471,18.085295,459.61911,-10.282294
196.6843,0.52744257,9.4870453,0.0,0,18.0,450.0,1.0022058,2.463896,18.08197,459.63223,-10.315641
196.6887,0.524275,9.4874897,0.0,0,18.0,450.0,1.0020012,2.4500744,18.080399,459.61548,-10.350783
196.6931,0.49905574,9.4914913,0.0,0,18.0,450.0,1.0029635,2.3263485,18.080153,459.58923,-10.384119
196.6975,0.49861601,9.4880505,0.0,0,18.0,450.0,1.0019867,2.3054485,18.080442,459.53134,-10.415726
196.7019,0.52055037,9.4902029,0.0,0,18.0,450.0,1.0025376,2.4303355,18.07497,459.43939,-10.44905
196.7063,0.53298557,9.4908714,0.0,0,18.0,450.0,1.0023366,2.5038891,18.078753,459.3609,-10.481318
196.7107,0.50697213,9.4902973,0.0,0,18.0,450.0,1.0025136,2.3651652,18.07766,459.33463,-10.516255
196.7151,0.49756014,9.4891291,0.0,0,18.0,450.0,1.0019811,2.329102,18.079393,459.30838,-10.548925
196.7195,0.53428477,9.4921398,0.0,0,18.0,450.0,1.0024332,2.458432,18.071873,459.34299,-10.580888
196.7239,0.54249609,9.4922018,0.0,0,18.0,450.0,1.0022799,2.5526385,18.070591,459.38239,-10.61432
196.7283,0.5088833,9.4934254,0.0,0,18.0,450.0,1.0024557,2.3980012,18.071325,459.37912,-10.647001
196.7327,0.50379914,9.4892178,0.0,0,18.0,450.0,1.0016783,2.3786936,18.073435,459.35284,-10.679247
196.7371,0.52559084,9.4934454,0.0,0,18.0,450.0,1.0021534,2.4238522,18.068481,459.33148,-10.713212
196.7415,0.55527991,9.4923372,0.0,0,18.0,450.0,1.0020777,2.5849745,18.067419,459.31833,-10.744735
196.7459,0.51833826,9.4954643,0.0,0,18.0,450.0,1.0022322,2.4236655,18.065151,459.30145,-10.778419
196.7503,0.51640189,9.4930964,0.0,0,18.0,450.0,1.0018148,2.3997152,18.067898,459.24893,-10.810885
196.7547,0.52680129,9.4945078,0.0,0,18.0,450.0,1.0019398,2.4124365,18.064724,459.19641,-10.843144
196.7591,0.55809009,9.4936228,0.0,0,18.0,450.0,1.0018209,2.5922151,18.063986,459.10092,-10.875928
196.7635,0.53139502,9.4954023,0.0,0,18.0,450.0,1.0018461,2.480777,18.063028,458.99585,-10.909906
196.7679,0.5141055,9.4938269,0.0,0,18.0,450.0,1.0016088,2.4157376,18.060215,458.95474,-10.944201
196.7723,0.51168007,9.4948111,0.0,0,18.0,450.0,1.0015216,2.404345,18.061338,458.96786,-10.975322
196.7767,0.55497396,9.4907665,0.0,0,18.0,450.0,1.0011066,2.589772,18.059801,458.97754,-11.007012
196.7811,0.53305513,9.4954567,0.0,0,18.0,450.0,1.0014917,2.5090997,18.059912,458.97754,-11.043495
196.7855,0.50591499,9.4919415,0.0,0,18.0,450.0,1.0012256,2.3885334,18.054041,458.97754,-11.076899
196.7899,0.5189122,9.4962473,0.0,0,18.0,450.0,1.0012877,2.4521811,18.052755,458.91278,-11.106363
196.7943,0.56068939,9.4915962,0.0,0,18.0,450.0,1.0008293,2.6076143,18.051395,458.84714,-11.138107
196.7987,0.5650751,9.496212,0.0,0,18.0,450.0,1.0012177,2.6857994,18.054096,458.80011,-11.172658
196.8031,0.52869326,9.4908237,0.0,0,18.0,450.0,1.0008142,2.449368,18.050045,458.76071,-11.206962
196.8075,0.52272826,9.4954863,0.0,0,18.0,450.0,1.0010264,2.4373095,18.05512,458.70996,-11.24091
196.8119,0.56127256,9.4902077,0.0,0,18.0,450.0,1.0005993,2.5798624,18.049456,458.64426,-11.273201
196.8163,0.5544526,9.4960032,0.0,0,18.0,450.0,1.0012316,2.626852,18.052347,458.58463,-11.306715
196.8207,0.51936215,9.490634,0.0,0,18.0,450.0,1.0006489,2.4513476,18.051178,458.55835,-11.338656
197.1244,0.48497283,9.4917364,0.0,0,18.0,0.036865965,1.0018271,2.266006,18.018291,444.25854,-11.481493
199.3244,0.46573761,9.5069065,0.0,0,18.0,3.6775802e-32,1.004469,2.1736758,18.000141,415.71173,-11.481315
201.5244,0.49457678,9.5187778,0.0,0,18.0,1.4012985e-45,1.0065888,2.2997189,17.99925,393.08624,-11.482525
203.7244,0.50408453,9.5284777,0.0,0,18.0,1.4012985e-45,1.0083536,2.3353415,17.999233,373.9021,-11.4809
205.9244,0.52628922,9.5385389,0.0,0,18.0,1.4012985e-45,1.0102535,2.436769,17.999578,355.98087,-11.481462
208.1244,0.54123122,9.5487795,0.0,0,18.0,1.4012985e-45,1.0121509,2.500335,18.001055,339.71164,-11.48217
210.3244,0.55016232,9.5571146,0.0,0,18.0,1.4012985e-45,1.0137841,2.5474808,18.00152,323.85864,-11.482996
212.5244,0.54889244,9.5666447,0.0,0,18.0,1.4012985e-45,1.0156066,2.5356822,17.999826,309.22327,-11.481857
214.7244,0.55659926,9.5754757,0.0,0,18.0,1.4012985e-45,1.017208,2.5650866,17.999413,295.23471,-11.48204
216.9244,0.56752843,9.5837173,0.0,0,18.0,1.4012985e-45,1.0187223,2.6090488,17.999352,282.32394,-11.481707
219.1244,0.58136135,9.591814,0.0,0,18.0,1.4012985e-45,1.0201617,2.6698794,18.00021,269.78464,-11.482937
221.3244,0.59393036,9.5996876,0.0,0,18.0,1.4012985e-45,1.0215874,2.7228668,17.999166,257.99014,-11.483086
223.5244,0.59787929,9.6071997,0.0,0,18.0,1.4012985e-45,1.0229336,2.7354128,18.000963,246.76117,-11.482925
225.7244,0.59966934,9.6140699,0.0,0,18.0,1.4012985e-45,1.0241964,2.7389448,17.999313,236.34622,-11.482346
227.9244,0.60948431,9.6210737,0.0,0,18.0,1.4012985e-45,1.025483,2.7804699,18.00012,225.866,-11.481913
230.1244,0.63716578,9.6275406,0.0,0,18.0,1.4012985e-45,1.0267057,2.9061437,18.000715,216.24286,-11.481551
232.3244,0.63498086,9.6341629,0.0,0,18.0,1.4012985e-45,1.0279315,2.8932476,17.999088,207.01331,-11.482537
234.5244,0.65473962,9.6398029,0.0,0,18.0,1.4012985e-45,1.0290172,2.9804726,18.000078,198.40784,-11.48303
236.7244,0.64484203,9.6455688,0.0,0,18.0,1.4012985e-45,1.030081,2.9348767,18.000378,190.12531,-11.483192
238.9244,0.63667738,9.6508894,0.0,0,18.0,1.4012985e-45,1.0310622,2.8972845,18.001059,182.40094,-11.481991
241.1244,0.6407454,9.6559982,0.0,0,18.0,1.4012985e-45,1.0320292,2.9108946,17.999784,174.96083,-11.481343
243.3244,0.64626038,9.661272,0.0,0,18.0,1.4012985e-45,1.0330344,2.9319098,18.000484,167.83502,-11.481406
245.5244,0.65908384,9.6658134,0.0,0,18.0,1.4012985e-45,1.033854,2.9842107,17.999346,161.1727,-11.481795
247.7244,0.66726434,9.6707535,0.0,0,18.0,1.4012985e-45,1.0347649,3.0189126,18.000193,154.86253,-11.482682
249.9244,0.6733402,9.6756325,0.0,0,18.0,1.4012985e-45,1.0357108,3.035887,18.000063,148.88655,-11.482852
252.1244,0.66821355,9.6794939,0.0,0,18.0,1.4012985e-45,1.0364252,3.010329,18.000193,142.9536,-11.482591
254.3244,0.67733324,9.6836319,0.0,0,18.0,1.4012985e-45,1.0372082,3.0571852,17.999722,137.25291,-11.481609
256.5244,0.67772275,9.6880732,0.0,0,18.0,1.4012985e-45,1.0380478,3.0556128,18.000713,132.10812,-11.481382
256.8244,0.67846763,9.6885147,0.0,0,18.0,1.4012985e-45,1.0382152,3.0569556,17.998539,131.26788,-11.481232