File: examples/dan-msc-case-studies/CS3/data/01 raw data/baron_test_026.csv
Time(sec),Force(kN),Jaw(mm),PowAngle(deg),Power(W),Pram,PTemp,Strain,Stress(MPa),Stroke(mm),TC1(C),wedge(mm)
0.0,1.0872432,0.54699361,0.0,0,10.594783,0.0010186214,0.03713911,13.300141,10.594673,28.377308,-9.1209784
2.2,0.96287179,-0.0014455584,0.0,0,10.594783,6.5159163,-7.4240757e-05,12.261419,10.594515,28.359333,-9.4895563
4.4,0.91523963,-0.0012071793,0.0,0,10.594783,13.115915,-9.1018534e-05,11.666848,10.595173,28.244186,-9.4858408
6.6,0.8760916,-0.0013777737,0.0,0,10.594783,19.715914,-8.607065e-05,11.163937,10.594475,28.247648,-9.4823446
8.8,0.86793369,-0.0011032039,0.0,0,10.594783,26.315916,-9.3495903e-05,11.05949,10.594806,28.124489,-9.478447
11.0,0.86194575,-8.5229345e-05,26.058773,0,10.594783,32.915913,-1.4030935e-05,10.959284,10.595542,28.16744,-9.4745569
13.2,0.86743832,-0.00080467167,44.039104,0,10.594783,39.515911,-6.3572079e-05,11.04449,10.594378,30.164703,-9.4705076
15.4,0.8864758,-0.0062091565,52.203758,0,10.594783,46.115917,-0.00040820157,11.303135,10.595511,35.993805,-9.4667101
17.6,0.90431559,-0.013826059,55.596767,0,10.594783,52.715919,-0.00092030171,11.544684,10.594784,45.135479,-9.4626217
19.8,0.92483735,-0.022055143,55.84351,0,10.594783,59.315914,-0.0014644761,11.784166,10.594478,56.134521,-9.4587803
22.0,0.94043267,-0.029439006,53.685955,0,10.594783,65.915901,-0.0019458462,11.977112,10.594723,66.921997,-9.4551849
24.2,0.95414072,-0.034976769,50.478123,0,10.594783,72.5159,-0.0023460835,12.16574,10.595228,75.957924,-9.4507284
26.4,0.93855053,-0.039822698,47.505028,0,10.594783,79.115906,-0.002643432,11.98841,10.594599,82.927742,-9.4468288
28.6,0.9133144,-0.043054111,46.582035,0,10.594783,85.715897,-0.0028863002,11.668854,10.595568,87.818306,-9.4427948
30.8,0.90207154,-0.046801515,48.041245,0,10.594783,92.315895,-0.0031169434,11.524287,10.594321,92.054832,-9.438796
33.0,0.91741592,-0.0502728,50.755131,0,10.594783,98.915894,-0.0033612601,11.723635,10.594701,96.515236,-9.4351463
35.2,0.93893224,-0.055436548,53.315563,0,10.594783,105.51588,-0.0036869305,11.98816,10.594266,102.06236,-9.4314737
37.4,0.95112026,-0.061479349,55.056152,0,10.594783,112.11589,-0.0040936745,12.150071,10.594646,108.95226,-9.4274788
39.6,0.95768577,-0.068976782,55.843506,0,10.594783,118.7159,-0.0045938673,12.262121,10.595354,116.5794,-9.4233599
41.8,0.9575848,-0.075443782,55.862007,0,10.594783,125.31589,-0.0049969852,12.27334,10.595756,124.29643,-9.4194336
44.0,0.96819109,-0.081167564,55.84351,0,10.594783,131.91589,-0.0054114652,12.395792,10.594699,131.57729,-9.4154787
46.2,0.9813301,-0.086727127,55.667675,0,10.594783,138.51588,-0.0057521919,12.560666,10.594655,138.5549,-9.4117727
48.4,0.98059738,-0.092511512,55.584419,0,10.594783,145.11589,-0.006165328,12.555072,10.594078,145.17001,-9.4080982
50.6,0.98487657,-0.098103046,55.843506,0,10.594783,151.71588,-0.0065155709,12.62248,10.595478,151.48352,-9.4046764
52.8,0.97929102,-0.10265444,56.425701,0,10.594783,158.31587,-0.0068209018,12.574927,10.595128,157.63579,-9.4008541
55.0,0.97897863,-0.10807686,57.234375,0,10.594783,164.91588,-0.0071766539,12.546148,10.594736,163.64101,-9.3965912
57.2,0.98718625,-0.11392911,57.971813,0,10.594783,171.51587,-0.007551434,12.656762,10.594673,170.03819,-9.3922701
59.4,0.99685001,-0.11958202,58.579208,0,10.594783,178.11588,-0.0079498934,12.786217,10.595071,176.82112,-9.3883858
61.6,1.0050437,-0.12664178,58.98447,0,10.594783,184.71587,-0.0083886841,12.909212,10.594473,183.59349,-9.3852806
63.8,1.0051351,-0.13198918,59.348137,0,10.594783,191.31587,-0.0087736826,12.939362,10.594579,190.34488,-9.3816071
66.0,0.99859583,-0.13892744,59.600826,0,10.594783,197.91588,-0.0092180669,12.858032,10.594122,197.23491,-9.3780603
68.2,0.99089956,-0.14511962,59.450718,0,10.594783,204.5159,-0.0096395835,12.746444,10.594572,204.37122,-9.3738995
70.4,0.99599594,-0.15135887,59.355286,0,10.594783,211.11589,-0.010037033,12.781361,10.595416,211.06885,-9.3700771
72.6,1.0024626,-0.15792148,59.600826,0,10.594783,217.71587,-0.010470144,12.897394,10.595155,217.39731,-9.3658752
74.8,0.99845535,-0.16327998,60.084225,0,10.594783,224.31587,-0.010823974,12.857134,10.594652,223.57278,-9.3626604
77.0,1.0128301,-0.16963904,60.556534,0,10.594783,230.91588,-0.011235818,13.056372,10.594046,229.98311,-9.359293
79.2,1.0006831,-0.17615928,60.98555,0,10.594783,237.51587,-0.011687844,12.885388,10.59422,236.45595,-9.3557243
81.4,1.0066603,-0.18214053,61.237789,0,10.594783,244.11586,-0.0120599,12.979201,10.59496,243.14644,-9.3515587
83.6,1.0166162,-0.18869816,61.675556,0,10.594783,250.71585,-0.012520545,13.08858,10.594224,249.83713,-9.3472958
85.8,1.0155375,-0.19563636,61.907955,0,10.594783,257.31613,-0.012955844,13.105422,10.594223,256.47906,-9.3436794
88.0,1.0178651,-0.20323856,62.116692,0,10.594783,263.91586,-0.013460618,13.144239,10.594002,263.25031,-9.3403912
90.2,1.0045075,-0.20956391,62.233078,0,10.594783,270.51584,-0.013873477,12.969079,10.59551,270.0914,-9.3369617
92.4,1.0130459,-0.21566333,62.336418,0,10.594783,277.11588,-0.014256543,13.087708,10.595159,276.83777,-9.3336134
94.6,1.0147902,-0.22322793,62.336418,0,10.594783,283.71588,-0.014778081,13.10306,10.595397,283.42648,-9.3300915
96.8,1.0095546,-0.2286043,62.545162,0,10.594783,290.31586,-0.0151225,13.054446,10.594096,289.90091,-9.3256435
99.0,1.0210236,-0.23476809,62.753899,0,10.594783,296.91583,-0.015541899,13.208328,10.594564,296.39972,-9.3216906
101.2,1.0113087,-0.24184109,63.049164,0,10.594783,303.51584,-0.015984194,13.105379,10.595246,302.88467,-9.3180075
103.4,1.0109396,-0.24795057,63.383705,0,10.594783,310.11584,-0.016392227,13.078588,10.594751,309.19376,-9.3143845
105.6,1.009015,-0.25566867,63.807636,0,10.594783,316.71585,-0.01689747,13.038766,10.593983,315.69968,-9.3109064
107.8,1.017104,-0.26274511,63.973385,0,10.594783,323.31586,-0.017349103,13.173197,10.594253,322.70151,-9.3075762
110.0,1.0137651,-0.27033105,64.037308,0,10.594783,329.91586,-0.017867597,13.130912,10.595783,329.55969,-9.3039379
112.2,1.0154359,-0.27778947,64.171135,0,10.594783,336.51587,-0.018337259,13.176734,10.594748,336.06342,-9.3002167
114.4,1.0200747,-0.28549778,64.357903,0,10.594783,343.11588,-0.018874586,13.234414,10.59425,342.54916,-9.2970085
116.6,1.0144912,-0.29154232,64.742432,0,10.594783,349.71588,-0.019243011,13.169956,10.594637,348.8252,-9.2932358
118.8,1.0212088,-0.29794312,65.115959,0,10.594783,356.31586,-0.019677874,13.260447,10.59513,355.23676,-9.2889643
121.0,1.0251211,-0.30568776,65.578987,0,10.594783,362.91583,-0.020170512,13.327868,10.594092,361.61511,-9.285305
123.2,1.0190581,-0.31322432,66.034859,0,10.594783,369.51584,-0.020652412,13.247557,10.594948,368.06116,-9.2813931
125.4,1.0251579,-0.32007429,66.54409,0,10.594783,376.11584,-0.021120396,13.341798,10.595065,374.63474,-9.2777367
127.6,1.0244467,-0.32859674,66.708992,0,10.594783,382.71582,-0.021655317,13.325949,10.595676,381.81268,-9.273921
129.8,1.0142746,-0.33531371,66.878716,0,10.594783,389.31583,-0.022118088,13.206196,10.594109,388.77728,-9.2701254
132.0,1.0243104,-0.34238812,66.63974,0,10.594783,395.91586,-0.022560243,13.342211,10.593993,396.20309,-9.2663422
134.2,1.0285391,-0.35004312,66.016853,0,10.594783,402.51584,-0.023067983,13.393951,10.594677,403.79285,-9.2627478
136.4,1.0182918,-0.35494411,65.143929,0,10.594783,409.11584,-0.023396265,13.265285,10.594811,411.1907,-9.2595873
138.6,1.0099285,-0.36048374,64.249138,0,10.594783,415.71585,-0.023731947,13.177113,10.594875,418.27963,-9.2556152
140.8,1.0179669,-0.36409795,63.972271,0,10.594783,422.31583,-0.023992268,13.28154,10.595462,423.95685,-9.2520819
143.0,1.0086353,-0.36926028,64.170692,0,10.594783,428.91583,-0.024307068,13.159142,10.594867,429.22623,-9.2482967
145.2,1.0210898,-0.37397599,64.742409,0,10.594783,435.51584,-0.024640093,13.325355,10.595512,434.49216,-9.2446451
147.4,1.0322508,-0.37866163,65.840782,0,10.594783,442.11581,-0.024928201,13.472951,10.594126,439.72324,-9.240592
149.6,1.0308715,-0.38649037,66.708977,0,10.594783,448.71582,-0.025422346,13.449082,10.594806,445.9852,-9.2374554
151.8,1.0303984,-0.39117652,67.502708,0,10.594783,455.31583,-0.025748216,13.470686,10.594907,452.80469,-9.2334051
154.0,1.0212972,-0.39908332,67.785454,0,10.594783,461.9158,-0.026250998,13.353043,10.595038,460.21442,-9.2296181
156.2,1.0245026,-0.40450749,67.873528,0,10.594783,468.51584,-0.026627084,13.391539,10.595147,467.57986,-9.2257118
158.4,1.026463,-0.41120565,67.873543,0,10.594783,475.11584,-0.027048379,13.423703,10.594563,474.96289,-9.2220001
160.6,1.0249711,-0.41506141,67.468185,0,10.594783,481.71582,-0.027289107,13.410329,10.595607,482.41183,-9.2183304
162.8,0.99926049,-0.42019644,66.884789,0,10.594783,488.31583,-0.02763034,13.090253,10.594837,489.7825,-9.214613
165.0,0.99543464,-0.42204106,66.196587,0,10.594783,494.9158,-0.027735868,13.038902,10.594738,496.75293,-9.211051
167.2,0.085381545,-0.43659896,64.997986,0,10.594783,499.99884,-0.028697556,1.116407,10.59428,503.32623,-9.2084866
169.4,0.021400122,-0.43106633,63.174038,0,10.594783,499.99884,-0.028326705,0.30331683,10.594648,504.2843,-9.2082443
171.6,-0.00074123772,-0.42398581,63.775028,0,10.594783,499.99884,-0.02788051,-0.0056658736,10.593616,500.55807,-9.2080183
173.8,-0.026768377,-0.41749194,66.848671,0,10.594783,499.99884,-0.027455878,-0.3497082,10.594556,494.3024,-9.2080441
176.0,-0.043474331,-0.41172999,72.101303,0,10.594783,499.99884,-0.027061112,-0.58250356,10.594983,485.20749,-9.207716
178.2,0.80393326,-0.40519193,76.222351,0,10.594783,499.99884,-0.026673097,10.522225,10.594783,483.04697,-9.2076979
180.4,0.88367456,-0.42895532,75.213814,0,10.594783,499.99884,-0.028185245,11.556185,10.594762,496.76492,-9.2075987
182.6,0.91073936,-0.4397935,70.889145,0,10.594783,499.99884,-0.028890638,11.929923,10.595274,510.84756,-9.2074108
184.8,0.90813833,-0.44216469,62.73621,0,10.594783,499.99884,-0.029064214,11.889567,10.595306,520.83228,-9.2074976
187.0,0.85267067,-0.43913594,49.818913,0,10.594783,499.99884,-0.028848313,11.165875,10.59436,523.5744,-9.2075605
189.2,0.82002807,-0.42373431,36.083923,0,10.594783,499.99884,-0.027865509,10.744215,10.594599,517.72229,-9.2077036
191.4,0.80428088,-0.40764889,38.38974,0,10.594783,499.99884,-0.02680237,10.526629,10.594975,505.87045,-9.2079201
193.6,0.80579799,-0.40013564,50.159294,0,10.594783,499.99884,-0.02631633,10.525601,10.59511,494.65457,-9.2076778
195.8,0.83251864,-0.39851519,58.279881,0,10.594783,499.99884,-0.026232585,10.878754,10.594244,489.28198,-9.207902
198.0,0.86947,-0.40220779,62.54459,0,10.594783,499.99884,-0.026460994,11.3739,10.594966,489.51904,-9.207963
200.2,0.90854418,-0.40917453,64.357132,0,10.594783,499.99884,-0.026924958,11.883315,10.595007,493.02304,-9.2077761
202.4,0.93132782,-0.4154186,63.796715,0,10.594783,499.99884,-0.027320491,12.179827,10.595282,498.14957,-9.2080879
204.6,0.93298262,-0.42088398,61.482555,0,10.594783,499.99884,-0.027661838,12.199609,10.594479,502.98065,-9.2077675
206.8,0.9291997,-0.42194235,58.084087,0,10.594783,499.99884,-0.027755598,12.16355,10.59401,506.10657,-9.2075062
209.0,0.88518953,-0.42140293,54.577633,0,10.594783,499.99884,-0.027709179,11.591438,10.595432,506.54703,-9.2077141
211.2,0.86483955,-0.41749239,52.635502,0,10.594783,499.99884,-0.027433734,11.324,10.594393,504.51797,-9.2074795
211.9517,0.85955119,0.020153305,49.559628,0,10.5948,1.5409619e-16,0.0014320678,10.903971,10.592443,503.39539,-9.2079954
211.9561,0.87954885,0.019101111,26.508591,0,10.5948,0.0,0.0012716907,11.313021,10.596817,503.36908,-9.2092543
211.9605,0.82938164,0.019739933,3.4575582,0,10.5948,0.0,0.0012999733,10.52728,10.592894,503.34274,-9.2069435
211.9649,0.83224469,0.018619858,0.0,0,10.5948,0.0,0.0011835363,10.568003,10.596662,503.22696,-9.2073135
211.9693,0.84558648,0.020780819,0.0,0,10.5948,0.0,0.0012371199,10.7187,10.591916,503.0954,-9.2084503
211.9737,0.84206504,0.019180769,0.0,0,10.5948,0.0,0.0011588793,10.685443,10.592175,503.10162,-9.2080879
211.9781,0.83041048,0.022697244,0.0,0,10.5948,0.0,0.001344868,10.554667,10.595212,503.20688,-9.2086506
211.9825,0.8413142,0.020460321,0.0,0,10.5948,0.0,0.0012242385,10.634461,10.595765,503.27914,-9.2068481
211.9869,0.84666413,0.023971543,0.0,0,10.5948,0.0,0.0012862193,10.739026,10.594074,503.27914,-9.2073584
211.9913,0.84855568,0.020194713,0.0,0,10.5948,0.0,0.0012492058,10.772337,10.594518,503.27975,-9.2075834
211.9957,0.83434886,0.02399105,0.0,0,10.5948,0.0,0.0013302662,10.604789,10.592898,503.29288,-9.2073755
212.0001,0.83411098,0.020497307,0.0,0,10.578863,0.0,0.0012686399,10.604099,10.593991,503.30603,-9.2080202
212.0045,0.84117955,0.023393467,0.0,0,10.512864,0.0,0.0014246216,10.676576,10.592861,503.32941,-9.2055988
212.0089,0.85266525,0.021236714,0.0,0,10.446864,0.0,0.0013492531,10.790306,10.582678,503.35574,-9.2080832
212.0133,0.82306856,0.024094045,0.0,0,10.380864,0.0,0.0015100078,10.565984,10.533622,503.34857,-9.2090044
212.0177,0.8324123,0.021016821,0.0,0,10.314864,0.0,0.001427413,10.565578,10.433482,503.30911,-9.2075243
212.0221,0.83239508,0.023739778,0.0,0,10.248864,0.0,0.0016122621,10.538438,10.331498,503.27597,-9.2080393
212.0265,0.83794457,0.019303806,0.0,0,10.182864,0.0,0.0013705477,10.565459,10.252921,503.26282,-9.2061472
212.0309,0.82596529,0.021067746,0.0,0,10.116864,0.0,0.0015388787,10.584536,10.202121,503.24966,-9.2064123
212.0353,0.82836753,0.019843977,0.0,0,10.050864,0.0,0.0014245814,10.479944,10.15193,503.26208,-9.2070951
212.0397,1.6199492,0.024685984,0.0,0,9.9848633,0.0,0.0018899671,20.282495,10.089395,503.27527,-9.2062731
212.0441,3.6050813,0.057781048,0.0,0,9.9188633,0.0,0.0040069227,45.622112,10.029069,503.3811,-9.2053328
212.0485,3.8670287,0.13440135,0.0,0,9.8528633,0.0,0.0092061432,48.811104,9.9490795,503.52585,-9.2046709
212.0529,4.0160403,0.20687774,0.0,0,9.7868633,0.0,0.01404634,50.377689,9.8690748,503.73373,-9.2042522
212.0573,4.0503087,0.272304,0.0,0,9.7208633,0.0,0.018497195,50.696743,9.8010483,504.02322,-9.2059994
212.0617,4.0764041,0.33759394,0.0,0,9.6548634,0.0,0.022825278,50.674385,9.7341948,504.28613,-9.2051363
212.0661,4.0679359,0.39740142,0.0,0,9.5888634,0.0,0.026863327,50.466881,9.6771116,504.41769,-9.2056274
212.0705,4.1404538,0.46293661,0.0,0,9.5228634,0.0,0.031366095,51.173244,9.6075659,504.54929,-9.2068262
212.0749,4.2203598,0.53075808,0.0,0,9.4574747,0.0,0.035989057,51.796402,9.5348539,504.5506,-9.2059059
212.0793,4.2310305,0.6019001,0.0,0,9.393095,0.0,0.040833481,51.652893,9.4707994,504.53748,-9.2048512
212.0837,4.2175722,0.66578257,0.0,0,9.3287144,0.0,0.045271311,51.252533,9.4018507,504.57416,-9.2062836
212.0881,4.1882153,0.72936255,0.0,0,9.2643328,0.0,0.049598679,50.743313,9.3388071,504.63992,-9.2067623
212.0925,4.2609735,0.78811187,0.0,0,9.1999531,0.0,0.053700615,51.288548,9.2759886,504.72003,-9.2064314
212.0969,4.3132606,0.85517812,0.0,0,9.1355715,0.0,0.058399539,51.714825,9.2070169,504.82523,-9.2063551
212.1013,4.3379765,0.92000633,0.0,0,9.0711908,0.0,0.063078016,51.953613,9.1429548,504.92416,-9.2064028
212.1057,4.3142238,0.98978627,0.0,0,9.0068102,0.0,0.067917965,51.345219,9.071764,504.96362,-9.2066374
212.1101,4.3235841,1.0456017,0.0,0,8.9424286,0.0,0.072085366,51.159508,9.0124292,505.00308,-9.2064362
212.1145,4.3728986,1.1090788,0.0,0,8.8780489,0.0,0.076474391,51.495453,8.9513826,504.98813,-9.2061157
212.1189,4.40557,1.1686728,0.0,0,8.8136673,0.0,0.080949955,51.682579,8.8832121,504.96182,-9.2055836
212.1233,4.4635177,1.2409821,0.0,0,8.7493448,0.0,0.086132795,52.104969,8.8171673,505.05316,-9.2069654
212.1277,4.453733,1.3021034,0.0,0,8.6880999,0.0,0.090738386,51.739403,8.748065,505.2373,-9.2058535
212.1321,4.4722214,1.36587,0.0,0,8.6268702,0.0,0.095406495,51.727959,8.6833344,505.44437,-9.2057133
212.1365,4.46701,1.4232197,0.0,0,8.5656395,0.0,0.099755295,51.483387,8.6237917,505.7074,-9.2049198
212.1409,4.4599137,1.4855658,0.0,0,8.5044088,0.0,0.10437483,51.167728,8.5634689,505.9668,-9.2049217
212.1453,4.4749026,1.5374573,0.0,0,8.4431791,0.0,0.10824043,51.180275,8.5076284,506.07202,-9.2067118
212.1497,4.5780554,1.6015546,0.0,0,8.3819485,0.0,0.11307562,52.062054,8.443327,506.17725,-9.2045135
212.1541,4.5943584,1.6628534,0.0,0,8.3207188,0.0,0.11773217,52.049843,8.3789635,506.2626,-9.2057343
212.1585,4.5976114,1.7272193,0.0,0,8.2594881,0.0,0.12255656,51.894863,8.3131523,506.34149,-9.2056856
212.1629,4.6418834,1.7922512,0.0,0,8.1982584,0.0,0.12740728,52.005505,8.2493305,506.45239,-9.2059126
212.1673,4.6505561,1.8555223,0.0,0,8.1370277,0.0,0.13227984,51.787258,8.1868086,506.59705,-9.2056713
212.1717,4.6611791,1.9147639,0.0,0,8.0757971,0.0,0.13672394,51.790539,8.1254539,506.75891,-9.2053471
212.1761,4.6534352,1.9734149,0.0,0,8.0165014,0.0,0.14121857,51.457096,8.0650539,506.98248,-9.205163
212.1805,4.682138,2.0344331,0.0,0,7.9582458,0.0,0.14582896,51.536285,8.0051641,507.20605,-9.2060366
212.1849,4.7123685,2.0930178,0.0,0,7.8999891,0.0,0.1502341,51.621975,7.9412904,507.32968,-9.2057533
212.1893,4.7145667,2.1506286,0.0,0,7.8417335,0.0,0.15478688,51.461143,7.8848166,507.44806,-9.2059736
212.1937,4.709445,2.2045512,0.0,0,7.7834773,0.0,0.1588645,51.138317,7.8260746,507.50363,-9.2054796
212.1981,4.7423744,2.2633891,0.0,0,7.7252216,0.0,0.16340028,51.219151,7.7700644,507.52994,-9.2057791
212.2025,4.7563429,2.3175311,0.0,0,7.666965,0.0,0.16760541,51.198589,7.7133522,507.58887,-9.2060556
212.2069,4.8149414,2.3797905,0.0,0,7.6087093,0.0,0.17240544,51.641979,7.6529279,507.69409,-9.204607
212.2113,4.8366146,2.4356506,0.0,0,7.5504532,0.0,0.17693447,51.691277,7.596818,507.78973,-9.2070818
212.2157,4.8488135,2.4986911,0.0,0,7.4921975,0.0,0.18187059,51.513699,7.534236,507.82919,-9.2057734
212.2201,4.8831177,2.5534065,0.0,0,7.4339414,0.0,0.18638717,51.519787,7.4742179,507.86862,-9.2070408
212.2245,4.8847275,2.6150737,0.0,0,7.3765039,0.0,0.19109987,51.335583,7.4172759,507.96579,-9.2059937
212.2289,4.9308047,2.6676102,0.0,0,7.3210988,0.0,0.19557959,51.543259,7.3614335,508.07098,-9.2068968
212.2333,4.9049869,2.7293518,0.0,0,7.2656941,0.0,0.2005287,51.144794,7.2987776,508.23227,-9.2053003
212.2377,4.9098525,2.7769489,0.0,0,7.210289,0.0,0.20465811,50.93663,7.2476554,508.42957,-9.2049799
212.2421,4.9513311,2.8356829,0.0,0,7.1548843,0.0,0.20944342,51.112385,7.1916628,508.27713,-9.2066526
212.2465,5.0070524,2.8871074,0.0,0,7.0994792,0.0,0.21378636,51.570335,7.1374774,507.44858,-9.2048435
212.2509,5.0047531,2.9450028,0.0,0,7.044075,0.0,0.21860114,51.218899,7.0817404,506.62006,-9.2055855
212.2553,5.0275149,2.9994318,0.0,0,6.9886694,0.0,0.2232326,51.188835,7.0241351,505.79153,-9.2050285
212.2597,5.0649529,3.0567846,0.0,0,6.9332652,0.0,0.22807561,51.373482,6.9643078,504.96301,-9.2055664
212.2641,5.0808096,3.1088293,0.0,0,6.8778601,0.0,0.23246396,51.278175,6.9067621,504.59995,-9.2057543
212.2685,5.080514,3.1635952,0.0,0,6.8224554,0.0,0.23719779,51.016289,6.8553658,504.34998,-9.2059679
212.2729,5.0872688,3.2164359,0.0,0,6.7670503,0.0,0.24162784,50.85387,6.8011599,503.27426,-9.2067852
212.2773,5.1344113,3.2715762,0.0,0,6.7141318,0.0,0.24642657,51.13797,6.7404552,501.4848,-9.2049093
212.2817,5.144424,3.3248353,0.0,0,6.6614199,0.0,0.25083318,50.999264,6.6881056,499.76236,-9.2055006
212.2861,5.1933351,3.3762119,0.0,0,6.6087079,0.0,0.25529602,51.247196,6.6368341,498.22287,-9.2051535
212.2905,5.1796331,3.4318671,0.0,0,6.5559959,0.0,0.25991344,50.828213,6.5824404,496.68338,-9.2054186
212.2949,5.1922026,3.48159,0.0,0,6.503284,0.0,0.26422039,50.737614,6.5297894,496.94653,-9.2054081
212.2993,5.2345433,3.5344634,0.0,0,6.450572,0.0,0.26877868,50.851242,6.4740238,497.20969,-9.2047882
212.3037,5.2760844,3.5879629,0.0,0,6.3978601,0.0,0.27327946,51.120975,6.4270201,497.65582,-9.2056284
212.3081,5.2797794,3.6409006,0.0,0,6.3451481,0.0,0.27789921,50.929234,6.3711839,498.16901,-9.2051506
212.3125,5.2870269,3.6937175,0.0,0,6.2924366,0.0,0.28251499,50.682137,6.3164134,498.63947,-9.2064695
212.3169,5.3265553,3.7480197,0.0,0,6.2397246,0.0,0.28713334,50.875198,6.2663698,499.06052,-9.2080641
212.3213,5.3660645,3.8010695,0.0,0,6.1870127,0.0,0.29189962,51.054398,6.2109389,499.50989,-9.2043839
212.3257,5.3390284,3.8527255,0.0,0,6.1357436,0.0,0.29639405,50.497425,6.1602983,500.07568,-9.2055521
212.3301,5.3613267,3.9020913,0.0,0,6.0856099,0.0,0.30099675,50.489487,6.1056499,500.64148,-9.205286
212.3345,5.4107533,3.9571233,0.0,0,6.0354762,0.0,0.30580857,50.746727,6.0542521,500.86563,-9.2046871
212.3389,5.4162974,4.0038123,0.0,0,5.9853425,0.0,0.31019747,50.546082,6.0071287,501.06302,-9.2057314
212.3433,5.4457836,4.0579243,0.0,0,5.9352088,0.0,0.3149406,50.625397,5.9568038,501.23438,-9.2064266
212.3477,5.4424,4.1040006,0.0,0,5.8850756,0.0,0.31944102,50.287251,5.9056263,501.39227,-9.2050953
212.3521,5.4652572,4.1543517,0.0,0,5.8349419,0.0,0.32402369,50.293247,5.8562255,501.76105,-9.2049026
212.3565,5.505919,4.2019873,0.0,0,5.7848082,0.0,0.32849705,50.509819,5.8053799,502.45844,-9.2046499
212.3609,5.5231943,4.2549162,0.0,0,5.7346745,0.0,0.33355704,50.398605,5.7570529,503.16226,-9.2062769
212.3653,5.5602388,4.3035402,0.0,0,5.6845412,0.0,0.33822557,50.482563,5.7033262,503.91214,-9.2047262
212.3697,5.5838342,4.3557763,0.0,0,5.634407,0.0,0.34316215,50.427475,5.6558032,504.66205,-9.2056789
212.3741,5.6238194,4.4034586,0.0,0,5.5847516,0.0,0.34776381,50.535614,5.6044044,505.24316,-9.2049704
212.3785,5.6282034,4.455925,0.0,0,5.5370555,0.0,0.35280445,50.400761,5.5499902,505.79559,-9.2050114
212.3829,5.5974808,4.4990778,0.0,0,5.4893594,0.0,0.35703322,49.917908,5.5002041,506.20145,-9.2065802
212.3873,5.5786128,4.5456643,0.0,0,5.4416633,0.0,0.36146784,49.442207,5.4559412,506.50391,-9.2053061
212.3917,5.6651487,4.5897927,0.0,0,5.3939681,0.0,0.36559308,50.002209,5.4101224,506.71014,-9.2060127
212.3961,5.7187309,4.6374474,0.0,0,5.346272,0.0,0.37023064,50.276554,5.3643007,506.71014,-9.205534
212.4005,5.7288756,4.6873932,0.0,0,5.2985759,0.0,0.37496015,50.24276,5.3120461,506.7049,-9.2053719
212.4049,5.728395,4.735754,0.0,0,5.2508798,0.0,0.37964109,49.868824,5.2640548,506.59967,-9.2062664
212.4093,5.7765059,4.7840056,0.0,0,5.2031837,0.0,0.38424996,50.080608,5.2170839,506.49445,-9.2049026
212.4137,5.8100743,4.8327966,0.0,0,5.155488,0.0,0.38892382,50.145287,5.1619163,506.59488,-9.2053299
212.4181,5.8037558,4.8805594,0.0,0,5.1077919,0.0,0.39357394,49.854675,5.1234317,506.75272,-9.2063017
212.4225,5.82725,4.9273515,0.0,0,5.0600958,0.0,0.39811248,49.888847,5.0704546,507.02536,-9.2051258
212.4269,5.8325839,4.9772077,0.0,0,5.0143409,0.0,0.40285015,49.662918,5.0295749,507.40674,-9.2052622
212.4313,5.8890648,5.0213532,0.0,0,4.968977,0.0,0.40723622,49.875771,4.9827685,507.4039,-9.2051697
212.4357,5.9088755,5.0705867,0.0,0,4.9236126,0.0,0.41212904,49.83437,4.9380779,506.21997,-9.2065506
212.4401,5.8985257,5.1128631,0.0,0,4.8782492,0.0,0.41636571,49.499416,4.8892083,505.03604,-9.205513
212.4445,5.9258351,5.162931,0.0,0,4.8328848,0.0,0.4212338,49.445629,4.8452649,499.87793,-9.2035236
212.4489,5.9972968,5.2061458,0.0,0,4.7875209,0.0,0.42588526,49.848778,4.795742,494.62738,-9.20467
212.4533,6.0334272,5.2566385,0.0,0,4.7421565,0.0,0.43090722,49.936565,4.7512031,490.74841,-9.2055607
212.4577,5.9912853,5.3003988,0.0,0,4.6967926,0.0,0.43564031,49.351204,4.7019048,487.4321,-9.2049961
212.4621,5.9917874,5.3435888,0.0,0,4.6514287,0.0,0.44009277,49.104748,4.6626744,486.05994,-9.2067728
212.4665,6.1032677,5.3870177,0.0,0,4.6060648,0.0,0.44466943,49.872818,4.6167531,487.15292,-9.2053967
212.4709,6.1432858,5.4359641,0.0,0,4.5607004,0.0,0.44986928,49.87196,4.5715194,488.15268,-9.2047052
212.4753,6.1605864,5.4779248,0.0,0,4.5163722,0.0,0.45447561,49.788036,4.5262461,488.70578,-9.2057323
212.4797,6.1846952,5.5281897,0.0,0,4.4732165,0.0,0.459892,49.645733,4.4763956,489.25888,-9.2062101
212.4841,6.1602402,5.5676088,0.0,0,4.4300613,0.0,0.46402186,49.300419,4.4342914,489.81158,-9.2066717
212.4885,6.1799664,5.6138,0.0,0,4.3869061,0.0,0.46915269,49.167358,4.3873277,490.36423,-9.205369
212.4929,6.1716709,5.6500912,0.0,0,4.343751,0.0,0.4729782,48.974636,4.3482523,491.31879,-9.2056484
212.4973,6.1894479,5.6931601,0.0,0,4.3005962,0.0,0.47778347,48.892349,4.3065314,492.50302,-9.2070847
212.5017,6.2850361,5.7332416,0.0,0,4.2574406,0.0,0.48207286,49.401348,4.2644606,493.77444,-9.2049284
212.5061,6.3242812,5.7780442,0.0,0,4.2142854,0.0,0.48704505,49.480946,4.221766,495.19553,-9.2050171
212.5105,6.3726759,5.8222938,0.0,0,4.1711302,0.0,0.49169433,49.659046,4.1751137,496.60608,-9.2052727
212.5149,6.3632054,5.8646908,0.0,0,4.127975,0.0,0.49639744,49.346039,4.1302042,497.92188,-9.2059536
212.5193,6.3995819,5.9125543,0.0,0,4.0848203,0.0,0.50132221,49.350292,4.0855031,499.2377,-9.2041407
212.5237,6.4241681,5.9497023,0.0,0,4.0418863,0.0,0.50538659,49.3395,4.0450516,496.1412,-9.2049046
212.5281,6.4608779,5.9980097,0.0,0,4.0008435,0.0,0.51069719,49.385609,4.0041108,492.15262,-9.2057734
212.5325,6.4608049,6.0378275,0.0,0,3.9598002,0.0,0.51491916,49.149906,3.9592524,488.31274,-9.2060566
212.5369,6.476738,6.0813317,0.0,0,3.918757,0.0,0.51963973,49.045433,3.9205739,484.58798,-9.2060757
212.5413,6.4944658,6.1204057,0.0,0,3.8777139,0.0,0.5239867,48.96257,3.8858228,482.42288,-9.2064619
212.5457,6.5499749,6.1606088,0.0,0,3.8366706,0.0,0.52839559,49.156998,3.8433313,483.97684,-9.2070646
212.5501,6.6044765,6.2030015,0.0,0,3.7956276,0.0,0.53312403,49.324467,3.8004262,485.53903,-9.2054987
212.5545,6.6625638,6.2494783,0.0,0,3.7545841,0.0,0.53822011,49.503185,3.7576425,487.39536,-9.2048349
212.5589,6.6938486,6.2890215,0.0,0,3.713541,0.0,0.54305047,49.540436,3.7143044,489.25165,-9.2050018
212.5633,6.670404,6.335741,0.0,0,3.672498,0.0,0.54816729,49.07457,3.6750803,491.17737,-9.2065086
212.5677,6.7173862,6.3701487,0.0,0,3.6314545,0.0,0.55249768,49.233398,3.6356144,493.12512,-9.2048178
212.5721,6.6938109,6.4182024,0.0,0,3.5904114,0.0,0.55773646,48.824787,3.5912871,494.95645,-9.2054787
212.5765,6.7763739,6.449461,0.0,0,3.5508497,0.0,0.56170046,49.147938,3.5533862,496.66702,-9.2055902
212.5809,6.8854413,6.4971013,0.0,0,3.5118039,0.0,0.5671711,49.7509,3.5142956,498.22226,-9.205267
212.5853,6.8878946,6.5321455,0.0,0,3.4727583,0.0,0.57171321,49.557247,3.4716206,499.23541,-9.2063608
212.5897,6.8661118,6.5772767,0.0,0,3.4337125,0.0,0.57703525,49.100582,3.4306953,500.24857,-9.2065077
212.5941,6.9058247,6.6135082,0.0,0,3.3946671,0.0,0.58156741,49.131168,3.3928416,500.54257,-9.2067146
212.5985,6.9115481,6.6509428,0.0,0,3.3556216,0.0,0.58624011,48.987713,3.3565094,500.80234,-9.2059851
212.6029,6.9707556,6.6856356,0.0,0,3.316576,0.0,0.59050256,49.191391,3.317302,500.61026,-9.2059946
212.6073,7.0306401,6.7277517,0.0,0,3.27753,0.0,0.59559435,49.315517,3.2759972,500.36026,-9.2061253
212.6117,7.0826955,6.7660985,0.0,0,3.2384844,0.0,0.60027385,49.446918,3.2355871,500.56577,-9.205595
212.6161,7.1603918,6.8091273,0.0,0,3.199439,0.0,0.60564774,49.738491,3.1956124,501.05261,-9.2052698
212.6205,7.1838737,6.8462162,0.0,0,3.1603935,0.0,0.61003119,49.715603,3.1576555,501.64078,-9.2049599
212.6249,7.1456499,6.8848295,0.0,0,3.122066,0.0,0.61494619,49.22057,3.118155,502.41711,-9.2055311
212.6293,7.1894197,6.9235215,0.0,0,3.0849211,0.0,0.61956149,49.284031,3.0808022,503.12024,-9.2064295
212.6337,7.2132092,6.9587693,0.0,0,3.0477762,0.0,0.62394875,49.208275,3.0408154,503.0018,-9.2065392
212.6381,7.283463,6.9965816,0.0,0,3.0106313,0.0,0.62849456,49.54213,3.0009391,502.88339,-9.2052736
212.6425,7.2522254,7.0359635,0.0,0,2.9734867,0.0,0.63309121,49.092098,2.9683452,502.4545,-9.2065325
212.6469,7.2993603,7.0701656,0.0,0,2.9363418,0.0,0.63732165,49.14653,2.9320374,501.9545,-9.2055483
212.6513,7.3805356,7.1066432,0.0,0,2.8991969,0.0,0.64182281,49.462124,2.8982854,501.48318,-9.206501
212.6557,7.4501076,7.1466904,0.0,0,2.8620524,0.0,0.64673102,49.68417,2.8629816,501.0358,-9.2050972
212.6601,7.4643893,7.1852984,0.0,0,2.8249075,0.0,0.65161347,49.564266,2.8201904,500.81461,-9.2048683
212.6645,7.4649348,7.2233586,0.0,0,2.7877626,0.0,0.65627617,49.288876,2.7889295,501.18304,-9.2060432
212.6689,7.5497813,7.2592196,0.0,0,2.7506177,0.0,0.6609717,49.640701,2.7531655,501.55505,-9.20609
212.6733,7.6531792,7.2995734,0.0,0,2.7135069,0.0,0.66579157,50.066959,2.7158568,502.31824,-9.2051754
212.6777,7.6697493,7.3362284,0.0,0,2.6781669,0.0,0.67092502,50.002922,2.6779983,503.08142,-9.2063971
212.6821,7.7379417,7.3763204,0.0,0,2.6428349,0.0,0.67578065,50.136604,2.638123,503.7178,-9.2050991
212.6865,7.7934871,7.412014,0.0,0,2.6075029,0.0,0.68112928,50.188786,2.6000097,504.30984,-9.2066584
212.6909,7.772861,7.4526973,0.0,0,2.572171,0.0,0.68631423,49.845909,2.5577655,504.63443,-9.2055788
212.6953,7.7368822,7.4816198,0.0,0,2.5368388,0.0,0.69051862,49.43885,2.5281725,504.66074,-9.2052279
212.6997,7.7251191,7.5172172,0.0,0,2.5015068,0.0,0.69522303,49.133301,2.4997027,504.71396,-9.2050438
212.7041,7.8543401,7.5457277,0.0,0,2.4661748,0.0,0.69927424,49.671425,2.4630618,504.87177,-9.2060289
212.7085,7.9834657,7.584909,0.0,0,2.4308426,0.0,0.70472217,50.215851,2.42505,505.02957,-9.2053566
212.7129,8.0471735,7.6185813,0.0,0,2.3955109,0.0,0.70940781,50.347733,2.3937221,505.33521,-9.2053556
212.7173,7.9647675,7.6550221,0.0,0,2.3601789,0.0,0.7144897,49.668766,2.3559935,505.65088,-9.2051601
212.7217,8.0164061,7.6830411,0.0,0,2.3248467,0.0,0.71840948,49.777142,2.325949,505.78198,-9.2053175
212.7261,8.1409798,7.7210145,0.0,0,2.2906368,0.0,0.72373658,50.23637,2.2899055,505.82141,-9.2051802
212.7305,8.2421284,7.7528796,0.0,0,2.2570295,0.0,0.7280857,50.682266,2.2547605,505.22409,-9.2058516
212.7349,8.3244324,7.7907982,0.0,0,2.2234225,0.0,0.73345947,50.91552,2.2176418,503.67154,-9.2061176
212.7393,8.3282909,7.827424,0.0,0,2.1898153,0.0,0.73842847,50.683025,2.1815782,502.11209,-9.2057343
212.7437,8.3247423,7.8605556,0.0,0,2.156208,0.0,0.74306774,50.399426,2.1456552,500.50699,-9.2058344
212.7481,8.3501644,7.8963652,0.0,0,2.1226008,0.0,0.74771553,50.311928,2.1114714,498.90186,-9.2049437
212.7525,8.4165964,7.9270282,0.0,0,2.0889935,0.0,0.75199252,50.501282,2.0793898,497.56934,-9.2050447
212.7569,8.4181662,7.9606814,0.0,0,2.0553865,0.0,0.75655776,50.29607,2.0506144,496.27985,-9.206151
212.7613,8.5242043,7.9946122,0.0,0,2.0217793,0.0,0.76118135,50.675964,2.0139165,495.0217,-9.2044592
212.7657,8.6319551,8.0303335,0.0,0,1.9881722,0.0,0.76615918,51.076359,1.9794762,493.78482,-9.2055788
212.7701,8.690115,8.0626001,0.0,0,1.954565,0.0,0.77082479,51.202049,1.9452269,492.99152,-9.2061243
212.7745,8.6591082,8.0993347,0.0,0,1.9214275,0.0,0.77587306,50.770378,1.9143715,493.10995,-9.2050886
212.7789,8.6714039,8.1276836,0.0,0,1.889457,0.0,0.77978975,50.624378,1.8830224,493.22137,-9.2056341
212.7833,8.7821035,8.1638012,0.0,0,1.8574866,0.0,0.78492588,50.993839,1.84851,493.22137,-9.2057858
212.7877,8.8424349,8.1903048,0.0,0,1.8255162,0.0,0.78906137,51.173054,1.8202553,493.22137,-9.2061176
212.7921,8.9038334,8.229887,0.0,0,1.7935458,0.0,0.79440689,51.208946,1.7887236,494.29327,-9.2055864
212.7965,8.9489985,8.2589436,0.0,0,1.7615755,0.0,0.79916412,51.286125,1.7555196,495.64856,-9.2061396
212.8009,9.0702467,8.2929258,0.0,0,1.729605,0.0,0.80412769,51.653248,1.7245245,497.052,-9.2061243
212.8053,9.136426,8.3223248,0.0,0,1.6976346,0.0,0.80882043,51.788353,1.6910371,498.49939,-9.2049894
212.8097,9.1450901,8.3605633,0.0,0,1.6656642,0.0,0.81451082,51.581242,1.65926,499.47119,-9.2064924
212.8141,9.1999693,8.3862524,0.0,0,1.6336937,0.0,0.81867588,51.663998,1.6306714,499.05011,-9.2055359
212.8185,9.345912,8.4220724,0.0,0,1.6017234,0.0,0.82431865,52.138706,1.5966424,498.62903,-9.2053204
212.8229,9.4490252,8.4530954,0.0,0,1.5697531,0.0,0.82928795,52.493477,1.5667132,498.1301,-9.2051611
212.8273,9.4747171,8.4880924,0.0,0,1.5392207,0.0,0.83488166,52.350327,1.5298599,497.6301,-9.2054701
212.8317,9.4672499,8.5143757,0.0,0,1.5088079,0.0,0.83890098,52.135014,1.4982344,497.67819,-9.2054901
212.8361,9.4934359,8.5450144,0.0,0,1.478395,0.0,0.84394962,51.951794,1.4699241,497.94138,-9.2056751
212.8405,9.5406876,8.5741806,0.0,0,1.4479822,0.0,0.84863287,51.952374,1.438856,498.35257,-9.2043791
212.8449,9.5697203,8.6025229,0.0,0,1.4175695,0.0,0.85303378,51.921669,1.4117461,498.94467,-9.2065868
212.8493,9.6402321,8.6282797,0.0,0,1.3871567,0.0,0.85701251,52.096981,1.3818344,499.52484,-9.2063503
212.8537,9.7091026,8.6593437,0.0,0,1.3567439,0.0,0.86198509,52.193783,1.3515565,500.05115,-9.2054176
212.8581,9.8755274,8.686202,0.0,0,1.3263311,0.0,0.86594564,52.877335,1.3239169,500.57748,-9.2050562
212.8625,10.02886,8.7192144,0.0,0,1.2959183,0.0,0.87114948,53.429989,1.2906061,500.88742,-9.2042847
212.8669,10.122579,8.7567692,0.0,0,1.2655054,0.0,0.87698328,53.606297,1.2569078,501.17691,-9.2056484
212.8713,10.164188,8.7872715,0.0,0,1.2350928,0.0,0.88142407,53.578857,1.2233733,501.41541,-9.2046223
212.8757,10.200651,8.8216763,0.0,0,1.2055123,0.0,0.88678259,53.48164,1.1915478,501.62592,-9.2050371
212.8801,10.218655,8.8479328,0.0,0,1.1765865,0.0,0.89098406,53.367115,1.166634,501.82156,-9.2053003
212.8845,10.241092,8.8791733,0.0,0,1.1476611,0.0,0.895702,53.23378,1.1344311,501.99261,-9.2049398
212.8889,10.275936,8.9042206,0.0,0,1.1187353,0.0,0.89996791,53.187424,1.1089205,502.17087,-9.2050924
212.8933,10.3587,8.9350567,0.0,0,1.0898098,0.0,0.9047094,53.407425,1.0830231,502.40771,-9.2051744
212.8977,10.546057,8.9622841,0.0,0,1.0608841,0.0,0.9091146,54.034489,1.0521162,502.64456,-9.204711
212.9021,10.605169,8.9960127,0.0,0,1.0319586,0.0,0.91431004,54.159176,1.0252008,502.90353,-9.2075405
212.9065,10.655121,9.023201,0.0,0,1.0030329,0.0,0.9194082,54.104221,0.99359608,503.16669,-9.2051802
212.9109,10.772021,9.0526705,0.0,0,0.97410738,0.0,0.92401934,54.416199,0.96571296,502.05075,-9.2044411
212.9153,10.864186,9.0811234,0.0,0,0.94518173,0.0,0.92923647,54.582832,0.93575555,499.90598,-9.2048559
212.9197,10.839055,9.109643,0.0,0,0.91625619,0.0,0.93407333,54.280502,0.91033328,497.38849,-9.2043247
212.9241,10.907248,9.1365967,0.0,0,0.88760823,0.0,0.93886817,54.29879,0.88155001,494.01981,-9.2064962
212.9285,11.02536,9.1627607,0.0,0,0.86009943,0.0,0.94338506,54.633965,0.85547411,490.71234,-9.2038822
212.9329,11.189274,9.1889915,0.0,0,0.83259064,0.0,0.94825,55.156178,0.82415348,489.0275,-9.2050428
212.9373,11.228683,9.2183685,0.0,0,0.80508184,0.0,0.95363545,55.098465,0.79696351,487.34262,-9.2052765
212.9417,11.238829,9.2397528,0.0,0,0.77757305,0.0,0.95752996,54.971165,0.76897228,485.96063,-9.2053881
212.9461,11.335956,9.2683716,0.0,0,0.75006425,0.0,0.96285254,55.116886,0.74524009,484.67007,-9.206481
212.9505,11.506652,9.293973,0.0,0,0.72255546,0.0,0.9672175,55.662712,0.7137484,483.72849,-9.205472
212.9549,11.685364,9.3228788,0.0,0,0.6950466,0.0,0.97270441,56.247982,0.68628359,483.13586,-9.2061338
212.9593,11.670632,9.3501492,0.0,0,0.66753787,0.0,0.97747886,55.888073,0.65553814,482.91571,-9.2044764
212.9637,11.662311,9.3733654,0.0,0,0.64002901,0.0,0.98178327,55.638737,0.63065404,483.92972,-9.2043657
212.9681,11.730467,9.3990688,0.0,0,0.61252022,0.0,0.98610264,55.666214,0.60130912,484.94373,-9.2059612
212.9725,11.882756,9.4253559,0.0,0,0.58501148,0.0,0.99057657,56.17345,0.57989049,486.19885,-9.2045994
212.9769,11.997943,9.4510851,0.0,0,0.55860865,0.0,0.99506402,56.508968,0.55202568,487.4631,-9.2051582
212.9813,11.040605,9.4578171,0.0,0,0.53242874,0.0,0.99614054,51.90395,0.53480715,488.53473,-9.206378
212.9857,10.547693,9.4583082,0.0,0,0.50624865,0.0,0.99600244,49.612408,0.51523697,489.522,-9.2055101
212.9901,10.086749,9.4617777,0.0,0,0.48006868,0.0,0.99643368,47.449242,0.49793148,490.59348,-9.2062445
212.9945,9.7899542,9.4707918,0.0,0,0.45388871,0.0,0.99768984,46.000282,0.4785533,491.7778,-9.2069235
212.9989,9.4976311,9.4702778,0.0,0,0.42770869,0.0,0.99745411,44.599197,0.45428529,492.92648,-9.2061596
213.0033,9.1570606,9.4771357,0.0,0,0.40152869,0.0,0.99816018,42.965111,0.43662778,493.88705,-9.2077732
213.0077,8.7862082,9.4774084,0.0,0,0.37534866,0.0,0.99818498,41.270004,0.42627838,494.8476,-9.205883
213.0121,8.4462042,9.478961,0.0,0,0.34916869,0.0,0.99843657,39.656799,0.42008686,495.51508,-9.2080832
213.0165,8.2138157,9.478878,0.0,0,0.32298869,0.0,0.99859041,38.521481,0.41410699,496.14667,-9.2077761
213.0209,8.1599684,9.4869747,0.0,0,0.29680869,0.0,0.99954855,38.216629,0.39622581,496.71271,-9.2073011
213.0253,8.2902184,9.4830484,0.0,0,0.27123094,0.0,0.99956918,38.813145,0.37583816,497.23901,-9.2060013
213.0297,8.5865078,9.4899149,0.0,0,0.24633573,0.0,1.0004894,40.186119,0.33881253,497.73734,-9.206728
213.0341,8.7877798,9.4915419,0.0,0,0.22144051,0.0,1.0011231,41.086796,0.30287409,498.18472,-9.2064314
213.0385,8.886569,9.4957266,0.0,0,0.19654538,0.0,1.0019513,41.53363,0.27259219,498.61731,-9.2068596
213.0429,8.9083223,9.4953928,0.0,0,0.17165017,0.0,1.0023843,41.590988,0.24376941,498.89365,-9.2051497
213.0473,8.9269829,9.4995203,0.0,0,0.14675498,0.0,1.0032651,41.665779,0.21480615,499.16998,-9.2056637
213.0517,8.8923388,9.5002241,0.0,0,0.12185977,0.0,1.0034274,41.512409,0.18922023,499.414,-9.2049847
213.0561,8.8402367,9.5012283,0.0,0,0.096964568,0.0,1.0042247,41.220078,0.16577671,499.65085,-9.2063894
213.0605,8.7761278,9.5003128,0.0,0,0.072069369,0.0,1.004108,40.936172,0.14765944,499.90942,-9.2069197
213.0649,8.7481117,9.5045557,0.0,0,0.047174159,0.0,1.0052708,40.765251,0.11887358,500.18573,-9.2050848
213.0693,8.7162533,9.5046206,0.0,0,0.022278961,0.0,1.0051445,40.619331,0.10209054,500.42865,-9.2067852
213.0737,8.6514845,9.5033884,0.0,0,-0.002552425,0.0,1.0051531,40.323856,0.08063744,500.58655,-9.2063808
213.0781,8.5743704,9.5085773,0.0,0,-0.02684043,0.0,1.0058645,39.933243,0.058736324,500.74463,-9.2065258
213.0825,8.494132,9.5077181,0.0,0,-0.051128428,0.0,1.0057487,39.549007,0.049270254,500.91571,-9.2074718
213.0869,8.4485254,9.5099525,0.0,0,-0.075416431,0.0,1.0060023,39.323471,0.028893687,501.08676,-9.2064095
213.0913,8.3703833,9.5097532,0.0,0,-0.09970443,0.0,1.0057703,38.982815,0.015432764,501.24802,-9.2064848
213.0957,8.2592134,9.5136175,0.0,0,0.31743845,500.0,1.0061234,38.457401,0.0051684757,501.40591,-9.2061901
213.1001,7.7998004,9.5137138,0.0,0,1.1142955,500.0,1.0059893,36.388039,0.012800946,501.55124,-9.2058535
213.1045,4.5996003,9.503664,0.0,0,1.9111538,500.0,1.0041116,21.622221,0.18142237,501.6828,-9.2098665
213.1089,-0.16144051,9.4735432,0.0,0,2.7080109,500.0,0.99849987,-0.70758361,0.52677292,501.81989,-9.2132444
213.1133,-0.048730303,9.4813347,0.0,0,3.504869,500.0,0.99920475,-0.32040945,1.6362715,501.97778,-9.2146635
213.1177,0.022897394,9.4780865,0.0,0,4.3017259,500.0,0.99868387,0.19322196,2.8740225,502.13568,-9.2138042
213.1221,-0.014893915,9.4801674,0.0,0,5.0985842,500.0,0.99871039,-0.089753658,3.7127366,502.20694,-9.2125502
213.1265,-0.088381708,9.4795122,0.0,0,5.8954415,500.0,0.99865347,-0.39932582,4.4737821,502.27271,-9.2109365
213.1309,-0.10024072,9.4781342,0.0,0,6.6922989,500.0,0.99818552,-0.47820136,5.2342114,502.29425,-9.2095671
213.1353,0.077616885,9.4787264,0.0,0,7.4891567,500.0,0.99872792,0.38055825,6.0337524,502.29425,-9.2083101
213.1397,-0.13625878,9.4807196,0.0,0,8.2860146,500.0,0.99861896,-0.60374725,6.8679051,502.31021,-9.2090178
213.1441,0.11050711,9.4756784,0.0,0,9.0828733,500.0,0.99829769,0.51020902,7.7071557,502.3497,-9.2073202
213.1485,-0.19323084,9.480237,0.0,0,9.8797302,500.0,0.99894506,-0.93401837,8.5229664,502.38916,-9.2077827
213.1529,0.16123985,9.4755812,0.0,0,10.676588,500.0,0.99860674,0.6976679,9.3482695,502.42865,-9.2080431
213.1573,-0.13524897,9.4778585,0.0,0,11.473446,500.0,0.99896759,-0.57795537,10.155935,502.46811,-9.2070055
213.1617,-0.062915593,9.4731655,0.0,0,12.270304,500.0,0.99831331,-0.33573881,10.951653,502.47333,-9.2081242
213.1661,-0.10664992,9.475997,0.0,0,13.067161,500.0,0.99918848,-0.40651873,11.723666,502.47333,-9.2066031
213.1705,0.0059910524,9.473794,0.0,0,13.864018,500.0,0.99891365,-0.017471036,12.504449,502.49701,-9.2080564
213.1749,0.042388532,9.4717159,0.0,0,14.660877,500.0,0.99881804,0.25992599,13.304901,502.5365,-9.2062902
213.1793,-0.12037529,9.471468,0.0,0,15.457734,500.0,0.99888188,-0.5494796,14.10199,502.5585,-9.2078514
213.1837,-0.013163184,9.4707689,0.0,0,16.254593,500.0,0.99918646,-0.01079966,14.921556,502.54535,-9.2063951
213.1881,-0.083019815,9.4719,0.0,0,17.051451,500.0,0.99919027,-0.42275241,15.717472,502.53134,-9.2059336
213.1925,0.058113694,9.4676533,0.0,0,17.848307,500.0,0.99855965,0.27085745,16.523272,502.50504,-9.2065706
213.1969,-0.15526254,9.4703398,0.0,0,18.0,500.0,0.99880201,-0.67339492,17.309191,502.4787,-9.2072134
213.2013,0.0048274086,9.4679899,0.0,0,18.0,500.0,0.9985007,0.022437135,17.996166,502.47333,-9.2074642
213.2057,-0.057197362,9.4736252,0.0,0,18.0,500.0,0.99927646,-0.19945724,18.409561,502.47333,-9.2130461
213.2101,0.019668702,9.4860334,0.0,0,18.0,500.0,1.0012393,0.038805783,18.407955,502.45251,-9.2233038
213.2145,0.84210044,9.5048771,0.0,0,18.0,500.0,1.0043033,3.9162722,18.200775,502.41302,-9.2413235
213.2189,0.91278416,9.5120859,0.0,0,18.0,500.0,1.0055107,4.2144089,18.069557,502.37357,-9.2692604
213.2233,0.83317214,9.5136452,0.0,0,18.0,500.0,1.0056769,3.9171641,18.055693,502.33408,-9.3069029
213.2277,0.75589031,9.5128288,0.0,0,18.0,500.0,1.0051939,3.5162423,18.085875,502.29462,-9.3455954
213.2321,0.77799541,9.5137072,0.0,0,18.0,500.0,1.005023,3.6277709,18.128668,502.22906,-9.3821802
213.2365,0.85952085,9.5133905,0.0,0,18.0,500.0,1.0048811,3.9915783,18.139469,502.16327,-9.415638
213.2409,0.86039072,9.5168276,0.0,0,18.0,500.0,1.0052767,4.0346975,18.145792,502.14502,-9.4498796
213.2453,0.78319931,9.5145912,0.0,0,18.0,500.0,1.0050929,3.6717966,18.134899,502.14502,-9.4821863
213.2497,0.78271228,9.5206156,0.0,0,18.0,500.0,1.0056118,3.6338868,18.134241,502.16895,-9.515667
213.2541,0.8748033,9.5165129,0.0,0,18.0,500.0,1.0054542,4.0337491,18.131733,502.22159,-9.547637
213.2585,0.88616252,9.5207758,0.0,0,18.0,500.0,1.0059841,4.1407437,18.123432,502.26196,-9.5811167
213.2629,0.80746824,9.5176964,0.0,0,18.0,500.0,1.0059105,3.7867193,18.122721,502.24878,-9.6153841
213.2673,0.77361667,9.5201149,0.0,0,18.0,500.0,1.0061567,3.5895078,18.11985,502.23563,-9.6490183
213.2717,0.84980386,9.5165205,0.0,0,18.0,500.0,1.0062429,3.9805346,18.113451,502.21039,-9.6813145
213.2761,0.89058679,9.5184212,0.0,0,18.0,500.0,1.0066925,4.153223,18.113752,502.18408,-9.7158585
213.2805,0.83514011,9.5136719,0.0,0,18.0,500.0,1.0060179,3.9336438,18.110374,502.13211,-9.7480011
213.2849,0.76944143,9.5176344,0.0,0,18.0,500.0,1.0070395,3.597728,18.112797,502.06631,-9.7821951
213.2893,0.82857192,9.5140839,0.0,0,18.0,500.0,1.0064242,3.7951369,18.110132,502.00552,-9.8143148
213.2937,0.89273852,9.5140858,0.0,0,18.0,500.0,1.0069581,4.1536388,18.107656,501.95291,-9.8482761
213.2981,0.84701782,9.5113564,0.0,0,18.0,500.0,1.006373,3.9713871,18.101084,501.90625,-9.8830929
213.3025,0.7699948,9.5146494,0.0,0,18.0,500.0,1.0071965,3.6285491,18.095846,501.90625,-9.9167547
213.3069,0.80058461,9.5122061,0.0,0,18.0,500.0,1.0065829,3.6943576,18.100105,501.90625,-9.9491034
213.3113,0.89911222,9.5110922,0.0,0,18.0,500.0,1.0064441,4.1286812,18.097328,501.83951,-9.9830332
213.3157,0.88406062,9.5147839,0.0,0,18.0,500.0,1.0066866,4.1336689,18.092827,501.76056,-10.016407
213.3201,0.80562836,9.5127649,0.0,0,18.0,500.0,1.0064247,3.7470298,18.094221,501.71198,-10.047992
213.3245,0.79772639,9.5143042,0.0,0,18.0,500.0,1.0062491,3.713042,18.094706,501.6857,-10.081331
213.3289,0.90000641,9.5147676,0.0,0,18.0,500.0,1.0061144,4.1557822,18.093004,501.66751,-10.114251
213.3333,0.91416705,9.5155306,0.0,0,18.0,500.0,1.0059249,4.3046384,18.091618,501.66751,-10.148782
213.3377,0.83241379,9.5144577,0.0,0,18.0,500.0,1.0056697,3.9305475,18.086367,501.66644,-10.181392
213.3421,0.79013211,9.5186138,0.0,0,18.0,500.0,1.0061445,3.6483865,18.084808,501.64011,-10.216022
213.3465,0.88782579,9.51548,0.0,0,18.0,500.0,1.0053064,4.1351709,18.087086,501.6138,-10.248981
213.3509,0.92413896,9.5210953,0.0,0,18.0,500.0,1.0061617,4.3172836,18.085531,501.60782,-10.284464
213.3553,0.84488827,9.5194349,0.0,0,18.0,500.0,1.0059364,3.9771099,18.084538,501.60782,-10.316702
213.3597,0.79577577,9.5234566,0.0,0,18.0,500.0,1.0063473,3.7087078,18.077919,501.56799,-10.350695
213.3641,0.85619247,9.5211172,0.0,0,18.0,500.0,1.0063845,3.9254699,18.078465,501.48904,-10.383245
213.3685,0.93632191,9.5242558,0.0,0,18.0,500.0,1.0066481,4.3505926,18.080677,501.4101,-10.415218
213.3729,0.86435413,9.5212584,0.0,0,18.0,500.0,1.0063875,4.0691352,18.078547,501.33112,-10.448412
213.3773,0.79948682,9.5233908,0.0,0,18.0,500.0,1.0066774,3.7255268,18.08112,501.25217,-10.481481
213.3817,0.83598459,9.5208282,0.0,0,18.0,500.0,1.0066798,3.8473921,18.076847,501.19873,-10.514658
213.3861,0.93309033,9.5222721,0.0,0,18.0,500.0,1.0069834,4.3307533,18.077084,501.14609,-10.548422
213.3905,0.89833045,9.5199394,0.0,0,18.0,500.0,1.0070565,4.2091236,18.077633,501.11188,-10.58183
213.3949,0.80920261,9.5224352,0.0,0,18.0,500.0,1.0077807,3.7537518,18.076635,501.08557,-10.616693
213.3993,0.82049668,9.519928,0.0,0,18.0,500.0,1.0073768,3.7975087,18.075207,501.06494,-10.651
213.4037,0.93092883,9.5203562,0.0,0,18.0,500.0,1.0079076,4.2781739,18.071934,501.05179,-10.683894
213.4081,0.91367042,9.5162859,0.0,0,18.0,500.0,1.0071839,4.3195262,18.073805,501.0343,-10.717157
213.4125,0.83131588,9.5168886,0.0,0,18.0,500.0,1.0076056,3.9107387,18.0718,500.99484,-10.749654
213.4169,0.81484038,9.5169296,0.0,0,18.0,500.0,1.0074148,3.7769129,18.068913,500.95535,-10.780811
213.4213,0.89849025,9.5169163,0.0,0,18.0,500.0,1.0074401,4.1253252,18.069656,500.93945,-10.815615
213.4257,0.94602334,9.5160332,0.0,0,18.0,500.0,1.0070367,4.4143906,18.065367,500.9263,-10.849872
213.4301,0.84457284,9.5170813,0.0,0,18.0,500.0,1.0073633,3.973815,18.06345,500.91315,-10.884296
213.4345,0.80386585,9.5173674,0.0,0,18.0,500.0,1.0070693,3.746032,18.060251,500.89996,-10.917517
213.4389,0.88834566,9.5150833,0.0,0,18.0,500.0,1.0064262,4.0937185,18.061296,500.85373,-10.950633
213.4433,0.95097238,9.5161772,0.0,0,18.0,500.0,1.0065017,4.4254737,18.064724,500.74847,-10.983098
213.4477,0.87931222,9.5165348,0.0,0,18.0,500.0,1.0062054,4.1423764,18.060175,500.64798,-11.017348
213.4521,0.80894786,9.5197115,0.0,0,18.0,500.0,1.0066404,3.7651856,18.059931,500.59534,-11.049068
213.4565,0.87006176,9.520546,0.0,0,18.0,500.0,1.0063508,4.0072775,18.059113,500.54272,-11.083515
213.4609,0.96016037,9.522438,0.0,0,18.0,500.0,1.0064343,4.4564805,18.058914,500.51175,-11.116636
213.4653,0.91207731,9.5208769,0.0,0,18.0,500.0,1.0060892,4.3123631,18.058815,500.48541,-11.152695
213.4697,0.83241177,9.5225506,0.0,0,18.0,500.0,1.0062758,3.9012644,18.054453,500.44452,-11.183049
213.4741,0.86104566,9.522646,0.0,0,18.0,500.0,1.0064765,3.955287,18.051855,500.39188,-11.216474
213.4785,0.9610014,9.5265942,0.0,0,18.0,500.0,1.0069115,4.4311509,18.049704,500.34677,-11.25127
213.4829,0.94898754,9.5226727,0.0,0,18.0,500.0,1.0065705,4.4464684,18.047951,500.32047,-11.285663
213.4873,0.84517032,9.5244656,0.0,0,18.0,500.0,1.0066998,3.9840498,18.049685,500.29462,-11.317525
213.4917,0.85139865,9.5220833,0.0,0,18.0,500.0,1.0068221,3.9307845,18.047066,500.29462,-11.348969
214.8932,0.82637984,9.5334711,0.0,0,18.0,4.0912095e-17,1.0093921,3.8315806,18.000158,476.46902,-11.481421
217.0932,0.86288452,9.552269,0.0,0,18.0,1.4012985e-45,1.0128917,3.9804189,17.999714,450.93622,-11.482746
219.2932,0.87650102,9.5681124,0.0,0,18.0,1.4012985e-45,1.0158184,4.0392423,18.000492,428.19247,-11.482627
221.4932,0.88980925,9.58358,0.0,0,18.0,1.4012985e-45,1.018544,4.0963993,18.000502,406.67252,-11.482148
223.6932,0.88960296,9.5975904,0.0,0,18.0,1.4012985e-45,1.0212103,4.0866728,18.00069,386.51764,-11.482708
225.8932,0.89325136,9.6101522,0.0,0,18.0,1.4012985e-45,1.023564,4.0923638,18.000786,367.44257,-11.482681
228.0932,0.9005599,9.6218853,0.0,0,18.0,1.4012985e-45,1.025697,4.1112218,17.999981,349.09869,-11.482124
230.2932,0.91673845,9.6329155,0.0,0,18.0,1.4012985e-45,1.0277736,4.1666026,17.999901,331.76779,-11.482106
232.4932,0.93582237,9.6429205,0.0,0,18.0,1.4012985e-45,1.0296026,4.2514901,17.999521,315.32111,-11.482683
234.6932,0.93746513,9.6528425,0.0,0,18.0,1.4012985e-45,1.0315232,4.2597537,18.000435,299.75323,-11.482869
236.8932,0.95072061,9.6620293,0.0,0,18.0,1.4012985e-45,1.0332502,4.3139572,18.000311,284.92667,-11.483053
239.0932,0.93851745,9.6712627,0.0,0,18.0,1.4012985e-45,1.0348693,4.2438941,17.999926,271.18179,-11.482518
241.2932,0.94916236,9.679822,0.0,0,18.0,1.4012985e-45,1.0365547,4.2819886,17.999615,257.7489,-11.482307
243.4932,0.96290672,9.6881838,0.0,0,18.0,1.4012985e-45,1.0381548,4.3340745,17.999865,244.83871,-11.48207
245.6932,0.98429877,9.6957893,0.0,0,18.0,1.4012985e-45,1.0395235,4.4300542,17.999949,232.67749,-11.482344
247.8932,0.9886108,9.7033405,0.0,0,18.0,1.4012985e-45,1.0410007,4.4481311,17.999462,221.32999,-11.482658
250.0932,0.98131973,9.7109938,0.0,0,18.0,1.4012985e-45,1.0423975,4.4126835,18.000925,210.68671,-11.482594
252.2932,0.98447174,9.7177696,0.0,0,18.0,1.4012985e-45,1.0437373,4.4204364,17.999512,200.55449,-11.482614
254.4932,0.98753238,9.7248278,0.0,0,18.0,1.4012985e-45,1.0450947,4.4162817,18.002264,190.87944,-11.482571
256.6932,1.006169,9.7312479,0.0,0,18.0,1.4012985e-45,1.0462099,4.4888473,18.000162,182.16121,-11.481578
258.8932,1.0174223,9.7371025,0.0,0,18.0,1.4012985e-45,1.0473856,4.5413918,18.000761,173.68669,-11.481424
261.0932,1.0148287,9.7426367,0.0,0,18.0,1.4012985e-45,1.048467,4.5337415,17.999989,165.64871,-11.481351
263.2932,1.0111986,9.7483301,0.0,0,18.0,1.4012985e-45,1.0494735,4.515501,17.999575,158.36333,-11.482471
265.4932,0.99780542,9.7535133,0.0,0,18.0,1.4012985e-45,1.0504893,4.4520736,18.000467,151.46552,-11.48272
267.6932,1.0083238,9.75877,0.0,0,18.0,1.4012985e-45,1.0514612,4.481154,18.000029,144.65131,-11.482658
269.8932,1.0183904,9.7634821,0.0,0,18.0,1.4012985e-45,1.0524324,4.5162134,18.00029,138.38007,-11.482739
272.0932,1.0215243,9.767971,0.0,0,18.0,1.4012985e-45,1.0532893,4.5307693,17.999111,132.36977,-11.482469
273.4932,1.0034682,9.7707577,0.0,0,18.0,1.4012985e-45,1.0537164,4.4565597,18.000902,128.78468,-11.482038