File: examples/dan-msc-case-studies/CS3/data/01 raw data/baron_test_133.csv
Time(sec),Force(kN),Jaw(mm),PowAngle(deg),Power(W),Pram,PTemp,Strain,Stress(MPa),Stroke(mm),TC1(C),wedge(mm)
0.0,1.2667143,0.32044634,0.0,0,11.076097,1.7993902e-06,0.021580214,15.797739,11.077076,23.536787,-9.1152735
1.2,1.1879802,-0.0019282954,0.0,0,11.076097,3.5158744,-0.0001301725,15.128749,11.07632,23.465767,-9.4849072
2.4,1.1655536,-0.0018371837,0.0,0,11.076097,7.1158757,-0.00011955059,14.833401,11.076646,23.426683,-9.4829416
3.6,1.1360488,-0.0016233431,0.0,0,11.076097,10.715877,-9.6411037e-05,14.463152,11.076753,23.415144,-9.4813585
4.8,1.1066587,-0.001852982,0.0,0,11.076097,14.315875,-0.0001357827,14.103682,11.076437,23.406078,-9.479003
6.0,1.094736,-0.0022088725,0.0,0,11.076097,17.915876,-0.00014824509,13.948386,11.076109,23.403852,-9.4771166
7.2,1.0835476,-0.0021442173,0.0,0,11.076097,21.515875,-0.0001494921,13.800657,11.075665,23.335333,-9.475029
8.4,1.0471523,-0.0022136495,8.0275564,0,11.076097,25.115875,-0.00012272314,13.328914,11.075093,23.367212,-9.4732056
9.6,1.0429525,-0.0019179489,27.360924,0,11.076097,28.715874,-0.00014248822,13.28056,11.077361,23.797066,-9.4705658
10.8,1.0580691,-0.0036932966,35.4258,0,11.076097,32.31588,-0.0002397424,13.466368,11.075009,26.141655,-9.4692831
12.0,1.0643113,-0.0065826993,39.841621,0,11.076097,35.915878,-0.00043775517,13.553748,11.074662,29.820723,-9.4674778
13.2,1.075175,-0.010249407,41.802109,0,11.076097,39.515881,-0.00066102302,13.707898,11.075834,34.338207,-9.4656916
14.4,1.077782,-0.012330355,43.437675,0,11.076097,43.115879,-0.00084175688,13.735432,11.07496,38.846451,-9.4632921
15.6,1.0803232,-0.015446526,44.205559,0,11.076097,46.715878,-0.0010239648,13.76878,11.075608,43.372879,-9.4613609
16.8,1.0872692,-0.017996153,45.08522,0,11.076097,50.315884,-0.0011967282,13.863822,11.075776,47.689171,-9.4594717
18.0,1.0937003,-0.021403557,45.614494,0,11.076097,53.915874,-0.0014144911,13.935999,11.075615,51.760838,-9.4571457
19.2,1.0964077,-0.024229664,45.760502,0,11.076097,57.515877,-0.0016387668,13.98385,11.076247,55.911739,-9.4550943
20.4,1.1036707,-0.027609773,45.755253,0,11.076097,61.115875,-0.0018339336,14.082929,11.075897,60.175491,-9.4526081
21.6,1.1150942,-0.031246718,45.615238,0,11.076097,64.715897,-0.0020862299,14.233137,11.07618,64.258575,-9.4509459
22.8,1.1180053,-0.034158912,45.615238,0,11.076097,68.31588,-0.0022747333,14.267308,11.075972,68.170998,-9.4490128
24.0,1.1113394,-0.036396392,45.592499,0,11.076097,71.915886,-0.0024423981,14.183064,11.076351,71.916901,-9.4469671
25.2,1.1167676,-0.038875129,45.255672,0,11.076097,75.515877,-0.0025834884,14.280036,11.076421,75.543907,-9.4448299
26.4,1.117228,-0.041931346,45.594738,0,11.076097,79.115898,-0.0027834682,14.272394,11.07534,79.066216,-9.4424915
27.6,1.1300354,-0.044602573,45.577412,0,11.076097,82.715889,-0.0029708906,14.436947,11.075973,82.617599,-9.440629
28.8,1.1290741,-0.048280388,45.615231,0,11.076097,86.315903,-0.0032267668,14.408635,11.076241,86.045876,-9.438158
30.0,1.123211,-0.050157782,46.109619,0,11.076097,89.915878,-0.003323382,14.344696,11.076372,89.503433,-9.4362164
31.2,1.1240872,-0.052771725,46.26545,0,11.076097,93.515892,-0.0034941558,14.356737,11.07672,93.070976,-9.4343081
32.4,1.1243106,-0.055926163,46.824169,0,11.076097,97.115883,-0.0037241415,14.376698,11.075989,96.459816,-9.431777
33.6,1.1387898,-0.058163624,47.058109,0,11.076097,100.7159,-0.0038885956,14.547084,11.075588,99.975876,-9.430172
34.8,1.1334355,-0.062185396,47.504883,0,11.076097,104.3159,-0.0041309749,14.482776,11.076832,103.53963,-9.4280834
36.0,1.145506,-0.065665148,47.932388,0,11.076097,107.91589,-0.0043529854,14.640471,11.076303,107.1796,-9.4264288
37.2,1.1376306,-0.067810304,47.955318,0,11.076097,111.51588,-0.0045131161,14.567999,11.075269,110.85652,-9.4244118
38.4,1.1353745,-0.070521466,48.065014,0,11.076097,115.11589,-0.0047090682,14.530728,11.076845,114.61974,-9.4220657
39.6,1.1440454,-0.073190741,48.383785,0,11.076097,118.71588,-0.0048623402,14.638437,11.076084,118.15921,-9.4202166
40.8,1.1539074,-0.076092012,48.792442,0,11.076097,122.31587,-0.0050473558,14.768705,11.075844,121.77612,-9.4181614
42.0,1.1507922,-0.078988314,48.812252,0,11.076097,125.91588,-0.0052657491,14.731262,11.076124,125.24139,-9.4159155
43.2,1.1539183,-0.083258986,49.291733,0,11.076097,129.51599,-0.0055417335,14.776654,11.075775,128.74228,-9.4136944
44.4,1.157251,-0.085546821,49.636227,0,11.076097,133.11588,-0.0056840368,14.833802,11.075856,132.32608,-9.4116392
45.6,1.1638124,-0.0883421,50.042683,0,11.076097,136.71587,-0.0058507551,14.915406,11.077506,135.91112,-9.4098825
46.8,1.1654825,-0.090713061,50.235535,0,11.076097,140.31587,-0.0060415636,14.916158,11.075828,139.55008,-9.4077168
48.0,1.1646149,-0.093853801,50.438229,0,11.076097,143.91589,-0.0062374277,14.91568,11.075905,143.16196,-9.4058371
49.2,1.1650124,-0.097037107,50.82275,0,11.076097,147.51587,-0.0064494843,14.938688,11.075736,146.87511,-9.403717
50.4,1.1671578,-0.10024505,51.082874,0,11.076097,151.11589,-0.0066434499,14.972964,11.075589,150.36879,-9.4017534
51.6,1.1784452,-0.10319142,51.196285,0,11.076097,154.71588,-0.006872586,15.12162,11.076203,154.05257,-9.3999949
52.8,1.1847543,-0.10792893,51.415619,0,11.076097,158.31589,-0.0071627107,15.191558,11.075554,157.70697,-9.3979893
54.0,1.1875753,-0.11059948,51.56982,0,11.076097,161.91588,-0.0073381453,15.22807,11.076403,161.35684,-9.3959579
55.2,1.1691279,-0.11333075,51.898502,0,11.076097,165.5159,-0.0075246319,14.986943,11.077206,164.8914,-9.3935556
56.4,1.1805542,-0.11589366,51.932369,0,11.076097,169.11588,-0.007708176,15.162678,11.076375,168.5345,-9.3912878
57.6,1.185832,-0.11910512,52.064087,0,11.076097,172.7159,-0.0078949258,15.224089,11.075453,172.21272,-9.3891659
58.8,1.1910783,-0.12212316,52.283936,0,11.076097,176.31589,-0.0080929063,15.289975,11.076715,175.84247,-9.387619
60.0,1.1892916,-0.12532271,52.377354,0,11.076097,179.91589,-0.0083224941,15.274763,11.076299,179.41824,-9.3852301
61.2,1.1954592,-0.12790295,52.635494,0,11.076097,183.51588,-0.008502299,15.350379,11.07615,182.84203,-9.3835888
62.4,1.2030526,-0.13089292,52.97607,0,11.076097,187.11591,-0.0086874068,15.444851,11.076169,186.4465,-9.381525
63.6,1.2016228,-0.13574313,53.315475,0,11.076097,190.71588,-0.008992983,15.43652,11.076539,189.90041,-9.3795004
64.8,1.1972423,-0.13997228,53.448227,0,11.076097,194.3159,-0.0092968512,15.37179,11.07615,193.60435,-9.377737
66.0,1.196842,-0.14183503,53.731876,0,11.076097,197.91588,-0.009418292,15.379468,11.076081,197.0983,-9.3755827
67.2,1.1978817,-0.14517204,53.975826,0,11.076097,201.5159,-0.0096252114,15.399279,11.076475,200.68102,-9.3737144
68.4,1.201642,-0.14833805,54.305061,0,11.076097,205.11589,-0.0098104738,15.455852,11.075112,204.34323,-9.3716326
69.6,1.2041054,-0.15182775,54.406349,0,11.076097,208.7159,-0.010080868,15.495694,11.075301,207.97491,-9.3692446
70.8,1.205649,-0.15517315,54.624008,0,11.076097,212.31589,-0.010298787,15.508377,11.075905,211.72127,-9.367507
72.0,1.2018203,-0.15841037,54.624744,0,11.076097,215.91591,-0.010504862,15.473159,11.076069,215.29877,-9.365387
73.2,1.2032282,-0.16152397,54.931637,0,11.076097,219.51588,-0.010679387,15.484148,11.075361,218.90282,-9.3632479
74.4,1.2073325,-0.16476184,55.206024,0,11.076097,223.11591,-0.010941412,15.550448,11.076106,222.43797,-9.3612299
75.6,1.2073091,-0.16862074,55.239254,0,11.076097,226.7159,-0.011168228,15.550732,11.076459,226.14276,-9.3593531
76.8,1.215786,-0.1731658,55.521759,0,11.076097,230.3159,-0.011481316,15.655293,11.076318,229.63876,-9.3574095
78.0,1.2089881,-0.17726123,55.535885,0,11.076097,233.91588,-0.011732683,15.579483,11.076586,233.29907,-9.3553944
79.2,1.2182641,-0.17903686,55.843506,0,11.076097,237.5159,-0.011884494,15.684748,11.075466,236.81218,-9.353755
80.4,1.2068756,-0.18269424,55.871155,0,11.076097,241.11588,-0.012099799,15.558308,11.076214,240.55527,-9.3516254
81.6,1.2079265,-0.18590394,56.129147,0,11.076097,244.71588,-0.012310001,15.572618,11.076648,244.12766,-9.3500166
82.8,1.2017294,-0.189356,56.425766,0,11.076097,248.31589,-0.012542713,15.486284,11.076596,247.62688,-9.3475294
84.0,1.2074499,-0.19254972,56.670666,0,11.076097,251.91588,-0.012774576,15.56065,11.076476,251.16362,-9.3457556
85.2,1.2056694,-0.19656524,56.711422,0,11.076097,255.51588,-0.013001168,15.550439,11.075556,254.87276,-9.3437147
86.4,1.2125812,-0.19971991,56.8489,0,11.076097,259.11612,-0.013217468,15.644522,11.076504,258.56873,-9.341608
87.6,1.2184671,-0.20327705,56.986084,0,11.076097,262.71588,-0.01346489,15.738948,11.076915,262.20923,-9.3394127
88.8,1.2184995,-0.20666517,56.986084,0,11.076097,266.31586,-0.013710086,15.716628,11.076283,265.91479,-9.3374319
90.0,1.2132103,-0.21132064,57.162148,0,11.076097,269.91586,-0.013991191,15.677801,11.076342,269.49054,-9.3351574
91.2,1.2116315,-0.2159027,57.260738,0,11.076097,273.51587,-0.014271516,15.634075,11.076539,273.04269,-9.3335562
92.4,1.2080631,-0.21763264,57.434883,0,11.076097,277.11588,-0.014409155,15.599011,11.075998,276.59418,-9.3317375
93.6,1.2102203,-0.22072423,57.535397,0,11.076097,280.71588,-0.014616943,15.62324,11.075179,280.07086,-9.3298092
94.8,1.2041775,-0.22413525,57.810051,0,11.076097,284.31589,-0.014833728,15.552369,11.075802,283.72717,-9.3277006
96.0,1.2054642,-0.22780949,57.810051,0,11.076097,287.91589,-0.015050917,15.574212,11.07539,287.38998,-9.3258991
97.2,1.2079097,-0.23067397,58.045536,0,11.076097,291.51587,-0.015269076,15.619272,11.075745,291.10394,-9.3233929
98.4,1.2052902,-0.23368767,58.073727,0,11.076097,295.11591,-0.015471591,15.585609,11.075753,294.80499,-9.3211012
99.6,1.2221165,-0.23902948,58.073727,0,11.076097,298.71588,-0.015809176,15.815602,11.075836,298.50238,-9.3192968
100.8,1.2196898,-0.24181755,58.015751,0,11.076097,302.31592,-0.015975336,15.780058,11.076466,302.26715,-9.3173733
102.0,1.2030553,-0.24413729,58.073727,0,11.076097,305.91589,-0.016161684,15.572598,11.075326,305.71899,-9.3152905
103.2,1.2020395,-0.24790178,58.335007,0,11.076097,309.51593,-0.016390432,15.561172,11.075722,309.08594,-9.3136063
104.4,1.2126983,-0.2508561,58.390797,0,11.076097,313.11591,-0.016582895,15.70065,11.07585,312.53931,-9.3118715
105.6,1.2145888,-0.25429568,58.62178,0,11.076097,316.71588,-0.016790558,15.726665,11.076036,315.97711,-9.3100767
106.8,1.2213384,-0.25800771,59.105309,0,11.076097,320.31592,-0.017079901,15.821187,11.0759,319.37054,-9.3078995
108.0,1.2184842,-0.26354188,59.335602,0,11.076097,323.91592,-0.017415879,15.7776,11.076769,322.92725,-9.3059711
109.2,1.2012899,-0.26576748,59.599636,0,11.076097,327.51593,-0.017553555,15.556792,11.075166,326.43488,-9.303688
110.4,1.203837,-0.26883012,59.82851,0,11.076097,331.11594,-0.017756587,15.61548,11.075734,330.1076,-9.3017807
111.6,1.2093226,-0.27201393,59.983883,0,11.076097,334.71588,-0.017988982,15.680584,11.075766,333.73492,-9.2997036
112.8,1.2069325,-0.27547613,60.084225,0,11.076097,338.31595,-0.018186755,15.647166,11.075256,337.53946,-9.2975817
114.0,1.2085153,-0.27894476,60.155125,0,11.076097,341.91589,-0.018417757,15.662427,11.075315,341.21588,-9.2955103
115.2,1.2105318,-0.28235343,60.302395,0,11.076097,345.51593,-0.018645676,15.713836,11.076752,345.07022,-9.2937117
116.4,1.214169,-0.28507456,60.264713,0,11.076097,349.11594,-0.018841485,15.756023,11.07576,348.78339,-9.291688
117.6,1.2165458,-0.2903572,60.084568,0,11.076097,352.71591,-0.019167613,15.8,11.075686,352.61084,-9.289794
118.8,1.2158043,-0.29520762,60.212101,0,11.076097,356.31592,-0.019483777,15.778268,11.075859,356.20874,-9.2879534
120.0,1.2192578,-0.29645342,60.223576,0,11.076097,359.91589,-0.0195668,15.827974,11.076886,359.77551,-9.2860041
121.2,1.1950275,-0.29951471,60.262779,0,11.076097,363.51596,-0.01978831,15.530313,11.075315,363.38669,-9.2843895
122.4,1.2052734,-0.30246755,60.25877,0,11.076097,367.11591,-0.019960484,15.644605,11.07635,367.06363,-9.2822628
123.6,1.2066668,-0.30548409,60.314934,0,11.076097,370.71594,-0.020145202,15.674234,11.077074,370.4407,-9.2801285
124.8,1.1919647,-0.30841926,60.556622,0,11.076097,374.31589,-0.020355305,15.480505,11.075571,373.87537,-9.2776728
126.0,1.2166388,-0.3108834,60.573296,0,11.076097,377.91589,-0.020522747,15.806464,11.076874,377.49942,-9.2758694
127.2,1.2206085,-0.31454593,60.556709,0,11.076097,381.5159,-0.020750705,15.873203,11.075208,381.25491,-9.2740602
128.4,1.2230679,-0.32040998,60.556648,0,11.076097,385.11591,-0.021125859,15.908397,11.076054,384.94855,-9.271904
129.6,1.215656,-0.32193094,60.787346,0,11.076097,388.71591,-0.021245824,15.80479,11.076167,388.38794,-9.2698002
130.8,1.20726,-0.32413453,60.787346,0,11.076097,392.31589,-0.021387551,15.691566,11.07494,391.99405,-9.2675295
132.0,1.2000762,-0.32720882,60.950813,0,11.076097,395.91589,-0.021576071,15.609869,11.07669,395.56473,-9.2656393
133.2,1.2064319,-0.33015558,60.988117,0,11.076097,399.5159,-0.02175495,15.701564,11.075536,399.21344,-9.2641163
134.4,1.2124544,-0.33220646,61.018063,0,11.076097,403.11591,-0.021920541,15.782139,11.076402,402.71686,-9.2621517
135.6,1.2139994,-0.3354612,61.237789,0,11.076097,406.71591,-0.022125799,15.79858,11.075733,406.19189,-9.2601118
136.8,1.2280263,-0.34153751,61.237789,0,11.076097,410.31592,-0.02252234,15.995187,11.075224,409.85773,-9.2583275
138.0,1.2221655,-0.34198332,61.468498,0,11.076097,413.91592,-0.022527728,15.901825,11.077265,413.37317,-9.2563686
139.2,1.2100494,-0.34503797,61.468498,0,11.076097,417.51593,-0.022759229,15.763758,11.074638,416.98715,-9.2545185
140.4,1.2129651,-0.34802195,61.546837,0,11.076097,421.11591,-0.022930918,15.81137,11.075369,420.74692,-9.2527781
141.6,1.2268161,-0.35066435,61.688229,0,11.076097,424.71594,-0.023108924,15.980411,11.076751,424.31375,-9.2507648
142.8,1.2195699,-0.35700065,61.688229,0,11.076097,428.31592,-0.02351452,15.890709,11.076605,428.05182,-9.2489948
144.0,1.2023734,-0.35708886,61.688229,0,11.076097,431.91595,-0.023547199,15.665615,11.07597,431.76852,-9.2465639
145.2,1.2119125,-0.36055732,61.682468,0,11.076097,435.51593,-0.023740049,15.796339,11.075539,435.51859,-9.2449341
146.4,1.2128216,-0.36231208,61.604244,0,11.076097,439.11594,-0.023866443,15.813133,11.076097,439.19424,-9.2428751
147.6,1.2195679,-0.36557484,61.688229,0,11.076097,442.71591,-0.024084048,15.90356,11.075548,442.66873,-9.2410507
148.8,1.2195784,-0.36881161,61.688229,0,11.076097,446.31595,-0.024300002,15.903394,11.076238,446.16162,-9.2384291
150.0,1.2042549,-0.37104979,61.756489,0,11.076097,449.91592,-0.024421254,15.719665,11.076311,449.63181,-9.2364836
151.2,1.2192175,-0.37213504,60.089771,0,11.076097,449.9989,-0.024490118,15.919412,11.075877,452.82602,-9.2363806
152.4,1.2128947,-0.37311089,57.969429,0,11.076097,449.9989,-0.024581676,15.825488,11.07629,455.08035,-9.2363052
153.6,1.1882496,-0.3719945,56.130398,0,11.076097,449.9989,-0.024515873,15.497475,11.075766,455.95413,-9.2361507
154.8,1.1663632,-0.37162033,54.423473,0,11.076097,449.9989,-0.024467025,15.224984,11.075541,455.87485,-9.2357817
156.0,1.1550318,-0.36916721,53.316677,0,11.076097,449.9989,-0.024289411,15.073683,11.076719,455.09006,-9.2361145
157.2,1.0923789,-0.3709425,52.635521,0,11.076097,449.9989,-0.024440048,14.262973,11.07546,453.77942,-9.235796
158.4,1.0046371,-0.3693805,52.676662,0,11.076097,449.9989,-0.02433143,13.106926,11.076242,452.28384,-9.2358294
159.6,0.95903742,-0.36875755,53.044666,0,11.076097,449.9989,-0.024279399,12.512698,11.075957,450.97739,-9.2357311
160.8,0.94449526,-0.36856687,53.664169,0,11.076097,449.9989,-0.024255853,12.328222,11.07663,449.87064,-9.235817
162.0,0.9024623,-0.36890563,54.480091,0,11.076097,449.9989,-0.024308898,11.766738,11.076819,449.03653,-9.2353964
163.2,0.88713318,-0.36937195,55.111839,0,11.076097,449.9989,-0.024333462,11.577163,11.075829,448.63089,-9.2355995
164.4,0.86783832,-0.36972266,55.535885,0,11.076097,449.9989,-0.024349375,11.34481,11.07522,448.44562,-9.2358274
165.6,0.85627657,-0.37321746,55.890285,0,11.076097,449.9989,-0.024551019,11.174017,11.076012,448.55661,-9.2358837
166.8,0.82908654,-0.37294561,56.129276,0,11.076097,449.9989,-0.024575982,10.815207,11.076254,448.75726,-9.2360201
168.0,0.81910807,-0.37368652,56.425766,0,11.076097,449.9989,-0.024597809,10.696774,11.076302,449.06271,-9.2363472
169.2,0.81817126,-0.37667879,56.425777,0,11.076097,449.9989,-0.024809243,10.682733,11.075925,449.36954,-9.2365465
170.4,0.80657709,-0.37652457,56.304047,0,11.076097,449.9989,-0.024774784,10.530127,11.075645,449.72385,-9.236433
171.6,0.80003566,-0.37672275,56.129154,0,11.076097,449.9989,-0.024827287,10.453866,11.076113,450.03287,-9.236413
172.8,0.79853433,-0.37748948,56.129154,0,11.076097,449.9989,-0.024850791,10.418139,11.076632,450.1134,-9.2365103
174.0,0.80114979,-0.37931529,55.84351,0,11.076097,449.9989,-0.024961235,10.461162,11.077298,450.30981,-9.2360859
175.2,0.79647839,-0.3797484,55.84351,0,11.076097,449.9989,-0.024998521,10.400458,11.074903,450.44272,-9.2357922
176.4,0.79735404,-0.37983385,55.535892,0,11.076097,449.9989,-0.025014834,10.407721,11.07566,450.54803,-9.2357912
177.6,0.79864794,-0.38314071,55.239807,0,11.076097,449.9989,-0.025212636,10.420051,11.076047,450.66995,-9.2356958
178.8,0.79281867,-0.38153222,55.239262,0,11.076097,449.9989,-0.025099568,10.354698,11.075446,450.57013,-9.2357244
180.0,0.78053719,-0.38202801,55.146778,0,11.076097,449.9989,-0.025161063,10.196772,11.075867,450.44031,-9.2356901
181.2,0.79457921,-0.38138202,55.061237,0,11.076097,449.9989,-0.025119528,10.382687,11.075827,450.3056,-9.2356892
182.4,0.80268782,-0.38278076,55.155697,0,11.076097,449.9989,-0.025196051,10.476541,11.075141,450.17618,-9.2360983
183.6,0.78195179,-0.38315788,55.239243,0,11.076097,449.9989,-0.025204619,10.203322,11.076172,449.98035,-9.2358131
184.8,0.79486215,-0.38280505,55.252262,0,11.076097,449.9989,-0.025208946,10.383881,11.076466,449.77081,-9.2362165
186.0,0.80299783,-0.3836039,55.535885,0,11.076097,449.9989,-0.025247237,10.475199,11.076271,449.73129,-9.2359753
187.2,0.79672301,-0.38554415,55.535885,0,11.076097,449.9989,-0.025368052,10.409453,11.077012,449.6503,-9.2362738
188.4,0.79131395,-0.3854624,55.535942,0,11.076097,449.9989,-0.02536449,10.3384,11.076568,449.71091,-9.2362232
189.6,0.78890318,-0.38596761,55.535946,0,11.076097,449.9989,-0.025417212,10.301824,11.077188,449.87085,-9.2365808
190.8,0.79046273,-0.38563278,55.55254,0,11.076097,449.9989,-0.025377823,10.321076,11.075595,449.88782,-9.236352
192.0,0.79597402,-0.38726765,55.535892,0,11.076097,449.9989,-0.025490435,10.383776,11.076141,449.98346,-9.2362099
193.2,0.80741286,-0.38831741,55.535892,0,11.076097,449.9989,-0.025549119,10.550977,11.076823,450.12045,-9.2359867
194.4,0.79109323,-0.38819158,55.470852,0,11.076097,449.9989,-0.025560567,10.341849,11.07631,450.17133,-9.2362032
195.2805,0.79173106,0.023584789,42.008068,0,11.076099,3.2070339,0.0016517653,10.0524,11.0749,450.1593,-9.2368078
195.2829,0.84534794,0.023490829,28.777111,0,11.076099,1.3864e-16,0.0017334977,10.81896,11.07626,450.17365,-9.2366247
195.2853,0.77503639,0.024831139,15.546151,0,11.076099,5.9934041e-33,0.0016759562,9.8642607,11.075443,450.18799,-9.236124
195.2877,0.80414575,0.028105406,2.3151901,0,11.076099,0.0,0.0015733974,10.157128,11.077708,450.20233,-9.235754
195.2901,0.79899263,0.028931288,0.0,0,11.076099,0.0,0.0016959126,10.140694,11.077323,450.25809,-9.2366104
195.2925,0.7786029,0.026823122,0.0,0,11.076099,0.0,0.0019873856,9.904954,11.07515,450.32263,-9.2366066
195.2949,0.77793527,0.022460518,0.0,0,11.076099,0.0,0.0017534061,9.8884268,11.074231,450.38721,-9.2358255
195.2973,0.78080559,0.021821532,0.0,0,11.076099,0.0,0.0014242542,9.8408279,11.074032,450.45175,-9.2359924
195.2997,0.77749282,0.023194149,0.0,0,11.076099,0.0,0.0013759271,9.9409227,11.076919,450.465,-9.2366276
195.3021,0.77269852,0.024110718,0.0,0,11.076099,0.0,0.0015227406,9.8904238,11.077372,450.45065,-9.2364483
195.3045,0.76205105,0.022496128,0.0,0,11.076099,0.0,0.0016841672,9.742281,11.074949,450.43631,-9.2361441
195.3069,0.76427728,0.022940295,0.0,0,11.076099,0.0,0.0017552852,9.7289915,11.072604,450.42197,-9.2349939
195.3093,0.76624101,0.025296208,0.0,0,11.076099,0.0,0.0016545547,9.7840109,11.074449,450.40762,-9.2359276
195.3117,0.77377409,0.028692314,0.0,0,11.076099,0.0,0.0016222068,9.7995987,11.075011,450.39328,-9.2361307
195.3141,0.75800687,0.028062822,0.0,0,11.076099,0.0,0.0017516093,9.6798401,11.075347,450.37894,-9.2364283
195.3165,0.76396924,0.024670266,0.0,0,11.076099,0.0,0.0018251712,9.6963816,11.079052,450.36459,-9.2365656
195.3189,0.75714171,0.021085855,0.0,0,11.076099,0.0,0.0017042637,9.7283802,11.076558,450.34595,-9.2346706
195.3213,0.76883662,0.022111759,0.0,0,11.076099,0.0,0.0014337538,9.6711454,11.072958,450.31726,-9.2350101
195.3237,0.76278067,0.025433403,0.0,0,11.076099,0.0,0.0015042851,9.7613144,11.075665,450.28857,-9.2366009
195.3261,0.76144081,0.025324682,0.0,0,11.076099,0.0,0.0016733244,9.6056604,11.074174,450.25989,-9.2354565
195.3285,0.76053727,0.022397695,0.0,0,11.076099,0.0,0.0017237465,9.5840082,11.073982,450.2348,-9.2357731
195.3309,0.77416593,0.022532089,0.0,0,10.976462,0.0,0.0016667286,9.8535042,11.074379,450.2348,-9.2357159
195.3333,0.76328057,0.024810877,0.0,0,10.615488,0.0,0.0015190635,9.6824484,11.075585,450.2348,-9.2358913
195.3357,0.75344086,0.028303504,0.0,0,10.254516,0.0,0.0015586357,9.5928307,11.059528,450.2348,-9.2360945
195.3381,0.76646101,0.028357325,0.0,0,9.8935413,0.0,0.0017960732,9.8028526,10.927361,450.2348,-9.2363634
195.3405,0.74400693,0.023817223,0.0,0,9.532568,0.0,0.0018542368,9.3465347,10.642642,450.81393,-9.2354488
195.3429,0.7980184,0.022354169,0.0,0,9.1800203,0.0,0.0017372564,10.08124,10.249225,451.42355,-9.2361727
195.3453,5.3034201,0.25635907,0.0,0,8.8288527,0.0,0.016095962,66.625114,9.7969112,452.03314,-9.2314911
195.3477,5.6912546,0.73377103,0.0,0,8.4910202,0.0,0.049657863,67.794289,9.2791271,452.64276,-9.2329769
195.3501,5.960258,1.1696995,0.0,0,8.1570358,0.0,0.080977947,69.828346,8.8180838,452.00711,-9.2318974
195.3525,5.9794683,1.5579424,0.0,0,7.8342905,0.0,0.1093654,68.466469,8.449234,451.00998,-9.2308111
195.3549,6.3608489,1.8657393,0.0,0,7.51653,0.0,0.13252786,71.075905,8.1195965,450.01285,-9.2296982
195.3573,6.381423,2.1584213,0.0,0,7.2082467,0.0,0.1548695,69.43219,7.8065529,449.01572,-9.2317352
195.3597,6.5848846,2.4599719,0.0,0,6.9060383,0.0,0.1782352,70.069206,7.5064373,447.38559,-9.2313528
195.3621,6.6500282,2.741895,0.0,0,6.611557,0.0,0.20148738,69.190514,7.2270837,445.33347,-9.231595
195.3645,6.8949308,3.0096502,0.0,0,6.3240371,0.0,0.2239669,70.139633,6.9452605,443.28134,-9.2311945
195.3669,7.0038018,3.291307,0.0,0,6.0427437,0.0,0.24757013,69.595177,6.6583538,441.22922,-9.2322464
195.3693,7.225265,3.5840399,0.0,0,5.7692871,0.0,0.27245352,70.031593,6.3725462,439.66461,-9.2333069
195.3717,7.4395409,3.871444,0.0,0,5.5006094,0.0,0.29781407,70.271729,6.082633,438.75958,-9.2312202
195.3741,7.6198101,4.1586547,0.0,0,5.2404494,0.0,0.32425529,70.159966,5.7953095,437.85452,-9.2304535
195.3765,7.7872615,4.4404063,0.0,0,4.9838004,0.0,0.35106522,69.906006,5.5074053,436.94946,-9.2306938
195.3789,7.9970922,4.7179847,0.0,0,4.7363601,0.0,0.3774879,69.792145,5.2298026,435.202,-9.2321796
195.3813,8.1938162,4.9944129,0.0,0,4.4912419,0.0,0.40404657,69.608063,4.9581041,430.92758,-9.2334356
195.3837,8.3985596,5.2554588,0.0,0,4.2558494,0.0,0.43030933,69.554413,4.6976109,426.65314,-9.2324553
195.3861,8.5482807,5.5050025,0.0,0,4.0217218,0.0,0.45699742,68.869064,4.4454284,422.37869,-9.2315683
195.3885,8.7447195,5.7388453,0.0,0,3.7978458,0.0,0.48254627,68.647026,4.2028303,418.28629,-9.2323761
195.3909,8.973834,5.9705825,0.0,0,3.5743463,0.0,0.50739539,68.746483,3.97192,416.43835,-9.2325668
195.3933,9.2094755,6.2024364,0.0,0,3.3612814,0.0,0.53271133,68.830933,3.743464,414.59042,-9.2314205
195.3957,9.4383659,6.4272466,0.0,0,3.1483054,0.0,0.55851227,68.73967,3.5221958,412.74252,-9.2305317
195.3981,9.6899433,6.6417274,0.0,0,2.9451032,0.0,0.58450824,68.705307,3.3047574,410.89459,-9.2297955
195.4005,9.954195,6.8514609,0.0,0,2.7424951,0.0,0.61066049,68.781342,3.0947952,409.00089,-9.2298899
195.4029,10.287563,7.0616293,0.0,0,2.5483842,0.0,0.6362772,69.275871,2.8852088,407.10208,-9.2306337
195.4053,10.621018,7.2752752,0.0,0,2.3556643,0.0,0.66242057,69.692924,2.6779406,405.20328,-9.2289019
195.4077,10.91037,7.4805217,0.0,0,2.1702452,0.0,0.68930387,69.702087,2.475105,403.30447,-9.2297831
195.4101,11.237967,7.6726384,0.0,0,1.9869331,0.0,0.71622801,69.908508,2.2822969,398.47406,-9.2297163
195.4125,11.624269,7.8574972,0.0,0,1.8098055,0.0,0.74251074,70.395546,2.0891955,392.53171,-9.229641
195.4149,12.058277,8.046463,0.0,0,1.6354215,0.0,0.76861095,71.142754,1.9019283,386.58939,-9.2289658
195.4173,12.450218,8.2318354,0.0,0,1.4662145,0.0,0.79465401,71.613907,1.7178319,380.64703,-9.2292204
195.4197,12.879704,8.412075,0.0,0,1.3003267,0.0,0.82182741,72.037483,1.5451165,376.5278,-9.2276096
195.4221,13.358578,8.5854902,0.0,0,1.1387058,0.0,0.84936649,72.676781,1.3661903,373.90009,-9.2291021
195.4245,13.899371,8.7509508,0.0,0,0.98092979,0.0,0.87605786,73.612236,1.1963326,371.27237,-9.2297344
195.4269,14.433774,8.9168301,0.0,0,0.82657492,0.0,0.90239275,74.50174,1.0307016,368.64465,-9.2295179
195.4293,14.983843,9.0831976,0.0,0,0.67652696,0.0,0.92880601,75.287834,0.87038183,366.90192,-9.2270422
195.4317,15.544981,9.2392836,0.0,0,0.52908367,0.0,0.9556765,76.081627,0.70999223,366.634,-9.2279434
195.4341,16.176657,9.3858318,0.0,0,0.38628361,0.0,0.98280883,77.047935,0.56266361,366.36606,-9.2272158
195.4365,14.081748,9.4236145,0.0,0,0.24541798,0.0,0.99051845,66.695267,0.47086677,366.09814,-9.2294827
195.4389,12.535526,9.4406328,0.0,0,0.10962597,0.0,0.99256951,59.21273,0.42226279,366.59293,-9.2311277
195.4413,11.860456,9.4435024,0.0,0,-0.02551849,0.0,0.99205357,56.042847,0.39350957,370.13818,-9.2307634
195.4437,11.511198,9.4535332,0.0,0,-0.15795054,0.0,0.99433094,54.212566,0.36737797,373.68344,-9.2319317
195.4461,11.508939,9.4526291,0.0,0,-0.29038256,0.0,0.99533999,54.164249,0.32489142,377.2287,-9.2321653
195.4485,11.841187,9.4595003,0.0,0,-0.42281455,0.0,0.99716038,55.615932,0.26430172,380.79953,-9.2311392
195.4509,11.965556,9.4699488,0.0,0,-0.55524653,0.0,0.99775434,56.197395,0.19682303,385.36752,-9.2309475
195.4533,11.940019,9.4801474,0.0,0,-0.68767852,0.0,0.99841672,56.017433,0.12949768,389.93549,-9.2316751
195.4557,11.788445,9.4861622,0.0,0,-0.8201105,0.0,0.99980134,55.234634,0.075586513,394.50345,-9.2311268
195.4581,11.553044,9.4855461,0.0,0,-0.95254248,0.0,1.0016053,54.04768,0.033332679,399.07141,-9.2312288
195.4605,11.24468,9.4833879,11.982427,0,-1.0849745,0.0,1.0016011,52.59457,0.004876439,402.34802,-9.2322693
195.4629,10.808871,9.4854536,26.079134,0,-0.72869962,450.0,1.0004696,50.649399,-0.0089396769,405.39679,-9.2318258
195.4653,10.300905,9.4898806,40.175846,0,-0.27021334,450.0,1.0004954,48.264488,-0.0050916811,408.44556,-9.2317667
195.4677,9.8661232,9.4913893,54.272552,0,0.18827303,450.0,1.0012929,46.196838,-0.0017020011,411.49432,-9.2329683
195.4701,9.5315418,9.4856987,58.85376,0,0.64675945,450.0,1.0015072,44.598663,0.003418291,414.39502,-9.2324753
195.4725,9.2234678,9.4817991,58.85376,0,1.1052461,450.0,1.0010327,43.149799,0.00010408338,417.2244,-9.2319698
195.4749,8.9613991,9.4900761,58.85376,0,1.5637323,450.0,1.0011722,41.942459,0.016850069,420.05377,-9.2330828
195.4773,7.6969161,9.4939318,58.85376,0,2.0222187,450.0,1.0009022,36.147163,0.071225211,422.88315,-9.2343502
195.4797,5.4544101,9.4830713,57.147205,0,2.4807055,450.0,0.99951553,25.812393,0.18583381,425.28635,-9.2359686
195.4821,1.8692715,9.4515886,53.734207,0,2.9391916,450.0,0.99561024,9.1143713,0.41502604,427.26343,-9.2379923
195.4845,0.15598635,9.3890495,50.321213,0,3.3976781,450.0,0.98444861,0.95374751,0.85664648,429.24048,-9.239749
195.4869,-0.31491721,9.4282656,46.908215,0,3.8561647,450.0,0.98998964,-1.3292246,1.5753695,431.21756,-9.2402029
195.4893,-0.032553595,9.4159927,44.604492,0,4.314651,450.0,0.98723406,-0.16577268,2.4023747,433.01428,-9.2400208
195.4917,0.057057779,9.4244547,44.604492,0,4.7731371,450.0,0.98938096,0.24027802,3.1283059,434.43652,-9.2414732
195.4941,-0.049102314,9.4233809,44.604492,0,5.2316236,450.0,0.99039328,-0.2400569,3.6617928,435.85876,-9.2404804
195.4965,-0.047218379,9.428606,44.604492,0,5.6901102,450.0,0.99120069,-0.29068571,4.0878749,437.28098,-9.2404242
195.4989,-0.049943764,9.432126,44.111042,0,6.1485963,450.0,0.99063021,-0.21308044,4.4993062,438.63315,-9.2401094
195.5013,-0.021303613,9.4367933,40.821724,0,6.6070824,450.0,0.99053997,-0.098766185,4.9092631,439.58835,-9.2383919
195.5037,-0.036398388,9.4336281,37.532402,0,7.0655694,450.0,0.99077201,-0.14955378,5.331409,440.54352,-9.2387247
195.5061,-0.05092768,9.4256353,34.243084,0,7.524056,450.0,0.99089015,-0.26150283,5.791852,441.49869,-9.2386026
195.5085,-0.050070785,9.4200144,30.953762,0,7.9825425,450.0,0.98990643,-0.12643515,6.2693415,442.45386,-9.2376852
195.5109,-0.14065509,9.423501,30.871582,0,8.4410286,450.0,0.98906523,-0.69346923,6.7557988,443.19144,-9.2381554
195.5133,0.086499289,9.4248953,30.871582,0,8.8995142,450.0,0.98874271,0.33599749,7.2522922,443.92343,-9.2375898
195.5157,-0.069660828,9.4259796,30.871582,0,9.3580008,450.0,0.98979849,-0.16304195,7.7357497,444.65543,-9.2366009
195.5181,-0.20805952,9.4253588,30.871582,0,9.8164873,450.0,0.99078333,-1.0714264,8.2002449,445.38742,-9.2363853
195.5205,0.0865376,9.4202223,27.080107,0,10.274974,450.0,0.98978293,0.33538389,8.6658602,446.03873,-9.2374439
195.5229,-0.10191973,9.4237719,22.340857,0,10.73346,450.0,0.98891354,-0.42969677,9.1348,446.66986,-9.2356119
195.5253,-0.092905626,9.4300308,17.601603,0,11.191947,450.0,0.98925841,-0.46925184,9.6040897,447.30096,-9.2356615
195.5277,0.043697026,9.4280462,12.862352,0,11.650433,450.0,0.99011409,0.22512533,10.083409,447.9321,-9.2355108
195.5301,-0.090257496,9.4218588,11.085205,0,12.10892,450.0,0.99038976,-0.46361467,10.551691,448.49597,-9.2365398
195.5325,-0.061054774,9.419981,11.085205,0,12.567406,450.0,0.98958224,-0.36867139,11.020517,449.01953,-9.2348614
195.5349,0.046574052,9.4224081,11.085205,0,13.025892,450.0,0.98862195,0.2407257,11.490153,449.54306,-9.2339029
195.5373,-0.10402298,9.4262438,11.085205,0,13.484379,450.0,0.98912001,-0.45835331,11.940938,450.06662,-9.2349701
195.5397,-0.054112237,9.4253502,9.8903522,0,13.942865,450.0,0.98987883,-0.30620211,12.39862,450.53528,-9.2340956
195.5421,0.034050617,9.4202175,7.2352128,0,14.401352,450.0,0.99006319,0.14631552,12.865609,450.93692,-9.234436
195.5445,-0.081309445,9.4188166,4.5800734,0,14.859838,450.0,0.9890995,-0.35413763,13.337485,451.33853,-9.2338171
195.5469,0.0049036178,9.4238586,1.9249345,0,15.318325,450.0,0.98853785,0.0048037027,13.819937,451.74017,-9.2343588
195.5493,-0.034462139,9.4283562,0.0,0,15.776811,450.0,0.98894072,-0.1196942,14.301363,452.13193,-9.2348957
195.5517,-0.1542476,9.4269533,0.0,0,16.235298,450.0,0.99013108,-0.67806667,14.773073,452.49771,-9.234333
195.5541,-0.02049808,9.4200382,0.0,0,16.693783,450.0,0.99008006,-0.16706549,15.231099,452.86346,-9.2342358
195.5565,0.046117276,9.4187164,0.0,0,17.152269,450.0,0.98915124,0.19094324,15.693525,453.22922,-9.23417
195.5589,-0.1751052,9.4223032,0.0,0,17.610758,450.0,0.98840469,-0.77662754,16.144323,453.5871,-9.2340384
195.5613,0.02914682,9.4246016,0.0,0,17.999975,450.0,0.98885727,0.044817604,16.599695,453.87396,-9.2350092
195.5637,0.0025480678,9.4187155,0.0,0,18.0,450.0,0.98893219,-0.0011475192,17.060505,454.16086,-9.2334566
195.5661,-0.10742928,9.4151497,0.0,0,18.0,450.0,0.98918128,-0.43187037,17.484644,454.44772,-9.2345858
195.5685,-0.022838939,9.4191494,0.0,0,18.0,450.0,0.98929667,-0.15518251,17.86767,454.73459,-9.2358551
195.5709,-0.01798775,9.42451,0.0,0,18.0,450.0,0.98867977,-0.11131771,18.187683,454.96838,-9.237422
195.5733,-0.094538391,9.4331474,0.0,0,18.0,450.0,0.98996252,-0.49243441,18.414148,455.19791,-9.2398329
195.5757,-0.025648708,9.4356031,0.0,0,18.0,450.0,0.99199122,-0.10276353,18.524794,455.4274,-9.2436132
195.5781,0.14296989,9.4370527,0.0,0,18.0,450.0,0.99312246,0.63441575,18.503954,455.65689,-9.2512531
195.5805,0.56038612,9.4459057,0.0,0,18.0,450.0,0.99370009,2.6619885,18.379501,455.9079,-9.2616367
195.5829,0.61569649,9.4496918,0.0,0,18.0,450.0,0.99334949,2.9176166,18.238924,456.16608,-9.2762518
195.5853,0.57486218,9.449626,0.0,0,18.0,450.0,0.99326324,2.7703843,18.118256,456.42426,-9.2913132
195.5877,0.51435661,9.4456806,0.0,0,18.0,450.0,0.9940145,2.385916,18.045393,456.68246,-9.3094301
195.5901,0.54988497,9.4403353,0.0,0,18.0,450.0,0.99371588,2.6061926,18.030136,456.91177,-9.3291931
195.5925,0.56451851,9.4440241,0.0,0,18.0,450.0,0.99345809,2.6396377,18.035023,457.11975,-9.350316
195.5949,0.53688949,9.4514666,0.0,0,18.0,450.0,0.99337053,2.5856955,18.049931,457.32776,-9.3710012
195.5973,0.532444,9.4523783,0.0,0,18.0,450.0,0.99354124,2.4838138,18.077414,457.53574,-9.390089
195.5997,0.49902287,9.4452105,0.0,0,18.0,450.0,0.99398637,2.3735025,18.104366,457.7265,-9.4083738
195.6021,0.55826521,9.4401617,0.0,0,18.0,450.0,0.99367338,2.5847559,18.12508,457.89145,-9.4263687
195.6045,0.58637029,9.442461,0.0,0,18.0,450.0,0.99301976,2.7560575,18.13863,458.0564,-9.4442043
195.6069,0.54564345,9.4479303,0.0,0,18.0,450.0,0.9929654,2.567832,18.147316,458.22134,-9.4617977
195.6093,0.52789408,9.4489546,0.0,0,18.0,450.0,0.9934302,2.503094,18.145168,458.38788,-9.4798002
195.6117,0.5490641,9.4420958,0.0,0,18.0,450.0,0.99330097,2.5428956,18.143852,458.55988,-9.4967413
195.6141,0.59241545,9.4384508,0.0,0,18.0,450.0,0.99341577,2.7863507,18.135647,458.73187,-9.5146589
195.6165,0.56872851,9.4440603,0.0,0,18.0,450.0,0.99327368,2.703892,18.135666,458.90387,-9.5341282
195.6189,0.53412974,9.4505415,0.0,0,18.0,450.0,0.99317646,2.5243387,18.131563,459.0737,-9.5524263
195.6213,0.52096444,9.4524221,0.0,0,18.0,450.0,0.99386525,2.4469798,18.127657,459.20264,-9.5702276
195.6237,0.57489079,9.4478731,0.0,0,18.0,450.0,0.99469781,2.6865516,18.123938,459.33154,-9.5877943
195.6261,0.60554647,9.4426069,0.0,0,18.0,450.0,0.99406511,2.8180318,18.118973,459.46048,-9.6058531
195.6285,0.55627,9.4436083,0.0,0,18.0,450.0,0.99292564,2.6612229,18.118912,459.58939,-9.6241474
195.6309,0.52366972,9.4477758,0.0,0,18.0,450.0,0.99309349,2.4582767,18.116003,459.68069,-9.6410503
195.6333,0.53686082,9.447403,0.0,0,18.0,450.0,0.99333626,2.5022509,18.113802,459.76666,-9.6582909
195.6357,0.58345932,9.4435568,0.0,0,18.0,450.0,0.99390203,2.7552845,18.111992,459.8526,-9.6763868
195.6381,0.59299636,9.4414864,0.0,0,18.0,450.0,0.99356508,2.7977502,18.111952,459.93854,-9.6946983
195.6405,0.53922272,9.4467468,0.0,0,18.0,450.0,0.99357766,2.5523303,18.11132,460.02951,-9.7126627
195.6429,0.52659476,9.4540215,0.0,0,18.0,450.0,0.99366236,2.4629648,18.104485,460.12262,-9.7300644
195.6453,0.55837667,9.452013,0.0,0,18.0,450.0,0.993963,2.6276202,18.101566,460.21573,-9.7482424
195.6477,0.5943163,9.4447536,0.0,0,18.0,450.0,0.99425793,2.8126712,18.100136,460.30884,-9.7680435
195.6501,0.55228066,9.4407167,0.0,0,18.0,450.0,0.99377829,2.6101241,18.102772,460.39441,-9.7871532
195.6525,0.51899201,9.4420233,0.0,0,18.0,450.0,0.99260056,2.4719307,18.099659,460.47321,-9.8047848
195.6549,0.5251314,9.4454107,0.0,0,18.0,450.0,0.99251068,2.4453235,18.100704,460.552,-9.8221607
195.6573,0.58515781,9.4467812,0.0,0,18.0,450.0,0.99336201,2.7478063,18.098846,460.6308,-9.8393364
195.6597,0.57842356,9.4441338,0.0,0,18.0,450.0,0.99405509,2.7322464,18.09754,460.70706,-9.8579035
195.6621,0.53940988,9.441617,0.0,0,18.0,450.0,0.99371469,2.5619907,18.096237,460.77869,-9.8744497
195.6645,0.50973922,9.4465437,0.0,0,18.0,450.0,0.99330735,2.428129,18.098043,460.85031,-9.8919468
195.6669,0.56331867,9.4525375,0.0,0,18.0,450.0,0.99318385,2.624193,18.095175,460.92194,-9.9086933
195.6693,0.5995757,9.4529982,0.0,0,18.0,450.0,0.99433064,2.8490996,18.095234,460.99231,-9.9285641
195.6717,0.55836284,9.4460497,0.0,0,18.0,450.0,0.99469209,2.6485255,18.093418,461.05676,-9.9475079
195.6741,0.52099192,9.4417973,0.0,0,18.0,450.0,0.99385011,2.4996028,18.094841,461.12122,-9.9647398
195.6765,0.52626032,9.4464445,0.0,0,18.0,450.0,0.99295098,2.5071194,18.093325,461.18567,-9.9830437
195.6789,0.60037386,9.4506807,0.0,0,18.0,450.0,0.99339372,2.7802775,18.090429,461.25012,-9.9995537
195.6813,0.59425676,9.4497271,0.0,0,18.0,450.0,0.99393898,2.8102071,18.088118,461.29309,-10.018684
195.6837,0.55275643,9.4442263,0.0,0,18.0,450.0,0.99418938,2.6047609,18.09042,461.33609,-10.037588
195.6861,0.52679062,9.4430685,0.0,0,18.0,450.0,0.99373806,2.4651115,18.086771,461.37906,-10.054266
195.6885,0.57437861,9.4459906,0.0,0,18.0,450.0,0.99295628,2.6789529,18.080601,461.42206,-10.071521
195.6909,0.61632323,9.453249,0.0,0,18.0,450.0,0.99330288,2.8916857,18.085716,461.45319,-10.090466
195.6933,0.59289366,9.4530249,0.0,0,18.0,450.0,0.99450761,2.7715335,18.086712,461.48184,-10.109258
195.6957,0.53497499,9.4463711,0.0,0,18.0,450.0,0.99502277,2.5185056,18.085096,461.51047,-10.126228
195.6981,0.54438758,9.4442244,0.0,0,18.0,450.0,0.99385828,2.5536537,18.089354,461.53912,-10.143467
195.7005,0.60860366,9.4459085,0.0,0,18.0,450.0,0.99280846,2.8704953,18.084763,461.56775,-10.160871
195.7029,0.62195396,9.4476652,0.0,0,18.0,450.0,0.99293184,2.9273427,18.082546,461.59641,-10.179511
195.7053,0.54975569,9.448163,0.0,0,18.0,450.0,0.99405187,2.6389694,18.084112,461.62506,-10.197729
195.7077,0.54762179,9.4453449,0.0,0,18.0,450.0,0.99446809,2.5513783,18.081814,461.65372,-10.215872
195.7101,0.58425933,9.4457169,0.0,0,18.0,450.0,0.99417037,2.7725182,18.079391,461.67899,-10.234204
195.7125,0.62552422,9.449955,0.0,0,18.0,450.0,0.99334449,2.9166958,18.075895,461.70047,-10.252193
195.7149,0.57544011,9.4542513,0.0,0,18.0,450.0,0.99369329,2.7412643,18.076941,461.72195,-10.270267
195.7173,0.53347051,9.4520416,0.0,0,18.0,450.0,0.99476659,2.5387006,18.077263,461.74344,-10.287575
195.7197,0.541462,9.4459782,0.0,0,18.0,450.0,0.99493665,2.5394731,18.07618,461.75848,-10.304654
195.7221,0.5923959,9.4429636,0.0,0,18.0,450.0,0.99342912,2.8116112,18.078028,461.75848,-10.325365
195.7245,0.61938506,9.4488449,0.0,0,18.0,450.0,0.99325389,2.9476607,18.074169,461.75848,-10.343703
195.7269,0.54123074,9.4494829,0.0,0,18.0,450.0,0.99338901,2.5875878,18.073978,461.75848,-10.361799
195.7293,0.52447522,9.446085,0.0,0,18.0,450.0,0.99380916,2.4791834,18.070091,461.7576,-10.379518
195.7317,0.56820571,9.4409876,0.0,0,18.0,450.0,0.99385858,2.6652403,18.076408,461.75043,-10.395858
195.7341,0.61929137,9.4432697,0.0,0,18.0,450.0,0.99351293,2.9244261,18.072084,461.74326,-10.41292
195.7365,0.58763123,9.4499855,0.0,0,18.0,450.0,0.993361,2.8146882,18.071083,461.73608,-10.43187
195.7389,0.54603678,9.4539537,0.0,0,18.0,450.0,0.9938044,2.5734398,18.069689,461.72894,-10.450621
195.7413,0.54338515,9.4486551,0.0,0,18.0,450.0,0.99438536,2.530829,18.070786,461.72177,-10.467212
195.7437,0.60975075,9.4430885,0.0,0,18.0,450.0,0.99413824,2.8597713,18.067274,461.7146,-10.484268
195.7461,0.62190247,9.441987,0.0,0,18.0,450.0,0.99312305,2.9393978,18.064463,461.70746,-10.502146
195.7485,0.55628431,9.4468708,0.0,0,18.0,450.0,0.99285525,2.6223218,18.068426,461.70029,-10.522861
195.7509,0.54317909,9.4475517,0.0,0,18.0,450.0,0.99303079,2.5682631,18.069706,461.70422,-10.541811
195.7533,0.57044363,9.4447412,0.0,0,18.0,450.0,0.99359632,2.6612332,18.067701,461.7114,-10.558755
195.7557,0.62941402,9.4412565,0.0,0,18.0,450.0,0.99375367,2.980624,18.064539,461.71854,-10.576409
195.7581,0.59778607,9.4420633,0.0,0,18.0,450.0,0.99309474,2.8269699,18.064686,461.72571,-10.595043
195.7605,0.5541783,9.4502373,0.0,0,18.0,450.0,0.99317783,2.6357968,18.062931,461.73718,-10.614089
195.7629,0.54464161,9.4520483,0.0,0,18.0,450.0,0.99366915,2.5633452,18.066261,461.7515,-10.630576
195.7653,0.63187277,9.4471178,0.0,0,18.0,450.0,0.99443907,2.9449697,18.067375,461.76584,-10.648435
195.7677,0.62949485,9.442688,0.0,0,18.0,450.0,0.99417847,2.9732594,18.063046,461.78015,-10.66736
195.7701,0.57218486,9.4430876,0.0,0,18.0,450.0,0.99314916,2.7226148,18.063494,461.80362,-10.684457
195.7725,0.5486896,9.4460163,0.0,0,18.0,450.0,0.99263978,2.6035657,18.066122,461.83942,-10.702088
195.7749,0.58082134,9.4476013,0.0,0,18.0,450.0,0.99326712,2.7024617,18.061443,461.87521,-10.719995
195.7773,0.64232701,9.4435921,0.0,0,18.0,450.0,0.99390107,2.9855778,18.060884,461.91101,-10.737943
195.7797,0.60800558,9.4423714,0.0,0,18.0,450.0,0.99411589,2.9130847,18.060549,461.93607,-10.755687
195.7821,0.55228776,9.4456224,0.0,0,18.0,450.0,0.99364287,2.5980425,18.063349,461.92892,-10.773942
195.7845,0.54622173,9.4522943,0.0,0,18.0,450.0,0.99336171,2.5782006,18.06303,461.92175,-10.792315
195.7869,0.62267035,9.4537172,0.0,0,18.0,450.0,0.99397987,2.9008391,18.06044,461.91461,-10.808342
195.7893,0.62690383,9.4455967,0.0,0,18.0,450.0,0.99434292,2.9816926,18.06024,461.90424,-10.827903
195.7917,0.5814572,9.4411888,0.0,0,18.0,450.0,0.99391955,2.7584295,18.060692,461.8541,-10.846066
195.7941,0.5479359,9.4434128,0.0,0,18.0,450.0,0.99288553,2.5789518,18.06105,461.80396,-10.864457
195.7965,0.57964355,9.448205,0.0,0,18.0,450.0,0.99302846,2.6950819,18.058266,461.75381,-10.882829
195.7989,0.62689984,9.450367,0.0,0,18.0,450.0,0.99361116,2.9425461,18.063677,461.70367,-10.899975
195.8013,0.61744589,9.4463444,0.0,0,18.0,450.0,0.99424487,2.9042664,18.057142,461.69867,-10.917022
195.8037,0.56291527,9.4428167,0.0,0,18.0,450.0,0.99393398,2.6549716,18.058359,461.69867,-10.936693
195.8061,0.55689621,9.4428968,0.0,0,18.0,450.0,0.99273801,2.6043303,18.056923,461.69867,-10.954671
195.8085,0.62260574,9.4475193,0.0,0,18.0,450.0,0.99256891,2.9026594,18.059986,461.69867,-10.972318
195.8109,0.62965524,9.4504442,0.0,0,18.0,450.0,0.9936083,2.979414,18.054321,461.70905,-10.98922
195.8133,0.58877122,9.4455118,0.0,0,18.0,450.0,0.99437582,2.7893362,18.057451,461.72339,-11.008455
195.8157,0.55320823,9.4419317,0.0,0,18.0,450.0,0.99388242,2.6195765,18.05636,461.7377,-11.025665
195.8181,0.59614986,9.441411,0.0,0,18.0,450.0,0.99257332,2.763088,18.059101,461.75204,-11.043413
195.8205,0.64228559,9.4466534,0.0,0,18.0,450.0,0.99278158,3.0333178,18.05616,461.74667,-11.060505
195.8229,0.6292699,9.4479914,0.0,0,18.0,450.0,0.99358243,3.0053475,18.055227,461.72516,-11.078146
195.8253,0.56249464,9.4415827,0.0,0,18.0,450.0,0.99372715,2.6723819,18.051935,461.70367,-11.095296
195.8277,0.57347339,9.4426184,0.0,0,18.0,450.0,0.99395555,2.7052486,18.053885,461.68219,-11.113482
195.8301,0.62988579,9.4471312,0.0,0,18.0,450.0,0.99328071,2.9486787,18.047756,461.65802,-11.133593
195.8325,0.64204633,9.4538059,0.0,0,18.0,450.0,0.99344617,3.0622048,18.053986,461.62936,-11.151265
195.8349,0.59207076,9.4519043,0.0,0,18.0,450.0,0.99416953,2.8003469,18.050009,461.60071,-11.168868
195.8373,0.56137449,9.4456053,0.0,0,18.0,450.0,0.99460185,2.6294889,18.049276,461.57205,-11.185475
195.8397,0.58931863,9.4395685,0.0,0,18.0,450.0,0.99334961,2.7705271,18.050928,461.5434,-11.205118
195.8421,0.65397763,9.442605,0.0,0,18.0,450.0,0.99249822,3.0855932,18.049498,461.51477,-11.224106
195.8445,0.62707239,9.4501486,0.0,0,18.0,450.0,0.99335605,2.9748511,18.044802,461.48611,-11.242599
195.8469,0.57850301,9.4492636,0.0,0,18.0,450.0,0.99397671,2.7113087,18.047152,461.45749,-11.259788
195.8493,0.57370389,9.4425449,0.0,0,18.0,450.0,0.99379563,2.6692772,18.045244,461.42957,-11.276114
195.8517,0.63537031,9.4405575,0.0,0,18.0,450.0,0.99337745,2.9543314,18.049007,461.42957,-11.294281
195.8541,0.64889115,9.4453716,0.0,0,18.0,450.0,0.99275464,3.0556805,18.045349,461.42957,-11.312993
195.8565,0.60030192,9.4517069,0.0,0,18.0,450.0,0.99303782,2.8999972,18.043451,461.42957,-11.330887
195.8589,0.56920964,9.4473019,0.0,0,18.0,450.0,0.99374807,2.6357579,18.04653,461.42957,-11.348113
196.0608,0.57467532,9.447176,0.0,0,18.0,0.85476553,0.99375498,2.707371,18.024302,453.83856,-11.47926
197.2608,0.50559974,9.4578991,0.0,0,18.0,3.6951356e-17,0.99570137,2.3756745,18.000107,430.68918,-11.480264
198.4608,0.48563957,9.4661589,0.0,0,18.0,1.5974008e-33,0.99709821,2.2757747,17.999125,415.8132,-11.48109
199.6608,0.46838808,9.473382,0.0,0,18.0,1.4012985e-45,0.99851334,2.2015495,17.999205,402.87714,-11.481535
200.8608,0.46269524,9.4803619,0.0,0,18.0,1.4012985e-45,0.99974853,2.1750569,17.999426,390.44931,-11.481249
202.0608,0.46661341,9.486722,0.0,0,18.0,1.4012985e-45,1.0009344,2.1881397,18.000895,379.19583,-11.48131
203.2608,0.45499483,9.4931307,0.0,0,18.0,1.4012985e-45,1.0020087,2.1242039,18.000626,368.15414,-11.48073
204.4608,0.45390007,9.4992695,0.0,0,18.0,1.4012985e-45,1.0031867,2.1187966,17.999701,357.40771,-11.480761
205.6608,0.45984188,9.5053415,0.0,0,18.0,1.4012985e-45,1.0043377,2.1473768,17.999516,346.98303,-11.481443
206.8608,0.46103191,9.5112391,0.0,0,18.0,1.4012985e-45,1.0053092,2.1490355,17.999544,337.29279,-11.481817
208.0608,0.46865356,9.5168028,0.0,0,18.0,1.4012985e-45,1.0063528,2.1787663,17.999924,327.64636,-11.482263
209.2608,0.4575651,9.5226736,0.0,0,18.0,1.4012985e-45,1.0074506,2.1189003,18.000084,318.47424,-11.481529
210.4608,0.45382187,9.5281487,0.0,0,18.0,1.4012985e-45,1.0084842,2.1051903,17.99996,309.71295,-11.481428
211.6608,0.45956975,9.5340061,0.0,0,18.0,1.4012985e-45,1.0094341,2.1387846,17.999828,300.94122,-11.481852
212.8608,0.4618651,9.538516,0.0,0,18.0,1.4012985e-45,1.0103598,2.1479609,18.000532,292.3399,-11.48197
214.0608,0.46176404,9.5439463,0.0,0,18.0,1.4012985e-45,1.0113614,2.128262,17.99917,284.28183,-11.48158
215.2608,0.44989684,9.5486851,0.0,0,18.0,1.4012985e-45,1.0122228,2.0823431,17.999601,276.40076,-11.481552
216.4608,0.45321533,9.5537109,0.0,0,18.0,1.4012985e-45,1.0130759,2.0990152,17.999929,268.59177,-11.481861
217.6608,0.45327064,9.5581217,0.0,0,18.0,1.4012985e-45,1.0139525,2.0959637,17.999531,261.3356,-11.481764
218.8608,0.45324239,9.5633392,0.0,0,18.0,1.4012985e-45,1.01494,2.095722,17.999229,254.26321,-11.481962
220.0608,0.46340495,9.5677691,0.0,0,18.0,1.4012985e-45,1.0156553,2.1352139,18.000673,247.3255,-11.482503
221.2608,0.45360696,9.5722809,0.0,0,18.0,1.4012985e-45,1.016543,2.087343,18.000715,240.58331,-11.482401
222.4608,0.44950444,9.5764208,0.0,0,18.0,1.4012985e-45,1.0172949,2.0721784,17.999638,234.08215,-11.482498
223.6608,0.45275545,9.5807447,0.0,0,18.0,1.4012985e-45,1.0181533,2.0867081,17.999432,227.84209,-11.482459
224.8608,0.4528777,9.5850821,0.0,0,18.0,1.4012985e-45,1.0188481,2.0846617,17.999676,221.6763,-11.48223
226.0608,0.44966641,9.5890551,0.0,0,18.0,1.4012985e-45,1.0196863,2.0570543,17.999205,215.60503,-11.482152
227.2608,0.45053515,9.5922365,0.0,0,18.0,1.4012985e-45,1.0202435,2.064868,17.998621,209.77019,-11.482547
228.4608,0.43904409,9.5965776,0.0,0,18.0,1.4012985e-45,1.0210078,2.0181236,17.998989,204.26764,-11.48222
229.6608,0.45030752,9.6001406,0.0,0,18.0,1.4012985e-45,1.0216378,2.0656159,18.000034,198.86224,-11.482433
230.8608,0.45910424,9.6036625,0.0,0,18.0,1.4012985e-45,1.0223376,2.0998657,17.998154,193.39433,-11.482263
232.0608,0.45219293,9.6071463,0.0,0,18.0,1.4012985e-45,1.0230492,2.0669425,18.000292,188.53546,-11.482225
233.2608,0.44274902,9.6107292,0.0,0,18.0,1.4012985e-45,1.0235761,2.0256436,18.000446,183.62576,-11.482319
234.4608,0.4400731,9.6140652,0.0,0,18.0,1.4012985e-45,1.0242771,2.0159392,18.000652,178.99234,-11.481644
235.6608,0.4512853,9.6171722,0.0,0,18.0,1.4012985e-45,1.0248083,2.0628533,18.000483,174.21675,-11.482232
236.8608,0.4552266,9.6204424,0.0,0,18.0,1.4012985e-45,1.0254812,2.0769007,18.000324,169.78644,-11.481948
238.0608,0.4391084,9.6239462,0.0,0,18.0,1.4012985e-45,1.0260431,2.0008636,17.999475,165.32257,-11.482009
239.2608,0.43990901,9.6265917,0.0,0,18.0,1.4012985e-45,1.0266213,2.0077753,18.000048,161.16275,-11.482196
240.4608,0.44197944,9.6290073,0.0,0,18.0,1.4012985e-45,1.0270369,2.0188441,18.000437,157.15985,-11.48177
241.6608,0.44995832,9.6321745,0.0,0,18.0,1.4012985e-45,1.0276313,2.0555,17.999701,153.0619,-11.481797
242.8608,0.44806659,9.6354532,0.0,0,18.0,1.4012985e-45,1.0281998,2.0319228,18.000881,149.23657,-11.482115
244.0608,0.4482151,9.6378336,0.0,0,18.0,1.4012985e-45,1.0286975,2.0382283,17.999756,145.56856,-11.482347
245.2608,0.44681925,9.6405182,0.0,0,18.0,1.4012985e-45,1.0292403,2.0350718,18.000418,141.9344,-11.482126
246.4608,0.44796506,9.6428595,0.0,0,18.0,1.4012985e-45,1.0295621,2.0397022,18.000071,138.39542,-11.482239
247.6608,0.45426381,9.6452188,0.0,0,18.0,1.4012985e-45,1.0300845,2.0602686,18.000141,134.98018,-11.482935
248.8608,0.44509673,9.6475143,0.0,0,18.0,1.4012985e-45,1.0304809,2.0206928,18.000908,131.80093,-11.482299
250.0608,0.43708822,9.6497688,0.0,0,18.0,1.4012985e-45,1.0309546,1.9811145,18.000051,128.63808,-11.482537
251.2608,0.44259304,9.652338,0.0,0,18.0,1.4012985e-45,1.0313318,2.0111303,17.99947,125.68579,-11.482437
252.4608,0.44531241,9.6542578,0.0,0,18.0,1.4012985e-45,1.0317851,2.0243313,18.00062,122.68493,-11.482617
253.6608,0.4516418,9.6564798,0.0,0,18.0,1.4012985e-45,1.032163,2.0488503,17.999876,119.78793,-11.482838
254.8608,0.44337672,9.6583157,0.0,0,18.0,1.4012985e-45,1.032501,2.0057158,18.000586,116.93391,-11.482374
255.8608,0.44539508,9.6600266,0.0,0,18.0,1.4012985e-45,1.0328075,2.0159228,18.000118,114.70777,-11.482295