File: examples/dan-msc-case-studies/CS3/data/01 raw data/baron_test_119.csv
Time(sec),Force(kN),Jaw(mm),PowAngle(deg),Power(W),Pram,PTemp,Strain,Stress(MPa),Stroke(mm),TC1(C),wedge(mm)
0.0,0.97094256,0.45647097,0.0,0,11.076097,7.2711024e-05,0.030905643,11.992923,11.076406,23.112101,-9.1276731
1.2,0.90497702,0.0062681935,0.0,0,11.076097,3.5159149,0.00039259958,11.511145,11.076292,22.99588,-9.4948759
2.4,0.87460083,0.0060866023,0.0,0,11.076097,7.1159153,0.00043219494,11.142708,11.075755,23.049833,-9.4914665
3.6,0.85404855,0.0063542039,0.0,0,11.076097,10.715911,0.00043679116,10.869743,11.075435,23.024012,-9.490695
4.8,0.84265399,0.006300387,0.0,0,11.076097,14.31591,0.00040310007,10.73317,11.076439,23.011589,-9.4887705
6.0,0.82496077,0.0063033854,0.0,0,11.076097,17.915916,0.0004245957,10.495381,11.076574,23.069439,-9.4863749
7.2,0.80468142,0.0060946462,0.0,0,11.076097,21.515915,0.00037914369,10.241966,11.075898,22.961855,-9.4833746
8.4,0.79819232,0.0067947344,15.690179,0,11.076097,25.115913,0.00047974699,10.160156,11.07573,23.009233,-9.4813557
9.6,0.80049288,0.0070804749,30.865656,0,11.076097,28.715912,0.00048615973,10.182143,11.075678,23.620701,-9.4791832
10.8,0.82465142,0.0047649476,36.7822,0,11.076097,32.315914,0.00030379836,10.491499,11.075567,26.076067,-9.4777946
12.0,0.83516216,0.0011864975,38.551022,0,11.076097,35.915916,7.22982e-05,10.64279,11.076155,30.092602,-9.4762697
13.2,0.8435818,-0.0024857896,39.254353,0,11.076097,39.515919,-0.00018897525,10.749078,11.076041,34.31884,-9.4742231
14.4,0.85113448,-0.0067539108,39.934998,0,11.076097,43.115921,-0.00042049235,10.834785,11.077234,38.550545,-9.4717484
15.6,0.86040121,-0.010279304,40.087505,0,11.076097,46.715919,-0.00067201012,10.9626,11.076467,42.926548,-9.4694405
16.8,0.86500901,-0.013936975,40.523262,0,11.076097,50.315922,-0.0009328273,11.010523,11.074974,47.193336,-9.4667749
18.0,0.8729037,-0.017847173,40.567432,0,11.076097,53.915924,-0.0011943836,11.129007,11.076248,51.313538,-9.4647455
19.2,0.88358217,-0.020861514,40.525093,0,11.076097,57.515923,-0.0014098234,11.263161,11.075504,55.392689,-9.4632187
20.4,0.88985181,-0.024683632,40.572506,0,11.076097,61.115925,-0.0016271496,11.354379,11.075609,59.366333,-9.4615812
21.6,0.89837348,-0.027953321,40.517834,0,11.076097,64.715904,-0.0018497276,11.453419,11.07657,63.280052,-9.4596815
22.8,0.9007839,-0.031319056,40.524532,0,11.076097,68.315903,-0.0020946281,11.503792,11.076293,67.115685,-9.4576874
24.0,0.90610588,-0.034401651,40.572506,0,11.076097,71.915909,-0.0022922652,11.562406,11.075948,70.897591,-9.4548016
25.2,0.9057942,-0.037477743,40.848785,0,11.076097,75.5159,-0.0025233093,11.567838,11.075304,74.510216,-9.4523821
26.4,0.91435194,-0.041009229,41.196056,0,11.076097,79.115913,-0.0027064651,11.670967,11.075669,78.175339,-9.4505577
27.6,0.91375101,-0.043975949,41.202374,0,11.076097,82.715904,-0.002920364,11.653024,11.076071,81.858444,-9.4480848
28.8,0.92287886,-0.047206104,41.282829,0,11.076097,86.315918,-0.0031428139,11.782034,11.076068,85.517998,-9.446126
30.0,0.92336357,-0.050096013,41.548073,0,11.076097,89.915916,-0.0033333616,11.804076,11.075603,89.203957,-9.4444685
31.2,0.92088974,-0.052899253,41.758213,0,11.076097,93.51593,-0.003543091,11.777463,11.075357,92.873619,-9.4424543
32.4,0.92639589,-0.056490432,41.803982,0,11.076097,97.115913,-0.0037354045,11.839053,11.075573,96.38813,-9.4399719
33.6,0.93185478,-0.059468966,42.396236,0,11.076097,100.71593,-0.0039557805,11.91296,11.075503,99.932747,-9.4379015
34.8,0.93607402,-0.062740788,42.741676,0,11.076097,104.31591,-0.0041709864,11.969521,11.076296,103.47215,-9.4361258
36.0,0.93668044,-0.066680118,42.708107,0,11.076097,107.91593,-0.0044419677,11.97749,11.07515,107.18191,-9.4337263
37.2,0.93621629,-0.069919489,42.978512,0,11.076097,111.51591,-0.0046710116,11.980897,11.075839,110.85158,-9.4314909
38.4,0.93906802,-0.073446631,42.978554,0,11.076097,115.11593,-0.0048699812,12.011789,11.075317,114.54408,-9.4292698
39.6,0.94776827,-0.076681949,43.237312,0,11.076097,118.71592,-0.0051128138,12.130761,11.076992,118.02316,-9.427742
40.8,0.94657916,-0.080299534,43.527828,0,11.076097,122.31593,-0.005328693,12.11193,11.075551,121.62914,-9.4259329
42.0,0.95281607,-0.083597161,43.96814,0,11.076097,125.91592,-0.0055477088,12.197931,11.075989,125.17426,-9.4230299
43.2,0.9467954,-0.087035738,44.077145,0,11.076097,129.51604,-0.0058042859,12.133541,11.075256,128.79623,-9.420826
44.4,0.95459342,-0.09109515,44.08662,0,11.076097,133.11594,-0.0060429149,12.21649,11.076231,132.42072,-9.4193392
45.6,0.94748276,-0.094874769,44.220993,0,11.076097,136.71591,-0.0063223746,12.138137,11.075511,136.07732,-9.417037
46.8,0.96311438,-0.097639337,44.604092,0,11.076097,140.31592,-0.0064685293,12.314224,11.076406,139.65649,-9.415019
48.0,0.96752,-0.10084301,44.604488,0,11.076097,143.91591,-0.0066851606,12.385132,11.076391,143.37607,-9.4128637
49.2,0.97339743,-0.10560134,44.605824,0,11.076097,147.51593,-0.007014778,12.487083,11.075992,146.95694,-9.4111013
50.4,0.96644604,-0.11033398,44.944458,0,11.076097,151.11591,-0.0073328316,12.397884,11.075952,150.57462,-9.4095669
51.6,0.96803403,-0.11305735,45.12085,0,11.076097,154.71591,-0.0075536026,12.419239,11.075539,154.11833,-9.4074917
52.8,0.96488249,-0.11566432,45.12085,0,11.076097,158.3159,-0.0076600742,12.380315,11.075507,157.7737,-9.4049845
54.0,0.96351039,-0.1184293,45.261139,0,11.076097,161.91592,-0.0078636352,12.367767,11.075745,161.39986,-9.4025021
55.2,0.96482748,-0.12191353,45.615231,0,11.076097,165.5159,-0.0080881938,12.389138,11.075574,164.94771,-9.4010592
56.4,0.96297169,-0.12566063,45.615238,0,11.076097,169.11591,-0.0083388938,12.369138,11.076555,168.51007,-9.3990259
57.6,0.96789783,-0.12944847,46.100258,0,11.076097,172.7159,-0.0086164903,12.433908,11.075328,172.04085,-9.3967419
58.8,0.95826524,-0.13434725,46.313042,0,11.076097,176.3159,-0.008897637,12.317349,11.076706,175.58096,-9.3947811
60.0,0.96349251,-0.13850349,46.556572,0,11.076097,179.91591,-0.0092009399,12.371546,11.076614,179.23997,-9.3922386
61.2,0.97007,-0.1425094,46.582027,0,11.076097,183.5159,-0.0094345594,12.477928,11.075293,182.80396,-9.3911915
62.4,0.95785803,-0.14634168,46.731335,0,11.076097,187.11591,-0.0096969791,12.316139,11.076863,186.44476,-9.3889618
63.6,0.96723473,-0.1501009,46.872231,0,11.076097,190.7159,-0.0099721225,12.439369,11.0759,190.11006,-9.3862715
64.8,0.96749848,-0.15273042,46.866127,0,11.076097,194.31592,-0.010134252,12.436569,11.075644,193.8299,-9.3839073
66.0,0.97015518,-0.15833738,46.658852,0,11.076097,197.91591,-0.010509381,12.468581,11.076007,197.67169,-9.3821917
67.2,0.97714621,-0.16203219,46.588009,0,11.076097,201.51591,-0.01073081,12.565161,11.076488,201.31442,-9.3807888
68.4,0.98331058,-0.16289267,46.822994,0,11.076097,205.11591,-0.01080745,12.656936,11.075634,204.8483,-9.3786669
69.6,0.98411053,-0.1660904,47.05444,0,11.076097,208.71593,-0.010995844,12.680995,11.075961,208.35825,-9.3757124
70.8,0.97894144,-0.17042193,47.05444,0,11.076097,212.3159,-0.011295483,12.599253,11.075477,211.98073,-9.3737793
72.0,0.98063612,-0.17491962,47.275215,0,11.076097,215.91592,-0.011611093,12.629974,11.075489,215.50752,-9.3718538
73.2,0.97127777,-0.1795074,47.504883,0,11.076097,219.51591,-0.01188574,12.518543,11.075334,219.03578,-9.3699341
74.4,0.97328258,-0.18369907,47.521252,0,11.076097,223.11592,-0.012199808,12.542458,11.076406,222.69365,-9.3684778
75.6,0.9717176,-0.18784723,47.504887,0,11.076097,226.7159,-0.012420636,12.525751,11.076767,226.30193,-9.3663225
76.8,0.97519946,-0.19148912,47.78772,0,11.076097,230.31592,-0.012670452,12.574917,11.075989,229.88303,-9.3637104
78.0,0.97795355,-0.19523169,47.906597,0,11.076097,233.91591,-0.012942589,12.61131,11.076297,233.56386,-9.3618422
79.2,0.97476012,-0.199378,47.553619,0,11.076097,237.51591,-0.013205549,12.59706,11.076979,237.27289,-9.3598967
80.4,0.98223519,-0.20287533,47.955318,0,11.076097,241.11592,-0.01345187,12.68549,11.075963,240.77649,-9.357852
81.6,0.97713214,-0.20722905,48.197441,0,11.076097,244.71591,-0.013700494,12.62652,11.076687,244.24464,-9.3560991
82.8,0.98323989,-0.21012549,48.383785,0,11.076097,248.3159,-0.013922882,12.677563,11.076731,247.70097,-9.3541298
84.0,0.99231279,-0.21296148,48.812252,0,11.076097,251.91592,-0.014088517,12.790649,11.076208,251.0887,-9.3517532
85.2,0.99932498,-0.21686742,48.812252,0,11.076097,255.51591,-0.01433603,12.898247,11.075829,254.93706,-9.3493557
86.4,1.0000837,-0.22145854,48.81226,0,11.076097,259.11615,-0.014664209,12.918042,11.076511,258.6076,-9.3477964
87.6,0.9985438,-0.22722812,49.137722,0,11.076097,262.71594,-0.015023209,12.91043,11.076811,262.09573,-9.3455448
88.8,0.99555707,-0.23219295,49.229733,0,11.076097,266.31589,-0.015377722,12.875605,11.07569,265.70963,-9.3433657
90.0,0.99595809,-0.23654449,49.22971,0,11.076097,269.91586,-0.015621241,12.898155,11.076539,269.46375,-9.341361
91.2,0.99159992,-0.23943147,49.236374,0,11.076097,273.5159,-0.015848352,12.813231,11.075894,273.07816,-9.3390026
92.4,0.99480569,-0.24170792,49.426586,0,11.076097,277.11588,-0.016001716,12.8783,11.076389,276.6373,-9.3373461
93.6,0.99113047,-0.24436003,49.63586,0,11.076097,280.71591,-0.016171569,12.828103,11.076053,280.20474,-9.3356504
94.8,0.98398101,-0.24761365,49.636227,0,11.076097,284.31589,-0.016393665,12.743387,11.076894,283.79196,-9.3332148
96.0,0.9947409,-0.25153568,49.899616,0,11.076097,287.91589,-0.016629083,12.883928,11.075706,287.3287,-9.3308945
97.2,0.9926852,-0.25621328,50.042721,0,11.076097,291.5159,-0.016939081,12.850707,11.075569,290.9173,-9.3287878
98.4,0.99306434,-0.26090986,50.042728,0,11.076097,295.11591,-0.017215258,12.872526,11.076424,294.5452,-9.3271208
99.6,0.9958238,-0.26513937,50.297516,0,11.076097,298.71591,-0.017509922,12.918846,11.076649,298.11169,-9.3251734
100.8,0.99435079,-0.26924002,50.236149,0,11.076097,302.31586,-0.017793886,12.901983,11.075251,301.80832,-9.323061
102.0,0.9933421,-0.27362755,50.473427,0,11.076097,305.91589,-0.018081125,12.876037,11.075818,305.32986,-9.3207293
103.2,0.99459308,-0.2780062,50.712097,0,11.076097,309.5159,-0.018383035,12.909064,11.076103,308.89795,-9.3184471
104.4,0.98564726,-0.28246132,50.787361,0,11.076097,313.11591,-0.018629642,12.795749,11.076018,312.59537,-9.3168793
105.6,0.99514866,-0.28651491,50.820034,0,11.076097,316.71591,-0.018910373,12.901714,11.076313,316.26114,-9.3148298
106.8,0.9901616,-0.28936952,50.82275,0,11.076097,320.31592,-0.019107884,12.849192,11.076143,319.91022,-9.312602
108.0,0.98949426,-0.29391313,50.978283,0,11.076097,323.91589,-0.019386098,12.823619,11.076531,323.34607,-9.3103209
109.2,0.99246168,-0.30112296,51.196285,0,11.076097,327.51593,-0.019884532,12.869835,11.075811,326.92148,-9.30832
110.4,1.0051273,-0.30611712,51.212173,0,11.076097,331.11591,-0.020214066,13.054144,11.076523,330.52234,-9.3067112
111.6,1.0128353,-0.30762112,51.569462,0,11.076097,334.71591,-0.020331929,13.164864,11.076097,334.1062,-9.3046923
112.8,1.0127611,-0.31014356,51.56982,0,11.076097,338.31592,-0.020451706,13.162244,11.076058,337.69724,-9.3025732
114.0,1.0148733,-0.31375122,51.607368,0,11.076097,341.91592,-0.020689473,13.198132,11.076271,341.35696,-9.3005552
115.2,1.0160178,-0.31809026,51.740067,0,11.076097,345.51593,-0.02099232,13.220564,11.076027,344.99924,-9.2990503
116.4,1.0148215,-0.32236296,51.761921,0,11.076097,349.11594,-0.021262061,13.19904,11.076375,348.69543,-9.2970715
117.6,1.0122792,-0.32660165,51.876427,0,11.076097,352.71591,-0.021572961,13.176562,11.075772,352.31903,-9.2949934
118.8,1.0139052,-0.33145419,51.90379,0,11.076097,356.31595,-0.021844603,13.187522,11.076016,355.87967,-9.2921181
120.0,1.0185726,-0.336438,52.086891,0,11.076097,359.91586,-0.02220792,13.267609,11.075396,359.44617,-9.290472
121.2,0.10396931,-0.36205703,46.633595,0,11.076097,359.99924,-0.023828238,1.3623035,11.075275,364.10434,-9.2901258
122.4,0.065418415,-0.36066785,40.476612,0,11.076097,359.99924,-0.023736348,0.84997314,11.075762,366.86044,-9.2903624
123.6,0.054421771,-0.35710454,42.619053,0,11.076097,359.99924,-0.023525279,0.71236736,11.076252,364.2634,-9.2903776
124.8,0.052341703,-0.35569772,46.564114,0,11.076097,359.99924,-0.023435051,0.67087877,11.075888,361.11664,-9.2907104
126.0,0.052153397,-0.35554087,48.608112,0,11.076097,359.99924,-0.023448231,0.70453632,11.076358,359.48657,-9.2903461
127.2,0.053832818,-0.35534811,49.739483,0,11.076097,359.99924,-0.023395024,0.69708008,11.076163,358.59555,-9.2904692
128.4,0.055056345,-0.35503435,50.941803,0,11.076097,359.99924,-0.02340143,0.72222573,11.076719,357.90891,-9.2903786
129.6,0.062930375,-0.35503477,51.859829,0,11.076097,359.99924,-0.023361227,0.81310821,11.076854,357.52475,-9.2903357
130.8,0.067027584,-0.35518602,52.166218,0,11.076097,359.99924,-0.023387484,0.88490897,11.076303,357.66574,-9.290122
132.0,0.07744886,-0.35511276,52.285423,0,11.076097,359.99924,-0.023404151,1.0091432,11.075884,357.94601,-9.2898741
133.2,0.087651052,-0.35552791,52.355778,0,11.076097,359.99924,-0.023427978,1.1516496,11.076241,358.28217,-9.2904816
134.4,0.095926613,-0.35842967,52.283939,0,11.076097,359.99924,-0.023639116,1.2419711,11.076084,358.59406,-9.2906933
135.6,0.08693137,-0.35864767,52.283939,0,11.076097,359.99924,-0.023617269,1.1395891,11.076735,358.91437,-9.2900658
136.8,0.084576301,-0.35873494,52.370598,0,11.076097,359.99924,-0.02365499,1.0896853,11.075396,359.06656,-9.2900734
138.0,0.077475607,-0.35935682,52.283939,0,11.076097,359.99924,-0.02365371,1.0251937,11.076254,359.27576,-9.2897921
139.2,0.087067358,-0.35986832,52.283939,0,11.076097,359.99924,-0.02370524,1.1549499,11.075876,359.43961,-9.2901249
140.4,0.0859043,-0.360585,52.283936,0,11.076097,359.99924,-0.023749186,1.1191517,11.075832,359.47357,-9.2904711
141.6,0.089974858,-0.36084953,52.591049,0,11.076097,359.99924,-0.023757506,1.1752623,11.076293,359.37027,-9.2900076
142.8,0.087591082,-0.36132368,52.635494,0,11.076097,359.99924,-0.023816483,1.137599,11.075982,359.42261,-9.2896385
144.0,0.098797143,-0.36182219,52.635494,0,11.076097,359.99924,-0.023831923,1.2986923,11.075367,359.4826,-9.2901068
145.2,0.092942692,-0.36193573,52.635509,0,11.076097,359.99924,-0.02386274,1.2036937,11.075665,359.53638,-9.2900925
146.4,0.10636721,-0.36310235,52.731941,0,11.076097,359.99924,-0.023903534,1.4092609,11.075719,359.56219,-9.2901955
147.6,0.10036765,-0.36433306,52.976063,0,11.076097,359.99924,-0.024009887,1.2974668,11.07546,359.53415,-9.2898378
148.8,0.10368022,-0.36597085,52.676495,0,11.076097,359.99924,-0.02409385,1.3600898,11.076014,359.74741,-9.2895136
150.0,0.10264346,-0.3670902,52.635502,0,11.076097,359.99924,-0.024178989,1.3234146,11.075728,359.9032,-9.2899008
151.2,0.1032052,-0.36827219,52.635502,0,11.076097,359.99924,-0.024259133,1.3542407,11.075857,359.98114,-9.2901745
152.4,0.10072023,-0.36890343,52.635471,0,11.076097,359.99924,-0.024289334,1.2929008,11.076371,360.03827,-9.2900763
153.6,0.095501937,-0.36877775,52.417458,0,11.076097,359.99924,-0.024301352,1.2619408,11.075775,360.09216,-9.2899513
154.8,0.10212428,-0.36838314,52.385506,0,11.076097,359.99924,-0.024240511,1.3230628,11.076167,360.10455,-9.2900381
156.0,0.094976336,-0.36843926,52.283939,0,11.076097,359.99924,-0.024285533,1.2369918,11.075872,360.19336,-9.290081
157.2,0.085115537,-0.36951488,52.245777,0,11.076097,359.99924,-0.024317957,1.1017579,11.07645,360.20145,-9.2895947
158.4,0.092309102,-0.37012875,52.240547,0,11.076097,359.99924,-0.024366658,1.2203645,11.07584,360.23398,-9.289937
159.6,0.10061634,-0.37066114,52.166264,0,11.076097,359.99924,-0.024403913,1.2955006,11.075315,360.1713,-9.2896318
160.8,0.095719144,-0.37101889,52.129002,0,11.076097,359.99924,-0.024420237,1.2545061,11.07666,360.15378,-9.2900047
162.0,0.090697691,-0.37176496,52.134602,0,11.076097,359.99924,-0.024488606,1.1758271,11.076263,360.15445,-9.2894058
163.2,0.093225159,-0.37195516,52.266277,0,11.076097,359.99924,-0.024498953,1.2170759,11.075747,360.10013,-9.2894087
164.4,0.1025747,-0.3722356,52.283905,0,11.076097,359.99924,-0.024539219,1.3409057,11.075809,360.10895,-9.2896099
165.2852,0.26318139,0.015231512,52.283939,0,11.076099,2.5665329,0.00094509585,3.3205569,11.077885,360.05475,-9.2897539
165.2876,0.24419126,0.020503741,52.283939,0,11.076099,1.1095114e-16,0.0011760121,3.0828488,11.075802,360.04019,-9.2908564
165.29,0.24658805,0.021933686,43.395626,0,11.076099,4.7964155e-33,0.0012884132,3.1600909,11.075088,360.03079,-9.2897177
165.2924,0.22920068,0.021138908,30.847485,0,11.076099,0.0,0.0015490048,2.8146634,11.074462,360.02353,-9.2893772
165.2948,0.23010342,0.016948888,18.299339,0,11.076099,0.0,0.0014122585,2.9751298,11.074839,360.01627,-9.2901354
165.2972,0.24127789,0.017147074,5.751195,0,11.076099,0.0,0.0012293851,3.0977154,11.075358,360.009,-9.290369
165.2996,0.25916827,0.017348191,0.0,0,11.076099,0.0,0.00091899093,3.254508,11.076438,360.02536,-9.290307
165.302,0.25424036,0.018036714,0.0,0,11.076099,0.0,0.001003544,3.1216273,11.07631,360.06174,-9.2887859
165.3044,0.23738593,0.017432429,0.0,0,11.076099,0.0,0.0012300549,3.0589149,11.075493,360.09811,-9.2895489
165.3068,0.24454761,0.015496392,0.0,0,11.076099,0.0,0.0012884586,3.1543658,11.075285,360.13446,-9.290143
165.3092,0.25765866,0.017580697,0.0,0,11.076099,0.0,0.0012184628,3.2148476,11.075398,360.1463,-9.2894478
165.3116,0.25635552,0.019449394,0.0,0,11.076099,0.0,0.0011348433,3.3558981,11.075147,360.11719,-9.2901249
165.314,0.25590488,0.022355368,0.0,0,11.076099,0.0,0.0011623476,3.326298,11.074584,360.0881,-9.289876
165.3164,0.24338977,0.020702068,0.0,0,11.076099,0.0,0.0013484192,3.1043184,11.0725,360.05902,-9.2895136
165.3188,0.26851648,0.01853252,0.0,0,11.076099,0.0,0.0014053894,3.3020864,11.072967,360.03445,-9.2893391
165.3212,0.2700423,0.015573128,0.0,0,11.076099,0.0,0.0013408131,3.4241464,11.075596,360.02719,-9.2898531
165.3236,0.26019669,0.01762837,0.0,0,11.076099,0.0,0.0011623817,3.3360202,11.075613,360.01993,-9.2899799
165.326,0.26493707,0.02077312,0.0,0,11.076099,0.0,0.0011953636,3.4186876,11.075289,360.01263,-9.2897282
165.3284,0.26829875,0.019818166,0.0,0,11.076099,0.0,0.0012429161,3.3925509,11.074636,360.00598,-9.2904139
165.3308,0.26580307,0.017728627,0.0,0,11.076099,0.0,0.00127656,3.4254627,11.077522,360.01324,-9.290164
165.3332,0.28531417,0.016457917,0.0,0,11.076099,0.0,0.0013426667,3.6537366,11.07479,360.02054,-9.2901478
165.3356,0.27067184,0.019264933,0.0,0,10.976469,0.0,0.0012719977,3.4385235,11.074608,360.0278,-9.2894983
165.338,0.25840294,0.022821302,0.0,0,10.615495,0.0,0.0013229907,3.325263,11.0755,360.03506,-9.290102
165.3404,0.27919185,0.024660768,0.0,0,10.254521,0.0,0.0014635585,3.5015602,11.057116,360.04871,-9.2894258
165.3428,0.32085747,0.022380302,0.0,0,9.893548,0.0,0.001579766,4.1121659,10.92661,360.06326,-9.2912855
165.3452,0.25898102,0.01994008,0.0,0,9.5325737,0.0,0.0015759114,3.2655258,10.645473,360.07779,-9.2900944
165.3476,0.30712849,0.019155262,0.0,0,9.1800261,0.0,0.0013626837,3.9596069,10.261158,360.09235,-9.2904472
165.35,6.3559127,0.33408934,0.0,0,8.8288584,0.0,0.021562841,78.861031,9.8202105,361.08978,-9.2852793
165.3524,7.9465537,0.75763011,0.0,0,8.4910259,0.0,0.051278651,95.915939,9.3019762,362.49191,-9.2839632
165.3548,8.4161739,1.1965483,0.0,0,8.1570415,0.0,0.082665622,98.924438,8.8447857,363.89404,-9.2838783
165.3572,8.6098289,1.5907166,0.0,0,7.8342957,0.0,0.11209244,97.644272,8.4594679,365.2962,-9.2820549
165.3596,8.8889313,1.8994547,0.0,0,7.5165353,0.0,0.13521904,98.710884,8.1325989,366.85947,-9.2814302
165.362,9.1086731,2.192188,0.0,0,7.2082515,0.0,0.15739486,98.973694,7.8221798,368.55905,-9.2814198
165.3644,9.3072815,2.491873,0.0,0,6.9060431,0.0,0.18089674,98.987343,7.5241342,370.25867,-9.2820177
165.3668,9.5818014,2.7730591,0.0,0,6.6115613,0.0,0.2038762,99.444443,7.2372785,371.95825,-9.2816715
165.3692,9.8272829,3.0587838,0.0,0,6.3240418,0.0,0.22793187,99.595459,6.9519668,372.32013,-9.2820625
165.3716,10.081161,3.3351107,0.0,0,6.042748,0.0,0.25147316,99.72155,6.6626582,370.45251,-9.283124
165.374,10.387546,3.6264608,0.0,0,5.7692914,0.0,0.27624151,100.29845,6.3684149,368.58487,-9.2830143
165.3764,10.667119,3.9195356,0.0,0,5.5006137,0.0,0.30203128,100.36957,6.080924,366.71725,-9.2830238
165.3788,10.924113,4.2064633,0.0,0,5.2404532,0.0,0.32842547,100.12989,5.7886477,364.58441,-9.2833242
165.3812,11.205388,4.4884334,0.0,0,4.9838042,0.0,0.35531241,99.96479,5.5054722,361.44388,-9.2843237
165.3836,11.486151,4.7636375,0.0,0,4.7363639,0.0,0.38209087,99.775002,5.2250066,358.30331,-9.283556
165.386,11.78159,5.0365887,0.0,0,4.4912457,0.0,0.40875325,99.639008,4.9547443,355.16275,-9.2837381
165.3884,12.051209,5.2997961,0.0,0,4.2558532,0.0,0.43499154,99.337029,4.6959882,352.16672,-9.2825994
165.3908,12.318392,5.5496821,0.0,0,4.0217257,0.0,0.46102723,98.921127,4.4433184,352.49402,-9.2830648
165.3932,12.620973,5.7858634,0.0,0,3.7978494,0.0,0.48698133,98.673607,4.2016096,352.82132,-9.2818689
165.3956,12.95612,6.013617,0.0,0,3.5743496,0.0,0.5125286,98.744553,3.9705925,353.14862,-9.2824326
165.398,13.280515,6.2370319,0.0,0,3.3612847,0.0,0.53754056,98.768906,3.747927,353.47592,-9.2831621
165.4004,13.620713,6.4585977,0.0,0,3.1483088,0.0,0.56230372,98.767021,3.5316668,353.05103,-9.2832413
165.4028,13.981308,6.6731668,0.0,0,2.9451065,0.0,0.58759874,98.875,3.3140087,352.51865,-9.2836704
165.4052,14.403036,6.8854303,0.0,0,2.7424984,0.0,0.61402631,99.195511,3.1013107,351.9863,-9.2820616
165.4076,14.855058,7.0914063,0.0,0,2.5483873,0.0,0.64024484,99.659607,2.8953395,351.45392,-9.2815084
165.41,15.305148,7.2972054,0.0,0,2.3556671,0.0,0.66659778,100.01643,2.6933815,350.36035,-9.2814465
165.4124,15.784534,7.5046668,0.0,0,2.1702483,0.0,0.69300389,100.45269,2.4854724,349.03568,-9.2806997
165.4148,16.304386,7.7096095,0.0,0,1.9869361,0.0,0.72004622,100.97844,2.2889452,347.71103,-9.2815857
165.4172,16.893854,7.9005141,0.0,0,1.8098084,0.0,0.74697739,101.83369,2.0915339,346.38635,-9.2801514
165.4196,17.489611,8.0853662,0.0,0,1.6354244,0.0,0.7746821,102.58121,1.89992,346.39899,-9.2802086
165.422,18.089855,8.2636099,0.0,0,1.4662173,0.0,0.80105734,103.31362,1.7200102,347.54315,-9.2806959
165.4244,18.709745,8.4422588,0.0,0,1.3003293,0.0,0.82692736,104.15624,1.5453787,348.68732,-9.2798767
165.4268,19.411556,8.6174326,0.0,0,1.1387084,0.0,0.85314,105.24738,1.3736937,349.83148,-9.2790184
165.4292,20.146896,8.7837143,0.0,0,0.98093235,0.0,0.87978601,106.31609,1.2042997,350.6669,-9.2794914
165.4316,20.909117,8.9433613,0.0,0,0.82657731,0.0,0.90702069,107.47316,1.0448726,350.98776,-9.2776499
165.434,21.711182,9.0964146,0.0,0,0.67652941,0.0,0.93309379,108.67892,0.88203055,351.30865,-9.2780256
165.4364,22.559212,9.2534065,0.0,0,0.52908593,0.0,0.9593451,110.01012,0.72461265,351.62952,-9.2783413
165.4388,23.472679,9.4047794,0.0,0,0.3862859,0.0,0.98481947,111.55369,0.57694948,351.6087,-9.2773991
165.4412,21.546515,9.4751043,0.0,0,0.24542016,0.0,0.99762952,101.33974,0.47524348,350.28955,-9.2791367
165.4436,19.883183,9.4852686,0.0,0,0.10962815,0.0,1.0006934,93.142952,0.43687686,348.97037,-9.2810993
165.446,19.180902,9.4848042,0.0,0,-0.025516368,0.0,1.0017622,89.738823,0.40686274,347.65118,-9.2806864
165.4484,18.818581,9.4881878,0.0,0,-0.15794842,0.0,1.0019435,87.959824,0.3790848,346.3985,-9.2808075
165.4508,18.996408,9.4947662,0.0,0,-0.29038045,0.0,1.0018592,88.800056,0.32592353,346.67496,-9.2809191
165.4532,19.226307,9.5060616,0.0,0,-0.42281243,0.0,1.0035515,89.72525,0.25917277,346.95142,-9.2808542
165.4556,19.295164,9.5123711,0.0,0,-0.55524439,0.0,1.0051723,89.908073,0.19125968,347.22784,-9.2811499
165.458,19.212835,9.5139723,0.0,0,-0.68767637,0.0,1.0068327,89.397797,0.13480769,347.5043,-9.2823067
165.4604,19.013859,9.518281,0.0,0,-0.82010835,0.0,1.0077304,88.465958,0.082308613,349.3168,-9.2833462
165.4628,18.74107,9.5268259,0.0,0,-0.9525404,0.0,1.0080042,87.098862,0.043472495,351.34879,-9.2829561
165.4652,18.374207,9.5326834,0.0,0,-1.0849724,0.0,1.0078884,85.381996,0.018535895,353.38074,-9.2837124
165.4676,17.84737,9.5348177,0.0,0,-0.72870702,359.99997,1.008886,82.900589,0.014334932,355.41269,-9.2840624
165.47,17.282335,9.5324745,0.0,0,-0.27022067,359.99997,1.0100982,80.184525,0.018461173,357.03574,-9.2849417
165.4724,16.824781,9.5286064,0.0,0,0.18826568,359.99997,1.0098459,78.104225,0.024339527,358.49039,-9.2843876
165.4748,16.512835,9.5287428,0.0,0,0.64675206,359.99997,1.0086327,76.680939,0.024267318,359.94507,-9.2845659
165.4772,16.266973,9.5339966,0.0,0,1.1052387,359.99997,1.0084242,75.601395,0.026497351,361.39972,-9.2841864
165.4796,15.800699,9.5346842,0.0,0,1.563725,359.99997,1.0089681,73.412552,0.033694737,362.77499,-9.284379
165.482,14.458116,9.5297365,0.0,0,2.0222113,359.99997,1.0090612,67.282555,0.085992992,364.08307,-9.2853041
165.4844,11.801679,9.5142088,0.0,0,2.4806981,359.99997,1.0071496,55.21014,0.20574756,365.39114,-9.2860222
165.4868,7.2431974,9.4956865,0.0,0,2.9391842,359.99997,1.0033789,34.222092,0.42908657,366.69925,-9.289999
165.4892,0.37042949,9.3351679,0.0,0,3.3976707,359.99997,0.97350842,1.7239583,0.87403065,367.75635,-9.2971125
165.4916,-0.31054795,9.2322483,0.0,0,3.8561573,359.99997,0.95466501,-1.2761141,1.5754709,368.39523,-9.29739
165.494,0.10008027,9.1395464,0.0,0,4.3146434,359.99997,0.94008732,0.3717964,2.3908272,369.03409,-9.2980404
165.4964,-0.11725702,9.1074772,0.0,0,4.7731299,359.99997,0.93553698,-0.53461272,3.0937636,369.67294,-9.2953472
165.4988,0.041528888,9.1238346,0.0,0,5.2316165,359.99997,0.9378469,0.19812487,3.6143219,370.25882,-9.2946758
165.5012,-0.08506494,9.1840115,0.0,0,5.6901026,359.99997,0.94680083,-0.32669258,4.0480986,370.64337,-9.2947836
165.5036,0.025092337,9.2643414,0.0,0,6.1485891,359.99997,0.96027076,0.020345243,4.4697471,371.02792,-9.2936163
165.506,0.0079722088,9.3702497,0.0,0,6.6070752,359.99997,0.97944921,0.0043189153,4.8904953,371.41248,-9.2932758
165.5084,2.8031244,9.4651175,0.0,0,7.0655618,359.99997,0.99796659,13.22473,5.3231587,371.80276,-9.2913189
165.5108,-0.077619106,9.409215,0.0,0,7.5240483,359.99997,0.98813975,-0.25698,5.7786512,372.3252,-9.2920017
165.5132,0.052867673,9.3850899,0.0,0,7.9825354,359.99997,0.98262328,0.14443746,6.2580924,372.8476,-9.2938938
165.5156,-0.010386314,9.401845,0.0,0,8.441021,359.99997,0.98424464,0.017881058,6.7489333,373.37,-9.2923489
165.518,0.97920787,9.448,0.0,0,8.8995075,359.99997,0.99304956,4.451704,7.2384768,373.8924,-9.2905865
165.5204,0.049662426,9.4291258,0.0,0,9.3579931,359.99997,0.99118197,0.24434374,7.7196574,374.21164,-9.290513
165.5228,0.25760779,9.4342794,0.0,0,9.8164806,359.99997,0.99263322,1.2230368,8.1946058,374.50189,-9.2903175
165.5252,0.19414698,9.4302349,0.0,0,10.274966,359.99997,0.99107623,0.94278729,8.6632214,374.79211,-9.2902613
165.5276,0.28561223,9.4328175,0.0,0,10.733453,359.99997,0.99028635,1.3218483,9.1374702,375.08234,-9.2895336
165.53,0.18896022,9.4341087,0.0,0,11.191939,359.99997,0.99055845,0.87255913,9.5973616,375.27493,-9.2879972
165.5324,0.24312131,9.4376879,0.0,0,11.650426,359.99997,0.9922238,1.1074383,10.072563,375.42731,-9.289937
165.5348,0.28304979,9.4312334,0.0,0,12.108912,359.99997,0.9921428,1.3734523,10.555912,375.57968,-9.2884197
165.5372,0.19361821,9.4321518,0.0,0,12.567399,359.99997,0.99167335,0.94370484,11.018085,375.73206,-9.2897377
165.5396,0.26601896,9.4338751,0.0,0,13.025885,359.99997,0.99069595,1.256283,11.483553,375.8844,-9.2885742
165.542,0.23742411,9.4412203,0.0,0,13.484371,359.99997,0.9913516,1.1358602,11.948058,376.03677,-9.2878723
165.5444,0.25272861,9.4394579,0.0,0,13.942858,359.99997,0.99221826,1.2151983,12.40675,376.18912,-9.2872581
165.5468,0.23103574,9.4346151,0.0,0,14.401344,359.99997,0.9925617,1.0879638,12.870245,376.34149,-9.287961
165.5492,0.31997269,9.4291496,0.0,0,14.859831,359.99997,0.99140829,1.5077277,13.34199,376.52377,-9.2867651
165.5516,0.22731136,9.4325533,0.0,0,15.318317,359.99997,0.99073058,1.0576367,13.821469,376.75595,-9.287117
165.554,0.27520698,9.4353113,0.0,0,15.776803,359.99997,0.99056292,1.2640727,14.296262,376.98813,-9.2865133
165.5564,0.26343259,9.4382067,0.0,0,16.235291,359.99997,0.9916538,1.2789541,14.766595,377.22031,-9.2870455
165.5588,0.21712363,9.4333134,0.0,0,16.693775,359.99997,0.99192828,1.0820489,15.224046,377.45248,-9.2866964
165.5612,0.29189175,9.4262447,0.0,0,17.152262,359.99997,0.99120957,1.3464184,15.688835,377.68466,-9.2874842
165.5636,0.26491454,9.4329205,0.0,0,17.61075,359.99997,0.99124593,1.2217475,16.137768,377.91687,-9.2878227
165.566,0.24208914,9.4386387,0.0,0,17.999975,359.99997,0.99116057,1.1581721,16.592501,378.14905,-9.2870436
165.5684,0.2495157,9.4412966,0.0,0,18.0,359.99997,0.99183834,1.1706676,17.049341,378.38214,-9.2875519
165.5708,0.34812501,9.4361591,0.0,0,18.0,359.99997,0.99232602,1.6614113,17.473114,378.63608,-9.2876015
165.5732,0.2640987,9.4347687,0.0,0,18.0,359.99997,0.99277502,1.2470087,17.863464,378.89005,-9.2883978
165.5756,0.33018562,9.4313688,0.0,0,18.0,359.99997,0.99138302,1.6074535,18.186958,379.14398,-9.2901621
165.578,0.32450098,9.4359818,0.0,0,18.0,359.99997,0.99083316,1.5334903,18.420879,379.39795,-9.2937641
165.5804,0.36451015,9.4382925,0.0,0,18.0,359.99997,0.9912833,1.7234623,18.54233,379.6011,-9.2969952
165.5828,0.44682673,9.4369917,0.0,0,18.0,359.99997,0.99213302,2.1028969,18.531096,379.797,-9.3042231
165.5852,0.33580214,9.4345932,0.0,0,18.0,359.99997,0.99273396,1.6929196,18.406401,379.99289,-9.3127804
165.5876,0.39177316,9.434782,0.0,0,18.0,359.99997,0.9922381,1.8048352,18.254503,380.18881,-9.3274012
165.59,0.37493327,9.437417,0.0,0,18.0,359.99997,0.99128807,1.8498738,18.133699,380.33331,-9.3421936
165.5924,0.39397186,9.4386625,0.0,0,18.0,359.99997,0.99080193,1.8377589,18.059082,380.45667,-9.3594894
165.5948,0.39965242,9.4351492,0.0,0,18.0,359.99997,0.99140996,1.9454958,18.040403,380.58002,-9.3790531
165.5972,0.38196486,9.4278784,0.0,0,18.0,359.99997,0.99139786,1.8100358,18.041622,380.70337,-9.3995857
165.5996,0.34198365,9.425581,0.0,0,18.0,359.99997,0.99110776,1.5323993,18.062889,380.81491,-9.4209747
165.602,0.3883746,9.4262257,0.0,0,18.0,359.99997,0.98986179,1.8299755,18.091312,380.91647,-9.4409332
165.6044,0.39721981,9.4306412,0.0,0,18.0,359.99997,0.98950899,1.8530625,18.113733,381.01804,-9.459054
165.6068,0.40968448,9.4311647,0.0,0,18.0,359.99997,0.99034119,1.9310808,18.128742,381.11963,-9.4767342
165.6092,0.37663928,9.4271564,0.0,0,18.0,359.99997,0.99081123,1.851163,18.142649,381.22119,-9.49296
165.6116,0.38988763,9.4251194,0.0,0,18.0,359.99997,0.99104846,1.8101877,18.147312,381.32272,-9.5104017
165.614,0.42705891,9.427043,0.0,0,18.0,359.99997,0.99039125,1.9709649,18.142733,381.42429,-9.5286522
165.6164,0.42695358,9.432271,0.0,0,18.0,359.99997,0.98989481,2.0448821,18.144442,381.52585,-9.5445375
165.6188,0.41549143,9.4358892,0.0,0,18.0,359.99997,0.9906196,2.0034895,18.138884,381.63339,-9.5617619
165.6212,0.38388807,9.4344168,0.0,0,18.0,359.99997,0.99178505,1.8427024,18.137604,381.76379,-9.5808964
165.6236,0.40155298,9.4258051,0.0,0,18.0,359.99997,0.99137282,1.9211557,18.135361,381.89423,-9.5974083
165.626,0.43622988,9.4259348,0.0,0,18.0,359.99997,0.99030101,2.0367863,18.136335,382.02463,-9.6169415
165.6284,0.43526611,9.4281893,0.0,0,18.0,359.99997,0.98966426,2.0758386,18.131083,382.15323,-9.6320543
165.6308,0.42485571,9.4334249,0.0,0,18.0,359.99997,0.99029231,2.0249677,18.121931,382.24008,-9.6503935
165.6332,0.4102096,9.4330082,0.0,0,18.0,359.99997,0.99141675,1.9700961,18.12068,382.32693,-9.6675797
165.6356,0.44459632,9.428319,0.0,0,18.0,359.99997,0.99142879,2.0837696,18.120382,382.41382,-9.6847029
165.638,0.44669977,9.4284058,0.0,0,18.0,359.99997,0.99122399,2.0956371,18.118439,382.50067,-9.701582
165.6404,0.44329786,9.4347954,0.0,0,18.0,359.99997,0.99107772,2.1385679,18.116964,382.58755,-9.7190399
165.6428,0.41543016,9.4384918,0.0,0,18.0,359.99997,0.99075568,1.9728911,18.115297,382.67441,-9.737298
165.6452,0.43351999,9.4351597,0.0,0,18.0,359.99997,0.99106908,2.0120418,18.110994,382.76129,-9.7548895
165.6476,0.44174999,9.4306364,0.0,0,18.0,359.99997,0.99169433,2.0981417,18.111544,382.84818,-9.7723608
165.65,0.45631915,9.4264793,0.0,0,18.0,359.99997,0.99120641,2.1822052,18.108757,382.93503,-9.7895803
165.6524,0.43931442,9.4264793,0.0,0,18.0,359.99997,0.98986816,2.0654061,18.11067,383.02191,-9.8075399
165.6548,0.4322719,9.4302855,0.0,0,18.0,359.99997,0.98966849,2.0373902,18.104908,383.1088,-9.8254728
165.6572,0.43850356,9.4318867,0.0,0,18.0,359.99997,0.99045652,2.0788283,18.102936,383.19565,-9.8431911
165.6596,0.45242938,9.4275131,0.0,0,18.0,359.99997,0.99089342,2.1145334,18.106947,383.259,-9.8612041
165.662,0.45364895,9.4281855,0.0,0,18.0,359.99997,0.99140245,2.1199789,18.103315,383.30243,-9.8778925
165.6644,0.4314754,9.4274492,0.0,0,18.0,359.99997,0.99042815,2.0640895,18.103563,383.34586,-9.8965654
165.6668,0.43946016,9.4328318,0.0,0,18.0,359.99997,0.99032211,2.0595257,18.102795,383.38931,-9.9139147
165.6692,0.43963102,9.4344673,0.0,0,18.0,359.99997,0.99027997,2.0914803,18.102667,383.43274,-9.9305067
165.6716,0.46124509,9.4332094,0.0,0,18.0,359.99997,0.99157703,2.1683807,18.102631,383.47617,-9.9483156
165.674,0.45208615,9.4284573,0.0,0,18.0,359.99997,0.99165732,2.1373529,18.102137,383.51962,-9.9662571
165.6764,0.44086006,9.4261351,0.0,0,18.0,359.99997,0.99078071,2.0894847,18.100693,383.56305,-9.9832115
165.6788,0.46779144,9.4302874,0.0,0,18.0,359.99997,0.99006069,2.1725359,18.102095,383.608,-10.001009
165.6812,0.48745862,9.4335442,0.0,0,18.0,359.99997,0.99039239,2.2884445,18.098351,383.65869,-10.018408
165.6836,0.46112779,9.4319582,0.0,0,18.0,359.99997,0.99094939,2.1705394,18.096106,383.70935,-10.03642
165.686,0.45402908,9.4298153,0.0,0,18.0,359.99997,0.9916715,2.1575811,18.100397,383.76004,-10.054076
165.6884,0.47349504,9.429285,0.0,0,18.0,359.99997,0.99145061,2.1897464,18.092104,383.8107,-10.071504
165.6908,0.48118761,9.4317179,0.0,0,18.0,359.99997,0.99053115,2.2393377,18.097101,383.86139,-10.089183
165.6932,0.49779987,9.4346571,0.0,0,18.0,359.99997,0.99005079,2.3706267,18.094561,383.91205,-10.105861
165.6956,0.47923392,9.4385834,0.0,0,18.0,359.99997,0.99173212,2.2930946,18.094858,383.96271,-10.12397
165.698,0.4632124,9.4347458,0.0,0,18.0,359.99997,0.99239546,2.1983759,18.093935,384.01337,-10.140657
165.7004,0.48221594,9.4287567,0.0,0,18.0,359.99997,0.99173152,2.264312,18.090433,384.03873,-10.157963
165.7028,0.49808288,9.4296808,0.0,0,18.0,359.99997,0.99045795,2.3697431,18.088398,384.06046,-10.175814
165.7052,0.49893332,9.4332857,0.0,0,18.0,359.99997,0.99028367,2.3889725,18.085386,384.08218,-10.194106
165.7076,0.48099962,9.4344893,0.0,0,18.0,359.99997,0.99066168,2.2810168,18.084877,384.10388,-10.211772
165.71,0.48098591,9.4308729,0.0,0,18.0,359.99997,0.99126422,2.3034527,18.084864,384.09485,-10.228854
165.7124,0.49606919,9.4248571,0.0,0,18.0,359.99997,0.99098521,2.3447597,18.084703,384.07312,-10.24708
165.7148,0.51413012,9.4275694,0.0,0,18.0,359.99997,0.99056256,2.4239631,18.08366,384.05139,-10.265086
165.7172,0.50167954,9.4347353,0.0,0,18.0,359.99997,0.99050182,2.3881872,18.087074,384.02966,-10.28296
165.7196,0.47640687,9.43855,0.0,0,18.0,359.99997,0.99092448,2.2672427,18.086586,384.03149,-10.30047
165.722,0.49246219,9.4364433,0.0,0,18.0,359.99997,0.99184537,2.3150666,18.084587,384.05319,-10.318184
165.7244,0.49599132,9.4292583,0.0,0,18.0,359.99997,0.99180543,2.3388662,18.083969,384.07492,-10.334586
165.7268,0.51538616,9.4269648,0.0,0,18.0,359.99997,0.99076599,2.4121788,18.083942,384.09665,-10.353127
165.7292,0.48928931,9.4303799,0.0,0,18.0,359.99997,0.99011737,2.3510392,18.083109,384.12924,-10.371881
165.7316,0.49141842,9.434329,0.0,0,18.0,359.99997,0.99051017,2.3094072,18.081148,384.1799,-10.388289
165.734,0.51676196,9.4336481,0.0,0,18.0,359.99997,0.99122459,2.42945,18.081242,384.23056,-10.404416
165.7364,0.52126932,9.4314804,0.0,0,18.0,359.99997,0.99197429,2.4689658,18.082062,384.28125,-10.422067
165.7388,0.50935572,9.4314756,0.0,0,18.0,359.99997,0.99188882,2.4087367,18.079777,384.31683,-10.440699
165.7412,0.49056813,9.4332247,0.0,0,18.0,359.99997,0.99092907,2.3358314,18.080025,384.2951,-10.458777
165.7436,0.4995628,9.4366159,0.0,0,18.0,359.99997,0.99061847,2.4024971,18.078264,384.27341,-10.476108
165.746,0.51516247,9.4395294,0.0,0,18.0,359.99997,0.99158376,2.4503064,18.078852,384.25168,-10.494278
165.7484,0.52683163,9.4354839,0.0,0,18.0,359.99997,0.99236548,2.4782665,18.076674,384.22995,-10.511247
165.7508,0.51474559,9.4317646,0.0,0,18.0,359.99997,0.99225682,2.4425409,18.076433,384.20825,-10.529451
165.7532,0.50810754,9.4334803,0.0,0,18.0,359.99997,0.99144238,2.4479487,18.074341,384.18652,-10.546784
165.7556,0.52128959,9.4352322,0.0,0,18.0,359.99997,0.99062294,2.478092,18.071444,384.16483,-10.563091
165.758,0.55000991,9.4347181,0.0,0,18.0,359.99997,0.99066657,2.5736313,18.068747,384.1431,-10.58075
165.7604,0.53756821,9.4335985,0.0,0,18.0,359.99997,0.99176425,2.5197139,18.072386,384.15305,-10.599133
165.7628,0.51833117,9.4301929,0.0,0,18.0,359.99997,0.99191755,2.4181099,18.072697,384.16751,-10.616962
165.7652,0.52707922,9.4280005,0.0,0,18.0,359.99997,0.99076831,2.4827597,18.071447,384.18198,-10.634932
165.7676,0.53944093,9.4361525,0.0,0,18.0,359.99997,0.99085039,2.5573232,18.067081,384.19647,-10.651452
165.77,0.55530679,9.4415627,0.0,0,18.0,359.99997,0.99138397,2.6297972,18.075539,384.20068,-10.668325
165.7724,0.5469206,9.4397907,0.0,0,18.0,359.99997,0.99256712,2.5963769,18.070763,384.20068,-10.685395
165.7748,0.52766234,9.4334593,0.0,0,18.0,359.99997,0.99250168,2.4856761,18.070889,384.20068,-10.703725
165.7772,0.54830974,9.4294815,0.0,0,18.0,359.99997,0.9914304,2.5946434,18.07345,384.20068,-10.722344
165.7796,0.55455077,9.432312,0.0,0,18.0,359.99997,0.99058294,2.6448605,18.069532,384.19284,-10.737461
165.782,0.55057073,9.4357347,0.0,0,18.0,359.99997,0.99070144,2.6179602,18.066786,384.17838,-10.75595
165.7844,0.53200102,9.4371128,0.0,0,18.0,359.99997,0.99162585,2.5161827,18.066765,384.16391,-10.773532
165.7868,0.53884506,9.432766,0.0,0,18.0,359.99997,0.99209732,2.5527291,18.064798,384.14941,-10.791604
165.7892,0.55351883,9.4310112,0.0,0,18.0,359.99997,0.99181861,2.5999484,18.066584,384.1431,-10.80878
165.7916,0.55807197,9.4344645,0.0,0,18.0,359.99997,0.99118996,2.6148112,18.066366,384.15033,-10.826448
165.794,0.55573881,9.4411507,0.0,0,18.0,359.99997,0.99140298,2.6561377,18.065674,384.15756,-10.84515
165.7964,0.53017509,9.441534,0.0,0,18.0,359.99997,0.99196851,2.5310369,18.066496,384.16479,-10.863112
165.7988,0.55581504,9.4359455,0.0,0,18.0,359.99997,0.99243462,2.6419156,18.061592,384.17053,-10.881636
165.8012,0.56978852,9.4288874,0.0,0,18.0,359.99997,0.99171299,2.6554518,18.063696,384.17053,-10.897458
165.8036,0.55935836,9.432147,0.0,0,18.0,359.99997,0.99120969,2.6616299,18.064476,384.17053,-10.914235
165.806,0.55244052,9.4389391,0.0,0,18.0,359.99997,0.99117309,2.6096337,18.063251,384.17053,-10.933009
165.8084,0.54971957,9.4374924,0.0,0,18.0,359.99997,0.99128222,2.6044145,18.058083,384.16904,-10.950555
165.8108,0.55590999,9.4320869,0.0,0,18.0,359.99997,0.99149096,2.6299403,18.058558,384.13281,-10.968246
165.8132,0.57726109,9.4295282,0.0,0,18.0,359.99997,0.99180561,2.7372463,18.06147,384.09662,-10.983835
165.8156,0.57787138,9.4322281,0.0,0,18.0,359.99997,0.99169308,2.7410724,18.058552,384.06042,-11.00276
165.818,0.55107081,9.4379387,0.0,0,18.0,359.99997,0.99131483,2.5781746,18.056255,384.02423,-11.02115
165.8204,0.56288207,9.4395027,0.0,0,18.0,359.99997,0.99102843,2.6548753,18.053255,383.99438,-11.037341
165.8228,0.58003521,9.4366522,0.0,0,18.0,359.99997,0.99162209,2.7332435,18.057514,383.96542,-11.054259
165.8252,0.58357435,9.4330425,0.0,0,18.0,359.99997,0.99231595,2.7572925,18.052835,383.93646,-11.071764
165.8276,0.56395119,9.4315081,0.0,0,18.0,359.99997,0.99186391,2.7279792,18.054844,383.90753,-11.090034
165.83,0.55740082,9.4342365,0.0,0,18.0,359.99997,0.99104887,2.642518,18.057226,383.8837,-11.107532
165.8324,0.56300139,9.4350548,0.0,0,18.0,359.99997,0.99060678,2.6313562,18.051687,383.86197,-11.124904
165.8348,0.60509473,9.435585,0.0,0,18.0,359.99997,0.99128759,2.8659432,18.053181,383.84027,-11.14251
165.8372,0.59570682,9.4343424,0.0,0,18.0,359.99997,0.9922207,2.8209994,18.05826,383.81854,-11.160256
165.8396,0.57368273,9.4317636,0.0,0,18.0,359.99997,0.99204701,2.6979268,18.050726,383.80075,-11.177938
165.842,0.58025342,9.4338961,0.0,0,18.0,359.99997,0.99127275,2.7401474,18.054604,383.78625,-11.195246
165.8444,0.60498822,9.4397278,0.0,0,18.0,359.99997,0.99122936,2.8276901,18.051296,383.77176,-11.213502
165.8468,0.60752416,9.4413767,0.0,0,18.0,359.99997,0.9916836,2.8699577,18.052048,383.75729,-11.230304
165.8492,0.59707326,9.4382648,0.0,0,18.0,359.99997,0.99278462,2.8128276,18.050308,383.74551,-11.2485
165.8516,0.57265747,9.4333057,0.0,0,18.0,359.99997,0.99252921,2.7411842,18.049116,383.73828,-11.265792
165.854,0.5875234,9.4342384,0.0,0,18.0,359.99997,0.99163318,2.7928932,18.050415,383.73105,-11.284343
165.8564,0.62131459,9.4367571,0.0,0,18.0,359.99997,0.99100459,2.9261787,18.048836,383.72382,-11.301274
165.8588,0.60817659,9.4405918,0.0,0,18.0,359.99997,0.99170798,2.8760028,18.049307,383.70901,-11.318761
165.8612,0.59157872,9.4377155,0.0,0,18.0,359.99997,0.99222738,2.8062127,18.04842,383.66559,-11.336452
165.8636,0.58357495,9.4315624,0.0,0,18.0,359.99997,0.99219704,2.7555976,18.048567,383.62216,-11.352133
166.0655,0.60153431,9.4372616,0.0,0,18.0,0.68381351,0.99195695,2.836993,18.025738,375.91464,-11.481241
167.2655,0.67195469,9.4476023,0.0,0,18.0,2.9561132e-17,0.99375421,3.1664319,18.000837,349.85541,-11.481903
168.4655,0.69888151,9.4545956,0.0,0,18.0,1.2779233e-33,0.99506301,3.2897425,18.000021,335.92471,-11.482854
169.6655,0.70130962,9.4616337,0.0,0,18.0,1.4012985e-45,0.99627614,3.2984107,17.999367,324.82938,-11.482533
170.8655,0.71448833,9.4674549,0.0,0,18.0,1.4012985e-45,0.99747032,3.3545437,17.998182,314.98398,-11.483677
172.0655,0.71551049,9.4734449,0.0,0,18.0,1.4012985e-45,0.99851853,3.3536727,17.999601,305.94968,-11.483498
173.2655,0.72370714,9.4788303,0.0,0,18.0,1.4012985e-45,0.99947989,3.3865314,17.99873,297.07999,-11.482859
174.4655,0.72450978,9.4840212,0.0,0,18.0,1.4012985e-45,1.0004352,3.3899255,17.999586,288.53644,-11.482865
175.6655,0.7315644,9.4893799,0.0,0,18.0,1.4012985e-45,1.0013124,3.4207904,18.001125,280.17084,-11.48266
176.8655,0.73235404,9.4941444,0.0,0,18.0,1.4012985e-45,1.0022207,3.4211056,17.99939,271.93225,-11.48318
178.0655,0.740704,9.4996414,0.0,0,18.0,1.4012985e-45,1.003144,3.4638665,18.000278,263.87878,-11.483104
179.2655,0.74332273,9.5042486,0.0,0,18.0,1.4012985e-45,1.0041215,3.4617524,18.000322,256.23187,-11.483097
180.4655,0.74685854,9.5092392,0.0,0,18.0,1.4012985e-45,1.0050113,3.4841444,18.000038,249.19719,-11.482907
181.6655,0.75645804,9.5138922,0.0,0,18.0,1.4012985e-45,1.0058874,3.5196779,18.00001,242.2558,-11.483228
182.8655,0.75289148,9.5190487,0.0,0,18.0,1.4012985e-45,1.0068223,3.506495,17.999544,235.2462,-11.48353
184.0655,0.76236659,9.5229874,0.0,0,18.0,1.4012985e-45,1.0074401,3.5409019,18.000019,228.60364,-11.482475
185.2655,0.76332933,9.5272779,0.0,0,18.0,1.4012985e-45,1.0082498,3.5490551,18.000092,222.16861,-11.482802
186.4655,0.76892978,9.5316381,0.0,0,18.0,1.4012985e-45,1.0089942,3.5629914,17.99958,215.8324,-11.48314
187.6655,0.77263176,9.535779,0.0,0,18.0,1.4012985e-45,1.0098469,3.5829279,18.000153,209.71361,-11.483633
188.8655,0.77637362,9.5397387,0.0,0,18.0,1.4012985e-45,1.0105305,3.5964634,17.999649,203.69231,-11.483103
190.0655,0.78018612,9.5438156,0.0,0,18.0,1.4012985e-45,1.0114083,3.6227775,17.999134,198.01247,-11.483233
191.2655,0.78770834,9.5481539,0.0,0,18.0,1.4012985e-45,1.0121605,3.6441305,17.999786,192.32285,-11.48276
192.4655,0.7821514,9.5516844,0.0,0,18.0,1.4012985e-45,1.0127553,3.6136076,17.999928,186.94781,-11.483319
193.6655,0.79223722,9.5556469,0.0,0,18.0,1.4012985e-45,1.0134939,3.6562808,18.000805,181.74417,-11.483232
194.8655,0.78647119,9.5590076,0.0,0,18.0,1.4012985e-45,1.0140065,3.6321912,18.00013,176.75227,-11.483007
196.0655,0.80486852,9.5625429,0.0,0,18.0,1.4012985e-45,1.01472,3.7176518,18.00075,172.13898,-11.482697
197.2655,0.79530871,9.5663519,0.0,0,18.0,1.4012985e-45,1.0153638,3.6640322,18.000177,167.5874,-11.483542
198.4655,0.80809891,9.5692167,0.0,0,18.0,1.4012985e-45,1.0160198,3.7266679,18.000519,163.15584,-11.48355
199.6655,0.80447447,9.5725193,0.0,0,18.0,1.4012985e-45,1.0166162,3.7052264,17.999353,158.89597,-11.482733
200.8655,0.81025636,9.5753746,0.0,0,18.0,1.4012985e-45,1.0171839,3.7341959,17.999197,154.86189,-11.482511
202.0655,0.80637646,9.5785723,0.0,0,18.0,1.4012985e-45,1.0177305,3.7028272,17.999323,150.87036,-11.482877
203.2655,0.81946158,9.5812159,0.0,0,18.0,1.4012985e-45,1.0181601,3.7732224,18.00004,147.063,-11.483444
204.4655,0.80323386,9.5843983,0.0,0,18.0,1.4012985e-45,1.0187598,3.685149,17.999565,143.22978,-11.483129
205.6655,0.81536752,9.5871458,0.0,0,18.0,1.4012985e-45,1.0192024,3.7483046,18.000092,139.51062,-11.483025
206.8655,0.81164294,9.5891495,0.0,0,18.0,1.4012985e-45,1.0196556,3.7246861,17.999763,135.99225,-11.48315
208.0655,0.81632984,9.592021,0.0,0,18.0,1.4012985e-45,1.0201323,3.7541308,17.998827,132.48022,-11.483131
209.2655,0.82397819,9.5941706,0.0,0,18.0,1.4012985e-45,1.0206528,3.7750142,17.999336,129.13736,-11.483846
210.4655,0.81571543,9.5970259,0.0,0,18.0,1.4012985e-45,1.0211105,3.7429025,17.998957,125.92954,-11.483318
211.6655,0.81991011,9.5997496,0.0,0,18.0,1.4012985e-45,1.0216674,3.755769,18.000332,122.76505,-11.483356
212.8655,0.81930536,9.6023617,0.0,0,18.0,1.4012985e-45,1.0221592,3.7553978,18.000334,119.7327,-11.483114
214.0655,0.82697064,9.6045666,0.0,0,18.0,1.4012985e-45,1.022459,3.7918293,17.999231,116.77666,-11.483143
215.2655,0.81964386,9.6066666,0.0,0,18.0,1.4012985e-45,1.022859,3.7607431,17.999771,114.01044,-11.484111
216.4655,0.82413149,9.6090078,0.0,0,18.0,1.4012985e-45,1.023247,3.766587,18.000238,111.24324,-11.483191
217.6655,0.81989622,9.6107368,0.0,0,18.0,1.4012985e-45,1.02363,3.7532079,17.999981,108.53773,-11.483194
218.8655,0.82654387,9.6133795,0.0,0,18.0,1.4012985e-45,1.0240463,3.7787211,18.000357,106.03836,-11.482898
220.0655,0.82143331,9.615365,0.0,0,18.0,1.4012985e-45,1.0245749,3.7545795,18.001276,103.55823,-11.483637
221.2655,0.82763106,9.6177168,0.0,0,18.0,1.4012985e-45,1.0249319,3.7805188,17.999561,101.13488,-11.483345
222.4655,0.81577039,9.6187458,0.0,0,18.0,1.4012985e-45,1.0252086,3.72365,18.001122,98.841881,-11.482925
223.6655,0.83191234,9.6212378,0.0,0,18.0,1.4012985e-45,1.0256377,3.8023612,18.000143,96.62001,-11.482825
224.8655,0.8253262,9.6228991,0.0,0,18.0,1.4012985e-45,1.0258958,3.7645247,17.999006,94.441681,-11.483315
225.8655,0.82137364,9.6243401,0.0,0,18.0,1.4012985e-45,1.0261978,3.7539127,18.001661,92.645103,-11.483914