File: examples/dan-msc-case-studies/CS3/data/01 raw data/baron_test_073.csv
Time(sec),Force(kN),Jaw(mm),PowAngle(deg),Power(W),Pram,PTemp,Strain,Stress(MPa),Stroke(mm),TC1(C),wedge(mm)
0.0,0.88198155,0.62536412,0.0,0,10.594783,0.0016511733,0.042602543,10.766031,10.595671,22.438175,-9.1271181
2.2,0.80684793,-0.0015295394,0.0,0,10.594783,6.5159173,-9.3707313e-05,10.273387,10.59472,22.375996,-9.4915161
4.4,0.77285087,-0.0016691696,0.0,0,10.594783,13.115914,-0.00010937139,9.8380976,10.595228,22.381554,-9.4883728
6.6,0.74521697,-0.0017890421,0.0,0,10.594783,19.715912,-0.00011306991,9.4786959,10.594262,22.379124,-9.4841766
8.8,0.73290038,-0.0010888117,20.228083,0,10.594783,26.315912,-9.0935682e-05,9.3363857,10.595038,22.910986,-9.4799099
11.0,0.75258291,-0.0045696492,30.814121,0,10.594783,32.915924,-0.00029595496,9.5937071,10.59437,29.136003,-9.4763765
13.2,0.759588,-0.0098920595,32.849117,0,10.594783,39.515911,-0.00067158509,9.6796474,10.594325,37.157276,-9.4727106
15.4,0.75058132,-0.015224718,32.849129,0,10.594783,46.115906,-0.00098880986,9.5611629,10.594153,45.221195,-9.4684486
17.6,0.76251131,-0.019849373,34.148705,0,10.594783,52.715904,-0.0013142037,9.7263012,10.594717,51.76355,-9.4641848
19.8,0.77148879,-0.024804832,34.650875,0,10.594783,59.315899,-0.001659859,9.8271894,10.595179,58.68795,-9.4600868
22.0,0.77404165,-0.030508744,35.496826,0,10.594783,65.915901,-0.002034239,9.8691158,10.595933,65.455818,-9.4564676
24.2,0.77658302,-0.034734692,35.496826,0,10.594783,72.5159,-0.0023319607,9.9164438,10.594967,72.230896,-9.4523582
26.4,0.78061205,-0.039054904,36.293388,0,10.594783,79.115891,-0.0025780268,9.9603872,10.594494,78.796799,-9.4480114
28.6,0.77283436,-0.044139687,36.605568,0,10.594783,85.715897,-0.0029542183,9.8411083,10.594123,85.281868,-9.4437361
30.8,0.78100759,-0.049123351,37.08984,0,10.594783,92.315895,-0.0032586628,9.9845657,10.595003,92.007751,-9.4401474
33.0,0.78340888,-0.053573206,37.144161,0,10.594783,98.915894,-0.0035629133,10.003976,10.594308,98.65892,-9.4363127
35.2,0.79591417,-0.058688097,37.83691,0,10.594783,105.51589,-0.0039159968,10.15537,10.594938,105.32296,-9.4323044
37.4,0.80558181,-0.063645676,38.368332,0,10.594783,112.1159,-0.0042372681,10.291729,10.594251,111.77982,-9.4282856
39.6,0.80944681,-0.069179468,38.551022,0,10.594783,118.7159,-0.0046202885,10.355208,10.594887,118.3336,-9.424119
41.8,0.82646543,-0.075688325,39.241047,0,10.594783,125.3159,-0.0049967724,10.579772,10.594757,124.97021,-9.4205227
44.0,0.8260268,-0.081646204,39.24316,0,10.594783,131.91588,-0.0054137837,10.586465,10.595155,131.65997,-9.416605
46.2,0.83718491,-0.087021343,39.875774,0,10.594783,138.51588,-0.00580524,10.725053,10.594843,138.23926,-9.4129753
48.4,0.84662604,-0.091741621,39.834991,0,10.594783,145.11588,-0.0061027454,10.847615,10.595144,144.99596,-9.4087143
50.6,0.84421939,-0.097436063,40.42337,0,10.594783,151.71588,-0.0064886934,10.818145,10.595166,151.39488,-9.4046001
52.8,0.84949738,-0.10398003,40.572506,0,10.594783,158.31587,-0.006880146,10.884702,10.594345,157.96535,-9.4007587
55.0,0.86491877,-0.10990325,41.198463,0,10.594783,164.91588,-0.0072895032,11.097309,10.594989,164.55238,-9.3973131
57.2,0.86870766,-0.11591391,40.07457,0,10.594783,171.51588,-0.0077069271,11.144163,10.594039,171.82796,-9.3937979
59.4,0.86935109,-0.12116306,39.924313,0,10.594783,178.11589,-0.0080351597,11.16738,10.594657,178.43964,-9.3897552
61.6,0.87574905,-0.12656532,41.792461,0,10.594783,184.71588,-0.0084181409,11.256755,10.594604,183.8223,-9.3855858
63.8,0.87691957,-0.13338616,41.822769,0,10.594783,191.31589,-0.0088357348,11.264731,10.594398,190.76733,-9.3816719
66.0,0.88515687,-0.13901334,41.219063,0,10.594783,197.91588,-0.0092169112,11.381588,10.594226,197.9668,-9.378562
68.2,0.88951719,-0.14460637,41.795628,0,10.594783,204.51587,-0.0096143326,11.433613,10.594691,204.3588,-9.3747435
70.4,0.89467585,-0.15049185,42.369209,0,10.594783,211.11588,-0.0099529512,11.514533,10.594603,210.70982,-9.3713093
72.6,0.89903349,-0.15654491,43.019978,0,10.594783,217.71587,-0.010375448,11.564665,10.595072,216.9333,-9.3670797
74.8,0.90171814,-0.16352041,44.362049,0,10.594783,224.31586,-0.010851722,11.59833,10.594546,223.29118,-9.3633556
77.0,0.90410185,-0.17079425,45.12085,0,10.594783,230.91586,-0.011317485,11.652407,10.594304,229.89943,-9.3592615
79.2,0.91298926,-0.17860809,45.615231,0,10.594783,237.51585,-0.011838727,11.782028,10.594843,236.82799,-9.3560019
81.4,0.90978336,-0.18692629,45.663559,0,10.594783,244.11588,-0.012381631,11.742178,10.594358,243.76445,-9.3522673
83.6,0.91442704,-0.1946923,45.62516,0,10.594783,250.71587,-0.012891156,11.791761,10.595104,250.57893,-9.3489132
85.8,0.90980232,-0.202315,45.615238,0,10.594783,257.31613,-0.013416705,11.741738,10.595094,257.49908,-9.3446875
88.0,0.90375847,-0.20985517,45.140694,0,10.594783,263.91589,-0.013882047,11.673899,10.595915,264.11389,-9.341012
90.2,0.90657616,-0.21677209,45.420128,0,10.594783,270.51587,-0.014350149,11.723444,10.595575,270.54926,-9.337203
92.4,0.90709692,-0.2238452,45.587475,0,10.594783,277.11584,-0.014832463,11.735875,10.594678,277.09445,-9.3335457
94.6,0.90474015,-0.2310681,45.615231,0,10.594783,283.71582,-0.015279558,11.688931,10.594352,283.52066,-9.3299046
96.8,0.91969734,-0.23701449,46.078941,0,10.594783,290.31586,-0.015686393,11.874269,10.594697,290.1199,-9.3264532
99.0,0.92497331,-0.24417722,46.109619,0,10.594783,296.91583,-0.016155481,11.9588,10.595214,296.56982,-9.3224068
101.2,0.92355859,-0.25283569,46.420536,0,10.594783,303.51584,-0.016692141,11.962356,10.595011,303.3111,-9.3186197
103.4,0.9343822,-0.26061141,46.582027,0,10.594783,310.11584,-0.017211389,12.118313,10.595096,310.02527,-9.3150787
105.6,0.93340027,-0.26768714,47.05444,0,10.594783,316.71588,-0.017707085,12.090633,10.59381,316.20877,-9.3109674
107.8,0.93142903,-0.2735236,47.504883,0,10.594783,323.31586,-0.018071009,12.081733,10.594743,322.73352,-9.3077021
110.0,0.9335916,-0.27933866,47.955318,0,10.594783,329.91586,-0.018449645,12.111789,10.595505,329.4303,-9.3043747
112.2,0.92950684,-0.28682739,47.955318,0,10.594783,336.51584,-0.018954024,12.060153,10.59439,336.2583,-9.3003025
114.4,0.9262681,-0.29467732,48.383541,0,10.594783,343.11581,-0.019439936,12.013372,10.594449,342.72784,-9.2958565
116.6,0.93001729,-0.3027032,48.610977,0,10.594783,349.71582,-0.01998017,12.094707,10.59513,349.31464,-9.2927227
118.8,0.92631173,-0.31015065,48.629299,0,10.594783,356.31583,-0.020482471,12.027783,10.594599,356.1322,-9.2892847
121.0,0.9470917,-0.31991997,48.701656,0,10.594783,362.91583,-0.021113936,12.30744,10.594995,362.84372,-9.285943
123.2,0.95010257,-0.32429567,48.384422,0,10.594783,369.51581,-0.021382755,12.366328,10.594622,369.67575,-9.2820711
125.4,0.94454962,-0.33201745,48.383785,0,10.594783,376.11581,-0.021887679,12.297319,10.59552,376.32135,-9.2781467
127.6,0.93524462,-0.33931372,48.383785,0,10.594783,382.71585,-0.022382725,12.177157,10.594835,382.55774,-9.2740784
129.8,0.93363786,-0.34694463,48.812252,0,10.594783,389.31583,-0.022845037,12.172709,10.594489,388.91699,-9.2707815
132.0,0.94131231,-0.35404176,49.437649,0,10.594783,395.91586,-0.02332869,12.257985,10.594842,395.33145,-9.2672663
134.2,0.95597583,-0.36512288,49.636234,0,10.594783,402.51584,-0.024068143,12.47087,10.594946,401.97784,-9.2636213
136.4,0.95834446,-0.37031958,50.042721,0,10.594783,409.11581,-0.024381103,12.500498,10.594904,408.7196,-9.2598467
138.6,0.95181352,-0.37749448,50.042721,0,10.594783,415.71582,-0.024851495,12.422523,10.594833,415.54559,-9.2556791
140.8,0.94550335,-0.38604012,50.105915,0,10.594783,422.31583,-0.025417091,12.343855,10.594976,422.15781,-9.2518063
143.0,0.94558603,-0.39411923,50.438229,0,10.594783,428.9158,-0.02593953,12.369041,10.594559,428.52652,-9.2485409
145.2,0.94179207,-0.40269893,50.82275,0,10.594783,435.51581,-0.026484411,12.310314,10.594851,434.9982,-9.2448635
147.4,0.96609622,-0.41339213,51.196285,0,10.594783,442.11581,-0.027187018,12.633122,10.594809,441.48895,-9.2410383
149.6,0.96270156,-0.41814187,51.196293,0,10.594783,448.71582,-0.027516909,12.598291,10.593751,448.52835,-9.2375956
151.8,0.95252711,-0.42854533,51.24213,0,10.594783,455.31586,-0.028151881,12.488177,10.594352,455.21048,-9.2345304
154.0,0.96760911,-0.43586475,51.56982,0,10.594783,461.91583,-0.028627833,12.663876,10.595402,461.59769,-9.2306328
156.2,0.97057617,-0.44381961,51.56982,0,10.594783,468.51581,-0.029150877,12.723133,10.59498,468.39566,-9.2264528
158.4,0.95815438,-0.45414811,51.56982,0,10.594783,475.11578,-0.029843479,12.593481,10.594881,475.10071,-9.2229872
160.6,0.98346901,-0.46502498,51.569828,0,10.594783,481.71579,-0.030514464,12.904898,10.593964,481.78497,-9.219286
162.8,0.9680475,-0.4710702,51.56982,0,10.594783,488.3158,-0.03091901,12.718478,10.594686,488.38324,-9.2159214
165.0,0.97154617,-0.47727886,51.196293,0,10.594783,494.9158,-0.031343225,12.758795,10.594046,495.06284,-9.2120533
167.2,0.11131487,-0.50007945,50.438492,0,10.594783,499.99884,-0.032799739,1.4855402,10.595393,501.09393,-9.2087641
169.4,0.074449122,-0.49791762,50.278049,0,10.594783,499.99884,-0.032623667,0.9836781,10.59505,500.77039,-9.2091627
171.6,0.064554706,-0.49595857,47.651344,0,10.594783,499.99884,-0.032517284,0.83361477,10.593718,502.3334,-9.2089701
173.8,0.051649414,-0.49056959,47.954563,0,10.594783,499.99884,-0.032203585,0.66799027,10.594543,500.56934,-9.2091513
176.0,0.047885455,-0.48989078,51.274433,0,10.594783,499.99884,-0.032135539,0.63613147,10.594425,497.35764,-9.2085648
178.2,0.090829551,-0.49104631,54.300098,0,10.594783,499.99884,-0.032205179,1.198915,10.594394,496.06802,-9.2090311
180.4,0.087375239,-0.49374536,54.624027,0,10.594783,499.99884,-0.032370966,1.1520555,10.594913,498.24283,-9.2088594
182.6,0.089084432,-0.49611813,52.287395,0,10.594783,499.99884,-0.032573164,1.1697218,10.594413,501.60391,-9.2092943
184.8,0.083406553,-0.49615562,49.24897,0,10.594783,499.99884,-0.032542642,1.0859338,10.594675,503.2215,-9.2088871
187.0,0.055938426,-0.49620944,48.812252,0,10.594783,499.99884,-0.032515533,0.74244583,10.59423,501.58487,-9.2084713
189.2,0.061039299,-0.49565235,51.164417,0,10.594783,499.99884,-0.032503251,0.80377144,10.595235,498.69489,-9.2083321
191.4,0.092179991,-0.49554607,53.276337,0,10.594783,499.99884,-0.032522589,1.2016605,10.594097,497.49069,-9.2082176
193.6,0.081336319,-0.50049883,53.317825,0,10.594783,499.99884,-0.032837719,1.077332,10.594604,498.98825,-9.2079916
195.8,0.10196339,-0.50311196,51.23167,0,10.594783,499.99884,-0.032951847,1.3349668,10.595104,501.67557,-9.2081833
198.0,0.084744737,-0.50169718,49.229744,0,10.594783,499.99884,-0.032904916,1.1098942,10.595249,502.47537,-9.2083063
200.2,0.061847933,-0.50221956,49.632313,0,10.594783,499.99884,-0.032942154,0.82667029,10.594518,500.54718,-9.2086191
202.4,0.07920599,-0.504206,51.567974,0,10.594783,499.99884,-0.033089425,1.0467539,10.594344,498.39954,-9.2086353
204.6,0.099522978,-0.50631154,52.753651,0,10.594783,499.99884,-0.033186425,1.3059058,10.593915,498.34604,-9.2085037
206.8,0.087145783,-0.50829679,50.831993,0,10.594783,499.99884,-0.033321336,1.1460031,10.594178,501.19888,-9.2088451
209.0,0.07620506,-0.50725865,48.814106,0,10.594783,499.99884,-0.03324734,1.0140446,10.593912,501.98691,-9.2084141
211.2,0.064602673,-0.50714517,50.042698,0,10.594783,499.99884,-0.033266451,0.84091496,10.594438,499.76599,-9.2084103
211.9512,0.18207879,0.01224245,50.822754,0,10.5948,1.5409619e-16,0.0010666517,2.3477035,10.595862,498.98557,-9.2082434
211.9556,0.16407196,0.012506719,35.443462,0,10.5948,0.0,0.0010504486,2.1076229,10.593168,498.97241,-9.2082262
211.96,0.16609395,0.015600956,13.036635,0,10.5948,0.0,0.0012820887,2.0764019,10.593243,498.95926,-9.2074442
211.9644,0.18102102,0.0094109671,0.0,0,10.5948,0.0,0.00093492842,2.3567717,10.593472,498.98462,-9.2087212
211.9688,0.1616393,0.011629364,0.0,0,10.5948,0.0,0.0010093433,2.1384964,10.594178,499.06357,-9.208168
211.9732,0.16673079,0.010901754,0.0,0,10.5948,0.0,0.0009793035,2.2244091,10.594877,499.12869,-9.2082777
211.9776,0.19593529,0.013592252,0.0,0,10.5948,0.0,0.0010855886,2.564841,10.597192,499.11554,-9.2075224
211.982,0.18413176,0.011422481,0.0,0,10.5948,0.0,0.00092481048,2.36601,10.59671,499.10239,-9.2069921
211.9864,0.17686222,0.013199252,0.0,0,10.5948,0.0,0.0010425565,2.2928047,10.594119,499.07764,-9.2077217
211.9908,0.18256456,0.011770068,0.0,0,10.5948,0.0,0.00090100401,2.2938769,10.595759,499.0513,-9.2092066
211.9952,0.19468774,0.013933128,0.0,0,10.5948,0.0,0.0010842544,2.4832642,10.594314,499.02499,-9.2080507
211.9996,0.19766264,0.012159656,0.0,0,10.578863,0.0,0.00094503595,2.6215048,10.593075,498.99866,-9.2076521
212.004,0.18055162,0.015173624,0.0,0,10.512864,0.0,0.0011286594,2.3049467,10.594824,498.96326,-9.2083406
212.0084,0.1817147,0.013468187,0.0,0,10.446864,0.0,0.00093865028,2.3443072,10.583278,498.91061,-9.2073164
212.0128,0.19987878,0.013359793,0.0,0,10.380864,0.0,0.0010284059,2.5694444,10.532081,498.86411,-9.207757
212.0172,0.19606282,0.013578098,0.0,0,10.314864,0.0,0.00092027884,2.5285079,10.435209,498.89041,-9.2082558
212.0216,0.19445273,0.016342307,0.0,0,10.248864,0.0,0.0011180404,2.4720964,10.333697,498.91672,-9.2084122
212.026,0.19169207,0.01480343,0.0,0,10.182864,0.0,0.00094990211,2.5395606,10.253839,498.90045,-9.208086
212.0304,0.21031134,0.017465148,0.0,0,10.116864,0.0,0.0011744233,2.6085212,10.20408,498.87415,-9.2062702
212.0348,0.21262097,0.015718317,0.0,0,10.050864,0.0,0.00098695129,2.7391219,10.148748,498.89764,-9.2065468
212.0392,1.629339,0.038361777,0.0,0,9.9848633,0.0,0.0025239575,20.630653,10.093143,498.96344,-9.2057953
212.0436,3.2383413,0.073440298,0.0,0,9.9188633,0.0,0.0048348657,40.9902,10.023947,499.4921,-9.2066345
212.048,3.5764842,0.15139692,0.0,0,9.8528633,0.0,0.0099794939,45.076366,9.9473553,501.25504,-9.2058783
212.0524,3.7143359,0.22133394,0.0,0,9.7868633,0.0,0.014705525,46.558842,9.8732748,503.0181,-9.2036438
212.0568,3.7773538,0.29054376,0.0,0,9.7208633,0.0,0.01936201,47.142143,9.8065987,504.80725,-9.2065992
212.0612,3.7651701,0.34995079,0.0,0,9.6548634,0.0,0.02346031,46.848351,9.7417126,506.59644,-9.2054567
212.0656,3.8299441,0.41307676,0.0,0,9.5888634,0.0,0.027675707,47.329147,9.6805925,507.22305,-9.206151
212.07,3.9172804,0.47968256,0.0,0,9.5228634,0.0,0.032354448,48.373661,9.6099405,507.43347,-9.2067213
212.0744,3.9400482,0.55469781,0.0,0,9.4574747,0.0,0.037368488,48.376545,9.5376072,507.6131,-9.2061329
212.0788,3.9168606,0.61781114,0.0,0,9.393095,0.0,0.041774247,47.872662,9.4666796,507.75775,-9.2063971
212.0832,3.8939741,0.68311548,0.0,0,9.3287144,0.0,0.046309244,47.355156,9.4015551,507.91293,-9.2075901
212.0876,3.934984,0.73933059,0.0,0,9.2643328,0.0,0.05031725,47.649372,9.3418379,508.1102,-9.2059965
212.092,3.9949248,0.80577344,0.0,0,9.1999531,0.0,0.054893889,48.162586,9.2776766,508.30746,-9.2076139
212.0964,4.006371,0.87002224,0.0,0,9.1355715,0.0,0.059534743,48.111835,9.2112427,508.48022,-9.2073603
212.1008,4.0018935,0.93664223,0.0,0,9.0711908,0.0,0.064123541,47.827641,9.1465206,508.65121,-9.2074966
212.1052,4.0773053,0.99920964,0.0,0,9.0068102,0.0,0.068695508,48.450909,9.0774632,508.80472,-9.2076445
212.1096,4.0791063,1.0697919,0.0,0,8.9424286,0.0,0.073580548,48.201244,9.0093479,508.94937,-9.2066202
212.114,4.0731759,1.1275289,0.0,0,8.8780489,0.0,0.077919096,47.990868,8.9430256,509.09406,-9.2069244
212.1184,4.0580859,1.1931592,0.0,0,8.8136673,0.0,0.082485653,47.624664,8.8850136,509.23871,-9.2072277
212.1228,4.1399894,1.2553177,0.0,0,8.7493448,0.0,0.08717519,48.353535,8.8142176,509.36328,-9.2072506
212.1272,4.1383939,1.3222114,0.0,0,8.6880999,0.0,0.091869898,48.158112,8.7502317,509.35013,-9.2069073
212.1316,4.1325636,1.3810534,0.0,0,8.6268702,0.0,0.096380599,47.803879,8.6875505,509.33701,-9.2066154
212.136,4.1216955,1.4447255,0.0,0,8.5656395,0.0,0.10090019,47.519386,8.628624,509.34644,-9.2060986
212.1404,4.1710439,1.5022912,0.0,0,8.5044088,0.0,0.10533404,47.715084,8.565937,509.35956,-9.2069044
212.1448,4.2224526,1.5672131,0.0,0,8.4431791,0.0,0.10998781,48.143631,8.5061064,509.38824,-9.2055721
212.1492,4.222671,1.6265492,0.0,0,8.3819485,0.0,0.11460002,47.931694,8.4409552,509.4277,-9.2078781
212.1536,4.2185969,1.6926687,0.0,0,8.3207188,0.0,0.11942871,47.708187,8.3774872,509.40775,-9.2079611
212.158,4.2405777,1.7488382,0.0,0,8.2594881,0.0,0.12376061,47.727707,8.3150911,509.26309,-9.2060699
212.1624,4.3014717,1.815264,0.0,0,8.1982584,0.0,0.12876971,48.076839,8.251483,509.08832,-9.2060719
212.1668,4.2695198,1.8718414,0.0,0,8.1370277,0.0,0.13313599,47.625412,8.1887703,508.3913,-9.206645
212.1712,4.2970972,1.9361405,0.0,0,8.0757971,0.0,0.13788545,47.692001,8.1272564,507.69427,-9.2075844
212.1756,4.309679,1.990486,0.0,0,8.0165014,0.0,0.14225553,47.588551,8.0684185,507.00763,-9.2062702
212.18,4.3424196,2.0565152,0.0,0,7.9582458,0.0,0.14729296,47.645588,8.0031672,506.32376,-9.2059011
212.1844,4.3370247,2.1081588,0.0,0,7.8999891,0.0,0.15135907,47.539413,7.9448109,505.91931,-9.2062473
212.1888,4.3289723,2.170059,0.0,0,7.8417335,0.0,0.15613231,47.197346,7.8881855,505.77463,-9.2066946
212.1932,4.3283858,2.2215114,0.0,0,7.7834773,0.0,0.16027556,46.979877,7.8309722,505.44247,-9.2070456
212.1976,4.3955264,2.2818253,0.0,0,7.7252216,0.0,0.16496003,47.344322,7.7726803,504.54788,-9.2060251
212.202,4.4322343,2.3361061,0.0,0,7.666965,0.0,0.16931257,47.678452,7.7130075,503.65329,-9.2063761
212.2064,4.4355917,2.4001119,0.0,0,7.6087093,0.0,0.17443058,47.444496,7.6495099,501.94476,-9.2063675
212.2108,4.4299212,2.4551983,0.0,0,7.5504532,0.0,0.17878495,47.120956,7.591743,500.22116,-9.2058134
212.2152,4.465446,2.5139933,0.0,0,7.4921975,0.0,0.18359992,47.278801,7.5369477,499.31442,-9.2060461
212.2196,4.5181441,2.5698636,0.0,0,7.4339414,0.0,0.18801226,47.630138,7.4791613,498.73547,-9.2066984
212.224,4.510088,2.6321046,0.0,0,7.3765039,0.0,0.19312152,47.479832,7.4195609,498.66058,-9.2060556
212.2284,4.5250273,2.6882441,0.0,0,7.3210988,0.0,0.1976572,47.257061,7.3580022,499.21323,-9.206172
212.2328,4.5242286,2.747076,0.0,0,7.2656941,0.0,0.20243162,47.033749,7.2981615,499.7822,-9.2063427
212.2372,4.5511055,2.8010232,0.0,0,7.210289,0.0,0.20681976,47.085369,7.2414379,500.42694,-9.2055216
212.2416,4.5486779,2.8542724,0.0,0,7.1548843,0.0,0.21132253,46.878971,7.1869068,501.07169,-9.20611
212.246,4.5400267,2.9059393,0.0,0,7.0994792,0.0,0.21559912,46.556179,7.1338897,501.53702,-9.2068501
212.2504,4.5904555,2.9596684,0.0,0,7.044075,0.0,0.22011301,46.862682,7.0817666,501.98438,-9.2061329
212.2548,4.6476159,3.0149002,0.0,0,6.9886694,0.0,0.22467363,47.274712,7.0230885,502.24622,-9.2064447
212.2592,4.6636672,3.0736728,0.0,0,6.9332652,0.0,0.22959146,47.188545,6.9656081,502.40411,-9.2056179
212.2636,4.6304846,3.1274896,0.0,0,6.8778601,0.0,0.23411672,46.669754,6.9099865,502.66013,-9.2063265
212.268,4.6760902,3.1816828,0.0,0,6.8224554,0.0,0.23878603,46.867207,6.8531318,503.08118,-9.2071838
212.2724,4.717473,3.238616,0.0,0,6.7670503,0.0,0.24356291,47.008625,6.7966485,503.45819,-9.2064266
212.2768,4.7457905,3.2929034,0.0,0,6.7141318,0.0,0.24822628,47.093349,6.7411704,503.45819,-9.2060804
212.2812,4.7055902,3.3460307,0.0,0,6.6614199,0.0,0.25280884,46.512505,6.6860714,503.45819,-9.2060986
212.2856,4.7053552,3.3981104,0.0,0,6.6087079,0.0,0.25724998,46.333038,6.6315589,502.44574,-9.2067223
212.29,4.7204871,3.4465704,0.0,0,6.5559959,0.0,0.26142335,46.319603,6.5842986,501.2352,-9.2068033
212.2944,4.7726808,3.4984443,0.0,0,6.503284,0.0,0.26596379,46.597363,6.5328488,499.57608,-9.2058754
212.2988,4.7854519,3.5487089,0.0,0,6.450572,0.0,0.27021575,46.514725,6.4807463,497.57605,-9.2067375
212.3032,4.8004813,3.6016412,0.0,0,6.3978601,0.0,0.27499384,46.388142,6.4278865,495.69443,-9.2066069
212.3076,4.8829451,3.6599276,0.0,0,6.3451481,0.0,0.27995324,46.903084,6.3687582,494.08914,-9.2066031
212.312,4.8821077,3.7094581,0.0,0,6.2924366,0.0,0.28451601,46.7509,6.3128157,492.51608,-9.2055445
212.3164,4.9028916,3.766983,0.0,0,6.2397246,0.0,0.2894786,46.741695,6.2601204,491.92395,-9.206007
212.3208,4.8812623,3.8199351,0.0,0,6.1870127,0.0,0.29420653,46.358189,6.2079172,491.33185,-9.2058229
212.3252,4.9067373,3.8717175,0.0,0,6.1357436,0.0,0.29874295,46.33857,6.159234,491.31247,-9.2072783
212.3296,4.9278054,3.9198191,0.0,0,6.0856099,0.0,0.30314925,46.334427,6.1066823,491.47037,-9.2058983
212.334,4.9443688,3.9737399,0.0,0,6.0354762,0.0,0.30799788,46.311691,6.0557942,491.91513,-9.2059822
212.3384,4.9392972,4.0225067,0.0,0,5.9853425,0.0,0.31238315,46.105942,6.00489,492.65198,-9.2063589
212.3428,4.9544563,4.0736876,0.0,0,5.9352088,0.0,0.31700426,45.875748,5.9536848,493.42773,-9.2061157
212.3472,4.9937735,4.1211534,0.0,0,5.8850756,0.0,0.32120496,46.058594,5.9054985,494.33563,-9.2054501
212.3516,5.0497856,4.1720896,0.0,0,5.8349419,0.0,0.32596967,46.43206,5.8559475,495.24353,-9.204565
212.356,5.0685415,4.2255921,0.0,0,5.7848082,0.0,0.33092695,46.308643,5.7980008,496.13882,-9.2051392
212.3604,5.0517187,4.278945,0.0,0,5.7346745,0.0,0.33584595,45.932564,5.7519035,497.03357,-9.2068815
212.3648,5.0783181,4.3256736,0.0,0,5.6845412,0.0,0.34010944,46.029503,5.6973181,497.93741,-9.2068119
212.3692,5.0639238,4.374826,0.0,0,5.634407,0.0,0.34470716,45.701534,5.651371,498.84534,-9.2060766
212.3736,5.0597544,4.4182596,0.0,0,5.5847516,0.0,0.34885925,45.429939,5.605547,499.70319,-9.206049
212.378,5.1223769,4.4684124,0.0,0,5.5370555,0.0,0.35354808,45.796719,5.5560555,500.49268,-9.2070408
212.3824,5.1970539,4.516685,0.0,0,5.4893594,0.0,0.35812756,46.221485,5.5051951,501.28012,-9.2035408
212.3868,5.2363229,4.5731149,0.0,0,5.4416633,0.0,0.36346084,46.429596,5.4552159,502.05643,-9.2050667
212.3912,5.2021689,4.6211114,0.0,0,5.3939681,0.0,0.36805496,45.849644,5.4030566,502.83276,-9.2067518
212.3956,5.1608834,4.6701345,0.0,0,5.346272,0.0,0.37276748,45.271049,5.3556519,503.53906,-9.2055902
212.4,5.1893849,4.7140131,0.0,0,5.2985759,0.0,0.37700647,45.278965,5.3124018,504.23639,-9.2060184
212.4044,5.2576766,4.7614169,0.0,0,5.2508798,0.0,0.38153172,45.774826,5.2682104,504.85226,-9.2074051
212.4088,5.3011284,4.8079758,0.0,0,5.2031837,0.0,0.38609925,45.914368,5.2197733,505.41785,-9.2058945
212.4132,5.2955618,4.861052,0.0,0,5.155488,0.0,0.39120552,45.583179,5.1665287,505.93277,-9.2048512
212.4176,5.3466377,4.9068055,0.0,0,5.1077919,0.0,0.3957403,45.788883,5.1210809,506.35358,-9.2056694
212.422,5.3751569,4.9582052,0.0,0,5.0600958,0.0,0.40085086,45.819645,5.071084,506.77228,-9.2067575
212.4264,5.3396559,5.0025244,0.0,0,5.0143409,0.0,0.40519974,45.363396,5.0251651,507.16681,-9.2056999
212.4308,5.3608432,5.0503511,0.0,0,4.968977,0.0,0.40997484,45.288898,4.9806809,507.56134,-9.2058554
212.4352,5.3813806,5.093811,0.0,0,4.9236126,0.0,0.41451621,45.228909,4.9348078,507.97726,-9.2053185
212.4396,5.4406962,5.1406298,0.0,0,4.8782492,0.0,0.41898644,45.521275,4.8851414,508.39813,-9.2046347
212.444,5.4408755,5.185617,0.0,0,4.8328848,0.0,0.42375463,45.328224,4.8430929,508.71854,-9.2059059
212.4484,5.4621716,5.2343769,0.0,0,4.7875209,0.0,0.42851463,45.311275,4.7971416,508.95526,-9.2060347
212.4528,5.4830914,5.277504,0.0,0,4.7421565,0.0,0.43323481,45.165245,4.7480001,509.12634,-9.2059565
212.4572,5.4924335,5.3259511,0.0,0,4.6967926,0.0,0.4378581,45.173138,4.7057219,509.12634,-9.2058144
212.4616,5.5136795,5.3659272,0.0,0,4.6514287,0.0,0.44235587,45.095592,4.6604738,509.12274,-9.2058773
212.466,5.5726023,5.4149489,0.0,0,4.6060648,0.0,0.4472281,45.399025,4.6178122,508.72821,-9.2055511
212.4704,5.5632815,5.4599843,0.0,0,4.5607004,0.0,0.45207673,45.05529,4.5718861,508.33368,-9.205492
212.4748,5.6190643,5.5073051,0.0,0,4.5163722,0.0,0.45685604,45.311775,4.5227036,507.3934,-9.2061481
212.4792,5.6444988,5.5477538,0.0,0,4.4732165,0.0,0.46139657,45.323112,4.4775615,506.26233,-9.2060127
212.4836,5.6396799,5.5975232,0.0,0,4.4300613,0.0,0.46653548,45.029427,4.431304,505.36752,-9.2066536
212.488,5.6395311,5.6363535,0.0,0,4.3869061,0.0,0.47087395,44.84026,4.3899703,504.73627,-9.2060804
212.4924,5.658278,5.6809483,0.0,0,4.343751,0.0,0.47541073,44.803288,4.3505559,503.12485,-9.2062807
212.4968,5.7381692,5.7224793,0.0,0,4.3005962,0.0,0.48016128,45.216221,4.3056421,497.70187,-9.2054911
212.5012,5.7578325,5.7707114,0.0,0,4.2574406,0.0,0.48520702,45.136372,4.2629914,492.2789,-9.2055435
212.5056,5.7700486,5.8111653,0.0,0,4.2142854,0.0,0.48968297,44.973408,4.2192287,486.17789,-9.205512
212.51,5.797308,5.858705,0.0,0,4.1711302,0.0,0.49479377,45.02626,4.1737618,480.03079,-9.2062235
212.5144,5.8509846,5.8990407,0.0,0,4.127975,0.0,0.49943218,45.183681,4.1312299,476.8027,-9.2056751
212.5188,5.8592076,5.9455581,0.0,0,4.0848203,0.0,0.50438941,45.077957,4.0882587,475.02423,-9.206398
212.5232,5.8631787,5.9844832,0.0,0,4.0418863,0.0,0.50894862,44.887115,4.0490494,473.83069,-9.2058916
212.5276,5.8876071,6.0315247,0.0,0,4.0008435,0.0,0.51410186,44.846848,4.0013885,473.51462,-9.2067451
212.532,5.8996668,6.0679221,0.0,0,3.9598002,0.0,0.51834857,44.727215,3.9599009,473.49899,-9.2060661
212.5364,5.9330382,6.1131897,0.0,0,3.918757,0.0,0.52331543,44.787384,3.9217362,475.46185,-9.2045794
212.5408,5.96632,6.1485786,0.0,0,3.8777139,0.0,0.52749377,44.835529,3.8796926,477.42471,-9.2054605
212.5452,6.0078416,6.1935778,0.0,0,3.8366706,0.0,0.53257662,44.961742,3.838872,478.26105,-9.2060232
212.5496,6.0336261,6.2293615,0.0,0,3.7956276,0.0,0.53680581,44.871922,3.7962737,478.91949,-9.2059717
212.554,6.0579171,6.2768354,0.0,0,3.7545841,0.0,0.54216993,44.867271,3.758816,480.05627,-9.204874
212.5584,6.1087384,6.3143139,0.0,0,3.713541,0.0,0.54647976,45.04583,3.7137487,481.51804,-9.2054186
212.5628,6.1543417,6.3593521,0.0,0,3.672498,0.0,0.55172753,45.139946,3.6749039,483.47528,-9.2048388
212.5672,6.1826115,6.3971763,0.0,0,3.6314545,0.0,0.5561474,45.095573,3.6285915,486.45102,-9.2061558
212.5716,6.1866894,6.4425731,0.0,0,3.5904114,0.0,0.56156516,44.941227,3.5906029,489.36215,-9.2058506
212.576,6.181488,6.4811273,0.0,0,3.5508497,0.0,0.56610727,44.685352,3.5496807,491.24423,-9.2052383
212.5804,6.1762481,6.5188994,0.0,0,3.5118039,0.0,0.57064253,44.408672,3.5121822,493.12631,-9.2059603
212.5848,6.2378874,6.5562716,0.0,0,3.4727583,0.0,0.57493502,44.721157,3.4719341,494.27954,-9.2057743
212.5892,6.2724676,6.5939074,0.0,0,3.4337125,0.0,0.57954067,44.658916,3.4347458,495.24005,-9.2063475
212.5936,6.3222251,6.6327786,0.0,0,3.3946671,0.0,0.58412749,44.884781,3.396929,495.8223,-9.2049828
212.598,6.3859115,6.6733871,0.0,0,3.3556216,0.0,0.58913529,45.10321,3.3557096,496.05914,-9.2054787
212.6024,6.4636312,6.7166572,0.0,0,3.316576,0.0,0.59439737,45.363152,3.3144734,496.27591,-9.2050953
212.6068,6.4385347,6.7555327,0.0,0,3.27753,0.0,0.59910959,45.0228,3.274852,496.43381,-9.2055283
212.6112,6.4514251,6.7928061,0.0,0,3.2384844,0.0,0.60366142,44.955284,3.2350757,496.59171,-9.2047777
212.6156,6.4412122,6.8314857,0.0,0,3.199439,0.0,0.60854197,44.665291,3.1976473,494.77661,-9.2060757
212.62,6.5355153,6.8686919,0.0,0,3.1603935,0.0,0.61290962,45.024014,3.1618338,492.9342,-9.2060757
212.6244,6.6373539,6.9107914,0.0,0,3.122066,0.0,0.61807829,45.5112,3.1201348,490.81763,-9.2044649
212.6288,6.6678357,6.9492927,0.0,0,3.0849211,0.0,0.62288606,45.560116,3.0834117,488.59348,-9.2055635
212.6332,6.6554556,6.9915309,0.0,0,3.0477762,0.0,0.62811279,45.228188,3.0393794,487.64267,-9.2063189
212.6376,6.6382389,7.0252647,0.0,0,3.0106313,0.0,0.63241047,44.908443,3.0017934,488.24817,-9.2055302
212.642,6.6347899,7.0640168,0.0,0,2.9734867,0.0,0.63735592,44.673534,2.9684451,488.99008,-9.206624
212.6464,6.6644254,7.0968013,0.0,0,2.9363418,0.0,0.6413976,44.727104,2.9325495,490.34586,-9.205349
212.6508,6.7331519,7.1315551,0.0,0,2.8991969,0.0,0.64573085,44.929344,2.9003835,491.7016,-9.2052231
212.6552,6.7851229,7.1694121,0.0,0,2.8620524,0.0,0.65058041,45.082726,2.8609126,492.87659,-9.205472
212.6596,6.9009118,7.2068706,0.0,0,2.8249075,0.0,0.65538442,45.61166,2.8212934,494.03448,-9.2044802
212.664,6.9555254,7.2457457,0.0,0,2.7877626,0.0,0.66029501,45.767395,2.7848086,495.49814,-9.2048082
212.6684,6.9583664,7.2866907,0.0,0,2.7506177,0.0,0.66565943,45.524624,2.7461803,497.12976,-9.205493
212.6728,6.9663029,7.3235083,0.0,0,2.7135069,0.0,0.67032403,45.367931,2.7119277,498.59256,-9.2058296
212.6772,7.0321984,7.3591566,0.0,0,2.6781669,0.0,0.67500091,45.529095,2.6741459,499.77679,-9.2053108
212.6816,7.0567126,7.395597,0.0,0,2.6428349,0.0,0.67952782,45.535091,2.6371679,500.01584,-9.2045259
212.686,7.0807004,7.4311595,0.0,0,2.6075029,0.0,0.68444711,45.491447,2.6025808,492.53604,-9.2051239
212.6904,7.1098104,7.4685717,0.0,0,2.572171,0.0,0.68925029,45.451385,2.5685492,485.05624,-9.2058849
212.6948,7.1855793,7.5013962,0.0,0,2.5368388,0.0,0.69350809,45.686317,2.5308263,477.45483,-9.2061224
212.6992,7.2470365,7.5417056,0.0,0,2.5015068,0.0,0.69883043,45.876427,2.4986503,469.83041,-9.2060766
212.7036,7.2809043,7.5740457,0.0,0,2.4661748,0.0,0.70317942,45.931252,2.4571888,467.77304,-9.2047338
212.708,7.2970619,7.6110983,0.0,0,2.4308426,0.0,0.70822453,45.720383,2.4239616,469.86871,-9.2064638
212.7124,7.3049335,7.647408,0.0,0,2.3955109,0.0,0.71291649,45.671864,2.3890264,472.32535,-9.2046986
212.7168,7.3576655,7.681181,0.0,0,2.3601789,0.0,0.71747011,45.697571,2.3559198,475.60617,-9.2057886
212.7212,7.413022,7.7151632,0.0,0,2.3248467,0.0,0.72211277,45.870876,2.3217382,478.86493,-9.2059107
212.7256,7.4750099,7.7518735,0.0,0,2.2906368,0.0,0.72700381,46.018547,2.28632,481.53824,-9.2060537
212.73,7.4994969,7.7862926,0.0,0,2.2570295,0.0,0.73179656,45.946003,2.2540925,484.21152,-9.2074938
212.7344,7.572258,7.8207769,0.0,0,2.2234225,0.0,0.73639482,46.12524,2.2155941,486.34848,-9.2067833
212.7388,7.624783,7.8534393,0.0,0,2.1898153,0.0,0.7410655,46.296135,2.183898,488.32361,-9.205864
212.7432,7.6449313,7.8910828,0.0,0,2.156208,0.0,0.74628025,46.121937,2.1474395,489.02405,-9.2058001
212.7476,7.7109447,7.9226537,0.0,0,2.1226008,0.0,0.7506603,46.305756,2.1173513,488.44989,-9.2069263
212.752,7.7696128,7.9600286,0.0,0,2.0889935,0.0,0.75580072,46.423527,2.0821884,487.10153,-9.2060547
212.7564,7.8201857,7.9904723,0.0,0,2.0553865,0.0,0.76024002,46.593014,2.0495608,481.66101,-9.2056923
212.7608,7.8578506,8.0299664,0.0,0,2.0217793,0.0,0.76557332,46.510468,2.0156093,476.22049,-9.2066078
212.7652,7.8730474,8.0609655,0.0,0,1.9881722,0.0,0.77004969,46.351765,1.9825603,472.2233,-9.2060814
212.7696,7.9366379,8.0926828,0.0,0,1.954565,0.0,0.77467144,46.584892,1.9535002,468.40286,-9.205266
212.774,8.0452394,8.1275034,0.0,0,1.9214275,0.0,0.77976012,47.005955,1.9208467,468.20099,-9.2059259
212.7784,8.1137094,8.165514,0.0,0,1.889457,0.0,0.78509754,47.143162,1.8856755,470.19147,-9.2045746
212.7828,8.1317844,8.199338,0.0,0,1.8574866,0.0,0.79036021,46.954865,1.8476334,472.38251,-9.2046404
212.7872,8.1230793,8.2332687,0.0,0,1.8255162,0.0,0.79499459,46.759991,1.8144542,474.93872,-9.2060347
212.7916,8.1309538,8.261982,0.0,0,1.7935458,0.0,0.79952604,46.499161,1.7855334,477.42773,-9.2058611
212.796,8.2103672,8.2932339,0.0,0,1.7615755,0.0,0.803918,46.763115,1.75576,479.20557,-9.2065401
212.8004,8.2355003,8.3223124,0.0,0,1.729605,0.0,0.80842406,46.729679,1.7219493,480.9834,-9.2061567
212.8048,8.3440571,8.3549566,0.0,0,1.6976346,0.0,0.81294334,47.062328,1.6925068,482.41641,-9.2064495
212.8092,8.4448547,8.3844299,0.0,0,1.6656642,0.0,0.8179186,47.447044,1.6619378,483.77283,-9.2053585
212.8136,8.52845,8.420476,0.0,0,1.6336937,0.0,0.82309699,47.708588,1.6287366,484.67291,-9.2043715
212.818,8.5535831,8.45158,0.0,0,1.6017234,0.0,0.8280769,47.573055,1.592558,485.19968,-9.2066231
212.8224,8.5910063,8.4871511,0.0,0,1.5697531,0.0,0.83312649,47.542622,1.5627381,485.60028,-9.2052813
212.8268,8.6551294,8.5131664,0.0,0,1.5392207,0.0,0.83762896,47.64138,1.5329182,485.67926,-9.2045174
212.8312,8.6978312,8.5489159,0.0,0,1.5088079,0.0,0.84279275,47.712509,1.5014182,485.76294,-9.2059393
212.8356,8.68857,8.5741224,0.0,0,1.478395,0.0,0.8469674,47.481636,1.4742314,486.18439,-9.2061014
212.84,8.8138285,8.6063366,0.0,0,1.4479822,0.0,0.85182172,47.882252,1.4437879,486.6058,-9.2060623
212.8444,8.959712,8.6398735,0.0,0,1.4175695,0.0,0.85735184,48.396431,1.4127905,487.25299,-9.2060232
212.8488,9.0526228,8.6725063,0.0,0,1.3871567,0.0,0.86236334,48.6394,1.3774074,487.97723,-9.2049799
212.8532,9.0401154,8.7005701,0.0,0,1.3567439,0.0,0.86717886,48.393913,1.348551,489.12845,-9.2047529
212.8576,9.0500507,8.7357292,0.0,0,1.3263311,0.0,0.87264073,48.095978,1.3146592,490.74725,-9.206028
212.862,9.0974312,8.7622414,0.0,0,1.2959183,0.0,0.87714505,48.175846,1.2851299,492.40726,-9.2043438
212.8664,9.1618538,8.7918501,0.0,0,1.2655054,0.0,0.88169432,48.311314,1.2569901,494.22305,-9.2051563
212.8708,9.2566357,8.8163366,0.0,0,1.2350928,0.0,0.88587296,48.622169,1.2294766,496.03888,-9.2060652
212.8752,9.3646193,8.8520079,0.0,0,1.2055123,0.0,0.89159554,48.895897,1.1962111,497.16138,-9.2049961
212.8796,9.4494123,8.8772774,0.0,0,1.1765865,0.0,0.8959946,49.089161,1.1635597,498.24036,-9.2048101
212.884,9.4901075,8.9120684,0.0,0,1.1476611,0.0,0.90163291,49.044403,1.1356643,499.04492,-9.2057972
212.8884,9.489789,8.9363222,0.0,0,1.1187353,0.0,0.90601194,48.814297,1.1065633,499.71597,-9.2053509
212.8928,9.5139112,8.9693785,0.0,0,1.0898098,0.0,0.91129738,48.702709,1.0817566,500.3764,-9.2054777
212.8972,9.6274261,8.9898472,0.0,0,1.0608841,0.0,0.91466135,49.081261,1.0501345,501.02115,-9.2049723
212.9016,9.7217112,9.0221062,0.0,0,1.0319586,0.0,0.9204874,49.268753,1.0253843,501.59412,-9.2049122
212.906,9.7778282,9.047884,0.0,0,1.0030329,0.0,0.92466563,49.398834,0.99419272,501.71252,-9.2058868
212.9104,9.8243103,9.0780945,0.0,0,0.97410738,0.0,0.92989385,49.357941,0.96592021,501.83096,-9.2053652
212.9148,9.8996668,9.1019192,0.0,0,0.94518173,0.0,0.93380952,49.522648,0.94002897,501.53812,-9.2053461
212.9192,10.057832,9.1327591,0.0,0,0.91625619,0.0,0.93937093,50.065105,0.90965682,501.18286,-9.2047253
212.9236,10.142325,9.1572323,0.0,0,0.88760823,0.0,0.94358897,50.275036,0.88406849,501.35657,-9.2059526
212.928,10.219958,9.1887474,0.0,0,0.86009943,0.0,0.94904029,50.369862,0.85523629,501.88287,-9.2039757
212.9324,10.280738,9.215745,0.0,0,0.83259064,0.0,0.95365572,50.460487,0.82558417,500.03705,-9.2050781
212.9368,10.411847,9.2481394,0.0,0,0.80508184,0.0,0.95937318,50.758495,0.79538894,493.4144,-9.2060585
212.9412,10.480177,9.2718382,0.0,0,0.77757305,0.0,0.96354717,50.939034,0.76905978,486.86804,-9.206048
212.9456,10.461708,9.3019438,0.0,0,0.75006425,0.0,0.96890867,50.557327,0.74075258,481.44504,-9.2051497
212.95,10.515011,9.3264894,0.0,0,0.72255546,0.0,0.97329658,50.582916,0.71261454,476.02203,-9.2052507
212.9544,10.665324,9.35287,0.0,0,0.6950466,0.0,0.97793424,51.034222,0.68838912,477.09222,-9.2053165
212.9588,10.777574,9.3809242,0.0,0,0.66753787,0.0,0.9828704,51.335182,0.65774596,479.83215,-9.2059746
212.9632,10.797056,9.4066362,0.0,0,0.64002901,0.0,0.98755699,51.20314,0.63284445,481.91202,-9.2053032
212.9676,10.875938,9.4340639,0.0,0,0.61252022,0.0,0.99233192,51.318134,0.60333622,483.40012,-9.2057848
212.972,10.992937,9.4596863,0.0,0,0.58501148,0.0,0.99709415,51.609154,0.57973683,484.44809,-9.2052603
212.9764,11.061107,9.4875174,0.0,0,0.55860865,0.0,1.0019767,51.75058,0.54950958,484.2374,-9.2051086
212.9808,9.9444199,9.4936781,0.0,0,0.53242874,0.0,1.0031689,46.494644,0.53411096,484.0267,-9.2075691
212.9852,9.3964672,9.4989777,0.0,0,0.50624865,0.0,1.0040872,43.818195,0.51672804,484.11612,-9.2074089
212.9896,9.1138668,9.5041714,0.0,0,0.48006868,0.0,1.0050935,42.482929,0.49958271,484.20828,-9.2065983
212.994,8.9161921,9.5071335,0.0,0,0.45388871,0.0,1.005728,41.535473,0.48276272,485.51859,-9.2067404
212.9984,8.6149769,9.5106211,0.0,0,0.42770869,0.0,1.0063287,40.12122,0.4603875,487.2962,-9.2081146
213.0028,8.3322783,9.5167093,0.0,0,0.40152869,0.0,1.0072192,38.794777,0.44127363,489.0137,-9.2064705
213.0072,8.0068827,9.5141582,0.0,0,0.37534866,0.0,1.0069278,37.259987,0.42824125,490.65903,-9.2056227
213.0116,7.7110767,9.5179262,0.0,0,0.34916869,0.0,1.0074768,35.864567,0.42437786,492.189,-9.2077017
213.016,7.5131269,9.5168486,0.0,0,0.32298869,0.0,1.0070752,34.925499,0.4145655,493.21533,-9.2075253
213.0204,7.4671116,9.520175,0.0,0,0.29680869,0.0,1.0075146,34.723148,0.40400928,494.24164,-9.2074919
213.0248,7.603148,9.5230207,0.0,0,0.27123094,0.0,1.0079168,35.308018,0.38005158,494.68808,-9.2075634
213.0292,7.8909106,9.525568,0.0,0,0.24633573,0.0,1.0084342,36.614941,0.33962464,495.08286,-9.2074413
213.0336,8.0931911,9.5299587,0.0,0,0.22144051,0.0,1.0091742,37.532547,0.30649731,495.35785,-9.2059307
213.038,8.1771088,9.5333099,0.0,0,0.19654538,0.0,1.009794,37.954414,0.2761364,495.56836,-9.2058344
213.0424,8.1955442,9.5331507,0.0,0,0.17165017,0.0,1.0096349,38.01619,0.24452414,495.83414,-9.2070608
213.0468,8.1744537,9.5368013,0.0,0,0.14675498,0.0,1.0102172,37.896263,0.21948299,496.18942,-9.2063465
213.0512,8.1590996,9.5412779,0.0,0,0.12185977,0.0,1.0109158,37.807034,0.19698371,496.53723,-9.2061319
213.0556,8.1140509,9.5435524,0.0,0,0.096964568,0.0,1.0112798,37.581135,0.16825135,496.82669,-9.2059183
213.06,8.033247,9.5432272,0.0,0,0.072069369,0.0,1.0110663,37.26622,0.14834563,497.11618,-9.2067137
213.0644,7.9756069,9.5489082,0.0,0,0.047174159,0.0,1.0120779,36.924042,0.12459432,497.35004,-9.2059593
213.0688,7.9362617,9.5485239,0.0,0,0.022278961,0.0,1.0119848,36.736076,0.1059145,497.57373,-9.2060194
213.0732,7.8852434,9.5530796,0.0,0,-0.002552425,0.0,1.0125581,36.49493,0.086206384,497.82019,-9.2067928
213.0776,7.8199439,9.5537319,0.0,0,-0.02684043,0.0,1.012794,36.179329,0.066210195,498.08334,-9.2065964
213.082,7.7515364,9.5571575,0.0,0,-0.051128428,0.0,1.0132145,35.830963,0.050488215,498.30585,-9.2060232
213.0864,7.6915421,9.557045,0.0,0,-0.075416431,0.0,1.0131624,35.533787,0.037598666,498.43744,-9.2053022
213.0908,7.6121449,9.5626526,0.0,0,-0.09970443,0.0,1.0139266,35.157467,0.022660144,498.57224,-9.206563
213.0952,7.5002522,9.5620089,0.0,0,0.31743845,500.0,1.0138975,34.672379,0.013321148,498.78278,-9.2061453
213.0996,7.1232643,9.5624981,0.0,0,1.1142955,500.0,1.0139602,32.947235,0.017443556,498.99329,-9.2061319
213.104,4.3053308,9.5467358,0.0,0,1.9111538,500.0,1.0111096,20.077129,0.18533538,499.28516,-9.2078409
213.1084,0.38456368,9.5218201,0.0,0,2.7080109,500.0,1.0064074,2.0477815,0.50037557,499.60098,-9.2111912
213.1128,-0.20551117,9.52421,0.0,0,3.504869,500.0,1.0070248,-1.0106645,1.5777979,499.91013,-9.2121611
213.1172,0.0018242148,9.5139914,0.0,0,4.3017259,500.0,1.0046217,0.058337662,2.8445444,500.21277,-9.2110996
213.1216,0.049774811,9.5064049,0.0,0,5.0985842,500.0,1.0034649,0.22939387,3.6760767,500.50604,-9.2118692
213.126,0.002755824,9.5101433,0.0,0,5.8954415,500.0,1.0040126,0.043377586,4.4368286,500.76923,-9.2118034
213.1304,0.011853176,9.5072975,0.0,0,6.6922989,500.0,1.0038239,0.037126899,5.1918621,501.03241,-9.210638
213.1348,0.082648605,9.5089912,0.0,0,7.4891567,500.0,1.0037286,0.30454341,5.9763618,501.20639,-9.2083044
213.1392,-0.015864287,9.5080957,0.0,0,8.2860146,500.0,1.0038593,-0.047404133,6.7989459,501.37744,-9.2090797
213.1436,0.037210301,9.5099049,0.0,0,9.0828733,500.0,1.0038345,0.11795612,7.6358485,501.57611,-9.2086535
213.148,-0.052638274,9.5036345,0.0,0,9.8797302,500.0,1.0030249,-0.26050338,8.4609528,501.78662,-9.2087069
213.1524,0.019191898,9.5073957,0.0,0,10.676588,500.0,1.0033617,0.072379142,9.2729683,501.99149,-9.2074986
213.1568,0.026620423,9.5029583,0.0,0,11.473446,500.0,1.003059,0.096225135,10.089114,502.18887,-9.2062912
213.1612,-0.0095820408,9.5101595,0.0,0,12.270304,500.0,1.0037917,-0.033687234,10.895389,502.37979,-9.2073393
213.1656,-0.069076739,9.5044403,0.0,0,13.067161,500.0,1.0031956,-0.27210888,11.689334,502.53769,-9.207592
213.17,-0.07182432,9.5084476,0.0,0,13.864018,500.0,1.0035721,-0.28808954,12.458581,502.69559,-9.2075024
213.1744,-0.0079909042,9.4999266,0.0,0,14.660877,500.0,1.0024465,0.027983531,13.231298,502.86526,-9.2071571
213.1788,0.01505538,9.5070572,0.0,0,15.457734,500.0,1.0035808,0.081538096,14.021314,503.03632,-9.2062626
213.1832,0.013793049,9.5030508,0.0,0,16.254593,500.0,1.0032737,0.072735503,14.83221,503.22388,-9.2061367
213.1876,-0.036617741,9.5065804,0.0,0,17.051451,500.0,1.0037664,-0.19877684,15.643348,503.42123,-9.2059698
213.192,0.012128874,9.5049286,0.0,0,17.848307,500.0,1.0037519,0.031007543,16.44718,503.62332,-9.2060757
213.1964,-0.024891989,9.5084677,0.0,0,18.0,500.0,1.0040292,-0.13356863,17.25174,503.83386,-9.2061052
213.2008,-0.013190104,9.5036821,0.0,0,18.0,500.0,1.0034913,-0.017565379,17.954727,504.03485,-9.2071218
213.2052,0.047515932,9.513566,0.0,0,18.0,500.0,1.0050235,0.22330904,18.407551,504.14011,-9.213459
213.2096,0.080617301,9.5206108,0.0,0,18.0,500.0,1.0067455,0.39360321,18.46361,504.24536,-9.2223873
213.214,0.6896764,9.5384674,0.0,0,18.0,500.0,1.0098836,3.2622306,18.245077,504.37225,-9.2420349
213.2184,0.55164391,9.5391512,0.0,0,18.0,500.0,1.0103582,2.5490165,18.073965,504.50381,-9.2740374
213.2228,0.49361748,9.5417728,0.0,0,18.0,500.0,1.0106924,2.3006182,18.045794,504.62805,-9.3127823
213.2272,0.49436176,9.534647,0.0,0,18.0,500.0,1.0096045,2.2801218,18.077944,504.74646,-9.3512669
213.2316,0.50104535,9.5361423,0.0,0,18.0,500.0,1.009946,2.3301506,18.125216,504.83847,-9.3871956
213.236,0.53493106,9.5330534,0.0,0,18.0,500.0,1.009535,2.4943802,18.143923,504.86475,-9.4200735
213.2404,0.49657869,9.538208,0.0,0,18.0,500.0,1.0105535,2.3064113,18.142567,504.89249,-9.4527035
213.2448,0.49639949,9.5309963,0.0,0,18.0,500.0,1.0093105,2.2953429,18.143795,504.99768,-9.4863396
213.2492,0.51824319,9.5374575,0.0,0,18.0,500.0,1.0105653,2.4089913,18.138781,505.10291,-9.5181141
213.2536,0.53308034,9.5319366,0.0,0,18.0,500.0,1.0095036,2.4675958,18.130085,505.2081,-9.5514832
213.258,0.51463121,9.5359116,0.0,0,18.0,500.0,1.010478,2.3866196,18.124289,505.31332,-9.5853195
213.2624,0.51156688,9.534977,0.0,0,18.0,500.0,1.0101935,2.3878193,18.122896,505.39319,-9.6185045
213.2668,0.52029806,9.5357008,0.0,0,18.0,500.0,1.0105895,2.3931692,18.12122,505.44577,-9.6516781
213.2712,0.54890281,9.5309658,0.0,0,18.0,500.0,1.0095912,2.549979,18.111172,505.49557,-9.685111
213.2756,0.53743398,9.5366106,0.0,0,18.0,500.0,1.0108095,2.4797556,18.110146,505.53503,-9.7195702
213.28,0.49990344,9.5326281,0.0,0,18.0,500.0,1.0102779,2.2790475,18.107588,505.57449,-9.7516375
213.2844,0.51203704,9.5321245,0.0,0,18.0,500.0,1.0102038,2.3795488,18.104294,505.61395,-9.7847147
213.2888,0.53947681,9.5308971,0.0,0,18.0,500.0,1.0098962,2.4877522,18.105129,505.65341,-9.8183336
213.2932,0.51758003,9.5323792,0.0,0,18.0,500.0,1.0103699,2.4388998,18.108635,505.67505,-9.8528376
213.2976,0.50533152,9.5320301,0.0,0,18.0,500.0,1.0102623,2.3203154,18.106897,505.6882,-9.8867598
213.302,0.51738757,9.5313339,0.0,0,18.0,500.0,1.0101753,2.3611419,18.10173,505.70673,-9.9185152
213.3064,0.54110497,9.5315189,0.0,0,18.0,500.0,1.0101448,2.4995763,18.098602,505.73303,-9.9497976
213.3108,0.53659874,9.5328417,0.0,0,18.0,500.0,1.010571,2.5061524,18.097624,505.76489,-9.9851274
213.3152,0.50717592,9.5328341,0.0,0,18.0,500.0,1.0104564,2.3781557,18.094023,505.83063,-10.019205
213.3196,0.52536243,9.5343914,0.0,0,18.0,500.0,1.0108153,2.4452333,18.091888,505.89639,-10.053963
213.324,0.54396176,9.5301838,0.0,0,18.0,500.0,1.0098693,2.5052063,18.092861,505.80145,-10.085173
213.3284,0.5603928,9.5316448,0.0,0,18.0,500.0,1.0104514,2.5694158,18.096189,505.68311,-10.117723
213.3328,0.53468937,9.5328665,0.0,0,18.0,500.0,1.0102841,2.4800475,18.089319,505.53293,-10.153056
213.3372,0.53479862,9.5325804,0.0,0,18.0,500.0,1.0104586,2.4740117,18.090199,505.362,-10.186355
213.3416,0.54496866,9.5311804,0.0,0,18.0,500.0,1.0099723,2.516923,18.089798,505.22641,-10.217143
213.346,0.56387538,9.5321398,0.0,0,18.0,500.0,1.0101805,2.5919104,18.086473,505.16064,-10.254304
213.3504,0.53283662,9.5338211,0.0,0,18.0,500.0,1.0103003,2.491554,18.08835,505.09399,-10.287035
213.3548,0.54459566,9.5324545,0.0,0,18.0,500.0,1.0102466,2.5177035,18.083376,505.01508,-10.31965
213.3592,0.54278064,9.5324535,0.0,0,18.0,500.0,1.0099618,2.5105562,18.082273,504.93619,-10.352652
213.3636,0.56740141,9.5324469,0.0,0,18.0,500.0,1.0098966,2.6546865,18.077799,504.88885,-10.386512
213.368,0.54705721,9.534029,0.0,0,18.0,500.0,1.0100571,2.5166087,18.077444,504.8494,-10.421562
213.3724,0.53580004,9.5332546,0.0,0,18.0,500.0,1.0098546,2.4464533,18.07514,504.85892,-10.453611
213.3768,0.54799581,9.5345001,0.0,0,18.0,500.0,1.0100169,2.5262337,18.07564,504.9115,-10.485372
213.3812,0.57251215,9.5331049,0.0,0,18.0,500.0,1.0097106,2.6586001,18.074337,504.9537,-10.517296
213.3856,0.55725247,9.5339727,0.0,0,18.0,500.0,1.0098454,2.6071689,18.073566,504.96683,-10.552429
213.39,0.53444785,9.5330944,0.0,0,18.0,500.0,1.009383,2.480624,18.071085,504.97998,-10.584896
213.3944,0.54131776,9.5357742,0.0,0,18.0,500.0,1.010101,2.5498531,18.07136,504.90149,-10.620481
213.3988,0.56968379,9.5346956,0.0,0,18.0,500.0,1.009506,2.6848991,18.067961,504.8226,-10.653154
213.4032,0.57416219,9.5352831,0.0,0,18.0,500.0,1.0095762,2.6800582,18.070055,504.75327,-10.686131
213.4076,0.54780549,9.5351295,0.0,0,18.0,500.0,1.0096315,2.5312853,18.067797,504.6875,-10.719605
213.412,0.54540306,9.5385742,0.0,0,18.0,500.0,1.0101458,2.5320318,18.067003,504.63986,-10.752033
213.4164,0.57675958,9.5333967,0.0,0,18.0,500.0,1.009151,2.6840949,18.061941,504.61356,-10.785071
213.4208,0.57650942,9.5401316,0.0,0,18.0,500.0,1.0101779,2.6786897,18.062769,504.58978,-10.818714
213.4252,0.54116017,9.538949,0.0,0,18.0,500.0,1.0098329,2.5049868,18.06633,504.57663,-10.852999
213.4296,0.54318827,9.5355139,0.0,0,18.0,500.0,1.0090926,2.5416133,18.065357,504.56345,-10.887559
213.434,0.56875551,9.5375776,0.0,0,18.0,500.0,1.0095117,2.6304018,18.063793,504.57458,-10.918938
213.4384,0.57456088,9.5402164,0.0,0,18.0,500.0,1.0097539,2.6811361,18.058643,504.58774,-10.952544
213.4428,0.5547387,9.5386543,0.0,0,18.0,500.0,1.0095899,2.6057515,18.061983,504.58368,-10.987684
213.4472,0.54592472,9.5418882,0.0,0,18.0,500.0,1.0100942,2.4920442,18.061646,504.57053,-11.021799
213.4516,0.56092381,9.5348129,0.0,0,18.0,500.0,1.0087301,2.5902307,18.063847,504.55737,-11.053975
213.456,0.58132476,9.5413504,0.0,0,18.0,500.0,1.0099678,2.7241695,18.055557,504.54422,-11.087021
213.4604,0.56215769,9.5396338,0.0,0,18.0,500.0,1.0095333,2.644135,18.062359,504.53262,-11.11874
213.4648,0.54860717,9.5420341,0.0,0,18.0,500.0,1.0100381,2.5541213,18.058861,504.53262,-11.152501
213.4692,0.5638752,9.5399427,0.0,0,18.0,500.0,1.0095458,2.5878327,18.055593,504.53262,-11.187921
213.4736,0.58896416,9.544014,0.0,0,18.0,500.0,1.0100462,2.7102516,18.053886,504.49905,-11.221696
213.478,0.57155752,9.5407419,0.0,0,18.0,500.0,1.0096015,2.674036,18.054401,504.45959,-11.25445
213.4824,0.55961782,9.5442448,0.0,0,18.0,500.0,1.0101036,2.5958867,18.053808,504.42776,-11.286112
213.4868,0.55439121,9.5404253,0.0,0,18.0,500.0,1.0098124,2.5503502,18.048471,504.40146,-11.320616
213.4912,0.58306366,9.5452995,0.0,0,18.0,500.0,1.0101547,2.7281768,18.050104,504.37927,-11.352663
214.8927,0.514965,9.551177,0.0,0,18.0,4.0912095e-17,1.0126277,2.3821123,17.999767,475.60828,-11.481215
217.0927,0.5456323,9.5669985,0.0,0,18.0,1.4012985e-45,1.0155951,2.5143249,17.999477,453.00992,-11.482297
219.2927,0.56572133,9.5808134,0.0,0,18.0,1.4012985e-45,1.0180968,2.6047554,17.999838,433.07104,-11.482435
221.4927,0.57808483,9.5926781,0.0,0,18.0,1.4012985e-45,1.0202034,2.6506186,17.999645,413.6254,-11.482148
223.6927,0.59249163,9.6043167,0.0,0,18.0,1.4012985e-45,1.0224941,2.7119391,18.000805,395.68204,-11.482357
225.8927,0.61172932,9.6156769,0.0,0,18.0,1.4012985e-45,1.0245919,2.7977793,18.00053,378.35812,-11.482369
228.0927,0.62281281,9.6273518,0.0,0,18.0,1.4012985e-45,1.0267397,2.8371913,17.999937,360.57303,-11.482028
230.2927,0.63428891,9.6378794,0.0,0,18.0,1.4012985e-45,1.0287175,2.886956,18.000517,344.65558,-11.482295
232.4927,0.64915442,9.6487741,0.0,0,18.0,1.4012985e-45,1.0306308,2.9476278,18.000427,328.99585,-11.481999
234.6927,0.66106951,9.6581144,0.0,0,18.0,1.4012985e-45,1.0324979,2.9938779,18.0002,314.51236,-11.482461
236.8927,0.6692251,9.6678782,0.0,0,18.0,1.4012985e-45,1.0343765,3.0309255,18.000019,300.75269,-11.482507
239.0927,0.68397224,9.676795,0.0,0,18.0,1.4012985e-45,1.0359617,3.092346,17.999689,288.31464,-11.482233
241.2927,0.68922156,9.6862011,0.0,0,18.0,1.4012985e-45,1.0378143,3.1066787,17.999231,275.48538,-11.481801
243.4927,0.69742852,9.6944199,0.0,0,18.0,1.4012985e-45,1.0392603,3.1447668,17.999929,263.68033,-11.482142
245.6927,0.71217084,9.7028322,0.0,0,18.0,1.4012985e-45,1.0407856,3.2002311,17.999716,252.57561,-11.482032
247.8927,0.71621454,9.7102814,0.0,0,18.0,1.4012985e-45,1.0422827,3.2133875,17.999861,241.78088,-11.482521
250.0927,0.72360146,9.7176018,0.0,0,18.0,1.4012985e-45,1.0437293,3.2468688,17.999813,231.62601,-11.482436
252.2927,0.73970443,9.7252645,0.0,0,18.0,1.4012985e-45,1.0451143,3.316637,17.99992,221.97885,-11.48198
254.4927,0.74358147,9.7320728,0.0,0,18.0,1.4012985e-45,1.0464057,3.3181736,17.999727,212.95464,-11.481681
256.6927,0.74638724,9.7385616,0.0,0,18.0,1.4012985e-45,1.0477033,3.3359511,17.999855,204.1185,-11.481136
258.8927,0.76004207,9.7449064,0.0,0,18.0,1.4012985e-45,1.0488067,3.3935854,17.999439,195.80719,-11.481652
261.0927,0.77046859,9.7511568,0.0,0,18.0,1.4012985e-45,1.049933,3.4282885,17.999735,187.91368,-11.481812
263.2927,0.7722348,9.7572908,0.0,0,18.0,1.4012985e-45,1.0512202,3.4383907,18.000631,180.3008,-11.481924
265.4927,0.78329659,9.7623672,0.0,0,18.0,1.4012985e-45,1.0522768,3.4821851,17.999521,172.95502,-11.48194
267.6927,0.78717512,9.7681131,0.0,0,18.0,1.4012985e-45,1.0532558,3.482372,17.998989,165.83554,-11.482053
269.8927,0.78972948,9.7736759,0.0,0,18.0,1.4012985e-45,1.0543498,3.5008762,17.999615,159.19543,-11.481879
272.0927,0.8051213,9.7784958,0.0,0,18.0,1.4012985e-45,1.055323,3.5709786,18.000076,152.99475,-11.482487
273.4927,0.79885572,9.7821093,0.0,0,18.0,1.4012985e-45,1.0558921,3.5359018,18.0005,149.0448,-11.546988