File: examples/dan-msc-case-studies/CS3/data/01 raw data/baron_test_067.csv
Time(sec),Force(kN),Jaw(mm),PowAngle(deg),Power(W),Pram,PTemp,Strain,Stress(MPa),Stroke(mm),TC1(C),wedge(mm)
0.0,0.9089756,0.53340834,0.0,0,10.594783,0.00097944913,0.036211539,11.164934,10.595138,24.592331,-9.119009
2.1,0.82687992,-0.00033119318,0.0,0,10.594783,6.2159019,-1.6277279e-05,10.539949,10.595588,24.586735,-9.4849291
4.2,0.79573071,-0.00035063474,0.0,0,10.594783,12.515902,-2.7552627e-05,10.143624,10.59495,24.548126,-9.4821787
6.3,0.7706461,-0.00022204439,0.0,0,10.594783,18.815903,-3.0120855e-05,9.814785,10.595016,24.539059,-9.4788313
8.4,0.74918574,-0.00053895439,0.0,0,10.594783,25.115906,-3.9074224e-05,9.5451584,10.595567,24.525301,-9.4745789
10.5,0.76254213,-0.00066588394,30.73513,0,10.594783,31.415909,-1.7902363e-05,9.7155886,10.593946,26.170921,-9.471364
12.6,0.76876497,-0.0057037412,35.495644,0,10.594783,37.715904,-0.00040888705,9.782033,10.594326,33.970474,-9.468257
14.7,0.77357084,-0.010424593,35.496826,0,10.594783,44.015903,-0.00068033329,9.8535795,10.595167,42.266224,-9.4646416
16.8,0.77457941,-0.015628465,36.140007,0,10.594783,50.315914,-0.0010233144,9.8757229,10.59495,49.276997,-9.4609337
18.9,0.78235662,-0.019066449,37.451897,0,10.594783,56.615925,-0.0012700702,9.9830761,10.594385,55.498646,-9.4574871
21.0,0.78588653,-0.023628555,38.549168,0,10.594783,62.915924,-0.0015928091,10.02679,10.594799,61.998756,-9.4536467
23.1,0.79361194,-0.028501458,39.24316,0,10.594783,69.215927,-0.0018979937,10.127991,10.594201,68.411621,-9.4502153
25.2,0.8033458,-0.034212429,39.924294,0,10.594783,75.51593,-0.0022616647,10.248417,10.594457,74.929077,-9.4467764
27.3,0.79562849,-0.037552644,40.062805,0,10.594783,81.815918,-0.0025176597,10.148096,10.594718,81.308052,-9.442956
29.4,0.80364442,-0.042814791,41.198727,0,10.594783,88.115921,-0.0028346605,10.267777,10.594219,87.324158,-9.4395571
31.5,0.81304663,-0.048057888,41.48613,0,10.594783,94.415939,-0.0031894518,10.387932,10.587861,93.983536,-9.4357338
33.6,0.82735747,-0.053170498,41.802975,0,10.594783,100.71593,-0.0035424423,10.5797,10.594868,100.39114,-9.432025
35.7,0.83637607,-0.057681598,41.801914,0,10.594783,107.01594,-0.0038509513,10.685331,10.59452,106.90846,-9.428937
37.8,0.83269876,-0.063085958,41.802975,0,10.594783,113.31592,-0.0042008637,10.654796,10.595116,113.14172,-9.4254694
39.9,0.85064971,-0.068942107,42.394547,0,10.594783,119.61593,-0.0045618643,10.879071,10.594388,119.24039,-9.4214306
42.0,0.84964114,-0.07250642,42.516632,0,10.594783,125.91595,-0.0048434944,10.871096,10.59468,125.58519,-9.4178658
44.1,0.84926438,-0.078285955,43.451134,0,10.594783,132.21593,-0.0051939702,10.865787,10.594016,131.63675,-9.414402
46.2,0.8530615,-0.084180966,43.527828,0,10.594783,138.51593,-0.0055804029,10.916686,10.594253,138.20003,-9.4108715
48.3,0.87344277,-0.090111353,42.978519,0,10.594783,144.81593,-0.005992027,11.198559,10.593946,144.9052,-9.407671
50.4,0.87390137,-0.093622953,43.51749,0,10.594783,151.11592,-0.0062274341,11.204473,10.595285,150.93811,-9.4037609
52.5,0.87588036,-0.098936111,43.793777,0,10.594783,157.41594,-0.0065777376,11.229049,10.594928,157.03395,-9.4001951
54.6,0.87649566,-0.104789,44.59655,0,10.594783,163.71594,-0.0069417912,11.226188,10.594277,163.20288,-9.3967571
56.7,0.87917209,-0.11016341,44.554192,0,10.594783,170.01595,-0.007340909,11.26936,10.594414,169.78714,-9.3928709
58.8,0.89213198,-0.11672238,44.534645,0,10.594783,176.31595,-0.0077464893,11.444742,10.595108,176.20203,-9.3899155
60.9,0.892694,-0.12044614,44.604488,0,10.594783,182.61594,-0.0079720216,11.459361,10.594443,182.45221,-9.3869286
63.0,0.89625722,-0.12623106,45.11657,0,10.594783,188.91595,-0.0084052812,11.515039,10.594975,188.58104,-9.3832073
65.1,0.89453197,-0.13146588,45.121017,0,10.594783,195.21596,-0.0087144412,11.505806,10.594617,194.90326,-9.379385
67.2,0.89833939,-0.13895656,46.061493,0,10.594783,201.51595,-0.0092001427,11.540433,10.594308,200.93744,-9.3753004
69.3,0.90547687,-0.14319177,46.581898,0,10.594783,207.81595,-0.0095081758,11.641474,10.593082,207.22391,-9.37216
71.4,0.89082128,-0.14938448,47.05444,0,10.594783,214.11595,-0.0099216588,11.46976,10.59521,213.28191,-9.369215
73.5,0.9095574,-0.15502621,47.504883,0,10.594783,220.41595,-0.010278616,11.702516,10.594916,219.83551,-9.3658714
75.6,0.90701532,-0.16151801,47.504883,0,10.594783,226.71597,-0.010688532,11.67075,10.595035,226.42632,-9.362215
77.7,0.9012056,-0.16726358,47.733398,0,10.594783,233.01596,-0.011107328,11.598879,10.595047,232.77518,-9.3583317
79.8,0.91172457,-0.17281958,47.688904,0,10.594783,239.31596,-0.011436713,11.742564,10.59535,239.21007,-9.3545046
81.9,0.91841614,-0.18126877,47.955318,0,10.594783,245.61597,-0.011981216,11.816945,10.5946,245.40576,-9.3516941
84.0,0.90197545,-0.18632659,47.955318,0,10.594783,251.91595,-0.012357023,11.626516,10.593585,251.88664,-9.3485479
86.1,0.91133708,-0.19152741,47.823006,0,10.594783,258.21625,-0.012678974,11.754258,10.594492,258.28912,-9.3452396
88.2,0.92555958,-0.19945998,47.885342,0,10.594783,264.51596,-0.013203325,11.947437,10.595248,264.53381,-9.341362
90.3,0.90964144,-0.20384938,47.843822,0,10.594783,270.81595,-0.013492344,11.749552,10.595045,270.82416,-9.3375845
92.4,0.9172678,-0.20872599,47.955318,0,10.594783,277.11597,-0.013835958,11.846977,10.59509,276.89719,-9.3339329
94.5,0.92355597,-0.21685241,48.731602,0,10.594783,283.41599,-0.014347661,11.924712,10.594706,282.81467,-9.3306913
96.6,0.91671759,-0.22152567,48.841671,0,10.594783,289.71597,-0.014637648,11.84373,10.595044,289.21933,-9.3271198
98.7,0.92843467,-0.2271971,49.229733,0,10.594783,296.01596,-0.015055038,12.004224,10.59569,295.61472,-9.3239841
100.8,0.92347968,-0.23434722,49.230576,0,10.594783,302.31595,-0.015486732,11.925518,10.595718,301.99677,-9.3203573
102.9,0.91452044,-0.24023943,49.447067,0,10.594783,308.61597,-0.015878847,11.825431,10.594997,308.39774,-9.3167324
105.0,0.92735076,-0.24609673,49.636227,0,10.594783,314.91602,-0.016271209,12.000362,10.594718,314.7822,-9.3129978
107.1,0.93216729,-0.25277823,49.22974,0,10.594783,321.21597,-0.016718989,12.060279,10.595154,321.40527,-9.3094893
109.2,0.92072731,-0.25831768,49.22974,0,10.594783,327.51596,-0.017077092,11.941145,10.594904,327.71051,-9.3056059
111.3,0.9330166,-0.26311365,49.22974,0,10.594783,333.81598,-0.017363785,12.09373,10.594751,333.81613,-9.3022947
113.4,0.93165147,-0.27109978,49.636227,0,10.594783,340.11603,-0.017923569,12.079233,10.594796,339.77817,-9.2989702
115.5,0.92264932,-0.27624133,50.042721,0,10.594783,346.41599,-0.01823312,11.982183,10.593269,345.90836,-9.2960606
117.6,0.93662786,-0.28230578,50.438229,0,10.594783,352.71597,-0.018624913,12.168456,10.59426,352.19638,-9.2924471
119.7,0.9512549,-0.29000273,50.82275,0,10.594783,359.01596,-0.019155145,12.34472,10.593607,358.48059,-9.2886686
121.8,0.92811221,-0.29578876,51.149654,0,10.594783,365.31601,-0.019556282,12.02878,10.594615,364.87955,-9.2854147
123.9,0.92658061,-0.30292091,51.196285,0,10.594783,371.61603,-0.019988686,12.051572,10.595037,371.27429,-9.2817297
126.0,0.94267535,-0.30875221,51.513866,0,10.594783,377.91602,-0.02035214,12.241234,10.595419,377.50238,-9.2781258
128.1,0.94735205,-0.31677845,51.56982,0,10.594783,384.21597,-0.020900302,12.314471,10.594995,383.98135,-9.2744541
130.2,0.93364036,-0.32311481,51.932369,0,10.594783,390.51599,-0.021306224,12.161868,10.593912,390.10043,-9.2711096
132.3,0.94377184,-0.32969946,51.932369,0,10.594783,396.81598,-0.021729177,12.286639,10.595555,396.40463,-9.2672501
134.4,0.077089958,-0.34865868,51.922005,0,10.594783,399.99893,-0.022977941,1.0077389,10.594169,399.91299,-9.2654533
136.5,0.059999313,-0.34756783,54.080105,0,10.594783,399.99893,-0.022923317,0.77023977,10.594559,397.88364,-9.2657909
138.6,0.075491801,-0.34831244,53.163933,0,10.594783,399.99893,-0.022953231,0.9875176,10.594412,400.26828,-9.2657003
140.7,0.080902234,-0.35074562,50.141972,0,10.594783,399.99893,-0.023097873,1.0498456,10.594208,402.88812,-9.2658834
142.8,0.039322916,-0.34909105,47.955338,0,10.594783,399.99893,-0.023020227,0.51979959,10.595434,402.84845,-9.2654543
144.9,0.037663274,-0.3467342,50.041306,0,10.594783,399.99893,-0.022858523,0.48798054,10.594494,399.46353,-9.2652817
147.0,0.04907744,-0.34695926,52.953472,0,10.594783,399.99893,-0.022867117,0.63103992,10.595559,397.09528,-9.2655401
149.1,0.074180759,-0.34909314,53.975826,0,10.594783,399.99893,-0.022987148,0.96781212,10.596009,397.95224,-9.2655287
151.2,0.085024431,-0.35339579,52.635674,0,10.594783,399.99893,-0.023307107,1.0997778,10.594916,400.48141,-9.2647038
153.3,0.069558039,-0.35345253,50.439003,0,10.594783,399.99893,-0.023275739,0.92441797,10.59463,402.25928,-9.2647486
155.4,0.0748844,-0.35403714,48.81226,0,10.594783,399.99893,-0.023317209,0.98465043,10.594681,402.30432,-9.2651691
157.5,0.041894112,-0.35281116,48.815853,0,10.594783,399.99893,-0.023240302,0.5491668,10.594838,400.763,-9.2644644
159.6,0.036330096,-0.35272953,50.822685,0,10.594783,399.99893,-0.023257909,0.48353338,10.595085,398.58234,-9.2641182
161.7,0.082679346,-0.35475391,52.038242,0,10.594783,399.99893,-0.023366502,1.0778443,10.594263,398.44516,-9.2647514
163.8,0.080114745,-0.35523817,51.569828,0,10.594783,399.99893,-0.023388222,1.0374677,10.59525,399.88107,-9.2649088
165.9,0.074444763,-0.3565335,50.438244,0,10.594783,399.99893,-0.0234937,0.96939594,10.59421,400.97009,-9.26507
168.0,0.052953344,-0.3573941,49.636234,0,10.594783,399.99893,-0.023560578,0.67926252,10.594633,401.14435,-9.2646179
170.1,0.052489031,-0.35827541,49.808067,0,10.594783,399.99893,-0.023600461,0.70549083,10.594935,400.15646,-9.2643776
172.2,0.046746206,-0.35682315,51.196125,0,10.594783,399.99893,-0.023490936,0.61206466,10.594777,398.88217,-9.2639809
174.3,0.082953744,-0.35775149,51.642075,0,10.594783,399.99893,-0.023577604,1.0885041,10.594706,399.13513,-9.2645025
176.4,0.071060613,-0.3596977,50.823505,0,10.594783,399.99893,-0.023707647,0.92928618,10.594081,400.41626,-9.2646103
178.4633,0.07425607,-0.013877884,49.908379,0,10.594783,399.99893,-0.00091739965,0.95013243,10.59503,401.06723,-9.2648897
178.6352,0.21117295,0.068490081,24.818016,0,10.5948,1.8726911e-23,0.0045545637,2.737164,10.593019,401.08405,-9.2648172
178.6394,0.16838662,0.071921065,3.9707992,0,10.5948,0.0,0.0047614588,2.0948062,10.595743,401.08405,-9.2644615
178.6436,0.17315927,0.068255432,0.0,0,10.5948,0.0,0.0047855214,2.0619428,10.595309,401.07382,-9.2654219
178.6478,0.17806084,0.07056623,0.0,0,10.5948,0.0,0.0046016015,2.1999891,10.594666,401.06119,-9.2656536
178.652,0.18167517,0.075172246,0.0,0,10.5948,0.0,0.0048207697,2.330086,10.59626,401.07019,-9.264535
178.6562,0.17508796,0.069239467,0.0,0,10.5948,0.0,0.0049163187,2.2326872,10.595949,401.10812,-9.264431
178.6604,0.173935,0.069474667,0.0,0,10.5948,0.0,0.0046303072,2.204669,10.592879,401.14423,-9.2647867
178.6646,0.16986284,0.0704806,0.0,0,10.5948,0.0,0.0046127886,2.1417818,10.596493,401.14423,-9.2654133
178.6688,0.16334735,0.069860503,0.0,0,10.5948,0.0,0.004889675,2.0834551,10.595686,401.14423,-9.2645435
178.673,0.16959569,0.071121648,0.0,0,10.5948,0.0,0.0046690083,2.1126919,10.591106,401.11053,-9.2647285
178.6772,0.18892495,0.076386288,0.0,0,10.5948,0.0,0.004945612,2.4612792,10.592981,401.05997,-9.2650852
178.6814,0.20003119,0.071890265,0.0,0,10.5948,0.0,0.0049968502,2.5175388,10.59749,401.02747,-9.2647419
178.6856,0.19222842,0.070067897,0.0,0,10.533863,0.0,0.0046613845,2.4946306,10.596004,401.0401,-9.2642193
178.6898,0.18835419,0.072211012,0.0,0,10.470864,0.0,0.0047588996,2.3797858,10.589675,401.05276,-9.2646847
178.694,0.19870643,0.071395583,0.0,0,10.407864,0.0,0.0049898056,2.5388374,10.559996,401.07681,-9.2650414
178.6982,0.18865865,0.072401442,0.0,0,10.344864,0.0,0.0047890171,2.4219127,10.488982,401.10211,-9.2641735
178.7024,0.19525126,0.077681072,0.0,0,10.281863,0.0,0.0049712379,2.4954987,10.388996,401.10751,-9.2645168
178.7066,0.20387483,0.07179106,0.0,0,10.218863,0.0,0.0050532762,2.5351763,10.29721,401.09488,-9.2645044
178.7108,0.21384573,0.070987538,0.0,0,10.155864,0.0,0.0047116443,2.6906822,10.233277,401.08765,-9.2658434
178.715,0.21375628,0.071793579,0.0,0,10.092864,0.0,0.0046488959,2.7741489,10.180548,401.11295,-9.2650309
178.7192,0.20567761,0.071012586,0.0,0,10.029863,0.0,0.0049333838,2.6420016,10.129915,401.13821,-9.2637882
178.7234,0.24175709,0.073699653,0.0,0,9.9668636,0.0,0.0048912778,2.914135,10.062778,401.17313,-9.2641048
178.7276,2.1705065,0.10187661,0.0,0,9.9038639,0.0,0.0065711932,27.230297,10.00455,401.21106,-9.2625618
178.7318,3.8203762,0.13572119,0.0,0,9.8408632,0.0,0.0093225669,47.976353,9.9401627,401.40311,-9.2616806
178.736,4.6605539,0.19261913,0.0,0,9.7778635,0.0,0.012903829,58.470596,9.8767281,401.84558,-9.2628584
178.7402,5.1848769,0.25499392,0.0,0,9.7148628,0.0,0.017022029,64.9179,9.8079453,402.28806,-9.2610655
178.7444,5.5007029,0.31705442,0.0,0,9.6518641,0.0,0.021534447,68.500732,9.7418671,403.16037,-9.2626581
178.7486,5.6951752,0.38107491,0.0,0,9.5888634,0.0,0.025658544,70.689331,9.6794243,404.03268,-9.2615299
178.7528,5.8012671,0.44927457,0.0,0,9.5258636,0.0,0.030083958,71.780281,9.6118002,404.68585,-9.2616329
178.757,5.8818488,0.50775641,0.0,0,9.4633293,0.0,0.034628242,72.321144,9.5477743,405.20419,-9.2621536
178.7612,5.9703102,0.56745535,0.0,0,9.4018736,0.0,0.038525198,73.076027,9.4808235,405.6051,-9.2623024
178.7654,6.012567,0.63047427,0.0,0,9.3404198,0.0,0.042747673,73.347816,9.4164715,405.6304,-9.2621126
178.7696,6.0848451,0.68970984,0.0,0,9.278965,0.0,0.047254991,73.905289,9.3597078,405.6557,-9.262742
178.7738,6.1727624,0.75443482,0.0,0,9.2175112,0.0,0.051544245,74.599052,9.2901773,405.6376,-9.260931
178.778,6.1989803,0.81953186,0.0,0,9.1560564,0.0,0.055855103,74.602463,9.2293777,405.6123,-9.2624264
178.7822,6.2146535,0.87648183,0.0,0,9.0946016,0.0,0.060356215,74.437752,9.1665287,405.56293,-9.2620115
178.7864,6.2476239,0.9347021,0.0,0,9.0331469,0.0,0.064239651,74.714066,9.1054888,405.48709,-9.2609282
178.7906,6.2852483,0.99523395,0.0,0,8.971693,0.0,0.068457566,74.689499,9.0423641,405.41245,-9.2625904
178.7948,6.3435855,1.0551037,0.0,0,8.9102392,0.0,0.07308466,75.051651,8.9827385,405.34924,-9.2619619
178.799,6.3925018,1.1200013,0.0,0,8.8487844,0.0,0.07755819,75.326241,8.9183083,405.28604,-9.2629366
178.8032,6.4217401,1.1827779,0.0,0,8.7873297,0.0,0.081806116,75.336639,8.8595734,405.33121,-9.2621193
178.8074,6.4689798,1.2390499,0.0,0,8.7270651,0.0,0.086418509,75.51461,8.7942085,405.41971,-9.2614527
178.8116,6.4984617,1.2973036,0.0,0,8.6686182,0.0,0.090466745,75.592415,8.7334967,405.46606,-9.2619963
178.8158,6.5182605,1.3583928,0.0,0,8.6101713,0.0,0.094704598,75.375114,8.6730976,405.4281,-9.2622843
178.82,6.5415649,1.4171958,0.0,0,8.5517235,0.0,0.09938664,75.483826,8.6149225,405.39017,-9.2617369
178.8242,6.5483146,1.4758282,0.0,0,8.4932766,0.0,0.10354435,75.223305,8.5536261,405.1235,-9.2625113
178.8284,6.597827,1.5388813,0.0,0,8.4348297,0.0,0.10783739,75.290863,8.4960251,404.8454,-9.2616758
178.8326,6.6725621,1.5934972,0.0,0,8.3763819,0.0,0.11250304,75.737358,8.4358835,404.70453,-9.2616911
178.8368,6.7070398,1.6482213,0.0,0,8.317935,0.0,0.11636677,75.935936,8.3777351,404.66656,-9.2621384
178.841,6.74296,1.7149417,0.0,0,8.2594881,0.0,0.12120461,76.001495,8.3136415,404.67441,-9.262413
178.8452,6.7512431,1.7708124,0.0,0,8.2010412,0.0,0.12575127,75.813354,8.2526007,404.87668,-9.2613096
178.8494,6.7517333,1.8280611,0.0,0,8.1425943,0.0,0.13002574,75.491074,8.1936903,405.07895,-9.2622528
178.8536,6.7759862,1.8877374,0.0,0,8.0841465,0.0,0.13406752,75.458534,8.1395521,405.18912,-9.26159
178.8578,6.8451576,1.9432191,0.0,0,8.0270939,0.0,0.13892384,75.778717,8.0753851,405.27762,-9.2629166
178.862,6.8602409,1.9953829,0.0,0,7.9714851,0.0,0.14281377,75.743843,8.0219679,405.13855,-9.26192
178.8662,6.910048,2.053813,0.0,0,7.9158773,0.0,0.14703797,75.932632,7.9626594,404.69608,-9.2617617
178.8704,6.9440861,2.1072834,0.0,0,7.8602695,0.0,0.15161189,75.928886,7.9069376,404.23312,-9.2624207
178.8746,6.9617381,2.1617708,0.0,0,7.8046613,0.0,0.15569901,75.912186,7.8503699,403.36081,-9.2626219
178.8788,6.9788938,2.2244744,0.0,0,7.7490535,0.0,0.16006404,75.653633,7.7931671,402.48853,-9.2616463
178.883,7.0122581,2.2742679,0.0,0,7.6934457,0.0,0.1645402,75.654793,7.7394743,401.05023,-9.2619095
178.8872,7.0414009,2.3293154,0.0,0,7.6378374,0.0,0.16877824,75.78289,7.680697,399.32898,-9.2623987
178.8914,7.1042662,2.3852229,0.0,0,7.5822296,0.0,0.17298603,76.080933,7.6235542,397.8204,-9.2617559
178.8956,7.1340141,2.4378648,0.0,0,7.5266213,0.0,0.17752676,76.08036,7.5698528,396.6947,-9.2624025
178.8998,7.1699462,2.494225,0.0,0,7.4710135,0.0,0.18195389,76.076363,7.5141664,395.56897,-9.2610149
178.904,7.2425637,2.5592604,0.0,0,7.4154053,0.0,0.18658818,76.563835,7.4564896,395.24536,-9.2628422
178.9082,7.2412734,2.6133502,0.0,0,7.361393,0.0,0.19163746,76.087166,7.3953757,394.94135,-9.2625809
178.9124,7.2238317,2.6641636,0.0,0,7.308507,0.0,0.19565798,75.679779,7.3410506,394.93137,-9.2616653
178.9166,7.2385983,2.7184813,0.0,0,7.2556205,0.0,0.1996755,75.494881,7.2901783,395.1214,-9.2631426
178.9208,7.2998171,2.7676749,0.0,0,7.202734,0.0,0.20406921,75.796585,7.2367768,395.57986,-9.2623196
178.925,7.3592501,2.8209419,0.0,0,7.1498475,0.0,0.20851526,76.050697,7.181488,397.02258,-9.2612047
178.9292,7.3801317,2.8797784,0.0,0,7.096961,0.0,0.21266465,75.978302,7.1256537,398.4653,-9.2609682
178.9334,7.3825908,2.9280643,0.0,0,7.044075,0.0,0.21731474,75.682503,7.0784621,399.38013,-9.2615175
178.9376,7.3729863,2.9709573,0.0,0,6.991188,0.0,0.22088875,75.272865,7.0289798,400.18939,-9.2617359
178.9418,7.4389882,3.0253081,0.0,0,6.938302,0.0,0.22491369,75.650734,6.9760079,400.71835,-9.2622757
178.946,7.4855704,3.0782712,0.0,0,6.8854156,0.0,0.22973152,75.706993,6.9209895,400.90796,-9.2609701
178.9502,7.5416217,3.1310844,0.0,0,6.8325291,0.0,0.23424497,75.95031,6.8663173,401.11023,-9.2618942
178.9544,7.5978875,3.1931219,0.0,0,6.7796426,0.0,0.23893119,76.169853,6.8087707,401.47687,-9.2619801
178.9586,7.5987172,3.2420635,0.0,0,6.728508,0.0,0.24358685,75.833847,6.7575493,401.84348,-9.2624426
178.9628,7.6189694,3.2848914,0.0,0,6.6781921,0.0,0.24742128,75.72123,6.7106261,402.28867,-9.2603951
178.967,7.6524167,3.3433278,0.0,0,6.6278758,0.0,0.25183561,75.771538,6.6561847,402.76907,-9.2612076
178.9712,7.6781816,3.3916769,0.0,0,6.5775599,0.0,0.25642669,75.618324,6.6046,403.2338,-9.2623901
178.9754,7.6992822,3.4443138,0.0,0,6.5272441,0.0,0.26100168,75.433655,6.5515409,403.66364,-9.2624779
178.9796,7.7042518,3.4975789,0.0,0,6.4769282,0.0,0.26493907,75.327286,6.5036716,404.09344,-9.2622242
178.9838,7.7308526,3.5437789,0.0,0,6.4266124,0.0,0.26956618,75.172531,6.4568892,404.07721,-9.2612333
178.988,7.8452458,3.5869236,0.0,0,6.376296,0.0,0.27358243,76.005348,6.4019723,404.02664,-9.2623873
178.9922,7.8888254,3.6461327,0.0,0,6.3259802,0.0,0.27809256,76.085556,6.3508692,403.96225,-9.2595978
178.9964,7.8813944,3.6958232,0.0,0,6.2756648,0.0,0.28297326,75.640114,6.2979393,403.88638,-9.2628613
179.0006,7.889246,3.7428496,0.0,0,6.2253485,0.0,0.28723755,75.36824,6.2487507,403.88217,-9.2619686
179.0048,7.9061179,3.7966661,0.0,0,6.1750326,0.0,0.29138049,75.189621,6.1985874,404.23615,-9.2624159
179.009,7.9444451,3.8457708,0.0,0,6.1266279,0.0,0.29626507,75.176445,6.1499405,404.59012,-9.2623882
179.0132,8.0202513,3.8914466,0.0,0,6.0787735,0.0,0.30066875,75.63121,6.0975404,404.98383,-9.2609282
179.0174,8.0284224,3.9431279,0.0,0,6.0309186,0.0,0.30456871,75.354408,6.0496192,405.38837,-9.262187
179.0216,8.0461216,3.9896924,0.0,0,5.9830642,0.0,0.30930817,75.120506,6.0049281,405.72641,-9.26194
179.0258,8.086565,4.0343237,0.0,0,5.9352088,0.0,0.31355831,75.208153,5.9540386,405.96661,-9.2614031
179.03,8.099802,4.0877109,0.0,0,5.8873544,0.0,0.31761941,75.139008,5.9039059,406.2095,-9.2609053
179.0342,8.1608076,4.1378126,0.0,0,5.8394995,0.0,0.32278582,75.228188,5.8550777,406.56348,-9.2616997
179.0384,8.1949186,4.1780915,0.0,0,5.7916446,0.0,0.32683119,75.306168,5.8051877,406.91745,-9.2619276
179.0426,8.217308,4.2306819,0.0,0,5.7437897,0.0,0.3309685,75.058258,5.7598057,407.47461,-9.2623224
179.0468,8.2334862,4.2761636,0.0,0,5.6959348,0.0,0.33557189,74.948265,5.7130156,408.14465,-9.2608519
179.051,8.2752676,4.3187013,0.0,0,5.6480803,0.0,0.33985603,74.984131,5.6661606,408.75842,-9.2610121
179.0552,8.3237162,4.3700638,0.0,0,5.600225,0.0,0.34393752,75.14888,5.6197643,409.21353,-9.2616234
179.0594,8.3913994,4.421936,0.0,0,5.5544,0.0,0.34913641,75.281021,5.5707188,409.66867,-9.2610092
179.0636,8.4133091,4.4623246,0.0,0,5.5088716,0.0,0.3534745,75.199371,5.5211902,409.54465,-9.2616787
179.0678,8.3882647,4.5121279,0.0,0,5.4633436,0.0,0.35747439,74.73217,5.473443,409.34235,-9.2630348
179.072,8.4135475,4.5599127,0.0,0,5.4178157,0.0,0.36238769,74.527931,5.4291987,408.66599,-9.2609758
179.0762,8.4598179,4.5986485,0.0,0,5.3722878,0.0,0.36648029,74.661201,5.3881602,407.51556,-9.2630548
179.0804,8.5124073,4.6508636,0.0,0,5.3267598,0.0,0.37064496,74.840401,5.340878,406.21008,-9.2611017
179.0846,8.5566397,4.6961164,0.0,0,5.2812319,0.0,0.37538171,74.835808,5.2990336,403.75745,-9.2608223
179.0888,8.6101618,4.7379093,0.0,0,5.2357039,0.0,0.38008392,74.995094,5.2504654,401.30478,-9.2612543
179.093,8.5930853,4.7835131,0.0,0,5.1901755,0.0,0.38370809,74.635399,5.2035961,399.54266,-9.2619867
179.0972,8.6218004,4.8308568,0.0,0,5.1446476,0.0,0.38863882,74.484344,5.1586485,398.0256,-9.262598
179.1014,8.6718473,4.8705196,0.0,0,5.0991197,0.0,0.39295396,74.538467,5.1110907,397.21292,-9.2608385
179.1056,8.7086267,4.9243822,0.0,0,5.0535922,0.0,0.39742991,74.567505,5.0662708,397.66815,-9.2622967
179.1098,8.795393,4.9699407,0.0,0,5.0102167,0.0,0.40229329,74.845406,5.0214281,398.12338,-9.260994
179.114,8.8324327,5.0079036,0.0,0,4.9669147,0.0,0.40679955,74.899986,4.9752631,397.73849,-9.26196
179.1182,8.8313885,5.0548105,0.0,0,4.9236126,0.0,0.41055158,74.567375,4.9322743,397.3331,-9.2620945
179.1224,8.8552475,5.1008229,0.0,0,4.880311,0.0,0.41555393,74.447296,4.8851118,396.61902,-9.2624779
179.1266,8.8698626,5.141551,0.0,0,4.8370085,0.0,0.42014778,74.20137,4.8424659,395.69504,-9.2609243
179.1308,8.8777304,5.1893935,0.0,0,4.7937069,0.0,0.42411429,73.914566,4.8016481,395.00705,-9.2611074
179.135,8.9642992,5.2344131,0.0,0,4.7504048,0.0,0.42892569,74.363686,4.7581587,395.18442,-9.2624283
179.1392,9.0230551,5.2695436,0.0,0,4.7071028,0.0,0.43324709,74.504227,4.7146349,395.36179,-9.2609205
179.1434,9.057271,5.3156705,0.0,0,4.6638007,0.0,0.43710458,74.466301,4.6695333,395.95062,-9.2612543
179.1476,9.0541248,5.3607407,0.0,0,4.6204991,0.0,0.44210821,74.093071,4.6260142,396.62177,-9.2618084
179.1518,9.0796051,5.3961129,0.0,0,4.5771966,0.0,0.44628924,74.083389,4.5866017,397.2869,-9.2615414
179.156,9.1360807,5.4443212,0.0,0,4.5340271,0.0,0.45042527,74.115417,4.5424471,397.94476,-9.2625675
179.1602,9.196805,5.4891624,0.0,0,4.4928331,0.0,0.45528734,74.285881,4.5001373,398.59808,-9.2617321
179.1644,9.2262611,5.5263085,0.0,0,4.4516392,0.0,0.46006542,74.115326,4.4551492,399.19226,-9.2613192
179.1686,9.2922239,5.5696945,0.0,0,4.4104452,0.0,0.46382895,74.370438,4.4151969,399.78644,-9.2617702
179.1728,9.3533239,5.6163354,0.0,0,4.3692517,0.0,0.46884912,74.492783,4.3677049,400.22348,-9.2606277
179.177,9.3466473,5.6529899,0.0,0,4.3280582,0.0,0.47350752,74.148407,4.3293133,400.59012,-9.2609301
179.1812,9.3670845,5.6991844,0.0,0,4.2868648,0.0,0.47742641,74.00119,4.288681,400.94501,-9.2608089
179.1854,9.3965759,5.7408361,0.0,0,4.2456713,0.0,0.48207006,73.941223,4.2513394,401.27368,-9.2621717
179.1896,9.3999434,5.7740622,0.0,0,4.2044773,0.0,0.48659441,73.611412,4.2147894,401.60239,-9.2619743
179.1938,9.511055,5.8150449,0.0,0,4.1632838,0.0,0.49012727,74.095558,4.1731,402.24802,-9.2616844
179.198,9.5957432,5.8610392,0.0,0,4.1220903,0.0,0.49534464,74.406662,4.1276364,402.91806,-9.2619295
179.2022,9.6507406,5.8998742,0.0,0,4.0808969,0.0,0.50032091,74.57489,4.0852938,403.15195,-9.2615604
179.2064,9.6808214,5.9460301,0.0,0,4.0400209,0.0,0.50445437,74.395515,4.0406036,403.02551,-9.2597513
179.2106,9.6697826,5.9893417,0.0,0,4.0008435,0.0,0.509251,74.019913,4.0043669,402.87592,-9.2608166
179.2148,9.7371702,6.0205817,0.0,0,3.9616656,0.0,0.51375175,74.228806,3.9624989,402.61044,-9.2631884
179.219,9.7440376,6.0637231,0.0,0,3.9224882,0.0,0.51759833,73.988281,3.9209037,402.34497,-9.2620602
179.2232,9.7261534,6.1028948,0.0,0,3.8833106,0.0,0.52192152,73.498596,3.8863263,402.44699,-9.2624617
179.2274,9.8163891,6.1352553,0.0,0,3.8441329,0.0,0.52644515,73.803635,3.8485036,402.64926,-9.2614832
179.2316,9.9351206,6.1775255,0.0,0,3.8049555,0.0,0.53047305,74.422958,3.8099928,402.45752,-9.2607155
179.2358,10.017912,6.2244873,0.0,0,3.7657778,0.0,0.53564268,74.646317,3.7700732,401.68634,-9.2614765
179.24,10.06034,6.2566681,0.0,0,3.7266002,0.0,0.54039156,74.62616,3.7288451,400.89166,-9.2609835
179.2442,10.064857,6.3002067,0.0,0,3.6874225,0.0,0.54442829,74.364838,3.6903856,399.13315,-9.2609119
179.2484,10.106704,6.3417988,0.0,0,3.6482451,0.0,0.54921377,74.378593,3.6469967,397.37463,-9.2606773
179.2526,10.160554,6.3775268,0.0,0,3.6090674,0.0,0.554254,74.289497,3.6052258,396.04675,-9.2609062
179.2568,10.206345,6.4197001,0.0,0,3.5703723,0.0,0.55834186,74.394554,3.5683234,394.95816,-9.2604351
179.261,10.251033,6.463243,0.0,0,3.5331016,0.0,0.56321037,74.306229,3.5310841,394.18121,-9.2616682
179.2652,10.311892,6.4934244,0.0,0,3.4958305,0.0,0.56794035,74.368256,3.4932172,394.28256,-9.2610273
179.2694,10.340859,6.5315309,0.0,0,3.4585598,0.0,0.57148272,74.366432,3.4564142,394.38394,-9.2607155
179.2736,10.355776,6.5691209,0.0,0,3.4212892,0.0,0.57575661,74.130836,3.4194531,395.19907,-9.2615623
179.2778,10.384048,6.6008382,0.0,0,3.3840184,0.0,0.58037144,74.005112,3.3853998,396.11066,-9.2617378
179.282,10.464437,6.6393042,0.0,0,3.3467472,0.0,0.58425343,74.295265,3.3459885,396.80084,-9.261631
179.2862,10.560708,6.6850729,0.0,0,3.3094764,0.0,0.58937609,74.527794,3.306612,397.26959,-9.2600279
179.2904,10.632389,6.7150006,0.0,0,3.2722056,0.0,0.59428191,74.688515,3.2698851,397.64642,-9.2607851
179.2946,10.694901,6.751781,0.0,0,3.234935,0.0,0.59787166,74.866661,3.2332814,397.3429,-9.262392
179.2988,10.759542,6.7958026,0.0,0,3.1976643,0.0,0.60302311,74.897499,3.1955109,397.0394,-9.2599697
179.303,10.834588,6.8289213,0.0,0,3.1603935,0.0,0.6080851,75.072693,3.1585383,396.37079,-9.261528
179.3072,10.874275,6.8678646,0.0,0,3.1237545,0.0,0.61211026,75.088882,3.1191795,395.57266,-9.2616758
179.3114,10.864161,6.9140425,0.0,0,3.0882978,0.0,0.61713833,74.664597,3.0849824,394.80621,-9.2611141
179.3156,10.90169,6.941535,0.0,0,3.0528414,0.0,0.62202346,74.460358,3.0490546,394.09677,-9.2610903
179.3198,10.977572,6.9757872,0.0,0,3.017385,0.0,0.62534511,74.780205,3.0163031,393.38733,-9.261055
179.324,11.06452,7.0122557,0.0,0,2.9819286,0.0,0.62960202,75.06041,2.9805164,392.82626,-9.2618999
179.3282,11.178062,7.0463295,0.0,0,2.9464724,0.0,0.63497049,75.386215,2.9445996,392.26883,-9.2618904
179.3324,11.221275,7.0835638,0.0,0,2.9110157,0.0,0.63898367,75.425163,2.9065692,391.4324,-9.2597427
179.3366,11.249949,7.1288238,0.0,0,2.8755593,0.0,0.64414191,75.177208,2.8659894,390.40625,-9.2609005
179.3408,11.285877,7.1550579,0.0,0,2.8401029,0.0,0.64881366,75.076164,2.8345551,389.44254,-9.2609758
179.345,11.325872,7.1880374,0.0,0,2.8046467,0.0,0.65230751,75.060097,2.801373,388.70773,-9.2623291
179.3492,11.368681,7.2250385,0.0,0,2.7691901,0.0,0.65666473,75.050713,2.7681379,387.97296,-9.2612686
179.3534,11.476185,7.257062,0.0,0,2.7337339,0.0,0.66178596,75.354561,2.7339368,387.2804,-9.2596025
179.3576,11.590364,7.2921472,0.0,0,2.6990452,0.0,0.66572475,75.855957,2.6968107,386.59631,-9.2615643
179.3618,11.718225,7.3378348,0.0,0,2.665319,0.0,0.67098838,76.293411,2.6614394,385.95804,-9.2608395
179.366,11.749246,7.3672733,0.0,0,2.631593,0.0,0.67632669,76.079865,2.6241374,385.37527,-9.2610826
179.3702,11.771553,7.4019318,0.0,0,2.597867,0.0,0.68003213,75.980118,2.587213,384.86942,-9.2616615
179.3744,11.834723,7.4379654,0.0,0,2.564141,0.0,0.68441868,75.987198,2.556026,385.36349,-9.2605333
179.3786,11.836287,7.4689322,0.0,0,2.5304151,0.0,0.68952185,75.590477,2.521261,385.85757,-9.2602978
179.3828,11.915292,7.5025682,0.0,0,2.4966891,0.0,0.69348633,75.821625,2.4926198,386.29044,-9.2611723
179.387,11.992495,7.5422091,0.0,0,2.4629631,0.0,0.69792688,75.939018,2.4569654,386.69583,-9.2615252
179.3912,12.050134,7.5668225,0.0,0,2.4292369,0.0,0.70271319,75.984703,2.4261694,387.15616,-9.2608137
179.3954,12.135336,7.5960417,0.0,0,2.3955109,0.0,0.70600331,76.283699,2.3946953,387.73889,-9.2614441
179.3996,12.243059,7.6338205,0.0,0,2.3617849,0.0,0.71050531,76.601791,2.3615069,388.32166,-9.2608194
179.4038,12.335622,7.6654849,0.0,0,2.328059,0.0,0.7160241,76.769997,2.3249593,389.49258,-9.2613316
179.408,12.41534,7.7031193,0.0,0,2.2952197,0.0,0.72055602,76.844345,2.2898746,390.7088,-9.2603273
179.4122,12.459867,7.7441516,0.0,0,2.26314,0.0,0.72522664,76.812279,2.2530508,391.75153,-9.2599363
179.4164,12.504611,7.7717252,0.0,0,2.2310605,0.0,0.73062366,76.695549,2.2242568,392.651,-9.260643
179.4206,12.602005,7.7978044,0.0,0,2.198981,0.0,0.73374707,76.978966,2.1911836,393.55893,-9.2619638
179.4248,12.643895,7.8383288,0.0,0,2.1669014,0.0,0.73857373,76.954987,2.1596911,394.50909,-9.2609835
179.429,12.677599,7.8622499,0.0,0,2.1348217,0.0,0.74307579,76.74279,2.1277421,395.45923,-9.2614288
179.4332,12.719495,7.8956575,0.0,0,2.102742,0.0,0.74759078,76.703522,2.0982382,395.91168,-9.2604952
179.4374,12.835997,7.9345188,0.0,0,2.0706627,0.0,0.75181127,77.036499,2.066503,396.22839,-9.2618723
179.4416,12.918191,7.9603257,0.0,0,2.038583,0.0,0.75700027,77.137398,2.0332799,396.36053,-9.260314
179.4458,13.049255,7.9862981,0.0,0,2.0065033,0.0,0.760288,77.656624,2.0049889,396.22119,-9.2609234
179.45,13.183467,8.0266685,0.0,0,1.9744238,0.0,0.76530969,78.089539,1.9723134,396.10019,-9.2611351
179.4542,13.284368,8.0557966,0.0,0,1.9423442,0.0,0.77057344,78.291382,1.9399441,396.73267,-9.2598667
179.4584,13.388663,8.0900993,0.0,0,1.911255,0.0,0.77538145,78.504845,1.9021747,397.36511,-9.2608652
179.4626,13.434091,8.1323929,0.0,0,1.8807379,0.0,0.78013134,78.449005,1.8729897,397.65616,-9.2617645
179.4668,13.492294,8.1602592,0.0,0,1.8502207,0.0,0.78576952,78.306511,1.837971,397.75754,-9.2609348
179.471,13.513239,8.1841707,0.0,0,1.8197033,0.0,0.7890318,78.148613,1.8073246,397.39462,-9.2602015
179.4752,13.568163,8.219058,0.0,0,1.7891862,0.0,0.79321462,78.156303,1.7769952,395.7233,-9.2605839
179.4794,13.656214,8.2474794,0.0,0,1.758669,0.0,0.7984761,78.218147,1.7519753,394.052,-9.2597427
179.4836,13.753562,8.2724562,0.0,0,1.7281518,0.0,0.80217904,78.484818,1.7189134,393.69678,-9.2615795
179.4878,13.806846,8.3123827,0.0,0,1.6976346,0.0,0.80671942,78.452934,1.6939263,393.51944,-9.2597218
179.492,13.890635,8.3344736,0.0,0,1.6671174,0.0,0.81154335,78.587502,1.6629885,393.71579,-9.2601032
179.4962,14.027344,8.3598623,0.0,0,1.6366003,0.0,0.81537217,79.025581,1.6341873,394.28586,-9.2603149
179.5004,14.206847,8.3970699,0.0,0,1.6060829,0.0,0.81971127,79.678795,1.5996091,394.66592,-9.2606859
179.5046,14.324708,8.4266424,0.0,0,1.5755658,0.0,0.8254078,79.890572,1.5682349,393.63977,-9.2593307
179.5088,14.407497,8.4555731,0.0,0,1.5461327,0.0,0.82998997,79.969353,1.5352659,392.61362,-9.2607603
179.513,14.467568,8.49471,0.0,0,1.5171022,0.0,0.83414209,79.949432,1.5087602,391.51263,-9.259798
179.5172,14.524485,8.5186815,0.0,0,1.4880718,0.0,0.8395167,79.894592,1.4783021,390.3851,-9.2587299
179.5214,14.611429,8.5454235,0.0,0,1.4590415,0.0,0.84368891,80.044182,1.446982,389.90009,-9.2617121
179.5256,14.655521,8.577529,0.0,0,1.430011,0.0,0.84735548,79.9618,1.4208504,390.57153,-9.2594185
179.5298,14.76269,8.6047173,0.0,0,1.4009807,0.0,0.85276341,80.107376,1.3954259,391.24298,-9.2601767
179.534,14.87541,8.6311922,0.0,0,1.3719503,0.0,0.85713589,80.34668,1.3630726,392.32254,-9.2607365
179.5382,15.010702,8.6673231,0.0,0,1.3429198,0.0,0.86107779,80.753357,1.3383199,393.41205,-9.2591438
179.5424,15.134528,8.6939354,0.0,0,1.3138895,0.0,0.86684906,80.979446,1.3067541,393.74747,-9.2608786
179.5466,15.243124,8.7145205,0.0,0,1.2848592,0.0,0.87035561,81.2948,1.2792604,393.5701,-9.2594833
179.5508,15.338532,8.7477779,0.0,0,1.2558287,0.0,0.87429506,81.500137,1.250282,393.18097,-9.2608538
179.555,15.428269,8.7776632,0.0,0,1.2267983,0.0,0.8801102,81.496292,1.2199804,392.01547,-9.260251
179.5592,15.521687,8.7999449,0.0,0,1.1989383,0.0,0.88408929,81.662239,1.1918283,390.84995,-9.2609081
179.5634,15.597894,8.8372622,0.0,0,1.1713274,0.0,0.88839614,81.665504,1.1592996,388.1207,-9.2601109
179.5676,15.686384,8.8623095,0.0,0,1.1437165,0.0,0.89394993,81.739212,1.1369294,385.07864,-9.2598076
179.5718,15.802385,8.8801775,0.0,0,1.1161058,0.0,0.89730304,81.985916,1.1093118,382.51813,-9.2599001
179.576,15.947242,8.9138842,0.0,0,1.0884949,0.0,0.90103555,82.471176,1.0812814,380.5405,-9.2599812
179.5802,16.047337,8.9394388,0.0,0,1.0608841,0.0,0.906488,82.56852,1.0530151,378.68686,-9.2597075
179.5844,16.124952,8.9629288,0.0,0,1.0332733,0.0,0.91078579,82.572105,1.0256722,378.44562,-9.2584887
179.5886,16.186707,8.997303,0.0,0,1.0056624,0.0,0.91477603,82.600708,0.99820018,378.20438,-9.2598352
179.5928,16.30641,9.0217505,0.0,0,0.97805184,0.0,0.9200967,82.741867,0.97160983,378.14725,-9.2580729
179.597,16.459249,9.0421782,0.0,0,0.95044094,0.0,0.92401934,83.155792,0.9464739,378.17264,-9.2589674
179.6012,16.64682,9.0740623,0.0,0,0.92283016,0.0,0.92772609,83.799973,0.91843712,378.56726,-9.2592249
179.6054,16.866594,9.1001301,0.0,0,0.89521939,0.0,0.93328327,84.444511,0.88971514,379.78555,-9.258606
179.6096,16.985617,9.1262913,0.0,0,0.86885226,0.0,0.9381218,84.675034,0.86296636,381.00381,-9.2593832
179.6138,17.077168,9.1598854,0.0,0,0.84259385,0.0,0.94225371,84.725067,0.83247346,382.2684,-9.2593956
179.618,17.193306,9.188158,0.0,0,0.81633544,0.0,0.94819957,84.801071,0.80516857,383.53656,-9.2599497
179.6222,17.286369,9.2080154,0.0,0,0.79007703,0.0,0.95253223,84.888313,0.78012788,384.1796,-9.2599649
179.6264,17.348156,9.238802,0.0,0,0.76381862,0.0,0.95590383,84.890472,0.75308692,384.3063,-9.2583055
179.6306,17.454138,9.2621479,0.0,0,0.73756027,0.0,0.96112585,84.948517,0.72761559,384.41818,-9.2587404
179.6348,17.576109,9.2812366,0.0,0,0.71130186,0.0,0.96520615,85.208229,0.70363826,384.45618,-9.2582064
179.639,17.71323,9.3158598,0.0,0,0.68504345,0.0,0.96939158,85.526573,0.67896861,384.49417,-9.2580147
179.6432,17.799082,9.3395205,0.0,0,0.6587851,0.0,0.97441316,85.580727,0.65129161,384.88058,-9.2591105
179.6474,17.93684,9.3573971,0.0,0,0.6325267,0.0,0.97876054,85.851097,0.62881303,385.362,-9.2579021
179.6516,18.104185,9.3861771,0.0,0,0.60626829,0.0,0.98205233,86.338989,0.60217506,385.83316,-9.2578382
179.6558,18.313545,9.413003,0.0,0,0.58003461,0.0,0.98771912,86.806328,0.57547629,386.28922,-9.2591324
179.66,18.502594,9.4364815,0.0,0,0.55503875,0.0,0.99274153,87.252052,0.54630315,386.76279,-9.2592525
179.6642,18.623491,9.4664469,0.0,0,0.53004873,0.0,0.99612093,87.554985,0.51868439,387.95364,-9.2577791
179.6684,17.931112,9.4844017,0.0,0,0.50505871,0.0,1.0001694,84.02932,0.50027817,389.1445,-9.2587881
179.6726,17.059801,9.4836321,0.0,0,0.48006868,0.0,1.0015273,79.833,0.48263559,390.48196,-9.2603321
179.6768,16.594059,9.4945107,0.0,0,0.45507869,0.0,1.001376,77.633041,0.47208616,391.90085,-9.2598267
179.681,16.255682,9.5007381,0.0,0,0.4300887,0.0,1.0032711,75.877541,0.45545632,393.22018,-9.2613745
179.6852,15.942345,9.4988298,0.0,0,0.40509868,0.0,1.0040941,74.385704,0.43651491,394.25903,-9.2611322
179.6894,15.45685,9.5093184,0.0,0,0.38010871,0.0,1.0039186,72.143806,0.42838997,395.29788,-9.2610703
179.6936,15.006159,9.5147228,0.0,0,0.35511869,0.0,1.0056416,69.876678,0.42087689,396.22455,-9.2611599
179.6978,14.665904,9.5058289,0.0,0,0.33012873,0.0,1.0055817,68.317604,0.41771358,397.13608,-9.2616825
179.702,14.518864,9.5109625,0.0,0,0.30513871,0.0,1.0044672,67.733337,0.40564752,397.927,-9.2619667
179.7062,14.480327,9.5143204,0.0,0,0.28028375,0.0,1.0057113,67.455025,0.38818124,398.59726,-9.2619581
179.7104,14.671547,9.5112705,0.0,0,0.25652012,0.0,1.0064148,68.24839,0.3618581,399.24796,-9.2614613
179.7146,14.882543,9.5204229,0.0,0,0.23275654,0.0,1.006152,69.298065,0.32827032,399.75363,-9.2603817
179.7188,15.027447,9.5249577,0.0,0,0.20899299,0.0,1.0075154,69.861053,0.29358292,400.25931,-9.2600145
179.723,15.09922,9.521512,0.0,0,0.18522939,0.0,1.008343,70.130768,0.26301745,400.66235,-9.2602177
179.7272,15.119182,9.5259171,0.0,0,0.16146579,0.0,1.0072043,70.290428,0.23503688,401.02896,-9.2607813
179.7314,15.100273,9.5308352,0.0,0,0.13770218,0.0,1.00862,70.086372,0.20880727,401.3956,-9.2606764
179.7356,15.058521,9.5275307,0.0,0,0.11393858,0.0,1.0094285,69.875946,0.18436413,401.76221,-9.2605333
179.7398,14.997149,9.536809,0.0,0,0.090174973,0.0,1.0092238,69.645088,0.16100083,402.12885,-9.2599678
179.744,14.922432,9.5389919,0.0,0,0.066411369,0.0,1.0098448,69.223846,0.13820301,402.43378,-9.2598734
179.7482,14.835079,9.5355015,0.0,0,0.042647772,0.0,1.0111706,68.70591,0.11924077,402.73718,-9.2597275
179.7524,14.746037,9.537529,0.0,0,0.018884173,0.0,1.0095958,68.415695,0.10041898,402.97284,-9.2610073
179.7566,14.68515,9.5426159,0.0,0,-0.0047604209,0.0,1.0108198,68.066666,0.081882812,403.16248,-9.2616396
179.7608,14.618263,9.5435619,0.0,0,-0.02794442,0.0,1.0124526,67.603004,0.062430624,403.34396,-9.2608566
179.765,14.519408,9.5441446,0.0,0,-0.051128417,0.0,1.0105247,67.26561,0.048168842,403.49567,-9.2621841
179.7692,14.41052,9.5556049,0.0,0,-0.074312419,0.0,1.0128351,66.644051,0.034812383,403.64737,-9.2609339
179.7734,14.286444,9.5423861,0.0,0,-0.097496413,0.0,1.0122317,66.092484,0.020399505,403.75696,-9.2595377
179.7776,14.17064,9.5487165,0.0,0,0.20877577,400.0,1.0115267,65.626709,0.009662848,403.85809,-9.2606487
179.7818,13.933499,9.5502176,0.0,0,0.96941304,400.0,1.0120618,64.530403,0.006375242,403.98782,-9.2608194
179.786,11.135262,9.5374498,0.0,0,1.7300493,400.0,1.0113173,51.735794,0.12958287,404.15216,-9.262578
179.7902,6.3357997,9.5242596,0.0,0,2.4906862,400.0,1.0069659,29.752335,0.38311672,404.31561,-9.2648191
179.7944,-0.066092603,9.4080162,0.0,0,3.2513227,400.0,0.98609442,-0.40111345,1.1543264,404.46732,-9.2723627
179.7986,-0.061263658,9.4312887,0.0,0,4.0119596,400.0,0.99184722,-0.16726224,2.4430623,404.61899,-9.270133
179.8028,0.11536741,9.4908733,0.0,0,4.7725964,400.0,1.0014479,0.38656631,3.3714793,404.43027,-9.2699509
179.807,0.020585746,9.5032959,0.0,0,5.5332332,400.0,1.0033153,0.094515853,4.1064258,404.08896,-9.2687273
179.8112,-0.021717144,9.5017128,0.0,0,6.2938704,400.0,1.0045837,-0.15506305,4.8185782,403.8063,-9.268074
179.8154,0.022469077,9.503274,0.0,0,7.0545073,400.0,1.0031251,0.13493407,5.5364718,403.6546,-9.2658281
179.8196,0.010777238,9.5100098,0.0,0,7.8151436,400.0,1.0041851,0.078915231,6.298048,403.5029,-9.2660666
179.8238,-0.11256981,9.4973011,0.0,0,8.5757809,400.0,1.0040154,-0.55488157,7.0856085,403.65643,-9.2656126
179.828,-0.059126034,9.4980936,0.0,0,9.3364182,400.0,1.0024252,-0.28066024,7.8963523,403.8334,-9.2651339
179.8322,0.027020404,9.4996824,0.0,0,10.097054,400.0,1.0026375,0.11626597,8.6953096,403.95502,-9.2654305
179.8364,-0.087298349,9.4983587,0.0,0,10.857692,400.0,1.0041106,-0.38897103,9.4735575,404.03085,-9.2649803
179.8406,0.044350289,9.4999666,0.0,0,11.618328,400.0,1.002802,0.14768192,10.240887,404.06244,-9.264081
179.8448,-0.042811241,9.5065279,0.0,0,12.378964,400.0,1.0034436,-0.25166887,10.994958,403.87283,-9.2643118
179.849,-0.04875223,9.4946823,0.0,0,13.139602,400.0,1.0036225,-0.19919105,11.7491,403.6832,-9.264432
179.8532,-0.036447126,9.4956217,0.0,0,13.900239,400.0,1.0021528,-0.11390155,12.485586,403.42404,-9.2644186
179.8574,-0.079508997,9.5007668,0.0,0,14.660876,400.0,1.0027714,-0.28582397,13.229802,403.1459,-9.2639828
179.8616,-0.067588001,9.4948826,0.0,0,15.421513,400.0,1.0034347,-0.34850362,13.997268,403.1492,-9.2637787
179.8658,0.060969114,9.4979973,0.0,0,16.18215,400.0,1.0026935,0.26661074,14.766335,403.56641,-9.263751
179.87,0.0074454844,9.5048199,0.0,0,16.942787,400.0,1.0031397,-0.039351642,15.533845,403.97879,-9.2638407
179.8742,-0.018170921,9.4974394,0.0,0,17.703424,400.0,1.003873,-0.049074709,16.301212,404.1937,-9.2640581
179.8784,0.051060606,9.4953136,0.0,0,18.0,400.0,1.002102,0.18506238,17.067583,404.4086,-9.262908
179.8826,-0.092472576,9.5034475,0.0,0,18.0,400.0,1.003193,-0.44919291,17.765034,404.30658,-9.2646179
179.8868,0.025572252,9.4979801,0.0,0,18.0,400.0,1.0041108,0.1363807,18.27832,404.02844,-9.2671251
179.891,-0.017326659,9.5077286,0.0,0,18.0,400.0,1.0043342,-0.081234381,18.449257,403.80954,-9.2735586
179.8952,0.052564133,9.5306225,0.0,0,18.0,400.0,1.0078982,0.24730484,18.318764,403.75739,-9.2888832
179.8994,0.30761105,9.5446014,0.0,0,18.0,400.0,1.0126312,1.3649107,18.144936,403.70523,-9.3101835
179.9036,0.63668489,9.5611334,0.0,0,18.0,400.0,1.0143242,2.8978004,18.067261,403.87134,-9.3433952
179.9078,0.49719784,9.562933,0.0,0,18.0,400.0,1.0141134,2.3015571,18.069992,404.04831,-9.3794394
179.912,0.47438663,9.5556068,0.0,0,18.0,400.0,1.0147115,2.2501497,18.101068,404.11694,-9.4151211
179.9162,0.43785974,9.5583448,0.0,0,18.0,400.0,1.0136825,2.0709941,18.127371,404.10431,-9.4490433
179.9204,0.41050476,9.5700397,0.0,0,18.0,400.0,1.0150162,1.9057063,18.135967,404.07962,-9.4793692
179.9246,0.42951858,9.5606766,0.0,0,18.0,400.0,1.0155188,1.9739372,18.135925,404.00375,-9.5104523
179.9288,0.48236629,9.5575228,0.0,0,18.0,400.0,1.013862,2.1848612,18.133665,403.92789,-9.5416384
179.933,0.52063459,9.5653543,0.0,0,18.0,400.0,1.0145794,2.391186,18.132795,404.01581,-9.5709877
179.9372,0.52538878,9.55863,0.0,0,18.0,400.0,1.0149517,2.4207644,18.124981,404.14224,-9.6020432
179.9414,0.50691903,9.5613766,0.0,0,18.0,400.0,1.0143824,2.345705,18.12121,404.25241,-9.6331921
179.9456,0.46814373,9.5687952,0.0,0,18.0,400.0,1.0145831,2.2212651,18.118671,404.34088,-9.6620064
179.9498,0.40862069,9.5624342,0.0,0,18.0,400.0,1.0158559,1.9331743,18.114712,404.42276,-9.6959028
179.954,0.43098462,9.5607786,0.0,0,18.0,400.0,1.0144619,1.9517095,18.111219,404.37219,-9.7246571
179.9582,0.47929633,9.5655241,0.0,0,18.0,400.0,1.0146496,2.1778252,18.109224,404.32162,-9.7579479
179.9624,0.51298171,9.5580282,0.0,0,18.0,400.0,1.0149583,2.3649509,18.104233,404.26263,-9.7902575
179.9666,0.52015209,9.5618639,0.0,0,18.0,400.0,1.0147924,2.3820198,18.103859,404.19943,-9.8210716
179.9708,0.52341366,9.5666552,0.0,0,18.0,400.0,1.0142554,2.4552979,18.105431,404.16873,-9.8502607
179.975,0.47289911,9.5646229,0.0,0,18.0,400.0,1.0160053,2.2276332,18.102985,404.2193,-9.8805189
179.9792,0.42717436,9.5594635,0.0,0,18.0,400.0,1.0142964,2.006799,18.101931,404.26984,-9.9116688
179.9834,0.4163239,9.5689611,0.0,0,18.0,400.0,1.0150037,1.9277922,18.101439,404.35471,-9.9433022
179.9876,0.46099225,9.5632057,0.0,0,18.0,400.0,1.015717,2.0730989,18.100754,404.44321,-9.9755363
179.9918,0.51030743,9.5624132,0.0,0,18.0,400.0,1.0147901,2.3498659,18.099119,404.47211,-10.005878
179.996,0.53278816,9.5689764,0.0,0,18.0,400.0,1.0147406,2.4786623,18.099375,404.44684,-10.038786
180.0002,0.5178467,9.5681667,0.0,0,18.0,400.0,1.0166503,2.3929546,18.094734,404.42697,-10.068099
180.0044,0.50700587,9.5598097,0.0,0,18.0,400.0,1.0143906,2.3748286,18.096008,404.43961,-10.099231
180.0086,0.45757419,9.5667295,0.0,0,18.0,400.0,1.0147017,2.1463151,18.089491,404.45224,-10.130404
180.0128,0.42703044,9.5645142,0.0,0,18.0,400.0,1.0158728,1.9585907,18.092514,404.47452,-10.159883
180.017,0.4732998,9.5630751,0.0,0,18.0,400.0,1.0150076,2.1913619,18.088236,404.49982,-10.192658
180.0212,0.53501773,9.5732012,0.0,0,18.0,400.0,1.0154327,2.4293115,18.084652,404.52029,-10.225123
180.0254,0.54489487,9.5660019,0.0,0,18.0,400.0,1.0161774,2.4704595,18.084803,404.53293,-10.254699
180.0296,0.55358237,9.5622253,0.0,0,18.0,400.0,1.014979,2.5794079,18.086187,404.54556,-10.285082
180.0338,0.5360077,9.5689964,0.0,0,18.0,400.0,1.0149806,2.4789848,18.084299,404.54556,-10.317859
180.038,0.4756735,9.5647326,0.0,0,18.0,400.0,1.0158101,2.2453907,18.083759,404.54556,-10.348381
180.0422,0.44895819,9.5644722,0.0,0,18.0,400.0,1.015492,2.0839307,18.081341,404.53775,-10.378713
180.0464,0.4554812,9.573287,0.0,0,18.0,400.0,1.0155255,2.0664027,18.077068,404.52512,-10.409905
180.0506,0.51733828,9.5669413,0.0,0,18.0,400.0,1.016475,2.3259819,18.081219,404.5275,-10.441368
180.0548,0.55982023,9.5629616,0.0,0,18.0,400.0,1.0150818,2.5675111,18.07671,404.57806,-10.470629
180.059,0.55316359,9.5650444,0.0,0,18.0,400.0,1.0142562,2.5670328,18.075338,404.62863,-10.501316
180.0632,0.544213,9.5662851,0.0,0,18.0,400.0,1.0161241,2.5274732,18.075802,404.6684,-10.532682
180.0674,0.50360703,9.5630331,0.0,0,18.0,400.0,1.015236,2.4078653,18.072512,404.70633,-10.565956
180.0716,0.4454844,9.5725508,0.0,0,18.0,400.0,1.015046,2.1099825,18.069571,404.73221,-10.595786
180.0758,0.45646,9.570734,0.0,0,18.0,400.0,1.0169413,2.1098859,18.075102,404.74484,-10.626906
180.08,0.52801585,9.5618515,0.0,0,18.0,400.0,1.015039,2.3623211,18.069723,404.75629,-10.658022
180.0842,0.55646491,9.5677328,0.0,0,18.0,400.0,1.0147424,2.5359933,18.070122,404.75629,-10.690014
180.0884,0.58259255,9.5640612,0.0,0,18.0,400.0,1.015563,2.668364,18.065666,404.75629,-10.719414
180.0926,0.55704325,9.5645847,0.0,0,18.0,400.0,1.0156721,2.6036742,18.072592,404.72015,-10.748615
180.0968,0.51009083,9.5724144,0.0,0,18.0,400.0,1.0151186,2.4102483,18.067921,404.66959,-10.781809
180.101,0.48358813,9.5698004,0.0,0,18.0,400.0,1.0168719,2.2413294,18.069105,404.64008,-10.812225
180.1052,0.45999265,9.5616913,0.0,0,18.0,400.0,1.0151731,2.1341193,18.061115,404.65271,-10.844913
180.1094,0.49635336,9.567894,0.0,0,18.0,400.0,1.0146441,2.2343707,18.065157,404.66534,-10.876605
180.1136,0.56216705,9.5666094,0.0,0,18.0,400.0,1.0161514,2.5839012,18.060339,404.67801,-10.906241
180.1178,0.56862849,9.5634975,0.0,0,18.0,400.0,1.0155568,2.661346,18.061642,404.69064,-10.936975
180.122,0.57052445,9.570569,0.0,0,18.0,400.0,1.0148554,2.5910871,18.060135,404.68161,-10.968219
180.1262,0.55497611,9.5693121,0.0,0,18.0,400.0,1.0164444,2.5948205,18.05652,404.65634,-10.999865
180.1304,0.48263583,9.5634708,0.0,0,18.0,400.0,1.0155637,2.2962875,18.059031,404.64069,-11.030736
180.1346,0.47431487,9.571641,0.0,0,18.0,400.0,1.015494,2.212955,18.05447,404.66595,-11.061658
180.1388,0.50510246,9.5659161,0.0,0,18.0,400.0,1.0158517,2.2699437,18.0571,404.69125,-11.093209
180.143,0.5596149,9.5638409,0.0,0,18.0,400.0,1.0157037,2.5171678,18.053759,404.737,-11.125247
180.1472,0.59326398,9.5708275,0.0,0,18.0,400.0,1.0150577,2.6921031,18.053453,404.78757,-11.156029
180.1514,0.59237921,9.5681868,0.0,0,18.0,400.0,1.0162847,2.7143259,18.053358,404.83813,-11.184704
180.1556,0.56548882,9.5612955,0.0,0,18.0,400.0,1.0152518,2.6305203,18.0488,404.88873,-11.216503
180.1598,0.51375198,9.5716963,0.0,0,18.0,400.0,1.015462,2.3900614,18.047974,404.93509,-11.248238
180.164,0.48393822,9.5661297,0.0,0,18.0,400.0,1.0158163,2.2537959,18.05113,404.89716,-11.278323
180.1682,0.48399419,9.5643969,0.0,0,18.0,400.0,1.0159827,2.2196367,18.047037,404.85922,-11.310934
180.1724,0.54795384,9.5734816,0.0,0,18.0,400.0,1.0154251,2.4880586,18.04911,404.80444,-11.340029
180.5757,0.48056754,9.5732117,0.0,0,18.0,0.0014183701,1.0166802,2.214803,18.012403,383.75864,-11.481264
182.6757,0.49744493,9.5930567,0.0,0,18.0,3.2689678000000003e-32,1.0204577,2.2837036,17.999371,331.21271,-11.481085
184.7757,0.50487947,9.6073713,0.0,0,18.0,1.4012985e-45,1.0229264,2.3173351,17.999449,295.29349,-11.481408
186.8757,0.53065193,9.6192579,0.0,0,18.0,1.4012985e-45,1.0252388,2.4245894,18.000828,269.06549,-11.481117
188.9757,0.54693627,9.6297827,0.0,0,18.0,1.4012985e-45,1.0271505,2.493572,18.000587,248.46774,-11.480865
191.0757,0.5669145,9.6390076,0.0,0,18.0,1.4012985e-45,1.0289896,2.5779343,18.000433,231.5045,-11.481149
193.1757,0.57284653,9.648262,0.0,0,18.0,1.4012985e-45,1.0305556,2.6058068,17.999979,217.23874,-11.481711
195.2757,0.57918513,9.6569023,0.0,0,18.0,1.4012985e-45,1.0322723,2.6283698,17.999763,204.72615,-11.481098
197.3757,0.59716243,9.664238,0.0,0,18.0,1.4012985e-45,1.0336063,2.7068675,17.999767,193.63988,-11.481273
199.4757,0.60790616,9.6716805,0.0,0,18.0,1.4012985e-45,1.0350884,2.7528172,18.000355,183.70024,-11.480736
201.5757,0.62497616,9.6793623,0.0,0,18.0,1.4012985e-45,1.0363734,2.8251517,17.99934,174.3806,-11.481202
203.6757,0.63824409,9.6856823,0.0,0,18.0,1.4012985e-45,1.0376768,2.8810167,18.000725,166.02534,-11.481941
205.7757,0.63704467,9.6918592,0.0,0,18.0,1.4012985e-45,1.0387855,2.8724864,17.999355,158.02864,-11.481974
207.8757,0.65673047,9.6987877,0.0,0,18.0,1.4012985e-45,1.0401852,2.9586833,17.999285,150.77359,-11.481672
209.9757,0.66224074,9.7042961,0.0,0,18.0,1.4012985e-45,1.0410651,2.9794803,17.99954,143.93091,-11.481235
212.0757,0.66619146,9.7101955,0.0,0,18.0,1.4012985e-45,1.0423425,2.9881377,17.999811,137.28931,-11.480795
214.1757,0.6767869,9.7156687,0.0,0,18.0,1.4012985e-45,1.0432918,3.0340605,17.99966,131.19128,-11.481291
216.2757,0.69565088,9.7204971,0.0,0,18.0,1.4012985e-45,1.0442528,3.1186635,17.998903,125.60201,-11.481906
218.3757,0.69996208,9.725668,0.0,0,18.0,1.4012985e-45,1.0451012,3.1334605,17.999544,120.34779,-11.482428
220.4757,0.70880473,9.7306805,0.0,0,18.0,1.4012985e-45,1.0462067,3.1701875,17.999937,115.3772,-11.482278
222.5757,0.71422493,9.734726,0.0,0,18.0,1.4012985e-45,1.046885,3.1903763,17.999685,110.57408,-11.481441
224.6757,0.71838331,9.7386198,0.0,0,18.0,1.4012985e-45,1.0477247,3.2111809,17.999933,106.0479,-11.480575
226.7757,0.72457552,9.7434683,0.0,0,18.0,1.4012985e-45,1.048468,3.2374279,18.00041,101.69053,-11.480554
228.8757,0.7442944,9.7472162,0.0,0,18.0,1.4012985e-45,1.049346,3.3217485,17.999889,97.701736,-11.48102
230.9757,0.75074208,9.7513008,0.0,0,18.0,1.4012985e-45,1.0500466,3.3481307,17.99984,93.885536,-11.482072
233.0757,0.75007087,9.7541933,0.0,0,18.0,1.4012985e-45,1.0507333,3.338284,18.000624,90.318199,-11.482496
235.1757,0.75919962,9.7580433,0.0,0,18.0,1.4012985e-45,1.0512781,3.38222,18.000769,86.951195,-11.48283
237.2757,0.75841278,9.761447,0.0,0,18.0,1.4012985e-45,1.0520288,3.3756847,17.999485,83.760666,-11.482646
239.3757,0.75794899,9.7639627,0.0,0,18.0,1.4012985e-45,1.0524918,3.3700984,18.000921,80.687798,-11.481622
240.1757,0.75817239,9.7657213,0.0,0,18.0,1.4012985e-45,1.0528439,3.3687646,18.000263,79.590889,-11.481425