File: examples/dan-msc-case-studies/CS3/data/01 raw data/baron_test_022.csv
Time(sec),Force(kN),Jaw(mm),PowAngle(deg),Power(W),Pram,PTemp,Strain,Stress(MPa),Stroke(mm),TC1(C),wedge(mm)
0.0,0.23292203,0.046516415,0.0,0,10.594783,0.0016184063,0.0031134628,2.9457119,10.59502,26.583063,-9.1187077
2.2,0.15495275,0.0011992431,0.0,0,10.594783,6.5159006,0.00010141873,1.9730626,10.595531,26.481653,-9.4880857
4.4,0.12638126,0.0012935804,0.0,0,10.594783,13.115902,9.5849326e-05,1.6184194,10.594667,26.429537,-9.4852171
6.6,0.10452544,0.0013929552,0.0,0,10.594783,19.715906,8.9466339e-05,1.3187374,10.594304,26.448135,-9.4806938
8.8,0.083990104,0.0013365546,0.0,0,10.594783,26.315908,8.4022082e-05,1.0590172,10.595332,26.34593,-9.4768639
11.0,0.072904192,0.0014436248,33.225624,0,10.594783,32.915901,0.00010614705,0.93296212,10.593966,26.381304,-9.4734278
13.2,0.067472935,0.0010409758,49.153629,0,10.594783,39.515915,7.0081558e-05,0.86191642,10.594069,27.717937,-9.4692373
15.4,0.063478783,-0.0019831369,58.562126,0,10.594783,46.115917,-0.00013957078,0.81629705,10.593967,31.326979,-9.4654074
17.6,0.089456059,-0.0065503176,64.780754,0,10.594783,52.715923,-0.00045872398,1.135923,10.594739,37.079472,-9.4616671
19.8,0.12896803,-0.012344522,68.654953,0,10.594783,59.315922,-0.00082912674,1.6458457,10.594797,45.259346,-9.4585018
22.0,0.14074226,-0.019883612,70.715164,0,10.594783,65.915916,-0.0013282542,1.7862678,10.595684,55.479214,-9.4546814
24.2,0.16093294,-0.027549775,71.139839,0,10.594783,72.51593,-0.0018266618,2.0467637,10.595056,67.122757,-9.4506216
26.4,0.17421712,-0.03565808,70.30616,0,10.594783,79.115929,-0.0023619686,2.2192235,10.594714,79.152695,-9.4462061
28.6,0.19265468,-0.042157803,68.383469,0,10.594783,85.715927,-0.002794005,2.4594147,10.594851,90.121964,-9.4428387
30.8,0.19937922,-0.048330694,65.712341,0,10.594783,92.315926,-0.003212041,2.5260999,10.594324,99.521584,-9.4393387
33.0,0.19527374,-0.053515237,62.963642,0,10.594783,98.915932,-0.0035594504,2.497716,10.594644,106.79646,-9.4356956
35.2,0.17064947,-0.056827575,60.560944,0,10.594783,105.51592,-0.0037807426,2.1843858,10.595072,112.25491,-9.4315557
37.4,0.15297824,-0.059768952,59.555233,0,10.594783,112.11593,-0.0039655929,1.9540595,10.593866,116.3968,-9.4278164
39.6,0.13896005,-0.062422,60.057751,0,10.594783,118.71593,-0.0041612373,1.7739942,10.594863,119.70822,-9.4241514
41.8,0.13482822,-0.064516827,61.889343,0,10.594783,125.31594,-0.0043025953,1.7190188,10.59482,122.91133,-9.4206305
44.0,0.12881649,-0.068084031,64.344757,0,10.594783,131.91594,-0.0045442837,1.6416036,10.594232,126.74902,-9.4170866
46.2,0.13031316,-0.072284721,66.858963,0,10.594783,138.51595,-0.0048218123,1.6787019,10.594108,131.69131,-9.412693
48.4,0.16955258,-0.077657856,68.815765,0,10.594783,145.11595,-0.0051675979,2.1627328,10.595246,138.21306,-9.4088001
50.6,0.18419944,-0.083262481,70.015808,0,10.594783,151.71594,-0.0055244868,2.34951,10.59429,146.16718,-9.4051924
52.8,0.2005036,-0.09019541,70.575012,0,10.594783,158.31592,-0.0059802821,2.5835485,10.59492,154.92314,-9.4017935
55.0,0.20124976,-0.097476408,70.304276,0,10.594783,164.91592,-0.006465775,2.5856655,10.594056,164.0945,-9.3979759
57.2,0.2103017,-0.10417449,69.635704,0,10.594783,171.51596,-0.0069195847,2.6804361,10.594844,172.73058,-9.3944101
59.4,0.20456666,-0.11021101,68.818382,0,10.594783,178.11595,-0.0073223729,2.6108978,10.593907,180.53917,-9.3902893
61.6,0.21087277,-0.11578074,67.874435,0,10.594783,184.71596,-0.007679319,2.7129138,10.594332,187.65614,-9.3861694
63.8,0.21405154,-0.12178058,67.225449,0,10.594783,191.31596,-0.0080833798,2.7470555,10.594635,193.95454,-9.3829308
66.0,0.1985015,-0.12563093,66.746887,0,10.594783,197.91595,-0.0083513353,2.5591869,10.594948,199.82919,-9.3795195
68.2,0.21079779,-0.1304141,66.884758,0,10.594783,204.51596,-0.0086672427,2.7063601,10.594865,205.08545,-9.3761435
70.4,0.18390746,-0.13560982,67.225342,0,10.594783,211.11595,-0.0090189995,2.3652234,10.594747,210.62773,-9.3720398
72.6,0.2006869,-0.14008661,67.857109,0,10.594783,217.71594,-0.0093043791,2.5704517,10.594749,216.32256,-9.3678522
74.8,0.2130201,-0.14532475,68.510742,0,10.594783,224.31596,-0.0096431281,2.7464426,10.594548,222.16408,-9.3640537
77.0,0.21587764,-0.15087052,69.268791,0,10.594783,230.91597,-0.010005553,2.7916596,10.594764,228.36401,-9.3607721
79.2,0.22278699,-0.15827186,69.862053,0,10.594783,237.51596,-0.01049185,2.8624957,10.595365,235.31985,-9.3577518
81.4,0.22220808,-0.16351599,70.154297,0,10.594783,244.11598,-0.0108291,2.839854,10.594741,242.62456,-9.3542633
83.6,0.2186958,-0.16940756,70.301506,0,10.594783,250.71597,-0.011214866,2.8115935,10.594824,249.66652,-9.3502417
85.8,0.22200036,-0.17517376,70.445854,0,10.594783,257.31622,-0.01160332,2.8583229,10.594744,256.40182,-9.3462896
88.0,0.21857144,-0.18140262,70.684677,0,10.594783,263.91595,-0.012016718,2.8146114,10.595504,263.07718,-9.3419142
90.2,0.21999685,-0.18758123,70.718987,0,10.594783,270.51593,-0.012423785,2.8281865,10.595066,270.01944,-9.3383589
92.4,0.22175293,-0.19384284,70.719185,0,10.594783,277.11597,-0.012832338,2.8609688,10.595264,276.87503,-9.3352318
94.6,0.22571968,-0.20037551,70.719002,0,10.594783,283.71597,-0.01327196,2.9027071,10.59516,283.74002,-9.3319683
96.8,0.22035506,-0.20676593,70.57618,0,10.594783,290.31598,-0.013698942,2.8364406,10.595293,290.68817,-9.3285971
99.0,0.22038276,-0.21407202,70.446381,0,10.594783,296.91599,-0.014185134,2.8510523,10.59646,297.21185,-9.3245049
101.2,0.22873196,-0.2198143,70.576164,0,10.594783,303.51599,-0.014567545,2.9412558,10.594404,303.45627,-9.3201904
103.4,0.2267497,-0.22518177,70.718987,0,10.594783,310.116,-0.014908273,2.9198818,10.5954,309.61703,-9.3162556
105.6,0.22326647,-0.23161778,70.993652,0,10.594783,316.71597,-0.015319901,2.8774776,10.594379,315.84409,-9.3126354
107.8,0.2175559,-0.23784734,71.136467,0,10.594783,323.31595,-0.015718183,2.8249068,10.594295,322.54617,-9.3089552
110.0,0.22721025,-0.24419478,71.411125,0,10.594783,329.91599,-0.016132288,2.9284863,10.594518,328.92776,-9.3060732
112.2,0.22578721,-0.25153661,71.674797,0,10.594783,336.51599,-0.016625056,2.9121442,10.595018,335.50229,-9.3019781
114.4,0.22859839,-0.25701448,71.938469,0,10.594783,343.11603,-0.016991382,2.9593337,10.595271,342.03601,-9.2984333
116.6,0.21468072,-0.2636342,72.070305,0,10.594783,349.71603,-0.017415561,2.8118465,10.59437,348.85184,-9.2948332
118.8,0.21930085,-0.27010223,72.322197,0,10.594783,356.31601,-0.01783338,2.8537464,10.594395,355.38132,-9.2912292
121.0,0.21898355,-0.27632686,72.468002,0,10.594783,362.91599,-0.018256053,2.830442,10.595002,362.00381,-9.2871981
123.2,0.23025671,-0.28371519,72.707512,0,10.594783,369.51596,-0.018745735,2.9941449,10.594953,368.66055,-9.2833805
125.4,0.23058908,-0.28912309,72.839348,0,10.594783,376.11597,-0.019100053,3.0139909,10.59461,375.24429,-9.279851
127.6,0.21869905,-0.29609862,73.081055,0,10.594783,382.71597,-0.019562814,2.8473332,10.594675,381.71353,-9.2761221
129.8,0.22362892,-0.30275562,73.454422,0,10.594783,389.31598,-0.019991068,2.9163437,10.595448,387.96967,-9.2722902
132.0,0.22305924,-0.31059682,73.817131,0,10.594783,395.91602,-0.020511391,2.8956277,10.595198,394.3309,-9.2683048
134.2,0.22808868,-0.31703782,73.455315,0,10.594783,399.99893,-0.02092002,2.9711382,10.594902,400.9697,-9.2661924
136.4,0.22177872,-0.32272586,70.999031,0,10.594783,399.99893,-0.021274857,2.8817289,10.594633,406.89221,-9.2659187
138.6,0.21373218,-0.32591265,67.564949,0,10.594783,399.99893,-0.021479812,2.7893112,10.593579,410.6409,-9.2660179
140.8,0.21399073,-0.3276473,63.584126,0,10.594783,399.99893,-0.021592129,2.7822065,10.594491,411.74249,-9.2665148
143.0,0.17206001,-0.32596943,60.090763,0,10.594783,399.99893,-0.021492414,2.2399457,10.594809,410.11551,-9.2658386
145.2,0.2381836,-0.3223179,58.478352,0,10.594783,399.99893,-0.02125898,3.1072924,10.594827,406.25888,-9.2657557
147.4,0.2745457,-0.3189885,58.713188,0,10.594783,399.99893,-0.02103824,3.5716774,10.595157,402.17474,-9.2662535
149.6,0.28226194,-0.31734994,60.31126,0,10.594783,399.99893,-0.020924667,3.6805685,10.594689,398.69278,-9.2661648
151.8,0.28689918,-0.31692663,62.518745,0,10.594783,399.99893,-0.020896191,3.7365479,10.594833,396.08017,-9.266221
154.0,0.32197651,-0.3169907,64.284332,0,10.594783,399.99893,-0.020911146,4.1756678,10.594871,395.41898,-9.2663555
156.2,0.34200883,-0.31864285,65.299698,0,10.594783,399.99893,-0.021027889,4.4393072,10.59507,396.36404,-9.2659101
158.4,0.34844866,-0.3210302,65.478508,0,10.594783,399.99893,-0.021188758,4.5266008,10.593712,398.0853,-9.2661591
160.6,0.34722799,-0.32405612,65.123344,0,10.594783,399.99893,-0.021391522,4.5117373,10.594833,399.85141,-9.2656517
162.8,0.35908082,-0.32673171,64.555672,0,10.594783,399.99893,-0.02156575,4.680203,10.596403,401.19019,-9.2654638
165.0,0.36067012,-0.32731357,63.57851,0,10.594783,399.99893,-0.021602631,4.6848669,10.594596,402.04211,-9.2659597
167.2,0.35055515,-0.32827702,62.753914,0,10.594783,399.99893,-0.021653058,4.5678501,10.594795,402.38123,-9.2648067
169.4,0.36848933,-0.32874283,61.989857,0,10.594783,399.99893,-0.021671467,4.8021207,10.594913,402.06482,-9.2653942
171.6,0.34024656,-0.32873037,61.790791,0,10.594783,399.99893,-0.021661168,4.4399638,10.594889,401.15073,-9.2657385
173.8,0.33520794,-0.32869151,61.907955,0,10.594783,399.99893,-0.021656686,4.34237,10.594174,400.29541,-9.2650738
176.0,0.33605719,-0.32954428,62.181107,0,10.594783,399.99893,-0.021730056,4.380775,10.594552,399.64545,-9.2647953
178.2,0.35769892,-0.32926366,62.555244,0,10.594783,399.99893,-0.021710867,4.6562314,10.595257,399.19089,-9.2652121
178.6168,0.37261105,0.0069316635,0.62514615,0,10.5948,9.9926843e-21,0.00067009847,4.7701416,10.596621,399.21875,-9.264348
178.6212,0.36419511,0.0061813667,0.0,0,10.5948,0.0,0.00060199347,4.7389216,10.594922,399.17902,-9.2653027
178.6256,0.35779068,0.0047995318,0.0,0,10.5948,0.0,0.00052242045,4.5409107,10.593783,399.13928,-9.2661066
178.63,0.3516762,0.0063706106,0.0,0,10.5948,0.0,0.00053503341,4.510519,10.595116,399.14621,-9.2652674
178.6344,0.35527557,0.0060980963,0.0,0,10.5948,0.0,0.00043428887,4.5485716,10.594859,399.1727,-9.2641468
178.6388,0.35774258,0.0068341368,0.0,0,10.5948,0.0,0.00043929214,4.5619478,10.591956,399.17059,-9.2645273
178.6432,0.33132142,0.0071574729,0.0,0,10.5948,0.0,0.00045523583,4.2335615,10.593664,399.13086,-9.2664051
178.6476,0.32720846,0.0086527308,0.0,0,10.5948,0.0,0.00046445604,4.18574,10.594504,399.10165,-9.2649345
178.652,0.33964291,0.0076480759,0.0,0,10.5948,0.0,0.00040755433,4.4096742,10.59344,399.12814,-9.2642174
178.6564,0.3466697,0.010197651,0.0,0,10.5948,0.0,0.00050388242,4.4052844,10.596426,399.15463,-9.2662325
178.6608,0.32924187,0.0088593531,0.0,0,10.5948,0.0,0.00045832124,4.1716371,10.59387,399.15765,-9.2652273
178.6652,0.32184589,0.011700364,0.0,0,10.569862,0.0,0.00051431713,4.1423364,10.597013,399.15765,-9.2663813
178.6696,0.3188329,0.0086317956,0.0,0,10.503863,0.0,0.00036135246,4.0339055,10.597216,399.14954,-9.2652864
178.674,0.33644316,0.011459332,0.0,0,10.437862,0.0,0.00049353496,4.2858438,10.579087,399.13626,-9.2646933
178.6784,0.33120528,0.0091975313,0.0,0,10.371863,0.0,0.0005203826,4.2718697,10.521567,399.14108,-9.266283
178.6828,0.31666589,0.011276965,0.0,0,10.305863,0.0,0.00061715278,3.9506571,10.419174,399.18082,-9.2652721
178.6872,0.32625985,0.0088875452,0.0,0,10.239863,0.0,0.00054861105,4.1518888,10.319992,399.22055,-9.2645655
178.6916,0.33086428,0.012427486,0.0,0,10.173863,0.0,0.00071893266,4.2392125,10.243093,399.26028,-9.2648573
178.696,0.33525136,0.0079813544,0.0,0,10.107863,0.0,0.00056407083,4.3792763,10.191468,399.30002,-9.2658548
178.7004,0.32605249,0.010005056,0.0,0,10.041862,0.0,0.00080020755,4.2512054,10.142167,399.25546,-9.2664557
178.7048,0.36404741,0.0077673369,0.0,0,9.9758625,0.0,0.00061119796,4.6287713,10.075809,399.18924,-9.2649708
178.7092,1.7854232,0.017519219,0.0,0,9.9098625,0.0,0.0013350735,22.280228,10.011236,399.31686,-9.2639523
178.7136,4.4382167,0.046013638,0.0,0,9.8438625,0.0,0.0031264455,56.099869,9.9560013,399.62146,-9.2628956
178.718,5.4765368,0.11374047,0.0,0,9.7778625,0.0,0.0077836234,69.103569,9.8761663,399.97574,-9.2623701
178.7224,6.0250735,0.18527895,0.0,0,9.7118626,0.0,0.01256878,75.638496,9.7948799,400.47903,-9.2605743
178.7268,6.27456,0.2496089,0.0,0,9.6458626,0.0,0.017009815,78.484123,9.7237692,400.9823,-9.2607403
178.7312,6.438272,0.309356,0.0,0,9.5798626,0.0,0.020955589,80.263222,9.6586933,401.17496,-9.2601738
178.7356,6.5594258,0.3702853,0.0,0,9.5138626,0.0,0.025128497,81.457947,9.5965309,401.36038,-9.2627106
178.74,6.7538543,0.43553889,0.0,0,9.4486961,0.0,0.02953844,83.347954,9.5307398,401.50848,-9.26334
178.7444,6.8571687,0.49955958,0.0,0,9.3843145,0.0,0.03390998,84.357613,9.4663248,401.6409,-9.2618389
178.7488,6.9375072,0.56779957,0.0,0,9.3199339,0.0,0.038539317,84.984062,9.399744,401.78479,-9.262639
178.7532,6.9973211,0.62983304,0.0,0,9.2555532,0.0,0.042839445,85.360817,9.3303165,401.94373,-9.2613859
178.7576,7.0971141,0.70030034,0.0,0,9.1911726,0.0,0.047688585,86.124619,9.2624865,402.10477,-9.2628937
178.762,7.1632614,0.76169872,0.0,0,9.126792,0.0,0.051947974,86.568619,9.1962423,402.27692,-9.2618685
178.7664,7.2052908,0.82747567,0.0,0,9.0624104,0.0,0.056537636,86.754715,9.1291895,402.4491,-9.2627373
178.7708,7.2420483,0.88874847,0.0,0,8.9980307,0.0,0.060884979,86.805183,9.0655365,402.63303,-9.262434
178.7752,7.3172941,0.957394,0.0,0,8.93365,0.0,0.065605238,87.285469,8.9962482,402.81845,-9.2623568
178.7796,7.3904648,1.0154713,0.0,0,8.8692684,0.0,0.069922939,87.751289,8.9364548,403.01196,-9.2625484
178.784,7.4436183,1.0822749,0.0,0,8.8048878,0.0,0.074563511,87.909035,8.8708372,403.21063,-9.2609472
178.7884,7.4868841,1.1445248,0.0,0,8.7409811,0.0,0.079195857,88.070969,8.8026485,402.91711,-9.26334
178.7928,7.515017,1.211115,0.0,0,8.6797504,0.0,0.083909035,88.012871,8.7401867,401.67218,-9.2644567
178.7972,7.6051488,1.2707646,0.0,0,8.6185198,0.0,0.088373177,88.54467,8.6755934,400.41278,-9.2619085
178.8016,7.5929184,1.3337892,0.0,0,8.5572891,0.0,0.092934981,88.136246,8.6154995,398.95584,-9.2623901
178.806,7.6309257,1.3847349,0.0,0,8.4960594,0.0,0.09684132,88.114487,8.5557461,397.49887,-9.2621565
178.8104,7.6698227,1.4487509,0.0,0,8.4348288,0.0,0.10159894,88.289207,8.4950371,397.52747,-9.2623425
178.8148,7.7633877,1.504887,0.0,0,8.3735981,0.0,0.1057962,88.861389,8.4281816,397.93802,-9.2629528
178.8192,7.817678,1.5685924,0.0,0,8.3123684,0.0,0.11064193,89.119606,8.3685007,398.56326,-9.2616758
178.8236,7.8274503,1.6271237,0.0,0,8.2511387,0.0,0.1149655,88.843132,8.311039,399.38449,-9.2639437
178.828,7.8795419,1.6874293,0.0,0,8.189908,0.0,0.11963139,88.982574,8.2472496,400.11963,-9.2626953
178.8324,7.9453692,1.7510315,0.0,0,8.1286774,0.0,0.12433503,89.24585,8.1842127,400.59644,-9.2619333
178.8368,8.029254,1.8131567,0.0,0,8.0674467,0.0,0.12913071,89.854584,8.1185207,401.07321,-9.2617884
178.8412,8.0332155,1.8771809,0.0,0,8.0085573,0.0,0.13383721,89.464729,8.0520315,401.53708,-9.2609234
178.8456,8.0263262,1.9342614,0.0,0,7.9503012,0.0,0.13824122,89.121246,7.9945879,402.00061,-9.2625551
178.85,8.0508966,1.989517,0.0,0,7.8920455,0.0,0.14241451,88.813187,7.9379115,402.5015,-9.2627964
178.8544,8.1471167,2.0484786,0.0,0,7.8337889,0.0,0.14684443,89.528328,7.8799067,403.01801,-9.2624846
178.8588,8.1616526,2.104064,0.0,0,7.7755332,0.0,0.15102655,89.467041,7.8208928,403.42584,-9.262557
178.8632,8.1917858,2.1613026,0.0,0,7.7172766,0.0,0.15546727,89.264893,7.7657752,403.6907,-9.2621489
178.8676,8.2378798,2.2208152,0.0,0,7.6590209,0.0,0.15999876,89.286758,7.7057695,403.92188,-9.2620144
178.872,8.3327723,2.2749615,0.0,0,7.6007652,0.0,0.16427283,89.953308,7.6441879,403.97485,-9.2623606
178.8764,8.37918,2.3398275,0.0,0,7.5425086,0.0,0.16918758,90.137253,7.5840631,404.02786,-9.2619219
178.8808,8.3732071,2.3969109,0.0,0,7.4842529,0.0,0.17378953,89.618767,7.5261097,403.353,-9.2633476
178.8852,8.415678,2.4560275,0.0,0,7.4259968,0.0,0.17838149,89.658279,7.4700994,402.58487,-9.2624331
178.8896,8.4916201,2.5100756,0.0,0,7.368948,0.0,0.18287987,90.074303,7.4069295,401.48349,-9.2618399
178.894,8.532403,2.5731044,0.0,0,7.3135433,0.0,0.18778621,90.017319,7.345736,400.1723,-9.2621479
178.8984,8.5069389,2.6231143,0.0,0,7.2581382,0.0,0.19200212,89.449936,7.2909718,399.25848,-9.262701
178.9028,8.5387526,2.6796715,0.0,0,7.2027335,0.0,0.19648989,89.285393,7.2394953,399.11279,-9.2627172
178.9072,8.5970612,2.7306063,0.0,0,7.1473284,0.0,0.20084706,89.529762,7.1855621,399.03033,-9.2618294
178.9116,8.6800919,2.7887735,0.0,0,7.0919237,0.0,0.20556748,89.928123,7.1266828,399.81174,-9.2619143
178.916,8.7195702,2.8391802,0.0,0,7.0365186,0.0,0.20982501,90.064896,7.0769973,400.59314,-9.2627354
178.9204,8.7249289,2.899184,0.0,0,6.9811139,0.0,0.21481578,89.65274,7.0151677,401.1217,-9.2616882
178.9248,8.7833643,2.9508076,0.0,0,6.9257092,0.0,0.21910907,89.76329,6.9626198,401.58524,-9.2617922
178.9292,8.8752556,3.0057061,0.0,0,6.8703051,0.0,0.22382538,90.22963,6.9038987,402.06955,-9.2627163
178.9336,8.906127,3.0635202,0.0,0,6.8148994,0.0,0.22873332,90.243835,6.8465405,402.57281,-9.2608891
178.938,8.8898087,3.1175792,0.0,0,6.7596555,0.0,0.23326083,89.67823,6.7911143,403.11252,-9.2618551
178.9424,8.9287033,3.1684403,0.0,0,6.7069435,0.0,0.23760431,89.647751,6.7359028,403.76147,-9.261651
178.9468,8.980176,3.2221861,0.0,0,6.6542315,0.0,0.24213406,89.742889,6.680728,404.41043,-9.2611628
178.9512,9.0162678,3.273196,0.0,0,6.6015196,0.0,0.24648778,89.627029,6.6307497,404.73581,-9.2626009
178.9556,9.0319366,3.3232157,0.0,0,6.5488076,0.0,0.25069627,89.557877,6.5764456,405.05368,-9.2603359
178.96,9.070859,3.3793442,0.0,0,6.4960957,0.0,0.25532413,89.38987,6.5269985,404.63437,-9.2613411
178.9644,9.1413946,3.4290061,0.0,0,6.4433837,0.0,0.25956148,89.758293,6.4720416,403.90594,-9.2617388
178.9688,9.1993656,3.4849696,0.0,0,6.3906717,0.0,0.26436409,89.927925,6.4168711,402.64548,-9.2611618
178.9732,9.2350197,3.5405478,0.0,0,6.3379598,0.0,0.26909536,89.841537,6.361186,400.68506,-9.2632475
178.9776,9.2544365,3.5965536,0.0,0,6.2852478,0.0,0.2739327,89.592873,6.3051348,398.94803,-9.2623816
178.982,9.3053703,3.6476417,0.0,0,6.2325358,0.0,0.27833676,89.633102,6.2521958,398.39178,-9.2626133
178.9864,9.3279619,3.7012599,0.0,0,6.1798239,0.0,0.28297436,89.505821,6.1987014,397.83554,-9.2613945
178.9908,9.3467541,3.7510645,0.0,0,6.1289063,0.0,0.28742498,89.319008,6.144733,398.6413,-9.261528
178.9952,9.3358841,3.8003561,0.0,0,6.078773,0.0,0.291668,88.835045,6.1050935,399.62167,-9.2627459
178.9996,9.4658899,3.8480957,0.0,0,6.0286393,0.0,0.29619181,89.586334,6.0477686,400.27676,-9.2617874
179.004,9.4971294,3.9044237,0.0,0,5.9785056,0.0,0.30100209,89.543304,5.9972286,400.72708,-9.2618027
179.0084,9.4859085,3.9511433,0.0,0,5.9283719,0.0,0.30550319,89.029312,5.9460206,401.11417,-9.2617455
179.0128,9.5113878,4.0031347,0.0,0,5.8782387,0.0,0.31007519,88.890305,5.8973422,401.37903,-9.2621021
179.0172,9.5471201,4.0462742,0.0,0,5.828105,0.0,0.31421939,88.779251,5.8500967,401.65475,-9.2627735
179.0216,9.6569471,4.097796,0.0,0,5.7779708,0.0,0.31897217,89.326744,5.8002925,402.07855,-9.2612333
179.026,9.7038507,4.149364,0.0,0,5.727838,0.0,0.3238903,89.383087,5.7456799,402.50238,-9.2609987
179.0304,9.7098932,4.199512,0.0,0,5.6777039,0.0,0.32847828,89.084404,5.6963649,402.8735,-9.2622538
179.0348,9.7210817,4.2492738,0.0,0,5.6275702,0.0,0.33321276,88.696915,5.6424909,403.23111,-9.2620754
179.0392,9.8098583,4.2961659,0.0,0,5.5782471,0.0,0.33774951,89.013649,5.5982385,403.54022,-9.2625647
179.0436,9.839798,4.3434715,0.0,0,5.530551,0.0,0.34219116,88.99157,5.548779,403.80511,-9.2617102
179.048,9.8806391,4.3939233,0.0,0,5.4828548,0.0,0.3469764,88.921097,5.4952536,404.03357,-9.2612448
179.0524,9.8838921,4.440114,0.0,0,5.4351592,0.0,0.35135427,88.560181,5.4502468,404.15277,-9.2613029
179.0568,9.946703,4.4862208,0.0,0,5.3874631,0.0,0.35583818,88.648827,5.398921,404.27194,-9.2621536
179.0612,9.9710598,4.5366025,0.0,0,5.3397675,0.0,0.36041486,88.56115,5.3503017,404.50763,-9.2623796
179.0656,10.010112,4.5790057,0.0,0,5.2920713,0.0,0.36449102,88.553032,5.3073215,404.74603,-9.2622538
179.07,10.050517,4.6281042,0.0,0,5.2443752,0.0,0.36914521,88.474594,5.2585812,404.9751,-9.2615948
179.0744,10.059608,4.6740079,0.0,0,5.1966791,0.0,0.3733981,88.157867,5.2140946,405.20026,-9.2625227
179.0788,10.205021,4.722043,0.0,0,5.1489835,0.0,0.37803516,89.017815,5.1619325,405.35107,-9.2629099
179.0832,10.208712,4.7718945,0.0,0,5.1012869,0.0,0.38282022,88.679802,5.1156201,405.40402,-9.2615557
179.0876,10.217191,4.8202457,0.0,0,5.0535917,0.0,0.38720408,88.315491,5.0675693,405.46332,-9.2624331
179.092,10.275261,4.8654847,0.0,0,5.0081544,0.0,0.39173368,88.403954,5.0189052,405.55606,-9.2622337
179.0964,10.362219,4.9164958,0.0,0,4.9627905,0.0,0.39665681,88.72966,4.9764295,405.64877,-9.2626963
179.1008,10.416733,4.9640326,0.0,0,4.9174266,0.0,0.40147188,88.739326,4.9228907,405.5419,-9.2605019
179.1052,10.441135,5.0154133,0.0,0,4.8720622,0.0,0.40642264,88.531013,4.8744736,405.40945,-9.2611179
179.1096,10.423892,5.0562553,0.0,0,4.8266983,0.0,0.41067308,87.98877,4.8305292,405.35828,-9.2615433
179.114,10.445279,5.1040864,0.0,0,4.7813344,0.0,0.41539478,87.736855,4.7879739,405.35828,-9.2615213
179.1184,10.518983,5.1396174,0.0,0,4.7359705,0.0,0.41934088,88.057312,4.7473645,405.48923,-9.2629976
179.1228,10.568915,5.1887846,0.0,0,4.6906061,0.0,0.42418852,88.056488,4.7030592,405.87329,-9.261199
179.1272,10.620415,5.2318664,0.0,0,4.6452422,0.0,0.4287807,88.011963,4.6561847,406.25107,-9.2630558
179.1316,10.694489,5.2797003,0.0,0,4.5998783,0.0,0.4337799,88.256279,4.6072412,406.54242,-9.2616768
179.136,10.765516,5.3243399,0.0,0,4.5545144,0.0,0.43853703,88.421463,4.5648246,406.83377,-9.2613468
179.1404,10.787545,5.3736491,0.0,0,4.5104866,0.0,0.44365862,88.158165,4.5156894,406.98819,-9.2611542
179.1448,10.790113,5.4119115,0.0,0,4.4673309,0.0,0.44774655,87.770912,4.4741197,407.10742,-9.2617292
179.1492,10.866747,5.4599552,0.0,0,4.4241762,0.0,0.45292762,87.922043,4.4240565,407.17816,-9.2621174
179.1536,10.858016,5.4979773,0.0,0,4.381021,0.0,0.45696092,87.499855,4.3862004,407.20462,-9.26231
179.158,10.9264,5.5411921,0.0,0,4.3378658,0.0,0.46158239,87.681198,4.3418765,406.97284,-9.2610302
179.1624,10.949103,5.5808258,0.0,0,4.2947106,0.0,0.46569046,87.510185,4.3029447,405.96631,-9.2606831
179.1668,11.053992,5.6261954,0.0,0,4.2515554,0.0,0.47059906,87.854088,4.2556796,404.95975,-9.2622795
179.1712,11.108279,5.668673,0.0,0,4.2084002,0.0,0.47505307,87.937691,4.211576,403.13776,-9.2610083
179.1756,11.117919,5.7089863,0.0,0,4.1652451,0.0,0.47932908,87.627502,4.171349,401.29681,-9.2622795
179.18,11.161387,5.7535195,0.0,0,4.1220899,0.0,0.48401484,87.572838,4.128993,400.31436,-9.2616987
179.1844,11.252876,5.7940788,0.0,0,4.0789347,0.0,0.48817599,87.928665,4.0870166,399.69193,-9.2617455
179.1888,11.347882,5.8428836,0.0,0,4.0362892,0.0,0.4934532,88.223824,4.043426,399.62994,-9.2625933
179.1932,11.42805,5.884738,0.0,0,3.9952464,0.0,0.49787718,88.405174,3.9990704,400.30536,-9.2618542
179.1976,11.420419,5.9325156,0.0,0,3.9542034,0.0,0.50306088,87.960327,3.9532514,400.9808,-9.2631731
179.202,11.403279,5.9717207,0.0,0,3.9131598,0.0,0.50728166,87.388474,3.9108281,401.65625,-9.2625484
179.2064,11.484309,6.0155516,0.0,0,3.8721166,0.0,0.51192302,87.653221,3.8722873,402.3317,-9.2613211
179.2108,11.543486,6.0515785,0.0,0,3.8310735,0.0,0.51610392,87.717705,3.8354583,402.91324,-9.2625074
179.2152,11.613654,6.095273,0.0,0,3.7900302,0.0,0.52075171,87.862518,3.7917149,403.48273,-9.2605314
179.2196,11.638542,6.1355329,0.0,0,3.748987,0.0,0.52552348,87.572708,3.7543566,404.0766,-9.2625408
179.224,11.710314,6.1797462,0.0,0,3.7079439,0.0,0.53033829,87.74279,3.7116916,404.68585,-9.2618294
179.2284,11.82719,6.216619,0.0,0,3.6669009,0.0,0.53486592,88.179588,3.6658053,405.12802,-9.261734
179.2328,11.85055,6.263669,0.0,0,3.6258576,0.0,0.54009032,87.996101,3.6271973,405.24719,-9.2614717
179.2372,11.911929,6.2996902,0.0,0,3.5848143,0.0,0.54460895,87.978264,3.5851178,405.33389,-9.2615232
179.2416,11.961828,6.3453345,0.0,0,3.5455248,0.0,0.549779,87.859161,3.5420268,404.97632,-9.2619028
179.246,12.017795,6.381743,0.0,0,3.5064793,0.0,0.55428338,87.900185,3.5035563,404.61874,-9.262804
179.2504,12.059996,6.4209418,0.0,0,3.4674335,0.0,0.55900615,87.854858,3.46578,404.68256,-9.2609034
179.2548,12.07048,6.454761,0.0,0,3.4283879,0.0,0.56295478,87.571808,3.4307644,404.85471,-9.2616062
179.2592,12.145235,6.4929366,0.0,0,3.3893425,0.0,0.56770939,87.602898,3.392513,404.68073,-9.2608299
179.2636,12.302826,6.532927,0.0,0,3.350297,0.0,0.57257342,88.378151,3.3486507,404.1907,-9.2637434
179.268,12.314923,6.5707889,0.0,0,3.3112509,0.0,0.57694769,88.050629,3.3101339,403.6543,-9.2633772
179.2724,12.403333,6.6106534,0.0,0,3.2722054,0.0,0.58165222,88.305084,3.2727885,402.97885,-9.2616434
179.2768,12.41557,6.6497459,0.0,0,3.23316,0.0,0.58637828,87.930618,3.2326121,402.30341,-9.2624474
179.2812,12.50947,6.6892319,0.0,0,3.1941144,0.0,0.59089369,88.224289,3.1959498,403.3494,-9.2629833
179.2856,12.641917,6.728394,0.0,0,3.1550686,0.0,0.59558505,88.740479,3.151581,404.43542,-9.2616072
179.29,12.664639,6.772634,0.0,0,3.1170003,0.0,0.60071617,88.465904,3.1117399,405.35544,-9.2623196
179.2944,12.745319,6.8087749,0.0,0,3.0798554,0.0,0.60502452,88.622429,3.0694199,406.20587,-9.2621069
179.2988,12.749513,6.8483672,0.0,0,3.0427108,0.0,0.60975069,88.172386,3.0346785,406.44791,-9.2626791
179.3032,12.781111,6.8838983,0.0,0,3.0055659,0.0,0.61396891,88.022911,2.9991891,406.18304,-9.2626143
179.3076,12.828601,6.9201756,0.0,0,2.968421,0.0,0.61819082,88.029274,2.9645841,405.99399,-9.2601633
179.312,12.903563,6.9529233,0.0,0,2.9312763,0.0,0.62236851,88.196938,2.9309568,406.00723,-9.2613649
179.3164,13.010324,6.9942231,0.0,0,2.8941314,0.0,0.62717086,88.479149,2.8942895,406.02048,-9.2602987
179.3208,13.200026,7.0298376,0.0,0,2.8569865,0.0,0.63177007,89.295479,2.8562427,406.28537,-9.263133
179.3252,13.267817,7.0755525,0.0,0,2.8198419,0.0,0.63719243,89.284462,2.8152411,406.55026,-9.2616949
179.3296,13.300414,7.1097817,0.0,0,2.7826972,0.0,0.64189303,89.170425,2.7780468,406.7381,-9.2603283
179.334,13.328341,7.1527672,0.0,0,2.7455523,0.0,0.64710128,88.846375,2.7401531,406.897,-9.2630157
179.3384,13.430756,7.184032,0.0,0,2.7086806,0.0,0.65144515,89.119896,2.7022207,407.08002,-9.2602835
179.3428,13.520434,7.2263184,0.0,0,2.6733487,0.0,0.65668929,89.272705,2.6714168,407.2919,-9.2611208
179.3472,13.539887,7.2560263,0.0,0,2.6380167,0.0,0.661008,89.009819,2.6317906,406.99796,-9.2626371
179.3516,13.610697,7.2962656,0.0,0,2.6026847,0.0,0.6662882,89.019463,2.5959713,404.42789,-9.2625656
179.356,13.64472,7.3248978,0.0,0,2.5673528,0.0,0.67020184,88.879936,2.563782,401.85779,-9.2622414
179.3604,13.740856,7.3617907,0.0,0,2.5320206,0.0,0.67517698,89.072227,2.5297689,399.92648,-9.2620335
179.3648,13.840336,7.3921819,0.0,0,2.4966886,0.0,0.67919016,89.370216,2.4959557,398.05905,-9.2607689
179.3692,13.917933,7.4284663,0.0,0,2.4613566,0.0,0.68431717,89.428055,2.4580243,398.09689,-9.2624693
179.3736,14.036493,7.462492,0.0,0,2.4260244,0.0,0.68872386,89.738297,2.4212925,399.22339,-9.2618628
179.378,14.194777,7.4994988,0.0,0,2.3906927,0.0,0.69385242,90.276733,2.384737,400.52298,-9.2616405
179.3824,14.272167,7.5359359,0.0,0,2.3553605,0.0,0.69866842,90.337715,2.3474028,402.12552,-9.2603064
179.3868,14.249938,7.5754824,0.0,0,2.3200285,0.0,0.70391756,89.763123,2.3104305,403.67267,-9.2612476
179.3912,14.244519,7.6032581,0.0,0,2.2860539,0.0,0.70744061,89.394653,2.276032,404.66599,-9.262495
179.3956,14.403537,7.6384444,0.0,0,2.2524467,0.0,0.71213496,89.961426,2.2479074,405.65927,-9.2610445
179.4,14.517087,7.6708298,0.0,0,2.2188394,0.0,0.71643239,90.305954,2.2154243,405.47144,-9.2624817
179.4044,14.6003,7.7054114,0.0,0,2.1852324,0.0,0.72093827,90.415115,2.1803558,405.02115,-9.2617092
179.4088,14.714008,7.7440186,0.0,0,2.1516252,0.0,0.72605866,90.64167,2.1418009,404.48416,-9.2603264
179.4132,14.809216,7.7749,0.0,0,2.1180179,0.0,0.73026872,90.843361,2.1110449,403.87494,-9.2607269
179.4176,14.919728,7.813683,0.0,0,2.0844107,0.0,0.7353093,91.069077,2.0712273,403.01645,-9.2596989
179.422,14.880488,7.8455,0.0,0,2.0508037,0.0,0.73977178,90.454887,2.0463772,401.49341,-9.2625027
179.4264,14.920146,7.8804812,0.0,0,2.0171964,0.0,0.74428815,90.259399,2.0128374,399.97031,-9.2616272
179.4308,15.117427,7.9087639,0.0,0,1.9835892,0.0,0.74848163,91.039558,1.9767809,394.5159,-9.260479
179.4352,15.250553,7.9473352,0.0,0,1.949982,0.0,0.75370568,91.402161,1.9437621,389.06152,-9.2620296
179.4396,15.334373,7.9759431,0.0,0,1.9170676,0.0,0.75810844,91.465446,1.9143958,385.89459,-9.2603445
179.444,15.409997,8.0146141,0.0,0,1.8850971,0.0,0.76341856,91.461899,1.8781869,383.58545,-9.2604399
179.4484,15.512128,8.0420952,0.0,0,1.8531268,0.0,0.76763505,91.686493,1.8464607,383.76266,-9.2631025
179.4528,15.640438,8.0787411,0.0,0,1.8211564,0.0,0.77281833,91.927834,1.8131727,386.9234,-9.2604227
179.4572,15.700456,8.1058044,0.0,0,1.789186,0.0,0.77724028,91.933182,1.7851661,389.79422,-9.2601233
179.4616,15.74595,8.1420097,0.0,0,1.7572156,0.0,0.78259414,91.66674,1.7508867,391.36032,-9.2608023
179.466,15.83986,8.1697969,0.0,0,1.7252452,0.0,0.78685814,91.778809,1.7198387,392.92642,-9.2601442
179.4704,16.042034,8.2034273,0.0,0,1.6932747,0.0,0.79194593,92.537567,1.685981,393.74445,-9.260169
179.4748,16.184753,8.2300901,0.0,0,1.6613044,0.0,0.79614419,92.958397,1.6585482,394.48767,-9.2616386
179.4792,16.270967,8.2659941,0.0,0,1.629334,0.0,0.80175972,92.951424,1.6229539,395.31506,-9.2617998
179.4836,16.379061,8.2954607,0.0,0,1.5973636,0.0,0.80604863,93.111267,1.5891303,396.19058,-9.262682
179.488,16.532774,8.3338852,0.0,0,1.5654863,0.0,0.81193781,93.447807,1.5522275,396.97437,-9.2610035
179.4924,16.58728,8.3647928,0.0,0,1.5350733,0.0,0.81631565,93.367027,1.5271443,397.59769,-9.2618227
179.4968,16.581503,8.3927374,0.0,0,1.5046604,0.0,0.82072914,92.939262,1.4927932,398.22812,-9.260252
179.5012,16.611118,8.4212818,0.0,0,1.4742476,0.0,0.82476187,92.715118,1.4682548,398.93008,-9.2614861
179.5056,16.787563,8.4506989,0.0,0,1.4438349,0.0,0.82911253,93.24472,1.4394403,399.63202,-9.2616272
179.51,16.99522,8.4794474,0.0,0,1.413422,0.0,0.83316946,94.057434,1.4052206,400.56152,-9.2595778
179.5144,17.120428,8.5129557,0.0,0,1.3830092,0.0,0.83817989,94.221199,1.3710245,401.5416,-9.260293
179.5188,17.166578,8.544879,0.0,0,1.3525965,0.0,0.84299731,94.089897,1.3447142,402.25436,-9.2599792
179.5232,17.298048,8.5728979,0.0,0,1.3221837,0.0,0.84710634,94.408539,1.31282,402.74438,-9.2606983
179.5276,17.389921,8.6077452,0.0,0,1.2917709,0.0,0.85234296,94.432259,1.288891,403.18384,-9.261137
179.532,17.501842,8.6324444,0.0,0,1.2613581,0.0,0.85608965,94.699875,1.254191,403.48846,-9.2602606
179.5364,17.615652,8.6674757,0.0,0,1.2309452,0.0,0.86156148,94.797699,1.2278589,403.79309,-9.260726
179.5408,17.786797,8.6919308,0.0,0,1.2015675,0.0,0.86547083,95.286858,1.1977149,403.96527,-9.2603912
179.5452,17.951914,8.72752,0.0,0,1.172642,0.0,0.87066954,95.668533,1.1620697,404.13742,-9.2602434
179.5496,18.027807,8.7546911,0.0,0,1.1437162,0.0,0.87546855,95.639549,1.1340251,404.21329,-9.2606726
179.554,18.138037,8.7877569,0.0,0,1.1147908,0.0,0.88073808,95.756287,1.1085945,404.25299,-9.2609425
179.5584,18.240725,8.8084612,0.0,0,1.085865,0.0,0.88433021,95.896233,1.081422,404.34689,-9.2604342
179.5628,18.432381,8.844182,0.0,0,1.0569395,0.0,0.89011818,96.35186,1.0490115,404.50583,-9.2605314
179.5672,18.578482,8.8701468,0.0,0,1.0280138,0.0,0.89470166,96.66935,1.0217097,404.63828,-9.2609034
179.5716,18.653629,8.8987951,0.0,0,0.99908835,0.0,0.89958584,96.606651,0.99084729,404.65152,-9.2602577
179.576,18.772896,8.9253149,0.0,0,0.97016269,0.0,0.9041397,96.807205,0.95946711,404.66479,-9.2613745
179.5804,18.918966,8.9555769,0.0,0,0.94123709,0.0,0.90934551,96.964165,0.93269736,401.19446,-9.2609959
179.5848,19.115738,8.9795284,0.0,0,0.91231143,0.0,0.9134568,97.601517,0.90618837,397.37576,-9.2618046
179.5892,19.225252,9.0110893,0.0,0,0.88385683,0.0,0.91893125,97.687302,0.87617642,393.75958,-9.2604122
179.5936,19.334532,9.0348377,0.0,0,0.85634804,0.0,0.92299414,97.778824,0.84354591,390.25906,-9.2617569
179.598,19.517561,9.0650129,0.0,0,0.82883924,0.0,0.92826891,98.188141,0.81629544,387.64539,-9.2596407
179.6024,19.675486,9.092042,0.0,0,0.80133045,0.0,0.93253469,98.606583,0.78577387,386.58365,-9.2609682
179.6068,19.690556,9.1160479,0.0,0,0.77382165,0.0,0.93674719,98.274765,0.76084083,385.35748,-9.2612123
179.6112,19.6499,9.1404362,0.0,0,0.7463128,0.0,0.94052458,97.701515,0.73207521,382.48755,-9.2595491
179.6156,19.785227,9.1654472,0.0,0,0.71880406,0.0,0.94475996,97.908829,0.71377373,379.61761,-9.2616787
179.62,20.061146,9.1922808,0.0,0,0.69129521,0.0,0.9490816,98.864708,0.68834269,378.3671,-9.2601738
179.6244,20.312374,9.2172871,0.0,0,0.66378647,0.0,0.9531303,99.738998,0.65633482,377.47644,-9.2596216
179.6288,20.454638,9.246644,0.0,0,0.63627762,0.0,0.95797271,99.922905,0.62975246,377.91309,-9.2605114
179.6332,20.635729,9.2757225,0.0,0,0.60876882,0.0,0.96289206,100.27917,0.59865826,379.45584,-9.2599373
179.6376,20.738762,9.3060942,0.0,0,0.58126003,0.0,0.96791136,100.30215,0.575607,381.01257,-9.2606516
179.642,20.893333,9.3303804,0.0,0,0.55503851,0.0,0.97207236,100.62065,0.54879361,382.60663,-9.2613859
179.6464,20.994759,9.3599186,0.0,0,0.52885848,0.0,0.97697091,100.63959,0.51875383,384.20068,-9.2588682
179.6508,19.995861,9.3629179,0.0,0,0.50267845,0.0,0.97770613,95.850067,0.50691032,385.2359,-9.2607098
179.6552,19.328026,9.3729181,0.0,0,0.47649848,0.0,0.97908616,92.472343,0.48831299,386.27115,-9.2617369
179.6596,18.927382,9.3721218,0.0,0,0.45031849,0.0,0.97960681,90.486832,0.46985146,386.84305,-9.262989
179.664,18.608866,9.3820515,0.0,0,0.42413846,0.0,0.98104882,88.857841,0.45244536,387.24121,-9.2622156
179.6684,18.066124,9.3812342,0.0,0,0.39795846,0.0,0.98133588,86.26355,0.44215482,387.64539,-9.2620173
179.6728,17.484093,9.3844481,0.0,0,0.37177846,0.0,0.98209769,83.390144,0.43211663,388.05682,-9.2635698
179.6772,17.044872,9.383275,0.0,0,0.34559846,0.0,0.98231006,81.266121,0.42626056,388.45859,-9.2639265
179.6816,16.839378,9.3865938,0.0,0,0.31941846,0.0,0.98299628,80.234749,0.41273546,388.81693,-9.2647867
179.686,16.761549,9.3876934,0.0,0,0.29323849,0.0,0.98345518,79.803322,0.39410552,389.17529,-9.2631378
179.6904,16.941511,9.3880424,0.0,0,0.26783592,0.0,0.98376989,80.657715,0.35857067,389.54568,-9.2628288
179.6948,17.128363,9.3895702,0.0,0,0.24294072,0.0,0.98403347,81.529686,0.32305253,389.9173,-9.2628593
179.6992,17.254553,9.3934422,0.0,0,0.21804552,0.0,0.98507905,82.014511,0.2921901,390.34802,-9.2630787
179.7036,17.267757,9.3948069,0.0,0,0.19315037,0.0,0.98541582,82.088676,0.26152694,390.81256,-9.2618456
179.708,17.197929,9.3980436,0.0,0,0.16825517,0.0,0.98598289,81.734985,0.23755616,391.27707,-9.263237
179.7124,17.167938,9.3966417,0.0,0,0.14335997,0.0,0.98554337,81.556671,0.20965117,391.74158,-9.2605066
179.7168,17.12063,9.4006815,0.0,0,0.11846475,0.0,0.98638111,81.284477,0.18715286,392.18079,-9.2610149
179.7212,17.064068,9.4034004,0.0,0,0.093569554,0.0,0.98673117,80.981392,0.15960008,392.36658,-9.2606888
179.7256,16.977043,9.4055977,0.0,0,0.068674356,0.0,0.98643291,80.594299,0.14093101,392.5524,-9.2614021
179.73,16.913921,9.4087019,0.0,0,0.043779153,0.0,0.98703593,80.239761,0.1196825,392.65134,-9.2620754
179.7344,16.886532,9.4122467,0.0,0,0.018883955,0.0,0.98731309,80.090378,0.10042701,392.73096,-9.2615328
179.7388,16.845188,9.4139481,0.0,0,-0.0058646323,0.0,0.98734432,79.904907,0.078271337,392.96985,-9.261488
179.7432,16.748396,9.4140158,0.0,0,-0.030152632,0.0,0.98722339,79.470665,0.060128395,393.34146,-9.2602787
179.7476,16.668875,9.4207821,0.0,0,-0.054440632,0.0,0.98831403,78.986618,0.041812859,393.70584,-9.2614565
179.752,16.607634,9.4199104,0.0,0,-0.078728631,0.0,0.98804349,78.739143,0.03163201,394.0509,-9.2619104
179.7564,16.516605,9.4248219,0.0,0,-0.10301661,0.0,0.98856467,78.245621,0.01676601,394.396,-9.2608633
179.7608,16.377594,9.4227428,0.0,0,0.42610684,400.0,0.98853755,77.627838,0.0034819071,394.66144,-9.2623243
179.7652,15.499284,9.4305153,0.0,0,1.222965,400.0,0.98952883,73.514694,0.019951764,394.92688,-9.2612286
179.7696,11.260173,9.4127541,6.4125457,0,2.0198233,400.0,0.98685563,53.681816,0.21137407,395.25021,-9.2662487
179.774,-0.6071434,9.3565331,15.229733,0,2.8166804,400.0,0.97689366,-2.6701303,0.60767275,395.59531,-9.2747955
179.7784,-0.076470315,9.25348,20.039063,0,3.6135378,400.0,0.95909745,-0.37635696,1.8077976,395.94037,-9.2757959
179.7828,-0.020135013,9.3144388,20.039063,0,4.4103956,400.0,0.96954256,0.0041305139,2.9865317,396.28543,-9.273612
179.7872,0.52707928,9.4091215,19.534557,0,5.207253,400.0,0.98719615,2.8689039,3.8043852,396.61118,-9.2719164
179.7916,0.40913939,9.3966703,16.759848,0,6.0041108,400.0,0.98490834,1.9038292,4.5682383,396.85001,-9.2701187
179.796,0.17590021,9.3912735,13.985141,0,6.8009686,400.0,0.98394006,0.86128062,5.3378057,397.08887,-9.2713251
179.8004,0.21516293,9.3970194,13.73291,0,7.597826,400.0,0.98551077,0.99818158,6.149076,397.25516,-9.2702894
179.8048,0.16813298,9.3922129,13.73291,0,8.3946848,400.0,0.98468035,0.82334143,6.9742732,397.41418,-9.2694607
179.8092,0.14631695,9.39048,12.991547,0,9.1915417,400.0,0.98468786,0.68440837,7.8085022,397.54788,-9.2680244
179.8136,0.17067476,9.3896656,11.826556,0,9.9884005,400.0,0.98448467,0.82002407,8.6225281,397.66705,-9.2673082
179.818,0.16925043,9.3924885,11.085205,0,10.785257,400.0,0.98517656,0.71026421,9.4463205,397.79108,-9.2670441
179.8224,0.16404502,9.3887749,11.085205,0,11.582114,400.0,0.98416728,0.79362392,10.256977,397.92352,-9.2660007
179.8268,0.20887201,9.3894949,10.96303,0,12.378972,400.0,0.98447222,1.0033535,11.052861,398.05478,-9.2658634
179.8312,0.19148651,9.393219,9.6191826,0,13.17583,400.0,0.98476505,0.92448676,11.822298,398.17398,-9.2659159
179.8356,0.15014826,9.3906431,8.2753344,0,13.972688,400.0,0.9839586,0.68220502,12.593699,398.29315,-9.2651625
179.84,0.21912171,9.3906345,8.0310059,0,14.769546,400.0,0.98387641,1.0186462,13.405662,398.39066,-9.2652197
179.8444,0.15680704,9.3926601,8.0310059,0,15.566403,400.0,0.98384011,0.74555665,14.204515,398.48337,-9.2654772
179.8488,0.2170704,9.3944921,8.0310059,0,16.36326,400.0,0.98396373,1.0686557,15.019038,398.53275,-9.2655144
179.8532,0.15538749,9.3937674,8.0310059,0,17.160118,400.0,0.98370624,0.8127954,15.809586,398.54599,-9.2654409
179.8576,0.20369327,9.3959713,8.0310059,0,17.956976,400.0,0.98389882,0.94355893,16.606609,398.55923,-9.2645073
179.862,0.19477612,9.3952169,8.0310059,0,18.0,400.0,0.98370469,0.93207484,17.401621,398.57251,-9.2646885
179.8664,0.24779744,9.4010849,8.0309973,0,18.0,400.0,0.98439604,1.185571,18.07379,398.58575,-9.267621
179.8708,0.30687836,9.3968315,6.4406171,0,18.0,400.0,0.98383582,1.4337397,18.44614,398.65198,-9.2706242
179.8752,0.26297197,9.4019156,4.8502359,0,18.0,400.0,0.98433018,1.2668488,18.408205,398.71817,-9.282094
179.8796,0.30409163,9.4004307,4.4165039,0,18.0,400.0,0.984559,1.4315062,18.193697,398.71698,-9.3023453
179.884,0.31570658,9.4008999,4.4165039,0,18.0,400.0,0.98451537,1.4486015,18.051046,398.69049,-9.3309193
179.8884,0.32069322,9.3945913,5.1394124,0,18.0,400.0,0.98392528,1.5376621,18.043589,398.664,-9.3661165
179.8928,0.27320382,9.396821,6.7297931,0,18.0,400.0,0.98432469,1.2787701,18.075867,398.63751,-9.4028893
179.8972,0.24911651,9.3924255,8.0310059,0,18.0,400.0,0.98393476,1.171591,18.120604,398.62549,-9.4370003
179.9016,0.30024514,9.3942547,8.0310059,0,18.0,400.0,0.98442477,1.4007536,18.13335,398.67844,-9.4715595
179.906,0.33271289,9.3900089,8.0310059,0,18.0,400.0,0.9838742,1.5661486,18.134645,398.73141,-9.5019016
179.9104,0.30121773,9.391818,6.585197,0,18.0,400.0,0.98454291,1.4329723,18.132868,398.78439,-9.5359631
179.9148,0.26999715,9.3905334,4.9948163,0,18.0,400.0,0.98444217,1.2830818,18.128778,398.83737,-9.5663576
179.9192,0.30398113,9.3886414,4.4165039,0,18.0,400.0,0.98428148,1.43694,18.12425,398.82291,-9.5992146
179.9236,0.34515777,9.3884687,4.4165039,0,18.0,400.0,0.98427385,1.6084574,18.118956,398.76996,-9.6332493
179.928,0.318059,9.390686,4.4165039,0,18.0,400.0,0.98471195,1.5472672,18.112074,398.73624,-9.6653461
179.9324,0.27444988,9.3887243,4.4165039,0,18.0,400.0,0.98429734,1.3120021,18.111437,398.73624,-9.6976919
179.9368,0.28785756,9.387063,4.4165039,0,18.0,400.0,0.98393309,1.3762367,18.111612,398.73865,-9.729353
179.9412,0.33516797,9.3870115,4.4165039,0,18.0,400.0,0.98370737,1.6384248,18.107813,398.76514,-9.7628565
179.9456,0.32130718,9.3874884,4.4165039,0,18.0,400.0,0.9835279,1.5526179,18.104931,398.79163,-9.7955284
179.95,0.28006989,9.3917122,4.4165039,0,18.0,400.0,0.9839893,1.3187599,18.101023,398.75308,-9.8279486
179.9544,0.27568895,9.387558,4.4165039,0,18.0,400.0,0.98293114,1.3197321,18.098694,398.7001,-9.8593893
179.9588,0.32914209,9.3886328,4.4165039,0,18.0,400.0,0.98290855,1.6080421,18.098663,398.66879,-9.8928299
179.9632,0.33742341,9.390995,4.4165039,0,18.0,400.0,0.98307341,1.6454574,18.092846,398.65558,-9.9254084
179.9676,0.27964932,9.3939991,4.4165039,0,18.0,400.0,0.98335642,1.3534395,18.093811,398.64954,-9.9589396
179.972,0.27113143,9.393199,4.4165039,0,18.0,400.0,0.98330462,1.2981708,18.09374,398.66278,-9.991168
179.9764,0.32801726,9.3958721,4.4165039,0,18.0,400.0,0.98327053,1.5334781,18.093643,398.67603,-10.02496
179.9808,0.34864581,9.3926802,4.4165039,0,18.0,400.0,0.98309612,1.6742948,18.090195,398.66278,-10.056529
179.9852,0.29964662,9.3987236,4.4165039,0,18.0,400.0,0.98379153,1.4697168,18.089739,398.64954,-10.08936
179.9896,0.27388883,9.3933725,5.5731525,0,18.0,400.0,0.98342586,1.30047,18.091724,398.61703,-10.121272
179.994,0.32754093,9.398468,7.1635332,0,18.0,400.0,0.98408306,1.5054176,18.088484,398.5773,-10.153228
179.9984,0.36660296,9.3936195,8.0310059,0,18.0,400.0,0.98366272,1.7699974,18.087305,398.54358,-10.185398
180.0028,0.3186422,9.3976212,8.0310059,0,18.0,400.0,0.9844768,1.5537977,18.083368,398.51709,-10.217784
180.0072,0.28582692,9.3923197,8.0310059,0,18.0,400.0,0.9840377,1.3768396,18.077772,398.49301,-10.250226
180.0116,0.30771795,9.3944149,8.0310059,0,18.0,400.0,0.98460191,1.4451399,18.082077,398.47977,-10.282083
180.016,0.37856737,9.3905687,8.0310059,0,18.0,400.0,0.98399109,1.7796965,18.078445,398.46652,-10.313228
180.0204,0.33074483,9.3936901,8.0310059,0,18.0,400.0,0.98488522,1.6129017,18.080122,398.3931,-10.347946
180.0248,0.28952196,9.3901434,8.0310059,0,18.0,400.0,0.98431021,1.385841,18.075533,398.31363,-10.381412
180.0292,0.27681214,9.3894501,8.8861885,0,18.0,400.0,0.98453355,1.2982612,18.078318,398.25943,-10.413037
180.0336,0.36207491,9.3849926,10.230037,0,18.0,400.0,0.98374498,1.6821313,18.077526,398.21973,-10.44687
180.038,0.34868741,9.389596,11.085205,0,18.0,400.0,0.98452014,1.6744039,18.075777,398.18961,-10.479627
180.0424,0.29129344,9.3854551,11.085205,0,18.0,400.0,0.98372072,1.4552742,18.073536,398.17636,-10.510756
180.0468,0.27997494,9.3869944,11.085205,0,18.0,400.0,0.98387229,1.3169641,18.075037,398.15833,-10.54217
180.0512,0.36528409,9.3875961,11.085205,0,18.0,400.0,0.98368055,1.7070159,18.072575,398.0921,-10.573611
180.0556,0.37417522,9.385273,11.085205,0,18.0,400.0,0.98299855,1.7728497,18.072968,398.02588,-10.607557
180.06,0.31363571,9.3888979,11.085205,0,18.0,400.0,0.98343921,1.5109216,18.068611,398.00299,-10.64078
180.0644,0.28824747,9.389533,11.085205,0,18.0,400.0,0.98334539,1.3679422,18.068184,397.98972,-10.672554
180.0688,0.33412468,9.3891134,11.085205,0,18.0,400.0,0.98290652,1.5577207,18.069317,397.96927,-10.705626
180.0732,0.3916133,9.3899155,11.085205,0,18.0,400.0,0.98275518,1.8595662,18.067595,397.94278,-10.739111
180.0776,0.33288291,9.3955564,11.085205,0,18.0,400.0,0.98361444,1.6175129,18.06344,397.91269,-10.771672
180.082,0.30257249,9.3903065,11.085205,0,18.0,400.0,0.98259342,1.4460695,18.059706,397.87296,-10.804049
180.0864,0.32877633,9.3939695,11.085205,0,18.0,400.0,0.98297471,1.5500391,18.058142,397.83322,-10.83455
180.0908,0.39979798,9.3914938,11.085205,0,18.0,400.0,0.98293209,1.8759139,18.059082,397.81998,-10.867613
180.0952,0.35440189,9.3979807,11.085205,0,18.0,400.0,0.98363417,1.7368252,18.057749,397.8067,-10.90014
180.0996,0.30812013,9.3926048,11.085205,0,18.0,400.0,0.98331493,1.5012989,18.055147,397.76459,-10.933385
180.104,0.32251489,9.396203,11.085205,0,18.0,400.0,0.98386151,1.482909,18.057919,397.71164,-10.964813
180.1084,0.38692728,9.3917818,11.614752,0,18.0,400.0,0.98336452,1.83009,18.053808,397.64661,-10.997102
180.1128,0.37403077,9.3952656,12.779741,0,18.0,400.0,0.9840591,1.8221558,18.056936,397.56714,-11.031642
180.1172,0.32053792,9.3910789,13.73291,0,18.0,400.0,0.98382485,1.5277222,18.051582,397.49008,-11.062745
180.1216,0.30216631,9.3919945,13.73291,0,18.0,400.0,0.98420274,1.4444672,18.055769,397.42386,-11.095746
180.126,0.37189338,9.3875275,13.73291,0,18.0,400.0,0.98362714,1.7255969,18.048532,397.35764,-11.129351
180.1304,0.3969534,9.3927126,14.664557,0,18.0,400.0,0.98476595,1.8662621,18.052908,397.31549,-11.162174
180.1348,0.32830259,9.3880892,15.68936,0,18.0,400.0,0.98401666,1.5728514,18.050926,397.27576,-11.193983
180.1392,0.31308335,9.3888645,16.062012,0,18.0,400.0,0.98445314,1.484423,18.048721,397.24448,-11.22401
180.1436,0.37094745,9.3856277,16.062012,0,18.0,400.0,0.98376852,1.7202623,18.049482,397.21796,-11.258299
180.148,0.39955911,9.3854551,16.062012,0,18.0,400.0,0.98375535,1.9043298,18.050371,397.19147,-11.291201
180.1524,0.36648399,9.388483,16.062012,0,18.0,400.0,0.9840253,1.7254575,18.043919,397.16498,-11.322467
180.1568,0.30594361,9.3848381,16.062012,0,18.0,400.0,0.98339415,1.4514277,18.043589,397.13846,-11.356872
181.8577,0.28609222,9.4009199,1.3465923e-22,0,18.0,2.6539197000000002e-21,0.98544204,1.3570492,18.0,365.61996,-11.481581
184.0577,0.32443357,9.4128666,7.9874012e-44,0,18.0,1.4012985e-45,0.98751408,1.5296327,17.999031,343.20068,-11.482656
186.2577,0.33003771,9.4228802,7.9874012e-44,0,18.0,1.4012985e-45,0.98931271,1.5649501,17.999563,323.52103,-11.481989
188.4577,0.33663318,9.4324932,7.9874012e-44,0,18.0,1.4012985e-45,0.99104953,1.5968163,18.000628,305.87335,-11.481793
190.6577,0.3443881,9.4412823,7.9874012e-44,0,18.0,1.4012985e-45,0.99266118,1.6289889,17.999914,289.65442,-11.482206
192.8577,0.35648799,9.4494085,7.9874012e-44,0,18.0,1.4012985e-45,0.99414849,1.6773107,18.000496,274.44049,-11.482235
195.0577,0.36076781,9.4574289,7.9874012e-44,0,18.0,1.4012985e-45,0.99560291,1.6888757,17.999516,260.44449,-11.481677
197.2577,0.37896633,9.4644747,7.9874012e-44,0,18.0,1.4012985e-45,0.99694085,1.7784392,17.99964,247.16365,-11.481823
199.4577,0.37765208,9.4719172,7.9874012e-44,0,18.0,1.4012985e-45,0.9982565,1.7783413,18.000456,234.59125,-11.482103
201.6577,0.38172916,9.4793348,7.9874012e-44,0,18.0,1.4012985e-45,0.99956119,1.7947524,17.999355,222.59187,-11.482452
203.8577,0.39206061,9.4864998,7.9874012e-44,0,18.0,1.4012985e-45,1.0008341,1.8344357,17.999565,211.47478,-11.481952
206.0577,0.40974328,9.493269,7.9874012e-44,0,18.0,1.4012985e-45,1.0020719,1.9126116,18.000244,200.74548,-11.48162
208.2577,0.41307953,9.4993334,7.9874012e-44,0,18.0,1.4012985e-45,1.0031973,1.9296737,18.000374,190.83279,-11.481647
210.4577,0.42425039,9.5054035,7.9874012e-44,0,18.0,1.4012985e-45,1.0043432,1.9815559,18.000755,181.42453,-11.482238
212.6577,0.43088323,9.5110502,7.9874012e-44,0,18.0,1.4012985e-45,1.0053639,2.0063307,17.998938,172.53514,-11.482432
214.8577,0.4368903,9.5161915,7.9874012e-44,0,18.0,1.4012985e-45,1.00623,2.0264654,18.00036,164.15587,-11.4824
217.0577,0.44496158,9.5219545,7.9874012e-44,0,18.0,1.4012985e-45,1.0072823,2.0616906,18.001083,156.57996,-11.481581
219.2577,0.45155802,9.5271978,7.9874012e-44,0,18.0,1.4012985e-45,1.008207,2.099339,17.999504,149.13914,-11.481063
221.4577,0.451601,9.5316267,7.9874012e-44,0,18.0,1.4012985e-45,1.0089984,2.0996208,17.99987,142.27911,-11.481227
223.6577,0.46482909,9.5364666,7.9874012e-44,0,18.0,1.4012985e-45,1.0098881,2.1556983,18.000027,135.6871,-11.481902
225.8577,0.47261938,9.5403233,7.9874012e-44,0,18.0,1.4012985e-45,1.0106244,2.1837554,18.000086,129.4525,-11.481944
228.0577,0.48193288,9.5441046,7.9874012e-44,0,18.0,1.4012985e-45,1.0113298,2.2262437,17.999876,123.58488,-11.482622
230.2577,0.47187096,9.5476179,7.9874012e-44,0,18.0,1.4012985e-45,1.0120473,2.1867173,18.000051,118.19197,-11.481997
232.4577,0.45606071,9.5514355,7.9874012e-44,0,18.0,1.4012985e-45,1.0127457,2.1188893,17.99984,113.09116,-11.481235
234.6577,0.45682147,9.5552197,7.9874012e-44,0,18.0,1.4012985e-45,1.0134394,2.1071224,17.998913,108.10843,-11.480838
236.8577,0.47494453,9.5580893,7.9874012e-44,0,18.0,1.4012985e-45,1.0139197,2.190171,18.000021,103.57565,-11.480654
239.0577,0.49680042,9.5610571,7.9874012e-44,0,18.0,1.4012985e-45,1.0144597,2.2921281,18.000326,99.250458,-11.481796
240.1577,0.48244435,9.5629015,7.9874012e-44,0,18.0,1.4012985e-45,1.0148251,2.2263551,18.000286,97.271652,-11.546471