File: examples/dan-msc-case-studies/CS3/data/01 raw data/baron_test_013.csv
Time(sec),Force(kN),Jaw(mm),PowAngle(deg),Power(W),Pram,PTemp,Strain,Stress(MPa),Stroke(mm),TC1(C),wedge(mm)
0.0,1.4681821,0.24574691,0.0,0,11.076097,0.0,0.016505221,18.38818,11.076669,25.880417,-9.1212797
1.1,1.4064535,-0.003694512,0.0,0,11.076097,3.2158821,-0.00021785143,17.912851,11.076905,25.779015,-9.4901323
2.2,1.361632,-0.003336644,0.0,0,11.076097,6.5158801,-0.00021361795,17.365046,11.076347,25.721952,-9.4871712
3.3,1.3404838,-0.0033478942,0.0,0,11.076097,9.8158827,-0.00023425838,17.076181,11.075919,25.676214,-9.4858046
4.4,1.3247206,-0.0035669713,0.0,0,11.076097,13.115881,-0.00024712805,16.858366,11.076382,25.698296,-9.4839849
5.5,1.3076421,-0.0035725937,0.0,0,11.076097,16.415884,-0.00021477579,16.668625,11.076538,25.679312,-9.4822912
6.6,1.2999692,-0.003338153,0.0,0,11.076097,19.715881,-0.00021828676,16.568604,11.075952,25.609823,-9.4801607
7.7,1.2882586,-0.0029180478,0.0,0,11.076097,23.015877,-0.00022237415,16.399271,11.07555,25.614027,-9.47785
8.8,1.2868074,-0.0035255949,0.0,0,11.076097,26.315886,-0.0002294693,16.395611,11.07608,25.556545,-9.4758406
9.9,1.2731652,-0.0025624253,23.099615,0,11.076097,29.615881,-0.00016627452,16.213001,11.076691,25.517647,-9.4739943
11.0,1.2801346,-0.0024553528,35.315022,0,11.076097,32.915878,-0.00015236328,16.293283,11.076332,25.830795,-9.4719067
12.1,1.2928945,-0.0034634303,43.36776,0,11.076097,36.215881,-0.00025816896,16.46559,11.076538,26.714157,-9.4708567
13.2,1.2942257,-0.00736028,48.936642,0,11.076097,39.515884,-0.00046786488,16.492153,11.077089,28.678734,-9.4691029
14.3,1.3066581,-0.010853935,52.617203,0,11.076097,42.815895,-0.00073234766,16.643904,11.075787,31.75149,-9.466898
15.4,1.3309063,-0.016381968,55.353535,0,11.076097,46.115894,-0.0010873249,16.947824,11.076309,35.637688,-9.4650784
16.5,1.3550617,-0.021098146,56.985023,0,11.076097,49.415894,-0.0014311136,17.291536,11.075735,40.255238,-9.4631634
17.6,1.3700918,-0.02631822,57.810013,0,11.076097,52.715893,-0.0017344358,17.473225,11.076165,45.693958,-9.460866
18.7,1.3808939,-0.031827331,57.810051,0,11.076097,56.015892,-0.0021080216,17.621962,11.076242,51.530685,-9.4587517
19.8,1.3968755,-0.037600152,56.997688,0,11.076097,59.315887,-0.0025271599,17.835629,11.076313,57.533062,-9.4569836
20.9,1.392833,-0.04255088,55.542564,0,11.076097,62.615887,-0.0028366884,17.799221,11.076769,63.527828,-9.4550314
22.0,1.4037453,-0.046518005,53.404209,0,11.076097,65.915886,-0.0030921544,17.921402,11.074874,69.270966,-9.4535084
23.1,1.4195229,-0.050383601,50.616329,0,11.076097,69.215897,-0.0033331674,18.129787,11.075595,74.579018,-9.4518166
24.2,1.4043047,-0.052422579,47.507359,0,11.076097,72.5159,-0.0035220846,17.964127,11.076129,79.159256,-9.4495821
25.3,1.391625,-0.054462962,44.078571,0,11.076097,75.815895,-0.0035978337,17.788738,11.076505,82.982628,-9.4476118
26.4,1.3736376,-0.055580303,40.606441,0,11.076097,79.115906,-0.0036988356,17.544868,11.075313,85.971939,-9.4460936
27.5,1.3681972,-0.056343399,38.556393,0,11.076097,82.415894,-0.00376436,17.498463,11.075352,88.108665,-9.4444504
28.6,1.3423133,-0.056756683,37.880539,0,11.076097,85.715904,-0.0037939046,17.1581,11.075225,89.671295,-9.4423418
29.7,1.3312672,-0.057514947,39.60313,0,11.076097,89.0159,-0.0038111231,17.013397,11.07554,90.665321,-9.440238
30.8,1.329252,-0.059088115,42.367455,0,11.076097,92.315895,-0.0039191255,16.995113,11.075904,91.570404,-9.4383621
31.9,1.3185846,-0.059968099,45.611752,0,11.076097,95.615891,-0.0040104087,16.868504,11.076356,92.57666,-9.4360466
33.0,1.3319458,-0.062169176,49.092171,0,11.076097,98.915894,-0.0041271378,17.016336,11.07578,93.918274,-9.4341087
34.1,1.3589261,-0.065396622,52.034374,0,11.076097,102.21589,-0.0043515847,17.357367,11.075038,95.831566,-9.4328108
35.2,1.3672314,-0.06908679,54.611618,0,11.076097,105.51588,-0.0046070484,17.502523,11.075579,98.262108,-9.4312963
36.3,1.3869858,-0.074086875,56.583515,0,11.076097,108.81589,-0.0049415678,17.740864,11.075303,101.50661,-9.4295731
37.4,1.4087175,-0.077101953,58.018723,0,11.076097,112.11588,-0.0050977189,18.019999,11.076472,105.30868,-9.4270258
38.5,1.4100916,-0.082347721,58.837566,0,11.076097,115.41588,-0.0054628868,18.065226,11.076986,109.72334,-9.4252663
39.6,1.4144258,-0.087415151,59.106438,0,11.076097,118.71587,-0.0058235498,18.116859,11.075318,114.51598,-9.4233952
40.7,1.4305409,-0.092736229,58.923149,0,11.076097,122.01588,-0.0061499299,18.327728,11.076715,119.56317,-9.4218225
41.8,1.4354925,-0.098406814,58.338108,0,11.076097,125.31589,-0.0065425332,18.395342,11.076859,124.75085,-9.4195595
42.9,1.4289627,-0.10109488,57.270477,0,11.076097,128.61601,-0.0067224712,18.326624,11.075327,129.79933,-9.4179497
44.0,1.4301445,-0.10545792,55.997231,0,11.076097,131.91591,-0.0070154159,18.334223,11.076522,134.60051,-9.4156618
45.1,1.43127,-0.10922867,54.330154,0,11.076097,135.2159,-0.007229533,18.357569,11.076442,139.06636,-9.4142971
46.2,1.4323988,-0.1121015,52.650887,0,11.076097,138.5159,-0.0074299192,18.389856,11.076359,143.12535,-9.412344
47.3,1.4304657,-0.11479609,51.196762,0,11.076097,141.8159,-0.0076490636,18.351847,11.075207,146.59627,-9.4105616
48.4,1.4212269,-0.11561717,49.714775,0,11.076097,145.11589,-0.0076602185,18.232786,11.076158,149.51283,-9.4090147
49.5,1.4125667,-0.1175922,49.114624,0,11.076097,148.41589,-0.007813788,18.134571,11.075444,152.03134,-9.4068966
50.6,1.3963366,-0.11945659,49.229733,0,11.076097,151.7159,-0.0079396851,17.929426,11.075697,153.90385,-9.4052105
51.7,1.396615,-0.12119512,50.039497,0,11.076097,155.0159,-0.0080459947,17.918844,11.076329,155.64302,-9.4035549
52.8,1.406121,-0.12322397,51.196064,0,11.076097,158.31589,-0.0081826383,18.044832,11.076437,157.32475,-9.4015636
53.9,1.4046144,-0.12513244,52.967888,0,11.076097,161.61589,-0.0082920268,18.047791,11.076005,159.12648,-9.3997602
55.0,1.4146714,-0.12784533,54.605255,0,11.076097,164.91588,-0.0084993849,18.163469,11.075609,161.20285,-9.397872
56.1,1.4260094,-0.13160338,56.125439,0,11.076097,168.21588,-0.0087116547,18.32135,11.075106,163.68649,-9.3962679
57.2,1.4374197,-0.13611665,57.534576,0,11.076097,171.51588,-0.0090176789,18.479391,11.076365,166.65062,-9.3945427
58.3,1.4411776,-0.13879995,58.643658,0,11.076097,174.81589,-0.0092328833,18.51412,11.076203,169.89204,-9.3924694
59.4,1.4454104,-0.14380519,59.348137,0,11.076097,178.11589,-0.0095138391,18.575901,11.075777,173.68132,-9.3902149
60.5,1.4376965,-0.14874581,59.842525,0,11.076097,181.41589,-0.0098678218,18.51141,11.075257,177.81035,-9.3885422
61.6,1.4373535,-0.15313679,60.084225,0,11.076097,184.7159,-0.010169573,18.493967,11.075096,182.04385,-9.3868752
62.7,1.4504166,-0.15881026,59.956234,0,11.076097,188.01588,-0.010542247,18.663349,11.07491,186.49666,-9.3843126
63.8,1.4514747,-0.16171791,59.601128,0,11.076097,191.31589,-0.010708767,18.685919,11.076133,190.9512,-9.382865
64.9,1.4346048,-0.16656233,58.986595,0,11.076097,194.61589,-0.011026811,18.476397,11.075973,195.41182,-9.3809824
66.0,1.4437164,-0.17032343,58.223114,0,11.076097,197.91589,-0.011312077,18.588291,11.076261,199.60414,-9.3793411
67.1,1.4493265,-0.17347859,57.389545,0,11.076097,201.21588,-0.011462118,18.66268,11.076068,203.60561,-9.3776703
68.2,1.4430017,-0.17752726,56.520599,0,11.076097,204.5159,-0.011760772,18.608526,11.075968,207.2751,-9.3757439
69.3,1.4371021,-0.17874415,55.852379,0,11.076097,207.81589,-0.011869021,18.506285,11.075695,210.53583,-9.3742266
70.4,1.440941,-0.18208475,55.535892,0,11.076097,211.11589,-0.012035021,18.574064,11.076175,213.4623,-9.3723783
71.5,1.4342288,-0.18449599,55.339558,0,11.076097,214.41589,-0.012234782,18.492571,11.07654,216.04903,-9.3710165
72.6,1.4375802,-0.18678689,55.535885,0,11.076097,217.71588,-0.012397006,18.528524,11.076303,218.599,-9.3693399
73.7,1.4481083,-0.19045834,56.05854,0,11.076097,221.01588,-0.012610164,18.663939,11.075971,220.89351,-9.3675842
74.8,1.4399323,-0.19177033,56.662918,0,11.076097,224.31589,-0.012706857,18.575621,11.077243,223.36922,-9.3657227
75.9,1.4387196,-0.19414766,57.260738,0,11.076097,227.61588,-0.012852364,18.557076,11.075808,225.86572,-9.364007
77.0,1.4423966,-0.19797288,58.073704,0,11.076097,230.91588,-0.01312049,18.591833,11.0762,228.59921,-9.3618422
78.1,1.4530348,-0.20126782,58.853577,0,11.076097,234.21588,-0.01330831,18.774399,11.075171,231.50551,-9.3600464
79.2,1.4341891,-0.20541948,59.600574,0,11.076097,237.5159,-0.013591276,18.525946,11.0757,234.64517,-9.358242
80.3,1.4484459,-0.20923291,60.180115,0,11.076097,240.8159,-0.013869148,18.685682,11.076447,237.91672,-9.355978
81.4,1.4564797,-0.21317029,60.782982,0,11.076097,244.11589,-0.014091615,18.819981,11.076197,241.39026,-9.3543177
82.5,1.4544711,-0.21624146,61.072327,0,11.076097,247.41591,-0.01429924,18.794476,11.074824,244.93538,-9.3523417
83.6,1.4513025,-0.22105201,61.349163,0,11.076097,250.7159,-0.014654632,18.768829,11.07588,248.67262,-9.3505058
84.7,1.4512601,-0.22603691,61.539623,0,11.076097,254.01591,-0.014929067,18.771397,11.075967,252.33871,-9.3486795
85.8,1.4372711,-0.23010412,61.468754,0,11.076097,257.31622,-0.015228375,18.58885,11.075344,256.24887,-9.3466959
86.9,1.4489241,-0.23381214,61.468513,0,11.076097,260.61621,-0.015482851,18.739227,11.076005,260.12738,-9.3450022
88.0,1.4558184,-0.23891638,61.238029,0,11.076097,263.91592,-0.015792115,18.818523,11.0752,263.78912,-9.3432798
89.1,1.4590393,-0.24094073,61.023983,0,11.076097,267.21591,-0.015947299,18.878046,11.075788,267.52347,-9.3414049
90.2,1.4585714,-0.24402887,60.855927,0,11.076097,270.5159,-0.016153049,18.893288,11.076549,271.14813,-9.3396645
91.3,1.4524353,-0.24847627,60.642689,0,11.076097,273.81592,-0.016427729,18.799171,11.076511,274.56754,-9.3379488
92.4,1.4585011,-0.25214711,60.524841,0,11.076097,277.11588,-0.016671937,18.870974,11.07493,277.93561,-9.3363085
93.5,1.4540191,-0.2551603,60.314949,0,11.076097,280.41589,-0.016863825,18.843357,11.076222,281.16388,-9.3350229
94.6,1.4453766,-0.25905323,60.314949,0,11.076097,283.71588,-0.017132277,18.704159,11.076319,284.31595,-9.3328476
95.7,1.450793,-0.26161954,60.314934,0,11.076097,287.0159,-0.017291449,18.780058,11.076595,287.45239,-9.3306608
96.8,1.4560812,-0.26564205,60.314934,0,11.076097,290.31589,-0.017542152,18.881088,11.075109,290.49463,-9.3286514
97.9,1.4501659,-0.2694335,60.556637,0,11.076097,293.61591,-0.017819706,18.795675,11.075706,293.3237,-9.3272734
99.0,1.4534682,-0.27116111,60.787346,0,11.076097,296.91586,-0.01790713,18.838171,11.076682,296.24487,-9.3256035
100.1,1.4579288,-0.27375099,61.237686,0,11.076097,300.21591,-0.018081689,18.905811,11.076363,299.03326,-9.3238182
101.2,1.4540009,-0.27714497,61.683399,0,11.076097,303.5159,-0.018319057,18.855488,11.075435,301.96564,-9.3220034
102.3,1.4554031,-0.28153524,62.116486,0,11.076097,306.81589,-0.018568465,18.884621,11.076573,304.91699,-9.3200417
103.4,1.4538233,-0.2857013,62.538734,0,11.076097,310.11588,-0.018853091,18.850962,11.075933,308.22879,-9.3182802
104.5,1.4520949,-0.2896792,62.828262,0,11.076097,313.41592,-0.019149031,18.853498,11.075607,311.45276,-9.316946
105.6,1.4484921,-0.29371512,63.171383,0,11.076097,316.71591,-0.019362113,18.805946,11.076606,314.84622,-9.3149691
106.7,1.4473726,-0.29775277,63.369137,0,11.076097,320.0159,-0.019639445,18.799255,11.075534,318.36621,-9.3127909
107.8,1.4528503,-0.30153736,63.569302,0,11.076097,323.31592,-0.019915238,18.887245,11.075884,321.97418,-9.3107214
108.9,1.4510969,-0.30581924,63.577873,0,11.076097,326.61591,-0.020165525,18.850111,11.075549,325.55414,-9.3093538
110.0,1.4562614,-0.30902651,63.615543,0,11.076097,329.91592,-0.020391485,18.917089,11.076488,329.10544,-9.3075018
111.1,1.4585519,-0.31231165,62.138718,0,11.076097,329.99976,-0.020639773,18.954533,11.075824,332.52985,-9.3076096
112.2,1.4449052,-0.31506354,59.868179,0,11.076097,329.99976,-0.020763572,18.781637,11.075919,335.74655,-9.3076077
113.3,1.4503139,-0.31631467,57.170197,0,11.076097,329.99976,-0.0208639,18.85078,11.076255,338.06393,-9.3076506
114.4,1.4364949,-0.31610093,53.768501,0,11.076097,329.99976,-0.020876382,18.67976,11.076359,339.74576,-9.3071022
115.5,1.3060547,-0.31624508,50.182678,0,11.076097,329.99976,-0.02084293,16.981091,11.076439,340.263,-9.3072186
116.6,1.1934607,-0.31551281,47.056351,0,11.076097,329.99976,-0.02081343,15.507922,11.07734,339.86627,-9.306941
117.7,1.1046282,-0.31366888,44.256729,0,11.076097,329.99976,-0.020722877,14.349519,11.075807,338.50067,-9.3071127
118.8,1.0316365,-0.31167409,43.481293,0,11.076097,329.99976,-0.020542564,13.414188,11.07627,336.18719,-9.3072681
119.9,0.98803097,-0.30940279,44.076839,0,11.076097,329.99976,-0.020415729,12.839715,11.076295,333.48788,-9.3075294
121.0,0.96102124,-0.30690038,46.095871,0,11.076097,329.99976,-0.020277983,12.486099,11.075721,330.72037,-9.3071585
122.1,0.94626999,-0.30634326,48.770046,0,11.076097,329.99976,-0.020199504,12.308379,11.075686,328.02191,-9.307106
123.2,0.92749977,-0.30585811,51.326992,0,11.076097,329.99976,-0.020191066,12.066736,11.077071,326.01202,-9.3069983
124.3,0.91616076,-0.30604497,53.865269,0,11.076097,329.99976,-0.020224297,11.905722,11.077406,324.53903,-9.3062582
125.4,0.93018687,-0.30654788,55.838863,0,11.076097,329.99976,-0.020209281,12.094393,11.076317,323.75574,-9.3069763
126.5,0.92293829,-0.30814743,57.470181,0,11.076097,329.99976,-0.020343952,12.011142,11.07667,323.6431,-9.3071489
127.6,0.91807318,-0.30988172,58.670273,0,11.076097,329.99976,-0.02047877,11.929337,11.075379,324.04492,-9.3067751
128.7,0.92503142,-0.31264019,59.348137,0,11.076097,329.99976,-0.020612283,12.020673,11.075347,325.00085,-9.3060875
129.8,0.92852354,-0.31480935,59.600826,0,11.076097,329.99976,-0.020769538,12.093175,11.075912,326.30151,-9.3064289
130.9,0.92961913,-0.31736845,59.600861,0,11.076097,329.99976,-0.020963781,12.072622,11.077008,327.72461,-9.306221
132.0,0.93550378,-0.31992891,59.110138,0,11.076097,329.99976,-0.021076757,12.149042,11.07707,329.27417,-9.306673
133.1,0.93458641,-0.32124826,58.338547,0,11.076097,329.99976,-0.02118477,12.160802,11.075644,330.8515,-9.3068027
134.2,0.9208914,-0.32237536,57.261093,0,11.076097,329.99976,-0.021284593,11.989678,11.075716,332.15158,-9.3064241
135.3,0.93544626,-0.32358843,55.87294,0,11.076097,329.99976,-0.021312814,12.165008,11.075558,333.37192,-9.3062925
136.4,0.93863064,-0.32381853,54.369198,0,11.076097,329.99976,-0.021353742,12.215852,11.075917,334.1521,-9.3061752
137.5,0.92792064,-0.32384506,52.865364,0,11.076097,329.99976,-0.021380108,12.089325,11.075635,334.6188,-9.3064613
138.6,0.90515542,-0.32361278,51.569897,0,11.076097,329.99976,-0.021315688,11.776385,11.075797,334.57202,-9.3068628
139.7,0.89927095,-0.32310891,50.438309,0,11.076097,329.99976,-0.021301143,11.68864,11.075865,334.05789,-9.3063822
140.8,0.90123528,-0.32192615,50.031673,0,11.076097,329.99976,-0.021248981,11.728426,11.0764,333.17047,-9.3067598
141.9,0.88437855,-0.32122496,50.042187,0,11.076097,329.99976,-0.021164056,11.516187,11.076086,331.99521,-9.3063536
143.0,0.88051552,-0.3203246,50.436001,0,11.076097,329.99976,-0.021118328,11.429195,11.074773,330.85208,-9.3057613
144.1,0.88511914,-0.31921712,51.196262,0,11.076097,329.99976,-0.021069342,11.514555,11.076558,329.64301,-9.3063059
145.2,0.87970823,-0.31934929,52.22718,0,11.076097,329.99976,-0.021048002,11.452719,11.076243,328.72339,-9.3062773
146.3,0.89898115,-0.31881842,53.231277,0,11.076097,329.99976,-0.021025596,11.688002,11.075375,327.88077,-9.306386
147.4,0.90971738,-0.31933686,54.259766,0,11.076097,329.99976,-0.021074135,11.836799,11.075784,327.48639,-9.3064098
148.5,0.91780782,-0.32034352,55.106068,0,11.076097,329.99976,-0.021142654,11.942172,11.07519,327.14584,-9.3061218
149.6,0.91682202,-0.32183936,55.804695,0,11.076097,329.99976,-0.02124168,11.916848,11.075973,327.29559,-9.3061447
150.7,0.92818153,-0.32275033,56.129147,0,11.076097,329.99976,-0.021276291,12.066785,11.076065,327.66721,-9.3055649
151.8,0.92853928,-0.32322866,56.240242,0,11.076097,329.99976,-0.021326134,12.08353,11.075686,328.30438,-9.305974
152.9,0.92347199,-0.32495686,56.261383,0,11.076097,329.99976,-0.021454435,12.00306,11.075081,328.93671,-9.3059797
154.0,0.93062264,-0.32633319,56.129154,0,11.076097,329.99976,-0.021499399,12.092463,11.075745,329.55807,-9.3063726
155.1,0.93322146,-0.014083736,55.709728,0,11.076097,329.99976,-0.00092053408,11.906102,11.076093,330.25925,-9.3063803
155.2817,0.91829568,0.012678622,32.21051,0,11.076099,1.5464025e-08,0.00066173647,11.807037,11.079764,330.44287,-9.3056908
155.2839,0.94970274,0.0084704524,19.992619,0,11.076099,1.5445149e-23,0.00069654518,12.105777,11.078582,330.42276,-9.305789
155.2861,0.92953318,0.010671715,7.7747226,0,11.076099,1.5426298e-38,0.0005733202,11.794342,11.074531,330.40262,-9.3053322
155.2883,0.95421934,0.011325243,0.0,0,11.076099,0.0,0.00093353871,12.106773,11.078113,330.42639,-9.3057756
155.2905,0.95139486,0.012935854,0.0,0,11.076099,0.0,0.00065763178,12.074689,11.076046,330.52698,-9.3052893
155.2927,0.93332976,0.0086779268,0.0,0,11.076099,0.0,0.00075187389,11.954479,11.076879,330.62753,-9.3054762
155.2949,0.91973305,0.0091283442,0.0,0,11.076099,0.0,0.00042309033,11.705984,11.076362,330.72812,-9.3062725
155.2971,0.91124392,0.0090356572,0.0,0,11.076099,0.0,0.00084120681,11.612176,11.076136,330.82867,-9.3068542
155.2993,0.913656,0.012543837,0.0,0,11.076099,0.0,0.00062706386,11.634435,11.076437,330.81952,-9.3069057
155.3015,0.90970868,0.0084286435,0.0,0,11.076099,0.0,0.00075539894,11.591096,11.07093,330.78601,-9.3062277
155.3037,0.92280519,0.0099653257,0.0,0,11.076099,0.0,0.00047845574,11.711867,11.078471,330.75247,-9.3070831
155.3059,0.92160821,0.0093501844,0.0,0,11.076099,0.0,0.00089571142,11.70974,11.077805,330.71896,-9.306529
155.3081,0.93165815,0.011321468,0.0,0,11.076099,0.0,0.00055614405,11.883127,11.07372,330.68726,-9.3064222
155.3103,0.9346419,0.0086958455,0.0,0,11.076099,0.0,0.0008317348,11.938851,11.074981,330.66043,-9.3060455
155.3125,0.91492337,0.010271367,0.0,0,11.076099,0.0,0.00048885017,11.708818,11.073937,330.63361,-9.3061132
155.3147,0.88971174,0.0099991439,0.0,0,11.076099,0.0,0.00090788613,11.317216,11.079186,330.60681,-9.3062363
155.3169,0.89954883,0.012559191,0.0,0,11.076099,0.0,0.00057814294,11.354447,11.077457,330.57999,-9.3061132
155.3191,0.89990264,0.0076271086,0.0,0,11.076099,0.0,0.00077434984,11.36615,11.071682,330.55804,-9.3057642
155.3213,0.90943319,0.01045893,0.0,0,11.076099,0.0,0.00049557805,11.567849,11.076508,330.53793,-9.3067007
155.3235,0.91403812,0.0081382487,0.0,0,11.076099,0.0,0.00082086999,11.662064,11.078739,330.51782,-9.3062439
155.3257,0.92104828,0.013548216,0.0,0,11.076099,0.0,0.00060363143,11.606933,11.07863,330.49771,-9.3061705
155.3279,0.91992939,0.0088704061,0.0,0,11.076099,0.0,0.0008759097,11.673208,11.075664,330.47882,-9.3067665
155.3301,0.92029458,0.01091984,0.0,0,11.076099,0.0,0.00053621357,11.723433,11.076577,330.46542,-9.3079767
155.3323,0.89913017,0.0078628333,0.0,0,10.765895,0.0,0.00082315883,11.524895,11.077151,330.452,-9.3062754
155.3345,0.89230275,0.013308289,0.0,0,10.435002,0.0,0.0005892578,11.373363,11.072483,330.43857,-9.3070478
155.3367,0.91142642,0.0075148959,0.0,0,10.104111,0.0,0.00074209645,11.50725,11.021823,330.42517,-9.306881
155.3389,0.91319031,0.010830768,0.0,0,9.7732182,0.0,0.00053461333,11.502379,10.839523,330.61658,-9.3067598
155.3411,0.92485368,0.0084150471,0.0,0,9.4434023,0.0,0.0008495418,11.832986,10.552342,330.92499,-9.3067732
155.3433,0.91966695,0.015207081,0.0,0,9.1214933,0.0,0.00070458662,11.692927,10.179871,331.2334,-9.3064852
155.3455,7.4619102,0.28976825,0.0,0,8.7995892,0.0,0.019077376,93.278534,9.8170013,331.54184,-9.3015308
155.3477,9.1903038,0.65468436,0.0,0,8.4910212,0.0,0.044117562,111.09012,9.4079523,332.17151,-9.3012037
155.3499,9.8131199,1.0260948,0.0,0,8.1848688,0.0,0.070931979,116.27946,9.0013676,336.01266,-9.3006229
155.3521,10.176443,1.3968921,0.0,0,7.8872514,0.0,0.096873835,117.53452,8.6416273,339.85385,-9.2980042
155.3543,10.758319,1.7091024,0.0,0,7.5959711,0.0,0.12094162,121.15333,8.2997293,343.69504,-9.298666
155.3565,11.058695,2.0328865,0.0,0,7.3089838,0.0,0.14498267,121.81029,7.9661064,347.53622,-9.2989063
155.3587,11.301879,2.3366957,0.0,0,7.0319595,0.0,0.16931708,121.49177,7.6556544,351.80054,-9.299159
155.3609,11.644167,2.6208122,0.0,0,6.7554379,0.0,0.19112724,122.35789,7.3671865,356.41748,-9.3000793
155.3631,11.898378,2.8881996,0.0,0,6.4917583,0.0,0.21380752,122.33724,7.091959,361.03442,-9.2987394
155.3653,12.16325,3.1579106,0.0,0,6.2281981,0.0,0.23569526,122.28962,6.8184676,365.65137,-9.2988005
155.3675,12.452283,3.4108074,0.0,0,5.97438,0.0,0.25804844,122.45917,6.5551696,370.26825,-9.2989101
155.3697,12.717562,3.6772079,0.0,0,5.723712,0.0,0.28036734,122.32182,6.2951698,372.20367,-9.300066
155.3719,13.037452,3.9191895,0.0,0,5.47893,0.0,0.30277717,122.57432,6.0420647,374.13913,-9.3001051
155.3741,13.325824,4.1727366,0.0,0,5.2404499,0.0,0.32530642,122.49682,5.7869186,376.07458,-9.300498
155.3763,13.610055,4.4183083,0.0,0,5.0044208,0.0,0.34887388,122.18296,5.5348902,378.01001,-9.2993155
155.3785,13.903691,4.6741443,0.0,0,4.7776008,0.0,0.37239999,121.8631,5.2826967,379.1322,-9.2999897
155.3807,14.198835,4.9122906,0.0,0,4.5507808,0.0,0.39663643,121.5542,5.0374961,379.2785,-9.2997169
155.3829,14.486823,5.153904,0.0,0,4.3343148,0.0,0.4202033,121.12223,4.7977691,379.42484,-9.2993412
155.3851,14.823377,5.3853049,0.0,0,4.1185384,0.0,0.44472227,120.93362,4.560338,379.57117,-9.298315
155.3873,15.145808,5.6239772,0.0,0,3.9097824,0.0,0.46899542,120.52372,4.3223329,379.71747,-9.2989588
155.3895,15.50676,5.8390083,0.0,0,3.7045665,0.0,0.49298626,120.4732,4.0983601,378.69101,-9.2990847
155.3917,15.88907,6.0602794,0.0,0,3.5032659,0.0,0.51683104,120.59782,3.8863807,377.5473,-9.2993765
155.3939,16.234327,6.2624631,0.0,0,3.308038,0.0,0.54042149,120.37256,3.6726594,376.40359,-9.2987633
155.3961,16.609938,6.4718385,0.0,0,3.1139472,0.0,0.56373084,120.28487,3.4691648,375.25989,-9.2990694
155.3983,16.964497,6.6585774,0.0,0,2.9282196,0.0,0.58667707,120.11626,3.2773812,374.44019,-9.2981596
155.4005,17.374802,6.8515759,0.0,0,2.7424955,0.0,0.60945779,120.26301,3.0844395,374.18747,-9.2983923
155.4027,17.817926,7.032608,0.0,0,2.5644448,0.0,0.63267273,120.42307,2.8940094,373.93472,-9.2969732
155.4049,18.261389,7.2241259,0.0,0,2.3877847,0.0,0.6560691,120.60515,2.7127273,373.68198,-9.2970934
155.4071,18.756226,7.3957171,0.0,0,2.216074,0.0,0.67940378,120.98846,2.5327017,373.42926,-9.2973099
155.4093,19.321238,7.5839062,0.0,0,2.048038,0.0,0.70370567,121.62725,2.3543167,373.66528,-9.2957869
155.4115,19.907593,7.7554092,0.0,0,1.8824661,0.0,0.72764403,122.356,2.1714418,374.00992,-9.2961807
155.4137,20.480885,7.9345398,0.0,0,1.722614,0.0,0.75194156,122.86229,1.9973648,374.35458,-9.2956009
155.4159,21.062365,8.0983763,0.0,0,1.5630525,0.0,0.77615356,123.34862,1.8283418,374.69922,-9.2953987
155.4181,21.696522,8.2674809,0.0,0,1.4109191,0.0,0.80042076,123.99406,1.6661929,375.04385,-9.2962036
155.4203,22.337914,8.4199467,0.0,0,1.2588551,0.0,0.823717,124.7596,1.5034034,374.64395,-9.2967758
155.4225,23.021471,8.5825138,0.0,0,1.1124103,0.0,0.84810096,125.43315,1.3428602,374.07861,-9.2953806
155.4247,23.75672,8.7247744,0.0,0,0.9677822,0.0,0.87105012,126.53004,1.1912223,373.51328,-9.2945805
155.4269,24.512165,8.8723812,0.0,0,0.82657528,0.0,0.89463198,127.45597,1.0444714,372.94794,-9.2938919
155.4291,25.339108,9.0064831,0.0,0,0.68903136,0.0,0.91710752,128.84489,0.89940977,372.36447,-9.2942324
155.4313,26.180122,9.1526403,0.0,0,0.5528841,0.0,0.94144481,129.91702,0.7556563,371.73264,-9.2927961
155.4335,27.034239,9.2825613,0.0,0,0.42198399,0.0,0.96407378,131.2063,0.61700553,371.1008,-9.2931519
155.4357,26.304495,9.3934174,0.0,0,0.29108396,0.0,0.98422879,125.81715,0.48639587,370.46896,-9.2923994
155.4379,24.531998,9.3998785,0.0,0,0.16620633,0.0,0.98547721,116.83067,0.43132576,369.8371,-9.2932129
155.4401,23.42927,9.4077778,0.0,0,0.041730318,0.0,0.986772,111.30294,0.39644402,370.24042,-9.2966118
155.4423,22.676151,9.4082317,0.0,0,-0.080698207,0.0,0.98654997,107.70202,0.36468598,371.03189,-9.2970467
155.4445,22.48369,9.4152241,0.0,0,-0.2020942,0.0,0.98815501,106.58044,0.32920849,371.82336,-9.297739
155.4467,22.551332,9.4144611,0.0,0,-0.32349023,0.0,0.98779327,106.8812,0.27712148,372.61484,-9.2978058
155.4489,22.692499,9.4272709,0.0,0,-0.44488621,0.0,0.99046725,107.34621,0.21820198,373.47403,-9.2968483
155.4511,22.755232,9.4285831,0.0,0,-0.56628221,0.0,0.9901647,107.65541,0.16074872,374.63794,-9.2970181
155.4533,22.695511,9.4339018,0.0,0,-0.68767816,0.0,0.99152088,107.21796,0.10296182,375.80188,-9.2976379
155.4555,22.540535,9.4381523,0.0,0,-0.80907416,0.0,0.99193436,106.46828,0.05486992,376.96579,-9.2978039
155.4577,22.283335,9.4489841,0.0,0,-0.93047017,0.0,0.9944399,104.9798,0.015787413,378.12973,-9.2997274
155.4599,21.927988,9.4478855,0.0,0,-1.0518663,0.0,0.99352068,103.42741,-0.0085384166,379.11966,-9.2984543
155.4621,21.456371,9.4470301,0.0,0,-0.88152969,330.0,0.9941898,101.17905,-0.020233002,380.01022,-9.3000126
155.4643,20.941168,9.4482889,0.0,0,-0.46125016,330.0,0.99352503,98.76754,-0.025515797,380.90076,-9.2998724
155.4665,20.400331,9.4542971,0.0,0,-0.040971316,330.0,0.99562532,96.033379,-0.022471396,381.79132,-9.2999344
155.4687,19.917021,9.4520836,0.0,0,0.37930778,330.0,0.99402845,93.937164,-0.013416938,382.6691,-9.3003492
155.4709,19.577019,9.4496412,0.0,0,0.79958731,330.0,0.9945907,92.209396,-0.0087386239,383.41922,-9.3017006
155.4731,19.292028,9.4495659,0.0,0,1.2198665,330.0,0.99366617,90.953773,-0.0084668892,384.16931,-9.3019514
155.4753,18.491354,9.4549017,0.0,0,1.6401452,330.0,0.99596202,87.08857,0.012660424,384.91943,-9.3016186
155.4775,16.557154,9.4514027,0.0,0,2.060425,330.0,0.99375325,78.298615,0.08693561,385.66956,-9.3033972
155.4797,13.022997,9.4352264,0.0,0,2.4807043,330.0,0.99221194,61.830887,0.24028927,386.32904,-9.3049288
155.4819,7.5952921,9.4133377,0.0,0,2.9009831,330.0,0.98717356,36.91468,0.46255332,386.91299,-9.3090763
155.4841,0.41761196,9.2986383,0.0,0,3.3212624,330.0,0.9685387,1.8241762,0.85612929,387.49698,-9.3182592
155.4863,-0.10116367,9.2709064,0.0,0,3.7415414,330.0,0.96175295,-0.091188543,1.5141112,388.08096,-9.3171635
155.4885,-0.28218392,9.3157158,0.0,0,4.1618209,330.0,0.97069144,-1.393487,2.2263825,388.66492,-9.3175049
155.4907,0.19001204,9.4184971,0.0,0,4.5820999,330.0,0.98740882,0.56876343,2.889163,389.08963,-9.3154726
155.4929,-0.30390733,9.4146414,0.0,0,5.0023794,330.0,0.98892099,-1.6255909,3.4295468,389.51434,-9.3152332
155.4951,0.2156146,9.4230709,0.0,0,5.422658,330.0,0.98865807,0.89136231,3.849179,389.93903,-9.3145008
155.4973,0.62135303,9.4190874,0.0,0,5.8429379,330.0,0.98953235,3.1324191,4.2363935,390.36374,-9.3123274
155.4995,0.56036437,9.4248466,0.0,0,6.2632165,330.0,0.9887749,2.7156861,4.6224089,390.73718,-9.3117809
155.5017,0.57303482,9.4139004,0.0,0,6.683496,330.0,0.98879153,2.677691,5.0185018,391.04904,-9.3109379
155.5039,0.47727889,9.4155474,0.0,0,7.1037755,330.0,0.98709512,2.2457447,5.4413357,391.36093,-9.310215
155.5061,0.61522049,9.4093676,0.0,0,7.5240545,330.0,0.98797381,2.928102,5.8723774,391.67282,-9.3091869
155.5083,0.61813921,9.4172201,0.0,0,7.944334,330.0,0.98728949,2.9414241,6.308568,391.98471,-9.3088341
155.5105,0.49227101,9.417057,0.0,0,8.3646135,330.0,0.98950064,2.3591268,6.7567749,392.21817,-9.3087168
155.5127,0.54987115,9.4215603,0.0,0,8.7848921,330.0,0.98785836,2.5771828,7.1958346,392.44382,-9.308259
155.5149,0.57246548,9.4134645,0.0,0,9.2051716,330.0,0.98858851,2.737572,7.6305251,392.66943,-9.308568
155.5171,0.5881446,9.4185467,0.0,0,9.6254511,330.0,0.98772609,2.8421409,8.059679,392.89505,-9.3070288
155.5193,0.46696994,9.416111,0.0,0,10.045731,330.0,0.98938739,2.2587547,8.4913635,393.09415,-9.3080587
155.5215,0.51159346,9.4220648,0.0,0,10.466009,330.0,0.98801982,2.3917639,8.9307308,393.24677,-9.3071184
155.5237,0.63759035,9.4125977,0.0,0,10.886289,330.0,0.988675,3.0130374,9.3633013,393.39938,-9.3066797
155.5259,0.6249696,9.4178257,0.0,0,11.306567,330.0,0.98750097,2.9762218,9.7906637,393.552,-9.30686
155.5281,0.52885479,9.4172869,0.0,0,11.726847,330.0,0.98960668,2.5058088,10.230461,393.70465,-9.3055496
155.5303,0.52139926,9.4240065,0.0,0,12.147126,330.0,0.98818403,2.4820063,10.657757,393.81927,-9.3057108
155.5325,0.58888483,9.413003,0.0,0,12.567405,330.0,0.98884249,2.770772,11.087948,393.92545,-9.3069878
155.5347,0.591501,9.4187641,0.0,0,12.987684,330.0,0.9875654,2.8706868,11.509918,394.03162,-9.3057299
155.5369,0.57606679,9.4146271,0.0,0,13.407964,330.0,0.98910499,2.7747245,11.917691,394.13779,-9.3045082
155.5391,0.50373143,9.4263086,0.0,0,13.828242,330.0,0.98856241,2.4395361,12.339338,394.24033,-9.3041029
155.5413,0.53979057,9.4145737,0.0,0,14.248522,330.0,0.98908323,2.4776452,12.773278,394.33322,-9.3042059
155.5435,0.6350525,9.4162579,0.0,0,14.6688,330.0,0.98726493,2.9688492,13.21067,394.42615,-9.3055248
155.5457,0.60730046,9.4152136,0.0,0,15.08908,330.0,0.98916,2.9132977,13.653027,394.51904,-9.3047762
155.5479,0.52553481,9.4260769,0.0,0,15.509359,330.0,0.98859185,2.5463352,14.093715,394.61194,-9.3042698
155.5501,0.52617645,9.4159203,0.0,0,15.929639,330.0,0.98933721,2.4684677,14.539016,394.70483,-9.3058844
155.5523,0.61567795,9.4178562,0.0,0,16.349918,330.0,0.98760688,2.9009461,14.969608,394.79773,-9.3056374
155.5545,0.60800987,9.412219,0.0,0,16.770197,330.0,0.98875481,2.8976951,15.377717,394.89066,-9.3037758
155.5567,0.52503049,9.4234657,0.0,0,17.190477,330.0,0.98817337,2.5399446,15.786262,394.98355,-9.3038187
155.5589,0.51921517,9.4136162,0.0,0,17.610756,330.0,0.98874539,2.4273202,16.204718,395.07162,-9.3045797
155.5611,0.54297513,9.4182034,0.0,0,17.999401,330.0,0.98767668,2.5622637,16.629213,395.138,-9.3043928
155.5633,0.68565673,9.41152,0.0,0,18.0,330.0,0.98849821,3.2246192,17.050034,395.20435,-9.3044949
155.5655,0.59629333,9.4261904,0.0,0,18.0,330.0,0.98866355,2.8577459,17.445038,395.27072,-9.3042307
155.5677,0.58693171,9.4150305,0.0,0,18.0,330.0,0.98910499,2.7264047,17.807734,395.33707,-9.3061924
155.5699,0.60712844,9.4193077,0.0,0,18.0,330.0,0.98782867,2.8705995,18.119495,395.36966,-9.3069801
155.5721,0.67707628,9.4141932,0.0,0,18.0,330.0,0.98896796,3.2112138,18.349176,395.38293,-9.3091211
155.5743,0.6269744,9.4245882,0.0,0,18.0,330.0,0.98842949,2.9979289,18.492023,395.39621,-9.3129883
155.5765,0.60134077,9.4140081,0.0,0,18.0,330.0,0.9886809,2.8495836,18.521717,395.40948,-9.3174715
155.5787,0.60890329,9.4202862,0.0,0,18.0,330.0,0.98816043,2.90623,18.450024,395.42154,-9.3238668
155.5809,0.67210686,9.4138012,0.0,0,18.0,330.0,0.98886955,3.1652355,18.320553,395.42154,-9.3333979
155.5831,0.68673247,9.4251328,0.0,0,18.0,330.0,0.98867291,3.2437963,18.192894,395.42154,-9.3447514
155.5853,0.66937059,9.4164419,0.0,0,18.0,330.0,0.98912114,3.1484952,18.096609,395.42154,-9.3592539
155.5875,0.68934911,9.422224,0.0,0,18.0,330.0,0.98844171,3.2703779,18.048988,395.42154,-9.3740091
155.5897,0.7231518,9.4119663,0.0,0,18.0,330.0,0.98822671,3.4216552,18.0389,395.436,-9.3919697
155.5919,0.66376024,9.4220085,0.0,0,18.0,330.0,0.98801166,3.1816838,18.039457,395.46255,-9.4103212
155.5941,0.61197209,9.4105844,0.0,0,18.0,330.0,0.98800248,2.9056294,18.05805,395.48911,-9.429142
155.5963,0.5972237,9.4163246,0.0,0,18.0,330.0,0.98752844,2.8211484,18.084879,395.51563,-9.4474802
155.5985,0.58963042,9.4084692,0.0,0,18.0,330.0,0.98763746,2.8297756,18.106894,395.54218,-9.4642363
155.6007,0.62010521,9.4199495,0.0,0,18.0,330.0,0.98793077,2.9132409,18.127888,395.55545,-9.4800034
155.6029,0.65927005,9.4092913,0.0,0,18.0,330.0,0.98767841,3.1235597,18.144463,395.56873,-9.4950466
155.6051,0.68813407,9.4155016,0.0,0,18.0,330.0,0.98745483,3.2734883,18.147104,395.582,-9.5123997
155.6073,0.69619703,9.4079733,0.0,0,18.0,330.0,0.98731267,3.324538,18.151194,395.59528,-9.5283642
155.6095,0.70888692,9.4207468,0.0,0,18.0,330.0,0.98829687,3.3769345,18.149757,395.60251,-9.5446644
155.6117,0.64913279,9.4111366,0.0,0,18.0,330.0,0.98778844,3.1105196,18.148041,395.60251,-9.5614977
155.6139,0.61841977,9.415205,0.0,0,18.0,330.0,0.98752964,2.9313443,18.142115,395.60251,-9.5768347
155.6161,0.59768695,9.4092426,0.0,0,18.0,330.0,0.98738414,2.8779244,18.138657,395.60251,-9.5920439
155.6183,0.63003385,9.4195576,0.0,0,18.0,330.0,0.98820955,2.9726629,18.131876,395.60251,-9.6073046
155.6205,0.66088557,9.410593,0.0,0,18.0,330.0,0.98746604,3.1056781,18.130928,395.59045,-9.6239843
155.6227,0.70573378,9.4155445,0.0,0,18.0,330.0,0.9879784,3.2874427,18.131733,395.57718,-9.6395493
155.6249,0.73532873,9.4117107,0.0,0,18.0,330.0,0.98751062,3.4300411,18.124743,395.5639,-9.6551838
155.6271,0.72167373,9.4192543,0.0,0,18.0,330.0,0.98830116,3.4206192,18.122284,395.55063,-9.6702557
155.6293,0.68838662,9.4118767,0.0,0,18.0,330.0,0.98770797,3.2933018,18.121193,395.54218,-9.6861897
155.6315,0.64988732,9.4183636,0.0,0,18.0,330.0,0.98853314,3.1284196,18.119322,395.54218,-9.7029314
155.6337,0.61024946,9.4113245,0.0,0,18.0,330.0,0.98757648,2.9076295,18.115231,395.54218,-9.7193975
155.6359,0.62318647,9.4190779,0.0,0,18.0,330.0,0.98837042,2.9363947,18.113462,395.54218,-9.7346935
155.6381,0.65729541,9.4119864,0.0,0,18.0,330.0,0.98745024,3.0888894,18.109167,395.54218,-9.7497358
155.6403,0.69096386,9.4151993,0.0,0,18.0,330.0,0.98797858,3.2303605,18.1094,395.53131,-9.7651205
155.6425,0.70725816,9.4119091,0.0,0,18.0,330.0,0.9875713,3.3449812,18.109596,395.51807,-9.7826872
155.6447,0.72761428,9.4192638,0.0,0,18.0,330.0,0.98883522,3.4667699,18.108929,395.50479,-9.7991838
155.6469,0.70864624,9.4136219,0.0,0,18.0,330.0,0.98755473,3.4036555,18.107237,395.49152,-9.8144445
155.6491,0.64935833,9.4138212,0.0,0,18.0,330.0,0.9879927,3.1211648,18.105003,395.47101,-9.8311281
155.6513,0.62344742,9.4101954,0.0,0,18.0,330.0,0.98706675,2.975415,18.104576,395.43118,-9.8479471
155.6535,0.61004263,9.4174576,0.0,0,18.0,330.0,0.98863125,2.9187431,18.103157,395.39136,-9.8632841
155.6557,0.62627476,9.4119835,0.0,0,18.0,330.0,0.98732322,2.9441295,18.105974,395.35156,-9.8782568
155.6579,0.68065965,9.4127674,0.0,0,18.0,330.0,0.98799807,3.1908131,18.098366,395.31174,-9.8945618
155.6601,0.70296329,9.4108715,0.0,0,18.0,330.0,0.98696965,3.3045187,18.097931,395.20435,-9.9099245
155.6623,0.71921372,9.4174156,0.0,0,18.0,330.0,0.98869491,3.4090536,18.10029,395.07162,-9.9263916
155.6645,0.71493232,9.4132051,0.0,0,18.0,330.0,0.98721576,3.4243243,18.101503,394.9389,-9.9439373
155.6667,0.66705644,9.4145641,0.0,0,18.0,330.0,0.9882071,3.2123725,18.101297,394.80618,-9.9589367
155.6689,0.64022118,9.4105272,0.0,0,18.0,330.0,0.98680896,3.0125923,18.098816,394.67105,-9.9747133
155.6711,0.61097169,9.414175,0.0,0,18.0,330.0,0.98821908,2.9079738,18.097818,394.52505,-9.9903383
155.6733,0.61798936,9.4142704,0.0,0,18.0,330.0,0.98721272,2.9712219,18.093533,394.37906,-10.005944
155.6755,0.64487576,9.4129,0.0,0,18.0,330.0,0.98807597,3.0057564,18.097998,394.23306,-10.022311
155.6777,0.69124764,9.409338,0.0,0,18.0,330.0,0.98640114,3.2523265,18.096573,394.0871,-10.038958
155.6799,0.72051704,9.4131365,0.0,0,18.0,330.0,0.98841375,3.4059784,18.091629,394.00021,-10.054419
155.6821,0.72447282,9.4147787,0.0,0,18.0,330.0,0.9871555,3.415339,18.093349,393.94714,-10.069805
155.6843,0.70547497,9.4126425,0.0,0,18.0,330.0,0.98806113,3.3932748,18.095373,393.89404,-10.086109
155.6865,0.6654439,9.4124994,0.0,0,18.0,330.0,0.98681492,3.1981015,18.091312,393.84097,-10.103649
155.6887,0.62328869,9.4153042,0.0,0,18.0,330.0,0.98885232,2.968797,18.092188,393.78668,-10.118092
155.6909,0.63051915,9.4168224,0.0,0,18.0,330.0,0.98742723,3.0079479,18.09203,393.72034,-10.134208
155.6931,0.64290065,9.4107285,0.0,0,18.0,330.0,0.98797023,3.0173168,18.089451,393.65396,-10.148848
155.6953,0.69773602,9.4140682,0.0,0,18.0,330.0,0.98695368,3.2399518,18.086187,393.58762,-10.16478
155.6975,0.7296263,9.4129868,0.0,0,18.0,330.0,0.98854238,3.4391894,18.089268,393.52124,-10.182565
155.6997,0.7481702,9.4157305,0.0,0,18.0,330.0,0.98717713,3.5233493,18.092201,393.4585,-10.199041
155.7019,0.71839184,9.4136429,0.0,0,18.0,330.0,0.98854226,3.4002326,18.086304,393.39877,-10.215603
155.7041,0.6995883,9.4125729,0.0,0,18.0,330.0,0.98679513,3.341902,18.088013,393.33905,-10.231877
155.7063,0.66695422,9.4150896,0.0,0,18.0,330.0,0.98901248,3.1907012,18.08742,393.27933,-10.246838
155.7085,0.63722199,9.4160013,0.0,0,18.0,330.0,0.98714226,3.0459535,18.087467,393.2196,-10.261231
155.7107,0.64609259,9.4087124,0.0,0,18.0,330.0,0.98790175,3.054611,18.086161,393.17978,-10.275647
155.7129,0.6849438,9.4134331,0.0,0,18.0,330.0,0.98679531,3.2277317,18.081589,393.13998,-10.292309
155.7151,0.7280457,9.4113646,0.0,0,18.0,330.0,0.98857713,3.4206133,18.079123,393.10016,-10.309195
155.7173,0.76217264,9.4162569,0.0,0,18.0,330.0,0.98705435,3.5840075,18.082758,393.06036,-10.324989
155.7195,0.741234,9.4100723,0.0,0,18.0,330.0,0.98827553,3.4974594,18.081263,393.01752,-10.341362
155.7217,0.70638478,9.4139509,0.0,0,18.0,330.0,0.98678964,3.4330189,18.076496,392.97107,-10.357279
155.7239,0.67749566,9.4091988,0.0,0,18.0,330.0,0.98822135,3.210048,18.082523,392.92459,-10.374281
155.7261,0.63664484,9.4152861,0.0,0,18.0,330.0,0.98693758,3.0768795,18.07498,392.87814,-10.390155
155.7283,0.63242793,9.4111624,0.0,0,18.0,330.0,0.98823369,3.0077538,18.075407,392.83167,-10.405415
155.7305,0.6556592,9.4138937,0.0,0,18.0,330.0,0.98677683,3.1131842,18.078527,392.79126,-10.422501
155.7327,0.69548517,9.4086781,0.0,0,18.0,330.0,0.98804468,3.2613204,18.077869,392.75143,-10.438165
155.7349,0.75056612,9.4148464,0.0,0,18.0,330.0,0.98654264,3.5092819,18.075052,392.71164,-10.454518
155.7371,0.75503665,9.4069443,0.0,0,18.0,330.0,0.98753411,3.5519528,18.077469,392.67181,-10.469586
155.7393,0.72253668,9.4142647,0.0,0,18.0,330.0,0.98690325,3.467386,18.075928,392.62717,-10.484938
155.7415,0.6856581,9.4111557,0.0,0,18.0,330.0,0.98852271,3.2657332,18.078869,392.5741,-10.503205
155.7437,0.64719129,9.4182053,0.0,0,18.0,330.0,0.9871937,3.0688512,18.084339,392.521,-10.518172
155.7459,0.64429647,9.4053516,0.0,0,18.0,330.0,0.98740596,3.0392444,18.072166,392.46793,-10.534343
155.7481,0.63877636,9.4138975,0.0,0,18.0,330.0,0.9866755,3.0309823,18.075573,392.41483,-10.548557
155.7503,0.68526542,9.4095392,0.0,0,18.0,330.0,0.98816222,3.2226987,18.074337,392.36719,-10.56336
155.7525,0.73036784,9.4171085,0.0,0,18.0,330.0,0.98686165,3.4893322,18.073076,392.32071,-10.580763
155.7547,0.76111853,9.4062319,0.0,0,18.0,330.0,0.98762518,3.5656013,18.073174,392.27426,-10.597892
155.7569,0.73379976,9.4140911,0.0,0,18.0,330.0,0.98680705,3.5268548,18.072973,392.22781,-10.614131
155.7591,0.70878571,9.4090223,0.0,0,18.0,330.0,0.98822606,3.4046342,18.0739,392.1868,-10.62928
155.7613,0.66255742,9.4172583,0.0,0,18.0,330.0,0.9869197,3.1760519,18.074705,392.16025,-10.645513
155.7635,0.64568627,9.4075909,0.0,0,18.0,330.0,0.98774552,3.088201,18.071123,392.1337,-10.661806
155.7657,0.63943428,9.4140406,0.0,0,18.0,330.0,0.98692209,3.0072498,18.071724,392.10715,-10.676934
155.7679,0.66495669,9.4073257,0.0,0,18.0,330.0,0.98787099,3.1336823,18.070797,392.0806,-10.692082
155.7701,0.7290321,9.4166927,0.0,0,18.0,330.0,0.98693717,3.3838179,18.068371,392.02994,-10.709267
155.7723,0.76534259,9.4091444,0.0,0,18.0,330.0,0.98791391,3.6172771,18.06365,391.97021,-10.725416
155.7745,0.75699204,9.4128304,0.0,0,18.0,330.0,0.98678595,3.595998,18.062214,391.91049,-10.741824
155.7767,0.72577834,9.4056549,0.0,0,18.0,330.0,0.98747998,3.4835975,18.067123,391.85077,-10.758895
155.7789,0.68998563,9.4192915,0.0,0,18.0,330.0,0.9874751,3.3034625,18.067911,391.79227,-10.775978
155.7811,0.66215986,9.4094305,0.0,0,18.0,330.0,0.98790205,3.1580639,18.063099,391.73917,-10.790971
155.7833,0.65491152,9.4159126,0.0,0,18.0,330.0,0.98730224,3.0890145,18.062618,391.6861,-10.805357
155.7855,0.6689555,9.4068203,0.0,0,18.0,330.0,0.98766905,3.1535602,18.064436,391.633,-10.820654
155.7877,0.7036112,9.4181013,0.0,0,18.0,330.0,0.98750627,3.2868068,18.061419,391.57993,-10.837726
155.7899,0.75522327,9.4072914,0.0,0,18.0,330.0,0.98746973,3.5227478,18.058123,391.53528,-10.852613
155.7921,0.77284479,9.4141226,0.0,0,18.0,330.0,0.98704231,3.6547868,18.065287,391.49545,-10.866991
155.7943,0.75705677,9.4083223,0.0,0,18.0,330.0,0.98768973,3.662421,18.065847,391.45566,-10.883315
155.7965,0.71831125,9.4212999,0.0,0,18.0,330.0,0.98816544,3.4468501,18.063461,391.41583,-10.899631
155.7987,0.67548656,9.4098854,0.0,0,18.0,330.0,0.98767889,3.2249856,18.058382,391.37723,-10.916771
155.8009,0.64409083,9.413166,0.0,0,18.0,330.0,0.98708576,3.0790718,18.061699,391.35068,-10.933555
155.8031,0.65531653,9.407939,0.0,0,18.0,330.0,0.98747909,3.1175745,18.065479,391.32413,-10.948454
155.8053,0.68762767,9.4186363,0.0,0,18.0,330.0,0.98782849,3.2253313,18.057524,391.29758,-10.964553
155.8075,0.74805802,9.4083309,0.0,0,18.0,330.0,0.98731607,3.4820714,18.058079,391.27103,-10.982948
155.8097,0.76064986,9.4117489,0.0,0,18.0,330.0,0.98688275,3.625968,18.058958,391.24088,-10.997041
155.8119,0.77236736,9.4056091,0.0,0,18.0,330.0,0.98684669,3.6847491,18.059004,391.2077,-11.014297
155.8141,0.72281128,9.4180794,0.0,0,18.0,330.0,0.98780835,3.5029643,18.057487,391.1745,-11.03023
155.8163,0.68565607,9.4098196,0.0,0,18.0,330.0,0.98752767,3.2604291,18.057281,391.14133,-11.045059
155.8185,0.65725559,9.4140234,0.0,0,18.0,330.0,0.98735166,3.1270671,18.057781,391.10815,-11.060957
155.8207,0.64819157,9.4084406,0.0,0,18.0,330.0,0.98711514,3.0958819,18.056562,391.05505,-11.076984
155.8229,0.6682241,9.4175968,0.0,0,18.0,330.0,0.98785633,3.1446798,18.057356,391.00198,-11.092972
155.8251,0.71489257,9.4054508,0.0,0,18.0,330.0,0.98672616,3.3431089,18.053307,390.94888,-11.108311
155.8273,0.76337636,9.4111233,0.0,0,18.0,330.0,0.98699141,3.6073399,18.054348,390.89581,-11.123571
155.8295,0.78041583,9.4075136,0.0,0,18.0,330.0,0.98692256,3.6947975,18.052149,390.85779,-11.137836
155.8317,0.76364243,9.4186621,0.0,0,18.0,330.0,0.98809403,3.6580808,18.05578,390.83789,-11.153504
155.8339,0.71091771,9.4079275,0.0,0,18.0,330.0,0.9870013,3.4036219,18.055702,390.81799,-11.171069
155.8361,0.66888851,9.4108925,0.0,0,18.0,330.0,0.98721063,3.238976,18.055317,390.7981,-11.186829
155.8383,0.64991033,9.4074211,0.0,0,18.0,330.0,0.98663527,3.0701542,18.05731,390.77817,-11.202554
155.8405,0.67169827,9.4153357,0.0,0,18.0,330.0,0.98784286,3.1521277,18.05385,390.75223,-11.217411
155.8427,0.7064749,9.4073381,0.0,0,18.0,330.0,0.986682,3.2993035,18.052916,390.72568,-11.234963
155.8449,0.75061333,9.4110203,0.0,0,18.0,330.0,0.98723745,3.5267096,18.053251,390.69913,-11.252703
155.8471,0.78112262,9.4079857,0.0,0,18.0,330.0,0.98670012,3.6857934,18.052725,390.67261,-11.268025
155.8493,0.78928304,9.4166775,0.0,0,18.0,330.0,0.98805875,3.7565854,18.046808,390.63638,-11.283659
155.8515,0.74656487,9.4112654,0.0,0,18.0,330.0,0.98716182,3.5814912,18.048975,390.58331,-11.299262
155.8537,0.70263088,9.4138536,0.0,0,18.0,330.0,0.98800886,3.3503075,18.051304,390.53021,-11.316149
155.8559,0.6610902,9.4069395,0.0,0,18.0,330.0,0.98645288,3.1929631,18.049732,390.47711,-11.331988
155.8581,0.66537243,9.415123,0.0,0,18.0,330.0,0.98817801,3.1388545,18.049963,390.42401,-11.347594
155.8603,0.68497151,9.4101458,0.0,0,18.0,330.0,0.98684543,3.2607126,18.049744,390.38721,-11.363398
156.6608,0.64662349,9.4175797,0.0,0,18.0,4.1213553e-09,0.98846555,3.0677674,18.002285,372.50967,-11.48249
157.7608,0.62484533,9.4242516,0.0,0,18.0,4.1163117e-24,0.98960078,2.9529655,18.000492,356.52267,-11.481806
158.8608,0.6238786,9.4302559,0.0,0,18.0,4.1112752e-39,0.99068248,2.9539163,17.999048,342.83398,-11.481894
159.9608,0.60248619,9.4362745,0.0,0,18.0,1.4012985e-45,0.99177384,2.8477373,18.000471,332.15317,-11.482299
161.0608,0.60255116,9.4410677,0.0,0,18.0,1.4012985e-45,0.99266344,2.8458443,17.999537,322.59341,-11.4827
162.1608,0.60008603,9.4461527,0.0,0,18.0,1.4012985e-45,0.99353725,2.8229055,17.998287,313.55026,-11.482421
163.2608,0.5860064,9.4507751,0.0,0,18.0,1.4012985e-45,0.99434471,2.7628355,17.998896,305.05191,-11.482008
164.3608,0.58391649,9.4553862,0.0,0,18.0,1.4012985e-45,0.99528158,2.745429,17.999121,296.85635,-11.481681
165.4608,0.59984463,9.4605827,0.0,0,18.0,1.4012985e-45,0.99618512,2.8185186,17.999317,289.16852,-11.481827
166.5608,0.60595524,9.4650412,0.0,0,18.0,1.4012985e-45,0.99687916,2.8505659,17.999891,281.62515,-11.482728
167.6608,0.59477472,9.4684439,0.0,0,18.0,1.4012985e-45,0.99767166,2.7949545,17.999794,274.45111,-11.482838
168.7608,0.58340824,9.472662,0.0,0,18.0,1.4012985e-45,0.99839664,2.7318113,17.99987,267.60718,-11.482011
169.8608,0.58734876,9.4776192,0.0,0,18.0,1.4012985e-45,0.99916995,2.7512934,17.999807,260.71832,-11.482483
170.9608,0.57776564,9.4810486,0.0,0,18.0,1.4012985e-45,0.9998861,2.711102,17.99988,254.10577,-11.482046
172.0608,0.58210588,9.4850826,0.0,0,18.0,1.4012985e-45,1.0006375,2.7226927,17.999828,247.91298,-11.481782
173.1608,0.58666861,9.4881306,0.0,0,18.0,1.4012985e-45,1.0011406,2.7430274,18.000023,242.1757,-11.481858
174.2608,0.59682178,9.4920769,0.0,0,18.0,1.4012985e-45,1.0018675,2.7962484,18.000063,236.88667,-11.482764
175.3608,0.5772438,9.4959269,0.0,0,18.0,1.4012985e-45,1.0025332,2.6951709,17.999598,230.91446,-11.482424
176.4608,0.58640176,9.499321,0.0,0,18.0,1.4012985e-45,1.0032542,2.7325513,17.999186,225.1723,-11.481842
177.5608,0.58561534,9.5026693,0.0,0,18.0,1.4012985e-45,1.0038112,2.7348156,17.999701,219.884,-11.481626
178.6608,0.58478403,9.5060949,0.0,0,18.0,1.4012985e-45,1.0043292,2.732614,17.99968,214.7832,-11.481885
179.7608,0.5949567,9.5083618,0.0,0,18.0,1.4012985e-45,1.0049132,2.7703133,17.999399,209.40068,-11.481906
180.8608,0.59540206,9.5110064,0.0,0,18.0,1.4012985e-45,1.0053574,2.7780578,17.999804,203.98132,-11.482362
181.9608,0.58010608,9.5134621,0.0,0,18.0,1.4012985e-45,1.0056973,2.7078233,17.999935,198.90846,-11.482676
183.0608,0.57084733,9.516284,0.0,0,18.0,1.4012985e-45,1.0062759,2.6566916,18.00016,193.96306,-11.482182
184.1608,0.58687371,9.5187998,0.0,0,18.0,1.4012985e-45,1.0067374,2.725081,18.000095,189.20599,-11.48162
185.2608,0.58399194,9.5210094,0.0,0,18.0,1.4012985e-45,1.0071422,2.7211285,18.000355,184.67792,-11.481801
186.3608,0.59043968,9.5242176,0.0,0,18.0,1.4012985e-45,1.0076743,2.7433162,17.999838,180.19881,-11.482268
187.4608,0.60126048,9.5268383,0.0,0,18.0,1.4012985e-45,1.0081213,2.7942965,17.999796,175.89047,-11.482745
188.5608,0.58192629,9.5285835,0.0,0,18.0,1.4012985e-45,1.0086077,2.7041936,17.999538,171.70396,-11.482058
189.6608,0.57240421,9.5315819,0.0,0,18.0,1.4012985e-45,1.0091211,2.6636686,17.99983,167.63918,-11.482109
190.7608,0.57742643,9.5341358,0.0,0,18.0,1.4012985e-45,1.0094732,2.6762381,17.999231,163.69257,-11.481696
191.8608,0.59936994,9.5362082,0.0,0,18.0,1.4012985e-45,1.0099325,2.7800081,17.999668,159.85515,-11.481905
192.9608,0.59211445,9.5390196,0.0,0,18.0,1.4012985e-45,1.0104488,2.749697,17.999399,156.19986,-11.48228
194.0608,0.57850713,9.5409374,0.0,0,18.0,1.4012985e-45,1.0107954,2.675915,17.99988,152.5316,-11.482171
195.1608,0.5838837,9.5433455,0.0,0,18.0,1.4012985e-45,1.0111846,2.7043598,18.000326,149.01738,-11.482185
196.2608,0.57896048,9.5458536,0.0,0,18.0,1.4012985e-45,1.0116043,2.6852102,18.00005,145.5912,-11.481847
197.3608,0.56383854,9.547946,0.0,0,18.0,1.4012985e-45,1.0121311,2.6080501,18.000677,142.21931,-11.481599
198.4608,0.56729573,9.5503635,0.0,0,18.0,1.4012985e-45,1.0125506,2.6176918,18.000521,138.98183,-11.481406
199.5608,0.58835149,9.5526628,0.0,0,18.0,1.4012985e-45,1.0128651,2.7190957,17.999918,135.91595,-11.481834
200.6608,0.58276421,9.5544109,0.0,0,18.0,1.4012985e-45,1.0132409,2.6980624,18.000164,132.87433,-11.482363
201.7608,0.56932694,9.5565529,0.0,0,18.0,1.4012985e-45,1.0136063,2.6261675,18.000374,129.88898,-11.48206
202.8608,0.57496136,9.5586376,0.0,0,18.0,1.4012985e-45,1.0141206,2.6530724,17.999794,126.96929,-11.481614
203.9608,0.57035232,9.5606594,0.0,0,18.0,1.4012985e-45,1.0144191,2.6365921,17.999628,124.2541,-11.481304
205.0608,0.56844002,9.562397,0.0,0,18.0,1.4012985e-45,1.0146391,2.6198683,18.000004,121.43824,-11.481094
206.1608,0.58829135,9.5648022,0.0,0,18.0,1.4012985e-45,1.0152261,2.7050369,17.999989,118.86348,-11.481621
207.2608,0.59217608,9.5662403,0.0,0,18.0,1.4012985e-45,1.0154595,2.735806,17.99967,116.28634,-11.48254
208.3608,0.58401084,9.5682926,0.0,0,18.0,1.4012985e-45,1.0157969,2.6979067,18.000069,113.81689,-11.482525
209.4608,0.56974655,9.5699034,0.0,0,18.0,1.4012985e-45,1.0160646,2.6176095,17.999212,111.24417,-11.481685
210.5608,0.57660639,9.5724401,0.0,0,18.0,1.4012985e-45,1.0164862,2.6576912,18.000004,109.0593,-11.481722
211.6608,0.56212544,9.5734959,0.0,0,18.0,1.4012985e-45,1.0168471,2.5959659,18.001261,106.70674,-11.481449
212.7608,0.56228596,9.5754871,0.0,0,18.0,1.4012985e-45,1.0171726,2.5874195,17.999138,104.53044,-11.480863
213.8608,0.57309026,9.5767069,0.0,0,18.0,1.4012985e-45,1.0173177,2.6333487,18.001013,102.38148,-11.481324
214.9608,0.57997215,9.5786772,0.0,0,18.0,1.4012985e-45,1.017702,2.677465,18.000051,100.27886,-11.481075
215.8608,0.57874924,9.5797567,0.0,0,18.0,1.4012985e-45,1.0179564,2.6537786,17.999815,98.517647,-11.481544