File: examples/dan-msc-case-studies/CS3/data/01 raw data/baron_test_023.csv
Time(sec),Force(kN),Jaw(mm),PowAngle(deg),Power(W),Pram,PTemp,Strain,Stress(MPa),Stroke(mm),TC1(C),wedge(mm)
0.0,2.4983976,22.610697,0.0,0,10.594783,0.0011718067,9.6158047,0.0021221682,10.595225,24.295002,-9.1261625
2.1,2.3345265,-0.0020037917,0.0,0,10.594783,6.2159009,-0.00013714327,29.710169,10.595545,24.312405,-9.4861002
4.2,2.3095486,-0.0017047798,0.0,0,10.594783,12.515903,-0.00010832052,29.409498,10.594384,24.305052,-9.4846792
6.3,2.2675779,-0.0019008067,0.0,0,10.594783,18.815905,-9.6747965e-05,28.878305,10.594934,24.342194,-9.4798813
8.4,2.2616217,-0.0014651772,1.5274954,0,10.594783,25.115908,-9.2695853e-05,28.80578,10.59541,24.228502,-9.4771938
10.5,2.2625179,-0.00062036555,32.741898,0,10.594783,31.415909,-7.321583e-05,28.796097,10.594659,25.270283,-9.4733667
12.6,2.274225,-0.0044688513,42.385323,0,10.594783,37.715919,-0.00029333579,28.969852,10.594916,30.819912,-9.4693661
14.7,2.2904446,-0.011079607,44.604488,0,10.594783,44.015915,-0.00074171234,29.188332,10.594436,39.695648,-9.4655514
16.8,2.2972677,-0.017192671,43.203571,0,10.594783,50.31591,-0.0011246073,29.272539,10.594487,49.381439,-9.4614286
18.9,2.3014255,-0.022165282,41.198734,0,10.594783,56.61591,-0.0014786781,29.357189,10.595052,57.547012,-9.4580154
21.0,2.2824941,-0.026591007,39.370724,0,10.594783,62.915924,-0.0017911213,29.095921,10.595095,64.08078,-9.4543076
23.1,2.2973452,-0.02972143,39.924313,0,10.594783,69.215919,-0.0019806637,29.319668,10.594755,69.377716,-9.4511414
25.2,2.2977309,-0.033974212,41.430084,0,10.594783,75.515923,-0.0022647236,29.320786,10.594718,74.828163,-9.4482632
27.3,2.2809155,-0.038722958,42.978512,0,10.594783,81.815933,-0.0025570237,29.11561,10.59548,80.537445,-9.4445572
29.4,2.276036,-0.043029934,44.07711,0,10.594783,88.115929,-0.0028595084,29.066885,10.594053,87.10466,-9.4401989
31.5,2.3280294,-0.046919666,44.434601,0,10.594783,94.415916,-0.0031492549,29.740818,10.595346,93.723373,-9.4388294
33.6,2.2948432,-0.052572686,44.604488,0,10.594783,100.71592,-0.0035070262,29.30669,10.595509,100.20344,-9.4330788
35.7,2.3223813,-0.056729943,45.12085,0,10.594783,107.01594,-0.0037600554,29.677206,10.595035,106.47665,-9.4299259
37.8,2.3196685,-0.061667476,45.614582,0,10.594783,113.31594,-0.0040985565,29.658007,10.595506,112.76343,-9.42698
39.9,2.3321624,-0.066228628,45.991173,0,10.594783,119.61594,-0.004386073,29.807909,10.594043,119.13735,-9.4233274
42.0,2.3364527,-0.071271583,46.582027,0,10.594783,125.91592,-0.0047496408,29.906946,10.594611,125.28342,-9.4200001
44.1,2.3443244,-0.07630913,47.05444,0,10.594783,132.21593,-0.0050925314,29.993446,10.594932,131.53856,-9.4169216
46.2,2.3529544,-0.081480727,47.516998,0,10.594783,138.51593,-0.0054179318,30.125669,10.594509,137.81323,-9.4126215
48.3,2.3452039,-0.086701594,48.127304,0,10.594783,144.81595,-0.0057585132,30.044277,10.594915,144.14073,-9.4090729
50.4,2.3762736,-0.091654427,48.38343,0,10.594783,151.11592,-0.0060736681,30.445189,10.59444,150.67424,-9.4061956
52.5,2.3660386,-0.097540997,48.383785,0,10.594783,157.41592,-0.0064688553,30.32844,10.593753,157.06216,-9.4023914
54.6,2.3749545,-0.10308291,48.812252,0,10.594783,163.71594,-0.0068650106,30.438362,10.594392,163.25552,-9.3984842
56.7,2.3770151,-0.10752937,48.88345,0,10.594783,170.01595,-0.007157377,30.491388,10.594722,169.76346,-9.3949728
58.8,2.3840075,-0.11349308,49.229733,0,10.594783,176.31596,-0.0075335074,30.583529,10.594362,175.92014,-9.3917904
60.9,2.3927288,-0.11844488,49.636227,0,10.594783,182.61595,-0.0078635914,30.714417,10.594537,182.188,-9.3882065
63.0,2.3948843,-0.12396809,50.042721,0,10.594783,188.91594,-0.0082113463,30.744287,10.594915,188.38397,-9.3851881
65.1,2.4068758,-0.12942354,50.428471,0,10.594783,195.21596,-0.0085688364,30.918499,10.594693,194.69154,-9.3814526
67.2,2.4000576,-0.13418314,50.438229,0,10.594783,201.51596,-0.0089174146,30.832911,10.595192,201.1189,-9.3778706
69.3,2.4082623,-0.13925254,50.82275,0,10.594783,207.81596,-0.0092599848,30.943645,10.595487,207.35612,-9.3742476
71.4,2.4206076,-0.14595406,51.195965,0,10.594783,214.11595,-0.0096808067,31.122343,10.594451,213.65961,-9.3704042
73.5,2.4166102,-0.15030736,51.56982,0,10.594783,220.41594,-0.0099694971,31.070498,10.594207,219.75259,-9.3669348
75.6,2.4241757,-0.15626556,51.932369,0,10.594783,226.71596,-0.010351368,31.193213,10.595086,226.09337,-9.3636723
77.7,2.4231937,-0.16183898,52.270344,0,10.594783,233.01596,-0.010711713,31.193077,10.594362,232.5144,-9.3596516
79.8,2.431252,-0.16726528,52.283936,0,10.594783,239.31596,-0.011090929,31.305162,10.594393,238.89519,-9.3568296
81.9,2.421351,-0.17247422,52.399189,0,10.594783,245.61595,-0.011453548,31.185402,10.59488,245.38223,-9.3527899
84.0,2.4435859,-0.17942372,52.635494,0,10.594783,251.91595,-0.011894321,31.475281,10.594683,251.66122,-9.3494024
86.1,2.4332316,-0.18436924,52.724873,0,10.594783,258.21622,-0.012211453,31.376709,10.593779,257.96237,-9.3457327
88.2,2.44349,-0.18987527,53.314812,0,10.594783,264.51599,-0.012572343,31.502785,10.594769,263.92914,-9.3424072
90.3,2.4456131,-0.19517377,53.657192,0,10.594783,270.81598,-0.012904858,31.547485,10.595347,270.21918,-9.3387012
92.4,2.444,-0.2025681,53.975658,0,10.594783,277.11597,-0.013399687,31.543192,10.595359,276.45789,-9.3351126
94.5,2.445848,-0.20839065,54.10976,0,10.594783,283.41595,-0.013818219,31.57159,10.594947,282.93869,-9.3314962
96.6,2.4433987,-0.21391837,53.991062,0,10.594783,289.71597,-0.014177467,31.552689,10.59459,289.48755,-9.3283653
98.7,2.4455023,-0.22088633,54.305416,0,10.594783,296.01599,-0.014608465,31.578871,10.594663,295.67368,-9.3246222
100.8,2.4471762,-0.22619383,54.624023,0,10.594783,302.31601,-0.014959191,31.638083,10.594592,301.91687,-9.3213377
102.9,2.4504178,-0.23126638,54.847954,0,10.594783,308.61597,-0.015282457,31.671398,10.595199,308.203,-9.3178453
105.0,2.4561632,-0.23860599,55.239254,0,10.594783,314.91595,-0.015761765,31.789021,10.594972,314.19177,-9.3140535
107.1,2.4459827,-0.24360414,55.535885,0,10.594783,321.21597,-0.016122477,31.647985,10.594419,320.63055,-9.3106718
109.2,2.4443567,-0.24946824,55.70565,0,10.594783,327.51602,-0.016510125,31.640928,10.594421,327.14172,-9.306673
111.3,2.4401681,-0.2541866,55.535892,0,10.594783,333.81601,-0.016817709,31.60582,10.593985,333.7756,-9.3033829
113.4,2.4468279,-0.25943139,55.535885,0,10.594783,340.116,-0.017139154,31.681189,10.59489,340.08899,-9.300128
115.5,2.4462554,-0.26580933,55.535885,0,10.594783,346.41599,-0.017567981,31.715837,10.594875,346.43347,-9.2963037
117.6,2.454602,-0.26995847,55.535885,0,10.594783,352.716,-0.017823286,31.802706,10.594834,352.63638,-9.2932768
119.7,2.4489582,-0.27626824,55.84185,0,10.594783,359.01602,-0.018220916,31.753107,10.595348,358.70825,-9.2897997
121.8,2.4406562,-0.28103906,56.123203,0,10.594783,365.31604,-0.018562138,31.660816,10.59497,364.78894,-9.2862291
123.9,2.4420936,-0.28522366,56.425354,0,10.594783,371.616,-0.018857274,31.693983,10.59514,371.04004,-9.2826071
126.0,2.4453197,-0.29176167,56.518291,0,10.594783,377.91599,-0.01928686,31.754398,10.595728,377.40005,-9.2793121
128.1,2.4399996,-0.29562944,56.702206,0,10.594783,384.21603,-0.019515326,31.676563,10.595137,383.96707,-9.2757263
130.2,2.4454565,-0.29906937,56.506329,0,10.594783,390.51602,-0.019739455,31.760744,10.593984,390.42929,-9.2725372
132.3,2.4156797,-0.30385739,56.711422,0,10.594783,396.81601,-0.020056536,31.379328,10.594896,396.60455,-9.2688637
134.4,2.4050062,-0.30643815,54.711132,0,10.594783,399.99893,-0.020203345,31.239107,10.593832,402.66248,-9.2669678
136.5,2.3557377,-0.30476865,49.663754,0,10.594783,399.99893,-0.020106224,30.6129,10.593615,405.93417,-9.2670631
138.6,2.3110449,-0.30022547,46.109886,0,10.594783,399.99893,-0.019826086,30.000826,10.595574,405.08115,-9.2667246
140.7,2.2756102,-0.29403242,46.109619,0,10.594783,399.99893,-0.019433549,29.557638,10.594653,402.03131,-9.2669563
142.8,2.2677364,-0.29050928,48.357201,0,10.594783,399.99893,-0.019205008,29.430552,10.595238,399.40103,-9.266819
144.9,2.2756398,-0.29003114,50.032852,0,10.594783,399.99893,-0.019137569,29.543045,10.594534,398.40063,-9.2666893
147.0,2.2705421,-0.29003987,50.809006,0,10.594783,399.99893,-0.019146312,29.453445,10.594688,398.74176,-9.266902
149.1,2.2693598,-0.28962445,50.61208,0,10.594783,399.99893,-0.019134019,29.443329,10.594906,399.54025,-9.2666788
151.2,2.2573388,-0.2903282,50.042728,0,10.594783,399.99893,-0.019157805,29.291189,10.594731,400.35327,-9.2665434
153.3,2.257221,-0.28914726,49.522606,0,10.594783,399.99893,-0.019072236,29.281551,10.594394,400.59186,-9.266469
155.4,2.232904,-0.28876686,49.22974,0,10.594783,399.99893,-0.019063989,28.970863,10.594851,400.55698,-9.266448
157.5,2.059885,-0.28945497,49.219517,0,10.594783,399.99893,-0.019126814,26.719587,10.594755,400.21802,-9.2664242
159.6,1.887073,-0.28957772,49.350922,0,10.594783,399.99893,-0.019137701,24.487803,10.594296,399.82712,-9.2666311
161.7,1.7103068,-0.29248309,49.636227,0,10.594783,399.99893,-0.019339338,22.203438,10.594992,399.58734,-9.2663031
163.8,1.5287089,-0.29529035,50.042721,0,10.594783,399.99893,-0.019503271,19.836885,10.595364,399.5538,-9.2665472
165.9,1.3596563,-0.2974062,50.2728,0,10.594783,399.99893,-0.019616911,17.664713,10.594763,399.67688,-9.2664127
168.0,1.1944205,-0.30187595,50.4384,0,10.594783,399.99893,-0.019921854,15.511844,10.594224,399.64063,-9.2666159
170.1,1.0444591,-0.3039391,50.82275,0,10.594783,399.99893,-0.020067371,13.564842,10.594486,399.50256,-9.2664518
172.2,0.93401062,-0.30621248,51.196285,0,10.594783,399.99893,-0.020197414,12.144812,10.595145,399.4585,-9.2669191
174.3,0.86567837,-0.30846226,51.56982,0,10.594783,399.99893,-0.020335251,11.244218,10.594099,399.52191,-9.2662954
176.4,0.85556036,-0.30939895,51.569828,0,10.594783,399.99893,-0.020409428,11.116762,10.594639,399.74182,-9.2662487
178.4647,0.84635764,-0.022724602,51.569828,0,10.594783,399.99893,-0.0015626258,10.796342,10.594904,400.06149,-9.2664623
178.6186,0.79859585,0.023106061,51.569824,0,10.5948,1.8726595e-23,0.0014320966,10.16118,10.590249,400.1055,-9.2665195
178.6228,0.86044526,0.024464086,51.569824,0,10.5948,0.0,0.0015060519,10.948301,10.597406,400.11813,-9.2666235
178.627,0.84670055,0.018766647,34.551731,0,10.5948,0.0,0.001526113,10.718552,10.589385,400.13077,-9.2673397
178.6312,0.8383258,0.021337101,12.892405,0,10.5948,0.0,0.001268701,10.734362,10.600389,400.14343,-9.2668085
178.6354,0.85448611,0.022089684,0.0,0,10.5948,0.0,0.0013887561,10.877118,10.59684,400.17651,-9.2682457
178.6396,0.83194077,0.019202475,0.0,0,10.5948,0.0,0.0014232422,10.620564,10.59812,400.23975,-9.2665768
178.6438,0.82842612,0.021883678,0.0,0,10.5948,0.0,0.0013197819,10.611633,10.593755,400.30115,-9.2662077
178.648,0.83293736,0.024643864,0.0,0,10.5948,0.0,0.001486157,10.595945,10.592702,400.28851,-9.2660189
178.6522,0.82911128,0.019079428,0.0,0,10.5948,0.0,0.0014636287,10.531017,10.595708,400.27588,-9.266983
178.6564,0.83727288,0.020197812,0.0,0,10.5948,0.0,0.0012039276,10.539965,10.591444,400.2551,-9.265666
178.6606,0.82603854,0.021252688,0.0,0,10.5948,0.0,0.0013205208,10.473215,10.59071,400.2298,-9.2654037
178.6648,0.81640679,0.019440249,0.0,0,10.5948,0.0,0.0014397098,10.365325,10.590603,400.21112,-9.2671671
178.669,0.81906563,0.022099189,0.0,0,10.533863,0.0,0.0013787651,10.382131,10.59529,400.21112,-9.265811
178.6732,0.80520517,0.0235295,0.0,0,10.470864,0.0,0.0014258457,10.226918,10.588611,400.21112,-9.2673302
178.6774,0.80742389,0.019214796,0.0,0,10.407864,0.0,0.0015492052,10.323534,10.558554,400.19998,-9.2658806
178.6816,0.81771183,0.019832348,0.0,0,10.344864,0.0,0.0012721921,10.359048,10.476557,400.18735,-9.2664757
178.6858,0.80991644,0.020531135,0.0,0,10.281863,0.0,0.0012994591,10.20149,10.376657,400.1684,-9.266449
178.69,0.81318116,0.019194856,0.0,0,10.218863,0.0,0.0014517187,10.363331,10.289405,400.14313,-9.2676563
178.6942,0.80611157,0.02088476,0.0,0,10.155864,0.0,0.0012125268,10.290281,10.230819,400.11935,-9.2678547
178.6984,0.79995334,0.024206584,0.0,0,10.092864,0.0,0.001458546,10.177224,10.186758,400.10672,-9.2666855
178.7026,0.79564112,0.019846676,0.0,0,10.029863,0.0,0.0015751478,10.125804,10.13284,400.09406,-9.264431
178.7068,0.79565823,0.01951245,0.0,0,9.9668636,0.0,0.0012388633,10.086562,10.067153,400.10941,-9.2672987
178.711,2.1055596,0.029482799,0.0,0,9.9038639,0.0,0.001849818,26.46163,9.9967747,400.1347,-9.2664642
178.7152,4.4322901,0.055090174,0.0,0,9.8408632,0.0,0.0038526428,56.03157,9.9435291,400.23672,-9.2639751
178.7194,5.6501908,0.10989545,0.0,0,9.7778635,0.0,0.0072579281,71.299759,9.8773746,400.47693,-9.2625628
178.7236,6.2292972,0.17855968,0.0,0,9.7148628,0.0,0.011781622,78.220184,9.8091908,400.71713,-9.2619505
178.7278,6.5816512,0.23914357,0.0,0,9.6518641,0.0,0.016220998,82.366562,9.7354832,401.00668,-9.2631721
178.732,6.8068004,0.29945663,0.0,0,9.5888634,0.0,0.020108161,84.910393,9.6710806,401.29745,-9.2624063
178.7362,6.9637976,0.36329606,0.0,0,9.5258636,0.0,0.024384568,86.553978,9.60676,401.49796,-9.2613745
178.7404,7.0962477,0.4220801,0.0,0,9.4633293,0.0,0.028684309,87.808571,9.543437,401.63702,-9.2633057
178.7446,7.1869822,0.48573655,0.0,0,9.4018736,0.0,0.032823239,88.62513,9.4783726,401.76523,-9.2634411
178.7488,7.2762647,0.55003697,0.0,0,9.3404198,0.0,0.037108563,89.307076,9.4173441,401.85373,-9.262639
178.753,7.3447294,0.60770154,0.0,0,9.278965,0.0,0.041568846,89.702789,9.352766,401.94223,-9.2630119
178.7572,7.4104447,0.66917318,0.0,0,9.2175112,0.0,0.045596991,90.126724,9.2899332,402.06232,-9.2630558
178.7614,7.4656749,0.73062664,0.0,0,9.1560564,0.0,0.049810704,90.405708,9.2295494,402.18875,-9.2641926
178.7656,7.5368075,0.79060352,0.0,0,9.0946016,0.0,0.054359742,90.805405,9.1666222,402.27512,-9.2623911
178.7698,7.6180649,0.85357559,0.0,0,9.0331469,0.0,0.058419049,91.466835,9.1039295,402.31305,-9.2628298
178.774,7.662044,0.91651261,0.0,0,8.971693,0.0,0.062738582,91.662193,9.038867,402.33652,-9.2640448
178.7782,7.7155552,0.9751246,0.0,0,8.9102392,0.0,0.067396745,91.903915,8.9761181,402.17218,-9.2641478
178.7824,7.7785068,1.0342917,0.0,0,8.8487844,0.0,0.071388401,92.212944,8.9122887,402.00784,-9.2642574
178.7866,7.8048072,1.0977,0.0,0,8.7873297,0.0,0.075849026,92.136086,8.8467789,401.95697,-9.263588
178.7908,7.8332462,1.1565105,0.0,0,8.7270651,0.0,0.080422513,91.976051,8.7857361,401.95697,-9.2622099
178.795,7.8825583,1.2162377,0.0,0,8.6686182,0.0,0.084446587,92.215912,8.7272978,401.98438,-9.2640505
178.7992,7.9147296,1.2766913,0.0,0,8.6101713,0.0,0.088645793,92.248993,8.6717682,402.07285,-9.2631893
178.8034,7.9818773,1.3314284,0.0,0,8.5517235,0.0,0.093114123,92.558708,8.6101961,402.16135,-9.2631559
178.8076,8.0198488,1.3857437,0.0,0,8.4932766,0.0,0.096813545,92.71553,8.5490055,402.34375,-9.263607
178.8118,8.0570822,1.4466876,0.0,0,8.4348297,0.0,0.10126337,92.702621,8.4937649,402.53336,-9.2628231
178.816,8.1029682,1.50082,0.0,0,8.3763819,0.0,0.10563162,92.849243,8.4316397,402.79913,-9.2640038
178.8202,8.1524029,1.5632217,0.0,0,8.317935,0.0,0.10999464,92.966248,8.3749685,403.12784,-9.2634096
178.8244,8.1771507,1.6246754,0.0,0,8.2594881,0.0,0.114315,92.819061,8.3136826,403.43759,-9.263216
178.8286,8.2254047,1.6783333,0.0,0,8.2010412,0.0,0.11888504,93.018311,8.2550812,403.6525,-9.2641716
178.8328,8.2887344,1.7337469,0.0,0,8.1425943,0.0,0.12277273,93.2397,8.198576,403.8674,-9.2630653
178.837,8.3591175,1.7957246,0.0,0,8.0841465,0.0,0.12733822,93.696098,8.1377144,403.93332,-9.263608
178.8412,8.3956041,1.8550475,0.0,0,8.0270939,0.0,0.13224517,93.581169,8.0716629,403.95862,-9.2629366
178.8454,8.4072628,1.9133642,0.0,0,7.9714851,0.0,0.13643144,93.371353,8.015605,403.87131,-9.2639618
178.8496,8.4132185,1.9752361,0.0,0,7.9158773,0.0,0.14092112,93.006119,7.9569597,403.61847,-9.2637358
178.8538,8.4433823,2.023164,0.0,0,7.8602695,0.0,0.14513722,92.986168,7.9026728,403.37225,-9.2635221
178.858,8.4867744,2.0750303,0.0,0,7.8046613,0.0,0.14887048,93.191963,7.8468914,403.39755,-9.2640162
178.8622,8.5419874,2.1337543,0.0,0,7.7490535,0.0,0.15319939,93.265892,7.789,403.42285,-9.2641535
178.8664,8.5792646,2.1875279,0.0,0,7.6934457,0.0,0.15781437,93.230278,7.7346325,402.91986,-9.2638798
178.8706,8.6181793,2.2407784,0.0,0,7.6378374,0.0,0.16179378,93.397614,7.6786904,402.12341,-9.2636099
178.8748,8.6238565,2.2994847,0.0,0,7.5822296,0.0,0.16596852,93.017494,7.6263075,401.39648,-9.2634678
178.879,8.6723375,2.3470256,0.0,0,7.5266213,0.0,0.17040187,93.18692,7.5684667,400.86551,-9.2638693
178.8832,8.7545156,2.4005411,0.0,0,7.4710135,0.0,0.17438056,93.641197,7.5139012,400.33453,-9.2626848
178.8874,8.7735395,2.4613845,0.0,0,7.4154053,0.0,0.17903598,93.409256,7.4561992,400.87274,-9.2632589
178.8916,8.834568,2.5149493,0.0,0,7.361393,0.0,0.18367001,93.596077,7.3996711,401.55539,-9.2651196
178.8958,8.8725014,2.5718493,0.0,0,7.308507,0.0,0.18810222,93.599495,7.3426962,402.08636,-9.2634869
178.9,8.88484,2.6307933,0.0,0,7.2556205,0.0,0.19242017,93.367126,7.2849097,402.46564,-9.2650843
178.9042,8.9059305,2.6750546,0.0,0,7.202734,0.0,0.19667569,93.069496,7.2341104,402.83588,-9.2631559
178.9084,8.9524364,2.7254529,0.0,0,7.1498475,0.0,0.20045017,93.266296,7.1815982,403.13928,-9.2636614
178.9126,8.9624186,2.7804878,0.0,0,7.096961,0.0,0.2048129,93.029861,7.1332655,403.44269,-9.2638292
178.9168,9.0101604,2.8293207,0.0,0,7.044075,0.0,0.20917293,93.03524,7.0784168,403.67145,-9.2625875
178.921,9.042985,2.881279,0.0,0,6.991188,0.0,0.21334794,93.029289,7.0309324,403.87375,-9.2627144
178.9252,9.1216793,2.9405892,0.0,0,6.938302,0.0,0.21779568,93.461464,6.9762106,404.0715,-9.2636185
178.9294,9.1764803,2.9890037,0.0,0,6.8854156,0.0,0.22248048,93.462463,6.9201989,404.26114,-9.2633228
178.9336,9.2215776,3.0408795,0.0,0,6.8325291,0.0,0.22655985,93.526161,6.8624411,404.45074,-9.262332
178.9378,9.2467642,3.095402,0.0,0,6.7796426,0.0,0.23091915,93.432426,6.8095732,404.57867,-9.2642469
178.942,9.2834482,3.1486306,0.0,0,6.728508,0.0,0.23573427,93.338898,6.7519307,404.70511,-9.262332
178.9462,9.2929564,3.1991589,0.0,0,6.6781921,0.0,0.23992893,93.156982,6.701654,403.78549,-9.2615175
178.9504,9.3035412,3.2553256,0.0,0,6.6278758,0.0,0.24414271,92.776146,6.6524258,402.1546,-9.2636957
178.9546,9.3383312,3.3004329,0.0,0,6.5775599,0.0,0.24865894,92.702225,6.6029849,400.62122,-9.2643852
178.9588,9.3526945,3.3431373,0.0,0,6.5272441,0.0,0.25213739,92.45874,6.5548348,399.44553,-9.2643385
178.963,9.4151907,3.3952794,0.0,0,6.4769282,0.0,0.25632432,92.762085,6.5078444,398.26981,-9.2619724
178.9672,9.47363,3.4403179,0.0,0,6.4266124,0.0,0.26066476,92.95118,6.4566712,398.84299,-9.2632055
178.9714,9.543026,3.4943933,0.0,0,6.376296,0.0,0.26526961,93.198479,6.4021683,399.7659,-9.2634315
178.9756,9.580946,3.5532293,0.0,0,6.3259802,0.0,0.26980701,93.123405,6.3479323,400.58588,-9.262908
178.9798,9.5872211,3.5996072,0.0,0,6.2756648,0.0,0.27465439,92.719177,6.3029046,401.28119,-9.2625198
178.984,9.6222849,3.6451952,0.0,0,6.2253485,0.0,0.27845517,92.725296,6.2492452,401.96207,-9.2622766
178.9882,9.6757135,3.6974175,0.0,0,6.1750326,0.0,0.28270966,92.795799,6.1968899,402.45511,-9.2630224
178.9924,9.7324486,3.7454441,0.0,0,6.1266279,0.0,0.28740063,92.91256,6.1489749,402.94815,-9.2636185
178.9966,9.7710266,3.7938871,0.0,0,6.0787735,0.0,0.29167369,92.971886,6.0987043,403.44992,-9.2626591
179.0008,9.7813778,3.8503618,0.0,0,6.0309186,0.0,0.29614788,92.685326,6.0504503,403.95563,-9.2640057
179.005,9.7866831,3.8950551,0.0,0,5.9830642,0.0,0.30085722,92.329842,6.0029874,404.4339,-9.2627192
179.0092,9.8293285,3.9389977,0.0,0,5.9352088,0.0,0.30464768,92.329346,5.9540362,404.8511,-9.2613478
179.0134,9.8803349,3.9881618,0.0,0,5.8873544,0.0,0.30872276,92.406113,5.9056706,405.26831,-9.2630253
179.0176,9.9235497,4.0344834,0.0,0,5.8394995,0.0,0.31346872,92.299133,5.8581009,405.74417,-9.2616386
179.0218,9.9703627,4.0804038,0.0,0,5.7916446,0.0,0.3175962,92.396233,5.8079758,406.22458,-9.2635078
179.026,10.019156,4.1362143,0.0,0,5.7437897,0.0,0.32197183,92.545685,5.7620478,406.08188,-9.2629452
179.0302,10.080157,4.1809034,0.0,0,5.6959348,0.0,0.32687682,92.530121,5.7081494,405.4245,-9.2623396
179.0344,10.08637,4.2238178,0.0,0,5.6480803,0.0,0.33081156,92.272919,5.664453,404.68073,-9.2632732
179.0386,10.126315,4.2777834,0.0,0,5.600225,0.0,0.3353954,92.093285,5.6138196,403.505,-9.2621927
179.0428,10.131558,4.3201528,0.0,0,5.5544,0.0,0.3397561,91.872704,5.5675597,402.32928,-9.2605581
179.047,10.165188,4.3647537,0.0,0,5.5088716,0.0,0.34402627,91.676239,5.5187421,402.34555,-9.2631044
179.0512,10.23105,4.4164457,0.0,0,5.4633436,0.0,0.34820703,91.959801,5.4759574,402.68689,-9.2640257
179.0554,10.292952,4.4589353,0.0,0,5.4178157,0.0,0.35297224,92.061928,5.4316816,403.29431,-9.2640266
179.0596,10.288054,4.4988494,0.0,0,5.3722878,0.0,0.35675976,91.614296,5.383554,404.29306,-9.2609425
179.0638,10.328806,4.5463142,0.0,0,5.3267598,0.0,0.36077377,91.686195,5.3403478,405.28458,-9.2617226
179.068,10.375467,4.5894508,0.0,0,5.2812319,0.0,0.36544225,91.717987,5.2969909,405.97989,-9.2632313
179.0722,10.41932,4.632504,0.0,0,5.2357039,0.0,0.36949912,91.676941,5.2515035,406.6752,-9.2637281
179.0764,10.483232,4.6838927,0.0,0,5.1901755,0.0,0.3737129,91.860382,5.2075782,406.98041,-9.2614574
179.0806,10.550382,4.7277694,0.0,0,5.1446476,0.0,0.37884763,91.888214,5.158885,407.06891,-9.2632484
179.0848,10.607368,4.7703471,0.0,0,5.0991197,0.0,0.38294902,92.05188,5.1118279,407.05475,-9.263175
179.089,10.665925,4.8215861,0.0,0,5.0535922,0.0,0.3873913,92.204384,5.0637631,406.75134,-9.2614651
179.0932,10.666512,4.8647461,0.0,0,5.0102167,0.0,0.39208719,91.780594,5.0204601,406.44794,-9.2633705
179.0974,10.69847,4.9089484,0.0,0,4.9669147,0.0,0.39656115,91.674782,4.9744349,406.33386,-9.2633619
179.1016,10.725771,4.9614248,0.0,0,4.9236126,0.0,0.40103546,91.414124,4.9312267,406.24536,-9.2626629
179.1058,10.74277,4.9990511,0.0,0,4.880311,0.0,0.40557382,91.189613,4.8855591,406.24536,-9.263422
179.11,10.779767,5.0376024,0.0,0,4.8370085,0.0,0.40952468,91.156464,4.8421502,406.33386,-9.2623301
179.1142,10.834225,5.0832233,0.0,0,4.7937069,0.0,0.4134216,91.204376,4.8026977,406.43588,-9.2615461
179.1184,10.885305,5.1232972,0.0,0,4.7504048,0.0,0.41803643,91.225014,4.7582936,406.63815,-9.2629967
179.1226,10.931471,5.1627345,0.0,0,4.7071028,0.0,0.42211065,91.303627,4.716609,406.84039,-9.2626085
179.1268,10.991958,5.2135215,0.0,0,4.6638007,0.0,0.42649534,91.30835,4.6763611,406.86539,-9.26334
179.131,11.057464,5.256958,0.0,0,4.6204991,0.0,0.43164083,91.477226,4.631381,406.82748,-9.2619305
179.1352,11.108201,5.2928467,0.0,0,4.5771966,0.0,0.43544504,91.476501,4.5855026,404.2514,-9.2626801
179.1394,11.148015,5.3444767,0.0,0,4.5340271,0.0,0.44005835,91.35981,4.5405378,397.10672,-9.2632484
179.1436,11.197814,5.3848453,0.0,0,4.4928331,0.0,0.44474655,91.372665,4.4952135,389.96204,-9.2633638
179.1478,11.241957,5.4270902,0.0,0,4.4516392,0.0,0.44936505,91.331108,4.455328,385.17059,-9.2629566
179.152,11.277987,5.4733424,0.0,0,4.4104452,0.0,0.45340264,91.282829,4.4112949,380.43655,-9.2629156
179.1562,11.271423,5.5141854,0.0,0,4.3692517,0.0,0.45836917,90.787376,4.3704801,380.47586,-9.2634382
179.1604,11.301443,5.5464497,0.0,0,4.3280582,0.0,0.46202892,90.668312,4.3324213,383.76108,-9.2637291
179.1646,11.356012,5.5891376,0.0,0,4.2868648,0.0,0.46568823,90.76001,4.291265,386.32059,-9.2626667
179.1688,11.433537,5.6285982,0.0,0,4.2456713,0.0,0.47049594,90.904785,4.2512498,386.21924,-9.2626877
179.173,11.495312,5.6653762,0.0,0,4.2044773,0.0,0.47472519,91.044495,4.2128124,386.11789,-9.262846
179.1772,11.592532,5.7158599,0.0,0,4.1632838,0.0,0.4791688,91.350319,4.1673999,385.60483,-9.2626581
179.1814,11.638883,5.7575316,0.0,0,4.1220903,0.0,0.48433179,91.33989,4.1235957,385.0094,-9.2634106
179.1856,11.657443,5.7918072,0.0,0,4.0808969,0.0,0.48830652,91.04837,4.0849609,385.52579,-9.2625408
179.1898,11.721132,5.8362527,0.0,0,4.0400209,0.0,0.49232137,91.297112,4.0456786,387.38809,-9.2631989
179.194,11.753934,5.8748479,0.0,0,4.0008435,0.0,0.49710175,91.073792,4.0069847,389.28116,-9.2634954
179.1982,11.825972,5.9131103,0.0,0,3.9616656,0.0,0.50161469,91.142059,3.9631922,391.57419,-9.2641964
179.2024,11.881762,5.9613924,0.0,0,3.9224882,0.0,0.50592166,91.219261,3.921103,393.86722,-9.2639742
179.2066,11.941949,6.0002103,0.0,0,3.8833106,0.0,0.5109154,91.138519,3.8849905,395.59979,-9.2620354
179.2108,12.017705,6.0340028,0.0,0,3.8441329,0.0,0.51511467,91.383636,3.8437939,397.08112,-9.2628183
179.215,12.102598,6.081934,0.0,0,3.8049555,0.0,0.51950735,91.633972,3.8028982,398.29181,-9.2615566
179.2192,12.107321,6.1190963,0.0,0,3.7657778,0.0,0.52400851,91.300346,3.7662036,398.89871,-9.2613974
179.2234,12.094937,6.1544952,0.0,0,3.7266002,0.0,0.52857798,90.76709,3.7284684,399.50562,-9.2639351
179.2276,12.113957,6.1960754,0.0,0,3.6874225,0.0,0.53215832,90.613647,3.692405,399.85416,-9.2632294
179.2318,12.194201,6.2322855,0.0,0,3.6482451,0.0,0.53690791,90.729424,3.6532605,400.18286,-9.262886
179.236,12.336384,6.2641296,0.0,0,3.6090674,0.0,0.54110551,91.443443,3.6153181,400.66385,-9.2640486
179.2402,12.416531,6.3060546,0.0,0,3.5703723,0.0,0.5449726,91.626152,3.5714273,401.27069,-9.2627993
179.2444,12.529242,6.3500113,0.0,0,3.5331016,0.0,0.55052274,92.035896,3.5318692,401.90491,-9.2623539
179.2486,12.577497,6.3872685,0.0,0,3.4958305,0.0,0.55517226,91.957832,3.4928417,402.67606,-9.2622204
179.2528,12.52193,6.4308586,0.0,0,3.4585598,0.0,0.55936593,91.187759,3.4566896,403.4472,-9.2636547
179.257,12.522971,6.466424,0.0,0,3.4212892,0.0,0.56390965,90.722099,3.4180744,404.0098,-9.2634716
179.2612,12.595803,6.4916477,0.0,0,3.3840184,0.0,0.56765848,90.97319,3.3839445,404.51547,-9.2632723
179.2654,12.74695,6.5331955,0.0,0,3.3467472,0.0,0.57145435,91.636436,3.3474615,404.98532,-9.2631512
179.2696,12.852074,6.575316,0.0,0,3.3094764,0.0,0.57683814,91.899719,3.3071399,405.40253,-9.263279
179.2738,12.900353,6.6075802,0.0,0,3.2722056,0.0,0.58125263,91.830643,3.2718823,405.82062,-9.2641191
179.278,12.903663,6.647325,0.0,0,3.234935,0.0,0.5849241,91.536003,3.2342439,406.27573,-9.2632561
179.2822,13.018542,6.6850181,0.0,0,3.1976643,0.0,0.58985019,91.881882,3.1966035,406.73087,-9.2624216
179.2864,13.10628,6.7154918,0.0,0,3.1603935,0.0,0.59419572,92.115959,3.1612542,407.0722,-9.2643557
179.2906,13.182079,6.7570906,0.0,0,3.1237545,0.0,0.59822792,92.322021,3.1208756,407.35031,-9.2626133
179.2948,13.232839,6.797822,0.0,0,3.0882978,0.0,0.60356301,92.105019,3.0854239,407.58209,-9.2628355
179.299,13.285076,6.8294563,0.0,0,3.0528414,0.0,0.60800886,92.091255,3.0489769,407.68323,-9.2624149
179.3032,13.315534,6.8694472,0.0,0,3.017385,0.0,0.61183637,91.983261,3.0133183,407.78436,-9.2617817
179.3074,13.36018,6.9043355,0.0,0,2.9819286,0.0,0.61639673,91.835373,2.981601,407.61819,-9.2629824
179.3116,13.480438,6.9322901,0.0,0,2.9464724,0.0,0.62082845,92.260155,2.9447322,407.41595,-9.262413
179.3158,13.571111,6.9703946,0.0,0,2.9110157,0.0,0.62446034,92.517159,2.9082925,407.13782,-9.261323
179.32,13.628536,7.0088835,0.0,0,2.8755593,0.0,0.62951863,92.459526,2.8740594,406.78384,-9.2626715
179.3242,13.712564,7.0406857,0.0,0,2.8401029,0.0,0.63429588,92.623169,2.8379421,406.44339,-9.2631254
179.3284,13.78883,7.0804319,0.0,0,2.8046467,0.0,0.6381529,92.732635,2.8032389,406.20319,-9.2627764
179.3326,13.90003,7.1178279,0.0,0,2.7691901,0.0,0.64324296,92.975525,2.7685945,405.96298,-9.2633715
179.3368,14.024635,7.1495724,0.0,0,2.7337339,0.0,0.64809352,93.352928,2.7301798,405.95609,-9.2620573
179.341,14.050695,7.1851921,0.0,0,2.6990449,0.0,0.65157628,93.295227,2.6999004,406.03192,-9.261734
179.3452,14.114479,7.2229748,0.0,0,2.665319,0.0,0.65673947,93.197212,2.6602883,406.22516,-9.2635736
179.3494,14.189162,7.2522063,0.0,0,2.631593,0.0,0.66130948,93.290131,2.6253614,406.6297,-9.2612467
179.3536,14.22957,7.2935414,0.0,0,2.5978668,0.0,0.66548377,93.111198,2.5894504,407.03424,-9.2641115
179.3578,14.325261,7.3322959,0.0,0,2.5641408,0.0,0.67052543,93.218369,2.5566812,407.27835,-9.2615252
179.362,14.368781,7.3540869,0.0,0,2.5304148,0.0,0.67456502,93.156593,2.5232625,407.51855,-9.2629395
179.3662,14.446305,7.3894734,0.0,0,2.4966888,0.0,0.67801905,93.344872,2.4924376,407.68353,-9.2627249
179.3704,14.550503,7.424861,0.0,0,2.4629629,0.0,0.68291199,93.597382,2.4583321,407.7973,-9.2613535
179.3746,14.653274,7.4526181,0.0,0,2.4292369,0.0,0.68743747,93.845879,2.4271026,407.02985,-9.2635708
179.3788,14.746518,7.4913602,0.0,0,2.3955109,0.0,0.69144356,94.004517,2.3866696,403.03116,-9.2626677
179.383,14.863375,7.5288401,0.0,0,2.3617849,0.0,0.69658566,94.286453,2.3585999,399.03247,-9.2625666
179.3872,14.940026,7.556921,0.0,0,2.3280587,0.0,0.70141208,94.31292,2.3207223,394.70599,-9.2617607
179.3914,14.99516,7.5937614,0.0,0,2.2952197,0.0,0.70530623,94.296341,2.289778,390.314,-9.2631283
179.3956,15.060025,7.6265354,0.0,0,2.26314,0.0,0.70995402,94.241997,2.2535913,387.91504,-9.2627764
179.3998,15.11996,7.6541748,0.0,0,2.2310605,0.0,0.71449286,94.224327,2.2270153,388.44714,-9.2629461
179.404,15.246153,7.6888471,0.0,0,2.198981,0.0,0.71804887,94.615517,2.1946688,389.01208,-9.2631083
179.4082,15.337532,7.7244301,0.0,0,2.1669014,0.0,0.7230643,94.789276,2.1614482,390.92505,-9.2627516
179.4124,15.378303,7.7506204,0.0,0,2.1348217,0.0,0.72783953,94.563477,2.1288474,392.83804,-9.2632332
179.4166,15.485253,7.7807574,0.0,0,2.102742,0.0,0.73095465,94.89328,2.1002119,394.48193,-9.2635279
179.4208,15.621706,7.8172846,0.0,0,2.0706627,0.0,0.73598301,95.240494,2.0670297,395.97638,-9.2618837
179.425,15.75365,7.8432407,0.0,0,2.038583,0.0,0.74069262,95.622604,2.032433,397.32455,-9.2617226
179.4292,15.89063,7.8812089,0.0,0,2.0065033,0.0,0.74481016,96.051628,1.9988106,398.26062,-9.2616863
179.4334,15.968965,7.9181833,0.0,0,1.9744238,0.0,0.74997973,96.065552,1.966959,399.19669,-9.2626305
179.4376,15.986755,7.9407883,0.0,0,1.9423442,0.0,0.75453198,95.736244,1.9362025,400.22137,-9.2625265
179.4418,16.081995,7.9732013,0.0,0,1.911255,0.0,0.7579506,95.947639,1.9036067,401.25803,-9.26054
179.446,16.19842,8.0087662,0.0,0,1.8807379,0.0,0.76309484,96.173286,1.8764354,402.19989,-9.2622395
179.4502,16.35774,8.0369139,0.0,0,1.8502207,0.0,0.76820415,96.59626,1.8418641,403.04691,-9.2632895
179.4544,16.452803,8.071476,0.0,0,1.8197033,0.0,0.77200085,96.773079,1.807788,403.65463,-9.2616501
179.4586,16.497889,8.1065817,0.0,0,1.7891862,0.0,0.7767995,96.567513,1.7765566,402.49155,-9.2620668
179.4628,16.52109,8.1275072,0.0,0,1.758669,0.0,0.78155011,96.29303,1.7506959,401.32849,-9.2620888
179.467,16.604471,8.1557178,0.0,0,1.7281518,0.0,0.78422272,96.516212,1.7235861,398.78204,-9.2619114
179.4712,16.769346,8.1867437,0.0,0,1.6976346,0.0,0.78874928,97.005394,1.6955211,395.74475,-9.261405
179.4754,16.928394,8.2135649,0.0,0,1.6671174,0.0,0.79384923,97.465294,1.6634899,393.89603,-9.2619848
179.4796,17.135736,8.2514324,0.0,0,1.6366003,0.0,0.79830259,98.16111,1.6338621,394.1868,-9.2624846
179.4838,17.288635,8.2874222,0.0,0,1.6060829,0.0,0.80333501,98.539162,1.5999771,394.47757,-9.2617865
179.488,17.352602,8.3145761,0.0,0,1.5755658,0.0,0.80897152,98.416306,1.5680248,396.47452,-9.2618675
179.4922,17.419653,8.3434935,0.0,0,1.5461327,0.0,0.812208,98.400475,1.5334818,398.51312,-9.2610788
179.4964,17.466646,8.3755531,0.0,0,1.5171022,0.0,0.8168028,98.267487,1.5110875,399.55649,-9.2623405
179.5006,17.549374,8.3993807,0.0,0,1.4880718,0.0,0.82170558,98.258415,1.4775511,399.9231,-9.2620239
179.5048,17.669762,8.4296722,0.0,0,1.4590415,0.0,0.82508659,98.592201,1.4525263,400.30869,-9.2618132
179.509,17.796654,8.4638586,0.0,0,1.430011,0.0,0.82994944,98.827538,1.420537,400.76379,-9.2627449
179.5132,17.916176,8.4822111,0.0,0,1.4009807,0.0,0.83439863,99.034401,1.3929838,401.21887,-9.26122
179.5174,18.053921,8.5144091,0.0,0,1.3719503,0.0,0.83808339,99.407707,1.363122,401.15778,-9.2619362
179.5216,18.160492,8.5458136,0.0,0,1.3429198,0.0,0.84278035,99.519691,1.3353913,400.99344,-9.2625847
179.5258,18.245533,8.5681353,0.0,0,1.3138895,0.0,0.84756714,99.516991,1.3058667,400.35992,-9.261879
179.53,18.441084,8.600193,0.0,0,1.2848592,0.0,0.85144007,100.18007,1.2795216,399.15845,-9.2605753
179.5342,18.538157,8.6331902,0.0,0,1.2558287,0.0,0.8563292,100.25519,1.2511042,398.05722,-9.2613554
179.5384,18.668598,8.6563025,0.0,0,1.2267983,0.0,0.86154628,100.42354,1.2187922,398.25952,-9.2617121
179.5426,18.811621,8.6831036,0.0,0,1.1989383,0.0,0.8645286,100.90745,1.1928809,398.46179,-9.2617073
179.5468,18.932657,8.7165594,0.0,0,1.1713274,0.0,0.86953318,101.02521,1.1649162,397.08984,-9.2613354
179.551,19.109888,8.7409773,0.0,0,1.1437165,0.0,0.87491494,101.4287,1.1353799,395.01218,-9.2594671
179.5552,19.207724,8.770997,0.0,0,1.1161058,0.0,0.87860775,101.57409,1.1105226,392.84091,-9.2623701
179.5594,19.330132,8.8037205,0.0,0,1.0884949,0.0,0.8831808,101.77187,1.079223,390.46088,-9.2613659
179.5636,19.446108,8.8232822,0.0,0,1.0608841,0.0,0.888138,101.88844,1.0529989,388.08084,-9.2618561
179.5678,19.542065,8.8488817,0.0,0,1.0332733,0.0,0.89119899,102.06808,1.0272095,388.42844,-9.2614613
179.572,19.639051,8.8787794,0.0,0,1.0056624,0.0,0.8955887,102.16148,0.99939996,388.98584,-9.2608595
179.5762,19.765137,8.9005661,0.0,0,0.97805178,0.0,0.90067965,102.20583,0.97179163,388.8287,-9.2628069
179.5804,19.969727,8.9299059,0.0,0,0.95044094,0.0,0.90437227,102.87695,0.94824195,388.08124,-9.2613926
179.5846,20.162971,8.9669466,0.0,0,0.9228301,0.0,0.90984356,103.29914,0.91640365,387.31903,-9.2624874
179.5888,20.340647,8.9845934,0.0,0,0.89521933,0.0,0.91469407,103.76172,0.89078861,386.48288,-9.2619543
179.593,20.452568,9.0110407,0.0,0,0.86885226,0.0,0.91794163,104.01232,0.86161441,385.64673,-9.2599678
179.5972,20.572355,9.0414553,0.0,0,0.84259379,0.0,0.92268014,104.09026,0.83286202,386.62222,-9.2607508
179.6014,20.65391,9.063098,0.0,0,0.81633544,0.0,0.92772841,103.99611,0.80518711,388.0918,-9.2617979
179.6056,20.76078,9.0874567,0.0,0,0.79007703,0.0,0.93091887,104.20336,0.78009862,389.86392,-9.2602825
179.6098,20.890814,9.119339,0.0,0,0.76381862,0.0,0.93546981,104.40008,0.75231069,392.08093,-9.260973
179.614,21.06846,9.1409578,0.0,0,0.73756021,0.0,0.941073,104.65841,0.73088133,394.26389,-9.2610941
179.6182,21.241745,9.1601849,0.0,0,0.7113018,0.0,0.94331229,105.25038,0.70485759,395.04932,-9.2611589
179.6224,21.363016,9.1923523,0.0,0,0.68504345,0.0,0.94811267,105.40809,0.68112481,395.83478,-9.2598658
179.6266,21.540428,9.21206,0.0,0,0.65878505,0.0,0.95309597,105.76016,0.65330631,396.19675,-9.2609339
179.6308,21.70953,9.2359104,0.0,0,0.63252664,0.0,0.95639074,106.22366,0.62820441,396.32343,-9.2613325
179.635,21.864037,9.2713041,0.0,0,0.60626823,0.0,0.96151227,106.41686,0.60023606,395.95242,-9.2605438
179.6392,22.072252,9.2897024,0.0,0,0.58003461,0.0,0.96683562,106.86481,0.57373565,394.1788,-9.2615652
179.6434,22.280416,9.3131266,0.0,0,0.55503869,0.0,0.96967036,107.57194,0.54981679,392.40518,-9.2600279
179.6476,21.83733,9.3380127,0.0,0,0.53004867,0.0,0.97365767,105.06024,0.52400607,391.39047,-9.2610044
179.6518,20.898556,9.3405685,0.0,0,0.50505865,0.0,0.97565264,100.35928,0.50671351,390.47836,-9.2633505
179.656,20.282887,9.3485575,0.0,0,0.48006868,0.0,0.97604465,97.320091,0.49363393,390.60504,-9.2631826
179.6602,19.848589,9.3628063,0.0,0,0.45507869,0.0,0.97751719,95.106102,0.47934103,391.77054,-9.2623034
179.6644,19.512651,9.3599701,0.0,0,0.4300887,0.0,0.97903121,93.35524,0.46035597,392.87573,-9.2636614
179.6686,19.051558,9.3624887,0.0,0,0.40509868,0.0,0.97861499,91.245132,0.44877389,393.53452,-9.2652607
179.6728,18.538696,9.3660517,0.0,0,0.38010868,0.0,0.97862756,88.710922,0.43658885,394.19327,-9.2641821
179.677,18.101177,9.3629045,0.0,0,0.35511869,0.0,0.97958928,86.568062,0.43098161,395.11334,-9.2633591
179.6812,17.833952,9.3674059,0.0,0,0.3301287,0.0,0.97948927,85.242393,0.4232693,396.12616,-9.2652197
179.6854,17.741617,9.3782549,0.0,0,0.30513871,0.0,0.98013806,84.757286,0.40266705,397.14786,-9.2642813
179.6896,17.814123,9.3726177,0.0,0,0.28028375,0.0,0.98130125,84.994949,0.38428804,398.18555,-9.2638903
179.6938,18.017019,9.3766279,0.0,0,0.25652012,0.0,0.98117059,86.001083,0.34993264,399.22321,-9.2629957
179.698,18.187218,9.3811941,0.0,0,0.23275654,0.0,0.98106241,86.777,0.31647757,399.72922,-9.2645454
179.7022,18.281849,9.3796692,0.0,0,0.20899297,0.0,0.98242176,87.110107,0.2873534,400.22229,-9.2635908
179.7064,18.319927,9.382165,0.0,0,0.18522938,0.0,0.98221844,87.343399,0.25599092,400.55728,-9.2623777
179.7106,18.330248,9.3944025,0.0,0,0.16146578,0.0,0.9829765,87.305649,0.22925097,400.78485,-9.2625952
179.7148,18.280354,9.3914785,0.0,0,0.13770218,0.0,0.98466313,86.945564,0.20361488,401.09909,-9.263011
179.719,18.208872,9.3869486,0.0,0,0.11393856,0.0,0.98317194,86.765373,0.18068539,401.73123,-9.2623978
179.7232,18.136305,9.3951941,0.0,0,0.090174966,0.0,0.98366958,86.36911,0.16016977,402.36334,-9.2629242
179.7274,18.057793,9.3940334,0.0,0,0.066411361,0.0,0.98496562,85.846588,0.13966185,403.03757,-9.2638454
179.7316,17.967415,9.3939333,0.0,0,0.04264776,0.0,0.98451233,85.506622,0.11848015,403.72025,-9.2629213
179.7358,17.862654,9.404952,0.0,0,0.018884161,0.0,0.98483741,84.97728,0.10279436,404.21991,-9.262785
179.74,17.773079,9.4015398,0.0,0,-0.0047604311,0.0,0.9863469,84.382149,0.085719429,404.49802,-9.2627354
179.7442,17.678875,9.3995819,0.0,0,-0.027944429,0.0,0.9853251,84.015785,0.071414247,404.7644,-9.2638674
179.7484,17.570841,9.4052315,0.0,0,-0.051128428,0.0,0.98537081,83.493629,0.055920519,404.87817,-9.2616339
179.7526,17.451405,9.4035244,0.0,0,-0.074312426,0.0,0.98665482,82.870415,0.043848645,404.99194,-9.2631149
179.7568,17.332747,9.4039717,0.0,0,-0.097496428,0.0,0.98636955,82.332123,0.032350991,404.98352,-9.262578
179.761,17.181496,9.4146347,0.0,0,0.2087761,400.0,0.986633,81.618652,0.02214003,404.92032,-9.2636089
179.7652,16.933336,9.4073296,0.0,0,0.96941334,400.0,0.98742008,80.348991,0.0167538,404.94321,-9.2638121
179.7694,13.97489,9.3988829,0.0,0,1.7300496,400.0,0.98537242,66.536491,0.13728712,405.15811,-9.2651491
179.7736,8.7779207,9.386344,0.0,0,2.4906867,400.0,0.9819876,42.163673,0.38775903,405.37302,-9.2685499
179.7778,-0.3401283,9.2693033,0.0,0,3.2513232,400.0,0.96306509,-1.7123115,1.1135396,405.47055,-9.2777719
179.782,0.19239868,9.3237114,0.0,0,4.01196,400.0,0.9717899,0.95004916,2.4826524,405.55902,-9.2763491
179.7862,-0.036273018,9.3737497,0.0,0,4.7725964,400.0,0.97941816,-0.073678486,3.4247246,405.62677,-9.2737179
179.7904,0.47727856,9.3767681,0.0,0,5.5332332,400.0,0.98183441,2.2462018,4.1497793,405.67734,-9.2712231
179.7946,0.51020408,9.3676634,0.0,0,6.2938709,400.0,0.97991145,2.4203959,4.8489494,405.74054,-9.2719078
179.7988,0.47279945,9.3742104,0.0,0,7.0545073,400.0,0.97982001,2.26842,5.564908,405.86697,-9.2731638
179.803,0.48072237,9.3730593,0.0,0,7.8151441,400.0,0.98099095,2.3098254,6.3502169,405.99341,-9.2715492
179.8072,0.50670224,9.3699265,0.0,0,8.5757818,400.0,0.98022711,2.4176083,7.1469021,406.08011,-9.2700834
179.8114,0.49328315,9.3781109,0.0,0,9.3364182,400.0,0.9801423,2.3575125,7.9317722,406.15594,-9.2706127
179.8156,0.4866837,9.3734589,0.0,0,10.097054,400.0,0.98121196,2.2815676,8.7143879,406.23181,-9.2701178
179.8198,0.49800545,9.3684464,0.0,0,10.857692,400.0,0.98019755,2.3911366,9.5032797,406.30765,-9.2686644
179.824,0.443149,9.3743057,0.0,0,11.618328,400.0,0.97983551,2.1493652,10.277282,406.38229,-9.2673559
179.8282,0.48760879,9.3701763,0.0,0,12.378965,400.0,0.98042428,2.3556466,11.039878,406.40756,-9.2672071
179.8324,0.49726516,9.3688145,0.0,0,13.139603,400.0,0.98016322,2.3822143,11.781114,406.43286,-9.2682352
179.8366,0.49860281,9.3775873,0.0,0,13.90024,400.0,0.97990692,2.374361,12.517859,406.4744,-9.2678032
179.8408,0.50853163,9.3742275,0.0,0,14.660877,400.0,0.98131806,2.3892648,13.270997,406.52496,-9.2652006
179.845,0.48914418,9.3687572,0.0,0,15.421513,400.0,0.98006606,2.3688951,14.048359,406.58878,-9.2668867
179.8492,0.47765824,9.3747396,0.0,0,16.18215,400.0,0.97980839,2.3160129,14.815273,406.68991,-9.2677822
179.8534,0.49429151,9.3721189,0.0,0,16.942787,400.0,0.98073363,2.331986,15.592474,406.79105,-9.2670918
179.8576,0.50102633,9.3720436,0.0,0,17.703424,400.0,0.98069382,2.3621042,16.34647,406.8031,-9.265378
179.8618,0.48386976,9.3781796,0.0,0,18.0,400.0,0.98005289,2.2879939,17.108047,406.8031,-9.2646046
179.866,0.53605777,9.3758497,0.0,0,18.0,400.0,0.98149794,2.535166,17.809208,406.8031,-9.2659798
179.8702,0.55322313,9.3706255,0.0,0,18.0,400.0,0.98055989,2.6446126,18.310966,406.8031,-9.2698669
179.8744,0.60458004,9.3778477,0.0,0,18.0,400.0,0.9802953,2.8978839,18.464651,406.80911,-9.2762594
179.8786,0.66085994,9.374074,0.0,0,18.0,400.0,0.98108542,3.1288538,18.318659,406.85968,-9.2893724
179.8828,0.64749902,9.3726873,0.0,0,18.0,400.0,0.98106748,3.1241739,18.136757,406.91025,-9.3127546
179.887,0.57091516,9.3772316,0.0,0,18.0,400.0,0.98003739,2.7439075,18.070494,406.92349,-9.3455658
179.8912,0.57207859,9.3734417,0.0,0,18.0,400.0,0.98106992,2.6781068,18.075413,406.92349,-9.3835859
179.8954,0.54150212,9.3648548,0.0,0,18.0,400.0,0.97958159,2.6313047,18.106339,406.91446,-9.420495
179.8996,0.57589501,9.3687515,0.0,0,18.0,400.0,0.9790116,2.7129145,18.128603,406.88916,-9.4541941
179.9038,0.61141306,9.3683977,0.0,0,18.0,400.0,0.98005545,2.8931406,18.144339,406.86389,-9.4847651
179.908,0.64761782,9.3651667,0.0,0,18.0,400.0,0.97979861,3.0824742,18.144197,406.87561,-9.514596
179.9122,0.64922863,9.3718214,0.0,0,18.0,400.0,0.97910738,3.0928454,18.138117,406.88824,-9.5433254
179.9164,0.61041993,9.3739939,0.0,0,18.0,400.0,0.98091578,2.9514871,18.131674,406.89337,-9.5747032
179.9206,0.579804,9.3652382,0.0,0,18.0,400.0,0.97978425,2.7601614,18.130795,406.89337,-9.6063662
179.9248,0.58247358,9.3699284,0.0,0,18.0,400.0,0.97909135,2.7794373,18.125629,406.88525,-9.6370382
179.929,0.58931446,9.3681822,0.0,0,18.0,400.0,0.97989517,2.7975328,18.125475,406.84732,-9.6673803
179.9332,0.62565404,9.3646002,0.0,0,18.0,400.0,0.97966063,2.946883,18.118429,406.80942,-9.7011194
179.9374,0.63727075,9.3728046,0.0,0,18.0,400.0,0.97943854,3.0182192,18.119572,406.76096,-9.731739
179.9416,0.64291632,9.3702812,0.0,0,18.0,400.0,0.98015785,3.0735974,18.111492,406.71039,-9.7609329
179.9458,0.61842513,9.3659401,0.0,0,18.0,400.0,0.98012149,3.0080042,18.111254,406.65979,-9.7910738
179.95,0.58534622,9.3711796,0.0,0,18.0,400.0,0.97931361,2.8153298,18.107544,406.60925,-9.8251982
179.9542,0.56366289,9.3696136,0.0,0,18.0,400.0,0.9800936,2.74594,18.10783,406.56049,-9.8537464
179.9584,0.57334864,9.3631372,0.0,0,18.0,400.0,0.97944421,2.6913114,18.104387,406.53519,-9.8858366
179.9626,0.59897792,9.3717718,0.0,0,18.0,400.0,0.97930884,2.836143,18.106789,406.50989,-9.9172096
179.9668,0.63215876,9.3736115,0.0,0,18.0,400.0,0.98091429,2.9868364,18.098824,406.50208,-9.9479656
179.971,0.64943135,9.3618155,0.0,0,18.0,400.0,0.97947383,3.0649941,18.099741,406.50208,-9.9791975
179.9752,0.64688963,9.3713627,0.0,0,18.0,400.0,0.97942579,3.1125619,18.094738,406.48642,-10.010462
179.9794,0.60327971,9.368865,0.0,0,18.0,400.0,0.97996366,2.9128885,18.097612,406.43585,-10.04077
179.9836,0.5786708,9.3664932,0.0,0,18.0,400.0,0.98010498,2.7510493,18.095213,406.38528,-10.074366
179.9878,0.57971817,9.3733301,0.0,0,18.0,400.0,0.97935003,2.7671976,18.093407,406.33472,-10.102417
179.992,0.60696954,9.3737488,0.0,0,18.0,400.0,0.98063195,2.8801711,18.093491,406.28418,-10.132625
179.9962,0.63873243,9.3647528,0.0,0,18.0,400.0,0.97984815,3.012841,18.093182,406.23358,-10.165749
180.0004,0.65879416,9.3690615,0.0,0,18.0,400.0,0.97887629,3.0964644,18.091869,406.18301,-10.196605
180.0046,0.65907651,9.3709316,0.0,0,18.0,400.0,0.98019528,3.1720543,18.089409,406.13455,-10.228306
180.0088,0.63882822,9.3662443,0.0,0,18.0,400.0,0.98012894,3.0733345,18.085999,406.09665,-10.259398
180.013,0.59322208,9.3718157,0.0,0,18.0,400.0,0.97924405,2.8607402,18.083488,406.05872,-10.290639
180.0172,0.57759416,9.3737907,0.0,0,18.0,400.0,0.98065072,2.7658012,18.084097,406.03073,-10.318995
180.0214,0.59235537,9.3631487,0.0,0,18.0,400.0,0.97972357,2.8150115,18.084316,406.00543,-10.349329
180.0256,0.6220727,9.3698759,0.0,0,18.0,400.0,0.97906876,2.9278457,18.079334,405.97504,-10.381822
180.0298,0.64800012,9.3708172,0.0,0,18.0,400.0,0.98022217,3.0821397,18.076937,405.9371,-10.412735
180.034,0.67368513,9.3659573,0.0,0,18.0,400.0,0.97999185,3.1977792,18.076134,405.89917,-10.444951
180.0382,0.64885509,9.3723602,0.0,0,18.0,400.0,0.97944164,3.1395929,18.082609,405.86127,-10.475824
180.0424,0.60484201,9.374958,0.0,0,18.0,400.0,0.98064351,2.9364502,18.076536,405.82333,-10.506559
180.0466,0.57544965,9.3666277,0.0,0,18.0,400.0,0.98036093,2.8095646,18.075979,405.79352,-10.538218
180.0508,0.58674616,9.367486,0.0,0,18.0,400.0,0.97860599,2.7650263,18.074289,405.76825,-10.569807
180.055,0.60906345,9.3728294,0.0,0,18.0,400.0,0.98052096,2.8957415,18.07559,405.74295,-10.600727
180.0592,0.65245908,9.3633556,0.0,0,18.0,400.0,0.97976381,3.0637095,18.072577,405.71768,-10.630823
180.0634,0.67525935,9.3716021,0.0,0,18.0,400.0,0.97932273,3.2034371,18.072456,405.69241,-10.662957
180.0676,0.67160571,9.3748198,0.0,0,18.0,400.0,0.98055887,3.2288525,18.070732,405.6337,-10.692555
180.0718,0.64210641,9.3654385,0.0,0,18.0,400.0,0.980115,3.100776,18.073574,405.5705,-10.724205
180.076,0.5977791,9.3697414,0.0,0,18.0,400.0,0.9791348,2.8971603,18.070992,405.52625,-10.755558
180.0802,0.58425528,9.3735723,0.0,0,18.0,400.0,0.98047394,2.8340836,18.064968,405.50098,-10.785143
180.0844,0.59460378,9.3663692,0.0,0,18.0,400.0,0.98022288,2.8178926,18.065979,405.47418,-10.818113
180.0886,0.6480698,9.3734131,0.0,0,18.0,400.0,0.97958428,3.024251,18.059044,405.43625,-10.848846
180.0928,0.67607588,9.3743811,0.0,0,18.0,400.0,0.98050135,3.2300115,18.061472,405.39832,-10.879856
180.097,0.68666738,9.3685026,0.0,0,18.0,400.0,0.98071694,3.3097723,18.062946,405.34174,-10.908113
180.1012,0.65405411,9.3706446,0.0,0,18.0,400.0,0.97937363,3.154942,18.060272,405.27853,-10.94043
180.1054,0.61620009,9.3728991,0.0,0,18.0,400.0,0.98038709,2.960691,18.058432,405.21078,-10.973062
180.1096,0.60132599,9.3649387,0.0,0,18.0,400.0,0.97998685,2.8770063,18.060848,405.13495,-11.004696
180.1138,0.60348612,9.3744392,0.0,0,18.0,400.0,0.97992581,2.8674617,18.057693,405.05908,-11.033934
180.118,0.61698312,9.3747168,0.0,0,18.0,400.0,0.98037374,2.925379,18.057955,405.00793,-11.065891
180.1222,0.67133033,9.3657446,0.0,0,18.0,400.0,0.98035491,3.1729293,18.05761,404.95737,-11.097566
180.1264,0.68969846,9.3695164,0.0,0,18.0,400.0,0.97899282,3.2995007,18.053904,404.9068,-11.126195
180.1306,0.6695196,9.3722687,0.0,0,18.0,400.0,0.98015428,3.1470132,18.058064,404.8562,-11.15941
180.1348,0.62793332,9.3667412,0.0,0,18.0,400.0,0.98057812,3.0695901,18.053932,404.80292,-11.191561
180.139,0.61097318,9.3725834,0.0,0,18.0,400.0,0.97963405,2.9184976,18.053345,404.73972,-11.221316
180.1432,0.60207134,9.3759279,0.0,0,18.0,400.0,0.98058885,2.8826988,18.055204,404.67648,-11.252329
180.1474,0.62436694,9.369338,0.0,0,18.0,400.0,0.98106575,2.9629741,18.051607,404.6449,-11.281928
180.1516,0.657929,9.3704348,0.0,0,18.0,400.0,0.97936022,3.0953455,18.050602,404.61963,-11.314827
180.1558,0.70385367,9.3728561,0.0,0,18.0,400.0,0.9801752,3.3033004,18.051594,404.56573,-11.344161
180.5591,0.60837656,9.373971,0.0,0,18.0,0.0014183699,0.98068017,2.9046404,18.012676,392.63901,-11.483465
182.6591,0.5568462,9.3881197,0.0,0,18.0,3.2689678000000003e-32,0.98312867,2.6444509,18.000387,367.27451,-11.483139
184.7591,0.53737497,9.3992329,0.0,0,18.0,1.4012985e-45,0.98504561,2.5537765,18.000137,347.51773,-11.484299
186.8591,0.52488482,9.4095783,0.0,0,18.0,1.4012985e-45,0.98693264,2.4851861,18.000048,329.90561,-11.483354
188.9591,0.52481264,9.4191504,0.0,0,18.0,1.4012985e-45,0.98867351,2.4910228,17.999619,313.74033,-11.483747
191.0591,0.51684386,9.4274874,0.0,0,18.0,1.4012985e-45,0.99025702,2.4444876,18.000175,298.88632,-11.483954
193.1591,0.523485,9.4360819,0.0,0,18.0,1.4012985e-45,0.99177521,2.4731848,17.999949,284.84219,-11.483808
195.2591,0.5118441,9.4436951,0.0,0,18.0,1.4012985e-45,0.99310046,2.4130139,17.999239,271.50381,-11.483442
197.3591,0.51883459,9.4513817,0.0,0,18.0,1.4012985e-45,0.99446279,2.4405141,17.999786,259.0549,-11.483387
199.4591,0.51439434,9.4588108,0.0,0,18.0,1.4012985e-45,0.99588317,2.4197628,17.999983,246.87546,-11.482819
201.5591,0.51298076,9.4650307,0.0,0,18.0,1.4012985e-45,0.99704331,2.4012809,17.999708,235.49326,-11.482851
203.6591,0.52026552,9.4721231,0.0,0,18.0,1.4012985e-45,0.99828142,2.4413123,18.00038,224.46361,-11.483233
205.7591,0.50953305,9.4792662,0.0,0,18.0,1.4012985e-45,0.99953449,2.3871965,18.000158,214.00163,-11.4835
207.8591,0.51325965,9.4858246,0.0,0,18.0,1.4012985e-45,1.0006671,2.3959994,18.000034,204.14102,-11.483064
209.9591,0.51099527,9.4919643,0.0,0,18.0,1.4012985e-45,1.0017536,2.3914559,17.999504,195.00459,-11.483253
212.0591,0.50489056,9.497592,0.0,0,18.0,1.4012985e-45,1.0028032,2.3587651,17.999874,186.38605,-11.483272
214.1591,0.51496094,9.5031605,0.0,0,18.0,1.4012985e-45,1.003822,2.4035378,18.00012,178.07196,-11.483487
216.2591,0.50103313,9.5082932,0.0,0,18.0,1.4012985e-45,1.0048181,2.3393757,17.999634,170.23663,-11.483274
218.3591,0.51133966,9.5141497,0.0,0,18.0,1.4012985e-45,1.005904,2.37362,17.999325,163.02202,-11.483245
220.4591,0.50119913,9.5184631,0.0,0,18.0,1.4012985e-45,1.0066868,2.3391125,17.999605,156.10391,-11.483342
222.5591,0.50266099,9.5234966,0.0,0,18.0,1.4012985e-45,1.007569,2.3327668,17.999828,149.45758,-11.482945
224.6591,0.50919133,9.5281887,0.0,0,18.0,1.4012985e-45,1.0084044,2.3657348,17.999548,143.27545,-11.483091
226.7591,0.49602911,9.5324993,0.0,0,18.0,1.4012985e-45,1.0092314,2.3002477,17.99966,137.17841,-11.482821
228.8591,0.51575828,9.5368776,0.0,0,18.0,1.4012985e-45,1.0101002,2.3870473,17.999521,131.52774,-11.482918
230.9591,0.49826196,9.5401316,0.0,0,18.0,1.4012985e-45,1.0107038,2.3157289,17.999912,126.20498,-11.483036
233.0591,0.50280225,9.5443134,0.0,0,18.0,1.4012985e-45,1.0114628,2.3191814,17.999779,121.01496,-11.482829
235.1591,0.50347686,9.547904,0.0,0,18.0,1.4012985e-45,1.0120578,2.3336389,17.99975,116.1608,-11.482577
237.2591,0.49225676,9.5508327,0.0,0,18.0,1.4012985e-45,1.0125737,2.2708402,17.999617,111.59274,-11.482651
239.3591,0.5106771,9.5543337,0.0,0,18.0,1.4012985e-45,1.0131767,2.3572137,17.999947,107.24596,-11.482459
240.1591,0.49984965,9.556057,0.0,0,18.0,1.4012985e-45,1.0134624,2.3057137,17.999252,105.65437,-11.482667