File: examples/dan-msc-case-studies/CS3/data/01 raw data/baron_test_105.csv
Time(sec),Force(kN),Jaw(mm),PowAngle(deg),Power(W),Pram,PTemp,Strain,Stress(MPa),Stroke(mm),TC1(C),wedge(mm)
0.0,2.3428197,0.14085181,0.0,0,11.076097,0.00081657618,0.0094080511,29.572199,11.075607,24.468807,-9.1271639
1.1,2.2466445,0.0038053235,0.0,0,11.076097,3.2158821,0.00023974574,28.584017,11.076044,24.492058,-9.4945869
2.2,2.1789525,0.0036605394,0.0,0,11.076097,6.5158834,0.00023665698,27.732641,11.076842,24.504005,-9.4916372
3.3,2.1628103,0.0036192574,0.0,0,11.076097,9.8158808,0.00026149667,27.528759,11.076172,24.403101,-9.4906731
4.4,2.1374822,0.0031508978,0.0,0,11.076097,13.115885,0.00024461487,27.209356,11.076315,24.437141,-9.4880276
5.5,2.1195304,0.003308709,0.0,0,11.076097,16.415882,0.00021260818,26.993862,11.075388,24.480396,-9.4865723
6.6,2.1183586,0.0033389169,0.0,0,11.076097,19.715883,0.00025190072,26.968998,11.076902,24.432932,-9.4848948
7.7,2.116152,0.0033137288,0.0,0,11.076097,23.015884,0.00018738999,26.933527,11.07658,24.442646,-9.4826527
8.8,2.1161206,0.0035460242,10.072852,0,11.076097,26.315882,0.00022465592,26.930113,11.076678,24.41161,-9.4801893
9.9,2.1349573,0.0035851204,26.168682,0,11.076097,29.615883,0.00022749875,27.18325,11.076201,24.934269,-9.4784155
11.0,2.1399176,0.0017472707,34.478466,0,11.076097,32.915874,0.0001376708,27.23926,11.075699,26.834118,-9.4762993
12.1,2.1614535,-0.0010890145,39.172874,0,11.076097,36.215878,-5.508008e-05,27.541292,11.07615,29.954618,-9.4753332
13.2,2.1701202,-0.0045729363,41.802124,0,11.076097,39.515881,-0.0002920636,27.630104,11.075937,33.57777,-9.4730558
14.3,2.1765621,-0.0081804879,43.527828,0,11.076097,42.815887,-0.00050927169,27.72908,11.075901,37.766579,-9.4712229
15.4,2.1869912,-0.012078297,44.129353,0,11.076097,46.115883,-0.00083101966,27.870749,11.075387,42.389923,-9.4693069
16.5,2.2067335,-0.016088048,44.077152,0,11.076097,49.415886,-0.0010828307,28.112701,11.076623,47.264549,-9.4675312
17.6,2.2036769,-0.01828254,42.978592,0,11.076097,52.715897,-0.0012425042,28.09086,11.076203,52.047428,-9.4651546
18.7,2.212894,-0.021343263,41.803028,0,11.076097,56.015896,-0.0014248912,28.212297,11.075568,56.405014,-9.4633732
19.8,2.2024434,-0.024662426,40.572536,0,11.076097,59.315903,-0.0016226916,28.07773,11.076286,60.439999,-9.4615879
20.9,2.1920776,-0.027054172,39.457191,0,11.076097,62.615898,-0.0017925171,27.962587,11.076018,63.920929,-9.459424
22.0,2.2053988,-0.029311357,39.243168,0,11.076097,65.915886,-0.0019103165,28.136631,11.076164,66.835014,-9.4575491
23.1,2.2030344,-0.031206377,39.641796,0,11.076097,69.215881,-0.0021181435,28.096518,11.075863,69.595299,-9.4553375
24.2,2.2061021,-0.033844259,40.030521,0,11.076097,72.515877,-0.0022418567,28.151222,11.07466,72.441589,-9.4532642
25.3,2.2151325,-0.036016081,41.016663,0,11.076097,75.815887,-0.0024200724,28.280155,11.076236,75.309464,-9.4512606
26.4,2.2151744,-0.039481103,41.792526,0,11.076097,79.115883,-0.0026392306,28.266275,11.075864,78.351646,-9.449439
27.5,2.2177258,-0.041900974,42.022228,0,11.076097,82.415894,-0.0027969219,28.330269,11.076361,81.610832,-9.4475679
28.6,2.2216237,-0.044366885,42.737286,0,11.076097,85.715897,-0.0029417756,28.360325,11.075835,84.763321,-9.4459085
29.7,2.2205653,-0.047087964,42.978512,0,11.076097,89.015892,-0.0030978525,28.353687,11.076213,88.197495,-9.4441452
30.8,2.2370639,-0.049268764,42.978512,0,11.076097,92.315903,-0.003305675,28.587589,11.075951,91.761948,-9.4422932
31.9,2.2336736,-0.052072786,43.274315,0,11.076097,95.615891,-0.0034339132,28.544573,11.076361,95.054428,-9.4403219
33.0,2.2306294,-0.055027232,43.527828,0,11.076097,98.915894,-0.0037043132,28.513151,11.07518,98.378227,-9.4384298
34.1,2.2426102,-0.057379983,43.709682,0,11.076097,102.21589,-0.0038241504,28.670349,11.077019,101.70353,-9.4366179
35.2,2.2450001,-0.059444577,44.077145,0,11.076097,105.51589,-0.0039741662,28.693909,11.076051,104.98862,-9.434618
36.3,2.2466466,-0.06184461,43.874775,0,11.076097,108.81589,-0.0041132923,28.730722,11.075878,108.63023,-9.4331036
37.4,2.2443373,-0.064925589,43.848194,0,11.076097,112.11588,-0.0043080822,28.69257,11.075885,112.00309,-9.4311676
38.5,2.2305853,-0.067137957,44.077145,0,11.076097,115.41588,-0.0044455482,28.532635,11.074876,115.06837,-9.4288445
39.6,2.2461662,-0.069996312,44.604488,0,11.076097,118.71589,-0.0046149916,28.737406,11.075952,118.06221,-9.4270601
40.7,2.2515941,-0.072118796,45.12085,0,11.076097,122.01588,-0.004817436,28.794497,11.074703,121.42798,-9.4249916
41.8,2.2400401,-0.075236589,45.564285,0,11.076097,125.31588,-0.0049840189,28.670412,11.076491,124.55894,-9.4226799
42.9,2.2496386,-0.077683501,45.841553,0,11.076097,128.61601,-0.0052000987,28.796175,11.076096,127.81045,-9.4209766
44.0,2.2602227,-0.08054515,46.109619,0,11.076097,131.91589,-0.0053697163,28.923004,11.075008,131.26489,-9.4190245
45.1,2.2642195,-0.082894184,46.109619,0,11.076097,135.2159,-0.0055191168,29.000404,11.076375,134.59988,-9.4168825
46.2,2.2766712,-0.085716382,46.200413,0,11.076097,138.51588,-0.0056866254,29.162607,11.075644,138.03896,-9.4152412
47.3,2.2790911,-0.089769319,46.582027,0,11.076097,141.81589,-0.0059435107,29.184866,11.076029,141.29175,-9.4131641
48.4,2.2746449,-0.09256722,46.851112,0,11.076097,145.11589,-0.0061484305,29.1507,11.076884,144.55515,-9.4115286
49.5,2.2769029,-0.095094018,47.05444,0,11.076097,148.41589,-0.0062904512,29.180878,11.075488,147.79739,-9.4093122
50.6,2.2701952,-0.097321808,47.503983,0,11.076097,151.7159,-0.0065006348,29.088234,11.076895,151.00806,-9.407424
51.7,2.2901974,-0.10001518,47.741714,0,11.076097,155.01588,-0.0066472441,29.356287,11.07617,154.25757,-9.405879
52.8,2.3013566,-0.10260775,47.955318,0,11.076097,158.31589,-0.0068400749,29.498669,11.07669,157.62648,-9.4040127
53.9,2.2969959,-0.10578289,48.095097,0,11.076097,161.61589,-0.0070309765,29.450008,11.076242,160.96964,-9.4018946
55.0,2.307534,-0.10859147,48.383698,0,11.076097,164.91589,-0.007213817,29.60339,11.076197,164.418,-9.4001303
56.1,2.3157299,-0.11277121,48.383785,0,11.076097,168.2159,-0.0074748481,29.70426,11.077395,167.61948,-9.3984346
57.2,2.3202608,-0.11508524,48.812252,0,11.076097,171.51588,-0.0075997072,29.78488,11.077359,170.82678,-9.3965092
58.3,2.318476,-0.11777976,49.144402,0,11.076097,174.81589,-0.0078322431,29.763304,11.075954,174.19713,-9.3946276
59.4,2.3252535,-0.12071983,49.229733,0,11.076097,178.11589,-0.0079921866,29.83909,11.074532,177.61754,-9.3927259
60.5,2.3346083,-0.12346756,49.229733,0,11.076097,181.41589,-0.0082312552,29.984207,11.074942,181.0564,-9.3907108
61.6,2.3378906,-0.12636153,49.229733,0,11.076097,184.7159,-0.0084054284,30.020634,11.076348,184.41588,-9.3889713
62.7,2.3384073,-0.12875569,49.229733,0,11.076097,188.01588,-0.0085557709,30.021523,11.075952,187.8526,-9.3872805
63.8,2.3444283,-0.13214186,49.229733,0,11.076097,191.3159,-0.0087558394,30.12604,11.075782,191.10121,-9.3853102
64.9,2.350261,-0.13673596,49.26955,0,11.076097,194.61591,-0.0090496745,30.192741,11.076266,194.39816,-9.3836184
66.0,2.3447697,-0.13866845,49.447514,0,11.076097,197.91592,-0.0091996808,30.121643,11.075776,197.73512,-9.3820705
67.1,2.3456748,-0.14100954,49.636223,0,11.076097,201.21591,-0.0093281548,30.149296,11.075868,200.92068,-9.3799868
68.2,2.3507712,-0.14357272,49.698582,0,11.076097,204.51591,-0.0095512355,30.210016,11.075923,204.16977,-9.3777304
69.3,2.3539562,-0.14651261,50.042721,0,11.076097,207.81592,-0.0097268363,30.275175,11.075184,207.36658,-9.376462
70.4,2.3579419,-0.14923947,50.437252,0,11.076097,211.11591,-0.0099210935,30.316103,11.074939,210.44963,-9.3743515
71.5,2.3636706,-0.15255195,50.759964,0,11.076097,214.41591,-0.010107033,30.402317,11.076177,213.64217,-9.3727522
72.6,2.3658645,-0.15557857,50.883343,0,11.076097,217.71591,-0.010316329,30.447052,11.076322,216.8889,-9.370966
73.7,2.3707037,-0.15848398,51.196285,0,11.076097,221.01591,-0.01049826,30.500647,11.076656,220.1404,-9.3688231
74.8,2.3693938,-0.16197182,51.564671,0,11.076097,224.31592,-0.010701696,30.488182,11.075276,223.57275,-9.3671207
75.9,2.3792491,-0.16485438,51.569077,0,11.076097,227.61591,-0.010954963,30.621809,11.075706,227.09341,-9.3653297
77.0,2.3730299,-0.16830635,51.437531,0,11.076097,230.91589,-0.011137055,30.557014,11.076524,230.66109,-9.363452
78.1,2.3741601,-0.1710854,51.451454,0,11.076097,234.2159,-0.011368814,30.570557,11.076391,234.06941,-9.3615599
79.2,2.3866701,-0.17465432,51.316307,0,11.076097,237.51588,-0.011580361,30.748522,11.07676,237.46744,-9.3597727
80.3,2.3798466,-0.17766848,51.312805,0,11.076097,240.8159,-0.011787561,30.658882,11.075343,240.75542,-9.3580656
81.4,2.3879106,-0.18046412,51.569805,0,11.076097,244.11589,-0.011938524,30.765139,11.076486,243.97754,-9.3567133
82.5,2.3969011,-0.18428862,51.56982,0,11.076097,247.41589,-0.012185434,30.886747,11.07538,247.30096,-9.3546162
83.6,2.3936348,-0.18762018,51.56982,0,11.076097,250.71591,-0.012432331,30.868656,11.075586,250.44188,-9.3527012
84.7,2.4040694,-0.19037981,51.577816,0,11.076097,254.0159,-0.012579893,30.997227,11.075658,253.8143,-9.350811
85.8,2.4047563,-0.19219461,51.899094,0,11.076097,257.31616,-0.012768562,31.023466,11.076101,257.07901,-9.3490667
86.9,2.3992567,-0.1948154,51.932369,0,11.076097,260.61618,-0.012902948,30.953299,11.076649,260.37646,-9.3472357
88.0,2.4082839,-0.19775108,52.045357,0,11.076097,263.91592,-0.013124093,31.071768,11.076857,263.5231,-9.3454409
89.1,2.4070528,-0.20057377,52.230896,0,11.076097,267.21591,-0.013284046,31.044062,11.077128,266.85468,-9.3436775
90.2,2.4081879,-0.2037961,52.283936,0,11.076097,270.5159,-0.013492114,31.07091,11.076507,270.20856,-9.3419781
91.3,2.4136672,-0.2070125,52.283936,0,11.076097,273.81589,-0.013692416,31.162731,11.076483,273.51306,-9.339901
92.4,2.4123411,-0.21025883,52.47279,0,11.076097,277.11591,-0.013874501,31.142841,11.075274,276.75812,-9.3382473
93.5,2.4098899,-0.2131367,52.548119,0,11.076097,280.41589,-0.014124804,31.122667,11.076476,280.08826,-9.3364515
94.6,2.4174027,-0.21608905,52.635494,0,11.076097,283.71591,-0.014289934,31.232447,11.076225,283.3298,-9.3345594
95.7,2.4117935,-0.21903138,52.789257,0,11.076097,287.0159,-0.014517685,31.169403,11.074829,286.66736,-9.332675
96.8,2.4158537,-0.22215432,52.9758,0,11.076097,290.31589,-0.01470952,31.23572,11.074766,289.88644,-9.3311176
97.9,2.420547,-0.2247802,52.97607,0,11.076097,293.61588,-0.014880317,31.296183,11.076747,293.20148,-9.3291378
99.0,2.4160755,-0.2276096,52.982155,0,11.076097,296.91589,-0.015057558,31.218204,11.0749,296.55771,-9.327837
100.1,2.4227407,-0.23060849,53.060516,0,11.076097,299.99545,-0.015217232,31.320784,11.075873,299.81363,-9.3266287
101.2,0.053388622,-0.26492584,49.610016,0,11.076097,299.99905,-0.017515792,0.69187266,11.076136,303.87888,-9.3262711
102.3,0.044087738,-0.26507631,44.542625,0,11.076097,299.99905,-0.017489977,0.57848608,11.075696,306.98148,-9.3258066
103.4,0.02490516,-0.26486456,40.213806,0,11.076097,299.99905,-0.01753336,0.32372686,11.075662,307.41315,-9.3257866
104.5,0.023767695,-0.26324421,38.551029,0,11.076097,299.99905,-0.017410686,0.30974081,11.076674,305.87473,-9.3259735
105.6,0.020780692,-0.26172101,39.243004,0,11.076097,299.99905,-0.01730239,0.26727107,11.075633,303.25912,-9.3264647
106.7,0.01317101,-0.26034519,41.920406,0,11.076097,299.99905,-0.017193407,0.17711738,11.075943,300.34302,-9.3265743
107.8,0.014154292,-0.25918794,45.583561,0,11.076097,299.99905,-0.017108886,0.20028679,11.077045,297.51337,-9.3269053
108.9,0.0075559062,-0.25761411,49.202816,0,11.076097,299.99905,-0.017032802,0.10188983,11.076211,295.10452,-9.3261738
110.0,0.0031147618,-0.25725496,52.558701,0,11.076097,299.99905,-0.01696752,0.05610992,11.075982,293.28671,-9.3257847
111.1,0.0079356246,-0.25663999,55.415382,0,11.076097,299.99905,-0.016996907,0.099076033,11.076604,292.03253,-9.3255825
112.2,0.0061448426,-0.25628367,57.793545,0,11.076097,299.99905,-0.016946835,0.082592264,11.076275,291.35654,-9.3256721
113.3,0.0074341628,-0.25637519,59.793121,0,11.076097,299.99905,-0.016963219,0.093164153,11.076385,291.31735,-9.325551
114.4,0.015869126,-0.25638357,61.235126,0,11.076097,299.99905,-0.016944688,0.19072951,11.075665,291.7749,-9.326232
115.5,0.01280205,-0.25669673,62.33596,0,11.076097,299.99905,-0.016954539,0.18323609,11.076495,292.5676,-9.3261557
116.6,0.024736453,-0.25681734,63.171143,0,11.076097,299.99905,-0.016965805,0.34121603,11.075935,293.67795,-9.3262634
117.7,0.034372542,-0.25764886,63.371952,0,11.076097,299.99905,-0.016994853,0.45193902,11.075078,295.33487,-9.3261251
118.8,0.038402252,-0.258762,63.189011,0,11.076097,299.99905,-0.017128343,0.4978964,11.075479,297.48309,-9.3259697
119.9,0.045339197,-0.26091143,62.546822,0,11.076097,299.99905,-0.017251432,0.5938772,11.076116,299.70981,-9.3258457
121.0,0.045058411,-0.26181993,61.507977,0,11.076097,299.99905,-0.017322825,0.57595408,11.076264,301.71182,-9.3255587
122.1,0.050461181,-0.26335031,60.226177,0,11.076097,299.99905,-0.017396249,0.66550958,11.07609,303.39987,-9.3255482
123.2,0.05176121,-0.26509815,58.74839,0,11.076097,299.99905,-0.017505271,0.670654,11.075677,304.70831,-9.3251925
124.3,0.048971128,-0.26525995,57.26503,0,11.076097,299.99905,-0.017533703,0.62876201,11.075244,305.36118,-9.3252478
125.4,0.047740959,-0.26489708,55.84367,0,11.076097,299.99905,-0.017476769,0.62182432,11.076681,305.59729,-9.3252535
126.5,0.045258649,-0.26432785,54.399834,0,11.076097,299.99905,-0.017505702,0.59140909,11.076094,305.3219,-9.3253574
127.6,0.028506681,-0.26416117,53.430267,0,11.076097,299.99905,-0.01746968,0.37331459,11.075762,304.6489,-9.3252525
128.7,0.024113849,-0.26464024,52.977139,0,11.076097,299.99905,-0.017502014,0.3219803,11.076113,303.4343,-9.3250847
129.8,0.01847407,-0.26388872,53.316639,0,11.076097,299.99905,-0.017432254,0.2358705,11.07652,302.00613,-9.3255577
130.9,0.010852332,-0.26378483,53.97567,0,11.076097,299.99905,-0.017408011,0.15020181,11.075356,300.40625,-9.3255854
132.0,0.01044801,-0.26298937,54.954819,0,11.076097,299.99905,-0.017389404,0.14543532,11.075851,298.88553,-9.3252563
133.1,0.0016869751,-0.26303676,56.404037,0,11.076097,299.99905,-0.017358035,0.0065660952,11.076035,297.51151,-9.3255548
134.2,0.0041037034,-0.26261494,57.759811,0,11.076097,299.99905,-0.017389901,0.053033452,11.07602,296.32935,-9.3254976
135.3,0.013192685,-0.26306754,59.046482,0,11.076097,299.99905,-0.017393302,0.16160145,11.076868,295.67175,-9.3255215
136.4,0.012437182,-0.26359496,60.083542,0,11.076097,299.99905,-0.017431965,0.16137485,11.075992,295.40305,-9.3256226
137.5,0.018247832,-0.26349899,60.832542,0,11.076097,299.99905,-0.0174051,0.24263842,11.076305,295.64072,-9.325386
138.6,0.026916673,-0.26324412,61.237789,0,11.076097,299.99905,-0.017374041,0.35269102,11.075176,296.48392,-9.3255091
139.7,0.037154026,-0.26319006,61.237804,0,11.076097,299.99905,-0.017407641,0.48415604,11.076457,297.84103,-9.3253632
140.8,0.049087264,-0.26469746,60.787373,0,11.076097,299.99905,-0.017461972,0.64209467,11.076317,299.45474,-9.3253479
141.9,0.043188896,-0.26556718,59.969486,0,11.076097,299.99905,-0.017588716,0.55744642,11.075431,301.03436,-9.3249159
143.0,0.046573069,-0.26640904,59.018284,0,11.076097,299.99905,-0.017617906,0.62039781,11.076851,302.24911,-9.3249893
144.1,0.04424521,-0.26746956,57.823612,0,11.076097,299.99905,-0.017680585,0.56616724,11.075806,303.18356,-9.3244791
145.132,0.14258008,-0.0080253882,56.986183,0,11.076097,299.99905,-0.00052866491,1.8055433,11.076387,303.55759,-9.3243856
145.2839,0.53041846,0.01430726,52.510372,0,11.076099,6.0864735e-10,0.0010975528,6.7068076,11.077848,303.79736,-9.3251791
145.2861,0.52454793,0.014895365,40.958084,0,11.076099,6.0790445e-25,0.00083157769,6.6727757,11.077679,303.8161,-9.3245554
145.2883,0.5869903,0.017006617,29.405796,0,11.076099,6.0716300999999994e-40,0.0012883694,7.4570398,11.078278,303.83487,-9.3224354
145.2905,0.54579073,0.01664914,17.853508,0,11.076099,0.0,0.00098465371,6.8842711,11.072019,303.85364,-9.3236885
145.2927,0.53581131,0.014151528,6.3012214,0,11.076099,0.0,0.0010379989,6.8050232,11.074884,303.87241,-9.3238049
145.2949,0.54150319,0.013844728,0.0,0,11.076099,0.0,0.00086479203,6.9603934,11.075487,303.8642,-9.3239851
145.2971,0.54474741,0.01798082,0.0,0,11.076099,0.0,0.001412714,6.9358582,11.075488,303.82364,-9.3234234
145.2993,0.546758,0.016292442,0.0,0,11.076099,0.0,0.00093106908,6.8914542,11.077383,303.78308,-9.3246069
145.3015,0.5509941,0.014294593,0.0,0,11.076099,0.0,0.0010679531,7.0347381,11.077864,303.74255,-9.3245058
145.3037,0.54824018,0.01404735,0.0,0,11.076099,0.0,0.00083606492,7.029212,11.073846,303.702,-9.3240681
145.3059,0.55749321,0.016652044,0.0,0,11.076099,0.0,0.0012316137,7.1747622,11.078625,303.7049,-9.3246202
145.3081,0.56295985,0.016061774,0.0,0,11.076099,0.0,0.00095397857,7.0384908,11.074762,303.71164,-9.3235703
145.3103,0.56911492,0.014016697,0.0,0,11.076099,0.0,0.0010774034,7.200839,11.075391,303.71841,-9.3248606
145.3125,0.56756926,0.01411608,0.0,0,11.076099,0.0,0.00089902303,7.1740885,11.079328,303.72519,-9.3248358
145.3147,0.58006907,0.019029861,0.0,0,11.076099,0.0,0.0013985859,7.3765988,11.076456,303.73453,-9.324954
145.3169,0.57918638,0.016981039,0.0,0,11.076099,0.0,0.0010287289,7.3584876,11.074202,303.74808,-9.3250713
145.3191,0.57502156,0.016623976,0.0,0,11.076099,0.0,0.0011645727,7.3473878,11.076047,303.7616,-9.3246441
145.3213,0.59269667,0.014589318,0.0,0,11.076099,0.0,0.00091357762,7.5359483,11.076488,303.77515,-9.3244057
145.3235,0.5886218,0.01943846,0.0,0,11.076099,0.0,0.0013157291,7.5363951,11.075784,303.78867,-9.325304
145.3257,0.58860618,0.016663376,0.0,0,11.076099,0.0,0.0010896245,7.5289154,11.077502,303.80222,-9.3249016
145.3279,0.59393287,0.017062385,0.0,0,11.076099,0.0,0.0011467763,7.538763,11.077331,303.81577,-9.3254642
145.3301,0.59364057,0.014693357,0.0,0,11.076099,0.0,0.00096098433,7.6432967,11.075426,303.82928,-9.3242283
145.3323,0.59658396,0.019852201,0.0,0,11.063763,0.0,0.0013418841,7.6697221,11.078686,303.84283,-9.3246393
145.3345,0.60730195,0.01548266,0.0,0,10.735819,0.0,0.0010787008,7.7127824,11.070634,303.85843,-9.3232031
145.3367,0.62162626,0.016843032,0.0,0,10.404926,0.0,0.0011627168,7.9445324,11.070029,303.87872,-9.3228159
145.3389,0.63580757,0.014848907,0.0,0,10.074035,0.0,0.0010035071,8.0837936,11.012961,303.89902,-9.3238344
145.3411,0.63648427,0.021859694,0.0,0,9.7431412,0.0,0.0013359775,8.1366825,10.826702,303.91928,-9.3233261
145.3433,0.65236187,0.014827327,0.0,0,9.4141388,0.0,0.0010477541,8.297905,10.529113,303.93958,-9.3231993
145.3455,0.61561948,0.018459357,0.0,0,9.0922337,0.0,0.0012013753,7.8364534,10.144956,305.07977,-9.3240719
145.3477,7.7017407,0.30841219,0.0,0,8.7703295,0.0,0.019872358,95.595695,9.7441845,306.54935,-9.3182583
145.3499,9.9910059,0.69390547,0.0,0,8.4631929,0.0,0.046859268,120.45585,9.2850876,308.01892,-9.316618
145.3521,10.975446,1.0963271,0.0,0,8.1570406,0.0,0.075739734,129.17572,8.8604879,309.48849,-9.3161306
145.3543,11.461279,1.4326329,0.0,0,7.860775,0.0,0.099879302,132.10938,8.5294905,311.03131,-9.3145046
145.3565,11.879117,1.7089578,0.0,0,7.5694952,0.0,0.12076282,133.78114,8.2072515,312.81079,-9.3146238
145.3587,12.270912,2.0196171,0.0,0,7.2838035,0.0,0.14405303,135.31259,7.8961544,314.59027,-9.3150911
145.3609,12.475426,2.2894425,0.0,0,7.0067787,0.0,0.16539717,134.63976,7.6296701,316.36975,-9.3156395
145.3631,12.841808,2.5409656,0.0,0,6.7313666,0.0,0.18509391,135.76347,7.3633447,318.1492,-9.3151693
145.3653,13.168159,2.7992094,0.0,0,6.467802,0.0,0.20637096,136.38368,7.0963869,318.3952,-9.3152876
145.3675,13.471942,3.0748813,0.0,0,6.2042418,0.0,0.22872975,136.42812,6.8303332,317.98398,-9.315382
145.3697,13.8641,3.3275499,0.0,0,5.9515953,0.0,0.25065643,137.30342,6.5649281,317.57275,-9.3144999
145.3719,14.178494,3.5967991,0.0,0,5.7009273,0.0,0.27359998,137.28963,6.2984743,317.16156,-9.3151979
145.3741,14.495185,3.8607211,0.0,0,5.457253,0.0,0.29742277,137.06439,6.0332723,316.76361,-9.3150454
145.3763,14.857166,4.1239834,0.0,0,5.2187734,0.0,0.32069048,137.18819,5.773777,316.4335,-9.3146276
145.3785,15.182746,4.3747439,0.0,0,4.9838037,0.0,0.34465724,136.93597,5.509388,316.10339,-9.3149366
145.3807,15.52703,4.6289544,0.0,0,4.7569838,0.0,0.36823729,136.73969,5.257206,315.77328,-9.3147116
145.3829,15.891399,4.8705702,0.0,0,4.5305758,0.0,0.39261773,136.58682,5.0181098,315.44318,-9.3159876
145.3851,16.231152,5.1181102,0.0,0,4.3147016,0.0,0.41646275,136.18373,4.7760878,315.68378,-9.3161707
145.3873,16.615921,5.3378224,0.0,0,4.0989256,0.0,0.4397777,136.19061,4.5457616,316.26352,-9.3161364
145.3895,17.022844,5.5654984,0.0,0,3.8911293,0.0,0.46280399,136.38464,4.3181305,316.84326,-9.3150949
145.3917,17.402691,5.7767229,0.0,0,3.6859133,0.0,0.48650247,136.17911,4.0972395,317.42297,-9.3132372
145.3939,17.82671,6.0040236,0.0,0,3.4855206,0.0,0.51021594,136.22394,3.8860493,317.94205,-9.3130913
145.3961,18.260168,6.2066073,0.0,0,3.2902927,0.0,0.53406936,136.22954,3.6697226,317.8544,-9.3140097
145.3983,18.706207,6.4166951,0.0,0,3.0970623,0.0,0.55733985,136.36198,3.4684563,317.76678,-9.3141251
145.4005,19.186153,6.6125932,0.0,0,2.9113381,0.0,0.58156103,136.47508,3.2646794,317.67917,-9.3150482
145.4027,19.693867,6.8189402,0.0,0,2.7256143,0.0,0.60493875,136.79883,3.0677023,317.59152,-9.3145943
145.4049,20.231316,6.9995475,0.0,0,2.5483871,0.0,0.62872511,137.29721,2.8749213,317.20483,-9.3138609
145.4071,20.784935,7.1882858,0.0,0,2.3717272,0.0,0.65145296,137.91484,2.6944921,316.57788,-9.3141069
145.4093,21.373926,7.3631282,0.0,0,2.2008002,0.0,0.67553681,138.42223,2.5123394,315.95096,-9.3137865
145.4115,21.964783,7.5513353,0.0,0,2.0327642,0.0,0.69870085,139.00212,2.3347118,315.32404,-9.3128815
145.4137,22.597305,7.7138271,0.0,0,1.8679363,0.0,0.72248346,139.65085,2.162514,314.70334,-9.3123102
145.4159,23.267086,7.8873706,0.0,0,1.7080842,0.0,0.7450363,140.55591,1.995613,314.42023,-9.3135071
145.4181,23.954756,8.0476732,0.0,0,1.5491643,0.0,0.76943249,141.23622,1.8276557,314.13708,-9.3129368
145.4203,24.715651,8.2176762,0.0,0,1.3970972,0.0,0.79223239,142.39571,1.6673588,313.85397,-9.3118267
145.4225,25.505682,8.362361,0.0,0,1.2450333,0.0,0.81579787,143.55634,1.5084343,313.57083,-9.3108654
145.4247,26.355886,8.5229979,0.0,0,1.0992643,0.0,0.83853006,144.95575,1.3542864,313.21625,-9.3100424
145.4269,27.212749,8.6675692,0.0,0,0.95463622,0.0,0.86311436,146.08487,1.2017429,312.78482,-9.3103733
145.4291,28.106649,8.8179922,0.0,0,0.8140732,0.0,0.88471282,147.668,1.0586727,312.35339,-9.3106251
145.4313,29.022421,8.9486952,0.0,0,0.67652929,0.0,0.90834808,148.9082,0.91322309,311.92194,-9.3105326
145.4335,29.97794,9.0889578,0.0,0,0.54098582,0.0,0.92991465,150.53488,0.77465612,311.49051,-9.3098679
145.4357,30.973139,9.2167435,0.0,0,0.4100858,0.0,0.95399505,151.82057,0.63980281,311.76016,-9.309145
145.4379,32.011585,9.3529654,0.0,0,0.27942529,0.0,0.97515184,153.60817,0.51159656,312.07025,-9.3080158
145.4401,29.958248,9.3828735,0.0,0,0.15489206,0.0,0.98340023,142.77339,0.43669724,312.38034,-9.3091211
145.4423,28.456734,9.3982506,0.0,0,0.030416043,0.0,0.98387009,135.6109,0.40252677,312.69043,-9.3108673
145.4445,27.933723,9.4071865,0.0,0,-0.091732524,0.0,0.98768586,132.47511,0.3683129,313.55136,-9.3122311
145.4467,27.74884,9.4181919,0.0,0,-0.21312852,0.0,0.98738211,131.64635,0.32022324,315.20795,-9.3125095
145.4489,27.732655,9.4189539,0.0,0,-0.33452454,0.0,0.98983157,131.25171,0.26809102,316.86453,-9.3132849
145.4511,27.744923,9.4241161,0.0,0,-0.45592052,0.0,0.98860532,131.42517,0.21254595,318.52112,-9.3140459
145.4533,27.672508,9.4316187,0.0,0,-0.57731652,0.0,0.99216413,130.64886,0.15689474,320.1777,-9.3128271
145.4555,27.54862,9.442215,0.0,0,-0.69871247,0.0,0.99176097,130.13438,0.11040234,321.50354,-9.3140001
145.4577,27.364723,9.4396839,0.0,0,-0.82010847,0.0,0.99348456,129.05885,0.065313317,322.7811,-9.315732
145.4599,27.098499,9.4485235,0.0,0,-0.94150448,0.0,0.99288493,127.87877,0.033225544,324.05869,-9.3147135
145.4621,26.739738,9.4483624,0.0,0,-1.0629005,0.0,0.99501956,125.93329,0.01368312,325.33627,-9.3153181
145.4643,26.282047,9.4547968,0.0,0,-0.84332824,300.0,0.99395281,123.8978,0.0013679236,326.38297,-9.3159008
145.4665,25.745308,9.4481449,0.0,0,-0.42304912,300.0,0.99494272,121.20155,0.0039332178,326.97418,-9.3159409
145.4687,25.296047,9.4507742,0.0,0,-0.0027696523,300.0,0.99341947,119.30465,0.010944634,327.56537,-9.3155994
145.4709,24.90523,9.4539671,0.0,0,0.4175092,300.0,0.9960171,117.1421,0.013339046,328.15659,-9.3164396
145.4731,24.612307,9.4589815,0.0,0,0.83778834,300.0,0.9948957,115.91301,0.014833632,328.7478,-9.3177023
145.4753,24.334095,9.4520636,0.0,0,1.2580682,300.0,0.99554348,114.54104,0.013915024,329.14551,-9.3184471
145.4775,23.600807,9.4520578,0.0,0,1.6783469,300.0,0.99387598,111.37852,0.030722685,329.49484,-9.3185987
145.4797,22.154793,9.4492579,0.0,0,2.0986257,300.0,0.99483961,104.43897,0.087584637,329.84418,-9.3192377
145.4819,19.482782,9.441247,0.0,0,2.5189054,300.0,0.99197751,92.336685,0.20171358,330.19351,-9.3210363
145.4841,14.219932,9.4210815,0.0,0,2.9391847,300.0,0.98971748,67.990562,0.41416481,330.67197,-9.3246603
145.4863,0.36328524,9.1958351,0.0,0,3.3594637,300.0,0.94985336,1.5170045,0.84607905,331.51108,-9.338357
145.4885,0.29106724,9.0492506,0.0,0,3.7797427,300.0,0.92540842,1.8509169,1.4885418,332.35022,-9.3347378
145.4907,-0.25920826,9.0043383,0.0,0,4.2000222,300.0,0.91627425,-1.1454738,2.2681391,333.18933,-9.3358908
145.4929,-0.10206746,9.0332146,0.0,0,4.6203012,300.0,0.92197996,-0.50293899,2.9559469,334.02844,-9.3366461
145.4951,-0.16151011,9.1702709,0.0,0,5.0405807,300.0,0.94384462,-0.82198447,3.4936118,332.99564,-9.3373375
145.4973,-0.041219935,9.3909883,0.0,0,5.4608598,300.0,0.98356658,-0.2776269,3.9065223,331.26083,-9.3363209
145.4995,0.22941086,9.3810596,0.0,0,5.8811393,300.0,0.98275578,0.85602617,4.2912822,329.52606,-9.334651
145.5017,-0.22193617,9.3728285,0.0,0,6.3014183,300.0,0.98233622,-1.0131848,4.6742349,327.79129,-9.3343859
145.5039,0.073239617,9.4056273,0.0,0,6.7216969,300.0,0.98593956,0.26393256,5.0443773,326.14542,-9.3325167
145.5061,-0.095232308,9.4233074,0.0,0,7.1419768,300.0,0.98898405,-0.47680163,5.4347625,324.87634,-9.3307552
145.5083,-0.058106072,9.4245052,0.0,0,7.5622559,300.0,0.98877883,-0.31129178,5.8560748,323.60724,-9.3296385
145.5105,-0.001574365,9.4185791,0.0,0,7.9825354,300.0,0.98868304,0.065500095,6.2989321,322.33817,-9.3302193
145.5127,-0.074488029,9.4111624,0.0,0,8.4028139,300.0,0.98733574,-0.39515877,6.7542601,321.06909,-9.3291368
145.5149,-0.15166911,9.4114132,0.0,0,8.8230925,300.0,0.98748803,-0.66848552,7.2027473,320.5336,-9.3288984
145.5171,-8.0337959e-05,9.4106798,0.0,0,9.243372,300.0,0.98701257,-0.036750741,7.6502318,320.38528,-9.3274059
145.5193,0.10016939,9.4023952,0.0,0,9.6636515,300.0,0.98580885,0.47611985,8.0889139,320.23697,-9.3263617
145.5215,-0.065197475,9.3986282,0.0,0,10.083931,300.0,0.98491418,-0.21935725,8.5092325,320.08865,-9.3265333
145.5237,-0.17340927,9.4095278,0.0,0,10.50421,300.0,0.98680741,-0.81763464,8.9349499,319.75897,-9.3263311
145.5259,0.034403149,9.3997326,0.0,0,10.924489,300.0,0.98528981,0.11253463,9.3633833,318.07599,-9.326169
145.5281,-0.0066938791,9.4043741,0.0,0,11.344769,300.0,0.98597175,0.011195803,9.7902384,316.39301,-9.3242493
145.5303,-0.07463029,9.4024534,0.0,0,11.765047,300.0,0.98595893,-0.36736736,10.218944,314.71002,-9.325779
145.5325,-0.06520056,9.4098053,0.0,0,12.185327,300.0,0.9868052,-0.3455632,10.656898,313.02704,-9.3255215
145.5347,-0.087218188,9.4013968,0.0,0,12.605606,300.0,0.98579496,-0.49995384,11.093654,311.51074,-9.3240128
145.5369,0.043657973,9.4059105,0.0,0,13.025885,300.0,0.98626792,0.12148686,11.52889,310.11429,-9.323432
145.5391,0.029078746,9.3985338,0.0,0,13.446164,300.0,0.98533773,0.19194312,11.939288,308.7178,-9.3239126
145.5413,-0.10825418,9.4076672,0.0,0,13.866444,300.0,0.98611248,-0.5171563,12.36073,307.32132,-9.323946
145.5435,-0.077660732,9.3994026,0.0,0,14.286723,300.0,0.98561066,-0.40332028,12.789702,305.93924,-9.3255129
145.5457,-0.016605867,9.4048233,0.0,0,14.707002,300.0,0.98591608,-0.10584413,13.220262,304.85916,-9.323863
145.5479,-0.06586159,9.3999624,0.0,0,15.127281,300.0,0.98576361,-0.23605701,13.657696,303.77908,-9.3245497
145.5501,-0.057403494,9.4059,0.0,0,15.547561,300.0,0.98564458,-0.25196069,14.100364,302.69901,-9.3236971
145.5523,-0.058150969,9.3961487,0.0,0,15.967839,300.0,0.9849059,-0.22280446,14.536336,301.61893,-9.3239403
145.5545,-0.1032632,9.4037113,0.0,0,16.388119,300.0,0.98562604,-0.5181821,14.965795,300.82339,-9.3224182
145.5567,0.10566393,9.3925419,0.0,0,16.808399,300.0,0.98454338,0.47767097,15.38763,300.30219,-9.3230667
145.5589,-0.013877045,9.4053631,0.0,0,17.228678,300.0,0.98559773,0.012867332,15.803979,299.78101,-9.323041
145.5611,-0.12263713,9.3985815,0.0,0,17.648958,300.0,0.98559481,-0.55951148,16.217539,299.25983,-9.3223934
145.5633,-0.11042853,9.4024115,0.0,0,17.999975,300.0,0.98508698,-0.50004965,16.629627,298.73865,-9.3228369
145.5655,-0.088419132,9.3988409,4.2969694,0,18.0,300.0,0.98586571,-0.46296579,17.047125,298.07916,-9.3236866
145.5677,0.023893077,9.4075403,8.7143984,0,18.0,300.0,0.98570114,0.12569453,17.448799,297.41583,-9.3241072
145.5699,-0.079857104,9.3996534,13.131826,0,18.0,300.0,0.9857142,-0.35652471,17.804487,296.7525,-9.3233337
145.5721,-0.056587003,9.4033365,17.549255,0,18.0,300.0,0.98530859,-0.27550349,18.104948,296.08914,-9.3238153
145.5743,0.024445595,9.3995686,20.039063,0,18.0,300.0,0.98611253,0.12210553,18.334347,295.55283,-9.3263369
145.5765,-0.020969335,9.4153957,20.039063,0,18.0,300.0,0.98699331,-0.056371085,18.476002,295.18054,-9.3297014
145.5787,-0.061906647,9.4093456,20.039063,0,18.0,300.0,0.9879694,-0.25154406,18.501982,294.80826,-9.3353004
145.5809,-0.096394628,9.4237137,20.039063,0,18.0,300.0,0.98874146,-0.38352245,18.434023,294.436,-9.3427439
145.5831,-0.10772549,9.4280243,20.039063,0,18.0,300.0,0.99138343,-0.51299375,18.313982,294.06372,-9.3516998
145.5853,-0.066954903,9.4532852,21.259674,0,18.0,300.0,0.9936353,-0.3295742,18.198137,293.94119,-9.3635359
145.5875,-0.10290744,9.4562559,22.615902,0,18.0,300.0,0.99621171,-0.47549897,18.108353,293.84644,-9.3787928
145.5897,-0.090002798,9.4761677,23.97213,0,18.0,300.0,0.99816972,-0.47340488,18.059723,293.75168,-9.3945122
145.5919,0.026063735,9.4870453,25.328358,0,18.0,300.0,1.0023057,0.029603988,18.050726,293.65692,-9.4129267
145.5941,0.090400949,9.5130796,26.191408,0,18.0,300.0,1.0043635,0.42305836,18.053532,293.47849,-9.4293547
145.5963,0.043945272,9.5203533,26.191408,0,18.0,300.0,1.0079465,0.21972737,18.060648,293.15356,-9.4474955
145.5985,-0.020834569,9.5447416,26.191408,0,18.0,300.0,1.010347,-0.024792822,18.077745,292.82867,-9.4658613
145.6007,-0.09608677,9.5565624,26.191408,0,18.0,300.0,1.0149285,-0.34095347,18.098331,292.50375,-9.4833393
145.6029,-0.14003082,9.5855713,26.191408,0,18.0,300.0,1.0175145,-0.62214547,18.113983,292.17886,-9.5001898
145.6051,-0.15007578,9.5886068,27.734123,0,18.0,300.0,1.0206872,-0.74021387,18.126753,291.67477,-9.5173082
145.6073,-0.096013986,9.6113052,29.598936,0,18.0,300.0,1.0227692,-0.49999979,18.130507,291.13327,-9.532856
145.6095,0.0027072718,9.6200209,31.463751,0,18.0,300.0,1.0266048,-0.033309523,18.134825,290.5918,-9.5465946
145.6117,0.068570606,9.6446333,33.328564,0,18.0,300.0,1.0281219,0.27245101,18.131468,290.05029,-9.5612297
145.6139,0.061332356,9.6461821,34.650879,0,18.0,300.0,1.0314991,0.32127348,18.133396,289.56775,-9.5773678
145.6161,0.012108601,9.6672211,34.650879,0,18.0,300.0,1.033193,0.070316501,18.132368,289.22891,-9.5939455
145.6183,-0.075016908,9.6819429,34.650879,0,18.0,300.0,1.0381299,-0.291172,18.133804,288.89008,-9.608449
145.6205,-0.13383518,9.7116261,34.650879,0,18.0,300.0,1.0411562,-0.5491603,18.128887,288.55124,-9.6252937
145.6227,-0.15312441,9.7150946,34.650879,0,18.0,300.0,1.0445065,-0.65281904,18.129215,288.2124,-9.6404743
145.6249,-0.11288036,9.7347698,35.41473,0,18.0,300.0,1.0458628,-0.51618743,18.126362,287.92419,-9.6567383
145.6271,-0.036152825,9.7434883,36.427055,0,18.0,300.0,1.0500276,-0.2487487,18.120754,287.65244,-9.6723156
145.6293,0.057096504,9.7677193,37.439384,0,18.0,300.0,1.0516456,0.19219986,18.114851,287.38071,-9.687995
145.6315,0.087348029,9.7746611,38.45171,0,18.0,300.0,1.0557833,0.38687259,18.116629,287.10895,-9.7039375
145.6337,0.056193348,9.7957144,39.243164,0,18.0,300.0,1.0572182,0.29421946,18.115767,286.849,-9.7193317
145.6359,-0.032788347,9.8094826,39.243164,0,18.0,300.0,1.0623181,-0.087019309,18.113329,286.63132,-9.7347717
145.6381,-0.12102991,9.8348608,39.243164,0,18.0,300.0,1.0648584,-0.48713064,18.110571,286.41367,-9.7516327
145.6403,-0.15566854,9.844512,39.243164,0,18.0,300.0,1.0691299,-0.65062928,18.112101,286.19598,-9.7693195
145.6425,-0.13677312,9.8621378,39.243164,0,18.0,300.0,1.0702128,-0.62667197,18.110151,285.9783,-9.785244
145.6447,-0.070689388,9.875206,39.717075,0,18.0,300.0,1.07515,-0.39243627,18.107576,285.7189,-9.8004284
145.6469,0.016490771,9.8950443,40.412144,0,18.0,300.0,1.0763669,0.027980072,18.107431,285.44003,-9.8164911
145.6491,0.074693315,9.9018631,41.107212,0,18.0,300.0,1.0802661,0.30432421,18.106901,285.16113,-9.8318291
145.6513,0.065173715,9.9198332,41.802277,0,18.0,300.0,1.081709,0.31249252,18.105797,284.88226,-9.8479652
145.6535,0.007659852,9.9367971,42.39624,0,18.0,300.0,1.087093,0.12001089,18.103554,284.5816,-9.8618526
145.6557,-0.098870501,9.9574976,42.39624,0,18.0,300.0,1.0889177,-0.33063981,18.104549,284.15308,-9.8787222
145.6579,-0.15837234,9.9668779,42.39624,0,18.0,300.0,1.092929,-0.66632205,18.10124,283.72455,-9.8954659
145.6601,-0.15733187,9.984437,42.39624,0,18.0,300.0,1.0943606,-0.68582165,18.099098,283.29602,-9.9104633
145.6623,-0.10020611,9.9988136,42.39624,0,18.0,300.0,1.0994428,-0.46290413,18.098711,282.86749,-9.9273987
145.6645,-0.0079370905,10.01633,42.958263,0,18.0,300.0,1.1008167,-0.087723546,18.098654,282.45554,-9.9415865
145.6667,0.041996211,10.030987,43.880985,0,18.0,300.0,1.1057006,0.14230509,18.095949,282.05423,-9.9571238
145.6689,0.073725738,10.045696,44.803703,0,18.0,300.0,1.106898,0.31132686,18.096117,281.65289,-9.9716158
145.6711,0.036581881,10.062906,45.726421,0,18.0,300.0,1.1121845,0.1662069,18.095369,281.25159,-9.987421
145.6733,-0.048684891,10.08148,46.582031,0,18.0,300.0,1.1139281,-0.13022825,18.094416,280.85669,-10.003934
145.6755,-0.14349404,10.095305,46.582031,0,18.0,300.0,1.1185127,-0.53740138,18.09742,280.54379,-10.020347
145.6777,-0.16355062,10.112392,46.582031,0,18.0,300.0,1.1205295,-0.69043118,18.093107,280.2309,-10.038501
145.6799,-0.11742901,10.131311,46.582031,0,18.0,300.0,1.1260095,-0.52033073,18.094662,279.918,-10.054341
145.6821,-0.025512042,10.146458,46.582031,0,18.0,300.0,1.127389,-0.19136885,18.093985,279.6051,-10.070278
145.6843,0.029620862,10.157425,46.895088,0,18.0,300.0,1.1312418,0.077426694,18.095894,279.28854,-10.085894
145.6865,0.065349467,10.171361,47.478752,0,18.0,300.0,1.1328337,0.26733103,18.089268,278.96884,-10.101282
145.6887,0.065611273,10.189943,48.062412,0,18.0,300.0,1.1378908,0.26284945,18.089479,278.64917,-10.117627
145.6909,-0.010362459,10.2056,48.646076,0,18.0,300.0,1.1400931,0.017839503,18.091843,278.32947,-10.13274
145.6931,-0.10555349,10.224928,49.229736,0,18.0,300.0,1.1449838,-0.37748733,18.090014,278.00977,-10.148795
145.6953,-0.16667807,10.237272,49.229736,0,18.0,300.0,1.1467828,-0.64009315,18.090012,277.73087,-10.165429
145.6975,-0.14766017,10.258828,49.229736,0,18.0,300.0,1.1522406,-0.61207652,18.091349,277.452,-10.18128
145.6997,-0.07510002,10.270446,49.229736,0,18.0,300.0,1.153652,-0.35756102,18.089808,277.1731,-10.196254
145.7019,0.012502634,10.283965,49.229736,0,18.0,300.0,1.1574807,0.01149972,18.085363,276.89423,-10.211522
145.7041,0.05544753,10.297596,49.430729,0,18.0,300.0,1.1595322,0.22865406,18.088375,276.64056,-10.227068
145.7063,0.064185649,10.318431,49.864239,0,18.0,300.0,1.1646312,0.25324836,18.086374,276.41608,-10.241217
145.7085,0.038057145,10.328421,50.297745,0,18.0,300.0,1.1662288,0.19425541,18.085052,276.19162,-10.257812
145.7107,-0.060266178,10.347276,50.731255,0,18.0,300.0,1.1706982,-0.18612276,18.07666,275.96713,-10.275537
145.7129,-0.15293291,10.363715,51.164764,0,18.0,300.0,1.1739292,-0.54827678,18.07905,275.74268,-10.291062
145.7151,-0.16292575,10.385774,51.196289,0,18.0,300.0,1.1787595,-0.6390329,18.083136,275.46143,-10.306796
145.7173,-0.10541968,10.393103,51.196289,0,18.0,300.0,1.1804942,-0.45504525,18.08168,275.17575,-10.322154
145.7195,-0.015664434,10.410464,51.196289,0,18.0,300.0,1.1843389,-0.11088851,18.078697,274.89005,-10.339194
145.7217,0.055106647,10.421952,51.196289,0,18.0,300.0,1.186934,0.1835168,18.07687,274.60437,-10.355604
145.7239,0.069176048,10.445823,51.349655,0,18.0,300.0,1.1917981,0.26552173,18.074492,274.34262,-10.370684
145.7261,0.042881209,10.455682,51.741997,0,18.0,300.0,1.1945375,0.21311043,18.075691,274.11816,-10.385635
145.7283,-0.024589149,10.47806,52.134331,0,18.0,300.0,1.1988796,-0.03532894,18.073532,273.89368,-10.402339
145.7305,-0.11490232,10.487954,52.526672,0,18.0,300.0,1.2016093,-0.38270888,18.076414,273.66922,-10.419164
145.7327,-0.17451614,10.514203,52.91901,0,18.0,300.0,1.2066133,-0.66573393,18.077728,273.44476,-10.435222
145.7349,-0.14124385,10.522647,52.976074,0,18.0,300.0,1.2094588,-0.59008592,18.072906,273.26077,-10.451863
145.7371,-0.031531602,10.542234,52.976074,0,18.0,300.0,1.2130085,-0.21961558,18.073973,273.08368,-10.467595
145.7393,0.048151948,10.547352,52.976074,0,18.0,300.0,1.2151049,0.14308076,18.076757,272.90659,-10.481552
145.7415,0.069713227,10.574236,52.976074,0,18.0,300.0,1.2197866,0.26279247,18.076935,272.72949,-10.497599
145.7437,0.053149376,10.581317,53.069317,0,18.0,300.0,1.2226385,0.21237333,18.071348,272.51965,-10.512728
145.7459,0.004312105,10.602526,53.362358,0,18.0,300.0,1.2262245,0.053346887,18.075832,272.23962,-10.528965
145.7481,-0.07418783,10.613408,53.655403,0,18.0,300.0,1.2301846,-0.22496651,18.075167,271.95963,-10.543767
145.7503,-0.16467071,10.641048,53.948444,0,18.0,300.0,1.2348109,-0.56991422,18.074942,271.67963,-10.560252
145.7525,-0.16773264,10.647277,54.241486,0,18.0,300.0,1.2380313,-0.63672489,18.071753,271.39963,-10.575941
145.7547,-0.088735096,10.666551,54.30542,0,18.0,300.0,1.240821,-0.3748078,18.072609,271.09781,-10.592507
145.7569,0.013765125,10.672891,54.30542,0,18.0,300.0,1.2441406,0.018676208,18.072155,270.78992,-10.608403
145.7591,0.073908135,10.700767,54.30542,0,18.0,300.0,1.2485203,0.24842103,18.072437,270.48203,-10.622993
145.7613,0.068940811,10.70878,54.30542,0,18.0,300.0,1.2523888,0.27905986,18.070442,270.17413,-10.639942
145.7635,0.023655368,10.730015,54.404099,0,18.0,300.0,1.2553787,0.10949202,18.070042,269.86963,-10.65529
145.7657,-0.054985322,10.738474,54.806126,0,18.0,300.0,1.2594998,-0.13747886,18.066435,269.57541,-10.671242
145.7679,-0.11458176,10.767738,55.208149,0,18.0,300.0,1.2636341,-0.37278247,18.06885,269.28119,-10.688119
145.7701,-0.16331166,10.770551,55.610176,0,18.0,300.0,1.2670903,-0.58185345,18.064043,268.98697,-10.703461
145.7723,-0.1264279,10.791791,56.012199,0,18.0,300.0,1.2699138,-0.49624649,18.065695,268.69278,-10.721185
145.7745,-0.023821497,10.799631,56.12915,0,18.0,300.0,1.2743356,-0.1449493,18.066084,268.45679,-10.736649
145.7767,0.062037114,10.827372,56.12915,0,18.0,300.0,1.2777373,0.19351438,18.0623,268.24466,-10.751445
145.7789,0.077537827,10.830812,56.12915,0,18.0,300.0,1.2816823,0.27307484,18.061707,268.03256,-10.765268
145.7811,0.048038688,10.852522,56.12915,0,18.0,300.0,1.2842133,0.1891945,18.063025,267.82047,-10.78032
145.7833,-0.01559817,10.862903,56.182693,0,18.0,300.0,1.2895203,-0.012576102,18.057911,267.60364,-10.79697
145.7855,-0.097870559,10.891738,56.492695,0,18.0,300.0,1.2931279,-0.29376906,18.06348,267.36417,-10.81202
145.7877,-0.1528503,10.897297,56.802689,0,18.0,300.0,1.297744,-0.50279081,18.064362,267.12466,-10.828691
145.7899,-0.1436929,10.921644,57.112682,0,18.0,300.0,1.300873,-0.51456571,18.059204,266.88519,-10.844721
145.7921,-0.069558956,10.927094,57.42268,0,18.0,300.0,1.3054851,-0.30050236,18.057215,266.64572,-10.859809
145.7943,0.0329808,10.951499,57.535404,0,18.0,300.0,1.3077461,0.042198114,18.060707,266.36273,-10.876337
145.7965,0.094284728,10.95647,57.535404,0,18.0,300.0,1.3125666,0.33207509,18.058998,266.05481,-10.892363
145.7987,0.067955926,10.980282,57.535404,0,18.0,300.0,1.3153068,0.25142023,18.060209,265.74692,-10.909253
145.8009,0.010982399,10.99052,57.535404,0,18.0,300.0,1.321188,0.069111042,18.058849,265.43903,-10.92495
145.8031,-0.073995776,11.01847,57.570038,0,18.0,300.0,1.3244989,-0.19671522,18.05864,265.13251,-10.94091
145.8053,-0.14164288,11.025408,57.916359,0,18.0,300.0,1.3296304,-0.43594167,18.060858,264.83829,-10.956998
145.8075,-0.15428336,11.048812,58.262684,0,18.0,300.0,1.3322648,-0.52698272,18.060192,264.5441,-10.974018
145.8097,-0.09340971,11.056295,58.609001,0,18.0,300.0,1.3376271,-0.36517707,18.060083,264.24988,-10.990118
145.8119,-0.0053319223,11.078781,58.955326,0,18.0,300.0,1.339584,-0.090457745,18.058792,263.95569,-11.004932
145.8141,0.079640001,11.082166,59.106441,0,18.0,300.0,1.3442993,0.20806091,18.060257,263.65762,-11.021027
145.8163,0.095768906,11.105153,59.106441,0,18.0,300.0,1.3466916,0.31051776,18.056288,263.35657,-11.035354
145.8185,0.034301635,11.114959,59.106441,0,18.0,300.0,1.3526958,0.16103899,18.056551,263.05551,-11.051446
145.8207,-0.049913306,11.141767,59.106441,0,18.0,300.0,1.3557129,-0.066847198,18.056683,262.75446,-11.067702
145.8229,-0.11881815,11.148319,59.115166,0,18.0,300.0,1.3613573,-0.34136343,18.056732,262.45413,-11.08308
145.8251,-0.15086336,11.169646,59.434845,0,18.0,300.0,1.3634621,-0.48088053,18.055508,262.18045,-11.097775
145.8273,-0.12477115,11.180451,59.754532,0,18.0,300.0,1.3696847,-0.4075954,18.054419,261.90677,-11.114722
145.8295,-0.048612852,11.201475,60.074211,0,18.0,300.0,1.3716931,-0.21956348,18.053556,261.63309,-11.130924
145.8317,0.04400098,11.210551,60.393898,0,18.0,300.0,1.37754,0.10000648,18.055584,261.35941,-11.146173
145.8339,0.094560102,11.232191,60.556641,0,18.0,300.0,1.379827,0.28267545,18.051846,261.11261,-11.162711
145.8361,0.082565263,11.244487,60.556641,0,18.0,300.0,1.3865441,0.28057757,18.053127,260.89365,-11.177132
145.8383,-0.0048923879,11.266823,60.556641,0,18.0,300.0,1.3888049,0.032158826,18.052576,260.67471,-11.193532
145.8405,-0.10316355,11.274632,60.556641,0,18.0,300.0,1.3945373,-0.28355309,18.053841,260.45578,-11.21044
145.8427,-0.14668487,11.296906,60.556641,0,18.0,300.0,1.3971769,-0.44092038,18.051899,260.23682,-11.225848
145.8449,-0.14261676,11.312119,60.748516,0,18.0,300.0,1.4048253,-0.44973543,18.051462,260.05054,-11.242527
145.8471,-0.073965214,11.331517,60.949528,0,18.0,300.0,1.4064384,-0.27179635,18.052176,259.86581,-11.258234
145.8493,0.012333896,11.337622,61.150539,0,18.0,300.0,1.4113309,-0.014554188,18.050869,259.68106,-11.274335
145.8515,0.072848499,11.354625,61.351555,0,18.0,300.0,1.4130793,0.20249549,18.051493,259.49634,-11.289377
145.8537,0.10328165,11.368896,61.468506,0,18.0,300.0,1.4199905,0.31823626,18.048439,259.30875,-11.305226
145.8559,0.053005114,11.388354,61.468506,0,18.0,300.0,1.4220295,0.19372973,18.050594,259.11716,-11.32065
145.8581,-0.063014112,11.403082,61.468506,0,18.0,300.0,1.4290429,-0.14070752,18.044756,258.92557,-11.33666
145.8603,-0.14696808,11.41842,61.468506,0,18.0,300.0,1.4308087,-0.40512484,18.048279,258.73401,-11.350154
145.8625,-0.15602706,11.436995,61.468506,0,18.0,300.0,1.4390799,-0.4695769,18.047626,258.54242,-11.367463
146.7628,-0.041079018,11.554401,3.3723184e-11,0,18.0,1.621674e-10,1.4706954,-0.11647681,18.000479,149.56804,-11.483589
147.8628,-0.037374336,11.554433,3.4610437e-26,0,18.0,1.6196895e-25,1.4709084,-0.10875265,18.001295,72.86071,-11.483348
148.9628,-0.040369574,11.554914,3.5567758e-41,0,18.0,1.617715e-40,1.4711182,-0.12046216,17.999468,43.775738,-11.483289
150.0628,-0.039842546,11.555501,7.9874012e-44,0,18.0,1.4012985e-45,1.4714063,-0.11328401,18.001696,32.602577,-11.483475
151.1628,-0.04076276,11.555547,7.9874012e-44,0,18.0,1.4012985e-45,1.4715136,-0.12362549,17.9998,28.243,-11.483849
152.2628,-0.047110599,11.556066,7.9874012e-44,0,18.0,1.4012985e-45,1.4713112,-0.13489397,17.999908,26.630489,-11.48328
153.3628,-0.036644962,11.556289,7.9874012e-44,0,18.0,1.4012985e-45,1.4714719,-0.10384057,18.00021,25.984167,-11.483359
154.4628,-0.041280568,11.556642,7.9874012e-44,0,18.0,1.4012985e-45,1.4713773,-0.12340338,18.000288,25.736309,-11.48343
155.5628,-0.043103829,11.556953,7.9874012e-44,0,18.0,1.4012985e-45,1.4716625,-0.1255625,18.000704,25.597929,-11.483241
156.6628,-0.039964456,11.557525,7.9874012e-44,0,18.0,1.4012985e-45,1.4719088,-0.1172231,18.000557,25.534159,-11.483186
157.7628,-0.045871202,11.557865,7.9874012e-44,0,18.0,1.4012985e-45,1.4721352,-0.13602172,17.999834,25.607306,-11.483607
158.8628,-0.041953478,11.55785,7.9874012e-44,0,18.0,1.4012985e-45,1.4721338,-0.12268532,17.999903,25.467426,-11.483968
159.9628,-0.043092467,11.558449,7.9874012e-44,0,18.0,1.4012985e-45,1.4719836,-0.12605454,17.99955,25.435957,-11.483545
161.0628,-0.046451561,11.559118,7.9874012e-44,0,18.0,1.4012985e-45,1.4722787,-0.13578005,18.000448,25.413986,-11.483692
162.1628,-0.043737281,11.559102,7.9874012e-44,0,18.0,1.4012985e-45,1.4721501,-0.12555617,18.000664,25.410131,-11.483776
163.2628,-0.040793873,11.558911,7.9874012e-44,0,18.0,1.4012985e-45,1.4722425,-0.12310115,18.000196,25.326574,-11.483671
164.3628,-0.046989672,11.559139,7.9874012e-44,0,18.0,1.4012985e-45,1.4723579,-0.13618973,17.999613,25.318748,-11.483598
165.4628,-0.041725099,11.559633,7.9874012e-44,0,18.0,1.4012985e-45,1.4726602,-0.12119131,17.999598,25.290422,-11.48327
166.5628,-0.043143906,11.559195,7.9874012e-44,0,18.0,1.4012985e-45,1.4725451,-0.12936592,17.999702,25.259577,-11.483401
167.6628,-0.046123423,11.560284,7.9874012e-44,0,18.0,1.4012985e-45,1.472515,-0.1340387,17.999903,25.273659,-11.483251
168.7628,-0.039761659,11.560208,7.9874012e-44,0,18.0,1.4012985e-45,1.4725602,-0.11938636,18.000326,25.182451,-11.483397
169.8628,-0.04642899,11.560109,7.9874012e-44,0,18.0,1.4012985e-45,1.4724674,-0.13770044,17.999304,25.18614,-11.483254
170.9628,-0.043995343,11.560834,7.9874012e-44,0,18.0,1.4012985e-45,1.4728645,-0.12637879,17.999323,25.174866,-11.483395
172.0628,-0.045218434,11.5612,7.9874012e-44,0,18.0,1.4012985e-45,1.4730598,-0.13444389,17.999893,25.087236,-11.483328
173.1628,-0.048454106,11.561458,7.9874012e-44,0,18.0,1.4012985e-45,1.4731609,-0.13845973,18.000437,25.118755,-11.483963
174.2628,-0.046462573,11.561667,7.9874012e-44,0,18.0,1.4012985e-45,1.4732403,-0.13462467,18.000277,25.117332,-11.483403
175.3628,-0.04829447,11.5619,7.9874012e-44,0,18.0,1.4012985e-45,1.4729402,-0.1419459,18.00046,25.023222,-11.483537
176.4628,-0.0496489,11.561965,7.9874012e-44,0,18.0,1.4012985e-45,1.4730643,-0.14281708,17.999973,25.140335,-11.483598
177.5628,-0.041462351,11.562643,7.9874012e-44,0,18.0,1.4012985e-45,1.4732499,-0.12020037,17.999769,25.086983,-11.484171
178.6628,-0.047721975,11.562572,7.9874012e-44,0,18.0,1.4012985e-45,1.4734279,-0.14021362,18.000004,25.061914,-11.484045
179.7628,-0.049457453,11.562449,7.9874012e-44,0,18.0,1.4012985e-45,1.4734918,-0.14309925,17.998446,25.050816,-11.483692
180.8628,-0.045315545,11.563247,7.9874012e-44,0,18.0,1.4012985e-45,1.4735553,-0.13115478,17.999868,25.036732,-11.483889
181.9628,-0.045758225,11.563277,7.9874012e-44,0,18.0,1.4012985e-45,1.4736539,-0.13193974,17.999472,24.948757,-11.484075
183.0628,-0.048814192,11.563732,7.9874012e-44,0,18.0,1.4012985e-45,1.4734462,-0.1420868,18.000046,24.949381,-11.483615
184.1628,-0.05057938,11.563908,7.9874012e-44,0,18.0,1.4012985e-45,1.4736152,-0.1494457,18.000372,24.991024,-11.483475
185.2628,-0.048476588,11.563712,7.9874012e-44,0,18.0,1.4012985e-45,1.4736242,-0.1414974,18.000006,24.897713,-11.483587
186.3628,-0.051592298,11.563688,7.9874012e-44,0,18.0,1.4012985e-45,1.4738054,-0.14992386,17.99996,24.910061,-11.483443
187.4628,-0.051918712,11.564395,7.9874012e-44,0,18.0,1.4012985e-45,1.4741019,-0.15211263,17.999079,24.752365,-11.483381
187.6628,-0.057501696,11.564412,0.0,0,18.0,1.4012985e-45,1.4736698,-0.16814014,17.999496,0.0,-11.483425