File: examples/dan-msc-case-studies/CS3/data/01 raw data/baron_test_125.csv
Time(sec),Force(kN),Jaw(mm),PowAngle(deg),Power(W),Pram,PTemp,Strain,Stress(MPa),Stroke(mm),TC1(C),wedge(mm)
0.0,0.95503676,0.33483434,0.0,0,11.076097,0.0013279186,0.02255474,11.899788,11.07549,23.618204,-9.1257048
1.2,0.874075,-0.0042707282,0.0,0,11.076097,3.5159009,-0.00030517791,11.117846,11.075594,23.593721,-9.4946203
2.4,0.84058976,-0.0043898593,0.0,0,11.076097,7.1159005,-0.00029438504,10.71155,11.075538,23.564283,-9.491559
3.6,0.813959,-0.0048896773,0.0,0,11.076097,10.7159,-0.00031576789,10.366659,11.07676,23.590679,-9.4904881
4.8,0.79681498,-0.0051072543,0.0,0,11.076097,14.315904,-0.00033766363,10.159602,11.075345,23.524111,-9.4882278
6.0,0.780361,-0.005502197,0.0,0,11.076097,17.915907,-0.00034373513,9.9481163,11.0761,23.522327,-9.4857988
7.2,0.75871342,-0.005486663,0.0,0,11.076097,21.515907,-0.00035007918,9.6684055,11.07646,23.522381,-9.4833508
8.4,0.74685365,-0.0051967092,11.647393,0,11.076097,25.115906,-0.0003639269,9.5240297,11.075081,23.489029,-9.4804611
9.6,0.74620628,-0.0054402933,30.043465,0,11.076097,28.715906,-0.00038131303,9.5044641,11.076311,23.812176,-9.4791603
10.8,0.75094002,-0.0070939343,37.081436,0,11.076097,32.315903,-0.00047852719,9.5697012,11.075415,25.805071,-9.4773951
12.0,0.76437336,-0.0096460925,40.333057,0,11.076097,35.915901,-0.00063992979,9.7329416,11.076358,29.129074,-9.4752264
13.2,0.78234947,-0.013034223,42.38306,0,11.076097,39.515903,-0.00087609881,9.9668617,11.076709,32.950268,-9.4732523
14.4,0.78650409,-0.016156979,43.955154,0,11.076097,43.115906,-0.0010552474,10.027607,11.075411,36.84177,-9.4706068
15.6,0.79411131,-0.019635802,45.111401,0,11.076097,46.715908,-0.0012781103,10.126188,11.076415,40.878746,-9.4686594
16.8,0.798639,-0.02339145,45.629799,0,11.076097,50.315914,-0.0015651624,10.190946,11.076165,45.048801,-9.467001
18.0,0.8115992,-0.027152427,46.381706,0,11.076097,53.915916,-0.0018382641,10.358206,11.076867,49.196201,-9.4648829
19.2,0.81766248,-0.031325899,46.582035,0,11.076097,57.515919,-0.0020927046,10.431152,11.07615,53.462727,-9.4623394
20.4,0.82854551,-0.035129473,46.876884,0,11.076097,61.115917,-0.0023300475,10.564679,11.076375,57.62014,-9.4603138
21.6,0.8404426,-0.038869943,46.856709,0,11.076097,64.715927,-0.002589443,10.727579,11.076552,61.902504,-9.4582729
22.8,0.84277958,-0.042847887,47.05444,0,11.076097,68.315918,-0.0028372477,10.762615,11.076191,65.970001,-9.4560604
24.0,0.84596407,-0.046425339,46.959091,0,11.076097,71.915916,-0.0030688678,10.806028,11.076242,70.038361,-9.4540606
25.2,0.8515957,-0.050525878,46.864399,0,11.076097,75.515915,-0.0033748946,10.873765,11.076054,74.039543,-9.4520378
26.4,0.84969944,-0.055241827,46.587906,0,11.076097,79.115913,-0.0036967727,10.854085,11.077138,78.038391,-9.4496641
27.6,0.86461741,-0.057747878,46.583385,0,11.076097,82.715912,-0.0038505653,11.039968,11.076797,81.8405,-9.447546
28.8,0.8605082,-0.06105613,46.582035,0,11.076097,86.31591,-0.0040615783,11.002704,11.076144,85.602783,-9.4454336
30.0,0.86328351,-0.064114951,46.582043,0,11.076097,89.915924,-0.004267307,11.027094,11.0773,89.348381,-9.4436674
31.2,0.86103088,-0.067725718,46.801414,0,11.076097,93.515907,-0.0045172279,11.009768,11.075633,92.912605,-9.4415369
32.4,0.8787002,-0.070949867,47.054001,0,11.076097,97.115929,-0.0047038398,11.244341,11.076358,96.513565,-9.4390049
33.6,0.8687157,-0.07402119,47.082981,0,11.076097,100.71592,-0.0049095349,11.121688,11.077077,100.09312,-9.436923
34.8,0.87665325,-0.077001862,47.170013,0,11.076097,104.31592,-0.0051352107,11.227216,11.076637,103.72153,-9.4348383
36.0,0.8780728,-0.079917081,47.504883,0,11.076097,107.91592,-0.0053342041,11.247718,11.076181,107.28329,-9.4329309
37.2,0.89004177,-0.083889611,47.504921,0,11.076097,111.51593,-0.0055862023,11.407971,11.075512,110.87529,-9.4308586
38.4,0.88914281,-0.088799521,47.9487,0,11.076097,115.11593,-0.0058926186,11.372074,11.075415,114.45518,-9.4283743
39.6,0.88413185,-0.09173537,47.955318,0,11.076097,118.71593,-0.0060869544,11.33074,11.075618,118.07623,-9.4262962
40.8,0.89053708,-0.094318226,48.179241,0,11.076097,122.31593,-0.0062580262,11.411286,11.076203,121.66325,-9.424777
42.0,0.88838089,-0.097950652,48.383785,0,11.076097,125.91593,-0.0064861225,11.389411,11.075067,125.20201,-9.4227219
43.2,0.89352936,-0.1011961,48.539471,0,11.076097,129.51605,-0.0067292852,11.440719,11.07598,128.77747,-9.4204578
44.4,0.88896859,-0.10467586,48.915184,0,11.076097,133.11592,-0.0069671581,11.40678,11.075784,132.26331,-9.4181108
45.6,0.8986823,-0.10786363,49.216759,0,11.076097,136.71593,-0.0071901218,11.531071,11.075563,135.89789,-9.4163876
46.8,0.89647782,-0.11094131,49.23003,0,11.076097,140.31593,-0.0073640947,11.495821,11.07587,139.56532,-9.4145947
48.0,0.8958019,-0.11433616,49.614944,0,11.076097,143.91592,-0.0075865746,11.509037,11.075437,143.1299,-9.4120331
49.2,0.90079314,-0.1193989,49.636227,0,11.076097,147.51595,-0.0079425983,11.555761,11.076013,146.80092,-9.4102678
50.4,0.89840114,-0.12274816,49.636227,0,11.076097,151.11594,-0.0081232814,11.53392,11.075228,150.36588,-9.4079103
51.6,0.89316624,-0.12622243,49.98444,0,11.076097,154.71593,-0.0083606467,11.474117,11.075823,153.96173,-9.4060936
52.8,0.88658595,-0.12973842,50.042721,0,11.076097,158.31595,-0.008613416,11.395311,11.075553,157.59274,-9.4041481
54.0,0.89426315,-0.13330235,50.186531,0,11.076097,161.91594,-0.0088685518,11.502987,11.076075,161.1348,-9.401969
55.2,0.8992871,-0.13623568,50.662872,0,11.076097,165.51595,-0.009054441,11.561269,11.076054,164.56778,-9.3996878
56.4,0.9074108,-0.14012605,50.760899,0,11.076097,169.11595,-0.009287932,11.667856,11.075036,168.22737,-9.397893
57.6,0.90614724,-0.14556,51.01001,0,11.076097,172.71596,-0.009661613,11.639571,11.076435,171.7912,-9.39608
58.8,0.9019503,-0.14870746,51.13163,0,11.076097,176.31595,-0.0098529626,11.606387,11.075024,175.46017,-9.3937492
60.0,0.90703362,-0.15222849,51.372253,0,11.076097,179.91595,-0.010073064,11.658917,11.075893,179.00691,-9.3917999
61.2,0.90118647,-0.15606198,51.56982,0,11.076097,183.51595,-0.010331812,11.608441,11.076182,182.66228,-9.3891563
62.4,0.9158591,-0.15953229,51.707294,0,11.076097,187.11595,-0.010586696,11.796523,11.076579,186.22119,-9.3877487
63.6,0.90542781,-0.1627349,51.892128,0,11.076097,190.71596,-0.010806697,11.650457,11.07604,189.87764,-9.3856516
64.8,0.91110957,-0.16610885,51.932369,0,11.076097,194.31595,-0.011030642,11.719857,11.075959,193.54866,-9.3834505
66.0,0.9082405,-0.17246963,51.936344,0,11.076097,197.91595,-0.01142907,11.702312,11.07726,197.15149,-9.3809319
67.2,0.9116466,-0.17469089,52.283932,0,11.076097,201.51595,-0.011566136,11.740764,11.076383,200.78464,-9.3786373
68.4,0.90681142,-0.17891836,52.283936,0,11.076097,205.11595,-0.011852573,11.677045,11.075875,204.44547,-9.3771572
69.6,0.89576471,-0.18282272,52.286655,0,11.076097,208.71596,-0.012095081,11.543176,11.076649,208.04323,-9.3752365
70.8,0.90388763,-0.1860567,52.627655,0,11.076097,212.31595,-0.012307812,11.642064,11.076584,211.64769,-9.3732796
72.0,0.90573382,-0.18953654,52.72934,0,11.076097,215.91595,-0.012555346,11.681923,11.075418,215.20633,-9.3705482
73.2,0.91363633,-0.19255133,52.967602,0,11.076097,219.51596,-0.012768882,11.778336,11.076061,218.73987,-9.3686876
74.4,0.91133654,-0.19669884,52.97607,0,11.076097,223.11595,-0.013047889,11.751116,11.074979,222.36514,-9.3667154
75.6,0.92034084,-0.20217688,53.315693,0,11.076097,226.71596,-0.01339932,11.888512,11.075302,225.86734,-9.3649025
76.8,0.90274608,-0.20670231,53.316681,0,11.076097,230.31595,-0.013672313,11.649967,11.075849,229.54149,-9.3625631
78.0,0.90991586,-0.20864676,53.60733,0,11.076097,233.91595,-0.013811677,11.74599,11.075464,233.07553,-9.3602486
79.2,0.9096427,-0.21293348,53.657223,0,11.076097,237.51596,-0.014082044,11.746213,11.075826,236.76712,-9.3578663
80.4,0.91529453,-0.21639167,53.657234,0,11.076097,241.11595,-0.014291848,11.831057,11.075917,240.45741,-9.3564301
81.6,0.90194577,-0.22025964,53.972462,0,11.076097,244.71596,-0.014574886,11.651702,11.076465,243.99413,-9.354291
82.8,0.91135073,-0.22381349,53.975826,0,11.076097,248.31596,-0.014828736,11.77511,11.07499,247.53952,-9.352108
84.0,0.90992123,-0.22736627,54.047333,0,11.076097,251.91597,-0.015055271,11.771722,11.075997,251.2498,-9.3494911
85.2,0.91537064,-0.23085439,54.110176,0,11.076097,255.51596,-0.015271775,11.836211,11.076103,254.93626,-9.3478298
86.4,0.9179247,-0.2344611,54.285137,0,11.076097,259.11624,-0.015500097,11.877619,11.075846,258.57666,-9.3461361
87.6,0.91471487,-0.2380427,54.302017,0,11.076097,262.71597,-0.015749812,11.822397,11.076199,262.22617,-9.3437767
88.8,0.92229545,-0.24262053,54.266838,0,11.076097,266.31595,-0.016040767,11.941169,11.07587,265.90106,-9.3420067
90.0,0.91911227,-0.24857001,54.231598,0,11.076097,269.91595,-0.016415212,11.904677,11.075721,269.61859,-9.3394375
91.2,0.91633862,-0.25317577,54.305416,0,11.076097,273.51596,-0.016730353,11.859789,11.075805,273.1265,-9.337719
92.4,0.92244762,-0.25711259,54.608212,0,11.076097,277.11594,-0.017005723,11.955948,11.076481,276.65506,-9.3361864
93.6,0.92154908,-0.26109856,54.624023,0,11.076097,280.71597,-0.017288027,11.936012,11.076719,280.19312,-9.3337221
94.8,0.92329443,-0.26500672,54.694603,0,11.076097,284.31598,-0.017525902,11.967422,11.076421,283.74551,-9.3317194
96.0,0.9165861,-0.26925576,54.904041,0,11.076097,287.91599,-0.017781297,11.884921,11.07524,287.38687,-9.3293467
97.2,0.92191237,-0.27281162,54.718887,0,11.076097,291.51599,-0.018018235,11.964191,11.076053,291.13077,-9.3279533
98.4,0.92618221,-0.27661732,54.829235,0,11.076097,295.116,-0.018269479,12.016785,11.076534,294.78265,-9.3254023
99.6,0.9262979,-0.28008112,54.624046,0,11.076097,298.71597,-0.018484766,12.01452,11.075696,298.56229,-9.3230247
100.8,0.92096293,-0.28346336,54.672146,0,11.076097,302.31598,-0.018710567,11.954802,11.076474,302.14355,-9.321126
102.0,0.92296469,-0.28732064,54.625095,0,11.076097,305.91599,-0.01899302,11.981222,11.076203,305.81155,-9.3194513
103.2,0.91392314,-0.291015,54.722202,0,11.076097,309.51599,-0.019241955,11.861227,11.076428,309.37817,-9.3172388
104.4,0.93239087,-0.29422274,54.931442,0,11.076097,313.116,-0.019450549,12.103473,11.075601,312.86621,-9.3153162
105.6,0.92373961,-0.29780918,54.739365,0,11.076097,316.716,-0.019667476,12.004157,11.075598,316.63068,-9.3131742
106.8,0.92272115,-0.30081192,54.765709,0,11.076097,320.31601,-0.019856511,11.986957,11.074955,320.22299,-9.3113003
108.0,0.92911541,-0.30354723,54.931602,0,11.076097,323.91602,-0.020045159,12.077179,11.076562,323.72189,-9.3097744
109.2,0.93318027,-0.30680528,54.931637,0,11.076097,327.51599,-0.020235516,12.127199,11.077217,327.33932,-9.3069353
110.4,0.92767662,-0.3100048,54.928711,0,11.076097,331.11603,-0.020445429,12.050467,11.075064,330.96283,-9.3046808
111.6,0.92211771,-0.31321913,54.928722,0,11.076097,334.716,-0.02067472,11.986112,11.075871,334.60278,-9.3029051
112.8,0.92423564,-0.31658003,54.931637,0,11.076097,338.31604,-0.020907924,12.023161,11.076027,338.21289,-9.3013353
114.0,0.92022109,-0.32011509,55.097225,0,11.076097,341.91599,-0.021138065,11.978294,11.076208,341.62936,-9.2991352
115.2,0.91979772,-0.32365698,54.931644,0,11.076097,345.51599,-0.021346169,11.976224,11.076269,345.40009,-9.2968359
116.4,0.92835814,-0.32705939,54.939156,0,11.076097,349.116,-0.02155455,12.092401,11.076676,349.00739,-9.2945919
117.6,0.93572438,-0.33050403,55.218517,0,11.076097,352.716,-0.02179426,12.181485,11.076209,352.4747,-9.2933311
118.8,0.93115658,-0.33429918,55.239254,0,11.076097,356.31601,-0.022022473,12.13259,11.076019,355.98621,-9.2911243
120.0,0.93167555,-0.33747447,55.483273,0,11.076097,359.91602,-0.022222182,12.116714,11.075487,359.49292,-9.2892132
121.2,0.93258882,-0.34151432,55.517284,0,11.076097,363.51599,-0.022507202,12.1539,11.075785,363.14481,-9.2866774
122.4,0.9414795,-0.34511471,55.406475,0,11.076097,367.116,-0.022752246,12.275045,11.075913,366.88754,-9.2849264
123.6,0.92779076,-0.34886175,55.535824,0,11.076097,370.716,-0.023004649,12.095725,11.075503,370.37741,-9.2829542
124.8,0.9248535,-0.35257593,55.466667,0,11.076097,374.31598,-0.023234181,12.057349,11.075962,374.09949,-9.2812891
126.0,0.90512681,-0.35712099,55.535885,0,11.076097,377.91599,-0.02351084,11.820607,11.076086,377.59842,-9.2788448
127.2,0.92265922,-0.36029238,55.543606,0,11.076097,381.51602,-0.023734456,12.042164,11.07639,381.2247,-9.2767124
128.4,0.91914386,-0.36402696,55.825966,0,11.076097,385.116,-0.023970999,11.980809,11.076123,384.74997,-9.2742825
129.6,0.93675083,-0.36727419,55.81646,0,11.076097,388.716,-0.024161914,12.206373,11.075894,388.4155,-9.2726784
130.8,0.92019588,-0.37105176,55.840939,0,11.076097,392.31601,-0.024428567,12.010644,11.075097,392.02341,-9.2709122
132.0,0.92575717,-0.37446985,55.843506,0,11.076097,395.91602,-0.024670959,12.091928,11.075919,395.65869,-9.2690401
133.2,0.9169268,-0.37810189,55.843506,0,11.076097,399.51599,-0.024919711,11.973864,11.074869,399.22815,-9.2664042
134.4,0.072891548,-0.42415237,51.719963,0,11.076097,399.99893,-0.027907422,0.94789433,11.077068,403.95483,-9.2659769
135.6,0.064761214,-0.42483377,47.506954,0,11.076097,399.99893,-0.027920308,0.84799749,11.075818,406.50394,-9.2662191
136.8,0.054977555,-0.42478871,48.556957,0,11.076097,399.99893,-0.02791363,0.7300362,11.076077,404.49057,-9.2665091
138.0,0.058220066,-0.42299452,51.806183,0,11.076097,399.99893,-0.027810609,0.76432323,11.076679,400.97791,-9.2670183
139.2,0.042705525,-0.42250484,55.2229,0,11.076097,399.99893,-0.027760493,0.57924837,11.076389,397.41812,-9.2668581
140.4,0.042795245,-0.42217571,58.545589,0,11.076097,399.99893,-0.027735418,0.56881213,11.076492,394.13315,-9.2664261
141.6,0.035953779,-0.42233664,61.445789,0,11.076097,399.99893,-0.027761746,0.47366357,11.076771,391.34967,-9.2660656
142.8,0.040098205,-0.42178464,63.914669,0,11.076097,399.99893,-0.027742779,0.52447712,11.077223,389.10617,-9.266181
144.0,0.038610805,-0.42126372,66.017044,0,11.076097,399.99893,-0.027720133,0.47941801,11.076082,387.36166,-9.2666435
145.2,0.043779336,-0.42248574,68.025261,0,11.076097,399.99893,-0.027785107,0.58886468,11.076408,385.85632,-9.2667685
146.4,0.03728389,-0.42166999,69.590782,0,11.076097,399.99893,-0.027716739,0.48958308,11.075947,385.16641,-9.2662163
147.6,0.043191917,-0.42162433,70.598244,0,11.076097,399.99893,-0.027712472,0.57690114,11.076703,385.54694,-9.2658491
148.8,0.05559551,-0.42266971,70.984985,0,11.076097,399.99893,-0.027785702,0.73121613,11.0767,387.50818,-9.2657061
150.0,0.071629286,-0.42502469,69.987259,0,11.076097,399.99893,-0.027918674,0.94235855,11.076737,392.06769,-9.2663746
151.2,0.077980988,-0.43053806,67.522964,0,11.076097,399.99893,-0.028273763,1.0159504,11.076288,398.65253,-9.2664738
152.4,0.073936723,-0.43458623,64.215935,0,11.076097,399.99893,-0.028560417,0.96512979,11.075848,404.89182,-9.2662668
153.6,0.075268611,-0.43780336,60.815014,0,11.076097,399.99893,-0.028787494,0.9799546,11.075982,409.21701,-9.2654982
154.8,0.066113017,-0.43772537,58.36314,0,11.076097,399.99893,-0.028791662,0.87333471,11.076223,410.63556,-9.2654276
156.0,0.067504786,-0.43577844,57.273697,0,11.076097,399.99893,-0.028641609,0.89251244,11.075349,409.98087,-9.2663155
157.2,0.050078612,-0.43528438,57.615318,0,11.076097,399.99893,-0.028594622,0.66643339,11.076722,407.87201,-9.2664318
158.4,0.042929649,-0.43544281,58.808174,0,11.076097,399.99893,-0.028613944,0.56262392,11.07611,405.00516,-9.2661314
159.6,0.03022933,-0.43515685,60.646393,0,11.076097,399.99893,-0.028594209,0.39185157,11.076062,401.55933,-9.2657871
160.8,0.030212171,-0.43491143,62.837742,0,11.076097,399.99893,-0.028562453,0.3968592,11.076043,398.08838,-9.2652044
162.0,0.024422286,-0.43366382,65.081619,0,11.076097,399.99893,-0.028481415,0.30921343,11.076599,394.76813,-9.265871
163.2,0.022901805,-0.4333083,67.202827,0,11.076097,399.99893,-0.028479399,0.31318036,11.075522,391.64413,-9.2661009
164.4,0.018478896,-0.43264368,69.25174,0,11.076097,399.99893,-0.028452417,0.22225027,11.076225,388.99255,-9.2663364
165.6,0.01338765,-0.43367654,71.197884,0,11.076097,399.99893,-0.028522408,0.18951802,11.07665,386.62756,-9.2655745
166.8,0.011785855,-0.43342698,72.913406,0,11.076097,399.99893,-0.028494613,0.14023288,11.075625,384.82852,-9.2651072
168.0,0.016341083,-0.43229404,74.433113,0,11.076097,399.99893,-0.028408343,0.22806314,11.075618,383.4895,-9.2656221
169.2,0.023368314,-0.43174788,75.527893,0,11.076097,399.99893,-0.028381109,0.2903285,11.076839,383.34152,-9.2663784
170.4,0.030035941,-0.43215626,76.145767,0,11.076097,399.99893,-0.028393073,0.391296,11.075863,384.64264,-9.2663422
171.6,0.05561037,-0.43383798,75.757431,0,11.076097,399.99893,-0.028491758,0.73331976,11.076015,388.69858,-9.2659416
172.8,0.067534715,-0.44180685,73.098221,0,11.076097,399.99893,-0.029018307,0.89174545,11.075654,398.22092,-9.2656288
174.0,0.083758652,-0.45089209,68.248978,0,11.076097,399.99893,-0.029622434,1.0952672,11.075848,409.85257,-9.2650394
175.2,0.082594767,-0.45564935,62.257545,0,11.076097,399.99893,-0.029946459,1.0689594,11.074614,418.53192,-9.2661524
176.4,0.074722335,-0.45551243,56.551754,0,11.076097,399.99893,-0.029930647,0.98768371,11.076609,422.56241,-9.2664328
177.6,0.045035467,-0.45582145,53.383526,0,11.076097,399.99893,-0.029927405,0.58478725,11.076903,421.72391,-9.266448
178.6169,0.11105016,0.058747355,53.31665,0,11.076099,65.880898,0.00389489,1.4027081,11.074401,418.38098,-9.2655249
178.6193,0.12728556,0.059168398,53.31665,0,11.076099,2.8482205e-15,0.0038133443,1.5833471,11.076721,418.3873,-9.2653122
178.6217,0.11302718,0.062653236,53.31665,0,11.076099,1.2312851e-31,0.0038948185,1.3004557,11.081067,418.3945,-9.2665644
178.6241,0.14516559,0.063128136,53.31665,0,11.076099,0.0,0.0041195382,1.7793155,11.077675,418.4017,-9.2657824
178.6265,0.11874606,0.060370285,53.31665,0,11.076099,0.0,0.0042506475,1.5349905,11.075427,418.40894,-9.2654829
178.6289,0.13229319,0.059017573,43.186428,0,11.076099,0.0,0.0041761696,1.6577815,11.074737,418.40472,-9.2649469
178.6313,0.2020532,0.059458945,30.390432,0,11.076099,0.0,0.0040515261,2.468106,11.081688,418.39749,-9.2661362
178.6337,0.1301568,0.062514998,17.594437,0,11.076099,0.0,0.0039354912,1.6748337,11.073956,418.39029,-9.2657042
178.6361,0.13938574,0.062541671,4.79844,0,11.076099,0.0,0.0040840949,1.7965608,11.076392,418.38309,-9.2649641
178.6385,0.1358297,0.061192501,0.0,0,11.076099,0.0,0.0042280038,1.7446008,11.074894,418.35785,-9.265172
178.6409,0.13993225,0.061222989,0.0,0,11.076099,0.0,0.0043379553,1.8566296,11.075348,418.32178,-9.2656994
178.6433,0.1582536,0.062348906,0.0,0,11.076099,0.0,0.0042205211,1.9671671,11.076248,418.28574,-9.265358
178.6457,0.15905257,0.066995315,0.0,0,11.076099,0.0,0.0042420672,2.0208688,11.075115,418.24969,-9.265337
178.6481,0.12347601,0.068536557,0.0,0,11.076099,0.0,0.0043693054,1.6128643,11.07657,418.22687,-9.2653685
178.6505,0.14876828,0.065933347,0.0,0,11.076099,0.0,0.0045118714,1.8907592,11.074977,418.21967,-9.2654505
178.6529,0.1554942,0.062037967,0.0,0,11.076099,0.0,0.0044092783,1.9909114,11.076958,418.21243,-9.2658892
178.6553,0.16291884,0.061810877,0.0,0,11.076099,0.0,0.0041482351,2.069247,11.076534,418.20523,-9.2652102
178.6577,0.15948175,0.064506046,0.0,0,11.076099,0.0,0.0041391579,2.037061,11.076849,418.20013,-9.2656031
178.6601,0.14636414,0.065408982,0.0,0,11.076099,0.0,0.0042687976,1.9313273,11.076324,418.20013,-9.2656336
178.6625,0.16189653,0.066497818,0.0,0,11.076099,0.0,0.0044945539,2.0123754,11.071151,418.20013,-9.2655668
178.6649,0.16628824,0.064545251,0.0,0,11.076099,0.0,0.004570358,2.1657317,11.075147,418.20013,-9.2667284
178.6673,0.17289273,0.06578169,0.0,0,11.006544,0.0,0.0045158789,2.1872277,11.074365,418.19382,-9.2663174
178.6697,0.14248779,0.068356588,0.0,0,10.645576,0.0,0.0043970626,1.8149889,11.068236,418.14337,-9.2658844
178.6721,0.16051763,0.071336098,0.0,0,10.284603,0.0,0.0044587459,2.0571041,11.06086,418.0929,-9.2667036
178.6745,0.20306846,0.07138139,0.0,0,9.9236288,0.0,0.0046641841,2.5550222,10.942534,418.04242,-9.2659044
178.6769,0.16868393,0.06859979,0.0,0,9.5626554,0.0,0.0047916858,2.0876765,10.666353,417.99197,-9.2660055
178.6793,0.20163356,0.065411098,0.0,0,9.2092905,0.0,0.0046081492,2.5085456,10.28849,418.26627,-9.2655029
178.6817,4.6893988,0.30356744,0.0,0,8.8581219,0.0,0.019551851,57.830204,9.8685207,418.55466,-9.2617617
178.6841,6.1837997,0.74358809,0.0,0,8.518857,0.0,0.050281718,74.970634,9.3910828,418.84305,-9.2600727
178.6865,6.63271,1.1783168,0.0,0,8.1848736,0.0,0.081277952,77.587486,8.9382343,419.13144,-9.261404
178.6889,6.7394357,1.5892435,0.0,0,7.8607755,0.0,0.11169395,76.52845,8.540493,418.8833,-9.2609491
178.6913,6.9976783,1.9259424,0.0,0,7.543015,0.0,0.13727511,77.479477,8.1874924,418.49396,-9.2612944
178.6937,7.1869802,2.2534783,0.0,0,7.2334356,0.0,0.16236182,77.764763,7.8430071,418.10461,-9.2622814
178.6961,7.3737268,2.5768178,0.0,0,6.9312277,0.0,0.18769942,77.758377,7.5207081,417.71527,-9.2610445
178.6985,7.5411305,2.8695607,0.0,0,6.6355219,0.0,0.21170683,77.659737,7.2263107,416.81641,-9.2610769
178.7009,7.7304907,3.1515901,0.0,0,6.3480015,0.0,0.2356983,77.757401,6.942914,415.61185,-9.2607765
178.7033,7.8940392,3.4293723,0.0,0,6.065536,0.0,0.2596719,77.523819,6.649044,414.40729,-9.2608957
178.7057,8.1357651,3.7161429,0.0,0,5.792079,0.0,0.28433755,77.875328,6.3596492,413.2027,-9.2610359
178.7081,8.3372965,3.9967864,0.0,0,5.5222936,0.0,0.30904248,77.917107,6.0859871,412.19949,-9.2624702
178.7105,8.5219202,4.2772746,0.0,0,5.2621331,0.0,0.33504611,77.61692,5.8048496,411.4342,-9.2622395
178.7129,8.7297306,4.5512547,0.0,0,5.0044241,0.0,0.36131015,77.423988,5.5250664,410.66895,-9.2608929
178.7153,8.9414387,4.8185019,0.0,0,4.7569842,0.0,0.38752267,77.248451,5.252573,409.90366,-9.260849
178.7177,9.1721001,5.0841932,0.0,0,4.5108657,0.0,0.4136591,77.197853,4.9881916,408.69324,-9.2593241
178.7201,9.4086456,5.3494434,0.0,0,4.2754698,0.0,0.44029084,77.142288,4.7282753,406.40176,-9.2599154
178.7225,9.6020994,5.6087141,0.0,0,4.0404716,0.0,0.46714434,76.629601,4.4752121,404.11029,-9.2605972
178.7249,9.8479738,5.8550024,0.0,0,3.8165054,0.0,0.49441484,76.4496,4.2238646,401.81882,-9.2601156
178.7273,10.118465,6.0919642,0.0,0,3.5926332,0.0,0.52131021,76.461906,3.9829581,399.42682,-9.2596712
178.7297,10.396858,6.3214359,0.0,0,3.3790326,0.0,0.54719394,76.566551,3.7514658,396.33121,-9.2597761
178.7321,10.641374,6.5441675,0.0,0,3.1660566,0.0,0.57249272,76.441612,3.5254879,393.23563,-9.2584381
178.7345,10.925397,6.7646403,0.0,0,2.9619906,0.0,0.59859169,76.433578,3.3129463,390.14001,-9.2606745
178.7369,11.242358,6.9785781,0.0,0,2.7593822,0.0,0.62543803,76.600029,3.0954955,387.0444,-9.2604818
178.7393,11.605714,7.1818233,0.0,0,2.5644474,0.0,0.65179038,76.933876,2.8886573,386.78363,-9.259902
178.7417,11.956381,7.3837719,0.0,0,2.3717272,0.0,0.67790788,77.290512,2.6874449,386.64606,-9.2595797
178.7441,12.320703,7.5851269,0.0,0,2.1855242,0.0,0.70399511,77.578888,2.4917006,386.50851,-9.2591839
178.7465,12.705379,7.784936,0.0,0,2.0022123,0.0,0.73039371,77.904625,2.2987077,386.37097,-9.2598982
178.7489,13.161261,7.9733305,0.0,0,1.8243403,0.0,0.75732768,78.526733,2.1081781,386.82947,-9.2594156
178.7513,13.660748,8.156456,0.0,0,1.6499563,0.0,0.78478765,79.286087,1.9189719,387.44479,-9.2575932
178.7537,14.121049,8.3316498,0.0,0,1.4800413,0.0,0.81111372,79.805687,1.7401414,388.06012,-9.2586632
178.7561,14.64381,8.5110989,0.0,0,1.3141534,0.0,0.83749306,80.62043,1.5652263,388.67545,-9.2584658
178.7585,15.192729,8.6851683,0.0,0,1.1518564,0.0,0.86384749,81.485046,1.3871728,387.07095,-9.2572603
178.7609,15.81925,8.8585939,0.0,0,0.99408036,0.0,0.89197052,82.51236,1.2188141,384.13458,-9.2569237
178.7633,16.476631,9.0235434,0.0,0,0.83908135,0.0,0.92020541,83.510399,1.0509396,381.19824,-9.2554283
178.7657,17.109041,9.1812801,0.0,0,0.68903339,0.0,0.94745922,84.391968,0.88839346,378.26187,-9.2569532
178.7681,17.796988,9.3357201,0.0,0,0.54098594,0.0,0.97368294,85.536171,0.72863603,376.21649,-9.2562027
178.7705,18.560343,9.4929867,0.0,0,0.39818591,0.0,1.0005599,86.823654,0.57662362,375.22406,-9.2549839
178.7729,16.68137,9.5449648,0.0,0,0.25673628,0.0,1.010343,77.460953,0.47061655,374.23163,-9.2572823
178.7753,15.04331,9.5574045,0.0,0,0.12094415,0.0,1.0139831,69.555817,0.43040663,373.2392,-9.2582054
178.7777,14.367801,9.5575132,0.0,0,-0.014479235,0.0,1.0150059,66.388062,0.40438512,373.31665,-9.2597513
178.7801,13.998733,9.5629272,0.0,0,-0.14691243,0.0,1.0156155,64.546074,0.37434775,375.9924,-9.258584
178.7825,14.017222,9.5713167,0.0,0,-0.27934441,0.0,1.0156045,64.619965,0.33015233,378.66815,-9.2590084
178.7849,14.359501,9.5803146,0.0,0,-0.41177642,0.0,1.0171323,66.061165,0.26352516,381.3439,-9.2591667
178.7873,14.492531,9.5855789,0.0,0,-0.54420841,0.0,1.0186719,66.623077,0.19785994,383.89612,-9.2592163
178.7897,14.462103,9.5855637,0.0,0,-0.67664039,0.0,1.0201383,66.400322,0.13780008,385.58353,-9.2596617
178.7921,14.296454,9.5910721,0.0,0,-0.80907238,0.0,1.020794,65.607948,0.080192842,387.27094,-9.2601118
178.7945,14.064912,9.6006622,0.0,0,-0.94150436,0.0,1.0212697,64.518494,0.042766143,388.95831,-9.2605877
178.7969,13.760314,9.6104202,0.0,0,-1.0739365,0.0,1.0219769,63.055935,0.010330502,390.64572,-9.2599802
178.7993,13.317271,9.6121836,0.0,0,-0.76691425,400.0,1.0232552,60.959461,-0.0022280719,391.89514,-9.2614222
178.8017,12.772077,9.6052446,0.0,0,-0.3084279,400.0,1.0236179,58.499405,0.0025322721,393.12555,-9.2615395
178.8041,12.312403,9.6008501,0.0,0,0.15005845,400.0,1.0231361,56.402935,0.0087486682,394.35593,-9.2615547
178.8065,11.976979,9.6019669,0.0,0,0.60854483,400.0,1.0218853,54.879421,0.012517574,395.5863,-9.2616386
178.8089,11.750663,9.6086493,0.0,0,1.0670311,400.0,1.0222266,53.842487,0.010327373,396.66693,-9.2623739
178.8113,11.3563,9.6070919,0.0,0,1.5255175,400.0,1.0224307,52.058708,0.017301094,397.70813,-9.2633352
178.8137,10.180984,9.6014442,0.0,0,1.9840039,400.0,1.0225044,46.733299,0.073960334,398.74936,-9.2637434
178.8161,7.6617403,9.5857935,0.0,0,2.4424908,400.0,1.0203775,35.435883,0.19186056,399.79059,-9.2640142
178.8185,3.8553314,9.5674181,0.0,0,2.9009769,400.0,1.0160488,18.112,0.41362628,400.70929,-9.2683392
178.8209,0.30314785,9.4693613,0.0,0,3.3594635,400.0,0.99692547,1.4458652,0.83884436,401.5545,-9.2711143
178.8233,-0.27858889,9.4258852,0.0,0,3.8179498,400.0,0.98883688,-1.1001323,1.5559373,402.39972,-9.2708883
178.8257,-0.035847981,9.3953896,0.0,0,4.2764363,400.0,0.98502767,-0.23151457,2.377969,403.24493,-9.2718945
178.8281,-0.051064275,9.4062796,0.0,0,4.7349229,400.0,0.98760927,-0.23954231,3.0949447,404.07028,-9.2718697
178.8305,0.07031256,9.4527025,0.0,0,5.1934094,400.0,0.99503118,0.34216771,3.6345623,404.87216,-9.2705927
178.8329,-0.086679019,9.5384855,0.0,0,5.651895,400.0,1.0091974,-0.41235641,4.0667906,405.67401,-9.271307
178.8353,0.10238422,9.5269384,0.0,0,6.1103816,400.0,1.0075977,0.37224248,4.4876313,406.47589,-9.2702532
178.8377,0.08604221,9.5441647,0.0,0,6.5688682,400.0,1.0111518,0.34340715,4.9066544,407.25879,-9.2693224
178.8401,0.19801298,9.5389547,0.0,0,7.0273547,400.0,1.011749,0.91681457,5.3286853,407.99567,-9.2686529
178.8425,0.14412259,9.5375462,0.0,0,7.4858413,400.0,1.0109658,0.65540832,5.7851086,408.73251,-9.2685413
178.8449,0.22940899,9.5378122,0.0,0,7.9443278,400.0,1.0095887,1.0630125,6.2673717,409.46936,-9.2684984
178.8473,0.14793251,9.5480242,0.0,0,8.4028139,400.0,1.0106659,0.70334351,6.7584176,410.18811,-9.2671824
178.8497,0.17772953,9.5481548,0.0,0,8.8612995,400.0,1.0115095,0.7885617,7.234849,410.78024,-9.2672186
178.8521,0.19725387,9.5437145,0.0,0,9.3197861,400.0,1.0123255,0.9516803,7.7141452,411.37238,-9.2672243
178.8545,0.10078411,9.5386381,0.0,0,9.7782726,400.0,1.0115777,0.51981461,8.182683,411.96451,-9.2669764
178.8569,0.15279023,9.5379734,0.0,0,10.236759,400.0,1.0101804,0.69409311,8.6566668,412.55664,-9.2675695
178.8593,0.20735404,9.5393629,0.0,0,10.695246,400.0,1.0095855,0.99796307,9.1346865,413.06522,-9.2655134
178.8617,0.14515205,9.5417681,0.0,0,11.153732,400.0,1.0102903,0.67157519,9.5989046,413.57016,-9.2647696
178.8641,0.18933535,9.5397768,0.0,0,11.612218,400.0,1.0111984,0.86696357,10.068902,414.0751,-9.2653532
178.8665,0.17192736,9.5359354,0.0,0,12.070705,400.0,1.0110931,0.81150258,10.539643,414.58005,-9.2662134
178.8689,0.078889593,9.540843,0.0,0,12.529191,400.0,1.0109533,0.3206552,11.001612,415.02771,-9.2652311
178.8713,0.21883287,9.5449457,0.0,0,12.987678,400.0,1.0103427,1.0068581,11.466602,415.46033,-9.265666
178.8737,0.10186187,9.547574,0.0,0,13.446164,400.0,1.0108951,0.48377118,11.92083,415.89294,-9.2655096
178.8761,0.14759442,9.5423613,0.0,0,13.904651,400.0,1.0118604,0.66397196,12.382862,416.32553,-9.2643366
178.8785,0.10945341,9.5388165,0.0,0,14.363137,400.0,1.0118208,0.48429978,12.858854,416.70407,-9.2661343
178.8809,0.18126892,9.5349455,0.0,0,14.821624,400.0,1.0099252,0.84983987,13.339977,417.05014,-9.265358
178.8833,0.094429739,9.5423651,0.0,0,15.28011,400.0,1.0101103,0.43994397,13.815041,417.39624,-9.2642221
178.8857,0.16076218,9.5407667,0.0,0,15.738596,400.0,1.0100137,0.70547736,14.292247,417.74231,-9.2644777
178.8881,0.11066747,9.5413551,0.0,0,16.197083,400.0,1.011,0.47722715,14.766338,418.0752,-9.2645445
178.8905,0.11344131,9.5369921,0.0,0,16.655569,400.0,1.0112584,0.51501656,15.221907,418.39243,-9.2644234
178.8929,0.15782571,9.5371132,0.0,0,17.114056,400.0,1.0107313,0.72910821,15.68072,418.70966,-9.2645302
178.8953,0.10865406,9.538538,0.0,0,17.572542,400.0,1.0095659,0.52878082,16.132,419.02692,-9.263052
178.8977,0.072396271,9.5473528,0.0,0,17.999401,400.0,1.0105875,0.3289783,16.587494,419.32944,-9.2631006
178.9001,0.12535964,9.544241,0.0,0,18.0,400.0,1.0111347,0.62665135,17.047964,419.59619,-9.2631683
178.9025,0.07459075,9.5391712,0.0,0,18.0,400.0,1.0116063,0.32751599,17.478382,419.86298,-9.2635965
178.9049,0.17080255,9.5357103,0.0,0,18.0,400.0,1.0108404,0.81783456,17.862057,420.12973,-9.2649231
178.9073,0.23402148,9.5402451,0.0,0,18.0,400.0,1.0102632,1.0065669,18.18346,420.39111,-9.2674704
178.9097,0.31093651,9.5445538,0.0,0,18.0,400.0,1.0104264,1.4650824,18.405148,420.61459,-9.269433
178.9121,0.32361633,9.54564,0.0,0,18.0,400.0,1.0111655,1.4785608,18.51495,420.8381,-9.2730284
178.9145,0.37794003,9.543067,0.0,0,18.0,400.0,1.0120072,1.7384889,18.492085,421.06161,-9.2796183
178.9169,0.33635366,9.5399771,0.0,0,18.0,400.0,1.0116102,1.5898604,18.373589,421.28513,-9.2887287
178.9193,0.35017782,9.5423069,0.0,0,18.0,400.0,1.0107769,1.5685011,18.239555,421.44644,-9.3009024
178.9217,0.35006398,9.5496426,0.0,0,18.0,400.0,1.010987,1.6485213,18.125004,421.60507,-9.3169737
178.9241,0.33514789,9.5487146,0.0,0,18.0,400.0,1.0113978,1.5144919,18.060286,421.7637,-9.3361292
178.9265,0.36073071,9.5406914,0.0,0,18.0,400.0,1.0114324,1.6706262,18.045448,421.92233,-9.3559694
178.9289,0.34810176,9.5363159,0.0,0,18.0,400.0,1.0112725,1.6131016,18.04805,422.0524,-9.3761683
178.9313,0.33246487,9.5369797,0.0,0,18.0,400.0,1.0100346,1.5739417,18.055538,422.17499,-9.396553
178.9337,0.31802455,9.5376606,0.0,0,18.0,400.0,1.0093056,1.5328965,18.082731,422.29755,-9.4178667
178.9361,0.3561759,9.5399685,0.0,0,18.0,400.0,1.0098993,1.6423538,18.104227,422.4201,-9.4370356
178.9385,0.36506602,9.5373917,0.0,0,18.0,400.0,1.0104142,1.6429342,18.121519,422.54266,-9.4528723
178.9409,0.3739315,9.5359049,0.0,0,18.0,400.0,1.0109179,1.7212979,18.131823,422.66525,-9.4706059
178.9433,0.34225231,9.5375929,0.0,0,18.0,400.0,1.0106469,1.6073661,18.14155,422.78784,-9.4885139
178.9457,0.38070679,9.5411558,0.0,0,18.0,400.0,1.0098932,1.7505014,18.13798,422.9104,-9.5050812
178.9481,0.38216218,9.54568,0.0,0,18.0,400.0,1.0102719,1.7747149,18.136703,423.01978,-9.5233879
178.9505,0.37996647,9.5429096,0.0,0,18.0,400.0,1.0111947,1.8133854,18.135853,423.11349,-9.5417404
178.9529,0.36962554,9.539361,0.0,0,18.0,400.0,1.0116698,1.7382947,18.127718,423.20721,-9.5587301
178.9553,0.38077992,9.5369301,0.0,0,18.0,400.0,1.0108931,1.7291385,18.125807,423.30093,-9.5761395
178.9577,0.38626856,9.5393009,0.0,0,18.0,400.0,1.0098388,1.7590035,18.12738,423.39676,-9.5938044
178.9601,0.40019619,9.5403442,0.0,0,18.0,400.0,1.0096747,1.8666229,18.12595,423.49768,-9.6113634
178.9625,0.39301407,9.543232,0.0,0,18.0,400.0,1.0109172,1.833519,18.118813,423.59863,-9.6283255
178.9649,0.37867147,9.5369053,0.0,0,18.0,400.0,1.0108218,1.7606288,18.115669,423.69958,-9.6463928
178.9673,0.38689879,9.534276,0.0,0,18.0,400.0,1.0106995,1.8108048,18.1101,423.79962,-9.6648178
178.9697,0.39338166,9.5371103,0.0,0,18.0,400.0,1.0098591,1.8301749,18.109066,423.89334,-9.6825781
178.9721,0.41430348,9.5460396,0.0,0,18.0,400.0,1.0101871,1.893591,18.108486,423.98709,-9.6993151
178.9745,0.39535582,9.5499792,0.0,0,18.0,400.0,1.0116506,1.8243464,18.103697,424.08084,-9.7172489
178.9769,0.39085513,9.5434504,0.0,0,18.0,400.0,1.0119052,1.7990555,18.107241,424.17456,-9.7359352
178.9793,0.39169088,9.5349169,0.0,0,18.0,400.0,1.0111018,1.8365648,18.105337,424.24066,-9.7532816
178.9817,0.40890062,9.5354967,0.0,0,18.0,400.0,1.0098572,1.8890716,18.101799,424.30554,-9.7705622
178.9841,0.399306,9.5401573,0.0,0,18.0,400.0,1.0095775,1.8941805,18.104935,424.37042,-9.7898293
178.9865,0.38199076,9.5432625,0.0,0,18.0,400.0,1.010566,1.7719026,18.105135,424.4353,-9.8078213
178.9889,0.39114329,9.5397177,0.0,0,18.0,400.0,1.0109683,1.8011169,18.100683,424.49448,-9.8255539
178.9913,0.40491915,9.5355158,0.0,0,18.0,400.0,1.0109714,1.8985671,18.100471,424.55215,-9.8426218
178.9937,0.41421252,9.5348072,0.0,0,18.0,400.0,1.010151,1.9216723,18.104303,424.60983,-9.8608742
178.9961,0.40553343,9.5423527,0.0,0,18.0,400.0,1.010013,1.8841035,18.100855,424.66751,-9.8769808
178.9985,0.40388027,9.5466328,0.0,0,18.0,400.0,1.0105295,1.8853507,18.093229,424.70718,-9.8941755
179.0009,0.40240625,9.5435047,0.0,0,18.0,400.0,1.011533,1.8644435,18.093828,424.73602,-9.9118824
179.0033,0.41092944,9.5366144,0.0,0,18.0,400.0,1.0111288,1.9286803,18.094107,424.76486,-9.9297457
179.0057,0.43124336,9.5357838,0.0,0,18.0,400.0,1.0102996,2.0006914,18.091618,424.7937,-9.9480886
179.0081,0.40723985,9.5395508,0.0,0,18.0,400.0,1.0098647,1.9025139,18.091967,424.80933,-9.9678631
179.0105,0.41823763,9.5412645,0.0,0,18.0,400.0,1.0097637,1.9028285,18.08894,424.80933,-9.9856415
179.0129,0.41945851,9.5391798,0.0,0,18.0,400.0,1.0104998,1.9321698,18.091576,424.80933,-10.001794
179.0153,0.44320232,9.5374126,0.0,0,18.0,400.0,1.011173,2.0414152,18.09152,424.80933,-10.020254
179.0177,0.44371164,9.5376997,0.0,0,18.0,400.0,1.0110888,2.0453668,18.091129,424.82193,-10.036979
179.0201,0.4295485,9.5402441,0.0,0,18.0,400.0,1.0100982,1.985593,18.089294,424.8652,-10.055374
179.0225,0.4330785,9.542449,0.0,0,18.0,400.0,1.0098101,2.0356638,18.087572,424.90848,-10.074019
179.0249,0.44458875,9.545825,0.0,0,18.0,400.0,1.0110793,2.02458,18.08676,424.95175,-10.091271
179.0273,0.46351096,9.5425234,0.0,0,18.0,400.0,1.0120085,2.1518931,18.090471,424.99231,-10.109159
179.0297,0.43345496,9.5376339,0.0,0,18.0,400.0,1.0113053,2.0005307,18.090506,425.01392,-10.12703
179.0321,0.44836381,9.5371637,0.0,0,18.0,400.0,1.0099862,2.0774117,18.088945,425.03555,-10.144545
179.0345,0.44406724,9.5383139,0.0,0,18.0,400.0,1.0093815,2.0462024,18.085844,425.05719,-10.161623
179.0369,0.46964774,9.5404797,0.0,0,18.0,400.0,1.0100365,2.1841335,18.085848,425.0788,-10.180445
179.0393,0.47499815,9.5406065,0.0,0,18.0,400.0,1.0111839,2.2020013,18.085024,425.06589,-10.19688
179.0417,0.43921196,9.5359201,0.0,0,18.0,400.0,1.0111325,2.0484648,18.081245,425.05148,-10.21521
179.0441,0.45697081,9.5361452,0.0,0,18.0,400.0,1.010273,2.0969262,18.077692,425.03705,-10.233853
179.0465,0.4590866,9.5422249,0.0,0,18.0,400.0,1.0099043,2.1810091,18.083525,425.02261,-10.250349
179.0489,0.47727513,9.5458918,0.0,0,18.0,400.0,1.0105537,2.2306409,18.082127,425.01962,-10.268624
179.0513,0.45918217,9.5462551,0.0,0,18.0,400.0,1.0120221,2.1327069,18.076038,425.01962,-10.287786
179.0537,0.45958322,9.5381804,0.0,0,18.0,400.0,1.0114329,2.0972555,18.07922,425.01962,-10.303848
179.0561,0.45443147,9.5349255,0.0,0,18.0,400.0,1.0101132,2.1005335,18.081806,425.01962,-10.32206
179.0585,0.4926129,9.5386868,0.0,0,18.0,400.0,1.0095251,2.2753687,18.074097,425.0061,-10.339393
179.0609,0.48261434,9.5425577,0.0,0,18.0,400.0,1.0100956,2.2250061,18.076342,424.98447,-10.357523
179.0633,0.44750258,9.5417843,0.0,0,18.0,400.0,1.0109037,2.0716767,18.077684,424.96286,-10.374811
179.0657,0.4518733,9.5352945,0.0,0,18.0,400.0,1.0107113,2.0991716,18.072741,424.94122,-10.392888
179.0681,0.48196205,9.5334854,0.0,0,18.0,400.0,1.010147,2.2275665,18.073927,424.91959,-10.409968
179.0705,0.50118458,9.5392075,0.0,0,18.0,400.0,1.0097504,2.321491,18.075991,424.89795,-10.429017
179.0729,0.47455522,9.5461216,0.0,0,18.0,400.0,1.0101506,2.2142,18.073429,424.87634,-10.447707
179.0753,0.46883085,9.5434618,0.0,0,18.0,400.0,1.0108476,2.1724083,18.073483,424.85471,-10.464312
179.0777,0.46419451,9.5373125,0.0,0,18.0,400.0,1.0111284,2.1199906,18.073427,424.83096,-10.480839
179.0801,0.50495541,9.5348444,0.0,0,18.0,400.0,1.0107517,2.3206551,18.072393,424.80212,-10.498664
179.0825,0.49257728,9.5379372,0.0,0,18.0,400.0,1.0100032,2.3126557,18.073517,424.77328,-10.517543
179.0849,0.47586852,9.5444851,0.0,0,18.0,400.0,1.0104731,2.1967492,18.07346,424.74445,-10.536596
179.0873,0.47359756,9.54142,0.0,0,18.0,400.0,1.0102613,2.2494249,18.072319,424.71561,-10.553327
179.0897,0.49765658,9.5380507,0.0,0,18.0,400.0,1.0108531,2.2783139,18.073021,424.68677,-10.570676
179.0921,0.52143788,9.535346,0.0,0,18.0,400.0,1.010916,2.4084601,18.069118,424.65793,-10.589052
179.0945,0.49515897,9.5372353,0.0,0,18.0,400.0,1.0100915,2.3152997,18.06987,424.62906,-10.60804
179.0969,0.48765314,9.5412741,0.0,0,18.0,400.0,1.0098109,2.2647657,18.067099,424.60022,-10.623147
179.0993,0.49552032,9.5449219,0.0,0,18.0,400.0,1.0106286,2.2951093,18.070568,424.57138,-10.640867
179.1017,0.52302349,9.5411873,0.0,0,18.0,400.0,1.0112616,2.411778,18.066349,424.54257,-10.659386
179.1041,0.53194112,9.5340767,0.0,0,18.0,400.0,1.0107616,2.4704068,18.064177,424.51373,-10.677043
179.1065,0.48927477,9.5354233,0.0,0,18.0,400.0,1.010069,2.2986772,18.068338,424.48489,-10.694695
179.1089,0.49393693,9.539156,0.0,0,18.0,400.0,1.0096823,2.292269,18.066257,424.45605,-10.712202
179.1113,0.51560724,9.541151,0.0,0,18.0,400.0,1.0099109,2.339112,18.064423,424.42722,-10.729783
179.1137,0.54436803,9.5393829,0.0,0,18.0,400.0,1.0106419,2.5152316,18.062418,424.39838,-10.747037
179.1161,0.53218186,9.5353737,0.0,0,18.0,400.0,1.0110883,2.4795942,18.065525,424.36951,-10.764999
179.1185,0.50106829,9.5355082,0.0,0,18.0,400.0,1.0104473,2.295208,18.063995,424.34067,-10.782869
179.1209,0.49964714,9.539155,0.0,0,18.0,400.0,1.0096506,2.3153894,18.056368,424.31183,-10.800618
179.1233,0.53363132,9.5455694,0.0,0,18.0,400.0,1.0101701,2.4520566,18.061985,424.28299,-10.817364
179.1257,0.54480475,9.5430441,0.0,0,18.0,400.0,1.0109656,2.5535567,18.058811,424.25415,-10.835622
179.1281,0.49998003,9.5380497,0.0,0,18.0,400.0,1.0114665,2.3491971,18.060665,424.22531,-10.85428
179.1305,0.50584579,9.5352201,0.0,0,18.0,400.0,1.0106075,2.3676445,18.062313,424.19647,-10.871432
179.1329,0.51317894,9.5373478,0.0,0,18.0,400.0,1.009663,2.3728955,18.056778,424.16763,-10.887305
179.1353,0.56296396,9.5417347,0.0,0,18.0,400.0,1.0098553,2.6134582,18.055202,424.13879,-10.905457
179.1377,0.54145777,9.5413408,0.0,0,18.0,400.0,1.0103983,2.5161743,18.054693,424.10577,-10.926157
179.1401,0.52254969,9.5388441,0.0,0,18.0,400.0,1.0111748,2.3941741,18.05633,424.0625,-10.944166
179.1425,0.50050527,9.5332022,0.0,0,18.0,400.0,1.010492,2.3599045,18.055716,424.01923,-10.960877
179.1449,0.55721539,9.5340004,0.0,0,18.0,400.0,1.0093951,2.5656304,18.055763,423.97595,-10.97808
179.1473,0.56323624,9.5426626,0.0,0,18.0,400.0,1.0097725,2.5711269,18.055571,423.93179,-10.996005
179.1497,0.52574748,9.5447397,0.0,0,18.0,400.0,1.0106362,2.4920878,18.054668,423.88135,-11.014078
179.1521,0.52784503,9.5413446,0.0,0,18.0,400.0,1.0114971,2.4436061,18.055504,423.83087,-11.031519
179.1545,0.53316003,9.5335627,0.0,0,18.0,400.0,1.0107622,2.4521177,18.053047,423.7804,-11.049228
179.1569,0.58135748,9.5356255,0.0,0,18.0,400.0,1.0098832,2.6819859,18.054531,423.72995,-11.066422
179.1593,0.569516,9.5412931,0.0,0,18.0,400.0,1.0099905,2.6421471,18.055054,423.71402,-11.083683
179.1617,0.53674901,9.5431604,0.0,0,18.0,400.0,1.0102836,2.4277108,18.050602,423.69958,-11.100288
179.1641,0.54439712,9.539422,0.0,0,18.0,400.0,1.0108303,2.4830015,18.054926,423.68515,-11.118512
179.1665,0.5641166,9.5344105,0.0,0,18.0,400.0,1.0106416,2.5892732,18.053633,423.67072,-11.137074
179.1689,0.58137161,9.5358582,0.0,0,18.0,400.0,1.0104346,2.7099857,18.054441,423.61636,-11.155183
179.1713,0.55000269,9.5416193,0.0,0,18.0,400.0,1.010039,2.5661542,18.051279,423.55148,-11.172875
179.1737,0.54757196,9.5449438,0.0,0,18.0,400.0,1.0101607,2.5320225,18.053442,423.48657,-11.191086
179.1761,0.54916066,9.542429,0.0,0,18.0,400.0,1.0110401,2.5044475,18.050833,423.42169,-11.208594
179.1785,0.60131735,9.5367689,0.0,0,18.0,400.0,1.0112474,2.7435131,18.048206,423.34329,-11.227753
179.1809,0.5801574,9.5355511,0.0,0,18.0,400.0,1.0105191,2.6976235,18.046947,423.25677,-11.24515
179.1833,0.54495704,9.5391283,0.0,0,18.0,400.0,1.0099561,2.5586536,18.052685,423.17026,-11.263622
179.1857,0.55252987,9.5409451,0.0,0,18.0,400.0,1.0099149,2.5724471,18.04995,423.08374,-11.280436
179.1881,0.58308351,9.5402479,0.0,0,18.0,400.0,1.0104839,2.6658583,18.047445,423.01703,-11.297889
179.1905,0.60356009,9.5381384,0.0,0,18.0,400.0,1.0110792,2.7870927,18.047417,422.97379,-11.314823
179.1929,0.56961089,9.536191,0.0,0,18.0,400.0,1.0108831,2.6780648,18.046682,422.93051,-11.33484
179.1953,0.54854715,9.5371799,0.0,0,18.0,400.0,1.0097086,2.5447745,18.051668,422.88727,-11.35109
179.2974,0.57807398,9.5383444,0.0,0,18.0,17.344156,1.0104002,2.6785586,18.036739,419.24646,-11.469575
180.4974,0.62139767,9.5507355,0.0,0,18.0,7.5886285e-16,1.012599,2.8711166,17.999722,390.68491,-11.481746
181.6974,0.65903652,9.5585394,0.0,0,18.0,3.280552e-32,1.0140822,3.0431006,17.999981,377.76425,-11.482175
182.8974,0.65573078,9.5664921,0.0,0,18.0,1.4012985e-45,1.0154802,3.0237377,17.999565,366.67236,-11.482763
184.0974,0.66227448,9.5739126,0.0,0,18.0,1.4012985e-45,1.0167688,3.054481,17.999809,356.35254,-11.48243
185.2974,0.67205161,9.5808153,0.0,0,18.0,1.4012985e-45,1.0180291,3.0930164,18.000099,346.28415,-11.482182
186.4974,0.68144333,9.5867682,0.0,0,18.0,1.4012985e-45,1.0191934,3.1357236,18.000092,336.80252,-11.48185
187.6974,0.69153374,9.5928545,0.0,0,18.0,1.4012985e-45,1.0203754,3.1728415,18.000278,327.03574,-11.483
188.8974,0.67364031,9.5996847,0.0,0,18.0,1.4012985e-45,1.0216274,3.0893793,17.999908,317.88815,-11.482409
190.0974,0.69267857,9.6051855,0.0,0,18.0,1.4012985e-45,1.022583,3.1723983,18.000347,308.95523,-11.481709
191.2974,0.68832928,9.6110058,0.0,0,18.0,1.4012985e-45,1.0237234,3.1482105,17.999371,300.16373,-11.481782
192.4974,0.70867151,9.6163721,0.0,0,18.0,1.4012985e-45,1.0247501,3.2419803,18.000376,291.65756,-11.482185
193.6974,0.69914502,9.6215773,0.0,0,18.0,1.4012985e-45,1.0256857,3.1924386,18.000128,283.35159,-11.482581
194.8974,0.72419161,9.6269741,0.0,0,18.0,1.4012985e-45,1.026602,3.3054006,17.999659,275.55698,-11.483251
196.0974,0.71443254,9.6328011,0.0,0,18.0,1.4012985e-45,1.0276748,3.2537754,17.999849,267.6868,-11.482982
197.2974,0.72355676,9.637063,0.0,0,18.0,1.4012985e-45,1.0285428,3.2992046,18.000978,259.96942,-11.482538
198.4974,0.71556568,9.6420326,0.0,0,18.0,1.4012985e-45,1.0295149,3.2462683,17.999157,252.645,-11.482093
199.6974,0.72821742,9.6468601,0.0,0,18.0,1.4012985e-45,1.0303406,3.3104026,18.000671,245.80859,-11.481821
200.8974,0.72325599,9.6513224,0.0,0,18.0,1.4012985e-45,1.0312063,3.280175,18.000179,238.99309,-11.481712
202.0974,0.73473316,9.6563835,0.0,0,18.0,1.4012985e-45,1.032228,3.3401058,17.998779,232.25269,-11.481667
203.2974,0.75500071,9.6608791,0.0,0,18.0,1.4012985e-45,1.0330606,3.4190381,18.000195,225.80556,-11.482447
204.4974,0.74497002,9.6652966,0.0,0,18.0,1.4012985e-45,1.0337851,3.3741782,18.000343,219.5699,-11.483112
205.6974,0.76353043,9.6699982,0.0,0,18.0,1.4012985e-45,1.0346287,3.4495482,17.999895,213.6031,-11.483211
206.8974,0.75206578,9.6740608,0.0,0,18.0,1.4012985e-45,1.0353931,3.4015555,18.000387,207.6868,-11.483334
208.0974,0.75427663,9.677989,0.0,0,18.0,1.4012985e-45,1.0362281,3.4079957,17.999979,202.02859,-11.483697
209.2974,0.74921072,9.6816998,0.0,0,18.0,1.4012985e-45,1.0369388,3.3855064,17.999823,196.57957,-11.483437
210.4974,0.76082373,9.6850281,0.0,0,18.0,1.4012985e-45,1.037509,3.435997,17.999556,191.30908,-11.483111
211.6974,0.75973153,9.6897173,0.0,0,18.0,1.4012985e-45,1.0384383,3.4237022,17.999565,186.24232,-11.482902
212.8974,0.76843113,9.6926546,0.0,0,18.0,1.4012985e-45,1.0390368,3.4657362,18.000036,181.32079,-11.482811
214.0974,0.76595247,9.6963472,0.0,0,18.0,1.4012985e-45,1.039696,3.4493361,18.000387,176.4888,-11.482595
215.2974,0.78133541,9.7001047,0.0,0,18.0,1.4012985e-45,1.040339,3.5163245,17.999475,171.87891,-11.482226
216.4974,0.78111887,9.7034473,0.0,0,18.0,1.4012985e-45,1.0409011,3.5099084,17.999083,167.42847,-11.482355
217.6974,0.80103791,9.706871,0.0,0,18.0,1.4012985e-45,1.041577,3.6065278,17.999277,163.07468,-11.483369
218.8974,0.79945374,9.7091274,0.0,0,18.0,1.4012985e-45,1.0421102,3.5841305,18.000481,158.99899,-11.48361
220.0974,0.78904176,9.71311,0.0,0,18.0,1.4012985e-45,1.0428536,3.5436206,18.000555,155.0791,-11.483195
221.2974,0.7957989,9.7150812,0.0,0,18.0,1.4012985e-45,1.0431734,3.5668797,18.000221,151.04294,-11.48261
222.4974,0.7938199,9.7186766,0.0,0,18.0,1.4012985e-45,1.0438646,3.5590806,17.999529,147.12083,-11.482154
223.6974,0.80473822,9.7210999,0.0,0,18.0,1.4012985e-45,1.0444372,3.5998561,17.999182,143.31671,-11.482969
224.8974,0.80194396,9.7239513,0.0,0,18.0,1.4012985e-45,1.0449537,3.592299,17.999977,139.7959,-11.483372
226.0974,0.80729967,9.7262573,0.0,0,18.0,1.4012985e-45,1.0453043,3.6137407,18.000422,136.26668,-11.483284
227.2974,0.78727043,9.7289181,0.0,0,18.0,1.4012985e-45,1.0457286,3.5206461,17.999973,132.88121,-11.483433
228.4974,0.80383807,9.7314491,0.0,0,18.0,1.4012985e-45,1.0462154,3.59762,17.999899,129.53632,-11.482929
229.6974,0.79822737,9.7337017,0.0,0,18.0,1.4012985e-45,1.0467227,3.5630133,17.999561,126.45617,-11.482692
230.8974,0.8188194,9.736536,0.0,0,18.0,1.4012985e-45,1.0472953,3.6589551,18.000412,123.34013,-11.483659
232.0974,0.79825675,9.7387819,0.0,0,18.0,1.4012985e-45,1.0476893,3.5648403,18.000109,120.36857,-11.483401
233.2974,0.81590962,9.7406235,0.0,0,18.0,1.4012985e-45,1.0480027,3.647759,17.999773,117.42353,-11.48359
234.4974,0.81602514,9.7431231,0.0,0,18.0,1.4012985e-45,1.0485164,3.6371655,18.000643,114.5519,-11.483796
235.6974,0.81751168,9.7445374,0.0,0,18.0,1.4012985e-45,1.0488586,3.6547961,18.000477,111.90281,-11.484142
236.8974,0.81623423,9.7469273,0.0,0,18.0,1.4012985e-45,1.0492915,3.633399,17.999474,109.30334,-11.483996
238.0974,0.80775076,9.7490511,0.0,0,18.0,1.4012985e-45,1.0496103,3.6081228,18.000179,106.81544,-11.483895
239.1974,0.80595267,9.750515,0.0,0,18.0,1.4012985e-45,1.0499802,3.585942,18.000315,104.41631,-11.483597