File: examples/dan-msc-case-studies/CS3/data/01 raw data/baron_test_024.csv
Time(sec),Force(kN),Jaw(mm),PowAngle(deg),Power(W),Pram,PTemp,Strain,Stress(MPa),Stroke(mm),TC1(C),wedge(mm)
0.0,1.0519155,0.44589663,0.0,0,10.594783,0.0012213017,0.030175149,12.992855,10.595537,26.801964,-9.1228113
2.2,0.94034624,0.0022097453,0.0,0,10.594783,6.5158739,0.00015305808,11.967407,10.594239,26.63216,-9.4922009
4.4,0.89978743,0.0020701746,0.0,0,10.594783,13.115873,0.00013520937,11.450301,10.59573,26.670546,-9.4889832
6.6,0.87620682,0.0019064978,0.0,0,10.594783,19.715878,0.00011551539,11.150686,10.59481,26.524157,-9.4848289
8.8,0.86031336,0.0023486943,0.0,0,10.594783,26.315876,0.00016057174,10.949642,10.595468,26.547886,-9.4802456
11.0,0.85727453,0.0027171294,32.451427,0,10.594783,32.915886,0.00018941981,10.914444,10.593559,26.540762,-9.4767294
13.2,0.86217654,0.0010348191,47.762051,0,10.594783,39.515884,4.997824e-05,10.983848,10.594586,28.750147,-9.4727659
15.4,0.89076269,-0.0049007805,54.920815,0,10.594783,46.115883,-0.00031641385,11.364403,10.59434,35.340557,-9.4689703
17.6,0.90652782,-0.012736117,57.807602,0,10.594783,52.715881,-0.00084372924,11.547344,10.594491,45.05032,-9.4648266
19.8,0.93094403,-0.020885507,57.53677,0,10.594783,59.315876,-0.0013943956,11.858099,10.59527,56.583569,-9.460494
22.0,0.94632936,-0.027629232,54.948929,0,10.594783,65.915878,-0.0018547365,12.087953,10.594413,67.790436,-9.4565887
24.2,0.95029157,-0.033295974,51.028542,0,10.594783,72.515884,-0.0022157202,12.138002,10.594596,77.244499,-9.4532127
26.4,0.92209524,-0.037814301,47.075108,0,10.594783,79.115875,-0.0024954469,11.768836,10.594807,84.222641,-9.4493294
28.6,0.89686549,-0.040208902,45.615238,0,10.594783,85.715874,-0.0026888289,11.443704,10.595195,88.680786,-9.4448195
30.8,0.89387137,-0.042314578,47.504105,0,10.594783,92.315865,-0.0028232485,11.416697,10.595433,92.020958,-9.4412041
33.0,0.88167179,-0.0455557,51.195591,0,10.594783,98.915871,-0.0030262482,11.268632,10.595108,95.710358,-9.4370146
35.2,0.91630685,-0.050214972,54.911411,0,10.594783,105.51589,-0.0033370007,11.710458,10.595125,100.59676,-9.4329681
37.4,0.92920643,-0.055411857,56.986057,0,10.594783,112.11588,-0.0036992643,11.861648,10.594828,107.56303,-9.4294243
39.6,0.9458636,-0.061582845,57.810051,0,10.594783,118.7159,-0.0040858616,12.097326,10.594157,115.99506,-9.4258041
41.8,0.96274823,-0.067969777,57.524162,0,10.594783,125.3159,-0.0045075971,12.317897,10.595086,124.65443,-9.4219627
44.0,0.95684725,-0.073894076,56.446777,0,10.594783,131.91588,-0.004911507,12.2509,10.594248,132.78964,-9.4179611
46.2,0.95672792,-0.079191551,55.540295,0,10.594783,138.51588,-0.0052732592,12.239654,10.594934,139.8799,-9.4139614
48.4,0.96210456,-0.083834484,55.239262,0,10.594783,145.11588,-0.0055671958,12.326305,10.594604,146.05432,-9.409955
50.6,0.967426,-0.088482067,55.535885,0,10.594783,151.71588,-0.0058701546,12.381983,10.5951,151.67529,-9.4065924
52.8,0.97758025,-0.092764176,56.47303,0,10.594783,158.31589,-0.0061657778,12.547785,10.59563,157.20535,-9.4025993
55.0,0.9690538,-0.09821704,57.809265,0,10.594783,164.91589,-0.0065392037,12.432203,10.595629,162.94879,-9.3993177
57.2,0.9722771,-0.10391948,58.836166,0,10.594783,171.5159,-0.0068963701,12.472026,10.594735,169.41574,-9.3949823
59.4,0.99133265,-0.11077896,59.257595,0,10.594783,178.11589,-0.0073477952,12.689587,10.594256,176.6228,-9.3913364
61.6,0.99500555,-0.11627984,59.6008,0,10.594783,184.71588,-0.0077309278,12.774238,10.595247,183.72678,-9.3876753
63.8,0.99881065,-0.12304232,59.563759,0,10.594783,191.31589,-0.008171034,12.824459,10.595116,190.97226,-9.3835888
66.0,0.98817158,-0.12848841,59.600826,0,10.594783,197.91591,-0.0085226214,12.695296,10.595345,197.71873,-9.3798895
68.2,0.9890998,-0.13399146,59.827614,0,10.594783,204.5159,-0.0088814301,12.700484,10.594424,204.09865,-9.3758497
70.4,1.0026033,-0.13950285,60.084225,0,10.594783,211.11589,-0.0092611797,12.877849,10.595556,210.39912,-9.3720694
72.6,1.0051458,-0.1449433,60.763584,0,10.594783,217.71588,-0.0096244477,12.934812,10.593951,216.53256,-9.3679504
74.8,1.006286,-0.15047994,61.237789,0,10.594783,224.31589,-0.0099773975,12.956367,10.594995,222.92412,-9.3645229
77.0,1.0033762,-0.15645902,61.907955,0,10.594783,230.91589,-0.010360424,12.912432,10.595358,229.40793,-9.3611565
79.2,1.011659,-0.16227572,62.116692,0,10.594783,237.51588,-0.010760608,12.992297,10.59509,236.58861,-9.3570728
81.4,1.0178242,-0.16836803,62.116604,0,10.594783,244.11589,-0.011177623,13.089781,10.595474,243.84732,-9.3536777
83.6,1.0210481,-0.17442702,62.099167,0,10.594783,250.7159,-0.011553558,13.158231,10.595075,250.60097,-9.3495808
85.8,1.0163866,-0.18154323,62.086002,0,10.594783,257.31616,-0.012019004,13.093872,10.595447,257.25977,-9.3461742
88.0,1.0125885,-0.18686612,62.116692,0,10.594783,263.91589,-0.01237748,13.044003,10.593929,263.78848,-9.342392
90.2,1.0231692,-0.19223045,62.335949,0,10.594783,270.51587,-0.012744473,13.188269,10.59466,270.07742,-9.3387756
92.4,1.029549,-0.1986777,62.706505,0,10.594783,277.11584,-0.013152543,13.278766,10.593909,276.36801,-9.3349323
94.6,1.0235879,-0.20413058,62.962639,0,10.594783,283.71585,-0.013518139,13.211866,10.593779,282.8826,-9.3311768
96.8,1.0194647,-0.21079417,63.171383,0,10.594783,290.31592,-0.013931577,13.158542,10.595634,289.67261,-9.3273878
99.0,1.0180086,-0.2161738,63.369137,0,10.594783,296.91589,-0.014323723,13.157763,10.59549,296.31409,-9.3234301
101.2,1.0309759,-0.22403288,63.577873,0,10.594783,303.51593,-0.014840276,13.308264,10.59436,302.94055,-9.3196468
103.4,1.0180081,-0.22910954,63.83419,0,10.594783,310.11591,-0.015146925,13.147271,10.594606,309.40225,-9.3162518
105.6,1.0217972,-0.23514821,64.171135,0,10.594783,316.71588,-0.01554434,13.210506,10.595716,315.79767,-9.3124037
107.8,1.0196307,-0.24164492,64.555656,0,10.594783,323.31589,-0.01598187,13.20552,10.595342,322.37619,-9.308567
110.0,1.0286988,-0.24865752,64.677078,0,10.594783,329.91589,-0.016462784,13.311557,10.595452,329.37784,-9.3051519
112.2,1.020515,-0.25471362,64.692757,0,10.594783,336.5159,-0.016823992,13.206928,10.595473,336.31326,-9.3012915
114.4,1.0203712,-0.26078534,64.742432,0,10.594783,343.11588,-0.017235843,13.225399,10.595646,342.83771,-9.2974997
116.6,1.0217859,-0.26650563,64.903061,0,10.594783,349.71591,-0.017594285,13.254211,10.594557,349.46326,-9.2936773
118.8,1.0233701,-0.27241796,64.929192,0,10.594783,356.31592,-0.018020228,13.264355,10.59497,356.00394,-9.2900858
121.0,1.031846,-0.27985701,65.115959,0,10.594783,362.91592,-0.018490599,13.382256,10.594587,362.44119,-9.2864017
123.2,1.02307,-0.28520793,65.409264,0,10.594783,369.5159,-0.018829001,13.26554,10.595168,368.79318,-9.2825346
125.4,1.0287573,-0.29116529,65.665276,0,10.594783,376.11588,-0.019208975,13.357267,10.594474,375.39182,-9.2788496
127.6,1.034693,-0.29824525,65.87516,0,10.594783,382.71588,-0.019691588,13.436007,10.595413,381.95078,-9.2755175
129.8,1.0138761,-0.30403155,66.086288,0,10.594783,389.31589,-0.020081911,13.184443,10.594559,388.59995,-9.271596
132.0,1.0289448,-0.31077796,66.192619,0,10.594783,395.91586,-0.020499675,13.375357,10.594408,395.43509,-9.2679415
134.2,1.0278774,-0.31663761,66.368401,0,10.594783,402.5159,-0.020894054,13.366106,10.59458,402.11896,-9.2637959
136.4,1.02573,-0.3237626,66.368401,0,10.594783,409.11594,-0.021334529,13.343901,10.596285,408.86115,-9.2603617
138.6,1.0251536,-0.33004397,66.368401,0,10.594783,415.71594,-0.021775123,13.347103,10.59472,415.58514,-9.2568827
140.8,1.012076,-0.33534473,66.368401,0,10.594783,422.31592,-0.02212506,13.189856,10.595211,422.3071,-9.2526522
143.0,1.0328187,-0.34270278,66.368401,0,10.594783,428.91589,-0.022579286,13.455866,10.596274,428.90594,-9.2491598
145.2,1.018463,-0.34791532,66.368416,0,10.594783,435.5159,-0.022922512,13.268254,10.595131,435.38242,-9.2455435
147.4,1.0373797,-0.35316285,66.53791,0,10.594783,442.11588,-0.02326547,13.53654,10.594522,441.86508,-9.2419357
149.6,1.0360171,-0.36060795,66.550865,0,10.594783,448.71588,-0.023769146,13.513063,10.594889,448.43872,-9.2386169
151.8,1.0232475,-0.36349097,64.206314,0,10.594783,449.9989,-0.023946736,13.334773,10.594478,454.73633,-9.2374401
154.0,1.0096846,-0.36420992,60.097298,0,10.594783,449.9989,-0.02398329,13.166117,10.594263,458.46451,-9.2372837
156.2,0.98197162,-0.36347118,55.852757,0,10.594783,449.9989,-0.023930971,12.804242,10.595148,458.77509,-9.2371931
158.4,0.79652107,-0.36210772,53.316669,0,10.594783,449.9989,-0.023855558,10.390643,10.594888,456.14835,-9.2369461
160.6,0.59136915,-0.35953367,54.028797,0,10.594783,449.9989,-0.023701081,7.7126551,10.594585,451.59909,-9.2369499
162.8,0.52346623,-0.35776761,56.854095,0,10.594783,449.9989,-0.023562422,6.8255768,10.594859,447.52042,-9.2372761
165.0,0.52384025,-0.35717651,59.83963,0,10.594783,449.9989,-0.023529669,6.8165956,10.595452,445.14023,-9.2371349
167.2,0.53414649,-0.35948017,61.907818,0,10.594783,449.9989,-0.023671329,6.9571891,10.594481,444.87189,-9.2367229
169.4,0.52306831,-0.36090732,63.171013,0,10.594783,449.9989,-0.023791708,6.8179822,10.594884,446.10074,-9.2371416
171.6,0.52010071,-0.36454701,63.369137,0,10.594783,449.9989,-0.024019782,6.7798681,10.594356,447.93817,-9.236784
173.8,0.52571183,-0.36630055,63.069592,0,10.594783,449.9989,-0.024115451,6.8581572,10.594595,449.77396,-9.236825
176.0,0.53028363,-0.36833853,62.325047,0,10.594783,449.9989,-0.024257267,6.9307785,10.594136,451.19946,-9.2364779
178.2,0.53159237,-0.37057152,61.238514,0,10.594783,449.9989,-0.024408177,6.9288788,10.594898,452.10577,-9.2367973
180.4,0.51984787,-0.37110072,60.315624,0,10.594783,449.9989,-0.024452677,6.786613,10.596189,452.16956,-9.2365932
182.6,0.51808566,-0.37105662,59.753521,0,10.594783,449.9989,-0.024429088,6.7544875,10.594898,451.7428,-9.2365217
184.8,0.49684432,-0.370545,59.600838,0,10.594783,449.9989,-0.024392789,6.4827957,10.594984,450.94296,-9.2368231
187.0,0.49281365,-0.37022334,59.842213,0,10.594783,449.9989,-0.024366148,6.4308968,10.594782,450.07202,-9.2364883
189.2,0.49856156,-0.37014368,60.314934,0,10.594783,449.9989,-0.024395704,6.4997196,10.595592,449.24725,-9.2364035
191.4,0.51555699,-0.37107041,60.787346,0,10.594783,449.9989,-0.024449112,6.7296,10.595267,449.08215,-9.2363491
193.6,0.52261621,-0.37295339,61.143627,0,10.594783,449.9989,-0.024550568,6.8188939,10.595404,449.08463,-9.2361908
195.2809,0.52435619,0.012452356,4.2861991,0,10.5948,0.0060070525,0.00066312408,6.5971909,10.596883,449.45212,-9.2362137
195.2853,0.50710356,0.016103463,0.0,0,10.5948,5.9923976e-33,0.000877154,6.4160104,10.596486,449.40091,-9.2359686
195.2897,0.50060564,0.011458512,0.0,0,10.5948,0.0,0.00060806132,6.3784804,10.594425,449.33502,-9.2372866
195.2941,0.50258702,0.016826186,0.0,0,10.5948,0.0,0.00084348349,6.3720622,10.5903,449.2916,-9.2353573
195.2985,0.51503879,0.012885903,0.0,0,10.5948,0.0,0.00069148379,6.6094031,10.596542,449.26526,-9.2355118
195.3029,0.50645393,0.016645296,0.0,0,10.5948,0.0,0.00090917537,6.4481845,10.592039,449.25449,-9.234724
195.3073,0.49281284,0.013011623,0.0,0,10.5948,0.0,0.00076110539,6.2741418,10.597102,449.28082,-9.2360258
195.3117,0.49346346,0.016162923,0.0,0,10.5948,0.0,0.00095397898,6.3003712,10.594943,449.30597,-9.2370777
195.3161,0.50499004,0.013712625,0.0,0,10.5948,0.0,0.00088529009,6.4636292,10.595903,449.27963,-9.2351799
195.3205,0.49435586,0.015274577,0.0,0,10.5948,0.0,0.00098648109,6.3195629,10.593718,449.2533,-9.2358103
195.3249,0.48265111,0.012214376,0.0,0,10.5948,0.0,0.00086964009,6.1558695,10.593427,449.22696,-9.2361851
195.3293,0.47762939,0.013571061,0.0,0,10.5948,0.0,0.001048472,6.0338526,10.595434,449.20059,-9.2352762
195.3337,0.48788697,0.011460239,0.0,0,10.542863,0.0,0.00087638025,6.2415314,10.594533,449.1994,-9.2352295
195.3381,0.49379656,0.012287374,0.0,0,10.476863,0.0,0.0010280857,6.3039708,10.59095,449.22574,-9.2349033
195.3425,0.47672799,0.01199112,0.0,0,10.410863,0.0,0.00093846093,6.0744624,10.562158,449.2413,-9.2355423
195.3469,0.47454736,0.011661668,0.0,0,10.344863,0.0,0.0010543242,6.0033503,10.484325,449.21497,-9.237299
195.3513,0.48392802,0.011503776,0.0,0,10.278863,0.0,0.00096670835,6.2286239,10.371324,449.18863,-9.2344637
195.3557,0.49290708,0.010406419,0.0,0,10.212863,0.0,0.00096363667,6.2615185,10.283752,449.18683,-9.2365274
195.3601,0.46974409,0.010818983,0.0,0,10.146863,0.0,0.00084757869,5.9802613,10.223537,449.18683,-9.2348623
195.3645,0.46874422,0.010466981,0.0,0,10.080863,0.0,0.00080534728,5.9533424,10.173695,449.22156,-9.2358627
195.3689,0.46857753,0.011813525,0.0,0,10.014863,0.0,0.00088518061,5.9640465,10.118094,449.27426,-9.2368174
195.3733,0.52902877,0.011434706,0.0,0,9.948863,0.0,0.00075866026,6.6630855,10.048773,449.33203,-9.2354612
195.3777,2.1474545,0.023637911,0.0,0,9.882863,0.0,0.0015212611,26.887672,9.9835987,449.39792,-9.2345133
195.3821,4.2366052,0.053785052,0.0,0,9.8168631,0.0,0.0034917856,53.518063,9.9220819,449.47577,-9.2335901
195.3865,4.8286047,0.12771587,0.0,0,9.7508631,0.0,0.0083522284,60.807697,9.845459,449.64703,-9.2323961
195.3909,5.0834517,0.19713755,0.0,0,9.6848621,0.0,0.013040729,63.887096,9.7676268,449.81827,-9.2327862
195.3953,5.1933603,0.26898193,0.0,0,9.6188631,0.0,0.017759077,65.011368,9.6992559,450.01172,-9.2315197
195.3997,5.282433,0.32953733,0.0,0,9.5528631,0.0,0.022022841,65.685944,9.6322966,450.20935,-9.2326231
195.4041,5.3658943,0.39280203,0.0,0,9.4868631,0.0,0.026145285,66.519608,9.5726852,450.36206,-9.2328777
195.4085,5.4487715,0.45364287,0.0,0,9.4223585,0.0,0.030538207,67.326088,9.4998569,450.48062,-9.2336016
195.4129,5.475934,0.52626818,0.0,0,9.3579769,0.0,0.035388,67.371582,9.4384584,450.59918,-9.2346001
195.4173,5.541708,0.58967394,0.0,0,9.2935963,0.0,0.039941616,67.773445,9.3670712,450.71774,-9.232832
195.4217,5.5751619,0.65701246,0.0,0,9.2292166,0.0,0.044508651,67.95015,9.3041153,450.8363,-9.232893
195.4261,5.6084504,0.71564251,0.0,0,9.164835,0.0,0.048779279,67.986961,9.2391129,450.9549,-9.2331486
195.4305,5.6382647,0.78264886,0.0,0,9.1004543,0.0,0.053515844,67.999283,9.1758184,451.07349,-9.234375
195.4349,5.6783214,0.84027988,0.0,0,9.0360737,0.0,0.057591181,68.222801,9.1069479,451.19205,-9.2332764
195.4393,5.7443881,0.9092173,0.0,0,8.9716921,0.0,0.062613927,68.706932,9.0436964,451.31064,-9.2334757
195.4437,5.7842712,0.97054642,0.0,0,8.9073124,0.0,0.066954121,68.905487,8.9747543,451.44177,-9.2338152
195.4481,5.777925,1.03344,0.0,0,8.8429308,0.0,0.071570173,68.434059,8.9136324,451.5867,-9.233243
195.4525,5.8223577,1.0959361,0.0,0,8.7785501,0.0,0.076033361,68.568085,8.8493414,451.60764,-9.2320604
195.4569,5.9093466,1.1615647,0.0,0,8.7159319,0.0,0.0808511,69.370659,8.7826643,451.14655,-9.2329111
195.4613,5.9157557,1.2230482,0.0,0,8.6547012,0.0,0.085264608,69.227341,8.7146883,450.68542,-9.2343054
195.4657,5.9309006,1.2867039,0.0,0,8.5934715,0.0,0.08992669,68.985649,8.653161,449.83145,-9.2343807
195.4701,5.9373398,1.3463686,0.0,0,8.5322418,0.0,0.094182581,68.780235,8.5930567,448.94873,-9.2341738
195.4745,5.9869385,1.40651,0.0,0,8.4710112,0.0,0.098617896,68.967209,8.5249176,448.70862,-9.2333441
195.4789,6.0142918,1.4639693,0.0,0,8.4097805,0.0,0.10285312,69.143608,8.4689674,448.80084,-9.2333517
195.4833,6.036099,1.5228635,0.0,0,8.3485489,0.0,0.10712922,69.054077,8.4072199,449.13739,-9.2327986
195.4877,6.0787387,1.5830003,0.0,0,8.2873192,0.0,0.11148714,69.262718,8.3515015,449.862,-9.2331553
195.4921,6.1689377,1.6468878,0.0,0,8.2260885,0.0,0.1162077,69.835175,8.2848797,450.55368,-9.2350187
195.4965,6.2134032,1.7143104,0.0,0,8.1648579,0.0,0.12121926,70.084946,8.219101,450.98843,-9.2337523
195.5009,6.2264814,1.7738637,0.0,0,8.1036282,0.0,0.12569973,69.878784,8.1575556,451.42322,-9.2336159
195.5053,6.2396698,1.8418671,0.0,0,8.0429811,0.0,0.13070388,69.717003,8.0899582,451.64746,-9.2340231
195.5097,6.2474136,1.900178,0.0,0,7.984725,0.0,0.13518998,69.489258,8.0270882,451.83191,-9.2339106
195.5141,6.2953038,1.9614917,0.0,0,7.9264684,0.0,0.13973856,69.682632,7.9721031,452.03882,-9.2343645
195.5185,6.3191133,2.0127709,0.0,0,7.8682127,0.0,0.14385389,69.630432,7.9102435,452.26279,-9.2335215
195.5229,6.3371172,2.0755537,0.0,0,7.8099566,0.0,0.1484907,69.54409,7.853837,452.45953,-9.2338476
195.5273,6.3488917,2.1288512,0.0,0,7.7517009,0.0,0.15286791,69.335762,7.7976561,452.59128,-9.2343054
195.5317,6.4104009,2.1894493,0.0,0,7.6934447,0.0,0.15743512,69.629173,7.7392678,452.71793,-9.2334032
195.5361,6.467309,2.2399099,0.0,0,7.6351886,0.0,0.16156828,70.008194,7.6826477,452.6257,-9.2343369
195.5405,6.5061755,2.3020296,0.0,0,7.5769329,0.0,0.1664367,70.172012,7.619689,452.53348,-9.2342567
195.5449,6.516151,2.3578269,0.0,0,7.5186768,0.0,0.17097993,69.996124,7.5618095,452.47092,-9.2333746
195.5493,6.5148296,2.4164011,0.0,0,7.4604206,0.0,0.17571475,69.569641,7.5043039,452.41821,-9.2330666
195.5537,6.6066961,2.470438,0.0,0,7.4021645,0.0,0.18001507,70.184654,7.4474831,452.47241,-9.2331696
195.5581,6.6240211,2.5298936,0.0,0,7.346282,0.0,0.18499339,70.153801,7.3902178,452.64368,-9.2336655
195.5625,6.6380191,2.5851469,0.0,0,7.2908773,0.0,0.18934904,69.982025,7.331193,452.79877,-9.2337542
195.5669,6.6697845,2.6428618,0.0,0,7.2354722,0.0,0.19411775,69.882019,7.2671361,452.89099,-9.2344961
195.5713,6.68785,2.6966696,0.0,0,7.1800675,0.0,0.19841993,69.78389,7.2167616,452.98322,-9.2343349
195.5757,6.722487,2.7493541,0.0,0,7.1246624,0.0,0.20271216,69.936943,7.1607709,452.67032,-9.232604
195.5801,6.7573037,2.8045733,0.0,0,7.0692577,0.0,0.20720078,69.995491,7.1053724,452.32776,-9.2322197
195.5845,6.7858787,2.8591468,0.0,0,7.0138526,0.0,0.21172205,69.914894,7.0495977,452.12415,-9.2349739
195.5889,6.8308916,2.9153607,0.0,0,6.9584484,0.0,0.21622504,70.040413,6.9953403,451.9924,-9.2333765
195.5933,6.8924875,2.9708619,0.0,0,6.9030437,0.0,0.22081207,70.356491,6.9428258,452.05917,-9.233098
195.5977,6.9022894,3.0285623,0.0,0,6.8476391,0.0,0.22550148,70.131783,6.8824964,452.44125,-9.2321043
195.6021,6.9094481,3.0835097,0.0,0,6.7922335,0.0,0.23000672,69.93959,6.826489,452.7829,-9.2328424
195.6065,6.9470463,3.1395149,0.0,0,6.738091,0.0,0.23466522,69.971672,6.7701516,452.80923,-9.2328472
195.6109,6.9846115,3.1903791,0.0,0,6.685379,0.0,0.23894688,70.071732,6.7121058,452.8356,-9.2328005
195.6153,6.9773841,3.2469375,0.0,0,6.6326671,0.0,0.24365984,69.673409,6.6629024,452.55173,-9.2336311
195.6197,7.0141454,3.2978847,0.0,0,6.5799551,0.0,0.24797376,69.689842,6.6075487,452.2092,-9.2331095
195.6241,7.0553856,3.3539605,0.0,0,6.5272431,0.0,0.25266451,69.73275,6.554451,452.00888,-9.2328205
195.6285,7.0953631,3.3999934,0.0,0,6.4745317,0.0,0.25674659,69.92025,6.5052538,451.91666,-9.2326603
195.6329,7.15136,3.4602005,0.0,0,6.4218192,0.0,0.26171532,70.114716,6.4473586,451.85947,-9.2334671
195.6373,7.166512,3.5101283,0.0,0,6.3691072,0.0,0.26629585,69.950394,6.3955379,451.8858,-9.2330618
195.6417,7.2077861,3.5690451,0.0,0,6.3163953,0.0,0.27136269,69.97612,6.3393154,451.91635,-9.233552
195.6461,7.2257652,3.6169529,0.0,0,6.2636838,0.0,0.27572241,69.825325,6.2836957,452.12714,-9.2333641
195.6505,7.241261,3.6712563,0.0,0,6.2109718,0.0,0.28047925,69.671471,6.232903,452.33792,-9.2337141
195.6549,7.2616796,3.719754,0.0,0,6.1585307,0.0,0.28496575,69.55764,6.1761255,452.70685,-9.2339916
195.6593,7.2751584,3.7721844,0.0,0,6.1083965,0.0,0.28956798,69.26252,6.1304836,453.12845,-9.2340755
195.6637,7.3493819,3.8174255,0.0,0,6.0582638,0.0,0.29377559,69.765259,6.0819197,453.44315,-9.2325649
195.6681,7.3858981,3.873003,0.0,0,6.0081296,0.0,0.29885143,69.733047,6.0275593,453.64075,-9.2320375
195.6725,7.3939786,3.9218535,0.0,0,5.9579964,0.0,0.30329803,69.505638,5.9759459,453.77908,-9.2332993
195.6769,7.383287,3.9717627,0.0,0,5.9078631,0.0,0.3078782,69.097244,5.9254827,453.68686,-9.2330742
195.6813,7.4299641,4.0174522,0.0,0,5.857729,0.0,0.31208366,69.158737,5.8769436,453.59464,-9.2332067
195.6857,7.5029278,4.065731,0.0,0,5.8075957,0.0,0.31658041,69.55928,5.8286166,453.70465,-9.2320995
195.6901,7.5488048,4.1192446,0.0,0,5.757462,0.0,0.32137233,69.749947,5.7764726,453.82947,-9.2327862
195.6945,7.5461836,4.1696835,0.0,0,5.7073283,0.0,0.32611144,69.258377,5.7264309,454.04108,-9.233531
195.6989,7.5868559,4.2191477,0.0,0,5.6571946,0.0,0.33050367,69.385551,5.6752467,454.27823,-9.232666
195.7033,7.6493301,4.269012,0.0,0,5.6070609,0.0,0.33510104,69.625633,5.6246719,454.47583,-9.2329102
195.7077,7.6402955,4.3192225,0.0,0,5.5587349,0.0,0.33961198,69.286346,5.5731988,454.63394,-9.2331915
195.7121,7.6310296,4.3661542,0.0,0,5.5110393,0.0,0.34404403,68.904182,5.5255237,454.78006,-9.2336311
195.7165,7.6827974,4.4166226,0.0,0,5.4633427,0.0,0.34864366,69.009941,5.4801245,454.88544,-9.2334833
195.7209,7.7469497,4.4625225,0.0,0,5.415647,0.0,0.35287616,69.286781,5.4278378,454.99084,-9.2329149
195.7253,7.7653761,4.5123749,0.0,0,5.3679509,0.0,0.35759583,69.220711,5.3785934,454.83215,-9.232295
195.7297,7.7371907,4.5583391,0.0,0,5.3202548,0.0,0.3619037,68.620811,5.3345699,454.66089,-9.2336254
195.7341,7.7680955,4.6049209,0.0,0,5.2725592,0.0,0.36625019,68.613159,5.2870393,454.53452,-9.2320375
195.7385,7.8943768,4.6518507,0.0,0,5.2248631,0.0,0.37085095,69.343353,5.2407026,454.42914,-9.2327747
195.7429,7.9389629,4.7061391,0.0,0,5.1771669,0.0,0.37585959,69.412209,5.1918597,454.41537,-9.2335463
195.7473,7.9437695,4.7509232,0.0,0,5.1294713,0.0,0.3804493,69.143341,5.1405315,454.53394,-9.2326641
195.7517,7.9156346,4.80124,0.0,0,5.0817752,0.0,0.38525686,68.593483,5.0973482,454.65433,-9.2329845
195.7561,8.0647402,4.8462615,0.0,0,5.0349603,0.0,0.38997218,69.508537,5.0449662,454.78607,-9.2332039
195.7605,8.0639095,4.8985729,0.0,0,4.9895964,0.0,0.39502302,69.252815,4.9992208,454.91779,-9.231657
195.7649,8.0381575,4.9410563,0.0,0,4.944232,0.0,0.39947125,68.667664,4.9539356,455.14056,-9.2328062
195.7693,8.0501833,4.9865665,0.0,0,4.8988686,0.0,0.40410262,68.41996,4.9086981,455.37772,-9.2335854
195.7737,8.0589762,5.0274291,0.0,0,4.8535042,0.0,0.40825707,68.168274,4.8655605,455.59149,-9.2335424
195.7781,8.1779432,5.0734587,0.0,0,4.8081403,0.0,0.41304493,68.869453,4.8172698,455.78912,-9.2310486
195.7825,8.2193308,5.1160383,0.0,0,4.7627759,0.0,0.41739219,69.010506,4.7735777,455.94064,-9.2328367
195.7869,8.2537813,5.1665344,0.0,0,4.7174125,0.0,0.42264995,68.826057,4.7260847,455.99335,-9.2337961
195.7913,8.277956,5.2088065,0.0,0,4.6720481,0.0,0.42701349,68.74823,4.6797714,456.04724,-9.2324114
195.7957,8.3519344,5.2553978,0.0,0,4.6266842,0.0,0.43185496,68.983162,4.631146,456.12628,-9.233901
195.8001,8.3536911,5.3018355,0.0,0,4.5813198,0.0,0.43649986,68.767181,4.589005,456.20529,-9.2326384
195.8045,8.3844948,5.3444471,0.0,0,4.5359974,0.0,0.44095138,68.642586,4.5420599,456.32507,-9.2332048
195.8089,8.3852901,5.389236,0.0,0,4.4928322,0.0,0.44550684,68.347038,4.4945698,456.45682,-9.2328939
195.8133,8.4497681,5.4327097,0.0,0,4.449677,0.0,0.45001411,68.530823,4.4526329,454.96127,-9.2324934
195.8177,8.4896336,5.4781122,0.0,0,4.4065218,0.0,0.4546558,68.632217,4.4131136,451.8385,-9.232914
195.8221,8.4698715,5.5183797,0.0,0,4.3633666,0.0,0.45866525,68.175308,4.3686914,448.68875,-9.2321796
195.8265,8.5218029,5.56252,0.0,0,4.3202114,0.0,0.46329612,68.252274,4.3234696,445.4473,-9.2320757
195.8309,8.5932026,5.604723,0.0,0,4.2770562,0.0,0.4677659,68.471725,4.2850537,442.20584,-9.2329483
195.8353,8.6529875,5.6494732,0.0,0,4.2339005,0.0,0.47229919,68.753914,4.2392035,443.12787,-9.2337093
195.8397,8.6638517,5.6898813,0.0,0,4.1907454,0.0,0.47663131,68.537285,4.1974568,444.24811,-9.2327595
195.8441,8.7239571,5.7396336,0.0,0,4.1475906,0.0,0.48175684,68.61013,4.1517005,445.71875,-9.2322035
195.8485,8.8281412,5.7812257,0.0,0,4.1044354,0.0,0.48631161,69.137466,4.1074147,447.35287,-9.2320852
195.8529,8.8332777,5.8297462,0.0,0,4.0612803,0.0,0.49140152,68.728615,4.0632677,447.67667,-9.2333651
195.8573,8.8626938,5.8676834,0.0,0,4.0194988,0.0,0.49578485,68.78936,4.0243282,446.10779,-9.2330475
195.8617,8.8911991,5.9177103,0.0,0,3.9784558,0.0,0.50105041,68.619637,3.9791393,444.46524,-9.2319784
195.8661,8.9092913,5.952795,0.0,0,3.9374127,0.0,0.50521284,68.464409,3.9360287,442.35608,-9.2327461
195.8705,8.9583387,6.0002141,0.0,0,3.8963695,0.0,0.51031673,68.389191,3.894448,440.24692,-9.2321043
195.8749,8.9897814,6.035326,0.0,0,3.8553262,0.0,0.51448292,68.463135,3.8592474,440.62021,-9.2327309
195.8793,9.0414057,6.0792236,0.0,0,3.8142829,0.0,0.51949489,68.477997,3.8178427,441.38541,-9.231842
195.8837,9.0870028,6.1155457,0.0,0,3.7732399,0.0,0.52379858,68.515129,3.7746813,442.55554,-9.2314081
195.8881,9.1406889,6.157897,0.0,0,3.7321966,0.0,0.52868009,68.579117,3.7369626,444.00595,-9.2334032
195.8925,9.2477245,6.19766,0.0,0,3.6911533,0.0,0.53325284,69.081955,3.6920257,445.35538,-9.2312908
195.8969,9.2471266,6.2418017,0.0,0,3.6501102,0.0,0.53846282,68.830032,3.6525743,446.4884,-9.2339211
195.9013,9.2520952,6.2788634,0.0,0,3.609067,0.0,0.54268748,68.45443,3.6103928,447.60825,-9.2315922
195.9057,9.3253994,6.3197618,0.0,0,3.5685971,0.0,0.54750592,68.671242,3.5698183,448.45142,-9.2318707
195.9101,9.3969355,6.3595099,0.0,0,3.5295513,0.0,0.55209923,68.894737,3.5269268,449.29459,-9.2314911
195.9145,9.42908,6.3999243,0.0,0,3.4905057,0.0,0.5567866,68.842529,3.487911,449.87308,-9.2323608
195.9189,9.4313297,6.436162,0.0,0,3.4514604,0.0,0.56101501,68.512161,3.4516487,450.37372,-9.2348022
195.9233,9.5621595,6.4772363,0.0,0,3.4124146,0.0,0.56576687,69.122398,3.4148779,450.76236,-9.233717
195.9277,9.5839386,6.5192466,0.0,0,3.3733687,0.0,0.57049692,68.964836,3.371943,451.03903,-9.2322321
195.9321,9.6148434,6.5543599,0.0,0,3.3343232,0.0,0.57461011,68.882683,3.3333261,451.30374,-9.2330627
195.9365,9.6586494,6.5963264,0.0,0,3.2952778,0.0,0.5793609,68.927681,3.2910917,451.52771,-9.2326488
195.9409,9.7769289,6.6360207,0.0,0,3.2562323,0.0,0.58396482,69.374763,3.2558196,451.75168,-9.2326651
195.9453,9.8363647,6.6794548,0.0,0,3.2171865,0.0,0.58903033,69.458168,3.2118878,452.17685,-9.2325649
195.9497,9.8237839,6.7179642,0.0,0,3.1781409,0.0,0.59355879,69.128571,3.1740136,452.6116,-9.2320843
195.9541,9.8124266,6.7567854,0.0,0,3.1390953,0.0,0.59813631,68.717964,3.1377587,452.98349,-9.2328367
195.9585,9.8934698,6.7916393,0.0,0,3.1018045,0.0,0.60245335,68.968239,3.101192,453.32605,-9.2324667
195.9629,10.012131,6.8326473,0.0,0,3.0646598,0.0,0.607099,69.399063,3.06604,453.14578,-9.232131
195.9673,10.046991,6.8691449,0.0,0,3.0275147,0.0,0.61174947,69.320328,3.0263956,452.21036,-9.2333908
195.9717,10.092352,6.9106092,0.0,0,2.9903703,0.0,0.61673367,69.412018,2.9873357,451.23724,-9.2314777
195.9761,10.129115,6.943511,0.0,0,2.9532254,0.0,0.62110901,69.203362,2.9508355,450.02518,-9.2314711
195.9805,10.232061,6.9864745,0.0,0,2.9160805,0.0,0.62628484,69.596535,2.910537,448.81311,-9.2316589
195.9849,10.276803,7.016892,0.0,0,2.8789358,0.0,0.63031244,69.684143,2.8778222,448.72748,-9.2326193
195.9893,10.28396,7.0590596,0.0,0,2.8417909,0.0,0.63575381,69.4039,2.8422666,448.8197,-9.2326488
195.9937,10.33895,7.0894752,0.0,0,2.8046463,0.0,0.63978219,69.454887,2.8043458,449.09875,-9.2328777
195.9981,10.42706,7.1286163,0.0,0,2.7675014,0.0,0.64502251,69.636879,2.7690642,449.50717,-9.2328777
196.0025,10.544827,7.1617489,0.0,0,2.7303565,0.0,0.64916974,70.141998,2.7324193,449.86111,-9.2312546
196.0069,10.668358,7.2032342,0.0,0,2.6942265,0.0,0.65473574,70.572418,2.6925683,450.09824,-9.2328787
196.0113,10.703106,7.2390981,0.0,0,2.6588945,0.0,0.65934527,70.414993,2.6560223,450.34259,-9.2328062
196.0157,10.691886,7.2782254,0.0,0,2.6235626,0.0,0.66451705,70.041603,2.6184397,450.73782,-9.2332706
196.0201,10.72212,7.3108974,0.0,0,2.5882306,0.0,0.66889626,69.966438,2.5832551,451.13309,-9.233427
196.0245,10.794499,7.3442712,0.0,0,2.5528984,0.0,0.67331362,70.059525,2.5466108,451.37561,-9.2312756
196.0289,10.821137,7.3781877,0.0,0,2.5175664,0.0,0.67763734,69.969795,2.5144799,451.57321,-9.2307615
196.0333,10.856454,7.408289,0.0,0,2.4822345,0.0,0.68160725,69.921074,2.4826789,451.64566,-9.233675
196.0377,11.043641,7.4476333,0.0,0,2.4469025,0.0,0.68649811,70.731918,2.44643,451.59296,-9.2314863
196.0421,11.108695,7.4841213,0.0,0,2.4115705,0.0,0.69126767,70.883469,2.4105346,451.51334,-9.2324781
196.0465,11.164065,7.5206771,0.0,0,2.3762386,0.0,0.69606048,70.892769,2.3727334,451.34207,-9.2323093
196.0509,11.245695,7.5555363,0.0,0,2.3409064,0.0,0.70052421,71.076462,2.3348751,451.17081,-9.2335062
196.0553,11.343689,7.5942163,0.0,0,2.3059125,0.0,0.70554489,71.300293,2.3018105,450.08148,-9.2325716
196.0597,11.424389,7.6296906,0.0,0,2.2723053,0.0,0.71012694,71.555428,2.2665842,448.94846,-9.2315311
196.0641,11.440423,7.6678901,0.0,0,2.238698,0.0,0.71513933,71.311653,2.230181,447.85135,-9.2321787
196.0685,11.441909,7.6989522,0.0,0,2.205091,0.0,0.7193808,70.926956,2.1979136,446.77106,-9.2330418
196.0729,11.520567,7.7364397,0.0,0,2.1714838,0.0,0.72439855,71.061737,2.1658814,446.12192,-9.2323999
196.0773,11.621819,7.7652082,0.0,0,2.1378765,0.0,0.72848374,71.404427,2.133173,446.09555,-9.2322302
196.0817,11.726975,7.802238,0.0,0,2.1042693,0.0,0.73325539,71.7052,2.0987535,446.13925,-9.2320528
196.0861,11.803604,7.8329301,0.0,0,2.0706623,0.0,0.73795748,71.830238,2.0652301,446.62674,-9.2320328
196.0905,11.919577,7.8696146,0.0,0,2.037055,0.0,0.74289507,72.155922,2.0298359,447.1142,-9.2321815
196.0949,11.997419,7.9022427,0.0,0,2.0034478,0.0,0.74782473,72.252396,1.993894,447.90887,-9.2323732
196.0993,12.062389,7.9396667,0.0,0,1.9698405,0.0,0.75296253,72.350174,1.9625084,448.75204,-9.2329683
196.1037,12.085123,7.968739,0.0,0,1.9362334,0.0,0.75756454,72.12236,1.9294461,449.32275,-9.2317524
196.1081,12.174235,8.0042973,0.0,0,1.9039886,0.0,0.7627601,72.259209,1.8956316,449.70483,-9.2327223
196.1125,12.285349,8.0324554,0.0,0,1.8720181,0.0,0.76692206,72.637131,1.8666725,448.992,-9.2326002
196.1169,12.371992,8.066083,0.0,0,1.8400478,0.0,0.77205116,72.818916,1.8305819,445.93301,-9.2322731
196.1213,12.365028,8.0945091,0.0,0,1.8080775,0.0,0.77618682,72.457245,1.8022205,442.91183,-9.2338352
196.1257,12.445891,8.1269264,0.0,0,1.7761071,0.0,0.78117591,72.528114,1.7668982,440.68408,-9.2313271
196.1301,12.578073,8.1558743,0.0,0,1.7441366,0.0,0.78526902,73.00856,1.7418327,438.45633,-9.2311306
196.1345,12.660273,8.1857185,0.0,0,1.7121662,0.0,0.78988296,73.131317,1.7085798,438.45987,-9.2313147
196.1389,12.81491,8.2177048,0.0,0,1.6801958,0.0,0.79445922,73.727409,1.6737602,439.11963,-9.2312937
196.1433,12.859494,8.2521038,0.0,0,1.6482253,0.0,0.79948324,73.641052,1.6448702,439.78598,-9.2329664
196.1477,13.042821,8.2841539,0.0,0,1.6162549,0.0,0.80403644,74.306343,1.6124544,440.45892,-9.2315903
196.1521,13.193372,8.3181419,0.0,0,1.5842845,0.0,0.80911881,74.804337,1.5747008,441.26373,-9.2324839
196.1565,13.249226,8.3524446,0.0,0,1.5530443,0.0,0.81409281,74.731003,1.5453558,442.51675,-9.2316036
196.1609,13.284901,8.3860121,0.0,0,1.5226315,0.0,0.81882375,74.653984,1.5114541,443.76974,-9.2319098
196.1653,13.377745,8.418869,0.0,0,1.4922187,0.0,0.82365936,74.696808,1.4810221,444.58142,-9.2313757
196.1697,13.428988,8.4465828,0.0,0,1.4618059,0.0,0.82776177,74.764847,1.4518083,445.3721,-9.2314892
196.1741,13.483161,8.4811468,0.0,0,1.431393,0.0,0.83276153,74.685432,1.4189798,445.79434,-9.2327223
196.1785,13.509407,8.5075483,0.0,0,1.4009804,0.0,0.83673769,74.536102,1.3950623,446.04465,-9.2320242
196.1829,13.631032,8.5376749,0.0,0,1.3705676,0.0,0.8412329,74.824501,1.3609216,446.16022,-9.2320747
196.1873,13.794806,8.5660801,0.0,0,1.3401548,0.0,0.84568417,75.357674,1.3354594,446.08118,-9.2314014
196.1917,13.908249,8.6006069,0.0,0,1.3097421,0.0,0.85066837,75.637817,1.3043356,446.06323,-9.2310286
196.1961,14.030161,8.6253786,0.0,0,1.2793292,0.0,0.85497928,76.009041,1.2738374,446.43213,-9.2311745
196.2005,14.131675,8.6601048,0.0,0,1.2489164,0.0,0.86019313,76.094856,1.2443033,446.80103,-9.2298584
196.2049,14.315196,8.6901121,0.0,0,1.2186599,0.0,0.86534125,76.679306,1.208591,447.26093,-9.2325735
196.2093,14.430121,8.7254162,0.0,0,1.1897342,0.0,0.8708961,76.957222,1.1759119,447.7352,-9.2317781
196.2137,14.43433,8.7500782,0.0,0,1.1608087,0.0,0.87510955,76.629295,1.1489393,448.0538,-9.2313004
196.2181,14.485162,8.7779474,0.0,0,1.131883,0.0,0.87979656,76.508774,1.1198032,448.26459,-9.2313976
196.2225,14.573149,8.8041306,0.0,0,1.1029575,0.0,0.88432175,76.607422,1.0970025,448.49634,-9.2316265
196.2269,14.732477,8.8347073,0.0,0,1.0740318,0.0,0.88936585,77.049316,1.0648645,448.77298,-9.2306948
196.2313,14.871045,8.8576727,0.0,0,1.0451063,0.0,0.89318609,77.553169,1.0389727,449.05685,-9.2312489
196.2357,14.934752,8.8892431,0.0,0,1.0161806,0.0,0.89875919,77.425209,1.0072494,449.49161,-9.2310104
196.2401,15.054594,8.9126949,0.0,0,0.98725498,0.0,0.90265644,77.723022,0.98266119,449.92639,-9.2312365
196.2445,15.269285,8.9433136,0.0,0,0.95832938,0.0,0.90780145,78.406258,0.95141232,450.21863,-9.2305832
196.2489,15.360723,8.9690886,0.0,0,0.92940378,0.0,0.9119786,78.585442,0.91717601,450.46896,-9.230814
196.2533,15.422157,8.9986315,0.0,0,0.90047812,0.0,0.91698253,78.53476,0.89137137,450.58093,-9.2311678
196.2577,15.587867,9.0294971,0.0,0,0.87260312,0.0,0.92189771,78.939072,0.86721945,450.55457,-9.2314301
196.2621,15.796943,9.0533972,0.0,0,0.84509432,0.0,0.92597884,79.65773,0.83565366,450.54019,-9.2299929
196.2665,15.859572,9.0844498,0.0,0,0.81758547,0.0,0.9308241,79.6036,0.80249274,450.56656,-9.2311449
196.2709,15.821589,9.1123676,0.0,0,0.79007667,0.0,0.93530053,79.044693,0.77732521,450.59293,-9.2316542
196.2753,15.833743,9.135973,0.0,0,0.76256788,0.0,0.9392187,78.823891,0.75398397,450.38031,-9.2312927
196.2797,16.016823,9.1619015,0.0,0,0.73505908,0.0,0.94333863,79.361504,0.72507608,450.15634,-9.2313232
196.2841,16.309469,9.1898785,0.0,0,0.70755029,0.0,0.9478268,80.495995,0.70199865,450.06711,-9.2297707
196.2885,16.477888,9.2156096,0.0,0,0.68004155,0.0,0.95222151,80.951683,0.66773099,450.04077,-9.2301292
196.2929,16.514875,9.2485752,0.0,0,0.6525327,0.0,0.95765549,80.718941,0.64754522,450.14917,-9.230401
196.2973,16.629492,9.2705698,0.0,0,0.62502396,0.0,0.96144915,80.888359,0.61302197,450.45218,-9.2297554
196.3017,16.748465,9.3024645,0.0,0,0.59751511,0.0,0.96671927,81.131058,0.59286189,450.62582,-9.231101
196.3061,16.941671,9.3248158,0.0,0,0.57050836,0.0,0.97101998,81.700813,0.56461406,449.98029,-9.2308903
196.3105,17.175478,9.3601303,0.0,0,0.54432839,0.0,0.97695923,82.344368,0.53825963,449.33472,-9.2299805
196.3149,17.101032,9.3772106,0.0,0,0.51814836,0.0,0.98068029,81.75972,0.51062965,448.45023,-9.2313738
196.3193,15.981868,9.3879795,0.0,0,0.49196839,0.0,0.98245424,76.172119,0.49357828,447.52795,-9.230917
196.3237,15.29838,9.387289,0.0,0,0.46578839,0.0,0.98266178,72.916023,0.47774878,447.0495,-9.2323837
196.3281,14.838635,9.3967524,0.0,0,0.4396084,0.0,0.98429269,70.590271,0.46284151,446.87823,-9.2343111
196.3325,14.510972,9.3947916,0.0,0,0.41342837,0.0,0.98438048,69.104408,0.44373137,446.79919,-9.2325087
196.3369,14.146666,9.4005556,0.0,0,0.38724837,0.0,0.98571366,67.201561,0.42589501,446.91776,-9.2327681
196.3413,13.599797,9.3994894,0.0,0,0.36106834,0.0,0.98568434,64.64489,0.41856456,447.04294,-9.2332754
196.3457,13.129362,9.4032869,0.0,0,0.33488834,0.0,0.98664463,62.3769,0.40864912,447.30643,-9.2335901
196.3501,12.810799,9.4005346,0.0,0,0.30870837,0.0,0.98623824,60.870342,0.40658158,447.56992,-9.235939
196.3545,12.751886,9.4018831,0.0,0,0.28255236,0.0,0.98672062,60.524242,0.38499558,447.79269,-9.2343512
196.3589,12.945293,9.4024868,0.0,0,0.25765142,0.0,0.98693359,61.416492,0.36267328,448.00348,-9.2337542
196.3633,13.19523,9.407094,0.0,0,0.23275623,0.0,0.98772579,62.564625,0.3271611,448.11548,-9.2333927
196.3677,13.328358,9.4070778,0.0,0,0.20786107,0.0,0.98752868,63.22126,0.29042313,448.12863,-9.2326822
196.3721,13.4058,9.4121084,0.0,0,0.18296587,0.0,0.98835969,63.536293,0.25833964,448.14481,-9.2323666
196.3765,13.457284,9.4132137,0.0,0,0.15807067,0.0,0.98830527,63.784515,0.22969672,448.17117,-9.2326765
196.3809,13.436619,9.4162388,0.0,0,0.13317546,0.0,0.98852009,63.672203,0.20172793,448.19754,-9.2339163
196.3853,13.37183,9.4230032,0.0,0,0.10828025,0.0,0.98952013,63.274391,0.1767744,448.28677,-9.2330952
196.3897,13.306189,9.4246597,0.0,0,0.08338505,0.0,0.98948354,63.00103,0.15403217,448.379,-9.233304
196.3941,13.249891,9.4276447,0.0,0,0.058489852,0.0,0.98992217,62.664116,0.13053171,448.48016,-9.2334824
196.3985,13.170674,9.4273958,0.0,0,0.033594649,0.0,0.98966104,62.346565,0.10969026,448.58557,-9.2341108
196.4029,13.075658,9.4338017,0.0,0,0.0086994497,0.0,0.99047041,61.869194,0.092487246,448.68018,-9.2334337
196.4073,12.986176,9.4346018,0.0,0,-0.015800733,0.0,0.99058354,61.424591,0.07190235,448.75925,-9.2331524
196.4117,12.918851,9.4400148,0.0,0,-0.040088736,0.0,0.99124271,60.995319,0.0505311,448.83292,-9.230731
196.4161,12.851846,9.4383221,0.0,0,-0.064376727,0.0,0.99122304,60.756519,0.040398888,448.87244,-9.2331638
196.4205,12.737302,9.4416389,0.0,0,-0.088664725,0.0,0.99144673,60.190742,0.018750947,448.91193,-9.2331648
196.4249,12.611111,9.4419575,0.0,0,-0.044734921,449.55518,0.99206084,59.563423,0.010134703,448.96286,-9.2328148
196.4293,12.444781,9.4469738,0.0,0,0.75209731,450.0,0.99269682,58.734112,-0.0037752681,449.01556,-9.2315302
196.4337,10.323862,9.4390173,0.0,0,1.5489554,450.0,0.99182266,48.878391,0.077290736,449.13831,-9.2328262
196.4381,5.4454083,9.4258175,0.0,0,2.3458138,450.0,0.98964626,26.048187,0.32735777,449.30957,-9.238534
196.4425,-0.05724337,9.3563671,0.0,0,3.1426711,450.0,0.97759485,-0.29814538,1.0571742,449.45148,-9.2431231
196.4469,-0.12518346,9.4138451,0.0,0,3.9395285,450.0,0.9877165,-0.52903825,2.3578258,449.53055,-9.2412128
196.4513,0.052111454,9.4217186,0.0,0,4.7363858,450.0,0.98961562,0.29056996,3.3379323,449.60303,-9.2413473
196.4557,-0.066056021,9.4180727,0.0,0,5.5332432,450.0,0.98921841,-0.31818929,4.1106968,449.53714,-9.2407932
196.4601,0.016337963,9.4137106,0.0,0,6.3301015,450.0,0.98843962,0.027830299,4.8735476,449.47128,-9.238513
196.4645,-0.049021803,9.4140806,0.0,0,7.1269588,450.0,0.98884809,-0.20054804,5.6616812,449.43594,-9.2400532
196.4689,0.063105419,9.4079809,0.0,0,7.9238162,450.0,0.98787153,0.28563654,6.4862275,449.40958,-9.238265
196.4733,-0.089407161,9.4102278,0.0,0,8.7206745,450.0,0.98831171,-0.36345655,7.3211484,449.36346,-9.23666
196.4777,-0.07165198,9.4100294,0.0,0,9.5175323,450.0,0.9880805,-0.41107166,8.1498842,449.29761,-9.2371502
196.4821,-0.012097401,9.4058838,0.0,0,10.31439,450.0,0.98735046,0.082319744,8.9732246,449.24072,-9.2373877
196.4865,-0.057421554,9.4080715,0.0,0,11.111248,450.0,0.98751003,-0.33425817,9.7831411,449.21439,-9.2360725
196.4909,-0.07423494,9.4092398,0.0,0,11.908105,450.0,0.98728496,-0.28760409,10.595773,449.18802,-9.236928
196.4953,-0.0027788442,9.4082756,0.0,0,12.704963,450.0,0.98711139,-0.08049947,11.373786,449.21198,-9.2374935
196.4997,-0.058270898,9.4088478,0.0,0,13.501821,450.0,0.98691946,-0.26838949,12.150852,449.23831,-9.2358999
196.5041,-0.10303567,9.4101801,0.0,0,14.298677,450.0,0.98677963,-0.43669897,12.933552,449.2377,-9.2354116
196.5085,0.069164574,9.4091187,0.0,0,15.095535,450.0,0.98645777,0.24224992,13.732163,449.22452,-9.2353172
196.5129,-0.22531004,9.4100571,0.0,0,15.892393,450.0,0.98630977,-1.0645268,14.536337,449.18439,-9.2350035
196.5173,0.053679176,9.4093456,0.0,0,16.689253,450.0,0.9861787,0.24929474,15.342848,449.10538,-9.2345514
196.5217,-0.13924925,9.4154148,0.0,0,17.486109,450.0,0.9870463,-0.62776101,16.145781,449.03351,-9.2337141
196.5261,-0.016188037,9.4110727,0.0,0,18.0,450.0,0.98632336,-0.097778939,16.940788,449.00717,-9.23491
196.5305,-0.01174058,9.4141703,0.0,0,18.0,450.0,0.98644286,0.0092803109,17.702574,448.98083,-9.234623
196.5349,0.049934138,9.4155931,1.6782923,0,18.0,450.0,0.98726875,0.2170534,18.255787,448.9317,-9.2390051
196.5393,0.21014883,9.4263563,3.6215541,0,18.0,450.0,0.9889012,0.97258699,18.460089,448.879,-9.2468882
196.5437,0.38916507,9.4267159,4.4165039,0,18.0,450.0,0.9894262,1.8593932,18.299953,448.81848,-9.2581644
196.5481,0.36553338,9.4284401,4.4165039,0,18.0,450.0,0.98957503,1.7337185,18.115879,448.75262,-9.2840977
196.5525,0.30974787,9.4272776,4.4165039,0,18.0,450.0,0.98996025,1.4702271,18.045433,448.70352,-9.3188534
196.5569,0.30377838,9.4275255,4.4165039,0,18.0,450.0,0.99019599,1.4610627,18.0539,448.69037,-9.3555403
196.5613,0.31470627,9.4207802,4.4165039,0,18.0,450.0,0.98923975,1.459386,18.10038,448.67419,-9.3889608
196.5657,0.33916074,9.4199524,4.4165039,0,18.0,450.0,0.98955387,1.6111646,18.132923,448.59512,-9.4253817
196.5701,0.33017853,9.4177017,4.4165039,0,18.0,450.0,0.98919314,1.5539259,18.138988,448.51608,-9.4576654
196.5745,0.29756585,9.4182081,5.6454515,0,18.0,450.0,0.98956573,1.4217485,18.142818,448.4472,-9.4911175
196.5789,0.31876695,9.4170265,7.2358327,0,18.0,450.0,0.98935348,1.5015506,18.136124,448.38135,-9.5233183
196.5833,0.36311761,9.4159842,8.0310059,0,18.0,450.0,0.98930514,1.7089124,18.127256,448.33524,-9.5557327
196.5877,0.33405426,9.4157848,8.0310059,0,18.0,450.0,0.98922974,1.5897307,18.124115,448.3089,-9.5898132
196.5921,0.30939901,9.4157925,8.0310059,0,18.0,450.0,0.98926097,1.470888,18.118294,448.27957,-9.6226082
196.5965,0.30872941,9.4180231,8.0310059,0,18.0,450.0,0.98919141,1.4879664,18.116499,448.24005,-9.6552572
196.6009,0.35591406,9.4131937,8.0310059,0,18.0,450.0,0.98836458,1.6652981,18.116739,448.20053,-9.6871405
196.6053,0.35464761,9.4190445,8.0310059,0,18.0,450.0,0.98913836,1.6876652,18.111189,448.12326,-9.7198048
196.6097,0.31863326,9.418581,8.0310059,0,18.0,450.0,0.98871493,1.5121406,18.105478,448.04419,-9.7570858
196.6141,0.29958823,9.4176865,8.9472799,0,18.0,450.0,0.98842257,1.4325005,18.105425,447.98312,-9.7878075
196.6185,0.34195074,9.419632,10.291127,0,18.0,450.0,0.9884221,1.6007607,18.106548,447.93042,-9.8190556
196.6229,0.36483601,9.4229774,11.085205,0,18.0,450.0,0.98881024,1.7272693,18.102449,447.88852,-9.8528728
196.6273,0.30698055,9.4179106,11.085205,0,18.0,450.0,0.98780161,1.4680965,18.102037,447.86215,-9.8871317
196.6317,0.3068803,9.4225874,11.085205,0,18.0,450.0,0.98841941,1.4722332,18.101456,447.83218,-9.9202547
196.6361,0.33580577,9.4200029,11.085205,0,18.0,450.0,0.98799855,1.5689076,18.097208,447.77948,-9.9520235
196.6405,0.36639339,9.4266996,11.085205,0,18.0,450.0,0.98878485,1.7156742,18.099468,447.72678,-9.9842873
196.6449,0.32940522,9.4205322,11.085205,0,18.0,450.0,0.98805553,1.5877669,18.096067,447.66272,-10.0158
196.6493,0.32420868,9.4274883,11.085205,0,18.0,450.0,0.98892033,1.5200316,18.089211,447.59686,-10.04936
196.6537,0.32764956,9.4238672,11.773621,0,18.0,450.0,0.98897386,1.5246078,18.088264,447.54657,-10.082553
196.6581,0.37826794,9.427948,12.938611,0,18.0,450.0,0.9894706,1.7389027,18.088663,447.50705,-10.115112
196.6625,0.35175264,9.4212513,13.73291,0,18.0,450.0,0.98879933,1.6817925,18.088236,447.46332,-10.150517
196.6669,0.32940993,9.4257412,13.73291,0,18.0,450.0,0.9896183,1.5654925,18.085564,447.41061,-10.1822
196.6713,0.33740294,9.4217844,13.73291,0,18.0,450.0,0.98935682,1.5686784,18.085936,447.35791,-10.214562
196.6757,0.38271686,9.4221153,13.73291,0,18.0,450.0,0.98956001,1.8223674,18.085613,447.30521,-10.248114
196.6801,0.36823928,9.4195824,13.73291,0,18.0,450.0,0.98946381,1.7911711,18.086533,447.2525,-10.279429
196.6845,0.32700527,9.4193544,13.73291,0,18.0,450.0,0.98964208,1.5858186,18.08046,447.16928,-10.313022
196.6889,0.31245995,9.4173508,13.73291,0,18.0,450.0,0.98934662,1.5109543,18.07935,447.07706,-10.345712
196.6933,0.36083159,9.4182434,14.278029,0,18.0,450.0,0.98969716,1.7373044,18.078234,446.97488,-10.379307
196.6977,0.38112143,9.4164906,15.368243,0,18.0,450.0,0.98917305,1.8118783,18.07692,446.86276,-10.412922
196.7021,0.33847159,9.4202061,16.062012,0,18.0,450.0,0.98997682,1.6169534,18.074165,446.78183,-10.445156
196.7065,0.32421002,9.414835,16.062012,0,18.0,450.0,0.98873675,1.4877331,18.070269,446.75549,-10.479833
196.7109,0.36228096,9.4171257,16.062012,0,18.0,450.0,0.98925066,1.6910938,18.073055,446.73154,-10.511467
196.7153,0.39162797,9.4173117,16.062012,0,18.0,450.0,0.98896277,1.8504788,18.070328,446.73154,-10.544761
196.7197,0.35787606,9.4162121,16.062012,0,18.0,450.0,0.98847908,1.7009544,18.073143,446.73154,-10.576335
196.7241,0.3410916,9.4167194,16.062012,0,18.0,450.0,0.98836166,1.5956753,18.068727,446.64529,-10.609841
196.7285,0.35875684,9.4163589,16.062012,0,18.0,450.0,0.98798871,1.6728797,18.069963,446.53992,-10.643178
196.7329,0.39876822,9.4188671,16.562994,0,18.0,450.0,0.98816651,1.8407882,18.069195,446.43451,-10.677075
196.7373,0.37978438,9.4193373,17.481451,0,18.0,450.0,0.98818088,1.8024567,18.067877,446.3291,-10.711794
196.7417,0.33785942,9.4208851,18.149414,0,18.0,450.0,0.98821348,1.6089753,18.063786,446.24884,-10.742316
196.7461,0.33380854,9.4234848,18.149414,0,18.0,450.0,0.98857182,1.575655,18.067053,446.23569,-10.77453
196.7505,0.39783758,9.4224072,18.14942,0,18.0,450.0,0.98822486,1.8737961,18.062078,446.2225,-10.808304
196.7549,0.38496017,9.4219074,18.980864,0,18.0,450.0,0.9883728,1.8434076,18.060831,446.1698,-10.842061
196.7593,0.34499452,9.427042,19.812309,0,18.0,450.0,0.98879403,1.6412965,18.059326,446.1171,-10.873851
196.7637,0.33373687,9.4228773,20.039063,0,18.0,450.0,0.98846716,1.5808834,18.058748,446.05481,-10.906193
196.7681,0.38963577,9.4256353,20.039063,0,18.0,450.0,0.98896718,1.8179322,18.052429,445.98892,-10.939878
196.7725,0.39607567,9.4230042,20.039063,0,18.0,450.0,0.98883021,1.8802975,18.057264,445.92905,-10.973103
196.7769,0.35632756,9.4233685,20.039063,0,18.0,450.0,0.98894411,1.6786131,18.05846,445.87637,-11.007438
196.7813,0.33811516,9.4204626,20.039063,0,18.0,450.0,0.98906308,1.579133,18.057959,445.82605,-11.041324
196.7857,0.36813426,9.4228649,20.039063,0,18.0,450.0,0.98963338,1.7312796,18.054956,445.78653,-11.072188
196.7901,0.40483314,9.4185791,20.039063,0,18.0,450.0,0.98904943,1.9307629,18.053667,445.74701,-11.104136
196.7945,0.36035252,9.4234304,20.729008,0,18.0,450.0,0.99028653,1.7326651,18.058153,445.65958,-11.135927
196.7989,0.33308855,9.415802,21.487944,0,18.0,450.0,0.9888761,1.596602,18.053043,445.56735,-11.169091
196.8033,0.37408426,9.4174995,21.763916,0,18.0,450.0,0.98953354,1.7281188,18.052282,445.45837,-11.201959
196.8077,0.41624296,9.4160633,21.763916,0,18.0,450.0,0.98921955,1.96463,18.052305,445.33978,-11.235142
196.8121,0.37548763,9.4152603,22.018805,0,18.0,450.0,0.9891668,1.8163462,18.052191,445.25955,-11.27048
196.8165,0.36404917,9.4153214,22.71973,0,18.0,450.0,0.98879194,1.7168049,18.049555,445.24637,-11.302958
196.8209,0.35986179,9.4152536,23.356934,0,18.0,450.0,0.98894167,1.6546202,18.050108,445.23441,-11.336134
197.2244,0.31932893,9.4221764,0.00010041973,0,18.0,0.0015956636,0.98929489,1.5136355,18.012009,436.27457,-11.481553
199.4244,0.24637021,9.4384604,9.7157501e-35,0,18.0,1.591761e-33,0.99219108,1.1617464,18.000223,409.60931,-11.481476
201.6244,0.22247899,9.4518099,7.9874012e-44,0,18.0,1.4012985e-45,0.99452376,1.0423392,18.000687,387.30365,-11.48192
203.8244,0.21751417,9.4638023,7.9874012e-44,0,18.0,1.4012985e-45,0.99677664,1.0205553,18.000561,363.16019,-11.481109
206.0244,0.21727651,9.4749765,7.9874012e-44,0,18.0,1.4012985e-45,0.99874085,1.0157459,18.000114,345.60834,-11.48162
208.2244,0.2218643,9.4856558,7.9874012e-44,0,18.0,1.4012985e-45,1.0007715,1.0437282,17.998856,328.6048,-11.482
210.4244,0.20384581,9.4932594,7.9874012e-44,0,18.0,1.4012985e-45,1.0020531,0.95417553,17.999477,312.72629,-11.48206
212.6244,0.21537544,9.5025959,7.9874012e-44,0,18.0,1.4012985e-45,1.0037364,1.0050775,18.000515,297.33893,-11.481658
214.8244,0.22057,9.511385,7.9874012e-44,0,18.0,1.4012985e-45,1.0054077,1.0261456,18.000309,282.84769,-11.481881
217.0244,0.21330401,9.5194025,7.9874012e-44,0,18.0,1.4012985e-45,1.0068465,0.99233735,18.00069,269.11169,-11.482104
219.2244,0.22782108,9.5283318,7.9874012e-44,0,18.0,1.4012985e-45,1.0084906,1.0625962,18.000433,255.99359,-11.4825
221.4244,0.2197475,9.5360126,7.9874012e-44,0,18.0,1.4012985e-45,1.0098045,1.0239071,17.999342,243.8244,-11.482715
223.6244,0.20336188,9.5440063,7.9874012e-44,0,18.0,1.4012985e-45,1.0113447,0.93964839,18.000891,232.04753,-11.481912
225.8244,0.20065273,9.5504513,7.9874012e-44,0,18.0,1.4012985e-45,1.0125198,0.92422664,18.000341,220.64374,-11.481569
228.0244,0.20459975,9.5575647,7.9874012e-44,0,18.0,1.4012985e-45,1.0138562,0.95096272,18.000038,210.28232,-11.481156
230.2244,0.20415895,9.56427,7.9874012e-44,0,18.0,1.4012985e-45,1.015058,0.94127429,17.99987,200.01712,-11.481318
232.4244,0.20297548,9.5704193,7.9874012e-44,0,18.0,1.4012985e-45,1.0161202,0.93756384,17.999704,190.69856,-11.481642
234.6244,0.20998687,9.5759077,7.9874012e-44,0,18.0,1.4012985e-45,1.017243,0.96584362,18.00046,182.29799,-11.482194
236.8244,0.20709866,9.581995,7.9874012e-44,0,18.0,1.4012985e-45,1.0183171,0.95110363,17.999823,174.53925,-11.482339
239.0244,0.20600295,9.587163,7.9874012e-44,0,18.0,1.4012985e-45,1.0193182,0.94501364,17.999636,166.72382,-11.481985
241.2244,0.20025304,9.5926476,7.9874012e-44,0,18.0,1.4012985e-45,1.0202765,0.92652971,17.999739,159.39717,-11.481762
243.4244,0.19990011,9.5971775,7.9874012e-44,0,18.0,1.4012985e-45,1.0210549,0.9162575,17.999855,152.28845,-11.482374
245.6244,0.19552928,9.6015158,7.9874012e-44,0,18.0,1.4012985e-45,1.0219489,0.88951069,17.999842,145.65652,-11.482153
247.8244,0.20579714,9.6062479,7.9874012e-44,0,18.0,1.4012985e-45,1.0227952,0.93752742,18.000509,139.43251,-11.48207
250.0244,0.20972042,9.6106129,7.9874012e-44,0,18.0,1.4012985e-45,1.0236548,0.95429683,17.99988,133.36829,-11.48241
252.2244,0.19974226,9.6144381,7.9874012e-44,0,18.0,1.4012985e-45,1.024291,0.91801918,18.000959,127.85423,-11.482213
254.4244,0.19648089,9.6189594,7.9874012e-44,0,18.0,1.4012985e-45,1.0250787,0.89584887,18.000517,122.55981,-11.481804
256.6244,0.19647017,9.6222858,7.9874012e-44,0,18.0,1.4012985e-45,1.0258098,0.89814377,18.000834,117.5488,-11.482217
256.8244,0.19808696,9.6225786,7.9874012e-44,0,18.0,1.4012985e-45,1.0258324,0.90968072,18.00016,117.09404,-11.482211