File: examples/dan-msc-case-studies/CS3/data/01 raw data/baron_test_136.csv
Time(sec),Force(kN),Jaw(mm),PowAngle(deg),Power(W),Pram,PTemp,Strain,Stress(MPa),Stroke(mm),TC1(C),wedge(mm)
0.0,0.27151775,0.38244238,0.0,0,11.076097,0.0012271219,0.025816439,3.369714,11.075974,23.153629,-9.1237984
1.3,0.23379888,0.0013022887,0.0,0,11.076097,3.815917,6.7235218e-05,2.9693611,11.075331,23.177637,-9.4897785
2.6,0.20797646,0.0012146187,0.0,0,11.076097,7.7159162,6.7207344e-05,2.6494448,11.076327,23.179058,-9.4867411
3.9,0.19314098,0.0012982847,0.0,0,11.076097,11.615913,6.7983819e-05,2.4519641,11.076102,23.150244,-9.4855204
5.2,0.17546326,0.001018202,0.0,0,11.076097,15.515914,4.8381757e-05,2.2412517,11.07624,23.154333,-9.4825392
6.5,0.15963304,0.00056789815,0.0,0,11.076097,19.415911,1.6010037e-05,2.0301511,11.076553,23.164982,-9.47999
7.8,0.15070798,0.00073305191,0.0,0,11.076097,23.315914,2.5364896e-05,1.9181834,11.075266,23.169147,-9.4782305
9.1,0.1394721,0.00081521377,25.744499,0,11.076097,27.215912,3.8527851e-05,1.7841122,11.076496,23.209007,-9.475522
10.4,0.13866252,0.00040371652,40.988998,0,11.076097,31.115908,1.4196351e-05,1.7734368,11.076526,24.410685,-9.4726753
11.7,0.151462,-0.002277992,48.790794,0,11.076097,35.015911,-0.00016474079,1.9283394,11.074959,27.83053,-9.4705076
13.0,0.17201371,-0.0069968076,52.283726,0,11.076097,38.915909,-0.00048109496,2.1879437,11.075447,33.693913,-9.4681864
14.3,0.18097107,-0.011725691,52.976254,0,11.076097,42.815899,-0.00079363358,2.3099852,11.075969,40.602264,-9.4661484
15.6,0.19149959,-0.01610335,51.313728,0,11.076097,46.7159,-0.0010878626,2.4421008,11.076628,47.411362,-9.4636517
16.9,0.19300392,-0.019725647,48.421684,0,11.076097,50.615902,-0.0013262104,2.4661219,11.076447,53.174744,-9.4611225
18.2,0.19717441,-0.022037234,45.616646,0,11.076097,54.515907,-0.0014880244,2.5108116,11.075856,57.449627,-9.4589157
19.5,0.18014681,-0.024144899,42.979473,0,11.076097,58.415909,-0.00161762,2.3086126,11.076306,60.819881,-9.4571323
20.8,0.17726851,-0.025735917,43.439114,0,11.076097,62.315914,-0.0017278538,2.266499,11.076231,62.899975,-9.4550972
22.1,0.16320966,-0.027793998,45.959656,0,11.076097,66.215904,-0.0018610287,2.0920303,11.075835,64.788231,-9.4531746
23.4,0.16015172,-0.030493287,48.806705,0,11.076097,70.115898,-0.0020386649,2.0297456,11.076278,67.547935,-9.4504738
24.7,0.18623707,-0.033173099,51.187363,0,11.076097,74.0159,-0.0022108571,2.3681343,11.075973,71.402039,-9.448123
26.0,0.18906814,-0.036350373,51.932369,0,11.076097,77.915901,-0.0024255572,2.4245498,11.075798,76.29744,-9.4454699
27.3,0.19948566,-0.039593216,52.283932,0,11.076097,81.81591,-0.0026408632,2.5521584,11.075714,80.962967,-9.4434471
28.6,0.20534942,-0.04269674,52.285965,0,11.076097,85.715904,-0.0028405231,2.6362791,11.07585,85.307198,-9.4415951
29.9,0.20278335,-0.045486514,52.29821,0,11.076097,89.615891,-0.0030317323,2.5902901,11.075817,89.47702,-9.4392881
31.2,0.20778447,-0.04883242,52.283939,0,11.076097,93.515892,-0.0032510024,2.6547053,11.076604,93.541153,-9.437541
32.5,0.21086121,-0.051314387,52.297398,0,11.076097,97.415894,-0.0034173371,2.6834996,11.076343,97.331253,-9.4346333
33.8,0.21576789,-0.054504074,52.635494,0,11.076097,101.3159,-0.0036339508,2.7535515,11.076367,101.00892,-9.4323149
35.1,0.22438897,-0.058023136,52.97607,0,11.076097,105.2159,-0.0038564212,2.8569934,11.076004,104.86248,-9.4300957
36.4,0.22715807,-0.061299451,53.31665,0,11.076097,109.11591,-0.0040822867,2.9019933,11.07595,108.6944,-9.4278383
37.7,0.22965001,-0.063958138,53.657223,0,11.076097,113.01591,-0.0042497767,2.9330723,11.07584,112.56365,-9.4257765
39.0,0.23688897,-0.066677608,53.975826,0,11.076097,116.91589,-0.004436553,3.0322988,11.07649,116.47739,-9.4243679
40.3,0.23846142,-0.069199584,53.975826,0,11.076097,120.8159,-0.0046075163,3.0402362,11.076546,120.59299,-9.4222221
41.6,0.23585546,-0.072084926,54.230873,0,11.076097,124.71589,-0.0047942931,3.0264568,11.076159,124.49375,-9.4195318
42.9,0.23743811,-0.075723045,54.305416,0,11.076097,128.61601,-0.0050371946,3.0426643,11.075945,128.32632,-9.4175243
44.2,0.24126835,-0.078765228,54.624023,0,11.076097,132.51588,-0.0052356678,3.0914898,11.075856,132.18082,-9.4150705
45.5,0.24369101,-0.082076132,54.925106,0,11.076097,136.41589,-0.0054586371,3.1178477,11.075788,136.01807,-9.4125795
46.8,0.24479556,-0.085069381,54.931637,0,11.076097,140.31589,-0.0056589823,3.1290569,11.076009,139.96469,-9.4105911
48.1,0.24548574,-0.087698162,55.239254,0,11.076097,144.21588,-0.0058293776,3.1544065,11.076623,143.90161,-9.4079151
49.4,0.2558645,-0.091440186,55.239262,0,11.076097,148.11588,-0.0060720998,3.2795899,11.07609,148.01036,-9.4060516
50.7,0.25916883,-0.09439408,55.492096,0,11.076097,152.01587,-0.0062661134,3.3187556,11.075569,151.79744,-9.4044905
52.0,0.26238695,-0.098254323,55.535885,0,11.076097,155.91586,-0.0065164408,3.3763149,11.075995,155.69997,-9.4020119
53.3,0.2525261,-0.10184348,55.744869,0,11.076097,159.81589,-0.0067592924,3.2423666,11.075763,159.56097,-9.3997707
54.6,0.25562707,-0.10504211,55.843506,0,11.076097,163.71588,-0.006970908,3.2767899,11.07517,163.45084,-9.3975983
55.9,0.26054829,-0.10748646,56.710514,0,11.076097,167.61588,-0.0071350085,3.3418782,11.076141,166.5173,-9.3954334
57.2,0.26717153,-0.11138607,57.808392,0,11.076097,171.51588,-0.0074007604,3.4352062,11.075867,169.89775,-9.3931456
58.5,0.26079288,-0.11563201,58.337399,0,11.076097,175.41588,-0.0076817549,3.3512397,11.075568,174.10544,-9.3908482
59.8,0.26510119,-0.11943568,58.59008,0,11.076097,179.31589,-0.0079267593,3.4071968,11.075534,178.62997,-9.3887339
61.1,0.26298103,-0.1237593,58.33744,0,11.076097,183.21588,-0.0082216747,3.3801126,11.07584,183.25838,-9.3861618
62.4,0.2634604,-0.12774871,57.858704,0,11.076097,187.11588,-0.0084768636,3.3916373,11.076543,187.70204,-9.3845482
63.7,0.26092267,-0.1317617,57.466412,0,11.076097,191.01587,-0.0087418081,3.336565,11.075918,191.77332,-9.3824463
65.0,0.26540485,-0.13517772,56.986088,0,11.076097,194.91586,-0.00897153,3.4194715,11.075408,195.68063,-9.3800716
66.3,0.26293308,-0.1379423,56.986088,0,11.076097,198.81587,-0.0091500795,3.3743455,11.075939,199.0248,-9.3776588
67.6,0.26468411,-0.14037687,57.134747,0,11.076097,202.71587,-0.0092971269,3.4065697,11.075677,202.58321,-9.375515
68.9,0.26609108,-0.14342527,57.662952,0,11.076097,206.61589,-0.0095045567,3.4122963,11.076451,205.96559,-9.3735504
70.2,0.25854051,-0.14648964,58.328506,0,11.076097,210.51588,-0.0097115142,3.3164511,11.076271,209.57498,-9.3716736
71.5,0.25647768,-0.15034674,58.853657,0,11.076097,214.41586,-0.0099570975,3.2986453,11.075641,213.31839,-9.3692884
72.8,0.25430751,-0.15407364,59.348129,0,11.076097,218.31586,-0.010208156,3.2724593,11.076273,217.32483,-9.3675947
74.1,0.25994521,-0.15806019,59.600826,0,11.076097,222.21587,-0.010472503,3.3342569,11.07559,221.56369,-9.3650665
75.4,0.25799003,-0.1615836,59.713318,0,11.076097,226.11586,-0.010706033,3.3195889,11.075654,225.7374,-9.3630333
76.7,0.25864118,-0.16545534,59.763924,0,11.076097,230.01587,-0.010960303,3.334662,11.075755,229.90459,-9.3608379
78.0,0.26170298,-0.16899313,59.745968,0,11.076097,233.91588,-0.01119298,3.3603671,11.0759,233.87868,-9.3592033
79.3,0.25261089,-0.17248347,59.771656,0,11.076097,237.81587,-0.01142587,3.244379,11.076609,237.76698,-9.3567591
80.6,0.2600874,-0.17605463,59.868645,0,11.076097,241.71585,-0.011654526,3.3495879,11.076179,241.45488,-9.35392
81.9,0.25140491,-0.17959671,60.220638,0,11.076097,245.61588,-0.011894214,3.2387757,11.076296,245.11459,-9.351613
83.2,0.26007363,-0.1833975,60.556637,0,11.076097,249.51585,-0.0121475,3.3548365,11.075827,249.00459,-9.3487768
84.5,0.25956216,-0.18732198,60.618839,0,11.076097,253.41586,-0.01239664,3.3431215,11.075825,253.08624,-9.3472624
85.8,0.26274243,-0.19074631,60.785385,0,11.076097,257.3161,-0.012622596,3.3968546,11.076906,257.04874,-9.3459082
87.1,0.26483756,-0.19415447,60.837719,0,11.076097,261.21613,-0.012855215,3.4125657,11.076207,260.91293,-9.3441067
88.4,0.25424081,-0.19829564,61.207909,0,11.076097,265.11584,-0.013125074,3.2788827,11.076159,264.60083,-9.3420334
89.7,0.25787038,-0.2012063,61.403416,0,11.076097,269.01587,-0.013325261,3.3367567,11.075494,268.50241,-9.3394661
91.0,0.26156169,-0.20514913,61.682751,0,11.076097,272.91586,-0.013570968,3.3711083,11.076583,272.42123,-9.3373003
92.3,0.26288611,-0.20910916,61.896976,0,11.076097,276.81586,-0.013837805,3.4010556,11.076182,276.29227,-9.3346004
93.6,0.25711864,-0.21311224,61.907955,0,11.076097,280.71582,-0.014101719,3.3258491,11.075133,280.32962,-9.3321819
94.9,0.25610721,-0.21687113,62.158562,0,11.076097,284.61581,-0.014348696,3.3117752,11.07598,284.20135,-9.3303175
96.2,0.25796556,-0.22152624,62.336418,0,11.076097,288.51584,-0.014649789,3.3384645,11.075735,288.16443,-9.3284063
97.5,0.26011062,-0.22556251,62.336433,0,11.076097,292.41583,-0.01492208,3.3663554,11.075725,292.36853,-9.326952
98.8,0.25778612,-0.22947605,62.116707,0,11.076097,296.31586,-0.015178133,3.337604,11.076584,296.56067,-9.3242369
100.1,0.25432846,-0.2330468,61.907967,0,11.076097,300.21588,-0.01541575,3.2929385,11.076423,300.53271,-9.322156
101.4,0.25391376,-0.23610616,62.029629,0,11.076097,304.11584,-0.015609818,3.2810585,11.076306,304.12357,-9.3196688
102.7,0.26270157,-0.23925345,62.129307,0,11.076097,308.01584,-0.015823305,3.40783,11.076446,307.74203,-9.318265
104.0,0.26093611,-0.24298076,62.545162,0,11.076097,311.91583,-0.016062837,3.3882339,11.076177,311.20898,-9.315958
105.3,0.26007697,-0.24664618,63.05962,0,11.076097,315.81583,-0.016296936,3.3666234,11.07659,314.83826,-9.3135452
106.6,0.26258183,-0.25013086,63.577873,0,11.076097,319.71582,-0.016534632,3.4026484,11.075901,318.47034,-9.3119221
107.9,0.25897586,-0.25422865,64.163841,0,11.076097,323.61584,-0.016804744,3.3585484,11.075977,322.37036,-9.309247
109.2,0.26183131,-0.25855196,64.736565,0,11.076097,327.51584,-0.01708697,3.3920021,11.075612,326.15979,-9.3068743
110.5,0.25956163,-0.26309112,64.929192,0,11.076097,331.41586,-0.017382579,3.358969,11.076311,330.54462,-9.3047943
111.8,0.26145318,-0.26751176,64.929192,0,11.076097,335.31586,-0.017673813,3.406471,11.075646,335.11124,-9.3026476
113.1,0.25701231,-0.27152109,64.745384,0,11.076097,339.21585,-0.017943382,3.3446262,11.076465,339.37766,-9.3005772
114.4,0.25631428,-0.27567744,64.679657,0,11.076097,343.11584,-0.018213274,3.3366416,11.076734,343.4079,-9.2981329
115.7,0.26196575,-0.27945268,64.483444,0,11.076097,347.01581,-0.01845381,3.4060788,11.076126,347.42804,-9.2959337
117.0,0.25986952,-0.28309491,64.357918,0,11.076097,350.9158,-0.018695014,3.3655353,11.075676,351.17786,-9.2938871
118.3,0.2511591,-0.2873916,64.357918,0,11.076097,354.81583,-0.018973395,3.2532899,11.076092,354.89276,-9.2918596
119.6,0.262373,-0.29077196,64.561142,0,11.076097,358.71585,-0.019200839,3.3948121,11.076009,358.35294,-9.2900038
120.9,0.26321104,-0.29466274,65.046082,0,11.076097,362.61588,-0.019451912,3.419405,11.07635,361.81076,-9.287796
122.2,0.25845414,-0.298729,65.478485,0,11.076097,366.51587,-0.019714579,3.3604183,11.075648,365.52481,-9.2855444
123.5,0.25942913,-0.30246285,65.840027,0,11.076097,370.41583,-0.019954357,3.3634257,11.07663,369.409,-9.2834816
124.8,0.25303426,-0.30676258,66.192619,0,11.076097,374.31583,-0.020232039,3.2840405,11.074874,373.27679,-9.2808809
126.1,0.26174188,-0.31085369,66.507545,0,11.076097,378.21582,-0.020499092,3.4101088,11.076195,377.36041,-9.2787371
127.4,0.26380435,-0.31500292,66.573189,0,11.076097,382.11581,-0.020769689,3.4342241,11.076481,381.56046,-9.2764797
128.7,0.2671594,-0.31951427,66.708977,0,11.076097,386.01581,-0.021072889,3.4791975,11.075566,385.61176,-9.273941
130.0,0.2701984,-0.32455105,66.884758,0,11.076097,389.91583,-0.021402985,3.5118411,11.07576,389.43906,-9.2721281
131.3,0.27063116,-0.32965243,67.049561,0,11.076097,393.81583,-0.021732245,3.5278072,11.075747,393.44763,-9.2698917
132.6,0.26876116,-0.33512759,67.225014,0,11.076097,397.71585,-0.022088872,3.5010235,11.075914,397.33176,-9.2677507
133.9,0.27363846,-0.34010428,67.225342,0,11.076097,401.61581,-0.022406561,3.5707777,11.07668,401.39542,-9.2657413
135.2,0.27179667,-0.34463334,67.247452,0,11.076097,405.51581,-0.02269735,3.5344346,11.076795,405.2984,-9.2636375
136.5,0.27108577,-0.34796089,67.369431,0,11.076097,409.41583,-0.02291335,3.5340188,11.076283,409.31436,-9.2618017
137.8,0.27110478,-0.35152435,67.344795,0,11.076097,413.3158,-0.02314356,3.5234742,11.076327,413.3494,-9.2597084
139.1,0.28150779,-0.35526642,67.049568,0,11.076097,417.21579,-0.023389729,3.6749163,11.076534,417.7554,-9.2577419
140.4,0.40982372,-0.35750335,66.709,0,11.076097,421.11581,-0.023541505,5.3440623,11.076243,422.01569,-9.2554493
141.7,0.54379785,-0.360158,66.030869,0,11.076097,425.01584,-0.023717407,7.0744891,11.075921,426.52667,-9.2527914
143.0,0.64847952,-0.36292237,65.304344,0,11.076097,428.91583,-0.023900375,8.4578791,11.075564,430.74396,-9.2501945
144.3,0.67462403,-0.36640787,64.374359,0,11.076097,432.81586,-0.024126777,8.8007183,11.074998,435.04868,-9.2474766
145.6,0.7783379,-0.36884812,64.171112,0,11.076097,436.71582,-0.024278274,10.150752,11.075827,437.81491,-9.2455997
146.9,0.9247213,-0.37067172,64.555496,0,11.076097,440.61578,-0.024400789,12.072791,11.076553,440.36169,-9.2436018
148.2,0.98258352,-0.37404186,64.919327,0,11.076097,444.51578,-0.024626194,12.810947,11.075809,443.8812,-9.2411404
149.5,0.99275243,-0.37851861,64.881859,0,11.076097,448.41583,-0.024917023,12.956717,11.076238,448.27759,-9.2384834
150.8,0.99517888,-0.38323933,64.555756,0,11.076097,452.31583,-0.025222989,12.99728,11.076921,452.71448,-9.2359791
152.1,1.0054742,-0.38773394,64.272644,0,11.076097,456.21585,-0.025522064,13.138965,11.075955,456.83179,-9.2342339
153.4,1.0185932,-0.39152479,64.17115,0,11.076097,460.11584,-0.025772151,13.30852,11.076077,460.52399,-9.2324886
154.7,1.0194676,-0.39544919,63.973396,0,11.076097,464.01584,-0.026019933,13.332311,11.076151,464.36115,-9.2307053
156.0,1.0143226,-0.39929557,63.775841,0,11.076097,467.9158,-0.026272781,13.25418,11.076667,468.35938,-9.2290001
157.3,1.024888,-0.40302172,63.580414,0,11.076097,471.81583,-0.026521312,13.40184,11.076308,472.25076,-9.2259007
158.6,1.0229545,-0.40675002,63.400719,0,11.076097,475.71579,-0.026768172,13.356348,11.075603,476.14444,-9.2237787
159.9,1.0236254,-0.40964299,63.263378,0,11.076097,479.61581,-0.026964732,13.374355,11.075525,480.06479,-9.2213516
161.2,1.029989,-0.41258681,63.362511,0,11.076097,483.51584,-0.027147869,13.45667,11.076299,483.56586,-9.2190523
162.5,1.0397867,-0.41628471,63.369137,0,11.076097,487.41583,-0.027382828,13.602727,11.076141,487.2504,-9.2168293
163.8,1.0413622,-0.42109481,63.577873,0,11.076097,491.31583,-0.027693145,13.621626,11.076004,490.9577,-9.2150755
165.1,1.048394,-0.42545554,63.851067,0,11.076097,495.21585,-0.027980972,13.719266,11.075054,494.68466,-9.2131271
166.4,1.0516438,-0.42762727,63.871204,0,11.076097,499.11584,-0.028136898,13.763238,11.0756,498.91226,-9.2107658
167.7,1.0506231,-0.42831355,62.174747,0,11.076097,499.99884,-0.028181648,13.765793,11.07505,502.80707,-9.2101574
169.0,1.0269377,-0.42690328,59.140034,0,11.076097,499.99884,-0.028088327,13.449077,11.076017,505.22424,-9.2101879
170.3,1.0215361,-0.42535093,55.845264,0,11.076097,499.99884,-0.027973512,13.382125,11.076824,505.58304,-9.2099495
171.6,1.0073582,-0.42235619,53.320145,0,11.076097,499.99884,-0.0277925,13.200194,11.075222,504.35828,-9.2096319
172.9,0.99706173,-0.41969132,52.635502,0,11.076097,499.99884,-0.027609564,13.046181,11.075859,502.10394,-9.2095842
174.2,0.9930436,-0.41712987,53.650906,0,11.076097,499.99884,-0.027454471,12.988054,11.076111,499.745,-9.2100096
175.5,0.98783505,-0.41684976,55.233719,0,11.076097,499.99884,-0.027420433,12.935795,11.076661,498.2746,-9.2094774
176.8,0.97013414,-0.41708139,56.775532,0,11.076097,499.99884,-0.027440393,12.698781,11.076321,497.71124,-9.2088175
178.1,0.88935494,-0.41944048,57.836487,0,11.076097,499.99884,-0.027594484,11.637672,11.07619,497.97748,-9.2090664
179.4,0.84332693,-0.42199686,58.585667,0,11.076097,499.99884,-0.027762171,11.035306,11.076371,498.5994,-9.2089157
180.7,0.80469108,-0.42483318,58.628685,0,11.076097,499.99884,-0.027939266,10.537928,11.075939,499.33426,-9.2087917
182.0,0.78760034,-0.42600259,58.471912,0,11.076097,499.99884,-0.028024025,10.304872,11.07711,500.01474,-9.2088938
183.3,0.78385186,-0.42893738,58.07391,0,11.076097,499.99884,-0.028190061,10.25886,11.076494,500.41953,-9.2091608
184.6,0.77449048,-0.43120062,57.551258,0,11.076097,499.99884,-0.028350038,10.14121,11.075703,500.74005,-9.2091265
185.9,0.77765894,-0.43108955,57.073887,0,11.076097,499.99884,-0.028349778,10.179703,11.076305,500.83789,-9.2092905
187.2,0.77436894,-0.43000036,56.711445,0,11.076097,499.99884,-0.028277406,10.135832,11.076095,500.67642,-9.2098141
188.5,0.76216036,-0.43029952,56.711422,0,11.076097,499.99884,-0.028282149,9.976675,11.075914,500.31287,-9.2093554
189.8,0.75389874,-0.43120345,56.711422,0,11.076097,499.99884,-0.028339962,9.8842888,11.075598,499.97324,-9.2095594
191.1,0.75614697,-0.43221965,56.986084,0,11.076097,499.99884,-0.028403068,9.8913517,11.075634,499.79816,-9.2096567
192.4,0.74838728,-0.43326479,57.164555,0,11.076097,499.99884,-0.028471837,9.8098822,11.075369,499.74664,-9.2092352
193.7,0.75494552,-0.43410343,57.260738,0,11.076097,499.99884,-0.028530184,9.8687353,11.076974,499.73865,-9.2092829
195.0,0.76996577,-0.4369975,57.260738,0,11.076097,499.99884,-0.028704213,10.090166,11.075946,499.96143,-9.2093916
196.3,0.76573551,-0.43598074,56.986095,0,11.076097,499.99884,-0.02865538,10.033483,11.075396,500.12799,-9.2092123
197.6,0.75980359,-0.43637231,56.713459,0,11.076097,499.99884,-0.028675385,9.9623032,11.075834,500.32349,-9.208847
198.9,0.75541508,-0.43749928,56.71143,0,11.076097,499.99884,-0.028737957,9.9056015,11.07685,500.22375,-9.2087231
200.2,0.7587356,-0.43842357,56.425793,0,11.076097,499.99884,-0.028799681,9.9383821,11.076562,500.31735,-9.2089758
201.5,0.75211424,-0.43915266,56.329937,0,11.076097,499.99884,-0.028852006,9.8498278,11.075119,500.28186,-9.208725
202.8,0.76018023,-0.44150847,56.129154,0,11.076097,499.99884,-0.028992798,9.9635468,11.076674,500.17902,-9.2086411
204.1,0.76718408,-0.43974432,56.144012,0,11.076097,499.99884,-0.028901415,10.068736,11.076557,500.1218,-9.2085266
205.4,0.75891525,-0.4400461,56.32642,0,11.076097,499.99884,-0.028912578,9.958252,11.075926,499.96475,-9.2085094
206.7,0.76109725,-0.44132012,56.423996,0,11.076097,499.99884,-0.028990515,9.991291,11.075297,499.85541,-9.2085962
208.0,0.75423294,-0.44234297,56.425777,0,11.076097,499.99884,-0.02906142,9.8888664,11.075121,499.95258,-9.2085838
209.3,0.7563895,-0.44298625,56.425777,0,11.076097,499.99884,-0.029103069,9.8952217,11.076193,500.05682,-9.2082691
210.6,0.7667191,-0.44587627,56.425777,0,11.076097,499.99884,-0.02928587,10.058938,11.076878,500.01889,-9.2083712
211.8967,0.76973945,0.011522103,56.269943,0,11.076097,499.99884,0.00075744063,9.7802076,11.076287,500.1235,-9.208252
211.9492,0.77087003,0.011310023,56.425781,0,11.076099,8.2176494e-14,0.0010037241,9.7886486,11.076406,500.12054,-9.2091475
211.9518,0.79538554,0.009988606,56.425781,0,11.076099,1.5376164e-31,0.00090449862,9.957427,11.075406,500.14386,-9.2089653
211.9544,0.76140761,0.013411244,56.425781,0,11.076099,0.0,0.00095002074,9.7198324,11.074708,500.16718,-9.2069187
211.957,0.75772464,0.018587621,46.813519,0,11.076099,0.0,0.001021788,9.6572752,11.074673,500.16,-9.2074413
211.9596,0.82150561,0.014873639,32.113419,0,11.076099,0.0,0.0007897435,10.299077,11.072853,500.13669,-9.2077103
211.9622,0.7394467,0.016840385,17.413313,0,11.076099,0.0,0.00088127609,9.3944397,11.078083,500.11334,-9.2084732
211.9648,0.75266784,0.012585916,2.7132082,0,11.076099,0.0,0.00075980864,9.6239119,11.074149,500.09003,-9.2077379
211.9674,0.75508165,0.010517143,0.0,0,11.076099,0.0,0.00078200205,9.5565777,11.073256,500.06036,-9.2076845
211.97,0.7345022,0.0083927549,0.0,0,11.076099,0.0,0.0008017642,9.3420115,11.076443,500.02927,-9.2088461
211.9726,0.73065001,0.0095726717,0.0,0,11.076099,0.0,0.00085067278,9.2296619,11.075466,499.99817,-9.2084274
211.9752,0.73471773,0.012023913,0.0,0,11.076099,0.0,0.00099089392,9.4342709,11.075769,499.96704,-9.207715
211.9778,0.73249239,0.012181016,0.0,0,11.076099,0.0,0.00078789075,9.3350563,11.076033,499.98154,-9.2069616
211.9804,0.72933877,0.01585706,0.0,0,11.076099,0.0,0.0008899509,9.2778883,11.076226,499.99707,-9.2082443
211.983,0.73949945,0.011748069,0.0,0,11.076099,0.0,0.00062754122,9.4377642,11.077794,500.01263,-9.2091684
211.9856,0.72362906,0.014202951,0.0,0,11.076099,0.0,0.00069939828,9.2165022,11.078035,500.02386,-9.2078085
211.9882,0.73558116,0.0089145126,0.0,0,11.076099,0.0,0.00052803103,9.3461142,11.075597,500.00833,-9.2081861
211.9908,0.73260564,0.0098389797,0.0,0,11.076099,0.0,0.00076073263,9.1985168,11.07647,499.99277,-9.208601
211.9934,0.72177935,0.0084737819,0.0,0,11.076099,0.0,0.00081970484,9.2476988,11.077354,499.97723,-9.2094498
211.996,0.72071153,0.0091735804,0.0,0,11.076099,0.0,0.00081660086,9.1021643,11.077974,499.97101,-9.2091274
211.9986,0.71819204,0.011319679,0.0,0,10.826047,0.0,0.00095838215,9.0970173,11.076844,499.98654,-9.2082777
212.0012,0.73061121,0.011185262,0.0,0,10.434992,0.0,0.00075568323,9.2403154,11.076069,500.00211,-9.2080746
212.0038,0.73273349,0.015081336,0.0,0,10.043937,0.0,0.00079339015,9.3239965,11.004763,500.01767,-9.2084007
212.0064,0.75680286,0.012073614,0.0,0,9.6528826,0.0,0.00065491354,9.7097607,10.756984,499.97937,-9.2083549
212.009,0.73902428,0.015763545,0.0,0,9.2678022,0.0,0.00076933624,9.392375,10.366319,499.8783,-9.2077093
212.0116,4.3324561,0.13391678,0.0,0,8.8873701,0.0,0.0085078431,54.118687,9.9172029,499.77722,-9.2059546
212.0142,4.4710164,0.71474665,0.0,0,8.5188427,0.0,0.048444312,53.643917,9.3337936,499.67615,-9.2058964
212.0168,4.8640313,1.1873351,0.0,0,8.1570263,0.0,0.082522228,57.089424,8.8364992,499.34735,-9.2046051
212.0194,4.9388614,1.6124625,0.0,0,7.8078017,0.0,0.11357757,56.106674,8.4330292,498.88086,-9.2038937
212.022,5.1761956,1.9448742,0.0,0,7.4635615,0.0,0.13858499,57.424652,8.0748959,498.41434,-9.204237
212.0246,5.3003731,2.2673151,0.0,0,7.1326861,0.0,0.16340521,57.224575,7.7414312,497.94781,-9.204298
212.0272,5.3475909,2.5795245,0.0,0,6.805294,0.0,0.18800159,56.309513,7.4199944,497.06644,-9.2040195
212.0298,5.5053959,2.886158,0.0,0,6.4917493,0.0,0.2130423,56.674919,7.1097293,496.0712,-9.2044764
212.0324,5.6397715,3.1973875,0.0,0,6.1802692,0.0,0.23891862,56.574112,6.7971678,495.07596,-9.2045765
212.035,5.8008103,3.50844,0.0,0,5.8832202,0.0,0.26594299,56.645977,6.479845,494.08072,-9.2045603
212.0376,6.0190048,3.8224885,0.0,0,5.5874305,0.0,0.29395252,57.0513,6.1652408,492.37857,-9.2052345
212.0402,6.1361194,4.139441,0.0,0,5.3054819,0.0,0.32291847,56.562065,5.8453817,490.63626,-9.2059803
212.0428,6.317276,4.4502349,0.0,0,5.0250378,0.0,0.35209057,56.53196,5.5294781,488.89395,-9.2057943
212.0454,6.5002103,4.7488394,0.0,0,4.7569733,0.0,0.38049844,56.536385,5.2355061,486.84528,-9.205409
212.048,6.5961547,5.036118,0.0,0,4.4912357,0.0,0.40862823,55.849892,4.9537535,482.25919,-9.2063599
212.0506,6.7776942,5.3165588,0.0,0,4.236227,0.0,0.4367592,55.730637,4.6752973,477.6731,-9.2058744
212.0532,6.985518,5.5766726,0.0,0,3.9843993,0.0,0.46395871,55.906029,4.4082975,473.08701,-9.2048521
212.0558,7.1441894,5.8377056,0.0,0,3.7418714,0.0,0.49196357,55.613716,4.1467657,469.02298,-9.2047024
212.0584,7.32265,6.0873876,0.0,0,3.5032594,0.0,0.52014357,55.34145,3.8914988,466.37561,-9.2055416
212.061,7.5624433,6.3352695,0.0,0,3.2725353,0.0,0.54872078,55.589722,3.6457076,463.72824,-9.2037687
212.0636,7.7542143,6.577879,0.0,0,3.0464017,0.0,0.57755888,55.460442,3.4053931,461.08087,-9.2038965
212.0662,8.0006247,6.8092246,0.0,0,2.8269095,0.0,0.60535932,55.537224,3.16945,456.39697,-9.2033997
212.0688,8.256567,7.0404372,0.0,0,2.6126189,0.0,0.63369793,55.759735,2.9411571,449.02246,-9.2037535
212.0714,8.5022678,7.2646151,0.0,0,2.4038389,0.0,0.66172874,55.868561,2.72247,441.64795,-9.2046118
212.074,8.7978516,7.4839153,0.0,0,2.2007923,0.0,0.68986648,56.124832,2.5067096,434.27341,-9.2044325
212.0766,9.1346254,7.6944346,0.0,0,2.0022042,0.0,0.71826214,56.626347,2.2940965,428.46527,-9.2021427
212.0792,9.4763994,7.9046102,0.0,0,1.8098006,0.0,0.74754393,57.061974,2.0846796,423.73508,-9.2023335
212.0818,9.8111429,8.1054592,0.0,0,1.6208847,0.0,0.7766484,57.403568,1.8821419,419.00488,-9.2039709
212.0844,10.206356,8.2999678,0.0,0,1.438562,0.0,0.80604208,58.043472,1.6887413,414.27472,-9.2037659
212.087,10.590275,8.4895515,0.0,0,1.2588501,0.0,0.8353191,58.471466,1.4975119,409.29587,-9.2018604
212.0896,11.01196,8.6760254,0.0,0,1.0861095,0.0,0.86428583,59.014332,1.309882,404.23587,-9.2014952
212.0922,11.497795,8.8616514,0.0,0,0.91518545,0.0,0.89356369,59.880581,1.1333997,399.17587,-9.2007046
212.0948,11.995572,9.034997,0.0,0,0.75154674,0.0,0.92161995,60.731304,0.95573205,394.11588,-9.2000475
212.0974,12.513,9.2133179,0.0,0,0.5889948,0.0,0.95097369,61.528648,0.77954233,391.96835,-9.2003117
212.1,13.106143,9.3746738,0.0,0,0.43387961,0.0,0.97929031,62.62672,0.6113286,390.08984,-9.2008095
212.1026,11.405688,9.4576197,0.0,0,0.27941936,0.0,0.99484569,53.637531,0.48673737,388.21136,-9.2022238
212.1052,9.8257513,9.4699707,0.0,0,0.13225418,0.0,0.99774665,46.214272,0.43316782,387.22968,-9.2047796
212.1078,9.1733809,9.4724741,0.0,0,-0.014485062,0.0,0.99885184,43.072609,0.39767525,397.00269,-9.2058554
212.1104,8.8127871,9.4798212,0.0,0,-0.15795425,0.0,1.0010099,41.248535,0.36714035,406.7757,-9.2047844
212.113,8.8559761,9.4843674,0.0,0,-0.30142227,0.0,1.0015157,41.407593,0.32119924,416.54871,-9.2033596
212.1156,9.152215,9.4959793,0.0,0,-0.44489023,0.0,1.0030577,42.725601,0.25366044,425.16901,-9.2046833
212.1182,9.2680197,9.5042048,0.0,0,-0.58835822,0.0,1.0039155,43.212399,0.18158689,430.10907,-9.2042341
212.1208,9.2348557,9.5140018,0.0,0,-0.73182625,0.0,1.0048871,43.017704,0.11625066,435.04913,-9.2030134
212.1234,9.0358629,9.5161972,0.0,0,-0.87529421,0.0,1.0051426,42.137688,0.058464266,439.9892,-9.2037659
212.126,8.7770557,9.5195713,0.0,0,-1.0187622,0.0,1.0060476,40.929359,0.020323697,444.43237,-9.204608
212.1286,8.4176378,9.5184698,0.0,0,-0.91972256,499.99997,1.0065515,39.192833,-0.0029745721,448.1304,-9.2053566
212.1312,7.9077883,9.5173502,0.0,0,-0.4230293,500.0,1.007198,36.782719,-0.0056784879,451.82843,-9.2059736
212.1338,7.4769964,9.5178156,0.0,0,0.073664263,500.0,1.0078979,34.773129,0.0013976464,455.52646,-9.203845
212.1364,7.1743813,9.5212326,8.081748,0,0.5703581,500.0,1.0083038,33.313446,0.003504097,458.94659,-9.2054462
212.139,6.9547563,9.5249062,22.472736,0,1.0670513,500.0,1.0084205,32.322865,0.0072853705,462.14978,-9.2068882
212.1416,6.576663,9.523983,36.863728,0,1.5637451,500.0,1.0074208,30.607435,0.014282729,465.35297,-9.2063103
212.1442,5.4153848,9.5238867,51.254715,0,2.0604391,500.0,1.0063939,25.337303,0.079134114,468.55612,-9.2066822
212.1468,3.0139704,9.5060911,55.239258,0,2.5571322,500.0,1.0032994,14.331446,0.21876913,470.88455,-9.2085495
212.1494,-0.17963457,9.4726114,55.239258,0,3.0538261,500.0,0.99767506,-0.68214303,0.48305365,472.87805,-9.2116117
212.152,-0.32498959,9.423439,55.239258,0,3.5505195,500.0,0.98959196,-1.566206,1.0661418,474.87155,-9.2129774
212.1546,-0.044327401,9.444726,55.239258,0,4.0472131,500.0,0.9941318,-0.1733737,1.9210734,476.86505,-9.211462
212.1572,-0.034671418,9.4471855,53.135124,0,4.5439067,500.0,0.99499685,-0.17313914,2.769366,478.07941,-9.2109337
212.1598,0.99308991,9.4545183,50.756664,0,5.0406008,500.0,0.99611896,2.6095302,3.4302347,479.19217,-9.21175
212.1624,-0.023720052,9.4630785,48.378201,0,5.5372939,500.0,0.99680257,-0.053940915,3.925468,480.30496,-9.2116289
212.165,0.05257801,9.4614248,46.109619,0,6.0339875,500.0,0.99586588,0.16788311,4.3789964,481.41522,-9.2107353
212.1676,-0.13950802,9.4694338,46.109619,0,6.5306816,500.0,0.99643731,-0.67185551,4.8276463,482.47354,-9.2105694
212.1702,-0.058345664,9.4597321,46.109619,0,7.0273747,500.0,0.99483603,-0.23266946,5.2873168,483.53186,-9.2105103
212.1728,0.0026675393,9.4577665,46.109619,0,7.5240688,500.0,0.9948563,-0.037918489,5.7865729,484.59018,-9.2105618
212.1754,-0.090500407,9.4508104,45.621471,0,8.0207624,500.0,0.99439365,-0.3156378,6.3021088,485.62747,-9.2094479
212.178,-0.0045517948,9.4494991,43.271626,0,8.5174551,500.0,0.99486113,-0.086150192,6.8216686,486.58447,-9.2101774
212.1806,-0.027123865,9.4494696,40.921783,0,9.0141487,500.0,0.99548507,-0.16273408,7.3490586,487.54147,-9.209403
212.1832,-0.025796305,9.4513311,38.571945,0,9.5108433,500.0,0.99551797,-0.17855465,7.871305,488.4985,-9.2098551
212.1858,-0.091394328,9.4572659,37.089844,0,10.007537,500.0,0.99575824,-0.40794256,8.3853121,489.38641,-9.2092867
212.1884,-0.0016694298,9.4572258,37.089844,0,10.50423,500.0,0.99518275,-0.063902251,8.8901453,490.15634,-9.2063627
212.191,-0.019897755,9.4600134,37.089844,0,11.000923,500.0,0.99477053,-0.085315101,9.4032927,490.92627,-9.2077503
212.1936,-0.13515186,9.4538164,37.089844,0,11.497618,500.0,0.99390358,-0.60340834,9.9073973,491.69617,-9.2081795
212.1962,0.059823219,9.4527369,35.582714,0,11.99431,500.0,0.99398857,0.25111452,10.429964,492.40408,-9.2077818
212.1988,-0.14218235,9.4498558,32.743443,0,12.491004,500.0,0.99430823,-0.63866961,10.940382,493.05722,-9.2068329
212.2014,0.025812669,9.4485874,29.904171,0,12.987698,500.0,0.99493968,0.090478249,11.440921,493.71033,-9.207612
212.204,-0.11795133,9.4495926,27.064899,0,13.484391,500.0,0.99558377,-0.51516527,11.92902,494.36346,-9.2068806
212.2066,-0.015955471,9.4491024,26.191408,0,13.981086,500.0,0.99500167,-0.0964505,12.434258,494.91968,-9.2068958
212.2092,-0.11324737,9.4563761,26.191408,0,14.477778,500.0,0.99565637,-0.45114908,12.938424,495.43286,-9.2060814
212.2118,-0.034240518,9.4553633,26.191408,0,14.974472,500.0,0.9947443,-0.19633612,13.450211,495.94604,-9.2065678
212.2144,-0.0033416164,9.4596786,26.191408,0,15.471166,500.0,0.99457049,0.02493065,13.97088,496.4592,-9.2061596
212.217,-0.16138895,9.4526167,23.41993,0,15.967859,500.0,0.99357152,-0.82795572,14.488566,496.93253,-9.2051153
212.2196,0.051639918,9.4500294,20.174229,0,16.464554,500.0,0.9936769,0.32888815,14.992559,497.39905,-9.2069578
212.2222,-0.047869418,9.4484844,16.928528,0,16.961246,500.0,0.99434429,-0.31912386,15.483895,497.86554,-9.2054834
212.2248,-0.0011147917,9.4477091,13.73291,0,17.457939,500.0,0.99460077,0.040374812,15.979982,498.33096,-9.2061338
212.2274,-0.079674564,9.4489031,13.73291,0,17.954634,500.0,0.99534744,-0.37417507,16.466446,498.72751,-9.2058792
212.23,0.0022615851,9.4479494,13.73291,0,18.0,500.0,0.99486655,-0.0065757204,16.958942,499.12405,-9.2054367
212.2326,-0.10242104,9.4558601,13.73291,0,18.0,500.0,0.99527937,-0.4323166,17.434462,499.5206,-9.2061825
212.2352,0.011258702,9.4552441,13.099766,0,18.0,500.0,0.99466687,0.070244931,17.855171,499.90338,-9.2069559
212.2378,-0.033102836,9.4620218,9.5220537,0,18.0,500.0,0.994986,-0.19007595,18.200649,500.22217,-9.2091236
212.2404,-0.022338735,9.4567747,5.9443417,0,18.0,500.0,0.9944374,-0.090529092,18.449448,500.54095,-9.2131462
212.243,-0.031758863,9.4640245,2.3666301,0,18.0,500.0,0.99613589,-0.16508278,18.552561,500.85974,-9.2191067
212.2456,-0.016171947,9.4678421,0.0,0,18.0,500.0,0.99769658,-0.18594798,18.495302,501.15485,-9.2276678
212.2482,0.19894902,9.4772091,0.0,0,18.0,500.0,1.0000669,0.99473202,18.337912,501.40366,-9.2380047
212.2508,0.75526762,9.4899349,0.0,0,18.0,500.0,1.0026518,3.5125411,18.185936,501.65244,-9.2535963
212.2534,0.48273125,9.4873457,0.0,0,18.0,500.0,1.001938,2.2518137,18.083111,501.90125,-9.2741594
212.256,0.49588779,9.4909925,0.0,0,18.0,500.0,1.0017209,2.3053179,18.036297,502.15005,-9.2952585
212.2586,0.52867752,9.4905491,0.0,0,18.0,500.0,1.0009834,2.4901211,18.031118,502.39886,-9.3198462
212.2612,0.46769261,9.4938231,0.0,0,18.0,500.0,1.0006804,2.2235477,18.048012,502.64767,-9.3432608
212.2638,0.50371462,9.4870682,0.0,0,18.0,500.0,0.99999166,2.3551385,18.079498,502.89648,-9.3650808
212.2664,0.53065085,9.487072,0.0,0,18.0,500.0,1.0003359,2.52491,18.101896,503.12473,-9.3874683
212.269,0.49449047,9.4821005,0.0,0,18.0,500.0,1.0003991,2.3080335,18.122862,503.34241,-9.4070101
212.2716,0.4993304,9.482131,0.0,0,18.0,500.0,1.0010886,2.3240964,18.137642,503.56012,-9.425312
212.2742,0.54863775,9.483139,0.0,0,18.0,500.0,1.0015416,2.563695,18.144526,503.77783,-9.4452419
212.2768,0.49278644,9.4862118,0.0,0,18.0,500.0,1.0015368,2.3409038,18.139948,503.95712,-9.4647312
212.2794,0.51380134,9.4920006,0.0,0,18.0,500.0,1.0017629,2.402725,18.140268,504.12817,-9.4823589
212.282,0.55806738,9.489912,0.0,0,18.0,500.0,1.0007195,2.5695775,18.133518,504.29919,-9.5017099
212.2846,0.50118876,9.4937115,0.0,0,18.0,500.0,1.0008134,2.3915823,18.131689,504.47025,-9.5216532
212.2872,0.51319838,9.4888926,0.0,0,18.0,500.0,1.0002638,2.393822,18.130976,504.64124,-9.5404081
212.2898,0.54676473,9.4899645,0.0,0,18.0,500.0,1.0009049,2.542331,18.12923,504.81223,-9.5611172
212.2924,0.51002878,9.4858513,0.0,0,18.0,500.0,1.0010345,2.4264917,18.120853,504.98322,-9.5807819
212.295,0.50190037,9.4853296,0.0,0,18.0,500.0,1.0016586,2.3265698,18.120598,505.14966,-9.6001358
212.2976,0.55648381,9.4875374,0.0,0,18.0,500.0,1.0024031,2.5637491,18.119137,505.28955,-9.6211071
212.3002,0.52256113,9.4888182,0.0,0,18.0,500.0,1.0019706,2.424901,18.114195,505.42941,-9.6407785
212.3028,0.50035077,9.494585,0.0,0,18.0,500.0,1.0021887,2.3338752,18.110106,505.56931,-9.6593742
212.3054,0.54444909,9.492734,0.0,0,18.0,500.0,1.0012631,2.5422025,18.112732,505.69962,-9.680171
212.308,0.52959841,9.4968805,0.0,0,18.0,500.0,1.0012234,2.5029373,18.106421,505.80841,-9.7001781
212.3106,0.49528399,9.4903393,0.0,0,18.0,500.0,1.0005515,2.3033049,18.107565,505.91721,-9.7184086
212.3132,0.54527563,9.4881802,0.0,0,18.0,500.0,1.0008185,2.5172935,18.103689,506.026,-9.7385998
212.3158,0.54128253,9.4860382,0.0,0,18.0,500.0,1.0011646,2.5245714,18.101616,506.12387,-9.7593069
212.3184,0.46771473,9.4827995,0.0,0,18.0,500.0,1.0012499,2.2108586,18.100912,506.20935,-9.7789583
212.321,0.53474337,9.4861698,0.0,0,18.0,500.0,1.0021163,2.5011919,18.099888,506.29483,-9.798069
212.3236,0.52217436,9.4876747,0.0,0,18.0,500.0,1.0017806,2.4533806,18.099104,506.38031,-9.8174248
212.3262,0.48448336,9.4931021,0.0,0,18.0,500.0,1.0020028,2.2955546,18.10088,506.47559,-9.836731
212.3288,0.54598963,9.4903479,0.0,0,18.0,500.0,1.0008411,2.4883521,18.101028,506.5766,-9.8563442
212.3314,0.54608881,9.4963045,0.0,0,18.0,500.0,1.0012242,2.5574243,18.093121,506.67761,-9.8758869
212.334,0.48800367,9.4891176,0.0,0,18.0,500.0,1.0003321,2.2950819,18.094599,506.77866,-9.8949614
212.3366,0.52710599,9.4880199,0.0,0,18.0,500.0,1.0007696,2.4564285,18.093863,506.8735,-9.9135408
212.3392,0.5503583,9.4872637,0.0,0,18.0,500.0,1.0015211,2.6088228,18.097223,506.96677,-9.9355087
212.3418,0.49004403,9.4829512,0.0,0,18.0,500.0,1.0014049,2.3071022,18.09605,507.06003,-9.9569254
212.3444,0.5340656,9.486146,0.0,0,18.0,500.0,1.0020794,2.4346101,18.09691,507.15329,-9.9767857
212.347,0.56018931,9.4892559,0.0,0,18.0,500.0,1.0019079,2.6301954,18.091034,507.19467,-9.9956799
212.3496,0.4970513,9.493824,0.0,0,18.0,500.0,1.001907,2.3616984,18.09094,507.23352,-10.015465
212.3522,0.52731603,9.489193,0.0,0,18.0,500.0,1.0004636,2.4569116,18.090578,507.2724,-10.034381
212.3548,0.58052897,9.494194,0.0,0,18.0,500.0,1.0007832,2.6910324,18.088219,507.31485,-10.054474
212.3574,0.50683582,9.4906569,0.0,0,18.0,500.0,1.0007544,2.3642416,18.087231,507.38477,-10.073812
212.36,0.53265584,9.4891968,0.0,0,18.0,500.0,1.0011461,2.4526086,18.088634,507.45471,-10.092155
212.3626,0.5744136,9.48804,0.0,0,18.0,500.0,1.0017018,2.6721926,18.088743,507.52463,-10.113832
212.3652,0.52309591,9.4875917,0.0,0,18.0,500.0,1.0021367,2.4412775,18.084864,507.59671,-10.135273
212.3678,0.52417451,9.4876432,0.0,0,18.0,500.0,1.0023537,2.4023433,18.083248,507.67444,-10.154812
212.3704,0.57510173,9.4876518,0.0,0,18.0,500.0,1.0016065,2.6683981,18.083519,507.75214,-10.172246
212.373,0.52322644,9.4939795,0.0,0,18.0,500.0,1.0018828,2.4365783,18.082815,507.82983,-10.192598
212.3756,0.52227676,9.4902534,0.0,0,18.0,500.0,1.0007423,2.387018,18.082878,507.8905,-10.212696
212.3782,0.57081258,9.4930267,0.0,0,18.0,500.0,1.0006104,2.6457911,18.082052,507.92938,-10.232605
212.3808,0.52779639,9.4895773,0.0,0,18.0,500.0,1.000707,2.4727829,18.077499,507.96823,-10.252899
212.3834,0.51676446,9.4873285,0.0,0,18.0,500.0,1.0008124,2.4149594,18.081512,508.00711,-10.273081
212.386,0.57248098,9.4855156,0.0,0,18.0,500.0,1.0013613,2.6292243,18.078516,508.03662,-10.291986
212.3886,0.52921653,9.4867315,0.0,0,18.0,500.0,1.0019634,2.481457,18.077396,508.05994,-10.311811
212.3912,0.4993194,9.4879713,0.0,0,18.0,500.0,1.002188,2.355834,18.080603,508.08325,-10.329743
212.3938,0.56334925,9.486701,0.0,0,18.0,500.0,1.0012703,2.6108558,18.079643,508.10657,-10.349056
212.3964,0.52919316,9.4941673,0.0,0,18.0,500.0,1.0018086,2.533972,18.074621,508.15948,-10.36949
212.399,0.48641828,9.4887724,0.0,0,18.0,500.0,1.0005509,2.2812796,18.071884,508.22165,-10.389387
212.4016,0.57390821,9.4933834,0.0,0,18.0,500.0,1.0005978,2.6523385,18.07572,508.28381,-10.407083
212.4042,0.54522443,9.488122,0.0,0,18.0,500.0,1.0003852,2.5531628,18.072037,508.34598,-10.429191
212.4068,0.50622147,9.4868832,0.0,0,18.0,500.0,1.0007172,2.3728933,18.075031,508.3938,-10.448778
212.4094,0.56232589,9.48458,0.0,0,18.0,500.0,1.0013105,2.5810175,18.074312,508.44043,-10.468716
212.412,0.55837083,9.486042,0.0,0,18.0,500.0,1.0018536,2.6005325,18.072283,508.48706,-10.487812
212.4146,0.51174903,9.4874678,0.0,0,18.0,500.0,1.0022418,2.4013331,18.067566,508.52972,-10.507384
212.4172,0.55290312,9.4874077,0.0,0,18.0,500.0,1.0014948,2.5560286,18.069317,508.52972,-10.525603
212.4198,0.57767659,9.4954729,0.0,0,18.0,500.0,1.0017155,2.7125261,18.072086,508.52972,-10.547156
212.4224,0.51081544,9.4921141,0.0,0,18.0,500.0,1.0009671,2.3988414,18.074511,508.52972,-10.565843
212.425,0.56348062,9.4963045,0.0,0,18.0,500.0,1.0011559,2.6140418,18.069935,508.53354,-10.585397
212.4276,0.58311307,9.4901028,0.0,0,18.0,500.0,1.0007484,2.7226737,18.0665,508.5491,-10.605592
212.4302,0.5192191,9.4873686,0.0,0,18.0,500.0,1.0010185,2.4453871,18.068911,508.56464,-10.628179
212.4328,0.54643887,9.4848671,0.0,0,18.0,500.0,1.0012776,2.5179286,18.069017,508.58017,-10.646806
212.4354,0.59260839,9.4850988,0.0,0,18.0,500.0,1.0017481,2.7601023,18.068535,508.58939,-10.665835
212.438,0.52698082,9.4873257,0.0,0,18.0,500.0,1.0021863,2.46244,18.066259,508.58939,-10.685516
212.4406,0.54188758,9.4863052,0.0,0,18.0,500.0,1.0012838,2.5449603,18.066853,508.58939,-10.70395
212.4432,0.58748412,9.4959755,0.0,0,18.0,500.0,1.0018564,2.7566509,18.069326,508.58939,-10.724913
212.4458,0.52839237,9.4921618,0.0,0,18.0,500.0,1.0010294,2.4727037,18.065432,508.60266,-10.746739
212.4484,0.53493059,9.4941645,0.0,0,18.0,500.0,1.0009625,2.5072176,18.065199,508.62598,-10.764142
212.451,0.5899021,9.4878922,0.0,0,18.0,500.0,1.0003875,2.7554209,18.062593,508.64929,-10.784078
212.4536,0.52940518,9.4863176,0.0,0,18.0,500.0,1.0009,2.4937789,18.061443,508.67261,-10.803431
212.4562,0.53455049,9.4850311,0.0,0,18.0,500.0,1.0014043,2.4868627,18.0581,508.69025,-10.822773
212.4588,0.59559375,9.4842968,0.0,0,18.0,500.0,1.0016248,2.7626774,18.059036,508.70578,-10.843932
212.4614,0.53571337,9.4877748,0.0,0,18.0,500.0,1.0022514,2.512074,18.056662,508.72131,-10.861871
212.464,0.52964944,9.4872513,0.0,0,18.0,500.0,1.0013475,2.4841447,18.062294,508.73685,-10.881792
212.4666,0.59176928,9.4938784,0.0,0,18.0,500.0,1.0014427,2.7426336,18.061911,508.72467,-10.901498
212.4692,0.54815292,9.4917784,0.0,0,18.0,500.0,1.0009489,2.6026762,18.054415,508.70914,-10.920154
212.4718,0.51714969,9.4944267,0.0,0,18.0,500.0,1.0008709,2.4551957,18.055347,508.6936,-10.939967
212.4744,0.59699726,9.4839554,0.0,0,18.0,500.0,0.99967045,2.781163,18.055378,508.68015,-10.962599
212.477,0.55206609,9.4832792,0.0,0,18.0,500.0,1.0003717,2.5859511,18.055664,508.70346,-10.983458
212.4796,0.52223718,9.4817915,0.0,0,18.0,500.0,1.0009511,2.4496167,18.053833,508.72678,-11.001109
212.4822,0.60022378,9.4825497,0.0,0,18.0,500.0,1.0012467,2.8073933,18.055025,508.75009,-11.021409
212.4848,0.56404763,9.4905148,0.0,0,18.0,500.0,1.0024559,2.6130595,18.052345,508.77505,-11.042391
212.4874,0.52627075,9.4882622,0.0,0,18.0,500.0,1.0014302,2.4383092,18.055214,508.80615,-11.060621
212.49,0.58419478,9.4932709,0.0,0,18.0,500.0,1.0012598,2.7039011,18.054968,508.83725,-11.07846
212.4926,0.5824821,9.4891644,0.0,0,18.0,500.0,1.0003778,2.7195368,18.052454,508.86832,-11.097911
212.4952,0.5338918,9.4917688,0.0,0,18.0,500.0,1.0005186,2.5097048,18.050541,508.88184,-11.117726
212.4978,0.57943356,9.4844217,0.0,0,18.0,500.0,0.99978596,2.7135293,18.052048,508.8663,-11.137516
212.5004,0.59548634,9.4869661,0.0,0,18.0,500.0,1.0011438,2.8000476,18.054106,508.85074,-11.158425
212.503,0.52410901,9.482398,0.0,0,18.0,500.0,1.0012052,2.4534142,18.051741,508.83521,-11.177782
212.5056,0.59468549,9.4827099,0.0,0,18.0,500.0,1.0013317,2.739939,18.051973,508.80292,-11.197773
212.5082,0.6072098,9.4886446,0.0,0,18.0,500.0,1.0021195,2.8301191,18.050236,508.75629,-11.218626
212.5108,0.52743858,9.4894209,0.0,0,18.0,500.0,1.0016801,2.4602065,18.054239,508.70966,-11.238098
212.5134,0.57782912,9.4943247,0.0,0,18.0,500.0,1.0015934,2.6829453,18.050278,508.66302,-11.258546
212.516,0.60053951,9.4908028,0.0,0,18.0,500.0,1.0007087,2.8115594,18.048971,508.64905,-11.277164
212.5186,0.53622043,9.492219,0.0,0,18.0,500.0,1.0007966,2.5319858,18.047688,508.64905,-11.29761
212.5212,0.57190692,9.4849043,0.0,0,18.0,500.0,1.0000532,2.6623385,18.04747,508.64905,-11.318278
212.5238,0.61063319,9.4853897,0.0,0,18.0,500.0,1.001032,2.8534698,18.048502,508.64905,-11.337872
212.5264,0.54957318,9.4827566,0.0,0,18.0,500.0,1.0012544,2.5470765,18.044558,508.66245,-11.355803
213.2275,0.50874633,9.4953136,0.0,0,18.0,1.4427128e-07,1.0023955,2.375293,18.003281,491.00388,-11.482936
214.5275,0.45114356,9.5064068,0.0,0,18.0,2.6994714e-25,1.0044039,2.106461,18.000681,473.15509,-11.482863
215.8275,0.43358317,9.5161381,0.0,0,18.0,5.0446745e-43,1.0061816,2.0192509,17.999477,457.91083,-11.482399
217.1275,0.43957359,9.5242767,0.0,0,18.0,1.4012985e-45,1.0076791,2.0437303,18.000185,444.1163,-11.483309
218.4275,0.42708263,9.5330601,0.0,0,18.0,1.4012985e-45,1.0092638,1.9777671,18.000624,431.20795,-11.483232
219.7275,0.41754529,9.5406265,0.0,0,18.0,1.4012985e-45,1.010657,1.9381044,18.000698,418.53082,-11.483334
221.0275,0.42642051,9.5485125,0.0,0,18.0,1.4012985e-45,1.0120862,1.972611,17.999386,406.32071,-11.48218
222.3275,0.42931134,9.5566235,0.0,0,18.0,1.4012985e-45,1.0136086,1.9817673,17.999096,394.48639,-11.482606
223.6275,0.42026943,9.5640221,0.0,0,18.0,1.4012985e-45,1.0149935,1.9419516,17.999666,382.90973,-11.482411
224.9275,0.43582946,9.5709648,0.0,0,18.0,1.4012985e-45,1.0162494,2.0077844,18.000135,371.79605,-11.483571
226.2275,0.42997828,9.5782537,0.0,0,18.0,1.4012985e-45,1.0176033,1.978495,17.99888,360.91483,-11.482792
227.5275,0.41663122,9.585288,0.0,0,18.0,1.4012985e-45,1.0188954,1.9121722,17.999964,350.4007,-11.482702
228.8275,0.42249304,9.5919914,0.0,0,18.0,1.4012985e-45,1.0201699,1.9439394,17.9995,340.17142,-11.482943
230.1275,0.42245823,9.5986223,0.0,0,18.0,1.4012985e-45,1.0214126,1.9377264,17.999928,330.20139,-11.482631
231.4275,0.41583881,9.6047993,0.0,0,18.0,1.4012985e-45,1.0225625,1.90606,18.000042,320.75742,-11.482509
232.7275,0.41781467,9.6104097,0.0,0,18.0,1.4012985e-45,1.0236058,1.9156116,18.000214,311.29184,-11.482752
234.0275,0.42557243,9.6166267,0.0,0,18.0,1.4012985e-45,1.0247645,1.9464802,17.999247,302.46832,-11.482952
235.3275,0.41535982,9.6221199,0.0,0,18.0,1.4012985e-45,1.0257645,1.8979335,17.999491,293.61414,-11.482985
236.6275,0.41574964,9.6275196,0.0,0,18.0,1.4012985e-45,1.0267954,1.9000708,18.000429,285.3595,-11.483153
237.9275,0.42482218,9.6330719,0.0,0,18.0,1.4012985e-45,1.0278244,1.9376625,18.000364,277.27484,-11.483281
239.2275,0.416715,9.6392269,0.0,0,18.0,1.4012985e-45,1.0289721,1.8903812,18.000093,269.18353,-11.482886
240.5275,0.41007465,9.6445541,0.0,0,18.0,1.4012985e-45,1.0299684,1.8660705,17.999023,261.58417,-11.483221
241.8275,0.41617134,9.6496,0.0,0,18.0,1.4012985e-45,1.0309269,1.8916144,18.000799,254.0961,-11.483143
243.1275,0.41608018,9.6546783,0.0,0,18.0,1.4012985e-45,1.0318902,1.8867469,18.000134,246.8847,-11.482909
244.4275,0.40964055,9.659586,0.0,0,18.0,1.4012985e-45,1.0327727,1.857551,18.000134,239.85556,-11.4832
245.7275,0.4207764,9.6637545,0.0,0,18.0,1.4012985e-45,1.033527,1.9097292,18.000191,233.15182,-11.482889
247.0275,0.40099677,9.6686411,0.0,0,18.0,1.4012985e-45,1.0344561,1.8121641,17.999933,226.45937,-11.482533
248.3275,0.40490344,9.6734543,0.0,0,18.0,1.4012985e-45,1.035328,1.8303306,17.999577,219.98462,-11.482608
249.6275,0.41841799,9.6776743,0.0,0,18.0,1.4012985e-45,1.0361303,1.8950678,17.999697,214.04443,-11.482635
250.9275,0.40816391,9.6819992,0.0,0,18.0,1.4012985e-45,1.0369676,1.8351426,18.001034,208.03151,-11.482427
252.2275,0.40535116,9.6859694,0.0,0,18.0,1.4012985e-45,1.0376841,1.8314191,18.000824,202.1357,-11.48243
253.5275,0.40700212,9.6899185,0.0,0,18.0,1.4012985e-45,1.0384548,1.8399506,17.999578,196.48914,-11.482835
254.8275,0.41132176,9.6933689,0.0,0,18.0,1.4012985e-45,1.0390867,1.8539786,17.999453,190.99429,-11.483063
256.1275,0.40931886,9.6980886,0.0,0,18.0,1.4012985e-45,1.0399734,1.8407989,17.999699,185.86128,-11.482727
257.4275,0.40812042,9.7007313,0.0,0,18.0,1.4012985e-45,1.040466,1.843295,17.999693,180.90477,-11.483058
258.7275,0.40524843,9.7051353,0.0,0,18.0,1.4012985e-45,1.0412992,1.8254101,17.999584,175.72203,-11.482978
260.0275,0.39438477,9.7081795,0.0,0,18.0,1.4012985e-45,1.0418969,1.7686374,18.00042,171.16856,-11.482268
261.3275,0.39683709,9.7115431,0.0,0,18.0,1.4012985e-45,1.0425364,1.7843684,17.999611,166.5786,-11.482514
262.6275,0.40309107,9.7147455,0.0,0,18.0,1.4012985e-45,1.0431443,1.8104306,18.000082,162.17168,-11.482356
263.9275,0.40441737,9.7180319,0.0,0,18.0,1.4012985e-45,1.0437503,1.8083254,18.000858,157.87952,-11.482666
265.2275,0.39872137,9.7209673,0.0,0,18.0,1.4012985e-45,1.044328,1.7893506,17.998981,153.77652,-11.482854
266.5275,0.41030294,9.7239761,0.0,0,18.0,1.4012985e-45,1.0448898,1.835622,17.999952,149.88882,-11.482911
267.8275,0.40151626,9.7270069,0.0,0,18.0,1.4012985e-45,1.04548,1.7916551,17.999104,145.88974,-11.482586
269.1275,0.39433688,9.7298365,0.0,0,18.0,1.4012985e-45,1.0460356,1.764923,17.999983,142.21918,-11.482767
270.4275,0.40222839,9.7324705,0.0,0,18.0,1.4012985e-45,1.0465107,1.8016323,18.001154,138.57227,-11.482762
271.7275,0.40240175,9.7348213,0.0,0,18.0,1.4012985e-45,1.0469875,1.7923539,17.99963,134.95901,-11.482659
272.5275,0.40601662,9.7365513,0.0,0,18.0,1.4012985e-45,1.0473017,1.8166989,17.999928,132.81413,-11.482531