File: examples/dan-msc-case-studies/CS3/data/01 raw data/baron_test_108.csv
Time(sec),Force(kN),Jaw(mm),PowAngle(deg),Power(W),Pram,PTemp,Strain,Stress(MPa),Stroke(mm),TC1(C),wedge(mm)
0.0,1.0919565,0.22644544,0.0,0,11.076097,0.0013240891,0.015187441,13.711393,11.076466,23.016302,-9.12819
1.1,1.0334514,-0.0035382442,0.0,0,11.076097,3.2158821,-0.00022044309,13.148396,11.076342,23.017178,-9.4947786
2.2,0.98188633,-0.0039606425,0.0,0,11.076097,6.5158825,-0.00026726152,12.505996,11.075926,23.076288,-9.4907084
3.3,0.97367203,-0.0035840643,0.0,0,11.076097,9.8158808,-0.0002423477,12.414372,11.075732,23.138109,-9.4899626
4.4,0.9518916,-0.0039128428,0.0,0,11.076097,13.115884,-0.00027255761,12.131149,11.075281,23.069635,-9.4876642
5.5,0.9331392,-0.0044662808,0.0,0,11.076097,16.415884,-0.00027284049,11.89795,11.076143,23.077579,-9.4856787
6.6,0.92083222,-0.0041808854,0.0,0,11.076097,19.715885,-0.00027019318,11.729609,11.077033,22.985443,-9.4839077
7.7,0.90787363,-0.0045903618,0.0,0,11.076097,23.015882,-0.00032961013,11.559512,11.076235,23.059473,-9.4818211
8.8,0.90985179,-0.0043087224,18.960041,0,11.076097,26.315884,-0.00026786793,11.598705,11.076428,23.051748,-9.4798269
9.9,0.90774512,-0.0042098206,32.600399,0,11.076097,29.615885,-0.00028995675,11.553838,11.075765,23.301344,-9.4779987
11.0,0.92365539,-0.0072501302,40.596977,0,11.076097,32.91589,-0.00048589506,11.767527,11.076324,24.526995,-9.4761162
12.1,0.9326303,-0.010089743,46.031693,0,11.076097,36.215889,-0.00068320328,11.900498,11.076123,26.832811,-9.4747
13.2,0.9490611,-0.014548525,49.226715,0,11.076097,39.515888,-0.00094606925,12.096316,11.076469,30.433489,-9.4726944
14.3,0.95927918,-0.01984825,51.195427,0,11.076097,42.815884,-0.0013163757,12.220199,11.07626,34.949158,-9.4702492
15.4,0.97214234,-0.023564342,52.057835,0,11.076097,46.115883,-0.0015952545,12.401297,11.076423,40.151459,-9.4685688
16.5,0.98222023,-0.028659778,51.596989,0,11.076097,49.415878,-0.0018891625,12.539628,11.076115,46.03204,-9.4667091
17.6,0.99656224,-0.032302,50.439732,0,11.076097,52.715874,-0.0021604535,12.716828,11.075141,51.825989,-9.4643593
18.7,1.002915,-0.035603531,48.386486,0,11.076097,56.015877,-0.0023648874,12.804385,11.076428,57.605709,-9.4622688
19.8,1.0051793,-0.038554493,45.270977,0,11.076097,59.315876,-0.0025811151,12.818918,11.075676,62.8843,-9.4605989
20.9,1.0070202,-0.040590994,42.398632,0,11.076097,62.615879,-0.00268024,12.855765,11.076734,67.222656,-9.4591465
22.0,0.99230903,-0.042377438,39.248909,0,11.076097,65.915886,-0.0028072316,12.669014,11.075757,70.82634,-9.4576015
23.1,0.97340393,-0.043211963,37.103558,0,11.076097,69.215881,-0.0029012505,12.425716,11.076056,73.666595,-9.4558315
24.2,0.96751189,-0.04410499,36.976624,0,11.076097,72.515892,-0.0029243757,12.34521,11.075605,75.526085,-9.4536228
25.3,0.94660962,-0.045373194,37.836914,0,11.076097,75.81588,-0.0030230682,12.098281,11.075962,77.061226,-9.4513435
26.4,0.94180948,-0.04651228,40.570107,0,11.076097,79.115875,-0.0030934012,12.036761,11.075608,78.385994,-9.449297
27.5,0.94873261,-0.048118081,43.612785,0,11.076097,82.415886,-0.0032156182,12.129542,11.076558,79.807106,-9.4471617
28.6,0.95767909,-0.050832774,46.578014,0,11.076097,85.715881,-0.0033559427,12.222627,11.076727,81.665291,-9.4452105
29.7,0.97445011,-0.05414876,49.059288,0,11.076097,89.015877,-0.0035945992,12.458687,11.076046,84.143883,-9.4437046
30.8,0.99681056,-0.056856737,50.817795,0,11.076097,92.31588,-0.003806575,12.753678,11.075788,87.398315,-9.4424171
31.9,1.0063186,-0.061837167,51.932137,0,11.076097,95.615891,-0.0040969159,12.865889,11.075934,91.125496,-9.4406796
33.0,1.0143843,-0.065435976,52.378887,0,11.076097,98.915901,-0.0043540718,12.97763,11.075819,95.567993,-9.4391584
34.1,1.0301815,-0.069019064,52.159584,0,11.076097,102.21589,-0.0045913598,13.181617,11.076312,100.34897,-9.4368801
35.2,1.0294011,-0.073067509,51.201782,0,11.076097,105.5159,-0.004872682,13.169981,11.076203,105.36982,-9.4348927
36.3,1.0297782,-0.076194115,49.640205,0,11.076097,108.81589,-0.0050483178,13.17743,11.075462,110.22883,-9.4328737
37.4,1.0259627,-0.07909333,48.046078,0,11.076097,112.1159,-0.0052476116,13.140596,11.074669,114.61696,-9.4310417
38.5,1.0271934,-0.081465364,46.583874,0,11.076097,115.41589,-0.0054374393,13.151826,11.075213,118.37554,-9.4290781
39.6,1.0259272,-0.083267495,45.626225,0,11.076097,118.7159,-0.0055118999,13.142127,11.076406,121.39326,-9.4276485
40.7,1.0329378,-0.085256778,45.397636,0,11.076097,122.01589,-0.0056806593,13.226149,11.076165,123.95859,-9.4255753
41.8,1.0025804,-0.087052472,45.615231,0,11.076097,125.3159,-0.0057922229,12.835718,11.075387,126.21764,-9.4236307
42.9,1.0167401,-0.08909972,46.855431,0,11.076097,128.61601,-0.0059253452,13.032402,11.076162,128.26328,-9.4222307
44.0,1.0242846,-0.091204092,48.009338,0,11.076097,131.91588,-0.0060453992,13.129854,11.075662,130.49438,-9.4202414
45.1,1.0239092,-0.093890049,49.634335,0,11.076097,135.21588,-0.0062254346,13.11482,11.075942,132.86174,-9.4182606
46.2,1.0355842,-0.096680827,51.167213,0,11.076097,138.51588,-0.0064478642,13.280739,11.075885,135.42535,-9.4165125
47.3,1.0348848,-0.099582337,52.283646,0,11.076097,141.81587,-0.0065999036,13.260512,11.076467,138.4512,-9.4145985
48.4,1.0460548,-0.10419453,53.275414,0,11.076097,145.11589,-0.0069267973,13.409499,11.076108,141.90356,-9.413043
49.5,1.0453246,-0.10700066,53.810486,0,11.076097,148.41588,-0.0071143252,13.385144,11.076554,145.59836,-9.411459
50.6,1.0478112,-0.1104884,53.975826,0,11.076097,151.7159,-0.0073568351,13.44499,11.076539,149.71559,-9.4099493
51.7,1.0525712,-0.11411008,53.975826,0,11.076097,155.0159,-0.0075593935,13.507454,11.075266,153.72646,-9.4082756
52.8,1.0592358,-0.1179694,53.939598,0,11.076097,158.31589,-0.007824936,13.605063,11.075299,157.56685,-9.4062443
53.9,1.0581053,-0.12241057,53.65723,0,11.076097,161.61591,-0.0081494814,13.574844,11.076259,161.5569,-9.4044533
55.0,1.0465947,-0.1249688,52.980324,0,11.076097,164.91591,-0.0082841394,13.439477,11.07631,165.62158,-9.402442
56.1,1.0574201,-0.1276308,52.388588,0,11.076097,168.2159,-0.008471828,13.588884,11.07565,169.28947,-9.400589
57.2,1.0506762,-0.13027184,51.932697,0,11.076097,171.51588,-0.0086445557,13.496112,11.075503,172.69168,-9.39853
58.3,1.0622247,-0.13270369,51.573895,0,11.076097,174.8159,-0.0088207014,13.651721,11.075821,175.94998,-9.3963938
59.4,1.0603833,-0.13667086,51.569828,0,11.076097,178.11589,-0.0090525681,13.619585,11.075377,179.04268,-9.3945217
60.5,1.0573182,-0.1392832,51.569828,0,11.076097,181.41589,-0.0092278142,13.582976,11.07664,181.98019,-9.3924351
61.6,1.0595078,-0.14092904,51.743443,0,11.076097,184.7159,-0.0093793338,13.622204,11.076183,184.94406,-9.3903131
62.7,1.05723,-0.1435284,52.283466,0,11.076097,188.0159,-0.009507454,13.588224,11.075932,187.68349,-9.388319
63.8,1.0626227,-0.14573142,52.905209,0,11.076097,191.31589,-0.0096684806,13.670986,11.075299,190.31563,-9.3868093
64.9,1.0625037,-0.14869216,53.33654,0,11.076097,194.61589,-0.0098619731,13.663848,11.076125,193.23679,-9.3851738
66.0,1.0705965,-0.15163505,54.241203,0,11.076097,197.91589,-0.010071705,13.762631,11.075068,196.09503,-9.3836479
67.1,1.0638187,-0.1556077,54.855476,0,11.076097,201.2159,-0.010295798,13.691398,11.076674,199.20647,-9.3819532
68.2,1.0629807,-0.1603241,55.239254,0,11.076097,204.51588,-0.010618967,13.667582,11.076575,202.56734,-9.3805752
69.3,1.0714766,-0.16298446,55.370979,0,11.076097,207.8159,-0.010826034,13.78432,11.07643,206.46616,-9.3791637
70.4,1.0598894,-0.16686992,55.534973,0,11.076097,211.11589,-0.011041154,13.650191,11.076082,210.1732,-9.3773737
71.5,1.0566063,-0.1695669,55.409019,0,11.076097,214.41591,-0.011243321,13.600767,11.07481,213.90573,-9.3757648
72.6,1.0588325,-0.1734816,55.148434,0,11.076097,217.7159,-0.011505893,13.65277,11.076109,217.7841,-9.3739624
73.7,1.0652932,-0.17651054,54.636402,0,11.076097,221.0159,-0.011706485,13.743785,11.07587,221.52429,-9.3722734
74.8,1.0630502,-0.17920628,54.334568,0,11.076097,224.3159,-0.011853663,13.690087,11.074976,225.08279,-9.3704414
75.9,1.0615155,-0.18226656,54.300499,0,11.076097,227.61589,-0.012069243,13.679896,11.075094,228.36815,-9.3684111
77.0,1.0720102,-0.18617471,53.975834,0,11.076097,230.91591,-0.012367378,13.811007,11.075938,231.57898,-9.3667841
78.1,1.0594662,-0.18973193,54.123768,0,11.076097,234.2159,-0.012545297,13.654504,11.076492,234.47684,-9.3645468
79.2,1.0572551,-0.19146463,54.305405,0,11.076097,237.5159,-0.012686002,13.628962,11.076546,237.62302,-9.362627
80.3,1.0596393,-0.19399342,54.305416,0,11.076097,240.8159,-0.012850086,13.671484,11.075672,240.63368,-9.3604689
81.4,1.0558341,-0.1972958,54.624023,0,11.076097,244.11589,-0.013077029,13.62445,11.075998,243.60786,-9.3587599
82.5,1.0571262,-0.20056637,54.931637,0,11.076097,247.41589,-0.013257602,13.65084,11.075509,246.69618,-9.3565397
83.6,1.070155,-0.20325889,55.438644,0,11.076097,250.7159,-0.01344795,13.798818,11.076238,249.72354,-9.3547974
84.7,1.0757163,-0.20692004,55.721172,0,11.076097,254.0159,-0.013731563,13.8863,11.075302,252.95674,-9.3530283
85.8,1.0724671,-0.21166024,56.074917,0,11.076097,257.31616,-0.013998079,13.849699,11.075951,256.20615,-9.3515787
86.9,1.0717452,-0.21373639,56.140026,0,11.076097,260.61615,-0.014150801,13.823409,11.075639,259.54285,-9.3492775
88.0,1.055972,-0.21731859,56.425777,0,11.076097,263.91586,-0.014379782,13.657674,11.076179,263.00717,-9.3475571
89.1,1.0634135,-0.22091396,56.574333,0,11.076097,267.21588,-0.014632761,13.741533,11.075606,266.41077,-9.3460236
90.2,1.0656874,-0.22445709,56.711422,0,11.076097,270.5159,-0.014832119,13.762028,11.075222,269.83325,-9.3440008
91.3,1.0672065,-0.22718517,56.711422,0,11.076097,273.81589,-0.01502018,13.805576,11.075686,273.33282,-9.342145
92.4,1.0718937,-0.23148617,56.711422,0,11.076097,277.11591,-0.015347704,13.856578,11.076844,276.71252,-9.340519
93.5,1.0707732,-0.23550203,56.711422,0,11.076097,280.41592,-0.015552036,13.837398,11.076144,280.08957,-9.3386316
94.6,1.0669225,-0.23769102,56.711445,0,11.076097,283.71591,-0.015724171,13.80113,11.075895,283.53036,-9.3369808
95.7,1.0601604,-0.24101341,56.71143,0,11.076097,287.0159,-0.015939575,13.725362,11.076089,287.0708,-9.3347712
96.8,1.0661407,-0.24397506,56.71143,0,11.076097,290.31589,-0.016153814,13.810544,11.076148,290.36853,-9.3333082
97.9,1.0704652,-0.24661991,56.711422,0,11.076097,293.61591,-0.016284602,13.860019,11.076606,293.66101,-9.331233
99.0,1.075634,-0.25083035,56.744778,0,11.076097,296.91589,-0.01658166,13.913983,11.076512,296.83325,-9.3295145
100.1,1.0367485,-0.25349963,56.852402,0,11.076097,299.99542,-0.016775336,13.425339,11.076223,299.83838,-9.328042
101.2,0.04631491,-0.27110744,54.355083,0,11.076097,299.99905,-0.017895157,0.60440671,11.075928,303.40286,-9.3278275
102.3,0.041534398,-0.27103132,50.473316,0,11.076097,299.99905,-0.017911149,0.53412181,11.07581,306.67645,-9.3280401
103.4,0.015615921,-0.27082044,46.588833,0,11.076097,299.99905,-0.017897166,0.18935534,11.07704,308.01059,-9.3279047
104.5,0.011517853,-0.26975793,43.528759,0,11.076097,299.99905,-0.017832726,0.16484687,11.075496,307.72653,-9.3277378
105.6,0.0045913304,-0.26860124,41.802982,0,11.076097,299.99905,-0.017720245,0.062890403,11.075813,306.05054,-9.3279781
106.7,-0.0055440618,-0.26649606,42.592297,0,11.076097,299.99905,-0.017600371,-0.071923129,11.076605,303.31027,-9.3277349
107.8,-0.0087193791,-0.264716,45.115952,0,11.076097,299.99905,-0.01751565,-0.1075517,11.0766,300.2218,-9.3279505
108.9,-0.0079509616,-0.26359117,48.709782,0,11.076097,299.99905,-0.017406637,-0.10908183,11.076337,297.01114,-9.3278952
110.0,-0.015626933,-0.26251099,52.235306,0,11.076097,299.99905,-0.017349066,-0.1989243,11.076091,294.25226,-9.3277245
111.1,-0.01192308,-0.26208305,55.685261,0,11.076097,299.99905,-0.017321104,-0.15270066,11.075097,291.92773,-9.3279343
112.2,-0.014797834,-0.26140857,58.775055,0,11.076097,299.99905,-0.017293455,-0.19719966,11.075868,290.29462,-9.3279696
113.3,-0.017989879,-0.2612901,61.331959,0,11.076097,299.99905,-0.017246071,-0.22890072,11.075799,289.22797,-9.3275375
114.4,-0.010124827,-0.26116636,63.558586,0,11.076097,299.99905,-0.017257143,-0.12439319,11.076369,288.70694,-9.3277426
115.5,-0.011306694,-0.2613374,65.461685,0,11.076097,299.99905,-0.017294053,-0.15123396,11.076093,288.69125,-9.3277521
116.6,0.0011607768,-0.26154938,66.910057,0,11.076097,299.99905,-0.017277986,0.027441809,11.076359,289.18021,-9.3278265
117.7,0.013093486,-0.26287231,68.031013,0,11.076097,299.99905,-0.017375484,0.16189672,11.075509,290.2995,-9.3276854
118.8,0.014502808,-0.26268876,68.664238,0,11.076097,299.99905,-0.017366515,0.19230355,11.076062,292.0741,-9.3276262
119.9,0.029178981,-0.26461685,68.788765,0,11.076097,299.99905,-0.01749555,0.39278576,11.076051,294.6492,-9.3275471
121.0,0.039221477,-0.26756063,68.193016,0,11.076097,299.99905,-0.017654316,0.51302254,11.075903,298.00488,-9.3273735
122.1,0.040015414,-0.2700572,67.030075,0,11.076097,299.99905,-0.017827421,0.52118385,11.076145,301.72305,-9.3273649
123.2,0.054734942,-0.27327684,65.167,0,11.076097,299.99905,-0.018080285,0.71751058,11.076224,305.30124,-9.3274126
124.3,0.054921903,-0.27510932,62.813946,0,11.076097,299.99905,-0.018155787,0.7009272,11.077229,308.36191,-9.3276501
125.4,0.04361004,-0.27554867,59.918327,0,11.076097,299.99905,-0.018203778,0.56565022,11.07522,310.77191,-9.3272486
126.5,0.047325619,-0.27575421,56.592934,0,11.076097,299.99905,-0.018220188,0.62326288,11.076303,312.18283,-9.3273544
127.6,0.026370343,-0.27554095,52.850224,0,11.076097,299.99905,-0.018209362,0.35358566,11.075797,312.73535,-9.3271151
128.7,0.0088271871,-0.27524117,49.642239,0,11.076097,299.99905,-0.018169032,0.12110408,11.075457,311.79837,-9.3269424
129.8,0.0033936503,-0.27430516,47.430023,0,11.076097,299.99905,-0.018105617,0.046648964,11.075681,309.7504,-9.3270388
130.9,-0.010037248,-0.27228358,46.605404,0,11.076097,299.99905,-0.018016901,-0.13016184,11.076826,306.88266,-9.3272724
132.0,-0.018724067,-0.27126986,47.682793,0,11.076097,299.99905,-0.017907286,-0.23266022,11.07513,303.49194,-9.3267078
133.1,-0.01942274,-0.26998612,50.029137,0,11.076097,299.99905,-0.017838679,-0.25745422,11.076002,299.97202,-9.3269949
134.2,-0.030074336,-0.2687521,52.952995,0,11.076097,299.99905,-0.017778112,-0.39648417,11.076382,296.73993,-9.3269119
135.3,-0.028235376,-0.26814309,56.108444,0,11.076097,299.99905,-0.017718391,-0.35556617,11.074896,293.79874,-9.3264551
136.4,-0.030346654,-0.2678926,59.227051,0,11.076097,299.99905,-0.017697133,-0.38913333,11.076285,291.34128,-9.3268509
137.5,-0.032891959,-0.26777264,62.007572,0,11.076097,299.99905,-0.017690146,-0.41490707,11.075957,289.4039,-9.3265295
138.6,-0.026760815,-0.26748365,64.526299,0,11.076097,299.99905,-0.017702587,-0.34567159,11.076362,288.05124,-9.3266163
139.7,-0.027633296,-0.26734963,66.701538,0,11.076097,299.99905,-0.017639898,-0.36703575,11.076457,287.21854,-9.3269224
140.8,-0.023847975,-0.26772627,68.628891,0,11.076097,299.99905,-0.01768939,-0.30140182,11.076001,287.02621,-9.3267136
141.9,-0.013633592,-0.26778328,70.254715,0,11.076097,299.99905,-0.01772047,-0.18557942,11.075686,287.23727,-9.3264809
143.0,-0.011213615,-0.26787561,71.4599,0,11.076097,299.99905,-0.017697804,-0.1512627,11.07603,288.07965,-9.3267889
144.1,0.0054668654,-0.26792368,72.32045,0,11.076097,299.99905,-0.017696353,0.082288042,11.075436,289.52969,-9.3265495
145.1301,0.033995647,-0.014615178,72.737671,0,11.076097,299.99905,-0.00094939809,0.43849906,11.075958,291.70175,-9.3262997
145.282,0.2008675,0.014903591,72.70752,0,11.076099,6.0864741e-10,0.0012429522,2.5503254,11.073768,292.29047,-9.3248758
145.2842,0.20354937,0.022263719,72.70752,0,11.076099,6.079045000000001e-25,0.0013194392,2.6363108,11.074972,292.29721,-9.3261385
145.2864,0.18868439,0.019439088,72.70752,0,11.076099,6.0716300999999994e-40,0.001565913,2.4313524,11.071381,292.30396,-9.3261328
145.2886,0.18166524,0.026315629,63.999958,0,11.076099,0.0,0.0014646609,2.3686028,11.074061,292.30701,-9.3279467
145.2908,0.22725309,0.019700229,48.036232,0,11.076099,0.0,0.0015366056,2.9075687,11.075528,292.30701,-9.3259001
145.293,0.2120827,0.022944914,32.072506,0,11.076099,0.0,0.0014106584,2.7097826,11.07525,292.30701,-9.3271866
145.2952,0.22305326,0.018724583,16.10878,0,11.076099,0.0,0.0015369855,2.7679284,11.075998,292.30701,-9.326149
145.2974,0.21444012,0.026418312,0.14505269,0,11.076099,0.0,0.0014086529,2.7451434,11.07567,292.30701,-9.3264532
145.2996,0.20575246,0.019754658,0.0,0,11.076099,0.0,0.0015356009,2.649096,11.076276,292.30032,-9.3270264
145.3018,0.19453631,0.022878516,0.0,0,11.076099,0.0,0.0013932848,2.4442987,11.077254,292.29358,-9.325449
145.304,0.2017508,0.019949257,0.0,0,11.076099,0.0,0.0015549697,2.5358033,11.073583,292.28683,-9.3259649
145.3062,0.19387148,0.025627764,0.0,0,11.076099,0.0,0.0014119036,2.45574,11.076395,292.28009,-9.3261719
145.3084,0.19216888,0.01896853,0.0,0,11.076099,0.0,0.0014009334,2.4431565,11.078915,292.29102,-9.3279057
145.3106,0.20396088,0.021988166,0.0,0,11.076099,0.0,0.0013313006,2.6072924,11.075193,292.32471,-9.3278465
145.3128,0.2190523,0.020099385,0.0,0,11.076099,0.0,0.0015319202,2.680613,11.07591,292.35843,-9.3263779
145.315,0.2214535,0.026730316,0.0,0,11.076099,0.0,0.001583879,2.924829,11.074115,292.39212,-9.3258696
145.3172,0.22596951,0.021761496,0.0,0,11.076099,0.0,0.00155952,2.8703954,11.073997,292.42581,-9.3251867
145.3194,0.22197327,0.023116702,0.0,0,11.076099,0.0,0.001398899,2.8286211,11.072987,292.43576,-9.3255434
145.3216,0.20562166,0.020908415,0.0,0,11.076099,0.0,0.0015655007,2.6347342,11.075882,292.4425,-9.3264589
145.3238,0.21167637,0.028152812,0.0,0,11.076099,0.0,0.0016530028,2.6640823,11.073812,292.44925,-9.3264885
145.326,0.21041103,0.021387419,0.0,0,11.076099,0.0,0.0016103192,2.7111537,11.075029,292.45596,-9.3261709
145.3282,0.21695344,0.024782678,0.0,0,11.076099,0.0,0.0015364593,2.7896106,11.074774,292.45831,-9.325736
145.3304,0.2197396,0.020351063,0.0,0,11.063763,0.0,0.0014933706,2.7553101,11.076276,292.45157,-9.3258133
145.3326,0.23681818,0.027572071,0.0,0,10.735819,0.0,0.0016484975,3.0310459,11.074656,292.44482,-9.3273716
145.3348,0.24620311,0.022520134,0.0,0,10.404926,0.0,0.0015869435,3.1091352,11.072715,292.43808,-9.32759
145.337,0.25586531,0.025057156,0.0,0,10.074035,0.0,0.001547784,3.221354,11.014231,292.43134,-9.3276672
145.3392,0.26392025,0.020283749,0.0,0,9.7431412,0.0,0.0014310186,3.275301,10.827357,293.63745,-9.3255186
145.3414,0.27456415,0.026942184,0.0,0,9.4141388,0.0,0.0016138409,3.4238262,10.529985,295.20029,-9.3272123
145.3436,0.20695134,0.023510469,0.0,0,9.0922337,0.0,0.0016930909,2.7131393,10.147758,296.76312,-9.327879
145.3458,7.5201321,0.35457966,0.0,0,8.7703295,0.0,0.023194982,93.201424,9.7433014,298.32596,-9.320857
145.348,9.8928461,0.71991271,0.0,0,8.4631929,0.0,0.04896114,119.2053,9.2790155,300.06314,-9.3193951
145.3502,10.702363,1.1307281,0.0,0,8.1570406,0.0,0.077997483,125.49137,8.8539467,302.42499,-9.3169661
145.3524,11.030787,1.4900789,0.0,0,7.860775,0.0,0.10420182,126.77687,8.5036287,304.78683,-9.3164949
145.3546,11.643999,1.7724456,0.0,0,7.5694952,0.0,0.12523288,130.42847,8.1908293,307.14865,-9.3156052
145.3568,11.823426,2.0641074,0.0,0,7.2838035,0.0,0.1476527,130.01831,7.8827295,309.5105,-9.3155251
145.359,12.080688,2.3513229,0.0,0,7.0067787,0.0,0.17000741,129.7294,7.6120982,310.87973,-9.3169909
145.3612,12.456163,2.5948467,0.0,0,6.7313666,0.0,0.18960464,131.16722,7.3518062,311.74588,-9.3169889
145.3634,12.732389,2.8523223,0.0,0,6.467802,0.0,0.21052724,131.35068,7.0861406,312.61203,-9.3183975
145.3656,13.036553,3.1146309,0.0,0,6.2042418,0.0,0.2323558,131.46565,6.822681,313.47818,-9.3188391
145.3678,13.38616,3.3754883,0.0,0,5.9515953,0.0,0.2544283,132.0887,6.5605884,314.2608,-9.3173161
145.37,13.685803,3.6313288,0.0,0,5.7009273,0.0,0.27670714,132.10098,6.2991629,314.36151,-9.3173761
145.3722,14.018054,3.8975854,0.0,0,5.457253,0.0,0.30049929,132.1228,6.0358915,314.46222,-9.316659
145.3744,14.336042,4.1572838,0.0,0,5.2187734,0.0,0.32407779,132.07816,5.771245,314.56293,-9.3169346
145.3766,14.666085,4.4235101,0.0,0,4.9838037,0.0,0.34902772,131.71265,5.510201,314.66364,-9.3173399
145.3788,14.998036,4.6712127,0.0,0,4.7569838,0.0,0.3726871,131.53493,5.2546029,314.73083,-9.3178511
145.381,15.33092,4.9191823,0.0,0,4.5305758,0.0,0.39712128,131.18747,5.0091791,314.77112,-9.3172464
145.3832,15.693191,5.1583786,0.0,0,4.3147016,0.0,0.42090851,131.09578,4.7665229,314.81143,-9.315753
145.3854,16.049166,5.3952866,0.0,0,4.0989256,0.0,0.44551381,130.75415,4.5349793,314.85172,-9.3170748
145.3876,16.405025,5.6139054,0.0,0,3.8911293,0.0,0.46821398,130.70767,4.308979,314.892,-9.3179331
145.3898,16.784973,5.8253622,0.0,0,3.6859133,0.0,0.49144796,130.67068,4.095562,313.56204,-9.3185291
145.392,17.173897,6.0333829,0.0,0,3.4855206,0.0,0.51395792,130.73268,3.8848655,312.23209,-9.3180523
145.3942,17.582853,6.2441688,0.0,0,3.2902927,0.0,0.53813118,130.63591,3.6783772,310.90216,-9.3167458
145.3964,18.005035,6.4445977,0.0,0,3.0970623,0.0,0.56082565,130.81676,3.4768121,309.5722,-9.3161201
145.3986,18.481485,6.6399808,0.0,0,2.9113381,0.0,0.58446199,131.08423,3.2779317,308.12814,-9.3157835
145.4008,18.96887,6.8358874,0.0,0,2.7256143,0.0,0.60754991,131.50851,3.0842543,306.54205,-9.3159428
145.403,19.502949,7.0301647,0.0,0,2.5483871,0.0,0.63236487,131.81586,2.8885047,304.95593,-9.3157082
145.4052,20.041893,7.2190962,0.0,0,2.3717272,0.0,0.65545946,132.43724,2.7027273,303.36984,-9.3163214
145.4074,20.625534,7.3988414,0.0,0,2.2008002,0.0,0.67975879,133.02187,2.5177596,301.78375,-9.3154135
145.4096,21.225704,7.5806231,0.0,0,2.0327642,0.0,0.70297807,133.7527,2.3367934,300.73981,-9.3145113
145.4118,21.851532,7.7586203,0.0,0,1.8679363,0.0,0.72834814,134.19644,2.1587892,299.76227,-9.3160057
145.414,22.501293,7.9324026,0.0,0,1.7080842,0.0,0.75137317,135.11436,1.990379,298.78473,-9.3156271
145.4162,23.187674,8.0958185,0.0,0,1.5491643,0.0,0.77599937,135.82109,1.8219135,297.80719,-9.314765
145.4184,23.935671,8.2572708,0.0,0,1.3970972,0.0,0.79849029,137.05678,1.6581321,296.83417,-9.3143988
145.4206,24.706478,8.4164438,0.0,0,1.2450333,0.0,0.82361001,137.9091,1.4977388,295.87012,-9.31359
145.4228,25.5077,8.5715866,0.0,0,1.0992643,0.0,0.84605187,139.25591,1.3459349,294.90604,-9.3124876
145.425,26.353086,8.7143126,0.0,0,0.95463622,0.0,0.87001425,140.4458,1.1952721,293.94199,-9.3110304
145.4272,27.221117,8.8558846,0.0,0,0.8140732,0.0,0.89139563,142.0105,1.0503696,292.97791,-9.3120594
145.4294,28.127417,8.9981318,0.0,0,0.67652929,0.0,0.91649842,143.13838,0.90688205,292.70432,-9.3115797
145.4316,29.05571,9.1352921,0.0,0,0.54098582,0.0,0.93762439,144.78729,0.76770544,292.62341,-9.310214
145.4338,30.032038,9.2576952,0.0,0,0.4100858,0.0,0.96058136,146.21994,0.634902,292.54251,-9.3108397
145.436,30.909397,9.3856382,0.0,0,0.27942529,0.0,0.98134285,147.56918,0.50679064,292.46161,-9.310957
145.4382,28.693134,9.4147863,0.0,0,0.15489206,0.0,0.98878562,136.0154,0.44321543,292.5462,-9.3120375
145.4404,27.239605,9.429944,0.0,0,0.030416045,0.0,0.98946631,128.99272,0.41191185,293.19339,-9.3136635
145.4426,26.810402,9.4286242,0.0,0,-0.091732524,0.0,0.99138767,126.71093,0.37771797,293.84061,-9.3142233
145.4448,26.718103,9.4373436,0.0,0,-0.21312852,0.0,0.9908998,126.23297,0.33065304,294.48779,-9.3154116
145.447,26.743708,9.4422779,0.0,0,-0.33452454,0.0,0.99404377,125.97245,0.27553833,295.13498,-9.3155079
145.4492,26.731331,9.453249,0.0,0,-0.45592052,0.0,0.9935714,126.06797,0.21596199,296.09512,-9.3161144
145.4514,26.692402,9.4483252,0.0,0,-0.57731652,0.0,0.99503183,125.65292,0.16213736,297.20752,-9.3170891
145.4536,26.562164,9.4570293,0.0,0,-0.69871247,0.0,0.99462998,125.10674,0.11226922,298.31992,-9.3156137
145.4558,26.35656,9.4590302,0.0,0,-0.82010847,0.0,0.9973442,123.82427,0.074515581,299.43228,-9.3166428
145.458,26.066618,9.4729576,0.0,0,-0.94150448,0.0,0.99724746,122.46832,0.040195651,300.54367,-9.3171225
145.4602,25.697752,9.4662971,0.0,0,-1.0629005,0.0,0.99837911,120.63914,0.020550739,301.64764,-9.317811
145.4624,25.198904,9.4721355,0.0,0,-0.84332824,300.0,0.99707073,118.41576,0.01005826,302.75162,-9.3180819
145.4646,24.670198,9.4666443,0.0,0,-0.42304912,300.0,0.99856752,115.74113,0.013167164,303.85556,-9.3182631
145.4668,24.202406,9.4730711,0.0,0,-0.0027696537,300.0,0.99712324,113.73128,0.020002907,304.95953,-9.3178883
145.469,23.838224,9.4682341,0.0,0,0.4175092,300.0,0.9988696,111.79345,0.020896237,305.92206,-9.318203
145.4712,23.55825,9.475976,0.0,0,0.83778834,300.0,0.99793053,110.60903,0.021299729,306.77505,-9.3186493
145.4734,23.298927,9.4696608,0.0,0,1.2580682,300.0,0.99907303,109.26833,0.020294324,307.62808,-9.3201122
145.4756,22.59655,9.4780083,0.0,0,1.6783469,300.0,0.99770641,106.17498,0.038480446,308.48111,-9.319025
145.4778,21.155329,9.462719,0.0,0,2.0986257,300.0,0.9977833,99.483536,0.096357346,309.33264,-9.3205175
145.48,18.483488,9.4627028,0.0,0,2.5189054,300.0,0.99550033,87.329414,0.20666498,310.0242,-9.3219204
145.4822,13.318916,9.4394722,0.0,0,2.9391847,300.0,0.99375552,63.371391,0.4231801,310.71579,-9.3264275
145.4844,0.24757841,9.2273941,0.0,0,3.3594637,300.0,0.95477706,1.0210222,0.84044296,311.40735,-9.3412209
145.4866,0.45084658,9.0107651,0.0,0,3.7797427,300.0,0.91983551,2.6904855,1.4612751,312.09891,-9.3367949
145.4888,-0.36158782,8.8655891,0.0,0,4.2000222,300.0,0.89370668,-1.6413928,2.2235048,312.51581,-9.3379288
145.491,-0.10242634,8.7382498,0.0,0,4.6203012,300.0,0.87492025,-0.68983424,2.9117212,312.60309,-9.3381958
145.4932,-0.029027339,8.6900206,0.0,0,5.0405807,300.0,0.86447138,-0.17238066,3.4471505,312.6904,-9.3374119
145.4954,-0.015768273,8.6742887,0.0,0,5.4608598,300.0,0.864452,-0.11837584,3.8666267,312.77768,-9.3369045
145.4976,-0.00047503936,8.7042742,0.0,0,5.8811393,300.0,0.86713433,0.043988436,4.2490759,312.86496,-9.3343134
145.4998,-0.01996786,8.7659607,0.0,0,6.3014183,300.0,0.87899506,-0.091440894,4.6311636,312.79514,-9.3342638
145.502,-0.060177799,8.8660116,0.0,0,6.7216969,300.0,0.89270449,-0.32893863,5.0189743,312.70786,-9.3342314
145.5042,0.027074888,8.9824724,0.0,0,7.1419768,300.0,0.91394746,0.049676664,5.4170518,312.62054,-9.3322754
145.5064,-0.047334347,9.143384,0.0,0,7.5622559,300.0,0.93893427,-0.12415381,5.8378463,312.53326,-9.3326521
145.5086,-0.22460377,9.3283978,0.0,0,7.9825354,300.0,0.97321999,-0.98916948,6.2736425,312.56195,-9.3318281
145.5108,0.24622516,9.4188643,0.0,0,8.4028139,300.0,0.9871394,1.0727285,6.7265458,312.81039,-9.3300095
145.513,-0.084455535,9.3896303,0.0,0,8.8230925,300.0,0.98363471,-0.48119599,7.1741819,313.05881,-9.3280048
145.5152,-0.010192029,9.417572,0.0,0,9.243372,300.0,0.98713326,-0.0057646688,7.6153145,313.30722,-9.3290062
145.5174,-0.034939084,9.4091797,0.0,0,9.6636515,300.0,0.98822182,-0.21228492,8.0488644,313.55566,-9.329504
145.5196,-0.15589032,9.439683,0.0,0,10.083931,300.0,0.99124342,-0.65411431,8.4747105,313.20401,-9.3283539
145.5218,-0.057870217,9.4290028,0.0,0,10.50421,300.0,0.99139929,-0.32410645,8.9031096,312.69373,-9.3283587
145.524,0.063314781,9.4265747,0.0,0,10.924489,300.0,0.98924273,0.31381261,9.3395643,312.18347,-9.326438
145.5262,-0.10741888,9.4137287,0.0,0,11.344769,300.0,0.98857957,-0.46976063,9.7716236,311.67319,-9.3268452
145.5284,-0.16634752,9.4323339,0.0,0,11.765047,300.0,0.98996609,-0.78155828,10.206409,311.31799,-9.3258839
145.5306,-0.019079505,9.423275,0.0,0,12.185327,300.0,0.99030358,-0.18053351,10.642297,311.46393,-9.3258905
145.5328,-0.046212442,9.4290848,0.0,0,12.605606,300.0,0.98983103,-0.26529637,11.079661,311.60986,-9.3266697
145.535,0.042641375,9.4145594,0.0,0,13.025885,300.0,0.98864627,0.21975301,11.506371,311.7558,-9.3260298
145.5372,-0.091357283,9.4282408,0.0,0,13.446164,300.0,0.9894557,-0.36550435,11.922596,311.91342,-9.3262138
145.5394,-0.058888882,9.4189816,0.0,0,13.866444,300.0,0.98936391,-0.31048131,12.336964,312.31628,-9.3251848
145.5416,-0.058662675,9.4252462,0.0,0,14.286723,300.0,0.98931372,-0.27158979,12.760842,312.71912,-9.3249283
145.5438,-0.042133551,9.419096,0.0,0,14.707002,300.0,0.9894917,-0.18660882,13.184912,313.12198,-9.3249044
145.546,-0.11209307,9.4304237,0.0,0,15.127281,300.0,0.98974168,-0.51164448,13.626384,313.52484,-9.324564
145.5482,-0.11987783,9.4187489,0.0,0,15.547561,300.0,0.98917651,-0.58562845,14.069063,313.9046,-9.324894
145.5504,-0.064657435,9.4220581,0.0,0,15.967839,300.0,0.98868006,-0.33087528,14.51182,314.26047,-9.3248701
145.5526,0.032644052,9.4173861,0.0,0,16.388119,300.0,0.98893106,0.13606673,14.944791,314.61633,-9.3245659
145.5548,-0.029862428,9.4260874,0.0,0,16.808399,300.0,0.98927963,-0.089406841,15.356403,314.9722,-9.3239346
145.557,-0.097739473,9.4168129,0.0,0,17.228678,300.0,0.98872274,-0.50702614,15.77172,315.32806,-9.3227377
145.5592,-0.0088686338,9.4236946,0.0,0,17.648958,300.0,0.98939151,-0.09574227,16.181873,316.03598,-9.3236828
145.5614,-0.036696881,9.417758,0.0,0,17.999975,300.0,0.98868316,-0.15328354,16.60631,316.76785,-9.3235798
145.5636,-0.061660066,9.4275484,0.0,0,18.0,300.0,0.98959923,-0.24714343,17.023413,317.49969,-9.3233023
145.5658,-0.071780406,9.4169331,0.0,0,18.0,300.0,0.98858905,-0.31749889,17.422194,318.23154,-9.3224487
145.568,-0.067068271,9.4247932,0.0,0,18.0,300.0,0.98953295,-0.335603,17.784006,318.81186,-9.324851
145.5702,0.010074927,9.4196968,0.0,0,18.0,300.0,0.98904479,0.02789879,18.096375,319.14682,-9.3271132
145.5724,-0.024599172,9.4305944,0.0,0,18.0,300.0,0.9902789,-0.11698268,18.334438,319.48175,-9.3281622
145.5746,0.014686975,9.4260912,0.0,0,18.0,300.0,0.99013555,0.03895494,18.486835,319.81671,-9.3309927
145.5768,-0.0069399537,9.4373112,0.0,0,18.0,300.0,0.99179327,-0.04438252,18.526386,320.15167,-9.3355484
145.579,-0.058483355,9.4388323,0.0,0,18.0,300.0,0.99208355,-0.21077746,18.461327,320.61386,-9.3427515
145.5812,-0.068016849,9.4563189,0.0,0,18.0,300.0,0.99538451,-0.31177193,18.340431,321.1026,-9.355135
145.5834,-0.084366389,9.463294,0.0,0,18.0,300.0,0.99673951,-0.41014153,18.213726,321.59134,-9.3675508
145.5856,-0.11424682,9.4820442,0.0,0,18.0,300.0,1.000131,-0.57155317,18.110722,322.08011,-9.3820629
145.5878,-0.097271241,9.4913425,0.0,0,18.0,300.0,1.0016723,-0.49485987,18.049366,322.23248,-9.3994198
145.59,-0.014552632,9.516098,0.0,0,18.0,300.0,1.0064878,-0.14986564,18.039621,321.48798,-9.4151688
145.5922,0.044384703,9.5304394,0.0,0,18.0,300.0,1.00851,0.15398338,18.043247,320.74344,-9.4348478
145.5944,0.02846445,9.5483227,0.0,0,18.0,300.0,1.012315,0.13613363,18.058952,319.9989,-9.4518204
145.5966,0.0033706145,9.5634842,0.0,0,18.0,300.0,1.0145762,0.04554588,18.083151,319.25436,-9.4705362
145.5988,-0.053405426,9.5868454,0.0,0,18.0,300.0,1.0194858,-0.21069415,18.107241,318.64532,-9.4870815
145.601,-0.14444268,9.5979137,0.0,0,18.0,300.0,1.0208411,-0.64617157,18.122707,318.08945,-9.5033045
145.6032,-0.18843116,9.6154242,0.0,0,18.0,300.0,1.0247867,-0.87281114,18.137033,317.53357,-9.5191107
145.6054,-0.12017646,9.6253843,0.0,0,18.0,300.0,1.0259618,-0.62251598,18.146544,316.97769,-9.5347252
145.6076,-0.0084684165,9.643568,0.0,0,18.0,300.0,1.0303822,-0.12156596,18.145859,316.651,-9.5493698
145.6098,0.047247853,9.6553316,0.0,0,18.0,300.0,1.0313493,0.15121222,18.140509,317.49591,-9.5637798
145.612,0.052899752,9.6694365,0.0,0,18.0,300.0,1.0349703,0.24744919,18.13727,318.34082,-9.5788355
145.6142,0.02919486,9.6862211,0.0,0,18.0,300.0,1.0370803,0.18311407,18.139753,319.18573,-9.5935049
145.6164,-0.034084346,9.7067194,0.0,0,18.0,300.0,1.0422628,-0.073710583,18.138371,320.03061,-9.6104145
145.6186,-0.11375906,9.7241449,0.0,0,18.0,300.0,1.0441586,-0.45646149,18.135798,320.41815,-9.6260576
145.6208,-0.17442851,9.7376289,0.0,0,18.0,300.0,1.0480418,-0.72076005,18.133852,320.51215,-9.6419525
145.623,-0.15181606,9.7516918,0.0,0,18.0,300.0,1.0494337,-0.70938981,18.131304,320.60614,-9.6588335
145.6252,-0.058004595,9.7687569,0.0,0,18.0,300.0,1.054141,-0.35582763,18.12702,320.70013,-9.6753111
145.6274,0.025587382,9.7848969,0.0,0,18.0,300.0,1.0555516,0.061716381,18.122402,320.79483,-9.6917067
145.6296,0.055903636,9.7965851,0.0,0,18.0,300.0,1.0594618,0.22886093,18.123055,320.90189,-9.7080517
145.6318,0.04563161,9.8120041,0.0,0,18.0,300.0,1.0608041,0.2052211,18.122097,321.00897,-9.7221165
145.634,-0.005644138,9.832551,0.0,0,18.0,300.0,1.0663933,0.018856937,18.11948,321.11603,-9.7370949
145.6362,-0.091592476,9.8503208,0.0,0,18.0,300.0,1.068103,-0.33999154,18.11808,321.22308,-9.75348
145.6384,-0.15383726,9.8615818,0.0,0,18.0,300.0,1.0722308,-0.65409923,18.114721,321.53433,-9.7697029
145.6406,-0.16248648,9.8781528,0.0,0,18.0,300.0,1.0735431,-0.7288034,18.114737,322.04974,-9.785759
145.6428,-0.10495037,9.8945875,0.0,0,18.0,300.0,1.078935,-0.50754327,18.113886,322.56516,-9.8027725
145.645,0.0021615352,9.914506,0.0,0,18.0,300.0,1.0804139,-0.083842039,18.106194,323.08057,-9.8169355
145.6472,0.064293057,9.9212685,0.0,0,18.0,300.0,1.0840489,0.20872898,18.104839,323.59601,-9.8317862
145.6494,0.052083917,9.937994,0.0,0,18.0,300.0,1.0852526,0.27063987,18.107038,323.75696,-9.8486843
145.6516,0.016298128,9.951705,0.0,0,18.0,300.0,1.0902082,0.093461968,18.105795,323.89749,-9.8640709
145.6538,-0.058157396,9.9742079,0.0,0,18.0,300.0,1.0922004,-0.21143305,18.104767,324.03799,-9.8805828
145.656,-0.13306376,9.9849644,0.0,0,18.0,300.0,1.0969467,-0.50494808,18.100758,324.1785,-9.8959293
145.6582,-0.17381644,10.005419,0.0,0,18.0,300.0,1.0984018,-0.74675333,18.102348,324.4158,-9.9112835
145.6604,-0.14351265,10.018854,0.0,0,18.0,300.0,1.1037135,-0.66032684,18.102255,324.80392,-9.9288931
145.6626,-0.047176629,10.038079,0.0,0,18.0,300.0,1.1050032,-0.28602532,18.100492,325.19202,-9.9454155
145.6648,0.048179224,10.044415,0.0,0,18.0,300.0,1.1088215,0.16656411,18.098991,325.58014,-9.9594965
145.667,0.072953597,10.065743,0.0,0,18.0,300.0,1.1106204,0.30177447,18.101166,325.96823,-9.9753008
145.6692,0.022060324,10.080354,0.0,0,18.0,300.0,1.116256,0.13557771,18.100914,325.61761,-9.9907084
145.6714,-0.029984958,10.101467,0.0,0,18.0,300.0,1.1176146,-0.038462751,18.098579,325.12244,-10.00631
145.6736,-0.10599554,10.10758,0.0,0,18.0,300.0,1.1216465,-0.38754946,18.097479,324.62726,-10.023664
145.6758,-0.15635934,10.128908,0.0,0,18.0,300.0,1.1234859,-0.62580317,18.099684,324.13211,-10.039124
145.678,-0.15458634,10.146047,0.0,0,18.0,300.0,1.1296213,-0.66286504,18.098492,323.57471,-10.055456
145.6802,-0.091482975,10.170842,0.0,0,18.0,300.0,1.1317186,-0.42357433,18.097185,322.85873,-10.072362
145.6824,0.012564979,10.170943,0.0,0,18.0,300.0,1.1347001,-0.028003158,18.094528,322.14276,-10.087677
145.6846,0.067836545,10.190162,0.0,0,18.0,300.0,1.135986,0.26115623,18.096317,321.42679,-10.102236
145.6868,0.062366933,10.198552,0.0,0,18.0,300.0,1.1407822,0.25797167,18.093775,320.71082,-10.117092
145.689,-0.0024398307,10.22733,0.0,0,18.0,300.0,1.1431329,0.028020347,18.087496,320.40344,-10.133457
145.6912,-0.08042787,10.234529,0.0,0,18.0,300.0,1.1480511,-0.27108499,18.092556,320.24927,-10.14927
145.6934,-0.14393796,10.256217,0.0,0,18.0,300.0,1.1498003,-0.53621835,18.091825,320.09509,-10.165543
145.6956,-0.15538134,10.267153,0.0,0,18.0,300.0,1.1551092,-0.62878138,18.094439,319.94089,-10.181767
145.6978,-0.10946821,10.293677,0.0,0,18.0,300.0,1.1572772,-0.49707559,18.088652,319.90466,-10.197455
145.7,-0.025685148,10.29434,0.0,0,18.0,300.0,1.1607165,-0.14955993,18.086992,320.43329,-10.213141
145.7022,0.067435302,10.317982,0.0,0,18.0,300.0,1.1631416,0.25319201,18.086519,320.96191,-10.228537
145.7044,0.088635832,10.327296,0.0,0,18.0,300.0,1.1679735,0.364353,18.084517,321.49051,-10.244658
145.7066,0.031403475,10.353951,0.0,0,18.0,300.0,1.1702336,0.15446094,18.085306,322.01913,-10.26
145.7088,-0.064258441,10.360909,0.0,0,18.0,300.0,1.1748064,-0.16270308,18.087099,322.7713,-10.275405
145.711,-0.13260867,10.383676,0.0,0,18.0,300.0,1.1771368,-0.45854944,18.088648,323.66153,-10.292041
145.7132,-0.14744569,10.392186,0.0,0,18.0,300.0,1.1817117,-0.5907281,18.086233,324.55176,-10.307869
145.7154,-0.13730526,10.419459,0.0,0,18.0,300.0,1.1844419,-0.55248135,18.083832,325.44196,-10.324031
145.7176,-0.060340472,10.420956,0.0,0,18.0,300.0,1.1878165,-0.31174153,18.085995,326.26959,-10.340249
145.7198,0.037637185,10.442822,0.0,0,18.0,300.0,1.1902212,0.082351446,18.084143,326.1759,-10.355382
145.722,0.081370197,10.452782,0.0,0,18.0,300.0,1.1950381,0.29710862,18.083261,326.08221,-10.370921
145.7242,0.066590898,10.477,0.0,0,18.0,300.0,1.1971036,0.25599226,18.080528,325.98856,-10.386743
145.7264,-0.0068118689,10.481232,0.0,0,18.0,300.0,1.201165,0.0031773497,18.079809,325.89487,-10.401854
145.7286,-0.1055477,10.506858,0.0,0,18.0,300.0,1.2042938,-0.35968786,18.081263,325.84207,-10.418875
145.7308,-0.15739247,10.517444,0.0,0,18.0,300.0,1.2094064,-0.55474526,18.08226,325.82867,-10.434232
145.733,-0.1426414,10.546103,0.0,0,18.0,300.0,1.2126424,-0.57817227,18.079967,325.81528,-10.450312
145.7352,-0.087240696,10.545977,0.0,0,18.0,300.0,1.2153249,-0.38481191,18.080069,325.80191,-10.466372
145.7374,0.0036223161,10.567787,0.0,0,18.0,300.0,1.218106,-0.05836146,18.076136,325.78851,-10.482207
145.7396,0.072764017,10.573993,0.0,0,18.0,300.0,1.2217958,0.20938246,18.077257,325.95398,-10.497189
145.7418,0.082688466,10.601718,0.0,0,18.0,300.0,1.2254199,0.30442002,18.077425,326.12796,-10.51339
145.744,0.020732058,10.607654,0.0,0,18.0,300.0,1.2292621,0.12748957,18.072048,326.30194,-10.529112
145.7462,-0.06756001,10.633931,0.0,0,18.0,300.0,1.2331011,-0.1989052,18.072319,326.47589,-10.544351
145.7484,-0.15428726,10.642676,0.0,0,18.0,300.0,1.2370766,-0.53282332,18.06921,326.60172,-10.56081
145.7506,-0.17262654,10.667994,0.0,0,18.0,300.0,1.2408309,-0.63484174,18.071724,326.65524,-10.576862
145.7528,-0.11265138,10.673739,0.0,0,18.0,300.0,1.2442176,-0.45270109,18.072229,326.70877,-10.594666
145.755,-0.016372476,10.695841,0.0,0,18.0,300.0,1.2476571,-0.11175743,18.075081,326.7623,-10.609826
145.7572,0.050437178,10.701576,0.0,0,18.0,300.0,1.2506082,0.14012295,18.070457,326.81583,-10.624893
145.7594,0.086213611,10.729702,0.0,0,18.0,300.0,1.2550929,0.31795135,18.069727,326.96552,-10.640469
145.7616,0.061605796,10.736175,0.0,0,18.0,300.0,1.2586815,0.2396501,18.070831,327.13281,-10.658096
145.7638,-0.02440756,10.758511,0.0,0,18.0,300.0,1.2623591,-0.033864543,18.068703,327.30011,-10.674421
145.766,-0.12146451,10.767692,0.0,0,18.0,300.0,1.2659001,-0.37713179,18.068981,327.46738,-10.690316
145.7682,-0.18133633,10.794042,0.0,0,18.0,300.0,1.2705393,-0.62477332,18.069201,327.6113,-10.705519
145.7704,-0.1280587,10.802527,0.0,0,18.0,300.0,1.2740482,-0.51885849,18.067465,327.6983,-10.721054
145.7726,-0.054581866,10.821532,0.0,0,18.0,300.0,1.2775946,-0.24543032,18.066994,327.78528,-10.736847
145.7748,0.024583312,10.828434,0.0,0,18.0,300.0,1.280107,0.029686084,18.068014,327.87225,-10.753093
145.777,0.07577306,10.851604,0.0,0,18.0,300.0,1.2845556,0.23217504,18.062868,327.95926,-10.767228
145.7792,0.079421774,10.8592,0.0,0,18.0,300.0,1.287636,0.30060107,18.061909,327.95755,-10.781499
145.7814,0.029904716,10.88154,0.0,0,18.0,300.0,1.2921196,0.14894706,18.063391,327.9241,-10.797112
145.7836,-0.086334296,10.89236,0.0,0,18.0,300.0,1.2954053,-0.26318863,18.063393,327.89066,-10.813772
145.7858,-0.15715638,10.91825,0.0,0,18.0,300.0,1.3008634,-0.53026295,18.065851,327.85721,-10.829627
145.788,-0.15851533,10.926809,0.0,0,18.0,300.0,1.3037924,-0.54487509,18.065851,327.80551,-10.847591
145.7902,-0.085765272,10.944527,0.0,0,18.0,300.0,1.3078458,-0.34644404,18.064552,327.67166,-10.862214
145.7924,0.017604856,10.955375,0.0,0,18.0,300.0,1.3104893,-0.0012319878,18.058628,327.53784,-10.878072
145.7946,0.059264909,10.978091,0.0,0,18.0,300.0,1.3160273,0.17335324,18.061665,327.40402,-10.89491
145.7968,0.069508024,10.985308,0.0,0,18.0,300.0,1.3179295,0.24179548,18.061295,327.2702,-10.911757
145.799,0.047117144,11.004599,0.0,0,18.0,300.0,1.3229128,0.20474252,18.059546,327.30005,-10.9265
145.8012,-0.036254402,11.016788,0.0,0,18.0,300.0,1.3255813,-0.074912019,18.05629,327.42719,-10.942291
145.8034,-0.14224888,11.043544,0.0,0,18.0,300.0,1.3328241,-0.42167935,18.058048,327.55432,-10.957168
145.8056,-0.18377326,11.05378,0.0,0,18.0,300.0,1.3349215,-0.57727665,18.061325,327.68146,-10.973803
145.8078,-0.12800857,11.068621,0.0,0,18.0,300.0,1.3394619,-0.47678682,18.057732,327.81784,-10.988815
145.81,-0.028544452,11.077403,0.0,0,18.0,300.0,1.3406969,-0.15899706,18.059414,328.07211,-11.006017
145.8122,0.057614896,11.101402,0.0,0,18.0,300.0,1.3480337,0.15131693,18.056686,328.32639,-11.021449
145.8144,0.076775506,11.115367,0.0,0,18.0,300.0,1.3502222,0.26063177,18.058817,328.58066,-11.035504
145.8166,0.064338982,11.129913,0.0,0,18.0,300.0,1.3551483,0.2333087,18.055632,328.83493,-11.052546
145.8188,0.0038104753,11.143276,0.0,0,18.0,300.0,1.3575121,0.039827339,18.051641,329.0441,-11.068673
145.821,-0.091885641,11.164859,0.0,0,18.0,300.0,1.3645408,-0.26890609,18.059011,329.2114,-11.085089
145.8232,-0.17485206,11.179421,0.0,0,18.0,300.0,1.3668619,-0.527937,18.056684,329.37869,-11.100668
145.8254,-0.16625841,11.192868,0.0,0,18.0,300.0,1.3719079,-0.52869672,18.054214,329.54596,-11.115293
145.8276,-0.074107327,11.206447,0.0,0,18.0,300.0,1.3739547,-0.28256395,18.051664,329.71326,-11.130425
145.8298,0.025143659,11.224165,0.0,0,18.0,300.0,1.3804905,0.042510528,18.056694,329.68063,-11.146935
145.832,0.075425401,11.237654,0.0,0,18.0,300.0,1.3820198,0.23070331,18.054558,329.6405,-11.163272
145.8342,0.070738018,11.255038,0.0,0,18.0,300.0,1.3885096,0.23711264,18.049208,329.60037,-11.17968
145.8364,0.024594286,11.268151,0.0,0,18.0,300.0,1.3900139,0.10405444,18.050789,329.56021,-11.194495
145.8386,-0.048137985,11.287761,0.0,0,18.0,300.0,1.3975821,-0.11915684,18.05254,329.46808,-11.210869
145.8408,-0.13834314,11.305915,0.0,0,18.0,300.0,1.3999927,-0.38277325,18.052179,329.30078,-11.227493
145.843,-0.17379612,11.318383,0.0,0,18.0,300.0,1.4058827,-0.577838,18.049948,329.13348,-11.243455
145.8452,-0.12208281,11.332503,0.0,0,18.0,300.0,1.4075822,-0.41776606,18.049141,328.96622,-11.259381
145.8474,0.00097949884,11.347749,0.0,0,18.0,300.0,1.4142783,-0.037329089,18.052849,328.79892,-11.274261
145.8496,0.064205699,11.362416,0.0,0,18.0,300.0,1.4152582,0.19158275,18.048256,328.51727,-11.289486
145.8518,0.083921522,11.376433,0.0,0,18.0,300.0,1.4220216,0.2351274,18.048025,328.21616,-11.30453
145.854,0.044109143,11.394477,0.0,0,18.0,300.0,1.4236828,0.17855684,18.04987,327.91504,-11.32128
145.8562,-0.025574531,11.410032,0.0,0,18.0,300.0,1.4314688,-0.044868562,18.050016,327.61392,-11.338085
145.8584,-0.10302208,11.431127,0.0,0,18.0,300.0,1.4341769,-0.27570552,18.047531,327.36499,-11.354314
145.8606,-0.15530448,11.441291,0.0,0,18.0,300.0,1.4401554,-0.47517011,18.049276,327.23785,-11.369982
146.7609,-0.049486432,11.552731,0.0,0,18.0,1.621674e-10,1.4705542,-0.14482711,18.00009,265.86856,-11.484591
147.8609,-0.053822141,11.551794,0.0,0,18.0,1.6196895e-25,1.470075,-0.15753484,17.999691,237.61786,-11.483729
148.9609,-0.049655642,11.552212,0.0,0,18.0,1.617715e-40,1.4704335,-0.14651296,17.999516,224.67474,-11.484165
150.0609,-0.04564457,11.552444,0.0,0,18.0,1.4012985e-45,1.4704185,-0.13064921,17.999916,200.83881,-11.484043
151.1609,-0.051915549,11.552851,0.0,0,18.0,1.4012985e-45,1.4703882,-0.15638126,17.999166,180.18993,-11.48452
152.2609,-0.054380458,11.552883,0.0,0,18.0,1.4012985e-45,1.4705559,-0.15737401,18.001394,163.77136,-11.484649
153.3609,-0.055358265,11.552412,0.0,0,18.0,1.4012985e-45,1.4702847,-0.16326234,18.000072,157.98929,-11.483766
154.4609,-0.057715371,11.552193,0.0,0,18.0,1.4012985e-45,1.4703761,-0.17064406,17.999195,149.8212,-11.483666
155.5609,-0.060425781,11.552658,0.0,0,18.0,1.4012985e-45,1.4702854,-0.17644343,17.999964,142.18343,-11.483551
156.6609,-0.050025579,11.55272,0.0,0,18.0,1.4012985e-45,1.4706179,-0.1446384,18.001547,131.32008,-11.484134
157.7609,-0.054102808,11.553261,0.0,0,18.0,1.4012985e-45,1.4706508,-0.16051531,18.000895,126.35034,-11.484502
158.8609,-0.051302657,11.553509,0.0,0,18.0,1.4012985e-45,1.4706351,-0.14850403,17.999331,120.15657,-11.484318
159.9609,-0.051511042,11.553352,0.0,0,18.0,1.4012985e-45,1.4707122,-0.15312842,17.999998,115.4453,-11.484307
161.0609,-0.060903691,11.553315,0.0,0,18.0,1.4012985e-45,1.4705899,-0.17917342,17.999983,109.82147,-11.483929
162.1609,-0.054323047,11.553868,0.0,0,18.0,1.4012985e-45,1.4708781,-0.15827248,17.999554,101.94742,-11.483869
163.2609,-0.057644192,11.554075,0.0,0,18.0,1.4012985e-45,1.470767,-0.17230734,17.99992,99.963913,-11.483835
164.3609,-0.062610716,11.553529,0.0,0,18.0,1.4012985e-45,1.4708354,-0.18148707,17.999462,92.032616,-11.483978
165.4609,-0.052786462,11.553829,0.0,0,18.0,1.4012985e-45,1.4708985,-0.15448201,18.000019,88.230301,-11.483962
166.5609,-0.055185821,11.554277,0.0,0,18.0,1.4012985e-45,1.4707532,-0.16452128,17.998812,87.288048,-11.483712
167.6609,-0.056987207,11.554349,0.0,0,18.0,1.4012985e-45,1.4710895,-0.16578612,18.000414,84.195663,-11.483861
168.7609,-0.055147715,11.554271,0.0,0,18.0,1.4012985e-45,1.4708427,-0.161431,17.999441,80.742798,-11.483556
169.8609,-0.062058557,11.554833,0.0,0,18.0,1.4012985e-45,1.4710941,-0.17958558,17.999247,75.644318,-11.483683
170.9609,-0.061866663,11.554667,0.0,0,18.0,1.4012985e-45,1.4709601,-0.17854223,17.99984,71.651901,-11.483562
172.0609,-0.056194063,11.554868,0.0,0,18.0,1.4012985e-45,1.4711267,-0.1661467,17.999722,67.004745,-11.483613
173.1609,-0.063236624,11.555128,0.0,0,18.0,1.4012985e-45,1.4712672,-0.18451814,18.000685,64.8703,-11.483293
174.2609,-0.054301452,11.554952,0.0,0,18.0,1.4012985e-45,1.470939,-0.15944611,17.999098,66.036766,-11.483262
175.3609,-0.054087225,11.555155,0.0,0,18.0,1.4012985e-45,1.4713384,-0.16010809,17.99968,63.704765,-11.483461
176.4609,-0.054695085,11.555627,0.0,0,18.0,1.4012985e-45,1.471285,-0.15759388,17.999346,59.987129,-11.483809
177.5609,-0.051092643,11.555588,0.0,0,18.0,1.4012985e-45,1.4712192,-0.146346,17.999008,58.527729,-11.483699
178.6609,-0.057396092,11.555783,0.0,0,18.0,1.4012985e-45,1.4713053,-0.17048301,18.000702,56.792755,-11.48342
179.7609,-0.05620249,11.5563,0.0,0,18.0,1.4012985e-45,1.4715044,-0.16398764,17.99968,53.076569,-11.483956
180.8609,-0.044830114,11.556481,0.0,0,18.0,1.4012985e-45,1.4716623,-0.12993054,18.000441,50.740387,-11.483989
181.9609,-0.051546972,11.556583,0.0,0,18.0,1.4012985e-45,1.4714419,-0.15352516,18.000095,49.558975,-11.483915
183.0609,-0.05310322,11.556917,0.0,0,18.0,1.4012985e-45,1.4718369,-0.15719572,18.00013,48.519558,-11.484078
184.1609,-0.053726241,11.556921,0.0,0,18.0,1.4012985e-45,1.4717593,-0.15786843,18.000275,47.913536,-11.483911
185.2609,-0.057250876,11.557239,0.0,0,18.0,1.4012985e-45,1.47168,-0.16670068,18.00013,46.496681,-11.483971
186.3609,-0.052592818,11.557233,0.0,0,18.0,1.4012985e-45,1.4718015,-0.15410601,18.000559,47.041977,-11.483992
187.4609,-0.059521489,11.55715,0.0,0,18.0,1.4012985e-45,1.4716804,-0.17849822,17.999594,44.181232,-11.483517
188.5609,-0.054840863,11.557478,0.0,0,18.0,1.4012985e-45,1.4719245,-0.15844934,17.999609,42.610256,-11.483596
189.6609,-0.054705665,11.557343,0.0,0,18.0,1.4012985e-45,1.4716983,-0.15678625,17.999733,41.352413,-11.483267
190.7609,-0.059567343,11.557155,0.0,0,18.0,1.4012985e-45,1.4718827,-0.17647579,18.000143,40.298683,-11.483207
191.8609,-0.063736141,11.557508,0.0,0,18.0,1.4012985e-45,1.4719677,-0.18559751,18.000076,39.671749,-11.483036
192.9609,-0.045937743,11.558109,0.0,0,18.0,1.4012985e-45,1.4718578,-0.13497235,17.999058,39.134598,-11.48337
194.0609,-0.058430769,11.557923,0.0,0,18.0,1.4012985e-45,1.472069,-0.16887701,18.000076,37.668617,-11.483619
195.1609,-0.062473055,11.558035,0.0,0,18.0,1.4012985e-45,1.4719663,-0.17634547,17.999922,36.551723,-11.483317
196.2609,-0.063110538,11.558273,0.0,0,18.0,1.4012985e-45,1.472049,-0.18694463,18.000387,36.262459,-11.483089
197.3609,-0.058480285,11.558139,0.0,0,18.0,1.4012985e-45,1.4719744,-0.17060877,17.999815,35.995319,-11.483301
198.4609,-0.063132517,11.558405,0.0,0,18.0,1.4012985e-45,1.4721568,-0.18512037,17.999517,35.738876,-11.483541
199.5609,-0.061762542,11.558633,0.0,0,18.0,1.4012985e-45,1.4722652,-0.18154401,17.999781,34.672768,-11.483368
200.6609,-0.065328941,11.558841,0.0,0,18.0,1.4012985e-45,1.4720852,-0.19078404,17.999435,33.798794,-11.483095
201.7609,-0.063051701,11.558505,0.0,0,18.0,1.4012985e-45,1.4723139,-0.18460292,17.99934,34.428062,-11.482998
202.8609,-0.059278563,11.559326,0.0,0,18.0,1.4012985e-45,1.4723393,-0.17391621,18.000101,33.720783,-11.483185
203.9609,-0.064079486,11.559661,0.0,0,18.0,1.4012985e-45,1.4723929,-0.18643348,17.99995,32.87608,-11.48336
205.0609,-0.057998963,11.559516,0.0,0,18.0,1.4012985e-45,1.4724575,-0.16813658,17.999498,32.217411,-11.483103
205.8609,-0.051778574,11.559269,0.0,0,18.0,1.4012985e-45,1.4724362,-0.1498749,18.000055,32.288418,-11.483523