File: examples/dan-msc-case-studies/CS3/data/01 raw data/baron_test_110.csv
Time(sec),Force(kN),Jaw(mm),PowAngle(deg),Power(W),Pram,PTemp,Strain,Stress(MPa),Stroke(mm),TC1(C),wedge(mm)
0.0,1.1319551,-0.050373081,0.0,0,11.076097,0.0,-0.0033439337,14.473775,11.076775,25.693802,-9.1401215
1.1,1.0619639,-0.0019150722,0.0,0,11.076097,3.2158816,-0.0001383685,13.519725,11.076243,25.692026,-9.4915991
2.2,1.0254434,-0.0019560519,0.0,0,11.076097,6.5158806,-0.00012322591,13.055845,11.075334,25.712538,-9.488883
3.3,1.010233,-0.0020828485,0.0,0,11.076097,9.8158827,-0.00012727029,12.884501,11.0758,25.704266,-9.4879293
4.4,0.98698568,-0.0019727675,0.0,0,11.076097,13.115879,-0.00013741938,12.576243,11.076305,25.630739,-9.4857559
5.5,0.97286594,-0.0019237654,0.0,0,11.076097,16.415888,-0.00013205483,12.364586,11.076862,25.589567,-9.4837751
6.6,0.96015382,-0.0017543475,0.0,0,11.076097,19.715881,-9.9782366e-05,12.214176,11.076835,25.626143,-9.4816399
7.7,0.94737911,-0.0016430749,0.0,0,11.076097,23.015879,-0.00011099367,12.075426,11.076232,25.648735,-9.4797773
8.8,0.94639421,-0.0017321379,2.4214997,0,11.076097,26.315884,-0.00011078043,12.050557,11.07632,25.564144,-9.4775352
9.9,0.9412626,-0.0013056352,26.089008,0,11.076097,29.615887,-7.5840449e-05,11.969682,11.07612,25.548603,-9.475914
11.0,0.94248152,-0.0019835245,36.971733,0,11.076097,32.915878,-0.00014911014,11.995534,11.076221,26.063179,-9.4744129
12.1,0.95839131,-0.0047109635,42.888088,0,11.076097,36.215878,-0.00029839121,12.221932,11.076097,27.57666,-9.4727859
13.2,0.96445596,-0.0078056767,46.575756,0,11.076097,39.515877,-0.0005168207,12.298674,11.076166,30.081722,-9.4703493
14.3,0.97623312,-0.01330139,48.448837,0,11.076097,42.81588,-0.00090716098,12.430576,11.076025,33.468826,-9.468956
15.4,0.98165697,-0.016709395,50.024014,0,11.076097,46.115883,-0.0011072053,12.518436,11.076123,37.213932,-9.4666281
16.5,0.99032027,-0.020495903,50.736,0,11.076097,49.415894,-0.001356689,12.640626,11.075846,41.479721,-9.4645472
17.6,1.008474,-0.024318757,50.925167,0,11.076097,52.715893,-0.001628285,12.855198,11.076733,45.787945,-9.4626703
18.7,1.0136921,-0.02834033,51.196285,0,11.076097,56.015896,-0.0018948356,12.919059,11.076132,50.053947,-9.4603348
19.8,1.0269568,-0.032990716,51.139927,0,11.076097,59.315903,-0.002188883,13.099842,11.075082,54.498592,-9.4587088
20.9,1.0359682,-0.035855565,50.43832,0,11.076097,62.615898,-0.0023974241,13.214914,11.075093,59.138081,-9.4570074
22.0,1.038721,-0.038948499,50.042889,0,11.076097,65.915878,-0.0026066869,13.263902,11.075998,63.32478,-9.4552727
23.1,1.0447605,-0.041807666,50.041771,0,11.076097,69.215889,-0.0027938064,13.331369,11.076687,67.138512,-9.4535027
24.2,1.0459461,-0.044588555,49.6376,0,11.076097,72.515892,-0.002960131,13.365482,11.076132,71.040329,-9.4514246
25.3,1.0450436,-0.048079569,49.633629,0,11.076097,75.815887,-0.0032174664,13.349388,11.076049,74.662949,-9.4494171
26.4,1.050359,-0.051463719,49.699905,0,11.076097,79.115906,-0.003423474,13.428162,11.076022,78.0802,-9.4476843
27.5,1.0490195,-0.053319518,49.672028,0,11.076097,82.415901,-0.0035419397,13.379555,11.075325,81.507233,-9.4456129
28.6,1.0472728,-0.055306539,50.419121,0,11.076097,85.715904,-0.0037026193,13.383605,11.075847,84.498024,-9.4443092
29.7,1.0564412,-0.058528751,50.890522,0,11.076097,89.0159,-0.0038870396,13.514993,11.075898,87.439674,-9.4424715
30.8,1.0621775,-0.061578885,51.394203,0,11.076097,92.315903,-0.0040764608,13.580454,11.074987,90.589455,-9.4400835
31.9,1.0613533,-0.064147234,51.696018,0,11.076097,95.615913,-0.0042893384,13.576885,11.075982,93.922363,-9.438241
33.0,1.0634037,-0.067440309,51.921032,0,11.076097,98.915901,-0.0044829464,13.61764,11.077049,97.270172,-9.4366112
34.1,1.0764104,-0.071469046,51.932377,0,11.076097,102.2159,-0.0047360156,13.772285,11.07558,100.97774,-9.434721
35.2,1.081442,-0.074347362,51.933613,0,11.076097,105.5159,-0.0049625444,13.833124,11.075045,104.33603,-9.4325542
36.3,1.0656501,-0.07658083,52.283932,0,11.076097,108.8159,-0.0050782138,13.629529,11.076553,107.53003,-9.4304438
37.4,1.0685297,-0.079991773,52.283936,0,11.076097,112.11589,-0.0053010774,13.693615,11.076279,111.08063,-9.4283304
38.5,1.0730841,-0.083329298,52.97599,0,11.076097,115.41589,-0.0055646054,13.738521,11.075926,113.84171,-9.4266109
39.6,1.0791628,-0.086460859,53.551247,0,11.076097,118.71588,-0.0057398737,13.817375,11.075453,116.94554,-9.4248381
40.7,1.0819193,-0.089732639,53.975826,0,11.076097,122.01589,-0.0059470851,13.85164,11.075749,120.11219,-9.4228754
41.8,1.0880795,-0.093446866,53.975742,0,11.076097,125.31589,-0.0062239156,13.937374,11.075274,123.67916,-9.421073
42.9,1.0855677,-0.097721949,54.296371,0,11.076097,128.61601,-0.0064733117,13.92361,11.075502,127.05081,-9.4193144
44.0,1.0876904,-0.099786855,53.975643,0,11.076097,131.91589,-0.0066141421,13.937923,11.076018,130.87483,-9.4175835
45.1,1.0794398,-0.10282473,53.760143,0,11.076097,135.2159,-0.0068463827,13.835349,11.075937,134.50087,-9.4159031
46.2,1.085399,-0.10536756,53.316654,0,11.076097,138.5159,-0.0070016827,13.92572,11.074917,138.36385,-9.4140501
47.3,1.0872065,-0.10775138,53.100113,0,11.076097,141.8159,-0.0071505434,13.940246,11.076084,141.92279,-9.4122353
48.4,1.0858054,-0.11043276,53.579933,0,11.076097,145.11589,-0.0073455391,13.929676,11.077061,144.77904,-9.4106236
49.5,1.0939111,-0.11473815,53.925953,0,11.076097,148.41589,-0.0076269894,14.036312,11.074925,147.79596,-9.4086628
50.6,1.0886973,-0.11679175,54.43745,0,11.076097,151.71588,-0.0077487272,13.974606,11.076553,150.67226,-9.4070978
51.7,1.0900525,-0.1197285,54.624023,0,11.076097,155.0159,-0.0079520084,14.000534,11.075646,153.84314,-9.405405
52.8,1.0886823,-0.12257563,55.239216,0,11.076097,158.31589,-0.0081477435,13.984969,11.075951,156.83195,-9.40341
53.9,1.0838708,-0.12591104,55.53561,0,11.076097,161.61589,-0.0083638486,13.920326,11.075483,160.06711,-9.4017553
55.0,1.0910947,-0.12911977,55.843506,0,11.076097,164.91589,-0.0085612154,14.018689,11.075114,163.28722,-9.400012
56.1,1.0949848,-0.13180198,55.927776,0,11.076097,168.21588,-0.0087618716,14.07557,11.075534,166.70151,-9.3977594
57.2,1.0880513,-0.13569939,56.425766,0,11.076097,171.5159,-0.0090143373,13.978117,11.075727,169.6225,-9.3959455
58.3,1.094061,-0.14102142,56.547115,0,11.076097,174.81589,-0.0093422327,14.061211,11.075624,173.17395,-9.394145
59.4,1.0943307,-0.14286503,56.129158,0,11.076097,178.11589,-0.0094991596,14.060984,11.076261,177.2198,-9.3924332
60.5,1.089613,-0.1461229,56.38958,0,11.076097,181.41589,-0.0096872756,14.017264,11.076678,180.40877,-9.3907328
61.6,1.0886199,-0.14909355,56.711422,0,11.076097,184.71588,-0.0098639941,14.011738,11.075046,183.42296,-9.3887138
62.7,1.0889001,-0.15196022,56.485458,0,11.076097,188.01588,-0.010094701,14.003896,11.076446,187.22075,-9.3866243
63.8,1.0946646,-0.15440419,56.164192,0,11.076097,191.31589,-0.010224958,14.086543,11.075901,190.97061,-9.3849487
64.9,1.0924847,-0.15752347,56.671173,0,11.076097,194.61591,-0.010432143,14.053338,11.076456,193.91899,-9.3828135
66.0,1.1004435,-0.16178843,56.986076,0,11.076097,197.91589,-0.010747562,14.161151,11.076039,196.84369,-9.3811741
67.1,1.0943208,-0.16491017,57.531326,0,11.076097,201.2159,-0.010923924,14.082368,11.075614,199.71924,-9.3795357
68.2,1.0879159,-0.16755047,57.889671,0,11.076097,204.51591,-0.011107438,14.012734,11.076488,202.79919,-9.3773537
69.3,1.0927962,-0.17088789,58.137726,0,11.076097,207.8159,-0.011334843,14.072545,11.075198,206.07886,-9.3754063
70.4,1.0955459,-0.17411211,58.58926,0,11.076097,211.11589,-0.011544406,14.108883,11.07643,209.16284,-9.3740635
71.5,1.0982609,-0.17806421,58.853752,0,11.076097,214.41589,-0.011804226,14.159791,11.076207,212.56754,-9.3720989
72.6,1.0988973,-0.18136756,58.918133,0,11.076097,217.7159,-0.0120183,14.175033,11.075147,215.94897,-9.3702459
73.7,1.1007376,-0.18696614,58.856907,0,11.076097,221.0159,-0.012411924,14.19175,11.076181,219.57463,-9.3683462
74.8,1.095325,-0.19044989,59.106438,0,11.076097,224.3159,-0.01260736,14.118822,11.075783,222.91736,-9.3667145
75.9,1.0909541,-0.19338106,59.334667,0,11.076097,227.61591,-0.012791129,14.076096,11.075726,226.19354,-9.3647575
77.0,1.0901694,-0.19653399,59.493408,0,11.076097,230.91589,-0.013036222,14.094421,11.076413,229.42052,-9.3631153
78.1,1.100844,-0.19985706,59.599762,0,11.076097,234.21588,-0.013219733,14.202473,11.075947,232.98666,-9.3610067
79.2,1.0959938,-0.20333453,59.18869,0,11.076097,237.5159,-0.013438585,14.121225,11.075275,236.88052,-9.3594818
80.3,1.0908768,-0.20576762,58.857769,0,11.076097,240.81589,-0.013635554,14.079004,11.075493,240.72748,-9.3574924
81.4,1.1054887,-0.2097595,59.106438,0,11.076097,244.11591,-0.013885036,14.285441,11.0759,243.80113,-9.3558369
82.5,1.1060324,-0.21456935,59.599403,0,11.076097,247.41591,-0.014192334,14.290959,11.075916,246.5182,-9.3539801
83.6,1.0958477,-0.21662223,59.817978,0,11.076097,250.71591,-0.014332799,14.145654,11.076046,249.72392,-9.3518238
84.7,1.0923707,-0.21996537,60.268497,0,11.076097,254.0159,-0.014550027,14.120867,11.075163,252.50746,-9.3504305
85.8,1.0945085,-0.22335835,60.519527,0,11.076097,257.31616,-0.014782099,14.157227,11.075714,255.7854,-9.3481426
86.9,1.1019039,-0.22664188,60.539272,0,11.076097,260.61618,-0.014981735,14.246032,11.076629,259.2804,-9.3471928
88.0,1.1024104,-0.22987805,60.684048,0,11.076097,263.91592,-0.015224359,14.255103,11.076179,262.55173,-9.3456297
89.1,1.1097271,-0.23307987,61.00856,0,11.076097,267.21591,-0.015411035,14.353233,11.075196,265.70023,-9.3436327
90.2,1.1126097,-0.23847984,61.237389,0,11.076097,270.51593,-0.015757095,14.400822,11.075864,268.86328,-9.3420906
91.3,1.1025325,-0.24303156,61.667725,0,11.076097,273.81592,-0.016087594,14.260577,11.075685,271.8259,-9.3401623
92.4,1.0953329,-0.24512196,61.90794,0,11.076097,277.11591,-0.016206048,14.163253,11.076077,275.09747,-9.3382635
93.5,1.0946919,-0.24893805,62.127468,0,11.076097,280.41589,-0.016446186,14.1879,11.076318,278.37604,-9.3363647
94.6,1.105006,-0.252682,62.348671,0,11.076097,283.71588,-0.016717004,14.310673,11.075788,281.60876,-9.3340702
95.7,1.1012597,-0.25620812,62.626804,0,11.076097,287.0159,-0.016944161,14.25735,11.076619,284.88654,-9.332551
96.8,1.1065855,-0.2593455,62.753899,0,11.076097,290.31586,-0.017145269,14.33348,11.076283,288.31906,-9.3308525
97.9,1.100314,-0.26499277,62.822086,0,11.076097,293.61588,-0.017498525,14.268306,11.076707,291.85492,-9.3292751
99.0,1.1111529,-0.26950184,62.96265,0,11.076097,296.91586,-0.017818507,14.399243,11.076084,295.20596,-9.32759
100.1,1.0969056,-0.27204657,62.857677,0,11.076097,299.99548,-0.017965853,14.205906,11.076461,298.841,-9.3260012
101.2,1.099063,-0.27493069,60.792953,0,11.076097,299.99905,-0.018142853,14.237803,11.075687,302.18506,-9.3254337
102.3,1.1009178,-0.2760556,58.479568,0,11.076097,299.99905,-0.018240631,14.288778,11.075274,304.82303,-9.3257942
103.4,1.1080325,-0.27656111,56.426991,0,11.076097,299.99905,-0.018269544,14.372142,11.075799,306.50571,-9.3254194
104.5,1.0864133,-0.27909058,54.629623,0,11.076097,299.99905,-0.018430971,14.079169,11.076565,307.37451,-9.325139
105.6,1.0702723,-0.27737075,53.039688,0,11.076097,299.99905,-0.018314363,13.886524,11.076703,307.60974,-9.3248558
106.7,1.0659834,-0.27659428,52.051029,0,11.076097,299.99905,-0.018295083,13.820351,11.076282,307.32053,-9.324954
107.8,1.0615537,-0.276131,51.196548,0,11.076097,299.99905,-0.018236656,13.759717,11.076447,306.77557,-9.3253574
108.9,1.0560564,-0.27539295,50.822765,0,11.076097,299.99905,-0.018171418,13.684568,11.076558,306.02542,-9.3254004
110.0,1.0487726,-0.27420226,50.738434,0,11.076097,299.99905,-0.018136235,13.605667,11.076344,305.14972,-9.3256922
111.1,1.0492901,-0.2758593,50.82275,0,11.076097,299.99905,-0.018212449,13.612082,11.075805,304.18213,-9.3255081
112.2,1.0487446,-0.27402633,50.82275,0,11.076097,299.99905,-0.018091926,13.579094,11.076367,303.37598,-9.3257256
113.3,1.030225,-0.27389827,51.14769,0,11.076097,299.99905,-0.018096901,13.350977,11.076237,302.60574,-9.325469
114.4,0.95924234,-0.27451566,51.464767,0,11.076097,299.99905,-0.018151438,12.444462,11.076628,301.94135,-9.3253174
115.5,0.88616729,-0.27467871,51.73801,0,11.076097,299.99905,-0.018136097,11.510504,11.076211,301.34024,-9.3253021
116.6,0.81673664,-0.27497354,51.932369,0,11.076097,299.99905,-0.01814737,10.599819,11.075651,300.80972,-9.3245897
117.7,0.75835276,-0.27591151,52.426971,0,11.076097,299.99905,-0.0182503,9.8300791,11.075817,300.32526,-9.3245564
118.8,0.71585822,-0.27850816,52.635494,0,11.076097,299.99905,-0.018389883,9.2758503,11.075727,300.03342,-9.3245802
119.9,0.67757338,-0.27770907,52.975998,0,11.076097,299.99905,-0.018328216,8.785924,11.076351,299.77066,-9.3244562
121.0,0.67894548,-0.27813202,53.093918,0,11.076097,299.99905,-0.018372079,8.8234978,11.075466,299.61642,-9.325223
122.1,0.66512203,-0.27849531,53.31665,0,11.076097,299.99905,-0.018410407,8.6298103,11.076028,299.46552,-9.324996
123.2,0.66282338,-0.27895841,53.610794,0,11.076097,299.99905,-0.01842702,8.5976963,11.075604,299.34149,-9.3249254
124.3,0.66276032,-0.27891338,53.659958,0,11.076097,299.99905,-0.018401798,8.594264,11.076688,299.4343,-9.3247271
125.4,0.66493863,-0.28050995,53.657246,0,11.076097,299.99905,-0.018553765,8.6127491,11.075632,299.37314,-9.3251371
126.5,0.66258782,-0.28147295,53.90432,0,11.076097,299.99905,-0.01857214,8.5969868,11.075745,299.34467,-9.3247604
127.6,0.64815331,-0.28135106,53.971836,0,11.076097,299.99905,-0.018569695,8.4034872,11.07616,299.45505,-9.3252096
128.7,0.65300828,-0.28183177,53.969723,0,11.076097,299.99905,-0.018628094,8.4737301,11.076833,299.51474,-9.3250942
129.8,0.64266592,-0.28218597,53.897125,0,11.076097,299.99905,-0.018650725,8.3353815,11.075555,299.51669,-9.3247538
130.9,0.64705312,-0.28268507,53.968994,0,11.076097,299.99905,-0.018672628,8.4075184,11.075954,299.68896,-9.3248377
132.0,0.65639931,-0.28277978,53.834572,0,11.076097,299.99905,-0.018650569,8.5139008,11.075859,299.83054,-9.3248177
133.1,0.65672272,-0.28354904,53.657322,0,11.076097,299.99905,-0.018750114,8.5248365,11.075634,299.94547,-9.3249273
134.2,0.65401429,-0.28570139,53.65723,0,11.076097,299.99905,-0.018861806,8.492178,11.076501,299.97842,-9.3248529
135.3,0.64941651,-0.28579366,53.65723,0,11.076097,299.99905,-0.018846672,8.4215307,11.075395,300.0332,-9.3241968
136.4,0.64652407,-0.28535423,53.65723,0,11.076097,299.99905,-0.018850591,8.3932648,11.076677,300.08945,-9.3246698
137.5,0.64424425,-0.28545257,53.657223,0,11.076097,299.99905,-0.018861761,8.3621521,11.075127,300.07297,-9.3242006
138.6,0.65404975,-0.28567243,53.598312,0,11.076097,299.99905,-0.018861875,8.4872427,11.076388,300.13037,-9.3242397
139.7,0.64842802,-0.2863256,53.455807,0,11.076097,299.99905,-0.018888101,8.4178915,11.07552,300.17673,-9.3241739
140.8,0.64918721,-0.28620568,53.502895,0,11.076097,299.99905,-0.018917233,8.4215193,11.076696,300.11075,-9.3241386
141.9,0.6537509,-0.28654662,53.567547,0,11.076097,299.99905,-0.018913507,8.4942713,11.075847,300.06558,-9.3239717
143.0,0.64867121,-0.28690991,53.321281,0,11.076097,299.99905,-0.018947473,8.413805,11.076032,300.19162,-9.3242035
144.1,0.64738125,-0.28750536,53.418793,0,11.076097,299.99905,-0.018979883,8.420742,11.07741,300.12662,-9.3238697
145.13,0.65617067,-0.0034093712,53.434372,0,11.076097,299.99905,-0.00022194162,8.3456001,11.07575,300.06409,-9.3242836
145.2819,0.64284122,0.014864642,6.9310284,0,11.076099,6.0864735e-10,0.00083387707,8.2163773,11.072652,300.06348,-9.3240414
145.2841,0.65322447,0.013644094,0.0,0,11.076099,6.0790445e-25,0.0010718284,8.3131552,11.077127,300.07544,-9.3240232
145.2863,0.64481652,0.016177047,0.0,0,11.076099,6.0716300999999994e-40,0.00089789304,8.2389984,11.076477,300.07544,-9.3256454
145.2885,0.62992913,0.012194544,0.0,0,11.076099,0.0,0.0010237972,8.0590343,11.077432,300.07544,-9.3247652
145.2907,0.63098323,0.01223412,0.0,0,11.076099,0.0,0.00062517112,8.112462,11.077826,300.07544,-9.3240318
145.2929,0.62994403,0.011615506,0.0,0,11.076099,0.0,0.0010487983,7.9381719,11.071977,300.07544,-9.3240042
145.2951,0.63261175,0.016768854,0.0,0,11.076099,0.0,0.00083909574,8.0839996,11.075563,300.06378,-9.3237772
145.2973,0.62555081,0.011870579,0.0,0,11.076099,0.0,0.001047311,7.9391103,11.077191,300.05026,-9.3233805
145.2995,0.63642561,0.014240908,0.0,0,11.076099,0.0,0.00077336782,8.1250439,11.076235,300.03674,-9.3247948
145.3017,0.63887608,0.012513314,0.0,0,11.076099,0.0,0.0011515834,8.122798,11.078116,300.02325,-9.3243847
145.3039,0.63842446,0.017807122,0.0,0,11.076099,0.0,0.00084763241,8.2053452,11.075962,300.01404,-9.3244371
145.3061,0.63713604,0.010950264,0.0,0,11.076099,0.0,0.00096061965,8.0822554,11.075539,300.01404,-9.3257093
145.3083,0.6219418,0.013727948,0.0,0,11.076099,0.0,0.00074120593,7.9248638,11.074854,300.01404,-9.324585
145.3105,0.61802381,0.012209827,0.0,0,11.076099,0.0,0.0011530813,7.8388309,11.076706,300.01404,-9.3231554
145.3127,0.6212858,0.018628974,0.0,0,11.076099,0.0,0.00091592554,7.9014482,11.080026,300.01404,-9.3248711
145.3149,0.62122792,0.011941949,0.0,0,11.076099,0.0,0.0010350486,7.897162,11.076306,300.00882,-9.3237686
145.3171,0.62387568,0.012418579,0.0,0,11.076099,0.0,0.00073115813,7.9040675,11.078129,300.00208,-9.3250494
145.3193,0.63272446,0.010535367,0.0,0,11.076099,0.0,0.00094346621,8.0689106,11.078203,299.9953,-9.3243332
145.3215,0.63111645,0.019086702,0.0,0,11.076099,0.0,0.00093472813,8.0079613,11.075717,299.98856,-9.3235054
145.3237,0.63296431,0.010756596,0.0,0,11.076099,0.0,0.00095629238,8.0733633,11.075621,299.98642,-9.3241501
145.3259,0.62894768,0.013271851,0.0,0,11.076099,0.0,0.000733144,8.0225687,11.073947,299.99991,-9.3229218
145.3281,0.619744,0.011403229,0.0,0,11.076099,0.0,0.0010206406,7.9538541,11.077278,300.01343,-9.3241606
145.3303,0.60676539,0.018547781,0.0,0,11.063763,0.0,0.0010009544,7.6711106,11.078282,300.02695,-9.3245344
145.3325,0.61408097,0.012200526,0.0,0,10.735819,0.0,0.00096948043,7.8169184,11.074228,300.04044,-9.3231039
145.3347,0.62869787,0.014262249,0.0,0,10.404926,0.0,0.00086608081,7.9686298,11.07357,300.27963,-9.324584
145.3369,0.63933003,0.011137309,0.0,0,10.074035,0.0,0.00086395553,8.1455126,11.013923,300.62415,-9.3239393
145.3391,0.65594506,0.017692959,0.0,0,9.7431412,0.0,0.0010342264,8.3175354,10.823888,300.96866,-9.3241978
145.3413,0.65606403,0.012716562,0.0,0,9.4141388,0.0,0.0009703174,8.3169441,10.522046,301.31317,-9.3242302
145.3435,0.62086833,0.014124052,0.0,0,9.0922337,0.0,0.00082954037,7.885788,10.13585,302.02802,-9.3234444
145.3457,7.2096944,0.35659257,0.0,0,8.7703295,0.0,0.023569152,89.105392,9.7294531,305.08804,-9.3175726
145.3479,9.1235399,0.69672716,0.0,0,8.4631929,0.0,0.047037881,110.42272,9.3157024,308.14804,-9.3163776
145.3501,9.870244,1.0926206,0.0,0,8.1570406,0.0,0.075352952,116.29695,8.8913116,311.20804,-9.3160448
145.3523,10.016067,1.4667103,0.0,0,7.860775,0.0,0.10234992,115.02708,8.550046,314.26804,-9.3153267
145.3545,10.562306,1.7509743,0.0,0,7.5694952,0.0,0.12359839,118.80648,8.2325335,317.26694,-9.3161926
145.3567,10.771791,2.0615945,0.0,0,7.2838035,0.0,0.14741489,118.44149,7.9125457,320.10287,-9.3166561
145.3589,10.995438,2.3473401,0.0,0,7.0067787,0.0,0.16976897,118.12592,7.6254721,322.93881,-9.3162622
145.3611,11.363402,2.6121039,0.0,0,6.7313666,0.0,0.1910165,119.44229,7.3518219,325.77472,-9.315938
145.3633,11.600006,2.8713467,0.0,0,6.467802,0.0,0.21203643,119.47765,7.0861969,328.61066,-9.315115
145.3655,11.886463,3.1442068,0.0,0,6.2042418,0.0,0.23495288,119.50498,6.8164544,328.71118,-9.3167162
145.3677,12.201307,3.4029725,0.0,0,5.9515953,0.0,0.25657773,120.16852,6.5495057,327.78592,-9.3166389
145.3699,12.47622,3.6576021,0.0,0,5.7009273,0.0,0.27924025,120.09336,6.2937088,326.86069,-9.3152819
145.3721,12.764135,3.9131219,0.0,0,5.457253,0.0,0.30178806,120.1506,6.0359564,325.93542,-9.3162365
145.3743,13.062036,4.1698213,0.0,0,5.2187734,0.0,0.32546851,120.04523,5.779861,325.07602,-9.3163919
145.3765,13.33905,4.4208622,0.0,0,4.9838037,0.0,0.3484585,119.87481,5.5263395,324.51282,-9.3173714
145.3787,13.679436,4.6692467,0.0,0,4.7569838,0.0,0.37268409,119.90139,5.2751756,323.94962,-9.3185329
145.3809,13.99502,4.9186835,0.0,0,4.5305758,0.0,0.39658606,119.84602,5.0268197,323.38641,-9.3175325
145.3831,14.323343,5.1638703,0.0,0,4.3147016,0.0,0.42202082,119.52101,4.7845855,322.82321,-9.3166676
145.3853,14.675257,5.3979702,0.0,0,4.0989256,0.0,0.44526476,119.67635,4.5459166,322.57147,-9.317709
145.3875,15.034219,5.6221943,0.0,0,3.8911293,0.0,0.46976104,119.58803,4.3141603,322.49771,-9.3162479
145.3897,15.370766,5.8446221,0.0,0,3.6859133,0.0,0.49288756,119.48651,4.0959578,322.42398,-9.315052
145.3919,15.737318,6.0587096,0.0,0,3.4855206,0.0,0.51747465,119.39239,3.8841982,322.35022,-9.3155546
145.3941,16.077547,6.2681603,0.0,0,3.2902927,0.0,0.54010594,119.17672,3.6750712,322.29901,-9.3159523
145.3963,16.469578,6.4642677,0.0,0,3.0970623,0.0,0.56398672,119.259,3.4728956,322.47336,-9.3157396
145.3985,16.891647,6.6681232,0.0,0,2.9113381,0.0,0.5869754,119.51254,3.2742877,322.64767,-9.3151426
145.4007,17.351881,6.8618321,0.0,0,2.7256143,0.0,0.61182475,119.77294,3.0804,322.82199,-9.3140678
145.4029,17.844528,7.0588326,0.0,0,2.5483871,0.0,0.63468832,120.40079,2.8856122,322.99634,-9.3147326
145.4051,18.341936,7.2386312,0.0,0,2.3717272,0.0,0.65922678,120.77708,2.6971307,322.88132,-9.3136158
145.4073,18.887941,7.4280481,0.0,0,2.2008002,0.0,0.68238389,121.48281,2.5144093,322.52521,-9.3140707
145.4095,19.454262,7.6041117,0.0,0,2.0327642,0.0,0.70764065,122.00742,2.3335938,322.1691,-9.3137665
145.4117,20.008261,7.7901211,0.0,0,1.8679363,0.0,0.73120564,122.59091,2.1540828,321.81299,-9.3141127
145.4139,20.597237,7.949862,0.0,0,1.7080842,0.0,0.75544184,123.15569,1.9822322,321.45688,-9.3138285
145.4161,21.233105,8.1223021,0.0,0,1.5491643,0.0,0.77873272,124.02652,1.815956,316.92706,-9.3121967
145.4183,21.894598,8.2801752,0.0,0,1.3970972,0.0,0.80351734,124.72705,1.6571569,312.39725,-9.312974
145.4205,22.6038,8.4471045,0.0,0,1.2450333,0.0,0.82643211,125.88829,1.4963973,307.8674,-9.3122778
145.4227,23.347811,8.592267,0.0,0,1.0992643,0.0,0.85093725,126.86691,1.3419316,303.33759,-9.3118219
145.4249,24.147329,8.7498922,0.0,0,0.95463622,0.0,0.87414759,128.14099,1.1902435,300.57321,-9.3116999
145.4271,24.945194,8.8884993,0.0,0,0.8140732,0.0,0.89833122,129.26067,1.0431947,299.92737,-9.3111038
145.4293,25.792547,9.0398731,0.0,0,0.67652929,0.0,0.9215607,130.55077,0.89376575,299.28149,-9.3098803
145.4315,26.637079,9.1664352,0.0,0,0.54098582,0.0,0.94482154,131.78204,0.75453955,298.63562,-9.3105431
145.4337,27.502762,9.3033838,0.0,0,0.4100858,0.0,0.96709281,133.06909,0.6222257,297.98978,-9.3101635
145.4359,27.009205,9.4088955,0.0,0,0.27942529,0.0,0.98770946,128.71263,0.49556538,302.02469,-9.3095255
145.4381,25.489679,9.4354935,0.0,0,0.15489206,0.0,0.99108076,120.82563,0.44505644,306.52771,-9.3112173
145.4403,24.346891,9.4282227,0.0,0,0.030416043,0.0,0.99110776,115.08205,0.41667077,311.0307,-9.3142385
145.4425,23.842625,9.4381399,0.0,0,-0.091732524,0.0,0.99143159,112.70496,0.38732317,315.53369,-9.3150043
145.4447,23.822527,9.4405146,0.0,0,-0.21312852,0.0,0.99287838,112.41715,0.34559557,319.20975,-9.3148613
145.4469,23.946272,9.4546728,0.0,0,-0.33452454,0.0,0.99456656,112.78627,0.29018214,321.43869,-9.3154621
145.4491,23.997435,9.451314,0.0,0,-0.45592052,0.0,0.99488276,112.98396,0.22740421,323.66763,-9.3152695
145.4513,23.945078,9.4630985,0.0,0,-0.57731652,0.0,0.99636298,112.55172,0.17364921,325.89658,-9.3140469
145.4535,23.828009,9.4621916,0.0,0,-0.69871247,0.0,0.99654955,112.00982,0.12108884,328.12549,-9.3140755
145.4557,23.616276,9.4762907,0.0,0,-0.82010847,0.0,0.99857789,110.78387,0.078855805,329.78049,-9.3152256
145.4579,23.329548,9.4721966,0.0,0,-0.94150448,0.0,0.99825764,109.49441,0.045769215,331.30792,-9.3168755
145.4601,22.963842,9.4777555,0.0,0,-1.0629005,0.0,0.99939758,107.67577,0.024441807,332.83536,-9.3174295
145.4623,22.479673,9.4753094,0.0,0,-0.84332824,300.0,0.99869287,105.46407,0.014356879,334.36276,-9.3158073
145.4645,21.947187,9.4848557,0.0,0,-0.42304912,300.0,1.000773,102.77396,0.019824881,335.77658,-9.3164301
145.4667,21.49625,9.4799662,0.0,0,-0.0027696523,300.0,0.99930054,100.7996,0.024474399,336.88733,-9.3171606
145.4689,21.118803,9.4796448,0.0,0,0.4175092,300.0,1.0000213,98.956261,0.029371733,337.99808,-9.319129
145.4711,20.851299,9.4782467,0.0,0,0.83778834,300.0,0.99890435,97.778496,0.028996583,339.10883,-9.3189497
145.4733,20.599951,9.4862194,0.0,0,1.2580682,300.0,1.0012307,96.396271,0.026584584,340.21957,-9.3178978
145.4755,19.894882,9.4806232,0.0,0,1.6783469,300.0,0.99924821,93.408836,0.043478981,341.09619,-9.3180075
145.4777,18.412384,9.4745245,0.0,0,2.0986257,300.0,0.99929988,86.457008,0.10590245,341.88501,-9.3201761
145.4799,15.44968,9.466691,0.0,0,2.5189054,300.0,0.99661976,72.908218,0.22443126,342.67383,-9.3226681
145.4821,10.699618,9.4534416,0.0,0,2.9391847,300.0,0.99588621,50.866924,0.43170696,343.46265,-9.3270578
145.4843,0.29364949,9.2744226,0.0,0,3.3594637,300.0,0.96325022,1.3341849,0.80456918,344.0983,-9.3364105
145.4865,0.2963976,9.1260529,0.0,0,3.7797427,300.0,0.93882525,1.8558599,1.4294872,344.04483,-9.333415
145.4887,-0.39560032,9.0471954,0.0,0,4.2000222,300.0,0.92349213,-1.9258467,2.1874621,343.99133,-9.3348989
145.4909,0.033646077,9.0102558,0.0,0,4.6203012,300.0,0.91912431,-0.056540113,2.8875263,343.93787,-9.3351927
145.4931,0.054235399,9.0402584,0.0,0,5.0405807,300.0,0.92170584,0.43965128,3.4584336,343.88437,-9.3340263
145.4953,-0.14933804,9.1160231,0.0,0,5.4608598,300.0,0.93657804,-0.7207703,3.8873355,342.71094,-9.3316317
145.4975,-0.086918473,9.231555,0.0,0,5.8811393,300.0,0.95427799,-0.41705626,4.2672238,340.89755,-9.3318243
145.4997,0.068172857,9.3786907,0.0,0,6.3014183,300.0,0.98218507,0.36246175,4.6541829,339.08417,-9.3310518
145.5019,-0.071499333,9.4407368,0.0,0,6.7216969,300.0,0.99089336,-0.038457047,5.0330086,337.27078,-9.3303633
145.5041,0.035141844,9.4414492,0.0,0,7.1419768,300.0,0.99369127,0.118664,5.418582,335.60342,-9.3296671
145.5063,-0.098816216,9.429121,0.0,0,7.5622559,300.0,0.989636,-0.46089512,5.8320479,335.39618,-9.3296099
145.5085,-0.11249925,9.4221487,0.0,0,7.9825354,300.0,0.99062979,-0.54679233,6.2654777,335.18896,-9.3287134
145.5107,-0.038947679,9.4342213,0.0,0,8.4028139,300.0,0.99002457,-0.19551891,6.7173405,334.98172,-9.329175
145.5129,0.046895854,9.426075,0.0,0,8.8230925,300.0,0.99107909,0.15771386,7.1724877,334.77451,-9.3287516
145.5151,-0.050941344,9.427949,0.0,0,9.243372,300.0,0.98916239,-0.14125784,7.6085572,335.21729,-9.3278179
145.5173,-0.097453006,9.4244194,0.0,0,9.6636515,300.0,0.99098432,-0.53210062,8.0423775,336.20175,-9.3273373
145.5195,0.033729397,9.4319382,0.0,0,10.083931,300.0,0.989784,0.13906761,8.4740295,337.18619,-9.3267746
145.5217,0.029856764,9.4229212,0.0,0,10.50421,300.0,0.99043173,0.20708625,8.9134703,338.17065,-9.3259134
145.5239,-0.099110588,9.4326916,0.0,0,10.924489,300.0,0.99024677,-0.36229044,9.343339,339.15512,-9.326273
145.5261,-0.099155858,9.421236,0.0,0,11.344769,300.0,0.99018764,-0.48768321,9.7698011,338.39896,-9.3263979
145.5283,-0.065392919,9.4338198,0.0,0,11.765047,300.0,0.99019355,-0.37219691,10.201622,337.64279,-9.3258476
145.5305,0.001223356,9.4245787,0.0,0,12.185327,300.0,0.99054891,-0.074219503,10.640715,336.8866,-9.3257151
145.5327,0.023597525,9.4274693,0.0,0,12.605606,300.0,0.98944068,0.14605702,11.068583,336.13043,-9.3255424
145.5349,-0.14280425,9.4230413,0.0,0,13.025885,300.0,0.99042445,-0.60757434,11.49183,335.24307,-9.3271036
145.5371,-0.09181986,9.4306755,0.0,0,13.446164,300.0,0.98993897,-0.49166974,11.909615,334.19827,-9.3262138
145.5393,0.10987549,9.4184542,0.0,0,13.866444,300.0,0.98939568,0.47623822,12.336699,333.15347,-9.324892
145.5415,-0.02389029,9.4288111,0.0,0,14.286723,300.0,0.98979473,-0.030674445,12.766226,332.10867,-9.3232546
145.5437,-0.096487053,9.4223986,0.0,0,14.707002,300.0,0.98981577,-0.49140799,13.193282,331.06384,-9.3234253
145.5459,-0.06810315,9.4287405,0.0,0,15.127281,300.0,0.98976612,-0.32247713,13.633265,330.12164,-9.3243656
145.5481,-0.028913196,9.4198475,0.0,0,15.547561,300.0,0.98924094,-0.22793053,14.075785,329.18967,-9.3243132
145.5503,0.04176211,9.4256248,0.0,0,15.967839,300.0,0.98953503,0.19719023,14.508814,328.25769,-9.3240137
145.5525,-0.044640113,9.4211588,0.0,0,16.388119,300.0,0.98929662,-0.209819,14.937783,327.32574,-9.3220501
145.5547,-0.078243449,9.4295225,0.0,0,16.808399,300.0,0.99017322,-0.38979635,15.352341,326.61563,-9.3226547
145.5569,-0.0087522157,9.4184666,0.0,0,17.228678,300.0,0.9886651,-0.075475864,15.776078,326.29382,-9.3223886
145.5591,0.005112119,9.4220238,0.0,0,17.648958,300.0,0.98929775,-0.030748781,16.194456,325.97198,-9.3230019
145.5613,0.0057521192,9.4178209,0.0,0,17.999975,300.0,0.98846602,0.12810957,16.608076,325.65018,-9.323781
145.5635,-0.18332008,9.4274025,0.0,0,18.0,300.0,0.99035031,-0.78816003,17.023075,325.32834,-9.3225384
145.5657,-0.071912482,9.4250393,0.0,0,18.0,300.0,0.98950076,-0.40446559,17.422682,324.91876,-9.3222857
145.5679,0.038138792,9.4243803,0.0,0,18.0,300.0,0.98988724,0.16912523,17.772333,324.48965,-9.323308
145.5701,-0.11603098,9.4205694,0.0,0,18.0,300.0,0.98878711,-0.49056572,18.086878,324.06055,-9.3240004
145.5723,-0.079138003,9.4279308,0.0,0,18.0,300.0,0.9908371,-0.41949239,18.316013,323.63144,-9.3272333
145.5745,0.01525355,9.4319868,0.0,0,18.0,300.0,0.99039871,0.093481228,18.454622,323.51318,-9.3290854
145.5767,-0.040511895,9.4335651,0.0,0,18.0,300.0,0.99171257,-0.10617962,18.489876,324.22388,-9.3336039
145.5789,-0.064607836,9.4404917,0.0,0,18.0,300.0,0.99183929,-0.254307,18.425932,324.9346,-9.3421221
145.5811,-0.065905571,9.4526405,0.0,0,18.0,300.0,0.99562007,-0.32477289,18.314274,325.64529,-9.3521175
145.5833,-0.065584153,9.4707594,0.0,0,18.0,300.0,0.99707067,-0.30675861,18.20179,326.35599,-9.3638382
145.5855,-0.087218888,9.4788313,0.0,0,18.0,300.0,1.0002061,-0.46242532,18.108479,326.81799,-9.3785954
145.5877,-0.067011639,9.4931335,0.0,0,18.0,300.0,1.0011898,-0.35418192,18.056612,327.18677,-9.3940744
145.5899,0.026587041,9.5087099,0.0,0,18.0,300.0,1.0061644,0.040579446,18.038336,327.55554,-9.4117489
145.5921,0.085493386,9.5291882,0.0,0,18.0,300.0,1.0075949,0.34498391,18.042114,327.92429,-9.4302454
145.5943,0.052654319,9.541626,0.0,0,18.0,300.0,1.0119609,0.24714717,18.05802,327.95779,-9.4467916
145.5965,0.0053563267,9.5627022,0.0,0,18.0,300.0,1.0135819,0.083103977,18.080532,326.48264,-9.4628448
145.5987,-0.080540814,9.5776701,0.0,0,18.0,300.0,1.0185485,-0.307542,18.105856,325.00748,-9.4798555
145.6009,-0.14869787,9.6008472,0.0,0,18.0,300.0,1.0204475,-0.68283945,18.126019,323.53232,-9.4971066
145.6031,-0.15539077,9.6089163,0.0,0,18.0,300.0,1.0245723,-0.70185262,18.141708,322.05716,-9.5143223
145.6053,-0.067974567,9.6262779,0.0,0,18.0,300.0,1.0255216,-0.36841926,18.145864,320.93094,-9.5301895
145.6075,0.01038536,9.6383162,0.0,0,18.0,300.0,1.0301681,0.0071824607,18.148933,320.00412,-9.5449839
145.6097,0.045069568,9.6602783,0.0,0,18.0,300.0,1.0312612,0.17129113,18.142086,319.07727,-9.5597515
145.6119,0.071305752,9.6664133,0.0,0,18.0,300.0,1.035181,0.35212433,18.140835,318.15045,-9.5759478
145.6141,0.022084242,9.6842051,0.0,0,18.0,300.0,1.0363168,0.19158167,18.14286,317.2785,-9.5917234
145.6163,-0.064197764,9.6965551,0.0,0,18.0,300.0,1.0410386,-0.19699986,18.139225,316.95557,-9.6066265
145.6185,-0.13610888,9.7254848,0.0,0,18.0,300.0,1.0436368,-0.58965212,18.131952,316.63263,-9.6226292
145.6207,-0.14280525,9.7321901,0.0,0,18.0,300.0,1.047683,-0.6477862,18.131187,316.30972,-9.6395674
145.6229,-0.099215366,9.7564678,0.0,0,18.0,300.0,1.0500637,-0.49815628,18.132114,315.98679,-9.6540775
145.6251,-0.023240453,9.7631721,0.0,0,18.0,300.0,1.0536662,-0.16657063,18.126905,315.70789,-9.6705465
145.6273,0.040647428,9.7877474,0.0,0,18.0,300.0,1.0555466,0.13328394,18.125658,315.46567,-9.6878233
145.6295,0.059822544,9.7931604,0.0,0,18.0,300.0,1.059164,0.27313417,18.124519,315.22348,-9.7020788
145.6317,0.050110932,9.8166742,0.0,0,18.0,300.0,1.0616065,0.26690516,18.12225,314.98126,-9.7178946
145.6339,-0.019488366,9.8246527,0.0,0,18.0,300.0,1.0650127,-0.030973097,18.117697,314.73907,-9.7336483
145.6361,-0.1072714,9.8529997,0.0,0,18.0,300.0,1.0684471,-0.39669603,18.117146,314.04611,-9.7496023
145.6383,-0.15698193,9.8587322,0.0,0,18.0,300.0,1.0714405,-0.68726963,18.114729,313.35318,-9.7659588
145.6405,-0.13297778,9.8817968,0.0,0,18.0,300.0,1.0744419,-0.60540819,18.115721,312.66022,-9.782485
145.6427,-0.045079924,9.8904715,0.0,0,18.0,300.0,1.0776703,-0.26911098,18.111757,311.96725,-9.7979822
145.6449,0.036492176,9.913413,0.0,0,18.0,300.0,1.0804813,0.068681888,18.109503,311.45474,-9.8135777
145.6471,0.058745399,9.9163408,0.0,0,18.0,300.0,1.0828351,0.24613647,18.111141,311.15872,-9.8292227
145.6493,0.050972637,9.9392195,0.0,0,18.0,300.0,1.0860854,0.25717378,18.108904,310.8627,-9.84519
145.6515,0.020816175,9.9504299,0.0,0,18.0,300.0,1.0889584,0.099419415,18.109331,310.56671,-9.8610764
145.6537,-0.070275739,9.9769278,0.0,0,18.0,300.0,1.0934258,-0.24592018,18.10734,310.27069,-9.8771048
145.6559,-0.15936121,9.9835768,0.0,0,18.0,300.0,1.0954236,-0.61092991,18.110046,308.87067,-9.8937664
145.6581,-0.16004808,10.003386,0.0,0,18.0,300.0,1.0991712,-0.69751483,18.108913,307.36026,-9.9090137
145.6603,-0.085924692,10.014421,0.0,0,18.0,300.0,1.1014938,-0.42588112,18.107765,305.84982,-9.9239635
145.6625,0.0076655666,10.037853,0.0,0,18.0,300.0,1.1059995,-0.04146577,18.1066,304.33942,-9.9407654
145.6647,0.048891738,10.04382,0.0,0,18.0,300.0,1.1071832,0.17805122,18.106464,302.70871,-9.9547215
145.6669,0.070105895,10.060099,0.0,0,18.0,300.0,1.1108294,0.28586689,18.105246,300.86746,-9.9704895
145.6691,0.026298812,10.074969,0.0,0,18.0,300.0,1.1133453,0.17066295,18.103666,299.02625,-9.986742
145.6713,-0.039260469,10.101095,0.0,0,18.0,300.0,1.1192949,-0.137265,18.105116,297.18503,-10.002984
145.6735,-0.12283761,10.113968,0.0,0,18.0,300.0,1.1209118,-0.46258226,18.101894,295.34381,-10.020082
145.6757,-0.16540906,10.129417,6.6761789,0,18.0,300.0,1.1254202,-0.71957856,18.099003,294.38449,-10.034733
145.6779,-0.11355164,10.141877,14.835944,0,18.0,300.0,1.126771,-0.54534942,18.097082,293.62115,-10.052518
145.6801,-0.011671626,10.158538,22.99571,0,18.0,300.0,1.1318002,-0.12942024,18.098074,292.85785,-10.067629
145.6823,0.050356101,10.176321,31.155474,0,18.0,300.0,1.1334416,0.15418288,18.097109,292.09451,-10.083692
145.6845,0.06179852,10.189349,37.089844,0,18.0,300.0,1.1380074,0.24497069,18.093294,291.43253,-10.097667
145.6867,0.05322732,10.205624,37.089844,0,18.0,300.0,1.1395968,0.23806256,18.09186,291.04071,-10.113121
145.6889,-0.00022773117,10.222821,37.089844,0,18.0,300.0,1.1451346,0.029623032,18.090893,290.6489,-10.129051
145.6911,-0.098497771,10.241383,37.089844,0,18.0,300.0,1.1466154,-0.31207949,18.090944,290.25711,-10.144974
145.6933,-0.15864313,10.250648,37.089844,0,18.0,300.0,1.1509646,-0.63200068,18.091078,289.8653,-10.161741
145.6955,-0.15301795,10.27054,38.032032,0,18.0,300.0,1.1532407,-0.6301316,18.090479,289.54663,-10.178098
145.6977,-0.057890166,10.284191,39.327541,0,18.0,300.0,1.1584224,-0.28212219,18.089157,289.25534,-10.193966
145.6999,0.043064699,10.303583,40.623051,0,18.0,300.0,1.1597347,0.10522221,18.091969,288.96408,-10.209298
145.7021,0.083404548,10.308332,41.918556,0,18.0,300.0,1.1636559,0.29045704,18.08708,288.67282,-10.224313
145.7043,0.060555585,10.332067,42.978516,0,18.0,300.0,1.1660155,0.25136817,18.081953,288.35324,-10.241503
145.7065,0.020781869,10.343991,42.978516,0,18.0,300.0,1.1713469,0.12330248,18.086029,287.90625,-10.255131
145.7087,-0.066094406,10.367266,42.978516,0,18.0,300.0,1.1730473,-0.15886901,18.084049,287.45929,-10.2716
145.7109,-0.14203589,10.375299,42.978516,0,18.0,300.0,1.17802,-0.52831131,18.085073,287.0123,-10.287621
145.7131,-0.15715839,10.396972,42.978516,0,18.0,300.0,1.1800696,-0.6297791,18.081327,286.56531,-10.304008
145.7153,-0.11030042,10.405477,43.67527,0,18.0,300.0,1.1848722,-0.46036309,18.085203,286.1954,-10.321823
145.7175,-0.0021573659,10.433043,44.770164,0,18.0,300.0,1.1873792,-0.067354381,18.082756,285.86957,-10.337861
145.7197,0.076756306,10.436421,45.865063,0,18.0,300.0,1.1914784,0.24749207,18.082584,285.54373,-10.353076
145.7219,0.06995289,10.455199,46.959961,0,18.0,300.0,1.1927888,0.24579379,18.075315,285.2179,-10.369185
145.7241,0.03708886,10.466695,47.955322,0,18.0,300.0,1.1981704,0.1660306,18.078239,284.89636,-10.384914
145.7263,-0.027551815,10.49593,47.955322,0,18.0,300.0,1.2013289,-0.069880381,18.076267,284.61804,-10.401338
145.7285,-0.10453469,10.501341,47.955322,0,18.0,300.0,1.2054806,-0.38588122,18.076353,284.33972,-10.417891
145.7307,-0.16059299,10.523595,47.955322,0,18.0,300.0,1.2079884,-0.58558416,18.078735,284.0614,-10.433787
145.7329,-0.13611595,10.533058,47.955322,0,18.0,300.0,1.2127987,-0.5263195,18.07918,283.78305,-10.447527
145.7351,-0.04722517,10.560421,48.157032,0,18.0,300.0,1.2160015,-0.19405408,18.076927,283.62692,-10.46389
145.7373,0.052087046,10.563776,48.526833,0,18.0,300.0,1.219193,0.13293223,18.073872,283.5726,-10.480315
145.7395,0.082653284,10.58358,48.896633,0,18.0,300.0,1.2218496,0.3084988,18.077566,283.51831,-10.495977
145.7417,0.051151764,10.591218,49.26643,0,18.0,300.0,1.225376,0.21196289,18.076374,283.46399,-10.509963
145.7439,0.00025406573,10.6226,49.63623,0,18.0,300.0,1.2303712,0.039760817,18.074366,283.40967,-10.524139
145.7461,-0.085004233,10.626594,49.63623,0,18.0,300.0,1.2331514,-0.27305949,18.072332,283.28748,-10.541487
145.7483,-0.14778571,10.649854,49.63623,0,18.0,300.0,1.2370836,-0.53293437,18.074453,283.16528,-10.558257
145.7505,-0.1541293,10.659488,49.63623,0,18.0,300.0,1.2404929,-0.58827519,18.075403,283.04309,-10.574972
145.7527,-0.085203759,10.684353,49.63623,0,18.0,300.0,1.2449105,-0.39014789,18.075741,282.9209,-10.590611
145.7549,0.019596716,10.687528,49.82959,0,18.0,300.0,1.2469255,0.026827918,18.072325,282.76477,-10.605021
145.7571,0.080449261,10.706302,50.254982,0,18.0,300.0,1.2508521,0.2635529,18.071795,282.5679,-10.621448
145.7593,0.08115004,10.715822,50.680374,0,18.0,300.0,1.2532339,0.31381795,18.072035,282.37103,-10.638515
145.7615,0.01762547,10.743297,51.105762,0,18.0,300.0,1.2594543,0.093640231,18.070824,282.17416,-10.654093
145.7637,-0.056106314,10.756083,51.531151,0,18.0,300.0,1.2621254,-0.13646583,18.071251,281.97729,-10.669411
145.7659,-0.12827964,10.773447,51.569824,0,18.0,300.0,1.2668312,-0.39600432,18.072201,281.80511,-10.685371
145.7681,-0.1442516,10.783465,51.569824,0,18.0,300.0,1.2688,-0.49113077,18.071384,281.63541,-10.700335
145.7703,-0.10811007,10.804915,51.569824,0,18.0,300.0,1.2746868,-0.39163101,18.070402,281.4657,-10.716925
145.7725,-0.016110463,10.814764,51.569824,0,18.0,300.0,1.2760917,-0.10407526,18.073059,281.29599,-10.733294
145.7747,0.064248294,10.828928,51.655079,0,18.0,300.0,1.2804565,0.19764253,18.070875,281.14603,-10.748023
145.7769,0.083627596,10.84424,51.889526,0,18.0,300.0,1.2827339,0.3219524,18.066664,281.03061,-10.763878
145.7791,0.055010285,10.866596,52.123974,0,18.0,300.0,1.2898128,0.21575063,18.064775,280.91522,-10.779248
145.7813,-0.024812937,10.883546,52.358425,0,18.0,300.0,1.2917222,-0.028533604,18.067873,280.7998,-10.796757
145.7835,-0.10473813,10.895582,52.592869,0,18.0,300.0,1.2967548,-0.33419216,18.06699,280.68442,-10.812573
145.7857,-0.1427255,10.910441,52.635498,0,18.0,300.0,1.2984102,-0.47050753,18.064791,280.54678,-10.826366
145.7879,-0.12890132,10.929632,52.635498,0,18.0,300.0,1.30557,-0.48254326,18.06698,280.40424,-10.842458
145.7901,-0.056232147,10.946997,52.635498,0,18.0,300.0,1.3070766,-0.23409472,18.063757,280.26169,-10.859006
145.7923,0.034305505,10.955815,52.635498,0,18.0,300.0,1.3121221,0.064678758,18.065941,280.11911,-10.875239
145.7945,0.088432729,10.972206,52.715916,0,18.0,300.0,1.3133683,0.29568243,18.06258,279.97287,-10.889487
145.7967,0.068417065,10.9859,53.010792,0,18.0,300.0,1.3196158,0.2835404,18.062111,279.81671,-10.906788
145.7989,0.0096421959,11.009161,53.305664,0,18.0,300.0,1.3224145,0.060312208,18.059589,279.66058,-10.921656
145.8011,-0.073520869,11.01896,53.60054,0,18.0,300.0,1.3278587,-0.22263491,18.060482,279.50446,-10.938113
145.8033,-0.13606499,11.039772,53.895412,0,18.0,300.0,1.3301036,-0.43611881,18.060131,279.3483,-10.95441
145.8055,-0.14501579,11.052068,53.97583,0,18.0,300.0,1.3367211,-0.4835366,18.060516,279.16748,-10.970586
145.8077,-0.10004807,11.073427,53.97583,0,18.0,300.0,1.3382498,-0.35872144,18.064379,278.97742,-10.986235
145.8099,0.0072770235,11.076689,53.97583,0,18.0,300.0,1.3428801,-0.019533217,18.058922,278.78732,-11.002299
145.8121,0.080805704,11.098365,53.97583,0,18.0,300.0,1.3449878,0.25498569,18.05513,278.59726,-11.017533
145.8143,0.099932879,11.109632,54.050537,0,18.0,300.0,1.351406,0.29437664,18.056978,278.39731,-11.031381
145.8165,0.031188592,11.134562,54.461426,0,18.0,300.0,1.3534991,0.15516022,18.055387,278.15292,-11.048045
145.8187,-0.04986804,11.140668,54.872314,0,18.0,300.0,1.3593349,-0.11630281,18.05756,277.90854,-11.06531
145.8209,-0.12294119,11.164787,55.283203,0,18.0,300.0,1.3622174,-0.36664429,18.056461,277.66415,-11.082015
145.8231,-0.14657855,11.171971,55.694096,0,18.0,300.0,1.3677,-0.48229864,18.057587,277.41977,-11.097594
145.8253,-0.10470746,11.199046,55.84351,0,18.0,300.0,1.3707443,-0.36794108,18.057173,277.20563,-11.112691
145.8275,-0.018914104,11.201992,55.84351,0,18.0,300.0,1.375188,-0.1297828,18.055399,277.00876,-11.126749
145.8297,0.047923293,11.224211,55.84351,0,18.0,300.0,1.3779975,0.11096298,18.056316,276.81189,-11.144541
145.8319,0.083779246,11.232306,55.84351,0,18.0,300.0,1.3834409,0.27318364,18.055334,276.61502,-11.159484
145.8341,0.06359347,11.261062,55.871853,0,18.0,300.0,1.3874465,0.21730423,18.056011,276.42188,-11.175891
145.8363,-0.010489431,11.267894,56.183643,0,18.0,300.0,1.3924127,0.02086444,18.054607,276.26575,-11.192857
145.8385,-0.10196673,11.29197,56.495434,0,18.0,300.0,1.3962322,-0.27866989,18.047796,276.10962,-11.20905
145.8407,-0.15255883,11.299727,56.807228,0,18.0,300.0,1.4009646,-0.47073272,18.053528,275.95349,-11.224535
145.8429,-0.13990967,11.327051,57.119019,0,18.0,300.0,1.4053681,-0.44625548,18.053032,275.79733,-11.240855
145.8451,-0.046883862,11.329268,57.260742,0,18.0,300.0,1.4086298,-0.18935202,18.05221,275.65604,-11.256052
145.8473,0.03877417,11.352063,57.260742,0,18.0,300.0,1.4128433,0.048084456,18.04871,275.52704,-11.271419
145.8495,0.069536448,11.360989,57.260742,0,18.0,300.0,1.4170789,0.22407685,18.051117,275.39804,-11.28806
145.8517,0.076357029,11.385479,57.260742,0,18.0,300.0,1.4219627,0.24977504,18.051447,275.26907,-11.302297
145.8539,0.026513765,11.389717,57.260731,0,18.0,300.0,1.4249228,0.1280854,18.050938,275.14008,-11.31787
145.8561,-0.070282258,11.41317,44.663368,0,18.0,300.0,1.430284,-0.16417548,18.049,274.95679,-11.332766
145.8583,-0.14079551,11.422309,32.066006,0,18.0,300.0,1.4335247,-0.39506406,18.046923,274.7735,-11.349466
145.8605,-0.13961168,11.447006,19.468641,0,18.0,300.0,1.440043,-0.42206791,18.048405,274.59021,-11.366849
146.7608,-0.039241184,11.556846,0.0,0,18.0,1.621674e-10,1.4718034,-0.1128747,18.001791,163.67693,-11.483751
147.8608,-0.039231047,11.556373,0.0,0,18.0,1.6196895e-25,1.4714432,-0.11351483,18.001036,87.86657,-11.4826
148.9608,-0.036463875,11.556336,0.0,0,18.0,1.617715e-40,1.4715635,-0.10722474,17.99951,51.279617,-11.483345
150.0608,-0.039565764,11.557434,0.0,0,18.0,1.4012985e-45,1.471845,-0.11833509,17.999153,36.587078,-11.483337
151.1608,-0.041833367,11.557406,0.0,0,18.0,1.4012985e-45,1.4719095,-0.12013302,18.000107,30.232624,-11.483679
152.2608,-0.03975768,11.557072,0.0,0,18.0,1.4012985e-45,1.4716463,-0.11541215,17.999828,27.471422,-11.482736
153.3608,-0.036964159,11.558024,0.0,0,18.0,1.4012985e-45,1.4720948,-0.10952848,17.99962,26.307974,-11.482931
154.4608,-0.042886607,11.557776,0.0,0,18.0,1.4012985e-45,1.4719955,-0.12818792,17.999763,25.80513,-11.483037
155.5608,-0.04379648,11.557598,0.0,0,18.0,1.4012985e-45,1.471844,-0.1285436,18.000107,25.619204,-11.483194
156.6608,-0.035457008,11.557651,0.0,0,18.0,1.4012985e-45,1.4718733,-0.10247087,17.999853,25.455999,-11.483552
157.7608,-0.038825743,11.558426,0.0,0,18.0,1.4012985e-45,1.4721067,-0.11522917,17.999468,25.380514,-11.483789
158.8608,-0.046383411,11.559015,0.0,0,18.0,1.4012985e-45,1.4724298,-0.13577785,18.000246,25.417711,-11.483749
159.9608,-0.046624146,11.558907,0.0,0,18.0,1.4012985e-45,1.4721625,-0.13618456,17.999788,25.42379,-11.483359
161.0608,-0.041082285,11.558069,0.0,0,18.0,1.4012985e-45,1.4721555,-0.11906809,18.001156,25.355337,-11.483249
162.1608,-0.042481247,11.560183,0.0,0,18.0,1.4012985e-45,1.4726161,-0.12639365,17.998905,25.360527,-11.483571
163.2608,-0.047401585,11.559548,0.0,0,18.0,1.4012985e-45,1.4724493,-0.13623689,17.999424,25.169382,-11.483533
164.3608,-0.047266793,11.560095,0.0,0,18.0,1.4012985e-45,1.4724853,-0.13404518,17.999636,25.18133,-11.482962
165.4608,-0.041791879,11.560292,0.0,0,18.0,1.4012985e-45,1.4727126,-0.12377873,17.998741,25.102228,-11.482999
166.5608,-0.043180097,11.560126,0.0,0,18.0,1.4012985e-45,1.4727288,-0.12944941,18.000116,25.12623,-11.483401
167.6608,-0.047875103,11.560762,0.0,0,18.0,1.4012985e-45,1.4727588,-0.13616265,18.00028,25.12989,-11.483499
168.7608,-0.044891305,11.561387,0.0,0,18.0,1.4012985e-45,1.4729447,-0.12924287,17.999697,25.112133,-11.483418
169.8608,-0.042668443,11.561584,0.0,0,18.0,1.4012985e-45,1.4729745,-0.12429449,17.999561,25.108503,-11.483567
170.9608,-0.044172619,11.562168,0.0,0,18.0,1.4012985e-45,1.473338,-0.12668952,17.999338,25.072489,-11.483831
172.0608,-0.049518991,11.561816,0.0,0,18.0,1.4012985e-45,1.4730144,-0.144582,18.000795,25.056795,-11.483714
173.1608,-0.046668485,11.562719,0.0,0,18.0,1.4012985e-45,1.4734168,-0.13448361,18.000387,25.082615,-11.483564
174.2608,-0.04378698,11.562332,0.0,0,18.0,1.4012985e-45,1.4731933,-0.12951988,18.000937,25.010197,-11.483851
175.3608,-0.048715789,11.562168,0.0,0,18.0,1.4012985e-45,1.4733304,-0.14094399,17.999815,25.001184,-11.483457
176.4608,-0.054516647,11.562878,0.0,0,18.0,1.4012985e-45,1.4732769,-0.15992756,17.999779,24.954067,-11.483287
177.5608,-0.050515831,11.562904,0.0,0,18.0,1.4012985e-45,1.4735241,-0.14678779,18.000448,24.917444,-11.482882
178.6608,-0.045082279,11.563378,0.0,0,18.0,1.4012985e-45,1.4735212,-0.13342677,17.999733,24.945173,-11.483103
179.7608,-0.050795633,11.563272,0.0,0,18.0,1.4012985e-45,1.4736081,-0.1484651,18.000143,24.883657,-11.482761
180.8608,-0.050574563,11.563581,0.0,0,18.0,1.4012985e-45,1.4734821,-0.1460432,17.999874,24.88431,-11.483148
181.9608,-0.050106451,11.56295,0.0,0,18.0,1.4012985e-45,1.4735043,-0.14523239,18.000174,24.89481,-11.482687
183.0608,-0.045412023,11.56378,0.0,0,18.0,1.4012985e-45,1.473659,-0.13145739,18.000362,24.855049,-11.482611
184.1608,-0.051459216,11.564013,0.0,0,18.0,1.4012985e-45,1.4737746,-0.14839472,18.000374,24.83704,-11.482866
185.2608,-0.055465955,11.564801,0.0,0,18.0,1.4012985e-45,1.4738394,-0.15815207,17.999411,24.808882,-11.482756
186.3608,-0.047489449,11.564725,0.0,0,18.0,1.4012985e-45,1.474021,-0.13581057,18.000616,24.797056,-11.482685
187.4608,-0.052631918,11.565148,0.0,0,18.0,1.4012985e-45,1.474128,-0.15001556,18.000458,24.839287,-11.483032
188.5608,-0.051520877,11.565476,0.0,0,18.0,1.4012985e-45,1.4741489,-0.15190305,17.998911,24.833784,-11.483064
189.6608,-0.056203306,11.565313,0.0,0,18.0,1.4012985e-45,1.4740463,-0.16122198,18.000183,24.771055,-11.482937
190.7608,-0.044624332,11.565479,0.0,0,18.0,1.4012985e-45,1.4742471,-0.12821853,17.999521,24.798521,-11.483427
191.8608,-0.047645442,11.566096,0.0,0,18.0,1.4012985e-45,1.4744403,-0.13831133,18.000204,24.745356,-11.483178
192.9608,-0.051064849,11.566585,0.0,0,18.0,1.4012985e-45,1.4744781,-0.14790834,17.999245,24.675508,-11.483439
194.0608,-0.056579363,11.566646,0.0,0,18.0,1.4012985e-45,1.4744617,-0.16213088,18.000027,24.69524,-11.483163
195.1608,-0.046130642,11.566977,0.0,0,18.0,1.4012985e-45,1.474624,-0.13439837,18.000065,24.692335,-11.483413
196.2608,-0.050272606,11.567094,0.0,0,18.0,1.4012985e-45,1.4747324,-0.14599866,17.999367,24.627407,-11.483512
197.3608,-0.054319285,11.567439,0.0,0,18.0,1.4012985e-45,1.474673,-0.15997387,18.000031,24.701738,-11.483379
198.4608,-0.055016112,11.568096,0.0,0,18.0,1.4012985e-45,1.4748679,-0.15774612,18.00004,24.675295,-11.48333
199.5608,-0.050991934,11.5678,0.0,0,18.0,1.4012985e-45,1.4748615,-0.14806999,18.000198,24.675959,-11.483036
200.6608,-0.053320393,11.567931,0.0,0,18.0,1.4012985e-45,1.4750197,-0.15811804,17.998852,24.707924,-11.482974
201.7608,-0.06015864,11.568513,0.0,0,18.0,1.4012985e-45,1.474969,-0.17482947,18.000212,24.677551,-11.482963
202.8608,-0.056372985,11.568342,0.0,0,18.0,1.4012985e-45,1.4749624,-0.16069211,17.999266,24.628029,-11.482841
203.9608,-0.055416625,11.568797,0.0,0,18.0,1.4012985e-45,1.475144,-0.15874639,18.000704,24.636459,-11.48283
205.0608,-0.053665351,11.568285,0.0,0,18.0,1.4012985e-45,1.475082,-0.15712839,18.000425,24.530815,-11.482961
205.8608,-0.05583955,11.568987,0.0,0,18.0,1.4012985e-45,1.4750659,-0.16430517,18.000582,24.611538,-11.482695