File: examples/dan-msc-case-studies/CS3/data/01 raw data/baron_test_018.csv
Time(sec),Force(kN),Jaw(mm),PowAngle(deg),Power(W),Pram,PTemp,Strain,Stress(MPa),Stroke(mm),TC1(C),wedge(mm)
0.0,0.68436545,0.2800225,0.0,0,11.076097,0.0016152931,0.018829446,8.5686674,11.076212,23.880646,-9.1262569
1.2,0.62081701,0.0046093673,0.0,0,11.076097,3.5158744,0.00030148757,7.9120464,11.076489,23.890984,-9.4951439
2.4,0.59432977,0.0041961726,0.0,0,11.076097,7.1158743,0.00029501415,7.5769238,11.076172,23.829708,-9.4919243
3.6,0.57653368,0.0042869085,0.0,0,11.076097,10.715876,0.00029280479,7.333796,11.07547,23.758625,-9.4908342
4.8,0.56652439,0.0042419476,0.0,0,11.076097,14.315876,0.00027993906,7.2086649,11.076094,23.794413,-9.488965
6.0,0.5446108,0.0042773387,0.0,0,11.076097,17.915878,0.00029371289,6.9327412,11.07603,23.803736,-9.4863472
7.2,0.52962554,0.0040528132,0.0,0,11.076097,21.515877,0.00025081827,6.7395625,11.076459,23.727236,-9.4837236
8.4,0.52172995,0.0040220036,5.5414753,0,11.076097,25.115875,0.00024929008,6.6427755,11.076329,23.746132,-9.4816837
9.6,0.519557,0.0041698115,27.211611,0,11.076097,28.715878,0.00028172194,6.611196,11.075474,23.740997,-9.4793501
10.8,0.51511091,0.0039711203,39.160187,0,11.076097,32.31588,0.0002824995,6.55617,11.076127,23.911247,-9.4777327
12.0,0.52228332,0.0028436286,47.409927,0,11.076097,35.915867,0.00019129604,6.6362066,11.075646,24.758081,-9.4758482
13.2,0.54315495,0.00037722112,53.18523,0,11.076097,39.515873,3.676338e-05,6.9054728,11.075979,26.616516,-9.4737701
14.4,0.55276221,-0.0026508181,57.346588,0,11.076097,43.115868,-0.00018107616,7.0414915,11.076335,29.577583,-9.4713078
15.6,0.56585091,-0.0070955758,60.394924,0,11.076097,46.715874,-0.00049034372,7.216702,11.075472,33.457539,-9.4688225
16.8,0.58199632,-0.012620093,62.53355,0,11.076097,50.315876,-0.00085531641,7.4163337,11.076285,38.321854,-9.4671211
18.0,0.60112923,-0.018536447,63.739017,0,11.076097,53.915874,-0.0012283329,7.6671004,11.075766,44.167747,-9.4644251
19.2,0.6162492,-0.024302742,63.973385,0,11.076097,57.515877,-0.0016011379,7.8491192,11.076492,50.802071,-9.4627523
20.4,0.63710821,-0.029879028,63.775642,0,11.076097,61.115875,-0.0019826146,8.1346531,11.076288,57.617233,-9.4607077
21.6,0.64926618,-0.035220023,62.599777,0,11.076097,64.715897,-0.0023414912,8.29426,11.075523,64.678192,-9.4587774
22.8,0.65573275,-0.040864471,60.80479,0,11.076097,68.315887,-0.0027157702,8.3687143,11.076593,71.593575,-9.4565401
24.0,0.65446162,-0.045596566,58.253586,0,11.076097,71.915878,-0.0030457536,8.3606453,11.076087,78.185806,-9.4543114
25.2,0.65578228,-0.049537957,54.940723,0,11.076097,75.515892,-0.0033127172,8.3744087,11.075373,84.124962,-9.4524307
26.4,0.64222234,-0.052677605,50.702023,0,11.076097,79.115883,-0.0034976688,8.2037411,11.076198,89.261284,-9.4497223
27.6,0.62994272,-0.054554958,45.955441,0,11.076097,82.715874,-0.0036125656,8.0579271,11.075646,93.42923,-9.4474115
28.8,0.61032146,-0.055806119,41.619694,0,11.076097,86.31588,-0.0037075337,7.7933846,11.075439,96.274078,-9.4455757
30.0,0.59059286,-0.055881273,38.55114,0,11.076097,89.915871,-0.0037098334,7.5416646,11.075496,98.013,-9.4428663
31.2,0.57829142,-0.055583652,37.836849,0,11.076097,93.515884,-0.0037126518,7.3901014,11.075697,98.810692,-9.4409237
32.4,0.5639804,-0.055840544,39.923866,0,11.076097,97.115868,-0.003736617,7.2251844,11.075929,99.024025,-9.4387684
33.6,0.55051219,-0.056003384,44.502106,0,11.076097,100.71588,-0.0037352194,7.0350041,11.076039,98.980927,-9.4365215
34.8,0.54702437,-0.056870844,49.185455,0,11.076097,104.31587,-0.0037683435,6.9906788,11.076464,99.045143,-9.434495
36.0,0.55404687,-0.058630306,53.734932,0,11.076097,107.91588,-0.0038884208,7.0743113,11.07598,99.710815,-9.4326611
37.2,0.58558244,-0.061221164,57.620167,0,11.076097,111.51588,-0.0040726676,7.4950876,11.076413,101.1471,-9.4304371
38.4,0.60095769,-0.064860061,60.762928,0,11.076097,115.11588,-0.004315068,7.6856194,11.076585,103.58504,-9.4285374
39.6,0.61794913,-0.069997914,63.149429,0,11.076097,118.71588,-0.0046760291,7.8958855,11.075774,107.11508,-9.4264479
40.8,0.63255107,-0.075691499,64.8004,0,11.076097,122.31588,-0.0050509018,8.0921154,11.076349,111.75124,-9.4243011
42.0,0.65614939,-0.081708938,65.840271,0,11.076097,125.91588,-0.0054316744,8.4006138,11.075699,117.15723,-9.4221773
43.2,0.66876698,-0.088038184,66.192619,0,11.076097,129.51602,-0.0058357576,8.5582819,11.075786,123.29515,-9.4201889
44.4,0.66748071,-0.094560303,65.854424,0,11.076097,133.11589,-0.0062846984,8.5592737,11.07648,129.91792,-9.4176836
45.6,0.67040592,-0.10045345,64.999451,0,11.076097,136.71588,-0.0066689891,8.5900221,11.076103,136.69594,-9.4154634
46.8,0.67107493,-0.10579949,63.589443,0,11.076097,140.31589,-0.0070332931,8.6001883,11.075105,143.18921,-9.413518
48.0,0.66742772,-0.11074093,61.695107,0,11.076097,143.91589,-0.0073673902,8.5612183,11.075232,149.52901,-9.4115057
49.2,0.65933353,-0.1144385,59.352371,0,11.076097,147.51588,-0.0076033012,8.4607277,11.075958,154.99883,-9.40942
50.4,0.66202199,-0.11729901,56.727676,0,11.076097,151.11589,-0.0077710007,8.5131693,11.075771,159.63615,-9.4070854
51.6,0.64546329,-0.11930785,54.044243,0,11.076097,154.7159,-0.0079092113,8.2724075,11.075396,163.49388,-9.4049568
52.8,0.62511891,-0.12096682,51.937763,0,11.076097,158.31589,-0.0080277855,8.0331106,11.075479,166.22961,-9.4031029
54.0,0.6114915,-0.12185977,50.822758,0,11.076097,161.91589,-0.0080791116,7.8454094,11.075476,168.20111,-9.4012041
55.2,0.59968221,-0.12252486,50.696266,0,11.076097,165.5159,-0.0081507722,7.6856365,11.076521,169.47461,-9.399354
56.4,0.58547431,-0.12361877,51.806,0,11.076097,169.11589,-0.0082174949,7.5113835,11.075806,170.30533,-9.3969002
57.6,0.58279222,-0.12469218,53.885567,0,11.076097,172.71591,-0.0082713561,7.4859867,11.076307,170.98268,-9.3952208
58.8,0.58724397,-0.12641662,56.416534,0,11.076097,176.3159,-0.0083727399,7.5349336,11.075725,171.86516,-9.392992
60.0,0.60831916,-0.12875539,59.079464,0,11.076097,179.91589,-0.0085487599,7.8130875,11.076693,173.23274,-9.3911886
61.2,0.62643367,-0.13197668,61.422581,0,11.076097,183.51591,-0.0087484578,8.0377512,11.075585,175.43764,-9.3882999
62.4,0.64185667,-0.13591704,63.353687,0,11.076097,187.11591,-0.0090281805,8.2479029,11.076905,178.39214,-9.3866835
63.6,0.65772367,-0.14031647,64.923584,0,11.076097,190.71588,-0.0093286214,8.4630537,11.07577,182.05766,-9.3847771
64.8,0.67445999,-0.14536981,66.007118,0,11.076097,194.3159,-0.0096555036,8.6710892,11.075953,186.55911,-9.3825998
66.0,0.67548764,-0.15125746,66.59671,0,11.076097,197.91589,-0.01002483,8.6809797,11.075682,191.69528,-9.3803568
67.2,0.67820626,-0.15710831,66.7127,0,11.076097,201.51588,-0.010416456,8.7215157,11.076167,197.3054,-9.3784389
68.4,0.67623615,-0.16257428,66.544197,0,11.076097,205.11589,-0.010782494,8.7157745,11.075727,203.15749,-9.3764019
69.6,0.67031735,-0.16755541,65.675034,0,11.076097,208.7159,-0.011104779,8.628231,11.076082,209.29523,-9.3740015
70.8,0.67322922,-0.17237233,64.430679,0,11.076097,212.31587,-0.011445465,8.6735601,11.076631,215.44954,-9.372139
72.0,0.6722796,-0.17646773,62.862289,0,11.076097,215.91589,-0.011721011,8.6644974,11.076198,221.09822,-9.3699989
73.2,0.67227352,-0.18003671,61.024792,0,11.076097,219.51587,-0.011920401,8.6675797,11.076613,226.13409,-9.3680506
74.4,0.66389674,-0.1827721,59.153645,0,11.076097,223.11588,-0.01210341,8.5585012,11.076661,230.26962,-9.3659811
75.6,0.65619081,-0.18497524,57.53714,0,11.076097,226.71588,-0.012254066,8.4636803,11.07668,233.64851,-9.3643961
76.8,0.63020831,-0.1866582,56.426453,0,11.076097,230.31587,-0.012363671,8.114851,11.075817,236.23181,-9.3623981
78.0,0.61636931,-0.18793385,56.129135,0,11.076097,233.91588,-0.012464182,7.9449306,11.075829,238.01064,-9.3604374
79.2,0.61502159,-0.18889378,56.425777,0,11.076097,237.51588,-0.012527082,7.9273243,11.075425,239.4725,-9.3580437
80.4,0.60723382,-0.19045116,57.534859,0,11.076097,241.11588,-0.012618525,7.8366814,11.07527,240.74323,-9.3560982
81.6,0.59993106,-0.19276045,59.105862,0,11.076097,244.7159,-0.012745493,7.7449174,11.076097,242.11337,-9.3536701
82.8,0.61372828,-0.19515467,60.937946,0,11.076097,248.31589,-0.012925053,7.9102731,11.075803,243.78885,-9.3516293
84.0,0.63276505,-0.1980657,62.534542,0,11.076097,251.91589,-0.013114496,8.1645422,11.076542,246.02817,-9.3495378
85.2,0.64770269,-0.20184971,63.972584,0,11.076097,255.5159,-0.013372452,8.3562107,11.07643,248.91112,-9.3471909
86.4,0.66546673,-0.20611647,65.278496,0,11.076097,259.11618,-0.013666003,8.5813513,11.076408,252.43304,-9.3454075
87.6,0.66804665,-0.21086805,66.115143,0,11.076097,262.71588,-0.013958691,8.6249084,11.076114,256.65704,-9.3438272
88.8,0.67385358,-0.21613593,66.694534,0,11.076097,266.31589,-0.0142853,8.7085047,11.075991,261.34311,-9.3418875
90.0,0.67126274,-0.22085002,66.884735,0,11.076097,269.91589,-0.014609738,8.6761227,11.075975,266.29971,-9.3400955
91.2,0.6770739,-0.22552122,66.884758,0,11.076097,273.5159,-0.014911353,8.7352219,11.075924,271.38199,-9.3373499
92.4,0.67130107,-0.23182495,66.544296,0,11.076097,277.11591,-0.015337365,8.682909,11.076271,276.50909,-9.3355284
93.6,0.68197781,-0.23566729,66.065849,0,11.076097,280.71591,-0.015614439,8.8080473,11.075705,281.34427,-9.3335943
94.8,0.67584401,-0.23874117,65.479126,0,11.076097,284.31592,-0.015797062,8.7437057,11.074833,286.06772,-9.3314476
96.0,0.67405522,-0.24244998,64.751762,0,11.076097,287.91592,-0.01601569,8.7227125,11.076075,290.53604,-9.3295603
97.2,0.66795862,-0.24602729,64.171196,0,11.076097,291.51593,-0.016257735,8.6370554,11.076185,294.54739,-9.3275108
98.4,0.66553968,-0.24925095,63.53759,0,11.076097,295.11591,-0.016473565,8.6306591,11.075928,298.26526,-9.3251667
99.6,0.65909225,-0.25216785,62.963894,0,11.076097,298.71594,-0.016668441,8.542985,11.076332,301.61713,-9.3231707
100.8,0.6562838,-0.25485933,62.753914,0,11.076097,302.31592,-0.016873328,8.4855289,11.075116,304.74088,-9.3210182
102.0,0.66868365,-0.25785032,62.582211,0,11.076097,305.91589,-0.017055271,8.6476679,11.076101,307.6069,-9.3193817
103.2,0.67035264,-0.2602312,62.753899,0,11.076097,309.5159,-0.017190974,8.6855841,11.075739,310.14755,-9.3170719
104.4,0.66877955,-0.26276881,63.171383,0,11.076097,313.11591,-0.017358216,8.6672583,11.075633,312.75339,-9.315341
105.6,0.65907848,-0.26602668,63.769756,0,11.076097,316.71588,-0.017572092,8.5324469,11.075778,315.45737,-9.312726
106.8,0.66051102,-0.26932889,64.346527,0,11.076097,320.31592,-0.017786866,8.5704889,11.075935,318.32169,-9.3112154
108.0,0.66967905,-0.27299479,64.926971,0,11.076097,323.91592,-0.018055724,8.6747017,11.075185,321.4202,-9.309288
109.2,0.67922163,-0.27742517,65.478439,0,11.076097,327.5159,-0.018341195,8.8098316,11.076045,324.73477,-9.3075571
110.4,0.67748642,-0.28037605,66.016037,0,11.076097,331.11588,-0.018518101,8.7911644,11.076197,328.28714,-9.3056097
111.6,0.67435539,-0.28447956,66.368393,0,11.076097,334.71585,-0.01876867,8.7584028,11.075932,331.95276,-9.3036165
112.8,0.65895253,-0.2890968,66.708977,0,11.076097,338.31586,-0.019084008,8.560957,11.075714,335.78815,-9.3015099
114.0,0.6672138,-0.29292047,67.049538,0,11.076097,341.91589,-0.019334106,8.6527319,11.074762,339.65979,-9.299283
115.2,0.67481345,-0.29846519,67.225342,0,11.076097,345.51587,-0.019713242,8.7627478,11.076173,343.57123,-9.2972937
116.4,0.67067474,-0.30098495,67.390076,0,11.076097,349.11588,-0.019878825,8.7128172,11.07608,347.72311,-9.2948475
117.6,0.67097449,-0.30576295,67.387787,0,11.076097,352.71588,-0.020185309,8.734458,11.077276,351.89084,-9.2931395
118.8,0.66579628,-0.31058976,67.225349,0,11.076097,356.31589,-0.020484673,8.6368847,11.076653,356.13882,-9.2908211
120.0,0.67669022,-0.31555346,66.88501,0,11.076097,359.91589,-0.020806406,8.7890072,11.075427,360.43842,-9.2883539
121.2,0.66634911,-0.31770316,66.544472,0,11.076097,363.51587,-0.020953415,8.6855087,11.075929,364.66504,-9.286253
122.4,0.66712433,-0.3218126,66.192657,0,11.076097,367.11588,-0.021238852,8.672617,11.075451,368.63281,-9.2845316
123.6,0.66979516,-0.32493028,65.842751,0,11.076097,370.71588,-0.021449968,8.695756,11.075963,372.41324,-9.282814
124.8,0.67119777,-0.32890996,65.570503,0,11.076097,374.31589,-0.021695983,8.7302113,11.076265,376.03665,-9.280549
126.0,0.66960144,-0.33159512,65.302742,0,11.076097,377.91589,-0.021844184,8.7080479,11.075618,379.54639,-9.2788305
127.2,0.66057211,-0.33546743,65.142838,0,11.076097,381.5159,-0.022116713,8.6009226,11.076281,382.81409,-9.2773056
128.4,0.66443843,-0.33919668,65.115974,0,11.076097,385.11591,-0.02234927,8.6454792,11.076155,386.08243,-9.2750998
129.6,0.66670781,-0.34083268,65.115974,0,11.076097,388.71588,-0.022478087,8.6874142,11.0769,389.24722,-9.2734194
130.8,0.65716118,-0.34432083,65.302353,0,11.076097,392.31592,-0.022706293,8.5565929,11.075868,392.35699,-9.2711334
132.0,0.67017841,-0.34798902,65.478508,0,11.076097,395.91589,-0.022931939,8.7369585,11.074553,395.43842,-9.2690001
133.2,0.67439097,-0.3500452,65.837234,0,11.076097,399.51593,-0.02305321,8.7780991,11.075625,398.58954,-9.2667875
134.4,0.66648322,-0.354081,66.191223,0,11.076097,403.11591,-0.023329731,8.6777849,11.076382,401.74005,-9.264699
135.6,0.66569239,-0.35776329,66.491348,0,11.076097,406.71594,-0.023565693,8.6823149,11.075892,405.11517,-9.2625742
136.8,0.67779189,-0.36095461,66.749695,0,11.076097,410.31592,-0.023788204,8.8376923,11.075898,408.57697,-9.2605114
138.0,0.6693182,-0.36581457,67.049202,0,11.076097,413.91592,-0.024113441,8.7329826,11.076053,412.25635,-9.2583294
139.2,0.66726458,-0.37013829,67.225342,0,11.076097,417.51593,-0.024380585,8.6988955,11.075823,416.06656,-9.2561207
140.4,0.68548089,-0.37540081,67.374191,0,11.076097,421.11594,-0.024708029,8.9538746,11.076421,419.90854,-9.2542887
141.6,0.66972357,-0.37858224,67.390129,0,11.076097,424.71594,-0.024934102,8.7360935,11.076368,423.86914,-9.2521839
142.8,0.66565704,-0.38378477,67.390129,0,11.076097,428.31595,-0.02525039,8.6762676,11.076336,427.78534,-9.2500772
144.0,0.68150651,-0.38809022,67.390129,0,11.076097,431.91592,-0.025545016,8.883666,11.075819,431.52777,-9.2484694
145.2,0.67727757,-0.39124134,67.390129,0,11.076097,435.5159,-0.025770554,8.8532066,11.075874,435.39026,-9.2465734
146.4,0.67282546,-0.39563754,67.226158,0,11.076097,439.11594,-0.026033735,8.7850657,11.075428,439.25702,-9.2447777
147.6,0.66258305,-0.40003186,67.225349,0,11.076097,442.71591,-0.026301686,8.6465225,11.075815,442.94073,-9.242794
148.8,0.68016654,-0.40422082,67.216125,0,11.076097,446.31595,-0.026580647,8.8931637,11.074861,446.54681,-9.2411623
150.0,0.68102151,-0.40744942,67.225281,0,11.076097,449.91415,-0.026800258,8.911809,11.075836,450.07654,-9.2391949
151.2,0.6760546,-0.40994313,65.670395,0,11.076097,449.9989,-0.026975011,8.8428307,11.076494,453.6196,-9.2392282
152.4,0.67031121,-0.41262928,63.499557,0,11.076097,449.9989,-0.027149837,8.7734489,11.075621,456.81168,-9.2392206
153.6,0.64712787,-0.41394803,60.859631,0,11.076097,449.9989,-0.0272153,8.4548826,11.076241,459.20422,-9.2388687
154.8,0.64018583,-0.41268381,57.818336,0,11.076097,449.9989,-0.027126452,8.3714037,11.075362,460.72372,-9.2388458
156.0,0.62260127,-0.41320634,54.613319,0,11.076097,449.9989,-0.027178483,8.1433935,11.075213,461.06689,-9.2385597
157.2,0.59903854,-0.40988165,51.596584,0,11.076097,449.9989,-0.026952637,7.8179264,11.076071,460.26193,-9.2383337
158.4,0.57699394,-0.40669894,49.638939,0,11.076097,449.9989,-0.026762553,7.5458679,11.076616,458.40933,-9.2383595
159.6,0.54840976,-0.40316913,49.119629,0,11.076097,449.9989,-0.026537584,7.1630616,11.075089,455.74472,-9.2382135
160.8,0.53343314,-0.40036824,50.146145,0,11.076097,449.9989,-0.026336173,6.9686613,11.076013,452.43591,-9.238059
162.0,0.53312773,-0.39832482,52.153442,0,11.076097,449.9989,-0.026206581,6.9754276,11.07546,449.37085,-9.2378597
163.2,0.53860998,-0.39556682,54.619114,0,11.076097,449.9989,-0.026028123,7.0466065,11.076025,446.63843,-9.2378435
164.4,0.53761178,-0.39582795,56.978615,0,11.076097,449.9989,-0.026048899,7.0328341,11.07555,444.66,-9.2379742
165.6,0.55597752,-0.39612916,59.09996,0,11.076097,449.9989,-0.026083361,7.2732129,11.075679,443.52533,-9.2378998
166.8,0.56785411,-0.39749187,60.719639,0,11.076097,449.9989,-0.026158884,7.4159598,11.076471,443.37857,-9.2376165
168.0,0.58954704,-0.39937502,61.846836,0,11.076097,449.9989,-0.026253514,7.7105742,11.076797,443.90216,-9.2375193
169.2,0.61052084,-0.40314925,62.38628,0,11.076097,449.9989,-0.02651182,7.9783082,11.075846,445.04688,-9.2374878
170.4,0.625193,-0.40422314,62.706554,0,11.076097,449.9989,-0.026596824,8.1738472,11.075874,446.48953,-9.2379141
171.6,0.63587195,-0.40685102,62.434494,0,11.076097,449.9989,-0.026762629,8.3287268,11.075948,448.27222,-9.2374439
172.8,0.64287847,-0.40914443,61.818211,0,11.076097,449.9989,-0.026925426,8.4187393,11.075776,450.04318,-9.2376776
174.0,0.64645064,-0.41120246,61.018478,0,11.076097,449.9989,-0.027038103,8.4610844,11.07598,451.57831,-9.2374477
175.2,0.64577812,-0.41269782,59.843216,0,11.076097,449.9989,-0.027120775,8.4442711,11.075344,452.97827,-9.23734
176.4,0.62996221,-0.4134005,58.497868,0,11.076097,449.9989,-0.027190456,8.2541542,11.075927,453.97754,-9.2368803
177.6,0.64165491,-0.4134956,57.260948,0,11.076097,449.9989,-0.027183037,8.4060526,11.075841,454.45547,-9.2375479
178.8,0.61847144,-0.41243479,55.858509,0,11.076097,449.9989,-0.027137607,8.0817766,11.075824,454.49225,-9.2372608
180.0,0.60830015,-0.41237697,54.936146,0,11.076097,449.9989,-0.027127344,7.9517798,11.075889,454.01801,-9.237361
181.2,0.60693294,-0.41245842,54.607796,0,11.076097,449.9989,-0.027111843,7.9412069,11.076207,453.12866,-9.2372131
182.4,0.60514027,-0.41225544,54.439579,0,11.076097,449.9989,-0.027096955,7.9198227,11.075571,451.98862,-9.2372074
183.6,0.59869844,-0.41135496,54.922554,0,11.076097,449.9989,-0.027056009,7.833581,11.076599,450.73312,-9.2377806
184.8,0.59462565,-0.41030255,55.535736,0,11.076097,449.9989,-0.02698868,7.7842269,11.076551,449.52377,-9.2379208
186.0,0.59260881,-0.41023993,56.424946,0,11.076097,449.9989,-0.027000805,7.7510567,11.07614,448.55423,-9.2377138
187.2,0.60550487,-0.41005078,57.260647,0,11.076097,449.9989,-0.026984867,7.9154983,11.076212,447.77826,-9.2377071
188.4,0.61295217,-0.41039491,58.181179,0,11.076097,449.9989,-0.02697582,8.0199404,11.075892,447.30127,-9.2374687
189.6,0.61655694,-0.41063303,58.853752,0,11.076097,449.9989,-0.027016576,8.0731573,11.076001,447.24335,-9.2369032
190.8,0.62946123,-0.41154712,59.348137,0,11.076097,449.9989,-0.027064603,8.2291956,11.075938,447.53885,-9.2370968
192.0,0.63186949,-0.41293722,59.600826,0,11.076097,449.9989,-0.027179267,8.2701511,11.075234,448.07465,-9.236742
193.2,0.64758658,-0.41443658,59.600838,0,11.076097,449.9989,-0.027275603,8.4709644,11.07696,448.88718,-9.2369795
194.4,0.65714401,-0.41633812,59.351723,0,11.076097,449.9989,-0.027374694,8.5939951,11.075541,449.66293,-9.2371788
195.284,0.63665259,0.011020545,59.106441,0,11.076099,3.2081649,0.00092163973,8.1133928,11.076834,450.24677,-9.2377014
195.2864,0.67415124,0.011902307,59.106441,0,11.076099,1.3868889000000002e-16,0.0010066086,8.5731382,11.075501,450.23959,-9.2376318
195.2888,0.64449561,0.0103216,54.377785,0,11.076099,5.9955178e-33,0.00070273236,8.1309328,11.0761,450.23718,-9.2375555
195.2912,0.62994379,0.01169787,40.192238,0,11.076099,0.0,0.00062867062,7.9410853,11.078279,450.24438,-9.2382126
195.2936,0.66282088,0.01300738,26.006691,0,11.076099,0.0,0.00074957515,8.5063324,11.080819,450.25156,-9.2373123
195.296,0.63400644,0.014403394,11.821143,0,11.076099,0.0,0.0010074715,8.1151266,11.0767,450.25876,-9.2374802
195.2984,0.64220554,0.012110187,0.0,0,11.076099,0.0,0.00097054651,8.1722574,11.076504,450.26953,-9.2370596
195.3008,0.63569307,0.013257318,0.0,0,11.076099,0.0,0.00096013991,8.0854406,11.079031,450.29828,-9.2365932
195.3032,0.61796802,0.016104726,0.0,0,11.076099,0.0,0.0008496613,7.9316673,11.076857,450.32703,-9.2364511
195.3056,0.62205082,0.017191809,0.0,0,11.076099,0.0,0.00093718356,7.8900404,11.077314,450.35577,-9.237236
195.308,0.63274485,0.014858842,0.0,0,11.076099,0.0,0.0011291651,8.0517931,11.076522,450.38452,-9.237792
195.3104,0.62439203,0.011300953,0.0,0,11.076099,0.0,0.0010142267,7.9121747,11.07906,450.36295,-9.2375298
195.3128,0.61177713,0.010813582,0.0,0,11.076099,0.0,0.00073811959,7.6727519,11.076544,450.3414,-9.2373447
195.3152,0.60970408,0.011788633,0.0,0,11.076099,0.0,0.00064103073,7.685956,11.076544,450.31982,-9.2373867
195.3176,0.62366587,0.012694749,0.0,0,11.076099,0.0,0.00073722459,7.9051762,11.076513,450.29828,-9.2378063
195.32,0.62270367,0.011949629,0.0,0,11.076099,0.0,0.00084267225,7.9845457,11.077908,450.3063,-9.2375793
195.3224,0.60342687,0.011174501,0.0,0,11.076099,0.0,0.00089374807,7.7776375,11.076362,450.32025,-9.2372437
195.3248,0.60753286,0.011088227,0.0,0,11.076099,0.0,0.00084812875,7.6815796,11.077752,450.3342,-9.2384186
195.3272,0.60888141,0.015564029,0.0,0,11.076099,0.0,0.00086324534,7.6438732,11.079981,450.34814,-9.2358093
195.3296,0.61588192,0.017313126,0.0,0,11.076099,0.0,0.00092157722,7.7449183,11.07989,450.34677,-9.2357807
195.332,0.61113727,0.015742054,0.0,0,11.076099,0.0,0.0010659624,7.7431521,11.076085,450.3324,-9.2356958
195.3344,0.60920823,0.012266926,0.0,0,10.976469,0.0,0.0010293988,7.7480927,11.076708,450.31802,-9.2375383
195.3368,0.61134207,0.011372594,0.0,0,10.615495,0.0,0.00079889956,7.7621703,11.077106,450.30365,-9.2370996
195.3392,0.61022574,0.010491771,0.0,0,10.254521,0.0,0.00058283663,7.7354288,11.0586,450.70422,-9.2366943
195.3416,0.63927722,0.012072723,0.0,0,9.893548,0.0,0.0007112879,8.0511904,10.924347,451.79639,-9.2356586
195.344,0.59620649,0.012582818,0.0,0,9.5325737,0.0,0.00086918491,7.6912284,10.639107,452.88855,-9.2368565
195.3464,0.61899906,0.010808862,0.0,0,9.1800261,0.0,0.00092710514,7.9338584,10.252978,453.98071,-9.2368908
195.3488,5.0502009,0.30057985,0.0,0,8.8288584,0.0,0.019501708,63.524624,9.8559952,455.73788,-9.2339706
195.3512,6.0247564,0.70471323,0.0,0,8.4910259,0.0,0.047789555,72.625076,9.3941565,460.02209,-9.2340784
195.3536,6.0032125,1.1434617,0.0,0,8.1570415,0.0,0.0785418,70.839302,8.9339161,464.30634,-9.2319794
195.356,6.2731738,1.5444667,0.0,0,7.8342957,0.0,0.10822947,71.520615,8.5458403,468.59055,-9.2319126
195.3584,6.5424905,1.8843958,0.0,0,7.5165353,0.0,0.13400006,72.843346,8.1871843,472.80237,-9.2325573
195.3608,6.6546946,2.210927,0.0,0,7.2082515,0.0,0.15924847,72.186378,7.8384147,475.34918,-9.2328663
195.3632,6.786757,2.534786,0.0,0,6.9060431,0.0,0.18459992,71.885086,7.5114512,477.89597,-9.2329073
195.3656,6.9486876,2.8332508,0.0,0,6.6115613,0.0,0.20879453,71.761795,7.2087283,480.44275,-9.2337103
195.368,7.1458879,3.1174269,0.0,0,6.3240418,0.0,0.23260176,72.074356,6.9188476,482.98953,-9.2328367
195.3704,7.3396034,3.3924434,0.0,0,6.042748,0.0,0.25631267,72.263786,6.6297393,483.48352,-9.2344246
195.3728,7.4605751,3.6741605,0.0,0,5.7692914,0.0,0.28077686,71.656166,6.3466182,483.68423,-9.2332802
195.3752,7.6291447,3.9511456,0.0,0,5.5006137,0.0,0.30507195,71.523132,6.0687513,483.88495,-9.2331104
195.3776,7.8151217,4.2300124,0.0,0,5.2404532,0.0,0.33035401,71.426788,5.7907681,484.08569,-9.2340441
195.38,8.0099468,4.5015273,0.0,0,4.9838042,0.0,0.35624781,71.392273,5.5139036,484.56061,-9.2334452
195.3824,8.1900711,4.768487,0.0,0,4.7363639,0.0,0.38257405,71.105247,5.2420497,485.14847,-9.2331009
195.3848,8.3584404,5.0321875,0.0,0,4.4912457,0.0,0.4086341,70.72715,4.9762578,485.7363,-9.2346315
195.3872,8.5374222,5.2959328,0.0,0,4.2558532,0.0,0.43504059,70.30732,4.7153211,486.32413,-9.2329483
195.3896,8.747489,5.5499511,0.0,0,4.0217257,0.0,0.46110538,70.179688,4.459023,486.37613,-9.2327347
195.392,8.9870949,5.7941914,0.0,0,3.7978494,0.0,0.4876743,70.183105,4.2113423,485.97467,-9.2335005
195.3944,9.1746292,6.0321217,0.0,0,3.5743496,0.0,0.51420611,69.790428,3.971066,485.57321,-9.2330265
195.3968,9.3872252,6.264008,0.0,0,3.3612847,0.0,0.54052323,69.606842,3.737267,485.17178,-9.2313499
195.3992,9.6239128,6.4937229,0.0,0,3.1483088,0.0,0.56667447,69.488243,3.5102055,484.63861,-9.2324896
195.4016,9.88867,6.716331,0.0,0,2.9451065,0.0,0.59254169,69.585281,3.2921262,483.88589,-9.2326698
195.404,10.152443,6.9304338,0.0,0,2.7424984,0.0,0.61920136,69.568825,3.0798631,483.13318,-9.232358
195.4064,10.418777,7.1342635,0.0,0,2.5483873,0.0,0.64575511,69.553978,2.8708253,482.38043,-9.2319269
195.4088,10.677277,7.3342404,0.0,0,2.3556671,0.0,0.67150623,69.392166,2.6686018,481.44095,-9.2319498
195.4112,11.005952,7.5317974,0.0,0,2.1702483,0.0,0.69682592,69.757271,2.4756751,479.79166,-9.2317905
195.4136,11.376144,7.727541,0.0,0,1.9869361,0.0,0.72298479,70.24707,2.2760019,478.1424,-9.2306738
195.416,11.73009,7.9191213,0.0,0,1.8098084,0.0,0.75006163,70.573723,2.0871866,476.49313,-9.2300205
195.4184,12.107183,8.1061592,0.0,0,1.6354244,0.0,0.77755052,70.792557,1.9003257,474.84561,-9.2305536
195.4208,12.529612,8.2861147,0.0,0,1.4662173,0.0,0.80411857,71.351433,1.7152131,473.23877,-9.2298012
195.4232,12.97468,8.4680519,0.0,0,1.3003293,0.0,0.83083165,71.919342,1.537486,471.63193,-9.2307968
195.4256,13.462558,8.6475601,0.0,0,1.1387084,0.0,0.8577826,72.68589,1.3625114,470.02509,-9.2300444
195.428,13.945817,8.817812,0.0,0,0.98093235,0.0,0.88528103,73.187363,1.1959972,468.41827,-9.2300472
195.4304,14.438859,8.9757032,0.0,0,0.82657731,0.0,0.91241932,73.753197,1.0289614,466.13147,-9.229146
195.4328,14.999748,9.1294937,0.0,0,0.67652941,0.0,0.93879813,74.646179,0.86558694,463.74753,-9.2290783
195.4352,15.576414,9.2845249,0.0,0,0.52908593,0.0,0.96446377,75.519318,0.70998561,461.36362,-9.229723
195.4376,16.14492,9.4336824,0.0,0,0.3862859,0.0,0.98996949,76.413223,0.558424,458.97968,-9.2294521
195.44,13.2719,9.4561176,0.0,0,0.24542016,0.0,0.99460572,62.58923,0.46971208,458.35553,-9.2309742
195.4424,11.987597,9.4515944,0.0,0,0.10962815,0.0,0.99492747,56.466824,0.41955256,458.45599,-9.2338505
195.4448,11.167049,9.4530869,0.0,0,-0.025516368,0.0,0.99586618,52.572659,0.38390148,458.55649,-9.233489
195.4472,10.844312,9.4562998,0.0,0,-0.15794842,0.0,0.99553978,51.04575,0.3526133,458.65695,-9.2344103
195.4496,10.870883,9.4692125,0.0,0,-0.29038045,0.0,0.99679816,51.057972,0.30972412,460.29742,-9.2342339
195.452,11.170557,9.478013,0.0,0,-0.42281243,0.0,0.99839878,52.419949,0.25095752,463.24097,-9.2341003
195.4544,11.367341,9.4794579,0.0,0,-0.55524439,0.0,0.99995661,53.259235,0.17523827,466.18451,-9.2322931
195.4568,11.356025,9.4793491,0.0,0,-0.68767637,0.0,1.0006864,53.140064,0.11272699,469.12805,-9.2325745
195.4592,11.247695,9.4828949,0.0,0,-0.82010835,0.0,1.0003941,52.694836,0.059820287,471.56491,-9.2332888
195.4616,11.019658,9.4905338,0.0,0,-0.9525404,0.0,1.000788,51.570744,0.016651498,473.15732,-9.2330265
195.464,10.672769,9.4945459,0.0,0,-1.0849724,0.0,1.0016536,49.9613,-0.018184928,474.74973,-9.2338438
195.4664,10.239186,9.495717,0.0,0,-0.72870702,450.0,1.0027591,47.866695,-0.029886855,476.3421,-9.234395
195.4688,9.7719364,9.4921417,0.0,0,-0.27022067,450.0,1.0028342,45.663212,-0.032586414,477.85516,-9.2338362
195.4712,9.3235407,9.4929199,0.0,0,0.18826568,450.0,1.0025008,43.581581,-0.023845172,479.06668,-9.234971
195.4736,8.9780378,9.4976444,0.0,0,0.64675206,450.0,1.0019736,41.973083,-0.018356215,480.2782,-9.2341146
195.476,8.7131424,9.5025539,0.0,0,1.1052387,450.0,1.002517,40.73558,-0.01510051,481.48972,-9.2343464
195.4784,8.2048092,9.5033636,0.0,0,1.563725,450.0,1.0039508,38.389652,-0.00060448278,482.69049,-9.2349033
195.4808,6.6649323,9.4906826,0.0,0,2.0222113,450.0,1.002694,31.339512,0.070829667,483.64392,-9.2357225
195.4832,3.7634974,9.4743671,0.0,0,2.4806981,450.0,0.99924999,17.902035,0.24098246,484.59738,-9.2385206
195.4856,0.26116362,9.4538975,0.0,0,2.9391842,450.0,0.9944703,1.6478695,0.50283712,485.55081,-9.2404289
195.488,-0.20444626,9.4247704,0.0,0,3.3976707,450.0,0.98894453,-1.0120326,0.98277563,486.50427,-9.24088
195.4904,0.094810612,9.4499741,0.0,0,3.8561573,450.0,0.99424183,0.33213866,1.7215966,487.03745,-9.241293
195.4928,-0.066310629,9.4684858,0.0,0,4.3146434,450.0,0.99871451,-0.32324323,2.49436,487.51059,-9.2404127
195.4952,0.0042619654,9.4669638,0.0,0,4.7731299,450.0,0.9978537,-0.00068428204,3.1553669,487.9837,-9.2395258
195.4976,-0.020225523,9.468564,0.0,0,5.2316165,450.0,0.99712533,-0.13355733,3.6587777,488.45685,-9.2392015
195.5,-0.025782289,9.472477,0.0,0,5.6901026,450.0,0.99706537,-0.21643153,4.0923572,488.76743,-9.2400627
195.5024,0.054513637,9.4665146,0.0,0,6.1485891,450.0,0.99697042,0.2857691,4.5183558,489.01108,-9.2383585
195.5048,-0.069575757,9.4576931,0.0,0,6.6070752,450.0,0.9968124,-0.31590253,4.9530439,489.25476,-9.2396278
195.5072,-0.023608586,9.4558496,0.0,0,7.0655618,450.0,0.99623042,-0.16004838,5.403688,489.49841,-9.2381296
195.5096,0.021342084,9.4608736,0.0,0,7.5240483,450.0,0.99581009,0.14393404,5.882381,489.73813,-9.2370195
195.512,-0.11942447,9.4618721,0.0,0,7.9825354,450.0,0.99540353,-0.58621949,6.352293,489.97452,-9.2375135
195.5144,0.0072092344,9.4602203,0.0,0,8.441021,450.0,0.99626589,0.0092204837,6.8370676,490.21091,-9.238615
195.5168,0.034316719,9.4575739,0.0,0,8.8995075,450.0,0.99658877,0.23222332,7.3129625,490.4473,-9.2388067
195.5192,-0.17588933,9.4589148,0.0,0,9.3579931,450.0,0.99662542,-0.86646271,7.7841372,490.67023,-9.238452
195.5216,0.036620133,9.4620342,0.0,0,9.8164806,450.0,0.99589908,0.078060053,8.2539978,490.87079,-9.2372189
195.524,0.082742989,9.4662066,0.0,0,10.274966,450.0,0.9956007,0.49894449,8.7244511,491.07135,-9.2362728
195.5264,-0.21012352,9.4659386,0.0,0,10.733453,450.0,0.99660319,-1.0016686,9.1972828,491.27188,-9.2369604
195.5288,0.13635331,9.4578304,0.0,0,11.191939,450.0,0.99661809,0.53809071,9.6820393,491.465,-9.2372255
195.5312,-0.081124134,9.4556007,0.0,0,11.650426,450.0,0.99611551,-0.24965534,10.158834,491.62973,-9.236412
195.5336,-0.10424209,9.4589653,0.0,0,12.108912,450.0,0.99559367,-0.57244492,10.62746,491.79449,-9.2365303
195.536,0.081464075,9.4628515,0.0,0,12.567399,450.0,0.99561405,0.31244665,11.101516,491.95923,-9.2372189
195.5384,-0.063017197,9.4622498,0.0,0,13.025885,450.0,0.9959597,-0.16037403,11.561819,492.12369,-9.2372627
195.5408,-0.19955705,9.4587402,0.0,0,13.484371,450.0,0.99663109,-1.0250523,12.001659,492.28128,-9.2379475
195.5432,0.14420705,9.4544525,0.0,0,13.942858,450.0,0.99595314,0.57612973,12.46929,492.43884,-9.2358046
195.5456,-0.099179626,9.4561062,0.0,0,14.401344,450.0,0.99507433,-0.38905281,12.929568,492.59641,-9.2353992
195.548,-0.076050743,9.4621706,0.0,0,14.859831,450.0,0.99522412,-0.39686725,13.405687,492.754,-9.2360191
195.5504,0.10130516,9.4627275,0.0,0,15.318317,450.0,0.9959119,0.45414445,13.89982,492.86142,-9.2358656
195.5528,-0.11546107,9.4572449,0.0,0,15.776803,450.0,0.99642998,-0.43898314,14.375361,492.9617,-9.2355871
195.5552,-0.040015925,9.4558058,0.0,0,16.235291,450.0,0.99639356,-0.33143964,14.838397,493.06198,-9.2364092
195.5576,0.15202132,9.4547281,0.0,0,16.693775,450.0,0.99508238,0.80464256,15.303781,493.16229,-9.2348156
195.56,-0.12978886,9.4601326,0.0,0,17.152262,450.0,0.9951691,-0.59606487,15.754339,493.24228,-9.2356234
195.5624,-0.093715936,9.4597273,0.0,0,17.61075,450.0,0.99547207,-0.50967485,16.202293,493.3139,-9.2351389
195.5648,0.04811487,9.4570408,0.0,0,17.999975,450.0,0.99619639,0.17836347,16.669022,493.38553,-9.2346601
195.5672,-0.080957308,9.4539995,0.0,0,18.0,450.0,0.99597889,-0.28208566,17.121805,493.45715,-9.2343912
195.5696,-0.047287624,9.4558182,0.0,0,18.0,450.0,0.9952634,-0.2884306,17.555389,493.53656,-9.2354736
195.572,0.016871225,9.4620237,0.0,0,18.0,450.0,0.99509519,0.096055076,17.92729,493.6225,-9.2356853
195.5744,-0.075780623,9.4649372,0.0,0,18.0,450.0,0.99619949,-0.36157095,18.230148,493.70844,-9.2374182
195.5768,0.023646761,9.4643908,0.0,0,18.0,450.0,0.99750745,0.099046059,18.432566,493.7944,-9.2409792
195.5792,0.050493967,9.4640837,0.0,0,18.0,450.0,0.99796289,0.2463807,18.507473,493.87497,-9.2447577
195.5816,-0.018842245,9.472477,0.0,0,18.0,450.0,0.998245,-0.11171587,18.453768,493.94659,-9.2516012
195.584,0.42325521,9.4859285,0.0,0,18.0,450.0,0.99972713,1.9322958,18.323648,494.01822,-9.2621508
195.5864,0.41376591,9.4912376,0.0,0,18.0,450.0,1.0011704,1.9689775,18.193714,494.08984,-9.2754192
195.5888,0.4747656,9.490675,0.0,0,18.0,450.0,1.0020534,2.1669359,18.091845,494.15253,-9.291132
195.5912,0.44854197,9.4877224,0.0,0,18.0,450.0,1.0021867,2.1174903,18.047907,494.18115,-9.3092871
195.5936,0.44153899,9.488184,0.0,0,18.0,450.0,1.0014086,2.0694764,18.043907,494.20981,-9.3296804
195.596,0.39190722,9.4937248,0.0,0,18.0,450.0,1.0010916,1.8597277,18.047195,494.23846,-9.3521194
195.5984,0.39429045,9.4942513,0.0,0,18.0,450.0,1.0013539,1.8569186,18.065645,494.26743,-9.3733101
195.6008,0.41402093,9.4887609,0.0,0,18.0,450.0,1.0016885,1.9435889,18.090824,494.30325,-9.3919668
195.6032,0.43709493,9.4832964,0.0,0,18.0,450.0,1.0014522,2.0290978,18.117596,494.33905,-9.4110212
195.6056,0.41955611,9.4860783,0.0,0,18.0,450.0,1.0010066,2.0037706,18.134121,494.37488,-9.4303818
195.608,0.41276929,9.4902754,0.0,0,18.0,450.0,1.0006675,1.9430966,18.146437,494.41068,-9.4479809
195.6104,0.41056228,9.4905424,0.0,0,18.0,450.0,1.0008347,1.9280249,18.150116,494.4465,-9.4656019
195.6128,0.44900993,9.4848633,0.0,0,18.0,450.0,1.0007113,2.08706,18.14467,494.48233,-9.4828329
195.6152,0.44438571,9.4804087,0.0,0,18.0,450.0,1.0006864,2.0654309,18.145226,494.51813,-9.5005217
195.6176,0.43002903,9.4843245,0.0,0,18.0,450.0,1.000767,2.0452294,18.140112,494.55396,-9.5172939
195.62,0.41261289,9.4905748,0.0,0,18.0,450.0,1.000857,1.909137,18.136013,494.56439,-9.5341082
195.6224,0.4395889,9.4959164,0.0,0,18.0,450.0,1.0013037,2.0250704,18.133514,494.56439,-9.5525694
195.6248,0.45272371,9.4931059,0.0,0,18.0,450.0,1.0021957,2.136548,18.129837,494.56439,-9.5712137
195.6272,0.45550379,9.4879713,0.0,0,18.0,450.0,1.0022823,2.1211948,18.128195,494.56439,-9.5900116
195.6296,0.41900873,9.4861364,0.0,0,18.0,450.0,1.0011189,1.9781922,18.126003,494.57993,-9.6090364
195.632,0.4230662,9.4871969,0.0,0,18.0,450.0,1.0002186,1.9887254,18.120499,494.60855,-9.6269512
195.6344,0.45759687,9.4901676,0.0,0,18.0,450.0,1.0007812,2.1250994,18.120884,494.63721,-9.6435385
195.6368,0.46160695,9.4895592,0.0,0,18.0,450.0,1.001372,2.1522546,18.11742,494.66586,-9.6611462
195.6392,0.45491648,9.485054,0.0,0,18.0,450.0,1.0015095,2.1321478,18.116999,494.69183,-9.6801357
195.6416,0.42227691,9.4842834,0.0,0,18.0,450.0,1.001121,1.9601809,18.11264,494.71332,-9.698534
195.644,0.43852249,9.4910736,0.0,0,18.0,450.0,1.001014,2.0564289,18.110132,494.7348,-9.7155485
195.6464,0.46055785,9.4967394,0.0,0,18.0,450.0,1.0013787,2.1446283,18.104548,494.75632,-9.7328863
195.6488,0.46718448,9.4934139,0.0,0,18.0,450.0,1.0019653,2.1709671,18.103561,494.77182,-9.7528734
195.6512,0.41938904,9.4890318,0.0,0,18.0,450.0,1.002316,1.9887322,18.110348,494.76465,-9.7700624
195.6536,0.4320505,9.4848709,0.0,0,18.0,450.0,1.0012641,1.991254,18.102863,494.75751,-9.7881041
195.656,0.44619441,9.4858255,0.0,0,18.0,450.0,1.0002102,2.0684307,18.102932,494.75034,-9.805809
195.6584,0.4626154,9.490819,0.0,0,18.0,450.0,1.0007676,2.1373665,18.100956,494.74408,-9.8243227
195.6608,0.43997729,9.4919643,0.0,0,18.0,450.0,1.0016432,2.0607824,18.100918,494.75839,-9.842351
195.6632,0.41363862,9.4868517,0.0,0,18.0,450.0,1.0017483,1.9434776,18.102671,494.77271,-9.8595161
195.6656,0.41177779,9.4853001,0.0,0,18.0,450.0,1.0014257,1.9447974,18.101971,494.78705,-9.8779936
195.668,0.44262296,9.4889154,0.0,0,18.0,450.0,1.0009239,2.090112,18.1012,494.80136,-9.89361
195.6704,0.44750249,9.4949694,0.0,0,18.0,450.0,1.0011562,2.0796781,18.099333,494.80316,-9.9114866
195.6728,0.4288438,9.4946451,0.0,0,18.0,450.0,1.0019678,1.9892353,18.101044,494.80316,-9.930192
195.6752,0.4221248,9.4901676,0.0,0,18.0,450.0,1.0024714,1.9629731,18.098345,494.80316,-9.9481544
195.6776,0.43857524,9.4861269,0.0,0,18.0,450.0,1.0017434,2.0591376,18.098511,494.80316,-9.9645424
195.68,0.44041982,9.487772,0.0,0,18.0,450.0,1.0007322,2.0843022,18.095732,494.7981,-9.9840622
195.6824,0.44531143,9.4897051,0.0,0,18.0,450.0,1.0006019,2.1016169,18.094667,494.79092,-10.00208
195.6848,0.41093084,9.4915371,0.0,0,18.0,450.0,1.0013639,1.937481,18.098112,494.78375,-10.021445
195.6872,0.42617744,9.4874277,0.0,0,18.0,450.0,1.0017126,1.9808259,18.09761,494.77661,-10.039728
195.6896,0.44691941,9.486928,0.0,0,18.0,450.0,1.0017084,2.067486,18.094643,494.76169,-10.058331
195.692,0.45913681,9.4924221,0.0,0,18.0,450.0,1.0016854,2.1526396,18.089598,494.74017,-10.076352
195.6944,0.43371299,9.4975071,0.0,0,18.0,450.0,1.0015178,2.0633347,18.088467,494.71869,-10.094878
195.6968,0.43683669,9.4974155,0.0,0,18.0,450.0,1.0020566,1.9958596,18.084177,494.6972,-10.112538
195.6992,0.45025653,9.4914675,0.0,0,18.0,450.0,1.0024751,2.083087,18.084255,494.67303,-10.129843
195.7016,0.46538177,9.4858541,0.0,0,18.0,450.0,1.001722,2.1702893,18.086555,494.64438,-10.147353
195.704,0.46368632,9.4865007,0.0,0,18.0,450.0,1.0007256,2.1876907,18.084711,494.61572,-10.164827
195.7064,0.43767333,9.4914713,0.0,0,18.0,450.0,1.0007813,2.0407236,18.084808,494.58707,-10.183292
195.7088,0.43895489,9.4929285,0.0,0,18.0,450.0,1.0015198,2.0292645,18.086813,494.5629,-10.200597
195.7112,0.45961741,9.4893713,0.0,0,18.0,450.0,1.0019593,2.1253071,18.084044,494.55573,-10.218395
195.7136,0.48635355,9.4861364,0.0,0,18.0,450.0,1.0017773,2.2827032,18.081879,494.54858,-10.237022
195.716,0.45696631,9.4887419,0.0,0,18.0,450.0,1.0013436,2.17662,18.083567,494.54141,-10.254224
195.7184,0.43723184,9.4970465,0.0,0,18.0,450.0,1.0015655,2.0517828,18.080589,494.53394,-10.273679
195.7208,0.44967678,9.4982615,0.0,0,18.0,450.0,1.0022711,2.1188779,18.082268,494.51962,-10.291291
195.7232,0.46022487,9.4940767,0.0,0,18.0,450.0,1.0029688,2.1633348,18.083702,494.50531,-10.308299
195.7256,0.4756172,9.4891338,0.0,0,18.0,450.0,1.0025325,2.2201254,18.080624,494.49097,-10.326187
195.728,0.44194365,9.4883289,0.0,0,18.0,450.0,1.0011452,2.0661998,18.081673,494.47665,-10.345595
195.7304,0.43430156,9.4937677,0.0,0,18.0,450.0,1.0013127,2.0358992,18.079285,494.47485,-10.363856
195.7328,0.45824924,9.4943714,0.0,0,18.0,450.0,1.0016707,2.1473603,18.077986,494.47485,-10.382358
195.7352,0.47379747,9.4917126,0.0,0,18.0,450.0,1.0022944,2.1952486,18.078314,494.47485,-10.400078
195.7376,0.44890213,9.4887466,0.0,0,18.0,450.0,1.0023241,2.1056955,18.07354,494.47485,-10.418789
195.74,0.4379316,9.4907675,0.0,0,18.0,450.0,1.0018567,2.0577538,18.078487,494.44949,-10.436534
195.7424,0.4440929,9.4958115,0.0,0,18.0,450.0,1.001567,2.0728807,18.078527,494.41367,-10.454145
195.7448,0.46400312,9.4983931,0.0,0,18.0,450.0,1.0020429,2.1571698,18.076912,494.37784,-10.472139
195.7472,0.49151084,9.4964352,0.0,0,18.0,450.0,1.0030556,2.2728155,18.071899,494.34204,-10.487955
195.7496,0.44566503,9.4895973,0.0,0,18.0,450.0,1.002553,2.0845621,18.072725,494.31009,-10.506991
195.752,0.43094355,9.4875832,0.0,0,18.0,450.0,1.0013264,2.0256345,18.075483,494.28146,-10.526005
195.7544,0.45692301,9.4908648,0.0,0,18.0,450.0,1.0008121,2.1268375,18.071196,494.25281,-10.544096
195.7568,0.47679204,9.4963942,0.0,0,18.0,450.0,1.0018878,2.2022452,18.071285,494.22415,-10.56216
195.7592,0.46420765,9.4944162,0.0,0,18.0,450.0,1.0024931,2.1594646,18.072838,494.21161,-10.578798
195.7616,0.44095439,9.489996,0.0,0,18.0,450.0,1.0025361,2.0710685,18.069397,494.22592,-10.59657
195.764,0.43939674,9.4909325,0.0,0,18.0,450.0,1.0019751,2.0328829,18.071909,494.24026,-10.615651
195.7664,0.47063774,9.4940643,0.0,0,18.0,450.0,1.0013204,2.1772158,18.077606,494.25458,-10.631902
195.7688,0.48102841,9.4976845,0.0,0,18.0,450.0,1.0017455,2.2381017,18.072636,494.26294,-10.650376
195.7712,0.44635782,9.4965887,0.0,0,18.0,450.0,1.0028563,2.1133237,18.066916,494.24863,-10.668839
195.7736,0.4472281,9.4922876,0.0,0,18.0,450.0,1.003045,2.0869441,18.069036,494.23428,-10.686822
195.776,0.46693766,9.490346,0.0,0,18.0,450.0,1.0020307,2.163965,18.067621,494.21997,-10.704638
195.7784,0.49025786,9.4937429,0.0,0,18.0,450.0,1.0015547,2.2602215,18.06612,494.20505,-10.722308
195.7808,0.48081788,9.4958935,0.0,0,18.0,450.0,1.0015334,2.2207181,18.065767,494.17639,-10.740239
195.7832,0.43732712,9.493577,0.0,0,18.0,450.0,1.0023367,2.079813,18.066002,494.14777,-10.758772
195.7856,0.44838229,9.4890594,0.0,0,18.0,450.0,1.0024991,2.0913851,18.06609,494.11911,-10.777246
195.788,0.49009109,9.4898987,0.0,0,18.0,450.0,1.0020376,2.2420263,18.064722,494.09045,-10.794321
195.7904,0.48760951,9.4966116,0.0,0,18.0,450.0,1.0018952,2.300633,18.06918,494.04929,-10.812778
195.7928,0.47135022,9.503109,0.0,0,18.0,450.0,1.0025336,2.2165027,18.061363,494.00629,-10.830515
195.7952,0.45481896,9.5009098,0.0,0,18.0,450.0,1.0032337,2.0778828,18.05868,493.96332,-10.84803
195.7976,0.46536124,9.4914923,0.0,0,18.0,450.0,1.0027847,2.172461,18.062866,493.92035,-10.86661
195.8,0.49342054,9.4888477,0.0,0,18.0,450.0,1.0019538,2.3144665,18.062384,493.87735,-10.883963
195.8024,0.48829779,9.4926405,0.0,0,18.0,450.0,1.0014958,2.3017848,18.061609,493.83438,-10.899417
195.8048,0.45719704,9.4964838,0.0,0,18.0,450.0,1.0017358,2.1592691,18.057859,493.79141,-10.917836
195.8072,0.44520018,9.4957781,0.0,0,18.0,450.0,1.0024093,2.0773857,18.060335,493.74841,-10.936058
195.8096,0.4723323,9.4914951,0.0,0,18.0,450.0,1.0027519,2.2004144,18.061586,493.7132,-10.953539
195.812,0.48616526,9.4898586,0.0,0,18.0,450.0,1.0022138,2.3153367,18.055111,493.68457,-10.973194
195.8144,0.46699044,9.4935942,0.0,0,18.0,450.0,1.0015805,2.1986988,18.058004,493.65591,-10.991499
195.8168,0.44746831,9.4968824,0.0,0,18.0,450.0,1.0012933,2.0851853,18.055941,493.62726,-11.009554
195.8192,0.46001458,9.4970007,0.0,0,18.0,450.0,1.002252,2.121367,18.056877,493.60397,-11.02729
195.8216,0.49210727,9.4914789,0.0,0,18.0,450.0,1.0026089,2.2971487,18.059238,493.58966,-11.045276
195.824,0.47364193,9.4884081,0.0,0,18.0,450.0,1.0020974,2.2393997,18.059645,493.57532,-11.063939
195.8264,0.45643282,9.4903145,0.0,0,18.0,450.0,1.0012534,2.1482985,18.055174,493.561,-11.082263
195.8288,0.45604825,9.4932938,0.0,0,18.0,450.0,1.0012559,2.1141987,18.054207,493.54816,-11.097907
195.8312,0.47397894,9.4940367,0.0,0,18.0,450.0,1.0018741,2.2307107,18.0513,493.54099,-11.116051
195.8336,0.4997189,9.4896517,0.0,0,18.0,450.0,1.0020819,2.3269951,18.052229,493.53384,-11.134886
195.836,0.47824594,9.4896698,0.0,0,18.0,450.0,1.0023727,2.2237577,18.050419,493.52667,-11.153135
195.8384,0.46129385,9.4929571,0.0,0,18.0,450.0,1.001748,2.1063325,18.050129,493.51862,-11.171305
195.8408,0.4700684,9.4982166,0.0,0,18.0,450.0,1.0016524,2.199429,18.051863,493.48996,-11.189168
195.8432,0.4926132,9.4973307,0.0,0,18.0,450.0,1.0020962,2.2986929,18.054392,493.46133,-11.206509
195.8456,0.49701062,9.4923515,0.0,0,18.0,450.0,1.0028697,2.3182089,18.049461,493.43268,-11.22506
195.848,0.47812611,9.4890299,0.0,0,18.0,450.0,1.00252,2.2103233,18.048386,493.40402,-11.242817
195.8504,0.45492405,9.491312,0.0,0,18.0,450.0,1.0016581,2.1359496,18.050964,493.35657,-11.259291
195.8528,0.48812491,9.4939461,0.0,0,18.0,450.0,1.0012261,2.2716403,18.049074,493.30643,-11.278011
195.8552,0.50521284,9.4958963,0.0,0,18.0,450.0,1.0019537,2.3502667,18.054676,493.25629,-11.295094
195.8576,0.48607674,9.4925127,0.0,0,18.0,450.0,1.0024629,2.2933872,18.049952,493.20615,-11.314028
195.86,0.4733884,9.4905224,0.0,0,18.0,450.0,1.0025834,2.215883,18.048145,493.18137,-11.33165
195.8624,0.47231567,9.4900579,0.0,0,18.0,450.0,1.0015036,2.2087815,18.048727,493.16705,-11.350706
196.0643,0.44735137,9.4934454,0.0,0,18.0,0.85476655,1.0020561,2.0914404,18.025442,488.33472,-11.48035
197.2643,0.3890996,9.5058155,0.0,0,18.0,3.6951402e-17,1.0044188,1.8161314,18.000652,469.06052,-11.481788
198.4643,0.38956872,9.516304,0.0,0,18.0,1.5974028e-33,1.0062904,1.8101315,17.999325,454.21442,-11.482119
199.6643,0.39085835,9.5254507,0.0,0,18.0,1.4012985e-45,1.0079379,1.8120855,17.999022,440.66608,-11.481836
200.8643,0.39387169,9.5338192,0.0,0,18.0,1.4012985e-45,1.0094978,1.8210174,17.999922,428.09204,-11.482976
202.0643,0.39578885,9.5414419,0.0,0,18.0,1.4012985e-45,1.0107877,1.8324512,17.999678,416.1452,-11.482435
203.2643,0.40052795,9.5486994,0.0,0,18.0,1.4012985e-45,1.0121835,1.8483361,18.000145,404.70599,-11.482142
204.4643,0.40220311,9.5559187,0.0,0,18.0,1.4012985e-45,1.0135838,1.8597065,18.000452,393.69647,-11.48232
205.6643,0.41434878,9.5628853,0.0,0,18.0,1.4012985e-45,1.0148076,1.9123205,17.999733,383.02435,-11.482352
206.8643,0.41646501,9.569519,0.0,0,18.0,1.4012985e-45,1.0160571,1.9107873,17.999981,372.69183,-11.48289
208.0643,0.41402411,9.5760612,0.0,0,18.0,1.4012985e-45,1.0172019,1.9011127,17.999846,362.66388,-11.483102
209.2643,0.41277283,9.5828104,0.0,0,18.0,1.4012985e-45,1.0184034,1.8948469,17.998642,352.91675,-11.482852
210.4643,0.4151271,9.5882397,0.0,0,18.0,1.4012985e-45,1.0195222,1.9046718,18.001123,343.29819,-11.482761
211.6643,0.42030728,9.5944061,0.0,0,18.0,1.4012985e-45,1.0206319,1.9269695,17.999847,334.20911,-11.482625
212.8643,0.42324692,9.5998249,0.0,0,18.0,1.4012985e-45,1.0216128,1.9364858,18.001328,325.32977,-11.48258
214.0643,0.42248076,9.6056452,0.0,0,18.0,1.4012985e-45,1.022696,1.933393,17.999605,316.65411,-11.482547
215.2643,0.42857227,9.6109581,0.0,0,18.0,1.4012985e-45,1.0236046,1.9615035,17.999241,308.30444,-11.482898
216.4643,0.43043181,9.6154499,0.0,0,18.0,1.4012985e-45,1.0245305,1.9678702,17.999866,300.09683,-11.482823
217.6643,0.43701333,9.6201019,0.0,0,18.0,1.4012985e-45,1.025436,1.9988688,18.000359,292.15167,-11.483388
218.8643,0.43174276,9.6254692,0.0,0,18.0,1.4012985e-45,1.0263579,1.9706842,17.999479,284.58444,-11.483026
220.0643,0.4420515,9.6301003,0.0,0,18.0,1.4012985e-45,1.0272714,2.0153203,17.999956,277.06656,-11.483175
221.2643,0.43726683,9.6349449,0.0,0,18.0,1.4012985e-45,1.0280828,1.9989078,18.000027,269.82013,-11.483094
222.4643,0.44923106,9.6392288,0.0,0,18.0,1.4012985e-45,1.0288988,2.0449026,17.999483,262.67227,-11.482874
223.6643,0.44640717,9.6436405,0.0,0,18.0,1.4012985e-45,1.0298284,2.0311422,18.000206,255.90341,-11.482502
224.8643,0.44907603,9.6487198,0.0,0,18.0,1.4012985e-45,1.0306879,2.037955,17.999281,249.23203,-11.481956
226.0643,0.44473606,9.652173,0.0,0,18.0,1.4012985e-45,1.0314058,2.0255694,17.999376,242.58499,-11.481962
227.2643,0.4537729,9.6566925,0.0,0,18.0,1.4012985e-45,1.0321589,2.0593328,18.000641,235.86951,-11.482206
228.4643,0.45265904,9.6606054,0.0,0,18.0,1.4012985e-45,1.0328913,2.0460145,17.99996,229.72345,-11.482027
229.6643,0.46196654,9.664362,0.0,0,18.0,1.4012985e-45,1.0336848,2.0923536,17.999546,223.73811,-11.482289
230.8643,0.45308521,9.6680012,0.0,0,18.0,1.4012985e-45,1.034338,2.0480134,18.000879,217.90045,-11.482727
232.0643,0.45309654,9.6717272,0.0,0,18.0,1.4012985e-45,1.0350358,2.0431364,17.99896,212.19554,-11.482454
233.2643,0.45885715,9.6753464,0.0,0,18.0,1.4012985e-45,1.0356439,2.0736821,18.000494,206.76688,-11.482745
234.4643,0.45916432,9.6790886,0.0,0,18.0,1.4012985e-45,1.0363611,2.0675473,17.99859,201.43509,-11.482828
235.6643,0.46306098,9.6817636,0.0,0,18.0,1.4012985e-45,1.0369606,2.081749,18.001101,196.22562,-11.48253
236.8643,0.45847589,9.6853523,0.0,0,18.0,1.4012985e-45,1.0375907,2.0590694,17.999929,191.17786,-11.482269
238.0643,0.46089545,9.6889048,0.0,0,18.0,1.4012985e-45,1.0382951,2.0782065,17.999815,186.41048,-11.482283
239.2643,0.4503876,9.692482,0.0,0,18.0,1.4012985e-45,1.0388998,2.0282464,17.999367,181.73865,-11.481583
240.4643,0.45498827,9.6953163,0.0,0,18.0,1.4012985e-45,1.0393927,2.0463445,18.000582,177.37895,-11.48156
241.6643,0.45988417,9.6982012,0.0,0,18.0,1.4012985e-45,1.0400575,2.0653534,17.999582,173.01453,-11.48179
242.8643,0.4530603,9.7014875,0.0,0,18.0,1.4012985e-45,1.0406289,2.0337389,18.000101,168.76544,-11.481615
244.0643,0.46171072,9.7045879,0.0,0,18.0,1.4012985e-45,1.0412499,2.0714672,17.999441,164.71622,-11.481486
245.2643,0.46150801,9.7078075,0.0,0,18.0,1.4012985e-45,1.0417911,2.0713768,17.999504,160.79742,-11.48178
246.4643,0.46666121,9.7105083,0.0,0,18.0,1.4012985e-45,1.0422734,2.0933216,18.000359,157.00858,-11.481616
247.6643,0.4574706,9.7129116,0.0,0,18.0,1.4012985e-45,1.0428399,2.0511138,17.998989,153.31841,-11.482179
248.8643,0.4601852,9.7154408,0.0,0,18.0,1.4012985e-45,1.0432552,2.0677552,18.000404,149.73813,-11.481843
250.0643,0.4581728,9.7180452,0.0,0,18.0,1.4012985e-45,1.0437787,2.0567427,18.001055,146.20988,-11.481897
251.2643,0.46047279,9.7202311,0.0,0,18.0,1.4012985e-45,1.0441155,2.065789,18.000456,142.7001,-11.482006
252.4643,0.46598518,9.7235441,0.0,0,18.0,1.4012985e-45,1.0447322,2.0913947,17.999321,139.32489,-11.481985
253.6643,0.46486983,9.7253666,0.0,0,18.0,1.4012985e-45,1.0452206,2.0872388,18.000368,136.06534,-11.481725
254.8643,0.46897975,9.7277908,0.0,0,18.0,1.4012985e-45,1.0456045,2.1036279,18.000301,132.88152,-11.481712
255.8643,0.46483183,9.7298565,0.0,0,18.0,1.4012985e-45,1.0459768,2.0785911,17.998852,130.29245,-11.481666