File: examples/dan-msc-case-studies/CS3/data/01 raw data/baron_test_068.csv
Time(sec),Force(kN),Jaw(mm),PowAngle(deg),Power(W),Pram,PTemp,Strain,Stress(MPa),Stroke(mm),TC1(C),wedge(mm)
0.0,0.91077042,0.28497121,0.0,0,10.594783,0.00076406932,0.019185696,11.380688,10.594667,24.594913,-9.1129675
2.1,0.82916784,0.0024356088,0.0,0,10.594783,6.2159009,0.00019362058,10.557607,10.594734,24.609442,-9.4791098
4.2,0.79921997,0.002579401,0.0,0,10.594783,12.515902,0.00015292982,10.171045,10.594259,24.638483,-9.47645
6.3,0.77722037,0.0024414121,0.0,0,10.594783,18.815908,0.0001806283,9.8924799,10.59488,24.538536,-9.4729052
8.4,0.75993925,0.0023058022,0.0,0,10.594783,25.115904,0.00017732845,9.6786432,10.595,24.475641,-9.4691095
10.5,0.76143771,0.0017296176,32.73156,0,10.594783,31.415911,0.00010235779,9.6977358,10.593322,25.256954,-9.4661045
12.6,0.78370601,-0.0029212025,42.973354,0,10.594783,37.715908,-0.00019600597,9.9822483,10.594274,30.380531,-9.4632483
14.7,0.79578841,-0.010495952,46.053883,0,10.594783,44.015907,-0.00070402486,10.131907,10.594848,39.103512,-9.4594193
16.8,0.81810123,-0.017949661,44.604553,0,10.594783,50.31591,-0.0011991009,10.428893,10.594708,49.175827,-9.4563217
18.9,0.81753379,-0.022343259,41.938251,0,10.594783,56.615925,-0.001512066,10.430523,10.594559,57.640293,-9.4526539
21.0,0.82412338,-0.026996529,40.572514,0,10.594783,62.915924,-0.001798925,10.509822,10.594957,64.114571,-9.4494638
23.1,0.82236689,-0.030497743,41.198147,0,10.594783,69.215927,-0.0020029671,10.491575,10.595374,69.476234,-9.4461594
25.2,0.83025116,-0.035073381,41.802975,0,10.594783,75.515938,-0.0023525986,10.603346,10.59452,75.078804,-9.4426794
27.3,0.83703279,-0.03959797,42.972111,0,10.594783,81.81591,-0.0026268633,10.686454,10.594044,81.070358,-9.4390507
29.4,0.82839644,-0.04492452,43.527828,0,10.594783,88.115921,-0.0029690154,10.574971,10.594984,87.351425,-9.4353895
31.5,0.84870857,-0.049728036,44.077145,0,10.594783,94.415932,-0.0033211326,10.851373,10.594655,93.847664,-9.4321089
33.6,0.85445929,-0.054245345,44.166973,0,10.594783,100.71593,-0.0036183661,10.929777,10.595022,100.33181,-9.4289627
35.7,0.85789222,-0.060061809,44.360901,0,10.594783,107.01595,-0.0039906264,10.967029,10.594943,106.7914,-9.4250965
37.8,0.85936666,-0.063802071,44.604488,0,10.594783,113.31593,-0.0042232242,10.989356,10.594421,113.11681,-9.4216747
39.9,0.86678022,-0.068623886,45.029114,0,10.594783,119.61593,-0.0045870957,11.078354,10.594657,119.26646,-9.4177341
42.0,0.87022227,-0.073506624,45.615231,0,10.594783,125.91592,-0.0048786597,11.122464,10.595218,125.33057,-9.4146347
44.1,0.86647403,-0.079726167,46.109619,0,10.594783,132.21596,-0.0052731521,11.09447,10.594898,131.62506,-9.4114971
46.2,0.87956148,-0.084293507,46.581272,0,10.594783,138.51593,-0.0056210901,11.261281,10.595186,138.01434,-9.4079523
48.3,0.89291185,-0.090146467,46.582027,0,10.594783,144.81595,-0.0059887576,11.450691,10.594276,144.41374,-9.4046144
50.4,0.87946355,-0.095588669,47.05444,0,10.594783,151.11592,-0.0063439696,11.270953,10.594951,150.61404,-9.400712
52.5,0.89189678,-0.10277741,47.504883,0,10.594783,157.41592,-0.0068287253,11.428572,10.594154,156.9088,-9.3974771
54.6,0.89271373,-0.10703122,47.955318,0,10.594783,163.71596,-0.0071344278,11.449331,10.594263,163.381,-9.3944197
56.7,0.89881492,-0.11338843,47.954754,0,10.594783,170.01595,-0.0075283502,11.530125,10.595059,169.83826,-9.3909092
58.8,0.89834082,-0.118907,47.955318,0,10.594783,176.31595,-0.0078737633,11.542893,10.594683,176.13326,-9.3876734
60.9,0.90040559,-0.12419355,48.375084,0,10.594783,182.61594,-0.0082622664,11.569691,10.594771,182.31607,-9.3838654
63.0,0.90152919,-0.12984039,48.384109,0,10.594783,188.91592,-0.0086156903,11.573636,10.59455,188.54196,-9.3803406
65.1,0.9048478,-0.13605815,48.812252,0,10.594783,195.21596,-0.0090202084,11.620847,10.594175,194.854,-9.3772087
67.2,0.90662873,-0.14333569,48.829739,0,10.594783,201.51595,-0.0095137963,11.660903,10.595134,201.29991,-9.3742294
69.3,0.90042979,-0.14788172,49.229733,0,10.594783,207.81596,-0.0098241903,11.590947,10.594179,207.4792,-9.3708162
71.4,0.91352642,-0.15302439,49.636227,0,10.594783,214.11595,-0.010153571,11.754802,10.593698,213.69664,-9.3668184
73.5,0.89736837,-0.15973522,49.636227,0,10.594783,220.41594,-0.010584224,11.558747,10.595247,220.14749,-9.3631296
75.6,0.91842461,-0.16458081,49.636227,0,10.594783,226.71597,-0.010930503,11.823846,10.594562,226.56406,-9.3600607
77.7,0.91497713,-0.17217766,50.042721,0,10.594783,233.01596,-0.011412781,11.784857,10.595055,232.67509,-9.3568134
79.8,0.90930682,-0.1774148,50.054325,0,10.594783,239.31596,-0.011731205,11.705548,10.594346,239.05205,-9.3533363
81.9,0.91625077,-0.18326525,50.044937,0,10.594783,245.61595,-0.012157839,11.80287,10.594963,245.57039,-9.3498306
84.0,0.92101038,-0.19076602,50.042728,0,10.594783,251.91597,-0.012629975,11.876482,10.594522,252.01823,-9.3464193
86.1,0.91874582,-0.19636725,50.296757,0,10.594783,258.21628,-0.01300166,11.881481,10.595209,258.03409,-9.3427963
88.2,0.92178124,-0.20204194,50.384239,0,10.594783,264.51596,-0.013380539,11.887502,10.594501,264.40131,-9.3389196
90.3,0.91983598,-0.2079159,50.262333,0,10.594783,270.81595,-0.013785059,11.861316,10.594539,270.82419,-9.335783
92.4,0.92344993,-0.2141176,50.82275,0,10.594783,277.11597,-0.01416632,11.925114,10.594992,276.60352,-9.3325357
94.5,0.92964488,-0.22029185,51.370918,0,10.594783,283.41599,-0.014559758,12.004525,10.594826,282.68051,-9.3291931
96.6,0.91965252,-0.22675982,51.502048,0,10.594783,289.716,-0.015032838,11.885525,10.596805,289.40106,-9.3254766
98.7,0.9179188,-0.23358978,51.196293,0,10.594783,296.01596,-0.015447491,11.870867,10.595063,296.00723,-9.3214855
100.8,0.93639427,-0.23941712,51.196293,0,10.594783,302.31595,-0.015807942,12.113109,10.594516,302.35193,-9.3182831
102.9,0.92905074,-0.24602228,51.566456,0,10.594783,308.61597,-0.016289042,12.009344,10.594052,308.3989,-9.314702
105.0,0.92752707,-0.25253645,51.56982,0,10.594783,314.91595,-0.016685344,12.008289,10.593342,314.72421,-9.3117085
107.1,0.92877042,-0.25853881,51.588017,0,10.594783,321.216,-0.017064776,12.035317,10.594793,321.00595,-9.3083344
109.2,0.94255084,-0.26616269,51.932369,0,10.594783,327.51596,-0.017594717,12.223026,10.594507,327.35922,-9.3049212
111.3,0.92539233,-0.2718865,51.932369,0,10.594783,333.81598,-0.01796449,11.999139,10.595671,333.63959,-9.3010578
113.4,0.93612701,-0.27810776,52.283928,0,10.594783,340.11597,-0.018369889,12.148854,10.594429,339.83405,-9.2972803
115.5,0.94344342,-0.28581327,52.285603,0,10.594783,346.41595,-0.018865881,12.228508,10.594581,346.05801,-9.2937918
117.6,0.9321686,-0.29202062,52.284111,0,10.594783,352.716,-0.019294381,12.103109,10.594487,352.56149,-9.2907715
119.7,0.94026166,-0.29817665,52.283939,0,10.594783,359.01599,-0.019684767,12.224326,10.594298,359.18555,-9.2877474
121.8,0.92944491,-0.30524024,51.932377,0,10.594783,365.31598,-0.020138841,12.062987,10.595251,365.66226,-9.2841482
123.9,0.93702513,-0.31163031,52.283722,0,10.594783,371.616,-0.020576954,12.189362,10.595056,371.48972,-9.2807407
126.0,0.95281249,-0.31881782,52.635494,0,10.594783,377.91602,-0.021044506,12.393021,10.594132,377.50385,-9.2767887
128.1,0.93385363,-0.32633588,52.97607,0,10.594783,384.21603,-0.021511635,12.151137,10.594616,383.66171,-9.2730494
130.2,0.93490088,-0.33320415,53.316616,0,10.594783,390.51599,-0.021994155,12.175096,10.594906,389.96472,-9.2698374
132.3,0.95429248,-0.3409107,53.228016,0,10.594783,396.81598,-0.022469409,12.424405,10.595096,396.72894,-9.2664442
134.4,0.06094135,-0.3587411,51.932537,0,10.594783,399.99893,-0.023625363,0.77026165,10.594374,401.32135,-9.2650003
136.5,0.043752965,-0.35772446,51.932377,0,10.594783,399.99893,-0.023591509,0.57259279,10.59462,400.54993,-9.265173
138.6,0.053917285,-0.3572025,51.980648,0,10.594783,399.99893,-0.02352149,0.70519692,10.594242,400.07724,-9.2650633
140.7,0.050566137,-0.35756218,52.285709,0,10.594783,399.99893,-0.023533249,0.65770596,10.593736,399.75034,-9.2651396
142.8,0.053449482,-0.35757211,52.635494,0,10.594783,399.99893,-0.023582047,0.69080573,10.59385,399.58835,-9.2644463
144.9,0.077364512,-0.35825673,52.668037,0,10.594783,399.99893,-0.023595354,1.0154827,10.596067,399.78214,-9.2648478
147.0,0.066297352,-0.35914037,52.635502,0,10.594783,399.99893,-0.023635963,0.84793824,10.596254,400.04517,-9.2643547
149.1,0.066717386,-0.36008641,52.402374,0,10.594783,399.99893,-0.02374964,0.86502606,10.594158,400.25983,-9.264369
151.2,0.072362274,-0.3604553,51.932377,0,10.594783,399.99893,-0.023739329,0.94785619,10.594998,400.67062,-9.2645826
153.3,0.080437437,-0.36116394,51.569828,0,10.594783,399.99893,-0.023772612,1.047783,10.594922,400.63901,-9.2650261
155.4,0.069088876,-0.36174253,51.325188,0,10.594783,399.99893,-0.023836968,0.90455294,10.594913,400.45798,-9.2651043
157.5,0.079312071,-0.3625707,51.417568,0,10.594783,399.99893,-0.02387318,1.0305295,10.595158,400.09946,-9.26472
159.6,0.066032223,-0.36316177,51.56982,0,10.594783,399.99893,-0.023896912,0.86941016,10.595195,399.85248,-9.2644625
161.7,0.069015428,-0.36348975,51.569828,0,10.594783,399.99893,-0.023956494,0.9149276,10.595117,399.94611,-9.2642965
163.8,0.065764271,-0.36447352,51.569828,0,10.594783,399.99893,-0.024004735,0.85229093,10.595051,399.99643,-9.2643423
165.9,0.079718575,-0.36520573,51.570927,0,10.594783,399.99893,-0.024036193,1.0505033,10.594725,399.98477,-9.2641592
168.0,0.071827583,-0.36605969,51.569828,0,10.594783,399.99893,-0.024116099,0.92717415,10.594958,400.01816,-9.2646227
170.1,0.078107499,-0.36623824,51.569828,0,10.594783,399.99893,-0.024117993,1.0292654,10.595132,400.02527,-9.2651768
172.2,0.064327031,-0.36773795,51.569828,0,10.594783,399.99893,-0.024213579,0.83620125,10.595303,400.04709,-9.2652426
174.3,0.072837427,-0.37007648,51.56982,0,10.594783,399.99893,-0.02437561,0.95242858,10.594666,400.13879,-9.2648077
176.4,0.062695414,-0.3683736,51.56982,0,10.594783,399.99893,-0.024269296,0.80990022,10.594666,399.99963,-9.2643595
178.4633,0.085251242,-0.0016444678,51.874607,0,10.594783,399.99893,-7.9867132e-05,1.0795822,10.594959,399.76709,-9.2639999
178.6172,0.20143707,0.0073732045,42.773926,0,10.5948,1.8726595e-23,0.00043962346,2.5911925,10.593399,399.73486,-9.26336
178.6214,0.22367455,0.0070742904,20.918621,0,10.5948,0.0,0.00035964066,2.7459879,10.592544,399.74753,-9.2635117
178.6256,0.21641557,0.0067522167,0.0,0,10.5948,0.0,0.00063714362,2.7968478,10.594684,399.75909,-9.264658
178.6298,0.21031016,0.0088965558,0.0,0,10.5948,0.0,0.00051755004,2.7228911,10.595316,399.74643,-9.26476
178.634,0.21391557,0.012839871,0.0,0,10.5948,0.0,0.00065962184,2.6930366,10.594769,399.73376,-9.2638855
178.6382,0.20405982,0.0077155423,0.0,0,10.5948,0.0,0.00073400239,2.5462811,10.594591,399.7211,-9.2631578
178.6424,0.20537804,0.0064911591,0.0,0,10.5948,0.0,0.00037128504,2.7281466,10.596344,399.70844,-9.2646923
178.6466,0.21269241,0.009712033,0.0,0,10.5948,0.0,0.00051731599,2.6213291,10.596933,399.69577,-9.2647448
178.6508,0.21305944,0.0076780673,0.0,0,10.5948,0.0,0.00071308954,2.6258092,10.595344,399.68311,-9.2631845
178.655,0.22128618,0.0097238338,0.0,0,10.5948,0.0,0.00057805981,2.7700942,10.598849,399.67044,-9.2640591
178.6592,0.23079734,0.013211082,0.0,0,10.5948,0.0,0.00066272035,2.9100208,10.59306,399.6925,-9.2631998
178.6634,0.23117295,0.010486799,0.0,0,10.5948,0.0,0.00091501797,2.9117727,10.596677,399.71783,-9.2643185
178.6676,0.22351028,0.0072517488,0.0,0,10.533863,0.0,0.00046702413,2.8639193,10.594489,399.75,-9.2638073
178.6718,0.21626137,0.010981337,0.0,0,10.470864,0.0,0.00061251043,2.7595627,10.588122,399.78799,-9.2647038
178.676,0.22765191,0.0088800127,0.0,0,10.407864,0.0,0.00075643737,2.7213612,10.555882,399.81982,-9.264061
178.6802,0.22122599,0.0097166682,0.0,0,10.344864,0.0,0.00064985396,2.8904459,10.489095,399.81982,-9.2648268
178.6844,0.22072518,0.01490662,0.0,0,10.281863,0.0,0.00076139864,2.7665195,10.388828,399.81982,-9.2642021
178.6886,0.23411982,0.01066824,0.0,0,10.218863,0.0,0.00088002614,3.01877,10.301164,399.79993,-9.2631426
178.6928,0.23418283,0.0078739226,0.0,0,10.155864,0.0,0.00055744074,3.0077364,10.231668,399.7746,-9.2638912
178.697,0.23714158,0.011088318,0.0,0,10.092864,0.0,0.00060586596,3.0340893,10.184895,399.74927,-9.2631474
178.7012,0.2263435,0.0097275293,0.0,0,10.029863,0.0,0.00082142587,3.0307293,10.130267,399.72394,-9.2634516
178.7054,0.52142954,0.015661065,0.0,0,9.9668636,0.0,0.0010455345,6.516582,10.066481,399.7269,-9.264308
178.7096,3.042392,0.043724593,0.0,0,9.9038639,0.0,0.00263593,38.2117,10.010385,400.55029,-9.262619
178.7138,4.7337213,0.081446141,0.0,0,9.8408632,0.0,0.0056386134,59.857582,9.9488182,401.37366,-9.2600756
178.718,5.2813292,0.15268183,0.0,0,9.7778635,0.0,0.010166703,66.462852,9.8712091,402.33853,-9.2596426
178.7222,5.5406899,0.22481138,0.0,0,9.7148628,0.0,0.014849842,69.51403,9.8019371,403.37729,-9.2608223
178.7264,5.6645746,0.28514233,0.0,0,9.6518641,0.0,0.019295834,70.777451,9.7309694,404.11349,-9.2613649
178.7306,5.7319822,0.34536391,0.0,0,9.5888634,0.0,0.023288514,71.31488,9.6717749,404.0755,-9.2593727
178.7348,5.809618,0.41044661,0.0,0,9.5258636,0.0,0.027413977,71.985634,9.6080017,404.03751,-9.2594461
178.739,5.8869224,0.46552563,0.0,0,9.4633293,0.0,0.031706508,72.501343,9.5498505,403.79318,-9.2600555
178.7432,5.9788146,0.52753353,0.0,0,9.4018736,0.0,0.035757065,73.372047,9.4804573,403.52716,-9.2616339
178.7474,6.0410705,0.59269214,0.0,0,9.3404198,0.0,0.040125672,73.787415,9.4159813,404.1048,-9.2607422
178.7516,6.0793557,0.6526683,0.0,0,9.278965,0.0,0.044563625,73.975258,9.3528843,405.43488,-9.2603874
178.7558,6.1096106,0.71462941,0.0,0,9.2175112,0.0,0.04885697,74.086182,9.2908049,406.82095,-9.2608461
178.76,6.1456952,0.77795357,0.0,0,9.1560564,0.0,0.052920956,74.170769,9.2268829,408.51837,-9.261342
178.7642,6.1608319,0.8364352,0.0,0,9.0946016,0.0,0.057550956,74.234238,9.1677265,410.21582,-9.2611256
178.7684,6.2118897,0.89406496,0.0,0,9.0331469,0.0,0.0614652,74.372055,9.102354,411.08728,-9.2615204
178.7726,6.2616105,0.96132153,0.0,0,8.971693,0.0,0.066024624,74.607758,9.0385761,411.72061,-9.2626181
178.7768,6.2950788,1.0201776,0.0,0,8.9102392,0.0,0.070516609,74.651428,8.9750385,412.13101,-9.2598877
178.781,6.3476005,1.0800643,0.0,0,8.8487844,0.0,0.074745223,74.96434,8.915266,412.20703,-9.2607861
178.7852,6.3890047,1.1463639,0.0,0,8.7873297,0.0,0.079085179,75.134567,8.8503771,412.26733,-9.2615976
178.7894,6.4006948,1.2036599,0.0,0,8.7270651,0.0,0.083806776,74.93367,8.7918062,411.68469,-9.2621517
178.7936,6.4225302,1.259974,0.0,0,8.6686182,0.0,0.087808512,74.820885,8.7292929,411.10205,-9.2615404
178.7978,6.4405522,1.3210179,0.0,0,8.6101713,0.0,0.091985345,74.872414,8.667942,410.4209,-9.2620077
178.802,6.4698148,1.3820153,0.0,0,8.5517235,0.0,0.096632257,74.775375,8.6087856,409.68619,-9.2606077
178.8062,6.5212612,1.4399278,0.0,0,8.4932766,0.0,0.1010569,74.958832,8.5481615,409.1062,-9.2616224
178.8104,6.5670934,1.5031431,0.0,0,8.4348297,0.0,0.1051751,75.274841,8.4897089,408.94153,-9.2609587
178.8146,6.5767665,1.5588069,0.0,0,8.3763819,0.0,0.10983622,74.997101,8.4305305,408.77686,-9.2606974
178.8188,6.5994015,1.6095787,0.0,0,8.317935,0.0,0.11362032,75.025253,8.3736181,409.03177,-9.2614851
178.823,6.606411,1.6687877,0.0,0,8.2594881,0.0,0.11770663,74.920944,8.3192959,409.33578,-9.2621841
178.8272,6.6575146,1.7253643,0.0,0,8.2010412,0.0,0.12228147,75.092995,8.2574883,409.61349,-9.2618704
178.8314,6.6921601,1.7823174,0.0,0,8.1425943,0.0,0.12662661,75.037781,8.196085,409.86685,-9.2603111
178.8356,6.7329383,1.8475685,0.0,0,8.0841465,0.0,0.13103366,75.17955,8.1374416,410.12744,-9.2630043
178.8398,6.781311,1.9029692,0.0,0,8.0270939,0.0,0.13576831,75.376923,8.0793056,410.43146,-9.2604437
178.844,6.8231792,1.9580623,0.0,0,7.9714851,0.0,0.14003161,75.476654,8.0193586,410.7355,-9.259757
178.8482,6.8199124,2.0157936,0.0,0,7.9158773,0.0,0.14405873,75.247765,7.9619694,411.07837,-9.2604284
178.8524,6.8287382,2.0690179,0.0,0,7.8602695,0.0,0.14848526,74.976585,7.9082804,411.43304,-9.2607689
178.8566,6.8544736,2.1237931,0.0,0,7.8046613,0.0,0.15278956,74.880699,7.8509269,411.57999,-9.2616863
178.8608,6.886065,2.184521,0.0,0,7.7490535,0.0,0.15690476,74.91449,7.7907104,411.40265,-9.2630692
178.865,6.9170599,2.2359221,0.0,0,7.6934457,0.0,0.16157489,74.902122,7.7371821,411.20883,-9.2615891
178.8692,6.9669442,2.2869434,0.0,0,7.6378374,0.0,0.16563348,75.167442,7.6835866,409.87875,-9.2610292
178.8734,7.0087786,2.3462002,0.0,0,7.5822296,0.0,0.16979992,75.344246,7.6259103,408.54868,-9.2614393
178.8776,7.0515881,2.4006956,0.0,0,7.5266213,0.0,0.17445834,75.363586,7.5716252,407.85715,-9.2604847
178.8818,7.0833368,2.4565239,0.0,0,7.4710135,0.0,0.17895208,75.351646,7.5112205,407.5278,-9.2616873
178.886,7.0943685,2.5185115,0.0,0,7.4154053,0.0,0.18336874,75.29953,7.455339,407.47049,-9.2606897
178.8902,7.0893931,2.5715215,0.0,0,7.361393,0.0,0.18810733,74.852348,7.3992414,408.17987,-9.2613163
178.8944,7.1084476,2.6179347,0.0,0,7.308507,0.0,0.19203468,74.699402,7.348371,408.88925,-9.2622442
178.8986,7.1614356,2.6751304,0.0,0,7.2556205,0.0,0.19609064,75.042015,7.2942128,408.67859,-9.2623959
178.9028,7.2184896,2.7288651,0.0,0,7.202734,0.0,0.20085977,75.159149,7.2361135,408.34921,-9.261405
178.907,7.2455883,2.7785652,0.0,0,7.1498475,0.0,0.2050457,75.19593,7.1839218,408.03925,-9.2614708
178.9112,7.2309132,2.8369462,0.0,0,7.096961,0.0,0.20919666,74.695877,7.1355762,407.74789,-9.2607422
178.9154,7.2435079,2.8862388,0.0,0,7.044075,0.0,0.21377982,74.458488,7.080586,407.5275,-9.2615128
178.9196,7.3006959,2.9293368,0.0,0,6.991188,0.0,0.21763225,74.804482,7.0271769,407.76816,-9.2631588
178.9238,7.3335533,2.9905841,0.0,0,6.938302,0.0,0.22204985,74.80304,6.9724259,408.00885,-9.2608318
178.928,7.3722849,3.043309,0.0,0,6.8854156,0.0,0.22672836,74.797707,6.916894,408.38379,-9.2608242
178.9322,7.4203787,3.0901699,0.0,0,6.8325291,0.0,0.23089285,74.985931,6.8665409,408.80182,-9.262001
178.9364,7.4597888,3.1505048,0.0,0,6.7796426,0.0,0.23540901,75.048454,6.8114033,409.24881,-9.2612276
178.9406,7.4859009,3.2037013,0.0,0,6.728508,0.0,0.2402332,75.0084,6.7619505,409.74286,-9.2602425
178.9448,7.5014672,3.2496333,0.0,0,6.6781921,0.0,0.24445733,74.86235,6.7084455,410.23633,-9.2619667
178.949,7.5023651,3.3027725,0.0,0,6.6278758,0.0,0.24843226,74.548454,6.6558471,410.61636,-9.2615032
178.9532,7.5289245,3.3505392,0.0,0,6.5775599,0.0,0.2527658,74.442734,6.6052537,410.99637,-9.2618122
178.9574,7.5401778,3.398284,0.0,0,6.5272441,0.0,0.25716403,74.272675,6.5544858,411.40024,-9.2623205
178.9616,7.6020803,3.4516304,0.0,0,6.4769282,0.0,0.26106146,74.449448,6.5037122,411.81818,-9.2615547
178.9658,7.6612988,3.5031345,0.0,0,6.4266124,0.0,0.26586676,74.778999,6.4568257,412.20096,-9.2629547
178.97,7.7126813,3.547673,0.0,0,6.376296,0.0,0.27019945,74.91317,6.4034171,412.47952,-9.2621899
178.9742,7.7291875,3.603169,0.0,0,6.3259802,0.0,0.27444777,74.757637,6.3509798,412.75812,-9.2611685
178.9784,7.7504125,3.65782,0.0,0,6.2756648,0.0,0.27940625,74.611343,6.2985988,412.80368,-9.262249
178.9826,7.7417836,3.7038174,0.0,0,6.2253485,0.0,0.28381035,74.165253,6.2474642,412.81635,-9.2615986
178.9868,7.7704062,3.7546246,0.0,0,6.1750326,0.0,0.28775588,74.171082,6.2019644,412.62003,-9.2612572
178.991,7.8199425,3.8058012,0.0,0,6.1266279,0.0,0.29245394,74.277252,6.1493292,412.21475,-9.2625217
178.9952,7.8754563,3.8509293,0.0,0,6.0787735,0.0,0.29702383,74.501015,6.1020918,411.67148,-9.2613611
178.9994,7.9165716,3.8980746,0.0,0,6.0309186,0.0,0.30060267,74.537491,6.0487213,410.15152,-9.261445
179.0036,7.9258919,3.9500308,0.0,0,5.9830642,0.0,0.30552828,74.287422,6.0001426,408.63153,-9.2612772
179.0078,7.9395223,3.9929838,0.0,0,5.9352088,0.0,0.30992395,74.164551,5.9544044,407.01675,-9.2604971
179.012,7.9499664,4.0457582,0.0,0,5.8873544,0.0,0.31395265,73.958572,5.9065332,405.37,-9.2616291
179.0162,7.9744539,4.0962195,0.0,0,5.8394995,0.0,0.31874782,73.839264,5.8584628,404.53723,-9.2629995
179.0204,8.0132732,4.1335545,0.0,0,5.7916446,0.0,0.32278821,73.833733,5.8119192,405.08191,-9.2616138
179.0246,8.0988855,4.1867313,0.0,0,5.7437897,0.0,0.3269847,74.354622,5.7646103,405.62662,-9.2604599
179.0288,8.1493959,4.2382264,0.0,0,5.6959348,0.0,0.33191052,74.412033,5.7085786,406.90253,-9.2599373
179.033,8.1685858,4.2835717,0.0,0,5.6480803,0.0,0.33662662,74.263985,5.6604376,408.18192,-9.2621441
179.0372,8.1835804,4.334641,0.0,0,5.600225,0.0,0.34072521,74.147881,5.6143112,408.92807,-9.2620096
179.0414,8.172183,4.3867469,0.0,0,5.5544,0.0,0.34568709,73.64959,5.5660877,409.3461,-9.2609425
179.0456,8.2006292,4.4261427,0.0,0,5.5088716,0.0,0.35007697,73.541328,5.5221848,409.78873,-9.260808
179.0498,8.2203016,4.4714937,0.0,0,5.4633436,0.0,0.35363275,73.503174,5.4725909,410.30811,-9.2608118
179.054,8.2488346,4.5189571,0.0,0,5.4178157,0.0,0.35828063,73.35128,5.4318027,410.82748,-9.262785
179.0582,8.2706957,4.5570955,0.0,0,5.3722878,0.0,0.36250344,73.234726,5.3855696,411.32489,-9.2611074
179.0624,8.3108063,4.6042142,0.0,0,5.3267598,0.0,0.36630172,73.373589,5.3444943,411.81891,-9.2617769
179.0666,8.4207077,4.6548786,0.0,0,5.2812319,0.0,0.37123898,73.962753,5.2994943,412.29407,-9.2616844
179.0708,8.4645958,4.6971717,0.0,0,5.2357039,0.0,0.37604886,74.025024,5.2507124,412.7496,-9.262166
179.075,8.480546,4.7476978,0.0,0,5.1901755,0.0,0.38029313,73.7509,5.1987834,413.20364,-9.2601414
179.0792,8.4612026,4.7964616,0.0,0,5.1446476,0.0,0.3851237,73.31945,5.155169,413.64618,-9.2615738
179.0834,8.5015135,4.8369555,0.0,0,5.0991197,0.0,0.38969618,73.247803,5.1113243,414.08868,-9.2615976
179.0876,8.5376644,4.8826509,0.0,0,5.0535922,0.0,0.39349437,73.344337,5.0659323,414.35388,-9.2609167
179.0918,8.5954561,4.9316607,0.0,0,5.0102167,0.0,0.39820039,73.48848,5.0216622,414.55618,-9.2603798
179.096,8.6333809,4.9694719,0.0,0,4.9669147,0.0,0.40285277,73.509682,4.9772191,414.26837,-9.260293
179.1002,8.6830921,5.0172186,0.0,0,4.9236126,0.0,0.40697268,73.598122,4.9298077,413.11646,-9.2614775
179.1044,8.6491289,5.0662694,0.0,0,4.880311,0.0,0.41187412,72.999809,4.8888683,411.96457,-9.2618971
179.1086,8.6722279,5.1020031,0.0,0,4.8370085,0.0,0.41616857,72.764679,4.8422713,410.2883,-9.2625742
179.1128,8.7370987,5.1482129,0.0,0,4.7937069,0.0,0.4200888,72.993668,4.8031149,408.6044,-9.2619457
179.117,8.7813082,5.1978679,0.0,0,4.7504048,0.0,0.42494625,73.062332,4.7579646,407.49136,-9.2625504
179.1212,8.81499,5.2330303,0.0,0,4.7071028,0.0,0.42958257,73.12175,4.7114935,406.74399,-9.261322
179.1254,8.8417807,5.2747545,0.0,0,4.6638007,0.0,0.43312186,72.999641,4.6728373,406.19168,-9.2615223
179.1296,8.8678484,5.3220439,0.0,0,4.6204991,0.0,0.43787667,72.934166,4.6292024,406.28036,-9.2610855
179.1338,8.8878679,5.3565545,0.0,0,4.5771966,0.0,0.44225368,72.729599,4.5876298,406.36905,-9.2616529
179.138,8.9298468,5.4048367,0.0,0,4.5340271,0.0,0.44656545,72.775978,4.5429721,406.6423,-9.2613544
179.1422,8.9896116,5.4527016,0.0,0,4.4928331,0.0,0.45134297,72.916283,4.5020251,406.94629,-9.2618256
179.1464,9.0767756,5.490653,0.0,0,4.4516392,0.0,0.45631462,73.190956,4.4544821,407.1102,-9.2626648
179.1506,9.0936804,5.5326629,0.0,0,4.4104452,0.0,0.45999235,73.151733,4.4136076,407.12286,-9.2610083
179.1548,9.084095,5.5788336,0.0,0,4.3692517,0.0,0.46480051,72.654449,4.3720946,407.17532,-9.2615242
179.159,9.0767918,5.6108737,0.0,0,4.3280582,0.0,0.4690226,72.281326,4.3344941,407.56802,-9.2616291
179.1632,9.1197386,5.6555719,0.0,0,4.2868648,0.0,0.47306007,72.346542,4.2978978,407.96069,-9.2619038
179.1674,9.1853743,5.7003322,0.0,0,4.2456713,0.0,0.47757211,72.610275,4.2542386,408.57489,-9.2633524
179.1716,9.2421846,5.734304,0.0,0,4.2044773,0.0,0.48230055,72.667374,4.214395,409.27161,-9.2621775
179.1758,9.3775854,5.7770262,0.0,0,4.1632838,0.0,0.48622081,73.385658,4.1709819,409.87012,-9.2603493
179.18,9.456974,5.8289819,0.0,0,4.1220903,0.0,0.49162704,73.665115,4.1217065,410.28815,-9.2608299
179.1842,9.4536076,5.8684387,0.0,0,4.0808969,0.0,0.49688813,73.190697,4.0791941,410.70618,-9.2629547
179.1884,9.4243765,5.9128485,0.0,0,4.0400209,0.0,0.50094771,72.69207,4.0391073,410.62958,-9.2621794
179.1926,9.4288435,5.9538951,0.0,0,4.0008435,0.0,0.50513071,72.402687,4.0004983,410.54089,-9.261734
179.1968,9.4709253,5.9873691,0.0,0,3.9616656,0.0,0.51004821,72.340118,3.9634154,410.23181,-9.2615204
179.201,9.4971046,6.0248489,0.0,0,3.9224882,0.0,0.51353931,72.425072,3.9241064,409.77579,-9.2630301
179.2052,9.5840054,6.0684924,0.0,0,3.8833106,0.0,0.51809579,72.667801,3.8806856,409.30841,-9.2620258
179.2094,9.618926,6.1051121,0.0,0,3.8441329,0.0,0.52298516,72.59787,3.8449476,408.8017,-9.2609129
179.2136,9.6476707,6.143569,0.0,0,3.8049555,0.0,0.52683049,72.497253,3.80846,408.29498,-9.2628269
179.2178,9.7036476,6.1890574,0.0,0,3.7657778,0.0,0.53140646,72.570755,3.7691867,408.05673,-9.262538
179.222,9.7674551,6.221911,0.0,0,3.7266002,0.0,0.53623283,72.775955,3.7313478,407.86673,-9.2615576
179.2262,9.8050919,6.2593803,0.0,0,3.6874225,0.0,0.54012859,72.698242,3.6931651,407.78421,-9.2621603
179.2304,9.8298378,6.3035417,0.0,0,3.6482451,0.0,0.54465628,72.550224,3.650497,407.8222,-9.2628965
179.2346,9.9008379,6.3371911,0.0,0,3.6090674,0.0,0.54943049,72.755463,3.6163342,407.82162,-9.2608471
179.2388,9.9913254,6.3788714,0.0,0,3.5703723,0.0,0.55384266,73.058357,3.5705049,407.45425,-9.2616091
179.243,10.064833,6.4273992,0.0,0,3.5331016,0.0,0.55882418,73.287361,3.5280395,407.08691,-9.2621565
179.2472,10.059967,6.4601202,0.0,0,3.4958305,0.0,0.56379288,72.843521,3.490591,406.9837,-9.2623768
179.2514,10.051039,6.493556,0.0,0,3.4585598,0.0,0.56718618,72.568687,3.4552379,406.9837,-9.2614002
179.2556,10.049263,6.531373,0.0,0,3.4212892,0.0,0.57117069,72.26403,3.4225225,407.22693,-9.2623577
179.2598,10.109023,6.5645213,0.0,0,3.3840184,0.0,0.57599515,72.36013,3.3863328,407.93628,-9.2609453
179.264,10.201555,6.603179,0.0,0,3.3467472,0.0,0.58035606,72.673218,3.3487673,408.64566,-9.2631807
179.2682,10.307781,6.6504526,0.0,0,3.3094764,0.0,0.58503926,73.176384,3.3119988,409.2081,-9.2617407
179.2724,10.375845,6.6834707,0.0,0,3.2722056,0.0,0.59017771,73.214668,3.2685773,409.76547,-9.2619667
179.2766,10.40925,6.7170262,0.0,0,3.234935,0.0,0.59388584,73.190216,3.2306657,410.17322,-9.2616959
179.2808,10.456202,6.7593884,0.0,0,3.1976643,0.0,0.59844339,73.172241,3.1953969,410.47726,-9.2614059
179.285,10.458216,6.793828,0.0,0,3.1603935,0.0,0.60352361,72.835358,3.1591344,410.13794,-9.2631102
179.2892,10.490532,6.8283658,0.0,0,3.1237545,0.0,0.60746735,72.807243,3.1236496,407.43979,-9.2631512
179.2934,10.553546,6.872241,0.0,0,3.0882978,0.0,0.61191732,72.87191,3.0902646,404.74161,-9.2608204
179.2976,10.625739,6.9024158,0.0,0,3.0528414,0.0,0.61690438,72.985573,3.0565081,402.03284,-9.2614613
179.3018,10.705619,6.9368901,0.0,0,3.017385,0.0,0.62095207,73.215912,3.0175538,399.32202,-9.2622805
179.306,10.784418,6.9776325,0.0,0,2.9819286,0.0,0.62523186,73.445892,2.9778903,398.18515,-9.2621975
179.3102,10.808138,7.0112176,0.0,0,2.9464724,0.0,0.6303364,73.278786,2.9471331,398.88187,-9.2615681
179.3144,10.854779,7.0471992,0.0,0,2.9110157,0.0,0.63472396,73.295059,2.9049191,399.57425,-9.261611
179.3186,10.874715,7.0903497,0.0,0,2.8755593,0.0,0.63913673,73.054237,2.8729928,400.22028,-9.2611628
179.3228,10.888231,7.1197171,0.0,0,2.8401029,0.0,0.6440767,72.812576,2.8380208,400.8663,-9.2625303
179.327,10.994843,7.1500106,0.0,0,2.8046467,0.0,0.64773744,73.24662,2.8043025,401.6022,-9.2616291
179.3312,11.115164,7.1892385,0.0,0,2.7691901,0.0,0.65196007,73.713661,2.7677603,402.37494,-9.2614288
179.3354,11.209044,7.2262559,0.0,0,2.7337339,0.0,0.65764707,73.935349,2.7326534,403.4559,-9.2607374
179.3396,11.274752,7.2591996,0.0,0,2.6990449,0.0,0.66183984,74.033165,2.6943595,405.15332,-9.2620411
179.3438,11.272111,7.3044744,0.0,0,2.665319,0.0,0.66648293,73.759773,2.6588318,406.85074,-9.2613754
179.348,11.261206,7.332561,0.0,0,2.631593,0.0,0.67148906,73.238564,2.6273758,407.80859,-9.2631283
179.3522,11.358858,7.3589611,0.0,0,2.5978668,0.0,0.67487973,73.631248,2.5957699,408.73331,-9.2631063
179.3564,11.444343,7.4022155,0.0,0,2.5641408,0.0,0.67941803,73.851822,2.5601594,408.86322,-9.2615175
179.3606,11.500697,7.4318099,0.0,0,2.5304148,0.0,0.68438631,73.791382,2.5241737,408.41986,-9.2619715
179.3648,11.552977,7.463038,0.0,0,2.4966888,0.0,0.68843514,73.865982,2.4907939,408.06729,-9.2620945
179.369,11.607648,7.5040388,0.0,0,2.4629629,0.0,0.69275445,73.951195,2.4560521,408.06729,-9.2617226
179.3732,11.70515,7.53473,0.0,0,2.4292369,0.0,0.69804871,74.197632,2.4250393,408.06729,-9.2618475
179.3774,11.806444,7.5644259,0.0,0,2.3955109,0.0,0.70221794,74.512543,2.3909893,407.62646,-9.2623501
179.3816,11.871786,7.6051512,0.0,0,2.3617849,0.0,0.70659328,74.635658,2.3570001,407.09445,-9.2609844
179.3858,11.906596,7.640296,0.0,0,2.3280587,0.0,0.71222639,74.342636,2.3189297,406.2587,-9.2617903
179.39,11.930456,7.6660466,0.0,0,2.2952197,0.0,0.71597642,74.251938,2.2894361,405.0553,-9.2611027
179.3942,11.994624,7.709374,0.0,0,2.26314,0.0,0.72047144,74.295296,2.2565117,403.93777,-9.2608061
179.3984,12.082949,7.7355986,0.0,0,2.2310605,0.0,0.72540772,74.495674,2.2259827,403.86179,-9.2606039
179.4026,12.168503,7.7635851,0.0,0,2.198981,0.0,0.72940475,74.746422,2.1928,403.78577,-9.2602577
179.4068,12.224071,7.7993574,0.0,0,2.1669014,0.0,0.7331267,74.816216,2.1626534,404.12653,-9.2632885
179.411,12.300597,7.8300781,0.0,0,2.1348217,0.0,0.73835546,74.84816,2.1298993,404.64587,-9.2609196
179.4152,12.367558,7.8592396,0.0,0,2.102742,0.0,0.74278247,74.932465,2.0995955,405.20215,-9.2619839
179.4194,12.48997,7.900527,0.0,0,2.0706627,0.0,0.74712431,75.313332,2.0608053,405.83554,-9.2620468
179.4236,12.587723,7.933033,0.0,0,2.038583,0.0,0.75280309,75.474327,2.0338051,406.4689,-9.2616262
179.4278,12.664514,7.9565883,0.0,0,2.0065033,0.0,0.75658947,75.651146,1.9986763,406.31003,-9.260499
179.432,12.726807,7.9945636,0.0,0,1.9744238,0.0,0.76057792,75.760353,1.9703674,406.10736,-9.2618275
179.4362,12.839328,8.0316544,0.0,0,1.9423442,0.0,0.76679796,75.927071,1.9383321,405.62238,-9.2621861
179.4404,12.87465,8.0570545,0.0,0,1.911255,0.0,0.77099365,75.830376,1.8978963,404.92566,-9.260644
179.4446,12.919518,8.0968189,0.0,0,1.8807379,0.0,0.77508318,75.823425,1.8716916,404.28586,-9.2618351
179.4488,13.01967,8.1303625,0.0,0,1.8502207,0.0,0.78108597,75.860001,1.8400036,403.88049,-9.2622833
179.453,13.053888,8.1513252,0.0,0,1.8197033,0.0,0.78470236,75.826569,1.8065094,403.47513,-9.2613802
179.4572,13.101054,8.1856632,0.0,0,1.7891862,0.0,0.78820926,75.815643,1.7795905,403.57813,-9.2609758
179.4614,13.166203,8.2145348,0.0,0,1.758669,0.0,0.79335839,75.841255,1.7534597,403.79349,-9.2613268
179.4656,13.246163,8.2396355,0.0,0,1.7281518,0.0,0.79758763,75.980171,1.7226931,403.89102,-9.2623911
179.4698,13.353028,8.2752132,0.0,0,1.6976346,0.0,0.80144882,76.272888,1.6937703,403.84036,-9.2621889
179.474,13.491618,8.305459,0.0,0,1.6671174,0.0,0.80680805,76.615051,1.6597831,403.75845,-9.2631464
179.4782,13.612443,8.3307323,0.0,0,1.6366003,0.0,0.81130171,76.985176,1.6308109,403.23911,-9.2624979
179.4824,13.668772,8.3641443,0.0,0,1.6060829,0.0,0.81474644,76.996094,1.6010795,402.71973,-9.2614212
179.4866,13.782603,8.3953772,0.0,0,1.5755658,0.0,0.82037407,77.29541,1.5707099,402.41028,-9.2609949
179.4908,13.908076,8.421669,0.0,0,1.5461327,0.0,0.82507193,77.582405,1.5394449,402.19492,-9.2616396
179.495,13.988373,8.4599457,0.0,0,1.5171022,0.0,0.82925242,77.709633,1.5066478,401.93179,-9.2612886
179.4992,14.039445,8.4916916,0.0,0,1.4880718,0.0,0.83483922,77.547249,1.4773797,401.56445,-9.2616777
179.5034,14.05179,8.5112619,0.0,0,1.4590415,0.0,0.83890665,77.332939,1.4519048,401.19711,-9.2615805
179.5076,14.136123,8.5445986,0.0,0,1.430011,0.0,0.84235501,77.485283,1.4223484,401.1387,-9.2613239
179.5118,14.281167,8.5733738,0.0,0,1.4009807,0.0,0.84740984,77.924248,1.395124,401.10071,-9.262496
179.516,14.413632,8.5999632,0.0,0,1.3719503,0.0,0.85256267,78.175049,1.3636731,401.04135,-9.2610159
179.5202,14.557918,8.6350374,0.0,0,1.3429198,0.0,0.85635829,78.727036,1.3362542,400.96533,-9.2606668
179.5244,14.683517,8.6654701,0.0,0,1.3138895,0.0,0.86179286,78.981133,1.30246,400.88696,-9.2615967
179.5286,14.761494,8.6908045,0.0,0,1.2848592,0.0,0.86703551,78.982399,1.2722358,400.79831,-9.2608662
179.5328,14.777023,8.7196922,0.0,0,1.2558287,0.0,0.86998945,78.864616,1.2440572,400.70963,-9.2607832
179.537,14.828203,8.7498312,0.0,0,1.2267983,0.0,0.87544906,78.655502,1.2149048,400.89783,-9.2616653
179.5412,14.866267,8.7738113,0.0,0,1.1989383,0.0,0.88011271,78.451935,1.1894366,401.15118,-9.2617664
179.5454,14.920423,8.805521,0.0,0,1.1713274,0.0,0.88346761,78.529457,1.1615192,401.45392,-9.2621841
179.5496,15.026221,8.8325863,0.0,0,1.1437165,0.0,0.88842958,78.716629,1.1418508,401.82129,-9.2624865
179.5538,15.217577,8.8484507,0.0,0,1.1161058,0.0,0.89232719,79.365997,1.1129782,402.20386,-9.2615728
179.558,15.399681,8.881916,0.0,0,1.0884949,0.0,0.89615786,80.059601,1.0824276,402.83722,-9.2608824
179.5622,15.468072,8.9104452,0.0,0,1.0608841,0.0,0.9012059,79.976608,1.0561516,403.47058,-9.2623825
179.5664,15.523913,8.9320536,0.0,0,1.0332733,0.0,0.90598786,79.888779,1.0276332,403.91418,-9.2612362
179.5706,15.624834,8.9653397,0.0,0,1.0056624,0.0,0.90965366,80.061722,0.99900931,404.26889,-9.260129
179.5748,15.789366,8.9959068,0.0,0,0.97805178,0.0,0.91494548,80.515953,0.97362667,404.48846,-9.2609901
179.579,15.987963,9.0157232,0.0,0,0.95044094,0.0,0.91999125,81.078903,0.94428998,404.39978,-9.2605124
179.5832,16.126696,9.0475388,0.0,0,0.9228301,0.0,0.92368215,81.499741,0.91323215,404.31113,-9.2604876
179.5874,16.167385,9.076519,0.0,0,0.89521933,0.0,0.92862993,81.347542,0.88834798,403.0079,-9.2617912
179.5916,16.198597,9.0951653,0.0,0,0.86885226,0.0,0.93318617,81.149895,0.8592751,401.61127,-9.2594395
179.5958,16.288767,9.1297255,0.0,0,0.84259379,0.0,0.93742329,81.232903,0.83303154,400.69373,-9.2611589
179.6,16.390284,9.1567764,0.0,0,0.81633544,0.0,0.94211364,81.288391,0.81272799,400.41504,-9.261611
179.6042,16.568409,9.1760244,0.0,0,0.79007703,0.0,0.9473626,81.754639,0.77957797,400.20468,-9.2604761
179.6084,16.743383,9.2042055,0.0,0,0.76381862,0.0,0.95033777,82.393906,0.75759053,401.23074,-9.2617111
179.6126,16.885351,9.2342148,0.0,0,0.73756021,0.0,0.95579505,82.639275,0.73044908,402.25681,-9.2618608
179.6168,16.979017,9.2552538,0.0,0,0.7113018,0.0,0.96085155,82.698631,0.70167428,402.82031,-9.2608995
179.621,17.038177,9.2863989,0.0,0,0.68504345,0.0,0.96446139,82.705223,0.67784274,403.16235,-9.2600145
179.6252,17.100302,9.3133574,0.0,0,0.65878505,0.0,0.96920878,82.602722,0.64779675,403.56897,-9.2606506
179.6294,17.223427,9.3328419,0.0,0,0.63252664,0.0,0.97463876,82.769348,0.62782329,404.12634,-9.2611103
179.6336,17.432629,9.3559084,0.0,0,0.60626823,0.0,0.97697037,83.534538,0.59855729,404.68372,-9.2605944
179.6378,17.615433,9.3909292,0.0,0,0.58003461,0.0,0.98293298,83.899818,0.57225078,404.60916,-9.2610474
179.642,17.77655,9.4102345,0.0,0,0.55503869,0.0,0.98807323,84.243729,0.54527491,404.48248,-9.2615385
179.6462,17.649229,9.4353418,0.0,0,0.53004867,0.0,0.99111325,83.535667,0.52080631,403.67599,-9.2615633
179.6504,16.500971,9.4501657,0.0,0,0.50505865,0.0,0.99322361,77.829628,0.50391936,402.30789,-9.2617893
179.6546,15.929414,9.4476156,0.0,0,0.48006868,0.0,0.99507004,75.005882,0.49146488,401.10703,-9.2618656
179.6588,15.550052,9.4563017,0.0,0,0.45507869,0.0,0.99492925,73.220871,0.47763896,400.71436,-9.2637596
179.663,15.247521,9.4628811,0.0,0,0.4300887,0.0,0.99586201,71.722702,0.45927438,400.32166,-9.2635221
179.6672,14.850775,9.4594078,0.0,0,0.40509868,0.0,0.99704117,69.777161,0.44603717,401.27881,-9.2634354
179.6714,14.384367,9.4661808,0.0,0,0.38010868,0.0,0.99669909,67.595879,0.43943933,402.58356,-9.2633066
179.6756,14.017069,9.470685,0.0,0,0.35511869,0.0,0.99725181,65.845009,0.43298399,403.66534,-9.2660122
179.6798,13.783751,9.4652557,0.0,0,0.3301287,0.0,0.99810565,64.686157,0.42372698,404.43808,-9.2633877
179.684,13.684181,9.4656773,0.0,0,0.30513871,0.0,0.996939,64.297928,0.40697157,405.19397,-9.2647724
179.6882,13.758749,9.4730492,0.0,0,0.28028375,0.0,0.99769974,64.565567,0.39189357,405.57397,-9.2637501
179.6924,14.021086,9.4696169,0.0,0,0.25652012,0.0,0.99888146,65.720238,0.35488254,405.95401,-9.2638683
179.6966,14.186324,9.4769497,0.0,0,0.23275654,0.0,0.99891239,66.50705,0.32330018,406.31714,-9.2629833
179.7008,14.281954,9.487462,0.0,0,0.20899297,0.0,0.99989671,66.86377,0.28667095,406.67184,-9.2636881
179.705,14.308665,9.4804649,0.0,0,0.18522938,0.0,1.0007765,66.977791,0.25747678,407.01181,-9.2629938
179.7092,14.275242,9.4826126,0.0,0,0.16146578,0.0,0.99992484,66.883835,0.23319812,407.31583,-9.262392
179.7134,14.226545,9.4907389,0.0,0,0.13770218,0.0,1.0008694,66.593315,0.20926309,407.61984,-9.2631531
179.7176,14.17246,9.4860697,0.0,0,0.11393856,0.0,1.001846,66.305275,0.18362808,407.83121,-9.2645731
179.7218,14.107902,9.4919109,0.0,0,0.090174966,0.0,1.0016739,65.983185,0.16476977,408.03387,-9.2632847
179.726,14.03323,9.5013819,0.0,0,0.066411361,0.0,1.0025541,65.550179,0.14054067,408.15475,-9.2635565
179.7302,13.959563,9.4969168,0.0,0,0.04264776,0.0,1.0037211,65.177612,0.12128533,408.20544,-9.2636185
179.7344,13.910454,9.4965887,0.0,0,0.018884161,0.0,1.0026048,64.972748,0.1021412,408.26636,-9.2618313
179.7386,13.845955,9.5024586,0.0,0,-0.0047604311,0.0,1.0031242,64.646698,0.084115945,408.38037,-9.2609282
179.7428,13.752821,9.4987421,0.0,0,-0.027944429,0.0,1.0041451,64.159149,0.065151714,408.49435,-9.2636776
179.747,13.650911,9.5010242,0.0,0,-0.051128428,0.0,1.0034015,63.754951,0.052540347,408.67804,-9.2630978
179.7512,13.523582,9.5102749,0.0,0,-0.074312426,0.0,1.0039513,63.141884,0.040690321,408.88074,-9.2628231
179.7554,13.420848,9.5054455,0.0,0,-0.097496428,0.0,1.0054725,62.516304,0.025875861,409.0575,-9.2634773
179.7596,13.300737,9.5048695,0.0,0,0.20877612,400.0,1.0042493,62.038982,0.018465195,409.19681,-9.2633772
179.7638,13.07091,9.5096951,0.0,0,0.96941334,400.0,1.0042508,61.007587,0.0091175567,409.33826,-9.2635117
179.768,10.347226,9.4989491,0.0,0,1.7300496,400.0,1.004107,48.475365,0.13500385,409.54095,-9.2646828
179.7722,5.6541281,9.4767094,0.0,0,2.4906867,400.0,0.99923325,26.791279,0.39130127,409.74362,-9.2674055
179.7764,-0.17460437,9.3968334,0.0,0,3.2513232,400.0,0.98358834,-0.98428625,1.13562,409.97128,-9.274229
179.7806,0.44472858,9.4600859,0.0,0,4.01196,400.0,0.99667406,1.8101528,2.4343154,410.21194,-9.2726288
179.7848,0.50045967,9.4604988,0.0,0,4.7725964,400.0,0.99637562,2.4721344,3.3752859,410.42059,-9.272171
179.789,0.30830306,9.464159,0.0,0,5.5332332,400.0,0.99606228,1.4298395,4.1092386,410.54727,-9.2704077
179.7932,0.3538751,9.4633303,0.0,0,6.2938709,400.0,0.99753231,1.6678087,4.8228269,410.67398,-9.2683372
179.7974,0.39788222,9.4606657,0.0,0,7.0545073,400.0,0.99635673,1.903574,5.5470915,410.80063,-9.2673531
179.8016,0.34647942,9.4702711,0.0,0,7.8151441,400.0,0.99672997,1.6324043,6.3097892,410.92731,-9.266531
179.8058,0.35728106,9.4603119,0.0,0,8.5757818,400.0,0.99680609,1.6673911,7.0965791,411.02719,-9.2669935
179.81,0.3433927,9.4587021,0.0,0,9.3364182,400.0,0.99601895,1.6061293,7.8984318,411.10318,-9.2666788
179.8142,0.29607099,9.4631376,0.0,0,10.097054,400.0,0.99575192,1.4087186,8.6911097,411.16953,-9.2664347
179.8184,0.34223497,9.4592171,0.0,0,10.857692,400.0,0.99669379,1.5851719,9.4707384,411.18222,-9.2655573
179.8226,0.31956896,9.4605017,0.0,0,11.618328,400.0,0.99629402,1.5023141,10.242873,411.19489,-9.2662573
179.8268,0.30054221,9.4650469,0.0,0,12.378965,400.0,0.99579489,1.3967583,11.003863,411.2764,-9.2653875
179.831,0.30221084,9.4636917,0.0,0,13.139603,400.0,0.9975009,1.411958,11.755738,411.37772,-9.2659798
179.8352,0.23996319,9.4595032,0.0,0,13.90024,400.0,0.99626213,1.1630355,12.494609,411.46893,-9.2641516
179.8394,0.24795415,9.4618979,0.0,0,14.660877,400.0,0.99549997,1.1829177,13.233488,411.54495,-9.2648945
179.8436,0.27585635,9.4577103,0.0,0,15.421513,400.0,0.99628443,1.2569344,13.997435,411.61975,-9.2646608
179.8478,0.2211529,9.4560204,0.0,0,16.18215,400.0,0.99556792,1.0198152,14.769464,411.64508,-9.2640629
179.852,0.27478945,9.4669743,0.0,0,16.942787,400.0,0.99600375,1.2169837,15.544817,411.67041,-9.2645836
179.8562,0.2244288,9.4627352,0.0,0,17.703424,400.0,0.99714893,1.0639608,16.306705,411.73676,-9.264143
179.8604,0.19158864,9.4561405,0.0,0,18.0,400.0,0.99577713,0.94833428,17.054667,411.82541,-9.263978
179.8646,0.32105824,9.4619017,0.0,0,18.0,400.0,0.99552107,1.4589939,17.761883,411.89688,-9.2635336
179.8688,0.42539266,9.4585266,0.0,0,18.0,400.0,0.99649137,2.0234227,18.287613,411.92224,-9.2661057
179.873,0.48754686,9.46315,0.0,0,18.0,400.0,0.99706447,2.3096364,18.484707,411.94757,-9.2750797
179.8772,0.46996114,9.4697933,0.0,0,18.0,400.0,0.99650377,2.1796668,18.337749,411.98425,-9.2888584
179.8814,0.520311,9.4656,0.0,0,18.0,400.0,0.99769711,2.3889804,18.144241,412.02225,-9.3112173
179.8856,0.50201035,9.4557867,0.0,0,18.0,400.0,0.99586266,2.3431275,18.058258,412.06683,-9.3442535
179.8898,0.49652043,9.4599485,0.0,0,18.0,400.0,0.99506766,2.3474407,18.063314,412.11752,-9.3796844
179.894,0.50631464,9.4564428,0.0,0,18.0,400.0,0.99584723,2.3685336,18.095367,412.16458,-9.4141817
179.8982,0.47589242,9.4555063,0.0,0,18.0,400.0,0.99573857,2.2690032,18.126337,412.18988,-9.4505062
179.9024,0.47267282,9.4631338,0.0,0,18.0,400.0,0.9951604,2.225831,18.136089,412.21521,-9.4824705
179.9066,0.49307346,9.4595757,0.0,0,18.0,400.0,0.99648422,2.3085837,18.136723,412.24054,-9.512001
179.9108,0.48734811,9.4535351,0.0,0,18.0,400.0,0.99578434,2.309859,18.139847,412.26587,-9.5404463
179.915,0.50409794,9.4579763,0.0,0,18.0,400.0,0.99471152,2.3779044,18.133289,412.27142,-9.5702801
179.9192,0.51925284,9.4569569,0.0,0,18.0,400.0,0.99583113,2.4319251,18.130648,412.24609,-9.6020355
179.9234,0.52114898,9.453619,0.0,0,18.0,400.0,0.9954502,2.4416063,18.12019,412.22076,-9.6338997
179.9276,0.52302194,9.4635935,0.0,0,18.0,400.0,0.9954384,2.443213,18.115549,412.19543,-9.6663122
179.9318,0.49035123,9.4619026,0.0,0,18.0,400.0,0.99667823,2.3440249,18.11562,412.1701,-9.6966801
179.936,0.4890987,9.4561291,0.0,0,18.0,400.0,0.99605286,2.3221388,18.111031,412.17712,-9.7277021
179.9402,0.49294415,9.4576521,0.0,0,18.0,400.0,0.9947331,2.3197768,18.112617,412.20242,-9.7580614
179.9444,0.48434967,9.4573727,0.0,0,18.0,400.0,0.99600154,2.2488284,18.106842,412.22113,-9.7891264
179.9486,0.50914329,9.4527779,0.0,0,18.0,400.0,0.99547601,2.3687587,18.105917,412.22113,-9.8187456
179.9528,0.52794391,9.4619188,0.0,0,18.0,400.0,0.99520952,2.4727604,18.106417,412.22113,-9.8520222
179.957,0.52505457,9.4605455,0.0,0,18.0,400.0,0.99644136,2.4714911,18.10075,412.17627,-9.8832855
179.9612,0.50451446,9.4524851,0.0,0,18.0,400.0,0.99557656,2.3816798,18.102486,412.12558,-9.9140701
179.9654,0.48896205,9.4621134,0.0,0,18.0,400.0,0.99535793,2.2991719,18.102249,412.09427,-9.9461174
179.9696,0.49288458,9.4548807,0.0,0,18.0,400.0,0.99546206,2.3138411,18.099361,412.0816,-9.9771347
179.9738,0.49233526,9.4537678,0.0,0,18.0,400.0,0.99570757,2.3125367,18.09857,412.0723,-10.005676
179.978,0.51814806,9.458066,0.0,0,18.0,400.0,0.99465823,2.4137638,18.097477,412.08496,-10.037409
179.9822,0.54264903,9.4614172,0.0,0,18.0,400.0,0.99642897,2.493732,18.093935,412.09763,-10.06853
179.9864,0.54419166,9.4525023,0.0,0,18.0,400.0,0.99574536,2.5511072,18.094658,412.07193,-10.100125
179.9906,0.52063853,9.4592981,0.0,0,18.0,400.0,0.99494362,2.4798868,18.088743,412.03397,-10.132341
179.9948,0.50805259,9.4584236,0.0,0,18.0,400.0,0.9959023,2.4051399,18.09256,412.01526,-10.162374
179.999,0.5112223,9.4526834,0.0,0,18.0,400.0,0.99551529,2.4119289,18.087179,412.02792,-10.194219
180.0032,0.51715255,9.4623423,0.0,0,18.0,400.0,0.99532551,2.4350524,18.085596,412.04077,-10.224867
180.0074,0.53487396,9.4587955,0.0,0,18.0,400.0,0.99590969,2.4804897,18.085381,412.09146,-10.255955
180.0116,0.54819995,9.4527559,0.0,0,18.0,400.0,0.99575341,2.570029,18.084284,412.14212,-10.285946
180.0158,0.54871202,9.4567156,0.0,0,18.0,400.0,0.99455279,2.5885792,18.082834,412.16095,-10.315611
180.02,0.55088532,9.4578934,0.0,0,18.0,400.0,0.99572784,2.5867097,18.081659,412.16095,-10.349527
180.0242,0.5136537,9.452158,0.0,0,18.0,400.0,0.99558449,2.4477849,18.080791,412.15137,-10.379399
180.0284,0.49834111,9.4581652,0.0,0,18.0,400.0,0.99485457,2.3632388,18.07962,412.11334,-10.409455
180.0326,0.50492162,9.4617128,0.0,0,18.0,400.0,0.99632502,2.4019735,18.080496,412.07532,-10.441062
180.0368,0.51511908,9.4498405,0.0,0,18.0,400.0,0.99534833,2.4288568,18.08098,412.04843,-10.472363
180.041,0.54919684,9.4570761,0.0,0,18.0,400.0,0.99456477,2.5830023,18.081848,412.0231,-10.500628
180.0452,0.55450249,9.4556255,0.0,0,18.0,400.0,0.99538147,2.6254261,18.075705,411.99142,-10.533834
180.0494,0.54335523,9.4544964,0.0,0,18.0,400.0,0.99594206,2.5811753,18.075146,411.95343,-10.565893
180.0536,0.52572095,9.4594908,0.0,0,18.0,400.0,0.99494362,2.4810009,18.074219,411.91385,-10.597043
180.0578,0.52708685,9.4617805,0.0,0,18.0,400.0,0.99616241,2.4813426,18.07268,411.86319,-10.626077
180.062,0.51735568,9.4514561,0.0,0,18.0,400.0,0.99564916,2.4324892,18.068892,411.81253,-10.658635
180.0662,0.52131486,9.4545412,0.0,0,18.0,400.0,0.99446112,2.465302,18.068089,411.79974,-10.689016
180.0704,0.54784721,9.4558325,0.0,0,18.0,400.0,0.99532676,2.5349343,18.066704,411.79974,-10.720005
180.0746,0.56302112,9.4535418,0.0,0,18.0,400.0,0.9958595,2.6246703,18.067909,411.79034,-10.751
180.0788,0.56899619,9.4598618,0.0,0,18.0,400.0,0.9949972,2.6727769,18.068241,411.76498,-10.783644
180.083,0.54275882,9.4601297,0.0,0,18.0,400.0,0.99566799,2.6091626,18.066538,411.73965,-10.812374
180.0872,0.53953779,9.4548845,0.0,0,18.0,400.0,0.99626011,2.5140479,18.063576,411.70172,-10.844739
180.0914,0.52850115,9.4531116,0.0,0,18.0,400.0,0.99405843,2.4943964,18.061739,411.6637,-10.875899
180.0956,0.53329539,9.4569883,0.0,0,18.0,400.0,0.99536133,2.4942288,18.060696,411.61786,-10.905298
180.0998,0.55949885,9.451335,0.0,0,18.0,400.0,0.9955163,2.5525091,18.062662,411.56717,-10.936954
180.104,0.5688976,9.4550285,0.0,0,18.0,400.0,0.99439186,2.6745183,18.060705,411.51959,-10.970109
180.1082,0.567563,9.4606428,0.0,0,18.0,400.0,0.99567348,2.6516283,18.063091,411.4816,-11.001464
180.1124,0.55645829,9.4541378,0.0,0,18.0,400.0,0.99616826,2.6441886,18.057468,411.4436,-11.031506
180.1166,0.54028779,9.4559755,0.0,0,18.0,400.0,0.99455869,2.5651705,18.05448,411.41656,-11.061416
180.1208,0.53450555,9.4585667,0.0,0,18.0,400.0,0.99547613,2.4738059,18.05534,411.39124,-11.093444
180.125,0.5407089,9.4510469,0.0,0,18.0,400.0,0.99535215,2.5474234,18.053404,411.36591,-11.124274
180.1292,0.55121326,9.4557648,0.0,0,18.0,400.0,0.99457818,2.5389097,18.052208,411.34055,-11.154657
180.1334,0.5743314,9.4609356,0.0,0,18.0,400.0,0.99549848,2.683717,18.053762,411.31232,-11.188218
180.1376,0.59109247,9.4508781,0.0,0,18.0,400.0,0.99549836,2.7884393,18.047077,411.26166,-11.21819
180.1418,0.57444292,9.4551029,0.0,0,18.0,400.0,0.99454921,2.717381,18.046432,411.211,-11.250194
180.146,0.5609417,9.4559355,0.0,0,18.0,400.0,0.9948554,2.6661563,18.046339,411.17902,-11.280822
180.1502,0.54712361,9.4507837,0.0,0,18.0,400.0,0.99553037,2.5628855,18.045876,411.15369,-11.311528
180.1544,0.53472394,9.4552002,0.0,0,18.0,400.0,0.99458188,2.5432529,18.049541,411.13751,-11.341064
180.5577,0.50861716,9.456502,0.0,0,18.0,0.0014183699,0.99540704,2.3889227,18.013006,395.01413,-11.482129
182.6577,0.50388271,9.4684038,0.0,0,18.0,3.2689678000000003e-32,0.99755466,2.3643517,18.000097,368.72122,-11.481738
184.7577,0.51399106,9.4780731,0.0,0,18.0,1.4012985e-45,0.99931484,2.4073033,18.000208,349.8653,-11.481779
186.8577,0.52535683,9.4872503,0.0,0,18.0,1.4012985e-45,1.000958,2.4567723,18.000967,333.21359,-11.48098
188.9577,0.54986596,9.4956589,0.0,0,18.0,1.4012985e-45,1.0025243,2.5712097,18.001129,317.85126,-11.48175
191.0577,0.56053764,9.50389,0.0,0,18.0,1.4012985e-45,1.0039996,2.6167781,17.99992,303.21686,-11.481959
193.1577,0.56741279,9.511713,0.0,0,18.0,1.4012985e-45,1.0054106,2.6475878,17.999178,289.54092,-11.481789
195.2577,0.59722275,9.5194044,0.0,0,18.0,1.4012985e-45,1.0068556,2.7778366,18.000132,276.68433,-11.482273
197.3577,0.60180569,9.5271091,0.0,0,18.0,1.4012985e-45,1.0082129,2.7933125,17.999353,264.45029,-11.482005
199.4577,0.62625021,9.534091,0.0,0,18.0,1.4012985e-45,1.0094953,2.8998475,17.999014,252.80324,-11.482136
201.5577,0.62746215,9.5407467,0.0,0,18.0,1.4012985e-45,1.0107656,2.9096744,18.000292,241.99188,-11.481886
203.6577,0.63877016,9.5476656,0.0,0,18.0,1.4012985e-45,1.0119601,2.9614611,18.000072,231.48961,-11.483064
205.7577,0.66038984,9.5538168,0.0,0,18.0,1.4012985e-45,1.0131109,3.053359,17.999882,221.58601,-11.483309
207.8577,0.66117197,9.5600548,0.0,0,18.0,1.4012985e-45,1.0143328,3.0537174,18.000492,212.33127,-11.48305
209.9577,0.67149627,9.5663071,0.0,0,18.0,1.4012985e-45,1.0153702,3.0928929,17.999969,203.28998,-11.481875
212.0577,0.67068827,9.5712452,0.0,0,18.0,1.4012985e-45,1.0163161,3.0846119,17.999914,194.93646,-11.481969
214.1577,0.68714613,9.5773478,0.0,0,18.0,1.4012985e-45,1.0175077,3.1633196,18.000521,186.92686,-11.482098
216.2577,0.69813478,9.5822735,0.0,0,18.0,1.4012985e-45,1.0183215,3.2141032,17.998539,179.24626,-11.482455
218.3577,0.71322137,9.5879593,0.0,0,18.0,1.4012985e-45,1.0194306,3.2780395,18.000244,172.12711,-11.482166
220.4577,0.71906215,9.5919981,0.0,0,18.0,1.4012985e-45,1.0202544,3.292783,17.999866,165.13641,-11.482563
222.5577,0.71599895,9.5970707,0.0,0,18.0,1.4012985e-45,1.0210301,3.280524,18.000519,158.68445,-11.482205
224.6577,0.72735798,9.6016741,0.0,0,18.0,1.4012985e-45,1.0220031,3.3351016,18.000315,152.59164,-11.48272
226.7577,0.73848295,9.606389,0.0,0,18.0,1.4012985e-45,1.0229151,3.3861673,17.999962,146.78152,-11.482779
228.8577,0.74772906,9.6105452,0.0,0,18.0,1.4012985e-45,1.02351,3.4257708,17.999529,140.89673,-11.482773
230.9577,0.76465189,9.6141691,0.0,0,18.0,1.4012985e-45,1.0243524,3.4987049,17.99925,135.41031,-11.483291
233.0577,0.756464,9.6184168,0.0,0,18.0,1.4012985e-45,1.0251436,3.4457664,18.000887,130.19856,-11.483054
235.1577,0.74730802,9.6223059,0.0,0,18.0,1.4012985e-45,1.0257175,3.4077122,18.000643,125.40932,-11.482766
237.2577,0.76393753,9.625411,0.0,0,18.0,1.4012985e-45,1.0264168,3.4924481,17.999983,120.77666,-11.483053
239.3577,0.7616213,9.6287117,0.0,0,18.0,1.4012985e-45,1.0270276,3.4806926,18.000116,116.13604,-11.481893
240.1577,0.75775504,9.6299543,0.0,0,18.0,1.4012985e-45,1.0272653,3.4555683,17.999249,114.54298,-11.481407