File: examples/dan-msc-case-studies/CS3/data/01 raw data/baron_test_021.csv
Time(sec),Force(kN),Jaw(mm),PowAngle(deg),Power(W),Pram,PTemp,Strain,Stress(MPa),Stroke(mm),TC1(C),wedge(mm)
0.0,0.9350456,0.55514538,0.0,0,11.076097,0.0011781701,0.037736036,11.474709,11.076553,30.340343,-9.1238365
1.2,0.86565071,0.0049571688,0.0,0,11.076097,3.5159168,0.00032480512,11.030704,11.076561,30.233124,-9.4842196
2.4,0.84205222,0.0046079499,0.0,0,11.076097,7.1159167,0.00028745364,10.711305,11.076105,30.170271,-9.4817915
3.6,0.82349098,0.0049992194,0.0,0,11.076097,10.715916,0.00032896324,10.490362,11.076663,30.135071,-9.4804916
4.8,0.80113322,0.0049498025,0.0,0,11.076097,14.315914,0.00035327481,10.211413,11.076532,30.167486,-9.4784479
6.0,0.79549193,0.0048394832,0.0,0,11.076097,17.915915,0.00030670461,10.126424,11.075388,30.09927,-9.4763489
7.2,0.77624214,0.0050443592,0.0,0,11.076097,21.515915,0.00033931783,9.8927011,11.076477,30.018412,-9.473609
8.4,0.77492714,0.0048774472,0.0,0,11.076097,25.115915,0.00032820713,9.8628693,11.076227,29.893736,-9.4717703
9.6,0.76131433,0.0050200373,0.0,0,11.076097,28.715914,0.00034825315,9.6895237,11.075555,29.794941,-9.4698763
10.8,0.76549053,0.0054074251,14.419912,0,11.076097,32.315907,0.00034742325,9.741786,11.076645,29.798058,-9.4682083
12.0,0.75553513,0.0055790567,30.812298,0,11.076097,35.915901,0.00037719312,9.6101856,11.076857,30.006319,-9.4663668
13.2,0.76245868,0.0053154412,40.120701,0,11.076097,39.515903,0.00035807074,9.6985912,11.0759,31.425703,-9.4641495
14.4,0.78319901,0.0031178675,45.589626,0,11.076097,43.115906,0.00021509391,9.9754181,11.075461,34.188545,-9.462204
15.6,0.79716021,-0.00025750959,48.811317,0,11.076097,46.715904,-3.7493606e-05,10.154431,11.075061,38.282204,-9.4601183
16.8,0.80735159,-0.0040509929,50.469105,0,11.076097,50.315907,-0.00026410189,10.28393,11.075869,43.436703,-9.4582062
18.0,0.81566721,-0.0079855127,51.196285,0,11.076097,53.915909,-0.00051987648,10.394786,11.07608,49.068615,-9.4561291
19.2,0.82285148,-0.012276042,50.823452,0,11.076097,57.515907,-0.00081698439,10.487622,11.075812,54.919353,-9.4540892
20.4,0.82719713,-0.015915893,49.65657,0,11.076097,61.11591,-0.0010788593,10.535175,11.076318,60.592751,-9.452013
21.6,0.83741194,-0.019211438,48.383846,0,11.076097,64.715904,-0.001274596,10.675034,11.076148,65.773819,-9.4504223
22.8,0.83660865,-0.022407549,46.655685,0,11.076097,68.315895,-0.0014822925,10.670304,11.075394,70.303558,-9.4482412
24.0,0.8266778,-0.025238857,45.615238,0,11.076097,71.915894,-0.001680402,10.544335,11.076214,74.201591,-9.4460793
25.2,0.83414257,-0.026768526,44.6045,0,11.076097,75.515892,-0.0018073184,10.6386,11.075999,77.665115,-9.4441051
26.4,0.8278383,-0.029148333,44.534832,0,11.076097,79.115891,-0.0019378038,10.555733,11.075729,80.537613,-9.4420519
27.6,0.81477994,-0.031283457,44.836437,0,11.076097,82.715904,-0.0020674346,10.391017,11.076012,83.303307,-9.439744
28.8,0.81943423,-0.033674538,45.615231,0,11.076097,86.315895,-0.0022383903,10.46621,11.075324,86.029915,-9.437767
30.0,0.82732904,-0.035343293,46.822041,0,11.076097,89.915894,-0.002381444,10.557711,11.076215,88.799187,-9.4356642
31.2,0.83099002,-0.037445512,47.954979,0,11.076097,93.5159,-0.0024846727,10.621401,11.076286,91.870987,-9.433774
32.4,0.8411389,-0.039850865,48.812248,0,11.076097,97.115891,-0.002639015,10.766062,11.075391,95.183578,-9.4322109
33.6,0.83827525,-0.0425332,49.649158,0,11.076097,100.7159,-0.0028246669,10.706774,11.076462,98.709503,-9.4299564
34.8,0.84841263,-0.045493983,50.308315,0,11.076097,104.3159,-0.0030524989,10.83652,11.076438,102.51758,-9.4282427
36.0,0.85343099,-0.048335444,50.438229,0,11.076097,107.9159,-0.0032090847,10.895096,11.075602,106.63342,-9.4263277
37.2,0.85570139,-0.051466051,50.438229,0,11.076097,111.51589,-0.0034194854,10.938804,11.076624,110.59737,-9.4242926
38.4,0.85383296,-0.054417513,50.438229,0,11.076097,115.1159,-0.0036174788,10.898056,11.07651,114.54964,-9.4219618
39.6,0.86180919,-0.057162877,50.438236,0,11.076097,118.7159,-0.0038211264,11.006895,11.076385,118.38029,-9.4197426
40.8,0.86522484,-0.059970748,50.438236,0,11.076097,122.3159,-0.0039924518,11.060785,11.075531,122.19561,-9.4180298
42.0,0.86559403,-0.062641412,50.438236,0,11.076097,125.91589,-0.0041620312,11.062843,11.075553,125.72229,-9.4156284
43.2,0.85835773,-0.065207809,50.61977,0,11.076097,129.51602,-0.0043348218,10.961455,11.075624,129.30077,-9.4134121
44.4,0.86308855,-0.067861833,50.82275,0,11.076097,133.11589,-0.0045329211,11.039054,11.076168,132.78427,-9.411684
45.6,0.87083131,-0.070389822,51.196217,0,11.076097,136.7159,-0.0046910169,11.139668,11.075759,136.15646,-9.4099245
46.8,0.86643016,-0.0734194,51.502518,0,11.076097,140.31589,-0.0048790341,11.067948,11.075253,139.58029,-9.4079132
48.0,0.87315565,-0.075821109,51.701508,0,11.076097,143.91588,-0.0050208825,11.16238,11.075886,143.15993,-9.4060783
49.2,0.87591708,-0.07819096,51.932369,0,11.076097,147.51588,-0.0052118762,11.205054,11.075501,146.74271,-9.4042187
50.4,0.87142724,-0.081254803,52.283936,0,11.076097,151.11589,-0.0054064337,11.154172,11.076744,150.40778,-9.402277
51.6,0.8708961,-0.084123284,52.288956,0,11.076097,154.71588,-0.0055991849,11.140423,11.075528,154.07751,-9.3999481
52.8,0.88395554,-0.087162554,52.635494,0,11.076097,158.31589,-0.0057728007,11.319611,11.076047,157.59781,-9.3984308
54.0,0.8779431,-0.090007067,52.975033,0,11.076097,161.91588,-0.0060030255,11.249051,11.07563,161.16837,-9.396102
55.2,0.87994713,-0.093141928,53.203999,0,11.076097,165.51588,-0.0061969585,11.289627,11.077611,164.76854,-9.3937883
56.4,0.88367712,-0.096124746,53.31665,0,11.076097,169.11588,-0.0063834758,11.333339,11.075924,168.38657,-9.3917618
57.6,0.88461733,-0.098909318,53.624447,0,11.076097,172.71588,-0.0065518818,11.342969,11.076086,172.02815,-9.3899603
58.8,0.88274485,-0.1019035,53.881195,0,11.076097,176.31587,-0.006785281,11.326574,11.07642,175.55627,-9.3876801
60.0,0.88867825,-0.1052954,53.975826,0,11.076097,179.91588,-0.0070133139,11.403505,11.076406,179.17589,-9.3858242
61.2,0.89632773,-0.10780762,54.305416,0,11.076097,183.51588,-0.0071584163,11.493934,11.075814,182.74187,-9.3839426
62.4,0.89292878,-0.11124645,54.623634,0,11.076097,187.11588,-0.0073678577,11.458028,11.076582,186.31523,-9.3819475
63.6,0.89479297,-0.11418603,54.931618,0,11.076097,190.71587,-0.007581647,11.482857,11.076042,189.82123,-9.3798075
64.8,0.89633483,-0.11691526,55.056416,0,11.076097,194.31587,-0.0077848383,11.502076,11.076311,193.48676,-9.377759
66.0,0.8978523,-0.12040816,55.239254,0,11.076097,197.91588,-0.0079919901,11.527822,11.077107,197.08836,-9.376092
67.2,0.90010518,-0.12372699,55.535885,0,11.076097,201.51587,-0.0082004806,11.545409,11.075983,200.79709,-9.3744574
68.4,0.89924359,-0.12710023,55.535885,0,11.076097,205.11586,-0.0084257592,11.533159,11.075769,204.48926,-9.3719425
69.6,0.89634877,-0.13011678,55.843506,0,11.076097,208.71588,-0.0086521991,11.509712,11.076176,208.15985,-9.3695316
70.8,0.89407027,-0.13338397,55.889698,0,11.076097,212.31587,-0.0088494886,11.48451,11.075329,211.74937,-9.3671532
72.0,0.90380359,-0.13682522,56.129147,0,11.076097,215.91586,-0.0090776356,11.620004,11.076538,215.3311,-9.3654652
73.2,0.8939752,-0.14016326,56.129147,0,11.076097,219.51587,-0.0092852516,11.480889,11.075472,218.95587,-9.3629313
74.4,0.905707,-0.14382853,56.425777,0,11.076097,223.11586,-0.0095535107,11.644589,11.075559,222.53938,-9.361639
75.6,0.90524918,-0.14777169,56.54678,0,11.076097,226.71587,-0.0098117525,11.628517,11.076342,226.15378,-9.3595543
76.8,0.90192413,-0.15097514,56.711418,0,11.076097,230.31587,-0.010009888,11.59308,11.076283,229.78886,-9.3579197
78.0,0.90808302,-0.15384272,56.711422,0,11.076097,233.91586,-0.010179601,11.673599,11.075392,233.47597,-9.3558207
79.2,0.90447754,-0.15624398,56.804401,0,11.076097,237.51587,-0.010364338,11.647475,11.07568,237.09532,-9.3542614
80.4,0.8882609,-0.15954039,56.986084,0,11.076097,241.11586,-0.010603505,11.42694,11.075377,240.66739,-9.3516912
81.6,0.8864494,-0.16327427,56.986084,0,11.076097,244.71587,-0.010823056,11.412642,11.076424,244.41965,-9.349288
82.8,0.90319258,-0.16649748,57.204578,0,11.076097,248.31587,-0.011022782,11.626119,11.075526,247.88678,-9.3477402
84.0,0.8972317,-0.16991718,57.260738,0,11.076097,251.91586,-0.011264418,11.574023,11.076155,251.42389,-9.345211
85.2,0.90235776,-0.17287853,57.414871,0,11.076097,255.51587,-0.011475414,11.631917,11.076539,255.05147,-9.3431416
86.4,0.91161829,-0.17578459,57.535397,0,11.076097,259.11615,-0.011642454,11.753083,11.075127,258.69437,-9.3413401
87.6,0.90741146,-0.17903139,57.810051,0,11.076097,262.71585,-0.011861061,11.689561,11.07645,262.07431,-9.3394356
88.8,0.9061476,-0.18180193,58.060905,0,11.076097,266.31589,-0.012033401,11.673377,11.076652,265.62289,-9.3375931
90.0,0.91364044,-0.1850075,58.073883,0,11.076097,269.91586,-0.012270168,11.77564,11.076554,269.23715,-9.3359327
91.2,0.91658008,-0.1888901,58.413971,0,11.076097,273.51584,-0.012526494,11.817043,11.075771,272.71353,-9.3340034
92.4,0.91398144,-0.19277886,58.59008,0,11.076097,277.11584,-0.012765422,11.786364,11.075885,276.31219,-9.3320808
93.6,0.90473288,-0.19508132,58.808018,0,11.076097,280.71585,-0.012895874,11.664644,11.075806,279.88968,-9.3294964
94.8,0.89711225,-0.19872552,59.100227,0,11.076097,284.31583,-0.013174564,11.571516,11.076017,283.47073,-9.3277054
96.0,0.90031022,-0.20210709,59.106438,0,11.076097,287.91583,-0.013402217,11.619557,11.076637,287.17596,-9.3252563
97.2,0.90370238,-0.20526111,59.348137,0,11.076097,291.51584,-0.013576416,11.665532,11.076365,290.69839,-9.323102
98.4,0.90324807,-0.20882444,59.600826,0,11.076097,295.11584,-0.013818691,11.654183,11.07668,294.26349,-9.3208227
99.6,0.89486849,-0.21240179,59.827717,0,11.076097,298.71585,-0.014045071,11.555792,11.075966,297.86557,-9.3182602
100.8,0.90808082,-0.21532927,59.842525,0,11.076097,302.31586,-0.014266718,11.734831,11.075319,301.61209,-9.3171549
102.0,0.91067904,-0.21892022,60.084225,0,11.076097,305.91586,-0.014490829,11.770296,11.076483,305.24582,-9.3150587
103.2,0.90986842,-0.22231349,60.084225,0,11.076097,309.51584,-0.014708677,11.759458,11.076651,309.04324,-9.3132839
104.4,0.913194,-0.22635275,60.084225,0,11.076097,313.11584,-0.014958744,11.801859,11.076026,312.71741,-9.3113651
105.6,0.91321796,-0.23087554,60.084286,0,11.076097,316.71582,-0.015281573,11.810796,11.076163,316.41489,-9.3095655
106.8,0.91278487,-0.23425092,60.120731,0,11.076097,320.31586,-0.01550935,11.821352,11.075473,320.06372,-9.3075504
108.0,0.91172725,-0.23688141,60.314934,0,11.076097,323.91586,-0.015656475,11.795043,11.075655,323.58185,-9.3057032
109.2,0.91156697,-0.2397508,60.314934,0,11.076097,327.51587,-0.015854921,11.783198,11.075633,327.11996,-9.3033533
110.4,0.89863503,-0.24399701,60.556637,0,11.076097,331.11584,-0.016132873,11.627518,11.076291,330.61963,-9.3011351
111.6,0.90583628,-0.24704096,60.70845,0,11.076097,334.71588,-0.016358303,11.730041,11.075569,334.17407,-9.298871
112.8,0.9071936,-0.25049004,60.787346,0,11.076097,338.31586,-0.016563544,11.752229,11.076065,337.74313,-9.2970467
114.0,0.91286087,-0.25385547,61.018063,0,11.076097,341.91589,-0.016786126,11.810917,11.076571,341.19409,-9.2947044
115.2,0.91156417,-0.25762257,61.237789,0,11.076097,345.51584,-0.017005691,11.815654,11.075194,344.73718,-9.2927599
116.4,0.91713619,-0.26044697,61.256702,0,11.076097,349.11584,-0.017217182,11.887586,11.075876,348.44067,-9.2908945
117.6,0.91714633,-0.26398078,61.468498,0,11.076097,352.71585,-0.01746117,11.887471,11.074908,352.03839,-9.2890224
118.8,0.91085827,-0.26779017,61.571377,0,11.076097,356.31586,-0.017689053,11.801932,11.076674,355.6907,-9.287323
120.0,0.91894919,-0.27220312,61.688229,0,11.076097,359.91586,-0.017980097,11.928652,11.075806,359.2941,-9.2847042
121.2,0.91039675,-0.27629197,61.799408,0,11.076097,363.51584,-0.018233145,11.78749,11.075534,362.94736,-9.2831059
122.4,0.91049641,-0.27847865,61.907955,0,11.076097,367.11584,-0.018400187,11.809293,11.076273,366.52859,-9.2813349
123.6,0.90547979,-0.28146863,62.096992,0,11.076097,370.71582,-0.018603291,11.732463,11.075274,370.06287,-9.2791281
124.8,0.89737976,-0.28569642,62.116692,0,11.076097,374.31583,-0.018858142,11.634043,11.076253,373.76508,-9.2769022
126.0,0.90530652,-0.28896925,62.295479,0,11.076097,377.9158,-0.019066872,11.751381,11.076444,377.36493,-9.2750177
127.2,0.90320301,-0.29222673,62.336418,0,11.076097,381.51581,-0.019290017,11.728783,11.075974,381.10916,-9.2726088
128.4,0.90738475,-0.29532704,62.336418,0,11.076097,385.11581,-0.019521156,11.782284,11.07493,384.82001,-9.2701626
129.6,0.903898,-0.29889765,62.336418,0,11.076097,388.71582,-0.019723753,11.744061,11.0769,388.43964,-9.2681646
130.8,0.90729481,-0.30209786,62.336433,0,11.076097,392.31583,-0.019933069,11.792747,11.076042,392.07227,-9.2660742
132.0,0.91428739,-0.30566499,62.427555,0,11.076097,395.91583,-0.02014941,11.881545,11.076556,395.71658,-9.2646427
133.2,0.91457641,-0.30884317,62.419899,0,11.076097,399.51581,-0.020398788,11.89622,11.076976,399.40973,-9.2628298
134.4,0.91716433,-0.31286794,62.336433,0,11.076097,403.11581,-0.020668535,11.928498,11.076475,403.25064,-9.2608194
135.6,0.91457617,-0.31739536,62.322109,0,11.076097,406.71582,-0.020930726,11.883735,11.075854,406.94156,-9.2588367
136.8,0.91541535,-0.32121485,62.116707,0,11.076097,410.31583,-0.021170253,11.902588,11.076486,410.54596,-9.2571058
138.0,0.91169149,-0.32299903,62.116707,0,11.076097,413.91583,-0.021292282,11.858114,11.074908,414.03543,-9.2552547
139.2,0.90457684,-0.32690054,62.335182,0,11.076097,417.51584,-0.021575106,11.776848,11.075998,417.41983,-9.2531986
140.4,0.90313399,-0.33061731,62.462662,0,11.076097,421.11584,-0.021801369,11.751592,11.075612,420.73911,-9.2506533
141.6,0.91264117,-0.3339248,62.630341,0,11.076097,424.71585,-0.022015618,11.873897,11.075828,424.12878,-9.2486553
142.8,0.91027701,-0.33722723,62.786297,0,11.076097,428.31583,-0.022211425,11.854955,11.074911,427.53702,-9.2463655
144.0,0.91584188,-0.34092185,63.154369,0,11.076097,431.91586,-0.022479223,11.929168,11.076109,430.93436,-9.2445107
145.2,0.92258793,-0.34624618,63.369137,0,11.076097,435.51584,-0.022842996,12.014494,11.075936,434.3782,-9.2422218
146.4,0.91715044,-0.34884676,63.577873,0,11.076097,439.11588,-0.022979746,11.939942,11.076344,437.935,-9.2403793
147.6,0.91048819,-0.35333106,63.775627,0,11.076097,442.71582,-0.02327808,11.862362,11.07624,441.55634,-9.2381287
148.8,0.90226871,-0.35662779,63.973385,0,11.076097,446.31583,-0.023476789,11.75778,11.076422,445.25748,-9.2362604
150.0,0.91086972,-0.36042693,64.058884,0,11.076097,449.91583,-0.02375235,11.864799,11.074916,449.07022,-9.2342253
151.2,0.91024345,-0.36380917,64.171135,0,11.076097,453.51581,-0.023978192,11.871744,11.075805,452.78848,-9.2321005
152.4,0.91716343,-0.36734959,64.171135,0,11.076097,457.11578,-0.024187932,11.968124,11.075973,456.64975,-9.2303905
153.6,0.91967195,-0.37320393,64.171135,0,11.076097,460.71585,-0.024574187,12.004295,11.076256,460.43414,-9.2286425
154.8,0.91897088,-0.37604779,64.171135,0,11.076097,464.3158,-0.024740526,11.993926,11.075822,464.18469,-9.226634
156.0,0.90423435,-0.37946892,63.976757,0,11.076097,467.91583,-0.025003303,11.805587,11.076168,468.05972,-9.2248125
157.2,0.91137791,-0.38321796,63.973396,0,11.076097,471.51581,-0.025230361,11.900593,11.075191,471.84387,-9.2227278
158.4,0.909899,-0.38647893,63.775642,0,11.076097,475.11581,-0.025437567,11.885988,11.076012,475.60565,-9.2211466
159.6,0.91865945,-0.38922554,63.599007,0,11.076097,478.71579,-0.025594488,11.998155,11.075494,479.31876,-9.2191973
160.8,0.92376053,-0.39301398,63.577888,0,11.076097,482.3158,-0.025880383,12.08256,11.07551,482.93939,-9.2172508
162.0,0.92083842,-0.39651248,63.420506,0,11.076097,485.9158,-0.02610003,12.028974,11.076974,486.43832,-9.2149115
163.2,0.90444553,-0.39941019,63.484787,0,11.076097,489.51578,-0.026270175,11.823078,11.07557,489.77008,-9.2128954
164.4,0.90853548,-0.40200275,63.501129,0,11.076097,493.11581,-0.026442844,11.881769,11.075656,493.2092,-9.2107353
165.6,0.91213822,-0.40466002,63.577873,0,11.076097,496.71579,-0.026595619,11.927402,11.076442,496.62589,-9.2085047
166.8,0.93087482,-0.40767875,63.581944,0,11.076097,499.99759,-0.026836371,12.174553,11.075807,500.10538,-9.2067671
168.0,0.91700459,-0.4107329,61.920425,0,11.076097,499.99884,-0.027022973,12.004184,11.07577,503.32401,-9.2065601
169.2,0.90345955,-0.41129398,59.735195,0,11.076097,499.99884,-0.027044933,11.808282,11.075687,505.82065,-9.2064924
170.4,0.88348824,-0.41120976,57.27396,0,11.076097,499.99884,-0.027041011,11.554369,11.075603,507.42249,-9.2063894
171.6,0.86745721,-0.41000727,54.944103,0,11.076097,499.99884,-0.026953083,11.34609,11.075774,507.9458,-9.2061205
172.8,0.8502022,-0.41018486,52.757885,0,11.076097,499.99884,-0.02700155,11.10849,11.075858,507.46643,-9.2060232
174.0,0.82994312,-0.40739197,51.569836,0,11.076097,499.99884,-0.026807221,10.830525,11.076085,506.09131,-9.2061319
175.2,0.75865054,-0.40533569,51.157841,0,11.076097,499.99884,-0.026659785,9.9153013,11.076024,504.2334,-9.2057438
176.4,0.62885857,-0.4043906,51.610115,0,11.076097,499.99884,-0.026580282,8.2215796,11.076029,501.95599,-9.2059813
177.6,0.5572409,-0.40418509,52.973255,0,11.076097,499.99884,-0.026594499,7.2854643,11.07611,499.66376,-9.2055597
178.8,0.50491726,-0.40281025,54.6217,0,11.076097,499.99884,-0.026526196,6.5884342,11.076588,497.76114,-9.2058525
180.0,0.488354,-0.40368533,56.418713,0,11.076097,499.99884,-0.026553858,6.381814,11.075807,496.35764,-9.2062454
181.2,0.4898296,-0.40400684,57.916637,0,11.076097,499.99884,-0.026569787,6.3963962,11.076931,495.50131,-9.2066851
182.4,0.48032412,-0.40412921,59.104877,0,11.076097,499.99884,-0.026563069,6.2810459,11.075968,495.33038,-9.2063379
183.6,0.48899177,-0.40724522,59.959518,0,11.076097,499.99884,-0.026797261,6.3829923,11.076592,495.74988,-9.2071781
184.8,0.47191507,-0.40729102,60.395943,0,11.076097,499.99884,-0.026817642,6.1754107,11.075332,496.57867,-9.2069206
186.0,0.47712085,-0.41003889,60.556637,0,11.076097,499.99884,-0.026961584,6.2701139,11.076327,497.68695,-9.2075796
187.2,0.47474974,-0.41204521,60.317394,0,11.076097,499.99884,-0.027102398,6.2175164,11.07579,498.81717,-9.2069683
188.4,0.47442386,-0.41297415,60.08424,0,11.076097,499.99884,-0.027137123,6.2123256,11.075542,499.87109,-9.2074661
189.6,0.48396772,-0.41409943,59.600838,0,11.076097,499.99884,-0.027246783,6.3351178,11.076504,500.69034,-9.207552
190.8,0.4805392,-0.41624835,59.106449,0,11.076097,499.99884,-0.027394336,6.2829733,11.07658,501.34076,-9.2075338
192.0,0.47739944,-0.41621423,58.408112,0,11.076097,499.99884,-0.027353834,6.2381821,11.07564,501.77966,-9.2071486
193.2,0.46173948,-0.41694126,57.812504,0,11.076097,499.99884,-0.027422527,6.0294847,11.07633,501.9726,-9.2070208
194.4,0.46304479,-0.41719061,57.411121,0,11.076097,499.99884,-0.02740597,6.04776,11.075765,501.91986,-9.2069387
195.6,0.45014423,-0.41728854,56.98624,0,11.076097,499.99884,-0.027450776,5.8971338,11.075355,501.79825,-9.2067099
196.8,0.44364494,-0.41716939,56.71143,0,11.076097,499.99884,-0.027456261,5.8126345,11.076775,501.47308,-9.2064352
198.0,0.45375973,-0.41664314,56.71143,0,11.076097,499.99884,-0.027385984,5.9321628,11.075881,500.96359,-9.2064199
199.2,0.44197017,-0.41695657,56.711979,0,11.076097,499.99884,-0.027417665,5.7887011,11.076751,500.50107,-9.2062531
200.4,0.4626455,-0.41839397,56.986084,0,11.076097,499.99884,-0.027495805,6.0565486,11.075163,500.02438,-9.2065105
201.6,0.451305,-0.41716579,57.260689,0,11.076097,499.99884,-0.027443567,5.8966722,11.077263,499.66678,-9.2063885
202.8,0.45459041,-0.41767672,57.535397,0,11.076097,499.99884,-0.027486481,5.9443593,11.076447,499.38174,-9.2063646
204.0,0.46672276,-0.41848773,57.794918,0,11.076097,499.99884,-0.027509633,6.106503,11.075505,499.27698,-9.2062674
205.2,0.45660546,-0.41895807,57.825439,0,11.076097,499.99884,-0.027545597,5.980598,11.075366,499.30609,-9.2063742
206.4,0.47437495,-0.41904312,57.968849,0,11.076097,499.99884,-0.027529333,6.2061014,11.076345,499.50821,-9.2063379
207.6,0.47114047,-0.42076233,58.073727,0,11.076097,499.99884,-0.027681043,6.1787715,11.076536,499.68088,-9.2061281
208.8,0.48076636,-0.42133847,57.952831,0,11.076097,499.99884,-0.027713683,6.2901826,11.075751,499.88678,-9.206337
210.0,0.45625162,-0.42196789,57.810291,0,11.076097,499.99884,-0.027734933,5.9808946,11.075358,500.02582,-9.2067404
211.2,0.46444839,-0.4224374,57.810066,0,11.076097,499.99884,-0.027773606,6.0925622,11.076431,500.06171,-9.2065773
211.9476,0.49451789,0.0045809639,28.847284,0,11.076099,0.0066778664,0.00022553605,6.4255061,11.070613,500.16016,-9.2070847
211.95,0.4769353,0.0075032618,15.000564,0,11.076099,2.8868397e-19,0.00032809551,6.1010408,11.075899,500.12442,-9.2083406
211.9524,0.47365457,0.0061826711,1.1538415,0,11.076099,1.2479803e-35,0.00035983592,6.0376592,11.078238,500.08868,-9.20821
211.9548,0.47455865,0.0044960137,0.0,0,11.076099,0.0,0.00040796239,5.9802442,11.076988,499.8891,-9.2071466
211.9572,0.46561438,0.0042279745,0.0,0,11.076099,0.0,0.00046393115,5.8873324,11.07198,499.67465,-9.2067518
211.9596,0.47232446,0.0050606579,0.0,0,11.076099,0.0,0.00040330656,5.9980812,11.076489,499.46021,-9.2062206
211.962,0.46638495,0.0083887195,0.0,0,11.076099,0.0,0.00031977639,5.962297,11.073524,499.24576,-9.2068033
211.9644,0.45196393,0.009486164,0.0,0,11.076099,0.0,0.00047358661,5.73241,11.071454,499.25931,-9.2068157
211.9668,0.46437624,0.0079510752,0.0,0,11.076099,0.0,0.00056714512,5.8630776,11.074475,499.35223,-9.2067719
211.9692,0.4672879,0.0045887106,0.0,0,11.076099,0.0,0.00050558016,5.8535142,11.072646,499.44516,-9.2070589
211.9716,0.46390992,0.0029850185,0.0,0,11.076099,0.0,0.00023101845,5.954967,11.074161,499.53809,-9.2076597
211.974,0.45439738,0.0049018478,0.0,0,11.076099,0.0,0.00014846779,5.6805625,11.075467,499.59457,-9.2073841
211.9764,0.43980554,0.0054055084,0.0,0,11.076099,0.0,0.00020786104,5.6744905,11.078053,499.62317,-9.2075472
211.9788,0.44122359,0.005857829,0.0,0,11.076099,0.0,0.00041849836,5.6159005,11.076995,499.65173,-9.2076254
211.9812,0.44924086,0.0045252284,0.0,0,11.076099,0.0,0.00046122467,5.7608118,11.073966,499.68033,-9.2083731
211.9836,0.44339225,0.0045850822,0.0,0,11.076099,0.0,0.00037085335,5.6708589,11.07258,499.70892,-9.2089062
211.986,0.43836167,0.0077315895,0.0,0,11.076099,0.0,0.00040826216,5.6016135,11.073813,499.73752,-9.2076426
211.9884,0.44000477,0.010364934,0.0,0,11.076099,0.0,0.00039183546,5.5692277,11.072384,499.76611,-9.2070341
211.9908,0.4355447,0.0085072387,0.0,0,11.076099,0.0,0.00054193445,5.5823436,11.073657,499.79471,-9.2073851
211.9932,0.43365484,0.0061501605,0.0,0,11.076099,0.0,0.00055210246,5.6086302,11.077405,499.82486,-9.2070608
211.9956,0.43690988,0.003979784,0.0,0,11.076099,0.0,0.0004766894,5.5377202,11.077304,499.8606,-9.2075548
211.998,0.41812262,0.0038323735,0.0,0,10.916306,0.0,0.00027465669,5.3389182,11.073882,499.89633,-9.2075005
212.0004,0.43026575,0.005433484,0.0,0,10.555332,0.0,0.00026943444,5.5399456,11.070764,499.9321,-9.2077055
212.0028,0.44414553,0.0054142238,0.0,0,10.194359,0.0,0.00031237659,5.7336588,11.043613,499.96365,-9.2070456
212.0052,0.41810977,0.0045528319,0.0,0,9.8333845,0.0,0.0003883504,5.3800368,10.886127,499.89932,-9.2074862
212.0076,0.44639632,0.0044014221,0.0,0,9.4727468,0.0,0.00051609776,5.6533165,10.584807,499.83499,-9.207469
212.01,0.41879112,0.0059179566,0.0,0,9.1214981,0.0,0.00041131242,5.278111,10.180301,499.77066,-9.2075491
212.0124,4.9870477,0.34935769,0.0,0,8.7703295,0.0,0.022982394,61.675472,9.7761412,499.70633,-9.2029953
212.0148,5.9502978,0.71511906,0.0,0,8.4353609,0.0,0.048198402,72.341438,9.3356476,499.80307,-9.2037802
212.0172,5.7466974,1.1721607,0.0,0,8.1013775,0.0,0.080921881,67.543373,8.8837128,499.92459,-9.2030334
212.0196,6.1434975,1.5661248,0.0,0,7.7813349,0.0,0.11023033,69.940544,8.4837227,500.04611,-9.2032576
212.022,6.3496923,1.9141854,0.0,0,7.4635754,0.0,0.13614795,70.597534,8.1218691,500.16763,-9.2039242
212.0244,6.4747534,2.2339833,0.0,0,7.1578832,0.0,0.16060781,70.07518,7.7804484,500.20016,-9.203021
212.0268,6.5130801,2.55885,0.0,0,6.8556757,0.0,0.18642291,68.853859,7.4597301,500.19302,-9.2028713
212.0292,6.7089672,2.8491092,0.0,0,6.5636415,0.0,0.21035731,69.112602,7.1629667,500.18585,-9.2041492
212.0316,6.8672771,3.1417484,0.0,0,6.2761216,0.0,0.23495948,69.156082,6.8613558,500.17871,-9.2032557
212.034,7.0431247,3.4247193,0.0,0,5.9971714,0.0,0.25889328,69.22332,6.5729346,964.18353,-9.2038126
212.0364,7.1147676,3.7084193,0.0,0,5.7237153,0.0,0.28339502,68.332741,6.2880487,1862.2589,-9.2037239
212.0388,7.2799129,3.9888277,0.0,0,5.457253,0.0,0.30824822,68.116707,6.0084171,2760.3342,-9.2027206
212.0412,7.4742193,4.2635498,0.0,0,5.1970935,0.0,0.33385602,68.105331,5.7303677,3658.4097,-9.2036209
212.0436,7.6578388,4.534678,0.0,0,4.9425635,0.0,0.35992017,68.112297,5.4538689,4556.5586,-9.2038021
212.046,7.8042083,4.8004365,0.0,0,4.6951237,0.0,0.38565844,67.564957,5.1798115,5454.8481,-9.2026348
212.0484,7.9643154,5.0641484,0.0,0,4.4520135,0.0,0.41137081,67.155434,4.9183726,6353.1382,-9.202673
212.0508,8.1296053,5.3222046,0.0,0,4.2166214,0.0,0.43744954,66.7743,4.6602445,7251.4277,-9.2027998
212.0532,8.3347816,5.5683851,0.0,0,3.9844091,0.0,0.46344399,66.693779,4.4118123,8000.0,-9.2023621
212.0556,8.5393305,5.8056583,0.0,0,3.7605371,0.0,0.48943993,66.64595,4.1696534,8000.0,-9.2018423
212.058,8.730278,6.0406737,0.0,0,3.5387647,0.0,0.51543349,66.310326,3.9343626,8000.0,-9.200819
212.0604,8.9260836,6.2732668,0.0,0,3.3257885,0.0,0.54117113,66.124023,3.7030396,8000.0,-9.2011023
212.0628,9.1708479,6.5012984,0.0,0,3.1139498,0.0,0.56704068,66.223587,3.4807091,8000.0,-9.2015142
212.0652,9.4421024,6.723011,0.0,0,2.9113381,0.0,0.59364325,66.32122,3.2587891,8000.0,-9.2013149
212.0676,9.6985083,6.935431,0.0,0,2.7090681,0.0,0.62040997,66.389435,3.0441308,8000.0,-9.2006769
212.07,9.9413099,7.1386414,0.0,0,2.5162671,0.0,0.64644963,66.283554,2.8352017,8000.0,-9.2007694
212.0724,10.202296,7.339622,0.0,0,2.3235471,0.0,0.67170745,66.35791,2.6361287,8000.0,-9.2011642
212.0748,10.530662,7.5358028,0.0,0,2.1396961,0.0,0.69691348,66.739883,2.444041,8000.0,-9.2002869
212.0772,10.904275,7.7276011,0.0,0,1.9563839,0.0,0.72314483,67.301971,2.250941,8000.0,-9.1996946
212.0796,11.24269,7.9128375,0.0,0,1.7807442,0.0,0.74951172,67.603302,2.0609617,8000.0,-9.1996098
212.082,11.621678,8.0975428,0.0,0,1.6063603,0.0,0.77655131,68.042152,1.8742914,8000.0,-9.1996546
212.0844,12.050278,8.2786589,0.0,0,1.4385692,0.0,0.80267918,68.735352,1.6917166,8000.0,-9.1995449
212.0868,12.508839,8.4634981,0.0,0,1.2726812,0.0,0.82955658,69.43631,1.5200189,8000.0,-9.1997805
212.0892,13.004155,8.6418772,0.0,0,1.1124123,0.0,0.85697567,70.245872,1.3395976,8000.0,-9.1992626
212.0916,13.468719,8.8098993,0.0,0,0.95463622,0.0,0.88450718,70.77565,1.1682801,8000.0,-9.1992159
212.094,13.963023,8.96702,0.0,0,0.80156928,0.0,0.91128904,71.398193,1.0047791,8000.0,-9.1980419
212.0964,14.527196,9.1233959,0.0,0,0.65152127,0.0,0.93736404,72.390015,0.84704822,8000.0,-9.197628
212.0988,15.143286,9.2793493,0.0,0,0.5052858,0.0,0.96338278,73.510902,0.68427694,8000.0,-9.1979027
212.1012,14.565434,9.4203854,0.0,0,0.36248577,0.0,0.98795074,69.823593,0.53116697,8000.0,-9.1975737
212.1036,12.203973,9.4236174,0.0,0,0.22278805,0.0,0.98973006,57.985401,0.45751476,8000.0,-9.1996813
212.106,11.20995,9.4266233,0.0,0,0.086996041,0.0,0.99095488,53.095718,0.40902895,8000.0,-9.2005806
212.1084,10.543867,9.4311113,0.0,0,-0.047588516,0.0,0.99183542,49.797619,0.37977278,8000.0,-9.2026453
212.1108,10.222337,9.4359369,0.0,0,-0.18002053,0.0,0.99157864,48.268188,0.34649813,8000.0,-9.2043381
212.1132,10.335471,9.4466982,0.0,0,-0.31245255,0.0,0.99251264,48.742363,0.30314618,8000.0,-9.2034111
212.1156,10.647717,9.453721,0.0,0,-0.44488451,0.0,0.9941625,50.156841,0.23705634,8000.0,-9.2042341
212.118,10.799024,9.4550371,0.0,0,-0.57731652,0.0,0.9957062,50.771515,0.16804293,8000.0,-9.2026014
212.1204,10.772323,9.4547977,0.0,0,-0.70974851,0.0,0.9961611,50.686573,0.10714076,8000.0,-9.2017794
212.1228,10.638955,9.4589844,0.0,0,-0.84218049,0.0,0.99600351,50.004433,0.053353854,8000.0,-9.2013283
212.1252,10.389222,9.4686089,0.0,0,-0.97461247,0.0,0.99679649,48.848457,0.010800839,8000.0,-9.2024355
212.1276,10.043567,9.4729757,0.0,0,-1.0959824,239.06335,0.99777192,47.189247,-0.017257245,8000.0,-9.2027817
212.13,9.6027603,9.4716263,0.0,0,-0.65229225,500.0,0.99838185,45.082478,-0.025684038,8000.0,-9.2034559
212.1324,9.1489191,9.4691372,0.0,0,-0.19380596,500.0,0.99880373,42.914761,-0.024563747,8000.0,-9.2030716
212.1348,8.7468901,9.4707174,0.0,0,0.26468039,500.0,0.99826843,41.021587,-0.023645379,8000.0,-9.2033014
212.1372,8.4012451,9.4763966,0.0,0,0.72316676,500.0,0.99804211,39.467983,-0.014289529,8000.0,-9.2041664
212.1396,8.1636086,9.4775887,0.0,0,1.1816531,500.0,0.9980092,38.338093,-0.011965335,8000.0,-9.204711
212.142,7.5204754,9.4779215,0.0,0,1.6401393,500.0,0.99946171,35.340515,0.0097612198,8000.0,-9.2044525
212.1444,5.8175654,9.4678354,0.0,0,2.0986257,500.0,0.99861348,27.442139,0.094335504,8000.0,-9.2055264
212.1468,2.9016318,9.4503193,0.0,0,2.5571125,500.0,0.99510288,13.91023,0.28288326,8000.0,-9.2085638
212.1492,-0.27759087,9.4182415,0.0,0,3.015599,500.0,0.98830032,-1.214353,0.54961848,8000.0,-9.210001
212.1516,-0.014965971,9.3815908,0.0,0,3.4740856,500.0,0.98129791,-0.23940191,1.1173298,8000.0,-9.2111778
212.154,0.19023106,9.3738632,0.0,0,3.9325716,500.0,0.98021978,1.067379,1.8968143,8000.0,-9.2112112
212.1564,-0.21351089,9.4056234,0.0,0,4.391058,500.0,0.98712409,-1.0065174,2.6617498,8000.0,-9.2106886
212.1588,0.11049326,9.4441404,0.0,0,4.8495445,500.0,0.9939481,0.52938449,3.2999177,8000.0,-9.2090921
212.1612,-0.092870615,9.4420176,0.0,0,5.3080311,500.0,0.99262869,-0.34086519,3.7805798,8000.0,-9.2106686
212.1636,0.045577187,9.4501371,0.0,0,5.7665176,500.0,0.99299389,0.10153618,4.2076898,8000.0,-9.2091961
212.166,-0.001479795,9.4494686,0.0,0,6.2250037,500.0,0.99342024,0.062188819,4.6309724,8000.0,-9.2096062
212.1684,-0.064261496,9.4399757,0.0,0,6.6834898,500.0,0.9931885,-0.21616945,5.0583005,8000.0,-9.20928
212.1708,-0.14098378,9.4360809,0.0,0,7.1419768,500.0,0.992854,-0.68108791,5.5003748,8000.0,-9.2090273
212.1732,0.15593295,9.4385633,0.0,0,7.6004629,500.0,0.99218124,0.73704612,5.9805131,8000.0,-9.2084227
212.1756,-0.14297441,9.4445601,0.0,0,8.0589485,500.0,0.99246234,-0.60913265,6.4607258,8000.0,-9.2075462
212.178,-0.054726016,9.444562,0.0,0,8.5174351,500.0,0.99255085,-0.40116826,6.949039,8000.0,-9.2074785
212.1804,0.15715569,9.4406214,0.0,0,8.9759216,500.0,0.99304873,0.75678998,7.4323106,8000.0,-9.2076178
212.1828,-0.23228826,9.4378405,0.0,0,9.4344082,500.0,0.99300832,-1.0181118,7.897655,8000.0,-9.2071714
212.1852,0.0083329687,9.4360018,0.0,0,9.8928947,500.0,0.99213821,-0.069254242,8.3616362,8000.0,-9.2066479
212.1876,0.154719,9.4407825,0.0,0,10.351381,500.0,0.99185532,0.78393567,8.8476782,8000.0,-9.2054749
212.19,-0.20883878,9.4467688,0.0,0,10.809868,500.0,0.9925127,-0.97004521,9.3249464,8000.0,-9.2061911
212.1924,0.052964795,9.4441671,0.0,0,11.268353,500.0,0.99339521,0.17204058,9.7953615,8000.0,-9.2066126
212.1948,0.039362427,9.4384947,0.0,0,11.72684,500.0,0.99335778,0.23897848,10.268671,8000.0,-9.2052784
212.1972,-0.1584795,9.4373169,0.0,0,12.185327,500.0,0.99253792,-0.72935027,10.725873,8000.0,-9.2050695
212.1996,0.10545406,9.4390907,0.0,0,12.643813,500.0,0.99170774,0.38832635,11.198394,8000.0,-9.2060604
212.202,-0.082471922,9.440484,0.0,0,13.1023,500.0,0.99154854,-0.24461922,11.657204,8000.0,-9.204422
212.2044,-0.10628757,9.4398556,0.0,0,13.560786,500.0,0.99236375,-0.52856147,12.103573,8000.0,-9.2059793
212.2068,0.028996605,9.4365587,0.0,0,14.019273,500.0,0.99275637,0.033093516,12.567942,8000.0,-9.2056608
212.2092,0.12590712,9.4345999,0.0,0,14.477758,500.0,0.99232298,0.64273369,13.047556,8000.0,-9.2048426
212.2116,-0.2516551,9.4407444,0.0,0,14.936245,500.0,0.99230689,-1.1605597,13.518865,8000.0,-9.2044048
212.214,0.067916788,9.446003,0.0,0,15.394732,500.0,0.99229705,0.19759475,14.000733,8000.0,-9.2051907
212.2164,0.032388855,9.4453897,0.0,0,15.853217,500.0,0.99276268,0.22923546,14.483766,8000.0,-9.2040634
212.2188,-0.10073562,9.4406109,0.0,0,16.311705,500.0,0.9934324,-0.4774293,14.949929,8000.0,-9.2037039
212.2212,0.033721216,9.436059,0.0,0,16.770191,500.0,0.99278921,0.10626026,15.416873,8000.0,-9.2047958
212.2236,-0.035170276,9.4369545,0.0,0,17.228678,500.0,0.99186015,-0.021923358,15.873951,8000.0,-9.2029228
212.226,-0.16944264,9.4415398,0.0,0,17.687164,500.0,0.9918139,-0.83064973,16.318062,8000.0,-9.2032833
212.2284,0.16084202,9.4410381,0.0,0,18.0,500.0,0.99215454,0.7424053,16.776476,8000.0,-9.2053566
212.2308,-0.054968972,9.438714,0.0,0,18.0,500.0,0.99262446,-0.17650124,17.229052,8000.0,-9.2037296
212.2332,-0.021536732,9.4345293,0.0,0,18.0,500.0,0.99255925,-0.1849408,17.644218,8000.0,-9.2051029
212.2356,-0.025432376,9.4372654,0.0,0,18.0,500.0,0.99218744,-0.088404417,18.008858,8000.0,-9.2059574
212.238,-0.022587437,9.4466782,0.0,0,18.0,500.0,0.99275064,-0.087621428,18.28787,8000.0,-9.2086821
212.2404,0.032918591,9.450984,0.0,0,18.0,500.0,0.99340379,0.13762012,18.463232,8000.0,-9.210741
212.2428,0.025027789,9.452507,0.0,0,18.0,500.0,0.99490428,0.16286837,18.509768,8000.0,-9.2161798
212.2452,-0.054070294,9.4560518,0.0,0,18.0,500.0,0.99628425,-0.20424582,18.434517,8000.0,-9.2239838
212.2476,0.29728493,9.4636765,0.0,0,18.0,500.0,0.99709767,1.3703642,18.300262,8000.0,-9.233983
212.25,0.23251136,9.4673805,0.0,0,18.0,500.0,0.99663025,1.0937566,18.166906,8000.0,-9.2477884
212.2524,0.29904735,9.471384,0.0,0,18.0,500.0,0.99726743,1.4170229,18.086634,8000.0,-9.2637815
212.2548,0.24841525,9.4696598,0.0,0,18.0,500.0,0.99785125,1.1724398,18.041449,8000.0,-9.2831554
212.2572,0.25935283,9.4650497,0.0,0,18.0,500.0,0.99795002,1.2006282,18.040571,8000.0,-9.3041945
212.2596,0.19818509,9.4634247,0.0,0,18.0,500.0,0.99739766,0.94195223,18.048773,8000.0,-9.3257656
212.262,0.2443108,9.4656305,0.0,0,18.0,500.0,0.99669296,1.1052011,18.070127,8000.0,-9.3453236
212.2644,0.2560485,9.4705544,0.0,0,18.0,500.0,0.99681151,1.1765398,18.099188,8000.0,-9.366725
212.2668,0.24910609,9.4715672,0.0,0,18.0,500.0,0.9977898,1.2153926,18.125666,8000.0,-9.3864822
212.2692,0.21161804,9.4681873,0.0,0,18.0,500.0,0.99845994,0.99584138,18.139097,8000.0,-9.4056816
212.2716,0.23482756,9.4631567,0.0,0,18.0,500.0,0.99771667,1.0817691,18.142422,8000.0,-9.4236135
212.274,0.24451746,9.4635239,0.0,0,18.0,500.0,0.99656397,1.1190603,18.153435,8000.0,-9.44104
212.2764,0.27057624,9.4667768,0.0,0,18.0,500.0,0.99636471,1.2635267,18.14728,8000.0,-9.4582071
212.2788,0.2375623,9.4678354,0.0,0,18.0,500.0,0.99706763,1.1206672,18.146585,8000.0,-9.4760408
212.2812,0.2333694,9.4662809,0.0,0,18.0,500.0,0.99777758,1.0637677,18.143017,8000.0,-9.4947405
212.2836,0.24659209,9.4638281,0.0,0,18.0,500.0,0.99772042,1.1605359,18.136572,8000.0,-9.5119095
212.286,0.27796525,9.4667826,0.0,0,18.0,500.0,0.99733794,1.3204248,18.133469,8000.0,-9.5298624
212.2884,0.26390019,9.4715376,0.0,0,18.0,500.0,0.99723828,1.2880975,18.129766,8000.0,-9.5477095
212.2908,0.25351432,9.4738693,0.0,0,18.0,500.0,0.99762332,1.1996126,18.125029,8000.0,-9.5658073
212.2932,0.25048095,9.470335,0.0,0,18.0,500.0,0.99830693,1.1385707,18.126556,8000.0,-9.5852737
212.2956,0.27593482,9.4640169,0.0,0,18.0,500.0,0.99794698,1.2713633,18.124592,8000.0,-9.6018887
212.298,0.26563391,9.4640732,0.0,0,18.0,500.0,0.9971664,1.2183669,18.120684,8000.0,-9.6218882
212.3004,0.25920954,9.4672279,0.0,0,18.0,500.0,0.99674129,1.2028251,18.121536,8000.0,-9.6399527
212.3028,0.23321408,9.4700108,0.0,0,18.0,500.0,0.99714595,1.1070356,18.119398,8000.0,-9.6585808
212.3052,0.25416815,9.4698267,0.0,0,18.0,500.0,0.99802524,1.2420862,18.11865,8000.0,-9.6750908
212.3076,0.27930471,9.4638519,0.0,0,18.0,500.0,0.99773902,1.2553469,18.113338,8000.0,-9.6947336
212.31,0.26608524,9.4635506,0.0,0,18.0,500.0,0.99749923,1.2722969,18.115461,8000.0,-9.7123566
212.3124,0.25442493,9.4688559,0.0,0,18.0,500.0,0.99695438,1.1981714,18.114765,8000.0,-9.7313328
212.3148,0.24659622,9.473115,0.0,0,18.0,500.0,0.99711132,1.1585177,18.111063,8000.0,-9.7490368
212.3172,0.2600424,9.4745617,0.0,0,18.0,500.0,0.99820089,1.2524874,18.108555,8000.0,-9.7667646
212.3196,0.26389393,9.4670496,0.0,0,18.0,500.0,0.99814475,1.232057,18.106937,8000.0,-9.785079
212.322,0.256762,9.4616604,0.0,0,18.0,500.0,0.99731517,1.2448697,18.10725,8000.0,-9.8044777
212.3244,0.23335879,9.465106,0.0,0,18.0,500.0,0.99671018,1.1295888,18.106163,8000.0,-9.8235512
212.3268,0.25788912,9.4692526,0.0,0,18.0,500.0,0.99689555,1.220445,18.10351,8000.0,-9.8413963
212.3292,0.25912097,9.4712038,0.0,0,18.0,500.0,0.99770719,1.1986462,18.103148,8000.0,-9.8576441
212.3316,0.27020448,9.4686842,0.0,0,18.0,500.0,0.99826735,1.259105,18.099155,8000.0,-9.8776522
212.334,0.24646494,9.4642506,0.0,0,18.0,500.0,0.99764454,1.1487197,18.100647,8000.0,-9.8957138
212.3364,0.23904911,9.4654913,0.0,0,18.0,500.0,0.99694479,1.1163076,18.103512,8000.0,-9.9142017
212.3388,0.24760352,9.4705629,0.0,0,18.0,500.0,0.9969573,1.1740737,18.100651,8000.0,-9.930563
212.3412,0.27238542,9.471035,0.0,0,18.0,500.0,0.9971506,1.2605789,18.09565,8000.0,-9.9482861
212.3436,0.25587028,9.4677649,0.0,0,18.0,500.0,0.99796677,1.1903086,18.096733,8000.0,-9.9675503
212.346,0.2332969,9.4661846,0.0,0,18.0,500.0,0.99842751,1.1368181,18.097065,8000.0,-9.9870205
212.3484,0.26061511,9.464201,0.0,0,18.0,500.0,0.99711853,1.1952801,18.098003,8000.0,-10.003515
212.3508,0.26522869,9.4685678,0.0,0,18.0,500.0,0.99672633,1.210853,18.098444,8000.0,-10.020309
212.3532,0.27371857,9.4681892,0.0,0,18.0,500.0,0.9967894,1.3124163,18.098505,8000.0,-10.039456
212.3556,0.25891185,9.4667091,0.0,0,18.0,500.0,0.99743104,1.23715,18.090607,8000.0,-10.059507
212.358,0.24285957,9.4650564,0.0,0,18.0,500.0,0.99795324,1.1268243,18.089277,8000.0,-10.077461
212.3604,0.26235944,9.4637823,0.0,0,18.0,500.0,0.9972111,1.2115515,18.089359,8000.0,-10.095271
212.3628,0.28292027,9.4686146,0.0,0,18.0,500.0,0.99687052,1.3093437,18.089066,8000.0,-10.11272
212.3652,0.27698183,9.4754248,0.0,0,18.0,500.0,0.99752933,1.2978487,18.088448,8000.0,-10.131767
212.3676,0.26949018,9.4735956,0.0,0,18.0,500.0,0.9983288,1.2486545,18.088573,8000.0,-10.149683
212.37,0.26541445,9.4694519,0.0,0,18.0,500.0,0.9986378,1.2167573,18.08956,8000.0,-10.168148
212.3724,0.28343701,9.4650097,0.0,0,18.0,500.0,0.99780655,1.3200192,18.08909,8000.0,-10.184698
212.3748,0.29411882,9.4668417,0.0,0,18.0,500.0,0.99690139,1.3755647,18.084921,8000.0,-10.203484
212.3772,0.27816975,9.4695015,0.0,0,18.0,500.0,0.99674875,1.2978425,18.084545,8000.0,-10.222694
212.3796,0.25394538,9.471612,0.0,0,18.0,500.0,0.99785399,1.1924473,18.084408,8000.0,-10.242606
212.382,0.27558115,9.4679718,0.0,0,18.0,500.0,0.99817824,1.2691879,18.086393,8000.0,-10.260552
212.3844,0.28836018,9.4665565,0.0,0,18.0,500.0,0.99807936,1.3610548,18.082823,8000.0,-10.278325
212.3868,0.28222263,9.4680367,0.0,0,18.0,500.0,0.99753553,1.3372095,18.081282,8000.0,-10.295744
212.3892,0.26402387,9.4732647,0.0,0,18.0,500.0,0.99731004,1.2267553,18.082094,8000.0,-10.315193
212.3916,0.26231116,9.4737625,0.0,0,18.0,500.0,0.99779332,1.255778,18.079441,8000.0,-10.334924
212.394,0.26915386,9.4702415,0.0,0,18.0,500.0,0.99852061,1.2866219,18.080935,8000.0,-10.351693
212.3964,0.29816896,9.4657507,0.0,0,18.0,500.0,0.99825847,1.3896894,18.071661,8000.0,-10.368397
212.3988,0.27362028,9.4656744,0.0,0,18.0,500.0,0.99718708,1.2729356,18.071228,8000.0,-10.385775
212.4012,0.24646242,9.46842,0.0,0,18.0,500.0,0.99681199,1.1545451,18.073069,8000.0,-10.404947
212.4036,0.27291659,9.4711189,0.0,0,18.0,500.0,0.99730718,1.2710274,18.074629,8000.0,-10.423246
212.406,0.26536226,9.4692297,0.0,0,18.0,500.0,0.99796772,1.2223477,18.0748,8000.0,-10.438851
212.4084,0.29496869,9.4659071,0.0,0,18.0,500.0,0.99815619,1.345363,18.072464,8000.0,-10.457479
212.4108,0.26945639,9.4656944,0.0,0,18.0,500.0,0.99756122,1.2497424,18.072573,8000.0,-10.477696
212.4132,0.25359824,9.4695663,0.0,0,18.0,500.0,0.9970457,1.1580648,18.076069,8000.0,-10.496095
212.4156,0.26927203,9.4750652,0.0,0,18.0,500.0,0.99744481,1.2482815,18.071611,8000.0,-10.514539
212.418,0.29291371,9.4739733,0.0,0,18.0,500.0,0.99835479,1.3455352,18.072483,8000.0,-10.53184
212.4204,0.27111113,9.4671974,0.0,0,18.0,500.0,0.99840456,1.2809075,18.070997,8000.0,-10.550076
212.4228,0.25580534,9.4638681,0.0,0,18.0,500.0,0.99759948,1.1913172,18.07136,8000.0,-10.569078
212.4252,0.27265629,9.4642677,0.0,0,18.0,500.0,0.99641073,1.2714421,18.071682,8000.0,-10.587172
212.4276,0.27381179,9.4677124,0.0,0,18.0,500.0,0.99653506,1.2381837,18.071529,8000.0,-10.604841
212.43,0.29435021,9.4701509,0.0,0,18.0,500.0,0.99758941,1.4178829,18.072798,8000.0,-10.623151
212.4324,0.26815468,9.466114,0.0,0,18.0,500.0,0.99792969,1.3154516,18.070524,8000.0,-10.642251
212.4348,0.2685079,9.4655819,0.0,0,18.0,500.0,0.99785143,1.2492495,18.068363,8000.0,-10.658868
212.4372,0.27486986,9.4670877,0.0,0,18.0,500.0,0.99724728,1.2873082,18.071779,8000.0,-10.677221
212.4396,0.30262625,9.4753399,0.0,0,18.0,500.0,0.99747014,1.4239625,18.070969,8000.0,-10.694218
212.442,0.28487831,9.4738369,0.0,0,18.0,500.0,0.99783188,1.3085326,18.069967,8000.0,-10.71298
212.4444,0.27588701,9.4706755,0.0,0,18.0,500.0,0.99865544,1.2789488,18.06925,8000.0,-10.732635
212.4468,0.2863895,9.4661369,0.0,0,18.0,500.0,0.99835873,1.30926,18.065372,8000.0,-10.749941
212.4492,0.29823479,9.4660454,0.0,0,18.0,500.0,0.9972316,1.3976657,18.068222,8000.0,-10.767741
212.4516,0.30433834,9.4692078,0.0,0,18.0,500.0,0.99677807,1.4186809,18.067057,8000.0,-10.786567
212.454,0.2838878,9.4698534,0.0,0,18.0,500.0,0.99725837,1.3619795,18.063477,8000.0,-10.805479
212.4564,0.27202609,9.4667387,0.0,0,18.0,500.0,0.99762851,1.2791091,18.061796,8000.0,-10.823681
212.4588,0.27965149,9.4632177,0.0,0,18.0,500.0,0.99769408,1.2991633,18.061527,8000.0,-10.842217
212.4612,0.30505139,9.4662857,0.0,0,18.0,500.0,0.99761814,1.4225467,18.061392,8000.0,-10.860142
212.4636,0.28978202,9.470439,0.0,0,18.0,500.0,0.99708432,1.3868073,18.055481,8000.0,-10.878059
212.466,0.27851281,9.4743643,0.0,0,18.0,500.0,0.99736512,1.3172559,18.06135,8000.0,-10.898455
212.4684,0.2775521,9.4729958,0.0,0,18.0,500.0,0.99844992,1.3066519,18.056261,8000.0,-10.914853
212.4708,0.29680863,9.4668617,0.0,0,18.0,500.0,0.99841011,1.3678488,18.056389,8000.0,-10.930246
212.4732,0.29315645,9.4623365,0.0,0,18.0,500.0,0.99712294,1.3859425,18.061447,8000.0,-10.949157
212.4756,0.29375467,9.4649191,0.0,0,18.0,500.0,0.99648577,1.3959697,18.053707,8000.0,-10.966817
212.478,0.27082711,9.4698544,0.0,0,18.0,500.0,0.99694878,1.2734784,18.052656,8000.0,-10.986461
212.4804,0.28086701,9.4689875,0.0,0,18.0,500.0,0.99760097,1.3108524,18.058384,8000.0,-11.004949
212.4828,0.2912215,9.4637432,0.0,0,18.0,500.0,0.99765426,1.3918279,18.055864,8000.0,-11.021485
212.4852,0.29376537,9.4625635,0.0,0,18.0,500.0,0.99721801,1.3462548,18.05419,8000.0,-11.040606
212.4876,0.27873537,9.4657145,0.0,0,18.0,500.0,0.99694949,1.3184035,18.052269,8000.0,-11.059641
212.49,0.27900109,9.4720507,0.0,0,18.0,500.0,0.99684185,1.3263881,18.054358,8000.0,-11.07735
212.4924,0.28263867,9.4731083,0.0,0,18.0,500.0,0.99784374,1.3435899,18.055885,8000.0,-11.095682
212.4948,0.30518779,9.468708,0.0,0,18.0,500.0,0.99826169,1.4228525,18.054111,8000.0,-11.113138
212.4972,0.28678861,9.4628563,0.0,0,18.0,500.0,0.99774998,1.3750792,18.05377,8000.0,-11.133083
212.4996,0.27243155,9.4649582,0.0,0,18.0,500.0,0.99693418,1.2916105,18.053606,8000.0,-11.151121
212.502,0.29001057,9.4684696,0.0,0,18.0,500.0,0.99671799,1.2884222,18.053265,8000.0,-11.169897
212.5044,0.28751364,9.4678698,0.0,0,18.0,500.0,0.99690676,1.3382109,18.054159,8000.0,-11.186475
212.5068,0.30600533,9.4649391,0.0,0,18.0,500.0,0.99736363,1.4398453,18.053463,8000.0,-11.204862
212.5092,0.28952792,9.4641743,0.0,0,18.0,500.0,0.99773592,1.3602402,18.051109,8000.0,-11.22405
212.5116,0.28448772,9.4652166,0.0,0,18.0,500.0,0.9973045,1.3457304,18.051844,8000.0,-11.242398
212.514,0.29712549,9.4696894,0.0,0,18.0,500.0,0.99678004,1.3506817,18.050014,8000.0,-11.261396
212.5164,0.32004443,9.4742165,0.0,0,18.0,500.0,0.99741089,1.5077941,18.051563,8000.0,-11.279609
212.5188,0.30302286,9.4720478,0.0,0,18.0,500.0,0.99828273,1.4313427,18.049109,8000.0,-11.295779
212.5212,0.29294476,9.4662561,0.0,0,18.0,500.0,0.99829519,1.3923259,18.046499,8000.0,-11.313683
212.5236,0.29508272,9.4627733,0.0,0,18.0,500.0,0.99719137,1.3799465,18.049109,8000.0,-11.3332
212.526,0.29943353,9.4652205,0.0,0,18.0,500.0,0.99649239,1.4051511,18.050543,8000.0,-11.350621
212.9275,0.25043771,9.4709759,0.0,0,18.0,0.0017792438,0.99795181,1.1742465,18.010941,8000.0,-11.480313
214.1275,0.20771343,9.4823523,0.0,0,18.0,7.691642999999999e-20,1.0001115,0.97434765,18.001019,8000.0,-11.480362
215.3275,0.19198668,9.4927702,0.0,0,18.0,3.3250839e-36,1.0020012,0.89603716,17.999287,8000.0,-11.481016
216.5275,0.18388385,9.5007877,0.0,0,18.0,1.4012985e-45,1.003502,0.85878986,17.999205,8000.0,-11.481404
217.7275,0.16948946,9.5089073,0.0,0,18.0,1.4012985e-45,1.0049292,0.7865063,18.000002,8000.0,-11.481544
218.9275,0.16865882,9.5175266,0.0,0,18.0,1.4012985e-45,1.0063941,0.78694928,17.999125,8000.0,-11.480805
220.1275,0.16572572,9.5242386,0.0,0,18.0,1.4012985e-45,1.0077274,0.77103961,18.00001,8000.0,-11.480604
221.3275,0.1752647,9.5319233,0.0,0,18.0,1.4012985e-45,1.0091145,0.81655121,17.999212,8000.0,-11.48112
222.5275,0.17109378,9.5385752,0.0,0,18.0,1.4012985e-45,1.0104213,0.79722804,18.000614,8000.0,-11.48167
223.7275,0.16993545,9.5454655,0.0,0,18.0,1.4012985e-45,1.0116168,0.78837717,18.000126,8000.0,-11.482071
224.9275,0.1663484,9.5528975,0.0,0,18.0,1.4012985e-45,1.0128847,0.76935285,17.999706,8000.0,-11.481838
226.1275,0.17138281,9.5588322,0.0,0,18.0,1.4012985e-45,1.0140795,0.79073703,18.000242,8000.0,-11.480958
227.3275,0.16219044,9.5646448,0.0,0,18.0,1.4012985e-45,1.0151225,0.75157696,18.000088,8000.0,-11.480536
228.5275,0.16589116,9.5706997,0.0,0,18.0,1.4012985e-45,1.0162743,0.76094532,18.000986,8000.0,-11.480968
229.7275,0.16501199,9.5759401,0.0,0,18.0,1.4012985e-45,1.0172229,0.75731713,17.999617,8000.0,-11.481038
230.9275,0.16321725,9.5821657,0.0,0,18.0,1.4012985e-45,1.0182835,0.75141567,17.99954,8000.0,-11.481742
232.1275,0.16063087,9.5876369,0.0,0,18.0,1.4012985e-45,1.0193506,0.74026203,17.998747,8000.0,-11.48176
233.3275,0.16082659,9.5930338,0.0,0,18.0,1.4012985e-45,1.0203813,0.73461747,17.999475,8000.0,-11.482017
234.5275,0.15936394,9.5972958,0.0,0,18.0,1.4012985e-45,1.0211802,0.72979587,17.99921,8000.0,-11.482467
235.7275,0.15289065,9.602397,0.0,0,18.0,1.4012985e-45,1.0221431,0.69819796,17.999989,8000.0,-11.482251
236.9275,0.15256988,9.6067133,0.0,0,18.0,1.4012985e-45,1.0228118,0.69395977,17.999107,8000.0,-11.481672
238.1275,0.15505958,9.6103239,0.0,0,18.0,1.4012985e-45,1.0235562,0.71282631,17.999767,8000.0,-11.482087
239.3275,0.1598209,9.6149015,0.0,0,18.0,1.4012985e-45,1.0244579,0.7316156,17.999722,8000.0,-11.481853
240.5275,0.15433833,9.6194487,0.0,0,18.0,1.4012985e-45,1.0252234,0.70469785,18.000095,8000.0,-11.481855
241.7275,0.15565646,9.6230192,0.0,0,18.0,1.4012985e-45,1.0260099,0.71361023,18.000284,8000.0,-11.481707
242.9275,0.15410914,9.6276169,0.0,0,18.0,1.4012985e-45,1.0267385,0.70207375,18.000135,8000.0,-11.482083
244.1275,0.15545848,9.6318426,0.0,0,18.0,1.4012985e-45,1.0275047,0.71011013,17.999725,8000.0,-11.482238
245.3275,0.15069404,9.6359367,0.0,0,18.0,1.4012985e-45,1.0283726,0.68810332,18.001421,8000.0,-11.482086
246.5275,0.15246752,9.6398191,0.0,0,18.0,1.4012985e-45,1.0290555,0.69601655,18.000748,8000.0,-11.482383
247.7275,0.16203971,9.6432619,0.0,0,18.0,1.4012985e-45,1.0297456,0.73920739,17.999722,8000.0,-11.48262
248.9275,0.14753425,9.6467314,0.0,0,18.0,1.4012985e-45,1.0303454,0.67177445,17.999685,8000.0,-11.482691
250.1275,0.1464123,9.6504164,0.0,0,18.0,1.4012985e-45,1.0309441,0.65948206,17.999491,8000.0,-11.481484
251.3275,0.14730634,9.6538839,0.0,0,18.0,1.4012985e-45,1.0317054,0.66950303,17.999931,8000.0,-11.481237
252.5275,0.14521959,9.6573057,0.0,0,18.0,1.4012985e-45,1.0323159,0.65904593,17.999676,8000.0,-11.480927
253.7275,0.14270674,9.6606312,0.0,0,18.0,1.4012985e-45,1.0329612,0.65012372,18.000357,8000.0,-11.48088
254.9275,0.14080644,9.6638241,0.0,0,18.0,1.4012985e-45,1.0336021,0.63724375,17.99967,8000.0,-11.480206
256.1275,0.1581993,9.6673346,0.0,0,18.0,1.4012985e-45,1.0341341,0.7132262,18.000856,8000.0,-11.48144
257.3275,0.14740261,9.6703939,0.0,0,18.0,1.4012985e-45,1.0347399,0.66676277,18.000227,8000.0,-11.481609
258.5275,0.15042266,9.6730318,0.0,0,18.0,1.4012985e-45,1.0353249,0.68230754,17.999956,8000.0,-11.481935
259.7275,0.14398783,9.6765575,0.0,0,18.0,1.4012985e-45,1.035924,0.64628518,17.999308,8000.0,-11.482
260.9275,0.14096738,9.6798058,0.0,0,18.0,1.4012985e-45,1.0365989,0.63857359,18.000523,8000.0,-11.48208
262.1275,0.14199264,9.6824474,0.0,0,18.0,1.4012985e-45,1.0370662,0.6411944,17.999945,8000.0,-11.482365
263.3275,0.13809967,9.6856508,0.0,0,18.0,1.4012985e-45,1.0375795,0.61723858,18.000563,8000.0,-11.482423
264.5275,0.14135137,9.6885405,0.0,0,18.0,1.4012985e-45,1.0381458,0.63652879,17.999838,8000.0,-11.482507
265.7275,0.12930319,9.6909037,0.0,0,18.0,1.4012985e-45,1.0386773,0.58343649,18.000185,8000.0,-11.481966
266.9275,0.13937856,9.693984,0.0,0,18.0,1.4012985e-45,1.0391858,0.62679249,17.998972,8000.0,-11.481708
268.1275,0.13663022,9.6971264,0.0,0,18.0,1.4012985e-45,1.0398558,0.61366451,18.000809,8000.0,-11.481531
269.3275,0.13293041,9.6994696,0.0,0,18.0,1.4012985e-45,1.0402604,0.59938133,17.999569,8000.0,-11.481701
270.5275,0.13413121,9.7023487,0.0,0,18.0,1.4012985e-45,1.0406967,0.60296601,17.999729,8000.0,-11.481714
271.7275,0.13749777,9.7044678,0.0,0,18.0,1.4012985e-45,1.0411698,0.62129331,18.00038,8000.0,-11.481618
272.5275,0.13895896,9.7059975,0.0,0,18.0,1.4012985e-45,1.0414355,0.62263244,17.99964,8000.0,-11.603467