File: examples/dan-msc-case-studies/CS3/data/01 raw data/baron_test_027.csv
Time(sec),Force(kN),Jaw(mm),PowAngle(deg),Power(W),Pram,PTemp,Strain,Stress(MPa),Stroke(mm),TC1(C),wedge(mm)
0.0,1.2102761,0.63199002,0.0,0,10.594783,0.0016338611,0.043048255,14.764412,10.594923,31.59836,-9.1020622
2.2,1.0919217,-0.001825485,0.0,0,10.594783,6.5159163,-0.00011120935,13.910764,10.595496,31.470901,-9.4715023
4.4,1.0508738,-0.0014310332,0.0,0,10.594783,13.115913,-0.00010741299,13.37868,10.595292,31.374571,-9.4688606
6.6,1.027786,-0.0012985349,0.0,0,10.594783,19.715914,-9.3564966e-05,13.084712,10.594798,31.300503,-9.4652758
8.8,1.0238124,-0.0012253532,0.0,0,10.594783,26.31591,-7.5167161e-05,13.034761,10.5942,31.191263,-9.461627
11.0,1.0084759,-0.00052468322,10.785813,0,10.594783,32.91592,-4.2858701e-05,12.842528,10.594129,31.020487,-9.4583645
13.2,1.0056789,5.2209365e-05,37.008224,0,10.594783,39.515915,-1.5065469e-07,12.824135,10.595146,32.329384,-9.4551859
15.4,1.0261199,-0.003333481,46.038265,0,10.594783,46.115913,-0.00021060648,13.065663,10.595591,38.195667,-9.4517937
17.6,1.0420153,-0.0094524994,48.812252,0,10.594783,52.715908,-0.00063577079,13.273619,10.596098,47.393772,-9.4481421
19.8,1.065887,-0.015343233,49.655739,0,10.594783,59.315903,-0.0010285481,13.570251,10.594988,56.486263,-9.4447088
22.0,1.0761454,-0.020890681,48.81226,0,10.594783,65.915901,-0.0013865214,13.723512,10.595009,65.645988,-9.4413414
24.2,1.0606208,-0.025349805,47.505848,0,10.594783,72.515907,-0.001690192,13.52828,10.594265,73.270683,-9.437458
26.4,1.068294,-0.029510006,47.054447,0,10.594783,79.115906,-0.001982711,13.624216,10.594195,79.758743,-9.4345036
28.6,1.0642633,-0.033211753,47.504883,0,10.594783,85.715897,-0.0022103644,13.56673,10.594779,85.569977,-9.4309206
30.8,1.0729703,-0.037498403,48.383785,0,10.594783,92.315895,-0.0024972185,13.686821,10.594907,91.617577,-9.4270153
33.0,1.0774604,-0.041485947,49.848656,0,10.594783,98.915901,-0.00277965,13.749062,10.594851,97.490395,-9.4236984
35.2,1.0854568,-0.046679724,51.196285,0,10.594783,105.51588,-0.0030997747,13.872843,10.595013,103.81894,-9.4196863
37.4,1.0742315,-0.051122591,51.923889,0,10.594783,112.11589,-0.0034135114,13.73357,10.594776,110.80666,-9.4158983
39.6,1.0865276,-0.056285731,52.543976,0,10.594783,118.7159,-0.0037555904,13.874053,10.594267,117.53991,-9.4127769
41.8,1.1074705,-0.061305687,52.635494,0,10.594783,125.3159,-0.0040792706,14.151758,10.594429,124.79193,-9.40975
44.0,1.1150253,-0.066683963,52.534222,0,10.594783,131.91588,-0.0044411495,14.265605,10.594301,131.84862,-9.4061871
46.2,1.1083153,-0.071479283,52.635494,0,10.594783,138.51587,-0.0047544846,14.188529,10.594059,138.23044,-9.4027462
48.4,1.1027617,-0.076340348,53.405609,0,10.594783,145.11589,-0.0050719599,14.123903,10.59462,144.25624,-9.3989182
50.6,1.1034663,-0.081331432,54.08736,0,10.594783,151.7159,-0.0054071788,14.125138,10.594991,150.69566,-9.3954582
52.8,1.1184459,-0.086655565,54.624023,0,10.594783,158.31589,-0.0057708411,14.311821,10.594628,157.37592,-9.391819
55.0,1.1287315,-0.091490045,54.931637,0,10.594783,164.91588,-0.006077949,14.455658,10.594865,164.1274,-9.3879824
57.2,1.1196384,-0.096941002,55.239254,0,10.594783,171.51587,-0.0064451783,14.340378,10.594653,170.81784,-9.3844309
59.4,1.1293433,-0.10232931,55.639862,0,10.594783,178.11589,-0.006807127,14.492135,10.594481,177.50658,-9.3807573
61.6,1.1359199,-0.10632585,56.425747,0,10.594783,184.71588,-0.0070583345,14.575584,10.594632,183.61981,-9.3772812
63.8,1.1355937,-0.11263799,56.549297,0,10.594783,191.31587,-0.0074884566,14.561248,10.594602,190.66676,-9.3733406
66.0,1.14922,-0.11764692,56.711189,0,10.594783,197.91586,-0.0078244964,14.73425,10.595299,197.3604,-9.3701859
68.2,1.1425164,-0.12329058,57.260738,0,10.594783,204.51587,-0.0081844321,14.664658,10.594651,203.73532,-9.3664427
70.4,1.1494253,-0.12877177,57.535397,0,10.594783,211.11588,-0.0085515045,14.756306,10.595076,210.46284,-9.3631907
72.6,1.135527,-0.13437362,57.535412,0,10.594783,217.71587,-0.0089313779,14.583639,10.594745,217.38757,-9.3593645
74.8,1.1410837,-0.1400297,58.590073,0,10.594783,224.31586,-0.0092837568,14.660924,10.59461,223.14175,-9.3557978
77.0,1.1580024,-0.14638492,58.59008,0,10.594783,230.91586,-0.0097254859,14.885889,10.593539,230.27893,-9.3522167
79.2,1.1562513,-0.15122998,58.566975,0,10.594783,237.51585,-0.010044249,14.869772,10.594951,237.29922,-9.3485746
81.4,1.1630818,-0.15732081,58.826958,0,10.594783,244.11588,-0.01043299,14.976234,10.594713,243.61516,-9.3454533
83.6,1.1593322,-0.16206865,59.825806,0,10.594783,250.71587,-0.010755598,14.919853,10.594262,249.27495,-9.3419991
85.8,1.1610794,-0.16890168,60.084225,0,10.594783,257.31616,-0.011202704,14.939992,10.59439,256.31113,-9.3383083
88.0,1.1543065,-0.1742126,60.084225,0,10.594783,263.91589,-0.011543327,14.872223,10.59485,263.38516,-9.3346939
90.2,1.1652973,-0.17949481,60.314934,0,10.594783,270.51587,-0.011904124,15.010766,10.594746,269.90775,-9.3313103
92.4,1.1691294,-0.18599205,61.015106,0,10.594783,277.11584,-0.012328001,15.083559,10.595471,275.95285,-9.3276052
94.6,1.1520166,-0.19180907,61.455482,0,10.594783,283.71585,-0.012696379,14.858624,10.594697,282.63052,-9.3240061
96.8,1.1579148,-0.19736704,61.680817,0,10.594783,290.31586,-0.013077136,14.941476,10.595533,289.40054,-9.3205709
99.0,1.1600429,-0.20313948,62.044983,0,10.594783,296.91586,-0.013454223,14.966966,10.594713,295.96451,-9.3169403
101.2,1.1619507,-0.20911449,62.336418,0,10.594783,303.51584,-0.013838117,14.998635,10.593789,302.58524,-9.3134651
103.4,1.1706485,-0.21510343,62.753887,0,10.594783,310.11581,-0.014243327,15.127291,10.594926,309.12744,-9.31005
105.6,1.1616985,-0.22151937,62.962639,0,10.594783,316.71585,-0.014665891,15.019477,10.594388,315.83432,-9.306509
107.8,1.1624694,-0.22795458,63.171383,0,10.594783,323.31586,-0.015080363,15.037819,10.593948,322.72479,-9.3027096
110.0,1.1629303,-0.23407213,63.369137,0,10.594783,329.91586,-0.015489563,15.038015,10.595174,329.27484,-9.2990675
112.2,1.1734021,-0.24035527,63.577873,0,10.594783,336.51587,-0.015906071,15.174331,10.59328,335.93286,-9.2957077
114.4,1.1597482,-0.24662794,63.973335,0,10.594783,343.11584,-0.01630234,15.017846,10.594653,342.26501,-9.2916288
116.6,1.1611133,-0.25352493,64.171135,0,10.594783,349.71585,-0.016759792,15.049879,10.595743,348.87827,-9.2876205
118.8,1.1723427,-0.26051041,64.357903,0,10.594783,356.31586,-0.017235503,15.199102,10.596542,355.61188,-9.2846031
121.0,1.1556594,-0.26728988,64.555656,0,10.594783,362.91583,-0.017655527,14.96409,10.594181,362.3349,-9.2804527
123.2,1.1758431,-0.27466622,64.742432,0,10.594783,369.51584,-0.018143546,15.238651,10.595067,368.91534,-9.2761459
125.4,1.1719118,-0.27975717,64.985435,0,10.594783,376.11581,-0.01848652,15.198451,10.595027,375.48209,-9.2736473
127.6,1.1750069,-0.28774783,65.115959,0,10.594783,382.71585,-0.018997278,15.255337,10.594048,382.23105,-9.270154
129.8,1.1600606,-0.29281485,65.115959,0,10.594783,389.31586,-0.019332947,15.063514,10.594489,389.01013,-9.2658529
132.0,1.1643443,-0.30014786,65.302727,0,10.594783,395.91586,-0.019834336,15.107814,10.595258,395.59436,-9.2620869
134.2,1.1711545,-0.30513662,65.478508,0,10.594783,402.51584,-0.020146273,15.201174,10.595369,401.88422,-9.2589273
136.4,1.1789157,-0.31090313,65.841057,0,10.594783,409.11584,-0.020517651,15.327282,10.595124,408.41086,-9.2561617
138.6,1.1647388,-0.31717438,65.975418,0,10.594783,415.71582,-0.020930849,15.14563,10.593562,415.19135,-9.2521172
140.8,1.1658998,-0.3233659,65.904221,0,10.594783,422.31583,-0.02132744,15.188043,10.594687,422.12921,-9.2482967
143.0,1.1704452,-0.33081633,65.841072,0,10.594783,428.9158,-0.021809893,15.217288,10.594789,428.9202,-9.2441502
145.2,1.1697469,-0.33557329,65.841072,0,10.594783,435.51581,-0.02213173,15.215447,10.59449,435.63916,-9.2402802
147.4,1.1824422,-0.34138304,65.841057,0,10.594783,442.11581,-0.022497496,15.402818,10.59467,442.22693,-9.2370501
149.6,1.167698,-0.34655088,65.826904,0,10.594783,448.71585,-0.022849064,15.216525,10.594853,448.7854,-9.233984
151.8,1.1720253,-0.35084748,65.841057,0,10.594783,455.31583,-0.023124807,15.279952,10.593518,455.36661,-9.2307892
154.0,1.1682557,-0.35612589,65.840942,0,10.594783,461.91583,-0.023455421,15.234652,10.594789,461.94406,-9.2273111
156.2,1.1649437,-0.35966662,65.696381,0,10.594783,468.51584,-0.023710635,15.185428,10.594715,468.66162,-9.2238245
158.4,1.1343008,-0.36434549,65.841057,0,10.594783,475.11581,-0.024005981,14.769502,10.594984,474.86133,-9.2193575
160.6,1.1333219,-0.36809546,66.192619,0,10.594783,481.71585,-0.024230782,14.782356,10.594228,481.05447,-9.2154083
162.8,1.12361,-0.37140998,66.368401,0,10.594783,488.31583,-0.024475291,14.663445,10.594584,487.5675,-9.2118568
165.0,1.1179186,-0.37490749,66.684486,0,10.594783,494.9158,-0.024677752,14.597031,10.593332,494.17877,-9.2083225
167.2,0.074312866,-0.3902908,66.368431,0,10.594783,499.99884,-0.025678644,0.95591223,10.594419,500.58804,-9.2055979
169.4,0.38223049,-0.37926283,66.708946,0,10.594783,499.99884,-0.024985516,4.9977751,10.59474,499.38727,-9.2056036
171.6,0.8464154,-0.37993461,64.823318,0,10.594783,499.99884,-0.025008485,11.046829,10.594578,503.46793,-9.2055931
173.8,1.1593105,-0.37745184,61.481018,0,10.594783,499.99884,-0.024840735,15.137237,10.594797,507.08228,-9.2056341
176.0,1.0776979,-0.37294716,57.811104,0,10.594783,499.99884,-0.024576144,14.057935,10.593957,507.92664,-9.2055025
178.2,0.86436218,-0.37033898,55.240681,0,10.594783,499.99884,-0.024382707,11.283398,10.595043,506.10333,-9.2057295
180.4,0.62826014,-0.36966282,55.234226,0,10.594783,499.99884,-0.024331424,8.1930132,10.594317,502.52252,-9.2061892
182.6,0.52103972,-0.36834183,56.956646,0,10.594783,499.99884,-0.024282156,6.7965798,10.594291,498.85318,-9.2060986
184.8,0.46623898,-0.36856097,59.343342,0,10.594783,499.99884,-0.024270741,6.0835614,10.595043,496.34552,-9.2065525
187.0,0.467435,-0.36865065,61.466629,0,10.594783,499.99884,-0.024268027,6.1061063,10.594884,495.57629,-9.2065191
189.2,0.45023826,-0.37128514,62.753819,0,10.594783,499.99884,-0.024460025,5.8704448,10.594089,496.1268,-9.2062168
191.4,0.45497197,-0.37385321,63.36911,0,10.594783,499.99884,-0.024613028,5.9433713,10.594589,497.60635,-9.2059984
193.6,0.45930517,-0.37692821,63.171394,0,10.594783,499.99884,-0.024805564,5.9812007,10.594721,499.38089,-9.2059479
195.8,0.45493165,-0.37958902,62.410671,0,10.594783,499.99884,-0.025000088,5.9451742,10.594482,500.87631,-9.2056675
198.0,0.4572061,-0.38272512,61.468533,0,10.594783,499.99884,-0.025200117,5.9651866,10.594238,501.87717,-9.2058067
200.2,0.44519317,-0.38219589,60.556648,0,10.594783,499.99884,-0.025169834,5.820529,10.594161,502.19269,-9.2059679
202.4,0.44410154,-0.38199258,59.842541,0,10.594783,499.99884,-0.025155883,5.8024521,10.595275,501.8541,-9.2062788
204.6,0.41908169,-0.38233864,59.600838,0,10.594783,499.99884,-0.025172416,5.4620833,10.5946,501.10028,-9.2061901
206.8,0.42357081,-0.38223028,59.755428,0,10.594783,499.99884,-0.025168227,5.5507522,10.593669,500.20566,-9.2063503
209.0,0.42720824,-0.38354912,60.084225,0,10.594783,499.99884,-0.025242904,5.5914426,10.595047,499.42999,-9.2061605
211.2,0.43637496,-0.38342318,60.729328,0,10.594783,499.99884,-0.025232172,5.6926188,10.595249,499.07288,-9.2062149
211.9496,0.45864189,0.0022653162,60.787354,0,10.5948,1.5401856000000002e-16,3.2910026e-05,5.8515587,10.593804,498.98868,-9.2059174
211.954,0.43884578,0.0076978579,57.010445,0,10.5948,0.0,0.00022280739,5.5088649,10.594675,499.01129,-9.2058001
211.9584,0.46955642,0.0028829866,30.210411,0,10.5948,0.0,7.8336634e-05,6.0238709,10.598168,499.01129,-9.2066126
211.9628,0.44550201,0.0080253975,3.4103801,0,10.5948,0.0,0.00021692576,5.5933342,10.593808,499.01129,-9.2063999
211.9672,0.43266642,0.0036209149,0.0,0,10.5948,0.0,0.00015661641,5.4953499,10.596193,498.96536,-9.2065172
211.9716,0.43852803,0.0081177549,0.0,0,10.5948,0.0,0.00035770517,5.4950566,10.596124,498.91272,-9.2058134
211.976,0.42696944,0.0042890878,0.0,0,10.5948,0.0,0.00014511042,5.4419885,10.594981,498.88394,-9.205719
211.9804,0.41410422,0.0072822631,0.0,0,10.5948,0.0,0.00038076419,5.2746415,10.595112,498.87079,-9.2062187
211.9848,0.41288769,0.0038000708,0.0,0,10.5948,0.0,0.00028346604,5.2451587,10.592763,498.85764,-9.2058372
211.9892,0.40295115,0.00716253,0.0,0,10.5948,0.0,0.00054379588,5.1649437,10.593562,498.84448,-9.2058344
211.9936,0.4142212,0.0035486941,0.0,0,10.5948,0.0,0.00029920801,5.2867293,10.59347,498.83401,-9.2058535
211.998,0.4018777,0.0052900668,0.0,0,10.578863,0.0,0.00048345717,5.1849508,10.594456,498.86032,-9.2076674
212.0024,0.38624147,0.0022423221,0.0,0,10.512863,0.0,0.0003267334,4.9053068,10.592602,498.88666,-9.2048826
212.0068,0.39658797,0.0018251048,0.0,0,10.446863,0.0,0.00037001065,5.0450449,10.58373,498.88138,-9.2061434
212.0112,0.41453147,0.0024537037,0.0,0,10.380863,0.0,0.00037686696,5.2259459,10.535225,498.86823,-9.2059412
212.0156,0.39088136,0.0020160158,0.0,0,10.314863,0.0,0.00039012425,5.0952306,10.438186,498.84805,-9.2054272
212.02,0.38906917,0.0023419701,0.0,0,10.248863,0.0,0.0003666408,4.9255848,10.330513,498.82175,-9.2067251
212.0244,0.38978475,0.00071869587,0.0,0,10.182863,0.0,0.00030421492,4.9814081,10.254291,498.79544,-9.2073841
212.0288,0.3993279,0.0030890093,0.0,0,10.116863,0.0,0.0003104127,4.9804106,10.199512,498.76913,-9.2069101
212.0332,0.3960512,0.0017276875,0.0,0,10.050863,0.0,0.00020940567,5.0959353,10.149108,498.74283,-9.2064886
212.0376,0.38333604,0.0030128895,0.0,0,9.9848633,0.0,0.00020793955,4.914783,10.085773,498.76889,-9.2058859
212.042,1.1252091,0.0058823959,0.0,0,9.9188633,0.0,0.0004085525,14.014182,10.016583,498.7952,-9.2048674
212.0464,3.6756828,0.035527904,0.0,0,9.8528633,0.0,0.0022955795,46.531563,9.9569311,498.80237,-9.2049646
212.0508,4.0864344,0.10363976,0.0,0,9.7868633,0.0,0.006839592,51.63147,9.8785372,498.80237,-9.2030172
212.0552,4.2426291,0.17803136,0.0,0,9.7208633,0.0,0.011742189,53.370586,9.8063669,498.75406,-9.20504
212.0596,4.3523164,0.24380423,0.0,0,9.6548634,0.0,0.016179617,54.439312,9.7367516,498.64877,-9.2025919
212.064,4.3902555,0.31078973,0.0,0,9.5888634,0.0,0.020694571,54.773693,9.6651602,498.52344,-9.2019901
212.0684,4.4028983,0.37157828,0.0,0,9.5228634,0.0,0.024889598,54.69075,9.6037607,498.3129,-9.2044458
212.0728,4.4437599,0.43954465,0.0,0,9.4574747,0.0,0.029412087,54.913246,9.5384502,498.10239,-9.2047739
212.0772,4.452589,0.49892634,0.0,0,9.3930941,0.0,0.033634607,54.951679,9.4777012,497.819,-9.2055016
212.0816,4.5322623,0.56415325,0.0,0,9.3287134,0.0,0.038026795,55.576584,9.4109945,497.52951,-9.2052574
212.086,4.5843239,0.63019878,0.0,0,9.2643328,0.0,0.042803992,55.930504,9.3402205,497.4209,-9.203824
212.0904,4.5259752,0.70028347,0.0,0,9.1999521,0.0,0.047615349,54.956905,9.2753172,497.40775,-9.2048578
212.0948,4.5591283,0.76066518,0.0,0,9.1355705,0.0,0.051969212,55.064831,9.2052479,497.43018,-9.2045965
212.0992,4.6210546,0.82516921,0.0,0,9.0711899,0.0,0.056506768,55.52972,9.1445417,497.50912,-9.2049828
212.1036,4.6721168,0.8868348,0.0,0,9.0068092,0.0,0.061000679,55.919735,9.0768833,497.56317,-9.203249
212.108,4.6453919,0.95691502,0.0,0,8.9424286,0.0,0.066018395,55.343273,9.0092201,497.43161,-9.2038651
212.1124,4.6552582,1.0173159,0.0,0,8.8780479,0.0,0.070285097,55.195801,8.9424591,497.30002,-9.2052107
212.1168,4.6954784,1.081799,0.0,0,8.8136663,0.0,0.075026035,55.459946,8.8801632,496.98947,-9.2045889
212.1212,4.7162948,1.1407503,0.0,0,8.7493448,0.0,0.079323456,55.490177,8.8145742,496.6474,-9.2048206
212.1256,4.7079196,1.2044588,0.0,0,8.6880999,0.0,0.083908878,55.174679,8.7563648,496.49667,-9.2046633
212.13,4.7446537,1.2658745,0.0,0,8.6268692,0.0,0.088335134,55.22451,8.6876183,496.48352,-9.204874
212.1344,4.773283,1.328101,0.0,0,8.5656385,0.0,0.092948064,55.309151,8.6267996,496.63956,-9.2051077
212.1388,4.813374,1.3903191,0.0,0,8.5044088,0.0,0.097409636,55.681446,8.5593901,497.16589,-9.2031946
212.1432,4.8049984,1.4506823,0.0,0,8.4431782,0.0,0.10185688,55.331852,8.5000668,497.67905,-9.2029305
212.1476,4.7873597,1.5110648,0.0,0,8.3819485,0.0,0.10625069,54.882622,8.4377174,497.91589,-9.2040854
212.152,4.8635945,1.5706686,0.0,0,8.3207178,0.0,0.1106002,55.311871,8.3749228,498.15274,-9.2049236
212.1564,4.8746853,1.6309538,0.0,0,8.2594872,0.0,0.11506538,55.374928,8.3179493,498.10321,-9.2047062
212.1608,4.9375143,1.6901923,0.0,0,8.1982574,0.0,0.11947845,55.782639,8.2576733,497.97162,-9.2049713
212.1652,4.9376211,1.7583472,0.0,0,8.1370268,0.0,0.12446342,55.506615,8.1935282,497.86685,-9.2033129
212.1696,4.9740214,1.817227,0.0,0,8.0757961,0.0,0.12894009,55.624889,8.1275311,497.7879,-9.2034578
212.174,5.0140352,1.8853645,0.0,0,8.0165014,0.0,0.13400841,55.817345,8.0609417,497.75967,-9.2038031
212.1784,4.9826961,1.9428895,0.0,0,7.9582448,0.0,0.13844495,55.199703,8.0037966,497.89127,-9.2053709
212.1828,4.987545,2.0031092,0.0,0,7.8999887,0.0,0.14295083,55.062206,7.9435554,498.02283,-9.2055235
212.1872,4.9928279,2.0558786,0.0,0,7.8417325,0.0,0.14723602,54.926472,7.8837347,498.28241,-9.2050705
212.1916,5.0455394,2.1176066,0.0,0,7.7834764,0.0,0.15176111,55.200573,7.8293815,498.54556,-9.2031612
212.196,5.0780039,2.1719074,0.0,0,7.7252207,0.0,0.15626657,55.309116,7.7679973,498.84216,-9.2034006
212.2004,5.0607066,2.2328253,0.0,0,7.6669641,0.0,0.16092587,54.887344,7.7118335,499.15283,-9.2043686
212.2048,5.1094947,2.2856157,0.0,0,7.6087089,0.0,0.16520742,55.091408,7.6512098,499.26434,-9.20401
212.2092,5.1653295,2.34746,0.0,0,7.5504522,0.0,0.17002767,55.540432,7.5926113,499.23804,-9.2030439
212.2136,5.1585674,2.4024408,0.0,0,7.4921966,0.0,0.17448606,55.188774,7.5351987,499.23721,-9.2040577
212.218,5.189249,2.4604895,0.0,0,7.4339404,0.0,0.17918168,55.283566,7.4779859,499.28983,-9.2021713
212.2224,5.1960602,2.5160499,0.0,0,7.376503,0.0,0.18359584,55.070324,7.4148107,499.35251,-9.2050829
212.2268,5.2207999,2.5751605,0.0,0,7.3210983,0.0,0.1885943,55.007339,7.3610396,499.58936,-9.2040701
212.2312,5.2620668,2.6283829,0.0,0,7.2656937,0.0,0.19279931,55.277332,7.2998676,499.8262,-9.2020159
212.2356,5.2506771,2.6826482,0.0,0,7.2102885,0.0,0.19735545,54.932789,7.2477403,500.06305,-9.2038937
212.24,5.2523856,2.7354472,0.0,0,7.1548839,0.0,0.20163903,54.715,7.1949177,500.2999,-9.2040854
212.2444,5.3084664,2.7933819,0.0,0,7.0994787,0.0,0.2064153,54.948944,7.1344523,500.55038,-9.2017183
212.2488,5.356401,2.8480651,0.0,0,7.0440741,0.0,0.21079606,55.261539,7.0783229,500.81354,-9.2039127
212.2532,5.3720837,2.9034951,0.0,0,6.9886689,0.0,0.21539141,55.223389,7.0255065,501.03723,-9.2026749
212.2576,5.3785582,2.9613729,0.0,0,6.9332647,0.0,0.22005664,54.90741,6.9663467,501.14249,-9.2038612
212.262,5.3852191,3.0137556,0.0,0,6.8778596,0.0,0.22433475,54.769646,6.9092078,501.24774,-9.2051649
212.2664,5.4358258,3.0719171,0.0,0,6.8224545,0.0,0.22920796,54.965759,6.8513079,501.4176,-9.2045145
212.2708,5.4597268,3.1245923,0.0,0,6.7670498,0.0,0.233528,54.970558,6.7971978,501.58865,-9.204731
212.2752,5.4406509,3.1840067,0.0,0,6.7141314,0.0,0.23846889,54.607853,6.7424417,501.7691,-9.2027216
212.2796,5.4169555,3.2334831,0.0,0,6.6614194,0.0,0.24255842,54.087421,6.6889987,501.95334,-9.2039766
212.284,5.4434133,3.285887,0.0,0,6.6087074,0.0,0.24695341,54.096558,6.6418409,502.07306,-9.2044477
212.2884,5.5386872,3.3379827,0.0,0,6.555995,0.0,0.25133073,54.739117,6.5883884,502.11255,-9.2030325
212.2928,5.5476336,3.3935318,0.0,0,6.5032835,0.0,0.25603253,54.728779,6.5314159,502.13568,-9.204977
212.2972,5.5783019,3.4451644,0.0,0,6.4505715,0.0,0.26062959,54.698174,6.4763217,502.08307,-9.2045536
212.3016,5.6105218,3.5060949,0.0,0,6.3978596,0.0,0.26571926,54.823719,6.4216428,502.03043,-9.2043819
212.306,5.6314535,3.552547,0.0,0,6.3451471,0.0,0.26997656,54.693901,6.3676758,502.04956,-9.2028122
212.3104,5.6201663,3.6114645,0.0,0,6.2924356,0.0,0.2750046,54.358547,6.3155551,502.07587,-9.2030115
212.3148,5.5895667,3.6541629,0.0,0,6.2397237,0.0,0.27894711,53.821095,6.2619529,502.1528,-9.2044182
212.3192,5.6600981,3.7096024,0.0,0,6.1870117,0.0,0.28382429,54.224277,6.2117352,502.25806,-9.2028589
212.3236,5.7091355,3.7568989,0.0,0,6.1357427,0.0,0.28823462,54.405514,6.1596441,502.37805,-9.2032309
212.328,5.7410235,3.8131585,0.0,0,6.0856094,0.0,0.29328161,54.582027,6.1095033,502.5228,-9.2045593
212.3324,5.7510076,3.8624935,0.0,0,6.0354757,0.0,0.29780596,54.357746,6.0527825,502.66754,-9.2039614
212.3368,5.7466221,3.9173548,0.0,0,5.985342,0.0,0.30284956,54.055027,6.0030551,502.81226,-9.2052107
212.3412,5.7356563,3.9616868,0.0,0,5.9352083,0.0,0.30684024,53.673145,5.9513116,502.957,-9.2048807
212.3456,5.7657647,4.0092764,0.0,0,5.8850746,0.0,0.31135669,53.780701,5.9059982,500.37238,-9.2021999
212.35,5.7928514,4.053771,0.0,0,5.8349409,0.0,0.31541523,53.794498,5.855865,497.25381,-9.2040892
212.3544,5.8330507,4.1072078,0.0,0,5.7848077,0.0,0.32037038,53.898056,5.8073521,494.70349,-9.2033062
212.3588,5.8907728,4.1562629,0.0,0,5.734674,0.0,0.32479894,54.148167,5.75633,492.58505,-9.2044916
212.3632,5.9211082,4.2069111,0.0,0,5.6845403,0.0,0.32955849,54.285229,5.7044611,491.54825,-9.2034903
212.3676,5.9388785,4.259644,0.0,0,5.6344061,0.0,0.33429202,54.144753,5.6499791,493.03522,-9.2029629
212.372,5.9658232,4.3108053,0.0,0,5.5847507,0.0,0.33904225,54.097267,5.5994053,494.4845,-9.204257
212.3764,5.9336915,4.3599176,0.0,0,5.537055,0.0,0.34358969,53.633953,5.5499449,494.78714,-9.2043104
212.3808,5.9548798,4.4059539,0.0,0,5.4893589,0.0,0.34778351,53.523766,5.5007191,495.08978,-9.2037563
212.3852,5.9992537,4.4537516,0.0,0,5.4416628,0.0,0.3521837,53.692059,5.4568262,491.54184,-9.2045031
212.3896,6.0130887,4.5001092,0.0,0,5.3939672,0.0,0.35660884,53.60532,5.4057398,486.80212,-9.2029781
212.394,6.0089793,4.5517101,0.0,0,5.346271,0.0,0.36134148,53.272083,5.3596497,482.9758,-9.2030554
212.3984,6.0562325,4.5942879,0.0,0,5.2985749,0.0,0.36541271,53.499779,5.3130741,480.07965,-9.2037153
212.4028,6.118536,4.6480265,0.0,0,5.2508793,0.0,0.37049225,53.825363,5.2658091,478.51819,-9.2030411
212.4072,6.0846982,4.6920958,0.0,0,5.2031832,0.0,0.37474257,53.267731,5.2198925,481.49438,-9.2034893
212.4116,6.1501775,4.745285,0.0,0,5.1554871,0.0,0.37966964,53.550755,5.1689215,484.47058,-9.2029133
212.416,6.2355604,4.7890043,0.0,0,5.1077909,0.0,0.38427141,54.026253,5.1168723,486.52448,-9.2037201
212.4204,6.2194781,4.8415766,0.0,0,5.0600948,0.0,0.38920438,53.65181,5.0718317,488.53906,-9.2035637
212.4248,6.2043085,4.8829432,0.0,0,5.0143404,0.0,0.39351666,53.26099,5.0283751,489.95288,-9.2038851
212.4292,6.2216783,4.9330711,0.0,0,4.968976,0.0,0.39831108,53.173977,4.9816303,491.09796,-9.2034979
212.4336,6.3030806,4.9777513,0.0,0,4.9236121,0.0,0.40304875,53.655239,4.9316268,492.02042,-9.2029324
212.438,6.3061433,5.0255718,0.0,0,4.8782487,0.0,0.40784431,53.464581,4.8885646,492.63882,-9.2034016
212.4424,6.314291,5.0652261,0.0,0,4.8328843,0.0,0.41205603,53.164288,4.844511,493.25522,-9.2025766
212.4468,6.3082895,5.1144323,0.0,0,4.7875204,0.0,0.41713926,52.961182,4.7957711,493.8605,-9.2018013
212.4512,6.3951945,5.1562471,0.0,0,4.742156,0.0,0.42139766,53.443523,4.7550483,494.46576,-9.2030058
212.4556,6.4489732,5.2051635,0.0,0,4.6967921,0.0,0.42653832,53.677956,4.7012005,495.0827,-9.2022209
212.46,6.446846,5.2486629,0.0,0,4.6514282,0.0,0.43089932,53.317497,4.6565628,495.70114,-9.2027121
212.4644,6.4425974,5.2950721,0.0,0,4.6060643,0.0,0.43588409,53.113937,4.6107874,496.31143,-9.2039528
212.4688,6.4467154,5.339088,0.0,0,4.5606999,0.0,0.4404203,52.868824,4.5711246,496.91669,-9.2027674
212.4732,6.5460424,5.3809552,0.0,0,4.5163713,0.0,0.44478169,53.478111,4.5255456,497.49432,-9.203227
212.4776,6.5892215,5.4296327,0.0,0,4.4732161,0.0,0.44977409,53.532707,4.4775939,498.02066,-9.2023401
212.482,6.5554862,5.4706454,0.0,0,4.4300609,0.0,0.45410782,53.019817,4.4282374,498.44791,-9.2027264
212.4864,6.5559359,5.5161262,0.0,0,4.3869057,0.0,0.45876822,52.756214,4.387711,497.7637,-9.2036905
212.4908,6.63202,5.5586925,0.0,0,4.3437505,0.0,0.46303359,53.133068,4.3467193,497.07947,-9.2031221
212.4952,6.6701264,5.6023359,0.0,0,4.3005953,0.0,0.46761957,53.261311,4.3065429,496.35245,-9.2035942
212.4996,6.6569943,5.6432667,0.0,0,4.2574401,0.0,0.47186965,52.928677,4.2596664,495.6156,-9.2029238
212.504,6.6825104,5.6880808,0.0,0,4.2142849,0.0,0.4765448,52.774876,4.2189331,495.54623,-9.2032871
212.5084,6.7076206,5.7287469,0.0,0,4.1711297,0.0,0.48078755,52.78418,4.1796503,496.03308,-9.2030153
212.5128,6.7951126,5.7730455,0.0,0,4.1279745,0.0,0.48535553,53.285225,4.1359649,496.33386,-9.201396
212.5172,6.8440804,5.8181148,0.0,0,4.0848193,0.0,0.49039185,53.326191,4.0909724,496.14966,-9.2022877
212.5216,6.8630838,5.8630452,0.0,0,4.0418859,0.0,0.4951559,53.264828,4.0473671,495.96735,-9.2035418
212.526,6.8997912,5.9051104,0.0,0,4.000843,0.0,0.49990386,53.261131,4.0014405,495.99365,-9.2027092
212.5304,6.9222479,5.9535832,0.0,0,3.9597998,0.0,0.50484109,53.17754,3.9580848,496.01999,-9.2029963
212.5348,6.8850093,5.9920955,0.0,0,3.9187565,0.0,0.50953984,52.73922,3.9196529,496.72873,-9.2015972
212.5392,6.8759785,6.0321565,0.0,0,3.8777134,0.0,0.51385087,52.417469,3.8847883,497.67612,-9.2038012
212.5436,6.9817386,6.0670176,0.0,0,3.8366702,0.0,0.51797891,52.93388,3.8428841,498.48044,-9.2043686
212.548,7.091495,6.11622,0.0,0,3.7956271,0.0,0.52346784,53.491367,3.7977412,499.12518,-9.2021141
212.5524,7.1050291,6.1533389,0.0,0,3.7545836,0.0,0.52795583,53.435631,3.7577219,499.7215,-9.2024755
212.5568,7.1209526,6.1990571,0.0,0,3.7135406,0.0,0.53311282,53.207298,3.7145741,500.12939,-9.203104
212.5612,7.1728926,6.2371793,0.0,0,3.6724975,0.0,0.53763545,53.330544,3.6705587,500.53729,-9.2023096
212.5656,7.1766338,6.2795343,0.0,0,3.631454,0.0,0.54274303,53.066269,3.6305487,500.63715,-9.2029066
212.57,7.1995783,6.317966,0.0,0,3.5904109,0.0,0.54700875,53.020115,3.5906532,500.71613,-9.2015152
212.5744,7.1707969,6.354682,0.0,0,3.5508492,0.0,0.55153126,52.605434,3.554121,500.76868,-9.2028189
212.5788,7.2188196,6.3944612,0.0,0,3.5118034,0.0,0.55616027,52.675671,3.5142581,500.80817,-9.2028131
212.5832,7.2967334,6.4302616,0.0,0,3.4727578,0.0,0.56042755,53.002575,3.4783108,500.87396,-9.2030535
212.5876,7.4139047,6.4697042,0.0,0,3.433712,0.0,0.56495875,53.642544,3.4356878,500.97922,-9.2025785
212.592,7.4446764,6.514441,0.0,0,3.3946667,0.0,0.57024121,53.636894,3.3943031,501.07062,-9.2024765
212.5964,7.4620686,6.5556545,0.0,0,3.3556211,0.0,0.57490522,53.471363,3.3512764,501.07062,-9.2039108
212.6008,7.4776282,6.5958247,0.0,0,3.3165755,0.0,0.57960391,53.339043,3.3152905,501.07062,-9.2028341
212.6052,7.4781885,6.6321025,0.0,0,3.2775295,0.0,0.58377874,53.060383,3.2742946,501.19562,-9.2031202
212.6096,7.4995279,6.6698141,0.0,0,3.2384839,0.0,0.58823979,53.041801,3.2391436,501.34036,-9.2030983
212.614,7.6022515,6.7115297,0.0,0,3.1994386,0.0,0.59303993,53.50732,3.1994107,501.39893,-9.2026701
212.6184,7.6794491,6.748045,0.0,0,3.160393,0.0,0.59749019,53.745712,3.1621201,501.39893,-9.2039433
212.6228,7.7495627,6.7943425,0.0,0,3.1220655,0.0,0.60279018,53.963867,3.1198711,501.40323,-9.2027788
212.6272,7.7760057,6.8344579,0.0,0,3.0849206,0.0,0.60754406,53.929634,3.0741885,501.41638,-9.2019253
212.6316,7.6418056,6.8711514,0.0,0,3.0477757,0.0,0.61208653,52.775063,3.0422261,501.44275,-9.2032032
212.636,7.6462979,6.9027457,0.0,0,3.0106308,0.0,0.61595082,52.562981,3.0100799,501.6796,-9.203001
212.6404,7.7841411,6.9411626,0.0,0,2.9734862,0.0,0.62048805,53.27478,2.9718401,501.91641,-9.2019854
212.6448,7.8818283,6.9738464,0.0,0,2.9363413,0.0,0.62487024,53.741856,2.9354978,501.99716,-9.2022667
212.6492,7.9680433,7.0161109,0.0,0,2.8991964,0.0,0.62987339,54.02322,2.9002633,502.03665,-9.2018661
212.6536,7.9697533,7.0529408,0.0,0,2.862052,0.0,0.63484836,53.771351,2.860944,501.86288,-9.2031412
212.658,8.0620918,7.0934067,0.0,0,2.8249071,0.0,0.63993239,54.162827,2.8215356,501.49445,-9.2013779
212.6624,8.1333914,7.130219,0.0,0,2.7877622,0.0,0.64478761,54.287868,2.7830667,501.00879,-9.2011948
212.6668,8.1137381,7.1716342,0.0,0,2.7506173,0.0,0.65003026,53.940491,2.749351,500.17984,-9.2023201
212.6712,8.1630449,7.205605,0.0,0,2.7135065,0.0,0.65463281,53.975727,2.7111187,499.35089,-9.2033215
212.6756,8.2101288,7.2426672,0.0,0,2.6781664,0.0,0.65980482,54.002823,2.675859,499.32663,-9.2035265
212.68,8.2986135,7.2751007,0.0,0,2.6428344,0.0,0.66403145,54.367077,2.6374004,499.31348,-9.2019596
212.6844,8.3030691,7.3149519,0.0,0,2.6075025,0.0,0.66934508,54.143211,2.5991681,499.2247,-9.2009077
212.6888,8.2263308,7.3462234,0.0,0,2.5721705,0.0,0.6734277,53.413715,2.566535,499.10626,-9.2043877
212.6932,8.3112459,7.3781862,0.0,0,2.5368385,0.0,0.67772102,53.699608,2.5346117,498.56152,-9.2021732
212.6976,8.4638243,7.4114985,0.0,0,2.5015066,0.0,0.68210626,54.488476,2.4994059,497.49573,-9.2027245
212.702,8.5118065,7.4474006,0.0,0,2.4661744,0.0,0.68691152,54.539314,2.4587929,496.61893,-9.2015181
212.7064,8.5232267,7.4837427,0.0,0,2.4308424,0.0,0.69152963,54.35648,2.4250331,496.59262,-9.202383
212.7108,8.5945129,7.5165105,0.0,0,2.3955104,0.0,0.69588971,54.539463,2.392544,496.56628,-9.2024174
212.7152,8.7176008,7.5572658,0.0,0,2.3601785,0.0,0.70125645,55.029182,2.3542047,496.9968,-9.2015457
212.7196,8.7464066,7.5909128,0.0,0,2.3248465,0.0,0.70547515,54.984901,2.3182242,497.47049,-9.2040281
212.724,8.7490177,7.6272645,0.0,0,2.2906365,0.0,0.71044886,54.761494,2.2884407,497.52802,-9.2028208
212.7284,8.7880917,7.6612401,0.0,0,2.2570291,0.0,0.71482235,54.734097,2.2507708,497.35696,-9.2027178
212.7328,8.8845501,7.6970582,0.0,0,2.2234221,0.0,0.71943605,55.068207,2.2171037,497.27029,-9.2045631
212.7372,8.907341,7.731523,0.0,0,2.1898148,0.0,0.72402418,55.019989,2.1826575,497.32291,-9.2017498
212.7416,8.9325438,7.7650065,0.0,0,2.1562076,0.0,0.72849953,54.901264,2.1520545,497.42725,-9.2018137
212.746,9.0290327,7.797359,0.0,0,2.1226003,0.0,0.73297215,55.215446,2.1171355,497.95358,-9.2030268
212.7504,9.1938076,7.8395181,0.0,0,2.0889933,0.0,0.73854184,55.887012,2.0807586,498.47989,-9.2018223
212.7548,9.2484503,7.8725867,0.0,0,2.0553861,0.0,0.74345875,55.99221,2.0459893,498.90665,-9.2023191
212.7592,9.1625576,7.9113154,0.0,0,2.0217791,0.0,0.74853909,55.187859,2.0113988,499.31454,-9.2019701
212.7636,9.1612253,7.9375062,0.0,0,1.9881717,0.0,0.75276005,54.932407,1.9794567,499.53406,-9.2018347
212.768,9.2127132,7.9738493,0.0,0,1.9545646,0.0,0.75760621,54.939011,1.9543768,499.61301,-9.2026119
212.7724,9.3611822,7.9994297,0.0,0,1.921427,0.0,0.76154578,55.626514,1.9218131,498.56152,-9.2016821
212.7768,9.4751158,8.0370064,0.0,0,1.8894565,0.0,0.76690179,56.046009,1.8834031,494.92877,-9.2016449
212.7812,9.5017986,8.0666294,0.0,0,1.8574861,0.0,0.77172184,55.915802,1.8489341,491.34393,-9.2029324
212.7856,9.5768156,8.1006718,0.0,0,1.8255159,0.0,0.77650213,56.076092,1.8181599,489.02808,-9.1999369
212.79,9.6325874,8.1317482,0.0,0,1.7935454,0.0,0.78134966,56.135674,1.7877476,486.71222,-9.2015333
212.7944,9.7221622,8.1636858,0.0,0,1.761575,0.0,0.78624582,56.377575,1.7536644,487.62167,-9.2011089
212.7988,9.7499495,8.1940413,0.0,0,1.7296046,0.0,0.79077828,56.311352,1.7197163,489.50439,-9.2029314
212.8032,9.8195448,8.2250671,0.0,0,1.6976342,0.0,0.79553789,56.390976,1.6906687,490.56415,-9.2018518
212.8076,9.9107571,8.2560263,0.0,0,1.6656637,0.0,0.80030596,56.67804,1.6613693,490.80103,-9.2016859
212.812,10.021111,8.2885609,0.0,0,1.6336933,0.0,0.80521774,57.065071,1.6287218,490.9769,-9.2013521
212.8164,10.065922,8.3203363,0.0,0,1.601723,0.0,0.8098135,57.051258,1.5924343,490.95059,-9.2032156
212.8208,10.100409,8.3526125,0.0,0,1.5697526,0.0,0.81461841,56.959866,1.5636796,490.92426,-9.2007084
212.8252,10.184406,8.3840275,0.0,0,1.5392203,0.0,0.8190285,57.143261,1.5322101,491.56998,-9.2031174
212.8296,10.332493,8.4153643,0.0,0,1.5088075,0.0,0.82383168,57.778809,1.5016844,492.24106,-9.2016115
212.834,10.364512,8.4484577,0.0,0,1.4783946,0.0,0.8286621,57.647419,1.4681579,492.82974,-9.2013531
212.8384,10.347297,8.4782295,0.0,0,1.4479818,0.0,0.83282226,57.254135,1.437479,493.38242,-9.2014933
212.8428,10.43834,8.5078316,0.0,0,1.4175692,0.0,0.83731741,57.473236,1.4079137,493.92941,-9.2016726
212.8472,10.490148,8.5383835,0.0,0,1.3871564,0.0,0.84184647,57.579514,1.382352,494.4689,-9.2015142
212.8516,10.567836,8.5696239,0.0,0,1.3567436,0.0,0.84660214,57.718903,1.3497276,494.98117,-9.2008619
212.856,10.636041,8.5962248,0.0,0,1.3263308,0.0,0.85060269,57.864147,1.3201227,495.34958,-9.2016745
212.8604,10.790874,8.631197,0.0,0,1.295918,0.0,0.85580987,58.347107,1.2916213,495.71799,-9.200263
212.8648,10.953062,8.6637125,0.0,0,1.2655051,0.0,0.86100584,58.9151,1.2559121,495.85196,-9.2007475
212.8692,10.982445,8.6926365,0.0,0,1.2350924,0.0,0.86520064,58.87746,1.227905,495.95724,-9.2018147
212.8736,11.014814,8.7231121,0.0,0,1.2055119,0.0,0.8703624,58.767506,1.1951554,495.79208,-9.2019672
212.878,11.055465,8.7564955,0.0,0,1.1765862,0.0,0.87550664,58.68206,1.1667383,495.46313,-9.2014656
212.8824,11.130279,8.7808018,0.0,0,1.1476607,0.0,0.87972873,58.746204,1.1409892,494.66296,-9.200758
212.8868,11.240238,8.8111048,0.0,0,1.118735,0.0,0.88466877,59.078148,1.1105318,493.00491,-9.2008991
212.8912,11.325652,8.8370819,0.0,0,1.0898094,0.0,0.88926953,59.272987,1.0864135,491.15118,-9.2021093
212.8956,11.457088,8.8686314,0.0,0,1.0608838,0.0,0.89433759,59.640976,1.0526218,487.22775,-9.2010994
212.9,11.542165,8.8961248,0.0,0,1.0319582,0.0,0.8991788,59.742294,1.0238999,483.30429,-9.2014179
212.9044,11.6097,8.9244432,0.0,0,1.0030326,0.0,0.90413994,59.856926,0.99628949,479.56284,-9.2014036
212.9088,11.730471,8.9492035,0.0,0,0.97410703,0.0,0.90826988,60.21059,0.96541309,475.86182,-9.1998024
212.9132,11.770894,8.9837465,0.0,0,0.94518137,0.0,0.91446602,60.067101,0.93803489,474.12399,-9.2008123
212.9176,11.871336,9.0065269,0.0,0,0.91625583,0.0,0.91813338,60.327099,0.9041037,473.99231,-9.2014589
212.922,11.958339,9.0353174,0.0,0,0.88760793,0.0,0.92313045,60.459969,0.8820762,474.48428,-9.2003841
212.9264,12.038412,9.0606384,0.0,0,0.86009914,0.0,0.92727268,60.667927,0.85197723,476.56552,-9.2014828
212.9308,12.166651,9.0879126,0.0,0,0.83259028,0.0,0.93218547,60.995358,0.8228423,478.64224,-9.1997232
212.9352,12.233626,9.1158743,0.0,0,0.80508155,0.0,0.93663681,61.03199,0.79271257,480.39374,-9.201355
212.9396,12.299914,9.1404638,0.0,0,0.77757269,0.0,0.94066346,61.08844,0.76966703,482.1452,-9.2002897
212.944,12.32015,9.1686344,0.0,0,0.75006396,0.0,0.94532019,60.975254,0.74138182,483.47455,-9.2010269
212.9484,12.374817,9.1937037,0.0,0,0.7225551,0.0,0.94935703,60.985256,0.71466601,484.65976,-9.2012262
212.9528,12.595674,9.2197599,0.0,0,0.69504631,0.0,0.9536224,61.803905,0.68774796,485.67529,-9.1991577
212.9572,12.847116,9.2507982,0.0,0,0.66753751,0.0,0.95882452,62.683079,0.65817374,486.50494,-9.2013636
212.9616,12.914498,9.2821941,0.0,0,0.64002872,0.0,0.96395302,62.745617,0.63066727,487.22443,-9.2012787
212.966,12.924163,9.3079948,0.0,0,0.61251992,0.0,0.96840578,62.481949,0.60136098,487.52731,-9.1996622
212.9704,12.990645,9.3360119,0.0,0,0.58501112,0.0,0.97303337,62.50956,0.57724726,487.8302,-9.2010956
212.9748,13.138088,9.3617573,0.0,0,0.55860835,0.0,0.97763681,62.85854,0.54888749,488.35596,-9.2013636
212.9792,12.266676,9.3779621,0.0,0,0.53242838,0.0,0.98019725,58.690151,0.52969027,488.89575,-9.2020693
212.9836,11.680638,9.3764925,0.0,0,0.5062483,0.0,0.98022979,55.825058,0.51095039,489.58597,-9.2013445
212.988,11.128795,9.3856506,0.0,0,0.48006836,0.0,0.98120195,53.165581,0.49623314,490.34937,-9.2019854
212.9924,10.834889,9.3841305,0.0,0,0.45388839,0.0,0.98156106,51.684566,0.48159927,490.99557,-9.2030678
212.9968,10.603518,9.3924217,0.0,0,0.42770836,0.0,0.98296326,50.57156,0.45769665,491.46927,-9.2029858
213.0012,10.314244,9.3917789,0.0,0,0.40152836,0.0,0.9832502,49.126606,0.43506783,491.92322,-9.2037973
213.0056,9.8707829,9.3978987,0.0,0,0.37534833,0.0,0.98439527,46.965885,0.42954901,492.25217,-9.2039061
213.01,9.4581881,9.3969173,0.0,0,0.34916836,0.0,0.98470759,44.983669,0.41775832,492.58109,-9.2045727
213.0144,9.1895199,9.3966494,0.0,0,0.32298836,0.0,0.98475045,43.705349,0.41560039,492.87579,-9.2048292
213.0188,9.1182623,9.3963232,0.0,0,0.29680836,0.0,0.98500031,43.351284,0.39896941,493.16528,-9.2024946
213.0232,9.2068872,9.4028807,0.0,0,0.27123061,0.0,0.98641002,43.697098,0.37707809,493.49423,-9.2021255
213.0276,9.4551678,9.3979912,0.0,0,0.24633542,0.0,0.98569244,44.918644,0.34218252,493.84949,-9.2030602
213.032,9.6713009,9.4041739,0.0,0,0.2214402,0.0,0.9869343,45.873192,0.30772617,494.16544,-9.2019463
213.0364,9.8245144,9.4048452,0.0,0,0.19654506,0.0,0.98715317,46.571064,0.27585387,494.40231,-9.2020979
213.0408,9.8645363,9.4067383,0.0,0,0.17164986,0.0,0.98759568,46.850098,0.24615294,494.62827,-9.2029982
213.0452,9.8468065,9.4078884,0.0,0,0.14675467,0.0,0.9877761,46.710468,0.2172263,494.69406,-9.2012587
213.0496,9.8255911,9.4099636,0.0,0,0.12185945,0.0,0.98826241,46.539112,0.19065656,494.75986,-9.2031689
213.054,9.7835274,9.4118099,0.0,0,0.096964255,0.0,0.98814058,46.384914,0.16634832,494.82565,-9.202034
213.0584,9.722538,9.416132,0.0,0,0.072069056,0.0,0.98883706,46.071156,0.146834,494.89145,-9.2023764
213.0628,9.6428194,9.4187155,0.0,0,0.04717385,0.0,0.98898649,45.680157,0.12409888,494.94336,-9.202157
213.0672,9.5781116,9.4189405,0.0,0,0.02227865,0.0,0.98888987,45.375515,0.10101968,494.98285,-9.2028437
213.0716,9.5515041,9.4236994,0.0,0,-0.0025527282,0.0,0.98929065,45.191559,0.080981851,495.00867,-9.2031956
213.076,9.5041637,9.4234209,0.0,0,-0.026840733,0.0,0.98913395,44.986996,0.066905104,494.99551,-9.2029543
213.0804,9.4085083,9.4305267,0.0,0,-0.05112873,0.0,0.99008286,44.516136,0.048597869,494.98236,-9.2019024
213.0848,9.3155632,9.4288702,0.0,0,-0.075416729,0.0,0.98981643,44.055363,0.033923112,494.94312,-9.201458
213.0892,9.2565022,9.4333715,0.0,0,-0.099704728,0.0,0.99025083,43.760483,0.017056648,494.90366,-9.2015839
213.0936,9.1561222,9.4341812,7.4425406,0,0.31744841,500.0,0.99041784,43.318707,0.0041478998,494.88318,-9.2018299
213.098,8.6771402,9.4364967,17.740187,0,1.1143054,500.0,0.99055713,41.081341,0.0070671844,494.87003,-9.202199
213.1024,5.3400941,9.4224911,23.356934,0,1.9111637,500.0,0.98861361,25.497931,0.17650534,494.8808,-9.2043657
213.1068,-0.19160001,9.3920975,23.356934,0,2.7080209,500.0,0.98282474,-0.89842671,0.53733325,494.92029,-9.2084293
213.1112,-0.073469885,9.3768177,23.356934,0,3.504879,500.0,0.98048657,-0.31371078,1.6494175,494.95483,-9.2079029
213.1156,0.042805843,9.4189911,23.356934,0,4.3017359,500.0,0.98814505,0.0961302,2.8676784,494.96802,-9.2077475
213.12,-0.12660867,9.4078455,23.356934,0,5.0985942,500.0,0.98638624,-0.55507636,3.6971362,494.98117,-9.2070379
213.1244,0.1034622,9.40557,23.356934,0,5.8954515,500.0,0.9861306,0.44911584,4.4655395,494.9339,-9.2062178
213.1288,-0.07022246,9.4008675,23.356934,0,6.6923089,500.0,0.98574609,-0.30071419,5.2435179,494.88129,-9.2062225
213.1332,-0.086916603,9.4056931,23.356934,0,7.4891667,500.0,0.98670369,-0.45184445,6.0508265,494.82864,-9.20679
213.1376,0.042687707,9.3998337,23.356934,0,8.286025,500.0,0.98579699,0.16763216,6.884469,494.776,-9.20679
213.142,-0.14724807,9.3985729,23.356934,0,9.0828829,500.0,0.98592865,-0.75273532,7.7007442,494.73343,-9.2066879
213.1464,0.086853258,9.3964815,23.356934,0,9.8797407,500.0,0.98560667,0.50168431,8.5416059,494.70709,-9.2046175
213.1508,-0.18224393,9.3990421,23.430147,0,10.676599,500.0,0.98613167,-0.89406216,9.3580227,494.6778,-9.2055979
213.1552,0.094089814,9.3959761,24.074358,0,11.473455,500.0,0.98566711,0.44828913,10.162766,494.62515,-9.2053566
213.1596,-0.13200529,9.3946638,24.718565,0,12.270313,500.0,0.98543519,-0.59864503,10.956726,494.57254,-9.2050743
213.164,0.057147834,9.3958158,24.818115,0,13.067171,500.0,0.98552072,0.25398374,11.734873,494.56439,-9.2049103
213.1684,-0.14426786,9.3959894,24.818115,0,13.864029,500.0,0.98540998,-0.62571895,12.512177,494.56439,-9.2038794
213.1728,-0.010742378,9.3946667,24.818115,0,14.660887,500.0,0.98511183,-0.10272633,13.303546,494.56439,-9.2042217
213.1772,-0.049616296,9.3940315,24.818115,0,15.457745,500.0,0.98451471,-0.12993634,14.104934,494.56439,-9.2037802
213.1816,-0.013619411,9.3969069,24.818115,0,16.254602,500.0,0.98478013,-0.13599202,14.910864,494.55624,-9.2041655
213.186,-0.045744203,9.396225,24.818115,0,17.05146,500.0,0.98454821,-0.103847,15.728292,494.52994,-9.2022953
213.1904,-0.076798759,9.3992405,24.818115,0,17.848316,500.0,0.98471808,-0.45631313,16.515209,494.50363,-9.2030964
213.1948,0.0016517349,9.3973169,24.818115,0,18.0,500.0,0.98427778,0.10296508,17.305346,494.47729,-9.2028723
213.1992,-0.0030382618,9.4017963,24.818115,0,18.0,500.0,0.98472005,-0.039829127,17.991665,494.45099,-9.2044992
213.2036,-0.039938785,9.4034052,24.818115,0,18.0,500.0,0.98500377,-0.12204926,18.411777,494.37955,-9.2100658
213.208,-0.058904015,9.4195023,24.818115,0,18.0,500.0,0.98749626,-0.3633644,18.421213,494.2948,-9.2213249
213.2124,0.33939546,9.4326878,25.217173,0,18.0,500.0,0.99021095,1.6267927,18.207907,494.23126,-9.2405176
213.2168,0.3039301,9.4331112,25.822632,0,18.0,500.0,0.99005926,1.4114277,18.067387,494.17862,-9.269824
213.2212,0.30084211,9.4288273,26.191408,0,18.0,500.0,0.98962027,1.4134276,18.048462,494.11057,-9.3062
213.2256,0.26205447,9.4326115,26.191408,0,18.0,500.0,0.99006104,1.2595397,18.078424,494.01846,-9.3458853
213.23,0.26320198,9.4279213,26.191408,0,18.0,500.0,0.98986441,1.2717656,18.117905,493.93765,-9.381135
213.2344,0.26180828,9.4309788,26.191408,0,18.0,500.0,0.99029195,1.2549093,18.136976,493.93765,-9.4132767
213.2388,0.30046108,9.4261007,26.191408,0,18.0,500.0,0.98994112,1.39113,18.13703,493.93765,-9.4454565
213.2432,0.30011359,9.4274378,26.191408,0,18.0,500.0,0.99024963,1.4015665,18.136854,493.90393,-9.4804821
213.2476,0.27449903,9.4222317,26.191408,0,18.0,500.0,0.98954129,1.3036311,18.133032,493.86444,-9.5129757
213.252,0.25833783,9.4278393,26.520868,0,18.0,500.0,0.99098825,1.2229315,18.125643,493.80954,-9.5476971
213.2564,0.28800038,9.4230442,27.082733,0,18.0,500.0,0.99012047,1.3470328,18.120802,493.74374,-9.578352
213.2608,0.31358409,9.4240866,27.46582,0,18.0,500.0,0.99064273,1.4531918,18.113487,493.69052,-9.6126127
213.2652,0.26956642,9.4231892,27.46582,0,18.0,500.0,0.99040812,1.2521275,18.112022,493.66418,-9.6475954
213.2696,0.27408794,9.4243174,27.46582,0,18.0,500.0,0.9908421,1.3033552,18.110022,493.63589,-9.6776714
213.274,0.28330442,9.4224443,27.46582,0,18.0,500.0,0.99030137,1.3215978,18.111073,493.5701,-9.7108288
213.2784,0.31884584,9.4233055,27.46582,0,18.0,500.0,0.99054945,1.4661801,18.106426,493.5043,-9.7462587
213.2828,0.28676224,9.4212236,27.46582,0,18.0,500.0,0.9898265,1.3775504,18.101652,493.46939,-9.7808285
213.2872,0.27439189,9.421155,27.46582,0,18.0,500.0,0.98968321,1.3025975,18.106493,493.44308,-9.8136721
213.2916,0.2669192,9.4229374,27.737003,0,18.0,500.0,0.98981822,1.2930501,18.099293,493.40326,-9.8466702
213.296,0.30487663,9.424511,28.264963,0,18.0,500.0,0.98987299,1.4227623,18.097559,493.35062,-9.8796234
213.3004,0.29010528,9.4246206,28.66333,0,18.0,500.0,0.98937798,1.4036982,18.09688,493.298,-9.914526
213.3048,0.258461,9.4235153,28.66333,0,18.0,500.0,0.98912078,1.1919978,18.097136,493.24536,-9.9472809
213.3092,0.26357597,9.427578,28.66333,0,18.0,500.0,0.98961902,1.2918916,18.096582,493.19272,-9.9797325
213.3136,0.30975699,9.425415,28.66333,0,18.0,500.0,0.98908317,1.4327638,18.093307,493.1658,-10.011077
213.318,0.31295452,9.4323425,28.66333,0,18.0,500.0,0.99013042,1.4827017,18.09366,493.1395,-10.046928
213.3224,0.27677631,9.4288588,28.66333,0,18.0,500.0,0.98947811,1.3435806,18.087889,493.10385,-10.079487
213.3268,0.28523654,9.4326401,28.66333,0,18.0,500.0,0.98977578,1.3621469,18.090637,493.06436,-10.112829
213.3312,0.29967383,9.4260159,28.883303,0,18.0,500.0,0.98920268,1.388038,18.086988,493.0307,-10.146585
213.3356,0.33651617,9.4334335,29.3822,0,18.0,500.0,0.99019575,1.6466585,18.081657,493.00436,-10.17999
213.34,0.29582661,9.4280405,29.794922,0,18.0,500.0,0.98969233,1.4000906,18.086281,492.97125,-10.215231
213.3444,0.28771198,9.4325409,29.794922,0,18.0,500.0,0.99041706,1.3455764,18.085209,492.90546,-10.248934
213.3488,0.29931211,9.4281769,29.794922,0,18.0,500.0,0.99002028,1.3742462,18.076675,492.83966,-10.280937
213.3532,0.33111107,9.4283848,29.794922,0,18.0,500.0,0.99004179,1.519767,18.078955,492.78577,-10.311863
213.3576,0.31593466,9.428793,29.794922,0,18.0,500.0,0.99079019,1.4995153,18.077375,492.73312,-10.346881
213.362,0.28713939,9.4289341,29.794922,0,18.0,500.0,0.99086201,1.3455652,18.078272,492.71399,-10.380693
213.3664,0.29946524,9.4251328,29.794922,0,18.0,500.0,0.99033612,1.3902251,18.076954,492.71399,-10.412416
213.3708,0.32487753,9.4253225,29.969692,0,18.0,500.0,0.99077737,1.5066595,18.077831,492.69461,-10.447686
213.3752,0.32047454,9.423111,30.444374,0,18.0,500.0,0.99040365,1.5625442,18.072216,492.642,-10.482415
213.3796,0.29371545,9.42311,30.871582,0,18.0,500.0,0.99067539,1.3764155,18.072166,492.58411,-10.514198
213.384,0.28772897,9.4200783,30.871582,0,18.0,500.0,0.98986995,1.3658887,18.069176,492.47885,-10.544823
213.3884,0.32461378,9.42206,30.871582,0,18.0,500.0,0.9903754,1.5134645,18.071342,492.37357,-10.579837
213.3928,0.33908442,9.4218864,31.242258,0,18.0,500.0,0.99001408,1.6224045,18.070011,492.31207,-10.612146
213.3972,0.29971895,9.4222946,31.687878,0,18.0,500.0,0.99006134,1.396405,18.065182,492.25946,-10.646727
213.4016,0.29706728,9.4218302,31.882326,0,18.0,500.0,0.98965007,1.3795503,18.069288,492.19199,-10.679166
213.406,0.31753629,9.4242849,31.882326,0,18.0,500.0,0.98996317,1.4437453,18.062311,492.11304,-10.713237
213.4104,0.33050263,9.4229126,31.882326,0,18.0,500.0,0.98946154,1.5723614,18.066135,492.03412,-10.747464
213.4148,0.33130637,9.4246826,31.882326,0,18.0,500.0,0.98955035,1.5790049,18.061577,491.95517,-10.779523
213.4192,0.28829998,9.4251804,31.882326,0,18.0,500.0,0.98935866,1.3604612,18.061872,491.87909,-10.814061
213.4236,0.31387597,9.424799,31.882326,0,18.0,500.0,0.98912132,1.4541764,18.062822,491.90536,-10.846993
213.428,0.33752334,9.4269857,31.882326,0,18.0,500.0,0.98921543,1.6353375,18.060682,491.93167,-10.879563
213.4324,0.31941545,9.4251938,32.205887,0,18.0,500.0,0.98897791,1.5150642,18.060526,491.91806,-10.915588
213.4368,0.29481456,9.429924,32.63213,0,18.0,500.0,0.98949426,1.3827955,18.057058,491.89175,-10.946506
213.4412,0.29834294,9.4266739,32.849121,0,18.0,500.0,0.98927015,1.3626559,18.059885,491.85251,-10.980733
213.4456,0.32784384,9.4282827,32.849121,0,18.0,500.0,0.98912084,1.537699,18.060581,491.7999,-11.013567
213.45,0.32990721,9.4282246,32.849121,0,18.0,500.0,0.9894824,1.5528506,18.055105,491.75311,-11.045925
213.4544,0.32325464,9.431798,32.849121,0,18.0,500.0,0.99021149,1.5260266,18.05722,491.72681,-11.080792
213.4588,0.29972303,9.4273167,32.849121,0,18.0,500.0,0.98979574,1.3916459,18.056332,491.70047,-11.112374
213.4632,0.33945233,9.4299688,32.849121,0,18.0,500.0,0.9902547,1.5913836,18.054195,491.64905,-11.146842
213.4676,0.34173417,9.4257212,32.849121,0,18.0,500.0,0.99005485,1.5843078,18.055429,491.59641,-11.180835
213.472,0.30755362,9.4283371,33.128384,0,18.0,500.0,0.99056703,1.4692879,18.049837,491.5257,-11.214188
213.4764,0.27939937,9.4259911,33.535252,0,18.0,500.0,0.99039549,1.3459191,18.053236,491.44675,-11.248358
213.4808,0.33262613,9.4279785,33.771973,0,18.0,500.0,0.9909451,1.5576135,18.0516,491.3678,-11.282477
213.4852,0.35177252,9.4207945,33.771973,0,18.0,500.0,0.98978138,1.685246,18.046648,491.28885,-11.313797
213.4896,0.31843984,9.425169,31.53845,0,18.0,500.0,0.99080151,1.5004721,18.0495,491.22174,-11.349271
214.8911,0.20664251,9.4363785,0.0,0,18.0,4.0912032e-17,0.99179095,0.98072213,18.001425,468.81497,-11.479361
217.0911,0.1981508,9.4521589,0.0,0,18.0,1.4012985e-45,0.99466163,0.94074893,18.00049,443.84863,-11.481201
219.2911,0.16497773,9.466383,0.0,0,18.0,1.4012985e-45,0.99718803,0.77548862,18.000414,421.564,-11.480147
221.4911,0.17083628,9.4794836,0.0,0,18.0,1.4012985e-45,0.99959844,0.80079681,18.000595,400.71027,-11.479866
223.6911,0.17923839,9.4902887,0.0,0,18.0,1.4012985e-45,1.0015795,0.83625925,17.999643,381.32098,-11.48077
225.8911,0.17484502,9.5010729,0.0,0,18.0,1.4012985e-45,1.0034391,0.82241601,18.000519,362.93417,-11.480796
228.0911,0.16729029,9.5121393,0.0,0,18.0,1.4012985e-45,1.0055346,0.78092015,17.999416,345.33777,-11.480488
230.2911,0.16604431,9.5220757,0.0,0,18.0,1.4012985e-45,1.0073557,0.77178419,18.000025,328.80554,-11.480333
232.4911,0.17605492,9.5320568,0.0,0,18.0,1.4012985e-45,1.0091338,0.81217271,17.999729,312.74869,-11.480835
234.6911,0.1658853,9.5413208,0.0,0,18.0,1.4012985e-45,1.0108554,0.76625514,18.000568,297.45581,-11.480924
236.8911,0.17648923,9.5497103,0.0,0,18.0,1.4012985e-45,1.0123423,0.8172307,18.000244,283.2735,-11.481359
239.0911,0.17229398,9.5587063,0.0,0,18.0,1.4012985e-45,1.0140672,0.79698235,18.00061,269.63986,-11.481842
241.2911,0.15215994,9.5664778,0.0,0,18.0,1.4012985e-45,1.0155277,0.70344114,18.000265,256.8269,-11.480711
243.4911,0.15746748,9.574645,0.0,0,18.0,1.4012985e-45,1.0169216,0.72668117,17.998266,244.64009,-11.480388
245.6911,0.16460246,9.5821056,0.0,0,18.0,1.4012985e-45,1.0183235,0.75484991,17.999294,233.07344,-11.480515
247.8911,0.17251906,9.5896215,0.0,0,18.0,1.4012985e-45,1.0197326,0.78597158,17.998938,222.15256,-11.480889
250.0911,0.16492373,9.5965881,0.0,0,18.0,1.4012985e-45,1.0210224,0.76020038,17.999233,212.04828,-11.481532
252.2911,0.15878332,9.602705,0.0,0,18.0,1.4012985e-45,1.022179,0.73043573,17.999702,202.29277,-11.481598
254.4911,0.15740941,9.6088591,0.0,0,18.0,1.4012985e-45,1.0232468,0.7204712,17.999704,193.20418,-11.481509
256.6911,0.15489085,9.6153259,0.0,0,18.0,1.4012985e-45,1.024539,0.70407408,18.000172,184.40494,-11.481609
258.8911,0.14885636,9.620718,0.0,0,18.0,1.4012985e-45,1.0255486,0.67736268,18.000269,176.09601,-11.481003
261.0911,0.15475781,9.6272783,0.0,0,18.0,1.4012985e-45,1.0266565,0.70003498,17.998844,168.21938,-11.481352
263.2911,0.15254641,9.6320038,0.0,0,18.0,1.4012985e-45,1.0275986,0.69694132,18.000544,160.75346,-11.481494
265.4911,0.14658757,9.6367159,0.0,0,18.0,1.4012985e-45,1.0284866,0.67078429,17.999577,153.87651,-11.481611
267.6911,0.1465901,9.6411505,0.0,0,18.0,1.4012985e-45,1.0292977,0.66411185,18.000633,147.22301,-11.481757
269.8911,0.15491731,9.6459608,0.0,0,18.0,1.4012985e-45,1.0302151,0.70423728,18.000927,140.82814,-11.481485
272.0911,0.13652644,9.6501226,0.0,0,18.0,1.4012985e-45,1.0309428,0.61913377,18.000443,134.7412,-11.480952
273.4911,0.15271199,9.6523571,0.0,0,18.0,1.4012985e-45,1.0314054,0.69872069,17.999954,131.07635,-11.481459