File: examples/dan-msc-case-studies/CS3/data/01 raw data/baron_test_123.csv
Time(sec),Force(kN),Jaw(mm),PowAngle(deg),Power(W),Pram,PTemp,Strain,Stress(MPa),Stroke(mm),TC1(C),wedge(mm)
0.0,0.25257403,0.51738846,0.0,0,11.076097,0.00016150315,0.035093214,3.0786638,11.076659,22.567295,-9.1269617
1.2,0.21873248,-2.0380014e-05,0.0,0,11.076097,3.5159011,3.6266949e-06,2.7835913,11.076282,22.54331,-9.4949951
2.4,0.18942016,-0.00048844604,0.0,0,11.076097,7.1159029,-1.6723819e-05,2.4027431,11.076317,22.565836,-9.4910822
3.6,0.17733453,-0.00018277306,0.0,0,11.076097,10.715902,-2.4117955e-05,2.2712681,11.076126,22.584642,-9.4903374
4.8,0.16208793,-0.00093000033,0.0,0,11.076097,14.315904,-6.1676648e-05,2.0536504,11.076751,22.60964,-9.488224
6.0,0.14416786,-0.0010555311,0.0,0,11.076097,17.915905,-6.8022469e-05,1.8328261,11.075727,22.540058,-9.4856253
7.2,0.13399559,-0.0011197435,0.0,0,11.076097,21.515907,-7.1584152e-05,1.7063519,11.075778,22.513428,-9.4833174
8.4,0.22127998,-0.0003681893,15.235278,0,11.076097,25.115908,-1.4561603e-05,2.8075914,11.076007,22.514366,-9.4807158
9.6,0.35973874,0.0016509749,30.810211,0,11.076097,28.715908,9.5458287e-05,4.5759258,11.07686,22.942455,-9.4786777
10.8,0.50387585,0.0016979256,38.979435,0,11.076097,32.315914,0.00012661847,6.4267836,11.075534,24.953863,-9.4768391
12.0,0.6349498,-0.00016135236,42.809727,0,11.076097,35.915916,1.0616895e-05,8.0836306,11.076181,28.932497,-9.4755602
13.2,0.67352021,-0.0038639507,44.174435,0,11.076097,39.515911,-0.00027295732,8.5838652,11.075295,34.137165,-9.4735794
14.4,0.67169732,-0.0087453155,44.604488,0,11.076097,43.11591,-0.00058357918,8.5569019,11.076259,39.595203,-9.4713087
15.6,0.67654234,-0.013116033,43.527851,0,11.076097,46.715904,-0.00087920547,8.6120853,11.075771,45.293888,-9.4687986
16.8,0.67608607,-0.017626617,41.804497,0,11.076097,50.315903,-0.001175081,8.6304235,11.076106,50.508659,-9.4669399
18.0,0.6710909,-0.01989552,40.496616,0,11.076097,53.915905,-0.0013154319,8.5415268,11.07596,54.968624,-9.4647446
19.2,0.67764348,-0.022089781,39.243168,0,11.076097,57.515903,-0.0014878303,8.643569,11.076081,58.873913,-9.4628763
20.4,0.68003714,-0.02459825,39.225655,0,11.076097,61.115913,-0.001630852,8.6758957,11.0762,62.009373,-9.4609985
21.6,0.6723823,-0.026645623,39.24316,0,11.076097,64.715935,-0.0017630057,8.5995312,11.075529,64.975769,-9.4585981
22.8,0.69119972,-0.029149918,40.572193,0,11.076097,68.315918,-0.0019421028,8.8212004,11.076504,67.824883,-9.4567413
24.0,0.69640702,-0.032115262,41.800903,0,11.076097,71.915932,-0.0021233815,8.8767233,11.076248,70.848701,-9.4548559
25.2,0.68973857,-0.036553342,42.887032,0,11.076097,75.51593,-0.0024628176,8.7927446,11.076247,74.194565,-9.452301
26.4,0.69524777,-0.038806375,43.527828,0,11.076097,79.115929,-0.0025756876,8.8857689,11.076369,77.72126,-9.450016
27.6,0.69017571,-0.042181332,44.077145,0,11.076097,82.715919,-0.0028046723,8.8119488,11.077151,81.518799,-9.4479856
28.8,0.69892037,-0.045501411,44.602013,0,11.076097,86.315933,-0.0030205064,8.9306383,11.075821,85.210136,-9.4459972
30.0,0.71450812,-0.049106952,44.604488,0,11.076097,89.915932,-0.0032472503,9.1186876,11.07633,89.036499,-9.4440813
31.2,0.71396005,-0.051897641,44.977646,0,11.076097,93.515945,-0.0034658047,9.1200294,11.076381,92.77285,-9.4423647
32.4,0.72258145,-0.055326119,45.16917,0,11.076097,97.115929,-0.003684273,9.2410631,11.075756,96.373451,-9.4404135
33.6,0.72538698,-0.058484409,45.615231,0,11.076097,100.71593,-0.0039110496,9.2642717,11.076098,99.896866,-9.4383116
34.8,0.72892761,-0.061744805,46.109619,0,11.076097,104.31593,-0.0041012596,9.3222027,11.075795,103.54993,-9.4359627
36.0,0.73001558,-0.065585658,46.208977,0,11.076097,107.91595,-0.0043577892,9.3298569,11.075315,107.19406,-9.4336109
37.2,0.7392903,-0.068747044,46.582027,0,11.076097,111.51592,-0.0045574172,9.4651251,11.076157,110.81293,-9.4311686
38.4,0.73615867,-0.072258033,46.582027,0,11.076097,115.11594,-0.0047891783,9.414937,11.075681,114.58928,-9.4290466
39.6,0.74534971,-0.075264379,46.801685,0,11.076097,118.71593,-0.0050028833,9.5423813,11.076015,118.30644,-9.4267979
40.8,0.74331999,-0.07883691,47.046844,0,11.076097,122.31594,-0.0052192034,9.5198231,11.077056,122.00912,-9.4244003
42.0,0.75301564,-0.082666352,47.05444,0,11.076097,125.91594,-0.0055164373,9.6439123,11.075093,125.46191,-9.4221478
43.2,0.76694536,-0.08605317,47.504883,0,11.076097,129.51605,-0.0057100039,9.8226614,11.076065,128.96739,-9.4205933
44.4,0.76660633,-0.089584611,47.504883,0,11.076097,133.11592,-0.0059710513,9.827734,11.076921,132.63103,-9.4187403
45.6,0.77321273,-0.093504384,47.955318,0,11.076097,136.71593,-0.0062211826,9.9128103,11.076493,136.04646,-9.4166241
46.8,0.78193033,-0.096919835,48.383785,0,11.076097,140.31593,-0.0064572147,10.018482,11.077096,139.62305,-9.4152899
48.0,0.7855252,-0.10118843,48.80925,0,11.076097,143.91592,-0.0067211185,10.081865,11.075117,143.11952,-9.4128418
49.2,0.79124308,-0.10544246,48.825508,0,11.076097,147.51591,-0.0070188185,10.147255,11.077139,146.76636,-9.4109669
50.4,0.79564071,-0.10998102,49.142757,0,11.076097,151.11594,-0.0072903913,10.213423,11.076368,150.52818,-9.4091825
51.6,0.8007139,-0.11389793,49.229733,0,11.076097,154.71594,-0.0075648907,10.27599,11.075315,154.23741,-9.4068689
52.8,0.80438507,-0.11778091,49.39632,0,11.076097,158.31593,-0.0078046345,10.322764,11.076454,157.86201,-9.4050579
54.0,0.80657113,-0.12156285,49.75679,0,11.076097,161.91594,-0.0080617843,10.360693,11.076351,161.24478,-9.4025936
55.2,0.81548083,-0.12551346,50.363724,0,11.076097,165.51595,-0.0083199693,10.472275,11.075568,164.67827,-9.4006157
56.4,0.82334197,-0.12999763,50.438229,0,11.076097,169.11594,-0.0086164093,10.571629,11.075776,168.41251,-9.3983965
57.6,0.8208763,-0.1339646,50.62265,0,11.076097,172.71596,-0.0088767987,10.548924,11.075483,172.09328,-9.3961763
58.8,0.83287567,-0.13839263,50.438236,0,11.076097,176.31595,-0.0091657201,10.694614,11.075706,175.96846,-9.3940001
60.0,0.83297151,-0.14225625,50.438236,0,11.076097,179.91595,-0.0094327359,10.717504,11.075243,179.84807,-9.3921776
61.2,0.84447175,-0.14602104,50.251804,0,11.076097,183.51595,-0.0096689854,10.857494,11.076009,183.67067,-9.3903732
62.4,0.84542787,-0.15003166,50.042728,0,11.076097,187.11597,-0.0099543417,10.878699,11.075347,187.49071,-9.3885546
63.6,0.84704894,-0.15396994,49.758835,0,11.076097,190.71594,-0.010197295,10.916478,11.075869,191.10617,-9.3862982
64.8,0.85446233,-0.1582403,50.042721,0,11.076097,194.31596,-0.010495717,10.994367,11.076414,194.3082,-9.384593
66.0,0.85529405,-0.16295201,50.277916,0,11.076097,197.91595,-0.010778936,11.020251,11.076306,197.71527,-9.3824139
67.2,0.86417466,-0.16615275,50.438229,0,11.076097,201.51598,-0.011009251,11.132756,11.076057,201.15514,-9.380352
68.4,0.86533558,-0.16836886,50.822712,0,11.076097,205.11595,-0.011145379,11.145406,11.076445,204.52121,-9.37852
69.6,0.85679972,-0.17306426,51.196243,0,11.076097,208.71597,-0.011460491,11.047194,11.075078,207.91959,-9.3758669
70.8,0.86055481,-0.17670715,51.569801,0,11.076097,212.31595,-0.011710062,11.100286,11.075382,211.55052,-9.3737059
72.0,0.86219049,-0.18078934,51.612812,0,11.076097,215.91597,-0.01196908,11.09429,11.076515,215.17604,-9.3716545
73.2,0.86861289,-0.18485293,51.932369,0,11.076097,219.51596,-0.012250553,11.196469,11.0752,218.92117,-9.3694019
74.4,0.87704325,-0.1884511,52.106785,0,11.076097,223.11598,-0.012469572,11.311398,11.076426,222.49225,-9.3671265
75.6,0.88371843,-0.19324292,52.275673,0,11.076097,226.71597,-0.012821844,11.393219,11.075914,226.22681,-9.3653517
76.8,0.88091832,-0.19897777,52.283936,0,11.076097,230.31598,-0.013164218,11.365649,11.076429,229.88048,-9.3638897
78.0,0.86924732,-0.2012859,52.392826,0,11.076097,233.91597,-0.013352755,11.231426,11.075059,233.50182,-9.3617411
79.2,0.87265706,-0.20583774,52.635494,0,11.076097,237.51598,-0.013623651,11.272378,11.075749,237.05257,-9.3598366
80.4,0.87962937,-0.2096124,52.789616,0,11.076097,241.11597,-0.013889588,11.368091,11.0755,240.59262,-9.3581343
81.6,0.88867074,-0.21281797,52.97607,0,11.076097,244.71599,-0.014070242,11.490252,11.076093,244.2278,-9.3562346
82.8,0.88774121,-0.2171824,52.97607,0,11.076097,248.31596,-0.014388528,11.46417,11.075809,247.88074,-9.3544416
84.0,0.89605868,-0.22338584,53.31665,0,11.076097,251.91599,-0.014749739,11.595247,11.076448,251.37814,-9.3525028
85.2,0.8808552,-0.22674932,53.442238,0,11.076097,255.51598,-0.014997659,11.389562,11.076488,254.97601,-9.3506203
86.4,0.88465804,-0.23092966,53.657223,0,11.076097,259.11624,-0.015280654,11.440285,11.075932,258.61179,-9.3480682
87.6,0.89277315,-0.23462553,53.657223,0,11.076097,262.71597,-0.015525547,11.548731,11.075816,262.22452,-9.3457642
88.8,0.89572847,-0.23823956,53.975826,0,11.076097,266.31598,-0.015775273,11.60687,11.076719,265.76459,-9.3436956
90.0,0.89898193,-0.2461016,53.975826,0,11.076097,269.91599,-0.016271252,11.639752,11.075088,269.57684,-9.3417187
91.2,0.88884723,-0.24791305,53.975826,0,11.076097,273.51596,-0.016410464,11.524299,11.074583,273.36517,-9.3393717
92.4,0.88668239,-0.25215125,53.975826,0,11.076097,277.116,-0.016658772,11.4759,11.075708,276.9841,-9.3374701
93.6,0.8936376,-0.25536749,54.070824,0,11.076097,280.71597,-0.016878687,11.585832,11.074989,280.41333,-9.3351116
94.8,0.9000743,-0.25932378,54.305416,0,11.076097,284.31598,-0.017142344,11.659438,11.076886,283.90195,-9.3335266
96.0,0.90830553,-0.26582143,54.62088,0,11.076097,287.91595,-0.017545346,11.77584,11.075635,287.32681,-9.3311615
97.2,0.89285874,-0.26883799,54.825439,0,11.076097,291.51599,-0.017775686,11.577004,11.075895,290.80423,-9.3289566
98.4,0.89777184,-0.27295217,55.189632,0,11.076097,295.11597,-0.018036574,11.652328,11.076383,294.26138,-9.3273802
99.6,0.90786451,-0.2761654,55.239403,0,11.076097,298.71597,-0.01825073,11.768051,11.076411,297.90875,-9.3253279
100.8,0.90794492,-0.28030682,55.535885,0,11.076097,302.31598,-0.018504884,11.773643,11.076468,301.49316,-9.3230562
102.0,0.90643728,-0.28829616,55.843487,0,11.076097,305.91599,-0.019028384,11.753191,11.075617,305.10571,-9.3211365
103.2,0.8954066,-0.28964242,55.93153,0,11.076097,309.51599,-0.019121187,11.624553,11.07569,308.7836,-9.3189287
104.4,0.90130019,-0.29519916,56.129147,0,11.076097,313.11597,-0.01948398,11.72311,11.075488,312.418,-9.3170576
105.6,0.90859014,-0.29947022,56.21566,0,11.076097,316.716,-0.019782705,11.803696,11.077236,316.07199,-9.314929
106.8,0.91006219,-0.30400467,56.425777,0,11.076097,320.31601,-0.020043014,11.830366,11.076374,319.68961,-9.3130636
108.0,0.90964311,-0.30791172,56.427052,0,11.076097,323.91602,-0.020316839,11.834783,11.07648,323.4101,-9.3105669
109.2,0.91372484,-0.31258512,56.711422,0,11.076097,327.51599,-0.020621749,11.869823,11.075931,326.94815,-9.3088131
110.4,0.91772252,-0.32005766,56.711422,0,11.076097,331.116,-0.021118358,11.938008,11.075885,330.73145,-9.3067369
111.6,0.92101139,-0.32499164,56.711422,0,11.076097,334.716,-0.02144175,11.977813,11.077058,334.43442,-9.3049984
112.8,0.92552233,-0.32652521,56.71143,0,11.076097,338.31598,-0.021510405,12.024732,11.076623,338.1076,-9.3028469
114.0,0.91505247,-0.33240709,56.986084,0,11.076097,341.91602,-0.021923499,11.888695,11.076695,341.47507,-9.3011827
115.2,0.90623617,-0.33704856,57.060665,0,11.076097,345.51599,-0.022219351,11.803354,11.076719,345.06488,-9.298914
116.4,0.91351873,-0.34146565,57.260738,0,11.076097,349.11603,-0.022510527,11.895607,11.07564,348.74039,-9.2965326
117.6,0.91185701,-0.34608436,57.260738,0,11.076097,352.716,-0.022819556,11.888424,11.076634,352.34677,-9.2947149
118.8,0.9172886,-0.35094881,57.266045,0,11.076097,356.31601,-0.023100443,11.95445,11.076164,356.04156,-9.2927599
120.0,0.91354227,-0.3553763,57.535397,0,11.076097,359.91602,-0.023401061,11.906745,11.076335,359.51038,-9.2905293
121.2,0.91395509,-0.35964721,57.535397,0,11.076097,363.51602,-0.023700489,11.913523,11.076443,363.26709,-9.2885647
122.4,0.91532487,-0.36473593,57.535397,0,11.076097,367.11603,-0.024020029,11.938085,11.076512,366.90106,-9.286334
123.6,0.92959815,-0.3685528,57.535648,0,11.076097,370.71603,-0.024278073,12.137598,11.074662,370.45605,-9.284687
124.8,0.92643303,-0.372978,57.80999,0,11.076097,374.31601,-0.02454499,12.085907,11.075217,373.98615,-9.2825108
126.0,0.93106258,-0.37703845,57.810051,0,11.076097,377.91599,-0.024812043,12.152096,11.076111,377.62747,-9.2806587
127.2,0.93820405,-0.38130403,57.810051,0,11.076097,381.51602,-0.025119754,12.245799,11.075841,381.23709,-9.2786846
128.4,0.93787086,-0.38531137,58.053036,0,11.076097,385.116,-0.025342483,12.249601,11.077588,384.67139,-9.2766008
129.6,0.93838143,-0.38946876,58.073727,0,11.076097,388.71603,-0.02562369,12.249752,11.07534,388.29803,-9.2744322
130.8,0.93759829,-0.39382133,58.337399,0,11.076097,392.31604,-0.025924705,12.246232,11.075312,391.64252,-9.2726259
132.0,0.9389953,-0.39829531,58.722721,0,11.076097,395.91602,-0.026191572,12.28012,11.076203,394.97302,-9.2700901
133.2,0.93780166,-0.40332124,59.106354,0,11.076097,399.51599,-0.026536435,12.267947,11.075664,398.39624,-9.2682381
134.4,0.9449957,-0.40756088,57.380093,0,11.076097,399.99893,-0.026805354,12.355278,11.076087,401.93481,-9.2679892
135.6,0.9389078,-0.40956035,54.800644,0,11.076097,399.99893,-0.026935637,12.282829,11.076827,404.78857,-9.2680225
136.8,0.92198575,-0.40995672,51.962856,0,11.076097,399.99893,-0.026982276,12.067616,11.076593,406.28015,-9.2679081
138.0,0.8966468,-0.409383,49.529537,0,11.076097,399.99893,-0.02692082,11.739794,11.074499,406.48749,-9.2681971
139.2,0.88104397,-0.40713513,47.955376,0,11.076097,399.99893,-0.026789092,11.515953,11.075596,405.58136,-9.2677641
140.4,0.86510772,-0.40499559,47.349018,0,11.076097,399.99893,-0.026655562,11.316106,11.075541,403.95685,-9.2677107
141.6,0.86111039,-0.40365097,47.504871,0,11.076097,399.99893,-0.02654228,11.26605,11.076135,402.30231,-9.2679844
142.8,0.85526139,-0.40265518,47.955318,0,11.076097,399.99893,-0.026488107,11.187427,11.075426,400.96036,-9.2677164
144.0,0.85453027,-0.40277982,48.812199,0,11.076097,399.99893,-0.026522538,11.166127,11.07619,399.92542,-9.2675142
145.2,0.85849142,-0.40491575,49.451069,0,11.076097,399.99893,-0.026635151,11.208655,11.07611,399.28229,-9.2674589
146.4,0.8714456,-0.40668687,50.00967,0,11.076097,399.99893,-0.026748857,11.390097,11.077204,399.04446,-9.2679005
147.6,0.87026972,-0.40595216,50.385174,0,11.076097,399.99893,-0.026712393,11.374828,11.075783,399.11386,-9.2674952
148.8,0.86627287,-0.40535331,50.438229,0,11.076097,399.99893,-0.026652629,11.322537,11.07585,399.20276,-9.2675123
150.0,0.88231462,-0.40745953,50.632183,0,11.076097,399.99893,-0.026805505,11.537706,11.076402,399.36459,-9.2678509
151.2,0.88109314,-0.40796727,50.822678,0,11.076097,399.99893,-0.026849322,11.529558,11.076126,399.51944,-9.2673836
152.4,0.89160103,-0.40913999,50.627769,0,11.076097,399.99893,-0.026898114,11.671344,11.075374,399.83124,-9.2677708
153.6,0.89329207,-0.40949199,50.438236,0,11.076097,399.99893,-0.026940966,11.697682,11.076503,399.99118,-9.2674456
154.8,0.89466977,-0.40990868,50.438236,0,11.076097,399.99893,-0.02697614,11.700881,11.075689,399.96689,-9.2673016
156.0,0.90176457,-0.41046,50.438236,0,11.076097,399.99893,-0.026991334,11.809775,11.07477,400.13983,-9.2672892
157.2,0.90866578,-0.41071275,50.438236,0,11.076097,399.99893,-0.027013998,11.881599,11.076041,400.11877,-9.2676582
158.4,0.91106325,-0.41079965,50.175865,0,11.076097,399.99893,-0.027033027,11.895074,11.075267,400.24365,-9.2677326
159.6,0.89924985,-0.41072062,50.044525,0,11.076097,399.99893,-0.027008662,11.760241,11.07653,400.20297,-9.2673845
160.8,0.90359437,-0.41206294,50.042732,0,11.076097,399.99893,-0.027101591,11.839724,11.076072,400.12686,-9.267169
162.0,0.91986197,-0.41415775,50.047337,0,11.076097,399.99893,-0.027252253,12.047437,11.076499,400.04349,-9.2672682
163.2,0.92743272,-0.41588759,50.363491,0,11.076097,399.99893,-0.027366674,12.129731,11.07646,399.95328,-9.2674351
164.4,0.92944628,-0.41721338,50.383339,0,11.076097,399.99893,-0.027412383,12.17466,11.076138,399.93777,-9.267539
165.6,0.92937481,-0.41743365,50.406857,0,11.076097,399.99893,-0.027419964,12.177593,11.076636,399.97345,-9.267746
166.8,0.9296273,-0.41696751,50.326359,0,11.076097,399.99893,-0.027413471,12.167667,11.076562,400.03503,-9.2673826
168.0,0.93203199,-0.41687128,50.042728,0,11.076097,399.99893,-0.027369004,12.18573,11.07746,400.06042,-9.2668886
169.2,0.93529499,-0.41698703,50.055897,0,11.076097,399.99893,-0.02740759,12.233249,11.075003,400.0047,-9.2669573
170.4,0.94331563,-0.41740218,50.349701,0,11.076097,399.99893,-0.027449157,12.328982,11.076754,399.95456,-9.2676821
171.6,0.94790196,-0.41870761,50.310631,0,11.076097,399.99893,-0.027513195,12.404936,11.07584,399.96741,-9.2672815
172.8,0.94295084,-0.41928983,50.089657,0,11.076097,399.99893,-0.027563948,12.339899,11.076788,400.06445,-9.2671556
174.0,0.94353133,-0.41960844,50.042728,0,11.076097,399.99893,-0.027577113,12.352299,11.075756,400.11932,-9.2666759
175.2,0.94818074,-0.42087388,50.042728,0,11.076097,399.99893,-0.027668601,12.405423,11.075896,400.09561,-9.2669744
176.4,0.95490927,-0.42155677,50.042728,0,11.076097,399.99893,-0.027685033,12.508184,11.074905,400.17886,-9.2668991
177.6,0.95409071,-0.4220289,49.779221,0,11.076097,399.99893,-0.027720852,12.51409,11.076651,400.18854,-9.266798
178.6159,0.94544017,0.0090552168,45.665249,0,11.076099,65.880898,0.00052976748,12.021799,11.076708,400.35681,-9.2672319
178.6183,0.94111985,0.0093519315,33.752552,0,11.076099,2.8482205e-15,0.00055142638,11.963745,11.075849,400.34238,-9.2675238
178.6207,0.98580271,0.0071380013,21.839859,0,11.076099,1.2312851e-31,0.00055780576,12.654395,11.073252,400.32794,-9.2668896
178.6231,0.91613954,0.010271085,9.9271603,0,11.076099,0.0,0.00092392298,11.613232,11.074118,400.31348,-9.2667103
178.6255,0.94341177,0.0079848906,0.0,0,11.076099,0.0,0.00057350175,11.933768,11.07176,400.29904,-9.2661123
178.6279,0.94747287,0.012421686,0.0,0,11.076099,0.0,0.00047331327,12.06498,11.075574,400.28461,-9.2651768
178.6303,0.92953187,0.013362877,0.0,0,11.076099,0.0,0.00070521986,11.77847,11.075757,400.27014,-9.2654839
178.6327,0.93231809,0.010857331,0.0,0,11.076099,0.0,0.00084184209,11.815744,11.072758,400.25571,-9.2652798
178.6351,0.93384397,0.006079386,0.0,0,11.076099,0.0,0.00068787165,11.757948,11.07452,400.24124,-9.2660389
178.6375,0.92936832,0.0071180682,0.0,0,11.076099,0.0,0.00043678848,11.879464,11.075646,400.25571,-9.2661037
178.6399,0.93447679,0.010031758,0.0,0,11.076099,0.0,0.00043956461,11.807171,11.073933,400.27014,-9.2670021
178.6423,0.91918111,0.0083845444,0.0,0,11.076099,0.0,0.00046276479,11.784412,11.071736,400.28461,-9.2679768
178.6447,0.90768111,0.0064616529,0.0,0,11.076099,0.0,0.00053513132,11.585866,11.075747,400.29904,-9.2673054
178.6471,0.92111295,0.0072266683,0.0,0,11.076099,0.0,0.00067006465,11.740046,11.075876,400.30145,-9.2665606
178.6495,0.92076474,0.0088755526,0.0,0,11.076099,0.0,0.00061898335,11.764521,11.077117,400.30145,-9.2669783
178.6519,0.91100204,0.013031158,0.0,0,11.076099,0.0,0.00059976254,11.600169,11.075967,400.30145,-9.2668629
178.6543,0.90910858,0.014299187,0.0,0,11.076099,0.0,0.00073233538,11.522344,11.076316,400.30145,-9.268795
178.6567,0.91430044,0.010334409,0.0,0,11.076099,0.0,0.00088604761,11.654667,11.076774,400.30145,-9.2682753
178.6591,0.91829067,0.0061789607,0.0,0,11.076099,0.0,0.00071971322,11.873257,11.076988,400.30145,-9.2675333
178.6615,0.91455036,0.005836701,0.0,0,11.076099,0.0,0.00037429816,11.669915,11.078375,400.30145,-9.2670145
178.6639,0.90640616,0.0074990615,0.0,0,11.076099,0.0,0.00032713322,11.50935,11.077306,400.30145,-9.2680416
178.6663,0.90224475,0.0092694219,0.0,0,11.006544,0.0,0.00047589769,11.556297,11.076808,400.30145,-9.2675962
178.6687,0.89930785,0.0077669825,0.0,0,10.645576,0.0,0.00064843212,11.543985,11.078239,400.30145,-9.2674465
178.6711,0.8982138,0.0062846309,0.0,0,10.284603,0.0,0.00065806438,11.57849,11.062458,400.30145,-9.2672482
178.6735,0.92908025,0.0083049657,0.0,0,9.9236288,0.0,0.00056485605,11.779584,10.948872,400.30145,-9.2681313
178.6759,0.88837296,0.013581995,0.0,0,9.5626554,0.0,0.00060756819,11.329727,10.678264,401.40317,-9.2679319
178.6783,0.93620861,0.013539865,0.0,0,9.2092905,0.0,0.00067215931,11.86673,10.304105,404.70819,-9.2674847
178.6807,5.4286189,0.29491696,0.0,0,8.8581219,0.0,0.019069897,68.275337,9.8730946,408.01324,-9.262702
178.6831,6.1156816,0.74629807,0.0,0,8.518857,0.0,0.051075991,73.812988,9.3328762,411.31827,-9.2633724
178.6855,6.3000722,1.2073283,0.0,0,8.1848736,0.0,0.083444349,73.703598,8.8638077,414.89084,-9.2631207
178.6879,6.3616982,1.6191143,0.0,0,7.8607755,0.0,0.11356598,72.079735,8.475316,419.80093,-9.2631474
178.6903,6.6006155,1.9304783,0.0,0,7.543015,0.0,0.13719748,73.307343,8.1334047,424.71106,-9.2636509
178.6927,6.7027707,2.2252612,0.0,0,7.2334356,0.0,0.1603788,72.69976,7.818716,429.62119,-9.2642527
178.6951,6.837944,2.5200133,0.0,0,6.9312277,0.0,0.18386582,72.533363,7.5229154,434.53125,-9.2634296
178.6975,7.0021086,2.7917922,0.0,0,6.6355219,0.0,0.20555571,72.426262,7.2475448,435.43814,-9.2627325
178.6999,7.232101,3.0724308,0.0,0,6.3480015,0.0,0.22830823,73.207993,6.9681754,436.34503,-9.2622347
178.7023,7.3694057,3.3562248,0.0,0,6.065536,0.0,0.25257784,72.884254,6.6857262,437.25192,-9.2627039
178.7047,7.5510511,3.6382084,0.0,0,5.792079,0.0,0.27780235,72.862038,6.392745,438.15878,-9.2620611
178.7071,7.7442307,3.9237661,0.0,0,5.5222936,0.0,0.30322334,72.807838,6.1076546,438.65759,-9.2635508
178.7095,7.9700394,4.2113543,0.0,0,5.2621331,0.0,0.32898775,72.980225,5.8189487,439.0748,-9.2636271
178.7119,8.1760321,4.4950991,0.0,0,5.0044241,0.0,0.35539752,73.029465,5.5323911,439.492,-9.2638607
178.7143,8.3555279,4.7729778,0.0,0,4.7569842,0.0,0.38230705,72.567741,5.2546272,439.90921,-9.2631731
178.7167,8.542491,5.0394468,0.0,0,4.5108657,0.0,0.40925241,72.231766,4.9847379,441.77875,-9.2621574
178.7191,8.772398,5.3005576,0.0,0,4.2754698,0.0,0.43595254,72.239937,4.7233133,444.37442,-9.262043
178.7215,8.9774017,5.5578489,0.0,0,4.0404716,0.0,0.46230388,71.929962,4.4676361,446.97009,-9.2633963
178.7239,9.1910048,5.807138,0.0,0,3.8165054,0.0,0.48848975,71.754967,4.2223263,449.56577,-9.2626076
178.7263,9.389945,6.042532,0.0,0,3.5926332,0.0,0.51474935,71.442307,3.9863276,451.7941,-9.2625952
178.7287,9.6177502,6.2645717,0.0,0,3.3790326,0.0,0.54070431,71.251877,3.7632174,453.65506,-9.262063
178.7311,9.8967781,6.4761386,0.0,0,3.1660566,0.0,0.56550908,71.498695,3.5414972,455.51605,-9.2611055
178.7335,10.197954,6.6911049,0.0,0,2.9619906,0.0,0.59007043,71.919205,3.327316,457.37704,-9.2609138
178.7359,10.487856,6.9121966,0.0,0,2.7593822,0.0,0.61657047,72.017784,3.1164484,457.61807,-9.261797
178.7383,10.802765,7.1228886,0.0,0,2.5644474,0.0,0.64347917,72.194786,2.9035761,454.61935,-9.2619915
178.7407,11.166493,7.3282919,0.0,0,2.3717272,0.0,0.67078245,72.671707,2.7002957,451.62064,-9.262145
178.7431,11.562286,7.5307317,0.0,0,2.1855242,0.0,0.69751072,73.253258,2.4965477,448.62192,-9.2608337
178.7455,11.961573,7.7337632,0.0,0,2.0022123,0.0,0.7239365,73.802986,2.2941682,445.49136,-9.2598696
178.7479,12.341912,7.9323115,0.0,0,1.8243403,0.0,0.75086188,74.156334,2.1004105,441.70172,-9.2603216
178.7503,12.774739,8.1203871,0.0,0,1.6499563,0.0,0.77847672,74.617981,1.9135497,437.91208,-9.26056
178.7527,13.275593,8.2939949,0.0,0,1.4800413,0.0,0.80548841,75.474083,1.7319493,434.12247,-9.2598467
178.7551,13.796149,8.4685669,0.0,0,1.3141534,0.0,0.8317799,76.444031,1.5572886,430.33286,-9.2590694
178.7575,14.290187,8.6419935,0.0,0,1.1518564,0.0,0.85766315,77.108711,1.3841574,429.82904,-9.2583914
178.7599,14.837398,8.8123417,0.0,0,0.99408036,0.0,0.88420135,77.963036,1.2143661,429.3252,-9.2589226
178.7623,15.443598,8.9751854,0.0,0,0.83908135,0.0,0.91144574,78.972046,1.0543861,428.82138,-9.2574606
178.7647,16.129137,9.1306658,0.0,0,0.68903339,0.0,0.93874818,80.204102,0.89055562,428.31754,-9.257453
178.7671,16.829763,9.2872953,0.0,0,0.54098594,0.0,0.96570557,81.544144,0.73159695,425.22675,-9.2562666
178.7695,17.530296,9.4440928,0.0,0,0.39818591,0.0,0.9924705,82.677963,0.57702321,421.61856,-9.2572956
178.7719,15.083614,9.5027599,0.0,0,0.25673628,0.0,1.0021842,70.69487,0.47922012,418.01041,-9.2587528
178.7743,13.483579,9.5182943,0.0,0,0.12094415,0.0,1.0059191,62.834412,0.43188447,414.40222,-9.2612534
178.7767,12.774308,9.5120392,0.0,0,-0.014479235,0.0,1.006602,59.49472,0.41207448,411.58371,-9.262044
178.7791,12.422778,9.5157232,0.0,0,-0.14691243,0.0,1.0071063,57.744625,0.38408867,409.16,-9.2627935
178.7815,12.499534,9.5219641,0.0,0,-0.27934441,0.0,1.0067267,58.171356,0.33766687,406.7363,-9.2639771
178.7839,12.793635,9.5304966,0.0,0,-0.41177642,0.0,1.0078235,59.457901,0.27226061,404.31259,-9.2627506
178.7863,12.864802,9.5386181,0.0,0,-0.54420841,0.0,1.0100051,59.709515,0.20478313,403.06464,-9.2624416
178.7887,12.861074,9.5400591,0.0,0,-0.67664039,0.0,1.0116683,59.56591,0.14542696,402.9924,-9.262579
178.7911,12.720115,9.5431318,0.0,0,-0.80907238,0.0,1.0119106,58.860432,0.093606025,402.92017,-9.2624063
178.7935,12.473745,9.5522146,0.0,0,-0.94150436,0.0,1.0123808,57.727592,0.050502766,402.8479,-9.2623301
178.7959,12.10337,9.5608854,0.0,0,-1.0739365,0.0,1.0129659,56.00695,0.023850204,402.95145,-9.2622671
178.7983,11.624701,9.5632,0.0,0,-0.76691425,400.0,1.0144016,53.685699,0.011715571,403.40659,-9.2634802
178.8007,11.137546,9.5574312,0.0,0,-0.3084279,400.0,1.014951,51.435207,0.016429573,403.86169,-9.2636118
178.8031,10.724742,9.5546207,0.0,0,0.15005845,400.0,1.0143901,49.508217,0.019843291,404.3168,-9.263051
178.8055,10.401238,9.559454,0.0,0,0.60854483,400.0,1.0136608,48.073708,0.026421998,404.81046,-9.265645
178.8079,10.153293,9.5631838,0.0,0,1.0670311,400.0,1.0138185,46.916267,0.024932003,405.49673,-9.2641449
178.8103,9.7716017,9.5614815,0.0,0,1.5255175,400.0,1.0143572,45.181923,0.031149181,406.18304,-9.2650137
178.8127,8.7372932,9.5543461,0.0,0,1.9840039,400.0,1.0143596,40.446102,0.079411723,406.86932,-9.2649984
178.8151,6.7794151,9.543313,0.0,0,2.4424908,400.0,1.0120842,31.621639,0.18157747,407.55563,-9.265852
178.8175,3.1987789,9.527277,0.0,0,2.9009769,400.0,1.007627,15.154681,0.39703268,411.30197,-9.2683048
178.8199,0.40187943,9.4576283,0.0,0,3.3594635,400.0,0.99445671,1.7705344,0.79399312,415.04831,-9.2707977
178.8223,0.075536199,9.4838648,0.0,0,3.8179498,400.0,0.99968058,0.57495499,1.4859561,418.79468,-9.2708035
178.8247,0.17034963,9.4894524,0.0,0,4.2764363,400.0,1.0028776,0.62905312,2.3042355,422.54102,-9.2721176
178.8271,0.16029134,9.481492,0.0,0,4.7349229,400.0,1.000801,0.7577365,3.0378947,427.38748,-9.2716408
178.8295,0.14032295,9.4910259,0.0,0,5.1934094,400.0,1.0013847,0.62840807,3.5819764,432.45398,-9.2706156
178.8319,0.068902269,9.493351,0.0,0,5.651895,400.0,1.0011172,0.31512684,4.005146,437.52048,-9.2701073
178.8343,0.1963591,9.4973259,0.0,0,6.1103816,400.0,1.0028794,0.90430158,4.42835,442.58698,-9.2693329
178.8367,0.13600676,9.4927502,0.0,0,6.5688682,400.0,1.0029813,0.67759043,4.8481903,444.65909,-9.2691765
178.8391,0.074806593,9.4921322,0.0,0,7.0273547,400.0,1.002534,0.29062244,5.2827229,445.2341,-9.2694168
178.8415,0.1553909,9.4949675,0.0,0,7.4858413,400.0,1.00169,0.67741406,5.7487493,445.80911,-9.2685184
178.8439,0.098955609,9.4950647,0.0,0,7.9443278,400.0,1.0010724,0.5182488,6.2238574,446.38412,-9.268219
178.8463,0.04406818,9.4952631,0.0,0,8.4028139,400.0,1.0023186,0.18776649,6.7083025,446.88721,-9.2682352
178.8487,0.14370714,9.4886436,0.0,0,8.8612995,400.0,1.0025667,0.68974119,7.1952801,447.31839,-9.2665062
178.8511,0.043297388,9.4864531,0.0,0,9.3197861,400.0,1.001491,0.25112623,7.676415,447.74957,-9.2667665
178.8535,0.0083630783,9.4897718,0.0,0,9.7782726,400.0,1.0007665,-0.031610794,8.1477728,448.18076,-9.267128
178.8559,0.076222911,9.4921522,0.0,0,10.236759,400.0,1.0008574,0.33750758,8.6160669,448.61673,-9.2664461
178.8583,0.021720149,9.4921608,0.0,0,10.695246,400.0,1.0018018,0.074184954,9.0857639,449.06226,-9.2668915
178.8607,0.038134351,9.485817,0.0,0,11.153732,400.0,1.0018651,0.21345495,9.5542593,449.50778,-9.2661219
178.8631,0.082189381,9.4862938,0.0,0,11.612218,400.0,1.0015094,0.40815058,10.0324,449.95334,-9.265975
178.8655,-0.011867581,9.4901152,0.0,0,12.070705,400.0,1.0008219,0.020015322,10.511497,450.30545,-9.265583
178.8679,-0.012207029,9.4976625,0.0,0,12.529191,400.0,1.0014739,-0.067411691,10.983822,450.19049,-9.2664108
178.8703,0.087735489,9.4932508,0.0,0,12.987678,400.0,1.0019785,0.44813228,11.447845,450.0755,-9.2663822
178.8727,0.0036758981,9.4873056,0.0,0,13.446164,400.0,1.0022309,-0.016194746,11.892928,449.96051,-9.2649431
178.8751,0.042770512,9.4812975,0.0,0,13.904651,400.0,1.000545,0.22040914,12.356479,449.84555,-9.2655287
178.8775,0.012570793,9.4864454,0.0,0,14.363137,400.0,1.0000515,0.076507106,12.827245,449.94617,-9.2651663
178.8799,-0.035686295,9.4913998,0.0,0,14.821624,400.0,1.0007968,-0.10046726,13.294855,450.04675,-9.2650394
178.8823,0.04491543,9.4897518,0.0,0,15.28011,400.0,1.0016975,0.13421676,13.77906,450.14737,-9.2645864
178.8847,0.067842454,9.484664,0.0,0,15.738596,400.0,1.0016048,0.33939382,14.262244,450.24799,-9.2643938
178.8871,-0.046681806,9.4841795,0.0,0,16.197083,400.0,1.0010384,-0.1970215,14.731428,449.88147,-9.2658625
178.8895,-0.0047301864,9.488328,0.0,0,16.655569,400.0,1.0003717,0.0064495825,15.189719,449.42157,-9.2655315
178.8919,0.041742951,9.4936333,0.0,0,17.114056,400.0,1.0006671,0.10719015,15.64718,448.96164,-9.264883
178.8943,0.0078154281,9.4903584,0.0,0,17.572542,400.0,1.0015787,0.0016488665,16.096992,448.50171,-9.2645903
178.8967,0.012768011,9.4854136,0.0,0,17.999401,400.0,1.0018629,0.084823586,16.548021,448.27176,-9.2645798
178.8991,0.066589162,9.4832134,0.0,0,18.0,400.0,1.0008563,0.31801257,17.006737,448.15677,-9.2644739
178.9015,-0.03074039,9.488163,0.0,0,18.0,400.0,1.0003297,-0.14902046,17.436201,448.04181,-9.2647381
178.9039,0.078340352,9.4891386,0.0,0,18.0,400.0,1.0004532,0.42838714,17.821827,447.92682,-9.2661495
178.9063,0.1105779,9.4895706,0.0,0,18.0,400.0,1.0015138,0.50388288,18.14253,447.65353,-9.2667694
178.9087,0.27565378,9.4871387,0.0,0,18.0,400.0,1.0021653,1.3096645,18.377823,447.22192,-9.269865
178.9111,0.4469758,9.4931297,0.0,0,18.0,400.0,1.0026512,2.0471032,18.495291,446.79034,-9.2744789
178.9135,0.81475097,9.5024233,0.0,0,18.0,400.0,1.0029062,3.7988186,18.483313,446.35873,-9.2807579
178.9159,0.6952545,9.5094557,0.0,0,18.0,400.0,1.003751,3.2433271,18.366795,446.04227,-9.2914124
178.9183,0.76314604,9.5064726,0.0,0,18.0,400.0,1.0046663,3.5531332,18.238901,445.95602,-9.3039227
178.9207,0.76040107,9.5017128,0.0,0,18.0,400.0,1.0047401,3.5851722,18.124554,445.86981,-9.3192339
178.9231,0.74205571,9.4998398,0.0,0,18.0,400.0,1.0037752,3.4826686,18.061758,445.78357,-9.3387394
178.9255,0.6911158,9.5028391,0.0,0,18.0,400.0,1.0030749,3.2865994,18.033529,445.6781,-9.3591385
178.9279,0.69153202,9.5036125,0.0,0,18.0,400.0,1.0029895,3.2332139,18.035416,445.47659,-9.3795137
178.9303,0.71555251,9.5003605,0.0,0,18.0,400.0,1.003529,3.3325598,18.056187,445.27505,-9.3979826
178.9327,0.74705225,9.4957685,0.0,0,18.0,400.0,1.0036968,3.4915137,18.074734,445.07355,-9.417285
178.9351,0.70614088,9.4946985,0.0,0,18.0,400.0,1.0027926,3.3128581,18.102812,444.87201,-9.4366674
178.9375,0.69536042,9.5006962,0.0,0,18.0,400.0,1.0025152,3.25705,18.121874,444.84326,-9.453887
178.9399,0.72120619,9.5062094,0.0,0,18.0,400.0,1.0033487,3.3263733,18.132954,444.81451,-9.4722347
178.9423,0.74924153,9.5048466,0.0,0,18.0,400.0,1.0043256,3.4669337,18.138613,444.7858,-9.4898348
178.9447,0.74955368,9.4960232,0.0,0,18.0,400.0,1.0039941,3.4749317,18.140207,444.75705,-9.5076752
178.9471,0.71367848,9.4955444,0.0,0,18.0,400.0,1.0029714,3.3529038,18.141348,444.75824,-9.524437
178.9495,0.70123124,9.4996443,0.0,0,18.0,400.0,1.0022942,3.2696726,18.133989,444.76544,-9.5415545
178.9519,0.73309207,9.5022373,0.0,0,18.0,400.0,1.0027051,3.431303,18.132242,444.77264,-9.559123
178.9543,0.76433229,9.498951,0.0,0,18.0,400.0,1.0033762,3.5774333,18.133379,444.77982,-9.5768328
178.9567,0.73973745,9.495759,0.0,0,18.0,400.0,1.0038339,3.509764,18.126451,444.60977,-9.5951281
178.9591,0.69927323,9.4984341,0.0,0,18.0,400.0,1.0035535,3.2820537,18.126665,444.35107,-9.6122017
178.9615,0.74494523,9.5038242,0.0,0,18.0,400.0,1.0030347,3.4448121,18.116695,444.09238,-9.6288919
178.9639,0.76419932,9.506958,0.0,0,18.0,400.0,1.0031445,3.5297818,18.116215,443.83365,-9.6472874
178.9663,0.76334381,9.5042543,0.0,0,18.0,400.0,1.0044824,3.5604296,18.111206,443.1933,-9.6654186
178.9687,0.71199131,9.4973936,0.0,0,18.0,400.0,1.0041281,3.3722994,18.112162,442.17126,-9.6835346
178.9711,0.70500112,9.4976559,0.0,0,18.0,400.0,1.0031099,3.2929773,18.114002,441.14923,-9.7014093
178.9735,0.73204714,9.5011244,0.0,0,18.0,400.0,1.0024745,3.4113674,18.111998,440.1272,-9.7187204
178.9759,0.77009064,9.5040283,0.0,0,18.0,400.0,1.0031357,3.6254559,18.110592,439.39795,-9.7377281
178.9783,0.7241075,9.4991541,0.0,0,18.0,400.0,1.0036346,3.4001739,18.111805,439.25424,-9.7568369
178.9807,0.71248376,9.4947004,0.0,0,18.0,400.0,1.003498,3.3204489,18.109974,439.11053,-9.77349
178.9831,0.72452492,9.4960632,0.0,0,18.0,400.0,1.0030396,3.3771546,18.101955,438.9668,-9.7899504
178.9855,0.76325566,9.5021658,0.0,0,18.0,400.0,1.0027752,3.5648601,18.104355,438.84103,-9.8077011
178.9879,0.75460488,9.5084515,0.0,0,18.0,400.0,1.0037786,3.5228314,18.106722,438.80505,-9.8250866
178.9903,0.71429449,9.505806,0.0,0,18.0,400.0,1.0047599,3.3236372,18.106009,438.76907,-9.8439207
178.9927,0.70605612,9.4983091,0.0,0,18.0,400.0,1.0041835,3.3003485,18.104834,438.73306,-9.8606339
178.9951,0.74076098,9.4950018,0.0,0,18.0,400.0,1.0027252,3.4239888,18.100151,438.69708,-9.8785133
178.9975,0.76819879,9.5009089,0.0,0,18.0,400.0,1.0023502,3.6006715,18.098194,438.7977,-9.8973608
178.9999,0.73696595,9.5042095,0.0,0,18.0,400.0,1.0032769,3.4498775,18.097692,438.89828,-9.9143801
179.0023,0.72257036,9.5017185,0.0,0,18.0,400.0,1.0042289,3.3613763,18.09462,438.9989,-9.932662
179.0047,0.71103215,9.4984512,0.0,0,18.0,400.0,1.0041212,3.3078351,18.09483,439.09952,-9.9489307
179.0071,0.76969939,9.5004234,0.0,0,18.0,400.0,1.003535,3.5882282,18.097015,439.0383,-9.9657183
179.0095,0.77211237,9.5052748,0.0,0,18.0,400.0,1.0032333,3.6273551,18.094545,438.94473,-9.9851494
179.0119,0.72298169,9.5086918,0.0,0,18.0,400.0,1.0038122,3.4166207,18.094637,438.85117,-10.002251
179.0143,0.71271777,9.5026722,0.0,0,18.0,400.0,1.0043617,3.3410687,18.094114,438.7576,-10.020615
179.0167,0.75879598,9.4966707,0.0,0,18.0,400.0,1.0041229,3.5246418,18.09276,438.64975,-10.037827
179.0191,0.77773046,9.500082,0.0,0,18.0,400.0,1.0034475,3.6225088,18.093748,438.53476,-10.055717
179.0215,0.76401865,9.5056381,0.0,0,18.0,400.0,1.0033218,3.5602658,18.092592,438.4198,-10.074509
179.0239,0.72539794,9.5067759,0.0,0,18.0,400.0,1.0037206,3.3694649,18.089548,438.30481,-10.090862
179.0263,0.74168563,9.5028305,0.0,0,18.0,400.0,1.0044299,3.4200962,18.091787,438.33368,-10.108492
179.0287,0.77992183,9.4989614,0.0,0,18.0,400.0,1.0042616,3.6303425,18.090401,438.50644,-10.126626
179.0311,0.78116429,9.5004444,0.0,0,18.0,400.0,1.0035868,3.6853268,18.084404,438.67917,-10.145123
179.0335,0.73517919,9.5084496,0.0,0,18.0,400.0,1.0037327,3.4544845,18.079561,438.8519,-10.163908
179.0359,0.73174286,9.5109053,0.0,0,18.0,400.0,1.0042323,3.3866937,18.082041,439.00061,-10.182186
179.0383,0.75872391,9.5060635,0.0,0,18.0,400.0,1.0050045,3.516819,18.085705,439.10123,-10.197449
179.0407,0.7917335,9.5007172,0.0,0,18.0,400.0,1.0047728,3.6864429,18.084379,439.20184,-10.217083
179.0431,0.76282924,9.5013638,0.0,0,18.0,400.0,1.0038583,3.5828238,18.080059,439.30246,-10.234656
179.0455,0.72417861,9.5038633,0.0,0,18.0,400.0,1.0028782,3.4033806,18.08227,439.36111,-10.252497
179.0479,0.74279499,9.5047016,0.0,0,18.0,400.0,1.003474,3.454746,18.078476,439.20996,-10.269428
179.0503,0.76900578,9.5015574,0.0,0,18.0,400.0,1.0041381,3.6085348,18.078346,439.05881,-10.287191
179.0527,0.80144662,9.5005798,0.0,0,18.0,400.0,1.0045878,3.7221589,18.077158,438.90765,-10.30416
179.0551,0.72608149,9.5024109,0.0,0,18.0,400.0,1.003885,3.436646,18.085461,438.7565,-10.322049
179.0575,0.72557133,9.5062361,0.0,0,18.0,400.0,1.0031545,3.374855,18.078285,438.74933,-10.339569
179.0599,0.75586164,9.5094509,0.0,0,18.0,400.0,1.0040451,3.4693022,18.078188,438.74213,-10.356578
179.0623,0.79033136,9.5051088,0.0,0,18.0,400.0,1.0048019,3.7191582,18.076876,438.73495,-10.375656
179.0647,0.76464266,9.4986601,0.0,0,18.0,400.0,1.0043035,3.5697076,18.076561,438.72775,-10.391794
179.0671,0.73631221,9.5018806,0.0,0,18.0,400.0,1.0036922,3.441788,18.074699,438.79852,-10.409557
179.0695,0.72380263,9.5065098,0.0,0,18.0,400.0,1.0035381,3.3543971,18.076599,438.88489,-10.427367
179.0719,0.775536,9.5086088,0.0,0,18.0,400.0,1.0041784,3.6456835,18.075375,438.97128,-10.445034
179.0743,0.79119998,9.5044641,0.0,0,18.0,400.0,1.0047424,3.733216,18.075932,439.05765,-10.462856
179.0767,0.74521995,9.5002756,0.0,0,18.0,400.0,1.0042151,3.4965329,18.071775,439.01456,-10.481537
179.0791,0.73121732,9.5028038,0.0,0,18.0,400.0,1.0039368,3.4030826,18.070988,438.90677,-10.499142
179.0815,0.75869191,9.5086517,0.0,0,18.0,400.0,1.0036639,3.5213466,18.07621,438.79898,-10.517992
179.0839,0.8067348,9.5120764,0.0,0,18.0,400.0,1.0046008,3.73756,18.074732,438.69119,-10.536538
179.0863,0.7809853,9.5078917,0.0,0,18.0,400.0,1.0054396,3.5952461,18.069334,438.48254,-10.555479
179.0887,0.74791855,9.5041485,0.0,0,18.0,400.0,1.0053101,3.4944978,18.071819,438.17307,-10.571722
179.0911,0.72741026,9.5039558,0.0,0,18.0,400.0,1.0040216,3.3656521,18.072886,437.86359,-10.589861
179.0935,0.7927686,9.5075836,0.0,0,18.0,400.0,1.0037038,3.6801038,18.069685,437.55411,-10.606592
179.0959,0.80708063,9.5093298,0.0,0,18.0,400.0,1.0044136,3.7825284,18.070805,437.32861,-10.625155
179.0983,0.75615764,9.5064306,0.0,0,18.0,400.0,1.0050248,3.553695,18.065945,437.27112,-10.64241
179.1007,0.75587684,9.5010891,0.0,0,18.0,400.0,1.0044007,3.5108433,18.064075,437.21362,-10.65926
179.1031,0.76468217,9.5022736,0.0,0,18.0,400.0,1.0037956,3.5857415,18.065121,437.15613,-10.674938
179.1055,0.81018531,9.51054,0.0,0,18.0,400.0,1.003938,3.7891729,18.063599,437.11301,-10.693398
179.1079,0.79507279,9.513917,0.0,0,18.0,400.0,1.0050769,3.734771,18.06242,437.14182,-10.713017
179.1103,0.74936712,9.508749,0.0,0,18.0,400.0,1.005667,3.4589169,18.062004,437.17059,-10.731803
179.1127,0.73803216,9.500596,0.0,0,18.0,400.0,1.0046642,3.4651449,18.065012,437.1994,-10.749169
179.1151,0.79189509,9.5017719,0.0,0,18.0,400.0,1.0034671,3.6986177,18.059273,437.22818,-10.766372
179.1175,0.80514753,9.5053644,0.0,0,18.0,400.0,1.003317,3.7637935,18.059448,437.35754,-10.7831
179.1199,0.77960795,9.5094471,0.0,0,18.0,400.0,1.0045617,3.6230609,18.058041,437.48688,-10.801086
179.1223,0.74469852,9.5040998,0.0,0,18.0,400.0,1.0048304,3.4823852,18.059013,437.61624,-10.819167
179.1247,0.76424181,9.5001411,0.0,0,18.0,400.0,1.0045258,3.5602832,18.064793,437.74561,-10.835483
179.1271,0.80967402,9.5040827,0.0,0,18.0,400.0,1.0038582,3.7502453,18.061014,438.09702,-10.855769
179.1295,0.8054834,9.5139847,0.0,0,18.0,400.0,1.004492,3.7964787,18.062759,438.49289,-10.871783
179.1319,0.74853319,9.5152702,0.0,0,18.0,400.0,1.0053426,3.5046062,18.064356,438.88873,-10.891111
179.1343,0.74062657,9.5063238,0.0,0,18.0,400.0,1.0054878,3.4949203,18.058771,439.28458,-10.907537
179.1367,0.7994684,9.5019217,0.0,0,18.0,400.0,1.0047846,3.6986809,18.058414,439.42612,-10.926188
179.1391,0.8236016,9.5044699,0.0,0,18.0,400.0,1.0039517,3.8491013,18.057207,439.44049,-10.943707
179.1415,0.77861613,9.5116024,0.0,0,18.0,400.0,1.004458,3.664762,18.057287,439.45486,-10.960759
179.1439,0.74795055,9.5127563,0.0,0,18.0,400.0,1.0051892,3.5013351,18.058088,439.46924,-10.978124
179.1463,0.77922475,9.5047045,0.0,0,18.0,400.0,1.005056,3.5685444,18.056036,439.49802,-10.994268
179.1487,0.82732373,9.501894,0.0,0,18.0,400.0,1.0045561,3.8191476,18.056578,439.5412,-11.013247
179.1511,0.81380844,9.5048132,0.0,0,18.0,400.0,1.003976,3.8227937,18.056744,439.58438,-11.032
179.1535,0.75977391,9.5142746,0.0,0,18.0,400.0,1.00459,3.5237432,18.053438,439.62756,-11.049024
179.1559,0.7580114,9.5145226,0.0,0,18.0,400.0,1.0052084,3.5334277,18.053226,439.67072,-11.068156
179.1583,0.79627174,9.5068731,0.0,0,18.0,400.0,1.0055029,3.714133,18.054115,439.71384,-11.086014
179.1607,0.83065009,9.503027,0.0,0,18.0,400.0,1.0049618,3.8813636,18.049467,439.75696,-11.10404
179.1631,0.78820294,9.5065126,0.0,0,18.0,400.0,1.0042605,3.6813829,18.049643,439.80008,-11.123074
179.1655,0.7549113,9.5094252,0.0,0,18.0,400.0,1.0039755,3.539505,18.052225,439.88159,-11.139412
179.1679,0.77350873,9.5088167,0.0,0,18.0,400.0,1.0045958,3.6105995,18.054132,440.15509,-11.155838
179.1703,0.81664777,9.5048409,0.0,0,18.0,400.0,1.004954,3.8256502,18.049213,440.42859,-11.172379
179.1727,0.81734622,9.5031977,0.0,0,18.0,400.0,1.004891,3.8204069,18.049566,440.70209,-11.190826
179.1751,0.77032626,9.5087709,0.0,0,18.0,400.0,1.0045764,3.6159248,18.049906,440.97559,-11.208823
179.1775,0.75645638,9.515008,0.0,0,18.0,400.0,1.0046706,3.5193272,18.054064,440.98279,-11.22605
179.1799,0.81842351,9.5145884,0.0,0,18.0,400.0,1.005232,3.7621346,18.045992,440.98996,-11.244411
179.1823,0.83737236,9.5078297,0.0,0,18.0,400.0,1.0056744,3.9174387,18.049551,440.99716,-11.26164
179.1847,0.80256951,9.5042715,0.0,0,18.0,400.0,1.005162,3.7795715,18.050825,441.00436,-11.279984
179.1871,0.77446693,9.5061417,0.0,0,18.0,400.0,1.0042078,3.5953691,18.050463,440.54971,-11.296474
179.1895,0.76248747,9.5098572,0.0,0,18.0,400.0,1.0039681,3.5739381,18.045687,440.00272,-11.31482
179.1919,0.83323497,9.5090895,0.0,0,18.0,400.0,1.0046787,3.8877573,18.046045,439.45572,-11.332829
179.1943,0.82073307,9.5068359,0.0,0,18.0,400.0,1.0054983,3.871696,18.049999,438.90872,-11.351028
179.2964,0.78738874,9.5102043,0.0,0,18.0,17.344156,1.0050721,3.6634223,18.035357,435.70203,-11.469927
180.4964,0.75399047,9.5248318,0.0,0,18.0,7.5886285e-16,1.0078139,3.5031891,17.999981,403.49844,-11.483952
181.6964,0.79574794,9.5344744,0.0,0,18.0,3.2805517000000004e-32,1.0095294,3.6896954,17.998766,388.2753,-11.483278
182.8964,0.80338246,9.543232,0.0,0,18.0,1.4012985e-45,1.0112238,3.7216148,17.99987,383.80524,-11.484073
184.0964,0.81468803,9.5514174,0.0,0,18.0,1.4012985e-45,1.0127417,3.7658508,17.999147,377.86371,-11.483514
185.2964,0.81020838,9.5591955,0.0,0,18.0,1.4012985e-45,1.0140548,3.7425117,18.000547,368.54028,-11.483517
186.4964,0.82005012,9.5661821,0.0,0,18.0,1.4012985e-45,1.0154215,3.7810788,17.999399,363.59393,-11.483304
187.6964,0.81707978,9.5729828,0.0,0,18.0,1.4012985e-45,1.0166584,3.7610428,17.999449,352.74362,-11.483029
188.8964,0.82782239,9.5794277,0.0,0,18.0,1.4012985e-45,1.0179098,3.8102093,17.998968,339.85074,-11.482798
190.0964,0.82863349,9.5860443,0.0,0,18.0,1.4012985e-45,1.0190139,3.8011425,18.000439,334.82867,-11.483014
191.2964,0.83510518,9.5922718,0.0,0,18.0,1.4012985e-45,1.0202739,3.8381653,17.999807,320.72919,-11.48334
192.4964,0.8370896,9.5982828,0.0,0,18.0,1.4012985e-45,1.0213218,3.8355405,17.99967,316.76923,-11.483367
193.6964,0.84167385,9.6042061,0.0,0,18.0,1.4012985e-45,1.0224357,3.8583171,18.000055,303.64944,-11.482949
194.8964,0.84970701,9.6101799,0.0,0,18.0,1.4012985e-45,1.0234834,3.8840935,18.000879,299.10864,-11.483064
196.0964,0.84783739,9.615344,0.0,0,18.0,1.4012985e-45,1.0245397,3.8766501,18.000418,288.77429,-11.483242
197.2964,0.85991573,9.6210461,0.0,0,18.0,1.4012985e-45,1.0255924,3.9178939,17.999556,278.91592,-11.483007
198.4964,0.85273093,9.6264868,0.0,0,18.0,1.4012985e-45,1.0265391,3.894326,18.000587,274.71771,-11.482406
199.6964,0.86460894,9.6314325,0.0,0,18.0,1.4012985e-45,1.0274794,3.9370184,17.999018,266.55469,-11.482812
200.8964,0.86228269,9.6366405,0.0,0,18.0,1.4012985e-45,1.0284601,3.9292521,18.00033,259.09344,-11.482985
202.0964,0.87443262,9.6414356,0.0,0,18.0,1.4012985e-45,1.0293967,3.9705153,17.999205,252.15591,-11.482814
203.2964,0.86875963,9.646575,0.0,0,18.0,1.4012985e-45,1.0302373,3.9475794,18.000139,242.95543,-11.48303
204.4964,0.8810038,9.6508169,0.0,0,18.0,1.4012985e-45,1.0311328,4.0039158,17.999739,237.51849,-11.482937
205.6964,0.87721562,9.6552582,0.0,0,18.0,1.4012985e-45,1.0319511,3.9752967,17.999392,231.56807,-11.483118
206.8964,0.88359213,9.659812,0.0,0,18.0,1.4012985e-45,1.0328355,4.0106773,17.999493,223.9801,-11.48276
208.0964,0.883277,9.6641474,0.0,0,18.0,1.4012985e-45,1.0335284,3.9978213,17.999971,219.23663,-11.483064
209.2964,0.88839036,9.6684713,0.0,0,18.0,1.4012985e-45,1.0344355,4.0269179,17.999994,208.29834,-11.483075
210.4964,0.88959724,9.6725826,0.0,0,18.0,1.4012985e-45,1.0351895,4.022131,17.999104,207.82861,-11.48299
211.6964,0.88860917,9.6768446,0.0,0,18.0,1.4012985e-45,1.0360453,4.0197043,18.000326,200.4454,-11.482906
212.8964,0.8949573,9.6807556,0.0,0,18.0,1.4012985e-45,1.0366403,4.0402975,18.000013,195.91925,-11.482766
214.0964,0.88757837,9.6838465,0.0,0,18.0,1.4012985e-45,1.0373099,4.009665,17.999395,190.89287,-11.482304
215.2964,0.90026027,9.6876335,0.0,0,18.0,1.4012985e-45,1.0380299,4.05901,18.000124,183.89606,-11.482446
216.4964,0.88998502,9.6914053,0.0,0,18.0,1.4012985e-45,1.0387725,4.0080023,17.99918,180.56412,-11.48242
217.6964,0.9035098,9.6948652,0.0,0,18.0,1.4012985e-45,1.0393366,4.0684528,18.000763,176.48637,-11.482292
218.8964,0.89321297,9.6983309,0.0,0,18.0,1.4012985e-45,1.040029,4.0212488,17.99963,170.17979,-11.48228
220.0964,0.90708488,9.7016125,0.0,0,18.0,1.4012985e-45,1.0406924,4.0844836,17.999138,167.52411,-11.481911
221.2964,0.89630836,9.7053757,0.0,0,18.0,1.4012985e-45,1.0413709,4.025106,18.00127,162.6022,-11.482024
222.4964,0.90488911,9.7078276,0.0,0,18.0,1.4012985e-45,1.0417796,4.0693831,17.999508,159.6311,-11.48177
223.6964,0.90045726,9.7115908,0.0,0,18.0,1.4012985e-45,1.0424757,4.0391951,18.000196,154.98206,-11.482541
224.8964,0.90137947,9.7141066,0.0,0,18.0,1.4012985e-45,1.0430983,4.0502667,18.000444,151.76295,-11.481727
226.0964,0.90393627,9.7169933,0.0,0,18.0,1.4012985e-45,1.0435543,4.0474286,18.000278,147.88643,-11.481895
227.2964,0.9016344,9.7196932,0.0,0,18.0,1.4012985e-45,1.0440921,4.0454526,17.999832,143.51605,-11.481718
228.4964,0.90554947,9.7226448,0.0,0,18.0,1.4012985e-45,1.0445741,4.0537429,17.99983,140.81627,-11.481381
229.6964,0.90158731,9.7256947,0.0,0,18.0,1.4012985e-45,1.0452386,4.0398664,17.999363,137.543,-11.48177
230.8964,0.9125244,9.7281046,0.0,0,18.0,1.4012985e-45,1.0456716,4.0792933,17.999977,134.19861,-11.481922
232.0964,0.89949995,9.7305756,0.0,0,18.0,1.4012985e-45,1.0461649,4.0239143,18.000298,131.21349,-11.48211
233.2964,0.91804725,9.7332659,0.0,0,18.0,1.4012985e-45,1.046615,4.1034603,17.999283,127.98713,-11.482127
234.4964,0.90127695,9.7358971,0.0,0,18.0,1.4012985e-45,1.0471052,4.0262303,17.999609,125.10275,-11.481821
235.6964,0.91917521,9.7380877,0.0,0,18.0,1.4012985e-45,1.0476226,4.1093097,18.000109,121.99108,-11.481745
236.8964,0.90663105,9.7403402,0.0,0,18.0,1.4012985e-45,1.0479301,4.0495863,17.999222,119.3247,-11.481568
238.0964,0.91828227,9.7427206,0.0,0,18.0,1.4012985e-45,1.0484842,4.1042757,17.999287,116.28022,-11.481602
239.1964,0.9145326,9.7447691,0.0,0,18.0,1.4012985e-45,1.0488002,4.074708,17.999681,113.98154,-11.481582