File: examples/dan-msc-case-studies/CS3/data/01 raw data/baron_test_146.csv
Time(sec),Force(kN),Jaw(mm),PowAngle(deg),Power(W),Pram,PTemp,Strain,Stress(MPa),Stroke(mm),TC1(C),wedge(mm)
0.0,1.1419036,0.50459266,0.0,0,10.594783,0.0016571138,0.034217849,14.070064,10.595058,29.677082,-9.127326
2.2,1.0101137,-0.00088188919,0.0,0,10.594783,6.5158763,-8.4045671e-05,12.868913,10.595473,29.468843,-9.4944668
4.4,0.97874457,-0.00068626116,0.0,0,10.594783,13.115877,-2.8139451e-05,12.43845,10.594563,29.404842,-9.4908276
6.6,0.96010786,-0.00060253701,0.0,0,10.594783,19.715876,-5.7187666e-05,12.229332,10.595115,29.16785,-9.4867487
8.8,0.94459617,-0.00043909776,0.0,0,10.594783,26.315876,-9.4686193e-06,12.034885,10.594475,29.049341,-9.4824171
11.0,0.93173814,0.0005551629,22.077505,0,10.594783,32.915886,4.0574883e-05,11.861334,10.595712,29.054901,-9.478446
13.2,0.93957901,-0.00077981164,42.723991,0,10.594783,39.515884,-4.4066117e-05,11.951932,10.594211,30.331411,-9.4743433
15.4,0.97201598,-0.0077380603,52.128044,0,10.594783,46.115883,-0.00050409813,12.36495,10.594144,35.218933,-9.4704647
17.6,1.0075425,-0.018019576,56.425163,0,10.594783,52.715878,-0.0012081638,12.843475,10.59576,43.806168,-9.4664392
19.8,1.0380833,-0.029464461,56.986092,0,10.594783,59.315876,-0.0019583926,13.257273,10.594618,55.330635,-9.4625273
22.0,1.0497904,-0.039641101,54.019718,0,10.594783,65.915894,-0.0026525636,13.388764,10.595193,67.626884,-9.4583302
24.2,1.0555588,-0.047120377,47.96785,0,10.594783,72.515892,-0.0031383531,13.486311,10.595279,78.845581,-9.4539986
26.4,1.0305768,-0.050621413,39.858028,0,10.594783,79.115883,-0.0033869869,13.165344,10.59472,86.693398,-9.4500866
28.6,0.99535197,-0.051582567,34.90918,0,10.594783,85.715881,-0.0034291362,12.725518,10.595342,90.808197,-9.446414
30.8,0.96868849,-0.051622946,38.91188,0,10.594783,92.315872,-0.0034533346,12.386012,10.595718,92.487228,-9.442275
33.0,0.9789353,-0.054677449,46.826256,0,10.594783,98.915871,-0.0036297545,12.493954,10.594493,94.218422,-9.4386692
35.2,1.0079029,-0.061299756,53.251667,0,10.594783,105.51588,-0.0041035269,12.877672,10.595842,98.102417,-9.4341583
37.4,1.0476781,-0.071364768,56.771969,0,10.594783,112.11589,-0.0047327536,13.411657,10.595526,105.27215,-9.4301901
39.6,1.071532,-0.081553452,57.535397,0,10.594783,118.71589,-0.0054500168,13.724599,10.594153,115.20961,-9.426549
41.8,1.0709115,-0.091948472,55.816284,0,10.594783,125.31589,-0.0060887053,13.712116,10.594147,126.08873,-9.4227695
44.0,1.0831907,-0.099255845,52.286972,0,10.594783,131.91588,-0.00661411,13.871507,10.594982,135.94278,-9.4188824
46.2,1.0744052,-0.10512272,48.38493,0,10.594783,138.51588,-0.0069661769,13.765471,10.594353,143.41057,-9.4151344
48.4,1.0409738,-0.10762371,46.109623,0,10.594783,145.11588,-0.0071649496,13.353783,10.594945,148.60995,-9.4113121
50.6,1.0242519,-0.11073659,47.496834,0,10.594783,151.71588,-0.0073374291,13.142361,10.594096,152.061,-9.4073029
52.8,1.0241628,-0.11435414,51.190777,0,10.594783,158.31589,-0.0076093152,13.121407,10.594942,155.33279,-9.4032354
55.0,1.0578206,-0.12071843,55.13789,0,10.594783,164.91589,-0.0079913205,13.574262,10.593656,159.8075,-9.3992357
57.2,1.0815483,-0.12823685,57.731308,0,10.594783,171.51588,-0.0085261604,13.89358,10.59423,166.40346,-9.3954802
59.4,1.0918852,-0.13697805,58.636784,0,10.594783,178.11589,-0.0090821609,14.03446,10.594531,174.86943,-9.3914557
61.6,1.0966625,-0.14724551,58.33741,0,10.594783,184.7159,-0.0097974977,14.109458,10.59493,183.98621,-9.3881073
63.8,1.0875119,-0.15398254,56.986298,0,10.594783,191.3159,-0.010200188,13.990658,10.595135,192.62103,-9.3844242
66.0,1.0894057,-0.16055524,55.5359,0,10.594783,197.91588,-0.010661844,14.021697,10.594374,200.17831,-9.3807516
68.2,1.0737562,-0.16607384,54.35004,0,10.594783,204.51588,-0.010999547,13.829996,10.593566,206.54477,-9.3769941
70.4,1.0782011,-0.17017478,54.305424,0,10.594783,211.11589,-0.011295416,13.888252,10.595144,212.03001,-9.3735065
72.6,1.0754812,-0.1751489,55.535641,0,10.594783,217.71588,-0.011610539,13.850049,10.594634,216.68701,-9.3699417
74.8,1.0881444,-0.18062252,57.260727,0,10.594783,224.3159,-0.011982713,14.014631,10.593843,221.78998,-9.3663683
77.0,1.0947253,-0.18764845,58.853638,0,10.594783,230.91589,-0.012423418,14.11204,10.594566,227.93671,-9.3622704
79.2,1.0915011,-0.19553967,59.69186,0,10.594783,237.5159,-0.012954132,14.087378,10.594702,235.18451,-9.3586416
81.4,1.0966133,-0.203559,60.074696,0,10.594783,244.11589,-0.013474403,14.161969,10.593906,242.78235,-9.3544483
83.6,1.095633,-0.21115875,59.756649,0,10.594783,250.7159,-0.013969949,14.135123,10.594975,250.59743,-9.350564
85.8,1.0874664,-0.21845925,59.106449,0,10.594783,257.31616,-0.014455089,14.046485,10.594933,258.23117,-9.3466434
88.0,1.0850234,-0.2243735,58.33741,0,10.594783,263.91589,-0.014826572,14.037949,10.595277,265.12857,-9.3428278
90.2,1.0879016,-0.22941799,58.07415,0,10.594783,270.5159,-0.015192159,14.05014,10.594547,271.26376,-9.3389282
92.4,1.0901158,-0.23511295,58.59008,0,10.594783,277.11588,-0.015534137,14.096232,10.59492,276.81796,-9.3353434
94.6,1.0954599,-0.24075156,59.53867,0,10.594783,283.71588,-0.01594523,14.165539,10.594227,282.37292,-9.3319836
96.8,1.0933031,-0.24730897,60.341934,0,10.594783,290.31592,-0.016343914,14.154193,10.594917,288.50137,-9.3279028
99.0,1.0838306,-0.25480616,61.237789,0,10.594783,296.91592,-0.01685602,14.037039,10.594894,294.8559,-9.3243837
101.2,1.0927567,-0.26225117,61.842953,0,10.594783,303.5159,-0.017316762,14.158832,10.59431,301.93085,-9.3204336
103.4,1.0988495,-0.27221188,61.908215,0,10.594783,310.11591,-0.01799215,14.240065,10.594614,309.28253,-9.3167067
105.6,1.1071607,-0.27857214,61.907955,0,10.594783,316.71591,-0.018396514,14.344586,10.59513,316.57663,-9.3132763
107.8,1.0848249,-0.28517976,61.468513,0,10.594783,323.31589,-0.018810926,14.076746,10.59496,323.92636,-9.3099136
110.0,1.0922859,-0.29125157,60.979519,0,10.594783,329.91589,-0.019240569,14.195509,10.594905,330.83362,-9.3054962
112.2,1.0972848,-0.29711199,60.787361,0,10.594783,336.51587,-0.019593088,14.245091,10.595177,337.11066,-9.3019686
114.4,1.0982866,-0.30270573,61.018063,0,10.594783,343.11591,-0.019996367,14.259001,10.594544,343.03705,-9.2991476
116.6,1.0991648,-0.30832282,61.344669,0,10.594783,349.71591,-0.020348851,14.27172,10.595163,349.07315,-9.2951813
118.8,1.1047175,-0.31533021,61.688229,0,10.594783,356.31592,-0.020822685,14.369764,10.594266,355.54535,-9.2913141
121.0,1.096891,-0.32281008,62.40657,0,10.594783,362.91589,-0.021291964,14.271287,10.595719,361.49945,-9.2873821
123.2,1.1020846,-0.32794461,62.755573,0,10.594783,369.5159,-0.021613088,14.310054,10.593221,368.35721,-9.2840328
125.4,1.0936607,-0.33527777,63.236439,0,10.594783,376.11591,-0.022119172,14.224185,10.594174,374.957,-9.2798424
127.6,1.0994415,-0.34186929,63.369152,0,10.594783,382.71588,-0.022513291,14.323614,10.594544,382.07721,-9.275897
129.8,1.0990876,-0.34770307,62.99474,0,10.594783,389.31589,-0.022938944,14.312115,10.59481,389.59396,-9.2721262
132.0,1.1027354,-0.35322067,62.753914,0,10.594783,395.91586,-0.023271848,14.380979,10.594769,396.57526,-9.268487
134.2,1.104917,-0.36012048,62.574886,0,10.594783,402.5159,-0.023738233,14.40266,10.594754,402.86798,-9.2649002
136.4,1.1061507,-0.36550665,63.171383,0,10.594783,409.11588,-0.024065504,14.429549,10.595176,408.505,-9.2611713
138.6,1.1002275,-0.37076324,63.956268,0,10.594783,415.71591,-0.024399072,14.341276,10.594046,414.22134,-9.2579174
140.8,1.0917783,-0.37804779,64.35788,0,10.594783,422.31592,-0.024908312,14.247788,10.595203,420.94662,-9.2537374
143.0,1.0991894,-0.3847059,64.173439,0,10.594783,428.91589,-0.025329428,14.367037,10.595541,428.56607,-9.2501545
145.2,1.0990807,-0.39047951,63.671768,0,10.594783,435.51593,-0.025700402,14.352656,10.595153,436.44879,-9.2459717
147.4,1.0710157,-0.39316037,60.339169,0,10.594783,442.11591,-0.025874102,14.002048,10.594515,447.72037,-9.2424889
149.6,1.0510368,-0.39486104,59.855816,0,10.594783,448.71588,-0.025968026,13.729347,10.594468,451.62683,-9.2387381
151.8,1.0640174,-0.39641446,57.908161,0,10.594783,449.9989,-0.026107542,13.912767,10.593949,454.34207,-9.238142
154.0,1.029723,-0.39723235,54.396759,0,10.594783,449.9989,-0.026136341,13.458755,10.594941,455.77905,-9.2380533
156.2,1.0066221,-0.39323825,52.291527,0,10.594783,449.9989,-0.025845075,13.141052,10.595391,454.401,-9.2379904
158.4,0.989178,-0.39006683,51.931915,0,10.594783,449.9989,-0.025700197,12.918233,10.594289,452.22028,-9.2379942
160.6,0.98036039,-0.38767099,53.316376,0,10.594783,449.9989,-0.025513358,12.814604,10.594596,449.40689,-9.2377338
162.8,0.98583794,-0.38695437,55.535625,0,10.594783,449.9989,-0.025452757,12.888778,10.594848,447.35449,-9.2378988
165.0,1.0220493,-0.38806462,57.451012,0,10.594783,449.9989,-0.02556631,13.347778,10.595205,446.75409,-9.2381573
167.2,1.0388781,-0.38940191,58.337399,0,10.594783,449.9989,-0.025627866,13.556391,10.593963,447.42783,-9.2377005
169.4,1.0423924,-0.3930541,58.59008,0,10.594783,449.9989,-0.025875293,13.614765,10.594409,448.87262,-9.2375984
171.6,1.0678223,-0.39483157,57.812088,0,10.594783,449.9989,-0.02599315,13.94987,10.593705,450.4996,-9.2376604
173.8,1.0593549,-0.3973434,56.457249,0,10.594783,449.9989,-0.026133543,13.847994,10.594546,451.73221,-9.237215
176.0,1.0368749,-0.39680448,55.245304,0,10.594783,449.9989,-0.026114732,13.556097,10.59522,452.10614,-9.2374487
178.2,1.034875,-0.3960703,54.640606,0,10.594783,449.9989,-0.026054891,13.51144,10.594717,451.5192,-9.2375832
180.4,1.0227532,-0.39725006,54.732746,0,10.594783,449.9989,-0.026127473,13.366062,10.593945,450.54517,-9.2374916
182.6,1.0135999,-0.39611033,55.535805,0,10.594783,449.9989,-0.026070664,13.253385,10.594829,449.38284,-9.237422
184.8,1.0280638,-0.39619693,56.383072,0,10.594783,449.9989,-0.026061399,13.439307,10.595053,448.84247,-9.2371159
187.0,1.047935,-0.39624441,56.758427,0,10.594783,449.9989,-0.026065759,13.698432,10.594443,448.94604,-9.2371902
189.2,1.0677756,-0.3985047,56.874687,0,10.594783,449.9989,-0.026215689,13.947452,10.594421,449.50504,-9.2372093
191.4,1.0657965,-0.39987719,56.662312,0,10.594783,449.9989,-0.026297895,13.942356,10.594011,450.05908,-9.2370787
193.6,1.0736027,-0.40041336,56.248093,0,10.594783,449.9989,-0.026324432,14.048778,10.594157,450.42963,-9.2370739
195.2807,1.08629,0.021941997,44.2533,0,10.5948,0.13881719,0.0013124271,13.684969,10.593775,450.56415,-9.2358418
195.2851,1.0747929,0.029299723,19.60577,0,10.5948,1.3847854e-31,0.0016863282,13.714463,10.594881,450.56415,-9.2371368
195.2895,1.0683503,0.023756983,0.0,0,10.5948,0.0,0.0014918679,13.531237,10.595439,450.55341,-9.2371626
195.2939,1.0461348,0.026588447,0.0,0,10.5948,0.0,0.0015082771,13.333571,10.595837,450.50079,-9.2366695
195.2983,1.0646234,0.022325616,0.0,0,10.5948,0.0,0.0013604774,13.603518,10.595381,450.44821,-9.2370949
195.3027,1.0593214,0.026760932,0.0,0,10.5948,0.0,0.0015568633,13.35923,10.595858,450.51755,-9.2361917
195.3071,1.0292628,0.023059441,0.0,0,10.5948,0.0,0.0014257614,13.143842,10.594553,450.59641,-9.2370539
195.3115,1.0311407,0.027209539,0.0,0,10.5948,0.0,0.0015509189,13.191534,10.597516,450.60693,-9.2373981
195.3159,1.0440558,0.022726066,0.0,0,10.5948,0.0,0.0014093131,13.215602,10.595473,450.58063,-9.2378025
195.3203,1.0339776,0.027196081,0.0,0,10.5948,0.0,0.0015457073,13.123564,10.595569,450.56415,-9.2370262
195.3247,1.013189,0.023331778,0.0,0,10.5948,0.0,0.0014185705,12.954818,10.595016,450.56415,-9.2365437
195.3291,1.0146568,0.027665118,0.0,0,10.5948,0.0,0.0016456996,12.932772,10.595832,450.5679,-9.2369318
195.3335,1.0267789,0.022987615,0.0,0,10.545863,0.0,0.0014266879,13.012377,10.593472,450.60736,-9.2370644
195.3379,1.0256181,0.027783806,0.0,0,10.479863,0.0,0.0016698246,13.108517,10.591748,450.64682,-9.2361279
195.3423,1.0178772,0.022777421,0.0,0,10.413863,0.0,0.0014442928,12.953433,10.564794,450.63248,-9.2370214
195.3467,1.0081245,0.027448909,0.0,0,10.347863,0.0,0.0016775625,12.816184,10.490692,450.6062,-9.2365732
195.3511,1.0217984,0.022381796,0.0,0,10.281863,0.0,0.0014350899,12.998472,10.379069,450.60123,-9.2375908
195.3555,1.0303315,0.027648911,0.0,0,10.215863,0.0,0.0016921369,13.161004,10.288288,450.61435,-9.2366896
195.3599,1.0211372,0.023753248,0.0,0,10.149863,0.0,0.0015467089,12.886387,10.226197,450.63791,-9.2364187
195.3643,1.0119674,0.026435198,0.0,0,10.083863,0.0,0.0016661669,12.916864,10.17786,450.69052,-9.2368469
195.3687,1.009552,0.023663437,0.0,0,10.017863,0.0,0.0015221278,12.891905,10.122355,450.74313,-9.2366095
195.3731,1.1808445,0.02737971,0.0,0,9.9518623,0.0,0.0017373204,14.885143,10.055085,451.08102,-9.2369843
195.3775,3.3304214,0.041436486,0.0,0,9.8858624,0.0,0.0027355102,42.103737,9.9889021,451.42288,-9.2348089
195.3819,3.9207034,0.10978316,0.0,0,9.8198624,0.0,0.0072336099,49.423981,9.9214153,455.15524,-9.2340097
195.3863,4.1589546,0.17760183,0.0,0,9.7538624,0.0,0.011924358,52.359917,9.842473,460.2785,-9.2347698
195.3907,4.2384601,0.24731132,0.0,0,9.6878624,0.0,0.016601384,53.119778,9.7743044,465.86023,-9.2343864
195.3951,4.2534833,0.30687016,0.0,0,9.6218624,0.0,0.020687949,53.0299,9.7060242,472.04517,-9.2353821
195.3995,4.3100328,0.37381679,0.0,0,9.5558634,0.0,0.025330259,53.439789,9.6461439,477.55801,-9.2336588
195.4039,4.4107442,0.43543246,0.0,0,9.4898624,0.0,0.029435439,54.450016,9.574255,479.39432,-9.2339096
195.4083,4.4308581,0.50618249,0.0,0,9.4252844,0.0,0.034353707,54.593105,9.5031881,481.23062,-9.2333689
195.4127,4.4337358,0.56997502,0.0,0,9.3609037,0.0,0.038800884,54.267998,9.4394751,482.12335,-9.2353296
195.4171,4.4618692,0.63799536,0.0,0,9.2965231,0.0,0.043542128,54.380348,9.3730688,482.88412,-9.2363033
195.4215,4.4950218,0.70448256,0.0,0,9.2321424,0.0,0.048129831,54.605553,9.3039103,483.47961,-9.2353754
195.4259,4.5098734,0.7704221,0.0,0,9.1677618,0.0,0.052801531,54.539383,9.237711,483.9649,-9.2369833
195.4303,4.4892993,0.82881486,0.0,0,9.1033802,0.0,0.056927931,54.105801,9.1725454,484.40363,-9.2371588
195.4347,4.5214634,0.89273697,0.0,0,9.0389996,0.0,0.061525449,54.109924,9.1097555,484.74466,-9.2358389
195.4391,4.5518956,0.95439094,0.0,0,8.9746189,0.0,0.065788485,54.184669,9.0422306,485.08331,-9.2362099
195.4435,4.6130924,1.0202857,0.0,0,8.9102383,0.0,0.070628285,54.695782,8.9781599,485.37189,-9.2352781
195.4479,4.6124606,1.0819534,0.0,0,8.8458576,0.0,0.07500682,54.502804,8.9110947,485.66046,-9.2339678
195.4523,4.6190948,1.1455641,0.0,0,8.781476,0.0,0.079686776,54.317104,8.8489609,485.88858,-9.2360973
195.4567,4.6668262,1.2089425,0.0,0,8.7187147,0.0,0.084208593,54.597267,8.7804804,486.09842,-9.2366962
195.4611,4.7094092,1.276019,0.0,0,8.657485,0.0,0.089150302,54.846664,8.7153778,486.21814,-9.2342281
195.4655,4.6719832,1.3364984,0.0,0,8.5962543,0.0,0.093462825,54.173931,8.6496811,486.24438,-9.2340584
195.4699,4.6481686,1.3958036,0.0,0,8.5350246,0.0,0.097936101,53.614506,8.5940962,486.27621,-9.2345762
195.4743,4.6922135,1.4525522,0.0,0,8.473794,0.0,0.10212015,53.85585,8.5350275,486.32867,-9.235158
195.4787,4.7515688,1.5155653,0.0,0,8.4125633,0.0,0.1067854,54.382858,8.4700794,486.38116,-9.2347946
195.4831,4.7633061,1.5762939,0.0,0,8.3513327,0.0,0.11120595,54.221603,8.4072361,486.58099,-9.2343483
195.4875,4.7521868,1.6347795,0.0,0,8.290102,0.0,0.11564908,53.950958,8.3464832,486.79086,-9.2341194
195.4919,4.79526,1.6957792,0.0,0,8.2288723,0.0,0.12021676,54.145042,8.2826996,486.99207,-9.2357302
195.4963,4.8302655,1.7580671,0.0,0,8.1676416,0.0,0.12499443,54.265759,8.2264719,487.18881,-9.2363167
195.5007,4.8542032,1.8185378,0.0,0,8.1064119,0.0,0.12944086,54.261765,8.1636839,487.38556,-9.2348404
195.5051,4.8835263,1.8784375,0.0,0,8.0456295,0.0,0.13406651,54.386158,8.0997744,487.58231,-9.2355061
195.5095,4.8933043,1.9445788,0.0,0,7.9873734,0.0,0.1390574,54.193108,8.0357361,487.77768,-9.2354794
195.5139,4.8970213,2.0050061,0.0,0,7.9291167,0.0,0.14378244,53.941948,7.971633,487.9613,-9.2339315
195.5183,4.883461,2.0618632,0.0,0,7.8708611,0.0,0.1480602,53.650566,7.9105463,488.14496,-9.2354345
195.5227,4.876029,2.1166532,0.0,0,7.8126049,0.0,0.15235795,53.273933,7.8572774,488.26349,-9.2357626
195.5271,4.9174552,2.1727376,0.0,0,7.7543492,0.0,0.156661,53.537369,7.800827,488.36844,-9.234827
195.5315,4.9716706,2.229496,0.0,0,7.6960936,0.0,0.16112368,53.828102,7.7440367,488.45892,-9.2342615
195.5359,5.0152688,2.2911839,0.0,0,7.6378374,0.0,0.16593336,54.088844,7.6785316,488.53763,-9.2340393
195.5403,5.0226474,2.3477314,0.0,0,7.5795813,0.0,0.17042682,53.866131,7.6235828,488.62347,-9.23493
195.5447,5.0149364,2.4084899,0.0,0,7.5213251,0.0,0.17517659,53.660282,7.562252,488.72839,-9.2340422
195.5491,5.0357046,2.4622874,0.0,0,7.4630694,0.0,0.17946234,53.495392,7.5040197,488.83331,-9.2348976
195.5535,5.087822,2.5223446,0.0,0,7.4048128,0.0,0.18422338,53.866783,7.4477944,488.80768,-9.234746
195.5579,5.1096287,2.5793982,0.0,0,7.3488007,0.0,0.18873785,53.902687,7.3871541,488.78143,-9.2340078
195.5623,5.0871243,2.6391306,0.0,0,7.293396,0.0,0.19358607,53.418789,7.329443,488.58566,-9.233922
195.5667,5.1075969,2.6935241,0.0,0,7.2379909,0.0,0.19796997,53.326073,7.2711554,488.32333,-9.2349854
195.5711,5.1321592,2.7496927,0.0,0,7.1825862,0.0,0.20255469,53.335335,7.2199759,487.93954,-9.234786
195.5755,5.1455674,2.7996378,0.0,0,7.1271815,0.0,0.20661037,53.259453,7.1654739,487.40179,-9.2354774
195.5799,5.1860051,2.8567314,0.0,0,7.0717769,0.0,0.21135104,53.371948,7.1117425,486.40894,-9.2357988
195.5843,5.1862621,2.9120288,0.0,0,7.0163722,0.0,0.2157817,53.241093,7.0536509,483.09012,-9.2342644
195.5887,5.2412281,2.96911,0.0,0,6.9609671,0.0,0.22052059,53.454395,6.9968104,479.77133,-9.2347431
195.5931,5.2714295,3.0230973,0.0,0,6.9055624,0.0,0.22503096,53.578953,6.9400029,475.99829,-9.2340975
195.5975,5.285378,3.0817478,0.0,0,6.8501582,0.0,0.22993129,53.538902,6.8825035,472.16702,-9.2350893
195.6019,5.2768497,3.136055,0.0,0,6.7947526,0.0,0.23450147,53.146187,6.8207107,470.26947,-9.2350454
195.6063,5.2868276,3.191463,0.0,0,6.7404876,0.0,0.23917072,52.944523,6.7692876,469.61295,-9.2338648
195.6107,5.3327956,3.2435343,0.0,0,6.6877756,0.0,0.24356942,53.283661,6.7176442,469.27884,-9.2355652
195.6151,5.3544407,3.2989621,0.0,0,6.6350632,0.0,0.24820633,53.1642,6.6593871,469.59396,-9.2346087
195.6195,5.3247018,3.3468549,0.0,0,6.5823517,0.0,0.25236923,52.611736,6.6091046,469.90051,-9.2341347
195.6239,5.3450651,3.4035363,0.0,0,6.5296397,0.0,0.25708061,52.534992,6.5557942,470.05807,-9.2342587
195.6283,5.3890185,3.4517739,0.0,0,6.4769278,0.0,0.26131502,52.868988,6.5052137,470.21564,-9.2336941
195.6327,5.4249344,3.5043318,0.0,0,6.4242158,0.0,0.26586971,52.956142,6.451417,470.55692,-9.2350616
195.6371,5.448843,3.5572381,0.0,0,6.3715038,0.0,0.27048206,52.913437,6.3965368,470.95087,-9.2345219
195.6415,5.4700842,3.6153679,0.0,0,6.3187919,0.0,0.27542189,52.841015,6.3443112,471.50238,-9.2346001
195.6459,5.5064645,3.6638908,0.0,0,6.2660799,0.0,0.27977225,53.060551,6.2888336,472.21143,-9.2355547
195.6503,5.4998846,3.7183857,0.0,0,6.2133679,0.0,0.28457907,52.667809,6.235393,472.92044,-9.2339211
195.6547,5.4768429,3.7667341,0.0,0,6.1608105,0.0,0.28880516,52.270912,6.1881208,473.62921,-9.2359324
195.6591,5.5471082,3.8210199,0.0,0,6.1106758,0.0,0.29358441,52.680332,6.1321139,474.33798,-9.234479
195.6635,5.5595937,3.8689485,0.0,0,6.0605426,0.0,0.29795703,52.608963,6.0829782,475.05878,-9.2340345
195.6679,5.6036372,3.9252944,0.0,0,6.0104089,0.0,0.30297768,52.684963,6.0302157,475.78027,-9.234066
195.6723,5.6116438,3.9721682,0.0,0,5.9602752,0.0,0.30732042,52.612892,5.9801865,476.56305,-9.2347555
195.6767,5.6060762,4.0262852,0.0,0,5.9101419,0.0,0.31208542,52.266769,5.9289479,477.37625,-9.2346983
195.6811,5.6363559,4.0742774,0.0,0,5.8600082,0.0,0.31659296,52.269276,5.876739,478.21887,-9.2351789
195.6855,5.6827707,4.1269531,0.0,0,5.8098745,0.0,0.32126567,52.390213,5.8304501,479.10727,-9.233016
195.6899,5.7122002,4.1736989,0.0,0,5.7597408,0.0,0.32570302,52.483814,5.7788601,479.96088,-9.234622
195.6943,5.685216,4.2289138,0.0,0,5.7096071,0.0,0.33062649,52.027519,5.7254763,480.72162,-9.2348261
195.6987,5.669744,4.2716279,0.0,0,5.6594739,0.0,0.3347809,51.630951,5.676868,481.48239,-9.2360744
195.7031,5.7280684,4.3229451,0.0,0,5.6093402,0.0,0.33935428,51.971184,5.6299596,482.11258,-9.2332478
195.7075,5.8023272,4.3682208,0.0,0,5.5609031,0.0,0.34386864,52.383667,5.5800219,482.74216,-9.2337179
195.7119,5.8186312,4.4249196,0.0,0,5.513207,0.0,0.3489652,52.301533,5.5283446,483.23044,-9.2353554
195.7163,5.8162594,4.471374,0.0,0,5.4655113,0.0,0.35369703,51.975552,5.474905,483.66327,-9.2346182
195.7207,5.8052974,4.5221076,0.0,0,5.4178152,0.0,0.3583084,51.621189,5.4289246,484.05563,-9.2337418
195.7251,5.8277097,4.5631323,0.0,0,5.3701191,0.0,0.36235607,51.655964,5.3828716,484.3967,-9.2333565
195.7295,5.8522458,4.6146712,0.0,0,5.322423,0.0,0.36707512,51.614708,5.3370996,484.72269,-9.2336073
195.7339,5.8694992,4.6569667,0.0,0,5.2747278,0.0,0.37140772,51.548893,5.2898917,484.97192,-9.234849
195.7383,5.9422884,4.7099938,0.0,0,5.2270312,0.0,0.37641042,51.9412,5.2411094,485.22113,-9.2347383
195.7427,5.9486537,4.7536335,0.0,0,5.1793356,0.0,0.38088331,51.824429,5.1899762,485.50522,-9.2337284
195.7471,5.9728861,4.8051777,0.0,0,5.1316395,0.0,0.38574621,51.710777,5.1413617,485.79376,-9.2349014
195.7515,6.0097814,4.8501534,0.0,0,5.0839434,0.0,0.39029482,51.752464,5.0940423,486.0184,-9.2348442
195.7559,6.0349832,4.9012756,0.0,0,5.0370221,0.0,0.39524117,51.656914,5.0447087,486.20206,-9.2340441
195.7603,6.0619144,4.9449425,0.0,0,4.9916587,0.0,0.39977419,51.807606,5.0019846,486.21161,-9.2336779
195.7647,6.077929,4.9987607,0.0,0,4.9462943,0.0,0.40501404,51.639545,4.9534607,485.87057,-9.2332945
195.7691,6.0484819,5.0383005,0.0,0,4.9009304,0.0,0.40912661,51.179111,4.907887,485.5267,-9.2347784
195.7735,6.0882707,5.0859952,0.0,0,4.855566,0.0,0.41385677,51.164543,4.8601618,485.13318,-9.2340326
195.7779,6.1066236,5.1276078,0.0,0,4.8102026,0.0,0.41811734,51.141533,4.8195877,484.73969,-9.2352524
195.7823,6.1332259,5.172339,0.0,0,4.7648382,0.0,0.42257798,51.20084,4.7762761,484.45831,-9.2329903
195.7867,6.1703615,5.2158399,0.0,0,4.7194743,0.0,0.42720303,51.297596,4.7317462,484.20911,-9.2355471
195.7911,6.2164469,5.263895,0.0,0,4.6741104,0.0,0.43212491,51.397316,4.6819825,484.21567,-9.2342958
195.7955,6.2554808,5.3083644,0.0,0,4.6287465,0.0,0.43675616,51.423882,4.6346049,484.478,-9.2349319
195.7999,6.2522216,5.3544989,0.0,0,4.5833826,0.0,0.44140923,51.241016,4.5936084,484.77539,-9.2345734
195.8043,6.3136649,5.3966961,0.0,0,4.5380182,0.0,0.44592068,51.550339,4.549149,485.19513,-9.2344351
195.8087,6.3802752,5.4510579,0.0,0,4.4947939,0.0,0.4516311,51.729206,4.4981217,485.61487,-9.23384
195.8131,6.3611894,5.4930692,0.0,0,4.4516387,0.0,0.45612139,51.307472,4.4480343,485.83618,-9.2339592
195.8175,6.2741647,5.5377088,0.0,0,4.4084835,0.0,0.46081483,50.488235,4.4110098,486.04602,-9.2330084
195.8219,6.2941976,5.5703692,0.0,0,4.3653283,0.0,0.4643473,50.315735,4.3725147,485.7388,-9.2344294
195.8263,6.3554025,5.6153631,0.0,0,4.3221731,0.0,0.46913025,50.627178,4.3320889,485.17477,-9.2342548
195.8307,6.4816613,5.655736,0.0,0,4.2790179,0.0,0.47344792,51.36235,4.2858219,483.41571,-9.2340975
195.8351,6.542531,5.7017913,0.0,0,4.2358627,0.0,0.47846624,51.620533,4.2427573,479.79465,-9.2332335
195.8395,6.5484805,5.7466555,0.0,0,4.1927075,0.0,0.48330459,51.39505,4.1950598,476.30777,-9.2323465
195.8439,6.5003533,5.7905788,0.0,0,4.1495523,0.0,0.48810425,50.763988,4.1507316,473.86765,-9.2337694
195.8483,6.5261559,5.8290067,0.0,0,4.1063972,0.0,0.49228638,50.734962,4.1118908,471.42749,-9.2351151
195.8527,6.6463537,5.875134,0.0,0,4.063242,0.0,0.49741045,51.383434,4.069437,471.0282,-9.2343273
195.8571,6.6473184,5.9164762,0.0,0,4.0213642,0.0,0.50192094,51.31287,4.0253797,471.0282,-9.2340345
195.8615,6.6600146,5.9600396,0.0,0,3.9803216,0.0,0.50683779,51.049339,3.982302,470.94009,-9.2350655
195.8659,6.6832557,6.0023479,0.0,0,3.9392784,0.0,0.51144814,51.009178,3.9386566,470.78253,-9.2339363
195.8703,6.7286291,6.0456347,0.0,0,3.8982351,0.0,0.51637822,51.037518,3.8976924,470.93948,-9.2353086
195.8747,6.7487893,6.0842633,0.0,0,3.8571918,0.0,0.52065623,51.063118,3.8559971,471.89792,-9.2332678
195.8791,6.7673635,6.126122,0.0,0,3.8161488,0.0,0.5253948,50.90926,3.81919,472.85785,-9.2345057
195.8835,6.8191772,6.164649,0.0,0,3.7751055,0.0,0.52981013,51.098721,3.7776053,474.14389,-9.2335196
195.8879,6.9079833,6.2112293,0.0,0,3.7340622,0.0,0.5351553,51.455341,3.7295952,475.42996,-9.2339888
195.8923,6.9023485,6.2525797,0.0,0,3.6930192,0.0,0.53982711,51.20364,3.68945,476.74417,-9.2351236
195.8967,6.8497477,6.2910981,0.0,0,3.6519756,0.0,0.54424083,50.631348,3.6492169,478.06894,-9.2333555
195.9011,6.914999,6.3279042,0.0,0,3.6109326,0.0,0.54846615,50.826805,3.6120241,479.14578,-9.2349319
195.9055,6.9932604,6.3719406,0.0,0,3.5703721,0.0,0.55363268,51.197987,3.5702453,479.91968,-9.2331781
195.9099,7.0717773,6.4125924,0.0,0,3.5313263,0.0,0.55821836,51.509178,3.5281663,480.60745,-9.2338209
195.9143,7.0387988,6.4534793,0.0,0,3.4922807,0.0,0.56310129,51.020088,3.4855349,480.8829,-9.233427
195.9187,7.0399604,6.4905229,0.0,0,3.4532354,0.0,0.56733179,50.841797,3.4514487,481.15833,-9.2326899
195.9231,7.1023893,6.5294518,0.0,0,3.4141896,0.0,0.57199448,51.045979,3.4105315,481.6687,-9.2339354
195.9275,7.1482558,6.5706768,0.0,0,3.3751438,0.0,0.5767628,51.146103,3.3740256,482.20648,-9.2345257
195.9319,7.1823797,6.6076717,0.0,0,3.3360982,0.0,0.58124411,51.151104,3.333452,482.66318,-9.2328014
195.9363,7.1953092,6.6471992,0.0,0,3.2970529,0.0,0.58589965,51.048096,3.2973382,483.06976,-9.2334614
195.9407,7.223412,6.6850076,0.0,0,3.2580073,0.0,0.59049183,50.956432,3.2569315,483.41824,-9.2342253
195.9451,7.2743492,6.7225623,0.0,0,3.2189617,0.0,0.59504294,51.124931,3.2195461,483.65436,-9.2345724
195.9495,7.3617206,6.7589588,0.0,0,3.1799159,0.0,0.59942287,51.451962,3.1805949,483.88879,-9.2327566
195.9539,7.374361,6.8031812,0.0,0,3.1408703,0.0,0.60469609,51.254013,3.1378815,484.09863,-9.233448
195.9583,7.3889856,6.8405218,0.0,0,3.1034932,0.0,0.60928768,51.137161,3.0993235,484.3085,-9.2346029
195.9627,7.4819207,6.8790016,0.0,0,3.0663483,0.0,0.61391282,51.515572,3.059341,484.55963,-9.2351007
195.9671,7.5051684,6.9169192,0.0,0,3.0292037,0.0,0.61871952,51.512848,3.0225375,484.82196,-9.2351112
195.9715,7.5142322,6.9545674,0.0,0,2.992059,0.0,0.62328452,51.294121,2.9853806,485.16443,-9.235487
195.9759,7.5366268,6.9923296,0.0,0,2.9549141,0.0,0.62781519,51.204468,2.9480734,485.58414,-9.2331295
195.9803,7.5704193,7.0285912,0.0,0,2.9177692,0.0,0.63234043,51.162697,2.9121156,485.99777,-9.2339849
195.9847,7.6600928,7.0630555,0.0,0,2.8806243,0.0,0.63667303,51.601746,2.8778107,486.3913,-9.2328129
195.9891,7.7174487,7.1026063,0.0,0,2.8434796,0.0,0.64162904,51.737644,2.8409076,486.78479,-9.2341595
195.9935,7.7278075,7.1401377,0.0,0,2.8063347,0.0,0.64642346,51.568249,2.8036885,486.67746,-9.2339773
195.9979,7.8088989,7.1796236,0.0,0,2.7691898,0.0,0.65127397,51.814499,2.7646756,486.5463,-9.2331934
196.0023,7.8596387,7.2176113,0.0,0,2.7320454,0.0,0.6562252,51.977371,2.7289484,478.69998,-9.23423
196.0067,7.9192572,7.2546268,0.0,0,2.6958327,0.0,0.66085064,52.131432,2.6900733,467.1774,-9.2346296
196.0111,7.9318933,7.2922201,0.0,0,2.6605008,0.0,0.66580254,51.888096,2.6533086,456.63928,-9.2331047
196.0155,7.9241781,7.3292656,0.0,0,2.6251688,0.0,0.67050326,51.595112,2.6184845,447.57779,-9.2346888
196.0199,7.9787617,7.3629127,0.0,0,2.5898366,0.0,0.67485785,51.703053,2.5799706,440.10645,-9.2329283
196.0243,8.0032883,7.3974214,0.0,0,2.5545046,0.0,0.67936653,51.731228,2.5514283,444.00134,-9.2338886
196.0287,8.05264,7.4295702,0.0,0,2.5191727,0.0,0.68356258,51.735558,2.5197635,447.89621,-9.2343044
196.0331,8.1277571,7.4670939,0.0,0,2.4838405,0.0,0.68844146,51.956516,2.4814529,451.12158,-9.2340441
196.0375,8.2221537,7.5001655,0.0,0,2.4485085,0.0,0.6928609,52.323147,2.4439282,454.22455,-9.2338305
196.0419,8.3000383,7.5413408,0.0,0,2.4131765,0.0,0.69816768,52.574951,2.4106801,456.82639,-9.2339287
196.0463,8.3342428,7.5749397,0.0,0,2.3778446,0.0,0.70275784,52.609688,2.3741798,459.04733,-9.233882
196.0507,8.364769,7.6141181,0.0,0,2.3425126,0.0,0.70793474,52.476631,2.33761,460.96216,-9.2346773
196.0551,8.410162,7.6473341,0.0,0,2.3074403,0.0,0.7124663,52.555649,2.2987268,462.1308,-9.2346067
196.0595,8.4890203,7.6854415,0.0,0,2.273833,0.0,0.71769309,52.694321,2.267745,463.2717,-9.234025
196.0639,8.467927,7.7159524,0.0,0,2.2402258,0.0,0.72180474,52.400341,2.232599,462.405,-9.233139
196.0683,8.4934216,7.751802,0.0,0,2.2066188,0.0,0.72660029,52.335346,2.2034152,461.53833,-9.23244
196.0727,8.5683784,7.7844558,0.0,0,2.1730115,0.0,0.7311222,52.47226,2.1673822,460.93277,-9.2341881
196.0771,8.6511583,7.8186455,0.0,0,2.1394043,0.0,0.73590523,52.716484,2.1336904,460.42065,-9.2334404
196.0815,8.7014408,7.8488464,0.0,0,2.1057971,0.0,0.74015296,52.824512,2.1009948,460.75858,-9.2336245
196.0859,8.7512321,7.8876591,0.0,0,2.07219,0.0,0.74539042,52.913528,2.0704155,462.09793,-9.2332401
196.0903,8.8325253,7.9179988,0.0,0,2.0385828,0.0,0.74971104,53.10928,2.0318246,463.28928,-9.2332268
196.0947,8.922184,7.9544582,0.0,0,2.0049756,0.0,0.75463581,53.373455,1.9986707,463.81451,-9.2328568
196.0991,8.9409847,7.9896789,0.0,0,1.9713683,0.0,0.75990152,53.244011,1.9640645,464.33975,-9.2329273
196.1035,8.9499798,8.0224047,0.0,0,1.9377612,0.0,0.76438779,53.068806,1.9296514,465.76767,-9.234561
196.1079,9.0226192,8.0505419,0.0,0,1.905442,0.0,0.76865178,53.215366,1.9020512,467.29086,-9.2339315
196.1123,9.1119356,8.0871058,0.0,0,1.8734715,0.0,0.77364093,53.475544,1.8660488,469.15997,-9.2323132
196.1167,9.1581192,8.1165113,0.0,0,1.8415012,0.0,0.77826637,53.565811,1.8368877,471.23462,-9.2346935
196.1211,9.2120581,8.1522789,0.0,0,1.8095309,0.0,0.78306949,53.578186,1.8007172,472.54636,-9.2335606
196.1255,9.3175459,8.1800127,0.0,0,1.7775605,0.0,0.78758645,53.924461,1.7723053,472.44135,-9.2333078
196.1299,9.3574076,8.2180738,0.0,0,1.74559,0.0,0.79271775,53.836712,1.7381532,472.26181,-9.2339382
196.1343,9.4597874,8.2462778,0.0,0,1.7136196,0.0,0.79742801,54.251995,1.7043041,471.13254,-9.2327757
196.1387,9.4882784,8.2825012,0.0,0,1.6816492,0.0,0.80234158,54.153912,1.672356,470.0033,-9.2331762
196.1431,9.5596647,8.3111773,0.0,0,1.6496787,0.0,0.80704659,54.280651,1.6474745,469.58429,-9.2319956
196.1475,9.6994581,8.3487358,0.0,0,1.6177083,0.0,0.81230098,54.774429,1.6088099,469.34796,-9.2341852
196.1519,9.7727766,8.3795767,0.0,0,1.5857379,0.0,0.81723279,54.900063,1.5761621,469.30212,-9.2333908
196.1563,9.7580051,8.4155254,0.0,0,1.554427,0.0,0.8224684,54.633968,1.5420847,469.43341,-9.2339087
196.1607,9.6940889,8.4394627,0.0,0,1.5240141,0.0,0.82660162,54.006794,1.5189022,469.53308,-9.2335367
196.1651,9.7809124,8.4739256,0.0,0,1.4936013,0.0,0.83155018,54.198536,1.4854457,469.53308,-9.2331791
196.1695,9.9093685,8.4967813,0.0,0,1.4631884,0.0,0.83539164,54.68074,1.4540133,469.53308,-9.2333546
196.1739,9.9976559,8.5333748,0.0,0,1.4327757,0.0,0.8407141,54.938007,1.4291868,470.01392,-9.2329063
196.1783,10.099185,8.559207,0.0,0,1.4023628,0.0,0.84493566,55.238274,1.392861,470.51288,-9.2338037
196.1827,10.208157,8.5946045,0.0,0,1.3719501,0.0,0.85041118,55.498581,1.3649598,471.01184,-9.2325392
196.1871,10.29131,8.6266832,0.0,0,1.3415372,0.0,0.85565543,55.711163,1.3284273,471.51083,-9.2324677
196.1915,10.301049,8.6584864,0.0,0,1.3111246,0.0,0.86044824,55.484119,1.3007741,471.98294,-9.2320108
196.1959,10.237513,8.6824226,0.0,0,1.2807117,0.0,0.86462891,54.890079,1.2724057,472.41626,-9.2326031
196.2003,10.349345,8.7138653,0.0,0,1.2502989,0.0,0.86932927,55.226803,1.2443081,472.75262,-9.2315235
196.2047,10.516313,8.7376566,0.0,0,1.2199751,0.0,0.87349433,55.855934,1.2158378,472.45062,-9.2326727
196.2091,10.623154,8.7718992,0.0,0,1.1910492,0.0,0.87881696,56.17252,1.1855705,472.14859,-9.2335815
196.2135,10.716125,8.8008919,0.0,0,1.1621237,0.0,0.8835656,56.379559,1.154935,471.0387,-9.2313786
196.2179,10.705161,8.8310394,0.0,0,1.133198,0.0,0.88841313,56.090668,1.1252255,469.79129,-9.2334137
196.2223,10.82483,8.8573847,0.0,0,1.1042725,0.0,0.89279974,56.436844,1.0962216,469.39285,-9.2335491
196.2267,10.92145,8.8900108,0.0,0,1.0753468,0.0,0.89835745,56.62571,1.0680708,469.61609,-9.2312422
196.2311,10.995555,8.913703,0.0,0,1.0464213,0.0,0.902156,56.816467,1.0396446,470.34729,-9.2339096
196.2355,11.040578,8.946496,0.0,0,1.0174956,0.0,0.90763503,56.721874,1.0094218,472.26382,-9.2326488
196.2399,11.133315,8.9719906,0.0,0,0.98856997,0.0,0.91201979,56.92107,0.98200589,474.15051,-9.2338991
196.2443,11.28618,9.0042677,0.0,0,0.95964432,0.0,0.9173612,57.365627,0.95227087,474.75436,-9.2332497
196.2487,11.351708,9.0284128,0.0,0,0.93071878,0.0,0.92143559,57.53521,0.9254511,475.35818,-9.2335453
196.2531,11.394665,9.0598764,0.0,0,0.90179312,0.0,0.92705494,57.416988,0.89102799,475.63901,-9.231761
196.2575,11.439081,9.0843782,0.0,0,0.87385368,0.0,0.93109608,57.405857,0.86681038,475.80954,-9.232358
196.2619,11.561727,9.1113777,0.0,0,0.84634483,0.0,0.93563724,57.710369,0.83702362,476.15811,-9.2316999
196.2663,11.619745,9.1369247,0.0,0,0.81883603,0.0,0.94010311,57.830841,0.81243068,476.70901,-9.2325134
196.2707,11.687506,9.1648483,0.0,0,0.79132724,0.0,0.9448902,57.812492,0.78303033,477.17224,-9.2314034
196.2751,11.731158,9.1911802,0.0,0,0.76381844,0.0,0.94930476,57.833023,0.75799209,477.26407,-9.2328949
196.2795,11.953173,9.2182674,0.0,0,0.73630965,0.0,0.95423591,58.557507,0.72857624,477.3559,-9.2311668
196.2839,12.08553,9.2445412,0.0,0,0.70880085,0.0,0.95873803,58.970764,0.70066452,477.65143,-9.232338
196.2883,12.137804,9.2728758,0.0,0,0.68129206,0.0,0.96382588,58.946514,0.6745553,477.96622,-9.2313309
196.2927,12.24647,9.2990055,0.0,0,0.65378326,0.0,0.96832889,59.22496,0.64404237,478.28101,-9.2329836
196.2971,12.334164,9.3276434,0.0,0,0.62627447,0.0,0.97330862,59.316341,0.61752051,478.59579,-9.2331266
196.3015,12.405703,9.3537493,0.0,0,0.59876567,0.0,0.9780274,59.403988,0.58910429,478.48669,-9.2316408
196.3059,12.485666,9.3802824,0.0,0,0.57169855,0.0,0.98294622,59.464031,0.56477773,477.621,-9.2317619
196.3103,12.534783,9.4033813,0.0,0,0.54551852,0.0,0.9868632,59.509884,0.53636438,476.68015,-9.2324562
196.3147,11.840969,9.4186878,0.0,0,0.51933855,0.0,0.98965514,56.062141,0.5149523,474.89554,-9.2330589
196.3191,11.280306,9.4187384,0.0,0,0.49315852,0.0,0.98959655,53.441486,0.49736133,473.11096,-9.2340679
196.3235,10.727235,9.4260206,0.0,0,0.46697855,0.0,0.99076015,50.755554,0.48216915,472.02277,-9.2340183
196.3279,10.415343,9.4268646,0.0,0,0.44079852,0.0,0.99093193,49.257877,0.46468848,471.10379,-9.2340069
196.3323,10.143604,9.4345016,0.0,0,0.41461855,0.0,0.99250883,47.910801,0.44800296,470.80783,-9.2350883
196.3367,9.8781471,9.4342098,0.0,0,0.38843849,0.0,0.99228615,46.658829,0.4226447,471.07047,-9.233984
196.3411,9.5805979,9.4368858,0.0,0,0.36225849,0.0,0.99297911,45.175945,0.40994143,471.4053,-9.2331934
196.3455,9.1817455,9.4390745,0.0,0,0.33607849,0.0,0.99325472,43.296291,0.40057379,471.95679,-9.2349005
196.3499,8.863739,9.4392614,0.0,0,0.3098985,0.0,0.99338502,41.846607,0.39554915,472.50827,-9.2347383
196.3543,8.6944361,9.441021,0.0,0,0.28371853,0.0,0.99342334,40.973133,0.38329172,473.07239,-9.2352304
196.3587,8.7744703,9.4431353,0.0,0,0.25878316,0.0,0.9938854,41.350433,0.3681874,473.63687,-9.2339869
196.3631,9.0548754,9.4448729,0.0,0,0.23388797,0.0,0.99412012,42.639336,0.33397827,474.21942,-9.2340641
196.3675,9.2762871,9.4464893,0.0,0,0.20899279,0.0,0.99455333,43.682632,0.29805243,474.80991,-9.2342501
196.3719,9.3915462,9.4515858,0.0,0,0.1840976,0.0,0.99521822,44.203068,0.26463407,475.24667,-9.2329788
196.3763,9.4680109,9.4519987,0.0,0,0.15920241,0.0,0.99536747,44.573559,0.23612759,475.46967,-9.2340164
196.3807,9.4884176,9.4585609,0.0,0,0.13430719,0.0,0.99624103,44.581165,0.19838281,475.61502,-9.2319012
196.3851,9.4542675,9.458725,0.0,0,0.10941199,0.0,0.99633282,44.455891,0.17934777,475.28711,-9.2337885
196.3895,9.3971796,9.4627123,0.0,0,0.084516786,0.0,0.99701124,44.174316,0.15658051,474.9592,-9.233676
196.3939,9.3558073,9.4634523,0.0,0,0.059621587,0.0,0.99722564,43.943272,0.12715052,474.56326,-9.231822
196.3983,9.3046246,9.4666243,0.0,0,0.034726385,0.0,0.99759245,43.693176,0.10996634,474.15662,-9.233386
196.4027,9.2236328,9.4664717,0.0,0,0.0098311882,0.0,0.99757659,43.3139,0.085771807,473.95764,-9.2351093
196.4071,9.1321907,9.4704552,0.0,0,-0.0146966,0.0,0.99825329,42.834785,0.067125887,473.90518,-9.2338905
196.4115,9.0696688,9.472003,0.0,0,-0.038984597,0.0,0.99832278,42.534222,0.048404954,473.91357,-9.2329006
196.4159,9.0021,9.4738226,0.0,0,-0.063272595,0.0,0.99857605,42.22718,0.031311367,474.05789,-9.2327557
196.4203,8.90662,9.4765882,0.0,0,-0.087560594,0.0,0.99907124,41.778568,0.019652477,474.20596,-9.2339973
196.4247,8.8206644,9.476368,0.0,0,-0.080412276,439.72079,0.99895608,41.362648,0.0045786877,474.46826,-9.2339926
196.4291,8.6763229,9.4786835,0.0,0,0.71587193,450.0,0.99936062,40.731606,-0.0078413663,474.73059,-9.2338676
196.4335,6.8265285,9.4753208,0.0,0,1.51273,450.0,0.99865043,32.175522,0.068509527,474.99292,-9.2348061
196.4379,2.6958814,9.4592018,0.0,0,2.3095884,450.0,0.9957276,12.921723,0.30895013,475.25528,-9.237689
196.4423,-0.01912009,9.4495544,0.0,0,3.1064456,450.0,0.99375594,-0.14831243,1.0340704,475.51761,-9.2409573
196.4467,-0.058153111,9.4414845,0.0,0,3.9033036,450.0,0.99242622,-0.21785706,2.3429768,475.77994,-9.2402325
196.4511,-0.043731034,9.439846,0.0,0,4.700161,450.0,0.99188364,-0.1931465,3.3560202,476.06326,-9.2385139
196.4555,-0.057446074,9.4399185,0.0,0,5.4970183,450.0,0.99199885,-0.2648333,4.1208296,476.43054,-9.2386322
196.4599,-0.015981067,9.4443998,0.0,0,6.2938766,450.0,0.99259257,-0.10887537,4.8653336,476.79779,-9.2385368
196.4643,-0.086709082,9.4413462,0.0,0,7.0907335,450.0,0.99219429,-0.37115416,5.6423054,477.14084,-9.2372265
196.4687,0.051352508,9.4409418,0.0,0,7.8875914,450.0,0.99188572,0.23611964,6.4611344,477.48187,-9.237792
196.4731,-0.065413468,9.4392042,0.0,0,8.6844492,450.0,0.99153256,-0.25721222,7.2978554,477.72131,-9.234724
196.4775,-0.014285957,9.4418573,0.0,0,9.481308,450.0,0.99206597,-0.19039588,8.1308804,477.90491,-9.2375555
196.4819,-0.023727337,9.4387779,0.0,0,10.278165,450.0,0.99147725,-0.060247518,8.9499626,478.07889,-9.2355766
196.4863,-0.019490054,9.4432058,0.0,0,11.075023,450.0,0.99221981,-0.15090059,9.7567968,478.2363,-9.2355852
196.4907,0.047858413,9.4375601,0.0,0,11.871881,450.0,0.99109393,0.29463893,10.565047,478.40085,-9.2359114
196.4951,-0.098987907,9.4423904,0.0,0,12.668737,450.0,0.99174541,-0.51210892,11.354415,478.63696,-9.2359972
196.4995,-0.015625717,9.4388905,0.0,0,13.465595,450.0,0.99128968,-0.073473811,12.126271,478.87305,-9.2361927
196.5039,-0.042812556,9.4425259,0.0,0,14.262453,450.0,0.99179566,-0.17982388,12.910724,479.07712,-9.2349472
196.5083,0.063089356,9.4367371,0.0,0,15.059311,450.0,0.99101216,0.31192532,13.716562,479.27386,-9.236969
196.5127,-0.17779441,9.4408112,0.0,0,15.856169,450.0,0.99145061,-0.84518093,14.513219,479.44949,-9.2357521
196.5171,0.10855907,9.4393597,0.0,0,16.653027,450.0,0.99147069,0.43822917,15.322651,479.6069,-9.2341442
196.5215,-0.11726137,9.4419899,0.0,0,17.449884,450.0,0.99164838,-0.56214029,16.127615,479.75409,-9.234086
196.5259,0.0082402891,9.4396868,0.0,0,18.0,450.0,0.99163228,0.0050218585,16.923893,479.87216,-9.235528
196.5303,-0.13649851,9.4420786,0.0,0,18.0,450.0,0.99163479,-0.54281992,17.686907,479.99023,-9.2347822
196.5347,0.016008856,9.4422016,0.0,0,18.0,450.0,0.99216646,0.13641316,18.258739,480.08252,-9.2387743
196.5391,0.037293319,9.4520521,0.0,0,18.0,450.0,0.99333537,0.12738584,18.476597,480.17432,-9.2447462
196.5435,0.58455193,9.461587,0.0,0,18.0,450.0,0.99554718,2.6811302,18.321247,480.32159,-9.2597713
196.5479,0.93454719,9.4790449,0.0,0,18.0,450.0,0.99820089,4.3533931,18.132462,480.4921,-9.2847385
196.5523,0.86581963,9.4764452,0.0,0,18.0,450.0,0.99821723,4.1048784,18.053928,480.6402,-9.318738
196.5567,0.80592132,9.4788027,0.0,0,18.0,450.0,0.99833041,3.7838132,18.06432,480.75824,-9.3560619
196.5611,0.81905055,9.4732056,0.0,0,18.0,450.0,0.99767983,3.837606,18.103014,480.86447,-9.3911505
196.5655,0.91449118,9.4799938,0.0,0,18.0,450.0,0.99871832,4.2634106,18.134508,480.90384,-9.425169
196.5699,0.88362843,9.4746838,0.0,0,18.0,450.0,0.99787611,4.2212481,18.144073,480.94318,-9.4583158
196.5743,0.81737334,9.4794741,0.0,0,18.0,450.0,0.99849647,3.8533442,18.138638,480.94818,-9.4910049
196.5787,0.81531924,9.4748917,0.0,0,18.0,450.0,0.99825346,3.8015795,18.140282,480.94818,-9.5215359
196.5831,0.89978838,9.4811373,0.0,0,18.0,450.0,0.99902517,4.1464291,18.135412,480.93256,-9.5549841
196.5875,0.93008775,9.4737587,0.0,0,18.0,450.0,0.9980678,4.3498569,18.126556,480.90631,-9.5881577
196.5919,0.84226018,9.4795637,0.0,0,18.0,450.0,0.99888897,3.9322846,18.1243,480.92181,-9.6226683
196.5963,0.80497134,9.4759617,0.0,0,18.0,450.0,0.99856526,3.7756579,18.119686,481.02673,-9.6552458
196.6007,0.88277072,9.4784117,0.0,0,18.0,450.0,0.99864995,4.1038108,18.120352,481.13113,-9.6890736
196.6051,0.93246907,9.4755106,0.0,0,18.0,450.0,0.99861825,4.3959937,18.115843,481.22296,-9.7219114
196.6095,0.84850246,9.4779043,0.0,0,18.0,450.0,0.99881834,4.0255799,18.110115,481.31479,-9.7561655
196.6139,0.80433452,9.4764204,0.0,0,18.0,450.0,0.9988817,3.7923119,18.111502,481.29642,-9.7876453
196.6183,0.85729873,9.4763956,0.0,0,18.0,450.0,0.99889535,3.9760008,18.103054,481.24396,-9.818593
196.6227,0.9267031,9.4766617,0.0,0,18.0,450.0,0.99906278,4.3390784,18.105673,481.21701,-9.8493824
196.6271,0.88283622,9.4776993,0.0,0,18.0,450.0,0.99904525,4.1555319,18.101278,481.21701,-9.8848667
196.6315,0.80422074,9.4778728,0.0,0,18.0,450.0,0.99946481,3.7806263,18.103714,481.2225,-9.916955
196.6359,0.83670586,9.4780283,0.0,0,18.0,450.0,0.99937379,3.8737752,18.102085,481.24872,-9.9506092
196.6403,0.9263317,9.4754868,0.0,0,18.0,450.0,0.99901503,4.3228951,18.10149,481.27493,-9.9852867
196.6447,0.90303773,9.4752483,0.0,0,18.0,450.0,0.99907929,4.2742963,18.090883,481.2034,-10.019514
196.6491,0.81108451,9.4744396,0.0,0,18.0,450.0,0.99925351,3.849448,18.09548,481.12473,-10.051508
196.6535,0.83932656,9.4772549,0.0,0,18.0,450.0,0.99959284,3.8782778,18.096127,481.08035,-10.082675
196.6579,0.92376751,9.4754152,0.0,0,18.0,450.0,0.99926418,4.2886829,18.094166,481.05411,-10.114944
196.6623,0.94490296,9.4771194,0.0,0,18.0,450.0,0.99980038,4.4292021,18.085243,481.03778,-10.148909
196.6667,0.84897631,9.4731722,0.0,0,18.0,450.0,0.99887156,4.0277743,18.084148,481.03778,-10.181076
196.6711,0.82972974,9.4755554,0.0,0,18.0,450.0,0.99966908,3.8906119,18.08427,481.03516,-10.21601
196.6755,0.92294097,9.4740429,0.0,0,18.0,450.0,0.99909568,4.2909684,18.083385,481.00894,-10.247515
196.6799,0.96470743,9.4748936,0.0,0,18.0,450.0,0.99941987,4.5167842,18.084171,480.9827,-10.282906
196.6843,0.87690723,9.4736204,0.0,0,18.0,450.0,0.99918324,4.1311727,18.083719,480.98965,-10.315394
196.6887,0.82906663,9.4745626,0.0,0,18.0,450.0,0.99951345,3.8751791,18.08161,481.00375,-10.347308
196.6931,0.90979302,9.4725218,0.0,0,18.0,450.0,0.99944478,4.2152743,18.082949,480.99869,-10.37962
196.6975,0.96246284,9.4761353,0.0,0,18.0,450.0,0.99996418,4.4694238,18.077324,480.98557,-10.411641
196.7019,0.8995477,9.4711046,0.0,0,18.0,450.0,0.99905008,4.2161059,18.080648,480.95563,-10.44642
196.7063,0.8205328,9.4736996,0.0,0,18.0,450.0,0.9996677,3.8840759,18.076221,480.90317,-10.480295
196.7107,0.88389295,9.470685,0.0,0,18.0,450.0,0.99894327,4.07833,18.077234,480.85464,-10.510565
196.7151,0.96695322,9.4733191,0.0,0,18.0,450.0,0.9997108,4.4991837,18.075735,480.8284,-10.54452
196.7195,0.93956846,9.4735565,0.0,0,18.0,450.0,0.99956393,4.4187613,18.072756,480.80215,-10.577684
196.7239,0.84175748,9.4724054,0.0,0,18.0,450.0,0.99946755,3.9454262,18.072906,480.82172,-10.611547
196.7283,0.85370034,9.4712648,0.0,0,18.0,450.0,0.99896526,3.9934661,18.073645,480.84796,-10.643045
196.7327,0.97544473,9.4715605,0.0,0,18.0,450.0,0.99925959,4.5314775,18.066166,480.84296,-10.675727
196.7371,0.95499092,9.470561,0.0,0,18.0,450.0,0.99896199,4.5121322,18.065168,480.81671,-10.709539
196.7415,0.86887842,9.4701424,0.0,0,18.0,450.0,0.99908358,4.1134605,18.068296,480.76962,-10.741821
196.7459,0.84154654,9.4715347,0.0,0,18.0,450.0,0.99919802,3.9497724,18.065125,480.6778,-10.776016
196.7503,0.95430714,9.4709492,0.0,0,18.0,450.0,0.9990682,4.4685507,18.068243,480.58975,-10.807628
196.7547,0.97661477,9.4729853,0.0,0,18.0,450.0,0.99921137,4.5993285,18.061913,480.58975,-10.840242
196.7591,0.88861728,9.470252,0.0,0,18.0,450.0,0.99905378,4.205246,18.064331,480.58975,-10.875146
196.7635,0.83386272,9.4717388,0.0,0,18.0,450.0,0.99898177,3.9339285,18.060034,480.58975,-10.907874
196.7679,0.9282732,9.4696398,0.0,0,18.0,450.0,0.99874336,4.3195786,18.061943,480.58975,-10.941686
196.7723,0.99260825,9.4719229,0.0,0,18.0,450.0,0.99915922,4.6459594,18.057096,480.55786,-10.973145
196.7767,0.90179354,9.4689932,0.0,0,18.0,450.0,0.99869072,4.2515655,18.061646,480.49228,-11.006066
196.7811,0.83978152,9.4708672,0.0,0,18.0,450.0,0.99865711,3.9276764,18.056755,480.43765,-11.039374
196.7855,0.88992459,9.4710493,0.0,0,18.0,450.0,0.99878842,4.1394935,18.055641,480.42453,-11.072148
196.7899,0.99534631,9.4713535,0.0,0,18.0,450.0,0.99880195,4.6527395,18.052557,480.41141,-11.105255
196.7943,0.9252106,9.4701853,0.0,0,18.0,450.0,0.99843776,4.4347839,18.057001,480.38608,-11.137948
196.7987,0.86500764,9.4710808,0.0,0,18.0,450.0,0.99865478,4.0248013,18.053225,480.35983,-11.170118
196.8031,0.8706522,9.4713097,0.0,0,18.0,450.0,0.99849367,3.9948094,18.051897,480.28207,-11.204868
196.8075,0.9916023,9.470993,0.0,0,18.0,450.0,0.99855077,4.5926867,18.049553,480.17715,-11.236538
196.8119,0.97321057,9.4716969,0.0,0,18.0,450.0,0.99835914,4.6227345,18.054346,480.08212,-11.269596
196.8163,0.87154907,9.472538,0.0,0,18.0,450.0,0.99861616,4.1118751,18.05114,480.00345,-11.302856
196.8207,0.87354624,9.4714136,0.0,0,18.0,450.0,0.99840474,4.0802279,18.050919,479.9313,-11.335126
197.1244,0.85982406,9.4779329,0.0,0,18.0,0.036866024,0.99918514,4.0227752,18.016624,470.79843,-11.481191
199.3244,0.8137579,9.4972725,0.0,0,18.0,3.6775861e-32,1.0028067,3.7975669,17.999931,442.68869,-11.481316
201.5244,0.83790773,9.5123491,0.0,0,18.0,1.4012985e-45,1.0056013,3.9033687,18.001593,420.384,-11.48253
203.7244,0.83089441,9.5260792,0.0,0,18.0,1.4012985e-45,1.0079761,3.8687191,18.000385,399.20819,-11.481453
205.9244,0.84124905,9.538063,0.0,0,18.0,1.4012985e-45,1.0102386,3.9074297,18.000542,378.78925,-11.481313
208.1244,0.85275161,9.5497656,0.0,0,18.0,1.4012985e-45,1.0124584,3.9429359,17.999352,359.51401,-11.48185
210.3244,0.8582229,9.5613012,0.0,0,18.0,1.4012985e-45,1.0144346,3.9509382,17.99955,341.53464,-11.4818
212.5244,0.86789089,9.5726509,0.0,0,18.0,1.4012985e-45,1.0166229,4.0002398,18.00029,324.26129,-11.481585
214.7244,0.87173563,9.5827188,0.0,0,18.0,1.4012985e-45,1.0185459,4.0163422,18.000055,308.11377,-11.481267
216.9244,0.87820393,9.5928936,0.0,0,18.0,1.4012985e-45,1.020261,4.0403705,17.999557,292.86755,-11.481351
219.1244,0.89213014,9.6025324,0.0,0,18.0,1.4012985e-45,1.0221592,4.0835757,17.999783,278.34149,-11.482
221.3244,0.91361237,9.6115141,0.0,0,18.0,1.4012985e-45,1.02385,4.1719818,17.999319,264.55502,-11.481958
223.5244,0.92048347,9.6202431,0.0,0,18.0,1.4012985e-45,1.0253564,4.20749,18.000019,251.68971,-11.482222
225.7244,0.9128952,9.6279211,0.0,0,18.0,1.4012985e-45,1.0268518,4.1741843,17.999012,239.39359,-11.481746
227.9244,0.91008461,9.6365261,0.0,0,18.0,1.4012985e-45,1.0284401,4.1489229,17.999599,227.73091,-11.481106
230.1244,0.92981392,9.6438408,0.0,0,18.0,1.4012985e-45,1.0298285,4.2212796,17.999826,216.90446,-11.480451
232.3244,0.95482004,9.6507759,0.0,0,18.0,1.4012985e-45,1.0310369,4.3282504,17.999693,207.49609,-11.480618
234.5244,0.97289389,9.6570625,0.0,0,18.0,1.4012985e-45,1.0322863,4.4154134,18.000248,198.06114,-11.48137
236.7244,0.96793962,9.6638107,0.0,0,18.0,1.4012985e-45,1.0336254,4.3913121,17.999903,188.78122,-11.48165
238.9244,0.96264607,9.6701651,0.0,0,18.0,1.4012985e-45,1.0346444,4.3577609,18.000282,179.97672,-11.482024
241.1244,0.96221262,9.6758928,0.0,0,18.0,1.4012985e-45,1.0358593,4.3392591,18.001005,171.7225,-11.481765
243.3244,0.9879154,9.6811991,0.0,0,18.0,1.4012985e-45,1.0367926,4.4483614,17.99884,164.04872,-11.482597
245.5244,0.99698198,9.6864643,0.0,0,18.0,1.4012985e-45,1.0378052,4.4978151,18.000214,156.39008,-11.482747
247.7244,0.9869011,9.6917686,0.0,0,18.0,1.4012985e-45,1.0387062,4.456841,18.000341,149.54753,-11.482369
249.9244,0.98829496,9.6970348,0.0,0,18.0,1.4012985e-45,1.0398304,4.4532161,17.999111,143.07036,-11.482745
252.1244,0.98818147,9.7014227,0.0,0,18.0,1.4012985e-45,1.0406654,4.4359379,18.000132,136.90138,-11.482173
254.3244,1.0081213,9.7062035,0.0,0,18.0,1.4012985e-45,1.0415192,4.5257993,17.999716,131.05786,-11.48231
256.5244,1.0085205,9.7102575,0.0,0,18.0,1.4012985e-45,1.0422174,4.5311871,17.999504,125.53261,-11.482031
256.8244,0.99285799,9.7107334,0.0,0,18.0,1.4012985e-45,1.0424203,4.4558606,17.999022,124.79863,-11.546281