File: examples/dan-msc-case-studies/CS3/data/01 raw data/baron_test_072.csv
Time(sec),Force(kN),Jaw(mm),PowAngle(deg),Power(W),Pram,PTemp,Strain,Stress(MPa),Stroke(mm),TC1(C),wedge(mm)
0.0,0.95864701,-0.38024622,0.0,0,10.594783,0.0016630022,-0.025032051,12.493991,10.595125,22.77957,-9.1075563
2.2,0.88262564,-0.0016443476,0.0,0,10.594783,6.5159163,-0.00011953969,11.225528,10.594846,22.737062,-9.4719658
4.4,0.84978533,-0.0014914052,0.0,0,10.594783,13.115913,-9.5077172e-05,10.823345,10.595153,22.763948,-9.4696178
6.6,0.82240868,-0.0014750564,0.0,0,10.594783,19.715914,-9.9891149e-05,10.488061,10.594948,22.765865,-9.4659023
8.8,0.79596913,-0.0010202152,19.942215,0,10.594783,26.315914,-7.8034835e-05,10.139092,10.595482,22.843189,-9.4618988
11.0,0.81795561,-0.0035991373,39.875546,0,10.594783,32.915913,-0.00023410193,10.419522,10.595371,25.149223,-9.4585066
13.2,0.84699959,-0.011475789,46.570724,0,10.594783,39.515907,-0.00075982616,10.797985,10.594825,32.55751,-9.4558048
15.4,0.88332725,-0.020179782,46.432953,0,10.594783,46.115902,-0.0013576413,11.265042,10.595213,43.581944,-9.4522123
17.6,0.88574904,-0.027634531,42.631561,0,10.594783,52.7159,-0.0018435827,11.308715,10.594976,54.165665,-9.448802
19.8,0.88955361,-0.032430258,37.089947,0,10.594783,59.315899,-0.0021507218,11.352004,10.595273,62.721489,-9.4454374
22.0,0.8679719,-0.034491699,36.309631,0,10.594783,65.915901,-0.0022842903,11.071627,10.59516,67.413162,-9.4418879
24.2,0.86763632,-0.037342947,39.921268,0,10.594783,72.5159,-0.0024992828,11.075535,10.594089,71.455757,-9.4386911
26.4,0.88118207,-0.042188223,43.286243,0,10.594783,79.115898,-0.0027873514,11.254948,10.595057,76.762238,-9.4349403
28.6,0.89609575,-0.047851592,44.601875,0,10.594783,85.715904,-0.0031775967,11.458241,10.594862,84.085907,-9.4311981
30.8,0.91232938,-0.05323004,44.077389,0,10.594783,92.315903,-0.0035623931,11.664947,10.594793,91.816978,-9.4277411
33.0,0.91920882,-0.060217377,42.978664,0,10.594783,98.915901,-0.0039736046,11.751434,10.594869,99.447456,-9.4245167
35.2,0.90591264,-0.064068079,42.317162,0,10.594783,105.51591,-0.0042601801,11.598171,10.595177,106.22684,-9.4209194
37.4,0.91183496,-0.068275183,42.396236,0,10.594783,112.11591,-0.0045656371,11.662022,10.595844,112.29182,-9.4172535
39.6,0.92380917,-0.072982438,43.527439,0,10.594783,118.7159,-0.0048581213,11.807506,10.594618,118.12112,-9.4138641
41.8,0.92540717,-0.078673206,44.52623,0,10.594783,125.3159,-0.0052241809,11.837728,10.595212,124.51608,-9.4099789
44.0,0.94049877,-0.084117554,45.12085,0,10.594783,131.91588,-0.0055824327,12.040956,10.594758,131.23141,-9.4074755
46.2,0.94939929,-0.089268439,44.911957,0,10.594783,138.51587,-0.005955027,12.164248,10.595247,138.30281,-9.4038038
48.4,0.94396251,-0.095224313,45.084732,0,10.594783,145.11588,-0.0063038087,12.102282,10.595992,145.02902,-9.4000883
50.6,0.95570272,-0.10052851,45.030777,0,10.594783,151.71588,-0.0066739456,12.268293,10.595144,151.64697,-9.396266
52.8,0.95311832,-0.10619454,45.12085,0,10.594783,158.31589,-0.007052369,12.227988,10.595824,158.04465,-9.3925753
55.0,0.95844907,-0.11227304,45.615231,0,10.594783,164.91588,-0.0074640955,12.30319,10.594309,164.45367,-9.3900347
57.2,0.95880431,-0.11798601,46.109619,0,10.594783,171.51587,-0.0078018899,12.31224,10.594331,171.02261,-9.3861818
59.4,0.95779598,-0.12421624,46.485374,0,10.594783,178.11588,-0.0082420278,12.311389,10.594934,177.72375,-9.3823338
61.6,0.96686482,-0.13032508,46.529194,0,10.594783,184.71587,-0.0086614704,12.419156,10.595206,184.54489,-9.3788748
63.8,0.96403944,-0.13639145,46.582027,0,10.594783,191.31587,-0.0090581495,12.395558,10.59441,190.9791,-9.3750172
66.0,0.96725172,-0.14295791,47.05444,0,10.594783,197.91586,-0.0094640097,12.437381,10.593448,197.45091,-9.3721218
68.2,0.96309376,-0.14906354,47.092022,0,10.594783,204.51587,-0.0098793246,12.395575,10.594386,204.2775,-9.3690109
70.4,0.96620715,-0.15516804,47.054447,0,10.594783,211.11586,-0.010307528,12.421861,10.594576,211.1442,-9.3652601
72.6,0.96599126,-0.16109708,47.105404,0,10.594783,217.71587,-0.010698196,12.426224,10.594967,217.60522,-9.361166
74.8,0.97162324,-0.16787156,47.504883,0,10.594783,224.31587,-0.011101844,12.523029,10.594565,224.21451,-9.3577604
77.0,0.96798456,-0.17425281,47.504883,0,10.594783,230.91586,-0.011548388,12.469608,10.594996,230.80417,-9.354291
79.2,0.96669412,-0.17985727,47.504883,0,10.594783,237.51587,-0.011922452,12.468304,10.59476,237.45567,-9.3512993
81.4,0.97088134,-0.18600288,47.523052,0,10.594783,244.11588,-0.012333149,12.532124,10.595201,243.93315,-9.3474445
83.6,0.96708858,-0.19246837,47.955318,0,10.594783,250.71588,-0.01273128,12.466273,10.595253,250.38719,-9.3435841
85.8,0.96996069,-0.19871534,48.383644,0,10.594783,257.31613,-0.013151582,12.529489,10.595027,257.01392,-9.3403158
88.0,0.97236377,-0.2048489,48.210213,0,10.594783,263.91583,-0.013548505,12.556652,10.595376,263.828,-9.3363485
90.2,0.97073263,-0.21141975,48.160725,0,10.594783,270.51584,-0.01400954,12.541712,10.594281,270.46262,-9.3330879
92.4,0.969069,-0.21841502,48.576031,0,10.594783,277.11581,-0.014470877,12.509885,10.594511,276.77161,-9.3293505
94.6,0.97740257,-0.22530212,48.812252,0,10.594783,283.71582,-0.014882635,12.640152,10.594284,283.51129,-9.3259888
96.8,0.9812572,-0.23161419,48.81226,0,10.594783,290.31583,-0.015319377,12.695918,10.594498,290.03012,-9.3223591
99.0,0.98604709,-0.23826289,49.229733,0,10.594783,296.91586,-0.015746074,12.753119,10.595819,296.70966,-9.3182955
101.2,0.98684889,-0.2445015,49.088005,0,10.594783,303.51584,-0.016186813,12.768312,10.595072,303.50723,-9.3147268
103.4,0.99382645,-0.25364643,49.229733,0,10.594783,310.11588,-0.016780803,12.878639,10.594579,310.0148,-9.3117247
105.6,0.98461527,-0.25898528,49.636192,0,10.594783,316.71585,-0.017106691,12.75092,10.594965,316.39752,-9.3083916
107.8,0.97922063,-0.26636979,49.889481,0,10.594783,323.31586,-0.017592449,12.687412,10.594871,322.92798,-9.3044176
110.0,0.9900021,-0.27333912,50.042721,0,10.594783,329.91586,-0.018045424,12.838859,10.594739,329.58823,-9.3001986
112.2,0.99395436,-0.28084132,50.042721,0,10.594783,336.51587,-0.018572357,12.90795,10.595369,336.35449,-9.2966471
114.4,0.991539,-0.28781474,50.438229,0,10.594783,343.11584,-0.019013576,12.859145,10.595304,342.70227,-9.2933426
116.6,0.983419,-0.29578435,50.803833,0,10.594783,349.71588,-0.019517545,12.768709,10.59635,349.2858,-9.2899885
118.8,0.99241549,-0.30293515,50.931435,0,10.594783,356.31586,-0.019978721,12.894496,10.594552,355.93549,-9.2866564
121.0,0.99917901,-0.30998164,51.061577,0,10.594783,362.91586,-0.020454908,12.992133,10.595363,362.73181,-9.2831087
123.2,1.0026767,-0.31861106,51.073387,0,10.594783,369.51584,-0.021015186,13.04365,10.595148,369.42218,-9.2789307
125.4,1.0010667,-0.32691032,50.880013,0,10.594783,376.11584,-0.02157017,13.024946,10.595886,376.13849,-9.2754002
127.6,0.99128485,-0.33407098,50.438412,0,10.594783,382.71585,-0.022039324,12.905152,10.594502,383.17352,-9.2719622
129.8,0.99347246,-0.34084746,50.066032,0,10.594783,389.31583,-0.022448238,12.95072,10.594884,389.70151,-9.2679377
132.0,1.0016731,-0.34724894,50.438229,0,10.594783,395.91586,-0.0228673,13.049698,10.595448,395.84,-9.2647448
134.2,1.0076681,-0.35426122,50.82275,0,10.594783,402.51584,-0.023337997,13.133732,10.594252,402.24048,-9.2611151
136.4,1.0203254,-0.36316952,51.196285,0,10.594783,409.11584,-0.023932256,13.308959,10.594394,408.58371,-9.2569599
138.6,1.0191802,-0.37289417,51.569809,0,10.594783,415.71582,-0.02459293,13.296803,10.595604,415.21384,-9.2538452
140.8,1.0203992,-0.38071945,51.196293,0,10.594783,422.31583,-0.025090676,13.332861,10.594323,422.34735,-9.2502995
143.0,1.0233476,-0.38728973,51.196293,0,10.594783,428.91583,-0.02549349,13.37278,10.594966,429.08182,-9.2468691
145.2,1.0179536,-0.3946518,50.822758,0,10.594783,435.51584,-0.025944324,13.31337,10.59514,435.77631,-9.2432947
147.4,1.0166353,-0.40303847,50.43829,0,10.594783,442.11584,-0.026511995,13.297684,10.594892,442.57407,-9.2395067
149.6,1.0150323,-0.41092733,50.044353,0,10.594783,448.71585,-0.027018832,13.283529,10.594678,449.10388,-9.2355175
151.8,1.0130036,-0.41987455,50.427765,0,10.594783,455.31583,-0.027611241,13.255812,10.595198,455.41867,-9.2321167
154.0,1.0052723,-0.42927727,50.437695,0,10.594783,461.9158,-0.02823572,13.172035,10.594914,461.95013,-9.2283735
156.2,1.0091223,-0.43507689,49.67939,0,10.594783,468.51581,-0.028615819,13.201637,10.594966,468.97885,-9.2250032
158.4,1.0267693,-0.44751284,49.230289,0,10.594783,475.11581,-0.029370569,13.457611,10.595677,475.655,-9.2218275
160.6,1.0355546,-0.45105663,49.22974,0,10.594783,481.71582,-0.029619062,13.573286,10.595602,482.04938,-9.2177181
162.8,1.0305983,-0.45750248,49.016552,0,10.594783,488.31583,-0.03003918,13.52644,10.5953,488.6304,-9.2138796
165.0,1.0316694,-0.46574712,48.817688,0,10.594783,494.91583,-0.030570969,13.550364,10.594056,495.11978,-9.2103968
167.2,0.13202897,-0.49020091,48.023415,0,10.594783,499.99884,-0.032153018,1.7337468,10.595306,500.9483,-9.2077885
169.4,0.12335104,-0.49428207,50.212097,0,10.594783,499.99884,-0.032428682,1.6136589,10.594926,498.78391,-9.207469
171.6,0.11930698,-0.49840564,49.392456,0,10.594783,499.99884,-0.032715082,1.5686935,10.595603,500.34494,-9.2074261
173.8,0.11722957,-0.49922588,47.223347,0,10.594783,499.99884,-0.03274494,1.5472372,10.594218,501.8439,-9.2072124
176.0,0.091853842,-0.49832308,46.109623,0,10.594783,499.99884,-0.032677244,1.2252837,10.595721,501.56979,-9.2078476
178.2,0.091128394,-0.49721655,46.109619,0,10.594783,499.99884,-0.03258517,1.2096732,10.595913,500.61935,-9.2078094
180.4,0.094123974,-0.49624491,46.776958,0,10.594783,499.99884,-0.032532722,1.2396392,10.59498,499.65955,-9.2078838
182.6,0.098153934,-0.49598897,47.792301,0,10.594783,499.99884,-0.032531332,1.2882696,10.594623,499.1727,-9.2074919
184.8,0.10731194,-0.4978902,48.130417,0,10.594783,499.99884,-0.032660127,1.4169513,10.594441,499.38501,-9.2071457
187.0,0.12342475,-0.50017452,47.955326,0,10.594783,499.99884,-0.032790694,1.6322299,10.595377,500.02817,-9.2075796
189.2,0.12515436,-0.49961692,47.056553,0,10.594783,499.99884,-0.032756209,1.6400417,10.595051,500.49539,-9.2075834
191.4,0.10804084,-0.49816185,46.582035,0,10.594783,499.99884,-0.032693345,1.4162771,10.594926,500.58847,-9.2076311
193.6,0.098743044,-0.4996618,46.583118,0,10.594783,499.99884,-0.032796498,1.3004227,10.596691,500.19525,-9.2071781
195.8,0.10853952,-0.50091678,47.05444,0,10.594783,499.99884,-0.032852806,1.4369305,10.594676,500.00806,-9.2072058
198.0,0.11583976,-0.50199807,47.023689,0,10.594783,499.99884,-0.032896467,1.5330818,10.595285,499.99268,-9.2072563
200.2,0.11475965,-0.50249177,46.823055,0,10.594783,499.99884,-0.032932781,1.5115362,10.595446,500.03491,-9.2072363
202.4,0.11835051,-0.50362748,47.054272,0,10.594783,499.99884,-0.033013094,1.5552982,10.594491,499.91766,-9.2074432
204.6,0.11424352,-0.50483453,46.885471,0,10.594783,499.99884,-0.033105616,1.5029697,10.594558,500.00919,-9.2071447
206.8,0.12030198,-0.5047915,47.046925,0,10.594783,499.99884,-0.033104185,1.5777459,10.595529,499.89886,-9.2068233
209.0,0.12929608,-0.50728589,46.820335,0,10.594783,499.99884,-0.033235002,1.7027016,10.595629,500.07645,-9.2065439
211.2,0.13406406,-0.50898063,46.582035,0,10.594783,499.99884,-0.033386432,1.7651807,10.594495,500.13275,-9.206811
211.9631,0.11499292,0.042665713,46.582031,0,10.5948,1.5409876e-16,0.0030416963,1.3831284,10.589924,500.16776,-9.2058611
211.9675,0.2427244,0.039764877,46.582031,0,10.5948,0.0,0.0027210268,2.9765155,10.595314,500.10211,-9.2066364
211.9719,0.23790634,0.040929563,31.20985,0,10.5948,0.0,0.0029925779,3.0702331,10.593305,500.06601,-9.2070398
211.9763,0.21491134,0.042487454,10.713757,0,10.5948,0.0,0.0029493028,2.7013936,10.593936,500.03973,-9.2065115
211.9807,0.23301384,0.04203172,0.0,0,10.5948,0.0,0.003068011,2.8542418,10.593462,499.83173,-9.20858
211.9851,0.22233686,0.039512679,0.0,0,10.5948,0.0,0.002793265,2.7157302,10.592852,499.42465,-9.2066202
211.9895,0.23942606,0.04015822,0.0,0,10.5948,0.0,0.0029254013,3.0491788,10.593331,499.13306,-9.2070131
211.9939,0.22815098,0.040348887,0.0,0,10.5948,0.0,0.0028605186,2.8825588,10.594914,499.29065,-9.2065496
211.9983,0.22421835,0.041938052,0.0,0,10.5948,0.0,0.0030183815,2.8141594,10.596801,499.44824,-9.2064629
212.0027,0.23178758,0.040024325,0.0,0,10.5948,0.0,0.0028707129,2.9088516,10.596762,499.55688,-9.2083864
212.0071,0.24620697,0.040725067,0.0,0,10.5948,0.0,0.0029769959,3.1140802,10.592278,499.66193,-9.2074718
212.0115,0.24324204,0.040437825,0.0,0,10.578863,0.0,0.0029507112,3.1121271,10.596783,499.72372,-9.2056456
212.0159,0.23930418,0.041325465,0.0,0,10.512864,0.0,0.0029907757,3.0018711,10.593708,499.76309,-9.207077
212.0203,0.24389873,0.040405814,0.0,0,10.446864,0.0,0.0028548066,3.0975506,10.581025,499.79807,-9.2064695
212.0247,0.25433749,0.0409953,0.0,0,10.380864,0.0,0.0029731919,3.1532366,10.53062,499.82599,-9.2070398
212.0291,0.25314882,0.041214064,0.0,0,10.314864,0.0,0.002946195,3.2140429,10.430825,499.85025,-9.2065783
212.0335,0.25109848,0.041053321,0.0,0,10.248864,0.0,0.0029779733,3.2051108,10.331025,499.86337,-9.2065382
212.0379,0.24936555,0.04155346,0.0,0,10.182864,0.0,0.0029681975,3.0937564,10.259388,499.8765,-9.2079268
212.0423,0.26307791,0.041175544,0.0,0,10.116864,0.0,0.0029947578,3.2665195,10.202126,499.83829,-9.2073784
212.0467,0.27226734,0.041908249,0.0,0,10.050864,0.0,0.0029834704,3.4967518,10.15331,499.79889,-9.2065907
212.0511,0.25243658,0.041101463,0.0,0,9.9848633,0.0,0.0029327427,3.255825,10.086588,499.77802,-9.2071943
212.0555,0.2740601,0.043714233,0.0,0,9.9188633,0.0,0.0030973314,3.4755652,10.013403,499.76486,-9.2071056
212.0599,2.2023914,0.069704972,0.0,0,9.8528633,0.0,0.004801224,27.564878,9.9522314,500.19406,-9.2054358
212.0643,3.2457876,0.11939012,0.0,0,9.7868633,0.0,0.008060446,40.98637,9.8844919,501.2052,-9.2047129
212.0687,3.4748032,0.19103849,0.0,0,9.7208633,0.0,0.01294117,43.727428,9.8126307,502.2623,-9.2038965
212.0731,3.5996845,0.26005524,0.0,0,9.6548634,0.0,0.017523328,44.994347,9.7361765,503.56219,-9.2062073
212.0775,3.6909401,0.3238079,0.0,0,9.5888634,0.0,0.02188345,45.967121,9.6713009,504.86212,-9.2041893
212.0819,3.7429459,0.39021757,0.0,0,9.5228634,0.0,0.026459454,46.415035,9.6059942,505.47519,-9.2044621
212.0863,3.7836478,0.45611259,0.0,0,9.4574747,0.0,0.03089742,46.672794,9.5400887,506.00021,-9.2048273
212.0907,3.7819288,0.52159178,0.0,0,9.393095,0.0,0.035378709,46.51947,9.4747553,506.44467,-9.2037077
212.0951,3.8299811,0.5814575,0.0,0,9.3287144,0.0,0.039512362,46.866425,9.4046144,506.83841,-9.2057047
212.0995,3.8872569,0.64961982,0.0,0,9.2643328,0.0,0.044224598,47.276215,9.342391,507.20084,-9.2041092
212.1039,3.8943608,0.71337974,0.0,0,9.1999531,0.0,0.048617166,47.304737,9.2751884,507.50272,-9.2046556
212.1083,3.8936861,0.78123105,0.0,0,9.1355715,0.0,0.053337328,47.00716,9.2081966,507.79294,-9.205018
212.1127,3.929831,0.84240711,0.0,0,9.0711908,0.0,0.057699874,47.199974,9.1421871,507.92419,-9.205925
212.1171,3.951714,0.90505749,0.0,0,9.0068102,0.0,0.062130652,47.248264,9.0760221,508.05542,-9.2045708
212.1215,3.9790673,0.96896762,0.0,0,8.9424286,0.0,0.066665247,47.455212,9.0160131,508.05096,-9.2042389
212.1259,3.9764326,1.0312521,0.0,0,8.8780489,0.0,0.071115881,47.152065,8.9514189,508.0116,-9.2063551
212.1303,3.9927788,1.0952945,0.0,0,8.8136673,0.0,0.075686641,47.173019,8.8846073,507.95163,-9.2049332
212.1347,4.0689893,1.167251,0.0,0,8.7493448,0.0,0.080735229,47.671162,8.811058,507.87289,-9.204834
212.1391,4.0636539,1.2276618,0.0,0,8.6880999,0.0,0.085233822,47.545784,8.7477837,507.81055,-9.2036829
212.1435,4.0519052,1.294975,0.0,0,8.6268702,0.0,0.090022728,47.142658,8.6800489,507.79742,-9.2055349
212.1479,4.0311999,1.3527973,0.0,0,8.5656395,0.0,0.094236799,46.705807,8.6234903,507.7843,-9.2047424
212.1523,4.0675926,1.4127233,0.0,0,8.5044088,0.0,0.098617777,46.863972,8.5640793,507.19397,-9.2059984
212.1567,4.0927649,1.4679121,0.0,0,8.4431791,0.0,0.10275499,47.138161,8.5084133,506.59024,-9.2046566
212.1611,4.1063962,1.5325392,0.0,0,8.3819485,0.0,0.10749248,47.073227,8.4424839,506.05124,-9.2054472
212.1655,4.1111174,1.5900619,0.0,0,8.3207188,0.0,0.11180092,46.831917,8.3817101,505.53937,-9.2064257
212.1699,4.1669993,1.654303,0.0,0,8.2594881,0.0,0.1165786,47.120411,8.3197908,505.30521,-9.2047462
212.1743,4.2201715,1.717559,0.0,0,8.1982584,0.0,0.12133867,47.621628,8.2552595,505.43646,-9.2062817
212.1787,4.2130375,1.7835366,0.0,0,8.1370277,0.0,0.12618847,47.294857,8.1841984,505.34,-9.2050743
212.1831,4.1811199,1.8426136,0.0,0,8.0757971,0.0,0.13080628,46.7663,8.1277323,504.04007,-9.2052383
212.1875,4.2116914,1.9044768,0.0,0,8.0165014,0.0,0.13533944,46.782082,8.0672264,502.74011,-9.2046223
212.1919,4.2455359,1.9602804,0.0,0,7.9582458,0.0,0.13980843,47.052391,8.0053434,501.05609,-9.2041569
212.1963,4.2417941,2.0202563,0.0,0,7.8999891,0.0,0.14421752,46.814751,7.9485817,499.32281,-9.2050495
212.2007,4.2494774,2.0739808,0.0,0,7.8417335,0.0,0.14855586,46.586868,7.8883634,498.50809,-9.2061825
212.2051,4.2610712,2.1339712,0.0,0,7.7834773,0.0,0.15296133,46.443928,7.831109,498.27176,-9.2056398
212.2095,4.3043442,2.1850352,0.0,0,7.7252216,0.0,0.1571994,46.795162,7.7760801,498.29504,-9.2043228
212.2139,4.3314166,2.2507131,0.0,0,7.666965,0.0,0.16207218,46.916252,7.7159481,498.82031,-9.2049112
212.2183,4.3424096,2.3032784,0.0,0,7.6087093,0.0,0.1665141,46.835754,7.6551638,499.35364,-9.2059774
212.2227,4.3332539,2.3694353,0.0,0,7.5504532,0.0,0.17150329,46.482239,7.5960655,499.99707,-9.204668
212.2271,4.3763108,2.4207056,0.0,0,7.4921975,0.0,0.17579587,46.777119,7.5335641,500.64053,-9.2046423
212.2315,4.4187346,2.4841366,0.0,0,7.4339414,0.0,0.18081068,46.866436,7.4738464,501.18997,-9.2066889
212.2359,4.4262648,2.5404458,0.0,0,7.3765039,0.0,0.1853222,46.767624,7.4156704,501.71524,-9.2049112
212.2403,4.4401741,2.6028969,0.0,0,7.3210988,0.0,0.19024353,46.703751,7.3567424,502.20621,-9.2048607
212.2447,4.4530821,2.6586931,0.0,0,7.2656941,0.0,0.19487616,46.602303,7.2956672,502.6658,-9.2041254
212.2491,4.4510713,2.7138784,0.0,0,7.210289,0.0,0.19926316,46.405502,7.2395878,503.09259,-9.2037563
212.2535,4.4171805,2.7615817,0.0,0,7.1548843,0.0,0.20329511,45.899319,7.1898093,503.4209,-9.2052708
212.2579,4.4726596,2.8202169,0.0,0,7.0994792,0.0,0.20797957,46.243252,7.1368399,503.74921,-9.2041445
212.2623,4.5073876,2.8679559,0.0,0,7.044075,0.0,0.21212943,46.387379,7.0811415,504.07742,-9.2046013
212.2667,4.5832796,2.9317856,0.0,0,6.9886694,0.0,0.21729331,46.932072,7.02354,504.40564,-9.2051239
212.2711,4.5716653,2.9863453,0.0,0,6.9332652,0.0,0.22193179,46.666954,6.9602976,504.73386,-9.204504
212.2755,4.5292068,3.0468497,0.0,0,6.8778601,0.0,0.22689463,45.936214,6.9049492,505.06207,-9.2046967
212.2799,4.5416436,3.0914526,0.0,0,6.8224554,0.0,0.23082276,45.879425,6.8558292,504.46603,-9.2038927
212.2843,4.5772052,3.1471138,0.0,0,6.7670503,0.0,0.23549677,46.050434,6.8026385,502.6539,-9.2048721
212.2887,4.6348968,3.1977603,0.0,0,6.7141318,0.0,0.23972262,46.485165,6.7487621,500.77911,-9.2048492
212.2931,4.6646056,3.2572427,0.0,0,6.6614199,0.0,0.24488996,46.467426,6.6905031,498.57306,-9.2039967
212.2975,4.6526928,3.3095782,0.0,0,6.6087079,0.0,0.24933237,46.110218,6.6325417,496.367,-9.2052145
212.3019,4.6301427,3.3636613,0.0,0,6.5559959,0.0,0.25393039,45.757542,6.5826173,495.67404,-9.2039738
212.3063,4.6848488,3.4105804,0.0,0,6.503284,0.0,0.25804502,46.089134,6.5272536,495.17505,-9.2039604
212.3107,4.6862316,3.4659846,0.0,0,6.450572,0.0,0.26291105,45.893616,6.4784164,495.31262,-9.2036886
212.3151,4.7110386,3.5154972,0.0,0,6.3978601,0.0,0.26719439,45.884499,6.4216871,495.85101,-9.2041759
212.3195,4.7234626,3.5714734,0.0,0,6.3451481,0.0,0.27216935,45.805046,6.3727031,496.68488,-9.2037106
212.3239,4.7574806,3.6167049,0.0,0,6.2924366,0.0,0.27607846,46.033688,6.3199244,498.09,-9.2046356
212.3283,4.7653203,3.6716456,0.0,0,6.2397246,0.0,0.28099373,45.838345,6.2695293,499.46823,-9.2050343
212.3327,4.7914081,3.7233424,0.0,0,6.1870127,0.0,0.28550279,45.829037,6.2174487,500.47937,-9.2050018
212.3371,4.8525634,3.7784586,0.0,0,6.1357436,0.0,0.29055786,46.216537,6.1595721,501.49054,-9.2036171
212.3415,4.8631468,3.8306475,0.0,0,6.0856099,0.0,0.29513264,46.107204,6.1053791,502.16742,-9.2053919
212.3459,4.8156533,3.8833427,0.0,0,6.0354762,0.0,0.29993707,45.461254,6.0573907,502.75833,-9.2047396
212.3503,4.8232331,3.9298468,0.0,0,5.9853425,0.0,0.30414343,45.269993,6.0070186,503.31491,-9.2038536
212.3547,4.8701696,3.9813972,0.0,0,5.9352088,0.0,0.3088862,45.570168,5.9584699,503.84015,-9.2055168
212.3591,4.9111567,4.028286,0.0,0,5.8850756,0.0,0.31312379,45.736687,5.9066734,504.36206,-9.2052584
212.3635,4.9196706,4.0812387,0.0,0,5.8349419,0.0,0.31796899,45.567474,5.8536339,504.87402,-9.2048779
212.3679,4.8965435,4.1280665,0.0,0,5.7848082,0.0,0.3221896,45.160858,5.8084102,505.38602,-9.205617
212.3723,4.9578133,4.17837,0.0,0,5.7346745,0.0,0.32693875,45.469368,5.7539907,505.84659,-9.203577
212.3767,5.0014257,4.2267704,0.0,0,5.6845412,0.0,0.33139953,45.75013,5.7039943,506.30597,-9.2038193
212.3811,5.0294766,4.2797275,0.0,0,5.634407,0.0,0.33629212,45.772938,5.6526003,506.80234,-9.2040892
212.3855,5.0360475,4.3311772,0.0,0,5.5847516,0.0,0.34107009,45.60881,5.5979385,507.31421,-9.2038403
212.3899,4.9787784,4.3804121,0.0,0,5.5370555,0.0,0.3457638,44.863472,5.5514412,507.84875,-9.204917
212.3943,5.0386958,4.4275856,0.0,0,5.4893594,0.0,0.35009658,45.287937,5.5036597,508.41312,-9.205555
212.3987,5.0598865,4.4736381,0.0,0,5.4416633,0.0,0.35456312,45.188782,5.4571128,508.95868,-9.2043133
212.4031,5.049674,4.522563,0.0,0,5.3939681,0.0,0.35919464,44.893688,5.4094086,509.40494,-9.2056618
212.4075,5.059329,4.5695286,0.0,0,5.346272,0.0,0.36368656,44.754658,5.3620119,509.85117,-9.2056055
212.4119,5.1125445,4.6135621,0.0,0,5.2985759,0.0,0.36782303,45.102356,5.3177671,510.1113,-9.2050543
212.4163,5.1456718,4.6616421,0.0,0,5.2508798,0.0,0.37249091,45.111279,5.2644048,510.34753,-9.2045527
212.4207,5.1711721,4.7117515,0.0,0,5.2031837,0.0,0.37720671,45.214378,5.2172451,510.53546,-9.2060757
212.4251,5.1551571,4.7587619,0.0,0,5.155488,0.0,0.38190779,44.776508,5.1748724,510.69296,-9.2047243
212.4295,5.2474809,4.8104997,0.0,0,5.1077919,0.0,0.38685384,45.368958,5.1210856,510.85941,-9.204072
212.4339,5.2461567,4.8581161,0.0,0,5.0600958,0.0,0.39155525,45.175377,5.0709858,511.04315,-9.204957
212.4383,5.1948972,4.9054618,0.0,0,5.0143409,0.0,0.39633855,44.559212,5.0260758,511.22153,-9.2048826
212.4427,5.2214084,4.9527149,0.0,0,4.968977,0.0,0.40074801,44.505054,4.978405,511.32651,-9.2046776
212.4471,5.2506919,4.9961195,0.0,0,4.9236126,0.0,0.40518025,44.562992,4.9377847,511.43152,-9.2049341
212.4515,5.3092017,5.040822,0.0,0,4.8782492,0.0,0.40953606,44.859207,4.8891845,511.50519,-9.2045755
212.4559,5.31463,5.0892291,0.0,0,4.8328848,0.0,0.41441357,44.729115,4.8460279,511.57083,-9.2050657
212.4603,5.32302,5.1356611,0.0,0,4.7875209,0.0,0.41909844,44.628628,4.7988644,511.62958,-9.2053823
212.4647,5.342206,5.1820998,0.0,0,4.7421565,0.0,0.42371342,44.529964,4.7503409,511.68207,-9.2036266
212.4691,5.3692408,5.2252574,0.0,0,4.6967926,0.0,0.42809191,44.552052,4.7074647,511.67877,-9.2048693
212.4735,5.4017653,5.272181,0.0,0,4.6514287,0.0,0.4328278,44.615036,4.6618257,511.50818,-9.2034512
212.4779,5.4083128,5.3147216,0.0,0,4.6060648,0.0,0.437282,44.431267,4.6168456,511.33755,-9.2055693
212.4823,5.4133463,5.3640695,0.0,0,4.5607004,0.0,0.44232506,44.26445,4.569119,511.06433,-9.2048769
212.4867,5.4798017,5.4043288,0.0,0,4.5163722,0.0,0.44650128,44.643452,4.5267553,510.7887,-9.2038565
212.4911,5.50354,5.4554572,0.0,0,4.4732165,0.0,0.45175049,44.583504,4.4779053,510.11548,-9.2047977
212.4955,5.5044594,5.4975657,0.0,0,4.4300613,0.0,0.45617211,44.413933,4.4348297,509.27548,-9.2047014
212.4999,5.5131645,5.546979,0.0,0,4.3869061,0.0,0.46133655,44.243942,4.3861609,508.33914,-9.2040958
212.5043,5.4915981,5.5829005,0.0,0,4.343751,0.0,0.46509185,43.865742,4.3469868,507.276,-9.2049656
212.5087,5.5391684,5.6297874,0.0,0,4.3005962,0.0,0.47008717,44.103149,4.3063717,506.25046,-9.2041101
212.5131,5.5714889,5.6677003,0.0,0,4.2574406,0.0,0.47402149,44.099468,4.265893,505.42346,-9.2055407
212.5175,5.6113706,5.714829,0.0,0,4.2142854,0.0,0.47911325,44.245686,4.219193,504.59647,-9.2050772
212.5219,5.6662693,5.759275,0.0,0,4.1711302,0.0,0.48400798,44.50713,4.1784701,504.19998,-9.2035532
212.5263,5.7182927,5.8069358,0.0,0,4.127975,0.0,0.4890644,44.612881,4.1267614,503.85867,-9.2046156
212.5307,5.7030463,5.8502517,0.0,0,4.0848203,0.0,0.49386522,44.342964,4.0856838,504.18597,-9.2043219
212.5351,5.7109947,5.8968248,0.0,0,4.0418863,0.0,0.49873263,44.13694,4.0447841,504.93423,-9.2046289
212.5395,5.7527308,5.9366465,0.0,0,4.0008435,0.0,0.50322884,44.250729,3.9998422,505.62875,-9.2043066
212.5439,5.7722116,5.9821897,0.0,0,3.9598002,0.0,0.50812924,44.205097,3.9571722,506.21945,-9.2032347
212.5483,5.748898,6.0218439,0.0,0,3.918757,0.0,0.51278377,43.845009,3.9192469,506.75015,-9.2041302
212.5527,5.7390003,6.0637689,0.0,0,3.8777139,0.0,0.51722038,43.587341,3.8756461,506.4614,-9.2044697
212.5571,5.7715158,6.0999813,0.0,0,3.8366706,0.0,0.52155107,43.607746,3.8395452,506.17264,-9.2047768
212.5615,5.8143868,6.1424413,0.0,0,3.7956276,0.0,0.52607226,43.772461,3.7999239,504.35892,-9.2045908
212.5659,5.8694577,6.1782341,0.0,0,3.7545841,0.0,0.53043061,43.97253,3.758868,502.15302,-9.2035961
212.5703,5.9130588,6.2256403,0.0,0,3.713541,0.0,0.53538477,44.049522,3.7159359,499.70682,-9.204916
212.5747,5.9681377,6.2635341,0.0,0,3.672498,0.0,0.54008484,44.307873,3.6748605,497.04117,-9.205451
212.5791,6.0044465,6.3092375,0.0,0,3.6314545,0.0,0.54514492,44.261147,3.629473,494.71036,-9.2039814
212.5835,6.0004668,6.3504434,0.0,0,3.5904114,0.0,0.55000389,44.057796,3.5903277,493.38403,-9.2052479
212.5879,6.0007625,6.3927445,0.0,0,3.5508497,0.0,0.55487251,43.865829,3.5507889,492.05774,-9.2037401
212.5923,6.0366435,6.4286017,0.0,0,3.5118039,0.0,0.55928272,43.938232,3.5105073,490.88519,-9.2043638
212.5967,6.0783257,6.4744835,0.0,0,3.4727583,0.0,0.56450516,44.040051,3.4687154,489.71622,-9.2041292
212.6011,6.1291695,6.5094428,0.0,0,3.4337125,0.0,0.56867725,44.178497,3.4302928,489.6669,-9.2044544
212.6055,6.0905309,6.552115,0.0,0,3.3946671,0.0,0.57366323,43.693356,3.3884909,490.0871,-9.2046738
212.6099,6.1076241,6.5884027,0.0,0,3.3556216,0.0,0.57808584,43.613522,3.3494933,491.00076,-9.2032385
212.6143,6.1378441,6.6257434,0.0,0,3.316576,0.0,0.58252251,43.616123,3.3130448,492.56369,-9.2040529
212.6187,6.1947417,6.6615181,0.0,0,3.27753,0.0,0.58695424,43.825356,3.2753029,493.91974,-9.2052717
212.6231,6.2564073,6.7042251,0.0,0,3.2384844,0.0,0.59195691,44.163589,3.235369,494.18237,-9.206151
212.6275,6.2566938,6.7430463,0.0,0,3.199439,0.0,0.59679252,43.822182,3.1981342,494.44501,-9.2056398
212.6319,6.3190675,6.7823839,0.0,0,3.1603935,0.0,0.60160196,44.059093,3.1614122,494.7775,-9.2043886
212.6363,6.3892961,6.8194928,0.0,0,3.122066,0.0,0.60634333,44.344116,3.1190343,495.1189,-9.2052574
212.6407,6.3845344,6.8614058,0.0,0,3.0849211,0.0,0.61135215,44.111217,3.0814173,496.48373,-9.2048416
212.6451,6.3471351,6.8967848,0.0,0,3.0477762,0.0,0.61593539,43.683319,3.0439394,498.49289,-9.2035055
212.6495,6.4011846,6.9345779,0.0,0,3.0106313,0.0,0.62065315,43.818844,3.0097752,500.17972,-9.2049074
212.6539,6.458909,6.9689555,0.0,0,2.9734867,0.0,0.62489295,43.998867,2.9700711,501.24341,-9.2046223
212.6583,6.491231,7.010426,0.0,0,2.9363418,0.0,0.63015133,44.01466,2.9357433,502.22739,-9.2053003
212.6627,6.5008759,7.0435452,0.0,0,2.8991969,0.0,0.63430238,43.938389,2.8982751,502.12234,-9.2054405
212.6671,6.5983176,7.0845513,0.0,0,2.8620524,0.0,0.63961852,44.325855,2.8614721,502.01727,-9.2055616
212.6715,6.6522179,7.1201963,0.0,0,2.8249075,0.0,0.64410299,44.512901,2.8223,502.21515,-9.2038269
212.6759,6.6245575,7.162662,0.0,0,2.7877626,0.0,0.64955151,44.079155,2.783843,502.49094,-9.2051554
212.6803,6.6138172,7.1924915,0.0,0,2.7506177,0.0,0.65336549,43.866199,2.7470458,502.78729,-9.2058029
212.6847,6.6538296,7.2334461,0.0,0,2.7135069,0.0,0.6587466,43.851009,2.714354,503.10245,-9.206172
212.6891,6.7700596,7.2630882,0.0,0,2.6781669,0.0,0.66252989,44.409584,2.6753933,503.19437,-9.2052727
212.6935,6.8071847,7.3051872,0.0,0,2.6428349,0.0,0.66814262,44.43264,2.6382272,502.61658,-9.204855
212.6979,6.8074999,7.3383422,0.0,0,2.6075029,0.0,0.67247999,44.25465,2.6052067,502.03876,-9.2056551
212.7023,6.808105,7.37747,0.0,0,2.572171,0.0,0.67748338,44.027241,2.5669069,500.76797,-9.2039747
212.7067,6.8544869,7.408927,0.0,0,2.536839,0.0,0.68166304,44.121929,2.5320256,499.48105,-9.2049847
212.7111,6.9071579,7.4445968,0.0,0,2.501507,0.0,0.68641949,44.265316,2.495378,498.88803,-9.2049971
212.7155,6.9341707,7.4760799,0.0,0,2.4661748,0.0,0.6906563,44.290833,2.4605331,498.586,-9.2062511
212.7199,7.0062251,7.5146542,0.0,0,2.4308429,0.0,0.69590718,44.494675,2.4305236,498.08551,-9.2061357
212.7243,7.0988765,7.5532889,0.0,0,2.3955109,0.0,0.70083475,44.844456,2.3860607,497.32388,-9.2050495
212.7287,7.1173034,7.5869846,0.0,0,2.3601789,0.0,0.70569932,44.76553,2.3535318,496.60818,-9.2043123
212.7331,7.1113081,7.6253142,0.0,0,2.324847,0.0,0.71060252,44.479641,2.3179703,496.13544,-9.204772
212.7375,7.1447301,7.6587687,0.0,0,2.2906368,0.0,0.71534109,44.513077,2.2838738,495.66266,-9.2039061
212.7419,7.1821923,7.6929293,0.0,0,2.2570295,0.0,0.71995324,44.520813,2.2496657,496.43536,-9.2049656
212.7463,7.2608032,7.7281294,0.0,0,2.2234225,0.0,0.72483331,44.782646,2.2135684,497.36774,-9.2048893
212.7507,7.2641025,7.7624607,0.0,0,2.1898153,0.0,0.729352,44.590511,2.1807706,497.90524,-9.2043171
212.7551,7.2600613,7.7943282,0.0,0,2.156208,0.0,0.73389637,44.397106,2.1463029,498.19415,-9.2042789
212.7595,7.2594428,7.8310423,0.0,0,2.1226008,0.0,0.73892486,44.130135,2.1152894,498.28159,-9.2041636
212.7639,7.3686604,7.8589959,0.0,0,2.0889935,0.0,0.74281216,44.580505,2.0796468,497.97955,-9.2049408
212.7683,7.4522243,7.8919992,0.0,0,2.0553865,0.0,0.74745691,44.930702,2.0497375,497.7196,-9.2060947
212.7727,7.5017633,7.9299979,0.0,0,2.0217793,0.0,0.75272602,44.981201,2.0137804,498.03476,-9.2055779
212.7771,7.5423465,7.9648285,0.0,0,1.9881722,0.0,0.75755292,45.024078,1.9769797,498.34995,-9.2061911
212.7815,7.5730805,7.9982004,0.0,0,1.954565,0.0,0.7623086,44.978497,1.9437793,499.40674,-9.204874
212.7859,7.5536318,8.0331488,0.0,0,1.9214275,0.0,0.76720828,44.659843,1.9130924,500.6543,-9.2042246
212.7903,7.5891724,8.0639791,0.0,0,1.889457,0.0,0.77150452,44.661724,1.8820548,500.3642,-9.2057657
212.7947,7.6770372,8.0957441,0.0,0,1.8574866,0.0,0.77609366,45.019535,1.8491209,498.67017,-9.2043638
212.7991,7.7360058,8.130435,0.0,0,1.8255162,0.0,0.7812323,45.068722,1.8205504,496.53287,-9.204587
212.8035,7.7870555,8.1638918,0.0,0,1.7935458,0.0,0.78591961,45.206123,1.7878653,493.06577,-9.2043638
212.8079,7.7751822,8.1940975,0.0,0,1.7615755,0.0,0.79027808,44.980373,1.7559316,489.59863,-9.2042799
212.8123,7.8499455,8.2288818,0.0,0,1.729605,0.0,0.79548919,45.082039,1.7195524,487.91476,-9.2060604
212.8167,7.9515729,8.258812,0.0,0,1.6976346,0.0,0.79976004,45.493008,1.687097,486.27237,-9.2046957
212.8211,8.0129223,8.2936525,0.0,0,1.6656642,0.0,0.80490059,45.575901,1.657106,485.63895,-9.2054195
212.8255,8.0417128,8.3259411,0.0,0,1.6336937,0.0,0.80963743,45.588924,1.6246253,485.42865,-9.2053261
212.8299,8.0204487,8.3611507,0.0,0,1.6017234,0.0,0.81483471,45.235306,1.5894128,485.5759,-9.2039862
212.8343,8.0516491,8.3881731,0.0,0,1.5697531,0.0,0.81887215,45.176102,1.5622536,486.1936,-9.2052298
212.8387,8.1377068,8.4204512,0.0,0,1.5392207,0.0,0.82377797,45.458828,1.5307606,486.88025,-9.2036114
212.8431,8.1432667,8.4482508,0.0,0,1.5088079,0.0,0.82783407,45.311852,1.5022048,487.9313,-9.2048197
212.8475,8.2105064,8.4821653,0.0,0,1.478395,0.0,0.83297122,45.457611,1.4706024,488.98236,-9.2048349
212.8519,8.3015118,8.5098057,0.0,0,1.4479822,0.0,0.8371613,45.778687,1.4402256,491.82584,-9.2041903
212.8563,8.3812141,8.543644,0.0,0,1.4175695,0.0,0.84236568,45.926617,1.4057407,494.89908,-9.2054148
212.8607,8.4500055,8.5738487,0.0,0,1.3871567,0.0,0.8469708,46.12796,1.376731,497.60141,-9.2032862
212.8651,8.4073229,8.6071396,0.0,0,1.3567439,0.0,0.8521862,45.65012,1.3477005,500.07019,-9.2041817
212.8695,8.4975882,8.6317911,0.0,0,1.3263311,0.0,0.85601121,45.962433,1.3205758,501.86301,-9.2046185
212.8739,8.6316776,8.6677675,0.0,0,1.2959183,0.0,0.86153871,46.422916,1.2895166,502.34888,-9.2050104
212.8783,8.6944227,8.6955729,0.0,0,1.2655054,0.0,0.86596578,46.588703,1.2599658,502.83743,-9.2048206
212.8827,8.7516289,8.7294226,0.0,0,1.2350928,0.0,0.87111282,46.631752,1.2282929,503.36267,-9.2036104
212.8871,8.8015537,8.7572556,0.0,0,1.2055123,0.0,0.87586236,46.697071,1.1963896,503.88791,-9.205328
212.8915,8.8654852,8.7914219,0.0,0,1.1765865,0.0,0.88097423,46.717503,1.1683582,504.32953,-9.2051315
212.8959,8.8808384,8.8191004,0.0,0,1.1476611,0.0,0.8856445,46.652779,1.136355,504.74969,-9.2037392
212.9003,8.8643465,8.8496161,0.0,0,1.1187353,0.0,0.89051712,46.353485,1.1075011,504.95023,-9.205018
212.9047,8.8834429,8.8747549,0.0,0,1.0898098,0.0,0.89475936,46.216328,1.0786697,504.95023,-9.2064695
212.9091,8.9793148,8.9048128,0.0,0,1.0608841,0.0,0.89924216,46.511112,1.0504299,504.89114,-9.2062378
212.9135,9.0539799,8.9293308,0.0,0,1.0319586,0.0,0.90375626,46.701775,1.0262163,504.65485,-9.2033319
212.9179,9.1125851,8.9611397,0.0,0,1.0030329,0.0,0.90869039,46.770447,0.99628377,504.41852,-9.2046757
212.9223,9.1696625,8.9830866,0.0,0,0.97410738,0.0,0.91274035,46.887905,0.96984762,504.10519,-9.2063875
212.9267,9.3403053,9.0190907,0.0,0,0.94518179,0.0,0.91828424,47.455853,0.93629038,503.79007,-9.2041302
212.9311,9.4052448,9.0445642,0.0,0,0.91625619,0.0,0.92300737,47.587353,0.90672237,503.73398,-9.2041988
212.9355,9.4386854,9.0778818,0.0,0,0.88760829,0.0,0.92824543,47.536568,0.87842703,503.7865,-9.2054014
212.9399,9.4653463,9.1009645,0.0,0,0.86009949,0.0,0.93264407,47.410164,0.85159194,503.8844,-9.2048864
212.9443,9.479866,9.135499,0.0,0,0.83259064,0.0,0.93806696,47.235737,0.82199347,504.04199,-9.2047052
212.9487,9.5566444,9.1554604,0.0,0,0.8050819,0.0,0.94200712,47.440231,0.79858714,504.03452,-9.2034864
212.9531,9.6284151,9.1873598,0.0,0,0.77757305,0.0,0.94701642,47.579662,0.76871288,503.15469,-9.2043982
212.9575,9.6522684,9.2075052,0.0,0,0.75006431,0.0,0.95099896,47.456215,0.74236476,502.27484,-9.2053089
212.9619,9.7508192,9.2399988,0.0,0,0.72255546,0.0,0.95638436,47.700405,0.71341515,500.70828,-9.2036152
212.9663,9.9268551,9.2655077,0.0,0,0.69504666,0.0,0.9611181,48.336227,0.69047505,499.05368,-9.2049351
212.9707,10.00008,9.2933884,0.0,0,0.66753787,0.0,0.96579045,48.500069,0.65711093,497.75363,-9.2042694
212.9751,10.049822,9.3224497,0.0,0,0.64002907,0.0,0.97124904,48.430309,0.63063806,496.67682,-9.2046852
212.9795,10.069241,9.3519449,0.0,0,0.61252028,0.0,0.97627902,48.276424,0.60715264,496.0253,-9.2045565
212.9839,10.155428,9.3741827,0.0,0,0.58501148,0.0,0.98047471,48.45565,0.57792801,496.19601,-9.2050877
212.9883,10.264668,9.4028511,0.0,0,0.55860871,0.0,0.98553801,48.808094,0.55009413,496.40973,-9.2040052
212.9927,10.234379,9.4290857,0.0,0,0.53242874,0.0,0.99043727,48.444176,0.52221709,497.21075,-9.2049561
212.9971,10.254025,9.4543819,0.0,0,0.50624865,0.0,0.99506348,48.250046,0.49721509,498.01178,-9.2047529
213.0015,10.353955,9.4763241,0.0,0,0.48006868,0.0,0.99909347,48.516792,0.47091347,498.47855,-9.204567
213.0059,10.525415,9.5024633,0.0,0,0.45388871,0.0,1.0039307,49.100468,0.44743454,498.85938,-9.2034969
213.0103,10.593331,9.5264006,0.0,0,0.42770869,0.0,1.0084249,49.213989,0.41781905,499.1647,-9.2033577
213.0147,9.867382,9.5466852,0.0,0,0.40152872,0.0,1.0122596,45.689159,0.39873329,499.40109,-9.2055569
213.0191,9.211936,9.5493031,0.0,0,0.37534869,0.0,1.0126905,42.587597,0.37616459,499.69656,-9.2058001
213.0235,8.8891058,9.5557642,0.0,0,0.34916872,0.0,1.0140474,41.04081,0.36359063,500.16928,-9.20646
213.0279,8.6851997,9.55902,0.0,0,0.32298869,0.0,1.0147039,40.08889,0.34478241,500.64203,-9.2047729
213.0323,8.4500637,9.5652142,0.0,0,0.29680869,0.0,1.0159286,38.963478,0.32591242,501.16611,-9.2064686
213.0367,8.1365623,9.5635395,0.0,0,0.27123094,0.0,1.015615,37.517578,0.30354807,501.69135,-9.2064209
213.0411,7.9382839,9.5674028,0.0,0,0.24633574,0.0,1.0164306,36.589146,0.28704828,502.16293,-9.2064524
213.0455,7.6367984,9.5682192,0.0,0,0.22144052,0.0,1.0165037,35.228546,0.27562663,502.62256,-9.2051964
213.0499,7.3322964,9.5701828,0.0,0,0.19654539,0.0,1.0172323,33.775532,0.27199447,502.98904,-9.2075996
213.0543,7.1407213,9.5696678,0.0,0,0.17165019,0.0,1.0168962,32.893261,0.26094839,503.27792,-9.2054977
213.0587,7.1292648,9.5702982,0.0,0,0.14675498,0.0,1.0173149,32.819717,0.25155577,503.52026,-9.2051697
213.0631,7.2804403,9.5713472,0.0,0,0.12185977,0.0,1.0175967,33.492325,0.22329736,503.63846,-9.2059374
213.0675,7.5384669,9.5761404,0.0,0,0.096964575,0.0,1.0183136,34.65601,0.18842703,503.75665,-9.2046976
213.0719,7.7191644,9.5778008,0.0,0,0.072069377,0.0,1.0187188,35.478603,0.15511562,503.86172,-9.2063847
213.0763,7.832376,9.5818462,0.0,0,0.047174171,0.0,1.0194783,35.961773,0.12526138,503.96677,-9.2051296
213.0807,7.8969851,9.5819855,0.0,0,0.022278972,0.0,1.019426,36.234413,0.092476062,504.13867,-9.2052898
213.0851,7.8796873,9.5877256,0.0,0,-0.0025524148,0.0,1.0206596,36.187077,0.066992439,504.33563,-9.2054319
213.0895,7.8411679,9.589469,0.0,0,-0.02684042,0.0,1.0207766,36.025894,0.037536465,504.53851,-9.2042599
213.0939,7.7903943,9.5898895,0.0,0,-0.051128417,0.0,1.0211601,35.729721,0.016529417,504.74857,-9.2046852
213.0983,7.7364993,9.5942421,0.0,0,-0.075416416,0.0,1.0216784,35.453659,-0.0059663709,504.92758,-9.2042503
213.1027,7.6763554,9.5926962,0.0,0,-0.099704415,0.0,1.021484,35.219158,-0.023907915,504.96695,-9.2050571
213.1071,7.6050248,9.5988941,0.0,0,0.31743813,500.0,1.0223882,34.859829,-0.044420991,505.00632,-9.2040949
213.1115,6.9960256,9.5947895,0.0,0,1.1142951,500.0,1.021928,32.147594,-0.037834156,505.10535,-9.2047434
213.1159,4.1510196,9.5839682,0.0,0,1.9111534,500.0,1.0196594,19.196447,0.1342224,505.21036,-9.2074118
213.1203,-0.15088686,9.5418272,0.0,0,2.7080107,500.0,1.011984,-0.66816711,0.45953092,505.34875,-9.2119827
213.1247,0.22600134,9.5558672,0.0,0,3.5048685,500.0,1.0144361,1.0072353,1.7545556,505.50626,-9.2112885
213.1291,0.026787922,9.5556135,0.0,0,4.3017259,500.0,1.0143658,0.083474055,2.9252918,505.64465,-9.2104511
213.1335,0.059018385,9.5525961,0.0,0,5.0985837,500.0,1.0135884,0.2998473,3.7099047,505.74963,-9.2108078
213.1379,0.0016417315,9.5498905,0.0,0,5.8954411,500.0,1.013008,0.064552225,4.450747,505.85107,-9.2093544
213.1423,0.038848408,9.549449,0.0,0,6.6922989,500.0,1.0128545,0.14784624,5.2057714,505.91669,-9.2088051
213.1467,0.081370912,9.549262,0.0,0,7.4891562,500.0,1.0127755,0.35477191,6.0005927,505.98233,-9.2073116
213.1511,-0.022413861,9.5505676,0.0,0,8.2860146,500.0,1.0129812,-0.091131002,6.8158998,506.02649,-9.2079258
213.1555,0.037984669,9.5487518,0.0,0,9.0828724,500.0,1.0126376,0.21554855,7.647563,506.06586,-9.208148
213.1599,0.053217925,9.5479012,0.0,0,9.8797302,500.0,1.0123641,0.2142055,8.4727201,506.13385,-9.2082043
213.1643,0.077005319,9.5494852,0.0,0,10.676588,500.0,1.0124832,0.36038271,9.2967243,506.22574,-9.2055941
213.1687,0.027747585,9.5498791,0.0,0,11.473445,500.0,1.0125421,0.13665952,10.093841,506.3176,-9.2058487
213.1731,0.063572764,9.547945,0.0,0,12.270303,500.0,1.0120205,0.30982536,10.89219,506.40948,-9.2063093
213.1775,0.013975705,9.5501137,0.0,0,13.067161,500.0,1.0123857,0.05878206,11.68278,506.50134,-9.2045298
213.1819,0.089337826,9.5467987,0.0,0,13.864018,500.0,1.0117087,0.37751654,12.447258,506.56699,-9.2064905
213.1863,0.048191708,9.550436,0.0,0,14.660876,500.0,1.0123061,0.22011848,13.236283,506.6326,-9.2052116
213.1907,-0.00086617493,9.5481806,0.0,0,15.457734,500.0,1.0118517,-0.012813322,14.042772,506.70776,-9.2058144
213.1951,0.032963142,9.5491371,0.0,0,16.254593,500.0,1.0118095,0.11718902,14.855948,506.78653,-9.2058535
213.1995,0.0047470862,9.5470276,0.0,0,17.051451,500.0,1.0115132,-0.010901743,15.659488,506.85928,-9.2059116
213.2039,0.032855019,9.5519342,0.0,0,17.848307,500.0,1.01212,0.21109279,16.456078,506.92493,-9.2050037
213.2083,0.007873727,9.5490084,0.0,0,18.0,500.0,1.0118037,-0.045211539,17.248949,506.98337,-9.2043047
213.2127,0.022747582,9.5529966,0.0,0,18.0,500.0,1.0121112,0.12105713,17.965281,507.00964,-9.2071648
213.2171,0.12658527,9.5525379,0.0,0,18.0,500.0,1.0122695,0.64890498,18.424879,507.03589,-9.211503
213.2215,0.43338141,9.5704012,0.0,0,18.0,500.0,1.0153626,1.9929169,18.479874,507.06213,-9.2223434
213.2259,0.57633954,9.5742188,0.0,0,18.0,500.0,1.0160356,2.6829946,18.248413,507.08838,-9.2423096
213.2303,0.57604569,9.5793934,0.0,0,18.0,500.0,1.0168655,2.6491342,18.078012,507.12299,-9.2735014
213.2347,0.51748008,9.5738554,0.0,0,18.0,500.0,1.0158978,2.4242363,18.044577,507.16238,-9.3111124
213.2391,0.54460716,9.5730419,0.0,0,18.0,500.0,1.0156242,2.5129182,18.076969,507.22562,-9.3509665
213.2435,0.54968452,9.5697336,0.0,0,18.0,500.0,1.0151216,2.5194733,18.119793,507.3306,-9.3856344
213.2479,0.56047118,9.5758457,0.0,0,18.0,500.0,1.0159484,2.614387,18.145103,507.43442,-9.4195356
213.2523,0.53999388,9.5756121,0.0,0,18.0,500.0,1.0161844,2.5194373,18.147404,507.52628,-9.45399
213.2567,0.56124979,9.5751753,0.0,0,18.0,500.0,1.0157421,2.5616646,18.143757,507.61816,-9.4854727
213.2611,0.58587873,9.5720568,0.0,0,18.0,500.0,1.0155305,2.6951966,18.136883,507.6456,-9.5178232
213.2655,0.57965529,9.5769529,0.0,0,18.0,500.0,1.0158858,2.6634915,18.133539,507.65872,-9.551198
213.2699,0.54944307,9.5735865,0.0,0,18.0,500.0,1.0160074,2.5751905,18.128193,507.68616,-9.585743
213.2743,0.56121868,9.5765676,0.0,0,18.0,500.0,1.0160094,2.5766475,18.119799,507.72552,-9.6190214
213.2787,0.57056749,9.5744228,0.0,0,18.0,500.0,1.0157998,2.6094348,18.120476,507.76492,-9.6513777
213.2831,0.58364165,9.5779696,0.0,0,18.0,500.0,1.0162352,2.6937549,18.112717,507.80429,-9.6848183
213.2875,0.56142288,9.575099,0.0,0,18.0,500.0,1.0162077,2.5684729,18.115324,507.84369,-9.718442
213.2919,0.55236661,9.5788317,0.0,0,18.0,500.0,1.0165684,2.5432568,18.105217,507.81741,-9.749958
213.2963,0.57006592,9.5718307,0.0,0,18.0,500.0,1.0156918,2.6302609,18.109129,507.79117,-9.7846222
213.3007,0.58292705,9.577034,0.0,0,18.0,500.0,1.0161656,2.6866388,18.100718,507.76492,-9.8189754
213.3051,0.5669477,9.5752287,0.0,0,18.0,500.0,1.01644,2.6241322,18.099936,507.73868,-9.851119
213.3095,0.54592693,9.579073,0.0,0,18.0,500.0,1.0166802,2.5181494,18.102587,507.72437,-9.8856373
213.3139,0.56547523,9.5740509,0.0,0,18.0,500.0,1.0162599,2.6212802,18.10017,507.72437,-9.9195662
213.3183,0.58422017,9.5756321,0.0,0,18.0,500.0,1.0163431,2.6801407,18.097481,507.72437,-9.9511261
213.3227,0.56763607,9.577836,0.0,0,18.0,500.0,1.0170685,2.6003385,18.10013,507.72437,-9.9859238
213.3271,0.54954082,9.5795689,0.0,0,18.0,500.0,1.0171118,2.519639,18.098906,507.72437,-10.018245
213.3315,0.57341868,9.5731936,0.0,0,18.0,500.0,1.0162534,2.6550324,18.096088,507.71243,-10.052583
213.3359,0.5928477,9.5767365,0.0,0,18.0,500.0,1.016868,2.7161317,18.098337,507.69928,-10.084702
213.3403,0.58705831,9.5758505,0.0,0,18.0,500.0,1.0168954,2.7409623,18.094719,507.71121,-10.119144
213.3447,0.56047189,9.5799427,0.0,0,18.0,500.0,1.0176283,2.5620503,18.093102,507.73749,-10.15242
213.3491,0.5803172,9.574111,0.0,0,18.0,500.0,1.0170375,2.6807346,18.086258,507.74463,-10.185297
213.3535,0.60241848,9.5775614,0.0,0,18.0,500.0,1.0173678,2.7860949,18.086369,507.71838,-10.218115
213.3579,0.59096378,9.5730028,0.0,0,18.0,500.0,1.0167272,2.7287107,18.084934,507.68735,-10.252858
213.3623,0.56684661,9.5794125,0.0,0,18.0,500.0,1.0179927,2.6124232,18.08176,507.60861,-10.284959
213.3667,0.56955886,9.5720234,0.0,0,18.0,500.0,1.0167608,2.6601336,18.082405,507.52985,-10.319274
213.3711,0.59613508,9.5762043,0.0,0,18.0,500.0,1.0175893,2.729785,18.080019,507.51553,-10.350746
213.3755,0.59848613,9.5746622,0.0,0,18.0,500.0,1.0171378,2.7165961,18.08226,507.51553,-10.384564
213.3799,0.57961333,9.5769234,0.0,0,18.0,500.0,1.0179329,2.6566463,18.08214,507.51553,-10.420283
213.3843,0.57586932,9.5739937,0.0,0,18.0,500.0,1.0174229,2.6456656,18.077118,507.51553,-10.451258
213.3887,0.59435457,9.5761347,0.0,0,18.0,500.0,1.0179322,2.7372563,18.077698,507.50836,-10.485907
213.3931,0.60651141,9.5707417,0.0,0,18.0,500.0,1.0169796,2.8318956,18.075743,507.48212,-10.518972
213.3975,0.5910871,9.5748281,0.0,0,18.0,500.0,1.0177591,2.7280185,18.077,507.45587,-10.553185
213.4019,0.57389772,9.5735731,0.0,0,18.0,500.0,1.0175439,2.6431789,18.07473,507.45587,-10.586758
213.4063,0.60491168,9.574008,0.0,0,18.0,500.0,1.0177791,2.7486417,18.071442,507.45587,-10.617136
213.4107,0.61488318,9.5704966,0.0,0,18.0,500.0,1.0172212,2.8292999,18.072439,507.41769,-10.652646
213.4151,0.59652382,9.5775766,0.0,0,18.0,500.0,1.0186369,2.7691791,18.068951,507.36517,-10.687757
213.4195,0.58638042,9.5732746,0.0,0,18.0,500.0,1.0178976,2.6991615,18.067337,507.31268,-10.719103
213.4239,0.59030622,9.5724392,0.0,0,18.0,500.0,1.017742,2.7129464,18.070818,507.26019,-10.753646
213.4283,0.62730771,9.5707626,0.0,0,18.0,500.0,1.0174097,2.8749349,18.066219,507.22443,-10.786525
213.4327,0.60905933,9.5757265,0.0,0,18.0,500.0,1.0182279,2.8124938,18.064964,507.26379,-10.819068
213.4371,0.58394343,9.5730886,0.0,0,18.0,500.0,1.0178384,2.691561,18.065233,507.30319,-10.853196
213.4415,0.58629489,9.571702,0.0,0,18.0,500.0,1.017602,2.6793585,18.066402,507.30676,-10.886829
213.4459,0.61687309,9.5724649,0.0,0,18.0,500.0,1.0175793,2.8267944,18.061895,507.30676,-10.919539
213.4503,0.60642481,9.5719595,0.0,0,18.0,500.0,1.017713,2.8029077,18.063383,507.27335,-10.952976
213.4547,0.58344012,9.5730352,0.0,0,18.0,500.0,1.0177354,2.6851671,18.059656,507.22086,-10.987041
213.4591,0.5866496,9.5705404,0.0,0,18.0,500.0,1.0175015,2.7377961,18.06328,507.16833,-11.019912
213.4635,0.60601008,9.5706377,0.0,0,18.0,500.0,1.0173354,2.783716,18.058504,507.11584,-11.051494
213.4679,0.61285317,9.5707769,0.0,0,18.0,500.0,1.0174538,2.8411298,18.060049,507.06693,-11.084905
213.4723,0.59699219,9.5734539,0.0,0,18.0,500.0,1.0175807,2.7503216,18.054964,507.0538,-11.119953
213.4767,0.59713084,9.5722027,0.0,0,18.0,500.0,1.0176202,2.7533748,18.053812,507.04065,-11.152838
213.4811,0.61512578,9.57265,0.0,0,18.0,500.0,1.0174483,2.8340969,18.053432,507.08124,-11.187306
213.4855,0.61473429,9.5711164,0.0,0,18.0,500.0,1.0171216,2.8601995,18.054773,507.13373,-11.219112
213.4899,0.58192021,9.5744019,0.0,0,18.0,500.0,1.0176455,2.7028003,18.054409,507.15042,-11.253335
213.4943,0.60246146,9.5723972,0.0,0,18.0,500.0,1.0172639,2.7552333,18.04661,507.1373,-11.287594
213.4987,0.61132163,9.5712748,0.0,0,18.0,500.0,1.0169353,2.814554,18.052126,507.10626,-11.320087
213.5031,0.62340373,9.5722218,0.0,0,18.0,500.0,1.0171187,2.8812566,18.053673,507.02753,-11.352083
214.9046,0.53455901,9.5894184,0.0,0,18.0,4.0912098e-17,1.0197625,2.4529972,18.000336,482.09085,-11.480968
217.1046,0.56083244,9.6052761,0.0,0,18.0,1.4012985e-45,1.022646,2.5753555,18.000933,459.9964,-11.481113
219.3046,0.57780421,9.6187696,0.0,0,18.0,1.4012985e-45,1.0250834,2.6400294,18.00016,440.3681,-11.481371
221.5046,0.59901822,9.6316929,0.0,0,18.0,1.4012985e-45,1.0274601,2.7306073,18.00005,421.60455,-11.480996
223.7046,0.61024714,9.6441898,0.0,0,18.0,1.4012985e-45,1.029784,2.7752292,18.000282,403.60251,-11.481285
225.9046,0.62863219,9.6559916,0.0,0,18.0,1.4012985e-45,1.0320421,2.8553638,18.000229,386.05145,-11.481364
228.1046,0.64363688,9.6668348,0.0,0,18.0,1.4012985e-45,1.0341135,2.9100125,17.99962,369.48331,-11.480949
230.3046,0.65430105,9.67801,0.0,0,18.0,1.4012985e-45,1.0362738,2.9535012,18.000984,353.31607,-11.481666
232.5046,0.66925484,9.6886644,0.0,0,18.0,1.4012985e-45,1.0382938,3.0203631,18.000042,338.10703,-11.481843
234.7046,0.68177736,9.6989851,0.0,0,18.0,1.4012985e-45,1.0401728,3.0662971,18.000029,323.43658,-11.480768
236.9046,0.68879539,9.70926,0.0,0,18.0,1.4012985e-45,1.0421022,3.0911663,17.998941,309.38614,-11.480954
239.1046,0.70613015,9.7179432,0.0,0,18.0,1.4012985e-45,1.0437008,3.1724339,17.99967,295.65375,-11.481644
241.3046,0.71294403,9.727725,0.0,0,18.0,1.4012985e-45,1.0456165,3.1915154,18.00108,282.80875,-11.481506
243.5046,0.71886349,9.7365551,0.0,0,18.0,1.4012985e-45,1.047312,3.2083657,18.000502,271.11581,-11.481447
245.7046,0.72789419,9.7449789,0.0,0,18.0,1.4012985e-45,1.0489261,3.2484403,17.999893,259.44907,-11.481046
247.9046,0.74466103,9.7533531,0.0,0,18.0,1.4012985e-45,1.0504646,3.3156414,17.999891,248.68826,-11.481297
250.1046,0.74676198,9.761447,0.0,0,18.0,1.4012985e-45,1.0519781,3.3187106,17.999174,238.26498,-11.481515
252.3046,0.75219083,9.7686825,0.0,0,18.0,1.4012985e-45,1.0533226,3.3435025,18.000042,228.342,-11.48137
254.5046,0.76863688,9.7758656,0.0,0,18.0,1.4012985e-45,1.0546837,3.4124742,17.999395,218.91656,-11.481205
256.7046,0.77294308,9.7829466,0.0,0,18.0,1.4012985e-45,1.0560486,3.4207244,17.998608,209.86217,-11.480486
258.9046,0.77272332,9.7896214,0.0,0,18.0,1.4012985e-45,1.0573454,3.4237888,18.001282,201.15791,-11.481097
261.1046,0.79064822,9.7966537,0.0,0,18.0,1.4012985e-45,1.058735,3.4939907,18.000559,193.01445,-11.481627
263.3046,0.78976512,9.8018837,0.0,0,18.0,1.4012985e-45,1.0597985,3.4796374,17.999668,185.22734,-11.481466
265.5046,0.79627383,9.8081741,0.0,0,18.0,1.4012985e-45,1.0610677,3.514102,17.999908,177.67781,-11.481028
267.7046,0.80629629,9.8129549,0.0,0,18.0,1.4012985e-45,1.0619808,3.5523667,18.000668,170.65733,-11.480696
269.9046,0.80753005,9.8183632,0.0,0,18.0,1.4012985e-45,1.0629747,3.5477843,17.999836,163.84192,-11.480412
272.1046,0.80635434,9.8236742,0.0,0,18.0,1.4012985e-45,1.063971,3.5428963,18.000175,157.37106,-11.481288
273.5046,0.82104599,9.8267918,0.0,0,18.0,1.4012985e-45,1.0646187,3.6028841,18.000372,153.52904,-11.481206