File: examples/dan-msc-case-studies/CS3/data/01 raw data/baron_test_012.csv
Time(sec),Force(kN),Jaw(mm),PowAngle(deg),Power(W),Pram,PTemp,Strain,Stress(MPa),Stroke(mm),TC1(C),wedge(mm)
0.0,0.18102135,0.37100393,0.0,0,11.076097,0.0014957101,0.025036,2.2516418,11.075686,23.773237,-9.1133108
1.1,0.12167019,0.0056889215,0.0,0,11.076097,3.2158809,0.00036020399,1.5531164,11.075403,23.777121,-9.4826555
2.2,0.10071559,0.0057196715,0.0,0,11.076097,6.515882,0.000369118,1.2653353,11.07561,23.727966,-9.4804258
3.3,0.090875678,0.0056304792,0.0,0,11.076097,9.8158808,0.00038602165,1.1612904,11.075256,23.774189,-9.4787683
4.4,0.071383417,0.0051782271,0.0,0,11.076097,13.115882,0.00036980963,0.90542728,11.076029,23.746147,-9.4768209
5.5,0.060463648,0.0051362682,0.0,0,11.076097,16.415882,0.00034539649,0.77052581,11.075751,23.74267,-9.4750166
6.6,0.053822786,0.0052187396,0.0,0,11.076097,19.715883,0.00036665506,0.68285638,11.075574,23.787394,-9.4732246
7.7,0.043046314,0.0052166218,0.0,0,11.076097,23.015882,0.00034198118,0.55277431,11.075423,23.680544,-9.4713173
8.8,0.035093918,0.0052050515,14.696727,0,11.076097,26.315882,0.00032368503,0.4348478,11.076177,23.759712,-9.4694738
9.9,0.035254478,0.0050594765,30.498205,0,11.076097,29.615883,0.00032424508,0.44006431,11.075031,23.872305,-9.4674959
11.0,0.034980614,0.0045055235,39.884926,0,11.076097,32.915878,0.00031475551,0.45970696,11.07623,24.436932,-9.4657745
12.1,0.032571435,0.0028485912,46.662743,0,11.076097,36.215881,0.00020370487,0.41212377,11.075522,25.767458,-9.4639482
13.2,0.030154927,0.001666564,51.882935,0,11.076097,39.515873,0.00010522593,0.38851842,11.075991,27.568708,-9.4621868
14.3,0.038877428,-0.00022702868,55.828804,0,11.076097,42.815872,-3.0595056e-06,0.49531507,11.076444,30.057096,-9.4607077
15.4,0.051737204,-0.0019787587,59.195324,0,11.076097,46.115875,-0.00014686068,0.67476112,11.076846,32.873592,-9.4589872
16.5,0.07573127,-0.0044167759,61.896324,0,11.076097,49.415878,-0.00031360291,0.96058667,11.077014,36.023247,-9.4573851
17.6,0.072321475,-0.0072814128,64.160461,0,11.076097,52.715885,-0.0004949898,0.93504864,11.074628,39.538544,-9.4555206
18.7,0.084472954,-0.010604314,65.998184,0,11.076097,56.015884,-0.0006932781,1.0830373,11.075969,43.544235,-9.4534883
19.8,0.1038397,-0.01488407,67.384865,0,11.076097,59.315891,-0.00097474741,1.3120656,11.076443,47.813377,-9.4515772
20.9,0.11191803,-0.018386453,68.387772,0,11.076097,62.615894,-0.001228666,1.4373738,11.076487,52.531517,-9.449707
22.0,0.11391905,-0.022284206,69.119308,0,11.076097,65.915871,-0.0014684515,1.4718636,11.075184,57.552502,-9.4479294
23.1,0.12809713,-0.026578311,69.363579,0,11.076097,69.215866,-0.0017746983,1.6430519,11.075997,63.148178,-9.446002
24.2,0.15559609,-0.031763084,69.422607,0,11.076097,72.515892,-0.0021382642,1.9752094,11.076199,68.425011,-9.4445581
25.3,0.13365099,-0.035317972,68.972862,0,11.076097,75.815872,-0.0023531737,1.6986254,11.075639,74.306923,-9.4426689
26.4,0.1398304,-0.03990313,68.359062,0,11.076097,79.115891,-0.0026335374,1.7808578,11.076494,79.831818,-9.4409437
27.5,0.15054998,-0.043373182,67.391609,0,11.076097,82.415901,-0.0028688961,1.9114165,11.07538,85.31649,-9.4391794
28.6,0.15657379,-0.048356988,66.195755,0,11.076097,85.715889,-0.0032185393,2.0102286,11.075894,90.569,-9.4374018
29.7,0.13890518,-0.051009599,64.766426,0,11.076097,89.0159,-0.0033814013,1.7803582,11.076691,95.249535,-9.4352961
30.8,0.14996766,-0.053638432,63.24329,0,11.076097,92.315895,-0.003586621,1.9175682,11.076157,99.522614,-9.4332418
31.9,0.15807217,-0.056513932,61.720779,0,11.076097,95.615906,-0.0037862975,2.0169442,11.075355,103.31477,-9.4316549
33.0,0.15266731,-0.059274368,60.15416,0,11.076097,98.915901,-0.0039397283,1.9552319,11.07552,106.63723,-9.4297533
34.1,0.14928187,-0.061443727,58.678368,0,11.076097,102.2159,-0.0040632393,1.90504,11.077007,109.59636,-9.4281425
35.2,0.26773873,-0.061388116,57.543396,0,11.076097,105.5159,-0.00408054,3.4392972,11.0771,112.13933,-9.4265614
36.3,0.52169901,-0.061011992,56.134247,0,11.076097,108.8159,-0.0040581329,6.6683722,11.075233,115.28827,-9.4249954
37.4,0.61581385,-0.061019361,54.316795,0,11.076097,112.1159,-0.0040642312,7.8719473,11.076039,118.68566,-9.4228668
38.5,0.75554341,-0.06083649,52.646919,0,11.076097,115.41589,-0.004070472,9.6510773,11.076701,121.7557,-9.4216681
39.6,0.82073957,-0.061703775,51.201275,0,11.076097,118.7159,-0.0041215033,10.487579,11.076618,124.36285,-9.4191523
40.7,0.88689154,-0.062601142,50.438236,0,11.076097,122.01589,-0.0041483608,11.352282,11.075986,126.62628,-9.4171925
41.8,0.92761403,-0.063557573,50.190723,0,11.076097,125.31589,-0.0042136502,11.857901,11.076362,128.48711,-9.4153929
42.9,0.95673287,-0.064620845,50.438229,0,11.076097,128.61601,-0.004302755,12.231912,11.075871,130.24254,-9.4137115
44.0,0.95028192,-0.067430541,51.556904,0,11.076097,131.91588,-0.0044767885,12.165895,11.076524,131.9915,-9.4112797
45.1,0.96530473,-0.068650506,52.857849,0,11.076097,135.2159,-0.0045867488,12.333476,11.07513,133.68265,-9.4102201
46.2,0.98770505,-0.070675127,54.292778,0,11.076097,138.51588,-0.0047233002,12.632071,11.076544,135.77782,-9.4080801
47.3,0.99922764,-0.073284276,55.53487,0,11.076097,141.81589,-0.0048751296,12.79864,11.076126,138.30377,-9.4066172
48.4,1.0034257,-0.076390028,56.711384,0,11.076097,145.11589,-0.0050515938,12.838456,11.075712,141.11433,-9.4050684
49.5,1.0120094,-0.079398096,57.928905,0,11.076097,148.41589,-0.0052872915,12.940409,11.076207,144.09392,-9.4033098
50.6,1.0220195,-0.082755312,58.717129,0,11.076097,151.7159,-0.0054927547,13.082332,11.076742,147.66539,-9.4014082
51.7,1.0266752,-0.08780437,59.347004,0,11.076097,155.01588,-0.0058469046,13.151366,11.076087,151.38806,-9.3994389
52.8,1.0293852,-0.090698041,59.600826,0,11.076097,158.3159,-0.0060441643,13.188222,11.076464,155.58267,-9.3976908
53.9,1.0417719,-0.094186306,59.842525,0,11.076097,161.61589,-0.0062523223,13.356315,11.07654,159.4088,-9.3958359
55.0,1.0494492,-0.098887756,59.842525,0,11.076097,164.91589,-0.0065590232,13.440941,11.075509,163.5565,-9.3939571
56.1,1.0500183,-0.10191934,59.600838,0,11.076097,168.2159,-0.0067676879,13.458259,11.075388,167.65504,-9.3918028
57.2,1.0617381,-0.10546498,59.348148,0,11.076097,171.5159,-0.0069944593,13.620042,11.075109,171.69408,-9.3904181
58.3,1.0667199,-0.10869506,58.940277,0,11.076097,174.81589,-0.0072254124,13.68779,11.075579,175.50719,-9.3890371
59.4,1.0739641,-0.11225838,58.402988,0,11.076097,178.11589,-0.0074671684,13.767278,11.076261,179.37358,-9.3869734
60.5,1.0710988,-0.11573231,58.073738,0,11.076097,181.41589,-0.0076873153,13.735223,11.076453,182.89851,-9.3852673
61.6,1.0764604,-0.11844731,57.560745,0,11.076097,184.7159,-0.0078345705,13.820655,11.076805,186.18452,-9.3836193
62.7,1.0713661,-0.12237346,57.535412,0,11.076097,188.0159,-0.0081268372,13.758111,11.076543,189.17809,-9.3819847
63.8,1.067543,-0.12438978,57.261436,0,11.076097,191.31589,-0.0082461536,13.698465,11.075579,192.25977,-9.3800545
64.9,1.0802743,-0.12662598,57.411758,0,11.076097,194.61589,-0.0084200539,13.869648,11.075705,195.17448,-9.3782358
66.0,1.0843819,-0.13022149,57.678108,0,11.076097,197.91589,-0.0086579053,13.926291,11.076576,197.89261,-9.3761978
67.1,1.0762174,-0.13294013,57.810051,0,11.076097,201.2159,-0.0088199917,13.823311,11.07548,200.77992,-9.3742304
68.2,1.0867491,-0.13563482,58.33733,0,11.076097,204.5159,-0.0089817401,13.970119,11.075999,203.63145,-9.3725595
69.3,1.090263,-0.13791098,58.811043,0,11.076097,207.8159,-0.0091603715,13.998489,11.075906,206.5508,-9.3708792
70.4,1.0949301,-0.14202566,59.106438,0,11.076097,211.11589,-0.0094095441,14.06243,11.075764,209.57489,-9.3692102
71.5,1.0976247,-0.1445242,59.597309,0,11.076097,214.41591,-0.0096074287,14.107085,11.076064,212.78589,-9.3677235
72.6,1.1044277,-0.14737178,59.921371,0,11.076097,217.7159,-0.0097953212,14.210681,11.075846,216.00563,-9.3659668
73.7,1.1100188,-0.15153758,60.314934,0,11.076097,221.0159,-0.01004098,14.276329,11.075792,219.13686,-9.3642378
74.8,1.1172134,-0.15437941,60.785992,0,11.076097,224.3159,-0.010226594,14.3593,11.07595,222.48419,-9.3626213
75.9,1.1125783,-0.15800086,61.018063,0,11.076097,227.61589,-0.010476766,14.332508,11.077044,225.914,-9.3608685
77.0,1.1155429,-0.1615231,61.237789,0,11.076097,230.91589,-0.010707557,14.348055,11.075492,229.45076,-9.3585186
78.1,1.1361176,-0.16486716,61.468464,0,11.076097,234.2159,-0.010955691,14.638393,11.075317,232.98911,-9.3567734
79.2,1.1231321,-0.1687454,61.468498,0,11.076097,237.51588,-0.011195486,14.462681,11.076719,236.50363,-9.3549376
80.3,1.129738,-0.17246401,61.468513,0,11.076097,240.8159,-0.011409554,14.546292,11.075417,240.10289,-9.3529921
81.4,1.1391151,-0.17563912,61.470112,0,11.076097,244.11589,-0.011629916,14.673139,11.076218,243.64751,-9.3511543
82.5,1.1472942,-0.17867212,61.468513,0,11.076097,247.41589,-0.011830353,14.796922,11.075968,247.1777,-9.3497887
83.6,1.1475312,-0.18394408,61.468513,0,11.076097,250.7159,-0.012205685,14.787548,11.076116,250.54855,-9.3479347
84.7,1.1427083,-0.18648194,61.468513,0,11.076097,254.0159,-0.012374616,14.722244,11.076239,254.01375,-9.3461151
85.8,1.1537162,-0.18966328,61.468513,0,11.076097,257.31616,-0.012559056,14.894245,11.076195,257.33179,-9.3446922
86.9,1.1547899,-0.19256912,61.468513,0,11.076097,260.61615,-0.012737512,14.886713,11.075391,260.70313,-9.3429146
88.0,1.1619803,-0.19590212,61.468513,0,11.076097,263.91592,-0.012981637,14.980977,11.076248,263.98605,-9.3414431
89.1,1.1615325,-0.19955185,61.468513,0,11.076097,267.21591,-0.013199803,14.980571,11.076574,267.19473,-9.339325
90.2,1.1566162,-0.20167184,61.501942,0,11.076097,270.51593,-0.013370052,14.923803,11.075605,270.3287,-9.3379364
91.3,1.1556907,-0.20474257,61.688229,0,11.076097,273.81592,-0.013564121,14.904191,11.075766,273.39749,-9.3358812
92.4,1.1644981,-0.20768298,61.895645,0,11.076097,277.11594,-0.013730277,15.044117,11.075258,276.47604,-9.3342352
93.5,1.1636631,-0.21016048,62.096981,0,11.076097,280.41592,-0.01391422,15.037961,11.076055,279.61874,-9.3322563
94.6,1.178148,-0.2146471,62.336418,0,11.076097,283.71591,-0.01420892,15.201243,11.075174,282.67502,-9.330657
95.7,1.1719121,-0.21812452,62.545162,0,11.076097,287.0159,-0.01444811,15.139125,11.075943,285.92648,-9.3286572
96.8,1.175481,-0.2204317,62.83363,0,11.076097,290.31592,-0.014610962,15.185038,11.076483,289.09686,-9.3266449
97.9,1.1646897,-0.22442719,63.169796,0,11.076097,293.61591,-0.014830343,15.052418,11.07655,292.30655,-9.3245745
99.0,1.182009,-0.22776273,63.346985,0,11.076097,296.91589,-0.015050307,15.281015,11.076176,295.61108,-9.3232679
100.1,1.1802006,-0.23141892,63.577873,0,11.076097,300.21588,-0.015306222,15.268593,11.076517,298.87106,-9.3210793
101.2,1.1880881,-0.23452882,63.775627,0,11.076097,303.5159,-0.015519742,15.369899,11.074893,302.31512,-9.3193588
102.3,1.1936827,-0.2379728,63.827259,0,11.076097,306.81589,-0.015753606,15.438053,11.076262,305.82132,-9.3179235
103.4,1.1858817,-0.24148592,63.973385,0,11.076097,310.11588,-0.015962044,15.352193,11.076155,309.20837,-9.3163099
104.5,1.1977972,-0.24489996,64.171097,0,11.076097,313.41586,-0.016170047,15.497953,11.075826,312.56732,-9.3145475
105.6,1.2028958,-0.24842876,64.171135,0,11.076097,316.71588,-0.016420582,15.563419,11.076541,315.99927,-9.3129034
106.7,1.1972309,-0.2521475,64.256561,0,11.076097,320.0159,-0.016668148,15.521781,11.076749,319.36884,-9.3112583
107.8,1.1998817,-0.25563744,64.357903,0,11.076097,323.31592,-0.016918734,15.541316,11.075763,322.76709,-9.3097954
108.9,1.2014041,-0.25912607,64.363564,0,11.076097,326.61591,-0.017119681,15.562032,11.076031,326.11694,-9.3081026
110.0,1.2096241,-0.26304072,64.555656,0,11.076097,329.91437,-0.01736692,15.669661,11.076329,329.3783,-9.3065357
111.1,1.2069209,-0.26591095,63.018551,0,11.076097,329.99976,-0.017570581,15.653882,11.074895,332.65393,-9.3060942
112.2,1.2092742,-0.26801825,61.075134,0,11.076097,329.99976,-0.017704545,15.67131,11.075767,335.42041,-9.3059473
113.3,1.2053493,-0.26949239,58.715805,0,11.076097,329.99976,-0.017828137,15.626008,11.075707,337.56879,-9.3057308
114.4,1.1259335,-0.27075544,56.099598,0,11.076097,329.99976,-0.017888051,14.609708,11.076841,338.80905,-9.3057785
115.5,1.0222468,-0.27128136,53.526962,0,11.076097,329.99976,-0.017902909,13.249617,11.075736,339.10168,-9.3055258
116.6,0.92156464,-0.27072147,51.198254,0,11.076097,329.99976,-0.017888483,11.937728,11.076084,338.60019,-9.305541
117.7,0.84913522,-0.27036992,49.250057,0,11.076097,329.99976,-0.017861584,11.014629,11.076058,337.36993,-9.3052483
118.8,0.79028779,-0.26988283,48.799126,0,11.076097,329.99976,-0.017855659,10.251605,11.077182,335.49234,-9.3055019
119.9,0.74810863,-0.26780185,48.812229,0,11.076097,329.99976,-0.017687179,9.7010145,11.076598,333.35281,-9.3053532
121.0,0.71409661,-0.266792,49.893715,0,11.076097,329.99976,-0.017610863,9.2632818,11.076144,331.15833,-9.3051081
122.1,0.68679368,-0.26611653,51.193272,0,11.076097,329.99976,-0.01757976,8.9145632,11.075966,329.22195,-9.3053303
123.2,0.68343127,-0.26555404,52.962849,0,11.076097,329.99976,-0.017558636,8.8584623,11.076718,327.59445,-9.3054886
124.3,0.68257892,-0.26574206,54.594509,0,11.076097,329.99976,-0.017583318,8.8537636,11.076719,326.49286,-9.3054314
125.4,0.68604314,-0.26647377,56.040909,0,11.076097,329.99976,-0.017592639,8.8822861,11.076514,325.76181,-9.3056803
126.5,0.6923247,-0.26727131,57.023396,0,11.076097,329.99976,-0.017647687,8.9588432,11.075998,325.63046,-9.3056545
127.6,0.69785631,-0.26702169,58.07671,0,11.076097,329.99976,-0.017645752,9.0511723,11.076098,325.68433,-9.3057947
128.7,0.69477987,-0.26787236,58.848774,0,11.076097,329.99976,-0.017712424,9.0032883,11.076819,326.16116,-9.3059921
129.8,0.69042486,-0.26992583,59.121613,0,11.076097,329.99976,-0.017848585,8.9536982,11.076829,326.84048,-9.3058958
130.9,0.69829756,-0.27154425,59.348137,0,11.076097,329.99976,-0.017915931,9.0502186,11.076527,327.75555,-9.3061333
132.0,0.69867271,-0.27323022,59.334702,0,11.076097,329.99976,-0.018046524,9.0732822,11.07529,328.65945,-9.3059902
133.1,0.70167845,-0.27397922,59.050312,0,11.076097,329.99976,-0.018090898,9.097477,11.076992,329.55399,-9.305541
134.2,0.70943195,-0.27492988,58.509853,0,11.076097,329.99976,-0.018181104,9.1943617,11.077438,330.49625,-9.3057098
135.3,0.7014448,-0.27642643,58.073738,0,11.076097,329.99976,-0.018270688,9.1038914,11.075994,331.16113,-9.3055687
136.4,0.69631022,-0.27738351,57.26181,0,11.076097,329.99976,-0.018297585,9.0403366,11.076026,331.77005,-9.3053169
137.5,0.70543116,-0.27814454,56.574249,0,11.076097,329.99976,-0.018375384,9.1475201,11.076423,332.20349,-9.3056726
138.6,0.70399374,-0.27755758,55.846821,0,11.076097,329.99976,-0.018334724,9.1444912,11.076379,332.39453,-9.3053055
139.7,0.7030462,-0.2775569,55.239403,0,11.076097,329.99976,-0.01835156,9.1128998,11.075506,332.42276,-9.3056889
140.8,0.68221998,-0.2781502,54.730591,0,11.076097,329.99976,-0.018366566,8.8475723,11.075329,332.23611,-9.3054285
141.9,0.67429078,-0.27803478,54.38905,0,11.076097,329.99976,-0.018347852,8.7475309,11.075732,331.8429,-9.3056459
143.0,0.67432344,-0.27822864,54.305424,0,11.076097,329.99976,-0.018370317,8.755784,11.076108,331.39392,-9.3054476
144.1,0.66808432,-0.27744237,54.305424,0,11.076097,329.99976,-0.018347446,8.6607456,11.075737,330.83337,-9.3055172
145.2,0.67306185,-0.27771068,54.621994,0,11.076097,329.99976,-0.018355384,8.7182302,11.076641,330.28375,-9.3054581
146.3,0.66577595,-0.27806953,54.909328,0,11.076097,329.99976,-0.01834454,8.6357279,11.075859,329.80756,-9.3050127
147.4,0.66573781,-0.27881685,55.229237,0,11.076097,329.99976,-0.018413287,8.6363277,11.077103,329.37531,-9.3046913
148.5,0.68784583,-0.27736202,55.535881,0,11.076097,329.99976,-0.018309122,8.9115829,11.075965,329.09003,-9.3053436
149.6,0.69486851,-0.27813372,55.843506,0,11.076097,329.99976,-0.018400574,9.0091524,11.075842,328.96973,-9.305788
150.7,0.68036538,-0.27851161,56.129147,0,11.076097,329.99976,-0.018402439,8.8233995,11.076127,328.97897,-9.3056078
151.8,0.68965107,-0.27975902,56.425697,0,11.076097,329.99976,-0.018463522,8.9447956,11.076954,328.98703,-9.3055067
152.9,0.70206583,-0.27946851,56.425777,0,11.076097,329.99976,-0.018455846,9.1160507,11.076203,329.15094,-9.3056269
154.0,0.69209695,-0.28069735,56.560032,0,11.076097,329.99976,-0.018542811,8.9906912,11.076088,329.38217,-9.3052092
155.1,0.69419056,-0.020876426,56.67775,0,11.076097,329.99976,-0.0013941259,8.8545294,11.076035,329.53589,-9.3049841
155.2817,0.70281106,0.00035119004,55.859982,0,11.076099,1.5461428e-08,0.00030246112,9.0003147,11.078128,329.65778,-9.3058119
155.2839,0.70424426,0.0075893751,43.421432,0,11.076099,1.5442553e-23,0.00030304815,9.0589752,11.075639,329.64435,-9.3056517
155.2861,0.7383157,0.0022731968,30.982885,0,11.076099,1.5423705e-38,0.00031884413,9.4989691,11.07673,329.63092,-9.3061848
155.2883,0.69001353,0.0040827352,18.544336,0,11.076099,0.0,0.00013361895,8.8600321,11.078345,329.61746,-9.3061857
155.2905,0.68935835,7.8917321e-05,6.1057868,0,11.076099,0.0,0.00016879581,8.7335567,11.075782,329.60403,-9.3049288
155.2927,0.69134504,0.0057992041,0.0,0,11.076099,0.0,0.00022663473,8.8011818,11.074197,329.54614,-9.3042364
155.2949,0.69160432,-0.00080079702,0.0,0,11.076099,0.0,5.8980022e-05,8.7908506,11.07527,329.44537,-9.3049622
155.2971,0.69608414,0.0037106953,0.0,0,11.076099,0.0,0.00014846548,8.8016167,11.078681,329.34457,-9.3053455
155.2993,0.69426966,0.0011665201,0.0,0,11.076099,0.0,0.00014193753,8.8220119,11.073541,329.2438,-9.3046036
155.3015,0.69780982,0.0058570281,0.0,0,11.076099,0.0,0.00026697552,8.9003534,11.079419,329.14304,-9.3047371
155.3037,0.68172961,0.0010552092,0.0,0,11.076099,0.0,0.00017136804,8.7508354,11.075942,329.19257,-9.3055563
155.3059,0.67799056,0.0032359706,0.0,0,11.076099,0.0,0.00019810149,8.5818081,11.074577,329.24631,-9.3037701
155.3081,0.66397768,0.00055953738,0.0,0,11.076099,0.0,9.4912022e-05,8.5047178,11.077077,329.30005,-9.3049135
155.3103,0.66266793,0.0063532507,0.0,0,11.076099,0.0,0.00032506351,8.4160032,11.078606,329.35379,-9.3042412
155.3125,0.66191423,0.0031835723,0.0,0,11.076099,0.0,0.0001971387,8.3857822,11.079644,329.38995,-9.3056049
155.3147,0.67917842,0.0039627049,0.0,0,11.076099,0.0,0.00025437947,8.5890207,11.074946,329.40341,-9.3049974
155.3169,0.67387968,0.00025430426,0.0,0,11.076099,0.0,1.9255376e-05,8.5872831,11.074367,329.41684,-9.3046331
155.3191,0.68764043,0.0049171075,0.0,0,11.076099,0.0,0.00029602807,8.7802801,11.07327,329.4303,-9.3049812
155.3213,0.6712153,0.0016195556,0.0,0,11.076099,0.0,8.9832807e-05,8.695056,11.076603,329.44373,-9.3059607
155.3235,0.6664027,0.0022991889,0.0,0,11.076099,0.0,0.00020368394,8.559639,11.074592,329.45715,-9.3057861
155.3257,0.66681468,0.0011589265,0.0,0,11.076099,0.0,6.3961503e-05,8.4957666,11.075066,329.47058,-9.3050346
155.3279,0.66736209,0.0058869207,0.0,0,11.076099,0.0,0.00045581159,8.4923391,11.074348,329.48404,-9.3040276
155.3301,0.65462309,0.0044566155,0.0,0,11.076099,0.0,0.00017169885,8.4092932,11.07565,329.49747,-9.3036575
155.3323,0.65805316,0.00086716958,0.0,0,10.765893,0.0,0.00019629922,8.4002476,11.075358,329.50601,-9.3037281
155.3345,0.68017364,-0.00060950691,0.0,0,10.435,0.0,-0.00014398132,8.6352711,11.074748,329.50601,-9.306591
155.3367,0.70316398,0.0046682735,0.0,0,10.104109,0.0,0.0004226926,8.8838949,11.022345,329.50601,-9.3060942
155.3389,0.68793583,0.0042013731,0.0,0,9.7732153,0.0,0.00011023575,8.6318798,10.838885,329.50601,-9.306325
155.3411,0.70029259,0.00153683,0.0,0,9.4433994,0.0,0.00022077115,8.9083042,10.54796,329.50601,-9.3050451
155.3433,0.66202688,0.0014702592,0.0,0,9.1214905,0.0,-4.5520603e-05,8.5062323,10.179037,330.04507,-9.3062897
155.3455,7.9807649,0.29311422,0.0,0,8.7995863,0.0,0.019476527,99.243645,9.8316498,330.69666,-9.300704
155.3477,9.9949818,0.64001179,0.0,0,8.4910183,0.0,0.043279927,121.09178,9.4287949,331.34824,-9.2982817
155.3499,10.649278,1.0162458,0.0,0,8.1848669,0.0,0.070069149,126.27889,9.0198612,331.99985,-9.2966137
155.3521,11.025032,1.3815278,0.0,0,7.887249,0.0,0.095939972,127.53542,8.6614561,332.71185,-9.2966814
155.3543,11.632166,1.7030257,0.0,0,7.5959687,0.0,0.12033641,131.18985,8.3110094,333.57108,-9.2964106
155.3565,11.947868,2.0346622,0.0,0,7.3089814,0.0,0.14505351,131.62411,7.9654169,334.4303,-9.2967825
155.3587,12.293265,2.3476243,0.0,0,7.0319571,0.0,0.1700884,131.96469,7.6548443,335.28952,-9.2957888
155.3609,12.68739,2.6293533,0.0,0,6.7554355,0.0,0.19192553,133.34238,7.3550086,336.14874,-9.295413
155.3631,12.982787,2.9047425,0.0,0,6.491756,0.0,0.21517073,133.23756,7.0751472,337.69382,-9.2968254
155.3653,13.288286,3.1702418,0.0,0,6.2281961,0.0,0.23665461,133.41293,6.8029256,339.46198,-9.2961636
155.3675,13.627322,3.4177969,0.0,0,5.9743776,0.0,0.25859869,133.91408,6.539803,341.2301,-9.2962379
155.3697,13.90541,3.6741877,0.0,0,5.7237096,0.0,0.28021544,133.79755,6.2869864,342.99826,-9.2949915
155.3719,14.205849,3.9213316,0.0,0,5.4789281,0.0,0.30309156,133.54602,6.0330086,344.75897,-9.2955017
155.3741,14.49532,4.1716995,0.0,0,5.240448,0.0,0.32483307,133.32617,5.7826562,346.49316,-9.2956715
155.3763,14.792271,4.4078145,0.0,0,5.0044188,0.0,0.34793654,132.97418,5.5322957,348.22736,-9.2970076
155.3785,15.119274,4.6561513,0.0,0,4.7775989,0.0,0.37082595,132.81815,5.2892461,349.96152,-9.2972069
155.3807,15.480764,4.897141,0.0,0,4.5507789,0.0,0.39540559,132.63123,5.0422826,351.69571,-9.2963095
155.3829,15.81833,5.1419916,0.0,0,4.3343129,0.0,0.41869482,132.41782,4.8031635,352.44788,-9.2951097
155.3851,16.187086,5.3667831,0.0,0,4.1185365,0.0,0.44297659,132.34377,4.5714459,352.74182,-9.2947626
155.3873,16.55751,5.5997729,0.0,0,3.9097805,0.0,0.46644464,132.1584,4.3397169,353.03577,-9.2963839
155.3895,16.923012,5.8163848,0.0,0,3.7045646,0.0,0.49074885,131.8347,4.1173301,353.32971,-9.2968073
155.3917,17.311981,6.0375843,0.0,0,3.5032644,0.0,0.51382023,131.79488,3.8992136,353.68878,-9.2957773
155.3939,17.69978,6.2366719,0.0,0,3.3080363,0.0,0.53762901,131.6161,3.689491,354.43033,-9.2944317
155.3961,18.098991,6.4447594,0.0,0,3.1139457,0.0,0.56059188,131.48032,3.4862309,355.17188,-9.293416
155.3983,18.550798,6.639729,0.0,0,2.9282179,0.0,0.58483738,131.53645,3.2875268,355.91342,-9.2947569
155.4005,19.029482,6.844636,0.0,0,2.7424941,0.0,0.60809666,131.80849,3.0922236,356.65497,-9.2947254
155.4027,19.527374,7.0198989,0.0,0,2.5644433,0.0,0.6312964,132.18706,2.9040809,357.38431,-9.2961178
155.4049,20.03923,7.2093844,0.0,0,2.3877833,0.0,0.65417635,132.61314,2.7204447,358.1058,-9.2945681
155.4071,20.5958,7.386806,0.0,0,2.2160726,0.0,0.67844248,133.02029,2.5331833,358.8273,-9.2925463
155.4093,21.158848,7.5740275,0.0,0,2.0480366,0.0,0.70193535,133.46953,2.3539224,359.5488,-9.2935467
155.4115,21.745014,7.7428956,0.0,0,1.8824648,0.0,0.7261101,133.85992,2.1799076,360.23969,-9.2933168
155.4137,22.371542,7.9176364,0.0,0,1.7226127,0.0,0.74950898,134.54987,2.0086937,360.54031,-9.2928457
155.4159,23.037888,8.0792093,0.0,0,1.5630513,0.0,0.77367306,135.26518,1.8352764,360.84091,-9.2931099
155.4181,23.734732,8.2568035,0.0,0,1.4109179,0.0,0.79848248,135.9239,1.6699064,361.14154,-9.2927246
155.4203,24.471115,8.4033232,0.0,0,1.2588538,0.0,0.82154495,136.94165,1.5122644,361.44217,-9.2940121
155.4225,25.221703,8.5594912,0.0,0,1.1124091,0.0,0.84466565,137.92215,1.3558921,361.3092,-9.2940311
155.4247,26.004772,8.6987467,0.0,0,0.96778101,0.0,0.86724281,139.01825,1.207303,360.80148,-9.2931652
155.4269,26.806238,8.851265,0.0,0,0.82657415,0.0,0.89083558,140.0152,1.0601259,360.29376,-9.2909021
155.4291,27.651564,8.9814215,0.0,0,0.68903023,0.0,0.91314781,141.21384,0.92263651,359.78604,-9.2895622
155.4313,28.514982,9.1194334,0.0,0,0.55288297,0.0,0.93586063,142.31345,0.780743,359.27832,-9.2897434
155.4335,29.443233,9.2427778,0.0,0,0.42198288,0.0,0.95731288,143.84483,0.65011793,358.94427,-9.2900276
155.4357,29.213142,9.363513,0.0,0,0.29108286,0.0,0.97841305,140.49857,0.51999652,358.61026,-9.2903814
155.4379,27.369431,9.3626852,0.0,0,0.1662053,0.0,0.97892678,131.17471,0.46024826,358.27625,-9.2909203
155.4401,26.246588,9.3669615,0.0,0,0.041729283,0.0,0.97935104,125.5743,0.41613731,357.9422,-9.2927647
155.4423,25.57666,9.369339,0.0,0,-0.08069922,0.0,0.97968322,122.29604,0.37647986,357.97369,-9.2942953
155.4445,25.437746,9.3816881,0.0,0,-0.20209521,0.0,0.98194826,121.31923,0.33085325,358.42798,-9.2950449
155.4467,25.506433,9.3804607,0.0,0,-0.32349122,0.0,0.98166126,121.65265,0.27437082,358.88226,-9.2944546
155.4489,25.550699,9.3893795,0.0,0,-0.44488719,0.0,0.98367167,121.62051,0.21405166,359.33655,-9.2956629
155.4511,25.518133,9.3919687,0.0,0,-0.56628323,0.0,0.98349285,121.50381,0.15320303,359.79083,-9.2957344
155.4533,25.392937,9.4019127,0.0,0,-0.68767917,0.0,0.9860034,120.64738,0.10603096,360.06546,-9.2944489
155.4555,25.173315,9.4019213,0.0,0,-0.80907518,0.0,0.98535162,119.68115,0.062770493,360.32599,-9.296155
155.4577,24.885239,9.4084949,0.0,0,-0.93047118,0.0,0.98718113,118.10693,0.028845424,360.58652,-9.2972298
155.4599,24.509035,9.4088564,0.0,0,-1.0518672,0.0,0.98634458,116.43298,0.010304959,360.84705,-9.2970257
155.4621,24.030195,9.4133015,0.0,0,-0.88152617,330.0,0.98817962,113.94926,-0.0027960518,361.09714,-9.2954988
155.4643,23.518164,9.4131794,0.0,0,-0.46124667,330.0,0.98703873,111.64268,-0.0032809454,361.33096,-9.2956753
155.4665,23.022427,9.4140978,0.0,0,-0.040967815,330.0,0.98842019,109.15102,0.0042119147,361.56479,-9.2972536
155.4687,22.581999,9.4147825,0.0,0,0.37931129,330.0,0.98733747,107.16611,0.0087492242,361.79861,-9.2989178
155.4709,22.25153,9.4139252,0.0,0,0.79959083,330.0,0.98857623,105.47567,0.010646729,362.03244,-9.2987852
155.4731,21.965027,9.4156036,0.0,0,1.21987,330.0,0.9872371,104.27865,0.010667877,362.11212,-9.2989655
155.4753,21.244724,9.4161282,0.0,0,1.6401486,330.0,0.98902601,100.75399,0.024807639,362.16556,-9.2993231
155.4775,19.2477,9.4095955,0.0,0,2.0604286,330.0,0.98618335,91.658989,0.10074434,362.21899,-9.3003874
155.4797,15.674825,9.3971109,0.0,0,2.4807079,330.0,0.98590237,74.834526,0.25035331,362.27243,-9.3039303
155.4819,10.236116,9.3856401,0.0,0,2.9009867,330.0,0.9817028,49.684193,0.48187846,362.328,-9.3086901
155.4841,0.28132662,9.2353592,0.0,0,3.3212659,330.0,0.95798486,1.1659268,0.84202689,362.38812,-9.3187828
155.4863,0.010977402,9.1392508,0.0,0,3.741545,330.0,0.93904841,0.44732442,1.5047777,362.44824,-9.3172932
155.4885,-0.3309221,9.1013832,0.0,0,4.1618242,330.0,0.93448174,-1.7103215,2.2259474,362.50836,-9.3176384
155.4907,0.10889862,9.107338,0.0,0,4.5821037,330.0,0.93333083,0.35895529,2.9033153,362.56848,-9.3175812
155.4929,0.096354447,9.1660242,0.0,0,5.0023828,330.0,0.94504541,0.53912127,3.4511979,362.72263,-9.3150549
155.4951,-0.15941885,9.286869,0.0,0,5.4226618,330.0,0.96385324,-0.68246543,3.8692935,362.90302,-9.3138132
155.4973,4.2683887,9.4101906,0.0,0,5.8429418,330.0,0.98825592,19.462383,4.2501278,363.0834,-9.3120909
155.4995,0.36081618,9.3496847,0.0,0,6.2632203,330.0,0.97518623,1.6506807,4.642067,363.26376,-9.312891
155.5017,0.023429286,9.3325958,0.0,0,6.6834993,330.0,0.97428477,0.22414079,5.050797,363.45892,-9.3110523
155.5039,0.21645732,9.3728237,0.0,0,7.1037793,330.0,0.97937,0.75229561,5.4734135,363.6994,-9.3122673
155.5061,-0.055060927,9.359725,0.0,0,7.5240583,330.0,0.97948831,-0.098617308,5.8939128,363.93991,-9.3105593
155.5083,0.45050511,9.3769331,0.0,0,7.9443378,330.0,0.97977448,2.0769053,6.3300934,364.18042,-9.3095694
155.5105,0.32751641,9.3612232,0.0,0,8.3646164,330.0,0.97979277,1.537998,6.778203,364.42093,-9.3082705
155.5127,0.3909784,9.3755836,0.0,0,8.7848949,330.0,0.98000836,1.9313527,7.216579,364.633,-9.3080883
155.5149,0.34995043,9.3706112,0.0,0,9.2051744,330.0,0.98134291,1.6571739,7.6416087,364.8334,-9.3078632
155.5171,0.31878063,9.3800497,0.0,0,9.6254539,330.0,0.9802773,1.4759645,8.0730581,365.03381,-9.3071938
155.5193,0.32823414,9.3641014,0.0,0,10.045733,330.0,0.97985232,1.5864757,8.5091324,365.23422,-9.3074751
155.5215,0.39396167,9.3699703,0.0,0,10.466012,330.0,0.97920156,1.8563148,8.9491806,365.42542,-9.3054085
155.5237,0.39449954,9.367034,0.0,0,10.886292,330.0,0.98047,1.9150007,9.3803034,365.57236,-9.3053627
155.5259,0.31314194,9.3807907,0.0,0,11.30657,330.0,0.9805519,1.511982,9.8157682,365.7193,-9.3064079
155.5281,0.34056741,9.368,0.0,0,11.72685,330.0,0.98056537,1.6710242,10.247003,365.86624,-9.3047705
155.5303,0.37763152,9.3735456,0.0,0,12.147129,330.0,0.97988009,1.8051976,10.685314,366.01318,-9.3036327
155.5325,0.37583286,9.3656435,0.0,0,12.567409,330.0,0.98028189,1.8065174,11.106509,366.14304,-9.3055477
155.5347,0.36812776,9.3778143,0.0,0,12.987687,330.0,0.98024452,1.7508013,11.515627,366.26312,-9.3050613
155.5369,0.29741016,9.3692131,0.0,0,13.407967,330.0,0.98054433,1.4485909,11.939933,366.38321,-9.3039703
155.5391,0.36918834,9.3763323,0.0,0,13.828245,330.0,0.98044771,1.7781794,12.369725,366.50333,-9.3033552
155.5413,0.39223239,9.3671713,0.0,0,14.248526,330.0,0.9799971,1.8238661,12.801937,366.61673,-9.3024254
155.5435,0.39541224,9.3776178,0.0,0,14.668804,330.0,0.9805395,1.9740033,13.233866,366.67004,-9.3043928
155.5457,0.30783853,9.3682003,0.0,0,15.089084,330.0,0.98022139,1.4928591,13.673822,366.72336,-9.3035412
155.5479,0.34272158,9.3729563,0.0,0,15.509363,330.0,0.98006886,1.6221411,14.116822,366.77667,-9.3026695
155.5501,0.38452613,9.3662519,0.0,0,15.929642,330.0,0.9796502,1.835768,14.564301,366.82999,-9.303546
155.5523,0.43139079,9.3770237,0.0,0,16.34992,330.0,0.98069447,2.0397396,14.986593,366.87576,-9.3035164
155.5545,0.36721361,9.3695812,0.0,0,16.770201,330.0,0.98020101,1.7477844,15.393364,366.91577,-9.3029032
155.5567,0.29515785,9.3747911,0.0,0,17.190479,330.0,0.98070687,1.4388746,15.80352,366.95575,-9.3027973
155.5589,0.38970122,9.3681374,0.0,0,17.61076,330.0,0.97982776,1.8230861,16.220114,366.99573,-9.3019085
155.5611,0.38928413,9.3755941,0.0,0,17.999401,330.0,0.98079324,1.8601983,16.637894,367.03699,-9.3031368
155.5633,0.38378543,9.3702049,0.0,0,18.0,330.0,0.98014832,1.8458431,17.061535,367.1236,-9.3029509
155.5655,0.37125853,9.3735428,0.0,0,18.0,330.0,0.98062104,1.7807857,17.461088,367.21024,-9.3022795
155.5677,0.38789424,9.3701344,0.0,0,18.0,330.0,0.98000365,1.8325458,17.821627,367.29688,-9.3032188
155.5699,0.37977195,9.3796644,0.0,0,18.0,330.0,0.98157173,1.7800529,18.132103,367.38351,-9.3041162
155.5721,0.43695396,9.3719263,0.0,0,18.0,330.0,0.98014301,2.0725133,18.360771,367.4538,-9.3063183
155.5743,0.45665303,9.3727665,0.0,0,18.0,330.0,0.98074037,2.1514273,18.489172,367.50711,-9.3100185
155.5765,0.44398686,9.3692865,0.0,0,18.0,330.0,0.97955209,2.1326201,18.515869,367.56042,-9.3159742
155.5787,0.42544216,9.3762016,0.0,0,18.0,330.0,0.98147053,2.0782528,18.438272,367.61374,-9.3246737
155.5809,0.48625186,9.3742933,0.0,0,18.0,330.0,0.98005539,2.3139348,18.317783,367.66708,-9.3330736
155.5831,0.48405308,9.3723078,0.0,0,18.0,330.0,0.98092473,2.3266616,18.196177,367.68857,-9.3453293
155.5853,0.42259479,9.3708992,0.0,0,18.0,330.0,0.97956681,2.0304196,18.096048,367.70859,-9.3592081
155.5875,0.40364748,9.3734722,0.0,0,18.0,330.0,0.9812969,1.9410039,18.045891,367.72858,-9.3755903
155.5897,0.4200502,9.372509,0.0,0,18.0,330.0,0.97966665,1.9588317,18.034369,367.74857,-9.3918152
155.5919,0.41212898,9.3677769,0.0,0,18.0,330.0,0.98028022,1.9539135,18.039623,367.76578,-9.4107523
155.5941,0.43015796,9.368681,0.0,0,18.0,330.0,0.97894871,2.0681565,18.056131,367.77908,-9.4270992
155.5963,0.44566911,9.3652172,0.0,0,18.0,330.0,0.97996169,2.1442413,18.082159,367.79242,-9.4453077
155.5985,0.47541618,9.3685856,0.0,0,18.0,330.0,0.97875607,2.2728393,18.106369,367.80576,-9.4614162
155.6007,0.4830257,9.3659763,0.0,0,18.0,330.0,0.98012501,2.2978425,18.123091,367.81906,-9.4790144
155.6029,0.44261193,9.367054,0.0,0,18.0,330.0,0.97865045,2.0839624,18.139311,367.85004,-9.4961815
155.6051,0.42141053,9.3680964,0.0,0,18.0,330.0,0.98063546,2.0330558,18.145506,367.88336,-9.5124884
155.6073,0.40337631,9.3707113,0.0,0,18.0,330.0,0.97909045,1.9249481,18.142912,367.91669,-9.5271645
155.6095,0.4221217,9.3633909,0.0,0,18.0,330.0,0.97974586,1.998673,18.143539,367.94998,-9.543663
155.6117,0.43566638,9.3658886,0.0,0,18.0,330.0,0.97811955,2.0531061,18.144367,367.98331,-9.5580921
155.6139,0.47071052,9.3657427,0.0,0,18.0,330.0,0.98015171,2.2273319,18.140461,368.01663,-9.5735922
155.6161,0.49190915,9.3722916,0.0,0,18.0,330.0,0.97918242,2.3002727,18.13586,368.04996,-9.5898218
155.6183,0.49526703,9.3627214,0.0,0,18.0,330.0,0.97984731,2.3543396,18.128649,368.08328,-9.6054583
155.6205,0.48199877,9.3685675,0.0,0,18.0,330.0,0.97875816,2.3330054,18.130716,368.11661,-9.6203403
155.6227,0.45388806,9.3662167,0.0,0,18.0,330.0,0.98046941,2.1988347,18.1264,368.13913,-9.6351604
155.6249,0.43286437,9.3734074,0.0,0,18.0,330.0,0.97913623,2.0897582,18.126707,368.15912,-9.651372
155.6271,0.42929924,9.3630934,0.0,0,18.0,330.0,0.97985131,2.0355988,18.12393,368.17911,-9.6679373
155.6293,0.42763942,9.3704367,0.0,0,18.0,330.0,0.97909504,2.0483625,18.12365,368.19913,-9.684309
155.6315,0.47401261,9.3671608,0.0,0,18.0,330.0,0.98064506,2.2027028,18.1108,368.21548,-9.698863
155.6337,0.49477491,9.3751287,0.0,0,18.0,330.0,0.97948587,2.3392465,18.114862,368.22214,-9.7160635
155.6359,0.50736016,9.36236,0.0,0,18.0,330.0,0.97965145,2.3913419,18.111425,368.22882,-9.7320843
155.6381,0.49738961,9.3691387,0.0,0,18.0,330.0,0.97883213,2.3995514,18.111509,368.23547,-9.7499485
155.6403,0.46748909,9.3663683,0.0,0,18.0,330.0,0.98045933,2.2513771,18.109884,368.24213,-9.7645884
155.6425,0.42924261,9.3766146,0.0,0,18.0,330.0,0.97971964,2.0833526,18.106182,368.23407,-9.7808428
155.6447,0.42355195,9.3629866,0.0,0,18.0,330.0,0.97971529,2.0559285,18.112982,368.22076,-9.7960901
155.6469,0.43462688,9.3696089,0.0,0,18.0,330.0,0.97918028,2.0877681,18.108011,368.20743,-9.8132
155.6491,0.45210314,9.3659306,0.0,0,18.0,330.0,0.98035651,2.122273,18.104942,368.19409,-9.8292198
155.6513,0.47057688,9.373641,0.0,0,18.0,330.0,0.97956419,2.2186491,18.109766,368.17679,-9.844223
155.6535,0.50810343,9.363451,0.0,0,18.0,330.0,0.97957444,2.3952308,18.105127,368.14346,-9.8599186
155.6557,0.50501746,9.3709555,0.0,0,18.0,330.0,0.97927493,2.4449079,18.105669,368.11014,-9.8757696
155.6579,0.47955614,9.366642,0.0,0,18.0,330.0,0.98024774,2.334244,18.100971,368.07681,-9.8927689
155.6601,0.43174744,9.374898,0.0,0,18.0,330.0,0.98003602,2.1164861,18.104813,368.04349,-9.9083624
155.6623,0.41264322,9.3653135,0.0,0,18.0,330.0,0.97982836,2.0051174,18.106461,368.00574,-9.9243441
155.6645,0.43790638,9.3698606,0.0,0,18.0,330.0,0.97936785,2.0590732,18.105656,367.96576,-9.9382305
155.6667,0.45314309,9.3624849,0.0,0,18.0,330.0,0.97916687,2.1137998,18.102299,367.92578,-9.9549932
155.6689,0.4543978,9.3714314,0.0,0,18.0,330.0,0.97945619,2.1772995,18.104486,367.88577,-9.9707012
155.6711,0.48180458,9.3650255,0.0,0,18.0,330.0,0.97947466,2.3003967,18.103672,367.85089,-9.9865274
155.6733,0.51411128,9.3690596,0.0,0,18.0,330.0,0.97924101,2.4281011,18.101654,367.85089,-10.004187
155.6755,0.48032373,9.3632956,0.0,0,18.0,330.0,0.97901249,2.2997468,18.098267,367.85089,-10.019904
155.6777,0.44616461,9.3723898,0.0,0,18.0,330.0,0.97987515,2.1785643,18.09647,367.85089,-10.034418
155.6799,0.426296,9.363863,0.0,0,18.0,330.0,0.97923738,2.0527685,18.098019,367.85089,-10.051548
155.6821,0.41721177,9.3695993,0.0,0,18.0,330.0,0.97962695,1.9950085,18.094751,367.84302,-10.066925
155.6843,0.43164682,9.3623362,0.0,0,18.0,330.0,0.97886223,2.0757377,18.095013,367.82968,-10.083594
155.6865,0.4724648,9.3723507,0.0,0,18.0,330.0,0.98017877,2.2181129,18.097116,367.81635,-10.100328
155.6887,0.48170954,9.3646955,0.0,0,18.0,330.0,0.97910428,2.2744577,18.09123,367.80301,-10.116341
155.6909,0.50559586,9.3668051,0.0,0,18.0,330.0,0.97960013,2.4158416,18.092251,367.78967,-10.131567
155.6931,0.51225692,9.3625965,0.0,0,18.0,330.0,0.97849232,2.4292178,18.0903,367.77637,-10.147787
155.6953,0.48503789,9.3722801,0.0,0,18.0,330.0,0.98043352,2.3447239,18.093489,367.76303,-10.163585
155.6975,0.45340297,9.3695164,0.0,0,18.0,330.0,0.97967196,2.2271287,18.089399,367.74973,-10.179572
155.6997,0.44046214,9.3689499,0.0,0,18.0,330.0,0.98009974,2.1038392,18.088631,367.73639,-10.194923
155.7019,0.43977529,9.363492,0.0,0,18.0,330.0,0.97857147,2.1249363,18.08942,367.72653,-10.211403
155.7041,0.45950067,9.370574,0.0,0,18.0,330.0,0.98043889,2.2165215,18.091236,367.71985,-10.226951
155.7063,0.49521747,9.3667927,0.0,0,18.0,330.0,0.9788776,2.3614643,18.085777,367.71317,-10.24237
155.7085,0.52531922,9.3674021,0.0,0,18.0,330.0,0.97992837,2.4822612,18.085117,367.70651,-10.257326
155.7107,0.52872831,9.3662491,0.0,0,18.0,330.0,0.97873479,2.5449953,18.08086,367.69983,-10.273891
155.7129,0.52866435,9.3717613,0.0,0,18.0,330.0,0.98091102,2.5377243,18.082937,367.68008,-10.291887
155.7151,0.46056849,9.3688202,0.0,0,18.0,330.0,0.97892404,2.2679009,18.084354,367.6601,-10.308696
155.7173,0.44881395,9.3673248,0.0,0,18.0,330.0,0.98005801,2.1505108,18.084673,367.64008,-10.323719
155.7195,0.43460831,9.3658066,0.0,0,18.0,330.0,0.97844905,2.0845456,18.078506,367.62009,-10.34029
155.7217,0.45759085,9.3659945,0.0,0,18.0,330.0,0.98026115,2.1882834,18.082535,367.59418,-10.357191
155.7239,0.48545775,9.369278,0.0,0,18.0,330.0,0.97885227,2.2795668,18.077429,367.56085,-10.373204
155.7261,0.52438569,9.364253,0.0,0,18.0,330.0,0.97973388,2.4650028,18.078247,367.52753,-10.389766
155.7283,0.52898735,9.3662462,0.0,0,18.0,330.0,0.97836185,2.5356247,18.081991,367.49423,-10.403994
155.7305,0.53070891,9.3670988,0.0,0,18.0,330.0,0.98053777,2.5113173,18.077944,367.46091,-10.419633
155.7327,0.49196348,9.3710289,0.0,0,18.0,330.0,0.97900796,2.3816118,18.074966,367.41547,-10.435458
155.7349,0.45388582,9.3653631,0.0,0,18.0,330.0,0.98011816,2.1959119,18.078011,367.3688,-10.453235
155.7371,0.42925969,9.3689919,0.0,0,18.0,330.0,0.97879636,2.0633585,18.074127,367.32217,-10.468593
155.7393,0.44116575,9.3632421,0.0,0,18.0,330.0,0.97985411,2.0793509,18.074627,367.27551,-10.48337
155.7415,0.45968017,9.3688507,0.0,0,18.0,330.0,0.9785862,2.1720169,18.078365,367.23135,-10.498629
155.7437,0.49913654,9.363657,0.0,0,18.0,330.0,0.97993267,2.3371873,18.077131,367.19135,-10.51323
155.7459,0.52428794,9.3683586,0.0,0,18.0,330.0,0.97866255,2.5119488,18.072458,367.15137,-10.530576
155.7481,0.52479869,9.3652449,0.0,0,18.0,330.0,0.98033565,2.5150018,18.074278,367.11139,-10.546788
155.7503,0.50380021,9.3728113,0.0,0,18.0,330.0,0.97913301,2.4198625,18.073971,367.07138,-10.563379
155.7525,0.47901082,9.3621988,0.0,0,18.0,330.0,0.9796592,2.2732148,18.073109,367.0314,-10.579115
155.7547,0.44247699,9.3662615,0.0,0,18.0,330.0,0.97844517,2.0958695,18.071123,366.99142,-10.594254
155.7569,0.43462542,9.364172,0.0,0,18.0,330.0,0.98016018,2.0919662,18.069685,366.95142,-10.610529
155.7591,0.44887888,9.3728619,0.0,0,18.0,330.0,0.97892606,2.1551695,18.068119,366.91144,-10.627604
155.7613,0.47678387,9.3603477,0.0,0,18.0,330.0,0.97942466,2.2494857,18.071934,366.88144,-10.642879
155.7635,0.51544112,9.3691521,0.0,0,18.0,330.0,0.97889674,2.4232707,18.073921,366.87479,-10.658534
155.7657,0.53800803,9.3631992,0.0,0,18.0,330.0,0.97987723,2.5722008,18.067326,366.86813,-10.67423
155.7679,0.52787536,9.3727274,0.0,0,18.0,330.0,0.97906804,2.56916,18.068686,366.86145,-10.691059
155.7701,0.48589939,9.3633003,0.0,0,18.0,330.0,0.97956961,2.3575356,18.069954,366.8548,-10.708848
155.7723,0.47482368,9.3671446,0.0,0,18.0,330.0,0.97870642,2.2580645,18.067398,366.83795,-10.723737
155.7745,0.44356096,9.3612232,0.0,0,18.0,330.0,0.97950089,2.1188488,18.066793,366.81796,-10.739361
155.7767,0.44895616,9.3723583,0.0,0,18.0,330.0,0.97914159,2.1157818,18.063875,366.79797,-10.75573
155.7789,0.47480312,9.3615332,0.0,0,18.0,330.0,0.97926855,2.2573419,18.063515,366.77798,-10.771028
155.7811,0.52200359,9.3676968,0.0,0,18.0,330.0,0.97895455,2.4667945,18.065426,366.7514,-10.786595
155.7833,0.54022014,9.3617468,0.0,0,18.0,330.0,0.97929335,2.5627263,18.06498,366.70239,-10.802539
155.7855,0.54717869,9.3734331,0.0,0,18.0,330.0,0.97961217,2.6391268,18.066816,366.65338,-10.817506
155.7877,0.52152288,9.3629227,0.0,0,18.0,330.0,0.97940165,2.5345731,18.060963,366.60437,-10.833777
155.7899,0.49277174,9.3704672,0.0,0,18.0,330.0,0.97938997,2.395673,18.057137,366.55536,-10.84816
155.7921,0.46757695,9.363019,0.0,0,18.0,330.0,0.97920579,2.2559891,18.060139,366.52667,-10.864577
155.7943,0.45595846,9.3732271,0.0,0,18.0,330.0,0.9797287,2.1827207,18.064783,366.50003,-10.882428
155.7965,0.46631053,9.3630848,0.0,0,18.0,330.0,0.97912437,2.1963108,18.058641,366.47336,-10.896821
155.7987,0.51033634,9.3669186,0.0,0,18.0,330.0,0.97910219,2.3908448,18.059906,366.44672,-10.914495
155.8009,0.53904217,9.3605871,0.0,0,18.0,330.0,0.97853148,2.5523255,18.058748,366.42004,-10.929564
155.8031,0.545394,9.3705435,0.0,0,18.0,330.0,0.97959149,2.6011677,18.06333,366.3934,-10.945955
155.8053,0.53727424,9.3611593,0.0,0,18.0,330.0,0.97865033,2.6024609,18.057627,366.36676,-10.96276
155.8075,0.49641928,9.3673592,0.0,0,18.0,330.0,0.97939944,2.4052744,18.057529,366.34009,-10.978548
155.8097,0.46772042,9.3650112,0.0,0,18.0,330.0,0.97923332,2.2636743,18.056528,366.31345,-10.995839
155.8119,0.46478704,9.3744392,0.0,0,18.0,330.0,0.98059899,2.2045238,18.057512,366.27557,-11.012458
155.8141,0.45880002,9.3635569,0.0,0,18.0,330.0,0.9787609,2.1986406,18.055193,366.23553,-11.026662
155.8163,0.48382604,9.3643742,0.0,0,18.0,330.0,0.97916663,2.2838843,18.056078,366.19547,-11.042048
155.8185,0.51875108,9.3633232,0.0,0,18.0,330.0,0.978607,2.4662671,18.057899,366.15543,-11.059024
155.8207,0.55040008,9.3692875,0.0,0,18.0,330.0,0.97996473,2.6065793,18.056524,366.11136,-11.074798
155.8229,0.53661281,9.3637753,0.0,0,18.0,330.0,0.9785291,2.5820141,18.052322,366.05789,-11.090787
155.8251,0.52522182,9.366231,0.0,0,18.0,330.0,0.97946441,2.5355263,18.05582,366.00446,-11.105792
155.8273,0.47911283,9.3644142,0.0,0,18.0,330.0,0.97866911,2.3205321,18.05533,365.95102,-11.121845
155.8295,0.45986325,9.3697939,0.0,0,18.0,330.0,0.98027217,2.2032075,18.054285,365.89758,-11.137951
155.8317,0.4487049,9.3661814,0.0,0,18.0,330.0,0.97868186,2.1589155,18.053623,365.86453,-11.153037
155.8339,0.47241497,9.3635235,0.0,0,18.0,330.0,0.97933394,2.2594113,18.053968,365.8378,-11.16973
155.8361,0.50832933,9.3629484,0.0,0,18.0,330.0,0.9781037,2.3964398,18.055054,365.8111,-11.185562
155.8383,0.5377934,9.36693,0.0,0,18.0,330.0,0.97999525,2.5600228,18.054296,365.78436,-11.202684
155.8405,0.55971122,9.3669367,0.0,0,18.0,330.0,0.97861362,2.6851134,18.055258,365.76523,-11.218225
155.8427,0.53597122,9.3633108,0.0,0,18.0,330.0,0.9794392,2.5752723,18.057276,365.77191,-11.233913
155.8449,0.51465362,9.3643169,0.0,0,18.0,330.0,0.97795421,2.4839475,18.054689,365.77859,-11.249185
155.8471,0.47997773,9.3661003,0.0,0,18.0,330.0,0.98026675,2.3030632,18.049973,365.78525,-11.264385
155.8493,0.46351132,9.3687143,0.0,0,18.0,330.0,0.9788996,2.2337737,18.050186,365.79193,-11.281178
155.8515,0.47044924,9.3622751,0.0,0,18.0,330.0,0.97953004,2.2653682,18.051237,365.78479,-11.297156
155.8537,0.50615615,9.3655434,0.0,0,18.0,330.0,0.97821403,2.3689463,18.05302,365.77142,-11.312234
155.8559,0.54328585,9.3639612,0.0,0,18.0,330.0,0.97991347,2.567323,18.049095,365.75806,-11.329611
155.8581,0.5694586,9.3685732,0.0,0,18.0,330.0,0.97879386,2.7191391,18.047203,365.74469,-11.344622
155.8603,0.56053275,9.3633356,0.0,0,18.0,330.0,0.97976625,2.6554854,18.046982,365.72409,-11.362763
156.6608,0.4612762,9.3710613,0.0,0,18.0,4.121353e-09,0.98016995,2.2019832,18.004379,345.33411,-11.481434
157.7608,0.43030679,9.3781538,0.0,0,18.0,4.1163093e-24,0.98140484,2.0557921,18.000671,330.03958,-11.481351
158.8608,0.40938517,9.383091,0.0,0,18.0,4.1112724e-39,0.98229539,1.9485557,18.000931,318.71262,-11.481096
159.9608,0.40367597,9.3886433,0.0,0,18.0,1.4012985e-45,0.98321342,1.9225125,17.999895,308.76718,-11.481353
161.0608,0.39898303,9.3937635,0.0,0,18.0,1.4012985e-45,0.98413992,1.8999053,18.000547,299.70767,-11.481729
162.1608,0.38310248,9.3980017,0.0,0,18.0,1.4012985e-45,0.98501861,1.8229363,17.999924,291.32281,-11.48205
163.2608,0.38079038,9.4025755,0.0,0,18.0,1.4012985e-45,0.98574644,1.8041003,17.999098,283.23355,-11.481266
164.3608,0.37956738,9.4070673,0.0,0,18.0,1.4012985e-45,0.98657531,1.8063536,18.000315,275.78497,-11.481383
165.4608,0.37590358,9.4112606,0.0,0,18.0,1.4012985e-45,0.98721111,1.7894262,18.000566,268.42731,-11.481214
166.5608,0.37648073,9.4153891,0.0,0,18.0,1.4012985e-45,0.98808658,1.7797908,17.99896,261.58652,-11.481049
167.6608,0.39152408,9.4186792,0.0,0,18.0,1.4012985e-45,0.98864406,1.8587849,17.999014,254.7157,-11.481731
168.7608,0.38603953,9.4229231,0.0,0,18.0,1.4012985e-45,0.98943645,1.8322456,17.999605,248.26587,-11.48199
169.8608,0.37900689,9.4260111,0.0,0,18.0,1.4012985e-45,0.98988104,1.7877681,18.000151,242.00551,-11.481874
170.9608,0.38056284,9.4299288,0.0,0,18.0,1.4012985e-45,0.9906621,1.797644,18.000254,235.7789,-11.482142
172.0608,0.37795359,9.4330406,0.0,0,18.0,1.4012985e-45,0.99123937,1.7886224,18.000679,229.79758,-11.482283
173.1608,0.37440711,9.4359016,0.0,0,18.0,1.4012985e-45,0.99173522,1.7754514,18.000029,223.98206,-11.482134
174.2608,0.38069689,9.4396143,0.0,0,18.0,1.4012985e-45,0.99238455,1.7922381,18.000065,218.35399,-11.481619
175.3608,0.37993383,9.4431744,0.0,0,18.0,1.4012985e-45,0.99297416,1.7953154,17.999403,212.9146,-11.481708
176.4608,0.36597902,9.4460831,0.0,0,18.0,1.4012985e-45,0.99361378,1.7286142,18.00036,207.64554,-11.481581
177.5608,0.37888968,9.4490633,0.0,0,18.0,1.4012985e-45,0.99407339,1.7811121,18.000818,202.40154,-11.481641
178.6608,0.38409236,9.4522362,0.0,0,18.0,1.4012985e-45,0.99468118,1.8089963,18.000139,197.47169,-11.481875
179.7608,0.36511782,9.4554939,0.0,0,18.0,1.4012985e-45,0.99515939,1.7250484,17.999943,192.70229,-11.481613
180.8608,0.37258348,9.4584942,0.0,0,18.0,1.4012985e-45,0.99582905,1.7510195,18.000523,188.06145,-11.482071
181.9608,0.38538361,9.4614429,0.0,0,18.0,1.4012985e-45,0.99631971,1.8074611,18.00012,183.53302,-11.482115
183.0608,0.37231615,9.4637671,0.0,0,18.0,1.4012985e-45,0.99678797,1.7544186,18.000429,179.07652,-11.482366
184.1608,0.37576422,9.4667292,0.0,0,18.0,1.4012985e-45,0.99719834,1.7654021,17.999601,174.75652,-11.482087
185.2608,0.37502977,9.4691257,0.0,0,18.0,1.4012985e-45,0.99773389,1.7571759,18.000647,170.59354,-11.481946
186.3608,0.37259403,9.4712667,0.0,0,18.0,1.4012985e-45,0.99811786,1.7550519,17.998865,166.56833,-11.481982
187.4608,0.36378834,9.4744711,0.0,0,18.0,1.4012985e-45,0.99870449,1.7054503,17.999638,162.70251,-11.481797
188.5608,0.37169123,9.4765158,0.0,0,18.0,1.4012985e-45,0.99901223,1.7369447,18.001125,158.83841,-11.481531
189.6608,0.37663636,9.4791641,0.0,0,18.0,1.4012985e-45,0.99950421,1.7680693,18.00119,155.22163,-11.48108
190.7608,0.36572438,9.4811163,0.0,0,18.0,1.4012985e-45,0.99993408,1.7148104,17.999714,151.64395,-11.481395
191.8608,0.36542597,9.48384,0.0,0,18.0,1.4012985e-45,1.0003726,1.7056557,18.000498,148.11989,-11.481317
192.9608,0.36982921,9.4861765,0.0,0,18.0,1.4012985e-45,1.000765,1.7280034,18.000332,144.67474,-11.481431
194.0608,0.37368482,9.4880629,0.0,0,18.0,1.4012985e-45,1.0010777,1.7533787,18.000004,141.44356,-11.482163
195.1608,0.37077403,9.4899969,0.0,0,18.0,1.4012985e-45,1.0015646,1.733875,17.99987,138.12735,-11.482027
196.2608,0.38159558,9.4921827,0.0,0,18.0,1.4012985e-45,1.0018724,1.7826704,18.000296,134.99081,-11.481817
197.3608,0.37737814,9.4947395,0.0,0,18.0,1.4012985e-45,1.0023617,1.7637173,18.000229,132.01479,-11.482057
198.4608,0.36915931,9.4966831,0.0,0,18.0,1.4012985e-45,1.0026419,1.724466,17.999847,128.91261,-11.482034
199.5608,0.37633756,9.4985361,0.0,0,18.0,1.4012985e-45,1.0031176,1.7525922,17.999651,126.12263,-11.48214
200.6608,0.37174779,9.5004902,0.0,0,18.0,1.4012985e-45,1.0033578,1.7378317,18.000271,123.23919,-11.482295
201.7608,0.3572807,9.5028477,0.0,0,18.0,1.4012985e-45,1.0038731,1.6659435,17.99991,120.58712,-11.481938
202.8608,0.37069887,9.5045919,0.0,0,18.0,1.4012985e-45,1.0040596,1.7281437,18.000154,117.81236,-11.482088
203.9608,0.36347973,9.5062962,0.0,0,18.0,1.4012985e-45,1.0045021,1.6926755,18.000048,115.39305,-11.48123
205.0608,0.36555222,9.5079269,0.0,0,18.0,1.4012985e-45,1.0047467,1.711412,17.999847,112.86597,-11.481608
206.1608,0.36337066,9.5095634,0.0,0,18.0,1.4012985e-45,1.0051073,1.6903622,18.000051,110.41821,-11.481661
207.2608,0.36069459,9.5115137,0.0,0,18.0,1.4012985e-45,1.0053208,1.6777263,17.99971,108.00887,-11.481546
208.3608,0.36179715,9.5132504,0.0,0,18.0,1.4012985e-45,1.005774,1.6883394,18.000162,105.80609,-11.481741
209.4608,0.36091816,9.5145521,0.0,0,18.0,1.4012985e-45,1.0059489,1.6848691,17.999706,103.53625,-11.481507
210.5608,0.36213753,9.5164995,0.0,0,18.0,1.4012985e-45,1.0063664,1.6821512,18.000734,101.35094,-11.481158
211.6608,0.36239794,9.518034,0.0,0,18.0,1.4012985e-45,1.0064971,1.6897604,17.99996,99.419609,-11.481731
212.7608,0.36817026,9.5196123,0.0,0,18.0,1.4012985e-45,1.0069219,1.7174572,17.999632,97.323837,-11.481733
213.8608,0.37253287,9.5208836,0.0,0,18.0,1.4012985e-45,1.0071218,1.7318399,17.999662,95.334297,-11.481903
214.9608,0.37699488,9.5221424,0.0,0,18.0,1.4012985e-45,1.0073781,1.7532607,18.00004,93.459503,-11.482139
215.8608,0.36869165,9.5236034,0.0,0,18.0,1.4012985e-45,1.0076357,1.7082485,18.000532,91.894295,-11.48197