File: examples/dan-msc-case-studies/CS3/data/01 raw data/baron_test_113.csv
Time(sec),Force(kN),Jaw(mm),PowAngle(deg),Power(W),Pram,PTemp,Strain,Stress(MPa),Stroke(mm),TC1(C),wedge(mm)
0.0,0.96756512,0.36023116,0.0,0,11.076097,0.0016198091,0.024312176,12.012052,11.076124,23.192907,-9.1032085
1.1,0.91312331,0.0024405383,0.0,0,11.076097,3.2158811,0.00015975857,11.624693,11.07647,23.14242,-9.4707737
2.2,0.8902691,0.0025191535,0.0,0,11.076097,6.5158801,0.00017746497,11.342573,11.076773,23.249207,-9.4685669
3.3,0.87272209,0.0024713113,0.0,0,11.076097,9.8158817,0.0001613284,11.11213,11.076405,23.182697,-9.4680939
4.4,0.8524856,0.0021764024,0.0,0,11.076097,13.11588,0.00011851365,10.860377,11.075937,23.144249,-9.4663134
5.5,0.83684111,0.0019388894,0.0,0,11.076097,16.415884,0.00010241841,10.656799,11.076041,23.166378,-9.4643335
6.6,0.81607461,0.0019624862,0.0,0,11.076097,19.715883,0.00014021729,10.395795,11.076064,23.119019,-9.4624014
7.7,0.81330091,0.0017732544,0.0,0,11.076097,23.015882,0.00014027649,10.352069,11.076174,23.202438,-9.4606686
8.8,0.80942804,0.0020795912,18.111217,0,11.076097,26.315886,0.00013640357,10.303727,11.076168,23.171688,-9.4587421
9.9,0.80281246,0.0018072521,31.820215,0,11.076097,29.615883,0.00012661227,10.220244,11.077411,23.505251,-9.4577055
11.0,0.82927525,0.00011203471,39.883205,0,11.076097,32.915878,1.7874512e-05,10.554168,11.075866,24.933191,-9.4561329
12.1,0.83704996,-0.0026212514,44.919724,0,11.076097,36.215878,-0.00019551415,10.648338,11.076161,27.632816,-9.4546871
13.2,0.84452909,-0.0062760026,47.632156,0,11.076097,39.515873,-0.0004389926,10.760345,11.076775,31.509832,-9.4531403
14.3,0.85694832,-0.010127968,49.345642,0,11.076097,42.815876,-0.00067571946,10.923157,11.076342,36.063251,-9.4516048
15.4,0.86603576,-0.013876131,50.042721,0,11.076097,46.115879,-0.00090293592,11.024146,11.076989,41.13625,-9.4498844
16.5,0.86951607,-0.016947946,49.636345,0,11.076097,49.415878,-0.0011082861,11.087993,11.076406,46.504028,-9.4477863
17.6,0.88657421,-0.020163285,48.819607,0,11.076097,52.715878,-0.0013496678,11.313977,11.077028,51.586136,-9.4463882
18.7,0.88669848,-0.022906335,47.955334,0,11.076097,56.015888,-0.0015067609,11.302847,11.076379,56.297459,-9.4444685
19.8,0.88937211,-0.025375012,46.58279,0,11.076097,59.315891,-0.0017007283,11.33993,11.077038,60.591518,-9.4430294
20.9,0.89023942,-0.027578091,45.318562,0,11.076097,62.615891,-0.0018642118,11.333917,11.07581,64.482475,-9.4411812
22.0,0.89185226,-0.029846115,44.604507,0,11.076097,65.915878,-0.0020054474,11.378723,11.076476,67.729439,-9.4396753
23.1,0.88852799,-0.032014471,44.077175,0,11.076097,69.215889,-0.0021178992,11.339522,11.077742,70.707748,-9.4377708
24.2,0.8886407,-0.033960786,44.336292,0,11.076097,72.515869,-0.0022424762,11.335373,11.076519,73.365067,-9.4363832
25.3,0.88659698,-0.035729587,44.973747,0,11.076097,75.815887,-0.0023835213,11.313243,11.075619,75.946785,-9.434556
26.4,0.8948251,-0.03754548,45.615231,0,11.076097,79.115891,-0.0024890669,11.418538,11.076016,78.478302,-9.4333458
27.5,0.89671546,-0.039822586,46.582027,0,11.076097,82.415878,-0.0026459191,11.460474,11.076403,81.205742,-9.4315453
28.6,0.89724588,-0.042011984,47.589855,0,11.076097,85.715897,-0.0028196501,11.446323,11.076064,84.063789,-9.4297991
29.7,0.90292841,-0.044636287,48.383785,0,11.076097,89.015884,-0.0029900849,11.536316,11.076743,87.229683,-9.4282341
30.8,0.90842628,-0.047367223,49.222668,0,11.076097,92.315903,-0.0031461117,11.590395,11.075777,90.472092,-9.42661
31.9,0.91516608,-0.05000459,49.636227,0,11.076097,95.615898,-0.003304105,11.690644,11.076689,93.802444,-9.4248581
33.0,0.92151314,-0.052565951,50.093884,0,11.076097,98.915901,-0.0034952795,11.780317,11.076912,97.370895,-9.4228296
34.1,0.91561311,-0.0554474,50.438229,0,11.076097,102.2159,-0.0036862858,11.697803,11.075996,101.00658,-9.420908
35.2,0.93149501,-0.058358509,50.438229,0,11.076097,105.5159,-0.0038680967,11.914286,11.075822,104.78895,-9.419322
36.3,0.93235707,-0.061787013,50.167694,0,11.076097,108.8159,-0.0041334582,11.910334,11.075625,108.46767,-9.4175558
37.4,0.92941463,-0.064554304,50.042728,0,11.076097,112.11589,-0.0043191751,11.881037,11.075872,112.00924,-9.4158726
38.5,0.93484628,-0.066471115,50.042728,0,11.076097,115.41589,-0.0044287262,11.955391,11.075842,115.33315,-9.4144716
39.6,0.93261623,-0.069250926,50.042728,0,11.076097,118.71589,-0.0045737042,11.932724,11.075966,118.63574,-9.4125509
40.7,0.93402463,-0.071180485,50.437984,0,11.076097,122.01588,-0.0047197896,11.94224,11.076096,121.78517,-9.4110651
41.8,0.93380892,-0.073970392,50.438229,0,11.076097,125.31587,-0.0049242876,11.950749,11.075454,124.93451,-9.4093428
42.9,0.94402719,-0.07618089,50.82275,0,11.076097,128.616,-0.0050484203,12.082234,11.076622,127.97997,-9.4076338
44.0,0.94137371,-0.078744955,51.196266,0,11.076097,131.91589,-0.0052471701,12.049183,11.075631,131.15767,-9.4061432
45.1,0.94327366,-0.081389301,51.56982,0,11.076097,135.21588,-0.0054423232,12.076348,11.075556,134.3062,-9.4049358
46.2,0.94086385,-0.084187411,51.932369,0,11.076097,138.51588,-0.0056015435,12.044933,11.076044,137.62015,-9.4030285
47.3,0.94365138,-0.087218039,52.283833,0,11.076097,141.81589,-0.0057658469,12.083999,11.076163,140.78258,-9.401722
48.4,0.94300032,-0.090598643,52.635395,0,11.076097,145.11591,-0.0060110963,12.070958,11.075271,144.11356,-9.3997087
49.5,0.94077682,-0.094047643,52.644657,0,11.076097,148.41589,-0.0062622847,12.044086,11.075172,147.52606,-9.3982906
50.6,0.94569731,-0.096660063,52.914406,0,11.076097,151.71588,-0.0064085266,12.133304,11.076804,150.98512,-9.3965111
51.7,0.94701695,-0.09868893,52.97607,0,11.076097,155.0159,-0.0065641906,12.144131,11.076637,154.34723,-9.3946152
52.8,0.94600779,-0.10118049,53.31665,0,11.076097,158.31589,-0.0067420332,12.122611,11.075089,157.4783,-9.3927326
53.9,0.94326484,-0.1045805,53.657223,0,11.076097,161.61589,-0.0069552273,12.110435,11.075922,160.83768,-9.3911476
55.0,0.94718492,-0.10738754,53.657627,0,11.076097,164.91589,-0.0071079978,12.15341,11.076787,164.15492,-9.3895741
56.1,0.945862,-0.11034305,53.975826,0,11.076097,168.2159,-0.0073174252,12.135175,11.076391,167.466,-9.3873434
57.2,0.94584394,-0.11297446,54.195099,0,11.076097,171.5159,-0.0075072721,12.142524,11.076355,170.82614,-9.3856792
58.3,0.95153052,-0.11546489,54.305386,0,11.076097,174.81589,-0.0076466841,12.19204,11.076477,174.27057,-9.3839283
59.4,0.94866556,-0.11807592,54.305416,0,11.076097,178.11589,-0.0078570964,12.186025,11.076248,177.62946,-9.3821669
60.5,0.95053077,-0.12126572,54.30827,0,11.076097,181.41588,-0.008074983,12.187933,11.076283,181.0168,-9.3807287
61.6,0.94577211,-0.1242421,54.624023,0,11.076097,184.7159,-0.0082608163,12.131549,11.076743,184.28798,-9.3787718
62.7,0.94773006,-0.12716807,54.624023,0,11.076097,188.01588,-0.0084165884,12.166028,11.076645,187.54526,-9.377389
63.8,0.94160455,-0.1298065,54.921207,0,11.076097,191.31589,-0.0086059021,12.08484,11.076521,190.84871,-9.3756132
64.9,0.95172256,-0.13255669,54.931637,0,11.076097,194.61589,-0.0087901801,12.22179,11.077398,194.06398,-9.374012
66.0,0.94592398,-0.13508831,55.238277,0,11.076097,197.91589,-0.008960099,12.162746,11.076499,197.37291,-9.3718557
67.1,0.94579595,-0.13789906,55.239254,0,11.076097,201.2159,-0.0091742715,12.16487,11.074962,200.69841,-9.3704653
68.2,0.95111656,-0.14079164,55.239254,0,11.076097,204.5159,-0.0093724607,12.235134,11.07655,204.12093,-9.3685493
69.3,0.95462441,-0.14372288,55.414867,0,11.076097,207.81589,-0.0095275529,12.281322,11.075592,207.45642,-9.3671618
70.4,0.95768321,-0.14660062,55.535885,0,11.076097,211.11591,-0.0096989125,12.321277,11.076601,210.7179,-9.3654842
71.5,0.95689684,-0.14976355,55.569443,0,11.076097,214.41589,-0.0099342335,12.307017,11.075738,213.94815,-9.3634796
72.6,0.95222962,-0.15256923,55.843506,0,11.076097,217.71591,-0.010117908,12.260397,11.076137,217.19183,-9.3615818
73.7,0.95979327,-0.15528803,56.128704,0,11.076097,221.0159,-0.010300207,12.348324,11.075789,220.42656,-9.3602457
74.8,0.9606511,-0.1582848,56.129147,0,11.076097,224.31589,-0.010524825,12.357038,11.076167,223.74062,-9.3581429
75.9,0.94763446,-0.16158767,56.129147,0,11.076097,227.61589,-0.010726538,12.198319,11.077284,227.19843,-9.3567648
77.0,0.95568168,-0.16518827,56.183388,0,11.076097,230.91589,-0.010942686,12.307384,11.075821,230.54114,-9.3553066
78.1,0.95841753,-0.16894889,56.425743,0,11.076097,234.21588,-0.011180425,12.340551,11.075595,233.86758,-9.3533945
79.2,0.95911455,-0.17228743,56.253639,0,11.076097,237.5159,-0.011419159,12.359082,11.075232,237.3569,-9.3518314
80.3,0.96072757,-0.1750052,56.425312,0,11.076097,240.8159,-0.011584293,12.37593,11.076538,240.63097,-9.3501415
81.4,0.95015574,-0.17733245,56.425777,0,11.076097,244.11589,-0.01175996,12.226855,11.076301,243.92838,-9.3483839
82.5,0.95239896,-0.18001533,56.457626,0,11.076097,247.41589,-0.011959903,12.268845,11.076531,247.11011,-9.3466501
83.6,0.94807088,-0.18313433,56.711422,0,11.076097,250.71588,-0.012149075,12.218373,11.075729,250.23482,-9.3449354
84.7,0.94740307,-0.18627584,56.864407,0,11.076097,254.0159,-0.01231026,12.210293,11.075993,253.49478,-9.3427324
85.8,0.9540742,-0.18944006,57.061749,0,11.076097,257.31613,-0.012543044,12.289564,11.076576,256.61896,-9.3410921
86.9,0.95864832,-0.19211245,57.260738,0,11.076097,260.61615,-0.012733885,12.359665,11.076241,259.91528,-9.3390179
88.0,0.95552558,-0.19542642,57.286182,0,11.076097,263.91592,-0.012934187,12.31652,11.076203,263.33984,-9.3374357
89.1,0.95332384,-0.19834051,57.535397,0,11.076097,267.21591,-0.013152554,12.294631,11.076375,266.68564,-9.3359804
90.2,0.96176577,-0.20162483,57.535397,0,11.076097,270.51593,-0.013376103,12.403937,11.076357,270.01682,-9.3341093
91.3,0.96243215,-0.20595689,57.549118,0,11.076097,273.81592,-0.013635733,12.424286,11.076557,273.4003,-9.3325119
92.4,0.96078879,-0.20918867,57.81004,0,11.076097,277.11591,-0.013814427,12.399039,11.076738,276.68942,-9.3310823
93.5,0.95065618,-0.2113338,57.810051,0,11.076097,280.41589,-0.013991416,12.262055,11.075897,280.03333,-9.3292351
94.6,0.95457613,-0.21437655,57.917206,0,11.076097,283.71588,-0.014178474,12.337785,11.076246,283.26749,-9.3276129
95.7,0.95170236,-0.21734154,58.028374,0,11.076097,287.0159,-0.014390442,12.278644,11.07567,286.65564,-9.3255091
96.8,0.95378935,-0.22033033,58.073727,0,11.076097,290.31586,-0.014603981,12.318622,11.075767,290.00299,-9.323844
97.9,0.95435917,-0.22327299,58.073727,0,11.076097,293.61588,-0.014785396,12.346296,11.07561,293.2923,-9.3221045
99.0,0.96359408,-0.22765587,58.073738,0,11.076097,296.91586,-0.015044223,12.464932,11.076422,296.57614,-9.3202305
100.1,0.96060699,-0.23063025,58.271656,0,11.076097,300.21588,-0.015243949,12.428443,11.075703,299.89917,-9.3186255
101.2,0.94461352,-0.23276801,58.337399,0,11.076097,303.51587,-0.015392708,12.206783,11.076122,303.13046,-9.3169127
102.3,0.95421863,-0.23568147,58.520802,0,11.076097,306.81586,-0.015582478,12.343856,11.076323,306.33688,-9.3152218
103.4,0.95293689,-0.23837692,58.59008,0,11.076097,310.11584,-0.015784575,12.331059,11.076762,309.60797,-9.3133602
104.5,0.96344584,-0.24085177,58.851929,0,11.076097,313.41589,-0.015950752,12.473147,11.076738,312.73303,-9.3120289
105.6,0.95975339,-0.24457665,59.073589,0,11.076097,316.71588,-0.016172016,12.423476,11.075782,315.96512,-9.3100119
106.7,0.96322531,-0.24930371,59.106438,0,11.076097,320.0159,-0.016456408,12.46978,11.076132,319.30527,-9.3084822
107.8,0.95429206,-0.25128007,59.348019,0,11.076097,323.31589,-0.016616054,12.353361,11.07591,322.595,-9.306426
108.9,0.95185828,-0.25450847,59.488976,0,11.076097,326.61588,-0.016799936,12.325106,11.076304,325.87308,-9.3047485
110.0,0.95581257,-0.25725359,59.600826,0,11.076097,329.91428,-0.017020855,12.376748,11.07687,329.27606,-9.3030319
111.1,0.064596236,-0.27399871,57.298996,0,11.076097,329.99976,-0.018125612,0.84011018,11.076642,333.17227,-9.3029737
112.2,0.055515449,-0.27482688,54.057678,0,11.076097,329.99976,-0.01815265,0.72245473,11.07608,336.4765,-9.3030119
113.3,0.040482879,-0.2748822,50.952816,0,11.076097,329.99976,-0.018131418,0.51959556,11.076146,337.77612,-9.3026514
114.4,0.023603378,-0.2737987,48.58371,0,11.076097,329.99976,-0.0180881,0.31034696,11.076198,337.43701,-9.3024845
115.5,0.02120656,-0.27223232,47.799973,0,11.076097,329.99976,-0.017983045,0.27582023,11.076329,335.60608,-9.3026495
116.6,0.0087770559,-0.27058449,48.563072,0,11.076097,329.99976,-0.017876362,0.11130884,11.075762,332.84998,-9.3025923
117.7,0.0054825475,-0.26904494,50.42997,0,11.076097,329.99976,-0.017802252,0.07833381,11.076812,329.88101,-9.3025494
118.8,0.0052654115,-0.26804212,53.144875,0,11.076097,329.99976,-0.017718252,0.078055233,11.076334,326.93857,-9.302844
119.9,-0.0022719873,-0.26681769,56.05444,0,11.076097,329.99976,-0.017605333,-0.031693503,11.076956,324.28357,-9.3027382
121.0,-0.0026841029,-0.2661401,58.723377,0,11.076097,329.99976,-0.017580226,-0.013145542,11.076451,322.23608,-9.3029213
122.1,0.0041150278,-0.26558605,61.17849,0,11.076097,329.99976,-0.017550085,0.065234303,11.075696,320.86166,-9.3030691
123.2,-0.00059148093,-0.26565719,63.182236,0,11.076097,329.99976,-0.017553359,-0.013995904,11.076678,320.13309,-9.3032064
124.3,0.0041731391,-0.26594236,65.024818,0,11.076097,329.99976,-0.017598351,0.062851854,11.076181,319.87094,-9.3030233
125.4,0.0095874621,-0.26583016,66.366417,0,11.076097,329.99976,-0.017578136,0.12346021,11.076113,320.22073,-9.302619
126.5,0.014524683,-0.26613712,67.552345,0,11.076097,329.99976,-0.017561249,0.18979307,11.076616,320.94672,-9.3030386
127.6,0.03853358,-0.26683041,68.192131,0,11.076097,329.99976,-0.017616421,0.50418866,11.075038,322.44095,-9.3025398
128.7,0.047817107,-0.26862982,68.201622,0,11.076097,329.99976,-0.017751051,0.60791957,11.076268,325.06616,-9.3027372
129.8,0.047542077,-0.27158543,67.709702,0,11.076097,329.99976,-0.017936489,0.61896473,11.076522,328.23987,-9.3027782
130.9,0.05726739,-0.27392435,66.653709,0,11.076097,329.99976,-0.018116713,0.75017512,11.076089,331.4826,-9.302454
132.0,0.054591641,-0.27585253,65.151428,0,11.076097,329.99976,-0.018238278,0.69574022,11.077102,334.32245,-9.3024178
133.1,0.060231984,-0.27738106,63.299782,0,11.076097,329.99976,-0.018313279,0.77791607,11.075819,336.74457,-9.3026829
134.2,0.060791969,-0.27851453,61.253574,0,11.076097,329.99976,-0.018382225,0.78843397,11.07558,338.33829,-9.302783
135.3,0.055808235,-0.27917865,58.915001,0,11.076097,329.99976,-0.018439572,0.72159821,11.075952,339.29367,-9.3027124
136.4,0.047737963,-0.2787334,56.71682,0,11.076097,329.99976,-0.018400596,0.62081796,11.076561,339.44223,-9.3027058
137.5,0.038705472,-0.27834284,54.692982,0,11.076097,329.99976,-0.018408943,0.5100565,11.076338,338.74814,-9.3027124
138.6,0.02377376,-0.27823687,53.332199,0,11.076097,329.99976,-0.018394798,0.29569778,11.074114,337.42172,-9.3029032
139.7,0.014601013,-0.27778777,52.883949,0,11.076097,329.99976,-0.018328926,0.20773047,11.077356,335.4252,-9.3029594
140.8,0.014913242,-0.27693501,53.267063,0,11.076097,329.99976,-0.018282531,0.18543239,11.075911,333.10388,-9.3029451
141.9,0.0026143794,-0.27573624,54.304989,0,11.076097,329.99976,-0.01821845,0.036984276,11.076151,330.5488,-9.3028593
143.0,-0.0034767878,-0.27476871,56.099113,0,11.076097,329.99976,-0.0181392,-0.027940147,11.076106,328.01666,-9.3022413
144.1,-0.00022783347,-0.27372092,58.202049,0,11.076097,329.99976,-0.018110892,0.0068448475,11.076035,325.60684,-9.302536
145.2,-0.0093523776,-0.27322635,60.308132,0,11.076097,329.99976,-0.018067647,-0.1183949,11.075925,323.57489,-9.3025265
146.3,-0.0045330604,-0.27302599,62.50462,0,11.076097,329.99976,-0.018015338,-0.047162741,11.07625,322.03723,-9.3023939
147.4,-0.0059852595,-0.27324414,64.323326,0,11.076097,329.99976,-0.018038081,-0.082328878,11.076276,321.0235,-9.3025475
148.5,-0.0053544343,-0.27308586,65.98497,0,11.076097,329.99976,-0.018037666,-0.061884578,11.076835,320.60596,-9.302557
149.6,0.0046629678,-0.27304599,67.368629,0,11.076097,329.99976,-0.01804439,0.073064931,11.075926,320.58362,-9.3026991
150.7,0.012092169,-0.27307957,68.485558,0,11.076097,329.99976,-0.018073419,0.16050114,11.075774,321.18045,-9.3023548
151.8,0.037664253,-0.27453962,68.896927,0,11.076097,329.99976,-0.018130517,0.48875412,11.075951,323.14478,-9.3027639
152.9,0.062413506,-0.27795863,68.664688,0,11.076097,329.99976,-0.018332526,0.79836935,11.076509,326.25189,-9.302969
154.0,0.063003279,-0.28119013,67.71241,0,11.076097,329.99976,-0.018567761,0.80978566,11.075476,329.99387,-9.3027859
155.1,0.068027802,-0.013308453,66.199966,0,11.076097,329.99976,-0.00086408749,0.88167268,11.076714,333.73093,-9.3028908
155.2827,0.19695894,0.00076128036,25.729303,0,11.076099,1.5468613e-08,9.0215122e-05,2.4759152,11.078997,334.34647,-9.3030252
155.2849,0.16723783,0.0024754843,11.215244,0,11.076099,1.544973e-23,0.00020855322,2.0604939,11.074375,334.36661,-9.3034325
155.2871,0.16687797,0.00078908866,0.0,0,11.076099,1.5430874e-38,5.1577576e-05,2.1726172,11.076853,334.38065,-9.303051
155.2893,0.16638939,0.0062361215,0.0,0,11.076099,0.0,0.00042421027,2.1273913,11.077274,334.37393,-9.302804
155.2915,0.17488457,0.001736408,0.0,0,11.076099,0.0,0.00013785942,2.247268,11.075488,334.36722,-9.3012209
155.2937,0.1740251,0.002250077,0.0,0,11.076099,0.0,0.00020283142,2.1479998,11.072681,334.36047,-9.3020515
155.2959,0.19179311,0.00049580762,0.0,0,11.076099,0.0,4.3742635e-05,2.3560858,11.0768,334.35376,-9.3027878
155.2981,0.19723308,0.0053138784,0.0,0,11.076099,0.0,0.00039645602,2.4901342,11.078731,334.34705,-9.3023167
155.3003,0.19567154,0.0023127603,0.0,0,11.076099,0.0,8.9467576e-05,2.4397953,11.074107,334.34033,-9.30231
155.3025,0.19008778,0.002493243,0.0,0,11.076099,0.0,0.0002120718,2.4948609,11.075197,334.33362,-9.3022633
155.3047,0.18431059,0.0019522221,0.0,0,11.076099,0.0,8.4322477e-05,2.3736181,11.076774,334.3269,-9.3021021
155.3069,0.1826583,0.0057035633,0.0,0,11.076099,0.0,0.0004469431,2.2867417,11.074957,334.32538,-9.3037271
155.3091,0.18222266,0.0021603766,0.0,0,11.076099,0.0,0.00011604896,2.3439784,11.078055,334.35226,-9.3036938
155.3113,0.18156162,0.0029704249,0.0,0,11.076099,0.0,0.00024033565,2.3542275,11.075429,334.37912,-9.304287
155.3135,0.19526805,0.0015114079,0.0,0,11.076099,0.0,3.3777011e-05,2.5209522,11.077651,334.40598,-9.3034725
155.3157,0.19918148,0.0053290837,0.0,0,11.076099,0.0,0.00047123988,2.5852637,11.077601,334.43286,-9.3036442
155.3179,0.20764966,0.0044833836,0.0,0,11.076099,0.0,0.00019216895,2.6082306,11.073488,334.45557,-9.3036776
155.3201,0.20010911,0.0029837068,0.0,0,11.076099,0.0,0.00030359218,2.5126708,11.075841,334.47574,-9.3021564
155.3223,0.1942167,0.0017500605,0.0,0,11.076099,0.0,1.4316211e-05,2.5844429,11.077284,334.49588,-9.3018942
155.3245,0.19209598,0.0039205989,0.0,0,11.076099,0.0,0.00044380437,2.4520133,11.076373,334.51605,-9.3028984
155.3267,0.1985417,0.0036551587,0.0,0,11.076099,0.0,9.3497358e-05,2.5619028,11.076961,334.53455,-9.3037148
155.3289,0.19897775,0.0029673192,0.0,0,11.076099,0.0,0.00031907158,2.5416791,11.075951,334.53455,-9.3044729
155.3311,0.2083457,0.0024952644,0.0,0,11.076099,0.0,1.369674e-05,2.6172354,11.078188,334.53455,-9.3045578
155.3333,0.21162367,0.0040905233,0.0,0,10.765901,0.0,0.0004730639,2.687856,11.078026,334.53455,-9.3022699
155.3355,0.22316776,0.0049022972,0.0,0,10.435008,0.0,0.00015609685,2.8564558,11.073111,334.53455,-9.3016624
155.3377,0.24468707,0.0034005323,0.0,0,10.104116,0.0,0.00034409706,3.0630727,11.025223,334.6662,-9.3029499
155.3399,0.20800039,0.0033001029,0.0,0,9.7732229,0.0,9.2085975e-05,2.6530044,10.851072,334.90756,-9.3022699
155.3421,0.25367889,0.005940259,0.0,0,9.4434071,0.0,0.00058784714,3.2135468,10.562643,335.14893,-9.3031073
155.3443,0.20053285,0.0077229012,0.0,0,9.1214981,0.0,0.00027232172,2.6446395,10.189781,335.39029,-9.3033037
155.3465,6.6558609,0.20105116,0.0,0,8.7995939,0.0,0.01274104,82.328598,9.7713413,335.638,-9.2978354
155.3487,8.3766975,0.65030515,0.0,0,8.4910259,0.0,0.043544598,101.7859,9.2806129,336.57596,-9.2944221
155.3509,9.2473898,1.0733283,0.0,0,8.1848736,0.0,0.074093379,109.55055,8.8681049,337.51392,-9.2946224
155.3531,9.8657427,1.4018943,0.0,0,7.8872557,0.0,0.097335197,113.83887,8.5273619,338.45187,-9.2937145
155.3553,9.9695282,1.6866124,0.0,0,7.5959754,0.0,0.11919681,112.63946,8.2082033,339.38986,-9.2941532
155.3575,10.371101,1.9726782,0.0,0,7.3089881,0.0,0.14050458,114.59381,7.906795,340.13455,-9.2957535
155.3597,10.546608,2.242852,0.0,0,7.0319633,0.0,0.16185254,114.38383,7.641192,340.66373,-9.2957945
155.3619,10.767963,2.4909766,0.0,0,6.7554417,0.0,0.18084577,114.39854,7.3891759,341.19287,-9.2946272
155.3641,11.077514,2.7397802,0.0,0,6.4917622,0.0,0.20163304,115.25251,7.1255145,341.72205,-9.2955847
155.3663,11.322207,3.0074446,0.0,0,6.2282019,0.0,0.22305083,115.25588,6.8714051,342.25122,-9.2943306
155.3685,11.640679,3.2666845,0.0,0,5.9743834,0.0,0.24556124,115.80489,6.6009469,342.1218,-9.2945585
155.3707,11.96629,3.542213,0.0,0,5.7237153,0.0,0.26852891,116.38837,6.3325424,341.94766,-9.2950344
155.3729,12.222523,3.804543,0.0,0,5.4789333,0.0,0.2925595,116.09602,6.0623598,341.7735,-9.2953758
155.3751,12.527981,4.0731401,0.0,0,5.2404532,0.0,0.31596097,116.24572,5.7955179,341.59933,-9.2943449
155.3773,12.816054,4.3340831,0.0,0,5.0044241,0.0,0.34100354,116.05573,5.528399,341.35284,-9.2952194
155.3795,13.07297,4.5913544,0.0,0,4.7776041,0.0,0.36443257,115.5519,5.2740993,340.99783,-9.2950773
155.3817,13.397561,4.8332415,0.0,0,4.5507841,0.0,0.38899514,115.60651,5.0239778,340.64282,-9.2937851
155.3839,13.704352,5.0742621,0.0,0,4.3343177,0.0,0.41194573,115.5038,4.7851563,340.28781,-9.2956915
155.3861,14.019098,5.3042264,0.0,0,4.1185417,0.0,0.43647912,115.26662,4.5549278,339.9328,-9.295536
155.3883,14.353722,5.5339131,0.0,0,3.9097853,0.0,0.45927539,115.39638,4.3301163,339.62985,-9.2964554
155.3905,14.679243,5.7438755,0.0,0,3.7045693,0.0,0.48296747,115.30486,4.108707,339.33511,-9.2943764
155.3927,15.014291,5.960165,0.0,0,3.5032687,0.0,0.50546831,115.27553,3.8978038,339.04041,-9.2937975
155.3949,15.361819,6.1578121,0.0,0,3.3080409,0.0,0.52878463,115.24363,3.6940804,338.74567,-9.2937031
155.3971,15.723757,6.3654418,0.0,0,3.11395,0.0,0.55102712,115.39362,3.4941764,338.2157,-9.2956457
155.3993,16.116905,6.5550122,0.0,0,2.9282222,0.0,0.57471395,115.43291,3.2994766,337.20227,-9.2950506
155.4015,16.574249,6.7562757,0.0,0,2.7424984,0.0,0.59760427,116.01479,3.0987585,336.18884,-9.2939348
155.4037,17.033867,6.9509425,0.0,0,2.5644474,0.0,0.62287486,116.28735,2.90521,335.17542,-9.2937031
155.4059,17.534721,7.1482196,0.0,0,2.3877873,0.0,0.64598304,116.96367,2.7151384,334.16199,-9.2935114
155.4081,18.036314,7.3233371,0.0,0,2.2160764,0.0,0.67018819,117.41096,2.5299935,333.39313,-9.2942829
155.4103,18.548983,7.504333,0.0,0,2.0480404,0.0,0.69267631,118.09326,2.3541598,332.6889,-9.2942429
155.4125,19.098417,7.6772623,0.0,0,1.8824685,0.0,0.71757805,118.61827,2.1745617,331.98468,-9.2924767
155.4147,19.672855,7.85745,0.0,0,1.7226164,0.0,0.7405169,119.42857,2.003293,331.28049,-9.2914944
155.4169,20.288038,8.0148525,0.0,0,1.5630548,0.0,0.76467443,120.12788,1.8367364,330.49557,-9.2912169
155.4191,20.927151,8.1867456,0.0,0,1.4109213,0.0,0.7879076,121.13158,1.66836,329.47443,-9.2914762
155.4213,21.605625,8.3406563,0.0,0,1.2588574,0.0,0.81251091,122.00083,1.5098612,328.45325,-9.2913074
155.4235,22.342936,8.5031767,0.0,0,1.1124125,0.0,0.83501369,123.35844,1.3529069,327.4321,-9.2902803
155.4257,23.112064,8.6436863,0.0,0,0.96778435,0.0,0.85921097,124.59222,1.198509,326.41095,-9.289937
155.4279,23.916004,8.7989769,0.0,0,0.82657731,0.0,0.88211542,125.96019,1.0468947,324.08838,-9.2902946
155.4301,24.763914,8.9417181,0.0,0,0.68903339,0.0,0.90743786,127.14654,0.89933366,321.25522,-9.2908421
155.4323,25.595728,9.0919638,0.0,0,0.55288601,0.0,0.92984396,128.52098,0.75718421,318.42203,-9.2889223
155.4345,26.468147,9.2129002,0.0,0,0.42198589,0.0,0.95291495,129.90468,0.61980277,315.58884,-9.289463
155.4367,27.365377,9.3487663,0.0,0,0.29108587,0.0,0.97487378,131.39793,0.4882417,313.30624,-9.2877884
155.4389,25.757618,9.4158201,0.0,0,0.16620816,0.0,0.98926008,121.86542,0.39166003,313.50107,-9.288167
155.4411,24.452175,9.4484472,0.0,0,0.041732151,0.0,0.99250013,115.47939,0.34818134,313.69589,-9.29181
155.4433,23.442991,9.4357243,0.0,0,-0.080696426,0.0,0.9926272,110.74188,0.32492304,313.89072,-9.2941799
155.4455,23.127159,9.4455719,0.0,0,-0.20209241,0.0,0.99261326,109.09466,0.29929501,314.08554,-9.2935057
155.4477,23.130196,9.4439802,0.0,0,-0.32348844,0.0,0.9943167,108.93839,0.25295791,315.18109,-9.2933903
155.4499,23.294294,9.4595003,0.0,0,-0.44488442,0.0,0.9948287,109.66679,0.19692142,316.77142,-9.2925415
155.4521,23.340023,9.4570827,0.0,0,-0.56628042,0.0,0.99633598,109.71378,0.13340174,318.36176,-9.2936344
155.4543,23.308626,9.4697218,0.0,0,-0.68767637,0.0,0.99693078,109.49863,0.080704391,319.95209,-9.2938223
155.4565,23.183439,9.4678373,0.62992579,0,-0.80907238,0.0,0.99862051,108.76512,0.028389435,321.43048,-9.293685
155.4587,22.964077,9.4837646,6.4035826,0,-0.93046838,0.0,0.9991858,107.70988,-0.014918082,321.99478,-9.2945633
155.4609,22.678705,9.4740858,12.177239,0,-1.0518645,0.0,0.99946278,106.33387,-0.043987285,322.55911,-9.2951431
155.4631,22.298067,9.4823751,17.950897,0,-0.88153589,330.0,0.9994092,104.53633,-0.062979124,323.12344,-9.2943735
155.4653,21.803259,9.4796982,23.724552,0,-0.46125633,330.0,1.0005548,102.12442,-0.068939708,323.68777,-9.2949572
155.4675,21.327744,9.4940681,26.191408,0,-0.040977493,330.0,1.0012411,99.793747,-0.06789501,324.53683,-9.294591
155.4697,20.878105,9.4811821,26.191408,0,0.37930161,330.0,1.0007354,97.749115,-0.060807139,325.5983,-9.2953558
155.4719,20.513006,9.4869804,26.191408,0,0.79958111,330.0,1.0003941,96.06089,-0.057076331,326.65979,-9.2961454
155.4741,20.243393,9.4800158,26.191408,0,1.2198603,330.0,1.0004443,94.794151,-0.057273313,327.72125,-9.2966814
155.4763,19.412012,9.4916248,25.981382,0,1.640139,330.0,1.0009065,90.944283,-0.034271136,328.77417,-9.2981901
155.4785,17.878119,9.4794931,20.207726,0,2.0604188,330.0,1.000214,83.908661,0.034595445,329.60049,-9.2986393
155.4807,14.682745,9.4723749,14.43407,0,2.4806981,330.0,0.99791807,69.301743,0.1663633,330.42685,-9.3003626
155.4829,8.605999,9.4422379,8.6604128,0,2.9009769,330.0,0.99379766,41.793709,0.39317635,331.25317,-9.3030577
155.4851,0.47752342,9.2418032,2.8867562,0,3.3212562,330.0,0.95687133,2.6228161,0.86235017,332.07953,-9.3112831
155.4873,-0.41399768,9.0807781,0.0,0,3.7415352,330.0,0.93040866,-1.969036,1.5115325,332.49603,-9.3141174
155.4895,-0.057764277,8.943778,0.0,0,4.1618147,330.0,0.90701735,-0.42051533,2.2622302,332.50275,-9.3138723
155.4917,-0.12801503,8.8465605,0.0,0,4.5820937,330.0,0.8915543,-0.48001009,2.9063823,332.50946,-9.3117313
155.4939,-0.26206946,8.827014,0.0,0,5.0023732,330.0,0.88749516,-1.4397367,3.4077251,332.51617,-9.3125334
155.4961,0.039650422,8.7934351,0.0,0,5.4226518,330.0,0.88292432,0.13648215,3.8173141,332.52289,-9.3106775
155.4983,-0.0071800244,8.8286467,0.93818766,0,5.8429317,330.0,0.88748246,0.012105141,4.2044106,331.76569,-9.3103762
155.5005,-0.018088795,8.8668528,1.9117657,0,6.2632103,330.0,0.8944487,-0.14366683,4.5860038,330.97968,-9.3091164
155.5027,-0.068914607,8.952013,2.8853436,0,6.6834898,330.0,0.90755188,-0.32171568,4.9778743,330.19363,-9.307765
155.5049,-0.067539752,9.0370598,3.858922,0,7.1037693,330.0,0.92236561,-0.3603439,5.3817525,329.40762,-9.3061094
155.5071,0.0038492624,9.1542568,4.4165039,0,7.5240483,330.0,0.94174296,-0.019760821,5.8182588,329.06079,-9.3065901
155.5093,-0.085498318,9.2844315,4.4165039,0,7.9443278,330.0,0.96447873,-0.31113678,6.2567892,329.30264,-9.3064775
155.5115,-0.21027969,9.4505453,4.4165039,0,8.3646069,330.0,0.99349236,-1.0242435,6.697866,329.54449,-9.3065758
155.5137,-0.16310389,9.4050932,4.4165039,0,8.7848854,330.0,0.98573744,-0.63881677,7.1425886,329.78635,-9.3045588
155.5159,0.13064186,9.4184418,4.4165039,0,9.2051649,330.0,0.9876731,0.43990004,7.584548,330.0282,-9.3043222
155.5181,0.015545368,9.4498978,3.5491219,0,9.6254444,330.0,0.99409586,0.094866872,8.0200396,331.4653,-9.3028822
155.5203,-0.14282534,9.4465094,2.5755439,0,10.045724,330.0,0.99358058,-0.59920609,8.4501619,333.04874,-9.3030148
155.5225,-0.046591163,9.4330273,1.6019659,0,10.466002,330.0,0.99151343,-0.25482622,8.8756056,334.6322,-9.3046656
155.5247,0.035526078,9.4308395,0.62838787,0,10.886282,330.0,0.99107105,0.16596636,9.3181887,336.21564,-9.3043404
155.5269,-0.027948236,9.4304199,0.0,0,11.306561,330.0,0.9905594,-0.095371746,9.7520857,337.48965,-9.3034458
155.5291,-0.13504839,9.433836,0.0,0,11.72684,330.0,0.99124354,-0.59213984,10.178229,338.20038,-9.3019009
155.5313,-0.19286805,9.4297676,0.0,0,12.14712,330.0,0.9903248,-1.0105728,10.609742,338.9111,-9.3021975
155.5335,-0.019168895,9.4310055,0.0,0,12.567399,330.0,0.99101067,-0.19992174,11.04534,339.6218,-9.3030806
155.5357,0.042519808,9.4257174,0.0,0,12.987678,330.0,0.98955977,0.17359653,11.470984,340.33252,-9.3021803
155.5379,-0.061326191,9.4339371,0.0,0,13.407957,330.0,0.99165475,-0.22272597,11.883298,340.59326,-9.3008652
155.5401,-0.042870451,9.4258451,0.0,0,13.828236,330.0,0.98962051,-0.17580858,12.300572,340.75403,-9.3009453
155.5423,-0.087613173,9.4318256,0.0,0,14.248516,330.0,0.99131423,-0.32308865,12.724271,340.91476,-9.3024473
155.5445,-0.022706959,9.4323406,0.0,0,14.668795,330.0,0.99072886,-0.14281258,13.158738,341.07553,-9.3010464
155.5467,0.018993359,9.4317522,0.0,0,15.089074,330.0,0.99129754,0.10986234,13.603293,341.25137,-9.3000231
155.5489,-0.16536042,9.4303436,0.0,0,15.509354,330.0,0.99030995,-0.73050219,14.040328,341.46573,-9.299202
155.5511,-0.096441634,9.428299,0.0,0,15.929632,330.0,0.99087554,-0.52472818,14.480024,341.68008,-9.3006468
155.5533,0.037850987,9.4264708,0.0,0,16.349911,330.0,0.98973811,0.12276667,14.91083,341.89444,-9.3012094
155.5555,0.028464658,9.4293222,0.0,0,16.770191,330.0,0.99119461,0.13287142,15.333662,342.10876,-9.3021574
155.5577,-0.10174964,9.4281492,0.0,0,17.19047,330.0,0.98962271,-0.4192118,15.752645,342.16833,-9.3006105
155.5599,-0.11153849,9.4287806,0.0,0,17.61075,330.0,0.99095207,-0.50126064,16.162394,342.17502,-9.3007441
155.5621,-0.096222401,9.4294243,0.0,0,17.999401,330.0,0.99000144,-0.48196074,16.57802,342.18173,-9.300561
155.5643,0.010273186,9.4328461,0.0,0,18.0,330.0,0.99196184,0.0499494,17.00316,342.18842,-9.2998791
155.5665,-0.066546865,9.4317369,0.0,0,18.0,330.0,0.99010372,-0.23464853,17.408104,342.18951,-9.3009949
155.5687,-0.11340712,9.430357,0.0,0,18.0,330.0,0.99142838,-0.5596801,17.768728,342.16943,-9.3014784
155.5709,-0.043229695,9.4282866,0.0,0,18.0,330.0,0.98982543,-0.20155339,18.083939,342.14932,-9.3030777
155.5731,-0.060849406,9.4336548,0.0,0,18.0,330.0,0.99205703,-0.30702347,18.329845,342.12924,-9.3051548
155.5753,0.0027540042,9.4403439,0.0,0,18.0,330.0,0.99174631,-0.0059551792,18.492455,342.10913,-9.3083162
155.5775,0.00093365001,9.4414349,0.0,0,18.0,330.0,0.99342382,0.062747531,18.539473,342.27832,-9.313262
155.5797,-0.072029822,9.4505377,0.0,0,18.0,330.0,0.99356389,-0.32709113,18.482241,342.53955,-9.3200312
155.5819,-0.088669978,9.4596128,0.0,0,18.0,330.0,0.99688929,-0.39443073,18.356964,342.80078,-9.3283291
155.5841,-0.066396795,9.4732819,0.0,0,18.0,330.0,0.99740624,-0.35281247,18.218632,343.06201,-9.3410912
155.5863,-0.097115338,9.4843626,0.0,0,18.0,330.0,1.0012007,-0.44212931,18.111301,343.1908,-9.3561697
155.5885,-0.117791,9.4999571,0.0,0,18.0,330.0,1.0024229,-0.51556009,18.049643,342.48065,-9.3733644
155.5907,-0.055931892,9.5185843,0.0,0,18.0,330.0,1.0077492,-0.37984836,18.035973,341.77051,-9.3915787
155.5929,0.045489252,9.5391741,0.0,0,18.0,330.0,1.0092915,0.14221027,18.038845,341.06036,-9.4092035
155.5951,0.052078653,9.5500021,0.0,0,18.0,330.0,1.0135064,0.2490977,18.051273,340.35022,-9.4265318
155.5973,0.01780745,9.5706663,0.0,0,18.0,330.0,1.0150712,0.090227552,18.074631,339.18939,-9.4448414
155.5995,-0.049888637,9.5873699,0.0,0,18.0,330.0,1.0202929,-0.16189906,18.101004,337.72815,-9.463191
155.6017,-0.10758876,9.6086264,0.0,0,18.0,330.0,1.0219779,-0.42752326,18.124428,336.26691,-9.4792585
155.6039,-0.16335635,9.6191368,0.0,0,18.0,330.0,1.0262388,-0.74788481,18.132444,334.80566,-9.4947338
155.6061,-0.14519586,9.6379709,0.0,0,18.0,330.0,1.027549,-0.69961798,18.141365,333.48135,-9.510375
155.6083,-0.048782546,9.6497126,0.0,0,18.0,330.0,1.0320952,-0.25826547,18.136641,334.17139,-9.525959
155.6105,0.030455267,9.6669559,0.0,0,18.0,330.0,1.0329459,0.10285575,18.138083,334.86145,-9.5421419
155.6127,0.04853531,9.6770687,0.0,0,18.0,330.0,1.0373302,0.18305191,18.139444,335.55148,-9.5573187
155.6149,0.029037302,9.6974735,0.0,0,18.0,330.0,1.0386617,0.10786494,18.136024,336.24152,-9.5719404
155.6171,-0.0094119655,9.7107143,0.0,0,18.0,330.0,1.0435554,0.01662128,18.131083,337.5466,-9.5875635
155.6193,-0.089612126,9.7351646,0.0,0,18.0,330.0,1.0455995,-0.35663909,18.130932,339.40305,-9.6036367
155.6215,-0.13789189,9.7422552,0.0,0,18.0,330.0,1.04963,-0.60776585,18.128414,341.25949,-9.6202812
155.6237,-0.16682245,9.7674637,0.0,0,18.0,330.0,1.0519954,-0.74236053,18.126667,343.11594,-9.6378765
155.6259,-0.098472171,9.7763767,0.0,0,18.0,330.0,1.0561923,-0.49794784,18.121929,344.97238,-9.6542492
155.6281,0.012446078,9.7986183,0.0,0,18.0,330.0,1.0576175,-0.034441069,18.119621,345.0025,-9.6694698
155.6303,0.071529865,9.8049641,0.0,0,18.0,330.0,1.0616654,0.26260051,18.119963,345.0159,-9.6842651
155.6325,0.053622998,9.8277664,0.0,0,18.0,330.0,1.0634669,0.21996979,18.117022,345.0293,-9.7012424
155.6347,0.010046935,9.8380251,0.0,0,18.0,330.0,1.0680742,0.081053816,18.115906,345.04269,-9.7172165
155.6369,-0.057523195,9.8600225,0.0,0,18.0,330.0,1.069311,-0.19426249,18.116674,344.59631,-9.732749
155.6391,-0.13281487,9.8691807,0.0,0,18.0,330.0,1.0741642,-0.5255689,18.112452,343.59827,-9.7483644
155.6413,-0.15830779,9.8917913,0.0,0,18.0,330.0,1.076106,-0.67465943,18.111317,342.60022,-9.7647066
155.6435,-0.12503009,9.9031115,0.0,0,18.0,330.0,1.0807397,-0.58438289,18.10796,341.60217,-9.7809982
155.6457,-0.035479166,9.9259329,0.0,0,18.0,330.0,1.0822997,-0.23263887,18.109354,340.60413,-9.7980309
155.6479,0.046819743,9.9295835,0.0,0,18.0,330.0,1.0858561,0.19056107,18.106981,339.88895,-9.8139534
155.6501,0.070433795,9.9506607,0.0,0,18.0,330.0,1.0875632,0.28858423,18.104813,339.19894,-9.8291426
155.6523,0.028114075,9.9597921,0.0,0,18.0,330.0,1.0920032,0.15994729,18.101547,338.50894,-9.8421154
155.6545,-0.043118604,9.98703,0.0,0,18.0,330.0,1.0944228,-0.088101506,18.101078,337.81894,-9.858367
155.6567,-0.11328609,9.9954033,0.0,0,18.0,330.0,1.0989236,-0.40462363,18.101843,337.33868,-9.8746843
155.6589,-0.15365492,10.01748,0.0,0,18.0,330.0,1.1008949,-0.62830108,18.10033,337.19803,-9.8919086
155.6611,-0.14572892,10.025903,0.0,0,18.0,330.0,1.1051742,-0.6381768,18.098946,337.05734,-9.9090624
155.6633,-0.081798211,10.049842,0.0,0,18.0,330.0,1.1070808,-0.39426142,18.099384,336.91669,-9.923728
155.6655,0.015770677,10.054319,0.0,0,18.0,330.0,1.1109006,0.060191073,18.099228,336.776,-9.9406614
155.6677,0.066057183,10.077929,0.0,0,18.0,330.0,1.1131264,0.27169955,18.101503,337.21304,-9.9575558
155.6699,0.049872596,10.086025,0.0,0,18.0,330.0,1.1174616,0.21989365,18.099684,337.75571,-9.9714146
155.6721,-0.018338358,10.113921,0.0,0,18.0,330.0,1.1200433,-0.012288742,18.099207,338.29834,-9.9864798
155.6743,-0.097846046,10.120671,0.0,0,18.0,330.0,1.1242018,-0.35012165,18.098822,338.84097,-10.002915
155.6765,-0.143949,10.144439,0.0,0,18.0,330.0,1.1267898,-0.58021015,18.09692,339.32147,-10.018518
155.6787,-0.16001685,10.152687,0.0,0,18.0,330.0,1.1308472,-0.65487677,18.094757,339.66309,-10.03687
155.6809,-0.11198048,10.179599,0.0,0,18.0,330.0,1.1337593,-0.53847212,18.095078,340.0047,-10.053741
155.6831,-0.014777831,10.183424,0.0,0,18.0,330.0,1.1370515,-0.14304432,18.094767,340.34631,-10.068472
155.6853,0.055149056,10.20636,0.0,0,18.0,330.0,1.1397408,0.18610749,18.094265,340.68793,-10.083635
155.6875,0.076618157,10.214516,0.0,0,18.0,330.0,1.1436917,0.30492559,18.091206,340.9808,-10.100072
155.6897,0.039873581,10.243842,0.0,0,18.0,330.0,1.1471463,0.14501315,18.091387,341.25934,-10.116741
155.6919,-0.069701903,10.25138,0.0,0,18.0,330.0,1.1510155,-0.2229834,18.091633,341.53787,-10.1333
155.6941,-0.13779826,10.273076,0.0,0,18.0,330.0,1.1538656,-0.50141639,18.092129,341.81641,-10.147975
155.6963,-0.14686252,10.27963,0.0,0,18.0,330.0,1.1572467,-0.5908668,18.090834,342.09494,-10.16401
155.6985,-0.126743,10.307425,0.0,0,18.0,330.0,1.1606954,-0.52169323,18.085026,342.67673,-10.179382
155.7007,-0.054602351,10.311142,0.0,0,18.0,330.0,1.1637111,-0.28475466,18.084873,343.30637,-10.195393
155.7029,0.033161271,10.335138,0.0,0,18.0,330.0,1.1670223,0.061701186,18.090054,343.936,-10.212863
155.7051,0.072477691,10.342406,0.0,0,18.0,330.0,1.1703727,0.30687422,18.086437,344.56564,-10.227704
155.7073,0.062811561,10.368138,0.0,0,18.0,330.0,1.1739112,0.24857877,18.083319,345.20407,-10.2432
155.7095,-0.011137498,10.372444,0.0,0,18.0,330.0,1.1767963,0.016768241,18.079676,345.8605,-10.26055
155.7117,-0.12745543,10.397543,0.0,0,18.0,330.0,1.1806377,-0.45823583,18.081697,346.51691,-10.275355
155.7139,-0.16992277,10.406402,0.0,0,18.0,330.0,1.184146,-0.64803439,18.087227,347.17334,-10.291055
155.7161,-0.1330083,10.431794,0.0,0,18.0,330.0,1.1878921,-0.56402075,18.085943,347.82977,-10.307361
155.7183,-0.07972043,10.43736,0.0,0,18.0,330.0,1.1910075,-0.34272057,18.08165,347.51144,-10.323423
155.7205,-0.0078811012,10.46159,0.0,0,18.0,330.0,1.1948624,-0.10005979,18.078074,346.93539,-10.340036
155.7227,0.059516575,10.468254,0.0,0,18.0,330.0,1.1974186,0.21073358,18.077497,346.35931,-10.355373
155.7249,0.070891291,10.491827,0.0,0,18.0,330.0,1.2012101,0.28472567,18.07704,345.78326,-10.372975
155.7271,0.011786973,10.499413,0.0,0,18.0,330.0,1.2041837,0.098003149,18.080158,345.42883,-10.390273
155.7293,-0.085676305,10.525064,0.0,0,18.0,330.0,1.2091781,-0.25545564,18.075659,345.72342,-10.404632
155.7315,-0.17059696,10.537941,0.0,0,18.0,330.0,1.2126532,-0.59405118,18.07605,346.01801,-10.420535
155.7337,-0.15661797,10.562457,0.0,0,18.0,330.0,1.2173172,-0.62608629,18.075811,346.31259,-10.436782
155.7359,-0.12068228,10.567319,0.0,0,18.0,330.0,1.2194744,-0.48808405,18.078999,346.60718,-10.451732
155.7381,-0.041307725,10.587708,0.0,0,18.0,330.0,1.2232971,-0.18580334,18.076483,347.33481,-10.466955
155.7403,0.028846843,10.595364,0.0,0,18.0,330.0,1.2256227,0.049696624,18.076071,348.23236,-10.480837
155.7425,0.07760293,10.620554,0.0,0,18.0,330.0,1.2305912,0.29505938,18.073879,349.12994,-10.497962
155.7447,0.048557911,10.628709,0.0,0,18.0,330.0,1.2332251,0.21510257,18.075264,350.02753,-10.512739
155.7469,-0.040349122,10.649449,0.0,0,18.0,330.0,1.2376481,-0.11436173,18.071665,350.78375,-10.529897
155.7491,-0.13289022,10.661796,0.0,0,18.0,330.0,1.2406385,-0.45946887,18.075375,350.90402,-10.54691
155.7513,-0.17427376,10.686667,0.0,0,18.0,330.0,1.2462531,-0.61400193,18.073397,351.02429,-10.563761
155.7535,-0.14269765,10.695647,0.0,0,18.0,330.0,1.2485366,-0.52673155,18.072439,351.14453,-10.580031
155.7557,-0.055851683,10.711495,0.0,0,18.0,330.0,1.2522995,-0.26916608,18.073515,351.2648,-10.595219
155.7579,0.015508866,10.721794,0.0,0,18.0,330.0,1.2544798,0.0012947255,18.069847,350.32169,-10.610105
155.7601,0.053716369,10.744725,0.0,0,18.0,330.0,1.2599144,0.19142976,18.068241,348.79446,-10.627173
155.7623,0.059085988,10.755544,0.0,0,18.0,330.0,1.2623188,0.252085,18.071815,347.26724,-10.642892
155.7645,0.0074331281,10.776109,0.0,0,18.0,330.0,1.2673897,0.092975587,18.067835,345.74005,-10.659655
155.7667,-0.097792283,10.789994,0.0,0,18.0,330.0,1.2701735,-0.30616608,18.07021,344.23114,-10.67475
155.7689,-0.16862047,10.812189,0.0,0,18.0,330.0,1.2761707,-0.58567548,18.068157,342.87186,-10.69138
155.7711,-0.16306056,10.82408,0.0,0,18.0,330.0,1.2782086,-0.61024725,18.065929,341.51254,-10.707084
155.7733,-0.081423521,10.837069,0.0,0,18.0,330.0,1.2823396,-0.32196075,18.066864,340.15326,-10.722849
155.7755,0.0085519496,10.850368,0.0,0,18.0,330.0,1.2844834,-0.014155868,18.065245,338.79395,-10.737753
155.7777,0.059071824,10.871086,0.0,0,18.0,330.0,1.290558,0.18370727,18.06138,338.45102,-10.753588
155.7799,0.061468743,10.883404,0.0,0,18.0,330.0,1.292164,0.21109974,18.06777,338.8663,-10.769051
155.7821,0.042388201,10.898951,0.0,0,18.0,330.0,1.2973599,0.17381862,18.061172,339.28162,-10.78607
155.7843,-0.059054818,10.915587,0.0,0,18.0,330.0,1.3003372,-0.12318306,18.062811,339.6969,-10.80292
155.7865,-0.14337207,10.937861,0.0,0,18.0,330.0,1.306947,-0.45531273,18.064997,340.09979,-10.819152
155.7887,-0.17560637,10.952044,0.0,0,18.0,330.0,1.3087034,-0.62215251,18.059727,340.17346,-10.833142
155.7909,-0.12600753,10.965771,0.0,0,18.0,330.0,1.314025,-0.474392,18.05966,340.24713,-10.850029
155.7931,-0.037207745,10.978866,0.0,0,18.0,330.0,1.3155984,-0.17274919,18.059687,340.32083,-10.866817
155.7953,0.046074349,10.996333,0.0,0,18.0,330.0,1.3219606,0.10142963,18.060265,340.3945,-10.881925
155.7975,0.066480622,11.010711,0.0,0,18.0,330.0,1.3235065,0.20428661,18.058634,340.64902,-10.897072
155.7997,0.03512482,11.02564,0.0,0,18.0,330.0,1.3291907,0.15148555,18.060411,341.08441,-10.914133
155.8019,-0.015514955,11.044795,0.0,0,18.0,330.0,1.3317943,-0.016059395,18.060181,341.51981,-10.930476
155.8041,-0.1104458,11.062078,0.0,0,18.0,330.0,1.3386134,-0.30138132,18.058134,341.9552,-10.946751
155.8063,-0.17436893,11.078844,0.0,0,18.0,330.0,1.3402392,-0.5593015,18.059961,342.39059,-10.963681
155.8085,-0.16299258,11.089295,0.0,0,18.0,330.0,1.345521,-0.57008117,18.057999,342.91635,-10.978729
155.8107,-0.068102159,11.106043,0.0,0,18.0,330.0,1.3475803,-0.26348096,18.058992,343.44553,-10.994583
155.8129,0.022619827,11.124109,0.0,0,18.0,330.0,1.3546001,0.032653298,18.059177,343.97467,-11.009746
155.8151,0.05742323,11.136163,0.0,0,18.0,330.0,1.3546637,0.17858778,18.056227,344.50385,-11.026785
155.8173,0.040627938,11.148172,0.0,0,18.0,330.0,1.3608861,0.16096884,18.059702,344.69244,-11.042185
155.8195,0.0025814045,11.167182,0.0,0,18.0,330.0,1.3627558,0.054744665,18.059166,344.4245,-11.056216
155.8217,-0.069823682,11.184616,0.0,0,18.0,330.0,1.3704174,-0.14763288,18.055836,344.15656,-11.072936
155.8239,-0.14974172,11.203697,0.0,0,18.0,330.0,1.3724734,-0.43180481,18.056896,343.88864,-11.089336
155.8261,-0.17016768,11.217417,0.0,0,18.0,330.0,1.3791834,-0.54577792,18.056458,343.6207,-11.106142
155.8283,-0.11991538,11.233833,0.0,0,18.0,330.0,1.3803844,-0.43052191,18.056507,343.06036,-11.123141
155.8305,-0.0095870029,11.245111,0.0,0,18.0,330.0,1.3868772,-0.076292075,18.056335,342.4642,-11.138394
155.8327,0.061023038,11.266437,0.0,0,18.0,330.0,1.3890712,0.18878256,18.05307,341.86804,-11.153038
155.8349,0.064012095,11.275958,0.0,0,18.0,330.0,1.3948807,0.18940796,18.054003,341.27191,-11.169918
155.8371,0.021822173,11.295243,0.0,0,18.0,330.0,1.3964247,0.083115511,18.054811,341.07474,-11.185841
155.8393,-0.044254925,11.310537,0.0,0,18.0,330.0,1.4042245,-0.098948345,18.051794,341.60388,-11.201716
155.8415,-0.11719762,11.332436,0.0,0,18.0,330.0,1.4064059,-0.32070354,18.052227,342.13306,-11.217061
155.8437,-0.16328281,11.342807,0.0,0,18.0,330.0,1.4130253,-0.48392645,18.053642,342.66223,-11.232628
155.8459,-0.14539868,11.361626,0.0,0,18.0,330.0,1.4148376,-0.47890908,18.051413,343.19138,-11.249376
155.8481,-0.056309875,11.371355,0.0,0,18.0,330.0,1.4214097,-0.23200299,18.05127,344.17542,-11.266059
155.8503,0.04574867,11.393413,0.0,0,18.0,330.0,1.4230832,0.11215364,18.049503,345.26056,-11.282001
155.8525,0.077816255,11.399768,0.0,0,18.0,330.0,1.429213,0.22982028,18.048485,346.3457,-11.296529
155.8547,0.055745892,11.421544,0.0,0,18.0,330.0,1.4312879,0.19410434,18.046196,347.43082,-11.311744
155.8569,-0.017051235,11.434463,0.0,0,18.0,330.0,1.4387678,-0.028052999,18.045326,348.38559,-11.328334
155.8591,-0.097495809,11.459211,0.0,0,18.0,330.0,1.4413577,-0.24642158,18.048477,349.00809,-11.345277
155.8613,-0.15258439,11.467302,0.0,0,18.0,330.0,1.4481125,-0.43475747,18.043129,349.63062,-11.360878
156.6618,-0.047248613,11.58321,0.0,0,18.0,4.1213597e-09,1.4793071,-0.1380589,18.002159,325.7814,-11.478917
157.7618,-0.041712232,11.583059,0.0,0,18.0,4.116316e-24,1.4793845,-0.11851453,17.999498,306.37796,-11.478561
158.8618,-0.043060083,11.582927,0.0,0,18.0,4.1112794e-39,1.4793009,-0.1286702,18.000298,296.58792,-11.478862
159.9618,-0.048945133,11.583599,0.0,0,18.0,1.4012985e-45,1.4792875,-0.13944922,18.000044,287.21298,-11.478834
161.0618,-0.042259749,11.583158,0.0,0,18.0,1.4012985e-45,1.4793108,-0.12131179,18.000839,276.54428,-11.479385
162.1618,-0.045862295,11.583895,0.0,0,18.0,1.4012985e-45,1.4797001,-0.13483068,18.000214,268.50891,-11.479216
163.2618,-0.048651088,11.583379,0.0,0,18.0,1.4012985e-45,1.4793689,-0.14141592,17.999939,263.35312,-11.479301
164.3618,-0.043532174,11.58307,0.0,0,18.0,1.4012985e-45,1.4794395,-0.12469597,18.000839,255.10132,-11.478334
165.4618,-0.04781587,11.584172,0.0,0,18.0,1.4012985e-45,1.4795362,-0.1400106,18.000504,246.78651,-11.479043
166.5618,-0.048587151,11.584168,0.0,0,18.0,1.4012985e-45,1.4794964,-0.13857096,18.000204,238.51926,-11.478986
167.6618,-0.043473251,11.584102,0.0,0,18.0,1.4012985e-45,1.4796726,-0.12595175,18.000652,232.56007,-11.479137
168.7618,-0.049994037,11.583574,0.0,0,18.0,1.4012985e-45,1.4795979,-0.14816934,17.99938,224.22806,-11.479173
169.8618,-0.047454484,11.584723,0.0,0,18.0,1.4012985e-45,1.4797701,-0.13625327,18.000786,211.50565,-11.479519
170.9618,-0.044072222,11.585154,0.0,0,18.0,1.4012985e-45,1.4800162,-0.12929557,17.999996,203.62915,-11.47947
172.0618,-0.052150417,11.585396,0.0,0,18.0,1.4012985e-45,1.4798772,-0.15501153,17.999767,196.73007,-11.479442
173.1618,-0.046050426,11.585059,0.0,0,18.0,1.4012985e-45,1.4797597,-0.13134415,17.999657,191.22913,-11.479433
174.2618,-0.044558048,11.585587,0.0,0,18.0,1.4012985e-45,1.480178,-0.1325991,18.000694,182.14937,-11.479301
175.3618,-0.051567297,11.585,0.0,0,18.0,1.4012985e-45,1.4798636,-0.14909989,17.998535,178.19382,-11.479341
176.4618,-0.04498649,11.585721,0.0,0,18.0,1.4012985e-45,1.4801005,-0.128674,18.00094,175.22891,-11.479099
177.5618,-0.045695148,11.585707,0.0,0,18.0,1.4012985e-45,1.4801018,-0.13601309,18.000168,169.58667,-11.478557
178.6618,-0.052032217,11.585918,0.0,0,18.0,1.4012985e-45,1.479986,-0.14915223,18.000557,163.51184,-11.478661
179.7618,-0.043360922,11.58598,0.0,0,18.0,1.4012985e-45,1.4801955,-0.12215518,18.000076,159.18201,-11.478779
180.8618,-0.047742873,11.586201,0.0,0,18.0,1.4012985e-45,1.4803531,-0.13995968,18.000475,154.78709,-11.479131
181.9618,-0.05006941,11.587243,0.0,0,18.0,1.4012985e-45,1.4804341,-0.14536835,18.000603,152.60912,-11.479299
183.0618,-0.044190209,11.587296,0.0,0,18.0,1.4012985e-45,1.4806886,-0.12939256,18.000229,147.61824,-11.479551
184.1618,-0.050358631,11.587869,0.0,0,18.0,1.4012985e-45,1.4806209,-0.14738844,18.000168,143.52118,-11.4793
185.2618,-0.048550561,11.587223,0.0,0,18.0,1.4012985e-45,1.4804555,-0.1402653,18.000435,137.27164,-11.479264
186.3618,-0.044377375,11.587993,0.0,0,18.0,1.4012985e-45,1.4809121,-0.12996422,18.000834,130.84109,-11.479328
187.4618,-0.050742716,11.588404,0.0,0,18.0,1.4012985e-45,1.4808828,-0.14928947,17.99938,123.62656,-11.479768
188.5618,-0.049061235,11.587658,0.0,0,18.0,1.4012985e-45,1.4806812,-0.13988559,17.999609,121.59686,-11.479792
189.6618,-0.044441082,11.588279,0.0,0,18.0,1.4012985e-45,1.4809082,-0.13212611,18.00012,114.37327,-11.479856
190.7618,-0.050683007,11.588982,0.0,0,18.0,1.4012985e-45,1.4808954,-0.14526628,17.99942,110.94173,-11.479958
191.8618,-0.046854064,11.588793,0.0,0,18.0,1.4012985e-45,1.4810137,-0.13645318,18.001135,104.41335,-11.480055
192.9618,-0.045299429,11.588933,0.0,0,18.0,1.4012985e-45,1.4811603,-0.13262329,18.000135,97.943367,-11.480156
194.0618,-0.052152865,11.588953,0.0,0,18.0,1.4012985e-45,1.4809946,-0.15053298,18.000231,98.273239,-11.480066
195.1618,-0.045198247,11.589486,0.0,0,18.0,1.4012985e-45,1.481318,-0.12721987,17.999662,96.534111,-11.480225
196.2618,-0.047097985,11.589872,0.0,0,18.0,1.4012985e-45,1.4811912,-0.13866864,18.000019,93.535591,-11.480295
197.3618,-0.051590201,11.589609,0.0,0,18.0,1.4012985e-45,1.4811683,-0.14794177,17.99984,91.1632,-11.479967
198.4618,-0.044130877,11.589812,0.0,0,18.0,1.4012985e-45,1.4814522,-0.12804534,18.000166,87.737267,-11.480126
199.5618,-0.049035653,11.590238,0.0,0,18.0,1.4012985e-45,1.4813619,-0.14453621,18.000635,86.598053,-11.480274
200.6618,-0.051598921,11.590276,0.0,0,18.0,1.4012985e-45,1.481495,-0.14679299,17.999723,86.450241,-11.479974
201.7618,-0.044096418,11.590833,0.0,0,18.0,1.4012985e-45,1.4815365,-0.12585734,17.998095,84.004936,-11.48019
202.8618,-0.050785832,11.590775,0.0,0,18.0,1.4012985e-45,1.4814399,-0.14612554,18.000723,82.745224,-11.480067
203.9618,-0.050650876,11.590358,0.0,0,18.0,1.4012985e-45,1.4815826,-0.1405015,18.000465,80.353355,-11.479759
205.0618,-0.044485882,11.59125,0.0,0,18.0,1.4012985e-45,1.4817528,-0.12995273,17.999516,79.478226,-11.479921
206.1618,-0.052165311,11.591426,0.0,0,18.0,1.4012985e-45,1.4817464,-0.1505302,18.000431,77.715393,-11.480148
207.2618,-0.048847985,11.591691,0.0,0,18.0,1.4012985e-45,1.4819318,-0.1385261,17.999601,75.268723,-11.479784
208.3618,-0.045816053,11.59163,0.0,0,18.0,1.4012985e-45,1.4816463,-0.13346736,18.000338,73.729225,-11.48006
209.4618,-0.052090749,11.591966,0.0,0,18.0,1.4012985e-45,1.4819628,-0.15247448,18.000027,72.477966,-11.4802
210.5618,-0.047859561,11.591733,0.0,0,18.0,1.4012985e-45,1.4819601,-0.13421513,17.999292,70.933777,-11.479906
211.6618,-0.047767557,11.591692,0.0,0,18.0,1.4012985e-45,1.4817958,-0.13881157,18.000154,70.281944,-11.479996
212.7618,-0.052186824,11.592158,0.0,0,18.0,1.4012985e-45,1.4820665,-0.15038042,17.999327,69.088951,-11.479989
213.8618,-0.04805395,11.592116,0.0,0,18.0,1.4012985e-45,1.4818479,-0.13742869,18.000444,67.949646,-11.479826
214.9618,-0.049199522,11.592512,0.0,0,18.0,1.4012985e-45,1.4820242,-0.14450862,18.000031,67.675293,-11.479753
215.8618,-0.051015273,11.592326,0.0,0,18.0,1.4012985e-45,1.4820579,-0.14963,17.999403,66.189461,-11.479863