File: examples/dan-msc-case-studies/CS3/data/01 raw data/baron_test_141.csv
Time(sec),Force(kN),Jaw(mm),PowAngle(deg),Power(W),Pram,PTemp,Strain,Stress(MPa),Stroke(mm),TC1(C),wedge(mm)
0.0,1.2054889,0.87526637,0.0,0,10.594783,0.00034301257,0.060152978,14.486876,10.594352,27.713997,-9.1065006
2.1,1.0890164,-0.0037512095,0.0,0,10.594783,6.2159019,-0.00023439845,13.869676,10.594758,27.616381,-9.4756956
4.2,1.0621237,-0.0036889368,0.0,0,10.594783,12.515903,-0.00024286809,13.514683,10.595764,27.518991,-9.4729204
6.3,1.0314815,-0.0032817165,0.0,0,10.594783,18.815903,-0.00022970364,13.145755,10.595529,27.515184,-9.4694986
8.4,1.0198599,-0.0032010588,0.0,0,10.594783,25.115906,-0.00023101074,12.978897,10.59487,27.467134,-9.4658747
10.5,1.0130212,-0.0027570862,22.974453,0,10.594783,31.415909,-0.00020667422,12.888033,10.595237,27.445908,-9.4625683
12.6,1.0069377,-0.0035059724,41.070805,0,10.594783,37.715919,-0.00024793044,12.835936,10.594236,29.534723,-9.4596872
14.7,1.0298318,-0.0071504815,49.599323,0,10.594783,44.015915,-0.00047011269,13.124123,10.594414,34.597572,-9.4562263
16.8,1.0563347,-0.014352283,54.180431,0,10.594783,50.315907,-0.00095060753,13.447722,10.595226,41.950981,-9.4529409
18.9,1.0793607,-0.021931585,55.535881,0,10.594783,56.61591,-0.0014546942,13.767573,10.594895,51.704742,-9.4492359
21.0,1.0915369,-0.029691834,55.445633,0,10.594783,62.91592,-0.0019757238,13.933744,10.595997,60.931305,-9.4465055
23.1,1.1077331,-0.036804631,53.976105,0,10.594783,69.215904,-0.0024432715,14.122077,10.594318,69.880287,-9.4427137
25.2,1.1155781,-0.042786118,51.585442,0,10.594783,75.515907,-0.002829476,14.237674,10.59406,78.160072,-9.4392939
27.3,1.1093084,-0.047444656,49.636234,0,10.594783,81.815933,-0.0031349165,14.186908,10.593915,84.707924,-9.4360542
29.4,1.1052256,-0.050620895,48.81226,0,10.594783,88.115929,-0.0033653467,14.10711,10.595002,89.858963,-9.433115
31.5,1.1032087,-0.054011367,49.296055,0,10.594783,94.415916,-0.003604226,14.092191,10.594463,94.71595,-9.4298887
33.6,1.1109577,-0.057775319,51.196072,0,10.594783,100.71591,-0.0038661144,14.205431,10.594049,99.256844,-9.4265776
35.7,1.1063684,-0.062515944,52.9758,0,10.594783,107.01592,-0.004177154,14.14639,10.59462,104.64957,-9.4232073
37.8,1.1183939,-0.067704789,54.305241,0,10.594783,113.31594,-0.0045193736,14.296709,10.594805,110.8714,-9.4190836
39.9,1.1310089,-0.073849946,55.27277,0,10.594783,119.61594,-0.0049227565,14.481724,10.595253,117.48897,-9.4160252
42.0,1.123654,-0.079180814,55.843506,0,10.594783,125.91593,-0.0052576824,14.390245,10.594714,124.3247,-9.4126997
44.1,1.132732,-0.085135609,56.425766,0,10.594783,132.21591,-0.0056489347,14.484044,10.594829,131.01723,-9.4095259
46.2,1.1517094,-0.090597011,56.554501,0,10.594783,138.51595,-0.0060188887,14.749882,10.594732,137.80676,-9.406374
48.3,1.1361678,-0.097237937,56.985909,0,10.594783,144.81592,-0.0064604934,14.57759,10.593364,143.94617,-9.4027472
50.4,1.1388543,-0.10245697,57.260738,0,10.594783,151.11594,-0.006802062,14.585329,10.594682,150.23299,-9.3992462
52.5,1.1560727,-0.10852798,57.535397,0,10.594783,157.41592,-0.0072007049,14.81,10.594569,156.91156,-9.3959455
54.6,1.1447222,-0.11395252,57.535397,0,10.594783,163.71593,-0.0075531234,14.693198,10.59367,163.43265,-9.3928394
56.7,1.1375954,-0.11996924,57.809814,0,10.594783,170.01596,-0.0079515129,14.58689,10.594733,169.55748,-9.3890381
58.8,1.1585863,-0.12506092,58.073727,0,10.594783,176.31593,-0.0082938587,14.856036,10.595074,175.7186,-9.3865547
60.9,1.154686,-0.13109328,58.337399,0,10.594783,182.61595,-0.0087049305,14.827199,10.594845,182.09021,-9.3825941
63.0,1.1525525,-0.1367532,58.59008,0,10.594783,188.91594,-0.0090855742,14.833266,10.594902,188.21956,-9.3791904
65.1,1.1525408,-0.14199948,59.106438,0,10.594783,195.21594,-0.0094368346,14.814231,10.594908,194.34514,-9.3755579
67.2,1.1595076,-0.14873996,59.346088,0,10.594783,201.51596,-0.0098832939,14.899452,10.594919,200.88179,-9.3722582
69.3,1.1537408,-0.15375991,59.190666,0,10.594783,207.81595,-0.010209517,14.850574,10.594287,207.59349,-9.3688993
71.4,1.1485837,-0.15890841,59.347034,0,10.594783,214.11595,-0.010541927,14.771369,10.594395,213.8847,-9.3656664
73.5,1.1608545,-0.16567087,59.518967,0,10.594783,220.41594,-0.010977144,14.933857,10.595106,220.04141,-9.3628626
75.6,1.1480217,-0.17039627,59.811577,0,10.594783,226.71594,-0.011282017,14.802141,10.595119,226.13585,-9.3589773
77.7,1.1535869,-0.17550759,60.084225,0,10.594783,233.01598,-0.011628197,14.88308,10.596222,232.31081,-9.3555298
79.8,1.1495142,-0.18241268,60.517845,0,10.594783,239.31596,-0.012081185,14.80087,10.5947,238.49059,-9.351573
81.9,1.1591535,-0.18724567,60.683117,0,10.594783,245.61597,-0.01239514,14.956812,10.593557,244.98833,-9.3487177
84.0,1.1485695,-0.19275586,60.895283,0,10.594783,251.91595,-0.012747523,14.815793,10.595414,251.32175,-9.3451567
86.1,1.1543554,-0.19892135,61.149563,0,10.594783,258.21619,-0.013154246,14.885769,10.594508,257.56049,-9.3419189
88.2,1.1531302,-0.20385672,61.468498,0,10.594783,264.51599,-0.013496064,14.880227,10.594962,263.74835,-9.3386011
90.3,1.1574682,-0.20890661,61.688229,0,10.594783,270.81598,-0.013831258,14.950865,10.593924,270.09644,-9.3354588
92.4,1.1467687,-0.21492313,61.907955,0,10.594783,277.11597,-0.0142338,14.804375,10.594941,276.54623,-9.3323078
94.5,1.1585774,-0.22078152,62.116692,0,10.594783,283.41595,-0.014619675,14.968874,10.594464,282.84201,-9.328557
96.6,1.1614021,-0.22672999,62.336418,0,10.594783,289.71594,-0.015033125,15.023566,10.593155,289.03168,-9.3251543
98.7,1.1471462,-0.2323146,62.753899,0,10.594783,296.01602,-0.015393311,14.830101,10.594477,295.11063,-9.3212156
100.8,1.1592931,-0.23855296,63.171383,0,10.594783,302.31595,-0.015786767,14.999499,10.594824,301.2052,-9.3176899
102.9,1.1652578,-0.24522562,63.52095,0,10.594783,308.61594,-0.016230674,15.09323,10.595268,307.62054,-9.3147001
105.0,1.1524969,-0.25053784,63.775627,0,10.594783,314.91595,-0.016562087,14.924404,10.594934,313.86551,-9.3116341
107.1,1.1599755,-0.25590262,63.973385,0,10.594783,321.21597,-0.016903507,15.01419,10.594982,320.4516,-9.308053
109.2,1.1738997,-0.26285094,64.171135,0,10.594783,327.51602,-0.017359382,15.202637,10.593262,326.82413,-9.3048601
111.3,1.1481894,-0.26808134,64.357903,0,10.594783,333.81598,-0.017719751,14.877347,10.59363,333.34204,-9.3017149
113.4,1.1600854,-0.27378181,64.357903,0,10.594783,340.11597,-0.018088305,15.028692,10.59484,339.77487,-9.2981253
115.5,1.1670876,-0.27965793,64.555656,0,10.594783,346.41599,-0.018459974,15.133407,10.594812,345.9433,-9.2943125
117.6,1.1567903,-0.28637221,64.742432,0,10.594783,352.716,-0.018900678,15.021218,10.595024,352.05725,-9.2905197
119.7,1.1614572,-0.29410458,65.115593,0,10.594783,359.01602,-0.019397156,15.067324,10.594076,358.17563,-9.2867241
121.8,1.1527181,-0.2995365,65.302727,0,10.594783,365.31601,-0.019753493,14.953287,10.593873,364.47333,-9.2833424
123.9,1.1647072,-0.30518541,65.478508,0,10.594783,371.61597,-0.020130539,15.146307,10.594607,370.80609,-9.2803078
126.0,1.1541786,-0.3117868,65.832947,0,10.594783,377.91599,-0.020558221,15.009454,10.594848,377.09879,-9.277422
128.1,1.1539363,-0.31747565,65.848145,0,10.594783,384.216,-0.02093591,14.990853,10.595049,383.66885,-9.274003
130.2,1.1554511,-0.32423732,65.666985,0,10.594783,390.51602,-0.021377835,15.040423,10.594089,390.58939,-9.2705898
132.3,1.1646332,-0.3282139,65.468323,0,10.594783,396.81598,-0.021653369,15.151823,10.594228,397.48047,-9.2670717
134.4,1.156333,-0.33354923,63.797077,0,10.594783,399.99893,-0.02200198,15.046061,10.594378,403.69937,-9.2648382
136.5,1.1532428,-0.33512223,59.859867,0,10.594783,399.99893,-0.022113746,15.011876,10.594083,407.84689,-9.2645893
138.6,1.1147292,-0.33422068,55.536339,0,10.594783,399.99893,-0.022051124,14.531658,10.594385,408.80682,-9.264102
140.7,1.0789083,-0.33104554,52.287785,0,10.594783,399.99893,-0.021839391,14.035604,10.595022,407.00623,-9.2646151
142.8,1.0517831,-0.32652614,51.931877,0,10.594783,399.99893,-0.021554569,13.675137,10.594815,403.36371,-9.2648468
144.9,1.0412174,-0.32394403,53.588448,0,10.594783,399.99893,-0.021380177,13.543528,10.595026,399.71823,-9.2646837
147.0,1.0369707,-0.32334256,55.991138,0,10.594783,399.99893,-0.021339402,13.484127,10.594646,397.14352,-9.2653742
149.1,1.0562316,-0.32240945,58.0228,0,10.594783,399.99893,-0.021276597,13.738527,10.594646,396.3269,-9.2650337
151.2,1.0772791,-0.32433224,59.251652,0,10.594783,399.99893,-0.021398915,14.007605,10.594366,396.85217,-9.2644978
153.3,1.0800092,-0.32670712,59.457554,0,10.594783,399.99893,-0.021548958,14.081509,10.594205,398.33914,-9.2643347
155.4,1.1026046,-0.32893339,59.106449,0,10.594783,399.99893,-0.021681502,14.352532,10.594478,399.79745,-9.2639618
157.5,1.1093674,-0.32883856,58.33778,0,10.594783,399.99893,-0.021676078,14.438617,10.594249,400.85883,-9.264101
159.6,1.098135,-0.3301602,57.535412,0,10.594783,399.99893,-0.021762287,14.299756,10.59435,401.48395,-9.264061
161.7,1.081311,-0.32980663,56.797832,0,10.594783,399.99893,-0.021748256,14.074159,10.595546,401.46628,-9.2644777
163.8,1.0859638,-0.33004186,56.427624,0,10.594783,399.99893,-0.02176773,14.141505,10.595952,401.03116,-9.2650356
165.9,1.0718352,-0.32990721,56.539028,0,10.594783,399.99893,-0.021752773,13.945825,10.594229,400.33328,-9.2646627
168.0,1.0667042,-0.33025143,56.711422,0,10.594783,399.99893,-0.021780731,13.891419,10.594307,399.82639,-9.2643061
170.1,1.0720813,-0.33053911,56.986084,0,10.594783,399.99893,-0.021792248,13.94698,10.594686,399.61127,-9.2637663
172.2,1.074952,-0.33033887,57.264957,0,10.594783,399.99893,-0.021771843,13.989505,10.595003,399.50226,-9.263875
174.3,1.07874,-0.33154634,57.533718,0,10.594783,399.99893,-0.021847449,14.049583,10.594684,399.68143,-9.2638321
176.4,1.083023,-0.33297947,57.260746,0,10.594783,399.99893,-0.02194714,14.092985,10.595284,400.06433,-9.2636147
178.4633,1.1007805,-0.010868333,57.005966,0,10.594783,399.99893,-0.00073457957,14.021494,10.594059,400.2886,-9.2637339
178.6172,1.1044832,0.0017925058,56.986084,0,10.5948,1.8720307e-23,0.00018828617,14.069564,10.595365,400.34518,-9.2627306
178.6214,1.1073513,0.0072594294,56.986084,0,10.5948,0.0,0.0003967208,14.177329,10.594855,400.33252,-9.2627592
178.6256,1.0917733,0.00608359,34.830822,0,10.5948,0.0,0.00059579225,13.903837,10.59276,400.34323,-9.2654428
178.6298,1.0741341,0.0081515769,10.8487,0,10.5948,0.0,0.00054520939,13.683648,10.592696,400.3559,-9.2653522
178.634,1.0740176,0.011232548,0.0,0,10.5948,0.0,0.00052792992,13.572425,10.594594,400.29227,-9.2639055
178.6382,1.0830353,0.006536677,0.0,0,10.5948,0.0,0.00062084943,13.808731,10.592882,400.16559,-9.2644215
178.6424,1.0991951,0.004667182,0.0,0,10.5948,0.0,0.00029447125,13.943112,10.591668,400.07367,-9.2637501
178.6466,1.1064092,0.0084445598,0.0,0,10.5948,0.0,0.00045112616,14.038659,10.597101,400.14969,-9.2637024
178.6508,1.1041217,0.00613624,0.0,0,10.5948,0.0,0.00061269815,13.948231,10.59351,400.22568,-9.2645006
178.655,1.0830084,0.0083690807,0.0,0,10.5948,0.0,0.00049504178,13.777712,10.590597,400.25131,-9.265419
178.6592,1.055472,0.011207906,0.0,0,10.5948,0.0,0.00057435641,13.46197,10.594608,400.26401,-9.264677
178.6634,1.059229,0.0053546615,0.0,0,10.5948,0.0,0.00059494656,13.48524,10.591896,400.28729,-9.2633924
178.6676,1.052057,0.0062896353,0.0,0,10.533863,0.0,0.00032092785,13.399485,10.5941,400.32529,-9.2635164
178.6718,1.0718601,0.0068596057,0.0,0,10.470863,0.0,0.00043515029,13.626904,10.586902,400.36218,-9.2629604
178.676,1.0891377,0.0052435151,0.0,0,10.407864,0.0,0.00055221113,13.856015,10.557291,400.37485,-9.2634296
178.6802,1.0757143,0.0086753182,0.0,0,10.344863,0.0,0.00045697746,13.654574,10.482109,400.38751,-9.2663193
178.6844,1.0668117,0.010664335,0.0,0,10.281863,0.0,0.00060818123,13.545372,10.37895,400.36639,-9.2645245
178.6886,1.0465791,0.0053801709,0.0,0,10.218863,0.0,0.00058355782,13.343649,10.299079,400.3284,-9.2638655
178.6928,1.0373846,0.0066449284,0.0,0,10.155864,0.0,0.00029936503,13.210526,10.24234,400.29041,-9.2638474
178.697,1.0412657,0.0076832827,0.0,0,10.092863,0.0,0.00051157182,13.310803,10.187957,400.25238,-9.263155
178.7012,1.0671929,0.0043723141,0.0,0,10.029862,0.0,0.00043059365,13.504866,10.133565,400.21439,-9.2645292
178.7054,1.6363729,0.011552203,0.0,0,9.9668627,0.0,0.00057415263,20.42378,10.067354,400.60492,-9.2633896
178.7096,4.3373241,0.028784808,0.0,0,9.903863,0.0,0.001965438,54.797882,10.010743,401.03561,-9.2627983
178.7138,5.6654787,0.07629358,0.0,0,9.8408632,0.0,0.0052525676,71.654045,9.9424,404.41434,-9.2614975
178.718,5.8802214,0.15133457,0.0,0,9.7778625,0.0,0.0099227987,74.146706,9.8666515,410.32349,-9.2597389
178.7222,5.9409318,0.22125715,0.0,0,9.7148628,0.0,0.014824842,74.496704,9.79498,416.22418,-9.2600231
178.7264,5.948947,0.28413147,0.0,0,9.6518631,0.0,0.019194206,74.2145,9.7300177,422.08124,-9.2608719
178.7306,5.9672003,0.34696195,0.0,0,9.5888634,0.0,0.023026308,74.275833,9.6724482,427.93826,-9.2597752
178.7348,6.020524,0.40402174,0.0,0,9.5258627,0.0,0.027436811,74.630234,9.6115313,429.71884,-9.2613468
178.739,6.0339913,0.46239009,0.0,0,9.4633284,0.0,0.031360783,74.52961,9.5428276,430.38773,-9.2622643
178.7432,6.0635834,0.52617258,0.0,0,9.4018736,0.0,0.035480291,74.526321,9.484354,430.96875,-9.2617979
178.7474,6.1054282,0.58859807,0.0,0,9.3404188,0.0,0.040119305,74.680969,9.4201593,431.4231,-9.2610502
178.7516,6.1368685,0.65091354,0.0,0,9.278965,0.0,0.044374797,74.755424,9.3558769,431.87155,-9.2609043
178.7558,6.1872692,0.72245455,0.0,0,9.2175102,0.0,0.048968975,74.835442,9.2875433,432.1492,-9.2625227
178.76,6.1725197,0.77402478,0.0,0,9.1560564,0.0,0.053163633,74.537201,9.2293434,432.42685,-9.2621984
178.7642,6.2187476,0.83145976,0.0,0,9.0946016,0.0,0.056951962,74.866348,9.1688757,432.62155,-9.2608175
178.7684,6.2588758,0.89316887,0.0,0,9.0331469,0.0,0.061206672,74.964745,9.1112385,432.77301,-9.2633667
178.7726,6.3095965,0.9561913,0.0,0,8.9716921,0.0,0.066054061,75.254623,9.0427732,432.90317,-9.2617369
178.7768,6.3325715,1.0208272,0.0,0,8.9102383,0.0,0.07043086,75.088486,8.9760056,432.97888,-9.2613964
178.781,6.3475933,1.0861652,0.0,0,8.8487835,0.0,0.074894667,74.959427,8.9152021,433.05463,-9.2624483
178.7852,6.3657017,1.1423119,0.0,0,8.7873297,0.0,0.07942234,74.751144,8.8546085,433.06183,-9.2614794
178.7894,6.4052529,1.1969107,0.0,0,8.7270651,0.0,0.083018176,75.056725,8.7952795,433.06183,-9.2621918
178.7936,6.4739051,1.2617816,0.0,0,8.6686182,0.0,0.087703347,75.510933,8.7308998,433.06183,-9.2624226
178.7978,6.4777651,1.3194748,0.0,0,8.6101704,0.0,0.092288598,75.233315,8.6711245,433.06183,-9.2615023
178.802,6.4933786,1.3816599,0.0,0,8.5517225,0.0,0.096373647,75.017197,8.6087246,433.07336,-9.2626705
178.8062,6.5296969,1.4422597,0.0,0,8.4932756,0.0,0.10087281,75.144943,8.5477018,433.14908,-9.2620249
178.8104,6.5266957,1.4943677,0.0,0,8.4348288,0.0,0.10520868,74.80529,8.4889393,433.22482,-9.2622404
178.8146,6.5329061,1.5508986,0.0,0,8.3763819,0.0,0.10890941,74.510231,8.4351473,433.32013,-9.263236
178.8188,6.6098266,1.6070017,0.0,0,8.317934,0.0,0.11326355,75.095001,8.3778286,433.42111,-9.2627363
178.823,6.677866,1.6662898,0.0,0,8.2594872,0.0,0.11790365,75.445724,8.3179207,433.51199,-9.2614136
178.8272,6.718709,1.730875,0.0,0,8.2010403,0.0,0.12226583,75.646751,8.253787,433.58771,-9.2614079
178.8314,6.7269397,1.7913036,0.0,0,8.1425934,0.0,0.12708679,75.30365,8.1965227,433.66403,-9.2630396
178.8356,6.7478728,1.8410424,0.0,0,8.0841455,0.0,0.13127512,75.371284,8.1371946,433.76498,-9.2614002
178.8398,6.7603717,1.9050415,0.0,0,8.0270929,0.0,0.13556841,75.249504,8.0779362,433.86597,-9.2613401
178.844,6.7751131,1.9631385,0.0,0,7.9714847,0.0,0.14029972,74.987541,8.0170908,433.91791,-9.2632284
178.8482,6.7928991,2.0130985,0.0,0,7.9158769,0.0,0.14428218,74.861473,7.9647436,433.94315,-9.2630453
178.8524,6.8493633,2.0727115,0.0,0,7.8602691,0.0,0.14833561,75.182487,7.908586,433.97522,-9.2623348
178.8566,6.8974051,2.1277938,0.0,0,7.8046608,0.0,0.15304601,75.350792,7.8529115,434.0257,-9.2617855
178.8608,6.9223628,2.1784258,0.0,0,7.749053,0.0,0.15703453,75.299736,7.7922778,434.0762,-9.2620392
178.865,6.9367857,2.2371702,0.0,0,7.6934452,0.0,0.16125795,75.113136,7.7337899,434.22836,-9.2608366
178.8692,6.955565,2.2913897,0.0,0,7.6378369,0.0,0.16586545,74.952187,7.679112,434.39243,-9.2616701
178.8734,6.9771876,2.3431458,0.0,0,7.5822291,0.0,0.16989508,74.958641,7.6262803,434.52371,-9.2614565
178.8776,7.0060563,2.406363,0.0,0,7.5266209,0.0,0.17448051,74.930298,7.5677934,434.62469,-9.2631245
178.8818,7.0620356,2.4556389,0.0,0,7.4710131,0.0,0.17898257,75.118958,7.5121679,434.72748,-9.2638817
178.886,7.10462,2.5071568,0.0,0,7.4154048,0.0,0.18281753,75.372475,7.4578948,434.84106,-9.2608309
178.8902,7.1456757,2.5649593,0.0,0,7.3613925,0.0,0.18730633,75.469666,7.4037838,434.95465,-9.2619953
178.8944,7.1654758,2.6180902,0.0,0,7.3085065,0.0,0.19204621,75.295303,7.3472605,435.08759,-9.2616262
178.8986,7.1562419,2.6731498,0.0,0,7.25562,0.0,0.19620523,74.849571,7.2889285,435.22641,-9.2600222
178.9028,7.1789856,2.731317,0.0,0,7.2027335,0.0,0.20063326,74.786469,7.2393885,435.34061,-9.2616482
178.907,7.2226925,2.7800093,0.0,0,7.149847,0.0,0.20524241,74.971275,7.1812325,435.41632,-9.260149
178.9112,7.2544689,2.8308225,0.0,0,7.0969605,0.0,0.20899726,74.82917,7.130703,435.49188,-9.2610893
178.9154,7.3238058,2.8857303,0.0,0,7.0440745,0.0,0.21346758,75.237701,7.0728736,435.55496,-9.2617054
178.9196,7.3327465,2.9355485,0.0,0,6.9911876,0.0,0.2180853,75.102798,7.0276241,435.61807,-9.2609291
178.9238,7.3579335,2.9907119,0.0,0,6.9383016,0.0,0.22214544,75.015945,6.9738855,435.68921,-9.2616377
178.928,7.4026136,3.0458341,0.0,0,6.8854151,0.0,0.22668181,75.163696,6.9209337,435.76495,-9.261487
178.9322,7.4139247,3.0934055,0.0,0,6.8325286,0.0,0.23131549,74.894936,6.8630538,435.83075,-9.2608767
178.9364,7.4294357,3.1455019,0.0,0,6.7796421,0.0,0.23506743,74.700798,6.8120499,435.86862,-9.2623158
178.9406,7.5036411,3.2018886,0.0,0,6.7285075,0.0,0.23993406,75.104866,6.7556071,435.90646,-9.2613182
178.9448,7.5388508,3.2503109,0.0,0,6.6781917,0.0,0.24445041,75.158035,6.7056746,435.93314,-9.2607784
178.949,7.5702066,3.3063734,0.0,0,6.6278753,0.0,0.24864812,75.101295,6.6522646,435.95837,-9.2606945
178.9532,7.5760684,3.3594339,0.0,0,6.5775595,0.0,0.25338456,74.844902,6.5992885,436.01578,-9.2623358
178.9574,7.5598841,3.3993006,0.0,0,6.5272436,0.0,0.25737244,74.479469,6.5494456,436.10413,-9.2616739
178.9616,7.5597043,3.4473646,0.0,0,6.4769278,0.0,0.26078829,74.203178,6.5065198,436.19415,-9.2608185
178.9658,7.6372576,3.4964707,0.0,0,6.4266119,0.0,0.26543871,74.575874,6.4535961,436.2951,-9.260745
178.97,7.6875148,3.5454443,0.0,0,6.3762956,0.0,0.26994386,74.692108,6.3983989,436.39609,-9.2604322
178.9742,7.7531362,3.6041956,0.0,0,6.3259797,0.0,0.2743184,74.983063,6.3526421,436.47794,-9.2621279
178.9784,7.786653,3.6519637,0.0,0,6.2756643,0.0,0.27903301,74.91787,6.2971721,436.55365,-9.2609653
178.9826,7.7891665,3.6970055,0.0,0,6.225348,0.0,0.28321493,74.781532,6.251018,436.61975,-9.2619686
178.9868,7.8686328,3.7500713,0.0,0,6.1750321,0.0,0.28732005,75.18924,6.1965852,436.67026,-9.2604542
178.991,7.8733268,3.799629,0.0,0,6.1266274,0.0,0.2922115,74.962425,6.1480742,436.72049,-9.2617931
178.9952,7.8818793,3.8475668,0.0,0,6.078773,0.0,0.29647258,74.665405,6.1001792,436.72049,-9.2609606
178.9994,7.914948,3.9020135,0.0,0,6.0309181,0.0,0.30069953,74.59153,6.0495081,436.72049,-9.2603025
179.0036,7.9542866,3.9497049,0.0,0,5.9830637,0.0,0.30580989,74.526192,5.9976802,436.75223,-9.2620525
179.0078,7.9831324,3.9916911,0.0,0,5.9352083,0.0,0.30947623,74.593575,5.9539113,436.8027,-9.2616482
179.012,8.0134697,4.0406322,0.0,0,5.8873539,0.0,0.31350145,74.534241,5.900784,436.86276,-9.2612677
179.0162,8.0462341,4.084578,0.0,0,5.839499,0.0,0.31810054,74.539352,5.8604007,436.95111,-9.2608232
179.0204,8.0852699,4.1324396,0.0,0,5.7916441,0.0,0.3222546,74.599258,5.8089542,437.03946,-9.2616472
179.0246,8.1337814,4.1892943,0.0,0,5.7437892,0.0,0.32694274,74.693459,5.7601295,437.08356,-9.26052
179.0288,8.1611395,4.2317052,0.0,0,5.6959343,0.0,0.33179063,74.571419,5.7108941,437.12143,-9.2610006
179.033,8.178319,4.2763362,0.0,0,5.6480799,0.0,0.33555442,74.390373,5.6635981,437.14667,-9.2604132
179.0372,8.238018,4.3281679,0.0,0,5.6002245,0.0,0.34011605,74.675621,5.6159444,437.1593,-9.2598438
179.0414,8.2962027,4.3746872,0.0,0,5.5543995,0.0,0.34517223,74.799995,5.5686603,437.17191,-9.2627048
179.0456,8.2975845,4.4189911,0.0,0,5.5088711,0.0,0.34882611,74.574356,5.5197434,437.18451,-9.2608452
179.0498,8.340353,4.4722214,0.0,0,5.4633431,0.0,0.35354555,74.527367,5.4743624,437.19714,-9.2602444
179.054,8.3880463,4.5099497,0.0,0,5.4178152,0.0,0.35802802,74.701241,5.4299374,437.21921,-9.259655
179.0582,8.3690195,4.5565987,0.0,0,5.3722873,0.0,0.36191341,74.248657,5.3814511,437.24445,-9.2610607
179.0624,8.3882666,4.6028333,0.0,0,5.3267593,0.0,0.36627319,74.080261,5.3397865,437.27438,-9.2613907
179.0666,8.4615669,4.6421509,0.0,0,5.2812314,0.0,0.37077236,74.316299,5.2905703,437.31223,-9.2601929
179.0708,8.5082321,4.6915388,0.0,0,5.2357035,0.0,0.37470028,74.472786,5.2502499,437.3501,-9.261095
179.075,8.564539,4.7370887,0.0,0,5.1901751,0.0,0.37924945,74.579552,5.2049675,437.40051,-9.2609911
179.0792,8.6701412,4.7786288,0.0,0,5.1446471,0.0,0.38394189,75.237854,5.1586094,437.45099,-9.2605343
179.0834,8.6892395,4.827785,0.0,0,5.0991192,0.0,0.38808322,75.070267,5.108294,437.49188,-9.2614403
179.0876,8.687439,4.8770356,0.0,0,5.0535917,0.0,0.39322287,74.692673,5.0629601,437.52686,-9.260725
179.0918,8.693306,4.9189548,0.0,0,5.0102162,0.0,0.39776558,74.393433,5.0169559,437.56018,-9.2616758
179.096,8.7400789,4.9665723,0.0,0,4.9669142,0.0,0.4016116,74.453209,4.9754891,437.56018,-9.2614012
179.1002,8.8153734,5.0141134,0.0,0,4.9236121,0.0,0.40679148,74.687424,4.9290056,437.56018,-9.2602749
179.1044,8.8286419,5.0456033,0.0,0,4.8803105,0.0,0.41043648,74.522606,4.8837585,437.54324,-9.2609348
179.1086,8.8367834,5.093473,0.0,0,4.837008,0.0,0.41450384,74.3246,4.8456001,437.51801,-9.2614212
179.1128,8.9129581,5.1336865,0.0,0,4.7937064,0.0,0.41901517,74.679832,4.8035588,437.37354,-9.2607965
179.117,8.9581003,5.1743007,0.0,0,4.7504044,0.0,0.423311,74.720757,4.7542291,436.94443,-9.261096
179.1212,8.9847651,5.2253828,0.0,0,4.7071023,0.0,0.42768186,74.58886,4.7147803,436.51532,-9.2603827
179.1254,9.0471382,5.2646952,0.0,0,4.6638002,0.0,0.43254396,74.731071,4.6722198,435.76144,-9.2615252
179.1296,9.0853939,5.3045182,0.0,0,4.6204987,0.0,0.43653738,74.754913,4.6266365,434.97897,-9.26085
179.1338,9.1701927,5.3532538,0.0,0,4.5771961,0.0,0.44090796,75.012405,4.584116,434.44315,-9.2621794
179.138,9.2453985,5.3941932,0.0,0,4.5340266,0.0,0.44584256,75.383621,4.5428996,434.11499,-9.2605782
179.1422,9.244813,5.4366412,0.0,0,4.4928327,0.0,0.45024639,75.035248,4.4993687,433.85837,-9.2607203
179.1464,9.2543163,5.4846044,0.0,0,4.4516387,0.0,0.45442948,74.799339,4.4558692,433.95935,-9.2601814
179.1506,9.3047438,5.5203767,0.0,0,4.4104447,0.0,0.45931861,74.875641,4.415803,434.06033,-9.2622795
179.1548,9.3540621,5.5581913,0.0,0,4.3692513,0.0,0.46291348,74.923141,4.3717628,434.18124,-9.2606182
179.159,9.408803,5.6052113,0.0,0,4.3280578,0.0,0.46745318,75.02697,4.3304896,434.30743,-9.2612457
179.1632,9.4091969,5.641345,0.0,0,4.2868643,0.0,0.47217295,74.671432,4.2889147,434.47025,-9.2620459
179.1674,9.4856396,5.6803217,0.0,0,4.2456708,0.0,0.47582442,75.048798,4.2503304,434.68478,-9.2610865
179.1716,9.5807562,5.7301416,0.0,0,4.2044768,0.0,0.48062932,75.404556,4.2116981,434.89886,-9.2623358
179.1758,9.6361065,5.7651987,0.0,0,4.1632833,0.0,0.4855338,75.527122,4.1697912,435.1008,-9.2606535
179.18,9.6790228,5.8045535,0.0,0,4.1220899,0.0,0.48917258,75.570129,4.1244283,435.3027,-9.2606373
179.1842,9.6955147,5.8480258,0.0,0,4.0808964,0.0,0.49383634,75.373978,4.0874615,435.42111,-9.2604351
179.1884,9.791378,5.8868957,0.0,0,4.0400205,0.0,0.49887222,75.645981,4.0470204,435.49683,-9.2607851
179.1926,9.8627167,5.9314466,0.0,0,4.000843,0.0,0.50304288,75.902702,4.0023923,435.54733,-9.2599602
179.1968,9.9198742,5.9772177,0.0,0,3.9616654,0.0,0.50788242,76.00647,3.9585063,435.5347,-9.2620258
179.201,9.9369287,6.0091109,0.0,0,3.922488,0.0,0.5125196,75.797722,3.9207635,435.52206,-9.2599354
179.2052,9.9903374,6.0481243,0.0,0,3.8833103,0.0,0.5158174,75.912064,3.8810723,435.49799,-9.2607594
179.2094,10.019016,6.0913057,0.0,0,3.8441327,0.0,0.52082151,75.832237,3.8486726,435.47275,-9.2606564
179.2136,10.072269,6.1258445,0.0,0,3.8049552,0.0,0.52527726,75.845787,3.8058307,435.61578,-9.259903
179.2178,10.129212,6.1683478,0.0,0,3.7657776,0.0,0.52927876,75.963211,3.7705584,435.90604,-9.2619848
179.222,10.228187,6.2113914,0.0,0,3.7265999,0.0,0.53433996,76.275787,3.7286568,436.20822,-9.2606525
179.2262,10.313221,6.2431021,0.0,0,3.687422,0.0,0.53871024,76.609879,3.6899445,436.57422,-9.260951
179.2304,10.379589,6.2870421,0.0,0,3.6482449,0.0,0.54260367,76.801949,3.6468501,436.94022,-9.2599697
179.2346,10.476479,6.3297811,0.0,0,3.609067,0.0,0.54811484,77.083382,3.6070678,437.11896,-9.2603397
179.2388,10.511295,6.3640523,0.0,0,3.5703721,0.0,0.55247426,76.953247,3.5623255,437.24515,-9.2607155
179.243,10.463964,6.408968,0.0,0,3.5331011,0.0,0.5565787,76.392021,3.529536,437.32028,-9.2607098
179.2472,10.488949,6.4403915,0.0,0,3.4958303,0.0,0.56117362,76.215897,3.496424,437.32028,-9.2623453
179.2514,10.576657,6.470612,0.0,0,3.4585595,0.0,0.56494117,76.499763,3.4584007,437.31738,-9.2594433
179.2556,10.66298,6.5128336,0.0,0,3.4212887,0.0,0.56893414,76.833862,3.4265666,437.21643,-9.2611628
179.2598,10.814883,6.5497174,0.0,0,3.3840182,0.0,0.57396716,77.5634,3.3824897,437.11548,-9.2607431
179.264,10.846029,6.5857415,0.0,0,3.3467469,0.0,0.57830119,77.447647,3.3452661,437.04745,-9.2604856
179.2682,10.91306,6.6286926,0.0,0,3.3094761,0.0,0.5824489,77.626465,3.309407,436.99695,-9.2618694
179.2724,10.969082,6.6637216,0.0,0,3.2722054,0.0,0.58784854,77.549919,3.2687976,436.93951,-9.2605286
179.2766,11.052525,6.6947594,0.0,0,3.2349346,0.0,0.59125435,77.90937,3.2358813,436.86377,-9.2606106
179.2808,11.141037,6.7401567,0.0,0,3.197664,0.0,0.59614557,78.158295,3.1962326,436.78806,-9.2599916
179.285,11.191661,6.7733731,0.0,0,3.160393,0.0,0.60101891,78.108482,3.1582918,436.70099,-9.2597733
179.2892,11.226343,6.8098187,0.0,0,3.123754,0.0,0.60514134,78.083801,3.1209345,436.61264,-9.2600145
179.2934,11.336655,6.8545012,0.0,0,3.0882976,0.0,0.60988086,78.394836,3.0838006,436.57056,-9.2588472
179.2976,11.351117,6.8808565,0.0,0,3.0528409,0.0,0.61444628,78.212776,3.0496197,436.57056,-9.2599277
179.3018,11.381377,6.9158816,0.0,0,3.0173845,0.0,0.61810851,78.119621,3.011184,436.57614,-9.2603006
179.306,11.471251,6.9528065,0.0,0,2.9819283,0.0,0.62228721,78.396568,2.9834735,436.61401,-9.259182
179.3102,11.569329,6.9834709,0.0,0,2.9464722,0.0,0.62715328,78.714005,2.944371,436.65186,-9.2609377
179.3144,11.60626,7.0186195,0.0,0,2.9110155,0.0,0.6307959,78.703636,2.9129353,436.71893,-9.2607088
179.3186,11.768787,7.062665,0.0,0,2.8755591,0.0,0.63593286,79.326111,2.8763213,436.79465,-9.2607613
179.3228,11.905032,7.0893579,0.0,0,2.8401027,0.0,0.64064348,79.862289,2.841429,436.85043,-9.2610502
179.327,12.00035,7.1300483,0.0,0,2.8046463,0.0,0.64464408,80.238983,2.8035872,436.87567,-9.2606287
179.3312,12.070463,7.1703916,0.0,0,2.7691898,0.0,0.64983767,80.221954,2.7660072,436.90021,-9.2593994
179.3354,12.120337,7.2008715,0.0,0,2.7337337,0.0,0.65469092,80.191681,2.7302067,436.88757,-9.259367
179.3396,12.160248,7.2416654,0.0,0,2.6990447,0.0,0.65880841,80.144714,2.6950164,436.87497,-9.260725
179.3438,12.204648,7.2794089,0.0,0,2.6653187,0.0,0.66384304,80.030571,2.6614013,436.91101,-9.2600365
179.348,12.305326,7.3027625,0.0,0,2.6315928,0.0,0.66793108,80.266685,2.6260436,436.97412,-9.2595024
179.3522,12.434176,7.3397002,0.0,0,2.5978665,0.0,0.67142338,80.855873,2.5914085,437.03049,-9.2599945
179.3564,12.486697,7.3763742,0.0,0,2.5641406,0.0,0.6766932,80.76725,2.5611687,437.06833,-9.2602453
179.3606,12.571813,7.4052653,0.0,0,2.5304146,0.0,0.68112516,81.000267,2.5272295,437.1062,-9.2592926
179.3648,12.621321,7.443646,0.0,0,2.4966886,0.0,0.68500751,81.009216,2.4925885,437.0654,-9.2603846
179.369,12.694447,7.4770284,0.0,0,2.4629626,0.0,0.69004703,81.076263,2.4600015,437.01492,-9.2597275
179.3732,12.84017,7.5018396,0.0,0,2.4292367,0.0,0.69408423,81.664169,2.4259317,436.97742,-9.2600079
179.3774,12.916186,7.5417795,0.0,0,2.3955107,0.0,0.69802386,81.814003,2.3902881,436.95218,-9.260684
179.3816,13.047957,7.5750337,0.0,0,2.3617847,0.0,0.70350605,82.178398,2.3563635,436.93216,-9.260746
179.3858,13.168513,7.6078205,0.0,0,2.3280585,0.0,0.70804483,82.586311,2.32482,436.94479,-9.2594957
179.39,13.257285,7.6473923,0.0,0,2.2952194,0.0,0.71215129,82.789726,2.2892268,436.95743,-9.2596292
179.3942,13.376485,7.6792235,0.0,0,2.2631397,0.0,0.71771508,83.131531,2.2523241,436.74887,-9.2590284
179.3984,13.410282,7.7085032,0.0,0,2.2310603,0.0,0.7215423,82.952446,2.2203982,436.47122,-9.2588797
179.4026,13.443519,7.7419872,0.0,0,2.1989808,0.0,0.72524315,82.932663,2.1930048,436.18384,-9.2607803
179.4068,13.576748,7.772614,0.0,0,2.1669011,0.0,0.73061484,83.245361,2.1579044,435.88095,-9.2588177
179.411,13.681038,7.8028259,0.0,0,2.1348214,0.0,0.73448598,83.583679,2.1268253,435.57635,-9.2601995
179.4152,13.772619,7.8424592,0.0,0,2.1027417,0.0,0.73894906,83.742828,2.0936284,435.09677,-9.2599325
179.4194,13.898752,7.86724,0.0,0,2.0706625,0.0,0.74401742,84.034462,2.0645795,434.61719,-9.2582827
179.4236,13.93588,7.8958521,0.0,0,2.0385828,0.0,0.74736422,84.029877,2.0337756,434.12161,-9.259594
179.4278,13.99947,7.9299541,0.0,0,2.0065031,0.0,0.75167257,84.116661,2.0050278,433.61679,-9.2573261
179.432,14.186529,7.9584284,0.0,0,1.9744235,0.0,0.75673169,84.743698,1.9733092,433.13141,-9.2605057
179.4362,14.277871,7.9890838,0.0,0,1.942344,0.0,0.76045316,85.002174,1.9373614,432.70233,-9.2589808
179.4404,14.469696,8.0308304,0.0,0,1.9112548,0.0,0.76582068,85.652214,1.9058021,432.27325,-9.2589865
179.4446,14.638851,8.0536776,0.0,0,1.8807377,0.0,0.77056843,86.173889,1.8748711,432.44452,-9.2603083
179.4488,14.718406,8.0876389,0.0,0,1.8502204,0.0,0.77458924,86.336967,1.8416657,432.69693,-9.2606659
179.453,14.744816,8.1219702,0.0,0,1.8197031,0.0,0.77926987,86.118568,1.8086667,433.064,-9.2600441
179.4572,14.827333,8.1473036,0.0,0,1.789186,0.0,0.78418171,86.209229,1.7824543,433.54361,-9.2611208
179.4614,14.954035,8.179141,0.0,0,1.7586688,0.0,0.78766066,86.665146,1.7487246,433.86578,-9.2600069
179.4656,15.064473,8.2145042,0.0,0,1.7281516,0.0,0.79270029,86.759575,1.7232676,433.12115,-9.2609787
179.4698,15.218617,8.2377377,0.0,0,1.6976343,0.0,0.79768372,87.278152,1.6929507,432.37656,-9.2601604
179.474,15.415385,8.2686367,0.0,0,1.6671171,0.0,0.80073476,88.09507,1.6619788,431.67941,-9.2590714
179.4782,15.60744,8.3060541,0.0,0,1.6366,0.0,0.80666935,88.654434,1.6275783,430.99789,-9.2597141
179.4824,15.68926,8.3311377,0.0,0,1.6060827,0.0,0.81129581,88.734665,1.5959396,430.43033,-9.2600708
179.4866,15.728209,8.3662539,0.0,0,1.5755656,0.0,0.81518942,88.647308,1.5658556,430.0517,-9.2585802
179.4908,15.800316,8.396699,0.0,0,1.5461324,0.0,0.82031125,88.563446,1.5402485,429.6731,-9.2606153
179.495,15.903261,8.4165421,0.0,0,1.517102,0.0,0.82441515,88.790901,1.5111682,428.52347,-9.2602901
179.4992,16.033489,8.4483938,0.0,0,1.4880716,0.0,0.82761836,89.262611,1.4814229,427.37387,-9.2591381
179.5034,16.186008,8.4793692,0.0,0,1.4590412,0.0,0.83315933,89.579353,1.4525028,426.29492,-9.2593107
179.5076,16.423193,8.5022116,0.0,0,1.4300108,0.0,0.83722699,90.476364,1.4192705,425.25858,-9.2576923
179.5118,16.558422,8.5408268,0.0,0,1.4009805,0.0,0.84164643,90.814377,1.390455,424.36618,-9.2588348
179.516,16.68038,8.5693865,0.0,0,1.37195,0.0,0.84733033,91.010101,1.3632777,423.91104,-9.2578964
179.5202,16.794907,8.5934801,0.0,0,1.3429196,0.0,0.85127026,91.340767,1.3284533,423.45587,-9.2590065
179.5244,16.843481,8.6237164,0.0,0,1.3138893,0.0,0.854581,91.23764,1.3047273,423.4855,-9.2606726
179.5286,16.967232,8.6504192,0.0,0,1.2848589,0.0,0.85995156,91.402245,1.2798659,423.58664,-9.2595587
179.5328,17.165905,8.6746149,0.0,0,1.2558285,0.0,0.86379892,92.134315,1.2483256,423.76291,-9.2591362
179.537,17.348806,8.7134676,0.0,0,1.2267981,0.0,0.86835164,92.682724,1.2221565,424.01578,-9.2597675
179.5412,17.581385,8.7382765,0.0,0,1.198938,0.0,0.87420022,93.322403,1.1891129,424.21143,-9.2591572
179.5454,17.720573,8.7604856,0.0,0,1.1713271,0.0,0.87729192,93.861923,1.1591676,423.98386,-9.2586403
179.5496,17.814884,8.7958994,0.0,0,1.1437162,0.0,0.88204986,93.876122,1.1334144,423.75629,-9.2579517
179.5538,17.950588,8.8142195,0.0,0,1.1161056,0.0,0.88647002,94.172211,1.1065043,423.64142,-9.258194
179.558,18.052769,8.8455391,0.0,0,1.0884947,0.0,0.89096779,94.318031,1.0816153,423.56555,-9.2591238
179.5622,18.139214,8.8774633,0.0,0,1.0608839,0.0,0.89500415,94.379951,1.052778,423.52679,-9.2595768
179.5664,18.310518,8.8972464,0.0,0,1.0332731,0.0,0.90019149,94.757858,1.0271692,423.55206,-9.2598848
179.5706,18.48344,8.9221764,0.0,0,1.0056622,0.0,0.90328401,95.382011,1.0013176,423.57736,-9.2595234
179.5748,18.743755,8.9549122,0.0,0,0.97805154,0.0,0.90822715,96.212967,0.96952367,423.6778,-9.2580242
179.579,19.030619,8.9776812,0.0,0,0.9504407,0.0,0.91334033,97.201485,0.94149715,423.77893,-9.2592669
179.5832,19.191366,9.0084305,0.0,0,0.92282987,0.0,0.91725743,97.655167,0.91244954,423.78687,-9.2586737
179.5874,19.248487,9.0406456,0.0,0,0.89521909,0.0,0.92233241,97.506104,0.88549125,423.7363,-9.2584181
179.5916,19.219559,9.0582123,0.0,0,0.86885202,0.0,0.92699897,96.80896,0.85865581,423.60446,-9.2582836
179.5958,19.321772,9.0810499,0.0,0,0.84259361,0.0,0.92947215,97.103531,0.83820701,423.21252,-9.2595444
179.6,19.618958,9.1114483,0.0,0,0.8163352,0.0,0.93466616,98.069221,0.80722004,422.82059,-9.2584143
179.6042,19.921316,9.1289558,0.0,0,0.79007679,0.0,0.93887341,99.074921,0.78352016,422.62485,-9.2564087
179.6084,20.196129,9.1639557,0.0,0,0.76381838,0.0,0.94316393,100.06228,0.75555581,422.46048,-9.2579947
179.6126,20.323524,9.19279,0.0,0,0.73756003,0.0,0.94843453,100.23582,0.72660023,422.59091,-9.2564201
179.6168,20.435081,9.2094011,0.0,0,0.71130162,0.0,0.9530037,100.34324,0.70382309,423.03342,-9.2591944
179.621,20.563257,9.2376184,0.0,0,0.68504322,0.0,0.95601118,100.66487,0.67499602,423.47589,-9.257699
179.6252,20.718628,9.2645578,0.0,0,0.65878487,0.0,0.96135515,100.87553,0.65015984,423.9184,-9.2584763
179.6294,20.928825,9.2835827,0.0,0,0.63252646,0.0,0.96546197,101.45062,0.6270138,424.3609,-9.2580481
179.6336,21.195759,9.3171635,0.0,0,0.60626805,0.0,0.9694792,102.33093,0.59790921,424.4418,-9.2575626
179.6378,21.394209,9.3419542,0.0,0,0.58003438,0.0,0.97516322,102.7091,0.5760383,424.3912,-9.2581844
179.642,21.759493,9.3588133,0.0,0,0.55503851,0.0,0.97874594,104.09789,0.54660636,424.36774,-9.2570019
179.6462,20.834705,9.3770285,0.0,0,0.53004849,0.0,0.98025376,99.580246,0.52759242,424.39304,-9.2588291
179.6504,19.820976,9.3800144,0.0,0,0.50505847,0.0,0.98205739,94.536522,0.51236647,424.4183,-9.2606096
179.6546,19.198723,9.3854942,0.0,0,0.48006845,0.0,0.98314679,91.504356,0.49547476,424.80325,-9.2588139
179.6588,18.752687,9.3994827,0.0,0,0.45507845,0.0,0.98382902,89.295982,0.48219317,425.19519,-9.2598267
179.663,18.291498,9.4008255,0.0,0,0.43008846,0.0,0.98609257,86.88588,0.4663389,425.56418,-9.2601156
179.6672,17.708363,9.3965054,0.0,0,0.40509844,0.0,0.98507148,84.243347,0.46120095,425.91818,-9.2612839
179.6714,17.256544,9.4024076,0.0,0,0.38010848,0.0,0.98485309,82.070145,0.45362097,426.24039,-9.2612381
179.6756,16.911297,9.4009047,0.0,0,0.35511845,0.0,0.98615766,80.31115,0.44566688,426.45532,-9.2617722
179.6798,16.755854,9.4019251,0.0,0,0.33012849,0.0,0.98570478,79.602646,0.42781085,426.67023,-9.2620058
179.684,16.805182,9.4138536,0.0,0,0.30513847,0.0,0.98651856,79.787331,0.40947852,426.87439,-9.2622023
179.6882,17.017057,9.4101143,0.0,0,0.28028354,0.0,0.98817647,80.654411,0.37578577,427.07666,-9.2610407
179.6924,17.187338,9.4088821,0.0,0,0.25651991,0.0,0.98686302,81.56395,0.34219623,427.23077,-9.2604628
179.6966,17.280844,9.4164391,0.0,0,0.23275633,0.0,0.98760164,81.948067,0.30967081,427.33194,-9.2608557
179.7008,17.315088,9.4116535,0.0,0,0.20899276,0.0,0.98834527,82.05011,0.27846909,427.42551,-9.2598028
179.705,17.310007,9.4203682,0.0,0,0.18522917,0.0,0.98876178,81.96666,0.25802845,427.45078,-9.2607708
179.7092,17.265245,9.4265413,0.0,0,0.16146557,0.0,0.98908722,81.777809,0.22727384,427.47604,-9.2607603
179.7134,17.187017,9.4223232,0.0,0,0.13770197,0.0,0.99028826,81.285645,0.20362516,427.52878,-9.260746
179.7176,17.084375,9.4244003,0.0,0,0.11393835,0.0,0.98925537,80.900131,0.18448116,427.59201,-9.2605839
179.7218,16.994499,9.4307165,0.0,0,0.090174757,0.0,0.99018484,80.406113,0.16337258,427.65961,-9.2579136
179.726,16.920984,9.4280462,0.0,0,0.066411152,0.0,0.9913913,79.955414,0.14443125,427.73547,-9.2595987
179.7302,16.835745,9.4347801,0.0,0,0.042647555,0.0,0.9909842,79.595184,0.12711726,427.81134,-9.2594824
179.7344,16.774672,9.4390354,0.0,0,0.018883955,0.0,0.99167496,79.240303,0.10792134,427.59244,-9.2586651
179.7386,16.690796,9.4332867,0.0,0,-0.0047606332,0.0,0.99230593,78.787193,0.092204951,427.36487,-9.2616034
179.7428,16.595995,9.437521,0.0,0,-0.027944632,0.0,0.99140292,78.402992,0.071806788,426.98679,-9.2602692
179.747,16.479645,9.439558,0.0,0,-0.05112863,0.0,0.99224418,77.803795,0.059794497,426.50635,-9.2596273
179.7512,16.331404,9.4378376,0.0,0,-0.074312627,0.0,0.9929741,77.05455,0.05033667,426.0647,-9.259757
179.7554,16.188133,9.4431381,0.0,0,-0.097496629,0.0,0.99203378,76.43634,0.03563742,425.76126,-9.2588472
179.7596,16.036831,9.4474421,0.0,0,0.20878275,400.0,0.99364823,75.577103,0.029378394,425.45782,-9.2605619
179.7638,15.796151,9.4392681,0.0,0,0.96942002,400.0,0.99320287,74.510254,0.026653275,425.87894,-9.2605486
179.768,12.887855,9.4388895,0.0,0,1.7300562,400.0,0.99125558,61.080162,0.13829261,426.43512,-9.2636757
179.7722,7.2471066,9.4231539,0.0,0,2.4906933,400.0,0.98957664,34.684082,0.40162063,427.0267,-9.2673635
179.7764,-0.13160928,9.3656673,0.0,0,3.2513299,400.0,0.97974497,-0.61750281,1.1959858,427.65875,-9.2745008
179.7806,0.81682688,9.4220495,0.0,0,4.0119667,400.0,0.98795968,3.7676976,2.457504,428.2359,-9.2722244
179.7848,0.7336337,9.4230261,0.0,0,4.772603,400.0,0.98984194,3.5045173,3.3732092,428.26114,-9.270257
179.789,0.71752149,9.4120102,0.0,0,5.5332398,400.0,0.98801368,3.371213,4.1116166,428.28638,-9.2692881
179.7932,0.75818574,9.4172134,0.0,0,6.2938776,400.0,0.98744863,3.5633559,4.8508148,428.33865,-9.2685089
179.7974,0.78502756,9.4132519,0.0,0,7.0545139,400.0,0.98824739,3.692883,5.600975,428.40176,-9.2684593
179.8016,0.73322564,9.4145823,0.0,0,7.8151507,400.0,0.98833644,3.5538185,6.3734779,428.44354,-9.2663374
179.8058,0.76602685,9.4198666,0.0,0,8.5757885,400.0,0.98741591,3.5856152,7.1775279,428.44354,-9.2669334
179.81,0.75573921,9.4136486,0.0,0,9.3364248,400.0,0.98845983,3.6544363,7.9624348,428.44354,-9.2650719
179.8142,0.62790394,9.4109402,0.0,0,10.097061,400.0,0.98740494,2.9233589,8.7391796,428.46783,-9.2652817
179.8184,0.69083458,9.4172068,0.0,0,10.857698,400.0,0.98750198,3.2739139,9.5268049,428.49307,-9.2656393
179.8226,0.70134473,9.4093943,0.0,0,11.618335,400.0,0.98782909,3.2906263,10.305891,428.53311,-9.2639074
179.8268,0.61264879,9.4125824,0.0,0,12.378972,400.0,0.98763424,2.880466,11.068567,428.58359,-9.2645988
179.831,0.67216516,9.4188747,0.0,0,13.139609,400.0,0.98754567,3.1606042,11.804901,428.61288,-9.2628031
179.8352,0.59330547,9.4139833,0.0,0,13.900247,400.0,0.98881555,2.8442516,12.541943,428.56244,-9.2641401
179.8394,0.53638893,9.4102507,0.0,0,14.660884,400.0,0.98687321,2.5136623,13.301342,428.51196,-9.2638512
179.8436,0.61489749,9.413682,0.0,0,15.421519,400.0,0.98689181,2.9405923,14.067044,428.49301,-9.263525
179.8478,0.56776148,9.4085846,0.0,0,16.182156,400.0,0.98792499,2.7088656,14.830339,428.48041,-9.2625189
179.852,0.52493346,9.4132071,0.0,0,16.942793,400.0,0.98740029,2.4156392,15.607483,428.47354,-9.2633543
179.8562,0.60592878,9.419158,0.0,0,17.70343,400.0,0.98778838,2.8485324,16.375858,428.47354,-9.263133
179.8604,0.55023736,9.4099455,0.0,0,18.0,400.0,0.98812461,2.6910825,17.129417,428.47659,-9.2627048
179.8646,0.55390894,9.4113359,0.0,0,18.0,400.0,0.98673517,2.6584725,17.831226,428.51447,-9.263278
179.8688,0.81137788,9.4166031,0.0,0,18.0,400.0,0.9879148,3.8644865,18.321264,428.55234,-9.2665205
179.873,0.89439952,9.4136305,0.0,0,18.0,400.0,0.98876929,4.2999377,18.465128,428.5813,-9.2748928
179.8772,0.86589175,9.4211721,0.0,0,18.0,400.0,0.98811626,4.1268454,18.288998,428.60654,-9.2881508
179.8814,0.83218545,9.4200773,0.0,0,18.0,400.0,0.98843694,3.9196455,18.110817,428.5903,-9.3116741
179.8856,0.83617878,9.4099522,0.0,0,18.0,400.0,0.98818433,3.9473884,18.054113,428.48932,-9.3420029
179.8898,0.87272877,9.4122095,0.0,0,18.0,400.0,0.9866752,4.0923634,18.065128,428.38837,-9.3754301
179.894,0.93002969,9.4121647,0.0,0,18.0,400.0,0.98742861,4.3638945,18.094887,428.35953,-9.4110117
179.8982,0.94708878,9.4079895,0.0,0,18.0,400.0,0.98750186,4.4809141,18.123558,428.33429,-9.4473963
179.9024,0.93428403,9.412921,0.0,0,18.0,400.0,0.98661137,4.4464989,18.131935,428.29453,-9.4776049
179.9066,0.88962454,9.41644,0.0,0,18.0,400.0,0.98840666,4.2444963,18.130978,428.24402,-9.5077047
179.9108,0.83308434,9.4046764,0.0,0,18.0,400.0,0.98714221,4.0253062,18.130901,428.19858,-9.5378284
179.915,0.83288634,9.4112568,0.0,0,18.0,400.0,0.98651135,3.9414549,18.124582,428.17334,-9.5694675
179.9192,0.84874833,9.4141483,0.0,0,18.0,400.0,0.9881568,3.9943919,18.122986,428.1481,-9.600317
179.9234,0.90898776,9.4060421,0.0,0,18.0,400.0,0.98697323,4.2555394,18.11804,428.13324,-9.6306534
179.9276,0.97892427,9.4178295,0.0,0,18.0,400.0,0.98722672,4.6322956,18.117208,428.12064,-9.6622286
179.9318,0.9801212,9.4128113,0.0,0,18.0,400.0,0.98827451,4.6566658,18.110254,428.07974,-9.6935606
179.936,0.90465546,9.4089422,0.0,0,18.0,400.0,0.98720747,4.3131909,18.110199,428.004,-9.7252207
179.9402,0.85925406,9.4147091,0.0,0,18.0,400.0,0.98700625,4.1644669,18.110277,427.93274,-9.7564049
179.9444,0.8190738,9.4105663,0.0,0,18.0,400.0,0.98794758,3.9304156,18.107519,427.9201,-9.7880583
179.9486,0.83791584,9.407547,0.0,0,18.0,400.0,0.98676223,3.9364226,18.102314,427.90747,-9.8171053
179.9528,0.88812459,9.4182816,0.0,0,18.0,400.0,0.98725569,4.172843,18.104084,427.85968,-9.8492289
179.957,0.94936907,9.4102812,0.0,0,18.0,400.0,0.98806798,4.4725523,18.100103,427.79645,-9.8782864
179.9612,0.97719675,9.4095631,0.0,0,18.0,400.0,0.98692346,4.6426439,18.099056,427.72922,-9.9115286
179.9654,0.95309889,9.4134026,0.0,0,18.0,400.0,0.98692197,4.5431991,18.09601,427.65335,-9.9419155
179.9696,0.89743644,9.4100142,0.0,0,18.0,400.0,0.98803139,4.2842283,18.093056,427.57751,-9.9710541
179.9738,0.8329348,9.4110308,0.0,0,18.0,400.0,0.98708481,3.9824965,18.099155,427.53741,-10.003222
179.978,0.82686853,9.4197512,0.0,0,18.0,400.0,0.98784691,3.8713865,18.092155,427.49948,-10.033847
179.9822,0.87230599,9.4098349,0.0,0,18.0,400.0,0.98804438,4.095448,18.091862,427.46872,-10.064817
179.9864,0.9469437,9.4115429,0.0,0,18.0,400.0,0.9868179,4.4411545,18.090696,427.44342,-10.096879
179.9906,0.99497902,9.4151049,0.0,0,18.0,400.0,0.98753524,4.6921024,18.089605,427.41815,-10.128453
179.9948,0.98661023,9.409976,0.0,0,18.0,400.0,0.98811549,4.7174234,18.088245,427.39288,-10.158612
179.999,0.93178362,9.4138479,0.0,0,18.0,400.0,0.98703545,4.4731374,18.086506,427.36758,-10.190251
180.0032,0.87770212,9.4185114,0.0,0,18.0,400.0,0.987894,4.1908293,18.082378,427.3114,-10.221651
180.0074,0.8446607,9.4104967,0.0,0,18.0,400.0,0.98838747,4.0125446,18.082438,427.2482,-10.2521
180.0116,0.85379213,9.4105635,0.0,0,18.0,400.0,0.98646826,4.0181155,18.084549,427.2016,-10.284413
180.0158,0.92002118,9.413249,0.0,0,18.0,400.0,0.98759645,4.3075714,18.08182,427.1763,-10.314141
180.02,0.97640437,9.4080286,0.0,0,18.0,400.0,0.9877339,4.6063056,18.082516,427.14944,-10.344288
180.0242,0.99563628,9.4168892,0.0,0,18.0,400.0,0.98726994,4.6959848,18.078283,427.09888,-10.376206
180.0284,0.95933795,9.4177256,0.0,0,18.0,400.0,0.98832667,4.6043897,18.078732,427.04831,-10.407929
180.0326,0.88766247,9.40767,0.0,0,18.0,400.0,0.9877128,4.2366877,18.07802,427.01508,-10.43956
180.0368,0.84378594,9.4161148,0.0,0,18.0,400.0,0.98725772,4.0198665,18.075459,426.98981,-10.470133
180.041,0.84142554,9.4144192,0.0,0,18.0,400.0,0.98817986,3.9595306,18.072783,426.96454,-10.499164
180.0452,0.89129257,9.4088821,0.0,0,18.0,400.0,0.98756719,4.1748614,18.07514,426.93924,-10.529257
180.0494,0.9762401,9.4185743,0.0,0,18.0,400.0,0.98736441,4.5511508,18.074511,426.91394,-10.560453
180.0536,1.0168798,9.4168663,0.0,0,18.0,400.0,0.98867601,4.8139768,18.072996,426.85327,-10.592517
180.0578,0.99508548,9.4095268,0.0,0,18.0,400.0,0.98774523,4.7256436,18.068974,426.79004,-10.623107
180.062,0.93969178,9.4174175,0.0,0,18.0,400.0,0.98745513,4.5125694,18.070383,426.74094,-10.656337
180.0662,0.87943488,9.4148378,0.0,0,18.0,400.0,0.98835385,4.1517258,18.067457,426.703,-10.690056
180.0704,0.84974235,9.4107189,0.0,0,18.0,400.0,0.98750997,4.0444541,18.069159,426.66049,-10.71731
180.0746,0.87755591,9.4237652,0.0,0,18.0,400.0,0.98812479,4.1433401,18.065098,426.59729,-10.748196
180.0788,0.94295055,9.4141464,0.0,0,18.0,400.0,0.98871273,4.3992639,18.065084,426.53406,-10.780322
180.083,1.0002844,9.4137554,0.0,0,18.0,400.0,0.98791498,4.7028708,18.060198,426.46066,-10.808687
180.0872,1.0176494,9.416604,0.0,0,18.0,400.0,0.98746711,4.8322344,18.06041,426.3848,-10.842802
180.0914,0.95252609,9.4131212,0.0,0,18.0,400.0,0.98851073,4.5644293,18.059996,426.32672,-10.872995
180.0956,0.8895849,9.416523,0.0,0,18.0,400.0,0.98815453,4.2626634,18.056507,426.2923,-10.903929
180.0998,0.85656995,9.4200439,0.0,0,18.0,400.0,0.98790413,4.0893879,18.056475,426.2579,-10.936106
180.104,0.86368936,9.4157925,0.0,0,18.0,400.0,0.98918092,4.0764508,18.056377,426.16946,-10.966798
180.1082,0.91711885,9.4130058,0.0,0,18.0,400.0,0.98729324,4.2754955,18.056416,426.0683,-10.995081
180.1124,0.99468881,9.4169474,0.0,0,18.0,400.0,0.98773825,4.6525121,18.057371,425.98907,-11.027694
180.1166,1.0292897,9.4131403,0.0,0,18.0,400.0,0.9887315,4.8624907,18.053238,425.93851,-11.058022
180.1208,1.0074669,9.4191189,0.0,0,18.0,400.0,0.98807997,4.782794,18.057934,425.89374,-11.089919
180.125,0.93904364,9.4211578,0.0,0,18.0,400.0,0.98833275,4.4882913,18.053862,425.94431,-11.121783
180.1292,0.8843677,9.414032,0.0,0,18.0,400.0,0.98906028,4.2547016,18.054764,425.99484,-11.151371
180.1334,0.86103415,9.4150915,0.0,0,18.0,400.0,0.98734432,4.0758443,18.053024,425.98517,-11.182499
180.1376,0.89250398,9.4191494,0.0,0,18.0,400.0,0.98828578,4.1965761,18.050253,425.94724,-11.214077
180.1418,0.96036875,9.4116879,0.0,0,18.0,400.0,0.98860705,4.480844,18.04937,425.90161,-11.244796
180.146,1.0264704,9.4187202,0.0,0,18.0,400.0,0.98799926,4.802464,18.049686,425.83838,-11.276385
180.1502,1.0335276,9.4217072,0.0,0,18.0,400.0,0.98874414,4.877737,18.047268,425.77518,-11.30584
180.1544,0.97245586,9.4126806,0.0,0,18.0,400.0,0.98864251,4.6535783,18.046436,425.70023,-11.338039
180.5577,0.88627201,9.4203329,0.0,0,18.0,0.0014183685,0.98891622,4.1931114,18.01177,416.09634,-11.480289
182.6577,0.83520132,9.4338074,0.0,0,18.0,3.2689643000000005e-32,0.9913289,3.9464769,17.999376,391.51297,-11.480516
184.7577,0.80816883,9.4437828,0.0,0,18.0,1.4012985e-45,0.99315393,3.8124406,18.000381,371.27295,-11.481181
186.8577,0.80907726,9.4538116,0.0,0,18.0,1.4012985e-45,0.99500299,3.8026297,18.000311,353.422,-11.480672
188.9577,0.81555909,9.4628458,0.0,0,18.0,1.4012985e-45,0.99661708,3.8329959,17.998638,336.2449,-11.480013
191.0577,0.81119454,9.4719286,0.0,0,18.0,1.4012985e-45,0.99827534,3.8125787,17.999765,318.98947,-11.480663
193.1577,0.80510521,9.4807997,0.0,0,18.0,1.4012985e-45,0.99988651,3.7639799,17.999506,303.50546,-11.481215
195.2577,0.82469314,9.4886408,0.0,0,18.0,1.4012985e-45,1.0012797,3.8486178,18.000525,288.89221,-11.480755
197.3577,0.82665747,9.4972773,0.0,0,18.0,1.4012985e-45,1.0028374,3.8711619,17.99934,275.13235,-11.480946
199.4577,0.82433116,9.5047255,0.0,0,18.0,1.4012985e-45,1.0041512,3.8475208,17.999548,261.92554,-11.480227
201.5577,0.83974558,9.5124645,0.0,0,18.0,1.4012985e-45,1.0055436,3.8998294,18.000607,249.74883,-11.48081
203.6577,0.85600531,9.5195112,0.0,0,18.0,1.4012985e-45,1.0068169,3.9823515,18.000086,237.87573,-11.481059
205.7577,0.84787571,9.5263672,0.0,0,18.0,1.4012985e-45,1.0080498,3.9443924,17.999472,226.75821,-11.481179
207.8577,0.85881501,9.5330305,0.0,0,18.0,1.4012985e-45,1.0092392,3.9792581,18.00021,216.2816,-11.480934
209.9577,0.87887812,9.5389347,0.0,0,18.0,1.4012985e-45,1.010353,4.0693364,17.999561,206.48853,-11.480268
212.0577,0.88238442,9.5446558,0.0,0,18.0,1.4012985e-45,1.0113635,4.1004329,17.99995,197.25157,-11.480505
214.1577,0.87868857,9.5502396,0.0,0,18.0,1.4012985e-45,1.012429,4.0620971,17.999094,188.2486,-11.480155
216.2577,0.90475506,9.5555601,0.0,0,18.0,1.4012985e-45,1.0133973,4.1748729,17.999489,179.76703,-11.480989
218.3577,0.90638828,9.5598707,0.0,0,18.0,1.4012985e-45,1.0141948,4.1921215,17.999836,171.99516,-11.480975
220.4577,0.90139425,9.5653839,0.0,0,18.0,1.4012985e-45,1.0152136,4.1630893,17.999367,164.53539,-11.481586
222.5577,0.91373599,9.5700054,0.0,0,18.0,1.4012985e-45,1.0160872,4.2061591,17.999596,157.53954,-11.480968
224.6577,0.93698043,9.5746822,0.0,0,18.0,1.4012985e-45,1.0169502,4.3088746,18.000093,150.90002,-11.480228
226.7577,0.92223197,9.5784006,0.0,0,18.0,1.4012985e-45,1.0176476,4.2540026,18.000139,144.48502,-11.480024
228.8577,0.92294019,9.5833807,0.0,0,18.0,1.4012985e-45,1.0185858,4.2377515,17.99877,138.33679,-11.479963
230.9577,0.94434661,9.5866728,0.0,0,18.0,1.4012985e-45,1.0191934,4.3309946,18.000416,132.78877,-11.480485
233.0577,0.93886125,9.5902147,0.0,0,18.0,1.4012985e-45,1.0198824,4.3187261,17.999502,127.3345,-11.480853
235.1577,0.93078834,9.593914,0.0,0,18.0,1.4012985e-45,1.02057,4.2699261,18.000341,122.11787,-11.481105
237.2577,0.94811022,9.5973387,0.0,0,18.0,1.4012985e-45,1.0212044,4.3362856,17.99921,117.31781,-11.480821
239.3577,0.95996058,9.6008663,0.0,0,18.0,1.4012985e-45,1.0218346,4.4041829,18.000145,112.70374,-11.481137
240.1577,0.94034195,9.6022663,0.0,0,18.0,1.4012985e-45,1.0220547,4.3036304,18.000368,110.96378,-11.545822