File: examples/dan-msc-case-studies/CS3/data/01 raw data/baron_test_132.csv
Time(sec),Force(kN),Jaw(mm),PowAngle(deg),Power(W),Pram,PTemp,Strain,Stress(MPa),Stroke(mm),TC1(C),wedge(mm)
0.0,1.2403492,0.4928489,0.0,0,11.076097,0.0012900118,0.033416219,15.255699,11.075618,24.649897,-9.1043358
1.2,1.1665425,0.0026114364,0.0,0,11.076097,3.5158758,0.00016130529,14.84329,11.076509,24.569601,-9.4736729
2.4,1.1369277,0.0027698088,0.0,0,11.076097,7.1158757,0.00020518441,14.472287,11.07672,24.538946,-9.4713688
3.6,1.1197358,0.0027688979,0.0,0,11.076097,10.715876,0.00018983017,14.258985,11.075841,24.566708,-9.4700947
4.8,1.0980005,0.0026366853,0.0,0,11.076097,14.315875,0.00017902417,13.974554,11.0764,24.566063,-9.4678793
6.0,1.0819674,0.0029477938,0.0,0,11.076097,17.915874,0.00019860205,13.767181,11.076764,24.527222,-9.466197
7.2,1.063753,0.0028599182,0.0,0,11.076097,21.515875,0.00017550866,13.537471,11.075888,24.518988,-9.4640799
8.4,1.0546486,0.0021928926,0.0,0,11.076097,25.115875,0.00015374717,13.44615,11.076195,24.523483,-9.462163
9.6,1.0536698,0.0028006786,23.285431,0,11.076097,28.715876,0.00017236909,13.40857,11.07583,24.531898,-9.4604225
10.8,1.060318,0.001601384,35.15826,0,11.076097,32.31588,0.00012331494,13.502842,11.076207,25.536331,-9.4588804
12.0,1.0681987,-0.0014470373,41.184521,0,11.076097,35.915878,-9.8860546e-05,13.585922,11.075945,28.393545,-9.4569025
13.2,1.085937,-0.0055897608,44.07618,0,11.076097,39.515877,-0.00036278326,13.83222,11.077467,32.85194,-9.4553738
14.4,1.1013161,-0.010315148,45.332142,0,11.076097,43.115883,-0.0006785919,14.042124,11.075632,38.032333,-9.4534101
15.6,1.1113701,-0.013514126,45.615231,0,11.076097,46.715881,-0.00090869615,14.173096,11.076147,43.363388,-9.4514999
16.8,1.1086134,-0.017064907,44.947594,0,11.076097,50.31588,-0.0011283765,14.129187,11.075858,48.767872,-9.449276
18.0,1.1191999,-0.020585438,44.077206,0,11.076097,53.915882,-0.0013863167,14.255669,11.075139,53.637436,-9.4474096
19.2,1.124522,-0.023998972,42.979084,0,11.076097,57.515884,-0.0015798386,14.347599,11.076847,57.976006,-9.4458857
20.4,1.1286864,-0.026268803,42.396244,0,11.076097,61.115891,-0.001755969,14.397389,11.076458,61.953529,-9.4438076
21.6,1.1248602,-0.029567881,41.91959,0,11.076097,64.715874,-0.0019522347,14.345474,11.075284,65.387314,-9.4419403
22.8,1.1320299,-0.031522036,42.395031,0,11.076097,68.315872,-0.0020993103,14.434307,11.075527,68.574837,-9.4403811
24.0,1.1259197,-0.0342451,42.911839,0,11.076097,71.915871,-0.0022732762,14.370582,11.074865,71.718369,-9.4384356
25.2,1.1290843,-0.037087053,43.504494,0,11.076097,75.515877,-0.0024548729,14.437309,11.077259,74.90789,-9.4364777
26.4,1.1397516,-0.040190525,44.077141,0,11.076097,79.115868,-0.0026881474,14.562246,11.076642,78.21788,-9.4344969
27.6,1.147064,-0.043183867,44.604488,0,11.076097,82.715874,-0.0028685515,14.646682,11.076222,81.769051,-9.4320345
28.8,1.1382375,-0.047218967,44.955467,0,11.076097,86.31588,-0.0031602022,14.525283,11.076525,85.447533,-9.4302511
30.0,1.1443939,-0.049215842,45.568462,0,11.076097,89.915871,-0.0032689455,14.617129,11.07663,89.005768,-9.4285421
31.2,1.1594464,-0.051482271,45.615231,0,11.076097,93.515877,-0.0034392406,14.830797,11.076755,92.731255,-9.4270744
32.4,1.1592314,-0.054396566,46.109619,0,11.076097,97.115883,-0.0036032221,14.810195,11.075644,96.303925,-9.4251184
33.6,1.1653868,-0.057259835,46.556221,0,11.076097,100.71588,-0.0037931185,14.887668,11.076404,99.960281,-9.4234266
34.8,1.161553,-0.060427688,46.582027,0,11.076097,104.31588,-0.0040192055,14.857965,11.075149,103.57318,-9.4214449
36.0,1.1574067,-0.063522652,47.052853,0,11.076097,107.91589,-0.0042266892,14.815989,11.076216,107.23283,-9.4194803
37.2,1.1701523,-0.066266328,47.05444,0,11.076097,111.51588,-0.0044157817,14.970695,11.075684,110.8939,-9.4174528
38.4,1.1758519,-0.069898285,47.504883,0,11.076097,115.11589,-0.0046456316,15.043172,11.075354,114.43347,-9.4153948
39.6,1.1709321,-0.072906949,47.826466,0,11.076097,118.71589,-0.0048625208,14.982042,11.076283,118.0758,-9.4134703
40.8,1.1694913,-0.076374754,47.955318,0,11.076097,122.3159,-0.0050568362,14.955439,11.076222,121.73903,-9.4115677
42.0,1.1793759,-0.079434216,48.077568,0,11.076097,125.91589,-0.0052759545,15.103246,11.077639,125.37592,-9.410078
43.2,1.1821116,-0.083395667,48.383785,0,11.076097,129.51602,-0.0055275457,15.147429,11.076994,128.98521,-9.4079599
44.4,1.1888301,-0.085873693,48.740002,0,11.076097,133.11589,-0.0057047787,15.212174,11.075802,132.51735,-9.4062529
45.6,1.1834387,-0.087803356,48.812252,0,11.076097,136.7159,-0.0058418633,15.157117,11.075433,136.12215,-9.4042482
46.8,1.1819946,-0.090961613,49.229733,0,11.076097,140.31589,-0.0060430891,15.142757,11.07618,139.51884,-9.4025888
48.0,1.1880152,-0.094177239,49.636227,0,11.076097,143.91588,-0.0062703174,15.224842,11.075586,142.95247,-9.4003134
49.2,1.1883358,-0.097642101,50.351006,0,11.076097,147.51588,-0.0064764735,15.225449,11.076488,146.45256,-9.398324
50.4,1.1873313,-0.10157547,50.438229,0,11.076097,151.11589,-0.0067624063,15.213374,11.076079,150.22205,-9.3965864
51.6,1.188432,-0.10450151,50.462181,0,11.076097,154.7159,-0.0069206888,15.240425,11.075521,154.10976,-9.3945637
52.8,1.1922088,-0.10787836,50.82275,0,11.076097,158.31589,-0.0071570445,15.2921,11.075017,157.70357,-9.392622
54.0,1.1872725,-0.11129449,50.949314,0,11.076097,161.91588,-0.0073848534,15.244026,11.07662,161.3817,-9.390789
55.2,1.1986247,-0.11441571,51.160728,0,11.076097,165.51587,-0.0075896899,15.351983,11.07612,164.95195,-9.3890419
56.4,1.1993529,-0.11833804,51.196285,0,11.076097,169.11589,-0.0078603737,15.38872,11.076007,168.71342,-9.3873682
57.6,1.2005508,-0.12250306,51.43367,0,11.076097,172.71588,-0.0081284875,15.414344,11.077017,172.21152,-9.3852711
58.8,1.2053715,-0.12455778,51.569775,0,11.076097,176.3159,-0.0082955556,15.481937,11.07568,175.899,-9.3835955
60.0,1.2009169,-0.12705332,51.927444,0,11.076097,179.91586,-0.0084302854,15.428799,11.076106,179.36064,-9.3814297
61.2,1.2000724,-0.13046668,51.932369,0,11.076097,183.51588,-0.0086712372,15.410169,11.076026,182.98111,-9.3794155
62.4,1.1979843,-0.13377079,51.932369,0,11.076097,187.11588,-0.0088560311,15.384346,11.075313,186.68489,-9.377532
63.6,1.1958508,-0.13738416,52.001625,0,11.076097,190.71587,-0.009111084,15.37625,11.076334,190.38625,-9.3757095
64.8,1.2003105,-0.14088856,52.283936,0,11.076097,194.31587,-0.0093447948,15.444607,11.077473,193.97742,-9.3737564
66.0,1.1954571,-0.14431778,52.312958,0,11.076097,197.91588,-0.0095611429,15.380457,11.075351,197.47995,-9.3714228
67.2,1.1991155,-0.14759482,52.969933,0,11.076097,201.51588,-0.0098081799,15.409142,11.07633,200.79248,-9.3694029
68.4,1.1985935,-0.15217085,52.97607,0,11.076097,205.11589,-0.010078114,15.416785,11.076368,204.34044,-9.3674345
69.6,1.2089027,-0.15586515,53.31665,0,11.076097,208.71588,-0.010356066,15.560322,11.076998,208.07753,-9.3657351
70.8,1.2034317,-0.15777698,53.31665,0,11.076097,212.31589,-0.010453186,15.481053,11.075967,211.69441,-9.3637905
72.0,1.2018048,-0.1614292,53.657223,0,11.076097,215.91588,-0.010713949,15.469261,11.075895,215.35539,-9.3616333
73.2,1.199122,-0.16495389,53.657223,0,11.076097,219.5159,-0.010919439,15.431038,11.077103,218.91548,-9.3599396
74.4,1.1962903,-0.16836125,53.975826,0,11.076097,223.11589,-0.01115378,15.400493,11.0771,222.55315,-9.3582697
75.6,1.201537,-0.17190278,53.975826,0,11.076097,226.71588,-0.011391773,15.474941,11.075961,226.18254,-9.3564234
76.8,1.2032634,-0.17660929,54.305416,0,11.076097,230.3159,-0.011687502,15.515684,11.076374,229.71217,-9.3542538
78.0,1.202692,-0.17898841,54.364998,0,11.076097,233.91589,-0.011877881,15.509872,11.0767,233.39975,-9.3524961
79.2,1.2012156,-0.18157171,54.624023,0,11.076097,237.51588,-0.012028435,15.474391,11.075209,237.00462,-9.3506956
80.4,1.1972358,-0.18564489,54.624027,0,11.076097,241.11591,-0.01230783,15.448495,11.076557,240.69341,-9.34863
81.6,1.2031925,-0.18911076,54.929371,0,11.076097,244.7159,-0.01252203,15.515194,11.075442,244.29362,-9.3468313
82.8,1.1975186,-0.19263223,54.931637,0,11.076097,248.3159,-0.012771743,15.432969,11.075912,247.98862,-9.3447104
84.0,1.2030139,-0.19745246,54.969498,0,11.076097,251.91589,-0.013054055,15.516092,11.076827,251.49365,-9.3428841
85.2,1.2059652,-0.19955762,54.941921,0,11.076097,255.5159,-0.013219623,15.571318,11.075899,255.27783,-9.3409452
86.4,1.2068334,-0.20250039,55.116734,0,11.076097,259.11615,-0.013395658,15.588785,11.075294,258.89902,-9.3385048
87.6,1.2045867,-0.20563577,55.239254,0,11.076097,262.71591,-0.013607269,15.556581,11.07576,262.29248,-9.3362837
88.8,1.2076178,-0.20958674,55.535885,0,11.076097,266.31589,-0.013880752,15.575553,11.077016,265.73227,-9.3349571
90.0,1.1992873,-0.21277472,55.843449,0,11.076097,269.91592,-0.014076793,15.480632,11.075685,269.28833,-9.3333626
91.2,1.2070671,-0.2166435,56.127918,0,11.076097,273.5159,-0.014344822,15.600894,11.07689,272.78461,-9.3305712
92.4,1.2069253,-0.2210256,56.129147,0,11.076097,277.11591,-0.014637343,15.594139,11.076353,276.46341,-9.3284979
93.6,1.210584,-0.22226204,56.425777,0,11.076097,280.71588,-0.014721397,15.63406,11.077592,279.91208,-9.3265762
94.8,1.2033606,-0.22642152,56.711422,0,11.076097,284.31589,-0.014964847,15.547407,11.07587,283.31879,-9.3247719
96.0,1.2039654,-0.23020078,56.986084,0,11.076097,287.91586,-0.015240501,15.565482,11.07612,287.06366,-9.3232584
97.2,1.2035919,-0.23414227,57.255165,0,11.076097,291.51593,-0.015468604,15.561541,11.076169,290.71207,-9.3213739
98.4,1.2122195,-0.23942964,57.260738,0,11.076097,295.11591,-0.015838983,15.686288,11.076234,294.40527,-9.3193827
99.6,1.2099606,-0.2409811,57.535381,0,11.076097,298.71588,-0.015922958,15.644807,11.075768,298.05008,-9.3168764
100.8,1.2068172,-0.24534935,57.506649,0,11.076097,302.31589,-0.016213393,15.611003,11.076125,301.92563,-9.3151741
102.0,1.2033738,-0.2491733,57.460545,0,11.076097,305.91589,-0.016476646,15.591022,11.077014,305.70969,-9.3132877
103.2,1.2091146,-0.2547113,57.535397,0,11.076097,309.5159,-0.016829252,15.658372,11.075708,309.32074,-9.3111019
104.4,1.2141874,-0.25518823,57.535397,0,11.076097,313.11584,-0.016881952,15.719523,11.075741,312.82739,-9.3092213
105.6,1.2027017,-0.25967044,57.6208,0,11.076097,316.71588,-0.017165776,15.584496,11.076197,316.46442,-9.3077116
106.8,1.1989039,-0.26318324,57.810051,0,11.076097,320.31589,-0.017409353,15.53495,11.075751,320.05035,-9.3055754
108.0,1.2140651,-0.26907372,57.810051,0,11.076097,323.91589,-0.017771507,15.747715,11.076495,323.68744,-9.303401
109.2,1.2108333,-0.26958677,58.027531,0,11.076097,327.5159,-0.017824821,15.695462,11.07625,327.19089,-9.3016977
110.4,1.2126223,-0.2741302,58.073727,0,11.076097,331.11591,-0.018091753,15.723608,11.07695,330.75519,-9.2998581
111.6,1.2018465,-0.27768612,58.073727,0,11.076097,334.71591,-0.018343318,15.582774,11.075953,334.37177,-9.297596
112.8,1.2071589,-0.28359672,58.073727,0,11.076097,338.31589,-0.018712195,15.658861,11.075928,338.09116,-9.2951736
114.0,1.2129028,-0.2839852,58.315269,0,11.076097,341.91589,-0.018752431,15.729912,11.076992,341.61661,-9.2937393
115.2,1.2107282,-0.28788611,58.337399,0,11.076097,345.5159,-0.019002937,15.720081,11.076656,345.11868,-9.2919807
116.4,1.2010032,-0.29189402,58.340439,0,11.076097,349.11591,-0.019253155,15.592049,11.076855,348.81866,-9.2898836
117.6,1.2067467,-0.2951481,58.59008,0,11.076097,352.71591,-0.019488601,15.667447,11.076444,352.38763,-9.2881041
118.8,1.2156746,-0.30055475,58.59008,0,11.076097,356.31592,-0.019830788,15.799358,11.07585,356.03699,-9.286108
120.0,1.2079237,-0.30140373,58.552738,0,11.076097,359.91589,-0.019915046,15.709189,11.076077,359.79865,-9.2840395
121.2,1.2106209,-0.30531582,58.59008,0,11.076097,363.5159,-0.020147247,15.722991,11.076008,363.2843,-9.2822647
122.4,1.2049259,-0.30912706,58.853752,0,11.076097,367.11591,-0.020414161,15.661542,11.075868,366.73523,-9.2796297
123.6,1.2004402,-0.3129482,59.105091,0,11.076097,370.71591,-0.020639883,15.606722,11.076205,370.12604,-9.2773972
124.8,1.2042272,-0.31631932,59.106438,0,11.076097,374.31592,-0.020876355,15.671123,11.07704,373.70526,-9.2754822
126.0,1.2237121,-0.32149607,59.348137,0,11.076097,377.91592,-0.021193651,15.909297,11.07635,377.14267,-9.2738457
127.2,1.2136679,-0.32210547,59.600826,0,11.076097,381.5159,-0.0212436,15.789492,11.076314,380.66779,-9.2718554
128.4,1.2068757,-0.32626492,59.842525,0,11.076097,385.11591,-0.02150972,15.703437,11.076651,384.32657,-9.2700491
129.6,1.2037593,-0.32971507,59.779327,0,11.076097,388.71591,-0.021730883,15.650762,11.077263,388.29657,-9.2683468
130.8,1.2085674,-0.33383089,59.842525,0,11.076097,392.31592,-0.021999817,15.736061,11.07637,391.9339,-9.2670536
132.0,1.2129664,-0.33798566,59.84264,0,11.076097,395.91592,-0.022266075,15.80145,11.075944,395.54144,-9.2644844
133.2,1.219667,-0.34184989,60.079868,0,11.076097,399.51593,-0.022543404,15.888618,11.076435,399.12384,-9.2622976
134.4,1.2064675,-0.34349173,60.161789,0,11.076097,403.11591,-0.022631869,15.702435,11.076962,402.54462,-9.2598953
135.6,1.2124171,-0.34752083,60.314934,0,11.076097,406.71591,-0.022915788,15.792975,11.076473,406.0423,-9.258112
136.8,1.2085611,-0.35156003,60.556637,0,11.076097,410.31589,-0.023157565,15.758649,11.076969,409.68082,-9.2560129
138.0,1.2039323,-0.35601193,60.660316,0,11.076097,413.91586,-0.023473334,15.681148,11.076623,413.28973,-9.2533646
139.2,1.2126933,-0.36038283,60.787346,0,11.076097,417.5159,-0.023721514,15.788183,11.076571,416.93594,-9.2517004
140.4,1.2244128,-0.36330128,60.789455,0,11.076097,421.11591,-0.023960084,15.973963,11.076965,420.62289,-9.2502193
141.6,1.2182971,-0.36485454,60.556648,0,11.076097,424.71588,-0.024012085,15.893683,11.076863,424.78101,-9.2482777
142.8,1.209816,-0.36873716,60.753735,0,11.076097,428.31592,-0.024294263,15.786622,11.076658,428.27127,-9.2461443
144.0,1.2003698,-0.37211376,60.556648,0,11.076097,431.91589,-0.024492703,15.669298,11.075718,432.08737,-9.2442617
145.2,1.1959642,-0.37504783,60.470234,0,11.076097,435.5159,-0.024693994,15.611636,11.076174,435.82822,-9.2426157
146.4,1.2190098,-0.37897107,60.379131,0,11.076097,439.11591,-0.024925008,15.914466,11.077853,439.39709,-9.240901
147.6,1.2228369,-0.3822453,60.500854,0,11.076097,442.71588,-0.025157161,15.967922,11.07641,442.78003,-9.23876
148.8,1.2135543,-0.38268006,60.556637,0,11.076097,446.31592,-0.025198033,15.841547,11.076108,446.36166,-9.2368898
150.0,1.208405,-0.38539365,60.562531,0,11.076097,449.91446,-0.02535888,15.772388,11.075187,449.69629,-9.2347765
151.2,1.2092378,-0.38723615,58.856266,0,11.076097,449.9989,-0.025499497,15.797912,11.077207,452.92731,-9.2343502
152.4,1.1914111,-0.38744804,56.720676,0,11.076097,449.9989,-0.02550035,15.566337,11.075445,454.92978,-9.2342033
153.6,1.174886,-0.38723424,54.629295,0,11.076097,449.9989,-0.025501641,15.345869,11.075013,455.87585,-9.233984
154.8,1.1565051,-0.3862251,52.97707,0,11.076097,449.9989,-0.025411597,15.105006,11.076533,455.62625,-9.2336302
156.0,1.1488765,-0.38441521,51.9324,0,11.076097,449.9989,-0.025323031,15.000718,11.076626,454.67896,-9.2338934
157.2,1.1311564,-0.38456449,51.487988,0,11.076097,449.9989,-0.025294866,14.771592,11.076632,453.42761,-9.2340069
158.4,1.0599402,-0.38317734,51.56982,0,11.076097,449.9989,-0.025248043,13.823544,11.0766,451.92853,-9.2338352
159.6,0.95080268,-0.38193828,52.188042,0,11.076097,449.9989,-0.025132375,12.41619,11.076825,450.61765,-9.2341356
160.8,0.86541629,-0.38224873,52.958725,0,11.076097,449.9989,-0.025169665,11.293238,11.075941,449.47205,-9.2341204
162.0,0.82220304,-0.38304365,53.842258,0,11.076097,449.9989,-0.025193404,10.723113,11.07656,448.55118,-9.2343206
163.2,0.80725652,-0.38338736,54.623985,0,11.076097,449.9989,-0.025224734,10.538273,11.076285,448.13159,-9.234395
164.4,0.79576188,-0.38519531,55.239254,0,11.076097,449.9989,-0.025349628,10.411705,11.076698,448.01804,-9.234726
165.6,0.79319334,-0.38636994,55.66785,0,11.076097,449.9989,-0.025419403,10.368698,11.075625,448.1488,-9.2348251
166.8,0.77531248,-0.38764262,55.843506,0,11.076097,449.9989,-0.02551619,10.140257,11.076412,448.56964,-9.2342367
168.0,0.76464319,-0.38953853,56.127438,0,11.076097,449.9989,-0.025640314,9.9863195,11.076201,448.95517,-9.233819
169.2,0.7362113,-0.39091301,55.989235,0,11.076097,449.9989,-0.025738265,9.6380167,11.076111,449.42407,-9.2338915
170.4,0.68519813,-0.39298195,55.84351,0,11.076097,449.9989,-0.025854295,8.9698229,11.07585,449.90305,-9.2338896
171.6,0.63876092,-0.3943052,55.535892,0,11.076097,449.9989,-0.025966646,8.3326941,11.076458,450.17062,-9.2339363
172.8,0.61387247,-0.39493468,55.535892,0,11.076097,449.9989,-0.025987407,8.0068483,11.07724,450.25528,-9.234066
174.0,0.60008878,-0.39551878,55.532795,0,11.076097,449.9989,-0.026047165,7.8266788,11.076741,450.20294,-9.2341833
175.2,0.59307683,-0.39643383,55.316723,0,11.076097,449.9989,-0.026073111,7.748384,11.075685,450.21484,-9.2339964
176.4,0.59249073,-0.39734909,55.239262,0,11.076097,449.9989,-0.026158066,7.7446408,11.076062,450.24231,-9.2346535
177.6,0.57887578,-0.39851287,55.239262,0,11.076097,449.9989,-0.026200568,7.5621195,11.076174,450.20007,-9.2343073
178.8,0.57140082,-0.39922127,55.239262,0,11.076097,449.9989,-0.026264638,7.4598145,11.076927,450.07532,-9.2342653
180.0,0.57981932,-0.40002152,55.239262,0,11.076097,449.9989,-0.026291497,7.5862231,11.076537,450.08856,-9.2347403
181.2,0.57059568,-0.40102008,55.239262,0,11.076097,449.9989,-0.026376091,7.4604297,11.076464,450.00732,-9.2344952
182.4,0.56986779,-0.40186188,55.275791,0,11.076097,449.9989,-0.026423069,7.4376254,11.075939,449.92358,-9.2349167
183.6,0.56994915,-0.40162551,55.499435,0,11.076097,449.9989,-0.026421376,7.4521813,11.076191,449.83475,-9.2351456
184.8,0.56319165,-0.4015606,55.535885,0,11.076097,449.9989,-0.026416337,7.3732843,11.075817,449.75296,-9.2343493
186.0,0.56532621,-0.4012405,55.535885,0,11.076097,449.9989,-0.026383767,7.3922639,11.07517,449.76993,-9.2338791
187.2,0.5632779,-0.40149248,55.535892,0,11.076097,449.9989,-0.026412765,7.3719106,11.075785,449.79694,-9.2335377
188.4,0.56211674,-0.40239298,55.535892,0,11.076097,449.9989,-0.02646655,7.3462167,11.076235,449.91238,-9.233777
189.6,0.55429691,-0.40319517,55.535892,0,11.076097,449.9989,-0.02653325,7.2618423,11.07655,450.1019,-9.233922
190.8,0.55803174,-0.40435708,55.466164,0,11.076097,449.9989,-0.026597675,7.3100843,11.076323,450.14166,-9.2339764
192.0,0.5555355,-0.40447429,55.248642,0,11.076097,449.9989,-0.026623042,7.2704639,11.07642,450.24612,-9.2339497
193.2,0.55375105,-0.40514758,55.239262,0,11.076097,449.9989,-0.026642499,7.2401934,11.075681,450.24252,-9.234292
194.4,0.55045289,-0.40584999,55.239262,0,11.076097,449.9989,-0.026711058,7.1864748,11.07517,450.09763,-9.2340975
195.3074,0.56622237,0.0069842632,55.239258,0,11.076099,3.2081649,0.00070000114,7.21557,11.075716,450.0704,-9.2347441
195.3098,0.54569191,0.0083267307,51.372429,0,11.076099,1.3868889000000002e-16,0.00048905524,6.9798222,11.076641,450.05515,-9.234046
195.3122,0.54878294,0.011369157,38.115005,0,11.076099,5.9955178e-33,0.0005483714,6.9686952,11.078031,450.05515,-9.2347012
195.3146,0.57217598,0.010166304,24.857588,0,11.076099,0.0,0.00064720871,7.2503252,11.077596,450.05515,-9.2351713
195.317,0.56899989,0.009616009,11.600164,0,11.076099,0.0,0.00085374498,7.2177482,11.075763,450.05515,-9.2345037
195.3194,0.561948,0.0076343855,0.0,0,11.076099,0.0,0.00069585646,7.1368656,11.075659,450.06143,-9.2352219
195.3218,0.55365568,0.010980665,0.0,0,11.076099,0.0,0.00057412131,6.9779124,11.076726,450.11172,-9.2345524
195.3242,0.5495854,0.014963701,0.0,0,11.076099,0.0,0.00060239504,6.9076886,11.079345,450.16205,-9.2334518
195.3266,0.55538344,0.014573788,0.0,0,11.076099,0.0,0.00089675712,7.0435009,11.077557,450.21234,-9.2349806
195.329,0.55647302,0.010958016,0.0,0,11.076099,0.0,0.0009504598,7.0229139,11.078251,450.26263,-9.2359343
195.3314,0.53236389,0.0078203157,0.0,0,11.076099,0.0,0.00069040881,6.8068709,11.077963,450.24408,-9.2362871
195.3338,0.53678316,0.0098625226,0.0,0,11.076099,0.0,0.00058053585,6.8913994,11.080934,450.22253,-9.2352657
195.3362,0.53692001,0.010955477,0.0,0,11.076099,0.0,0.00058868015,6.8067031,11.078746,450.20096,-9.236084
195.3386,0.54121292,0.01091125,0.0,0,11.076099,0.0,0.00069444958,6.8615046,11.076136,450.17941,-9.2353487
195.341,0.52912539,0.007980356,0.0,0,11.076099,0.0,0.00073635997,6.7877908,11.074489,450.16354,-9.234684
195.3434,0.5279153,0.0067645544,0.0,0,11.076099,0.0,0.00063337939,6.6041408,11.076672,450.14917,-9.2355127
195.3458,0.52539891,0.011310665,0.0,0,11.076099,0.0,0.00061090483,6.6971846,11.075607,450.1348,-9.2351999
195.3482,0.53407234,0.016266074,0.0,0,11.076099,0.0,0.00070265448,6.8011556,11.075166,450.12042,-9.2345438
195.3506,0.5309121,0.012904126,0.0,0,11.076099,0.0,0.00083314133,6.7028804,11.077039,450.133,-9.2348909
195.353,0.52627337,0.0081347944,0.0,0,11.076099,0.0,0.00081675517,6.7246222,11.078746,450.16174,-9.2351284
195.3554,0.52558863,0.0068853665,0.0,0,11.076099,0.0,0.00066703768,6.7040248,11.076666,450.19049,-9.2350473
195.3578,0.5304336,0.0085946331,0.0,0,10.976469,0.0,0.00047933974,6.7028255,11.074667,450.21924,-9.234479
195.3602,0.53894168,0.010234131,0.0,0,10.615495,0.0,0.0004933562,6.7751884,11.077189,450.2348,-9.23382
195.3626,0.52265882,0.0099634789,0.0,0,10.254521,0.0,0.00065750943,6.6617713,11.058324,450.2348,-9.2340336
195.365,0.54037189,0.0074727675,0.0,0,9.893548,0.0,0.0007331192,6.9229951,10.92988,450.2348,-9.2353764
195.3674,0.50940704,0.0089962129,0.0,0,9.5325737,0.0,0.00067779503,6.4301434,10.647726,450.2348,-9.2358112
195.3698,0.55932438,0.010310021,0.0,0,9.1800261,0.0,0.00052715465,7.1320281,10.25219,450.33749,-9.2351742
195.3722,5.1806569,0.27633291,0.0,0,8.8288584,0.0,0.017174326,65.317833,9.804945,450.68964,-9.230154
195.3746,5.7490721,0.71462339,0.0,0,8.4910259,0.0,0.048563004,69.185043,9.2966642,451.04175,-9.2321672
195.377,6.0180178,1.1511104,0.0,0,8.1570415,0.0,0.079842843,70.463539,8.8413267,451.39386,-9.2317886
195.3794,5.9954796,1.5441527,0.0,0,7.8342957,0.0,0.10832022,68.451729,8.4743748,451.55817,-9.2307253
195.3818,6.3110337,1.8420035,0.0,0,7.5165353,0.0,0.13037495,70.650314,8.147356,450.40787,-9.2293959
195.3842,6.3558683,2.1405413,0.0,0,7.2082515,0.0,0.15345344,69.428589,7.8325558,449.25757,-9.2297611
195.3866,6.6003227,2.4461944,0.0,0,6.9060431,0.0,0.17760311,70.410294,7.5290985,448.10727,-9.2298393
195.389,6.7181525,2.7337432,0.0,0,6.6115613,0.0,0.20124491,69.890747,7.2402797,446.95694,-9.2307825
195.3914,6.9510498,3.0174813,0.0,0,6.3240418,0.0,0.22433807,70.750771,6.949616,443.6615,-9.2306499
195.3938,7.0797639,3.3094194,0.0,0,6.042748,0.0,0.24851948,70.336143,6.6587644,440.27277,-9.231246
195.3962,7.2641172,3.6024883,0.0,0,5.7692914,0.0,0.27376169,70.292488,6.365253,436.88406,-9.2301559
195.3986,7.4653583,3.8864496,0.0,0,5.5006137,0.0,0.29953632,70.442467,6.0812945,433.49533,-9.2308807
195.401,7.66257,4.1654668,0.0,0,5.2404532,0.0,0.32526523,70.489418,5.7962966,431.06195,-9.2304583
195.4034,7.8216133,4.4403563,0.0,0,4.9838042,0.0,0.35077256,70.12973,5.5109916,428.87997,-9.229784
195.4058,8.0189962,4.7171545,0.0,0,4.7363639,0.0,0.37672108,70.005806,5.2380118,426.698,-9.2293272
195.4082,8.2142296,4.9870925,0.0,0,4.4912457,0.0,0.4034434,69.909592,4.9693484,424.51602,-9.2286596
195.4106,8.4447994,5.2454705,0.0,0,4.2558532,0.0,0.43003783,69.848793,4.7091823,422.5618,-9.2284422
195.413,8.6081476,5.4949617,0.0,0,4.0217257,0.0,0.45639801,69.504295,4.4598231,420.74423,-9.2285023
195.4154,8.8307838,5.7408819,0.0,0,3.7978494,0.0,0.48223394,69.417442,4.2091846,418.9267,-9.2291222
195.4178,9.0509453,5.9834423,0.0,0,3.5743496,0.0,0.50805545,69.268501,3.9708564,417.10913,-9.2285662
195.4202,9.3044806,6.2171402,0.0,0,3.3612847,0.0,0.53411067,69.38942,3.7439351,414.5094,-9.2306643
195.4226,9.5642405,6.4380245,0.0,0,3.1483088,0.0,0.56053525,69.503456,3.5200119,410.98529,-9.2309704
195.425,9.8121662,6.6507473,0.0,0,2.9451065,0.0,0.5862838,69.484291,3.3033066,407.46121,-9.2304268
195.4274,10.092371,6.8619556,0.0,0,2.7424984,0.0,0.61135286,69.674721,3.0873728,403.9371,-9.2303619
195.4298,10.419264,7.0749969,0.0,0,2.5483873,0.0,0.63681746,70.145706,2.8756769,399.99228,-9.2286234
195.4322,10.744119,7.2834249,0.0,0,2.3556671,0.0,0.6637122,70.387329,2.6772101,395.02579,-9.230443
195.4346,11.122172,7.4852552,0.0,0,2.1702483,0.0,0.6909951,70.928535,2.4753571,390.05927,-9.2287636
195.437,11.45737,7.6769719,0.0,0,1.9869361,0.0,0.71753782,71.202957,2.2769876,385.09277,-9.2281494
195.4394,11.834554,7.8674393,0.0,0,1.8098084,0.0,0.74318486,71.650261,2.0842533,380.59418,-9.2273912
195.4418,12.279353,8.0603132,0.0,0,1.6354244,0.0,0.76961714,72.379707,1.895865,379.37073,-9.227869
195.4442,12.713427,8.2431202,0.0,0,1.4662173,0.0,0.79625559,72.951675,1.7169738,378.14731,-9.2276392
195.4466,13.139974,8.418047,0.0,0,1.3003293,0.0,0.82373971,73.389938,1.543943,376.92389,-9.2266932
195.449,13.650033,8.5873823,0.0,0,1.1387084,0.0,0.85037285,74.230301,1.3713458,375.70044,-9.227047
195.4514,14.21551,8.7573938,0.0,0,0.98093235,0.0,0.87628275,75.319176,1.1991038,369.03247,-9.2270517
195.4538,14.794906,8.9243145,0.0,0,0.82657731,0.0,0.90233189,76.374992,1.0391204,362.12784,-9.225832
195.4562,15.394921,9.0848837,0.0,0,0.67652941,0.0,0.92931134,77.298645,0.8725577,355.22321,-9.2244892
195.4586,16.003355,9.2355022,0.0,0,0.52908593,0.0,0.95637769,78.268829,0.7159977,348.31854,-9.2244663
195.461,16.675434,9.3861666,0.0,0,0.3862859,0.0,0.9833715,79.350021,0.56020582,343.83817,-9.2244473
195.4634,14.869938,9.4531517,0.0,0,0.24542016,0.0,0.99517596,69.958557,0.45559734,339.99573,-9.2262669
195.4658,13.176723,9.4759197,0.0,0,0.10962815,0.0,0.99791062,61.978088,0.40714505,336.15329,-9.2271881
195.4682,12.463898,9.4785442,0.0,0,-0.025516368,0.0,0.99839056,58.470966,0.37488425,332.31082,-9.2283077
195.4706,11.961479,9.4808655,0.0,0,-0.15794842,0.0,1.0005333,56.026546,0.35080177,335.36224,-9.2295599
195.473,11.953966,9.4791231,0.0,0,-0.29038045,0.0,1.0006807,55.912289,0.30979338,342.54984,-9.2286282
195.4754,12.25955,9.4860716,0.0,0,-0.42281243,0.0,1.0008059,57.380116,0.24915354,349.73746,-9.2291851
195.4778,12.430006,9.4983072,0.0,0,-0.55524439,0.0,1.0019246,58.08308,0.18304305,356.92505,-9.2294207
195.4802,12.426854,9.5067701,0.0,0,-0.68767637,0.0,1.0039732,57.984661,0.11937401,362.84821,-9.230195
195.4826,12.282393,9.5086889,0.0,0,-0.82010835,0.0,1.0054878,57.239468,0.061595824,367.27704,-9.2297077
195.485,12.031208,9.508996,0.0,0,-0.9525404,0.0,1.0060503,56.0172,0.015364915,371.70587,-9.2290277
195.4874,11.709054,9.5120897,0.0,0,-1.0849724,0.0,1.0055237,54.56004,-0.0098789111,376.1347,-9.2297802
195.4898,11.281537,9.5212021,4.6697226,0,-0.72870702,450.0,1.0059479,52.548149,-0.025181731,380.29016,-9.2300606
195.4922,10.782709,9.5251293,20.679878,0,-0.27022067,450.0,1.0070273,50.186115,-0.024552451,383.78171,-9.2312555
195.4946,10.325465,9.520031,36.690037,0,0.18826568,450.0,1.0079077,48.028107,-0.019705113,387.27328,-9.2310839
195.497,9.9780884,9.5149212,52.700188,0,0.64675206,450.0,1.0074382,46.402489,-0.016704608,390.76483,-9.2314281
195.4994,9.7473793,9.5176172,66.708984,0,1.1052387,450.0,1.0064552,45.341633,-0.014767025,394.18689,-9.2308083
195.5018,9.3219376,9.5174665,66.708984,0,1.563725,450.0,1.0055006,43.468361,-0.0040127132,397.12225,-9.2316856
195.5042,8.1049376,9.5121422,66.708984,0,2.0222113,450.0,1.0049633,37.907368,0.058814045,400.05759,-9.2327042
195.5066,5.6478601,9.5059395,66.708984,0,2.4806981,450.0,1.0051681,26.63406,0.18232572,402.99295,-9.2335215
195.509,1.9686162,9.4768591,66.708984,0,2.9391842,450.0,1.0003196,9.5326099,0.40484747,405.92831,-9.2376719
195.5114,0.05874728,9.4033594,64.472702,0,3.3976707,450.0,0.98561472,0.52487755,0.8729834,408.43726,-9.2387028
195.5138,-0.46729684,9.4094172,62.13921,0,3.8561573,450.0,0.98560256,-2.2251813,1.5982653,410.92764,-9.2397442
195.5162,0.19353242,9.4234629,59.80571,0,4.3146434,450.0,0.98880857,0.74551529,2.4180729,413.41803,-9.2394705
195.5186,0.036092103,9.4496765,57.472218,0,4.7731299,450.0,0.99492419,0.2726222,3.116142,415.90842,-9.2393208
195.521,0.011554947,9.4621286,56.986084,0,5.2316165,450.0,0.99759263,-0.0065737264,3.6184361,417.80865,-9.2386379
195.5234,-0.040726516,9.465476,56.986084,0,5.6901026,450.0,0.9968856,-0.19004534,4.0521803,419.55359,-9.2372408
195.5258,-0.052181292,9.4728985,56.986084,0,6.1485891,450.0,0.99732697,-0.24279113,4.4679623,421.29852,-9.2373123
195.5282,-0.059654798,9.4684124,56.986084,0,6.6070752,450.0,0.9972502,-0.29191357,4.8886437,423.04346,-9.2369995
195.5306,0.052208379,9.461092,55.759998,0,7.0655618,450.0,0.99720693,0.20054595,5.3330746,424.46347,-9.2368031
195.533,0.017386131,9.4522076,53.798279,0,7.5240483,450.0,0.99573278,0.17017488,5.7987499,425.68857,-9.2368879
195.5354,-0.15303338,9.459672,51.836559,0,7.9825354,450.0,0.99582887,-0.68170786,6.2742901,426.91364,-9.2355824
195.5378,0.096604459,9.4634333,49.87484,0,8.441021,450.0,0.99530584,0.35931644,6.766398,428.13873,-9.2353153
195.5402,0.0019383791,9.4641542,48.812256,0,8.8995075,450.0,0.99618685,0.072325312,7.2513227,429.21478,-9.2353516
195.5426,-0.053061631,9.4589977,48.812256,0,9.3579931,450.0,0.99693775,-0.29553914,7.7241111,430.11472,-9.235918
195.545,0.085663438,9.453352,48.812256,0,9.8164806,450.0,0.9960978,0.34444395,8.2064123,431.01465,-9.2355309
195.5474,-0.10238653,9.45681,48.812256,0,10.274966,450.0,0.99510163,-0.46128044,8.6728973,431.91458,-9.2345161
195.5498,-0.048882876,9.4603262,48.363125,0,10.733453,450.0,0.99521399,-0.2775507,9.1351385,432.74725,-9.2340202
195.5522,0.12718657,9.458149,46.823284,0,11.191939,450.0,0.99542916,0.58279163,9.6073647,433.41663,-9.2335453
195.5546,-0.093216442,9.4543333,45.283436,0,11.650426,450.0,0.99604142,-0.3853792,10.083415,434.08597,-9.2336512
195.557,-0.03018358,9.4547491,43.743595,0,12.108912,450.0,0.99615097,-0.23140644,10.553485,434.75531,-9.2349625
195.5594,0.050266784,9.4578094,42.39624,0,12.567399,450.0,0.99514818,0.26782504,11.03225,435.40759,-9.2323427
195.5618,-0.09027417,9.4651556,42.39624,0,13.025885,450.0,0.9953742,-0.3828012,11.485979,435.94019,-9.2322836
195.5642,0.0075498745,9.4630156,42.39624,0,13.484371,450.0,0.9962526,0.00010364686,11.940413,436.47278,-9.2319069
195.5666,0.04513542,9.456646,42.39624,0,13.942858,450.0,0.99659574,0.20820351,12.40252,437.0054,-9.2328768
195.569,-0.12397461,9.451786,42.39624,0,14.401344,450.0,0.99568248,-0.53591996,12.867118,437.53799,-9.23246
195.5714,0.0071996264,9.4546947,41.175762,0,14.859831,450.0,0.99476498,-0.049563903,13.350208,437.97403,-9.2337923
195.5738,0.047638901,9.4556389,39.902229,0,15.318317,450.0,0.99418277,0.24505255,13.833148,438.40588,-9.2327414
195.5762,-0.071906827,9.4595041,38.628693,0,15.776803,450.0,0.99571419,-0.36624494,14.309203,438.83774,-9.2344484
195.5786,-0.078514017,9.4528008,37.355156,0,16.235291,450.0,0.99578846,-0.36140427,14.776875,439.26959,-9.2344017
195.581,0.031095078,9.4500151,37.089844,0,16.693775,450.0,0.9949764,0.13997725,15.233896,439.63876,-9.2339993
195.5834,-0.087054975,9.4555893,37.089844,0,17.152262,450.0,0.99467999,-0.37637487,15.683863,439.99142,-9.2337751
195.5858,0.017550612,9.4625778,37.089844,0,17.61075,450.0,0.99510014,0.017668638,16.135984,440.34409,-9.2330494
195.5882,-0.033312589,9.4587803,37.089844,0,17.999975,450.0,0.99550301,-0.099326454,16.596325,440.69675,-9.2330542
195.5906,-0.14974903,9.4563875,36.308708,0,18.0,450.0,0.99643797,-0.67112422,17.04726,441.04944,-9.2334251
195.593,0.067355007,9.4524937,35.058903,0,18.0,450.0,0.99551708,0.30192304,17.478182,441.4021,-9.2330818
195.5954,-0.018497108,9.4529343,33.809101,0,18.0,450.0,0.99428642,-0.053649191,17.855602,441.75476,-9.2333183
195.5978,0.02490689,9.4603891,32.559296,0,18.0,450.0,0.99526113,0.082788169,18.166756,442.10742,-9.2353086
195.6002,0.0060202675,9.4611349,31.882326,0,18.0,450.0,0.99622893,0.050394289,18.390478,442.46329,-9.2378178
195.6026,-0.0056670336,9.46313,31.882326,0,18.0,450.0,0.99760675,-0.0062800129,18.490808,442.82294,-9.2440281
195.605,0.12903346,9.4694872,31.882326,0,18.0,450.0,0.99857831,0.62529153,18.463753,443.18256,-9.2500439
195.6074,0.49715853,9.4841251,31.882326,0,18.0,450.0,0.99976027,2.3439977,18.345289,443.54221,-9.259697
195.6098,0.34795296,9.4872293,31.483955,0,18.0,450.0,0.99954379,1.643646,18.218008,443.88708,-9.2725906
195.6122,0.34800273,9.4861355,30.118134,0,18.0,450.0,1.0005592,1.6265719,18.121349,444.19614,-9.2906218
195.6146,0.33410788,9.4752855,28.752314,0,18.0,450.0,1.0001425,1.5764453,18.06419,444.50519,-9.3078547
195.617,0.33557171,9.4732246,27.386492,0,18.0,450.0,0.99929625,1.5977197,18.045811,444.81427,-9.3266773
195.6194,0.34419405,9.4744225,26.191408,0,18.0,450.0,0.99805456,1.6127675,18.048264,445.12152,-9.3470526
195.6218,0.32489133,9.4788179,26.191408,0,18.0,450.0,0.99847835,1.5385907,18.0648,445.41614,-9.3686218
195.6242,0.28797153,9.4778728,26.191408,0,18.0,450.0,0.99930829,1.3424749,18.088928,445.71078,-9.3888721
195.6266,0.32597634,9.4740953,26.191408,0,18.0,450.0,0.99958754,1.5173776,18.10541,446.0054,-9.4084167
195.629,0.33862403,9.4730234,26.191408,0,18.0,450.0,0.99908996,1.5657709,18.123026,446.30005,-9.4260664
195.6314,0.35999843,9.4768658,24.341738,0,18.0,450.0,0.9983077,1.6780267,18.13155,446.61533,-9.4442816
195.6338,0.32304215,9.4820652,22.411659,0,18.0,450.0,0.99875653,1.5553632,18.137739,446.93152,-9.4614344
195.6362,0.33131477,9.4825239,20.481581,0,18.0,450.0,1.0002527,1.5291264,18.134567,447.24771,-9.477355
195.6386,0.32436645,9.4737072,18.551502,0,18.0,450.0,0.99983406,1.5401589,18.133471,447.56393,-9.4955416
195.641,0.37378323,9.4727516,18.149414,0,18.0,450.0,0.99874979,1.7410196,18.131741,447.85165,-9.5124121
195.6434,0.3376556,9.4762506,18.149414,0,18.0,450.0,0.99816817,1.596047,18.128355,448.13193,-9.5303516
195.6458,0.33486983,9.4800406,18.149414,0,18.0,450.0,0.99867809,1.5530597,18.13059,448.4122,-9.5505514
195.6482,0.32990366,9.4775314,18.149414,0,18.0,450.0,0.99950683,1.5511882,18.126795,448.69244,-9.5694256
195.6506,0.3544862,9.4726429,16.631639,0,18.0,450.0,0.99954015,1.6515273,18.124769,448.92331,-9.5856886
195.653,0.36935762,9.4717112,14.20322,0,18.0,450.0,0.99860936,1.7421185,18.120281,449.12451,-9.6052208
195.6554,0.34070358,9.4784298,11.774803,0,18.0,450.0,0.99832922,1.5991566,18.116217,449.32571,-9.6246386
195.6578,0.32955486,9.4825373,9.346385,0,18.0,450.0,0.9988535,1.5526289,18.113943,449.52695,-9.6424084
195.6602,0.34138471,9.4791613,8.0310059,0,18.0,450.0,0.99971008,1.5708936,18.113419,449.72485,-9.65872
195.6626,0.36485171,9.4728584,8.0310059,0,18.0,450.0,0.99974054,1.7109103,18.112476,449.91888,-9.6767187
195.665,0.34386429,9.4743242,8.0310059,0,18.0,450.0,0.99906284,1.6504712,18.11095,450.11292,-9.6940765
195.6674,0.32576802,9.4773588,8.0310059,0,18.0,450.0,0.99834353,1.5598621,18.109938,450.30695,-9.7117567
195.6698,0.33447748,9.4789495,7.4688249,0,18.0,450.0,0.99873567,1.5788579,18.105562,450.50726,-9.730114
195.6722,0.35280085,9.4781389,5.5413828,0,18.0,450.0,0.99963534,1.6319903,18.10586,450.72287,-9.7467051
195.6746,0.36011839,9.4730015,3.6139414,0,18.0,450.0,0.99974066,1.7238599,18.103863,450.93845,-9.7651587
195.677,0.34224004,9.4753742,1.6865001,0,18.0,450.0,0.99911761,1.6560042,18.104967,451.15402,-9.7844639
195.6794,0.31532782,9.4810047,0.0,0,18.0,450.0,0.99885947,1.470843,18.104727,451.36063,-9.801899
195.6818,0.33048233,9.4833117,0.0,0,18.0,450.0,0.99892038,1.5620505,18.103586,451.50436,-9.8203115
195.6842,0.34891069,9.4779329,0.0,0,18.0,450.0,0.99961853,1.6595817,18.104595,451.64807,-9.8388748
195.6866,0.35369658,9.4728918,0.0,0,18.0,450.0,0.99981779,1.6631801,18.101843,451.79181,-9.8559465
195.689,0.32503706,9.473032,0.0,0,18.0,450.0,0.99857068,1.5491488,18.103596,451.93555,-9.8733635
195.6914,0.33002353,9.4754887,0.0,0,18.0,450.0,0.99798369,1.5448065,18.105305,452.07925,-9.8915796
195.6938,0.33868882,9.4763098,0.0,0,18.0,450.0,0.99814212,1.6087286,18.101137,452.22296,-9.9095974
195.6962,0.36389756,9.4739761,0.0,0,18.0,450.0,0.99902785,1.7219517,18.094929,452.3667,-9.9276209
195.6986,0.35141075,9.4700308,0.0,0,18.0,450.0,0.99912333,1.6072086,18.097437,452.51041,-9.9463015
195.701,0.32489806,9.4743614,0.0,0,18.0,450.0,0.99899137,1.5488852,18.098505,452.64844,-9.9633293
195.7034,0.34237716,9.4810295,0.0,0,18.0,450.0,0.99888158,1.5878481,18.096045,452.78497,-9.9812841
195.7058,0.36728376,9.4836597,0.0,0,18.0,450.0,0.999156,1.7188559,18.094456,452.92151,-9.9989491
195.7082,0.3708964,9.4793758,0.0,0,18.0,450.0,1.0001328,1.7292578,18.093132,453.05804,-10.01674
195.7106,0.32777393,9.4735041,0.0,0,18.0,450.0,0.99982792,1.5512096,18.096281,453.16763,-10.035188
195.713,0.34490898,9.472168,0.0,0,18.0,450.0,0.99844944,1.6383123,18.089384,453.26108,-10.052147
195.7154,0.35957602,9.474719,0.0,0,18.0,450.0,0.99775481,1.6770451,18.090063,453.35449,-10.070446
195.7178,0.38347027,9.4771557,0.0,0,18.0,450.0,0.99836534,1.8132927,18.090492,453.44794,-10.08777
195.7202,0.3650794,9.4762373,0.0,0,18.0,450.0,0.99957514,1.728829,18.089403,453.54135,-10.105719
195.7226,0.35025677,9.4731407,0.0,0,18.0,450.0,0.99956977,1.6378083,18.087196,453.63477,-10.125759
195.725,0.34036615,9.4712219,0.0,0,18.0,450.0,0.99827772,1.5974654,18.08872,453.72818,-10.143931
195.7274,0.38159221,9.4793758,0.0,0,18.0,450.0,0.99832118,1.7938286,18.087425,453.82159,-10.161084
195.7298,0.37864757,9.4839668,0.0,0,18.0,450.0,0.99936241,1.7627249,18.083666,453.9234,-10.178939
195.7322,0.34366545,9.4794674,0.0,0,18.0,450.0,1.0002217,1.6550967,18.082329,454.04556,-10.196772
195.7346,0.3460618,9.4724302,0.0,0,18.0,450.0,0.99967653,1.6548173,18.086571,454.16772,-10.21443
195.737,0.35373551,9.4710836,0.0,0,18.0,450.0,0.99811566,1.6414564,18.083445,454.28989,-10.232123
195.7394,0.38691345,9.4761629,0.0,0,18.0,450.0,0.99791843,1.8401502,18.082321,454.41028,-10.251258
195.7418,0.35850793,9.4795961,0.0,0,18.0,450.0,0.99883568,1.693364,18.080595,454.51807,-10.26888
195.7442,0.3459152,9.4748964,0.0,0,18.0,450.0,0.99953914,1.6064765,18.079992,454.62585,-10.287497
195.7466,0.34549519,9.4729729,0.0,0,18.0,450.0,0.99963623,1.6376514,18.08235,454.73367,-10.304892
195.749,0.37474629,9.4737682,0.0,0,18.0,450.0,0.9986406,1.7514066,18.078384,454.84146,-10.323995
195.7514,0.36566982,9.4833708,0.0,0,18.0,450.0,0.99890471,1.7314076,18.082048,454.91483,-10.339739
195.7538,0.35069308,9.4846649,0.0,0,18.0,450.0,0.99958044,1.6447635,18.079298,454.98666,-10.357432
195.7562,0.34497866,9.4772615,0.0,0,18.0,450.0,1.0001425,1.5870736,18.076416,455.05853,-10.37682
195.7586,0.358199,9.4686241,0.0,0,18.0,450.0,0.99901533,1.6434398,18.077774,455.13037,-10.395059
195.761,0.38565153,9.4728355,0.0,0,18.0,450.0,0.99837989,1.8223226,18.074415,455.2193,-10.410957
195.7634,0.35910285,9.4795084,0.0,0,18.0,450.0,0.99841398,1.6898,18.073439,455.31274,-10.428921
195.7658,0.34772006,9.4780035,0.0,0,18.0,450.0,0.99869132,1.6401892,18.07373,455.40616,-10.447727
195.7682,0.34635949,9.4707394,0.0,0,18.0,450.0,0.99870789,1.5986784,18.072083,455.49957,-10.466521
195.7706,0.3708849,9.4693518,0.0,0,18.0,450.0,0.9988063,1.7160554,18.073542,455.59747,-10.4851
195.773,0.38567737,9.4757595,0.0,0,18.0,450.0,0.99870181,1.8106109,18.07197,455.69809,-10.501971
195.7754,0.36165622,9.4814978,0.0,0,18.0,450.0,0.99856633,1.6886859,18.070822,455.79871,-10.52049
195.7778,0.3488957,9.4823503,0.0,0,18.0,450.0,0.99931884,1.6557519,18.071585,455.89929,-10.539543
195.7802,0.37014568,9.474741,0.0,0,18.0,450.0,0.99961126,1.714407,18.07091,455.97357,-10.556432
195.7826,0.38782755,9.4687405,0.0,0,18.0,450.0,0.99887377,1.8056767,18.071766,456.01666,-10.573932
195.785,0.36603758,9.4720945,0.0,0,18.0,450.0,0.99791539,1.7286224,18.070864,456.05978,-10.59307
195.7874,0.36068562,9.4776268,0.0,0,18.0,450.0,0.99812686,1.6855161,18.068871,456.10291,-10.612727
195.7898,0.36497608,9.4768753,0.0,0,18.0,450.0,0.99878174,1.7160873,18.065067,456.14035,-10.629022
195.7922,0.3763752,9.4734802,0.0,0,18.0,450.0,0.99944091,1.7781514,18.0697,456.16406,-10.646367
195.7946,0.3996726,9.474843,0.0,0,18.0,450.0,0.99960345,1.9066638,18.064871,456.18774,-10.66432
195.797,0.36717007,9.4759216,0.0,0,18.0,450.0,0.99859631,1.7103955,18.069084,456.21143,-10.683185
195.7994,0.36387399,9.4799948,0.0,0,18.0,450.0,0.9981758,1.7042847,18.059692,456.25201,-10.702014
195.8018,0.36769474,9.4781275,0.0,0,18.0,450.0,0.99876153,1.715928,18.063097,456.30951,-10.71913
195.8042,0.39685467,9.473567,0.0,0,18.0,450.0,0.99949318,1.8797556,18.065809,456.367,-10.737255
195.8066,0.37327462,9.4720478,0.0,0,18.0,450.0,0.99935848,1.7708853,18.062195,456.4245,-10.754297
195.809,0.35549945,9.4730921,0.0,0,18.0,450.0,0.99819666,1.6746122,18.06374,456.48438,-10.773423
195.8114,0.35479584,9.4776669,0.0,0,18.0,450.0,0.99818295,1.6990343,18.061274,456.54907,-10.79058
195.8138,0.37489891,9.4749308,0.0,0,18.0,450.0,0.99850279,1.7470751,18.064747,456.61374,-10.80861
195.8162,0.39259538,9.4724474,0.0,0,18.0,450.0,0.99944341,1.8466916,18.06361,456.67841,-10.827223
195.8186,0.35054803,9.4726219,0.0,0,18.0,450.0,0.99929851,1.6896406,18.064016,456.73709,-10.845318
195.821,0.37366852,9.4757204,0.0,0,18.0,450.0,0.99844444,1.7248796,18.059706,456.76584,-10.862416
195.8234,0.34652433,9.4795685,0.0,0,18.0,450.0,0.99792844,1.6567565,18.05925,456.79459,-10.880078
195.8258,0.40085682,9.4788227,0.0,0,18.0,450.0,0.99901557,1.8575121,18.05946,456.82333,-10.897781
195.8282,0.37421048,9.4736271,0.0,0,18.0,450.0,0.99976462,1.7856699,18.058872,456.85208,-10.915376
195.8306,0.36068341,9.470396,0.0,0,18.0,450.0,0.99892312,1.6782329,18.05748,456.87363,-10.932627
195.833,0.37025139,9.4731989,0.0,0,18.0,450.0,0.99795395,1.7263849,18.057632,456.8952,-10.950167
195.8354,0.38947961,9.4773016,0.0,0,18.0,450.0,0.99816167,1.7862712,18.054932,456.91675,-10.969346
195.8378,0.39301404,9.475955,0.0,0,18.0,450.0,0.99870825,1.8509957,18.059687,456.93829,-10.987852
195.8402,0.37098759,9.4719954,0.0,0,18.0,450.0,0.99931955,1.7375779,18.055281,456.97784,-11.006476
195.8426,0.36627474,9.4718962,0.0,0,18.0,450.0,0.99902928,1.7328284,18.053537,457.02097,-11.024887
195.845,0.36107486,9.4734144,0.0,0,18.0,450.0,0.99794507,1.6989176,18.055017,457.06409,-11.042977
195.8474,0.40610415,9.4795151,0.0,0,18.0,450.0,0.99807835,1.9102895,18.054855,457.10721,-11.060699
195.8498,0.37982282,9.4815378,0.0,0,18.0,450.0,0.99962032,1.8011004,18.055758,457.15991,-11.08087
195.8522,0.36868271,9.4746809,0.0,0,18.0,450.0,0.99995583,1.7217869,18.056425,457.21738,-11.099607
195.8546,0.37292737,9.4703875,0.0,0,18.0,450.0,0.99889487,1.7194365,18.054558,457.27487,-11.116334
195.857,0.39284909,9.4723358,0.0,0,18.0,450.0,0.99760407,1.8126107,18.05467,457.33234,-11.132931
195.8594,0.4073576,9.4762211,0.0,0,18.0,450.0,0.99806505,1.913713,18.050596,457.37906,-11.151377
195.8618,0.38005352,9.4764652,0.0,0,18.0,450.0,0.99899852,1.8084971,18.053196,457.41498,-11.169526
195.8642,0.36999476,9.472682,0.0,0,18.0,450.0,0.99940228,1.7244492,18.053125,457.45093,-11.187594
195.8666,0.37579694,9.4730463,0.0,0,18.0,450.0,0.99917901,1.7659895,18.050032,457.48685,-11.20276
195.869,0.41468751,9.4769773,0.0,0,18.0,450.0,0.99825698,1.9252015,18.048431,457.51318,-11.219954
195.8714,0.405274,9.4840269,0.0,0,18.0,450.0,0.99890286,1.9171227,18.049067,457.52039,-11.239751
195.8738,0.3788074,9.479558,0.0,0,18.0,450.0,0.9994815,1.7413853,18.049847,457.52756,-11.258853
195.8762,0.3670173,9.469717,0.0,0,18.0,450.0,0.99915487,1.7470291,18.046509,457.53476,-11.276853
195.8786,0.39090875,9.4679022,0.0,0,18.0,450.0,0.99815476,1.8171306,18.046053,457.54672,-11.292946
195.881,0.41794205,9.4721727,0.0,0,18.0,450.0,0.99755096,1.9774152,18.046915,457.58267,-11.311232
195.8834,0.38315803,9.4768763,0.0,0,18.0,450.0,0.99805915,1.8014761,18.046843,457.61859,-11.331652
195.8858,0.36959463,9.4745712,0.0,0,18.0,450.0,0.99878818,1.7483063,18.041996,457.65454,-11.349293
196.0877,0.36156508,9.4760456,0.0,0,18.0,0.85476655,0.998914,1.6947207,18.025152,448.42239,-11.477489
197.2877,0.28635621,9.4869347,0.0,0,18.0,3.6951402e-17,1.000917,1.3391939,18.000614,426.58286,-11.479206
198.4877,0.27450845,9.4951982,0.0,0,18.0,1.5974028e-33,1.0023794,1.2850518,18.000204,413.02319,-11.479135
199.6877,0.26155448,9.50212,0.0,0,18.0,1.4012985e-45,1.0036923,1.2224349,17.999784,401.25098,-11.48091
200.8877,0.24885659,9.5085821,0.0,0,18.0,1.4012985e-45,1.0048333,1.1608772,17.999887,390.31631,-11.479923
202.0877,0.24714679,9.5155468,0.0,0,18.0,1.4012985e-45,1.0061768,1.1523613,17.999521,379.51898,-11.479351
203.2877,0.2459659,9.5219955,0.0,0,18.0,1.4012985e-45,1.0072767,1.140339,18.000452,369.44089,-11.479303
204.4877,0.24739149,9.5279293,0.0,0,18.0,1.4012985e-45,1.0084671,1.1525766,17.999937,359.45822,-11.480289
205.6877,0.24837619,9.5343943,0.0,0,18.0,1.4012985e-45,1.0095881,1.1537811,18.001024,349.45538,-11.480297
206.8877,0.24043937,9.54002,0.0,0,18.0,1.4012985e-45,1.0106528,1.1168755,17.999187,340.27545,-11.480983
208.0877,0.23403549,9.5457058,0.0,0,18.0,1.4012985e-45,1.0116758,1.0823629,18.000311,330.87619,-11.480063
209.2877,0.24000491,9.5508718,0.0,0,18.0,1.4012985e-45,1.0126314,1.1112684,18.000443,322.23721,-11.479931
210.4877,0.23779598,9.5566196,0.0,0,18.0,1.4012985e-45,1.0136933,1.1049114,17.999689,313.26031,-11.479753
211.6877,0.24816601,9.5620279,0.0,0,18.0,1.4012985e-45,1.0146521,1.1471701,18.001022,304.48428,-11.480185
212.8877,0.24189389,9.5667095,0.0,0,18.0,1.4012985e-45,1.0155509,1.1122221,18.000019,296.3858,-11.480592
214.0877,0.2440526,9.5722599,0.0,0,18.0,1.4012985e-45,1.0165359,1.1255946,18.000366,288.50366,-11.481084
215.2877,0.23321481,9.5771208,0.0,0,18.0,1.4012985e-45,1.0174624,1.0781423,18.000799,280.625,-11.481223
216.4877,0.23428762,9.581542,0.0,0,18.0,1.4012985e-45,1.0182519,1.0818861,18.000441,272.93842,-11.480787
217.6877,0.24478012,9.5868435,0.0,0,18.0,1.4012985e-45,1.0192291,1.121588,18.000389,265.63977,-11.481039
218.8877,0.2444915,9.5915041,0.0,0,18.0,1.4012985e-45,1.0200278,1.1201807,18.000166,258.8468,-11.480754
220.0877,0.23502056,9.595438,0.0,0,18.0,1.4012985e-45,1.0208284,1.0782776,17.999403,252.11137,-11.480827
221.2877,0.2346158,9.6000986,0.0,0,18.0,1.4012985e-45,1.0216093,1.0734543,17.999224,245.4164,-11.480694
222.4877,0.23574401,9.6042213,0.0,0,18.0,1.4012985e-45,1.0224346,1.0797814,17.999746,239.05197,-11.48012
223.6877,0.23296815,9.6085005,0.0,0,18.0,1.4012985e-45,1.023164,1.0636493,18.000031,232.90601,-11.480187
224.8877,0.23868491,9.6128407,0.0,0,18.0,1.4012985e-45,1.0240167,1.092207,18.000648,226.63037,-11.480821
226.0877,0.23194182,9.6167917,0.0,0,18.0,1.4012985e-45,1.0246888,1.0599184,18.000746,220.63826,-11.481117
227.2877,0.23263831,9.6200457,0.0,0,18.0,1.4012985e-45,1.0253787,1.0692754,17.999861,214.74576,-11.48157
228.4877,0.23873876,9.6243572,0.0,0,18.0,1.4012985e-45,1.0261275,1.0922222,18.000641,209.02812,-11.481468
229.6877,0.23522136,9.6278362,0.0,0,18.0,1.4012985e-45,1.0268444,1.0711625,18.000746,203.40726,-11.481872
230.8877,0.23339163,9.6319094,0.0,0,18.0,1.4012985e-45,1.0275279,1.063722,17.999323,198.09143,-11.481853
232.0877,0.22701855,9.6347017,0.0,0,18.0,1.4012985e-45,1.0281374,1.0329926,18.000532,193.14064,-11.481915
233.2877,0.22703488,9.6387119,0.0,0,18.0,1.4012985e-45,1.0288148,1.0314233,18.00066,188.24884,-11.48155
234.4877,0.23183486,9.6419706,0.0,0,18.0,1.4012985e-45,1.0295091,1.054134,17.999418,183.33057,-11.480419
235.6877,0.22161129,9.64501,0.0,0,18.0,1.4012985e-45,1.0299798,1.004649,17.99992,178.83081,-11.480439
236.8877,0.22939557,9.6482906,0.0,0,18.0,1.4012985e-45,1.0306909,1.041907,17.999876,174.18246,-11.480066
238.0877,0.22592059,9.6511974,0.0,0,18.0,1.4012985e-45,1.0311902,1.0264938,18.000132,169.87015,-11.47973
239.2877,0.22414972,9.6546745,0.0,0,18.0,1.4012985e-45,1.0318812,1.0195359,18.000921,165.68129,-11.480197
240.4877,0.22796324,9.656971,0.0,0,18.0,1.4012985e-45,1.0322924,1.0319837,18.001114,161.62326,-11.480605
241.6877,0.23049694,9.6599369,0.0,0,18.0,1.4012985e-45,1.0328559,1.0452392,18.000193,157.68312,-11.480917
242.8877,0.22827469,9.6627703,0.0,0,18.0,1.4012985e-45,1.0333908,1.035598,17.999138,153.85846,-11.480697
244.0877,0.22907095,9.6656618,0.0,0,18.0,1.4012985e-45,1.0339421,1.0385829,18.000175,150.02843,-11.481525
245.2877,0.22651362,9.6686726,0.0,0,18.0,1.4012985e-45,1.0344938,1.0213106,18.00071,146.416,-11.481444
246.4877,0.22820787,9.6711073,0.0,0,18.0,1.4012985e-45,1.0349348,1.0330563,18.001842,142.81863,-11.482037
247.6877,0.22452943,9.673315,0.0,0,18.0,1.4012985e-45,1.0353804,1.0185887,18.000257,139.54131,-11.482051
248.8877,0.22934282,9.6763315,0.0,0,18.0,1.4012985e-45,1.0358679,1.0393931,18.000668,136.0282,-11.481865
250.0877,0.22006567,9.6784487,0.0,0,18.0,1.4012985e-45,1.0363017,1.0004982,18.00065,132.86505,-11.482091
251.2877,0.22592448,9.6807718,0.0,0,18.0,1.4012985e-45,1.0367252,1.0198631,18.000729,129.65971,-11.482075
252.4877,0.21697845,9.683568,0.0,0,18.0,1.4012985e-45,1.0372653,0.98459131,18.000063,126.67328,-11.481846
253.6877,0.22358939,9.68575,0.0,0,18.0,1.4012985e-45,1.0376533,1.0123589,18.000095,123.66528,-11.481985
254.8877,0.21466036,9.6877365,0.0,0,18.0,1.4012985e-45,1.038043,0.97209901,18.000238,120.73371,-11.482092
255.8877,0.22627579,9.689641,0.0,0,18.0,1.4012985e-45,1.0384471,1.019401,18.001188,118.25207,-11.482472