File: examples/dan-msc-case-studies/CS3/data/01 raw data/baron_test_066.csv
Time(sec),Force(kN),Jaw(mm),PowAngle(deg),Power(W),Pram,PTemp,Strain,Stress(MPa),Stroke(mm),TC1(C),wedge(mm)
0.0,0.90904856,0.21632373,0.0,0,10.594783,0.001361481,0.014534869,11.410231,10.595052,26.745852,-9.1060677
2.2,0.82151246,-0.0066528283,0.0,0,10.594783,6.5159144,-0.0004334705,10.467067,10.595481,26.676287,-9.4722252
4.4,0.79205996,-0.0066980021,0.0,0,10.594783,13.115914,-0.00046006215,10.089709,10.593974,26.607548,-9.4691868
6.6,0.76424152,-0.0069528678,0.0,0,10.594783,19.715914,-0.00045764539,9.7459373,10.594481,26.455027,-9.4658432
8.8,0.74360454,-0.0067747119,0.0,0,10.594783,26.315914,-0.00047014133,9.4665089,10.595825,26.463856,-9.4620323
11.0,0.74836671,-0.0075275917,30.327263,0,10.594783,32.915916,-0.00048003002,9.5312843,10.594698,27.49295,-9.4590397
13.2,0.76128793,-0.012017934,39.898766,0,10.594783,39.515911,-0.00080764911,9.7125378,10.594759,33.656967,-9.4558048
15.4,0.78499985,-0.018583462,42.396236,0,10.594783,46.115906,-0.0012208341,10.002763,10.594983,42.372162,-9.4525051
17.6,0.79847044,-0.025380353,41.802982,0,10.594783,52.715908,-0.0016712761,10.177869,10.594756,51.641582,-9.4489765
19.8,0.7918269,-0.030264528,39.92503,0,10.594783,59.31591,-0.0020165881,10.108064,10.594239,59.741325,-9.4451933
22.0,0.80338752,-0.034753725,39.243168,0,10.594783,65.915916,-0.0023078404,10.246836,10.594915,66.298393,-9.4419041
24.2,0.80428678,-0.04067409,40.083405,0,10.594783,72.515907,-0.0027182032,10.26691,10.595999,72.256279,-9.4383755
26.4,0.80583966,-0.044742867,41.198727,0,10.594783,79.115906,-0.0029748539,10.298762,10.595935,78.515381,-9.4350986
28.6,0.81304151,-0.049701024,42.090374,0,10.594783,85.715912,-0.0033301434,10.397282,10.595106,84.978271,-9.4312935
30.8,0.82081771,-0.056006886,42.442833,0,10.594783,92.315903,-0.0037074224,10.502587,10.595506,91.760262,-9.4275179
33.0,0.8297655,-0.060203288,42.978512,0,10.594783,98.915916,-0.0040246886,10.598416,10.593401,98.468742,-9.4241619
35.2,0.84059471,-0.06508898,43.217747,0,10.594783,105.51591,-0.0043044346,10.756825,10.594108,105.15992,-9.4211359
37.4,0.84412265,-0.071262628,43.527828,0,10.594783,112.11591,-0.0047282442,10.789221,10.595263,111.79818,-9.4177999
39.6,0.84210944,-0.075887762,44.077042,0,10.594783,118.71591,-0.00503112,10.783294,10.594046,118.33043,-9.4138937
41.8,0.85593784,-0.080540918,44.336025,0,10.594783,125.31591,-0.0053449105,10.953852,10.59439,124.90343,-9.4101925
44.0,0.87409657,-0.087039821,44.998447,0,10.594783,131.91591,-0.0057903919,11.197701,10.594324,131.41858,-9.4070435
46.2,0.86640924,-0.091712654,45.120853,0,10.594783,138.51588,-0.006093082,11.096557,10.593574,138.10306,-9.4039021
48.4,0.87312156,-0.097077683,45.615231,0,10.594783,145.11589,-0.0064657503,11.195965,10.5937,144.7023,-9.4006205
50.6,0.88320774,-0.10374487,46.108856,0,10.594783,151.71591,-0.0068882024,11.320235,10.595434,151.19644,-9.3966656
52.8,0.88269842,-0.10813458,46.408524,0,10.594783,158.3159,-0.0072052791,11.335982,10.594733,157.81384,-9.3928089
55.0,0.8920427,-0.11350309,46.771893,0,10.594783,164.91591,-0.0075245351,11.439086,10.595481,164.42532,-9.38978
57.2,0.89292967,-0.12049121,47.05444,0,10.594783,171.51591,-0.0080212932,11.471493,10.595159,171.18257,-9.3863335
59.4,0.88675618,-0.12540649,47.054729,0,10.594783,178.11591,-0.0083020991,11.380968,10.5958,177.85275,-9.3831902
61.6,0.89079601,-0.13126701,47.504883,0,10.594783,184.7159,-0.008717048,11.449814,10.595638,184.38063,-9.3795414
63.8,0.90252066,-0.13758206,47.950279,0,10.594783,191.31589,-0.0091137392,11.60546,10.595761,190.81017,-9.3751965
66.0,0.89733565,-0.14322217,47.955318,0,10.594783,197.91589,-0.009486788,11.548162,10.595003,197.62971,-9.3722134
68.2,0.89494067,-0.14891785,48.199577,0,10.594783,204.51591,-0.009878993,11.508734,10.596047,204.27298,-9.3687096
70.4,0.90049177,-0.15491438,48.381462,0,10.594783,211.11592,-0.010278627,11.59317,10.595705,210.90637,-9.3658924
72.6,0.88625872,-0.16128387,48.383293,0,10.594783,217.71593,-0.010716466,11.418424,10.594954,217.57845,-9.3618927
74.8,0.89059198,-0.16674665,48.76712,0,10.594783,224.31592,-0.011053809,11.462932,10.594213,223.94832,-9.3579397
77.0,0.89663792,-0.17251566,49.130825,0,10.594783,230.91592,-0.011460329,11.546192,10.594298,230.46207,-9.3542137
79.2,0.90509838,-0.1792409,49.352077,0,10.594783,237.51591,-0.011866232,11.653466,10.594827,237.07596,-9.350769
81.4,0.91045398,-0.1846815,49.636227,0,10.594783,244.11591,-0.012252989,11.744875,10.594858,243.74718,-9.3477917
83.6,0.90959215,-0.1904026,49.640041,0,10.594783,250.7159,-0.012594557,11.727262,10.594673,250.35333,-9.3449297
85.8,0.90815616,-0.19806948,50.042721,0,10.594783,257.31616,-0.013118337,11.716208,10.594741,256.98077,-9.3413458
88.0,0.90785635,-0.20357506,50.438229,0,10.594783,263.91589,-0.013454561,11.709337,10.594458,263.59457,-9.3379841
90.2,0.91263646,-0.20937602,50.425968,0,10.594783,270.51593,-0.013852257,11.784596,10.594781,270.35678,-9.333477
92.4,0.93445098,-0.21559428,50.43811,0,10.594783,277.11591,-0.014262194,12.067819,10.595266,277.04306,-9.3303814
94.6,0.91594422,-0.2214521,50.438229,0,10.594783,283.71588,-0.014647969,11.831577,10.595265,283.52161,-9.3273191
96.8,0.90707916,-0.22780821,50.822735,0,10.594783,290.31589,-0.015084871,11.734664,10.595304,290.04437,-9.3236036
99.0,0.92583627,-0.23397727,50.82275,0,10.594783,296.91589,-0.015475375,11.968757,10.59447,296.68552,-9.3199615
101.2,0.93268126,-0.24105304,51.196285,0,10.594783,303.5159,-0.015959805,12.055881,10.59473,303.1918,-9.3168154
103.4,0.91391975,-0.2487534,51.196285,0,10.594783,310.11591,-0.016446872,11.829626,10.594412,309.89011,-9.3131218
105.6,0.90409672,-0.25460184,51.331177,0,10.594783,316.71588,-0.016851149,11.70603,10.594503,316.46066,-9.3090324
107.8,0.91695511,-0.26079628,51.529907,0,10.594783,323.31589,-0.017231861,11.896995,10.595266,323.15143,-9.3053684
110.0,0.92783076,-0.26703379,51.56982,0,10.594783,329.91592,-0.017660078,12.021542,10.594337,329.72485,-9.3025312
112.2,0.93175513,-0.27477267,51.899731,0,10.594783,336.51593,-0.018140718,12.082424,10.594335,336.2337,-9.2994804
114.4,0.9177357,-0.28004983,51.937347,0,10.594783,343.11591,-0.018513052,11.902758,10.596266,342.78226,-9.2962885
116.6,0.92015874,-0.28741178,52.077236,0,10.594783,349.71594,-0.01895323,11.95436,10.594497,349.48148,-9.2922668
118.8,0.93243754,-0.29312786,51.932377,0,10.594783,356.31592,-0.01936774,12.111574,10.593191,356.53448,-9.2880011
121.0,0.069619603,-0.31046206,50.043407,0,10.594783,359.99924,-0.020464035,0.90607512,10.594618,361.92847,-9.2860622
123.2,0.043404769,-0.30988735,47.985176,0,10.594783,359.99924,-0.020438133,0.55728394,10.59542,362.20935,-9.2868881
125.4,0.03438212,-0.30767414,48.811909,0,10.594783,359.99924,-0.020284144,0.45230272,10.5951,360.33258,-9.2871914
127.6,0.037348151,-0.306494,50.819973,0,10.594783,359.99924,-0.020213261,0.49172863,10.5942,358.4451,-9.2874784
129.8,0.038792938,-0.30683699,52.424095,0,10.594783,359.99924,-0.020242909,0.5074935,10.594402,357.82513,-9.2871075
132.0,0.050298207,-0.3083761,53.424576,0,10.594783,359.99924,-0.02033761,0.65485537,10.59526,358.15463,-9.2862883
134.2,0.05609224,-0.30850342,53.316677,0,10.594783,359.99924,-0.020366415,0.72501677,10.594016,359.40811,-9.2864294
136.4,0.059330348,-0.3096956,52.635502,0,10.594783,359.99924,-0.020432154,0.77888441,10.595354,360.42908,-9.2866974
138.6,0.067798212,-0.31061989,51.932377,0,10.594783,359.99924,-0.020508723,0.8744483,10.595822,360.91083,-9.2867851
140.8,0.062572293,-0.31104758,51.213928,0,10.594783,359.99924,-0.020526804,0.78906727,10.594316,360.92221,-9.2868786
143.0,0.062210739,-0.31070459,51.194637,0,10.594783,359.99924,-0.020516519,0.82621908,10.594347,360.57764,-9.2876635
145.2,0.068988614,-0.31138307,51.196285,0,10.594783,359.99924,-0.020545157,0.90534067,10.595114,360.1221,-9.2874956
147.4,0.065259583,-0.31206408,51.56982,0,10.594783,359.99924,-0.020612352,0.83502752,10.594935,359.80341,-9.2870436
149.6,0.060939189,-0.31239164,51.855244,0,10.594783,359.99924,-0.020592285,0.79525071,10.5951,359.66949,-9.2869358
151.8,0.071573697,-0.31289923,51.932369,0,10.594783,359.99924,-0.020664753,0.93251318,10.594982,359.81366,-9.2869825
154.0,0.067972735,-0.31397742,51.926464,0,10.594783,359.99924,-0.020701462,0.8757478,10.59529,360.01227,-9.2871685
156.2,0.053422127,-0.31467155,51.570908,0,10.594783,359.99924,-0.02076233,0.69348878,10.595685,360.0676,-9.286705
158.4,0.064730853,-0.31554064,51.932365,0,10.594783,359.99924,-0.02079496,0.84307677,10.594619,359.83112,-9.2861156
160.6,0.063252799,-0.31588611,51.619579,0,10.594783,359.99924,-0.020835089,0.82482356,10.594157,360.14236,-9.2872801
162.8,0.047856066,-0.3167735,51.705364,0,10.594783,359.99924,-0.020884335,0.61771691,10.594521,360.0509,-9.2861624
165.0,0.071590021,-0.31731367,51.812134,0,10.594783,359.99924,-0.020925151,0.94439888,10.595101,360.04642,-9.2863636
165.2885,0.17579517,0.016470781,35.384762,0,10.5948,3.8939777e-22,0.0011575638,2.3205822,10.596366,360.02499,-9.286478
165.2929,0.17749666,0.017511761,12.488726,0,10.5948,0.0,0.0011603044,2.247962,10.595867,360.0517,-9.287261
165.2973,0.17807668,0.01658475,0.0,0,10.5948,0.0,0.0011029727,2.2565365,10.594007,359.94482,-9.2862291
165.3017,0.17448604,0.015094734,0.0,0,10.5948,0.0,0.00099582737,2.2124448,10.59852,359.67758,-9.2860746
165.3061,0.18773107,0.018834772,0.0,0,10.5948,0.0,0.001212826,2.384717,10.597325,359.48007,-9.2861624
165.3105,0.18587321,0.015688401,0.0,0,10.5948,0.0,0.0010051734,2.3254898,10.594127,359.58698,-9.2862082
165.3149,0.18714164,0.017383831,0.0,0,10.5948,0.0,0.0011376016,2.3359907,10.590881,359.69385,-9.287219
165.3193,0.17772569,0.017244279,0.0,0,10.5948,0.0,0.001109954,2.2545483,10.591139,359.75168,-9.2864714
165.3237,0.18781619,0.019491205,0.0,0,10.5948,0.0,0.0011528273,2.3748069,10.592094,359.80511,-9.2877159
165.3281,0.18827963,0.017714644,0.0,0,10.5948,0.0,0.0011019456,2.4433119,10.598443,359.84119,-9.2861862
165.3325,0.18241532,0.021651885,0.0,0,10.5948,0.0,0.001266829,2.375803,10.596518,359.86792,-9.2862043
165.3369,0.19316284,0.018239927,0.0,0,10.566863,0.0,0.0011247444,2.4181931,10.594965,359.88443,-9.286994
165.3413,0.19437864,0.022675293,0.0,0,10.500864,0.0,0.0012832099,2.4848602,10.590673,359.88443,-9.2863464
165.3457,0.19236287,0.018471107,0.0,0,10.434863,0.0,0.0011057311,2.487896,10.573252,359.88748,-9.2858458
165.3501,0.2008545,0.021950826,0.0,0,10.368864,0.0,0.0012655988,2.6232061,10.520494,359.91418,-9.2858105
165.3545,0.19048469,0.01830237,0.0,0,10.302863,0.0,0.0010750864,2.4355147,10.423232,359.94092,-9.2873526
165.3589,0.21131703,0.022147406,0.0,0,10.236864,0.0,0.0012252791,2.5631597,10.323299,359.94504,-9.2865295
165.3633,0.20155135,0.019659951,0.0,0,10.170864,0.0,0.0011494404,2.7071376,10.242934,359.94504,-9.2870836
165.3677,0.2102679,0.023231855,0.0,0,10.104864,0.0,0.0012850466,2.6064615,10.190284,359.92963,-9.2879696
165.3721,0.2097384,0.020242942,0.0,0,10.038863,0.0,0.0012404737,2.5736337,10.138435,359.90289,-9.2869844
165.3765,0.2149058,0.023682985,0.0,0,9.9728632,0.0,0.0013395349,2.8272586,10.076333,359.8927,-9.287775
165.3809,0.21154132,0.019612165,0.0,0,9.9068632,0.0,0.0012221438,2.7027161,10.005951,359.91943,-9.2864113
165.3853,0.21285893,0.026959458,0.0,0,9.8408632,0.0,0.0014695099,2.7268908,9.9295187,359.94617,-9.2868319
165.3897,0.34204376,0.022788456,0.0,0,9.7748632,0.0,0.0014257097,4.2140174,9.861105,359.97287,-9.2864275
165.3941,2.2916245,0.046848375,0.0,0,9.7088633,0.0,0.0027728048,28.778551,9.8052092,359.9996,-9.2855873
165.3985,4.2947149,0.074165314,0.0,0,9.6428633,0.0,0.0047782622,54.264507,9.7498751,360.10892,-9.2842808
165.4029,5.3713017,0.14660507,0.0,0,9.5768633,0.0,0.0094718877,67.698128,9.6787348,360.24252,-9.2832384
165.4073,6.0057096,0.21395776,0.0,0,9.5108633,0.0,0.01415637,75.353165,9.597126,360.39636,-9.2823849
165.4117,6.4142723,0.28686017,0.0,0,9.4457693,0.0,0.018995998,80.011658,9.525424,360.57007,-9.2836905
165.4161,6.644999,0.34835359,0.0,0,9.3813896,0.0,0.023344776,82.622856,9.4539461,360.72165,-9.2822361
165.4205,6.7828407,0.41269785,0.0,0,9.317008,0.0,0.027647687,84.031166,9.3926983,360.80182,-9.2824297
165.4249,6.8917727,0.46805114,0.0,0,9.2526274,0.0,0.03155056,84.959007,9.3302679,360.88196,-9.2826138
165.4293,7.0454912,0.5355112,0.0,0,9.1882467,0.0,0.036081888,86.519402,9.2660303,361.01389,-9.2827864
165.4337,7.1681771,0.59808779,0.0,0,9.1238651,0.0,0.040581729,87.639977,9.1961231,361.14749,-9.2827339
165.4381,7.2385035,0.6649766,0.0,0,9.0594854,0.0,0.045206826,88.095345,9.1349401,361.31851,-9.2840376
165.4425,7.2666359,0.72570068,0.0,0,8.9951048,0.0,0.049504697,88.090019,9.0680542,361.50558,-9.2846832
165.4469,7.3516035,0.79070002,0.0,0,8.9307232,0.0,0.053975418,88.599594,9.004571,361.61765,-9.2842617
165.4513,7.4517736,0.8528583,0.0,0,8.8663425,0.0,0.058465842,89.579094,8.9385414,361.63098,-9.2841339
165.4557,7.4960828,0.918836,0.0,0,8.8019619,0.0,0.063151635,89.600655,8.8706827,361.61591,-9.2824736
165.4601,7.5240841,0.97897911,0.0,0,8.7381983,0.0,0.067483023,89.616753,8.8087244,361.4556,-9.2839518
165.4645,7.597858,1.0467362,0.0,0,8.6769676,0.0,0.072320871,89.981964,8.7399559,361.29526,-9.2839346
165.4689,7.6729803,1.1042408,0.0,0,8.615737,0.0,0.076553091,90.416245,8.6735144,361.23062,-9.2842407
165.4733,7.6915383,1.1706045,0.0,0,8.5545063,0.0,0.081298828,90.279709,8.6138325,361.17719,-9.283432
165.4777,7.7157779,1.221943,0.0,0,8.4932766,0.0,0.08499942,90.228531,8.5561123,361.20755,-9.285368
165.4821,7.748776,1.282419,0.0,0,8.4320459,0.0,0.089526594,90.207161,8.4970207,361.28772,-9.284234
165.4865,7.8694477,1.3447251,0.0,0,8.3708162,0.0,0.093995571,91.201622,8.4344893,361.3775,-9.284543
165.4909,7.9204593,1.4130803,0.0,0,8.3095856,0.0,0.099139586,91.425194,8.3658342,361.48438,-9.2833185
165.4953,7.9379992,1.4713001,0.0,0,8.2483559,0.0,0.10335417,91.141762,8.2990704,361.59006,-9.2841663
165.4997,7.9529028,1.5335703,0.0,0,8.1871252,0.0,0.10801484,90.904617,8.2367592,361.68359,-9.283741
165.5041,8.0173025,1.5904603,0.0,0,8.1258955,0.0,0.11229806,91.220749,8.1814203,361.77713,-9.284071
165.5085,8.095768,1.6514152,0.0,0,8.0646648,0.0,0.11683235,91.751282,8.1184034,361.90363,-9.2827902
165.5129,8.1146183,1.7108165,0.0,0,8.0059099,0.0,0.12129845,91.564926,8.0563183,362.03723,-9.2823153
165.5173,8.1534395,1.7727714,0.0,0,7.9476533,0.0,0.1260013,91.600662,7.9949923,362.11896,-9.2830219
165.5217,8.1696663,1.8271165,0.0,0,7.8893976,0.0,0.13019557,91.249733,7.9393244,362.15906,-9.2830076
165.5261,8.2470274,1.8835661,0.0,0,7.831141,0.0,0.13448586,91.871536,7.8805552,362.20297,-9.2835016
165.5305,8.2592611,1.9398578,0.0,0,7.7728858,0.0,0.1387886,91.617447,7.8247614,362.25641,-9.2841949
165.5349,8.2889128,1.9984344,0.0,0,7.7146292,0.0,0.14327313,91.381531,7.7639413,362.31134,-9.2838459
165.5393,8.3451891,2.0546224,0.0,0,7.6563735,0.0,0.14755933,91.684555,7.7081418,362.44495,-9.2839508
165.5437,8.4534836,2.114939,0.0,0,7.5981178,0.0,0.15229625,92.376877,7.6427093,362.57855,-9.2838316
165.5481,8.4888191,2.1757123,0.0,0,7.5398612,0.0,0.15694848,92.419632,7.5821986,362.70212,-9.2833281
165.5525,8.5030174,2.2336955,0.0,0,7.4816051,0.0,0.16153802,92.072296,7.5206418,362.82239,-9.2830782
165.5569,8.5319653,2.2895751,0.0,0,7.4233494,0.0,0.16595969,92.100746,7.4660087,362.96194,-9.2834244
165.5613,8.5972052,2.3479161,0.0,0,7.3664303,0.0,0.17052822,92.238213,7.4063087,363.12228,-9.2847738
165.5657,8.648984,2.4034319,0.0,0,7.3110256,0.0,0.17486989,92.508629,7.3486381,363.28546,-9.2824001
165.5701,8.6495762,2.4601376,0.0,0,7.2556205,0.0,0.17940186,92.085648,7.2930865,363.45917,-9.2833681
165.5745,8.6928778,2.5138247,0.0,0,7.2002158,0.0,0.18365298,92.121521,7.2385669,363.63287,-9.2826796
165.5789,8.7412729,2.5667844,0.0,0,7.1448102,0.0,0.18791193,92.248367,7.1830263,362.53067,-9.2841148
165.5833,8.818944,2.6208382,0.0,0,7.089406,0.0,0.19223341,92.540817,7.1270304,361.35489,-9.2836046
165.5877,8.8501492,2.68118,0.0,0,7.0340009,0.0,0.19704881,92.464828,7.0645294,359.88953,-9.2822495
165.5921,8.8828249,2.7394001,0.0,0,6.9785962,0.0,0.20183094,92.408409,7.0118594,358.28619,-9.2842312
165.5965,8.9137373,2.7916503,0.0,0,6.9231911,0.0,0.2060243,92.338829,6.9550533,357.38251,-9.2846289
165.6009,8.9547729,2.8456388,0.0,0,6.8677864,0.0,0.21036965,92.371971,6.9031129,357.48941,-9.2841053
165.6053,8.9906273,2.8972108,0.0,0,6.8123817,0.0,0.21467501,92.437775,6.8482075,357.76199,-9.2835321
165.6097,9.0550489,2.9556165,0.0,0,6.7572598,0.0,0.21943372,92.518311,6.7891335,359.04465,-9.2833319
165.6141,9.124445,3.0102949,0.0,0,6.7045479,0.0,0.22394478,92.898026,6.7345295,360.3273,-9.2840128
165.6185,9.1492491,3.0680816,0.0,0,6.6518359,0.0,0.22886531,92.742615,6.6759262,361.02695,-9.2823124
165.6229,9.1616917,3.1186509,0.0,0,6.599124,0.0,0.23300605,92.413895,6.6232567,361.64157,-9.2817984
165.6273,9.1774321,3.1736023,0.0,0,6.5464115,0.0,0.23758368,92.110344,6.5708098,361.72305,-9.284214
165.6317,9.2425938,3.2211845,0.0,0,6.4937,0.0,0.24165675,92.457397,6.5193114,361.45584,-9.2835226
165.6361,9.3197708,3.2766852,0.0,0,6.4409881,0.0,0.24627052,92.622696,6.4616404,361.30997,-9.2823668
165.6405,9.3411827,3.3271272,0.0,0,6.3882761,0.0,0.2505818,92.523209,6.4136596,361.40347,-9.2848015
165.6449,9.3342028,3.3812962,0.0,0,6.3355641,0.0,0.25512907,92.147377,6.3623838,361.46878,-9.2845783
165.6493,9.4058628,3.4274175,0.0,0,6.2828526,0.0,0.25925657,92.429733,6.309927,361.1481,-9.2843065
165.6537,9.4950762,3.4838982,0.0,0,6.2301402,0.0,0.26398507,92.850281,6.2560039,360.82742,-9.2832222
165.6581,9.5498934,3.5354552,0.0,0,6.1774282,0.0,0.26852745,93.008514,6.2041044,359.77991,-9.2831354
165.6625,9.5795898,3.5949965,0.0,0,6.1266279,0.0,0.27361536,92.816544,6.1469851,358.55069,-9.2845573
165.6669,9.5924473,3.6441433,0.0,0,6.0764947,0.0,0.27797222,92.421974,6.0960608,357.47067,-9.2835045
165.6713,9.6311426,3.6952894,0.0,0,6.026361,0.0,0.2824429,92.503944,6.0460353,356.52203,-9.2834902
165.6757,9.6673918,3.7406106,0.0,0,5.9762278,0.0,0.28649777,92.400688,5.9988217,355.84814,-9.2836714
165.6801,9.6910591,3.7928336,0.0,0,5.9260936,0.0,0.29098916,92.185303,5.9467216,355.94168,-9.2835312
165.6845,9.7620754,3.8395102,0.0,0,5.8759604,0.0,0.29533887,92.514641,5.899539,356.03522,-9.2827168
165.6889,9.8457317,3.8957965,0.0,0,5.8258266,0.0,0.30014983,92.851799,5.8458781,356.60757,-9.2831659
165.6933,9.8621883,3.9431813,0.0,0,5.7756925,0.0,0.30463216,92.578934,5.7924747,357.1821,-9.2833223
165.6977,9.8902378,3.9963179,0.0,0,5.7255592,0.0,0.30930069,92.502617,5.7422004,357.46509,-9.2835674
165.7021,9.9295263,4.0427446,0.0,0,5.675426,0.0,0.31366649,92.388252,5.6911473,357.63879,-9.2832785
165.7065,9.9929991,4.0972619,0.0,0,5.6252923,0.0,0.3184,92.473015,5.642664,357.92902,-9.2821188
165.7109,10.058887,4.1444454,0.0,0,5.5760794,0.0,0.32297054,92.679588,5.5917072,358.35657,-9.2839346
165.7153,10.090716,4.1978059,0.0,0,5.5283837,0.0,0.32765573,92.621399,5.5407896,358.85556,-9.2832651
165.7197,10.079422,4.2412333,0.0,0,5.4806876,0.0,0.3321178,92.091118,5.4938226,359.65723,-9.2842836
165.7241,10.108005,4.291935,0.0,0,5.4329915,0.0,0.3365415,91.90641,5.4483171,360.45889,-9.2836742
165.7285,10.223951,4.332015,0.0,0,5.3852959,0.0,0.34048405,92.535469,5.4016042,360.81674,-9.2836094
165.7329,10.260184,4.3858414,0.0,0,5.3375998,0.0,0.34537196,92.484467,5.3518353,361.13739,-9.2839355
165.7373,10.280987,4.4294157,0.0,0,5.2899036,0.0,0.34979916,92.322334,5.3022594,361.27441,-9.2840767
165.7417,10.302614,4.4823146,0.0,0,5.2422075,0.0,0.35460418,91.974632,5.2540598,361.31451,-9.2830868
165.7461,10.386821,4.5246754,0.0,0,5.1945119,0.0,0.35884789,92.353706,5.2045989,361.37524,-9.2841311
165.7505,10.433862,4.5754356,0.0,0,5.1468158,0.0,0.36350256,92.388222,5.1636462,361.46878,-9.2831726
165.7549,10.461392,4.620955,0.0,0,5.0991197,0.0,0.36815825,92.203468,5.1117058,361.56705,-9.2837582
165.7593,10.521215,4.6719203,0.0,0,5.0514669,0.0,0.37290329,92.242691,5.0653028,361.70065,-9.2826443
165.7637,10.601094,4.7205739,0.0,0,5.006093,0.0,0.37774217,92.485939,5.0145555,361.83426,-9.2836075
165.7681,10.647464,4.7689776,0.0,0,4.9607286,0.0,0.38240731,92.416107,4.9711237,361.75208,-9.2817364
165.7725,10.630875,4.8109827,0.0,0,4.9153652,0.0,0.38673985,91.968895,4.9220157,361.63184,-9.2832918
165.7769,10.629546,4.8587103,0.0,0,4.8700008,0.0,0.39128825,91.488937,4.8796167,360.57874,-9.2841654
165.7813,10.708985,4.8947506,0.0,0,4.8246369,0.0,0.39503768,91.808456,4.8326464,358.85513,-9.2830791
165.7857,10.797904,4.9444613,0.0,0,4.7792726,0.0,0.40006658,92.146446,4.7911849,357.19443,-9.2847109
165.7901,10.850963,4.9878659,0.0,0,4.7339091,0.0,0.40441802,92.244942,4.7450266,355.67126,-9.2849951
165.7945,10.897287,5.0403004,0.0,0,4.6885448,0.0,0.40969828,92.183456,4.696444,354.23737,-9.2843924
165.7989,10.908888,5.0822544,0.0,0,4.6431808,0.0,0.41377157,91.775009,4.6477094,354.67828,-9.2844477
165.8033,10.985005,5.1266971,0.0,0,4.5978165,0.0,0.41844302,92.061501,4.6064095,355.1192,-9.2841854
165.8077,11.00048,5.1673636,0.0,0,4.552453,0.0,0.42250249,91.775543,4.5634871,355.67435,-9.282958
165.8121,11.067365,5.2141242,0.0,0,4.5085258,0.0,0.42741033,91.910149,4.5159273,356.26224,-9.2824268
165.8165,11.148612,5.2583613,0.0,0,4.4653702,0.0,0.43194506,92.189987,4.4708533,356.89093,-9.2829142
165.8209,11.209326,5.3048205,0.0,0,4.422215,0.0,0.43683457,92.188187,4.4234114,357.55899,-9.2839842
165.8253,11.228055,5.3472471,0.0,0,4.3790598,0.0,0.44113097,92.036751,4.3841634,358.20773,-9.2830019
165.8297,11.262143,5.3891134,0.0,0,4.3359046,0.0,0.44559672,91.736511,4.3377743,358.79562,-9.2838945
165.8341,11.298588,5.4307342,0.0,0,4.2927494,0.0,0.44991547,91.68618,4.2951393,359.38351,-9.2833519
165.8385,11.389489,5.4748688,0.0,0,4.2495942,0.0,0.45467821,92.012245,4.2518535,359.71146,-9.2837553
165.8429,11.460272,5.5197153,0.0,0,4.206439,0.0,0.45925978,92.170326,4.2128921,360.03214,-9.283947
165.8473,11.473758,5.5605745,0.0,0,4.1632838,0.0,0.4636797,91.880318,4.1680412,360.39987,-9.2835827
165.8517,11.54528,5.6040316,0.0,0,4.1201291,0.0,0.46822318,91.98735,4.1255841,360.78735,-9.2829075
165.8561,11.632733,5.6467772,0.0,0,4.0769739,0.0,0.47294402,92.303093,4.0781522,361.14566,-9.2833042
165.8605,11.668727,5.6912036,0.0,0,4.0344243,0.0,0.47762349,92.150841,4.0363531,361.46634,-9.2849503
165.8649,11.707938,5.7341681,0.0,0,3.9933808,0.0,0.48232719,91.969299,3.9951892,361.72861,-9.2838221
165.8693,11.758918,5.7743125,0.0,0,3.952338,0.0,0.48651636,92.052017,3.9566357,361.70187,-9.282896
165.8737,11.862448,5.8200784,0.0,0,3.9112947,0.0,0.49156019,92.354637,3.9095001,361.67517,-9.2840576
165.8781,11.874747,5.8602576,0.0,0,3.8702514,0.0,0.49584979,92.135429,3.8728988,360.91489,-9.2838564
165.8825,11.864695,5.8988414,0.0,0,3.8292081,0.0,0.50029552,91.63633,3.8291223,360.07312,-9.2844582
165.8869,11.898689,5.9365849,0.0,0,3.7881651,0.0,0.50422722,91.515778,3.7931492,359.06253,-9.2839479
165.8913,12.04192,5.9748816,0.0,0,3.7471218,0.0,0.50859159,92.157814,3.7508693,357.95358,-9.285553
165.8957,12.133333,6.0198245,0.0,0,3.7060785,0.0,0.51346231,92.490517,3.7120049,356.92233,-9.2842064
165.9001,12.18192,6.0587234,0.0,0,3.6650355,0.0,0.51770288,92.459793,3.6694632,356.02716,-9.284215
165.9045,12.23162,6.1042862,0.0,0,3.6239922,0.0,0.52275366,92.335091,3.6292014,355.16766,-9.2842398
165.9089,12.336275,6.146636,0.0,0,3.5829492,0.0,0.52752382,92.620636,3.5849173,354.64658,-9.2835407
165.9133,12.395405,6.1878195,0.0,0,3.5437503,0.0,0.53211033,92.711617,3.5456805,354.12546,-9.2843933
165.9177,12.449421,6.2288146,0.0,0,3.5047047,0.0,0.53664315,92.668922,3.5049272,354.07968,-9.2844276
165.9221,12.435866,6.2706828,0.0,0,3.4656589,0.0,0.54140759,92.146973,3.4659414,354.13312,-9.2843399
165.9265,12.496511,6.3047876,0.0,0,3.4266133,0.0,0.54536128,92.17981,3.4279311,354.35837,-9.2845573
165.9309,12.576658,6.3464055,0.0,0,3.387568,0.0,0.55016983,92.382568,3.3863728,354.71915,-9.2834311
165.9353,12.639455,6.3808455,0.0,0,3.3485222,0.0,0.55398208,92.450363,3.3474755,355.09933,-9.2847643
165.9397,12.710769,6.4225292,0.0,0,3.3094764,0.0,0.55887485,92.541313,3.3095341,355.52689,-9.2834949
165.9441,12.780061,6.4607978,0.0,0,3.270431,0.0,0.56321859,92.675697,3.2735593,355.94833,-9.2835712
165.9485,12.918202,6.5021477,0.0,0,3.2313855,0.0,0.56796968,93.175087,3.2305887,356.10867,-9.2837515
165.9529,12.997181,6.5455074,0.0,0,3.1923399,0.0,0.57311845,93.260178,3.1896787,356.26901,-9.2833376
165.9573,13.009337,6.5860391,0.0,0,3.1532941,0.0,0.57789272,92.95269,3.1483757,356.38904,-9.2834721
165.9617,13.0369,6.6219406,0.0,0,3.1153123,0.0,0.58214194,92.741264,3.1079042,356.49594,-9.2846165
165.9661,13.092826,6.6593823,0.0,0,3.0781677,0.0,0.58634889,92.698662,3.0734546,356.66782,-9.2839909
165.9705,13.147507,6.6940541,0.0,0,3.0410228,0.0,0.59067243,92.794746,3.0412652,356.90829,-9.2837286
165.9749,13.263949,6.7341809,0.0,0,3.0038779,0.0,0.59537929,93.134491,3.0066926,357.19836,-9.2842321
165.9793,13.318147,6.7691541,0.0,0,2.966733,0.0,0.59966969,93.168213,2.9686203,357.66602,-9.2845955
165.9837,13.444968,6.8131666,0.0,0,2.9295881,0.0,0.60482681,93.452888,2.9305475,358.13367,-9.2837172
165.9881,13.525386,6.845921,0.0,0,2.8924434,0.0,0.60895634,93.69976,2.8895257,358.58862,-9.2833767
165.9925,13.600728,6.8884063,0.0,0,2.8552985,0.0,0.61403745,93.724304,2.8527415,359.04291,-9.2838211
165.9969,13.642304,6.9259644,0.0,0,2.8181539,0.0,0.61877263,93.626038,2.8139079,359.33319,-9.283844
166.0013,13.688391,6.9647737,0.0,0,2.781009,0.0,0.6234979,93.453995,2.7755487,359.54697,-9.28335
166.0057,13.783113,6.998127,0.0,0,2.7438643,0.0,0.62767833,93.682144,2.7410095,359.6723,-9.2838249
166.0101,13.852477,7.035233,0.0,0,2.7070751,0.0,0.63209599,93.722115,2.7049241,359.6723,-9.2831764
166.0145,13.944266,7.0692267,0.0,0,2.6717429,0.0,0.63673818,93.928329,2.6718235,359.69757,-9.2844744
166.0189,14.043118,7.1122937,0.0,0,2.6364112,0.0,0.64188606,94.078995,2.6302624,359.87128,-9.2839298
166.0233,14.135242,7.1450748,0.0,0,2.601079,0.0,0.6463291,94.319313,2.5928099,360.04495,-9.2825165
166.0277,14.171276,7.1853242,0.0,0,2.565747,0.0,0.65115994,94.123985,2.5577364,360.60547,-9.2846441
166.0321,14.213224,7.2164783,0.0,0,2.5304151,0.0,0.65550607,94.016563,2.5262179,361.22006,-9.283268
166.0365,14.303948,7.2544155,0.0,0,2.4950829,0.0,0.66002417,94.100929,2.4915202,361.67191,-9.2842112
166.0409,14.412239,7.2832623,0.0,0,2.4597509,0.0,0.66408348,94.40107,2.4562094,362.01932,-9.2828064
166.0453,14.467283,7.3230634,0.0,0,2.4244189,0.0,0.6689899,94.353668,2.4218218,362.28015,-9.2830639
166.0497,14.59761,7.353611,0.0,0,2.389087,0.0,0.67337841,94.799461,2.3868032,362.37366,-9.2835846
166.0541,14.730732,7.3957982,0.0,0,2.353755,0.0,0.67857277,95.140213,2.3509543,362.47595,-9.2831097
166.0585,14.838615,7.4277902,0.0,0,2.318423,0.0,0.6831516,95.416168,2.3118243,362.68973,-9.2832832
166.0629,14.861897,7.4673071,0.0,0,2.2845263,0.0,0.68821204,95.11409,2.2789521,362.90353,-9.2829819
166.0673,14.917505,7.4954524,0.0,0,2.2509191,0.0,0.69213152,95.051125,2.2461929,363.08505,-9.2835321
166.0717,15.022139,7.5347176,0.0,0,2.2173121,0.0,0.69730473,95.210899,2.2104812,363.25873,-9.2841911
166.0761,15.145442,7.5657916,0.0,0,2.1837049,0.0,0.70165437,95.554947,2.176321,363.38226,-9.2827139
166.0805,15.268141,7.6021924,0.0,0,2.1500978,0.0,0.70648479,95.938599,2.1437936,363.46243,-9.2830095
166.0849,15.360018,7.6359801,0.0,0,2.1164904,0.0,0.71124262,96.087303,2.1069181,363.52829,-9.2834635
166.0893,15.414432,7.674994,0.0,0,2.0828834,0.0,0.71666265,95.868408,2.068455,363.55499,-9.2842731
166.0937,15.479779,7.7020054,0.0,0,2.0492761,0.0,0.72047341,95.865883,2.0391142,363.58173,-9.2840204
166.0981,15.557137,7.7374949,0.0,0,2.0156689,0.0,0.72530288,95.883614,2.0094945,363.6619,-9.2830648
166.1025,15.635906,7.7673197,0.0,0,1.9820617,0.0,0.72948527,96.009674,1.974373,363.74207,-9.283596
166.1069,15.700247,7.799809,0.0,0,1.9484546,0.0,0.73408014,95.949631,1.9444593,363.87112,-9.2850037
166.1113,15.912473,7.8309836,0.0,0,1.9156146,0.0,0.73825586,96.782883,1.9122145,364.0181,-9.2844086
166.1157,16.042587,7.8646965,0.0,0,1.8836442,0.0,0.74337393,97.100639,1.8749346,363.48364,-9.2840586
166.1201,16.093868,7.8989506,0.0,0,1.8516738,0.0,0.74812722,97.016212,1.8436575,362.16089,-9.2827549
166.1245,16.103756,7.9328032,0.0,0,1.8197033,0.0,0.75293064,96.551514,1.8153785,360.52997,-9.2831049
166.1289,16.259848,7.959518,0.0,0,1.787733,0.0,0.75671864,97.092514,1.7862394,357.63062,-9.2835369
166.1333,16.440905,7.993464,0.0,0,1.7557626,0.0,0.76178867,97.68338,1.7512952,354.73123,-9.2829094
166.1377,16.560362,8.0274725,0.0,0,1.7237922,0.0,0.76662809,97.942978,1.7170738,351.50568,-9.2829351
166.1421,16.593451,8.0614853,0.0,0,1.6918218,0.0,0.77170676,97.661507,1.6845064,348.25452,-9.2832947
166.1465,16.658905,8.0893602,0.0,0,1.6598514,0.0,0.7756114,97.661011,1.6553706,345.96313,-9.2827425
166.1509,16.816494,8.1199865,0.0,0,1.6278811,0.0,0.78015727,98.096497,1.6247755,344.16821,-9.2836065
166.1553,16.986397,8.1525784,0.0,0,1.5959105,0.0,0.78506559,98.660713,1.5891919,343.24249,-9.2835302
166.1597,17.101133,8.1863804,0.0,0,1.564104,0.0,0.78986984,98.824898,1.5562992,343.6712,-9.2838564
166.1641,17.136053,8.2154312,0.0,0,1.5336912,0.0,0.79427546,98.608597,1.5230895,344.12454,-9.2841215
166.1685,17.303852,8.2521048,0.0,0,1.5032783,0.0,0.79964459,99.022926,1.4934535,344.75418,-9.282774
166.1729,17.38821,8.2763681,0.0,0,1.4728655,0.0,0.80326092,99.150719,1.4609711,345.38382,-9.283247
166.1773,17.45952,8.3073359,0.0,0,1.4424527,0.0,0.80792987,99.122719,1.4354857,346.11649,-9.2843771
166.1817,17.531677,8.3375835,0.0,0,1.4120399,0.0,0.81234002,99.074791,1.4033403,346.8667,-9.2835512
166.1861,17.716536,8.3683414,0.0,0,1.3816271,0.0,0.81723654,99.641518,1.3724118,348.00131,-9.2830744
166.1905,17.819349,8.3967009,0.0,0,1.3512143,0.0,0.821163,99.797218,1.3455739,349.4071,-9.2833471
166.1949,17.902082,8.4246483,0.0,0,1.3208014,0.0,0.82559758,99.826653,1.3126423,350.96118,-9.2838783
166.1993,17.95969,8.4517298,0.0,0,1.2903887,0.0,0.82962489,99.716637,1.2852547,352.83304,-9.2826242
166.2037,18.124979,8.481967,0.0,0,1.2599759,0.0,0.83446151,100.13775,1.2619703,354.6647,-9.2832193
166.2081,18.321785,8.5122004,0.0,0,1.2295632,0.0,0.83884883,100.82543,1.2305653,355.73361,-9.2837372
166.2125,18.54921,8.5446196,0.0,0,1.200253,0.0,0.84378159,101.58977,1.1953099,356.80252,-9.2827024
166.2169,18.666885,8.5786047,0.0,0,1.1713274,0.0,0.84907186,101.72189,1.1616108,357.276,-9.2831411
166.2213,18.733324,8.6085577,0.0,0,1.1424017,0.0,0.85358596,101.59446,1.1314276,357.58328,-9.2830935
166.2257,18.832994,8.6371698,0.0,0,1.1134762,0.0,0.85808218,101.61203,1.1044395,358.1651,-9.2821255
166.2301,18.894983,8.6612101,0.0,0,1.0845505,0.0,0.86177319,101.66414,1.0782527,359.00687,-9.2846804
166.2345,19.018034,8.6892738,0.0,0,1.055625,0.0,0.86627543,101.83451,1.0478313,359.8027,-9.2833719
166.2389,19.177639,8.7206573,0.0,0,1.0266993,0.0,0.87096155,102.21885,1.018536,360.4574,-9.2832127
166.2433,19.3675,8.7478476,0.0,0,0.99777383,0.0,0.87520939,102.72473,0.99091297,361.11209,-9.2830811
166.2477,19.535803,8.7785435,0.0,0,0.96884817,0.0,0.88010877,103.17337,0.95991915,361.24411,-9.2817583
166.2521,19.639004,8.8066263,0.0,0,0.93992257,0.0,0.88470322,103.21927,0.92832386,361.36395,-9.2837343
166.2565,19.730955,8.8357058,0.0,0,0.91099691,0.0,0.88930738,103.26912,0.89967895,360.90936,-9.2831345
166.2609,19.88283,8.8640594,0.0,0,0.88260669,0.0,0.8937279,103.5465,0.87627125,360.4274,-9.2822418
166.2653,20.062986,8.8927441,0.0,0,0.85509789,0.0,0.89824575,104.04607,0.84583694,359.23318,-9.2824793
166.2697,20.167269,8.9208355,0.0,0,0.82758909,0.0,0.90277737,104.10111,0.81591463,357.72034,-9.2829018
166.2741,20.247116,8.9445658,0.0,0,0.8000803,0.0,0.9067542,104.10682,0.78936732,356.23608,-9.2831802
166.2785,20.306442,8.9726858,0.0,0,0.77257144,0.0,0.91129118,103.90842,0.7646172,354.79019,-9.281909
166.2829,20.471804,8.9955168,0.0,0,0.74506265,0.0,0.91502571,104.38945,0.73980188,353.57431,-9.2822905
166.2873,20.640272,9.024848,0.0,0,0.71755385,0.0,0.91973269,104.71871,0.71328562,353.53415,-9.283185
166.2917,20.864536,9.0483675,0.0,0,0.69004506,0.0,0.92372018,105.47644,0.68719882,353.49402,-9.2818813
166.2961,21.136507,9.0808983,0.0,0,0.66253626,0.0,0.9289403,106.26585,0.65527689,353.01984,-9.2823133
166.3005,21.387691,9.1102209,0.0,0,0.63502747,0.0,0.93403739,106.99624,0.62867695,352.49747,-9.2819967
166.3049,21.461672,9.1423855,0.0,0,0.60751867,0.0,0.93921518,106.85724,0.59737414,351.48026,-9.2826738
166.3093,21.498465,9.1671114,0.0,0,0.58003461,0.0,0.94358015,106.51498,0.57172602,350.18027,-9.2838907
166.3137,21.651855,9.1969194,0.0,0,0.55384874,0.0,0.94862252,106.75031,0.54603881,348.93954,-9.2832451
166.3181,21.849676,9.2195015,0.0,0,0.52766871,0.0,0.95264322,107.26089,0.51953524,347.79855,-9.2828655
166.3225,21.982157,9.2480001,0.0,0,0.50148869,0.0,0.9572553,107.43608,0.49046528,346.7088,-9.2812614
166.3269,22.08742,9.2701874,0.0,0,0.47530872,0.0,0.96144933,107.51963,0.46543849,346.0376,-9.2816839
166.3313,22.140934,9.2974033,0.0,0,0.44912872,0.0,0.96565461,107.30531,0.44234356,345.36642,-9.2825422
166.3357,22.329971,9.3180838,0.0,0,0.42294872,0.0,0.96976143,107.75866,0.41734186,345.03571,-9.2827282
166.3401,22.574354,9.3481865,0.0,0,0.39676872,0.0,0.97457767,108.47419,0.39091629,344.76724,-9.2832289
166.3445,22.748625,9.3685837,0.0,0,0.37058872,0.0,0.97863054,108.88316,0.36789167,344.28009,-9.2814283
166.3489,22.930933,9.3967562,0.0,0,0.34440869,0.0,0.98327333,109.21235,0.33686584,343.63577,-9.28158
166.3533,22.436338,9.4096041,0.0,0,0.31822872,0.0,0.98618209,106.60794,0.31734642,343.18365,-9.2833595
166.3577,21.595398,9.4219465,0.0,0,0.29204872,0.0,0.98808336,102.38702,0.29976103,343.14337,-9.2841473
166.3621,21.183481,9.4291658,0.0,0,0.26670453,0.0,0.98981833,100.26642,0.28860077,343.13531,-9.283227
166.3665,20.803394,9.4362173,0.0,0,0.24180934,0.0,0.9906882,98.377434,0.27212441,343.68567,-9.2857084
166.3709,20.286106,9.4359207,0.0,0,0.21691413,0.0,0.99106503,95.886368,0.26494339,344.23605,-9.283782
166.3753,19.848476,9.4372387,0.0,0,0.19201899,0.0,0.99112684,93.801132,0.25872824,344.89258,-9.2830801
166.3797,19.5406,9.4388132,0.0,0,0.16712378,0.0,0.9917317,92.319534,0.25374982,345.57718,-9.2853308
166.3841,19.376036,9.4431849,0.0,0,0.14222859,0.0,0.99248248,91.454155,0.23511298,346.31839,-9.2863083
166.3885,19.337509,9.4409027,0.0,0,0.11733338,0.0,0.99212736,91.295906,0.2175172,347.11038,-9.2841597
166.3929,19.566479,9.4504223,0.0,0,0.092438176,0.0,0.9938668,92.180786,0.18505758,347.83511,-9.2832022
166.3973,19.712164,9.4479856,0.0,0,0.06754297,0.0,0.99356568,92.932854,0.1491214,348.37207,-9.2840614
166.4017,19.76973,9.4538641,0.0,0,0.042647772,0.0,0.99455523,93.099831,0.12314719,348.909,-9.2846489
166.4061,19.771759,9.451828,0.0,0,0.017752571,0.0,0.99445206,93.138145,0.091110229,349.258,-9.2832499
166.4105,19.760374,9.4586353,0.0,0,-0.0069684195,0.0,0.99561149,92.915451,0.064434052,349.60703,-9.2835665
166.4149,19.725216,9.4575996,0.0,0,-0.031256419,0.0,0.99591231,92.800194,0.040615182,349.93628,-9.2846889
166.4193,19.642557,9.4626846,0.0,0,-0.055544417,0.0,0.99673986,92.30481,0.01492874,350.25845,-9.2832394
166.4237,19.552956,9.4634571,6.658052,0,-0.079832412,0.0,0.9969784,91.870102,-0.0070184972,350.56772,-9.2835197
166.4281,19.503742,9.4680586,20.742613,0,-0.10412041,0.0,0.99779671,91.527443,-0.028694844,350.86261,-9.2821131
166.4325,19.450058,9.4640694,31.882326,0,0.46232089,359.99997,0.99717063,91.350296,-0.051741067,351.16299,-9.2842321
166.4369,18.094303,9.4671898,31.882326,0,1.259179,359.99997,0.99801034,85.049843,-0.018939076,351.48434,-9.2853394
166.4413,13.671961,9.4510469,31.882326,0,2.0560365,359.99997,0.99493659,64.627441,0.17919761,351.80566,-9.287282
166.4457,0.29412004,9.2725677,29.505417,0,2.8528941,359.99997,0.96382135,1.337335,0.660936,352.7092,-9.2999935
166.4501,0.0031758342,9.1264858,26.991356,0,3.6497517,359.99997,0.93840647,-0.041497476,2.0308392,353.64636,-9.3006229
166.4545,-0.15097573,9.215086,26.191408,0,4.4466095,359.99997,0.95329136,-0.76442361,3.0549092,355.53284,-9.2978296
166.4589,-0.036602695,9.4668484,26.191408,0,5.2434669,359.99997,0.99752533,-0.15004303,3.831414,357.86234,-9.2972651
166.4633,0.10730662,9.4426718,29.075418,0,6.0403247,359.99997,0.99292415,0.45766741,4.5726314,356.6066,-9.2941141
166.4677,-0.083438545,9.4366293,35.972092,0,6.8371825,359.99997,0.99301571,-0.39044529,5.3434162,350.36252,-9.2920952
166.4721,-0.034614749,9.4318047,41.802979,0,7.6340399,359.99997,0.99228662,-0.14803724,6.1530414,345.15164,-9.2924681
166.4765,-0.014053102,9.4295893,41.802979,0,8.4308977,359.99997,0.99149066,-0.10529591,6.9762406,345.59344,-9.2909422
166.4809,-0.0088988971,9.4301043,41.802979,0,9.2277546,359.99997,0.99169129,-0.051133484,7.8085499,346.03528,-9.2901344
166.4853,0.0025403458,9.4288254,25.350555,0,10.024613,359.99997,0.99160385,0.0388234,8.6321936,353.04184,-9.2888079
166.4897,0.0013013231,9.4321899,6.8833756,0,10.821471,359.99997,0.99243855,-0.063989446,9.4415092,360.85229,-9.2882967
166.4941,-0.12683409,9.4256496,0.0,0,11.618328,359.99997,0.9908886,-0.59593272,10.237565,362.98254,-9.2891407
166.4985,-0.011871213,9.4275999,0.0,0,12.415186,359.99997,0.99145758,-0.0016295977,11.029822,361.73746,-9.2892981
166.5029,-0.082303628,9.429266,2.2060378,0,13.212044,359.99997,0.99148971,-0.33127287,11.823414,360.39502,-9.287941
166.5073,0.038726602,9.4245958,8.2727842,0,14.008901,359.99997,0.99090981,0.18581212,12.608873,358.8822,-9.2879286
166.5117,-0.093175262,9.4275961,13.73291,0,14.805758,359.99997,0.99121481,-0.44430292,13.396049,357.37872,-9.2879248
166.5161,-0.0092102373,9.4242468,13.73291,0,15.602617,359.99997,0.99075341,-0.019172026,14.192941,355.95959,-9.287117
166.5205,-0.043677889,9.4259882,13.73291,0,16.399475,359.99997,0.99096674,-0.15722635,15.004324,354.54047,-9.2866068
166.5249,-0.046778161,9.4264908,21.136822,0,17.196333,359.99997,0.9909811,-0.2812188,15.805531,352.9411,-9.286521
166.5293,-0.052531846,9.4242792,29.989422,0,17.986996,359.99997,0.99040496,-0.21490428,16.605055,351.30649,-9.2860537
166.5337,-0.052540425,9.426156,33.771973,0,18.0,359.99997,0.9906866,-0.2915048,17.391029,349.74765,-9.2867031
166.5381,-0.03488056,9.4290066,33.771973,0,18.0,359.99997,0.99114704,-0.12006627,18.068806,348.24536,-9.2885275
166.5425,0.00044213084,9.4342861,35.029053,0,18.0,359.99997,0.99198848,-0.00088768377,18.457546,346.80908,-9.2946892
166.5469,-0.025702585,9.4463177,39.096203,0,18.0,359.99997,0.99404001,-0.16153337,18.43298,345.52045,-9.3053865
166.5513,-0.037889794,9.4657431,42.978516,0,18.0,359.99997,0.99738723,-0.16949768,18.194401,344.23483,-9.3255196
166.5557,0.074110083,9.4930582,42.978516,0,18.0,359.99997,1.0024736,0.31316164,18.051254,343.01328,-9.3527946
166.5601,-0.012481624,9.5287485,42.978516,0,18.0,359.99997,1.0086856,-0.0232118,18.044367,341.79175,-9.3899632
166.5645,-0.15509023,9.5677071,44.845371,0,18.0,359.99997,1.015731,-0.64187586,18.081661,340.55972,-9.4285383
166.5689,-0.07309898,9.6033134,47.23325,0,18.0,359.99997,1.0223305,-0.41935104,18.12184,339.32477,-9.4640417
166.5733,0.072809912,9.6327333,48.383789,0,18.0,359.99997,1.0276263,0.34306431,18.148954,338.15936,-9.4948339
166.5777,0.016317677,9.6659298,48.383789,0,18.0,359.99997,1.0335689,0.1055184,18.146244,337.05862,-9.5274706
166.5821,-0.11509923,9.7013388,48.822342,0,18.0,359.99997,1.0400274,-0.44657809,18.143955,335.98138,-9.5596066
166.5865,-0.10256243,9.7307959,50.5453,0,18.0,359.99997,1.0457991,-0.51996553,18.134155,334.9729,-9.5910463
166.5909,0.071861997,9.7603359,52.268257,0,18.0,359.99997,1.0513694,0.31630084,18.130806,333.96445,-9.6216269
166.5953,0.034547526,9.7919369,52.283939,0,18.0,359.99997,1.0573577,0.20086029,18.121738,332.96814,-9.6545811
166.5997,-0.092092082,9.8302698,52.283939,0,18.0,359.99997,1.0644045,-0.35551217,18.121454,331.97198,-9.6876373
166.6041,-0.14548486,9.8593254,53.233425,0,18.0,359.99997,1.0700471,-0.66724294,18.116196,331.15198,-9.7196283
166.6085,0.062583968,9.8941374,54.53899,0,18.0,359.99997,1.0766554,0.20138678,18.113541,330.39801,-9.7523851
166.6129,0.054281775,9.923028,55.239258,0,18.0,359.99997,1.0823883,0.25468239,18.10998,329.61911,-9.7836246
166.6173,-0.064179778,9.9605885,55.239258,0,18.0,359.99997,1.0897245,-0.21951032,18.108229,328.81128,-9.8168507
166.6217,-0.13111961,9.9901199,55.466385,0,18.0,359.99997,1.0953999,-0.5881325,18.106363,327.93619,-9.8494062
166.6261,0.023997581,10.020707,56.602081,0,18.0,359.99997,1.1017603,0.026465822,18.104843,326.79181,-9.8812819
166.6305,0.082936436,10.051994,57.737774,0,18.0,359.99997,1.1078556,0.38180822,18.099987,325.64743,-9.912118
166.6349,-0.043008927,10.088792,57.810059,0,18.0,359.99997,1.1150229,-0.116301,18.103519,324.66693,-9.94487
166.6393,-0.14880659,10.118019,57.810059,0,18.0,359.99997,1.1213105,-0.61894196,18.101416,323.69757,-9.9763813
166.6437,-0.019214731,10.152779,58.414082,0,18.0,359.99997,1.1280802,-0.1297345,18.09812,322.90936,-10.008075
166.6481,0.10260327,10.179229,59.311958,0,18.0,359.99997,1.1340564,0.44334176,18.096169,322.20926,-10.041851
166.6525,-0.022125358,10.219323,59.842533,0,18.0,359.99997,1.1415051,-0.0500242,18.096025,321.32681,-10.072869
166.6569,-0.14509447,10.246138,59.842533,0,18.0,359.99997,1.1479076,-0.57954216,18.093395,320.18094,-10.106717
166.6613,-0.059289444,10.280538,60.002769,0,18.0,359.99997,1.1546597,-0.31397077,18.090706,319.03094,-10.138404
166.6657,0.10790172,10.309834,61.104492,0,18.0,359.99997,1.1612761,0.40802565,18.090797,317.85654,-10.169063
166.6701,0.013483465,10.344135,62.206207,0,18.0,359.99997,1.1684666,0.084376931,18.086088,316.68213,-10.201267
166.6745,-0.12553369,10.374819,62.336426,0,18.0,359.99997,1.1755432,-0.43049639,18.089552,315.84048,-10.235389
166.6789,-0.075109117,10.412051,62.336426,0,18.0,359.99997,1.1830744,-0.34770992,18.082373,315.04343,-10.265801
166.6833,0.089291707,10.4345,62.783463,0,18.0,359.99997,1.1884388,0.30366811,18.089493,314.22131,-10.298933
166.6877,0.058645584,10.470055,63.506615,0,18.0,359.99997,1.1959864,0.27265409,18.081865,313.38373,-10.33015
166.6921,-0.13245676,10.503154,63.973389,0,18.0,359.99997,1.2035377,-0.47147986,18.085327,312.47906,-10.362795
166.6965,-0.10322187,10.539449,63.973389,0,18.0,359.99997,1.2117611,-0.42529365,18.082148,311.45236,-10.394472
166.7009,0.068716489,10.566892,64.041328,0,18.0,359.99997,1.2182368,0.20080991,18.079226,310.44653,-10.428718
166.7053,0.077438436,10.598901,64.78875,0,18.0,359.99997,1.2251495,0.33974549,18.077427,309.64948,-10.458852
166.7097,-0.11979499,10.63005,65.536171,0,18.0,359.99997,1.2326484,-0.40064299,18.08005,308.85242,-10.492012
166.7141,-0.11510479,10.66693,65.665283,0,18.0,359.99997,1.2410172,-0.4709053,18.074528,307.99948,-10.525775
166.7185,0.032146793,10.690578,65.665283,0,18.0,359.99997,1.246894,0.061878473,18.079031,307.13486,-10.557602
166.7229,0.095627949,10.72686,66.094757,0,18.0,359.99997,1.2551864,0.35826877,18.071186,306.12512,-10.587081
166.7273,-0.057350017,10.75882,66.856743,0,18.0,359.99997,1.2631227,-0.16402796,18.07304,305.00302,-10.619552
166.7317,-0.14140849,10.794086,67.390137,0,18.0,359.99997,1.2714961,-0.52370965,18.065506,303.95752,-10.652507
166.7361,0.024343882,10.81977,67.390137,0,18.0,359.99997,1.277824,0.027181301,18.065702,303.09076,-10.685854
166.7405,0.09297999,10.852601,67.410599,0,18.0,359.99997,1.2859575,0.31348664,18.066778,302.22986,-10.717713
166.7449,-0.020815944,10.8845,67.973595,0,18.0,359.99997,1.2935641,-0.0190806,18.066889,301.52451,-10.7494
166.7493,-0.16526324,10.919522,68.536591,0,18.0,359.99997,1.3024024,-0.56380713,18.06801,300.81915,-10.783154
166.7537,0.016232384,10.947533,68.664551,0,18.0,359.99997,1.3094749,-0.010547407,18.064304,299.95657,-10.81636
166.7581,0.07991121,10.980186,68.664551,0,18.0,359.99997,1.3174911,0.26722646,18.063974,299.04776,-10.845468
166.7625,0.017630085,11.009432,68.699135,0,18.0,359.99997,1.3248891,0.095993176,18.062351,298.13202,-10.877435
166.7669,-0.15930717,11.045958,68.76709,0,18.0,359.99997,1.334549,-0.51250052,18.062769,297.20963,-10.910874
166.7713,-0.029223561,11.073235,68.818359,0,18.0,359.99997,1.3413119,-0.16010131,18.063425,296.34381,-10.944456
166.7757,0.075929806,11.105821,68.818359,0,18.0,359.99997,1.3499832,0.24916285,18.063463,295.65201,-10.975437
166.7801,0.035966814,11.136856,68.818359,0,18.0,359.99997,1.3579162,0.14966173,18.058756,294.96021,-11.006897
166.7845,-0.13706218,11.17065,69.271042,0,18.0,359.99997,1.3669626,-0.37998444,18.05628,294.18854,-11.038822
166.7889,-0.07247369,11.202249,69.732117,0,18.0,359.99997,1.3752546,-0.28230616,18.055084,293.41534,-11.071259
166.7933,0.087067038,11.230061,69.862061,0,18.0,359.99997,1.382625,0.29127806,18.053766,292.64218,-11.10308
166.7977,0.058806706,11.260211,69.862061,0,18.0,359.99997,1.3907622,0.20609847,18.052816,291.86899,-11.132926
166.8021,-0.10916908,11.296164,70.034134,0,18.0,359.99997,1.4006974,-0.28628686,18.052887,291.1821,-11.166405
166.8065,-0.10993276,11.326356,70.412697,0,18.0,359.99997,1.4086502,-0.37963691,18.048191,290.59882,-11.201315
166.8109,0.099910185,11.358612,70.718994,0,18.0,359.99997,1.4176803,0.27571738,18.046486,289.97128,-11.232086
166.8153,0.07016442,11.387611,70.718994,0,18.0,359.99997,1.4254498,0.22612947,18.05509,289.15622,-11.263271
166.8197,-0.068475835,11.423712,70.718994,0,18.0,359.99997,1.4355583,-0.15321954,18.048302,288.34116,-11.296601
166.8241,-0.14285181,11.457375,41.750187,0,18.0,359.99997,1.4449095,-0.43579921,18.047113,287.51212,-11.328752
166.8285,0.057337329,11.484073,10.508869,0,18.0,359.99997,1.4529128,0.14085732,18.04962,286.68201,-11.360604
168.6292,-0.030867491,11.606565,0.0,0,18.0,1.0338234000000001e-22,1.4860477,-0.090183258,18.000618,59.593021,-11.479856
170.8292,-0.037334442,11.606868,0.0,0,18.0,1.4012985e-45,1.4862645,-0.10857902,17.999104,29.527836,-11.481178
173.0292,-0.031883359,11.607429,0.0,0,18.0,1.4012985e-45,1.4863077,-0.09064246,18.000648,26.572586,-11.481044
175.2292,-0.028806904,11.606679,0.0,0,18.0,1.4012985e-45,1.4863049,-0.082753859,17.998968,26.067757,-11.481079
177.4292,-0.027790356,11.608346,0.0,0,18.0,1.4012985e-45,1.4866697,-0.079869159,18.000841,25.954859,-11.481591
179.6292,-0.045414981,11.607189,0.0,0,18.0,1.4012985e-45,1.4865378,-0.1334668,18.000193,25.818647,-11.48114
181.8292,-0.035101276,11.607511,0.0,0,18.0,1.4012985e-45,1.486516,-0.098347694,18.000277,25.803865,-11.480833
184.0292,-0.028911475,11.607996,0.0,0,18.0,1.4012985e-45,1.4867598,-0.087184265,18.000195,25.570705,-11.481327
186.2292,-0.034887336,11.608493,0.0,0,18.0,1.4012985e-45,1.4868891,-0.1031718,18.000202,25.56889,-11.481289
188.4292,-0.030547449,11.608653,0.0,0,18.0,1.4012985e-45,1.486903,-0.089696988,17.999277,25.432747,-11.481503
190.6292,-0.035490822,11.609568,0.0,0,18.0,1.4012985e-45,1.4871701,-0.10215578,18.000242,25.356312,-11.481679
192.8292,-0.040017329,11.609385,0.0,0,18.0,1.4012985e-45,1.4870559,-0.11656025,18.000385,25.398829,-11.481229
195.0292,-0.038970836,11.609861,0.0,0,18.0,1.4012985e-45,1.48722,-0.11445821,17.99991,25.354225,-11.48131
197.2292,-0.036886331,11.609977,0.0,0,18.0,1.4012985e-45,1.4871551,-0.10565893,17.999369,25.303823,-11.480869
199.4292,-0.029713688,11.611069,0.0,0,18.0,1.4012985e-45,1.4875182,-0.085898541,17.999926,25.298555,-11.481174
201.6292,-0.028960634,11.611717,0.0,0,18.0,1.4012985e-45,1.4876373,-0.084869526,18.001886,25.210146,-11.481594
203.8292,-0.037123095,11.61183,0.0,0,18.0,1.4012985e-45,1.4877526,-0.10751901,17.999868,25.058981,-11.481571
206.0292,-0.032586515,11.612552,0.0,0,18.0,1.4012985e-45,1.4878497,-0.094502777,18.000263,25.145559,-11.481563
208.2292,-0.025229247,11.612251,0.0,0,18.0,1.4012985e-45,1.4878465,-0.072528094,18.000122,25.062662,-11.481475
210.4292,-0.032843255,11.613592,0.0,0,18.0,1.4012985e-45,1.4881252,-0.097979307,18.000671,25.025505,-11.481431
212.6292,-0.047235217,11.612797,0.0,0,18.0,1.4012985e-45,1.4880381,-0.1337125,18.000435,25.09606,-11.48145
214.8292,-0.039173093,11.613706,0.0,0,18.0,1.4012985e-45,1.4882171,-0.11114091,17.999119,24.998739,-11.481507
217.0292,-0.039709579,11.613984,0.0,0,18.0,1.4012985e-45,1.4884472,-0.11280961,17.999916,24.945528,-11.480836
219.2292,-0.032259904,11.615074,0.0,0,18.0,1.4012985e-45,1.4886866,-0.090360634,18.000732,24.866571,-11.481462
221.4292,-0.035849597,11.615127,0.0,0,18.0,1.4012985e-45,1.4888916,-0.1001498,17.999586,24.94219,-11.4819
223.6292,-0.039441351,11.615403,0.0,0,18.0,1.4012985e-45,1.4889121,-0.11405732,18.000204,24.98452,-11.48072
225.8292,-0.04136787,11.615218,0.0,0,18.0,1.4012985e-45,1.4888545,-0.12026656,17.999687,24.923428,-11.479984
226.8292,-0.022354702,11.615341,0.0,0,18.0,1.4012985e-45,1.4889145,-0.06617786,18.000525,24.848774,-11.480677