File: examples/dan-msc-case-studies/CS3/data/01 raw data/baron_test_116.csv
Time(sec),Force(kN),Jaw(mm),PowAngle(deg),Power(W),Pram,PTemp,Strain,Stress(MPa),Stroke(mm),TC1(C),wedge(mm)
0.0,0.83086109,0.3689675,0.0,0,11.076097,0.0,0.024914473,10.334657,11.07656,24.496813,-9.1441822
1.2,0.77868283,0.0037631139,0.0,0,11.076097,3.5155816,0.00026105953,9.9097061,11.076201,24.406908,-9.4966459
2.4,0.74774063,0.0034248556,0.0,0,11.076097,7.1155815,0.00024623625,9.510541,11.076503,24.419802,-9.4942532
3.6,0.73106092,0.0033518423,0.0,0,11.076097,10.715581,0.00021398535,9.2996216,11.076303,24.450256,-9.4928436
4.8,0.70269096,0.0036517517,0.0,0,11.076097,14.31558,0.00022422674,8.9333858,11.076027,24.477047,-9.4900818
6.0,0.68677598,0.0035382824,0.0,0,11.076097,17.915585,0.00022988701,8.7423687,11.076151,24.353785,-9.4880219
7.2,0.67781609,0.0032541868,0.0,0,11.076097,21.515583,0.00022975008,8.6350813,11.076007,24.336414,-9.485899
8.4,0.66109359,0.0029127183,3.9810898,0,11.076097,25.115583,0.00019804473,8.4110603,11.076686,24.370623,-9.4833632
9.6,0.64911717,0.0036195694,27.341219,0,11.076097,28.715582,0.00026459788,8.2662077,11.076653,24.46117,-9.4811687
10.8,0.65830475,0.0027300909,36.960312,0,11.076097,32.315586,0.00018211718,8.3849726,11.074877,25.59889,-9.4793386
12.0,0.6544382,0.00034315608,41.801971,0,11.076097,35.915588,5.3331978e-06,8.3236027,11.076709,28.04727,-9.4773321
13.2,0.65230089,-0.0029648726,44.90081,0,11.076097,39.515591,-0.00020005921,8.3054399,11.076375,31.356211,-9.4753914
14.4,0.66151702,-0.0062544779,46.711857,0,11.076097,43.115593,-0.00041128864,8.4190912,11.077032,35.266212,-9.4734049
15.6,0.66050696,-0.010563359,47.955318,0,11.076097,46.715595,-0.00069500605,8.4086514,11.076282,39.371578,-9.4709749
16.8,0.65110075,-0.013152306,48.787682,0,11.076097,50.315594,-0.00085860514,8.2988186,11.076798,43.832283,-9.4688969
18.0,0.65720099,-0.016840946,48.814087,0,11.076097,53.9156,-0.001133095,8.377243,11.07678,48.489872,-9.466445
19.2,0.65165764,-0.020407088,49.203918,0,11.076097,57.515598,-0.0013822449,8.2973747,11.076612,52.925816,-9.4645166
20.4,0.65806425,-0.023754688,49.208927,0,11.076097,61.115597,-0.0015819913,8.407218,11.076329,57.402405,-9.4623013
21.6,0.65851766,-0.02795442,49.031254,0,11.076097,64.715576,-0.0018555912,8.3948231,11.076673,61.698288,-9.4599056
22.8,0.65730542,-0.03041896,48.982365,0,11.076097,68.315582,-0.0020248692,8.3917427,11.07603,65.874252,-9.4580603
24.0,0.6572746,-0.033319689,49.229733,0,11.076097,71.915573,-0.0021963585,8.389039,11.076044,69.780441,-9.4557104
25.2,0.65501016,-0.036410648,49.480545,0,11.076097,75.515579,-0.0024373746,8.3556585,11.076519,73.568481,-9.4538851
26.4,0.65746045,-0.038884949,49.630985,0,11.076097,79.115578,-0.0026086688,8.3865833,11.077008,77.453323,-9.4515533
27.6,0.66630632,-0.042508837,49.636227,0,11.076097,82.715591,-0.0028233693,8.5134554,11.076277,81.203224,-9.4497547
28.8,0.66770625,-0.045824204,50.042721,0,11.076097,86.315582,-0.0030452516,8.5340128,11.077299,84.790253,-9.4477005
30.0,0.65988714,-0.048407011,50.438229,0,11.076097,89.915596,-0.0032156527,8.4333258,11.075523,88.365273,-9.4455576
31.2,0.66176814,-0.051892936,50.822365,0,11.076097,93.515594,-0.0034224978,8.4644413,11.075706,91.937508,-9.4432917
32.4,0.65966612,-0.054968201,51.076206,0,11.076097,97.115601,-0.0036749109,8.4342499,11.076118,95.571846,-9.4410934
33.6,0.66494435,-0.058518197,51.351925,0,11.076097,100.71559,-0.0039093229,8.5097256,11.075383,99.261269,-9.4384794
34.8,0.67259872,-0.061102178,51.57827,0,11.076097,104.31561,-0.0040615508,8.600565,11.076844,102.80424,-9.4367332
36.0,0.6664471,-0.063973106,51.932369,0,11.076097,107.9156,-0.0042490647,8.5255556,11.075887,106.37856,-9.4341669
37.2,0.66460764,-0.067292094,52.225399,0,11.076097,111.5156,-0.0044635567,8.4986916,11.076594,110.13436,-9.4323397
38.4,0.67592031,-0.07045687,52.283936,0,11.076097,115.1156,-0.0046684383,8.6553736,11.076247,113.79237,-9.42941
39.6,0.6686359,-0.073305562,52.635494,0,11.076097,118.71561,-0.0048954091,8.5641441,11.076969,117.35044,-9.4276867
40.8,0.67351139,-0.076065697,52.974644,0,11.076097,122.31559,-0.005080122,8.6160755,11.075773,120.97997,-9.4258099
42.0,0.66657072,-0.079157054,52.97607,0,11.076097,125.9156,-0.005248968,8.5272045,11.075763,124.75628,-9.4236059
43.2,0.66526437,-0.082780354,53.892864,0,11.076097,129.51573,-0.0054964707,8.5128689,11.07599,127.71547,-9.4216042
44.4,0.68157566,-0.087009504,54.428638,0,11.076097,133.11559,-0.0057732263,8.7325916,11.076737,131.03313,-9.419816
45.6,0.67786485,-0.089452855,55.067139,0,11.076097,136.71561,-0.0059347581,8.678813,11.075838,134.36909,-9.4177494
46.8,0.67000729,-0.093484007,55.535812,0,11.076097,140.31557,-0.0062226485,8.5962448,11.076288,137.89995,-9.4161234
48.0,0.67021036,-0.096902378,55.399521,0,11.076097,143.9156,-0.006453224,8.588809,11.07617,142.12624,-9.4139318
49.2,0.68198466,-0.1013803,55.304653,0,11.076097,147.51559,-0.0067307907,8.736659,11.076723,146.08426,-9.411355
50.4,0.67096454,-0.10343795,55.627537,0,11.076097,151.11559,-0.0068744156,8.6059523,11.076002,149.6368,-9.4093523
51.6,0.67377359,-0.10672309,56.120644,0,11.076097,154.71558,-0.0070680054,8.6525135,11.076495,153.05981,-9.406992
52.8,0.67963046,-0.11045526,56.425777,0,11.076097,158.3156,-0.0073343161,8.7146034,11.077024,156.5556,-9.4049692
54.0,0.68697381,-0.1155191,56.94223,0,11.076097,161.91557,-0.0076948227,8.8118515,11.075123,159.9305,-9.4030294
55.2,0.68560976,-0.11673672,57.243744,0,11.076097,165.51556,-0.0077494155,8.7871342,11.077071,163.57813,-9.4006014
56.4,0.68346089,-0.12113624,57.136162,0,11.076097,169.11559,-0.0080310348,8.7760124,11.075544,167.55771,-9.3983727
57.6,0.68287432,-0.12478656,57.226219,0,11.076097,172.71558,-0.0082787117,8.7673502,11.076386,171.34784,-9.3966589
58.8,0.6896534,-0.12903769,57.223961,0,11.076097,176.31557,-0.0085423719,8.8524094,11.076307,175.27139,-9.3945675
60.0,0.68109274,-0.13084148,57.454391,0,11.076097,179.91557,-0.0086909803,8.7442474,11.076428,178.71852,-9.3924809
61.2,0.6770162,-0.13429081,57.810375,0,11.076097,183.51558,-0.00892979,8.7068653,11.076421,182.0683,-9.3906155
62.4,0.69391406,-0.13955367,58.073727,0,11.076097,187.11557,-0.0092547685,8.8949842,11.076179,185.7422,-9.3887796
63.6,0.68590361,-0.14134091,58.336494,0,11.076097,190.71559,-0.0093741203,8.8050289,11.077252,189.26595,-9.3873558
64.8,0.68693471,-0.14489651,58.58741,0,11.076097,194.31558,-0.0095986146,8.8355646,11.075933,192.77666,-9.3850565
66.0,0.69249445,-0.14960407,58.847279,0,11.076097,197.91559,-0.0099239899,8.8908148,11.07648,196.34404,-9.3826361
67.2,0.67944586,-0.15203463,59.005684,0,11.076097,201.51558,-0.010098923,8.7395611,11.075645,199.93532,-9.3804817
68.4,0.69072592,-0.15587801,59.106438,0,11.076097,205.1156,-0.010349412,8.8800364,11.075922,203.73984,-9.3787956
69.6,0.68815327,-0.15888016,59.348137,0,11.076097,208.71561,-0.01052926,8.8508339,11.076776,207.29808,-9.3763456
70.8,0.68737781,-0.1629252,59.600826,0,11.076097,212.3156,-0.010796416,8.850358,11.076758,210.81009,-9.3742085
72.0,0.69547278,-0.16849786,59.664162,0,11.076097,215.9156,-0.011149592,8.9481697,11.075778,214.53983,-9.3719072
73.2,0.69117206,-0.17047007,59.933163,0,11.076097,219.51559,-0.011314294,8.9050989,11.076277,218.12186,-9.3698769
74.4,0.68743229,-0.17459367,60.265732,0,11.076097,223.1156,-0.011591985,8.8630285,11.076246,221.5862,-9.3682327
75.6,0.6944589,-0.1778747,60.313435,0,11.076097,226.71561,-0.011767531,8.9468184,11.07618,225.23264,-9.3660297
76.8,0.68790388,-0.18197599,60.551628,0,11.076097,230.31561,-0.012056901,8.871048,11.075863,228.965,-9.3639231
78.0,0.70210308,-0.18746687,60.556534,0,11.076097,233.91562,-0.01240436,9.0756207,11.076168,232.73219,-9.3624096
79.2,0.69484514,-0.18954456,60.556637,0,11.076097,237.51561,-0.012556859,8.9572201,11.075814,236.45642,-9.360157
80.4,0.69121629,-0.19366691,60.787163,0,11.076097,241.1156,-0.012849726,8.9172287,11.076506,240.06065,-9.3579168
81.6,0.69527799,-0.19673131,60.787346,0,11.076097,244.71561,-0.013034054,8.9680996,11.076118,243.7287,-9.3557863
82.8,0.69257182,-0.20137203,61.018036,0,11.076097,248.31561,-0.013325677,8.9253368,11.075708,247.3166,-9.353508
84.0,0.70026159,-0.20581202,61.018063,0,11.076097,251.91559,-0.013622133,9.0469208,11.077139,250.9308,-9.3516388
85.2,0.69848084,-0.20902276,61.155697,0,11.076097,255.51561,-0.013823264,9.017231,11.076177,254.5937,-9.3496523
86.4,0.69107431,-0.21342915,61.248569,0,11.076097,259.11584,-0.014135139,8.9109917,11.076515,258.16,-9.3476028
87.6,0.70035726,-0.2160563,61.468498,0,11.076097,262.71567,-0.014314543,9.0468025,11.076427,261.72342,-9.3458786
88.8,0.69188958,-0.21994919,61.468498,0,11.076097,266.31561,-0.014560213,8.9449644,11.076121,265.47809,-9.344079
90.0,0.70322704,-0.22546178,61.468498,0,11.076097,269.91559,-0.01491397,9.1015139,11.07619,269.19727,-9.3418713
91.2,0.69837487,-0.22694425,61.687641,0,11.076097,273.51559,-0.015000965,9.0405931,11.076705,272.60233,-9.3401632
92.4,0.70077682,-0.23067451,61.907955,0,11.076097,277.1156,-0.015269235,9.0549049,11.076707,276.02002,-9.3380604
93.6,0.70488894,-0.23572481,62.116512,0,11.076097,280.71555,-0.015620479,9.1231728,11.076622,279.56741,-9.3360786
94.8,0.69786924,-0.23802231,62.336575,0,11.076097,284.31558,-0.015727868,9.0349922,11.075802,282.99243,-9.333684
96.0,0.6940043,-0.2423581,62.545074,0,11.076097,287.91556,-0.016033022,8.967783,11.076899,286.53293,-9.3317041
97.2,0.70281547,-0.24678513,62.753899,0,11.076097,291.51559,-0.016301718,9.1156626,11.076268,290.03006,-9.3296852
98.4,0.70123869,-0.25034228,62.962639,0,11.076097,295.11557,-0.016557265,9.0893803,11.077029,293.63898,-9.3277302
99.6,0.69532323,-0.25480527,63.150829,0,11.076097,298.71558,-0.016867775,8.9876404,11.076579,297.24164,-9.3255024
100.8,0.7062645,-0.2587907,63.202133,0,11.076097,302.31558,-0.017100869,9.1454544,11.076259,300.99506,-9.3237133
102.0,0.6981982,-0.26251182,63.369137,0,11.076097,305.91559,-0.017354662,9.0441914,11.076692,304.43976,-9.321187
103.2,0.70616144,-0.26648819,63.577873,0,11.076097,309.51559,-0.017594935,9.1362219,11.076369,308.05579,-9.3194456
104.4,0.70841289,-0.26981238,63.775627,0,11.076097,313.1156,-0.017836897,9.1854391,11.07591,311.56085,-9.317524
105.6,0.69633049,-0.27430612,63.973385,0,11.076097,316.71558,-0.01814463,9.0271158,11.076288,315.14438,-9.3154526
106.8,0.70411831,-0.27848154,64.069778,0,11.076097,320.31558,-0.018378234,9.1402473,11.075761,318.85715,-9.313693
108.0,0.70455444,-0.28183267,64.342796,0,11.076097,323.91559,-0.018618032,9.1411028,11.076388,322.36118,-9.3116341
109.2,0.70419371,-0.2867406,64.367958,0,11.076097,327.51559,-0.018915173,9.1248417,11.076838,326.05615,-9.3100166
110.4,0.71508473,-0.29214564,63.805428,0,11.076097,329.99976,-0.019286633,9.2784157,11.076693,329.88144,-9.3082695
111.6,0.70558709,-0.29212514,61.673248,0,11.076097,329.99976,-0.019304154,9.1661615,11.077756,333.30386,-9.3087473
112.8,0.70382476,-0.2943511,59.611713,0,11.076097,329.99976,-0.0194299,9.1267948,11.077039,335.60495,-9.3082323
114.0,0.69833195,-0.29694578,57.441715,0,11.076097,329.99976,-0.019593963,9.0589314,11.076512,337.19769,-9.3083162
115.2,0.69632649,-0.29510027,55.844337,0,11.076097,329.99976,-0.01945965,9.0507374,11.076401,337.78616,-9.3079615
116.4,0.67535824,-0.29547775,54.534904,0,11.076097,329.99976,-0.019509772,8.771204,11.076604,337.7132,-9.308219
117.6,0.64267325,-0.29628125,53.65723,0,11.076097,329.99976,-0.019588256,8.3458748,11.076111,337.22278,-9.3077106
118.8,0.55310917,-0.29473564,52.976078,0,11.076097,329.99976,-0.019447671,7.176991,11.076806,336.54379,-9.3076544
120.0,0.50499499,-0.29466328,52.635502,0,11.076097,329.99976,-0.019457638,6.5483184,11.075813,335.55484,-9.3075762
121.2,0.49050668,-0.29491717,52.635502,0,11.076097,329.99976,-0.019446634,6.3663306,11.076597,334.58691,-9.30793
122.4,0.48124138,-0.29460058,52.885727,0,11.076097,329.99976,-0.019451296,6.2477155,11.076307,333.55331,-9.3075113
123.6,0.46341732,-0.29384273,53.122604,0,11.076097,329.99976,-0.019417781,6.0128264,11.076259,332.63321,-9.3077192
124.8,0.46524882,-0.29415172,53.340698,0,11.076097,329.99976,-0.019424049,6.0451174,11.07587,331.86951,-9.3077402
126.0,0.46675935,-0.29400074,53.657223,0,11.076097,329.99976,-0.019404976,6.0465941,11.0768,331.22491,-9.3078175
127.2,0.46106961,-0.29508039,53.975826,0,11.076097,329.99976,-0.019464206,5.9866638,11.075584,330.69012,-9.3077869
128.4,0.46776515,-0.29376966,54.305416,0,11.076097,329.99976,-0.019392718,6.074245,11.07585,330.33737,-9.3077374
129.6,0.46026146,-0.29438698,54.508682,0,11.076097,329.99976,-0.019452821,5.9691038,11.076593,329.98657,-9.3080654
130.8,0.46210247,-0.29460102,54.717579,0,11.076097,329.99976,-0.019433452,6.0138135,11.076244,329.72852,-9.3080368
132.0,0.46964821,-0.29522663,54.929409,0,11.076097,329.99976,-0.019489998,6.0841126,11.076982,329.67487,-9.308362
133.2,0.47440293,-0.29701176,54.979866,0,11.076097,329.99976,-0.01959236,6.1727662,11.077614,329.62744,-9.3083067
134.4,0.46957457,-0.2953352,54.969101,0,11.076097,329.99976,-0.019512841,6.1126623,11.076142,329.64154,-9.3081923
135.6,0.47245184,-0.29605281,55.122288,0,11.076097,329.99976,-0.019563559,6.1371384,11.076263,329.62262,-9.3079023
136.8,0.47050393,-0.29685485,55.198174,0,11.076097,329.99976,-0.019590363,6.1015348,11.076429,329.62604,-9.3078613
138.0,0.45909968,-0.29758504,55.239254,0,11.076097,329.99976,-0.019635776,5.9837756,11.07631,329.62897,-9.3074656
139.2,0.46616006,-0.2981866,55.239254,0,11.076097,329.99976,-0.01966604,6.0460882,11.076159,329.71555,-9.3077765
140.4,0.45375937,-0.298538,55.239254,0,11.076097,329.99976,-0.019722039,5.8956475,11.07604,329.73593,-9.3069811
141.6,0.4721792,-0.2991986,55.106163,0,11.076097,329.99976,-0.019760627,6.1282768,11.07668,329.85196,-9.3071747
142.8,0.48057497,-0.30023432,55.238361,0,11.076097,329.99976,-0.019800186,6.2540846,11.075893,329.90515,-9.3073196
144.0,0.47306621,-0.30147597,55.101692,0,11.076097,329.99976,-0.019884728,6.1548328,11.075835,330.06,-9.3067999
145.2,0.47392377,-0.30197877,54.931644,0,11.076097,329.99976,-0.019917069,6.1523857,11.075795,330.23462,-9.3066225
146.4,0.4698799,-0.30263281,54.664539,0,11.076097,329.99976,-0.019989418,6.0994816,11.076874,330.32602,-9.306778
147.6,0.47258303,-0.30271232,54.697708,0,11.076097,329.99976,-0.019978799,6.1402817,11.075607,330.26337,-9.3065386
148.8,0.47912973,-0.30289084,54.624046,0,11.076097,329.99976,-0.01998568,6.2233315,11.07588,330.26855,-9.3070717
150.0,0.47418687,-0.30259132,54.677593,0,11.076097,329.99976,-0.019956106,6.1437049,11.077071,330.18314,-9.3072042
151.2,0.47321275,-0.30253753,54.674622,0,11.076097,329.99976,-0.019977147,6.1353569,11.076134,330.20398,-9.3075466
152.4,0.46129206,-0.30296013,54.697342,0,11.076097,329.99976,-0.02001721,5.9867039,11.076465,330.09579,-9.3071947
153.6,0.46847776,-0.3033008,54.764484,0,11.076097,329.99976,-0.020019973,6.0803905,11.076375,330.06387,-9.3074131
154.8,0.4727065,-0.30380407,54.762314,0,11.076097,329.99976,-0.020052716,6.1597557,11.075966,330.04977,-9.3074913
155.2833,0.46242893,0.055715218,45.138393,0,11.076099,8.2569668e-06,0.0033515596,5.7177429,11.075921,330.02939,-9.3078947
155.2857,0.53087521,0.055745095,32.054794,0,11.076099,3.5694848000000004e-22,0.0037237466,6.6063609,11.075563,330.03668,-9.307991
155.2881,0.47952119,0.051556647,18.971195,0,11.076099,1.5430874e-38,0.0037409705,6.0966382,11.076131,330.04398,-9.3079014
155.2905,0.47148171,0.048769124,5.887599,0,11.076099,0.0,0.003455041,5.9519286,11.075505,330.05127,-9.3070717
155.2929,0.46683842,0.049677663,0.0,0,11.076099,0.0,0.0031909931,5.9499383,11.07489,330.03851,-9.308588
155.2953,0.46606979,0.051704254,0.0,0,11.076099,0.0,0.0033323709,6.0189352,11.075611,330.00931,-9.3065195
155.2977,0.4716292,0.052331284,0.0,0,11.076099,0.0,0.0034723373,5.978199,11.075191,329.98013,-9.3055887
155.3001,0.47119391,0.051287185,0.0,0,11.076099,0.0,0.0036383073,5.9237852,11.07572,329.95093,-9.3070936
155.3025,0.45878968,0.049743596,0.0,0,11.076099,0.0,0.0035068644,5.821589,11.076969,329.93268,-9.3075361
155.3049,0.44754282,0.053207058,0.0,0,11.076099,0.0,0.0033755265,5.782691,11.077526,329.93268,-9.3087101
155.3073,0.46047267,0.056757733,0.0,0,11.076099,0.0,0.0034478742,5.9180236,11.075706,329.93268,-9.3070269
155.3097,0.46768466,0.056638926,0.0,0,11.076099,0.0,0.0036380969,5.8556886,11.074947,329.93268,-9.307354
155.3121,0.4460001,0.052031633,0.0,0,11.076099,0.0,0.0036882954,5.7253933,11.080366,329.93707,-9.3075323
155.3145,0.43824562,0.046495501,0.0,0,11.076099,0.0,0.0033796602,5.5977778,11.077486,329.95895,-9.3070364
155.3169,0.44216713,0.048556603,0.0,0,11.076099,0.0,0.0031773255,5.5776801,11.078331,329.98087,-9.3064079
155.3193,0.44967929,0.05086866,0.0,0,11.076099,0.0,0.0032248069,5.6544595,11.077554,330.00275,-9.3073883
155.3217,0.44694921,0.051140685,0.0,0,11.076099,0.0,0.0033797624,5.7816606,11.076683,330.02393,-9.3064651
155.3241,0.42911097,0.04899155,0.0,0,11.076099,0.0,0.0034944976,5.5139847,11.074828,330.01663,-9.3069668
155.3265,0.44117323,0.049757838,0.0,0,11.076099,0.0,0.0035137166,5.5709271,11.07649,330.00931,-9.3065071
155.3289,0.4364098,0.050907351,0.0,0,11.076099,0.0,0.0033668545,5.6124601,11.078401,330.00201,-9.3070965
155.3313,0.44740427,0.053792272,0.0,0,11.076099,0.0,0.0033130629,5.6828742,11.078732,329.99472,-9.3075333
155.3337,0.43591139,0.054831319,0.0,0,10.856144,0.0,0.003505866,5.5911689,11.076217,329.99982,-9.3074045
155.3361,0.42916957,0.054104324,0.0,0,10.495171,0.0,0.0037318962,5.3949161,11.076786,330.00714,-9.3080063
155.3385,0.44817078,0.049178563,0.0,0,10.134197,0.0,0.0035589307,5.6062007,11.035784,330.01443,-9.307312
155.3409,0.43129537,0.048837826,0.0,0,9.7732229,0.0,0.0032880555,5.5120544,10.846225,330.02173,-9.3067846
155.3433,0.46840847,0.051552888,0.0,0,9.4141388,0.0,0.0032600726,5.9590321,10.522493,331.92108,-9.3072367
155.3457,0.44665781,0.052654963,0.0,0,9.0629702,0.0,0.0033997537,5.6982737,10.089098,334.73138,-9.3079748
155.3481,7.6687727,0.42732549,0.0,0,8.7136879,0.0,0.028527187,94.078529,9.6256933,337.54169,-9.301301
155.3505,9.5255079,0.80378288,0.0,0,8.3796968,0.0,0.054648399,114.41585,9.1933632,340.35199,-9.2979078
155.3529,9.5883617,1.2207227,0.0,0,8.0462685,0.0,0.084611148,112.12296,8.7576036,343.12234,-9.2978821
155.3553,10.100621,1.5959458,0.0,0,7.7283754,0.0,0.11193667,114.72705,8.3719797,345.85275,-9.2968979
155.3577,10.359065,1.9377494,0.0,0,7.410615,0.0,0.13747002,115.04782,8.0466137,348.58319,-9.2975359
155.3601,10.794505,2.2215798,0.0,0,7.1075153,0.0,0.16005097,116.95628,7.7393103,351.3136,-9.2989159
155.3625,10.96591,2.5024254,0.0,0,6.8053074,0.0,0.18252091,116.29229,7.4373341,352.46149,-9.2977037
155.3649,11.277452,2.7990587,0.0,0,6.5157218,0.0,0.20618974,116.69408,7.140903,350.3226,-9.2976856
155.3673,11.545212,3.0957887,0.0,0,6.2282019,0.0,0.23047923,116.69053,6.8465781,348.18372,-9.2970409
155.3697,11.920573,3.3855641,0.0,0,5.9515953,0.0,0.25515455,117.52859,6.5531836,346.04483,-9.2992649
155.3721,12.18225,3.6754277,0.0,0,5.6781397,0.0,0.28078005,117.08023,6.2609506,344.00089,-9.300209
155.3745,12.483807,3.9589012,0.0,0,5.4138937,0.0,0.30650491,116.97984,5.9737887,342.495,-9.2993736
155.3769,12.769855,4.2406111,0.0,0,5.1537337,0.0,0.33202887,116.64972,5.691412,340.98911,-9.2986774
155.3793,13.096964,4.5226173,0.0,0,4.9013243,0.0,0.35794362,116.51337,5.4141383,339.48322,-9.2991018
155.3817,13.440562,4.7929025,0.0,0,4.6538844,0.0,0.38391498,116.50751,5.1423264,337.97736,-9.300128
155.3841,13.745994,5.0509391,0.0,0,4.4127817,0.0,0.41013196,116.05685,4.8796759,336.33136,-9.2990103
155.3865,14.052677,5.3000612,0.0,0,4.1773896,0.0,0.43610507,115.72643,4.6265044,334.68179,-9.2992992
155.3889,14.399157,5.5453372,0.0,0,3.9470973,0.0,0.46148092,115.44191,4.3812594,333.03223,-9.2980518
155.3913,14.769244,5.7888198,0.0,0,3.7232254,0.0,0.48687673,115.50637,4.1350026,331.38266,-9.2979622
155.3937,15.16072,6.0249414,0.0,0,3.5032687,0.0,0.51272935,115.57686,3.9009631,331.08768,-9.2978525
155.3961,15.550058,6.2542005,0.0,0,3.2902927,0.0,0.53903025,115.48589,3.6767879,331.13135,-9.2966814
155.3985,15.951632,6.4726315,0.0,0,3.0801783,0.0,0.56488425,115.39165,3.4502997,331.17502,-9.2964191
155.4009,16.404116,6.6909018,0.0,0,2.8775704,0.0,0.59076297,115.62988,3.233407,331.21866,-9.2966652
155.4033,16.90449,6.9097381,0.0,0,2.6768677,0.0,0.61663526,116.09513,3.0184267,331.54984,-9.298605
155.4057,17.385279,7.1223588,0.0,0,2.4841473,0.0,0.64264512,116.36105,2.8097405,332.05353,-9.2975988
155.4081,17.894819,7.3255563,0.0,0,2.2924595,0.0,0.66935313,116.64196,2.6078184,332.55719,-9.2973709
155.4105,18.442133,7.520824,0.0,0,2.1091442,0.0,0.6961953,116.96236,2.4078999,333.06088,-9.2975836
155.4129,19.043268,7.708952,0.0,0,1.9261373,0.0,0.72179681,117.73283,2.2139544,333.00043,-9.2965832
155.4153,19.667309,7.8963594,0.0,0,1.7516804,0.0,0.74684048,118.61496,2.0305762,332.25052,-9.296236
155.4177,20.316101,8.0827732,0.0,0,1.5772964,0.0,0.7728073,119.37498,1.8445789,331.50058,-9.2963715
155.4201,21.002445,8.2619839,0.0,0,1.4109213,0.0,0.79965085,120.17052,1.6648133,330.75067,-9.295702
155.4225,21.738838,8.430768,0.0,0,1.2450334,0.0,0.82586831,121.08713,1.4939474,329.63364,-9.2956495
155.4249,22.546179,8.5964603,0.0,0,1.0861164,0.0,0.85161144,122.40675,1.3208596,327.54874,-9.2944307
155.4273,23.353399,8.7642078,0.0,0,0.92834044,0.0,0.87713516,123.62686,1.160521,325.46384,-9.2947388
155.4297,24.184925,8.9301062,0.0,0,0.77656138,0.0,0.90294743,124.73707,0.99596727,323.37897,-9.2945032
155.4321,25.06061,9.0840578,0.0,0,0.62651336,0.0,0.92919582,125.96315,0.83602482,321.2673,-9.2935743
155.4345,26.000719,9.2263927,0.0,0,0.4814859,0.0,0.95511341,127.24047,0.6858269,318.91486,-9.2932749
155.4369,26.951504,9.3646231,0.0,0,0.3386859,0.0,0.97987342,128.71925,0.5412029,316.56238,-9.2931423
155.4393,25.1803,9.4504623,0.0,0,0.20015615,0.0,0.994322,118.78384,0.42097026,314.20993,-9.2942924
155.4417,24.035776,9.4788904,0.0,0,0.06436415,0.0,0.99804986,112.92196,0.37650895,311.85745,-9.2970572
155.4441,22.848005,9.4822559,0.0,0,-0.069660425,0.0,0.99945831,107.148,0.34651187,313.82562,-9.2974977
155.4465,22.486063,9.4797564,0.0,0,-0.20209241,0.0,1.0001785,105.3289,0.31174058,316.1441,-9.2979832
155.4489,22.569025,9.4861269,0.0,0,-0.33452442,0.0,1.0019112,105.4905,0.25715467,318.46255,-9.2994289
155.4513,22.700823,9.4925919,0.0,0,-0.46695644,0.0,1.0022148,106.08623,0.19514753,320.78104,-9.2988844
155.4537,22.656567,9.50562,0.0,0,-0.59938842,0.0,1.0030282,105.83814,0.13137333,323.57828,-9.2988272
155.4561,22.528467,9.5150204,0.0,0,-0.7318204,0.0,1.0048344,105.0206,0.076727897,326.5351,-9.2990999
155.4585,22.3393,9.5138273,0.0,0,-0.86425239,0.0,1.0064086,103.98248,0.023866868,329.49191,-9.299408
155.4609,22.071199,9.5147924,0.0,0,-0.99668443,0.0,1.0073935,102.64213,-0.014258117,332.44873,-9.2999353
155.4633,21.683407,9.5193396,0.0,0,-1.0343364,329.67371,1.0071738,100.85394,-0.038503338,334.99579,-9.2989273
155.4657,21.115915,9.5228949,0.0,0,-0.5758779,330.0,1.0065806,98.317329,-0.04735278,337.23999,-9.299387
155.4681,20.512733,9.5243711,0.0,0,-0.11739158,330.0,1.0069443,95.487968,-0.047543284,339.48419,-9.2995682
155.4705,19.989351,9.5204649,0.0,0,0.34109476,330.0,1.0074825,92.961769,-0.038541056,341.72836,-9.3003387
155.4729,19.595222,9.5161142,0.0,0,0.79958111,330.0,1.0076056,91.108658,-0.034436364,343.64832,-9.3010836
155.4753,19.260231,9.5204964,0.0,0,1.2580678,330.0,1.0075945,89.568626,-0.033476576,345.08188,-9.3010979
155.4777,18.276478,9.5259829,0.0,0,1.716554,330.0,1.0071918,85.089905,-0.0060094921,346.51547,-9.3014431
155.4801,16.398504,9.5265121,0.0,0,2.1750405,330.0,1.0068535,76.440842,0.073245667,347.94904,-9.3026085
155.4825,12.596856,9.5067978,0.0,0,2.6335266,330.0,1.0046037,59.082954,0.23715894,349.26941,-9.3068695
155.4849,1.7136279,9.4571524,0.0,0,3.0920129,330.0,0.99738538,10.407859,0.48935845,350.1998,-9.3123636
155.4873,-0.47036105,9.2475529,0.0,0,3.5504992,330.0,0.95961374,-2.4902678,1.0586308,351.13019,-9.3175602
155.4897,0.28875628,9.0844889,0.0,0,4.0089855,330.0,0.93023831,1.3869096,1.8726336,352.06058,-9.3167992
155.4921,-0.082951732,9.0108862,0.0,0,4.4674721,330.0,0.91729146,-0.37896371,2.6965733,352.9931,-9.3180103
155.4945,-0.011735744,8.9677448,0.0,0,4.9259591,330.0,0.91086239,0.012096241,3.3352189,353.96579,-9.3160725
155.4969,-0.089988887,8.9759789,0.0,0,5.3844447,330.0,0.91309434,-0.49588621,3.7981024,354.93848,-9.3161077
155.4993,0.063350804,9.0091352,0.0,0,5.8429317,330.0,0.91824824,0.29707804,4.2226105,355.91116,-9.3144369
155.5017,-0.088210367,9.0839453,0.0,0,6.3014183,330.0,0.92961216,-0.43123215,4.6393652,356.88385,-9.3119783
155.5041,-0.012906842,9.1866159,0.0,0,6.7599044,330.0,0.94625461,-0.080965281,5.0581164,357.18326,-9.3132935
155.5065,-0.046439134,9.3127441,0.0,0,7.2183909,330.0,0.96904624,-0.16459802,5.4968209,357.38651,-9.3120031
155.5089,-0.17039779,9.4539433,0.0,0,7.676877,330.0,0.99557942,-0.80061275,5.9526711,357.58975,-9.3113594
155.5113,0.13938871,9.4292164,0.0,0,8.1353626,330.0,0.99182743,0.57943743,6.4362917,357.793,-9.3103676
155.5137,0.12473308,9.4520464,0.0,0,8.5938492,330.0,0.99381423,0.50006425,6.9240456,357.99115,-9.310173
155.5161,-0.21743865,9.4864492,0.0,0,9.0523357,330.0,1.0000321,-1.01054,7.4025383,358.18713,-9.3089943
155.5185,0.0051054386,9.4693356,0.0,0,9.5108232,330.0,0.99770123,-0.041761767,7.8813858,358.38312,-9.310215
155.5209,-0.067258038,9.4708052,0.0,0,9.9693089,330.0,0.99876362,-0.2526713,8.3587379,358.57913,-9.3083963
155.5233,-0.083038464,9.4645882,0.0,0,10.427795,330.0,0.99808186,-0.42814812,8.8234224,358.142,-9.3082218
155.5257,0.016007297,9.469491,0.0,0,10.886282,330.0,0.99753439,0.021148881,9.3077097,357.13208,-9.3079214
155.5281,-0.096471347,9.4751701,0.0,0,11.344769,330.0,0.997486,-0.37350041,9.7770643,356.12216,-9.3082361
155.5305,-0.1332415,9.4754696,0.0,0,11.803254,330.0,0.99821478,-0.65137255,10.244017,355.11224,-9.3075294
155.5329,0.063034967,9.4693327,0.0,0,12.261742,330.0,0.99851644,0.23288012,10.718304,353.98062,-9.3081446
155.5353,-0.12878984,9.4630985,0.0,0,12.720228,330.0,0.9977001,-0.54586899,11.186631,352.62292,-9.3063784
155.5377,-0.0039191819,9.4625282,0.0,0,13.178715,330.0,0.99644107,-0.051090244,11.643613,351.26526,-9.3066273
155.5401,-0.068348132,9.4664249,0.0,0,13.6372,330.0,0.99618638,-0.28367138,12.100358,349.90756,-9.3071823
155.5425,0.0065254192,9.4691372,0.0,0,14.095686,330.0,0.99722582,-0.047117442,12.561753,348.87784,-9.3072252
155.5449,-0.096829414,9.4655848,0.0,0,14.554173,330.0,0.99778199,-0.46067771,13.033332,349.39417,-9.3070021
155.5473,0.076847367,9.4627495,0.0,0,15.012659,330.0,0.99775314,0.37015074,13.522295,349.91046,-9.305377
155.5497,-0.18266201,9.4665766,0.0,0,15.471146,330.0,0.99748987,-0.77504492,13.996335,350.42679,-9.3065367
155.5521,-0.070131831,9.4712095,0.0,0,15.929632,330.0,0.99707562,-0.40324932,14.468877,350.94312,-9.3062077
155.5545,0.043792915,9.473299,0.0,0,16.388119,330.0,0.99742156,0.2394056,14.92473,351.16116,-9.3059988
155.5569,-0.11623114,9.4687595,0.0,0,16.846605,330.0,0.99810886,-0.45153618,15.372454,351.37921,-9.3055792
155.5593,-0.052741766,9.461463,0.0,0,17.305092,330.0,0.99764085,-0.25401205,15.828897,351.59726,-9.3058443
155.5617,0.0042669028,9.4626226,0.0,0,17.763578,330.0,0.99683475,0.032020997,16.29888,351.81534,-9.3051672
155.5641,-0.078304999,9.4663486,0.0,0,18.0,330.0,0.99623364,-0.30312741,16.75745,351.45154,-9.3056173
155.5665,-0.1109741,9.4713621,0.0,0,18.0,330.0,0.99709457,-0.5366953,17.205786,350.96432,-9.3041925
155.5689,0.060611192,9.4657364,0.0,0,18.0,330.0,0.99739844,0.42191303,17.628927,350.47711,-9.3046131
155.5713,-0.16212985,9.4660091,0.0,0,18.0,330.0,0.99828666,-0.78440869,17.990734,349.98993,-9.3067007
155.5737,-0.011201356,9.4641075,0.0,0,18.0,330.0,0.99727499,-0.062113624,18.274179,349.63034,-9.3093128
155.5761,-0.070295952,9.4754753,0.0,0,18.0,330.0,0.99785721,-0.33526948,18.455719,349.33951,-9.3128185
155.5785,0.053655479,9.4846878,0.0,0,18.0,330.0,0.9991743,0.28032005,18.511242,349.04868,-9.3173532
155.5809,-0.073053353,9.4894218,0.0,0,18.0,330.0,1.0014057,-0.26275939,18.443501,348.75784,-9.3252726
155.5833,-0.066000111,9.4938145,0.0,0,18.0,330.0,1.0034252,-0.30156696,18.316927,348.05203,-9.3366194
155.5857,-0.096732661,9.5064669,0.0,0,18.0,330.0,1.0051838,-0.4456566,18.187544,346.88754,-9.350873
155.5881,0.065669686,9.5235777,0.0,0,18.0,330.0,1.0069079,0.21800056,18.100988,345.72305,-9.3666954
155.5905,0.035349879,9.5459309,0.0,0,18.0,330.0,1.0107216,0.24783425,18.050272,344.55856,-9.3849592
155.5929,-0.088976867,9.5638618,0.0,0,18.0,330.0,1.0149987,-0.39033368,18.042423,342.94559,-9.403965
155.5953,-0.16478698,9.581377,0.0,0,18.0,330.0,1.0193419,-0.75215536,18.049891,340.28619,-9.423481
155.5977,-0.022769747,9.5993042,0.0,0,18.0,330.0,1.0220964,-0.1689267,18.07646,337.6268,-9.4434452
155.6001,0.054852329,9.6172171,0.0,0,18.0,330.0,1.0241995,0.24101874,18.09457,334.96741,-9.4599323
155.6025,-0.00024892128,9.6398087,0.24044809,0,18.0,330.0,1.0274907,0.072621033,18.116541,332.52106,-9.4793892
155.6049,-0.16326994,9.6586342,2.1640422,0,18.0,330.0,1.0321161,-0.67629653,18.136629,331.56589,-9.4963522
155.6073,-0.10092698,9.6689615,4.0876365,0,18.0,330.0,1.0356151,-0.49852517,18.144821,330.61075,-9.5140285
155.6097,0.058564931,9.6816387,6.0112305,0,18.0,330.0,1.0378724,0.22447272,18.145041,329.65558,-9.5310717
155.6121,0.03302915,9.7032804,7.9348245,0,18.0,330.0,1.040609,0.16642405,18.143681,328.70044,-9.5475693
155.6145,-0.068174824,9.7237806,8.0310059,0,18.0,330.0,1.0436678,-0.26276293,18.140886,329.13116,-9.5644312
155.6169,-0.14550334,9.7414474,8.0310059,0,18.0,330.0,1.0478601,-0.65536982,18.139832,329.63486,-9.582366
155.6193,-0.025649445,9.7533655,8.0310059,0,18.0,330.0,1.0514244,-0.20453171,18.136595,330.13855,-9.5990849
155.6217,0.078427359,9.766242,8.0310059,0,18.0,330.0,1.0541044,0.33827069,18.13369,330.64221,-9.6137924
155.6241,-0.00042817366,9.7882414,6.5402217,0,18.0,330.0,1.0569247,0.060040638,18.133739,330.67636,-9.6310883
155.6265,-0.14146301,9.8140249,4.6166277,0,18.0,330.0,1.0605268,-0.59350854,18.12396,330.57416,-9.649519
155.6289,-0.10466128,9.8307085,2.6930332,0,18.0,330.0,1.0645745,-0.49910763,18.126514,330.47195,-9.668623
155.6313,0.0565046,9.8428354,0.7694391,0,18.0,330.0,1.0685129,0.22068186,18.11902,330.36975,-9.6860075
155.6337,0.050471783,9.8530416,0.0,0,18.0,330.0,1.0709735,0.2147689,18.115391,330.09674,-9.7029982
155.6361,-0.06991227,9.8741417,0.0,0,18.0,330.0,1.0736022,-0.22770508,18.115265,329.70984,-9.7200499
155.6385,-0.1583591,9.8973875,0.0,0,18.0,330.0,1.0772588,-0.68795025,18.116385,329.32297,-9.7387695
155.6409,-0.034961093,9.9163036,0.0,0,18.0,330.0,1.0812136,-0.20766126,18.113567,328.93607,-9.7577057
155.6433,0.067629419,9.9283524,2.3776467,0,18.0,330.0,1.0849301,0.300488,18.110723,328.45303,-9.7744637
155.6457,0.0050599556,9.9414501,7.9721217,0,18.0,330.0,1.0880201,0.074192002,18.108685,327.83984,-9.7906713
155.6481,-0.14358917,9.960309,13.566597,0,18.0,330.0,1.0908643,-0.60029459,18.106976,327.22668,-9.8090668
155.6505,-0.099543929,9.9830589,19.161072,0,18.0,330.0,1.0939548,-0.48141569,18.105534,326.61349,-9.8269501
155.6529,0.041004632,10.001266,23.356934,0,18.0,330.0,1.097911,0.12291325,18.104256,325.72781,-9.8447418
155.6553,0.051316831,10.017401,23.356934,0,18.0,330.0,1.10264,0.22235185,18.101015,324.02463,-9.860569
155.6577,-0.070387006,10.028114,23.356934,0,18.0,330.0,1.1057116,-0.23334476,18.101892,322.32144,-9.8764696
155.6601,-0.16584659,10.047736,23.356934,0,18.0,330.0,1.108536,-0.68827742,18.100731,320.61826,-9.8947678
155.6625,-0.040458728,10.065933,23.857035,0,18.0,330.0,1.1107448,-0.25824183,18.099844,318.9166,-9.9133654
155.6649,0.086716354,10.085662,30.525145,0,18.0,330.0,1.1148735,0.3706204,18.099934,317.23386,-9.929925
155.6673,0.00043940521,10.100621,37.193253,0,18.0,330.0,1.1191958,0.05584411,18.098131,315.55115,-9.9465704
155.6697,-0.14364378,10.115339,43.861362,0,18.0,330.0,1.1232603,-0.57765704,18.098885,313.86841,-9.9651194
155.6721,-0.11688488,10.134254,50.529469,0,18.0,330.0,1.126443,-0.514534,18.095631,312.1857,-9.9830761
155.6745,0.031259749,10.154681,51.196289,0,18.0,330.0,1.1288668,0.098074585,18.09819,311.3714,-9.9997625
155.6769,0.054113269,10.177662,51.196289,0,18.0,330.0,1.1330494,0.24212433,18.093237,310.65359,-10.017133
155.6793,-0.063732229,10.19253,51.196289,0,18.0,330.0,1.1379074,-0.2036159,18.094858,309.93579,-10.034431
155.6817,-0.1622995,10.203578,51.196289,0,18.0,330.0,1.1415511,-0.66722721,18.094629,309.21796,-10.053029
155.6841,-0.042604078,10.217506,52.052895,0,18.0,330.0,1.1440617,-0.25903326,18.09063,308.61697,-10.070432
155.6865,0.086002618,10.237237,53.234417,0,18.0,330.0,1.1464775,0.3369258,18.091986,308.0603,-10.086886
155.6889,0.010474317,10.257649,54.415939,0,18.0,330.0,1.1501908,0.11474083,18.093996,307.5036,-10.10422
155.6913,-0.12472586,10.275803,55.597466,0,18.0,330.0,1.155205,-0.46662071,18.088644,306.94693,-10.122732
155.6937,-0.10430429,10.285535,56.12915,0,18.0,330.0,1.1588445,-0.45061633,18.088118,305.98553,-10.140141
155.6961,0.020323811,10.303018,56.12915,0,18.0,330.0,1.162184,0.028536851,18.088123,304.69302,-10.155871
155.6985,0.072895765,10.325192,56.12915,0,18.0,330.0,1.1649802,0.32514474,18.088844,303.40051,-10.173127
155.7009,-0.049391083,10.350962,56.12915,0,18.0,330.0,1.1694531,-0.13621145,18.083296,302.108,-10.190524
155.7033,-0.16222782,10.369613,56.761684,0,18.0,330.0,1.1748296,-0.62358904,18.087818,300.85922,-10.209484
155.7057,-0.028985225,10.374475,58.448448,0,18.0,330.0,1.1777542,-0.19859378,18.085514,299.68332,-10.227901
155.7081,0.082823515,10.387277,60.135212,0,18.0,330.0,1.1806438,0.31277642,18.085608,298.50742,-10.244846
155.7105,0.018914416,10.409438,61.821976,0,18.0,330.0,1.1835428,0.12669747,18.083862,297.33151,-10.261536
155.7129,-0.11788375,10.433251,63.171391,0,18.0,330.0,1.1876599,-0.43370366,18.084023,296.30402,-10.280495
155.7153,-0.10942829,10.45075,63.171391,0,18.0,330.0,1.1926502,-0.47018436,18.083952,295.87012,-10.297233
155.7177,0.029356755,10.462661,63.171391,0,18.0,330.0,1.1967427,0.032087304,18.080845,295.43619,-10.31537
155.7201,0.076555602,10.474952,63.171391,0,18.0,330.0,1.1998575,0.29517341,18.08301,295.00226,-10.332372
155.7225,-0.056306321,10.496762,63.183033,0,18.0,330.0,1.2028654,-0.13510494,18.082352,294.57111,-10.348709
155.7249,-0.17546353,10.521403,63.6488,0,18.0,330.0,1.2068385,-0.65155375,18.080187,294.2475,-10.365985
155.7273,-0.025041409,10.538802,64.114563,0,18.0,330.0,1.211651,-0.16349439,18.075907,293.92389,-10.383121
155.7297,0.075055443,10.547881,64.580338,0,18.0,330.0,1.2156041,0.26792112,18.080933,293.60028,-10.40089
155.7321,0.020478293,10.561563,65.046097,0,18.0,330.0,1.2192543,0.097561643,18.079594,293.2767,-10.419518
155.7345,-0.10909934,10.58136,65.115967,0,18.0,330.0,1.2222844,-0.35869461,18.076958,292.99686,-10.436789
155.7369,-0.13249536,10.601959,65.115967,0,18.0,330.0,1.2255392,-0.53186905,18.076742,292.72473,-10.453169
155.7393,0.02392026,10.618992,65.115967,0,18.0,330.0,1.2301209,0.02266412,18.078903,292.45261,-10.469107
155.7417,0.082132578,10.633748,65.115967,0,18.0,330.0,1.2347666,0.31214142,18.073471,292.18048,-10.486358
155.7441,-0.04761013,10.650059,65.290039,0,18.0,330.0,1.2393599,-0.10395143,18.075089,291.92822,-10.505259
155.7465,-0.15739472,10.668489,65.54792,0,18.0,330.0,1.2422751,-0.56878835,18.073618,291.68552,-10.523989
155.7489,-0.046185724,10.69018,65.805801,0,18.0,330.0,1.2455716,-0.21234477,18.075171,291.44281,-10.541364
155.7513,0.073512681,10.7127,66.06369,0,18.0,330.0,1.2507375,0.2381326,18.073517,291.2001,-10.558937
155.7537,0.031262938,10.72576,66.192627,0,18.0,330.0,1.256127,0.15492004,18.068832,290.89114,-10.576942
155.7561,-0.11071822,10.738664,66.192627,0,18.0,330.0,1.2601198,-0.33079755,18.073195,290.51593,-10.593402
155.7585,-0.13036275,10.75598,66.192627,0,18.0,330.0,1.262923,-0.5281018,18.069,290.14072,-10.611401
155.7609,0.024802521,10.773266,66.192627,0,18.0,330.0,1.2654053,0.041514155,18.066261,289.76547,-10.629339
155.7633,0.087775342,10.791315,66.323471,0,18.0,330.0,1.269749,0.33327883,18.066452,289.37823,-10.647295
155.7657,-0.048031997,10.807907,66.726089,0,18.0,330.0,1.275201,-0.10401809,18.069822,288.96606,-10.664202
155.7681,-0.16196431,10.822896,67.128708,0,18.0,330.0,1.2801799,-0.5897001,18.068855,288.55386,-10.681477
155.7705,-0.042753674,10.840521,67.531319,0,18.0,330.0,1.2833246,-0.214288,18.068287,288.14169,-10.697398
155.7729,0.074763373,10.863934,67.873535,0,18.0,330.0,1.2870792,0.25405294,18.070652,287.75473,-10.71445
155.7753,0.047639921,10.884032,67.873535,0,18.0,330.0,1.2911856,0.19433755,18.067785,287.51083,-10.731285
155.7777,-0.10737411,10.899256,67.873535,0,18.0,330.0,1.2969072,-0.32727152,18.067568,287.26697,-10.747679
155.7801,-0.1387732,10.907981,67.873535,0,18.0,330.0,1.301088,-0.51202071,18.069113,287.02307,-10.766507
155.7825,0.032693606,10.922113,67.873535,0,18.0,330.0,1.30335,0.066268623,18.067007,286.77917,-10.784161
155.7849,0.085037366,10.941635,68.130096,0,18.0,330.0,1.306187,0.30495718,18.066393,286.44159,-10.801535
155.7873,-0.030280415,10.966289,68.39325,0,18.0,330.0,1.3119675,-0.072799973,18.065168,286.10162,-10.81883
155.7897,-0.16357392,10.986904,68.656395,0,18.0,330.0,1.3185992,-0.52494049,18.064003,285.76163,-10.83689
155.7921,-0.045329068,10.9969,68.91954,0,18.0,330.0,1.3226407,-0.20780338,18.063528,285.42166,-10.852805
155.7945,0.070312247,11.008854,68.972168,0,18.0,330.0,1.3251125,0.19575012,18.058842,285.1763,-10.869638
155.7969,0.039624926,11.029323,68.972168,0,18.0,330.0,1.3281822,0.18031414,18.062317,284.95456,-10.887926
155.7993,-0.10626785,11.054431,68.972168,0,18.0,330.0,1.3332597,-0.29562527,18.0627,284.73285,-10.906231
155.8017,-0.15147905,11.073503,68.972168,0,18.0,330.0,1.3395759,-0.52021933,18.058794,284.51114,-10.922909
155.8041,0.02798075,11.081294,69.084007,0,18.0,330.0,1.3439177,0.031030787,18.058384,284.3356,-10.940408
155.8065,0.089275084,11.092684,69.262939,0,18.0,330.0,1.3465368,0.29643244,18.057961,284.18777,-10.957045
155.8089,-0.036386453,11.113235,69.441887,0,18.0,330.0,1.3497577,-0.049606744,18.0602,284.03995,-10.974453
155.8113,-0.13890158,11.136742,69.620819,0,18.0,330.0,1.3548812,-0.41802013,18.059477,283.89212,-10.993606
155.8137,-0.057680447,11.153878,69.719238,0,18.0,330.0,1.360369,-0.26761454,18.054823,283.71771,-11.011617
155.8161,0.064277917,11.164482,69.719238,0,18.0,330.0,1.3648736,0.1979498,18.051943,283.51074,-11.028657
155.8185,0.059477195,11.180356,69.719238,0,18.0,330.0,1.3695292,0.19830056,18.052526,283.3038,-11.045206
155.8209,-0.104325,11.202185,69.719238,0,18.0,330.0,1.3731471,-0.28908327,18.054491,283.09686,-11.06277
155.8233,-0.16559802,11.224916,69.767006,0,18.0,330.0,1.3776222,-0.55854011,18.051126,282.88181,-11.080917
155.8257,0.025111545,11.245688,69.940674,0,18.0,330.0,1.3838069,0.048236854,18.04854,282.64529,-11.097152
155.8281,0.090175502,11.254522,70.114349,0,18.0,330.0,1.3888779,0.27966565,18.052574,282.40878,-11.114618
155.8305,-0.027157856,11.272217,70.288033,0,18.0,330.0,1.3942153,-0.028407494,18.049576,282.17227,-11.1326
155.8329,-0.14348902,11.290858,70.444336,0,18.0,330.0,1.3969878,-0.44528353,18.054136,281.94241,-11.150557
155.8353,-0.07054048,11.308538,70.444336,0,18.0,330.0,1.4003751,-0.25361782,18.050974,281.77243,-11.167577
155.8377,0.059517093,11.323586,70.444336,0,18.0,330.0,1.4049379,0.15311918,18.05229,281.60242,-11.184272
155.8401,0.077793166,11.340092,70.444336,0,18.0,330.0,1.4112729,0.25120479,18.054445,281.43243,-11.20081
155.8425,-0.10204235,11.356465,70.444336,0,18.0,330.0,1.4170517,-0.27648649,18.051775,281.26245,-11.219983
155.8449,-0.15348428,11.374197,70.597687,0,18.0,330.0,1.4202701,-0.50675887,18.052374,281.06512,-11.238826
155.8473,0.028517837,11.394419,70.763466,0,18.0,330.0,1.4237313,0.043768477,18.052275,280.86557,-11.254688
155.8497,0.089188986,11.414968,70.929245,0,18.0,330.0,1.4295753,0.25939697,18.050673,280.66602,-11.271834
155.8521,-0.01258452,11.429874,71.095032,0,18.0,330.0,1.4358482,-0.0035318236,18.050596,280.46646,-11.289269
155.8545,-0.13355274,11.440033,71.136475,0,18.0,330.0,1.4406124,-0.38465294,18.052008,280.22256,-11.306499
155.8569,-0.094881497,11.458546,71.136475,0,18.0,330.0,1.4441117,-0.32763863,18.049448,279.9639,-11.32446
155.8593,0.066144325,11.479909,71.136475,0,18.0,330.0,1.4480548,0.17853898,18.050251,279.70523,-11.340925
155.8617,0.073486589,11.500109,71.136475,0,18.0,330.0,1.4535279,0.24100451,18.046877,279.44653,-11.358974
156.4628,-0.034661084,11.617147,4.5574015e-07,0,18.0,2.199936e-06,1.4893819,-0.10288568,18.00692,180.90315,-11.483145
157.6628,-0.039138142,11.61716,1.9404238e-23,0,18.0,9.510283e-23,1.489188,-0.11121608,18.000771,73.487411,-11.482664
158.8628,-0.037123624,11.6167,8.2600799e-40,0,18.0,4.1112794e-39,1.4892682,-0.10515495,18.000166,39.137238,-11.483026
160.0628,-0.044757426,11.617744,7.9874012e-44,0,18.0,1.4012985e-45,1.4895024,-0.13016874,17.999262,29.515663,-11.483219
161.2628,-0.047837585,11.617377,7.9874012e-44,0,18.0,1.4012985e-45,1.489547,-0.13348165,17.999172,26.803612,-11.482942
162.4628,-0.040338669,11.617589,7.9874012e-44,0,18.0,1.4012985e-45,1.4894685,-0.11603086,17.999645,26.059366,-11.482718
163.6628,-0.044461668,11.617775,7.9874012e-44,0,18.0,1.4012985e-45,1.4893706,-0.12668283,17.998796,25.827093,-11.482403
164.8628,-0.043078292,11.618134,7.9874012e-44,0,18.0,1.4012985e-45,1.4897146,-0.12164392,17.999521,25.73316,-11.482713
166.0628,-0.042936444,11.618041,7.9874012e-44,0,18.0,1.4012985e-45,1.4895347,-0.12452965,17.999313,25.69887,-11.483027
167.2628,-0.043337349,11.619272,7.9874012e-44,0,18.0,1.4012985e-45,1.4900489,-0.12362731,18.000099,25.676655,-11.483441
168.4628,-0.039604202,11.619675,7.9874012e-44,0,18.0,1.4012985e-45,1.4899431,-0.11264259,18.00061,25.545938,-11.483871
169.6628,-0.048079778,11.619245,7.9874012e-44,0,18.0,1.4012985e-45,1.4899757,-0.13635443,17.999865,25.477173,-11.483319
170.8628,-0.048404563,11.619597,7.9874012e-44,0,18.0,1.4012985e-45,1.4900914,-0.13620517,18.000849,25.482206,-11.483327
172.0628,-0.039522868,11.620377,7.9874012e-44,0,18.0,1.4012985e-45,1.4903375,-0.1147154,18.000143,25.58934,-11.483475
173.2628,-0.048617724,11.620367,7.9874012e-44,0,18.0,1.4012985e-45,1.4902712,-0.14154635,18.000624,25.465015,-11.483249
174.4628,-0.049090199,11.620721,7.9874012e-44,0,18.0,1.4012985e-45,1.4902523,-0.13901842,18.000298,25.293415,-11.483292
175.6628,-0.04886632,11.621303,7.9874012e-44,0,18.0,1.4012985e-45,1.4906017,-0.14147463,18.00013,25.353819,-11.482647
176.8628,-0.052070387,11.620336,7.9874012e-44,0,18.0,1.4012985e-45,1.4902546,-0.14987177,17.999163,25.329666,-11.482687
178.0628,-0.04887408,11.621304,7.9874012e-44,0,18.0,1.4012985e-45,1.4906378,-0.13984542,17.999695,25.228657,-11.483013
179.2628,-0.047449209,11.621303,7.9874012e-44,0,18.0,1.4012985e-45,1.4904075,-0.14038165,17.999233,25.27706,-11.482909
180.4628,-0.052833181,11.622152,7.9874012e-44,0,18.0,1.4012985e-45,1.4907742,-0.15184732,17.999334,25.142591,-11.483284
181.6628,-0.041524455,11.622269,7.9874012e-44,0,18.0,1.4012985e-45,1.4908835,-0.11830753,18.000444,25.153484,-11.483682
182.8628,-0.046462618,11.622842,7.9874012e-44,0,18.0,1.4012985e-45,1.4910371,-0.13376863,18.000437,25.173374,-11.483509
184.0628,-0.04836867,11.623146,7.9874012e-44,0,18.0,1.4012985e-45,1.4911342,-0.13430123,17.999855,25.242685,-11.483611
185.2628,-0.047427602,11.623592,7.9874012e-44,0,18.0,1.4012985e-45,1.4911081,-0.13595539,18.000208,25.084875,-11.483479
186.4628,-0.050087214,11.623528,7.9874012e-44,0,18.0,1.4012985e-45,1.4912906,-0.14484303,17.999979,25.069914,-11.483447
187.6628,-0.048821904,11.623777,7.9874012e-44,0,18.0,1.4012985e-45,1.4912598,-0.13683611,18.000336,25.123426,-11.483641
188.8628,-0.04558485,11.624428,7.9874012e-44,0,18.0,1.4012985e-45,1.4916034,-0.13346209,18.000359,24.996475,-11.483536
190.0628,-0.050963752,11.624473,7.9874012e-44,0,18.0,1.4012985e-45,1.4914262,-0.1477869,17.999859,24.946123,-11.483764
191.2628,-0.044736087,11.625392,7.9874012e-44,0,18.0,1.4012985e-45,1.4917352,-0.12757601,17.999208,24.884312,-11.483757
192.4628,-0.049060632,11.624505,7.9874012e-44,0,18.0,1.4012985e-45,1.4915715,-0.14336401,18.000069,25.078842,-11.48322
193.6628,-0.059056908,11.625447,7.9874012e-44,0,18.0,1.4012985e-45,1.4918163,-0.16903281,17.999666,24.942503,-11.483308
194.8628,-0.056513883,11.624864,7.9874012e-44,0,18.0,1.4012985e-45,1.4916353,-0.15984842,17.999622,24.854132,-11.483022
196.0628,-0.057391863,11.626287,7.9874012e-44,0,18.0,1.4012985e-45,1.4919118,-0.16284682,18.000208,24.961897,-11.483068
197.2628,-0.059671801,11.625719,7.9874012e-44,0,18.0,1.4012985e-45,1.491966,-0.16858885,17.999836,24.988199,-11.48301
198.4628,-0.050955191,11.626117,7.9874012e-44,0,18.0,1.4012985e-45,1.4919617,-0.1457656,18.000261,24.912092,-11.482946
199.6628,-0.050461665,11.626494,7.9874012e-44,0,18.0,1.4012985e-45,1.492226,-0.14510874,17.999199,24.89967,-11.482929
200.8628,-0.049097661,11.626822,7.9874012e-44,0,18.0,1.4012985e-45,1.492087,-0.13732325,18.000931,25.042767,-11.483215
202.0628,-0.048009336,11.626727,7.9874012e-44,0,18.0,1.4012985e-45,1.492115,-0.13957815,18.000462,24.931376,-11.482761
203.2628,-0.058724802,11.627042,7.9874012e-44,0,18.0,1.4012985e-45,1.4922724,-0.16985297,18.000027,24.94718,-11.482864
204.4628,-0.052779041,11.627573,7.9874012e-44,0,18.0,1.4012985e-45,1.4924546,-0.14891817,18.000471,24.770668,-11.482845
205.6628,-0.057721838,11.627698,7.9874012e-44,0,18.0,1.4012985e-45,1.4924591,-0.16712774,17.999907,24.812851,-11.482667
206.8628,-0.058969069,11.627889,7.9874012e-44,0,18.0,1.4012985e-45,1.4924083,-0.17031823,17.999516,24.741779,-11.482537
208.0628,-0.055601228,11.627983,7.9874012e-44,0,18.0,1.4012985e-45,1.4926345,-0.15777558,17.999533,24.823395,-11.482827
209.2628,-0.053639613,11.628498,7.9874012e-44,0,18.0,1.4012985e-45,1.492659,-0.15565395,18.000622,24.876284,-11.48262
210.4628,-0.063535191,11.628842,7.9874012e-44,0,18.0,1.4012985e-45,1.4929323,-0.17902194,17.999893,24.90308,-11.482276
211.6628,-0.052340847,11.629535,7.9874012e-44,0,18.0,1.4012985e-45,1.4929159,-0.14981273,18.001192,24.897705,-11.482772
212.8628,-0.062559575,11.629302,7.9874012e-44,0,18.0,1.4012985e-45,1.492907,-0.18194166,17.999983,24.881361,-11.482207
214.0628,-0.058379032,11.62951,7.9874012e-44,0,18.0,1.4012985e-45,1.4930488,-0.16427493,18.001188,24.733343,-11.482516
215.2628,-0.052209154,11.629007,7.9874012e-44,0,18.0,1.4012985e-45,1.4928814,-0.15184228,17.999918,24.79417,-11.482759
215.8628,-0.055392321,11.629786,7.9874012e-44,0,18.0,1.4012985e-45,1.4931277,-0.15631664,17.999821,24.72961,-11.482851