File: examples/dan-msc-case-studies/CS3/data/01 raw data/baron_test_118.csv
Time(sec),Force(kN),Jaw(mm),PowAngle(deg),Power(W),Pram,PTemp,Strain,Stress(MPa),Stroke(mm),TC1(C),wedge(mm)
0.0,0.95365858,0.53053254,0.0,0,11.076097,0.001556817,0.035983797,11.702724,11.075787,23.314262,-9.1343536
1.2,0.89388496,0.0008494489,0.0,0,11.076097,3.5159132,5.9256814e-05,11.381591,11.076797,23.261324,-9.4945869
2.4,0.87069398,0.00070934091,0.0,0,11.076097,7.1159134,6.3412954e-05,11.079392,11.076115,23.239361,-9.4917564
3.6,0.84348446,0.00073803705,0.0,0,11.076097,10.715915,2.5310983e-05,10.73864,11.076621,23.265112,-9.4906263
4.8,0.83138657,0.00064767501,0.0,0,11.076097,14.315915,5.3114753e-05,10.58492,11.076303,23.234207,-9.4881029
6.0,0.80947638,0.00067897129,0.0,0,11.076097,17.915913,6.537755e-05,10.307495,11.076686,23.25526,-9.4860144
7.2,0.79202288,0.00053254009,0.0,0,11.076097,21.515913,1.0807045e-05,10.084478,11.076459,23.218977,-9.4834709
8.4,0.78695786,0.00097209128,13.316409,0,11.076097,25.115913,7.9911617e-05,10.006026,11.076553,23.289984,-9.4808378
9.6,0.78309995,0.0010107957,29.776098,0,11.076097,28.715914,8.1255668e-05,9.9765587,11.076124,23.902838,-9.479435
10.8,0.80030215,-0.0011918397,35.442451,0,11.076097,32.315914,-9.379199e-05,10.187308,11.07567,26.516581,-9.4771442
12.0,0.81114244,-0.0049987016,37.835262,0,11.076097,35.915924,-0.00032413279,10.323298,11.076492,30.253401,-9.4756012
13.2,0.82132471,-0.0081115318,39.840214,0,11.076097,39.515923,-0.00052802294,10.461343,11.076566,33.993992,-9.4734735
14.4,0.82009244,-0.012382198,41.370193,0,11.076097,43.115921,-0.00083894026,10.457012,11.076234,37.745991,-9.4712667
15.6,0.8396247,-0.015883338,42.395813,0,11.076097,46.715923,-0.0010585999,10.698366,11.076009,41.736382,-9.4691343
16.8,0.84940809,-0.020883933,42.978374,0,11.076097,50.315922,-0.0013928482,10.810172,11.076108,46.039455,-9.4670773
18.0,0.85770935,-0.024850594,42.978512,0,11.076097,53.915916,-0.0016559325,10.958686,11.075838,50.332096,-9.4643373
19.2,0.86968011,-0.029590441,42.978512,0,11.076097,57.515911,-0.0019747347,11.088495,11.076004,54.628323,-9.4621897
20.4,0.87260699,-0.033051349,42.815044,0,11.076097,61.11591,-0.0022011776,11.136661,11.076143,58.840961,-9.4610109
21.6,0.88509572,-0.038222007,42.65868,0,11.076097,64.715919,-0.0025451102,11.287535,11.075294,62.951298,-9.4584455
22.8,0.88737476,-0.040156908,42.396244,0,11.076097,68.31591,-0.0026932224,11.329763,11.075405,66.999153,-9.4563293
24.0,0.89562047,-0.044006608,42.396244,0,11.076097,71.915916,-0.0029308768,11.429243,11.076266,70.896355,-9.4539633
25.2,0.88971794,-0.047770556,41.851696,0,11.076097,75.515907,-0.0031577954,11.368736,11.075298,74.805405,-9.4520597
26.4,0.90729821,-0.049758211,41.994602,0,11.076097,79.115921,-0.0033393526,11.58949,11.076024,78.500633,-9.450367
27.6,0.90081477,-0.05443779,42.395943,0,11.076097,82.715919,-0.0036141733,11.49781,11.076337,82.133171,-9.4482718
28.8,0.91115195,-0.056874,42.396149,0,11.076097,86.315926,-0.0037594119,11.653173,11.076958,85.771301,-9.4454737
30.0,0.91331375,-0.060989022,42.396236,0,11.076097,89.915916,-0.0040717646,11.673354,11.07738,89.435112,-9.44349
31.2,0.91668236,-0.063506782,42.474079,0,11.076097,93.515923,-0.0042122826,11.71996,11.074743,93.033096,-9.4415617
32.4,0.92207688,-0.066442929,42.977657,0,11.076097,97.115921,-0.0044101737,11.797678,11.075976,96.472404,-9.4397516
33.6,0.91795284,-0.07032086,43.301514,0,11.076097,100.71593,-0.0046941573,11.748708,11.074919,100.00643,-9.4375181
34.8,0.93003947,-0.073090695,43.503059,0,11.076097,104.31593,-0.0048555806,11.883528,11.075549,103.63699,-9.4351921
36.0,0.93229419,-0.07662686,43.528522,0,11.076097,107.91592,-0.0050983317,11.926182,11.076928,107.31087,-9.432992
37.2,0.93034607,-0.080227487,43.939129,0,11.076097,111.51591,-0.0053368513,11.90855,11.077348,110.78529,-9.4310217
38.4,0.93585891,-0.084439524,44.077377,0,11.076097,115.11592,-0.0056326729,11.977156,11.076297,114.42713,-9.4292107
39.6,0.93594927,-0.087008893,44.306736,0,11.076097,118.71593,-0.0057768291,11.999401,11.075341,117.99953,-9.4272099
40.8,0.93856901,-0.08958514,44.604488,0,11.076097,122.31591,-0.005942706,12.024605,11.075205,121.66947,-9.4248123
42.0,0.94173098,-0.094422199,44.604488,0,11.076097,125.91591,-0.0062966277,12.055796,11.076546,125.21924,-9.4224586
43.2,0.94144118,-0.097441956,45.12085,0,11.076097,129.51601,-0.0064690085,12.071227,11.076036,128.76492,-9.4206057
44.4,0.94950277,-0.10331009,45.12085,0,11.076097,133.11592,-0.0068396586,12.167812,11.076436,132.39589,-9.4189053
45.6,0.93123519,-0.10513555,45.352261,0,11.076097,136.7159,-0.0070150658,11.929914,11.07524,136.01637,-9.4165306
46.8,0.95303351,-0.10749053,45.615189,0,11.076097,140.31589,-0.007132594,12.243324,11.07585,139.63258,-9.4144125
48.0,0.94248676,-0.11310214,45.788494,0,11.076097,143.91589,-0.0074904119,12.083376,11.075646,143.1454,-9.4123793
49.2,0.94688898,-0.11572982,46.108326,0,11.076097,147.5159,-0.0077078734,12.160249,11.075733,146.76051,-9.4105091
50.4,0.95763284,-0.12193625,46.251129,0,11.076097,151.11589,-0.0080948574,12.288182,11.076859,150.28008,-9.4087105
51.6,0.94192517,-0.12457843,46.582027,0,11.076097,154.7159,-0.0082651107,12.095838,11.076274,153.84828,-9.4065962
52.8,0.95587808,-0.12698132,46.749138,0,11.076097,158.3159,-0.0084309615,12.281074,11.075113,157.46692,-9.4046116
54.0,0.94206446,-0.13295561,47.054295,0,11.076097,161.91591,-0.0088239051,12.081612,11.077699,161.09401,-9.4019213
55.2,0.95430434,-0.13637844,47.316162,0,11.076097,165.5159,-0.0090531176,12.265426,11.076547,164.60345,-9.400136
56.4,0.95446306,-0.13881683,47.385448,0,11.076097,169.11592,-0.0091933766,12.267115,11.075386,168.32822,-9.3986502
57.6,0.95599264,-0.14352675,47.504883,0,11.076097,172.71591,-0.0095430873,12.282065,11.076348,172.02577,-9.3964777
58.8,0.95358682,-0.14819881,47.504883,0,11.076097,176.31593,-0.0098137353,12.249294,11.075244,175.66574,-9.3943682
60.0,0.9566226,-0.15066865,47.504883,0,11.076097,179.91592,-0.0099646822,12.317611,11.075626,179.42273,-9.3916788
61.2,0.94799256,-0.1553213,47.518112,0,11.076097,183.51591,-0.010327864,12.183285,11.076173,183.00262,-9.3898563
62.4,0.95493925,-0.15965018,47.786201,0,11.076097,187.11592,-0.010581176,12.291299,11.076454,186.57932,-9.3883829
63.6,0.95652902,-0.16218416,47.955318,0,11.076097,190.71591,-0.010755301,12.296595,11.076592,190.13167,-9.3858309
64.8,0.9584828,-0.16688001,48.371586,0,11.076097,194.31592,-0.011073719,12.335658,11.076318,193.62491,-9.3837376
66.0,0.96465576,-0.17123531,48.383793,0,11.076097,197.91592,-0.011369013,12.421388,11.075987,197.21869,-9.3815746
67.2,0.96855694,-0.17360419,48.734966,0,11.076097,201.51591,-0.011507233,12.465764,11.075564,200.77496,-9.3794632
68.4,0.96694285,-0.17971578,48.808121,0,11.076097,205.11592,-0.011876,12.473614,11.075646,204.51683,-9.3778849
69.6,0.96062666,-0.18306899,48.789646,0,11.076097,208.71593,-0.012151189,12.368467,11.076914,208.15097,-9.3758469
70.8,0.96730554,-0.18577199,48.812252,0,11.076097,212.31592,-0.012299386,12.465505,11.076416,211.84465,-9.3736229
72.0,0.96863478,-0.19240704,48.98909,0,11.076097,215.91591,-0.012725974,12.491495,11.076332,215.35014,-9.3708601
73.2,0.9611963,-0.19428283,49.229733,0,11.076097,219.51591,-0.012873278,12.400174,11.076154,218.79353,-9.3694391
74.4,0.96582586,-0.19723551,49.491623,0,11.076097,223.11592,-0.013058583,12.471422,11.076781,222.41805,-9.3672781
75.6,0.976264,-0.20399249,49.636227,0,11.076097,226.71591,-0.013514154,12.586198,11.07583,226.06929,-9.3655043
76.8,0.95975029,-0.20651443,49.636227,0,11.076097,230.31592,-0.01366503,12.382759,11.0769,229.73109,-9.3627234
78.0,0.96992642,-0.20880616,49.639874,0,11.076097,233.91591,-0.01384252,12.522476,11.075282,233.35907,-9.3607264
79.2,0.97415745,-0.21585816,49.687706,0,11.076097,237.51591,-0.014270116,12.58438,11.07683,236.98209,-9.3587055
80.4,0.96620679,-0.2183657,49.667522,0,11.076097,241.11589,-0.014434515,12.473767,11.075855,240.72432,-9.3570967
81.6,0.9748714,-0.220176,49.636234,0,11.076097,244.71591,-0.014581632,12.590276,11.076447,244.41229,-9.3551235
82.8,0.97337592,-0.22499594,49.636097,0,11.076097,248.31589,-0.014889234,12.576004,11.075672,248.14078,-9.3528481
84.0,0.97008741,-0.22984682,49.591358,0,11.076097,251.91589,-0.015203423,12.531162,11.076509,251.77522,-9.3507509
85.2,0.98060751,-0.23404092,49.636234,0,11.076097,255.5159,-0.015496293,12.687475,11.075223,255.34906,-9.3487101
86.4,0.96811587,-0.2379002,49.976246,0,11.076097,259.11615,-0.015758736,12.524598,11.076668,258.81897,-9.3463316
87.6,0.97383016,-0.24045092,50.042721,0,11.076097,262.71594,-0.015899163,12.602446,11.075317,262.37991,-9.3447857
88.8,0.97845161,-0.24627087,50.43652,0,11.076097,266.31589,-0.016247174,12.66723,11.076324,265.82645,-9.343112
90.0,0.96543127,-0.24960835,50.438087,0,11.076097,269.91592,-0.016523913,12.500926,11.075546,269.43289,-9.3404932
91.2,0.97797519,-0.25151807,50.468071,0,11.076097,273.5159,-0.016624739,12.659759,11.076918,272.98166,-9.3384142
92.4,0.96852118,-0.25763384,50.822742,0,11.076097,277.11591,-0.017013099,12.549139,11.076223,276.49292,-9.3365183
93.6,0.97261864,-0.26082993,50.853512,0,11.076097,280.71591,-0.017244315,12.617758,11.075796,280.06467,-9.334692
94.8,0.98886645,-0.26721284,51.02795,0,11.076097,284.31592,-0.017666938,12.810751,11.076085,283.69592,-9.3329763
96.0,0.9739331,-0.26968655,51.123463,0,11.076097,287.91592,-0.017819045,12.626076,11.075973,287.37814,-9.3310652
97.2,0.98184073,-0.27214238,51.18383,0,11.076097,291.5159,-0.017966116,12.737148,11.075826,291.08658,-9.3285866
98.4,0.98499811,-0.27903968,51.196285,0,11.076097,295.11591,-0.018434782,12.785525,11.076211,294.67715,-9.3267183
99.6,0.97629184,-0.28180146,51.196285,0,11.076097,298.71591,-0.018597597,12.671876,11.076774,298.27637,-9.3247213
100.8,0.98450089,-0.28353488,51.206497,0,11.076097,302.31592,-0.018706122,12.760957,11.076117,301.90039,-9.3222322
102.0,0.98833114,-0.29075006,51.56979,0,11.076097,305.91592,-0.019196648,12.826358,11.076243,305.39691,-9.3201513
103.2,0.97386879,-0.29331768,51.930649,0,11.076097,309.51593,-0.019376034,12.65341,11.076242,308.85617,-9.3181829
104.4,0.98225343,-0.2960653,51.932369,0,11.076097,313.11594,-0.01954376,12.7596,11.076726,312.47879,-9.3160725
105.6,0.99455768,-0.30352902,52.086388,0,11.076097,316.71591,-0.020024275,12.915942,11.076434,316.06891,-9.3144588
106.8,0.97089338,-0.3055414,52.119957,0,11.076097,320.31592,-0.020183628,12.620428,11.075599,319.75842,-9.3124733
108.0,0.98298228,-0.30877343,51.96283,0,11.076097,323.91592,-0.020367078,12.783525,11.075775,323.48169,-9.3102884
109.2,0.99157262,-0.31172594,52.225586,0,11.076097,327.51593,-0.020570528,12.884082,11.075703,327.08545,-9.3077774
110.4,0.97876793,-0.31696287,52.108727,0,11.076097,331.11594,-0.02092942,12.712916,11.077016,330.85715,-9.3058987
111.6,0.98005474,-0.32167512,51.932396,0,11.076097,334.71594,-0.021231435,12.75348,11.076527,334.54529,-9.3039961
112.8,0.99319762,-0.32299232,52.021042,0,11.076097,338.31592,-0.021303037,12.926358,11.076804,338.13721,-9.3023443
114.0,0.99113035,-0.32923794,52.295883,0,11.076097,341.91592,-0.021683259,12.886511,11.077077,341.46146,-9.3003693
115.2,0.98487312,-0.3343229,52.284107,0,11.076097,345.5159,-0.022067843,12.826227,11.075978,345.21313,-9.2988224
116.4,0.98686451,-0.3359378,52.578922,0,11.076097,349.11591,-0.022140106,12.844296,11.076941,348.71515,-9.2963076
117.6,0.99063265,-0.34150827,52.635487,0,11.076097,352.71591,-0.022489754,12.892916,11.076004,352.38089,-9.2943306
118.8,0.98567194,-0.34638655,52.63702,0,11.076097,356.31592,-0.022834254,12.834994,11.075343,355.91245,-9.2921162
120.0,0.99363339,-0.34805104,52.686108,0,11.076097,359.91422,-0.022954652,12.942022,11.076616,359.47781,-9.2899942
121.2,0.096823178,-0.36973751,47.130787,0,11.076097,359.99924,-0.024337105,1.2704545,11.076484,364.38699,-9.2899075
122.4,0.057425294,-0.36803478,43.486084,0,11.076097,359.99924,-0.024211876,0.75440592,11.075831,365.83374,-9.2896938
123.6,0.053269107,-0.36474103,46.282177,0,11.076097,359.99924,-0.024041491,0.68255407,11.076472,362.93759,-9.289731
124.8,0.057198912,-0.36401078,49.610371,0,11.076097,359.99924,-0.023975998,0.73608881,11.07649,359.90286,-9.2899961
126.0,0.047709178,-0.3632046,51.759163,0,11.076097,359.99924,-0.023925373,0.62705851,11.075705,358.17123,-9.2898102
127.2,0.053706355,-0.36290577,53.111984,0,11.076097,359.99924,-0.023895508,0.71005613,11.077296,357.1871,-9.2901993
128.4,0.05262237,-0.36224011,54.247337,0,11.076097,359.99924,-0.023879249,0.68666792,11.07649,356.7121,-9.2902164
129.6,0.065560572,-0.36385071,54.887447,0,11.076097,359.99924,-0.023971517,0.85838288,11.075057,356.68976,-9.2900286
130.8,0.07042782,-0.36347765,54.931644,0,11.076097,359.99924,-0.023920506,0.91137719,11.076325,357.12225,-9.2896023
132.0,0.077516153,-0.36436778,54.931644,0,11.076097,359.99924,-0.024013817,1.0179837,11.075517,357.75412,-9.289299
133.2,0.077679008,-0.36468741,54.649857,0,11.076097,359.99924,-0.02402278,1.0143093,11.07547,358.34238,-9.2893305
134.4,0.083952978,-0.36516699,54.631676,0,11.076097,359.99924,-0.02404823,1.0961711,11.075881,358.57806,-9.2891207
135.6,0.086848974,-0.36612263,54.767754,0,11.076097,359.99924,-0.024101255,1.1380002,11.07596,358.77356,-9.2891989
136.8,0.088021353,-0.36897647,54.732803,0,11.076097,359.99924,-0.024322597,1.1701056,11.076128,359.03003,-9.2891693
138.0,0.079962805,-0.36812404,54.736359,0,11.076097,359.99924,-0.02423436,1.0292356,11.076746,359.23871,-9.2892418
139.2,0.081076048,-0.36870646,54.805321,0,11.076097,359.99924,-0.024267578,1.0683123,11.07583,359.34885,-9.2892675
140.4,0.086571589,-0.36946082,54.783855,0,11.076097,359.99924,-0.024334358,1.1256545,11.075449,359.46762,-9.2895317
141.6,0.085320003,-0.36989704,54.750435,0,11.076097,359.99924,-0.024366528,1.120111,11.076188,359.60687,-9.2897301
142.8,0.089110598,-0.3703602,54.624146,0,11.076097,359.99924,-0.024396488,1.1617961,11.076312,359.74411,-9.2895737
144.0,0.090221666,-0.37098008,54.414989,0,11.076097,359.99924,-0.024400715,1.1791642,11.075565,360.02618,-9.2891645
145.2,0.091907047,-0.37096691,54.363117,0,11.076097,359.99924,-0.024448663,1.2104272,11.076097,359.97031,-9.288826
146.4,0.090955973,-0.37233236,54.588497,0,11.076097,359.99924,-0.024513837,1.2039171,11.075898,359.9462,-9.288722
147.6,0.097106285,-0.37402204,54.624023,0,11.076097,359.99924,-0.024629263,1.2614076,11.075461,359.86594,-9.2885056
148.8,0.091288045,-0.37447494,54.763519,0,11.076097,359.99924,-0.02464834,1.1871889,11.076057,359.67752,-9.2884254
150.0,0.097630017,-0.37371397,54.799961,0,11.076097,359.99924,-0.024623387,1.277662,11.076689,359.75436,-9.2885656
151.2,0.087229252,-0.37469533,54.624027,0,11.076097,359.99924,-0.024668351,1.1280547,11.076033,359.92145,-9.2890024
152.4,0.086860776,-0.37512344,54.395588,0,11.076097,359.99924,-0.024670476,1.1344018,11.076419,360.14505,-9.2888689
153.6,0.090373144,-0.37528455,54.43729,0,11.076097,359.99924,-0.024729019,1.1736497,11.076506,360.11761,-9.2892475
154.8,0.091897503,-0.37591287,54.62402,0,11.076097,359.99924,-0.024756644,1.2154092,11.076319,360.03049,-9.2889147
156.0,0.094387852,-0.37650204,54.623718,0,11.076097,359.99924,-0.024787337,1.2296934,11.075752,360.03717,-9.2889585
157.2,0.094425067,-0.376652,54.619984,0,11.076097,359.99924,-0.024780033,1.2488979,11.075672,360.03339,-9.2889233
158.4,0.096435182,-0.37661672,54.609974,0,11.076097,359.99924,-0.024819458,1.2603917,11.075839,359.97375,-9.2891293
159.6,0.086080067,-0.37705079,54.623371,0,11.076097,359.99924,-0.02481427,1.1302087,11.075562,359.92935,-9.2884369
160.8,0.089167587,-0.37775227,54.624023,0,11.076097,359.99924,-0.024857178,1.173794,11.075062,359.89804,-9.2887745
162.0,0.09226732,-0.37846893,54.718128,0,11.076097,359.99924,-0.024917385,1.2222368,11.075856,359.80505,-9.288578
163.2,0.10273138,-0.38025951,54.81702,0,11.076097,359.99924,-0.02506209,1.3470219,11.076171,359.81467,-9.2880154
164.4,0.099826433,-0.3804301,54.632847,0,11.076097,359.99924,-0.025034456,1.3037009,11.076077,359.92871,-9.2882624
165.2809,0.15092614,0.033963423,54.624023,0,11.076099,2.5664899,0.0025568181,1.9539665,11.073291,360.03595,-9.2895966
165.2833,0.19502094,0.037672207,54.624023,0,11.076099,1.1094927999999999e-16,0.0025555249,2.3912694,11.075865,360.03595,-9.2892227
165.2857,0.17905697,0.036414687,54.624023,0,11.076099,4.7963354e-33,0.0022452842,2.3149135,11.076272,360.03595,-9.2888851
165.2881,0.16810332,0.042352527,54.624023,0,11.076099,0.0,0.0024959436,2.1464086,11.073104,360.03595,-9.2875004
165.2905,0.15968962,0.040186115,45.337807,0,11.076099,0.0,0.0026438376,2.016695,11.076693,360.02563,-9.2879572
165.2929,0.16145378,0.035614684,32.228043,0,11.076099,0.0,0.002639205,2.0594156,11.075839,360.01111,-9.288641
165.2953,0.20767286,0.032793734,19.118277,0,11.076099,0.0,0.0024323796,2.6063113,11.073359,359.99655,-9.2887754
165.2977,0.16990799,0.036001112,6.0085125,0,11.076099,0.0,0.002388793,2.1862142,11.074345,359.98199,-9.2876425
165.3001,0.1624465,0.036785532,0.0,0,11.076099,0.0,0.0023149848,2.1787262,11.076206,359.99506,-9.2873735
165.3025,0.18226938,0.037210163,0.0,0,11.076099,0.0,0.0024476761,2.2508869,11.077654,360.0314,-9.2885571
165.3049,0.185637,0.03661814,0.0,0,11.076099,0.0,0.0025918358,2.3143523,11.076238,360.06778,-9.2891827
165.3073,0.18667492,0.035002355,0.0,0,11.076099,0.0,0.0025634319,2.3779328,11.07587,360.10416,-9.2898207
165.3097,0.17763665,0.036021497,0.0,0,11.076099,0.0,0.0024154175,2.2516415,11.076634,360.12418,-9.2883787
165.3121,0.1679702,0.040008448,0.0,0,11.076099,0.0,0.0023601269,2.1927752,11.077509,360.11688,-9.2884636
165.3145,0.18886358,0.041489374,0.0,0,11.076099,0.0,0.0025897874,2.4751956,11.079095,360.10962,-9.2877922
165.3169,0.19832332,0.038631722,0.0,0,11.076099,0.0,0.0027126013,2.4884579,11.074611,360.10236,-9.2874699
165.3193,0.19253427,0.034034364,0.0,0,11.076099,0.0,0.0025576274,2.3546638,11.077933,360.09357,-9.2888288
165.3217,0.18061495,0.034823779,0.0,0,11.076099,0.0,0.0023152798,2.2142825,11.070745,360.07901,-9.2887669
165.3241,0.18617137,0.036836788,0.0,0,11.076099,0.0,0.0022706583,2.2914133,11.077916,360.06445,-9.2884426
165.3265,0.20022728,0.038359024,0.0,0,11.076099,0.0,0.0024349254,2.5403986,11.077799,360.04993,-9.2876949
165.3289,0.20016867,0.038234465,0.0,0,11.076099,0.0,0.0025753661,2.4770138,11.079673,360.03568,-9.2892313
165.3313,0.19317868,0.037599321,0.0,0,10.976468,0.0,0.0027825192,2.4210973,11.073611,360.02841,-9.288744
165.3337,0.19330788,0.038130846,0.0,0,10.615494,0.0,0.0026638387,2.4353383,11.076643,360.02112,-9.2872477
165.3361,0.20490657,0.040668212,0.0,0,10.254521,0.0,0.002511736,2.4961195,11.058613,360.01385,-9.2867537
165.3385,0.25407639,0.044834327,0.0,0,9.8935471,0.0,0.002611567,3.1629045,10.929273,360.00659,-9.288518
165.3409,0.19499916,0.044209704,0.0,0,9.5325737,0.0,0.0028522345,2.5140507,10.647073,360.858,-9.2876196
165.3433,0.23249465,0.038141102,0.0,0,9.1800261,0.0,0.0028126284,3.0365624,10.256274,361.83209,-9.2873077
165.3457,6.8180022,0.36367857,0.0,0,8.8288574,0.0,0.023959823,84.730515,9.8088465,362.80615,-9.2830458
165.3481,8.3579645,0.76153475,0.0,0,8.491025,0.0,0.051660426,100.77556,9.307024,363.78024,-9.2816095
165.3505,8.8552046,1.2063302,0.0,0,8.1570406,0.0,0.083055876,103.99014,8.8509674,364.37344,-9.2815237
165.3529,9.0112791,1.6119119,0.0,0,7.8342953,0.0,0.11328153,102.12714,8.4641809,364.80984,-9.2812939
165.3553,9.3177071,1.9136668,0.0,0,7.5165353,0.0,0.13630395,103.44981,8.1344204,365.24622,-9.2805462
165.3577,9.5509481,2.2070918,0.0,0,7.2082515,0.0,0.15902677,103.56561,7.8184061,365.68262,-9.279521
165.3601,9.8323488,2.5113904,0.0,0,6.9060431,0.0,0.18280269,104.32588,7.5165868,364.75613,-9.281249
165.3625,10.047844,2.7915676,0.0,0,6.6115613,0.0,0.2051453,104.12956,7.2356534,362.67654,-9.2816057
165.3649,10.30858,3.0751939,0.0,0,6.3240414,0.0,0.22870505,104.45902,6.9523296,360.59692,-9.2813139
165.3673,10.577689,3.3541818,0.0,0,6.042748,0.0,0.25294611,104.56912,6.6616817,358.5173,-9.2802944
165.3697,10.904971,3.6358354,0.0,0,5.7692914,0.0,0.27764887,105.10729,6.373239,355.99939,-9.2811384
165.3721,11.163635,3.9244444,0.0,0,5.5006132,0.0,0.30287912,104.9737,6.0842133,352.75098,-9.2799902
165.3745,11.453073,4.2093353,0.0,0,5.2404532,0.0,0.32857412,104.8824,5.7995605,349.50256,-9.2800188
165.3769,11.720208,4.4910741,0.0,0,4.9838037,0.0,0.35502192,104.54935,5.5170183,346.25418,-9.2803354
165.3793,12.053651,4.7651639,0.0,0,4.7363639,0.0,0.38199908,104.65845,5.240243,343.33463,-9.2799282
165.3817,12.347825,5.0317278,0.0,0,4.4912457,0.0,0.40871942,104.44218,4.9714046,341.66464,-9.2815132
165.3841,12.641014,5.2905183,0.0,0,4.2558532,0.0,0.43472919,104.21258,4.7109013,339.99463,-9.2817612
165.3865,12.94578,5.5466852,0.0,0,4.0217257,0.0,0.4608674,103.95953,4.459281,338.32465,-9.2820768
165.3889,13.294073,5.7975321,0.0,0,3.7978492,0.0,0.48742199,103.9048,4.2096357,336.75577,-9.2814198
165.3913,13.667365,6.0316939,0.0,0,3.5743496,0.0,0.51395667,103.99112,3.9725702,337.51202,-9.2799454
165.3937,14.033773,6.2559419,0.0,0,3.3612847,0.0,0.53981847,104.07147,3.7443421,338.26831,-9.2786446
165.3961,14.40532,6.4739676,0.0,0,3.1483085,0.0,0.56497216,104.24671,3.5225465,339.02457,-9.2790346
165.3985,14.815789,6.6963959,0.0,0,2.9451063,0.0,0.590657,104.46387,3.3016114,339.78085,-9.2799644
165.4009,15.297463,6.9130869,0.0,0,2.7424982,0.0,0.61686349,105.0451,3.0859809,341.27631,-9.2788067
165.4033,15.790429,7.1213527,0.0,0,2.5483871,0.0,0.6432541,105.58659,2.8785865,343.39725,-9.2777777
165.4057,16.247217,7.3188777,0.0,0,2.3556671,0.0,0.66955245,105.91241,2.6772983,345.51819,-9.2779007
165.4081,16.793337,7.517467,0.0,0,2.170248,0.0,0.69564837,106.5137,2.4756596,347.63913,-9.2778997
165.4105,17.343323,7.7136211,0.0,0,1.986936,0.0,0.72142357,107.28519,2.2848215,348.27188,-9.27808
165.4129,17.956621,7.9089303,0.0,0,1.8098083,0.0,0.74772674,108.16208,2.0937326,346.42429,-9.2779913
165.4153,18.615965,8.0964108,0.0,0,1.6354243,0.0,0.77503562,109.12844,1.9096208,344.57669,-9.2771606
165.4177,19.267319,8.2719173,0.0,0,1.4662172,0.0,0.80189854,109.95888,1.7272335,342.7291,-9.2770987
165.4201,19.968296,8.4442329,0.0,0,1.3003292,0.0,0.82820863,111.01109,1.5521259,340.1427,-9.2769394
165.4225,20.766886,8.617651,0.0,0,1.1387082,0.0,0.85427994,112.43071,1.3773954,334.74881,-9.2761497
165.4249,21.590853,8.7892036,0.0,0,0.98093224,0.0,0.88037002,113.8962,1.2104189,329.35489,-9.2769213
165.4273,22.455637,8.952342,0.0,0,0.82657719,0.0,0.9072485,115.32363,1.0446866,323.961,-9.2764349
165.4297,23.337507,9.1102562,0.0,0,0.67652929,0.0,0.93488389,116.57941,0.88031793,318.81259,-9.2757139
165.4321,24.24538,9.2580061,0.0,0,0.52908581,0.0,0.96089381,118.02832,0.72237021,319.30997,-9.2744274
165.4345,25.213224,9.4055901,0.0,0,0.38628578,0.0,0.98623782,119.62302,0.57462943,319.80734,-9.2743034
165.4369,23.449593,9.4901657,0.0,0,0.24542005,0.0,1.0005493,109.76469,0.47158298,320.30472,-9.2763052
165.4393,21.826385,9.5050964,0.0,0,0.10962804,0.0,1.0028831,102.10413,0.4298965,320.80209,-9.2770596
165.4417,21.070761,9.5107269,0.0,0,-0.025516469,0.0,1.0053563,98.186325,0.40650213,324.81924,-9.279027
165.4441,20.689125,9.511301,0.0,0,-0.15794852,0.0,1.0065618,96.306519,0.37544158,329.33926,-9.2802544
165.4465,20.84634,9.5147181,0.0,0,-0.29038054,0.0,1.0067077,96.975632,0.32229203,333.85925,-9.2805328
165.4489,21.052254,9.5244322,0.0,0,-0.42281252,0.0,1.0072551,97.853683,0.25288042,338.37924,-9.2812176
165.4513,21.075556,9.5320387,0.0,0,-0.55524451,0.0,1.0081598,97.916901,0.18982936,341.52115,-9.2808332
165.4537,20.952188,9.5379276,0.0,0,-0.68767649,0.0,1.0100405,97.198982,0.13158908,344.09564,-9.2796383
165.4561,20.743402,9.5387983,0.0,0,-0.82010847,0.0,1.0113559,96.109055,0.079350509,346.6701,-9.2802649
165.4585,20.460312,9.5408449,0.0,0,-0.95254052,0.0,1.0116417,94.703773,0.040905491,349.2446,-9.2807751
165.4609,20.065758,9.546133,0.0,0,-1.0849725,0.0,1.0115117,92.951744,0.020372976,351.03186,-9.2810297
165.4633,19.525892,9.5526218,0.0,0,-0.72870666,359.99997,1.0115467,90.45977,0.012433308,352.15308,-9.2832689
165.4657,18.940968,9.5541134,0.0,0,-0.27022031,359.99997,1.0125449,87.695259,0.017465381,353.27426,-9.2829323
165.4681,18.478445,9.5496244,0.0,0,0.18826602,359.99997,1.013183,85.457451,0.020144684,354.39545,-9.2825699
165.4705,18.127506,9.5442133,0.72279179,0,0.64675242,359.99997,1.0127161,83.868698,0.023173478,355.42075,-9.2825432
165.4729,17.875416,9.5461454,2.6502333,0,1.105239,359.99997,1.0117888,82.749062,0.022513218,356.28629,-9.2836866
165.4753,17.402565,9.5520153,4.5776744,0,1.5637254,359.99997,1.0116538,80.649529,0.031971417,357.15179,-9.284605
165.4777,16.015436,9.5494461,6.505116,0,2.0222118,359.99997,1.0115341,74.329216,0.084249996,358.0173,-9.2836924
165.4801,13.152265,9.5377254,8.0310059,0,2.4806983,359.99997,1.0105178,61.24342,0.20842651,358.92679,-9.2878189
165.4825,8.4459028,9.5147314,8.0310059,0,2.9391847,359.99997,1.0071741,39.707523,0.43257207,360.00323,-9.2909861
165.4849,0.40547755,9.3260336,8.0310059,0,3.3976712,359.99997,0.97329313,1.8067735,0.86794239,361.07968,-9.2981787
165.4873,-0.51026762,9.1909657,8.0310059,0,3.8561575,359.99997,0.94780618,-2.2356064,1.5601944,362.15613,-9.2981396
165.4897,0.13529968,9.0589504,7.9506946,0,4.3146439,359.99997,0.92557788,0.43147734,2.3909314,363.2038,-9.2978954
165.4921,0.0021100172,8.9827127,6.023253,0,4.7731299,359.99997,0.91351795,0.17280675,3.106884,363.58929,-9.2966547
165.4945,-0.13142118,8.9561052,4.0958118,0,5.2316165,359.99997,0.9102093,-0.69399613,3.6337886,363.97479,-9.2967806
165.4969,0.0021099676,8.9616547,2.1683702,0,5.6901031,359.99997,0.91051638,0.076136932,4.0622988,364.36026,-9.2954159
165.4993,-0.057313394,8.9997129,0.24092895,0,6.1485891,359.99997,0.91549712,-0.30800685,4.4787583,364.74576,-9.294075
165.5017,0.043835334,9.0567837,0.0,0,6.6070752,359.99997,0.92484647,0.15628478,4.8983154,364.78122,-9.2930384
165.5041,0.0067232437,9.1354752,0.0,0,7.0655622,359.99997,0.93870997,0.015162586,5.3312621,364.76666,-9.2929621
165.5065,-0.037658356,9.2336884,0.0,0,7.5240488,359.99997,0.95648617,-0.098053202,5.7902312,364.75214,-9.2916241
165.5089,-0.069572091,9.3573771,0.0,0,7.9825354,359.99997,0.9783324,-0.41827598,6.2585607,364.73758,-9.2910852
165.5113,3.0335946,9.4713373,0.0,0,8.441021,359.99997,0.99771249,14.073261,6.7471747,364.97021,-9.2899332
165.5137,-0.022003375,9.42029,0.0,0,8.8995075,359.99997,0.98753005,0.028453803,7.230134,365.30463,-9.289587
165.5161,-0.11394402,9.3877459,0.0,0,9.3579931,359.99997,0.98242325,-0.64786839,7.7063732,365.63904,-9.2913799
165.5185,0.067109361,9.3699484,0.0,0,9.8164806,359.99997,0.9808194,0.33888149,8.1884642,365.97345,-9.2909012
165.5209,-0.056371447,9.3963327,0.0,0,10.274966,359.99997,0.98582125,-0.2211571,8.658824,366.31549,-9.2897568
165.5233,0.5203619,9.4489441,0.0,0,10.733453,359.99997,0.9939695,2.1556664,9.1283312,366.66397,-9.2898636
165.5257,0.028246006,9.4426727,0.0,0,11.191939,359.99997,0.99190897,0.21589094,9.6060925,367.01248,-9.2889843
165.5281,-0.085983224,9.4410267,0.0,0,11.650426,359.99997,0.99193573,-0.4024429,10.08189,367.36099,-9.2887917
165.5305,0.39858621,9.44946,0.0,0,12.108912,359.99997,0.99459016,1.869909,10.551931,367.66586,-9.2885246
165.5329,0.16694413,9.4412498,0.0,0,12.567399,359.99997,0.99385732,0.79458916,11.019845,367.89804,-9.2863703
165.5353,0.20363472,9.4463234,0.0,0,13.025885,359.99997,0.99394363,0.99194288,11.477945,368.13022,-9.2871723
165.5377,0.18944725,9.4487057,0.0,0,13.484371,359.99997,0.99318427,0.87696117,11.934978,368.3624,-9.2872124
165.5401,0.23205794,9.4529667,0.0,0,13.942858,359.99997,0.99354529,1.0873789,12.401031,368.59003,-9.2866993
165.5425,0.20702602,9.4523716,0.0,0,14.401344,359.99997,0.99493295,0.94352949,12.866676,368.80045,-9.2864637
165.5449,0.22733457,9.4455547,0.0,0,14.859831,359.99997,0.99467468,1.0543405,13.346071,369.01086,-9.2876024
165.5473,0.1961755,9.4432049,0.0,0,15.318317,359.99997,0.9936232,0.97828358,13.825733,369.22128,-9.2857151
165.5497,0.20535927,9.4468231,0.0,0,15.776803,359.99997,0.99310619,0.96567118,14.298063,369.43655,-9.2870522
165.5521,0.21889345,9.4477453,0.0,0,16.235291,359.99997,0.99299473,0.99707717,14.768569,369.76306,-9.2875996
165.5545,0.24867319,9.4488096,0.0,0,16.693775,359.99997,0.99407029,1.1808426,15.230376,370.08957,-9.2860928
165.5569,0.18288136,9.4459944,0.0,0,17.152262,359.99997,0.99452019,0.89621669,15.679571,370.41608,-9.2855253
165.5593,0.26685619,9.4430208,0.0,0,17.61075,359.99997,0.99398822,1.1984978,16.135403,370.74258,-9.2850504
165.5617,0.22398773,9.4466562,0.0,0,17.999975,359.99997,0.99334323,1.1608328,16.591709,371.02463,-9.2860012
165.5641,0.2187165,9.4539413,0.0,0,18.0,359.99997,0.99370283,0.99074399,17.049154,371.30035,-9.287075
165.5665,0.22263072,9.452136,0.0,0,18.0,359.99997,0.9941346,1.0468359,17.475588,371.57605,-9.2859106
165.5689,0.27458867,9.4462986,0.0,0,18.0,359.99997,0.99446273,1.3202938,17.858957,371.85178,-9.2872496
165.5713,0.25166091,9.441699,0.0,0,18.0,359.99997,0.99399197,1.1647452,18.171638,372.07608,-9.2897396
165.5737,0.29142213,9.4427223,0.0,0,18.0,359.99997,0.99291259,1.4084393,18.395468,372.27927,-9.2928495
165.5761,0.29376149,9.4465971,0.0,0,18.0,359.99997,0.99258286,1.3629305,18.497076,372.48242,-9.2972994
165.5785,0.37785992,9.451005,0.0,0,18.0,359.99997,0.9937861,1.8573568,18.474648,372.68558,-9.3028841
165.5809,0.27129546,9.4491634,0.0,0,18.0,359.99997,0.994578,1.2730836,18.358122,372.86908,-9.3123608
165.5833,0.34682122,9.4454346,0.0,0,18.0,359.99997,0.9944852,1.6273779,18.228151,373.03595,-9.3255749
165.5857,0.29361048,9.4441185,0.0,0,18.0,359.99997,0.99349415,1.4168886,18.124685,373.20282,-9.3424072
165.5881,0.35234162,9.4458313,0.0,0,18.0,359.99997,0.99245626,1.646842,18.058149,373.36969,-9.3597603
165.5905,0.33733654,9.4499674,0.0,0,18.0,359.99997,0.99291706,1.5892671,18.043793,373.53931,-9.3784523
165.5929,0.30111814,9.4467955,0.0,0,18.0,359.99997,0.99393994,1.431628,18.044352,373.71344,-9.3987713
165.5953,0.28909773,9.4399271,0.0,0,18.0,359.99997,0.99368197,1.3286451,18.062798,373.88757,-9.4203768
165.5977,0.33787555,9.4358559,0.0,0,18.0,359.99997,0.99224514,1.5738195,18.082415,374.06174,-9.4378443
165.6001,0.35088098,9.4376287,0.0,0,18.0,359.99997,0.99143517,1.6523058,18.102552,374.23285,-9.4554892
165.6025,0.34176567,9.441268,0.0,0,18.0,359.99997,0.99179465,1.6344074,18.118677,374.39246,-9.4738598
165.6049,0.31776854,9.4455023,0.0,0,18.0,359.99997,0.99352604,1.5181056,18.134266,374.55209,-9.4917469
165.6073,0.32114047,9.4401073,0.0,0,18.0,359.99997,0.9934814,1.4995226,18.136515,374.7117,-9.5094385
165.6097,0.35494882,9.4355354,0.0,0,18.0,359.99997,0.99260306,1.6871924,18.135916,374.87134,-9.5273924
165.6121,0.36581391,9.439291,0.0,0,18.0,359.99997,0.99188882,1.6937551,18.13611,375.03098,-9.5431213
165.6145,0.35387802,9.4491434,0.0,0,18.0,359.99997,0.99258858,1.7150512,18.131445,375.19058,-9.5611639
165.6169,0.33523342,9.4477577,0.0,0,18.0,359.99997,0.99329334,1.571519,18.13098,375.35022,-9.5799398
165.6193,0.37017083,9.4405775,0.0,0,18.0,359.99997,0.99346596,1.7243445,18.128317,375.50983,-9.5960331
165.6217,0.39693326,9.4364605,0.0,0,18.0,359.99997,0.9929989,1.8790699,18.12586,375.66312,-9.612813
165.6241,0.36583778,9.4401703,0.0,0,18.0,359.99997,0.99235564,1.7474614,18.120012,375.81546,-9.6311064
165.6265,0.36113808,9.4456558,0.0,0,18.0,359.99997,0.99234766,1.7095636,18.119101,375.96783,-9.6490641
165.6289,0.36139864,9.4462652,0.0,0,18.0,359.99997,0.99296325,1.7004395,18.116936,376.12021,-9.6673908
165.6313,0.3845785,9.4412031,0.0,0,18.0,359.99997,0.99309373,1.840946,18.11628,376.2366,-9.6834364
165.6337,0.38228142,9.4379053,0.0,0,18.0,359.99997,0.99317306,1.7948765,18.116383,376.33817,-9.7008457
165.6361,0.38604847,9.4406013,0.0,0,18.0,359.99997,0.99264002,1.8258892,18.111677,376.43976,-9.7182417
165.6385,0.36896843,9.4477224,0.0,0,18.0,359.99997,0.99264425,1.7435669,18.109793,376.54132,-9.736167
165.6409,0.38230804,9.4499941,0.0,0,18.0,359.99997,0.99307048,1.7889177,18.10874,376.64291,-9.7535229
165.6433,0.40439978,9.4450035,0.0,0,18.0,359.99997,0.99375111,1.9173044,18.107616,376.74451,-9.7702837
165.6457,0.38702846,9.437623,0.0,0,18.0,359.99997,0.99327749,1.8340384,18.103107,376.84607,-9.7883444
165.6481,0.3736093,9.4363003,0.0,0,18.0,359.99997,0.99215287,1.7963656,18.101362,376.94766,-9.8056183
165.6505,0.37408251,9.4393816,0.0,0,18.0,359.99997,0.99149889,1.753998,18.104671,377.03561,-9.8237
165.6529,0.38345519,9.4436541,0.0,0,18.0,359.99997,0.99225801,1.8298715,18.101202,377.10092,-9.8405542
165.6553,0.4022817,9.4410677,0.0,0,18.0,359.99997,0.99268496,1.895417,18.102772,377.16623,-9.8591604
165.6577,0.3962644,9.4383411,0.0,0,18.0,359.99997,0.99315566,1.8747144,18.099934,377.23151,-9.8775969
165.6601,0.36477649,9.4395895,0.0,0,18.0,359.99997,0.99323273,1.7585306,18.100451,377.29529,-9.8960361
165.6625,0.3918438,9.4433918,0.0,0,18.0,359.99997,0.99252468,1.849211,18.100691,377.35336,-9.9133034
165.6649,0.39267585,9.4485836,0.0,0,18.0,359.99997,0.99258107,1.8571724,18.100437,377.41141,-9.929657
165.6673,0.40725744,9.4479361,0.0,0,18.0,359.99997,0.99326587,1.9081678,18.095953,377.46945,-9.9462404
165.6697,0.37990797,9.4413748,0.0,0,18.0,359.99997,0.9937827,1.8279699,18.098192,377.5278,-9.9654112
165.6721,0.38655126,9.4348726,0.0,0,18.0,359.99997,0.99263912,1.8309069,18.098862,377.59311,-9.9823704
165.6745,0.39853957,9.4356632,0.0,0,18.0,359.99997,0.99151045,1.8792298,18.096617,377.65839,-9.9992285
165.6769,0.43023118,9.4426231,0.0,0,18.0,359.99997,0.99188012,2.0308485,18.095963,377.72369,-10.017611
165.6793,0.41865495,9.4465923,0.0,0,18.0,359.99997,0.99312133,1.9449513,18.097197,377.789,-10.035378
165.6817,0.38721746,9.4430847,0.0,0,18.0,359.99997,0.99353373,1.8394381,18.095808,377.83524,-10.053795
165.6841,0.41003826,9.4381008,0.0,0,18.0,359.99997,0.99340457,1.9406658,18.09079,377.87878,-10.071194
165.6865,0.43108642,9.4401588,0.0,0,18.0,359.99997,0.99274731,2.0031173,18.089643,377.9223,-10.087472
165.6889,0.43726733,9.4458599,0.0,0,18.0,359.99997,0.99233937,2.0693398,18.088865,377.96585,-10.105332
165.6913,0.42099062,9.4497557,0.0,0,18.0,359.99997,0.9930892,1.9772798,18.092175,378.02994,-10.123272
165.6937,0.41360763,9.4479265,0.0,0,18.0,359.99997,0.99438506,1.9424367,18.087528,378.10251,-10.142736
165.6961,0.43885404,9.4391336,0.0,0,18.0,359.99997,0.99365902,2.0397563,18.082268,378.17508,-10.159299
165.6985,0.45738313,9.4393625,0.0,0,18.0,359.99997,0.99261123,2.0975463,18.085867,378.24762,-10.176496
165.7009,0.44246462,9.44314,0.0,0,18.0,359.99997,0.99227661,2.10641,18.08383,378.30838,-10.193995
165.7033,0.42087194,9.4452257,0.0,0,18.0,359.99997,0.99238622,2.0375235,18.087038,378.35919,-10.212536
165.7057,0.44147038,9.4423037,0.0,0,18.0,359.99997,0.99306887,2.0448935,18.089495,378.40997,-10.228748
165.7081,0.44993827,9.4381495,0.0,0,18.0,359.99997,0.99331403,2.1447535,18.084875,378.46075,-10.245527
165.7105,0.46394342,9.4388752,0.0,0,18.0,359.99997,0.9929508,2.1809816,18.080679,378.49249,-10.262281
165.7129,0.44898131,9.4433289,0.0,0,18.0,359.99997,0.99242139,2.1280694,18.08227,378.49249,-10.281332
165.7153,0.43393561,9.4510269,0.0,0,18.0,359.99997,0.99291205,2.0350723,18.081976,378.49249,-10.299053
165.7177,0.45210314,9.4487457,0.0,0,18.0,359.99997,0.993545,2.1023638,18.080595,378.49249,-10.315662
165.7201,0.46448091,9.4400196,0.0,0,18.0,359.99997,0.99347937,2.1774292,18.080742,378.49704,-10.332602
165.7225,0.45564917,9.437933,0.0,0,18.0,359.99997,0.99303359,2.161978,18.082193,378.5188,-10.351859
165.7249,0.42508435,9.441823,0.0,0,18.0,359.99997,0.99252743,2.0709832,18.078587,378.54056,-10.369315
165.7273,0.45562941,9.4472179,0.0,0,18.0,359.99997,0.99269986,2.1147397,18.077866,378.56232,-10.386434
165.7297,0.44475779,9.4472418,0.0,0,18.0,359.99997,0.99319696,2.1057534,18.078379,378.58441,-10.402455
165.7321,0.46918949,9.4429607,0.0,0,18.0,359.99997,0.99364972,2.2358832,18.079048,378.61343,-10.41954
165.7345,0.4665972,9.4407415,0.0,0,18.0,359.99997,0.99369985,2.2172594,18.074408,378.64243,-10.438114
165.7369,0.43226859,9.4432001,0.0,0,18.0,359.99997,0.99304998,2.0650156,18.075138,378.67145,-10.455703
165.7393,0.45239988,9.4468861,0.0,0,18.0,359.99997,0.99259579,2.1497855,18.078627,378.70047,-10.474988
165.7417,0.46423236,9.4465714,0.0,0,18.0,359.99997,0.99260908,2.2177215,18.075697,378.7168,-10.492282
165.7441,0.48298615,9.4433899,0.0,0,18.0,359.99997,0.99362338,2.2807057,18.071562,378.73132,-10.510167
165.7465,0.44968033,9.4390106,0.0,0,18.0,359.99997,0.9936232,2.0888469,18.068707,378.74585,-10.526701
165.7489,0.46090764,9.4399862,0.0,0,18.0,359.99997,0.99282593,2.1953135,18.071688,378.76035,-10.544082
165.7513,0.46888363,9.4439487,0.0,0,18.0,359.99997,0.99220914,2.2087018,18.071009,378.76459,-10.561498
165.7537,0.49671188,9.445097,0.0,0,18.0,359.99997,0.99246949,2.3640254,18.064495,378.76459,-10.579558
165.7561,0.49006918,9.4445705,0.0,0,18.0,359.99997,0.99331868,2.3263092,18.07131,378.76459,-10.596492
165.7585,0.4707498,9.4409838,0.0,0,18.0,359.99997,0.99397558,2.2079179,18.066032,378.76459,-10.614812
165.7609,0.49181187,9.4406834,0.0,0,18.0,359.99997,0.99327034,2.3019366,18.066635,378.75671,-10.633073
165.7633,0.49916962,9.442399,0.0,0,18.0,359.99997,0.99223793,2.3739469,18.067707,378.74222,-10.650712
165.7657,0.50272715,9.4507666,0.0,0,18.0,359.99997,0.99306715,2.3675025,18.069551,378.72769,-10.668979
165.7681,0.49288452,9.4497194,0.0,0,18.0,359.99997,0.99380231,2.2858713,18.065689,378.71317,-10.685419
165.7705,0.47623,9.442297,0.0,0,18.0,359.99997,0.99403715,2.2744687,18.064257,378.7041,-10.702631
165.7729,0.49086142,9.4376154,0.0,0,18.0,359.99997,0.99313194,2.2861917,18.067184,378.7041,-10.720899
165.7753,0.52424592,9.4422731,0.0,0,18.0,359.99997,0.99249762,2.4748321,18.064272,378.7041,-10.738709
165.7777,0.50603408,9.4474745,0.0,0,18.0,359.99997,0.99269772,2.419656,18.065353,378.7041,-10.755423
165.7801,0.48765886,9.4467239,0.0,0,18.0,359.99997,0.99321777,2.3168166,18.062778,378.70712,-10.775283
165.7825,0.49455738,9.4408722,0.0,0,18.0,359.99997,0.9933688,2.3367829,18.064196,378.72165,-10.792204
165.7849,0.50702745,9.4373074,0.0,0,18.0,359.99997,0.99316925,2.3903174,18.061443,378.73615,-10.808534
165.7873,0.51287079,9.4427843,0.0,0,18.0,359.99997,0.99295765,2.4509079,18.062939,378.75067,-10.824373
165.7897,0.50130349,9.4486914,0.0,0,18.0,359.99997,0.99285376,2.4303904,18.062319,378.7652,-10.843217
165.7921,0.49830055,9.4478369,0.0,0,18.0,359.99997,0.99291092,2.3146312,18.062395,378.77969,-10.860225
165.7945,0.49943489,9.4418068,0.0,0,18.0,359.99997,0.9933573,2.3601134,18.058044,378.79422,-10.878817
165.7969,0.52399987,9.436657,0.0,0,18.0,359.99997,0.99318206,2.4609005,18.058123,378.80872,-10.896694
165.7993,0.53042042,9.439991,0.0,0,18.0,359.99997,0.99272162,2.5266643,18.058622,378.82324,-10.914594
165.8017,0.50237995,9.4428806,0.0,0,18.0,359.99997,0.99208826,2.3455236,18.055376,378.79965,-10.93014
165.8041,0.51022577,9.445528,0.0,0,18.0,359.99997,0.99263531,2.4068315,18.057751,378.77063,-10.949639
165.8065,0.51787281,9.444706,0.0,0,18.0,359.99997,0.99336255,2.4498305,18.059399,378.74161,-10.966225
165.8089,0.53628647,9.4410553,0.0,0,18.0,359.99997,0.99368316,2.5502114,18.054787,378.71255,-10.982
165.8113,0.52386224,9.4397039,0.0,0,18.0,359.99997,0.99292445,2.4648421,18.055943,378.69382,-11.000596
165.8137,0.50541228,9.4425135,0.0,0,18.0,359.99997,0.99212205,2.4001627,18.053299,378.67932,-11.017672
165.8161,0.5173763,9.447403,0.0,0,18.0,359.99997,0.99233943,2.4365544,18.055311,378.66479,-11.035513
165.8185,0.54347903,9.4464283,0.0,0,18.0,359.99997,0.99315387,2.5126803,18.054668,378.6503,-11.054943
165.8209,0.54211235,9.4408255,0.0,0,18.0,359.99997,0.99375206,2.5862105,18.049662,378.64758,-11.072616
165.8233,0.51352215,9.4380245,0.0,0,18.0,359.99997,0.99324703,2.4574778,18.051435,378.65485,-11.091071
165.8257,0.51985472,9.4416294,0.0,0,18.0,359.99997,0.99242002,2.476825,18.047327,378.66211,-11.108317
165.8281,0.52712756,9.4430771,0.0,0,18.0,359.99997,0.99188954,2.4847021,18.051146,378.66934,-11.123994
165.8305,0.54938519,9.4463806,0.0,0,18.0,359.99997,0.99303061,2.6360309,18.050579,378.67389,-11.141171
165.8329,0.53972322,9.4427834,0.0,0,18.0,359.99997,0.99353695,2.5601871,18.051638,378.67389,-11.158985
165.8353,0.53458524,9.4403067,0.0,0,18.0,359.99997,0.99359542,2.5234666,18.049814,378.67389,-11.177344
165.8377,0.53101349,9.4396429,0.0,0,18.0,359.99997,0.99235469,2.5433452,18.052044,378.67389,-11.195552
165.8401,0.56003171,9.4466009,0.0,0,18.0,359.99997,0.99239779,2.6086481,18.052473,378.67542,-11.213618
165.8425,0.56142461,9.4524012,0.0,0,18.0,359.99997,0.99360627,2.6690583,18.053047,378.68265,-11.230599
165.8449,0.54041016,9.4472475,0.0,0,18.0,359.99997,0.99443609,2.5646286,18.047293,378.68991,-11.248998
165.8473,0.5405938,9.4384785,0.0,0,18.0,359.99997,0.99319077,2.5714684,18.049522,378.69714,-11.265408
165.8497,0.55194187,9.436161,0.0,0,18.0,359.99997,0.99205869,2.601316,18.050591,378.70288,-11.281446
165.8521,0.57748133,9.4425993,0.0,0,18.0,359.99997,0.99194717,2.7384748,18.04645,378.67386,-11.29863
165.8545,0.56687617,9.4441137,0.0,0,18.0,359.99997,0.99239385,2.7127609,18.049635,378.64487,-11.318192
165.8569,0.54448831,9.4427776,0.0,0,18.0,359.99997,0.99304581,2.5945902,18.046305,378.61584,-11.334466
165.8593,0.54367274,9.4369268,0.0,0,18.0,359.99997,0.99308956,2.5818481,18.046259,378.58682,-11.352242
166.0612,0.55938476,9.4435816,0.0,0,18.0,0.68381345,0.99308878,2.6331158,18.024208,368.13547,-11.480425
167.2612,0.63578486,9.4531946,0.0,0,18.0,2.9561129e-17,0.99488395,2.9904895,18.001255,340.68454,-11.481105
168.4612,0.66211778,9.4605389,0.0,0,18.0,1.2779232e-33,0.99609441,3.1143022,18.000381,326.99915,-11.481515
169.6612,0.66382635,9.4672623,0.0,0,18.0,1.4012985e-45,0.99736351,3.1157346,18.00057,316.38623,-11.481951
170.8612,0.67293352,9.4728994,0.0,0,18.0,1.4012985e-45,0.99836016,3.1590025,17.999222,306.87619,-11.482216
172.0612,0.67696053,9.4787788,0.0,0,18.0,1.4012985e-45,0.99952996,3.1685927,17.999962,297.96451,-11.481986
173.2612,0.68213278,9.4841928,0.0,0,18.0,1.4012985e-45,1.0003734,3.1995761,17.99988,289.4462,-11.481708
174.4612,0.69119197,9.4889126,0.0,0,18.0,1.4012985e-45,1.0013527,3.2326274,18.000704,281.2897,-11.4816
175.6612,0.6879499,9.4944925,0.0,0,18.0,1.4012985e-45,1.0023314,3.21804,18.000431,273.27695,-11.481762
176.8612,0.70381486,9.5000877,0.0,0,18.0,1.4012985e-45,1.0033184,3.2798429,17.999195,265.30649,-11.482149
178.0612,0.70093274,9.5051365,0.0,0,18.0,1.4012985e-45,1.0042151,3.2706573,17.999929,257.52005,-11.482451
179.2612,0.7077952,9.5100718,0.0,0,18.0,1.4012985e-45,1.0051318,3.2941744,17.999634,250.14224,-11.482238
180.4612,0.70995575,9.5153837,0.0,0,18.0,1.4012985e-45,1.0061826,3.3063743,18.000122,242.96719,-11.482272
181.6612,0.72351867,9.5198088,0.0,0,18.0,1.4012985e-45,1.006839,3.3653853,17.999786,235.56279,-11.482224
182.8612,0.71270472,9.5244932,0.0,0,18.0,1.4012985e-45,1.0078294,3.3145554,18.000145,229.08011,-11.48218
184.0612,0.72858083,9.5288506,0.0,0,18.0,1.4012985e-45,1.0085731,3.3881552,17.999758,222.42198,-11.482759
185.2612,0.7246998,9.53333,0.0,0,18.0,1.4012985e-45,1.009403,3.3649592,18.000124,215.84604,-11.482806
186.4612,0.73680991,9.5376234,0.0,0,18.0,1.4012985e-45,1.0101008,3.4178748,17.999872,209.25801,-11.481674
187.6612,0.74071705,9.5416594,0.0,0,18.0,1.4012985e-45,1.0109221,3.4301188,17.99972,203.01923,-11.481836
188.8612,0.74389344,9.5457048,0.0,0,18.0,1.4012985e-45,1.0117309,3.445353,18.000788,197.1449,-11.48143
190.0612,0.74298376,9.5496626,0.0,0,18.0,1.4012985e-45,1.012316,3.4338853,18.000391,191.69228,-11.48207
191.2612,0.75559098,9.553503,0.0,0,18.0,1.4012985e-45,1.0130905,3.5012004,18.000126,186.53787,-11.48245
192.4612,0.75612885,9.5570335,0.0,0,18.0,1.4012985e-45,1.0137029,3.4888489,17.999592,181.3999,-11.482981
193.6612,0.75674021,9.5605803,0.0,0,18.0,1.4012985e-45,1.0144495,3.4982021,17.999887,176.50694,-11.483171
194.8612,0.75910997,9.5644274,0.0,0,18.0,1.4012985e-45,1.0150162,3.4985423,17.999693,171.68158,-11.48247
196.0612,0.76429087,9.5682192,0.0,0,18.0,1.4012985e-45,1.0158339,3.5271816,17.999907,167.43896,-11.482508
197.2612,0.76694363,9.5711069,0.0,0,18.0,1.4012985e-45,1.016342,3.5345149,18.000528,163.14871,-11.482477
198.4612,0.77446854,9.5748281,0.0,0,18.0,1.4012985e-45,1.0169766,3.5718904,17.999378,159.40829,-11.482412
199.6612,0.77841854,9.5777159,0.0,0,18.0,1.4012985e-45,1.0175029,3.5799437,17.999699,155.48242,-11.481994
200.8612,0.77977061,9.5805769,0.0,0,18.0,1.4012985e-45,1.0180662,3.5867939,18.000299,151.51643,-11.482907
202.0612,0.78766018,9.5835934,0.0,0,18.0,1.4012985e-45,1.0186805,3.619427,17.99988,148.27435,-11.482827
203.2612,0.78617954,9.5869246,0.0,0,18.0,1.4012985e-45,1.0191598,3.6090007,17.999557,145.25075,-11.482382
204.4612,0.79079449,9.5893784,0.0,0,18.0,1.4012985e-45,1.0197197,3.6331463,17.999084,141.35982,-11.482079
205.6612,0.78627485,9.5923195,0.0,0,18.0,1.4012985e-45,1.0202247,3.606195,17.998848,137.70224,-11.481666
206.8612,0.79893708,9.5939989,0.0,0,18.0,1.4012985e-45,1.0206004,3.6682403,17.999992,134.28761,-11.482375
208.0612,0.79408383,9.5978346,0.0,0,18.0,1.4012985e-45,1.0211722,3.6385753,17.999138,130.89838,-11.482798
209.2612,0.80514795,9.5997601,0.0,0,18.0,1.4012985e-45,1.0216719,3.6925442,18.000481,127.40781,-11.483304
210.4612,0.79041636,9.6020594,0.0,0,18.0,1.4012985e-45,1.0220743,3.6194561,18.000788,124.26385,-11.482433
211.6612,0.80249196,9.6045446,0.0,0,18.0,1.4012985e-45,1.0224537,3.6835518,17.999441,121.11398,-11.482509
212.8612,0.79462743,9.6072025,0.0,0,18.0,1.4012985e-45,1.022971,3.6312332,17.999538,118.22777,-11.481497
214.0612,0.80670738,9.6096125,0.0,0,18.0,1.4012985e-45,1.0234368,3.6963441,17.999945,115.29811,-11.481923
215.2612,0.81434804,9.6114912,0.0,0,18.0,1.4012985e-45,1.0238621,3.7208633,17.999981,112.41208,-11.482818
216.4612,0.79533434,9.6138115,0.0,0,18.0,1.4012985e-45,1.0241468,3.6448505,18.000044,109.6057,-11.482714
217.6612,0.81229854,9.6154356,0.0,0,18.0,1.4012985e-45,1.0245522,3.7091644,17.998997,107.07161,-11.483191
218.8612,0.80180526,9.6172695,0.0,0,18.0,1.4012985e-45,1.0248207,3.6726837,17.998697,104.39285,-11.483125
220.0612,0.80548936,9.6193924,0.0,0,18.0,1.4012985e-45,1.0253271,3.6763737,17.999887,101.98882,-11.482897
221.2612,0.80592334,9.6215067,0.0,0,18.0,1.4012985e-45,1.0255774,3.6815405,17.998974,99.606133,-11.48312
222.4612,0.81214887,9.6233854,0.0,0,18.0,1.4012985e-45,1.02604,3.7082634,17.999598,97.295013,-11.482647
223.6612,0.79498726,9.6252689,0.0,0,18.0,1.4012985e-45,1.0263716,3.6236341,17.999907,95.131546,-11.482332
224.8612,0.80971724,9.6276636,0.0,0,18.0,1.4012985e-45,1.026796,3.6994534,18.00029,92.893379,-11.482015
225.8612,0.82005394,9.628541,0.0,0,18.0,1.4012985e-45,1.0269271,3.7351856,18.000345,91.168747,-11.482252