File: examples/dan-msc-case-studies/CS3/data/01 raw data/baron_test_150.csv
Time(sec),Force(kN),Jaw(mm),PowAngle(deg),Power(W),Pram,PTemp,Strain,Stress(MPa),Stroke(mm),TC1(C),wedge(mm)
0.0,1.2132286,0.32549518,0.0,0,10.594783,0.0015217453,0.021931805,15.085735,10.595604,24.792152,-9.112936
2.2,1.1083941,-0.0029215263,0.0,0,10.594783,6.5159154,-0.00018718264,14.137591,10.595192,24.672781,-9.4803629
4.4,1.0634142,-0.0028855994,0.0,0,10.594783,13.115913,-0.00020256435,13.562606,10.595378,24.676607,-9.4771338
6.6,1.0418662,-0.0029915699,0.0,0,10.594783,19.715914,-0.00018357104,13.260802,10.594687,24.620064,-9.4729004
8.8,1.0397978,-0.002393669,7.9837279,0,10.594783,26.315914,-0.00017945611,13.239576,10.594336,24.679613,-9.468749
11.0,1.0402602,-0.0021632845,36.642746,0,10.594783,32.915905,-0.00014269991,13.245642,10.594836,25.679174,-9.4658232
13.2,1.0567447,-0.0070060464,47.462006,0,10.594783,39.515907,-0.0004495683,13.465031,10.593924,30.451479,-9.4620876
15.4,1.0893896,-0.015809638,52.219261,0,10.594783,46.115913,-0.0010833263,13.883651,10.59518,38.511166,-9.4585505
17.6,1.1274648,-0.026129765,52.635876,0,10.594783,52.715912,-0.0017415554,14.381797,10.594213,49.308571,-9.4544706
19.8,1.139294,-0.035126504,49.679554,0,10.594783,59.315918,-0.0023390737,14.55141,10.59403,60.563995,-9.4508963
22.0,1.1452893,-0.041893173,44.613213,0,10.594783,65.915894,-0.0028094125,14.616911,10.596606,70.142822,-9.4472532
24.2,1.1332314,-0.045362636,40.377781,0,10.594783,72.515907,-0.0030104297,14.459731,10.594402,76.685768,-9.4434023
26.4,1.114567,-0.047598284,39.700924,0,10.594783,79.115906,-0.0031741867,14.246485,10.594149,81.000526,-9.4396973
28.6,1.0995185,-0.05058416,42.522129,0,10.594783,85.715912,-0.0033669106,14.058517,10.59471,84.806694,-9.4359941
30.8,1.1199027,-0.055064257,46.579124,0,10.594783,92.31591,-0.0036414959,14.306943,10.595097,89.357445,-9.4324942
33.0,1.146873,-0.060971778,50.033813,0,10.594783,98.915909,-0.0040807705,14.662652,10.59429,95.091759,-9.4289255
35.2,1.1544805,-0.069403477,51.92403,0,10.594783,105.51591,-0.0046157436,14.766479,10.595923,102.32511,-9.4247713
37.4,1.1581279,-0.076683529,51.932377,0,10.594783,112.11589,-0.0050749104,14.823879,10.594245,110.72903,-9.4211159
39.6,1.1702855,-0.08367113,50.93816,0,10.594783,118.71588,-0.0055838707,14.960789,10.594731,119.04372,-9.4173193
41.8,1.1790322,-0.090527698,50.042728,0,10.594783,125.31589,-0.0060084765,15.111689,10.595307,126.39519,-9.4138241
44.0,1.1689355,-0.096258797,48.812538,0,10.594783,131.91586,-0.0063678212,14.976865,10.594266,133.1981,-9.4105721
46.2,1.161666,-0.10057414,48.809338,0,10.594783,138.51588,-0.0066956789,14.895479,10.594219,139.15685,-9.4061117
48.4,1.1763484,-0.10574301,49.636227,0,10.594783,145.11589,-0.0070191049,15.075746,10.595186,144.52797,-9.402544
50.6,1.1809059,-0.11186156,51.56863,0,10.594783,151.7159,-0.0073970789,15.144516,10.594957,149.87535,-9.3990679
52.8,1.1740779,-0.1183521,52.97607,0,10.594783,158.31587,-0.007872886,15.071026,10.595008,156.06877,-9.39536
55.0,1.1783888,-0.12520972,53.975826,0,10.594783,164.91588,-0.0083062863,15.127026,10.594371,163.18056,-9.3917065
57.2,1.18809,-0.13307805,54.305416,0,10.594783,171.51588,-0.0088075902,15.250468,10.595403,170.38501,-9.3884001
59.4,1.1872855,-0.14007026,54.624023,0,10.594783,178.11588,-0.0093139308,15.271524,10.595113,177.48701,-9.3845911
61.6,1.1849024,-0.14596854,54.624023,0,10.594783,184.71587,-0.009681209,15.230072,10.594836,184.46899,-9.3806963
63.8,1.1805179,-0.15228076,54.624023,0,10.594783,191.31587,-0.010082971,15.181156,10.595232,191.07675,-9.3769722
66.0,1.1897119,-0.15883669,54.931637,0,10.594783,197.91586,-0.010539858,15.311392,10.595062,197.44653,-9.3735104
68.2,1.17551,-0.16549648,54.632927,0,10.594783,204.51587,-0.010976463,15.129329,10.594554,204.53922,-9.3694382
70.4,1.1810708,-0.1709936,54.752403,0,10.594783,211.11588,-0.011328348,15.194702,10.594999,211.092,-9.3663502
72.6,1.1916083,-0.17936975,55.238789,0,10.594783,217.71588,-0.01187648,15.343344,10.594677,217.21797,-9.3628473
74.8,1.1940155,-0.18520367,55.710648,0,10.594783,224.31587,-0.012298252,15.404504,10.594577,223.48647,-9.359334
77.0,1.1840774,-0.19126819,56.425114,0,10.594783,230.91588,-0.012669872,15.277273,10.596033,229.84486,-9.3549986
79.2,1.1876907,-0.19798551,56.711422,0,10.594783,237.51587,-0.013087178,15.311957,10.595558,236.66203,-9.3515196
81.4,1.1889918,-0.20475179,56.986084,0,10.594783,244.11586,-0.013581034,15.337567,10.594719,243.4456,-9.3475142
83.6,1.1871957,-0.21213947,57.253876,0,10.594783,250.71585,-0.01404004,15.325589,10.593488,250.11084,-9.3439312
85.8,1.1806324,-0.21843804,57.534843,0,10.594783,257.3161,-0.014446416,15.254824,10.594614,256.71744,-9.3403215
88.0,1.1871144,-0.22510381,57.810051,0,10.594783,263.91589,-0.014891974,15.319246,10.594676,263.29077,-9.3372974
90.2,1.1837236,-0.23224844,58.073727,0,10.594783,270.51587,-0.015385662,15.316806,10.593669,269.85806,-9.3332033
92.4,1.1864401,-0.23923323,58.330341,0,10.594783,277.11584,-0.015831852,15.368757,10.59412,276.61194,-9.3297291
94.6,1.1778507,-0.24617203,58.59008,0,10.594783,283.71585,-0.016255222,15.251493,10.594171,283.13776,-9.3257647
96.8,1.1761291,-0.25270677,58.853752,0,10.594783,290.31586,-0.016727878,15.22486,10.59437,289.72876,-9.3221054
99.0,1.185236,-0.2591947,59.348122,0,10.594783,296.91586,-0.017124265,15.352166,10.593357,296.09055,-9.3184185
101.2,1.1907771,-0.26611811,59.768276,0,10.594783,303.51587,-0.017580468,15.432766,10.593667,302.57843,-9.315238
103.4,1.1879487,-0.27322632,60.084225,0,10.594783,310.11584,-0.01804415,15.405668,10.594532,309.11859,-9.3117781
105.6,1.1921761,-0.2803314,60.556637,0,10.594783,316.71585,-0.018544251,15.444306,10.594321,315.71512,-9.3078527
107.8,1.200955,-0.28737617,60.787346,0,10.594783,323.31583,-0.018965216,15.58093,10.594556,322.47098,-9.3043432
110.0,1.2035868,-0.29642758,61.018063,0,10.594783,329.91586,-0.019550763,15.643802,10.594625,329.2872,-9.3005371
112.2,1.1877033,-0.30276036,61.137863,0,10.594783,336.51587,-0.019990321,15.431734,10.594889,336.14572,-9.2967768
114.4,1.1962637,-0.30970049,61.237789,0,10.594783,343.11584,-0.02045658,15.533277,10.593966,342.9234,-9.2933636
116.6,1.2035285,-0.31759155,61.239033,0,10.594783,349.71585,-0.020941896,15.649883,10.59428,349.40399,-9.2901649
118.8,1.1992041,-0.32517356,61.468498,0,10.594783,356.31586,-0.021421611,15.607686,10.595161,355.95151,-9.286787
121.0,1.1778557,-0.33320346,61.688229,0,10.594783,362.91586,-0.021979984,15.343088,10.595605,362.42715,-9.2832165
123.2,1.2027633,-0.3398858,61.969769,0,10.594783,369.51584,-0.022414962,15.651716,10.595602,368.82339,-9.2794781
125.4,1.2076328,-0.34851328,62.336418,0,10.594783,376.11581,-0.02296425,15.736176,10.594093,375.25571,-9.2755699
127.6,1.1968104,-0.3550466,62.75386,0,10.594783,382.71582,-0.023372611,15.616739,10.595448,381.81357,-9.2718964
129.8,1.2003673,-0.36341926,62.962639,0,10.594783,389.31583,-0.023938246,15.649074,10.593814,388.52014,-9.2681723
132.0,1.2094867,-0.37065455,63.14167,0,10.594783,395.91583,-0.0244305,15.769004,10.594861,395.34753,-9.2642994
134.2,1.2117963,-0.37915066,63.057476,0,10.594783,402.51584,-0.024962375,15.826428,10.593397,402.42816,-9.260808
136.4,1.2051412,-0.38801315,62.78545,0,10.594783,409.11584,-0.025533795,15.750314,10.594714,409.44788,-9.2571592
138.6,1.1940324,-0.39587498,62.623928,0,10.594783,415.71585,-0.026027737,15.607734,10.594692,416.25516,-9.2542944
140.8,1.2106894,-0.40335026,62.336433,0,10.594783,422.31583,-0.026556881,15.831887,10.595475,422.89795,-9.2502832
143.0,1.2117182,-0.40759957,62.336418,0,10.594783,428.91583,-0.026826467,15.829357,10.595091,429.27054,-9.2471008
145.2,1.2060328,-0.41492054,62.545162,0,10.594783,435.51581,-0.027280807,15.78755,10.594602,435.36795,-9.2433987
147.4,1.1907458,-0.42168897,62.753899,0,10.594783,442.11581,-0.027706539,15.589397,10.593161,441.63565,-9.2390327
149.6,1.1968479,-0.42696396,62.962639,0,10.594783,448.71579,-0.0280596,15.66544,10.594555,448.18036,-9.2354364
151.8,1.2108479,-0.43478921,62.988373,0,10.594783,455.3158,-0.028606052,15.858005,10.594374,455.00513,-9.2314615
154.0,1.1997083,-0.43780884,63.005745,0,10.594783,461.9158,-0.028775163,15.727721,10.594747,461.75424,-9.2277431
156.2,1.1881576,-0.44327721,63.030727,0,10.594783,468.51584,-0.029120427,15.588331,10.594682,468.43387,-9.2244396
158.4,1.1660236,-0.44721088,63.007034,0,10.594783,475.11584,-0.029363286,15.281898,10.594893,475.10568,-9.2207537
160.6,1.1628518,-0.44837707,63.118176,0,10.594783,481.71582,-0.029442493,15.225017,10.595247,481.60226,-9.217145
162.8,1.1585715,-0.45169699,63.171314,0,10.594783,488.31583,-0.02969984,15.201751,10.595128,488.20059,-9.2142477
165.0,1.1194801,-0.45125628,62.96265,0,10.594783,494.9158,-0.029649818,14.690468,10.595037,495.20944,-9.210537
167.2,1.0944753,-0.45196736,61.72979,0,10.594783,499.99884,-0.029673068,14.359376,10.594459,502.41721,-9.2079039
169.4,1.0639464,-0.44645804,56.643669,0,10.594783,499.99884,-0.029321982,13.952396,10.594239,507.93826,-9.2081823
171.6,1.0371599,-0.43364811,50.448238,0,10.594783,499.99884,-0.028484635,13.590304,10.595687,509.43765,-9.2080154
173.8,1.0289251,-0.42235476,47.054455,0,10.594783,499.99884,-0.027782852,13.471466,10.594888,506.34381,-9.2079697
176.0,1.0215979,-0.41052508,48.378723,0,10.594783,499.99884,-0.027018882,13.365655,10.594356,501.38977,-9.2076769
178.2,1.0263449,-0.40559465,52.887653,0,10.594783,499.99884,-0.026684923,13.415219,10.594342,496.59988,-9.2077494
180.4,1.0357049,-0.40541831,57.225861,0,10.594783,499.99884,-0.026665581,13.561365,10.594966,493.88623,-9.2075415
182.6,1.0750681,-0.40676406,59.842506,0,10.594783,499.99884,-0.026729235,14.062501,10.59449,493.98169,-9.2075958
184.8,1.0937183,-0.40985432,60.568581,0,10.594783,499.99884,-0.026946578,14.301186,10.593905,496.68179,-9.2073059
187.0,1.073897,-0.40958256,59.601234,0,10.594783,499.99884,-0.026949292,14.038831,10.594065,500.23398,-9.2073517
189.2,1.0483294,-0.4093473,56.990288,0,10.594783,499.99884,-0.026945751,13.712612,10.59518,503.40652,-9.2074471
191.4,1.0187339,-0.4061771,53.984657,0,10.594783,499.99884,-0.026731975,13.313708,10.594812,504.72922,-9.2069616
193.6,1.0192634,-0.40017003,51.569851,0,10.594783,499.99884,-0.026321815,13.308025,10.594921,504.32813,-9.2073765
195.8,1.0198653,-0.39234844,51.179237,0,10.594783,499.99884,-0.025824565,13.316181,10.594188,502.07071,-9.2077608
198.0,1.0267425,-0.3890292,52.635353,0,10.594783,499.99884,-0.025578128,13.410275,10.594468,499.23798,-9.207346
200.2,1.0455897,-0.38746661,54.931057,0,10.594783,499.99884,-0.025481908,13.641684,10.594733,497.37814,-9.2073269
202.4,1.0470998,-0.38639435,56.71138,0,10.594783,499.99884,-0.025435098,13.680909,10.595121,496.93549,-9.2071466
204.6,1.059581,-0.38580099,57.535389,0,10.594783,499.99884,-0.025411835,13.822066,10.595017,497.77838,-9.207242
206.8,1.053849,-0.38604441,57.535412,0,10.594783,499.99884,-0.025434485,13.767165,10.594139,499.11627,-9.2069941
209.0,1.0361152,-0.38560483,56.43211,0,10.594783,499.99884,-0.025390144,13.537973,10.594398,500.89008,-9.207303
211.2,1.0332972,-0.38427347,55.16642,0,10.594783,499.99884,-0.025279293,13.495181,10.595407,501.95963,-9.2074671
211.9541,1.0210245,0.027860137,54.624023,0,10.5948,1.5409876e-16,0.0017776493,12.986075,10.593764,502.2644,-9.2078285
211.9585,1.0321013,0.035060853,51.892761,0,10.5948,0.0,0.0021886409,13.015688,10.592017,502.2674,-9.2057114
211.9629,1.0849376,0.032527175,27.858192,0,10.5948,0.0,0.002167441,13.815103,10.595486,502.29364,-9.2066383
211.9673,1.0217811,0.035996277,3.8236215,0,10.5948,0.0,0.00222028,13.02945,10.595327,502.31992,-9.2079363
211.9717,1.0017744,0.029511584,0.0,0,10.5948,0.0,0.0019708399,12.825964,10.595942,502.302,-9.205677
211.9761,1.0051653,0.034537155,0.0,0,10.5948,0.0,0.0021988996,12.830552,10.597685,502.27576,-9.2080803
211.9805,1.0123599,0.029761953,0.0,0,10.5948,0.0,0.001958437,12.794871,10.596274,502.23456,-9.2077065
211.9849,1.0139432,0.036318723,0.0,0,10.5948,0.0,0.0022749747,12.87018,10.595144,502.18204,-9.2075672
211.9893,0.9959867,0.031120742,0.0,0,10.5948,0.0,0.0020182368,12.636455,10.593395,502.13727,-9.2079544
211.9937,0.99656916,0.034535427,0.0,0,10.5948,0.0,0.0021847086,12.647486,10.594775,502.11099,-9.2055273
211.9981,1.0143703,0.031887654,0.0,0,10.5948,0.0,0.0021591068,12.909317,10.594194,502.08652,-9.2071838
212.0025,1.0183305,0.035340227,0.0,0,10.578863,0.0,0.0022388981,12.98283,10.596996,502.13904,-9.2066135
212.0069,0.99575108,0.032277718,0.0,0,10.512864,0.0,0.0021014735,12.664173,10.595045,502.19159,-9.2080631
212.0113,1.0004158,0.033730164,0.0,0,10.446864,0.0,0.0021698973,12.7907,10.58581,502.2244,-9.2074842
212.0157,1.0092996,0.032239068,0.0,0,10.380864,0.0,0.0021432526,12.793775,10.529459,502.25067,-9.2077322
212.0201,1.0042776,0.036325302,0.0,0,10.314864,0.0,0.0023934406,12.7676,10.42977,502.27695,-9.2066002
212.0245,1.003021,0.032405201,0.0,0,10.248864,0.0,0.0021340323,12.761628,10.329901,502.30319,-9.2067032
212.0289,0.99602056,0.035618331,0.0,0,10.182864,0.0,0.0023574871,12.721821,10.253915,502.32947,-9.2081575
212.0333,1.0018132,0.032199159,0.0,0,10.116864,0.0,0.0021712948,12.659532,10.198746,502.35574,-9.2067823
212.0377,1.0089903,0.035949349,0.0,0,10.050864,0.0,0.0024384956,12.88038,10.146502,502.38199,-9.2073078
212.0421,1.0078963,0.032417864,0.0,0,9.9848633,0.0,0.0022235601,12.83646,10.082591,502.34708,-9.2067089
212.0465,1.4595259,0.038165875,0.0,0,9.9188633,0.0,0.002621542,18.236916,10.018544,502.30768,-9.2073431
212.0509,3.0216944,0.067418166,0.0,0,9.8528633,0.0,0.0044803699,38.304298,9.9563913,502.3981,-9.2049847
212.0553,3.2311201,0.14562762,0.0,0,9.7868633,0.0,0.0097024376,40.730026,9.8813734,502.55569,-9.2052126
212.0597,3.2728171,0.21602656,0.0,0,9.7208633,0.0,0.014517155,40.996078,9.7976341,502.61182,-9.2057133
212.0641,3.2860548,0.28650689,0.0,0,9.6548634,0.0,0.019358482,41.083088,9.7323446,502.50674,-9.2057734
212.0685,3.2953284,0.34462404,0.0,0,9.5888634,0.0,0.023248926,40.861771,9.6698475,502.27039,-9.2055597
212.0729,3.3267858,0.4060027,0.0,0,9.5228634,0.0,0.027539788,41.17308,9.605444,501.00974,-9.2056103
212.0773,3.3681717,0.47141656,0.0,0,9.4574747,0.0,0.031948719,41.592159,9.5419569,499.74908,-9.2055225
212.0817,3.383894,0.54026467,0.0,0,9.393095,0.0,0.03680351,41.557896,9.4730787,500.7739,-9.2059498
212.0861,3.4099712,0.604258,0.0,0,9.3287144,0.0,0.04115865,41.652611,9.4044638,502.23105,-9.2058334
212.0905,3.4208293,0.67061192,0.0,0,9.2643328,0.0,0.045866262,41.715919,9.3420639,504.22546,-9.2063179
212.0949,3.4278326,0.73450702,0.0,0,9.1999531,0.0,0.050251029,41.491402,9.2727489,506.62814,-9.2052393
212.0993,3.4309273,0.80256867,0.0,0,9.1355715,0.0,0.055081278,41.373596,9.2052975,508.79401,-9.2054205
212.1037,3.4586904,0.86407536,0.0,0,9.0711908,0.0,0.059403259,41.470509,9.1405849,510.39523,-9.2059755
212.1081,3.4621713,0.9262175,0.0,0,9.0068102,0.0,0.0638749,41.343426,9.0763254,512.01794,-9.2057133
212.1125,3.4559331,0.98558998,0.0,0,8.9424286,0.0,0.068097129,41.124523,9.0153465,514.56415,-9.2069683
212.1169,3.5008137,1.0520833,0.0,0,8.8780489,0.0,0.072865866,41.416721,8.9495783,517.11041,-9.2044382
212.1213,3.5216017,1.1151239,0.0,0,8.8136673,0.0,0.077336244,41.395687,8.8823147,518.85907,-9.20613
212.1257,3.562614,1.1787206,0.0,0,8.7493448,0.0,0.082049109,41.860023,8.8179407,520.34192,-9.2065372
212.1301,3.5743122,1.2443221,0.0,0,8.6880999,0.0,0.086790353,41.759766,8.7466307,521.43011,-9.2071838
212.1345,3.5520322,1.3090045,0.0,0,8.6268702,0.0,0.091601558,41.224689,8.6875257,522.08606,-9.2073784
212.1389,3.5521541,1.368718,0.0,0,8.5656395,0.0,0.095874898,41.085442,8.6199617,522.742,-9.2052135
212.1433,3.5833375,1.4282252,0.0,0,8.5044088,0.0,0.10026264,41.262482,8.5641251,523.39795,-9.2054367
212.1477,3.5994809,1.4857361,0.0,0,8.4431791,0.0,0.10448724,41.344585,8.4992256,524.05389,-9.2056351
212.1521,3.6032722,1.5492377,0.0,0,8.3819485,0.0,0.10922806,41.176319,8.4396811,524.56317,-9.2058048
212.1565,3.6209433,1.6080273,0.0,0,8.3207188,0.0,0.11362863,41.182571,8.3793592,525.06171,-9.2067127
212.1609,3.6703601,1.670661,0.0,0,8.2594881,0.0,0.11830452,41.462704,8.3140831,525.59479,-9.2049675
212.1653,3.6896608,1.7336663,0.0,0,8.1982584,0.0,0.12307908,41.608063,8.2497911,526.14575,-9.205862
212.1697,3.6765032,1.7963902,0.0,0,8.1370277,0.0,0.12779717,41.246986,8.1914768,526.80322,-9.2059116
212.1741,3.6877844,1.858235,0.0,0,8.0757971,0.0,0.13252737,41.100956,8.1263371,527.62964,-9.2057772
212.1785,3.7214403,1.9171737,0.0,0,8.0165014,0.0,0.13699418,41.276047,8.0635557,528.39948,-9.2061958
212.1829,3.7500753,1.978844,0.0,0,7.9582458,0.0,0.14164896,41.434853,8.0012665,528.72742,-9.2056284
212.1873,3.7078681,2.0337586,0.0,0,7.8999891,0.0,0.14602803,40.883316,7.9441557,529.05542,-9.2053833
212.1917,3.716377,2.0933766,0.0,0,7.8417335,0.0,0.15056752,40.722286,7.8860087,529.16278,-9.2064514
212.1961,3.7439818,2.1470673,0.0,0,7.7834773,0.0,0.15478908,40.841656,7.8301396,529.22839,-9.2068129
212.2005,3.7691076,2.2033677,0.0,0,7.7252216,0.0,0.15910928,40.952999,7.7715478,529.48035,-9.2076845
212.2049,3.8135459,2.2619634,0.0,0,7.666965,0.0,0.16377924,41.222359,7.7141261,529.87384,-9.2046547
212.2093,3.814383,2.3215656,0.0,0,7.6087093,0.0,0.16840565,41.041729,7.652607,530.33716,-9.2049913
212.2137,3.81089,2.379287,0.0,0,7.5504532,0.0,0.1730511,40.862255,7.5939865,530.96686,-9.2065859
212.2181,3.8427844,2.4369872,0.0,0,7.4921975,0.0,0.17754515,40.825069,7.5332298,531.59033,-9.2051468
212.2225,3.8818345,2.4932592,0.0,0,7.4339414,0.0,0.18206248,41.171432,7.4759426,531.94458,-9.2048683
212.2269,3.876255,2.552458,0.0,0,7.3765039,0.0,0.18670671,40.955063,7.4164443,532.29877,-9.2063646
212.2313,3.9002345,2.6092861,0.0,0,7.3210988,0.0,0.1913996,40.997311,7.3579025,532.62347,-9.2061243
212.2357,3.8997378,2.6682458,0.0,0,7.2656941,0.0,0.19609866,40.810478,7.299417,532.93829,-9.2046528
212.2401,3.9190328,2.7214484,0.0,0,7.210289,0.0,0.20039995,40.892044,7.2456317,533.30328,-9.205205
212.2445,3.9251668,2.7770143,0.0,0,7.1548843,0.0,0.2048915,40.70639,7.1897407,533.72308,-9.2050009
212.2489,3.9676251,2.834007,0.0,0,7.0994792,0.0,0.20961222,40.932644,7.1340427,534.15094,-9.2054167
212.2533,3.9616046,2.8926246,0.0,0,7.044075,0.0,0.21438183,40.697887,7.0725942,534.61011,-9.2057266
212.2577,3.9812994,2.9440556,0.0,0,6.9886694,0.0,0.21867365,40.73391,7.0213866,535.06927,-9.20613
212.2621,3.9984479,3.0005777,0.0,0,6.9332652,0.0,0.22330922,40.646194,6.9637017,535.2962,-9.2049599
212.2665,3.9805722,3.0546949,0.0,0,6.8778601,0.0,0.22784095,40.309921,6.9121003,535.50616,-9.2054815
212.2709,4.0413046,3.1076846,0.0,0,6.8224554,0.0,0.2322077,40.775425,6.8538365,535.62103,-9.2053299
212.2753,4.0684252,3.1622968,0.0,0,6.7670503,0.0,0.23684363,40.895782,6.7984252,535.68665,-9.204155
212.2797,4.0763111,3.2202983,0.0,0,6.7141318,0.0,0.24175622,40.802643,6.7427683,535.76746,-9.2056684
212.2841,4.0826883,3.2744942,0.0,0,6.6614199,0.0,0.2464053,40.596249,6.6831465,535.87244,-9.205287
212.2885,4.0473433,3.3256805,0.0,0,6.6087079,0.0,0.25082096,40.024158,6.633646,535.97443,-9.205719
212.2929,4.0739102,3.3750618,0.0,0,6.5559959,0.0,0.25494829,40.219128,6.5844045,536.05316,-9.2060833
212.2973,4.1191044,3.4276958,0.0,0,6.503284,0.0,0.25942302,40.485291,6.5302258,536.1319,-9.2044563
212.3017,4.1120086,3.4770136,0.0,0,6.450572,0.0,0.26379415,40.310593,6.4790707,536.1665,-9.2064199
212.3061,4.1431537,3.5323451,0.0,0,6.3978601,0.0,0.26860929,40.311817,6.4251509,536.19275,-9.2050591
212.3105,4.1855216,3.583833,0.0,0,6.3451481,0.0,0.27295706,40.584785,6.3725214,536.21899,-9.2064724
212.3149,4.1862488,3.6392908,0.0,0,6.2924366,0.0,0.27794582,40.365116,6.3192787,536.24524,-9.2056351
212.3193,4.1995473,3.692776,0.0,0,6.2397246,0.0,0.282552,40.318466,6.2628632,536.22498,-9.2057981
212.3237,4.2016635,3.7414718,0.0,0,6.1870127,0.0,0.28686428,40.20723,6.2137766,536.09369,-9.2056427
212.3281,4.2601876,3.7963667,0.0,0,6.1357436,0.0,0.29177952,40.450256,6.1585803,535.96423,-9.2057362
212.3325,4.2486243,3.8503339,0.0,0,6.0856099,0.0,0.29645255,40.150017,6.1065021,535.9118,-9.2049875
212.3369,4.2546177,3.8980386,0.0,0,6.0354762,0.0,0.30084965,40.189053,6.0548401,535.85931,-9.2034349
212.3413,4.2462549,3.9504647,0.0,0,5.9853425,0.0,0.30551639,39.790123,6.0033555,535.95447,-9.2065878
212.3457,4.2937489,3.9961224,0.0,0,5.9352088,0.0,0.309697,40.090393,5.955512,536.09882,-9.2039766
212.3501,4.3548555,4.0522623,0.0,0,5.8850756,0.0,0.31475154,40.474346,5.9008417,536.18677,-9.2041826
212.3545,4.30446,4.1021657,0.0,0,5.8349419,0.0,0.31931725,39.856609,5.8514724,536.21301,-9.2049561
212.3589,4.3129959,4.1517291,0.0,0,5.7848082,0.0,0.32384032,39.709396,5.8029695,536.21509,-9.2048798
212.3633,4.3627844,4.2000446,0.0,0,5.7346745,0.0,0.3283703,39.938499,5.7545261,536.12323,-9.2056427
212.3677,4.3968334,4.2515693,0.0,0,5.6845412,0.0,0.33308125,40.119583,5.6987572,536.03143,-9.2053375
212.3721,4.3874903,4.2992463,0.0,0,5.634407,0.0,0.33757401,39.916435,5.6537848,535.90289,-9.2048826
212.3765,4.3837194,4.3521652,0.0,0,5.5847516,0.0,0.34234291,39.654587,5.6033711,535.77167,-9.2048998
212.3809,4.4259562,4.3994031,0.0,0,5.5370555,0.0,0.34685373,39.894711,5.549243,535.72693,-9.2050266
212.3853,4.4637008,4.4507375,0.0,0,5.4893594,0.0,0.35169828,39.962479,5.5020127,535.72693,-9.203968
212.3897,4.4611993,4.4952435,0.0,0,5.4416633,0.0,0.35600239,39.831757,5.4537072,535.76746,-9.2045469
212.3941,4.4231038,4.5441489,0.0,0,5.3939681,0.0,0.36051822,39.306423,5.4057994,535.87244,-9.2057066
212.3985,4.4585214,4.5880136,0.0,0,5.346272,0.0,0.36484057,39.418385,5.35953,535.98187,-9.2058344
212.4029,4.5090699,4.6389308,0.0,0,5.2985759,0.0,0.36959758,39.66901,5.3096967,536.12622,-9.2049561
212.4073,4.5405388,4.684999,0.0,0,5.2508798,0.0,0.37417594,39.746571,5.2659664,536.27063,-9.2054701
212.4117,4.5048132,4.7345219,0.0,0,5.2031837,0.0,0.37886399,39.344826,5.2159019,536.43701,-9.2049093
212.4161,4.5481009,4.7745695,0.0,0,5.155488,0.0,0.38282794,39.462143,5.1745181,536.6076,-9.2049875
212.4205,4.5969553,4.8287697,0.0,0,5.1077919,0.0,0.38801685,39.664989,5.1203222,536.78564,-9.2041597
212.4249,4.6521792,4.8767695,0.0,0,5.0600958,0.0,0.39278385,40.022236,5.0710254,536.96936,-9.2059555
212.4293,4.6008258,4.9278216,0.0,0,5.0143409,0.0,0.39778697,39.413425,5.026196,537.14923,-9.2063494
212.4337,4.6162386,4.9722872,0.0,0,4.968977,0.0,0.40231544,39.324608,4.978281,537.31982,-9.2054882
212.4381,4.646595,5.0227189,0.0,0,4.9236126,0.0,0.40718031,39.30489,4.9322405,537.48926,-9.2056351
212.4425,4.6876574,5.0629807,0.0,0,4.8782492,0.0,0.41136727,39.551586,4.8828425,537.60736,-9.2051144
212.4469,4.6770382,5.1127982,0.0,0,4.8328848,0.0,0.41633528,39.250835,4.8374224,537.72546,-9.2048321
212.4513,4.6380658,5.1535797,0.0,0,4.7875209,0.0,0.42042747,38.817078,4.7965555,537.82391,-9.2055197
212.4557,4.7031875,5.2020211,0.0,0,4.7421565,0.0,0.42525113,39.073399,4.7519665,537.91571,-9.2054605
212.4601,4.7408934,5.2387295,0.0,0,4.6967926,0.0,0.42909107,39.318699,4.7101221,538.00134,-9.2056627
212.4645,4.7852287,5.29111,0.0,0,4.6514287,0.0,0.43441907,39.451565,4.6577721,538.08008,-9.2062607
212.4689,4.7883787,5.3335586,0.0,0,4.6060648,0.0,0.43905556,39.339424,4.6177759,538.1615,-9.2063093
212.4733,4.8207278,5.386292,0.0,0,4.5607004,0.0,0.44416246,39.388638,4.5673003,538.25336,-9.2052755
212.4777,4.8291469,5.4267926,0.0,0,4.5163722,0.0,0.44859967,39.310135,4.5241437,538.34515,-9.2049875
212.4821,4.8392601,5.4757905,0.0,0,4.4732165,0.0,0.45354128,39.113705,4.4775019,538.40039,-9.2054901
212.4865,4.8314404,5.5155549,0.0,0,4.4300613,0.0,0.45803493,38.917187,4.4342117,538.45288,-9.2059326
212.4909,4.8193016,5.5602112,0.0,0,4.3869061,0.0,0.46247816,38.629372,4.3922138,538.41888,-9.2049608
212.4953,4.8765049,5.5964284,0.0,0,4.343751,0.0,0.46654594,38.962086,4.3498182,538.34015,-9.2048883
212.4997,4.9359488,5.6458464,0.0,0,4.3005962,0.0,0.47161976,39.184147,4.3065481,538.24109,-9.2049837
212.5041,4.9674797,5.6845698,0.0,0,4.2574406,0.0,0.47595242,39.314575,4.2641282,538.10986,-9.2050114
212.5085,4.9577355,5.7350602,0.0,0,4.2142854,0.0,0.48120946,39.047157,4.2161727,537.96667,-9.2059536
212.5129,4.9882488,5.7729807,0.0,0,4.1711302,0.0,0.48549175,39.021606,4.1752872,537.73047,-9.2044563
212.5173,5.0134826,5.8184624,0.0,0,4.127975,0.0,0.49031299,39.148567,4.1292243,537.49432,-9.2046318
212.5217,5.0202036,5.858736,0.0,0,4.0848203,0.0,0.49490669,38.925823,4.0883904,537.05945,-9.2047424
212.5261,5.0308528,5.9038649,0.0,0,4.0418863,0.0,0.49964419,38.840931,4.0469637,536.58704,-9.2050209
212.5305,5.0546927,5.9436245,0.0,0,4.0008435,0.0,0.50420302,38.852661,4.0065107,535.95807,-9.2056952
212.5349,5.0894246,5.9890232,0.0,0,3.9598002,0.0,0.50896722,39.004181,3.9615531,535.21014,-9.2048473
212.5393,5.1154189,6.0254292,0.0,0,3.918757,0.0,0.51327914,39.006351,3.9195659,534.47394,-9.2053204
212.5437,5.1659842,6.0727906,0.0,0,3.8777139,0.0,0.51850307,39.207829,3.8825235,533.76544,-9.2050972
212.5481,5.2001848,6.1151152,0.0,0,3.8366706,0.0,0.52332759,39.243698,3.8374963,533.03552,-9.2050991
212.5525,5.2045712,6.160111,0.0,0,3.7956276,0.0,0.52834475,39.06649,3.7941086,531.38257,-9.2049856
212.5569,5.1990943,6.1964908,0.0,0,3.7545841,0.0,0.53262186,38.806156,3.7524779,529.72961,-9.2061014
212.5613,5.1887403,6.2400222,0.0,0,3.713541,0.0,0.53738326,38.618824,3.7154813,527.62402,-9.2063684
212.5657,5.2372761,6.2755785,0.0,0,3.672498,0.0,0.54170108,38.799759,3.6759419,525.36761,-9.2063551
212.5701,5.3170533,6.3198929,0.0,0,3.6314545,0.0,0.54663324,39.111336,3.6324215,523.8938,-9.20578
212.5745,5.3178687,6.3574305,0.0,0,3.5904114,0.0,0.55119586,39.031036,3.5950146,523.27722,-9.2053366
212.5789,5.3268981,6.4029412,0.0,0,3.5508497,0.0,0.5562287,38.87632,3.5514374,522.8941,-9.2048922
212.5833,5.3303456,6.4356451,0.0,0,3.5118039,0.0,0.56035841,38.83223,3.514863,523.41882,-9.2070608
212.5877,5.3970218,6.4812179,0.0,0,3.4727583,0.0,0.56551856,38.974438,3.4739792,523.9436,-9.2054958
212.5921,5.4530926,6.5181379,0.0,0,3.4337125,0.0,0.56998849,39.274891,3.4334579,524.7326,-9.2040987
212.5965,5.4619002,6.5620208,0.0,0,3.3946671,0.0,0.57517177,39.129539,3.3932335,525.54089,-9.2066469
212.6009,5.4616613,6.5977397,0.0,0,3.3556216,0.0,0.57946569,38.989353,3.3530293,526.33478,-9.2063293
212.6053,5.4691081,6.6416483,0.0,0,3.316576,0.0,0.5846138,38.791824,3.3132434,527.12189,-9.2050085
212.6097,5.5132451,6.6739159,0.0,0,3.27753,0.0,0.58863384,38.939747,3.2795117,527.8017,-9.2060118
212.6141,5.5567636,6.7180104,0.0,0,3.2384844,0.0,0.59388214,39.08078,3.2362006,528.32648,-9.2055931
212.6185,5.5690875,6.7485809,0.0,0,3.199439,0.0,0.5977397,39.047626,3.197823,528.85303,-9.2055178
212.6229,5.646493,6.7947879,0.0,0,3.1603935,0.0,0.60335016,39.367199,3.1569235,529.39087,-9.2054186
212.6273,5.6873512,6.83184,0.0,0,3.122066,0.0,0.60781914,39.470238,3.1190164,529.92871,-9.2061872
212.6317,5.6404233,6.8742485,0.0,0,3.0849211,0.0,0.61304659,38.90583,3.0831182,530.37598,-9.2052679
212.6361,5.6581492,6.9042048,0.0,0,3.0477762,0.0,0.61684996,38.842968,3.0453856,530.80884,-9.2055178
212.6405,5.7215681,6.9466696,0.0,0,3.0106313,0.0,0.62221885,39.066319,3.0082059,531.15649,-9.204977
212.6449,5.7818856,6.9810247,0.0,0,2.9734867,0.0,0.62627351,39.337288,2.969538,531.44519,-9.204958
212.6493,5.820035,7.0227151,0.0,0,2.9363418,0.0,0.63162273,39.339184,2.9336941,531.70874,-9.2046633
212.6537,5.8225527,7.0564332,0.0,0,2.8991969,0.0,0.63584536,39.302948,2.8944666,531.91864,-9.2057981
212.6581,5.8257651,7.0971437,0.0,0,2.8620524,0.0,0.64108318,39.09539,2.8568532,532.125,-9.2050314
212.6625,5.8587103,7.1294627,0.0,0,2.8249075,0.0,0.64523935,39.110443,2.8219578,532.25616,-9.2050982
212.6669,5.9379692,7.1677856,0.0,0,2.7877626,0.0,0.65014738,39.419659,2.7888641,532.38733,-9.2044296
212.6713,6.0101771,7.2051072,0.0,0,2.7506177,0.0,0.65483803,39.78389,2.7495344,532.53876,-9.2071705
212.6757,6.0383964,7.2476344,0.0,0,2.7135069,0.0,0.66050428,39.701729,2.7102258,532.69617,-9.2068014
212.6801,6.0531263,7.2838774,0.0,0,2.6781669,0.0,0.66509598,39.638115,2.6706429,532.84052,-9.2069149
212.6845,6.0491409,7.3220572,0.0,0,2.6428349,0.0,0.67017597,39.406696,2.6340466,532.97174,-9.2066536
212.6889,6.0179634,7.3538733,0.0,0,2.6075029,0.0,0.6742053,39.019711,2.6026247,533.08502,-9.2053452
212.6933,6.0034423,7.3870721,0.0,0,2.572171,0.0,0.67878574,38.750744,2.5673177,533.13751,-9.2056351
212.6977,6.0909324,7.4169269,0.0,0,2.536839,0.0,0.68252331,39.192837,2.5363212,533.19,-9.207346
212.7021,6.1815205,7.4563332,0.0,0,2.501507,0.0,0.68793041,39.49976,2.4986067,533.1673,-9.2065363
212.7065,6.2691803,7.4922018,0.0,0,2.4661748,0.0,0.69253552,39.933331,2.4641654,533.14105,-9.2047644
212.7109,6.2978044,7.5281539,0.0,0,2.4308429,0.0,0.69742441,39.963818,2.4251568,533.07904,-9.2061119
212.7153,6.3273911,7.5644555,0.0,0,2.3955109,0.0,0.70233643,39.913769,2.3867767,533.00037,-9.205287
212.7197,6.370903,7.6015115,0.0,0,2.3601789,0.0,0.70748258,39.948593,2.350894,532.85187,-9.2057676
212.7241,6.3803678,7.6358919,0.0,0,2.324847,0.0,0.7120226,39.805828,2.3157077,532.6026,-9.2040653
212.7285,6.3776264,7.6702766,0.0,0,2.2906368,0.0,0.71676844,39.667019,2.283066,532.34796,-9.2067471
212.7329,6.4043584,7.7031755,0.0,0,2.2570295,0.0,0.72139454,39.622509,2.251909,532.05939,-9.2038755
212.7373,6.4576206,7.7374687,0.0,0,2.2234225,0.0,0.72607917,39.744808,2.215023,531.77075,-9.2053585
212.7417,6.5178676,7.7719212,0.0,0,2.1898153,0.0,0.73070842,39.941879,2.183048,531.52747,-9.2049141
212.7461,6.5596805,7.8047523,0.0,0,2.156208,0.0,0.7353611,40.017078,2.1513591,531.29132,-9.2063627
212.7505,6.587925,7.839983,0.0,0,2.1226008,0.0,0.74013484,40.017845,2.1150322,531.03192,-9.2044325
212.7549,6.6069188,7.8722224,0.0,0,2.0889935,0.0,0.74483961,39.95248,2.0848181,530.75641,-9.2056618
212.7593,6.6485825,7.9047785,0.0,0,2.0553865,0.0,0.7492947,39.990479,2.0489829,530.41418,-9.2050753
212.7637,6.7040863,7.9392071,0.0,0,2.0217793,0.0,0.75436169,40.114277,2.0150812,529.92877,-9.2050467
212.7681,6.7741704,7.9694552,0.0,0,1.9881722,0.0,0.75856531,40.38689,1.9842334,529.43976,-9.2053232
212.7725,6.7724128,8.0054674,0.0,0,1.954565,0.0,0.76364809,40.191753,1.9494817,528.87567,-9.2049475
212.7769,6.8017597,8.037611,0.0,0,1.9214275,0.0,0.76819837,40.137997,1.9193765,528.31158,-9.2050962
212.7813,6.8591256,8.0685349,0.0,0,1.889457,0.0,0.77287382,40.331135,1.8841131,527.92993,-9.2040291
212.7857,6.9703107,8.1046,0.0,0,1.8574866,0.0,0.77779907,40.777946,1.8540922,527.60199,-9.2045288
212.7901,6.9857268,8.1354828,0.0,0,1.8255162,0.0,0.78261638,40.696632,1.8188282,527.47736,-9.2043343
212.7945,7.0579033,8.1692343,0.0,0,1.7935458,0.0,0.78736109,40.880165,1.7832501,527.55603,-9.2055492
212.7989,7.0774217,8.2016096,0.0,0,1.7615755,0.0,0.7921741,40.784336,1.7524534,527.65558,-9.2057362
212.8033,7.1188908,8.2335768,0.0,0,1.729605,0.0,0.79686189,40.81641,1.7200885,527.82611,-9.2043581
212.8077,7.1122532,8.2649918,0.0,0,1.6976346,0.0,0.80155927,40.620728,1.6919062,527.99664,-9.2034693
212.8121,7.1769061,8.2992725,0.0,0,1.6656642,0.0,0.80642211,40.764374,1.6615117,527.75397,-9.2047539
212.8165,7.3119998,8.3273287,0.0,0,1.6336937,0.0,0.81080461,41.401073,1.6283847,527.49164,-9.2049856
212.8209,7.3755932,8.363678,0.0,0,1.6017234,0.0,0.81607544,41.510685,1.5971116,527.09509,-9.2058201
212.8253,7.4184351,8.3977365,0.0,0,1.5697531,0.0,0.82120025,41.539707,1.560441,526.63593,-9.2043619
212.8297,7.4137392,8.4299421,0.0,0,1.5392207,0.0,0.82600576,41.310181,1.5270401,526.30023,-9.2057114
212.8341,7.4285016,8.4607363,0.0,0,1.5088079,0.0,0.83082753,41.156834,1.4955541,526.14282,-9.2050152
212.8385,7.4467754,8.4908781,0.0,0,1.478395,0.0,0.8353017,41.134361,1.4687598,526.03369,-9.2041254
212.8429,7.5004196,8.5182514,0.0,0,1.4479822,0.0,0.83968019,41.233322,1.4392092,526.23047,-9.2049761
212.8473,7.5817904,8.5516529,0.0,0,1.4175695,0.0,0.8445853,41.4874,1.4082956,526.42725,-9.2052231
212.8517,7.6766109,8.5795383,0.0,0,1.3871567,0.0,0.84888691,41.793091,1.3761631,526.92993,-9.2053432
212.8561,7.7051816,8.6103048,0.0,0,1.3567439,0.0,0.85362923,41.811222,1.3465326,527.4809,-9.2050304
212.8605,7.7447124,8.6415024,0.0,0,1.3263311,0.0,0.85859364,41.829891,1.3163019,528.04736,-9.205018
212.8649,7.8243599,8.6733732,0.0,0,1.2959183,0.0,0.86361587,41.999088,1.2889519,528.62463,-9.2057285
212.8693,7.9186931,8.7031889,0.0,0,1.2655054,0.0,0.8681978,42.281448,1.255338,529.10168,-9.2055225
212.8737,7.98668,8.7332716,0.0,0,1.2350928,0.0,0.87310523,42.489899,1.224887,529.36407,-9.2044125
212.8781,7.9824729,8.7642975,0.0,0,1.2055123,0.0,0.87786913,42.278229,1.1966468,529.6145,-9.2053423
212.8825,8.0416355,8.793581,0.0,0,1.1765865,0.0,0.88267624,42.37373,1.1656568,529.6145,-9.2056046
212.8869,8.1170616,8.8216658,0.0,0,1.1476611,0.0,0.88708264,42.493645,1.1362866,529.6145,-9.2055483
212.8913,8.1927061,8.8566246,0.0,0,1.1187353,0.0,0.89272952,42.712418,1.1100506,529.7868,-9.2049809
212.8957,8.1878996,8.8815575,0.0,0,1.0898098,0.0,0.89657569,42.604092,1.080303,530.00983,-9.2049742
212.9001,8.1989431,8.9087038,0.0,0,1.0608841,0.0,0.90118247,42.391071,1.0539908,530.12787,-9.2063799
212.9045,8.2700396,8.9384642,0.0,0,1.0319586,0.0,0.90602911,42.52042,1.0224165,530.14099,-9.2041798
212.9089,8.3760624,8.9641685,0.0,0,1.0030329,0.0,0.91029322,42.91433,0.99778634,530.02295,-9.2053595
212.9133,8.4710054,8.9922304,0.0,0,0.97410738,0.0,0.91488045,43.210243,0.96852815,529.4588,-9.2057953
212.9177,8.536129,9.0251379,0.0,0,0.94518179,0.0,0.92030114,43.281612,0.9355377,528.89471,-9.2049465
212.9221,8.6524734,9.0515966,0.0,0,0.91625619,0.0,0.92463708,43.682667,0.90614349,528.54352,-9.2041206
212.9265,8.7330818,9.0854359,0.0,0,0.88760829,0.0,0.93032616,43.879436,0.87861794,528.20239,-9.2052345
212.9309,8.7453165,9.1108484,0.0,0,0.86009949,0.0,0.93457645,43.734089,0.84640044,527.81659,-9.2048407
212.9353,8.6737528,9.1421556,0.0,0,0.83259064,0.0,0.93983644,43.159409,0.82068056,527.40991,-9.2052937
212.9397,8.7426758,9.1622667,0.0,0,0.8050819,0.0,0.94343013,43.31958,0.79638308,527.10522,-9.2045097
212.9441,8.8474283,9.1915464,0.0,0,0.77757305,0.0,0.94823498,43.639679,0.76678276,526.94781,-9.204196
212.9485,8.9493999,9.2145557,0.0,0,0.75006431,0.0,0.95225137,43.954037,0.74227583,526.74927,-9.2049828
212.9529,9.0011606,9.2447367,0.0,0,0.72255546,0.0,0.95727819,44.004135,0.712933,526.2901,-9.206274
212.9573,9.1055412,9.2695293,0.0,0,0.69504666,0.0,0.96160519,44.305168,0.68718171,525.83093,-9.2043953
212.9617,9.2571516,9.3017006,0.0,0,0.66753787,0.0,0.96714145,44.786453,0.65946823,525.11121,-9.2049713
212.9661,9.2596912,9.3273926,0.0,0,0.64002907,0.0,0.97165179,44.589809,0.6305297,524.35028,-9.2049789
212.9705,9.2677135,9.3560019,0.0,0,0.61252028,0.0,0.97657835,44.488483,0.60563689,524.0235,-9.2056942
212.9749,9.2649212,9.3764687,0.0,0,0.58501148,0.0,0.98044711,44.284504,0.57955837,523.99725,-9.2048512
212.9793,8.6901913,9.3935528,0.0,0,0.55860871,0.0,0.98353302,41.395267,0.55985045,524.10461,-9.2051878
212.9837,8.2963953,9.3915567,0.0,0,0.53242874,0.0,0.98306262,39.530396,0.53822964,524.49817,-9.2045851
212.9881,7.8608794,9.3991079,0.0,0,0.50624865,0.0,0.98394454,37.481476,0.52194917,524.89172,-9.2054024
212.9925,7.5523872,9.3993607,0.0,0,0.48006868,0.0,0.98439336,35.911007,0.5044663,525.28528,-9.2058363
212.9969,7.3575392,9.4081831,0.0,0,0.45388871,0.0,0.98578024,34.967232,0.48478782,525.67883,-9.2069292
213.0013,7.1453862,9.4045811,0.0,0,0.42770869,0.0,0.98538578,33.93597,0.46382007,526.02173,-9.2063046
213.0057,6.9461355,9.4134178,0.0,0,0.40152872,0.0,0.98671627,32.978382,0.44617575,526.34967,-9.2066841
213.0101,6.7043762,9.4118986,0.0,0,0.37534869,0.0,0.98653746,31.84317,0.42516097,526.71045,-9.2067661
213.0145,6.383688,9.4167633,0.0,0,0.34916872,0.0,0.98728114,30.324461,0.41978332,527.104,-9.2077341
213.0189,6.1634159,9.4132586,0.0,0,0.32298869,0.0,0.98684239,29.239737,0.41312262,527.49756,-9.2067232
213.0233,6.1213341,9.4173098,0.0,0,0.29680869,0.0,0.98725647,29.03047,0.40722719,527.89117,-9.2072668
213.0277,6.2890415,9.4192657,0.0,0,0.27123094,0.0,0.98779935,29.811625,0.38250792,528.28473,-9.2063646
213.0321,6.5546002,9.4230728,0.0,0,0.24633574,0.0,0.98826963,31.084501,0.34768987,528.62817,-9.2060709
213.0365,6.7574315,9.424262,0.0,0,0.22144052,0.0,0.98882926,32.012032,0.31033358,528.96924,-9.2062387
213.0409,6.878262,9.4280481,0.0,0,0.19654539,0.0,0.98908669,32.566849,0.27726007,529.13147,-9.2047091
213.0453,6.9093409,9.4291124,0.0,0,0.17165019,0.0,0.98979747,32.679756,0.24704292,529.21021,-9.2069416
213.0497,6.8737903,9.434514,0.0,0,0.14675498,0.0,0.99021679,32.48,0.22251582,529.26746,-9.2064152
213.0541,6.8247404,9.4348183,0.0,0,0.12185977,0.0,0.99039888,32.284321,0.19188203,529.29364,-9.2043295
213.0585,6.7961068,9.4405174,0.0,0,0.096964575,0.0,0.99104762,32.100189,0.16995975,529.3324,-9.2061205
213.0629,6.7738624,9.439146,0.0,0,0.072069377,0.0,0.99150801,31.968721,0.14708221,529.45044,-9.2049427
213.0673,6.695899,9.4450426,0.0,0,0.047174171,0.0,0.99203616,31.620308,0.12704745,529.56854,-9.2068319
213.0717,6.64324,9.443202,0.0,0,0.022278972,0.0,0.99219972,31.364367,0.10759568,529.65265,-9.2075949
213.0761,6.5986395,9.4487457,0.0,0,-0.002552415,0.0,0.99265045,31.146303,0.084272593,529.73132,-9.2053423
213.0805,6.5560746,9.4501925,0.0,0,-0.02684042,0.0,0.99336487,30.893923,0.067043416,529.84106,-9.2069359
213.0849,6.4749794,9.4537601,0.0,0,-0.051128417,0.0,0.99375415,30.535898,0.052856777,529.97223,-9.2066269
213.0893,6.3736215,9.4504614,0.0,0,-0.075416416,0.0,0.99354559,30.010803,0.035733089,530.09509,-9.2062683
213.0937,6.2913847,9.4562178,0.0,0,-0.099704415,0.0,0.99421626,29.67395,0.025865836,530.20007,-9.206543
213.0981,6.2151661,9.4521132,0.0,0,0.31743813,500.0,0.99372947,29.268938,0.011840709,530.30383,-9.2064505
213.1025,5.831069,9.4592037,0.0,0,1.1142951,500.0,0.99485892,27.499029,0.018217577,530.38251,-9.2062426
213.1069,2.9682267,9.4425688,0.0,0,1.9111534,500.0,0.9922049,14.152418,0.18208416,530.46124,-9.2088928
213.1113,-0.064625055,9.4123106,0.0,0,2.7080107,500.0,0.98681629,-0.33915603,0.52543807,530.56024,-9.2113132
213.1157,-0.20251772,9.4104452,0.0,0,3.5048685,500.0,0.98665386,-1.0254247,1.64934,530.66516,-9.2108622
213.1201,-0.021951118,9.4149761,0.0,0,4.3017259,500.0,0.98712146,-0.12579244,2.8751144,530.71765,-9.2102404
213.1245,-0.046385143,9.4086704,0.0,0,5.0985837,500.0,0.98641396,-0.24944505,3.7070682,530.71765,-9.2096834
213.1289,-0.0069037769,9.412323,0.0,0,5.8954411,500.0,0.9867031,-0.0065556378,4.4692507,530.70575,-9.2088594
213.1333,-0.038705498,9.4030218,0.0,0,6.6922989,500.0,0.98539138,-0.1397412,5.2436237,530.65326,-9.2076225
213.1377,-0.010678898,9.4116287,0.0,0,7.4891562,500.0,0.98668975,-0.055308208,6.0477543,530.60077,-9.2089443
213.1421,0.0029138192,9.4072418,0.0,0,8.2860146,500.0,0.98607939,0.036448047,6.8778367,530.6485,-9.2080069
213.1465,-0.059784811,9.4066954,0.0,0,9.0828724,500.0,0.98585492,-0.38935915,7.710001,530.70093,-9.2098722
213.1509,0.0016915983,9.403595,0.0,0,9.8797302,500.0,0.98554748,0.095290728,8.5354662,530.7713,-9.2072935
213.1553,-0.089728177,9.4096966,0.0,0,10.676588,500.0,0.98650944,-0.410622,9.3437147,530.85004,-9.2062769
213.1597,0.020368384,9.4059772,0.0,0,11.473445,500.0,0.9860298,0.15300138,10.165639,530.89655,-9.2073755
213.1641,-0.045906879,9.4063978,0.0,0,12.270303,500.0,0.98603231,-0.23031123,10.968747,530.89655,-9.2065592
213.1685,0.037195727,9.4038963,0.0,0,13.067161,500.0,0.98579383,0.18324606,11.744426,530.90015,-9.2065849
213.1729,-0.067410789,9.4072523,0.0,0,13.864018,500.0,0.98596567,-0.32380441,12.519492,530.92633,-9.2068253
213.1773,0.067604423,9.4035654,0.0,0,14.660876,500.0,0.98590416,0.31092438,13.308265,530.95258,-9.2068787
213.1817,-0.10957941,9.4068384,0.0,0,15.457734,500.0,0.98628175,-0.50762266,14.112782,531.01282,-9.2070112
213.1861,0.037518285,9.4039106,0.0,0,16.254593,500.0,0.98597479,0.13724279,14.915458,531.07837,-9.2058859
213.1905,-0.0068118786,9.4060545,0.0,0,17.051451,500.0,0.98626584,0.013828106,15.718316,531.10522,-9.2058744
213.1949,0.002694617,9.4044456,0.0,0,17.848307,500.0,0.98606747,-0.10842263,16.515705,531.10522,-9.2068872
213.1993,-0.055169277,9.4051027,0.0,0,18.0,500.0,0.9862352,-0.26331568,17.31111,531.10107,-9.2050323
213.2037,0.042152118,9.4050531,0.0,0,18.0,500.0,0.98634911,0.12121332,18.008541,531.08795,-9.2079096
213.2081,-0.014804311,9.4124002,0.0,0,18.0,500.0,0.98756987,-0.036516313,18.43136,531.07544,-9.2121506
213.2125,-0.089199521,9.4178486,0.0,0,18.0,500.0,0.98869932,-0.46901578,18.44198,531.07544,-9.2221918
213.2169,0.22773919,9.4431429,0.0,0,18.0,500.0,0.99329853,1.0282824,18.215561,531.07544,-9.2428808
213.2213,0.84013629,9.451952,0.0,0,18.0,500.0,0.99494469,3.9894619,18.068287,531.05518,-9.2711143
213.2257,0.95177889,9.4552135,0.0,0,18.0,500.0,0.99561739,4.431756,18.046936,531.02893,-9.3080387
213.2301,0.97739023,9.4535704,0.0,0,18.0,500.0,0.99546748,4.5874619,18.081606,531.00922,-9.3488131
213.2345,0.94856435,9.4570532,0.0,0,18.0,500.0,0.99598104,4.4946146,18.125381,530.99609,-9.3827753
213.2389,0.88176847,9.4536009,0.0,0,18.0,500.0,0.995444,4.1902533,18.145987,530.99194,-9.417635
213.2433,0.91331053,9.4570713,0.0,0,18.0,500.0,0.99605519,4.2539921,18.144238,531.01819,-9.4492292
213.2477,0.98260653,9.4514418,0.0,0,18.0,500.0,0.99513143,4.6328816,18.143661,531.04443,-9.4836903
213.2521,0.99321991,9.4581051,0.0,0,18.0,500.0,0.99647683,4.6665549,18.131418,531.05817,-9.5169897
213.2565,0.91774219,9.4523783,0.0,0,18.0,500.0,0.99544233,4.3272376,18.127298,531.07129,-9.5500612
213.2609,0.89777809,9.4539566,0.0,0,18.0,500.0,0.99553245,4.2092695,18.124565,531.03967,-9.5820084
213.2653,1.0024943,9.4548664,0.0,0,18.0,500.0,0.99569952,4.6914797,18.114355,530.98718,-9.6156721
213.2697,1.0071799,9.4552994,0.0,0,18.0,500.0,0.99582791,4.7422929,18.112558,530.93469,-9.6490469
213.2741,0.92719334,9.4512453,0.0,0,18.0,500.0,0.99534297,4.4026814,18.108932,530.88226,-9.6847992
213.2785,0.89729977,9.4558983,0.0,0,18.0,500.0,0.99621481,4.2376928,18.105721,530.83331,-9.716794
213.2829,0.97311014,9.454113,0.0,0,18.0,500.0,0.99589771,4.5569096,18.108587,530.80713,-9.7511244
213.2873,1.0245757,9.4555168,0.0,0,18.0,500.0,0.99605995,4.8242049,18.099592,530.78088,-9.7836599
213.2917,0.95348608,9.453124,0.0,0,18.0,500.0,0.99570781,4.5359764,18.102293,530.77728,-9.81917
213.2961,0.89769673,9.4537296,0.0,0,18.0,500.0,0.99580842,4.1956916,18.101862,530.77728,-9.8517046
213.3005,0.9488703,9.4522648,0.0,0,18.0,500.0,0.99572462,4.4305143,18.0973,530.76178,-9.8818035
213.3049,1.0283586,9.4527798,0.0,0,18.0,500.0,0.99580365,4.8388271,18.097218,530.73553,-9.9156256
213.3093,0.96615952,9.4529362,0.0,0,18.0,500.0,0.99594784,4.5875711,18.098692,530.69263,-9.9496698
213.3137,0.9065935,9.452177,0.0,0,18.0,500.0,0.99596858,4.2609415,18.097237,530.61389,-9.9840183
213.3181,0.93227661,9.452776,0.0,0,18.0,500.0,0.99582338,4.3298144,18.090158,530.53876,-10.016614
213.3225,1.0417219,9.4529104,0.0,0,18.0,500.0,0.99580401,4.8564606,18.092863,530.53876,-10.050235
213.3269,0.99159694,9.4510508,0.0,0,18.0,500.0,0.99562037,4.7237692,18.092199,530.53876,-10.085731
213.3313,0.92959541,9.4510946,0.0,0,18.0,500.0,0.99574512,4.3929558,18.093056,530.51849,-10.118292
213.3357,0.9242056,9.4532375,0.0,0,18.0,500.0,0.99590367,4.3575196,18.089514,530.49225,-10.14951
213.3401,1.0212268,9.4521122,0.0,0,18.0,500.0,0.99586064,4.765326,18.086176,530.4726,-10.182496
213.3445,1.040175,9.4537649,0.0,0,18.0,500.0,0.99610436,4.9135065,18.085642,530.45947,-10.216457
213.3489,0.94270158,9.4511166,0.0,0,18.0,500.0,0.99574304,4.4259567,18.087399,530.45233,-10.251509
213.3533,0.91230088,9.4525871,0.0,0,18.0,500.0,0.9956947,4.2771578,18.082081,530.46545,-10.284594
213.3577,1.0053519,9.4516191,0.0,0,18.0,500.0,0.99550146,4.6597118,18.076921,530.47852,-10.316585
213.3621,1.0444382,9.4518023,0.0,0,18.0,500.0,0.99562162,4.9476428,18.07588,530.44153,-10.351034
213.3665,0.96345955,9.4532099,0.0,0,18.0,500.0,0.9959259,4.5940027,18.079782,530.40216,-10.382195
213.3709,0.91770607,9.4516373,0.0,0,18.0,500.0,0.99548715,4.3227019,18.075848,530.37177,-10.415291
213.3753,0.97121078,9.4519396,0.0,0,18.0,500.0,0.99565589,4.5509758,18.074921,530.34558,-10.450607
213.3797,1.0539582,9.451087,0.0,0,18.0,500.0,0.9953357,4.9028568,18.074499,530.31934,-10.481911
213.3841,0.97355211,9.4497471,0.0,0,18.0,500.0,0.99536788,4.6355343,18.074972,530.29309,-10.516773
213.3885,0.9116143,9.4506245,0.0,0,18.0,500.0,0.99535197,4.3215456,18.07313,530.26862,-10.549101
213.3929,0.95303315,9.4507484,0.0,0,18.0,500.0,0.99541289,4.4600935,18.072184,530.25549,-10.584199
213.3973,1.0354958,9.4513187,0.0,0,18.0,500.0,0.99529964,4.8866167,18.070393,530.24237,-10.619346
213.4017,1.0280132,9.4519672,0.0,0,18.0,500.0,0.99547613,4.8644204,18.07074,530.21796,-10.651307
213.4061,0.93650681,9.4516001,0.0,0,18.0,500.0,0.99513561,4.3922729,18.068859,530.19171,-10.685577
213.4105,0.9461717,9.4496956,0.0,0,18.0,500.0,0.99510372,4.4722066,18.071304,530.14996,-10.717689
213.4149,1.0506307,9.4540014,0.0,0,18.0,500.0,0.99564648,4.8736238,18.061483,530.09747,-10.74971
213.4193,1.0497757,9.4494677,0.0,0,18.0,500.0,0.99480212,4.9767766,18.06728,530.04083,-10.782893
213.4237,0.95828682,9.4516287,0.0,0,18.0,500.0,0.99522108,4.5531125,18.058641,529.97522,-10.816956
213.4281,0.94073725,9.4516163,0.0,0,18.0,500.0,0.99525863,4.4206305,18.064016,529.91199,-10.851502
213.4325,1.0224334,9.4523706,0.0,0,18.0,500.0,0.99531347,4.7979069,18.062315,529.89893,-10.885201
213.4369,1.0650839,9.4513655,0.0,0,18.0,500.0,0.99508798,5.0319753,18.059092,529.8858,-10.91705
213.4413,0.9713214,9.4512339,0.0,0,18.0,500.0,0.99489093,4.6325264,18.058374,529.85242,-10.952783
213.4457,0.92298049,9.4536896,0.0,0,18.0,500.0,0.99535269,4.392252,18.056419,529.81305,-10.984251
213.4501,1.0262679,9.4527979,0.0,0,18.0,500.0,0.99505544,4.7985229,18.057341,529.76056,-11.016929
213.4545,1.0617459,9.4502831,0.0,0,18.0,500.0,0.99473995,5.0335064,18.05764,529.69495,-11.050056
213.4589,1.0030837,9.4536457,0.0,0,18.0,500.0,0.99505252,4.7555728,18.055878,529.64429,-11.08372
213.4633,0.93700457,9.4510374,0.0,0,18.0,500.0,0.994739,4.4175401,18.055298,529.64429,-11.118202
213.4677,1.0066066,9.4523849,0.0,0,18.0,500.0,0.99477285,4.6469469,18.055676,529.64429,-11.150743
213.4721,1.0842081,9.4514942,0.0,0,18.0,500.0,0.99473518,5.0854917,18.051313,529.61926,-11.185496
213.4765,1.0359116,9.4537773,0.0,0,18.0,500.0,0.99516153,4.9240289,18.048367,529.59302,-11.218407
213.4809,0.95615637,9.453764,0.0,0,18.0,500.0,0.99506789,4.5203381,18.048664,529.54889,-11.250874
213.4853,0.97521991,9.4512253,0.0,0,18.0,500.0,0.99441189,4.5803323,18.053276,529.4964,-11.284654
213.4897,1.0845765,9.4527893,0.0,0,18.0,500.0,0.99480528,5.0840731,18.052717,529.45465,-11.317416
213.4941,1.0579972,9.4536066,0.0,0,18.0,500.0,0.99484706,5.0048566,18.050997,529.42841,-11.351317
214.8956,0.87750757,9.4704981,0.0,0,18.0,4.0912098e-17,0.99791408,4.1198745,17.999846,506.42508,-11.480869
217.0956,0.84781325,9.4903622,0.0,0,18.0,1.4012985e-45,1.0016035,3.9647696,17.999733,481.33777,-11.482264
219.2956,0.84195894,9.5087633,0.0,0,18.0,1.4012985e-45,1.0049484,3.9241109,17.99966,458.32883,-11.481956
221.4956,0.85992008,9.5240822,0.0,0,18.0,1.4012985e-45,1.0076857,3.9903579,17.999403,436.36508,-11.481602
223.6956,0.8677398,9.5393648,0.0,0,18.0,1.4012985e-45,1.0104363,4.022253,17.999493,415.25601,-11.48207
225.8956,0.85232925,9.5532475,0.0,0,18.0,1.4012985e-45,1.0129505,3.9505813,18.000032,394.8703,-11.482569
228.0956,0.84539992,9.5655727,0.0,0,18.0,1.4012985e-45,1.0152378,3.903234,18.000881,375.15054,-11.482061
230.2956,0.85381681,9.5775862,0.0,0,18.0,1.4012985e-45,1.0175626,3.9243267,17.99918,356.40881,-11.48165
232.4956,0.87584889,9.5891151,0.0,0,18.0,1.4012985e-45,1.0196652,4.0199451,18.00045,338.71768,-11.481803
234.6956,0.87748194,9.6006279,0.0,0,18.0,1.4012985e-45,1.021747,4.0258031,17.999891,322.01669,-11.482425
236.8956,0.87475491,9.6109362,0.0,0,18.0,1.4012985e-45,1.0236636,4.0071054,18.000616,306.33862,-11.482551
239.0956,0.88036942,9.6210585,0.0,0,18.0,1.4012985e-45,1.025625,4.0158458,17.999378,291.2887,-11.482411
241.2956,0.89518964,9.630187,0.0,0,18.0,1.4012985e-45,1.0273633,4.073669,18.000084,276.97247,-11.481916
243.4956,0.91240543,9.6399012,0.0,0,18.0,1.4012985e-45,1.0291388,4.1597905,17.999002,263.46426,-11.481929
245.6956,0.91541851,9.6489744,0.0,0,18.0,1.4012985e-45,1.0307899,4.1647825,18.000273,250.72453,-11.481873
247.8956,0.89921153,9.6578789,0.0,0,18.0,1.4012985e-45,1.0323665,4.0834894,18.000376,238.75015,-11.481793
250.0956,0.9232049,9.6662493,0.0,0,18.0,1.4012985e-45,1.0339189,4.1699266,18.00066,227.29414,-11.482109
252.2956,0.94098359,9.6743574,0.0,0,18.0,1.4012985e-45,1.0354191,4.2528563,17.999235,216.42168,-11.48246
254.4956,0.94437295,9.6813774,0.0,0,18.0,1.4012985e-45,1.036768,4.2753868,17.999826,206.20612,-11.481853
256.6956,0.93302804,9.688036,0.0,0,18.0,1.4012985e-45,1.0380818,4.214426,17.999468,196.53001,-11.481442
258.8956,0.93523014,9.6947823,0.0,0,18.0,1.4012985e-45,1.0393988,4.2015777,18.00036,187.17789,-11.48165
261.0956,0.95638287,9.7012835,0.0,0,18.0,1.4012985e-45,1.0406573,4.2932997,17.999802,177.72548,-11.481641
263.2956,0.95311111,9.7070951,0.0,0,18.0,1.4012985e-45,1.0417522,4.2901063,17.999456,169.44055,-11.481586
265.4956,0.94676805,9.7134151,0.0,0,18.0,1.4012985e-45,1.0429041,4.2573919,18.000761,161.76068,-11.481674
267.6956,0.95012927,9.7187853,0.0,0,18.0,1.4012985e-45,1.0438962,4.2648706,17.999899,154.49109,-11.481742
269.8956,0.95919001,9.7239704,0.0,0,18.0,1.4012985e-45,1.0448248,4.2884359,18.000751,147.23044,-11.481871
272.0956,0.97293031,9.7289,0.0,0,18.0,1.4012985e-45,1.0457847,4.3488269,17.999924,140.75662,-11.481942
273.4956,0.94855112,9.7323208,0.0,0,18.0,1.4012985e-45,1.0464572,4.238646,18.000242,136.7169,-11.482179