File: examples/dan-msc-case-studies/CS3/data/01 raw data/baron_test_015.csv
Time(sec),Force(kN),Jaw(mm),PowAngle(deg),Power(W),Pram,PTemp,Strain,Stress(MPa),Stroke(mm),TC1(C),wedge(mm)
0.0,1.3808398,28.376883,0.0,0,11.076097,0.001666312,9.6158047,0.0011723991,11.075915,23.411764,-9.1258345
1.1,1.3244559,0.0076772934,0.0,0,11.076097,3.2159133,0.00052792561,16.845661,11.076838,23.389763,-9.4936543
2.2,1.2634437,0.0073933154,0.0,0,11.076097,6.515914,0.00051690527,16.066469,11.075916,23.435001,-9.4886332
3.3,1.2805187,0.0073671383,0.0,0,11.076097,9.8159132,0.00047296361,16.30518,11.075878,23.437645,-9.4894867
4.4,1.2390212,0.0074320063,0.0,0,11.076097,13.115913,0.00050489797,15.764927,11.076675,23.484745,-9.4865513
5.5,1.2172201,0.0069070496,0.0,0,11.076097,16.415915,0.00048852398,15.482874,11.076558,23.415339,-9.4853525
6.6,1.2096963,0.0073169121,0.0,0,11.076097,19.715914,0.00045742473,15.394476,11.075283,23.426718,-9.4826899
7.7,1.1967705,0.0073919226,0.0,0,11.076097,23.015915,0.00050887611,15.242143,11.07656,23.383799,-9.4799929
8.8,1.1931348,0.0075383796,17.640093,0,11.076097,26.315914,0.00053411169,15.203889,11.076398,23.372234,-9.4783621
9.9,1.1982411,0.0079071522,31.442331,0,11.076097,29.615911,0.00050409167,15.244921,11.075972,23.536341,-9.4770298
11.0,1.2062601,0.00714151,40.29314,0,11.076097,32.915905,0.00048574977,15.342302,11.075206,24.508331,-9.47579
12.1,1.2211609,0.0043200837,46.079082,0,11.076097,36.215908,0.00031590546,15.531323,11.076067,26.481825,-9.4737072
13.2,1.223038,0.00094828755,50.037571,0,11.076097,39.515911,2.8326684e-05,15.565014,11.075719,29.577288,-9.4712267
14.3,1.2512926,-0.0029182865,52.631618,0,11.076097,42.81591,-0.00019590471,15.930851,11.075837,33.566883,-9.4695196
15.4,1.2636737,-0.0074179559,54.166973,0,11.076097,46.115906,-0.00046844184,16.093542,11.076896,38.389629,-9.4675922
16.5,1.2720429,-0.012539189,54.624016,0,11.076097,49.415901,-0.00086050737,16.210554,11.076451,43.891983,-9.4657192
17.6,1.2907805,-0.017696034,53.975876,0,11.076097,52.715908,-0.0011717808,16.454838,11.076623,49.98703,-9.4635983
18.7,1.300434,-0.02278441,52.498058,0,11.076097,56.015915,-0.0014900778,16.585093,11.07657,55.956944,-9.4614
19.8,1.3086343,-0.026330072,50.06216,0,11.076097,59.315914,-0.0017811798,16.69939,11.076789,61.872337,-9.4599676
20.9,1.3081851,-0.030017873,47.149601,0,11.076097,62.615917,-0.0019893397,16.693153,11.075851,67.104065,-9.4577169
22.0,1.2997797,-0.032556508,43.839329,0,11.076097,65.915909,-0.002137949,16.570824,11.076905,71.551193,-9.4563665
23.1,1.2858366,-0.034350526,40.574799,0,11.076097,69.215904,-0.0023060001,16.420977,11.076359,75.198204,-9.4543076
24.2,1.2702438,-0.035689402,37.853119,0,11.076097,72.515907,-0.0023704616,16.218422,11.076644,77.910339,-9.4522991
25.3,1.2624842,-0.036357049,36.838722,0,11.076097,75.815903,-0.0023974597,16.127903,11.076546,79.878487,-9.4506159
26.4,1.2489424,-0.037521094,37.739784,0,11.076097,79.115913,-0.0025184834,15.940608,11.075765,81.282967,-9.4482317
27.5,1.2369328,-0.038961131,39.83643,0,11.076097,82.415916,-0.0025780497,15.797272,11.076221,82.631821,-9.4464493
28.6,1.240469,-0.040877502,42.41243,0,11.076097,85.715904,-0.0026960524,15.844393,11.076713,83.858131,-9.4446793
29.7,1.2625923,-0.042516258,45.594547,0,11.076097,89.015923,-0.0028478072,16.102049,11.074961,85.582947,-9.443058
30.8,1.2640064,-0.045479875,48.320831,0,11.076097,92.31591,-0.0030176935,16.135799,11.077132,87.750267,-9.4412012
31.9,1.2761576,-0.048535839,50.379967,0,11.076097,95.615913,-0.0032139297,16.309067,11.076765,90.636536,-9.4397774
33.0,1.2880352,-0.052286569,51.832462,0,11.076097,98.915924,-0.0034931537,16.449097,11.076762,94.068108,-9.4375944
34.1,1.303524,-0.056297116,52.635494,0,11.076097,102.21592,-0.0037471512,16.658415,11.075631,98.057716,-9.4358873
35.2,1.3177607,-0.060683262,53.130615,0,11.076097,105.51593,-0.0040380755,16.847429,11.076322,102.28909,-9.4339342
36.3,1.3246889,-0.064464279,52.976078,0,11.076097,108.81592,-0.0042899828,16.937773,11.076449,106.98444,-9.4322319
37.4,1.3281529,-0.068380557,52.344501,0,11.076097,112.11591,-0.004558438,16.984722,11.07556,111.62703,-9.43048
38.5,1.3377496,-0.071716428,51.348442,0,11.076097,115.41591,-0.0047712848,17.118292,11.076571,116.25539,-9.4284325
39.6,1.3354843,-0.074838236,50.047596,0,11.076097,118.71591,-0.0049814093,17.084082,11.076102,120.62711,-9.4265175
40.7,1.3252829,-0.077719718,48.812523,0,11.076097,122.0159,-0.0051887198,16.967421,11.075662,124.52689,-9.4244757
41.8,1.3279983,-0.080554239,47.937531,0,11.076097,125.3159,-0.0053616967,16.998964,11.075668,127.88823,-9.4224825
42.9,1.3210584,-0.082655862,47.054447,0,11.076097,128.61604,-0.0054832101,16.895185,11.076729,130.94801,-9.4206285
44.0,1.3187083,-0.084412538,46.592445,0,11.076097,131.91589,-0.0056390162,16.889513,11.076269,133.68884,-9.4180822
45.1,1.3124163,-0.086666927,47.05444,0,11.076097,135.2159,-0.0057632881,16.799643,11.075561,136.11659,-9.4160776
46.2,1.3287233,-0.088700011,47.832417,0,11.076097,138.51591,-0.0058758669,17.006687,11.07618,138.40741,-9.4147482
47.3,1.3249015,-0.090964042,48.810562,0,11.076097,141.81587,-0.0060726479,16.973995,11.076615,140.76903,-9.4126415
48.4,1.3314204,-0.093702026,50.036991,0,11.076097,145.11591,-0.0062205885,17.066826,11.075389,143.25139,-9.4115515
49.5,1.3369489,-0.096893385,50.911461,0,11.076097,148.41589,-0.0064106397,17.134924,11.075534,146.16573,-9.4094
50.6,1.3426927,-0.099907927,51.92651,0,11.076097,151.71591,-0.0066594952,17.2022,11.077079,149.29204,-9.4077539
51.7,1.3459753,-0.10324117,52.608898,0,11.076097,155.01591,-0.0068448111,17.261169,11.076478,152.71082,-9.4058218
52.8,1.3494691,-0.10669021,52.97607,0,11.076097,158.3159,-0.0070720697,17.311554,11.076537,156.24902,-9.4040537
53.9,1.3446034,-0.11133206,53.31662,0,11.076097,161.61592,-0.0074223485,17.241776,11.077513,159.96783,-9.4019003
55.0,1.3552521,-0.11573791,53.204071,0,11.076097,164.91591,-0.0076892832,17.388302,11.075371,163.92476,-9.4002247
56.1,1.3528843,-0.11902174,52.976078,0,11.076097,168.21591,-0.0078838486,17.363392,11.075864,167.78906,-9.3982162
57.2,1.3433784,-0.12235104,52.637207,0,11.076097,171.5159,-0.0081318151,17.240366,11.076175,171.67546,-9.3970184
58.3,1.3362088,-0.12518209,52.284069,0,11.076097,174.81592,-0.0083208429,17.142426,11.076832,175.3389,-9.3947544
59.4,1.3395709,-0.12865235,51.932465,0,11.076097,178.11591,-0.0085412394,17.220703,11.075598,178.82857,-9.3926935
60.5,1.3382293,-0.13180493,51.745087,0,11.076097,181.41591,-0.0087491944,17.204926,11.075996,182.15781,-9.3906956
61.6,1.3395175,-0.13451429,51.569828,0,11.076097,184.71591,-0.0089438753,17.219585,11.076389,185.43388,-9.3887405
62.7,1.3463142,-0.13718748,51.569828,0,11.076097,188.01591,-0.0091049876,17.307222,11.076154,188.43698,-9.3863621
63.8,1.3516768,-0.13981472,51.571693,0,11.076097,191.3159,-0.0092564793,17.372131,11.076447,191.47809,-9.3849287
64.9,1.3516425,-0.14222926,51.932083,0,11.076097,194.61591,-0.0094610788,17.38065,11.076837,194.53043,-9.3836231
66.0,1.3548,-0.14602616,52.282303,0,11.076097,197.91591,-0.0096877543,17.405991,11.076259,197.52742,-9.3818188
67.1,1.3544599,-0.15017781,52.448383,0,11.076097,201.2159,-0.0099377632,17.422628,11.07668,200.59651,-9.379981
68.2,1.3547214,-0.15175231,52.789619,0,11.076097,204.51591,-0.010087529,17.420782,11.077417,203.77959,-9.377861
69.3,1.3415754,-0.15571241,52.97607,0,11.076097,207.81592,-0.010315121,17.271818,11.074874,206.92322,-9.3760872
70.4,1.3386545,-0.15881296,53.31665,0,11.076097,211.11591,-0.01051238,17.234991,11.075515,210.14819,-9.3738327
71.5,1.3470871,-0.16189203,53.657223,0,11.076097,214.41592,-0.010749632,17.339794,11.075752,213.53101,-9.3721371
72.6,1.3481276,-0.16504018,53.753735,0,11.076097,217.71591,-0.01094652,17.352219,11.076308,216.93381,-9.3701029
73.7,1.353981,-0.16793303,53.975826,0,11.076097,221.01591,-0.011137828,17.429873,11.076088,220.26141,-9.3688164
74.8,1.3533391,-0.17073289,53.975826,0,11.076097,224.31592,-0.011302959,17.440071,11.076684,223.68507,-9.3670254
75.9,1.3574388,-0.17489956,54.289589,0,11.076097,227.61591,-0.011620633,17.485077,11.075912,227.05626,-9.3649006
77.0,1.3592287,-0.17917302,54.396301,0,11.076097,230.91592,-0.011874958,17.522661,11.075913,230.2726,-9.3630981
78.1,1.3549095,-0.18181154,54.623909,0,11.076097,234.21591,-0.012012338,17.456438,11.075869,233.60909,-9.3610096
79.2,1.3512425,-0.18525574,54.624023,0,11.076097,237.5159,-0.012291003,17.40819,11.076208,236.92134,-9.3592472
80.3,1.3508649,-0.18847556,54.746555,0,11.076097,240.81592,-0.012472954,17.42049,11.077104,240.35507,-9.3573341
81.4,1.3500099,-0.19177167,54.931637,0,11.076097,244.11591,-0.012684247,17.422768,11.075126,243.66568,-9.3560085
82.5,1.346904,-0.19498506,54.931637,0,11.076097,247.41589,-0.012928926,17.372568,11.077126,246.98129,-9.35431
83.6,1.350139,-0.19782583,55.239239,0,11.076097,250.71591,-0.013096626,17.426815,11.076278,250.16731,-9.352025
84.7,1.3553907,-0.20071878,55.239685,0,11.076097,254.01591,-0.013294223,17.501289,11.075949,253.41783,-9.3504686
85.8,1.3495564,-0.20455249,55.467194,0,11.076097,257.31616,-0.013540465,17.410572,11.076198,256.87427,-9.3481779
86.9,1.3626506,-0.20779148,55.535885,0,11.076097,260.61615,-0.013786203,17.58683,11.075447,260.20419,-9.3459892
88.0,1.3594093,-0.21245253,55.731133,0,11.076097,263.91589,-0.014070041,17.563456,11.076262,263.39459,-9.3441753
89.1,1.354643,-0.21560384,55.843418,0,11.076097,267.21591,-0.014239142,17.501471,11.075929,266.74762,-9.3429041
90.2,1.3509922,-0.21766967,55.843506,0,11.076097,270.5159,-0.014424656,17.449343,11.076434,270.12192,-9.34097
91.3,1.3495591,-0.22128841,55.843506,0,11.076097,273.81592,-0.014643689,17.425055,11.076072,273.43411,-9.3390608
92.4,1.3542271,-0.22485033,55.942875,0,11.076097,277.11591,-0.01486028,17.49535,11.075777,276.7999,-9.3375435
93.5,1.3401664,-0.22787377,56.129147,0,11.076097,280.41592,-0.015082793,17.329779,11.077079,280.04025,-9.3354425
94.6,1.3523433,-0.2314053,56.155766,0,11.076097,283.71594,-0.015317676,17.471329,11.076123,283.2641,-9.3337851
95.7,1.3532803,-0.234688,56.425774,0,11.076097,287.01593,-0.015520994,17.506191,11.076028,286.60349,-9.3316193
96.8,1.3530976,-0.237866,56.425777,0,11.076097,290.31592,-0.015708663,17.5103,11.076469,289.91693,-9.3298178
97.9,1.3535453,-0.24086653,56.701664,0,11.076097,293.61591,-0.015957173,17.519567,11.075992,293.1427,-9.3281937
99.0,1.3496758,-0.2442545,56.711422,0,11.076097,296.91589,-0.016143428,17.461544,11.075292,296.51822,-9.3260326
100.1,1.3573333,-0.24754024,56.713314,0,11.076097,300.21588,-0.016346512,17.567646,11.076198,299.716,-9.324523
101.2,1.3579589,-0.25109139,56.986084,0,11.076097,303.5159,-0.016608281,17.588221,11.076058,303.02518,-9.3229961
102.3,1.3597704,-0.25436127,56.99889,0,11.076097,306.81589,-0.016824057,17.604885,11.075378,306.30078,-9.3207684
103.4,1.3633443,-0.25762612,57.260738,0,11.076097,310.11591,-0.017034642,17.656309,11.076791,309.53058,-9.3191881
104.5,1.3623077,-0.26107913,57.260738,0,11.076097,313.41589,-0.017234927,17.668045,11.075247,312.87469,-9.3169613
105.6,1.368055,-0.26392347,57.351563,0,11.076097,316.71588,-0.017467862,17.735296,11.07659,316.314,-9.3146706
106.7,1.3626044,-0.26838297,57.26181,0,11.076097,320.01587,-0.017727764,17.666151,11.075306,319.83847,-9.3130579
107.8,1.3616399,-0.27296799,57.361412,0,11.076097,323.31592,-0.018014487,17.663805,11.076262,323.12338,-9.3105478
108.9,1.3664619,-0.27698246,57.445103,0,11.076097,326.61588,-0.018317631,17.720406,11.07531,326.4563,-9.3091316
110.0,1.3532449,-0.28043705,57.350502,0,11.076097,329.91586,-0.018523669,17.542696,11.077466,329.82376,-9.307272
111.1,1.3563476,-0.28269204,57.532959,0,11.076097,333.21591,-0.018663129,17.592937,11.076712,333.10086,-9.3051386
112.2,1.354777,-0.28526279,57.535397,0,11.076097,336.5159,-0.018820809,17.573782,11.076121,336.42041,-9.3030844
113.3,1.3518903,-0.28891534,57.534195,0,11.076097,339.81592,-0.019104803,17.547255,11.07676,339.69464,-9.301281
114.4,1.3515724,-0.29270554,57.535397,0,11.076097,343.11594,-0.019317258,17.551628,11.075229,342.91968,-9.2991457
115.5,1.348642,-0.29579243,57.535397,0,11.076097,346.41592,-0.019506419,17.507938,11.075765,346.3215,-9.2973948
116.6,1.3539481,-0.29916391,57.599739,0,11.076097,349.71591,-0.019748202,17.578928,11.075888,349.53702,-9.2956915
117.7,1.3572351,-0.30207449,57.809689,0,11.076097,353.01593,-0.019954732,17.615932,11.075639,352.76193,-9.2942801
118.8,1.352211,-0.30519608,57.936356,0,11.076097,356.31592,-0.020143976,17.565832,11.075007,355.86255,-9.2919006
119.9,1.362348,-0.30863944,58.073727,0,11.076097,359.61591,-0.020344,17.70912,11.076735,359.02838,-9.290164
121.0,1.3675872,-0.310729,56.437027,0,11.076097,359.99924,-0.020521959,17.770876,11.075826,362.18781,-9.2901268
122.1,1.3525196,-0.31238219,53.994152,0,11.076097,359.99924,-0.020606453,17.577946,11.076499,364.77765,-9.2898226
123.2,1.3356628,-0.31272304,51.011902,0,11.076097,359.99924,-0.020625899,17.367678,11.07698,366.47992,-9.2900019
124.3,1.3244143,-0.31332877,48.002426,0,11.076097,359.99924,-0.020680754,17.21586,11.076646,367.10284,-9.2898769
125.4,1.2974606,-0.31240493,45.619652,0,11.076097,359.99924,-0.02062908,16.85799,11.075554,366.79507,-9.2895994
126.5,1.2743143,-0.30968031,44.077297,0,11.076097,359.99924,-0.020432029,16.566875,11.077016,365.57004,-9.2897625
127.6,1.2550675,-0.30802113,43.527905,0,11.076097,359.99924,-0.020298859,16.313557,11.075689,363.85382,-9.2897425
128.7,1.2477801,-0.30574217,44.603764,0,11.076097,359.99924,-0.020192964,16.216051,11.076711,361.8573,-9.2897234
129.8,1.1745279,-0.30516934,46.061825,0,11.076097,359.99924,-0.020140715,15.263925,11.075017,359.96674,-9.2897367
130.9,1.0715747,-0.30605513,47.81041,0,11.076097,359.99924,-0.020202665,13.917081,11.075793,358.46811,-9.2895365
132.0,1.0302153,-0.30619627,49.229671,0,11.076097,359.99924,-0.020193575,13.390344,11.075904,357.52609,-9.2897282
133.1,1.0082271,-0.3064892,50.786774,0,11.076097,359.99924,-0.020250272,13.116923,11.077076,357.00418,-9.289485
134.2,1.0051947,-0.30785143,51.56982,0,11.076097,359.99924,-0.02030587,13.063627,11.076347,356.98737,-9.2895546
135.3,1.0102737,-0.31007069,52.334137,0,11.076097,359.99924,-0.020456338,13.126178,11.076818,357.26385,-9.2893801
136.4,1.0060539,-0.31325191,52.638149,0,11.076097,359.99924,-0.020662434,13.076594,11.07737,357.81787,-9.2890396
137.5,0.99885088,-0.31312615,52.635616,0,11.076097,359.99924,-0.020684583,12.976753,11.076231,358.58682,-9.2889099
138.6,0.99621284,-0.3155165,52.290401,0,11.076097,359.99924,-0.020806547,12.951482,11.076386,359.49857,-9.288744
139.7,0.990668,-0.31687227,51.9324,0,11.076097,359.99924,-0.020879274,12.885846,11.076219,360.17392,-9.28897
140.8,0.99828637,-0.31712928,51.215759,0,11.076097,359.99924,-0.020926764,12.980387,11.077079,360.86865,-9.2884417
141.9,1.0033995,-0.31709519,50.73003,0,11.076097,359.99924,-0.020932134,13.052542,11.075931,361.2384,-9.2889805
143.0,0.99519765,-0.31902227,49.844471,0,11.076097,359.99924,-0.021049757,12.946595,11.076239,361.65186,-9.2887554
144.1,0.98873138,-0.31839696,49.229786,0,11.076097,359.99924,-0.020974034,12.860367,11.076219,361.54352,-9.2887945
145.2,0.97043186,-0.31831646,48.812294,0,11.076097,359.99924,-0.021008741,12.62703,11.075669,361.47766,-9.2885342
146.3,0.96955562,-0.31845194,48.81226,0,11.076097,359.99924,-0.021012515,12.601016,11.076769,361.16541,-9.2886019
147.4,0.9643634,-0.31817049,48.81226,0,11.076097,359.99924,-0.020994408,12.52579,11.076752,360.6911,-9.2886028
148.5,0.97063202,-0.3178412,48.81226,0,11.076097,359.99924,-0.020936152,12.628599,11.076262,360.21472,-9.288063
149.6,0.97986674,-0.31855878,49.229733,0,11.076097,359.99924,-0.02104505,12.742078,11.076114,359.86188,-9.2885017
150.7,0.96351123,-0.31865066,49.636227,0,11.076097,359.99924,-0.02101038,12.530408,11.076259,359.54822,-9.2881784
151.8,0.98082036,-0.31934118,50.042702,0,11.076097,359.99924,-0.021067871,12.769233,11.075667,359.38049,-9.2878952
152.9,0.98691601,-0.31971225,50.426094,0,11.076097,359.99924,-0.021065909,12.847151,11.076071,359.28171,-9.2878675
154.0,0.99286896,-0.31974652,50.461483,0,11.076097,359.99924,-0.021117855,12.920717,11.076455,359.32834,-9.2881479
155.1,0.9958955,-0.32018262,50.665417,0,11.076097,359.99924,-0.021104066,12.957917,11.075148,359.42068,-9.2881002
156.2,0.99316281,-0.32112506,50.735119,0,11.076097,359.99924,-0.021182166,12.909512,11.07531,359.60519,-9.2880373
157.3,0.9993704,-0.32311192,50.438347,0,11.076097,359.99924,-0.021294273,13.000558,11.076182,359.86218,-9.2878447
158.4,0.99015707,-0.32302043,50.438236,0,11.076097,359.99924,-0.021327635,12.868634,11.076357,360.03452,-9.2879353
159.5,0.98792005,-0.32357177,50.073799,0,11.076097,359.99924,-0.021333344,12.857075,11.075091,360.28418,-9.2879887
160.6,0.99698496,-0.32388952,50.042728,0,11.076097,359.99924,-0.021352924,12.973754,11.076034,360.32681,-9.2879877
161.7,0.99299723,-0.32392344,49.66143,0,11.076097,359.99924,-0.021346873,12.917979,11.075846,360.41519,-9.2879419
162.8,1.0004781,-0.32386899,49.636234,0,11.076097,359.99924,-0.021392817,13.021478,11.075698,360.38885,-9.2879725
163.9,0.98543954,-0.32559288,49.636234,0,11.076097,359.99924,-0.021457465,12.821671,11.076607,360.2995,-9.2881222
165.0,0.98661536,-0.32556763,49.636234,0,11.076097,359.99924,-0.021473803,12.82366,11.076499,360.22958,-9.2879105
165.2948,0.98588395,0.064036459,35.171349,0,11.076099,3.8987363e-07,0.0041497299,12.593845,11.078962,360.16223,-9.287282
165.297,1.04187,0.063999623,24.273176,0,11.076099,3.8939777e-22,0.0043690698,13.130859,11.078987,360.18884,-9.2875986
165.2992,0.98827654,0.066858344,13.375001,0,11.076099,3.8892252e-37,0.0043737451,12.564436,11.081485,360.21545,-9.2884216
165.3014,1.0051329,0.067886375,2.4768264,0,11.076099,0.0,0.0046586995,12.789957,11.0788,360.24207,-9.2877569
165.3036,1.0089034,0.066281945,0.0,0,11.076099,0.0,0.0042862729,12.83071,11.077198,360.22754,-9.2869577
165.3058,0.99851799,0.063885607,0.0,0,11.076099,0.0,0.0043392908,12.725084,11.07643,360.20093,-9.2873869
165.308,0.999502,0.063983358,0.0,0,11.076099,0.0,0.0041741543,12.665366,11.076505,360.17432,-9.2881575
165.3102,0.98995155,0.068183705,0.0,0,11.076099,0.0,0.0046654362,12.569936,11.075487,360.14771,-9.2884436
165.3124,0.98573232,0.067288034,0.0,0,11.076099,0.0,0.0043214923,12.496829,11.076711,360.12689,-9.288661
165.3146,0.98660141,0.063976616,0.0,0,11.076099,0.0,0.0043412321,12.539731,11.08003,360.12689,-9.2879086
165.3168,0.98383337,0.063203231,0.0,0,11.076099,0.0,0.0041293292,12.606068,11.072557,360.12689,-9.2872572
165.319,0.99014282,0.066870786,0.0,0,11.076099,0.0,0.004628954,12.558881,11.077859,360.12689,-9.2886763
165.3212,0.99282449,0.066574581,0.0,0,11.076099,0.0,0.004234652,12.563281,11.077951,360.12689,-9.2872152
165.3234,0.995956,0.064605668,0.0,0,11.076099,0.0,0.0043728692,12.577917,11.079721,360.13571,-9.288166
165.3256,0.99172014,0.063059509,0.0,0,11.076099,0.0,0.0040807589,12.533275,11.073379,360.14902,-9.287921
165.3278,0.97390789,0.06732513,0.0,0,11.076099,0.0,0.0046703801,12.343643,11.074574,360.16232,-9.2870903
165.33,0.96767801,0.067837581,0.0,0,11.076099,0.0,0.0043910574,12.341803,11.073158,360.17566,-9.2891531
165.3322,0.97492182,0.064557582,0.0,0,11.076099,0.0,0.0044311122,12.326171,11.078085,360.1875,-9.2896843
165.3344,0.97195977,0.06395752,0.0,0,11.076099,0.0,0.0041367617,12.301508,11.076497,360.1875,-9.2897224
165.3366,0.97445518,0.064799584,0.0,0,11.076099,0.0,0.0045193881,12.303096,11.073924,360.1875,-9.2886457
165.3388,0.97844917,0.066851981,0.0,0,11.076099,0.0,0.0042865574,12.29259,11.075911,360.1875,-9.2875051
165.341,0.97290844,0.065284073,0.0,0,11.076099,0.0,0.0044657975,12.313125,11.074264,360.1875,-9.2878752
165.3432,0.97298563,0.064322509,0.0,0,11.076099,0.0,0.0041357386,12.314561,11.076946,360.18011,-9.2884226
165.3454,0.96606833,0.065613128,0.0,0,10.795981,0.0,0.0045574373,12.262583,11.0776,360.16681,-9.2881575
165.3476,0.96172506,0.066714615,0.0,0,10.465089,0.0,0.0042518899,12.171906,11.073494,360.1535,-9.2884521
165.3498,0.97822291,0.063387699,0.0,0,10.134197,0.0,0.0043486799,12.382104,11.031658,360.1402,-9.2874289
165.352,0.95206702,0.064319253,0.0,0,9.8033047,0.0,0.0041458271,11.978326,10.864162,360.12689,-9.2877598
165.3542,0.97993618,0.06498348,0.0,0,9.4727468,0.0,0.0045561315,12.425168,10.58233,359.97385,-9.2883434
165.3564,0.95943028,0.067743257,0.0,0,9.1507626,0.0,0.0042970502,12.152058,10.219059,359.8208,-9.2878447
165.3586,7.2843318,0.28915405,0.0,0,8.8288584,0.0,0.018691752,90.765366,9.8568001,359.66779,-9.2821693
165.3608,8.89818,0.68262321,0.0,0,8.518857,0.0,0.045649342,107.62226,9.4325666,359.51474,-9.2810469
165.363,9.8576593,1.0722485,0.0,0,8.2127056,0.0,0.073972024,116.51346,9.0279999,360.38861,-9.2800732
165.3652,10.274589,1.4238162,0.0,0,7.9137359,0.0,0.098973349,118.63567,8.6661043,362.54089,-9.2801466
165.3674,10.693647,1.7470844,0.0,0,7.6224551,0.0,0.12372202,120.06258,8.3197699,364.69315,-9.2808819
165.3696,11.100091,2.0603459,0.0,0,7.3341722,0.0,0.14720473,121.8327,7.9902287,366.84543,-9.2798967
165.3718,11.34206,2.3628964,0.0,0,7.0571475,0.0,0.17137212,121.65415,7.6799493,368.99768,-9.2800493
165.374,11.67736,2.6474156,0.0,0,6.7801232,0.0,0.19345552,122.38776,7.3871498,371.54044,-9.2813292
165.3762,11.964289,2.9145393,0.0,0,6.5157218,0.0,0.21593395,122.65428,7.1086597,374.13098,-9.2812681
165.3784,12.201226,3.1799541,0.0,0,6.252162,0.0,0.23751572,122.46864,6.8386788,376.7215,-9.280715
165.3806,12.477186,3.4334917,0.0,0,5.9971719,0.0,0.25991863,122.49461,6.5786047,379.31204,-9.2800522
165.3828,12.756745,3.6891124,0.0,0,5.7465038,0.0,0.28147769,122.55425,6.3243203,381.20737,-9.2806749
165.385,13.073289,3.9326584,0.0,0,5.5006137,0.0,0.30407032,122.69379,6.069222,381.73108,-9.2801476
165.3872,13.401639,4.188766,0.0,0,5.2621331,0.0,0.3267028,122.97241,5.8190842,382.25479,-9.2806435
165.3894,13.71453,4.4346609,0.0,0,5.0250487,0.0,0.35046366,122.94255,5.5639091,382.77847,-9.2802687
165.3916,14.037731,4.6837354,0.0,0,4.798224,0.0,0.37340203,122.95901,5.3143053,383.30219,-9.2811317
165.3938,14.370182,4.9222078,0.0,0,4.571404,0.0,0.3977882,122.91356,5.0741067,381.67203,-9.281558
165.396,14.699836,5.1653872,0.0,0,4.3539338,0.0,0.42122951,122.78026,4.8288369,379.4408,-9.2807484
165.3982,15.035089,5.3948689,0.0,0,4.1381574,0.0,0.44587493,122.54433,4.5950994,377.20956,-9.2800293
165.4004,15.383774,5.6270318,0.0,0,3.9284413,0.0,0.46913764,122.50945,4.3645205,374.97833,-9.2799845
165.4026,15.766479,5.8403745,0.0,0,3.7232254,0.0,0.49338812,122.50162,4.13938,372.75189,-9.2793703
165.4048,16.170687,6.0610704,0.0,0,3.5210168,0.0,0.51666176,122.70925,3.9243252,370.54169,-9.2787371
165.407,16.581768,6.2694459,0.0,0,3.3257887,0.0,0.54138005,122.7959,3.7140493,368.33148,-9.2805643
165.4092,17.006157,6.4779339,0.0,0,3.1309152,0.0,0.56429738,123.09183,3.5095119,366.12128,-9.2799635
165.4114,17.441261,6.6712623,0.0,0,2.9451065,0.0,0.58854991,123.19309,3.306051,363.91107,-9.2795267
165.4136,17.905516,6.8691368,0.0,0,2.7593822,0.0,0.61137801,123.62924,3.1107202,361.66849,-9.2799911
165.4158,18.376202,7.0562577,0.0,0,2.5805073,0.0,0.63593024,123.8524,2.9185159,359.41013,-9.2791815
165.418,18.890671,7.2481365,0.0,0,2.4038472,0.0,0.65880513,124.44735,2.7355142,357.15176,-9.2773104
165.4202,19.443129,7.4238954,0.0,0,2.2313523,0.0,0.68338495,124.91855,2.5478632,354.8934,-9.2775583
165.4224,20.023121,7.6069565,0.0,0,2.0633163,0.0,0.70627528,125.72665,2.367238,352.84689,-9.2789688
165.4246,20.657532,7.7747273,0.0,0,1.8970004,0.0,0.7307319,126.57809,2.1945503,352.38113,-9.2783136
165.4268,21.310917,7.9514322,0.0,0,1.7371484,0.0,0.75382185,127.60798,2.0240099,351.91537,-9.2777185
165.429,21.989918,8.1110964,0.0,0,1.5772964,0.0,0.77860314,128.49129,1.8495363,351.44958,-9.2774897
165.4312,22.697529,8.280673,0.0,0,1.4247453,0.0,0.80191088,129.5365,1.684916,350.98383,-9.2765055
165.4334,23.428593,8.4361792,0.0,0,1.2726814,0.0,0.82715887,130.40695,1.5272127,352.16974,-9.2751446
165.4356,24.226624,8.6001749,0.0,0,1.1255604,0.0,0.85014665,131.77957,1.3674049,354.63437,-9.2758989
165.4378,25.06008,8.7399769,0.0,0,0.98093235,0.0,0.87451535,132.9817,1.2119441,357.099,-9.275075
165.44,25.954512,8.8922729,0.0,0,0.83908135,0.0,0.89713728,134.63174,1.0654167,359.5636,-9.2742558
165.4422,26.892378,9.0267115,0.0,0,0.70153737,0.0,0.92148465,136.15114,0.91586202,361.99918,-9.2736692
165.4444,27.856716,9.1747551,0.0,0,0.56478846,0.0,0.94410199,137.90883,0.77762097,361.26724,-9.2733078
165.4466,28.836205,9.2983036,0.0,0,0.4338859,0.0,0.96799713,139.35027,0.63727844,360.53531,-9.2734652
165.4488,29.676622,9.4272232,0.0,0,0.30298588,0.0,0.98871672,140.72871,0.50859934,359.80338,-9.2736454
165.451,26.606489,9.4413462,0.0,0,0.17752415,0.0,0.99349385,125.55369,0.44218495,359.07144,-9.2753687
165.4532,25.04105,9.4536028,0.0,0,0.053048152,0.0,0.99352568,118.06274,0.40360954,358.5361,-9.2763186
165.4554,24.214621,9.4467802,0.0,0,-0.069660425,0.0,0.99478579,114.11355,0.37187466,358.23669,-9.2775717
165.4576,23.837704,9.4611244,0.0,0,-0.19105642,0.0,0.9952358,112.14754,0.33659038,357.93726,-9.2799025
165.4598,23.819517,9.4575081,0.0,0,-0.31245244,0.0,0.99684858,111.92139,0.28913969,357.63785,-9.2800999
165.462,23.941805,9.4752645,0.0,0,-0.43384844,0.0,0.99731731,112.45003,0.22840048,357.33841,-9.2772579
165.4642,23.979654,9.4670782,0.0,0,-0.55524439,0.0,0.99851727,112.47398,0.16712162,358.62582,-9.2788239
165.4664,23.892317,9.4787436,0.0,0,-0.67664039,0.0,0.99854761,112.10446,0.11173367,360.08957,-9.2793283
165.4686,23.716921,9.4783783,0.0,0,-0.79803634,0.0,1.0006175,110.99656,0.066528499,361.55328,-9.2798176
165.4708,23.436373,9.4970045,0.0,0,-0.9194324,0.0,1.0012701,109.65311,0.03120701,363.01703,-9.2790613
165.473,23.061535,9.4879208,0.0,0,-1.0408285,0.0,1.002198,107.80084,0.0049036918,364.48462,-9.2797918
165.4752,22.566023,9.4928808,0.0,0,-0.9197427,359.99994,1.0010706,105.62431,-0.00462054,365.95953,-9.2799253
165.4774,21.994671,9.4882317,0.0,0,-0.49946383,359.99997,1.0023822,102.86131,-0.011630733,367.43445,-9.2809381
165.4796,21.425694,9.5017509,0.0,0,-0.079184711,359.99997,1.0022885,100.19115,-0.0038270762,368.90936,-9.2820787
165.4818,20.919945,9.4920826,0.0,0,0.34109476,359.99997,1.0030618,97.703529,0.0029212993,370.38431,-9.2831774
165.484,20.553196,9.4966555,0.0,0,0.76137364,359.99997,1.0017744,96.112915,0.0050684344,371.82141,-9.2818298
165.4862,20.257511,9.492198,0.0,0,1.1816528,359.99997,1.0031537,94.625771,0.0059061949,373.2485,-9.2828207
165.4884,19.646906,9.5026779,0.0,0,1.6019324,359.99997,1.0025328,91.922073,0.018489229,374.6756,-9.2831278
165.4906,17.899065,9.4863033,0.0,0,2.0222113,359.99997,1.0018942,83.806488,0.082263835,376.10272,-9.284668
165.4928,14.483735,9.4834557,0.0,0,2.4424908,359.99997,0.99941522,68.310631,0.22018456,377.41519,-9.2871361
165.495,8.949996,9.4542665,0.0,0,2.8627698,359.99997,0.99632156,42.980549,0.44757026,378.35739,-9.2925091
165.4972,0.39531815,9.3373108,0.0,0,3.2830491,359.99997,0.97355717,1.6821123,0.85483003,379.29959,-9.3016634
165.4994,0.10398899,9.2845459,0.0,0,3.7033279,359.99997,0.96595377,0.82594162,1.4632175,380.24176,-9.2995176
165.5016,-0.28817877,9.3335876,0.0,0,4.1236072,359.99997,0.97232658,-1.3532052,2.1487172,381.18396,-9.2995653
165.5038,0.081697196,9.4276981,0.0,0,4.5438867,359.99997,0.99098241,0.23840714,2.8086801,382.01691,-9.2992725
165.506,0.17513172,9.4736958,0.0,0,4.9641662,359.99997,0.99767166,1.6473445,3.3650093,382.79889,-9.2937737
165.5082,-0.11069263,9.4531183,0.0,0,5.3844447,359.99997,0.99564368,-0.71097773,3.803437,383.58087,-9.2968912
165.5104,1.3767848,9.462285,0.0,0,5.8047242,359.99997,0.99578553,6.6292253,4.1900282,384.36282,-9.2929611
165.5126,0.59828579,9.4522505,0.0,0,6.2250032,359.99997,0.99552208,2.7463167,4.5848842,385.13297,-9.2933445
165.5148,0.52023232,9.4544144,0.0,0,6.6452827,359.99997,0.99416113,2.408237,4.9795604,385.82172,-9.293294
165.517,0.57875556,9.4439688,0.0,0,7.0655618,359.99997,0.993976,2.715749,5.3963532,386.5105,-9.2917948
165.5192,0.72985947,9.4510832,0.0,0,7.4858413,359.99997,0.99375087,3.4551339,5.8283257,387.19925,-9.2912712
165.5214,0.63069004,9.4464989,0.0,0,7.9061203,359.99997,0.99461412,2.9693565,6.2550282,387.88803,-9.2910662
165.5236,0.55871701,9.4613409,0.0,0,8.3263998,359.99997,0.9952963,2.6199992,6.6965799,388.50092,-9.2904358
165.5258,0.66307688,9.4506502,0.0,0,8.7466784,359.99997,0.99501944,3.0921686,7.1427536,389.05722,-9.2911692
165.528,0.66201961,9.4547815,0.0,0,9.1669579,359.99997,0.9946444,3.1001308,7.5802684,389.61353,-9.2900658
165.5302,0.61987841,9.4493952,0.0,0,9.5872374,359.99997,0.9950276,2.9285605,8.0111179,390.16983,-9.2904358
165.5324,0.56715643,9.4565201,0.0,0,10.007517,359.99997,0.99455011,2.721921,8.4365997,390.72433,-9.2894258
165.5346,0.57236636,9.449955,0.0,0,10.427795,359.99997,0.99492353,2.6876538,8.8728933,391.1813,-9.2899246
165.5368,0.64439237,9.4556036,0.0,0,10.848075,359.99997,0.99466205,3.024168,9.3162184,391.63828,-9.2893057
165.539,0.63184774,9.4479065,0.0,0,11.268353,359.99997,0.99465948,2.9689567,9.7433424,392.09525,-9.2889433
165.5412,0.57123715,9.4620867,0.0,0,11.688633,359.99997,0.99559903,2.7038581,10.177881,392.55222,-9.28794
165.5434,0.55958492,9.4496384,0.0,0,12.108912,359.99997,0.99492383,2.6181464,10.615881,392.9631,-9.2876129
165.5456,0.61210167,9.4557629,0.0,0,12.529191,359.99997,0.99475551,2.8454823,11.046313,393.32074,-9.2888355
165.5478,0.66563493,9.447566,0.0,0,12.949471,359.99997,0.99440259,3.1806946,11.465657,393.67838,-9.2878389
165.55,0.58882886,9.4575796,0.0,0,13.36975,359.99997,0.99482816,2.8065279,11.880289,394.03601,-9.2880268
165.5522,0.56717736,9.4485798,0.0,0,13.790029,359.99997,0.99459261,2.685709,12.299535,394.39365,-9.2875071
165.5544,0.60875767,9.455862,0.0,0,14.210308,359.99997,0.99486864,2.8921275,12.725584,394.70911,-9.2870483
165.5566,0.63534796,9.448061,0.0,0,14.630587,359.99997,0.9946537,2.9501569,13.157333,395.02039,-9.2863607
165.5588,0.64193022,9.4580011,0.0,0,15.050866,359.99997,0.99508959,3.0670376,13.590921,395.33163,-9.2862301
165.561,0.58097053,9.450367,0.0,0,15.471146,359.99997,0.99485481,2.7487957,14.03173,395.64291,-9.2875862
165.5632,0.61723155,9.4542551,0.0,0,15.891425,359.99997,0.99471879,2.9009278,14.475775,395.91895,-9.2869625
165.5654,0.65022254,9.4494486,0.0,0,16.311705,359.99997,0.99454027,3.0262256,14.906188,396.13089,-9.2876272
165.5676,0.67215639,9.4587345,0.0,0,16.731983,359.99997,0.99521267,3.1535907,15.323192,396.3428,-9.2878437
165.5698,0.6043303,9.450655,0.0,0,17.152262,359.99997,0.994784,2.8844717,15.741252,396.55475,-9.286725
165.572,0.57277459,9.4582195,0.0,0,17.572542,359.99997,0.99528223,2.7396102,16.15756,396.76666,-9.2864113
165.5742,0.59997857,9.4496756,0.0,0,17.986284,359.99997,0.9946422,2.7720547,16.577812,396.94662,-9.2865324
165.5764,0.64230877,9.4587164,0.0,0,18.0,359.99997,0.9953056,3.051631,16.986818,397.11862,-9.2868757
165.5786,0.61048359,9.4520226,0.0,0,18.0,359.99997,0.99505252,2.8933806,17.399446,397.29059,-9.2873764
165.5808,0.65103388,9.455019,0.0,0,18.0,359.99997,0.99485499,3.0812771,17.764265,397.46259,-9.2862978
165.583,0.65987933,9.4503393,0.0,0,18.0,359.99997,0.99474639,3.0685022,18.081606,397.63779,-9.2878885
165.5852,0.7106474,9.4610033,0.0,0,18.0,359.99997,0.99575269,3.2983553,18.323452,397.82285,-9.2893324
165.5874,0.70148563,9.4518185,0.0,0,18.0,359.99997,0.99485356,3.345794,18.486992,398.0079,-9.29177
165.5896,0.69678861,9.4557934,0.0,0,18.0,359.99997,0.99519795,3.3027854,18.530264,398.19296,-9.2964954
165.5918,0.68564868,9.4502239,0.0,0,18.0,359.99997,0.99450547,3.2454436,18.475557,398.37805,-9.3050652
165.594,0.70710629,9.4594326,0.0,0,18.0,359.99997,0.99559247,3.3029077,18.35183,398.50372,-9.3150997
165.5962,0.72077042,9.4498224,0.0,0,18.0,359.99997,0.99450207,3.3760378,18.225456,398.60284,-9.3259945
165.5984,0.72543347,9.4558029,0.0,0,18.0,359.99997,0.99516338,3.4091721,18.125364,398.702,-9.3394089
165.6006,0.73068887,9.4509668,0.0,0,18.0,359.99997,0.99449277,3.4155176,18.06201,398.80112,-9.3554916
165.6028,0.76208091,9.4556017,0.0,0,18.0,359.99997,0.99509114,3.5555954,18.054028,398.89844,-9.3731451
165.605,0.74185264,9.4471302,0.0,0,18.0,359.99997,0.99388683,3.5224907,18.056385,398.98434,-9.3924932
165.6072,0.68717468,9.4512644,0.0,0,18.0,359.99997,0.9944554,3.318152,18.069441,399.07025,-9.4107447
165.6094,0.67099875,9.4438095,0.0,0,18.0,359.99997,0.99316084,3.1778977,18.089003,399.15619,-9.4307251
165.6116,0.66321069,9.4544325,0.0,0,18.0,359.99997,0.99492252,3.1249039,18.110147,399.2421,-9.4462404
165.6138,0.64522886,9.4476528,0.0,0,18.0,359.99997,0.99382353,3.0649536,18.129654,399.328,-9.4634008
165.616,0.67748076,9.4495773,0.0,0,18.0,359.99997,0.99429536,3.1674809,18.146343,399.41391,-9.4802895
165.6182,0.71915603,9.4435863,0.0,0,18.0,359.99997,0.99322796,3.3619206,18.151043,399.49985,-9.4969778
165.6204,0.74750555,9.4518881,0.0,0,18.0,359.99997,0.99454278,3.5311677,18.151932,399.58575,-9.5125742
165.6226,0.76697469,9.4473028,0.0,0,18.0,359.99997,0.99381858,3.6189215,18.151026,399.67114,-9.5293398
165.6248,0.73510647,9.4517536,0.0,0,18.0,359.99997,0.99456948,3.5341992,18.152361,399.73724,-9.5448656
165.627,0.6934821,9.4447708,0.0,0,18.0,359.99997,0.99327409,3.2985194,18.143049,399.80331,-9.5609379
165.6292,0.67438382,9.4529428,0.0,0,18.0,359.99997,0.99484456,3.1839154,18.144104,399.86942,-9.5766592
165.6314,0.66271323,9.4483576,0.0,0,18.0,359.99997,0.99380654,3.1536548,18.141497,399.93549,-9.5913181
165.6336,0.69573826,9.4486732,0.0,0,18.0,359.99997,0.99423081,3.2833915,18.137941,399.98907,-9.6073217
165.6358,0.71592569,9.4454498,0.0,0,18.0,359.99997,0.993312,3.3482647,18.133362,400.02875,-9.6241655
165.638,0.76351869,9.4527483,0.0,0,18.0,359.99997,0.99486578,3.5702114,18.133253,400.06839,-9.640543
165.6402,0.75848323,9.4508142,0.0,0,18.0,359.99997,0.99404269,3.5874014,18.13084,400.10803,-9.6568165
165.6424,0.7579819,9.4511414,0.0,0,18.0,359.99997,0.99471295,3.6247251,18.129215,400.14771,-9.6720324
165.6446,0.72925878,9.4453239,0.0,0,18.0,359.99997,0.99322647,3.4796236,18.126171,400.16916,-9.6875277
165.6468,0.70595884,9.4512672,0.0,0,18.0,359.99997,0.99482119,3.3384793,18.123461,400.18896,-9.7036581
165.649,0.67396647,9.4484262,0.0,0,18.0,359.99997,0.99363703,3.1885073,18.118311,400.2088,-9.7202024
165.6512,0.68327343,9.4486198,0.0,0,18.0,359.99997,0.99440426,3.2083504,18.118029,400.22864,-9.7356253
165.6534,0.71385229,9.4478683,0.0,0,18.0,359.99997,0.99351978,3.3395877,18.115864,400.24365,-9.7508087
165.6556,0.75292665,9.4525948,0.0,0,18.0,359.99997,0.99513578,3.4993958,18.115122,400.25024,-9.7674093
165.6578,0.77680641,9.4474058,0.0,0,18.0,359.99997,0.99335963,3.6551657,18.117144,400.25687,-9.7840271
165.66,0.77780449,9.4472713,0.0,0,18.0,359.99997,0.99423611,3.6725707,18.11618,400.26346,-9.79988
165.6622,0.73950905,9.4488802,0.0,0,18.0,359.99997,0.9937669,3.5186336,18.114384,400.27008,-9.8163071
165.6644,0.70628744,9.4523344,0.0,0,18.0,359.99997,0.99512988,3.371469,18.112551,400.25528,-9.8326998
165.6666,0.68263531,9.4487753,0.0,0,18.0,359.99997,0.99358815,3.24208,18.110001,400.23547,-9.8482485
165.6688,0.67424375,9.4479275,0.0,0,18.0,359.99997,0.99442631,3.1457133,18.108934,400.21564,-9.8637333
165.671,0.70487875,9.4460812,0.0,0,18.0,359.99997,0.99315017,3.2792115,18.104156,400.1958,-9.8802691
165.6732,0.73107225,9.4466429,0.0,0,18.0,359.99997,0.99429119,3.4269631,18.110762,400.18103,-9.8960161
165.6754,0.76222891,9.4490128,0.0,0,18.0,359.99997,0.99349004,3.5765743,18.108328,400.18103,-9.9128828
165.6776,0.77705175,9.4491854,0.0,0,18.0,359.99997,0.99473584,3.6601584,18.108257,400.18103,-9.9291306
165.6798,0.75189954,9.4472494,0.0,0,18.0,359.99997,0.99319166,3.5708332,18.110395,400.18103,-9.9448481
165.682,0.71767431,9.4485788,0.0,0,18.0,359.99997,0.99467009,3.4067318,18.108622,400.18103,-9.9625597
165.6842,0.67920232,9.4505501,0.0,0,18.0,359.99997,0.99376363,3.2379863,18.106667,400.19028,-9.9795647
165.6864,0.6525991,9.449398,0.0,0,18.0,359.99997,0.99461877,3.1094327,18.098799,400.20349,-9.995019
165.6886,0.66984969,9.4489107,0.0,0,18.0,359.99997,0.99348176,3.1541712,18.100809,400.21674,-10.010894
165.6908,0.70571852,9.449748,0.0,0,18.0,359.99997,0.99501997,3.2915478,18.097454,400.22995,-10.026357
165.693,0.75154418,9.4510946,0.0,0,18.0,359.99997,0.9936322,3.5157118,18.097395,400.24124,-10.041775
165.6952,0.76593983,9.4486494,0.0,0,18.0,359.99997,0.99465239,3.5548868,18.099735,400.24124,-10.058343
165.6974,0.7648809,9.4474936,0.0,0,18.0,359.99997,0.99315017,3.6120236,18.10268,400.24124,-10.074982
165.6996,0.73716873,9.4516344,0.0,0,18.0,359.99997,0.99546832,3.4814618,18.097389,400.24124,-10.089975
165.7018,0.71643519,9.4531031,0.0,0,18.0,359.99997,0.994102,3.4173782,18.097383,400.24124,-10.105413
165.704,0.68253773,9.4476252,0.0,0,18.0,359.99997,0.99455667,3.2330077,18.095612,400.24515,-10.12085
165.7062,0.68006784,9.4459143,0.0,0,18.0,359.99997,0.99287975,3.2062972,18.094128,400.25174,-10.13874
165.7084,0.69134903,9.4498148,0.0,0,18.0,359.99997,0.99522191,3.2188811,18.094759,400.25836,-10.155007
165.7106,0.75777215,9.4538813,0.0,0,18.0,359.99997,0.99399269,3.5316861,18.095003,400.26495,-10.170658
165.7128,0.77704227,9.4498959,0.0,0,18.0,359.99997,0.99510193,3.5998466,18.092823,400.27039,-10.187178
165.715,0.78465152,9.4497356,0.0,0,18.0,359.99997,0.99334699,3.733587,18.092148,400.24393,-10.203045
165.7172,0.77424908,9.4486313,0.0,0,18.0,359.99997,0.99479222,3.6861403,18.09481,400.2175,-10.218943
165.7194,0.74856663,9.4530039,0.0,0,18.0,359.99997,0.99389607,3.5088384,18.093067,400.19107,-10.236082
165.7216,0.70266396,9.4504118,0.0,0,18.0,359.99997,0.99521154,3.3307374,18.092133,400.16464,-10.251049
165.7238,0.6959632,9.4515438,0.0,0,18.0,359.99997,0.99377441,3.2982168,18.087185,400.14777,-10.266706
165.726,0.6962918,9.4494839,0.0,0,18.0,359.99997,0.9951278,3.2525232,18.09137,400.14114,-10.284218
165.7282,0.73710048,9.4514933,0.0,0,18.0,359.99997,0.99364686,3.443279,18.088421,400.13455,-10.299811
165.7304,0.77785569,9.4483204,0.0,0,18.0,359.99997,0.99486333,3.6248326,18.085104,400.12793,-10.315804
165.7326,0.7998054,9.4500437,0.0,0,18.0,359.99997,0.9933781,3.7573299,18.088121,400.12134,-10.330507
165.7348,0.78543407,9.4495687,0.0,0,18.0,359.99997,0.99498701,3.6881082,18.086674,400.12085,-10.34627
165.737,0.76226616,9.4507208,0.0,0,18.0,359.99997,0.99336004,3.6299143,18.085562,400.12085,-10.362554
165.7392,0.71536702,9.4458637,0.0,0,18.0,359.99997,0.99474221,3.4179208,18.08604,400.12085,-10.378658
165.7414,0.69183069,9.4511232,0.0,0,18.0,359.99997,0.9935742,3.3118114,18.08906,400.12085,-10.395496
165.7436,0.68847835,9.4499712,0.0,0,18.0,359.99997,0.99521774,3.2105172,18.081663,400.09622,-10.411462
165.7458,0.71549618,9.4542427,0.0,0,18.0,359.99997,0.99401474,3.3702435,18.07946,400.03012,-10.427988
165.748,0.75065744,9.449151,0.0,0,18.0,359.99997,0.99516326,3.4948215,18.07992,399.96402,-10.445094
165.7502,0.79142737,9.453474,0.0,0,18.0,359.99997,0.99383909,3.6940794,18.080601,399.89795,-10.462553
165.7524,0.78339016,9.4489079,0.0,0,18.0,359.99997,0.99505931,3.7104959,18.082037,399.83185,-10.47776
165.7546,0.76433647,9.4538374,0.0,0,18.0,359.99997,0.99388379,3.5958779,18.081007,399.77658,-10.493737
165.7568,0.73434341,9.4469938,0.0,0,18.0,359.99997,0.99469125,3.4879303,18.078093,399.72369,-10.509535
165.759,0.70759761,9.4517231,0.0,0,18.0,359.99997,0.99359256,3.3493583,18.08107,399.67084,-10.526123
165.7612,0.68121827,9.4485111,0.0,0,18.0,359.99997,0.99517709,3.221004,18.078848,399.61798,-10.542377
165.7634,0.69063032,9.4544573,0.0,0,18.0,359.99997,0.99393684,3.2419856,18.07988,399.57904,-10.557746
165.7656,0.75332391,9.4455643,0.0,0,18.0,359.99997,0.99451911,3.4937744,18.075575,399.57904,-10.573174
165.7678,0.77201003,9.4520931,0.0,0,18.0,359.99997,0.99371606,3.6037104,18.079536,399.57904,-10.590549
165.77,0.7997371,9.4490395,0.0,0,18.0,359.99997,0.99518687,3.7695365,18.079002,399.57904,-10.606734
165.7722,0.78078312,9.4544916,0.0,0,18.0,359.99997,0.99375713,3.7153802,18.076231,399.57904,-10.621911
165.7744,0.75442839,9.4466047,0.0,0,18.0,359.99997,0.99467254,3.5966487,18.076771,399.57904,-10.638858
165.7766,0.71086097,9.4522858,0.0,0,18.0,359.99997,0.99363607,3.4196258,18.077684,399.57904,-10.652717
165.7788,0.70484477,9.4492245,0.0,0,18.0,359.99997,0.99518949,3.3231912,18.076786,399.57904,-10.669868
165.781,0.69925559,9.4537182,0.0,0,18.0,359.99997,0.99376845,3.2776866,18.071318,399.57904,-10.683805
165.7832,0.74123883,9.4447756,0.0,0,18.0,359.99997,0.99440676,3.4781933,18.070385,399.57495,-10.701245
165.7854,0.76911187,9.4525471,0.0,0,18.0,359.99997,0.99351418,3.6032376,18.070667,399.54852,-10.718288
165.7876,0.80446362,9.4462872,0.0,0,18.0,359.99997,0.99473405,3.7678204,18.069023,399.52209,-10.73424
165.7898,0.80586386,9.4528027,0.0,0,18.0,359.99997,0.9934302,3.8074121,18.068581,399.49567,-10.750592
165.792,0.7799378,9.4467897,0.0,0,18.0,359.99997,0.99481946,3.6820939,18.067183,399.46921,-10.767124
165.7942,0.73622739,9.4532671,0.0,0,18.0,359.99997,0.99356812,3.5027814,18.071444,399.44196,-10.783307
165.7964,0.72764498,9.4466476,0.0,0,18.0,359.99997,0.99498802,3.4464006,18.066792,399.41412,-10.800503
165.7986,0.70253992,9.454855,0.0,0,18.0,359.99997,0.99382675,3.3233984,18.066944,399.38632,-10.815696
165.8008,0.7230621,9.4448004,0.0,0,18.0,359.99997,0.99441248,3.3696971,18.066353,399.35849,-10.831942
165.803,0.75940013,9.4521303,0.0,0,18.0,359.99997,0.99378961,3.5721438,18.063158,399.33105,-10.846819
165.8052,0.81355023,9.4457817,0.0,0,18.0,359.99997,0.99478096,3.8045809,18.061779,399.3046,-10.863172
165.8074,0.81194407,9.4549017,0.0,0,18.0,359.99997,0.99368167,3.8558271,18.062761,399.27817,-10.87971
165.8096,0.79575658,9.4472237,0.0,0,18.0,359.99997,0.99481946,3.7512383,18.061537,399.25174,-10.896277
165.8118,0.75026268,9.4536848,0.0,0,18.0,359.99997,0.99400234,3.569942,18.062944,399.22528,-10.912174
165.814,0.72414732,9.4455233,0.0,0,18.0,359.99997,0.99464715,3.4313493,18.062435,399.19885,-10.92609
165.8162,0.70745957,9.4544773,0.0,0,18.0,359.99997,0.99376225,3.3525338,18.062553,399.17239,-10.943527
165.8184,0.71867585,9.4454794,0.0,0,18.0,359.99997,0.99451518,3.3811517,18.061537,399.14597,-10.959595
165.8206,0.74714589,9.4505949,0.0,0,18.0,359.99997,0.99339426,3.4970813,18.061531,399.11954,-10.976319
165.8228,0.79141796,9.4449968,0.0,0,18.0,359.99997,0.99444348,3.6510057,18.062338,399.09308,-10.992554
165.825,0.82514405,9.4536762,0.0,0,18.0,359.99997,0.99360549,3.8679216,18.061472,399.06665,-11.00952
165.8272,0.80830538,9.44555,0.0,0,18.0,359.99997,0.9943794,3.842068,18.061018,399.04022,-11.02463
165.8294,0.77653182,9.4499788,0.0,0,18.0,359.99997,0.99337035,3.7202475,18.061262,399.01379,-11.041332
165.8316,0.74062419,9.4463348,0.0,0,18.0,359.99997,0.99474388,3.5006239,18.064449,398.98737,-11.057043
165.8338,0.71518421,9.4553394,0.0,0,18.0,359.99997,0.99373138,3.4020133,18.060637,398.96494,-11.07198
165.836,0.70737928,9.4441414,0.0,0,18.0,359.99997,0.99419874,3.3071711,18.061255,398.94513,-11.088541
165.8382,0.73738015,9.450036,0.0,0,18.0,359.99997,0.99336249,3.4059253,18.057173,398.92529,-11.102913
165.8404,0.77706808,9.4434185,0.0,0,18.0,359.99997,0.99435055,3.6157799,18.057055,398.90546,-11.120881
165.8426,0.81531036,9.4527855,0.0,0,18.0,359.99997,0.99350721,3.7897375,18.061359,398.88455,-11.137205
165.8448,0.8233484,9.4447947,0.0,0,18.0,359.99997,0.99429858,3.8908715,18.056784,398.84491,-11.15287
165.847,0.79597652,9.4503479,0.0,0,18.0,359.99997,0.99354362,3.749902,18.055073,398.80527,-11.169711
165.8492,0.75998116,9.4447012,0.0,0,18.0,359.99997,0.99448782,3.607933,18.053869,398.76563,-11.185524
165.8514,0.73394459,9.4574814,0.0,0,18.0,359.99997,0.99436432,3.5201445,18.052973,398.72598,-11.200619
165.8536,0.71235818,9.4457273,0.0,0,18.0,359.99997,0.99451172,3.3685362,18.058283,398.68964,-11.217565
165.8558,0.73131502,9.4506807,0.0,0,18.0,359.99997,0.99358702,3.4325292,18.05481,398.65659,-11.232561
165.858,0.77016115,9.4432192,0.0,0,18.0,359.99997,0.993945,3.5775528,18.054867,398.62354,-11.248942
165.8602,0.8106159,9.4556894,0.0,0,18.0,359.99997,0.99413514,3.782701,18.056677,398.59048,-11.263838
165.8624,0.82735032,9.4447088,0.0,0,18.0,359.99997,0.99420047,3.9084461,18.051619,398.55743,-11.280347
165.8646,0.84243542,9.4506159,0.0,0,18.0,359.99997,0.99358481,3.964824,18.053041,398.5369,-11.297259
165.8668,0.79261196,9.4459867,0.0,0,18.0,359.99997,0.99465567,3.7422359,18.053205,398.51706,-11.313619
165.869,0.75352174,9.4567614,0.0,0,18.0,359.99997,0.99440968,3.5798357,18.053604,398.49722,-11.328807
165.8712,0.72144663,9.4448843,0.0,0,18.0,359.99997,0.99404287,3.4226453,18.046131,398.47742,-11.344935
165.8734,0.72806966,9.4479208,0.0,0,18.0,359.99997,0.9931466,3.4443262,18.050903,398.44724,-11.360951
166.5741,0.71531349,9.4535513,0.0,0,18.0,1.0387566e-07,0.99490917,3.3642445,18.003668,381.0231,-11.481495
167.6741,0.6905067,9.4610548,0.0,0,18.0,1.037486e-22,0.99620813,3.241416,17.9998,366.28442,-11.481461
168.7741,0.66500968,9.4669418,0.0,0,18.0,1.0362165999999998e-37,0.99738699,3.1272483,18.000092,354.89969,-11.481368
169.8741,0.6558494,9.473691,0.0,0,18.0,1.4012985e-45,0.99845344,3.076082,18.000744,344.82745,-11.481763
170.9741,0.65487361,9.4783182,0.0,0,18.0,1.4012985e-45,0.99940526,3.0694432,18.000462,335.77527,-11.481687
172.0741,0.65699375,9.4833641,0.0,0,18.0,1.4012985e-45,1.0002643,3.0777826,18.00028,327.0126,-11.481959
173.1741,0.64614797,9.4883718,0.0,0,18.0,1.4012985e-45,1.0012993,3.0253124,18.000362,318.91797,-11.481584
174.2741,0.64592832,9.4931107,0.0,0,18.0,1.4012985e-45,1.0019791,3.0165823,18.000622,310.7739,-11.482014
175.3741,0.64557809,9.4977589,0.0,0,18.0,1.4012985e-45,1.0029038,3.0064745,18.000082,303.23383,-11.481654
176.4741,0.6536237,9.5027723,0.0,0,18.0,1.4012985e-45,1.00377,3.0514343,17.999388,295.82022,-11.481877
177.5741,0.6459375,9.506834,0.0,0,18.0,1.4012985e-45,1.0046442,3.0139101,18.000238,288.66046,-11.481711
178.6741,0.64176172,9.5116053,0.0,0,18.0,1.4012985e-45,1.0053279,2.9899542,18.000473,281.45279,-11.481744
179.7741,0.65210152,9.5156832,0.0,0,18.0,1.4012985e-45,1.0061351,3.0287147,18.00012,274.77618,-11.481715
180.8741,0.65444863,9.5189466,0.0,0,18.0,1.4012985e-45,1.006726,3.0482569,17.999706,267.82037,-11.481981
181.9741,0.64008361,9.522891,0.0,0,18.0,1.4012985e-45,1.0075719,2.9787664,18.000303,261.3103,-11.481639
183.0741,0.63854337,9.5274515,0.0,0,18.0,1.4012985e-45,1.0082588,2.9606757,18.000278,255.08223,-11.481483
184.1741,0.65083569,9.5310326,0.0,0,18.0,1.4012985e-45,1.0089252,3.018326,17.999891,248.90451,-11.481409
185.2741,0.64457172,9.5350666,0.0,0,18.0,1.4012985e-45,1.0097089,2.9987459,18.000065,242.99323,-11.481542
186.3741,0.63813221,9.538538,0.0,0,18.0,1.4012985e-45,1.0103881,2.9585907,18.000639,237.15222,-11.481895
187.4741,0.64692706,9.5422487,0.0,0,18.0,1.4012985e-45,1.0109977,2.9867826,18.000546,231.33705,-11.481591
188.5741,0.65749931,9.5462475,0.0,0,18.0,1.4012985e-45,1.0116563,3.0496483,17.999336,225.96133,-11.482112
189.6741,0.63769156,9.5492182,0.0,0,18.0,1.4012985e-45,1.0123302,2.9551978,17.999392,220.48833,-11.48184
190.7741,0.63923573,9.5521803,0.0,0,18.0,1.4012985e-45,1.0128466,2.9561152,18.000225,215.34558,-11.482022
191.8741,0.64708334,9.5552044,0.0,0,18.0,1.4012985e-45,1.0134133,2.9911709,18.00062,210.13008,-11.482206
192.9741,0.64534622,9.5594158,0.0,0,18.0,1.4012985e-45,1.0140643,2.9821994,18.000019,205.16269,-11.481868
194.0741,0.63718438,9.5612888,0.0,0,18.0,1.4012985e-45,1.014585,2.9501576,18.000221,200.36475,-11.48227
195.1741,0.63521093,9.5645523,0.0,0,18.0,1.4012985e-45,1.0150836,2.9285629,17.999956,195.52208,-11.481882
196.2741,0.64947402,9.5668211,0.0,0,18.0,1.4012985e-45,1.0156156,2.9922762,18.000443,190.67561,-11.481987
197.3741,0.64350152,9.5694666,0.0,0,18.0,1.4012985e-45,1.0159104,2.9700379,18.000219,186.33284,-11.482034
198.4741,0.63236219,9.5720873,0.0,0,18.0,1.4012985e-45,1.0165179,2.9169044,17.999372,181.96107,-11.482077
199.5741,0.64164138,9.5744848,0.0,0,18.0,1.4012985e-45,1.0168978,2.9517503,18.000151,177.54747,-11.481983
200.6741,0.63895679,9.5766077,0.0,0,18.0,1.4012985e-45,1.0174288,2.9401484,18.000837,173.6244,-11.481894
201.7741,0.63882589,9.5792589,0.0,0,18.0,1.4012985e-45,1.0177673,2.946249,18.000364,169.59265,-11.481823
202.8741,0.6405707,9.5821943,0.0,0,18.0,1.4012985e-45,1.0182922,2.9363556,17.999702,165.76489,-11.481838
203.9741,0.63723379,9.584219,0.0,0,18.0,1.4012985e-45,1.0188001,2.9257596,17.999655,161.92049,-11.481997
205.0741,0.63553452,9.5868111,0.0,0,18.0,1.4012985e-45,1.0192285,2.9233916,17.999922,158.25833,-11.481736
206.1741,0.62966305,9.589386,0.0,0,18.0,1.4012985e-45,1.0197158,2.8946247,17.998667,154.72009,-11.482226
207.2741,0.6362434,9.5914288,0.0,0,18.0,1.4012985e-45,1.0199443,2.9141443,18.000746,151.26184,-11.482285
208.3741,0.64779383,9.5936193,0.0,0,18.0,1.4012985e-45,1.0205142,2.9684649,17.999933,147.8029,-11.482387
209.4741,0.63825649,9.5961018,0.0,0,18.0,1.4012985e-45,1.0209043,2.9325771,18.000341,144.37943,-11.482071
210.5741,0.62402529,9.5977802,0.0,0,18.0,1.4012985e-45,1.0213418,2.8596437,18.000391,141.25008,-11.481915
211.6741,0.63638997,9.6007671,0.0,0,18.0,1.4012985e-45,1.0217265,2.9116037,18.000097,138.10194,-11.482007
212.7741,0.640459,9.6026306,0.0,0,18.0,1.4012985e-45,1.022118,2.9298286,17.999954,134.99805,-11.482132
213.8741,0.6368342,9.6050959,0.0,0,18.0,1.4012985e-45,1.0226004,2.9249821,17.999777,132.06337,-11.482323
214.9741,0.63341254,9.6069441,0.0,0,18.0,1.4012985e-45,1.0230026,2.8896959,17.999874,128.85011,-11.482152
216.0741,0.63472706,9.6091709,0.0,0,18.0,1.4012985e-45,1.0233437,2.8952303,18.0002,126.14027,-11.482186
217.1741,0.63481855,9.6114206,0.0,0,18.0,1.4012985e-45,1.0236552,2.9047956,18.00032,123.44457,-11.481921
218.2741,0.62769675,9.6132832,0.0,0,18.0,1.4012985e-45,1.0241563,2.874069,17.999949,120.79076,-11.48217
219.3741,0.62728047,9.6148815,0.0,0,18.0,1.4012985e-45,1.0243702,2.8605745,18.000629,118.25773,-11.482388
220.4741,0.63841009,9.6167049,0.0,0,18.0,1.4012985e-45,1.0248401,2.9146998,17.999548,115.78183,-11.48198
221.5741,0.62770289,9.618865,0.0,0,18.0,1.4012985e-45,1.0251013,2.8730597,17.999615,113.34418,-11.482094
222.6741,0.62481159,9.6204557,0.0,0,18.0,1.4012985e-45,1.0253831,2.8559303,18.00403,110.86098,-11.482297
223.7741,0.6325267,9.6221046,0.0,0,18.0,1.4012985e-45,1.025795,2.8829403,17.999969,108.68174,-11.482122
224.8741,0.64044434,9.6238174,0.0,0,18.0,1.4012985e-45,1.0260793,2.9243748,17.999483,106.46441,-11.482111
225.8741,0.61588669,9.6252575,0.0,0,18.0,1.4012985e-45,1.0263925,2.8098769,17.999107,104.43085,-11.482211