File: examples/dan-msc-case-studies/CS3/data/01 raw data/baron_test_017.csv
Time(sec),Force(kN),Jaw(mm),PowAngle(deg),Power(W),Pram,PTemp,Strain,Stress(MPa),Stroke(mm),TC1(C),wedge(mm)
0.0,1.1497059,0.39515114,0.0,0,11.076097,0.0015597969,0.026696105,14.241332,11.075536,25.319466,-9.1208105
1.2,1.0711907,0.0040173172,0.0,0,11.076097,3.5159004,0.00027756765,13.646629,11.077188,25.294565,-9.4902
2.4,1.0389103,0.0041613844,0.0,0,11.076097,7.1159019,0.00025788491,13.230803,11.075871,25.210844,-9.4872961
3.6,1.0121846,0.0042596646,0.0,0,11.076097,10.715903,0.00030038471,12.874728,11.07628,25.206423,-9.485795
4.8,0.99209934,0.0041613667,0.0,0,11.076097,14.315903,0.00028836043,12.626804,11.076001,25.220633,-9.4837589
6.0,0.9798829,0.0042870464,0.0,0,11.076097,17.915905,0.00026753265,12.476294,11.07606,25.240896,-9.4814281
7.2,0.97786444,0.0044583874,0.0,0,11.076097,21.515907,0.0002962474,12.447778,11.076497,25.210899,-9.4791336
8.4,0.96488279,0.0041459599,0.0,0,11.076097,25.115904,0.00027583449,12.282221,11.076418,25.18457,-9.4768953
9.6,0.95721841,0.0047377544,19.937946,0,11.076097,28.715908,0.00030832173,12.194727,11.075108,25.184868,-9.4745054
10.8,0.96323085,0.0051494301,34.882309,0,11.076097,32.31591,0.00034354514,12.256073,11.076188,25.260946,-9.4730558
12.0,0.96478611,0.0043673809,43.906765,0,11.076097,35.915916,0.00028688469,12.279399,11.075576,26.170029,-9.4708462
13.2,0.97981274,0.0020395967,49.811523,0,11.076097,39.515911,0.0001394671,12.47515,11.075519,28.303345,-9.4692602
14.4,0.99057221,-0.0023231707,53.800758,0,11.076097,43.11591,-0.00014452937,12.616614,11.076771,31.700926,-9.4668388
15.6,1.0057522,-0.0071874298,56.339588,0,11.076097,46.715912,-0.00049183471,12.815572,11.076262,36.378677,-9.4648018
16.8,1.0226177,-0.012129644,57.766155,0,11.076097,50.31591,-0.00079277641,13.059847,11.075137,41.95496,-9.4626446
18.0,1.03666,-0.017476475,57.831184,0,11.076097,53.915913,-0.0011456008,13.215682,11.075659,48.426186,-9.4608583
19.2,1.0489538,-0.022324996,57.108456,0,11.076097,57.515915,-0.0015120879,13.387805,11.076016,55.224777,-9.4584208
20.4,1.0575044,-0.027228601,55.564915,0,11.076097,61.115917,-0.0017990374,13.50474,11.075841,61.942215,-9.4564924
21.6,1.0612297,-0.031420622,53.194016,0,11.076097,64.715927,-0.0020737278,13.552733,11.076478,68.213112,-9.453887
22.8,1.0646389,-0.0346209,50.116127,0,11.076097,68.315918,-0.0023208465,13.58272,11.07522,73.776405,-9.4517355
24.0,1.0656837,-0.037107889,46.893265,0,11.076097,71.915932,-0.0024670833,13.609478,11.075975,78.427582,-9.4499474
25.2,1.0459189,-0.039211236,43.550148,0,11.076097,75.515923,-0.002592691,13.351665,11.07583,82.099075,-9.4475927
26.4,1.0252898,-0.039934479,41.575077,0,11.076097,79.115921,-0.0026735479,13.093447,11.076042,84.701324,-9.4455833
27.6,1.0090684,-0.040930167,41.194054,0,11.076097,82.715927,-0.0027231234,12.892268,11.07631,86.418114,-9.4433537
28.8,1.0023282,-0.041415274,42.395882,0,11.076097,86.315933,-0.0027472619,12.791011,11.075915,87.60907,-9.4417362
30.0,0.99047613,-0.042575251,45.264656,0,11.076097,89.915932,-0.0028427206,12.653302,11.075889,88.64077,-9.4396906
31.2,0.9949761,-0.044267941,48.582668,0,11.076097,93.515938,-0.0029420154,12.715811,11.075769,89.853874,-9.4372377
32.4,1.0043441,-0.04668612,51.875973,0,11.076097,97.115929,-0.0031162149,12.833633,11.076679,91.622299,-9.4356623
33.6,1.0210518,-0.049705256,54.574184,0,11.076097,100.71594,-0.0033126401,13.053166,11.076377,94.065208,-9.4337769
34.8,1.036621,-0.053512562,56.694389,0,11.076097,104.31593,-0.0035619715,13.252405,11.075792,97.360527,-9.4319363
36.0,1.0502292,-0.058283303,58.073368,0,11.076097,107.91594,-0.003886658,13.427643,11.075934,101.44024,-9.4293203
37.2,1.0668912,-0.063129053,58.853733,0,11.076097,111.51593,-0.0041914429,13.640932,11.076496,106.38713,-9.4272032
38.4,1.0786017,-0.06816452,58.853767,0,11.076097,115.11594,-0.0045271651,13.796411,11.074736,111.85572,-9.4251184
39.6,1.0828615,-0.072897717,58.337597,0,11.076097,118.71594,-0.0048588412,13.861876,11.076364,117.56857,-9.4228334
40.8,1.0900676,-0.077119842,57.265572,0,11.076097,122.31594,-0.0051176986,13.951621,11.076412,123.15633,-9.4207945
42.0,1.0887439,-0.080885395,55.902981,0,11.076097,125.91593,-0.0053599249,13.944162,11.075488,128.45457,-9.4187355
43.2,1.0926405,-0.083696149,54.305885,0,11.076097,129.51605,-0.0055826241,13.994087,11.076162,133.21562,-9.4163847
44.4,1.0800112,-0.087084562,52.635574,0,11.076097,133.11594,-0.0057865535,13.833327,11.07565,137.4111,-9.4145231
45.6,1.0830467,-0.08903373,51.199783,0,11.076097,136.71593,-0.0058982824,13.884276,11.075166,140.80045,-9.4121208
46.8,1.0655588,-0.091145225,50.438316,0,11.076097,140.31592,-0.0060780193,13.658787,11.075386,143.57338,-9.410141
48.0,1.0531378,-0.092729986,50.657921,0,11.076097,143.91592,-0.0061608953,13.486765,11.07651,145.83401,-9.408205
49.2,1.0559888,-0.094756119,51.344452,0,11.076097,147.51593,-0.0062917732,13.561948,11.075591,147.87411,-9.406148
50.4,1.0447178,-0.09664584,52.8675,0,11.076097,151.11592,-0.0064357934,13.401263,11.0762,149.68332,-9.4042206
51.6,1.0599589,-0.09860456,54.434353,0,11.076097,154.71594,-0.0065482827,13.591677,11.076077,151.8132,-9.4022121
52.8,1.0652078,-0.10149957,56.185947,0,11.076097,158.31593,-0.0067364452,13.667122,11.076286,154.23296,-9.4000015
54.0,1.0870125,-0.10509894,57.80077,0,11.076097,161.91594,-0.0069836201,13.94138,11.076337,157.23129,-9.3985748
55.2,1.0913972,-0.10930706,59.006763,0,11.076097,165.51595,-0.0072538038,14.002935,11.076302,160.6322,-9.3966646
56.4,1.0991781,-0.11351494,59.842484,0,11.076097,169.11594,-0.0075463932,14.111359,11.075724,164.66739,-9.3944092
57.6,1.1020271,-0.11713576,60.47625,0,11.076097,172.71594,-0.0077890498,14.147457,11.076434,169.00508,-9.3922987
58.8,1.1008537,-0.12175576,60.556637,0,11.076097,176.31595,-0.0080713294,14.149509,11.076323,173.89783,-9.3900156
60.0,1.1091557,-0.12660524,60.314949,0,11.076097,179.91594,-0.0084161023,14.263691,11.074496,178.80406,-9.3877945
61.2,1.1018142,-0.13123263,59.629074,0,11.076097,183.51595,-0.0086980993,14.148582,11.076503,183.84843,-9.3862743
62.4,1.1032724,-0.13559836,58.860577,0,11.076097,187.11595,-0.0089882333,14.176861,11.075484,188.69937,-9.3841038
63.6,1.1034453,-0.13879776,57.89267,0,11.076097,190.71594,-0.0092220875,14.181978,11.075869,193.11449,-9.3821917
64.8,1.1049066,-0.14264186,56.987427,0,11.076097,194.31595,-0.0094532417,14.20158,11.075377,197.18935,-9.3802776
66.0,1.1062163,-0.14511354,56.297001,0,11.076097,197.91595,-0.0096092038,14.235114,11.075418,200.71048,-9.3785477
67.2,1.0972933,-0.14704327,55.84351,0,11.076097,201.51596,-0.0097669866,14.123523,11.076056,203.87791,-9.3760672
68.4,1.0967858,-0.14982577,55.843067,0,11.076097,205.11595,-0.009930131,14.11496,11.07595,206.61226,-9.3738871
69.6,1.1006281,-0.15229134,56.12912,0,11.076097,208.71596,-0.010084966,14.163782,11.075598,209.21255,-9.3719912
70.8,1.1031417,-0.15508129,56.711418,0,11.076097,212.31595,-0.01029362,14.188656,11.076106,211.71223,-9.3695965
72.0,1.106738,-0.15750076,57.782158,0,11.076097,215.91595,-0.01043784,14.244821,11.077014,214.18744,-9.3677959
73.2,1.1125711,-0.16033746,58.672726,0,11.076097,219.51595,-0.010608527,14.324731,11.075878,216.94807,-9.3657818
74.4,1.1109734,-0.16429015,59.599644,0,11.076097,223.11597,-0.010906019,14.316179,11.076389,219.98535,-9.36376
75.6,1.1083858,-0.16851321,60.314934,0,11.076097,226.71596,-0.011161574,14.281426,11.076197,223.49287,-9.3621149
76.8,1.1198357,-0.17388757,61.018047,0,11.076097,230.31596,-0.011505745,14.430233,11.075717,227.27242,-9.3606758
78.0,1.1195984,-0.17653453,61.439125,0,11.076097,233.91597,-0.011717753,14.431761,11.076307,231.34061,-9.3579912
79.2,1.110339,-0.1811334,61.530472,0,11.076097,237.51596,-0.011993103,14.317887,11.07646,235.60898,-9.356144
80.4,1.1096528,-0.1857411,61.468521,0,11.076097,241.11597,-0.012289175,14.316485,11.07579,240.00337,-9.3541012
81.6,1.1216918,-0.19062586,61.239155,0,11.076097,244.71597,-0.01265204,14.463462,11.076598,244.49036,-9.3522339
82.8,1.1192315,-0.19391856,61.018078,0,11.076097,248.31596,-0.012844763,14.44073,11.075758,248.77148,-9.3500109
84.0,1.1127149,-0.19819599,60.556648,0,11.076097,251.91597,-0.01311863,14.367242,11.076752,252.94844,-9.3479614
85.2,1.1075201,-0.20213632,60.08424,0,11.076097,255.51598,-0.01339667,14.295848,11.076571,256.89975,-9.3456306
86.4,1.1135169,-0.20434652,59.602177,0,11.076097,259.11621,-0.013529359,14.386624,11.07675,260.64526,-9.3438597
87.6,1.105673,-0.20782012,59.348164,0,11.076097,262.716,-0.013751746,14.269424,11.075116,264.17197,-9.3418589
88.8,1.1140888,-0.21104014,59.169556,0,11.076097,266.31595,-0.013983739,14.395829,11.075493,267.55081,-9.3401518
90.0,1.1208012,-0.21472287,59.189812,0,11.076097,269.91599,-0.01420816,14.483134,11.076013,270.64246,-9.3381653
91.2,1.1132303,-0.21642986,59.348137,0,11.076097,273.51593,-0.01431831,14.379837,11.075889,273.71448,-9.3362904
92.4,1.1131581,-0.21988641,59.726631,0,11.076097,277.11597,-0.014561465,14.38775,11.075708,276.62158,-9.334219
93.6,1.1092943,-0.22332636,60.242516,0,11.076097,280.71594,-0.014784433,14.352702,11.075486,279.58508,-9.3323059
94.8,1.1211383,-0.22765528,60.787327,0,11.076097,284.31598,-0.015064517,14.502508,11.076105,282.59998,-9.3304911
96.0,1.1209681,-0.22998868,61.281631,0,11.076097,287.91595,-0.01523058,14.502129,11.074714,285.88498,-9.3284998
97.2,1.1092256,-0.23472239,61.831642,0,11.076097,291.51596,-0.015518812,14.362988,11.076731,289.42386,-9.3262997
98.4,1.1172017,-0.23874886,62.116692,0,11.076097,295.11594,-0.015798194,14.442394,11.076201,293.12778,-9.3238754
99.6,1.1195369,-0.24352969,62.336418,0,11.076097,298.71597,-0.01611531,14.497226,11.074838,297.02841,-9.3220005
100.8,1.121628,-0.24656819,62.545162,0,11.076097,302.31595,-0.01630865,14.524431,11.076185,301.01556,-9.3199806
102.0,1.1100413,-0.25119296,62.545162,0,11.076097,305.91592,-0.0166193,14.363954,11.075254,305.03375,-9.3177633
103.2,1.1106471,-0.25556818,62.545162,0,11.076097,309.51596,-0.016896838,14.388984,11.075526,309.09436,-9.3159189
104.4,1.1274376,-0.2605415,62.369244,0,11.076097,313.11597,-0.017219787,14.620596,11.075355,312.98248,-9.3138361
105.6,1.1237549,-0.26295561,62.323395,0,11.076097,316.71597,-0.017383641,14.565155,11.075878,316.96002,-9.3120165
106.8,1.1159712,-0.2671563,62.116726,0,11.076097,320.31595,-0.017652187,14.475672,11.075865,320.73145,-9.3102779
108.0,1.116275,-0.27116692,62.062611,0,11.076097,323.91595,-0.01789997,14.488002,11.076509,324.35739,-9.307991
109.2,1.122785,-0.27544695,61.909657,0,11.076097,327.51596,-0.018202819,14.565095,11.075516,327.90845,-9.3064899
110.4,1.110741,-0.27702066,61.907967,0,11.076097,331.11597,-0.01830036,14.414911,11.076437,331.44128,-9.3043213
111.6,1.1157278,-0.28102791,61.907967,0,11.076097,334.71597,-0.018556943,14.47686,11.07624,334.86429,-9.3027544
112.8,1.120091,-0.28453577,62.116692,0,11.076097,338.31598,-0.018797435,14.539754,11.07567,338.23306,-9.3008747
114.0,1.1135112,-0.28831488,62.141991,0,11.076097,341.91599,-0.019030139,14.459078,11.076042,341.56409,-9.2988768
115.2,1.113326,-0.2932308,62.336418,0,11.076097,345.51599,-0.019344561,14.455298,11.076803,345.04443,-9.29702
116.4,1.1190819,-0.29559964,62.476929,0,11.076097,349.116,-0.019521397,14.539694,11.076546,348.61139,-9.295104
117.6,1.1196749,-0.29862419,62.545162,0,11.076097,352.71597,-0.019703059,14.553792,11.076249,352.22894,-9.293047
118.8,1.1175239,-0.30277234,62.75386,0,11.076097,356.31601,-0.019971399,14.528281,11.076449,355.66898,-9.2908907
120.0,1.1109776,-0.30663478,62.77364,0,11.076097,359.91599,-0.020240029,14.424379,11.076088,359.3078,-9.2883768
121.2,1.1161573,-0.31022063,62.962639,0,11.076097,363.51602,-0.020463746,14.520905,11.076375,362.87881,-9.2866755
122.4,1.1208755,-0.31434852,63.125053,0,11.076097,367.116,-0.020728555,14.580922,11.076361,366.49606,-9.2843399
123.6,1.1168066,-0.31713432,63.171383,0,11.076097,370.71603,-0.020923216,14.529271,11.076389,370.15213,-9.2825403
124.8,1.1256622,-0.32165903,63.363251,0,11.076097,374.31601,-0.021200163,14.645814,11.076698,373.67896,-9.2808781
126.0,1.1306638,-0.32642722,63.369137,0,11.076097,377.91602,-0.021513686,14.713514,11.07639,377.41287,-9.2783327
127.2,1.1276246,-0.32929429,63.469677,0,11.076097,381.51602,-0.021727998,14.69369,11.076123,381.03412,-9.2764502
128.4,1.1223987,-0.33185607,63.577873,0,11.076097,385.11603,-0.02187505,14.618103,11.075785,384.72607,-9.2744417
129.6,1.1243467,-0.33488622,63.577873,0,11.076097,388.71603,-0.022067377,14.64398,11.076235,388.25723,-9.2722435
130.8,1.1261659,-0.33862218,63.775627,0,11.076097,392.31604,-0.022331532,14.671999,11.07538,391.84943,-9.2705688
132.0,1.1221153,-0.34265468,63.877438,0,11.076097,395.91605,-0.022583513,14.6388,11.075586,395.31039,-9.2684975
133.2,1.1193351,-0.34688744,63.973385,0,11.076097,399.51602,-0.02285509,14.595057,11.075838,398.95847,-9.2666359
134.4,1.1260597,-0.35024223,62.616074,0,11.076097,399.99893,-0.023092156,14.67906,11.075679,402.45764,-9.2660027
135.6,1.1207422,-0.3522552,60.327557,0,11.076097,399.99893,-0.023210049,14.601676,11.076152,405.67767,-9.2662926
136.8,1.1129569,-0.35337296,57.286945,0,11.076097,399.99893,-0.02326641,14.510298,11.076296,408.28122,-9.2665215
138.0,1.0930761,-0.35273674,54.005287,0,11.076097,399.99893,-0.023257444,14.24736,11.0756,409.59521,-9.2663841
139.2,1.0690743,-0.35176098,50.72477,0,11.076097,399.99893,-0.023172801,13.930103,11.075976,409.6933,-9.2664709
140.4,1.0446488,-0.34991708,48.384235,0,11.076097,399.99893,-0.023046551,13.610743,11.075661,408.30392,-9.2659483
141.6,1.017821,-0.34625933,47.295692,0,11.076097,399.99893,-0.022824794,13.269256,11.07585,406.06296,-9.2657843
142.8,0.89848453,-0.34363863,47.95525,0,11.076097,399.99893,-0.022661261,11.69492,11.075527,403.07056,-9.2662382
144.0,0.84868163,-0.34133732,50.041676,0,11.076097,399.99893,-0.022491273,11.057096,11.075722,399.98523,-9.2664289
145.2,0.84389246,-0.34006965,52.59787,0,11.076097,399.99893,-0.022424297,11.010835,11.075419,397.31256,-9.2658978
146.4,0.83718693,-0.33974609,55.087841,0,11.076097,399.99893,-0.0223943,10.918579,11.075667,395.23752,-9.2664595
147.6,0.85181189,-0.340175,57.249779,0,11.076097,399.99893,-0.022409499,11.108205,11.076067,394.18866,-9.2662773
148.8,0.85246569,-0.34127709,58.787125,0,11.076097,399.99893,-0.02250945,11.101153,11.07552,394.02438,-9.2662487
150.0,0.85449147,-0.34340242,59.750866,0,11.076097,399.99893,-0.022629635,11.13829,11.075835,394.74081,-9.2664413
151.2,0.85592705,-0.34579805,60.174129,0,11.076097,399.99893,-0.022782935,11.158594,11.075573,395.94656,-9.2665014
152.4,0.85649258,-0.3485269,60.08424,0,11.076097,399.99893,-0.022982419,11.174102,11.075869,397.57306,-9.266345
153.6,0.86118239,-0.3504777,59.604214,0,11.076097,399.99893,-0.023098683,11.223758,11.075668,399.24152,-9.2667608
154.8,0.86202782,-0.3520765,58.854271,0,11.076097,399.99893,-0.023200467,11.23363,11.076091,400.88782,-9.2662964
156.0,0.86144972,-0.35399392,57.750221,0,11.076097,399.99893,-0.023328315,11.228467,11.076666,402.31824,-9.2665472
157.2,0.85420591,-0.35502058,56.429192,0,11.076097,399.99893,-0.023390977,11.137444,11.076464,403.26208,-9.2663231
158.4,0.85270196,-0.35533166,55.239483,0,11.076097,399.99893,-0.02340783,11.109905,11.076179,403.70862,-9.2668457
159.6,0.83139724,-0.35511339,54.15958,0,11.076097,399.99893,-0.023405619,10.838749,11.076242,403.59714,-9.2665949
160.8,0.8248055,-0.35481104,53.564762,0,11.076097,399.99893,-0.023392202,10.747657,11.076058,403.02716,-9.2661915
162.0,0.821446,-0.353661,53.316654,0,11.076097,399.99893,-0.023314087,10.694122,11.075966,402.12338,-9.2665434
163.2,0.81230187,-0.35285783,53.321579,0,11.076097,399.99893,-0.023242049,10.579569,11.075221,401.18732,-9.2664185
164.4,0.81981027,-0.35215738,53.975498,0,11.076097,399.99893,-0.023223877,10.690254,11.075798,400.07065,-9.2664003
165.6,0.8140468,-0.35176513,54.624001,0,11.076097,399.99893,-0.023185173,10.608406,11.0766,399.12997,-9.2667484
166.8,0.81026304,-0.35206616,55.523365,0,11.076097,399.99893,-0.023191057,10.560191,11.075851,398.32971,-9.2663059
168.0,0.8170383,-0.3519116,56.272675,0,11.076097,399.99893,-0.023207936,10.654218,11.07646,397.93213,-9.2665548
169.2,0.83526593,-0.35215604,56.983173,0,11.076097,399.99893,-0.023202401,10.894361,11.076322,397.77615,-9.266305
170.4,0.83849984,-0.35321584,57.359512,0,11.076097,399.99893,-0.023258395,10.91871,11.076174,397.97226,-9.2660837
171.6,0.84761345,-0.3536686,57.535397,0,11.076097,399.99893,-0.023314619,11.045472,11.076474,398.39413,-9.2664728
172.8,0.84384757,-0.35521677,57.699917,0,11.076097,399.99893,-0.023397325,11.004917,11.076002,398.89853,-9.2665262
174.0,0.84319621,-0.3563709,57.535412,0,11.076097,399.99893,-0.02346292,11.000468,11.076384,399.57565,-9.2660608
175.2,0.84336597,-0.35749409,57.260746,0,11.076097,399.99893,-0.023564445,10.99526,11.075603,400.24252,-9.2661629
176.4,0.84815556,-0.35823986,56.71143,0,11.076097,399.99893,-0.023593172,11.048061,11.076178,400.92892,-9.2660055
177.6,0.84352124,-0.35891023,56.129154,0,11.076097,399.99893,-0.023624476,11.008773,11.075395,401.35568,-9.2662125
178.6136,0.83637249,0.013523987,55.535889,0,11.076099,65.879799,0.0011391781,10.69514,11.076693,401.62225,-9.2671738
178.616,0.83099294,0.013771217,55.535889,0,11.076099,2.8481728e-15,0.00093334302,10.573776,11.075265,401.60056,-9.2662086
178.6184,0.81471556,0.013429567,55.535889,0,11.076099,1.2312645e-31,0.00074687717,10.332415,11.077655,401.57889,-9.2668552
178.6208,0.85740161,0.017168529,55.535889,0,11.076099,0.0,0.0010202941,10.853809,11.07769,401.55722,-9.2674036
178.6232,0.84151942,0.015354199,55.535831,0,11.076099,0.0,0.0011972203,10.772466,11.076844,401.53555,-9.2669611
178.6256,0.82131582,0.015222282,42.207218,0,11.076099,0.0,0.0011875189,10.483688,11.076275,401.53555,-9.2665462
178.628,0.86337173,0.017305505,28.878607,0,11.076099,0.0,0.0010839015,11.024725,11.077725,401.53555,-9.2658138
178.6304,0.83743292,0.021589249,15.549994,0,11.076099,0.0,0.001130884,10.543977,11.076123,401.53555,-9.2669334
178.6328,0.84507751,0.020192912,2.2213802,0,11.076099,0.0,0.0011546988,10.74812,11.077509,401.53555,-9.2664709
178.6352,0.84628659,0.017279347,0.0,0,11.076099,0.0,0.0013500382,10.756096,11.076793,401.54761,-9.2666473
178.6376,0.81965697,0.013664409,0.0,0,11.076099,0.0,0.0011632773,10.435364,11.074759,401.56204,-9.2662039
178.64,0.82756585,0.01546108,0.0,0,11.076099,0.0,0.00094166095,10.448587,11.07445,401.57651,-9.2650442
178.6424,0.83467901,0.016759329,0.0,0,11.076099,0.0,0.00092534663,10.661336,11.075159,401.59094,-9.2659912
178.6448,0.82804537,0.015478355,0.0,0,11.076099,0.0,0.0009327138,10.545919,11.077094,401.59576,-9.2650642
178.6472,0.81884813,0.014383493,0.0,0,11.076099,0.0,0.0010854488,10.404025,11.073746,401.59576,-9.2674456
178.6496,0.82622832,0.014473802,0.0,0,11.076099,0.0,0.0012280804,10.508952,11.07232,401.59576,-9.2676678
178.652,0.82621396,0.018440265,0.0,0,11.076099,0.0,0.0011778445,10.522241,11.074685,401.59576,-9.2671461
178.6544,0.83267331,0.021021677,0.0,0,11.076099,0.0,0.0010874071,10.555685,11.075391,401.58493,-9.2665052
178.6568,0.82585371,0.020836717,0.0,0,11.076099,0.0,0.0012405815,10.481147,11.075621,401.56323,-9.2665777
178.6592,0.79679149,0.01784624,0.0,0,11.076099,0.0,0.0013774007,10.176116,11.073151,401.54156,-9.2661076
178.6616,0.81658894,0.013450018,0.0,0,11.076099,0.0,0.0011792524,10.405083,11.068928,401.5199,-9.2667284
178.664,0.83492202,0.014837206,0.0,0,11.006544,0.0,0.00098034577,10.556219,11.072455,401.50543,-9.2659655
178.6664,0.83362025,0.016523898,0.0,0,10.645576,0.0,0.000943347,10.632569,11.075167,401.50543,-9.267127
178.6688,0.81198692,0.017243095,0.0,0,10.284602,0.0,0.0010211883,10.379369,11.056931,401.50543,-9.2661076
178.6712,0.82649291,0.015488563,0.0,0,9.9236288,0.0,0.0011503315,10.408414,10.939136,401.50543,-9.2661915
178.6736,0.81591451,0.013510808,0.0,0,9.5626545,0.0,0.001127356,10.299244,10.665833,401.86877,-9.2674236
178.676,0.84030229,0.014506334,0.0,0,9.2092896,0.0,0.0009425155,10.800606,10.285924,404.0488,-9.2673063
178.6784,6.2513413,0.18686315,0.0,0,8.8581219,0.0,0.011476192,78.170723,9.8953428,406.22882,-9.2618837
178.6808,6.9817767,0.64427185,0.0,0,8.518857,0.0,0.043077581,84.123169,9.4400768,408.40884,-9.2621098
178.6832,7.7307997,1.0533289,0.0,0,8.1848736,0.0,0.072734334,91.522095,8.9958525,410.58887,-9.2608814
178.6856,7.9089665,1.4477158,0.0,0,7.860775,0.0,0.10130888,91.02758,8.6066608,414.08054,-9.2599621
178.688,8.3176584,1.8002415,0.0,0,7.543015,0.0,0.12729318,93.378494,8.2288389,417.57217,-9.2589569
178.6904,8.4634438,2.1468737,0.0,0,7.2334356,0.0,0.15382022,92.28653,7.8738589,421.06384,-9.2591295
178.6928,8.7572365,2.4646568,0.0,0,6.9312272,0.0,0.17894693,93.186455,7.5452199,424.55548,-9.2594824
178.6952,8.9327593,2.7653906,0.0,0,6.6355214,0.0,0.20349517,92.82856,7.2373114,426.59634,-9.2594414
178.6976,9.1381826,3.0503244,0.0,0,6.3480015,0.0,0.22717516,92.663673,6.9425435,428.34708,-9.258419
178.7,9.3052053,3.3334877,0.0,0,6.0655355,0.0,0.2509113,92.155434,6.6533017,430.09778,-9.2590981
178.7024,9.5605488,3.6180813,0.0,0,5.792079,0.0,0.27520958,92.375465,6.3665619,431.84851,-9.258934
178.7048,9.7678976,3.8999462,0.0,0,5.5222936,0.0,0.3003574,92.162048,6.0884538,433.00787,-9.2604589
178.7072,10.011025,4.1751027,0.0,0,5.2621331,0.0,0.3260954,91.885231,5.8061614,433.87155,-9.259284
178.7096,10.214218,4.4473057,0.0,0,5.0044241,0.0,0.35178882,91.487236,5.5258937,434.73523,-9.2593288
178.712,10.432175,4.7175236,0.0,0,4.7569838,0.0,0.37713531,91.086266,5.2550497,435.59891,-9.2594213
178.7144,10.674158,4.986546,0.0,0,4.5108657,0.0,0.40323073,90.77681,4.9925613,434.96793,-9.2602072
178.7168,10.944691,5.2429223,0.0,0,4.2754693,0.0,0.42934319,90.679665,4.7302947,432.84229,-9.2599583
178.7192,11.139978,5.4894695,0.0,0,4.0404716,0.0,0.45546412,90.001762,4.4778347,430.71664,-9.2599211
178.7216,11.420573,5.7322927,0.0,0,3.8165052,0.0,0.48157448,89.794296,4.2340341,428.591,-9.2602758
178.724,11.694566,5.9709778,0.0,0,3.5926332,0.0,0.50721449,89.545059,3.9949181,425.94125,-9.2599154
178.7264,11.994385,6.2062764,0.0,0,3.3790326,0.0,0.53296423,89.553696,3.7629156,422.24332,-9.2596626
178.7288,12.285814,6.4368768,0.0,0,3.1660566,0.0,0.55956548,89.388596,3.5353439,418.54535,-9.2589912
178.7312,12.59005,6.650569,0.0,0,2.9619904,0.0,0.58578467,89.255287,3.3210745,414.84741,-9.259654
178.7336,12.918908,6.8530622,0.0,0,2.7593822,0.0,0.61080486,89.246315,3.1060321,411.66724,-9.2600002
178.736,13.33362,7.0601912,0.0,0,2.5644472,0.0,0.6358462,89.880829,2.9011827,411.07578,-9.2601318
178.7384,13.732709,7.2680745,0.0,0,2.3717272,0.0,0.66166562,90.124779,2.6971362,410.48431,-9.2590942
178.7408,14.128619,7.4709749,0.0,0,2.185524,0.0,0.68841976,90.346687,2.4955301,409.89285,-9.2586908
178.7432,14.561553,7.6670537,0.0,0,2.002212,0.0,0.71547496,90.587204,2.2943773,409.30139,-9.257885
178.7456,15.038732,7.8562827,0.0,0,1.8243402,0.0,0.74211657,91.07753,2.1028101,406.20535,-9.2576208
178.748,15.560726,8.0443773,0.0,0,1.6499562,0.0,0.76835364,91.86834,1.9156319,403.10931,-9.2575617
178.7504,16.067877,8.2325926,0.0,0,1.4800411,0.0,0.79473001,92.391701,1.7321368,400.01328,-9.2562237
178.7528,16.597643,8.4098225,0.0,0,1.3141533,0.0,0.82114846,92.874229,1.5527121,396.91724,-9.2545214
178.7552,17.173071,8.5748425,0.0,0,1.1518563,0.0,0.84771025,93.604042,1.3825243,395.58252,-9.2551041
178.7576,17.827417,8.7375374,0.0,0,0.99408025,0.0,0.8741616,94.640495,1.2153509,394.60004,-9.2558651
178.76,18.545271,8.9010677,0.0,0,0.83908123,0.0,0.89971679,95.942497,1.0501939,393.61758,-9.2558308
178.7624,19.237362,9.0656872,0.0,0,0.68903327,0.0,0.92601854,97.013664,0.88171595,392.6351,-9.254302
178.7648,19.972588,9.2236395,0.0,0,0.54098582,0.0,0.95307362,97.961761,0.72378623,395.01181,-9.25525
178.7672,20.733381,9.3707228,0.0,0,0.39818579,0.0,0.98001915,99.003929,0.56956112,399.06808,-9.2547665
178.7696,18.205833,9.3961773,0.0,0,0.25673616,0.0,0.98557717,86.784225,0.4747743,403.12433,-9.2580175
178.772,16.363903,9.4062538,0.0,0,0.12094405,0.0,0.98659223,77.754517,0.4259035,407.1806,-9.260148
178.7744,15.562961,9.4199152,0.0,0,-0.014479335,0.0,0.98777467,73.88401,0.39781258,410.62296,-9.259861
178.7768,15.172935,9.4287128,0.0,0,-0.14691253,0.0,0.9895063,71.80899,0.36385855,413.45145,-9.2604837
178.7792,15.215885,9.42663,0.0,0,-0.27934453,0.0,0.99037468,71.945816,0.31756294,416.27991,-9.2591
178.7816,15.520174,9.4287577,0.0,0,-0.41177651,0.0,0.99166536,73.301949,0.25010696,419.10837,-9.2598724
178.784,15.638885,9.4344749,0.0,0,-0.54420853,0.0,0.99177039,73.813721,0.18249887,421.5827,-9.2605247
178.7864,15.610747,9.4442244,0.0,0,-0.67664051,0.0,0.99233854,73.686745,0.11881869,423.34879,-9.2600517
178.7888,15.438459,9.4519663,0.0,0,-0.80907249,0.0,0.99369454,72.781776,0.065660253,425.11487,-9.2599449
178.7912,15.157972,9.4543848,0.0,0,-0.94150448,0.0,0.99530131,71.358559,0.02614237,426.88095,-9.2601786
178.7936,14.795631,9.4515133,0.0,0,-1.0739366,0.0,0.9958027,69.619026,-0.007932419,428.48346,-9.2604542
178.796,14.34736,9.4535341,0.0,0,-0.76691389,400.0,0.99538058,67.526947,-0.017478894,429.26819,-9.2617416
178.7984,13.801179,9.4614267,0.0,0,-0.30842754,400.0,0.99531496,65.023453,-0.019729353,430.05292,-9.261548
178.8008,13.265738,9.4655085,0.0,0,0.15005879,400.0,0.99583948,62.427189,-0.013855245,430.83765,-9.2611647
178.8032,12.83278,9.4639645,0.0,0,0.60854518,400.0,0.99702293,60.303555,-0.0069062221,431.62238,-9.2600431
178.8056,12.549319,9.4599924,0.0,0,1.0670315,400.0,0.99737114,58.970116,-0.0081727095,432.53644,-9.2616043
178.808,12.096572,9.4578304,0.0,0,1.5255178,400.0,0.99608415,56.923515,0.0041981731,433.4505,-9.2622309
178.8104,10.706627,9.4577732,0.0,0,1.9840043,400.0,0.99498367,50.59407,0.061407026,434.36456,-9.2635632
178.8128,7.7268381,9.4504404,0.0,0,2.4424911,400.0,0.99342054,36.624084,0.20559545,435.27863,-9.2654629
178.8152,3.622987,9.4286804,0.0,0,2.9009774,400.0,0.99076283,17.568193,0.4365105,436.00677,-9.2687979
178.8176,0.067741372,9.3751345,0.0,0,3.3594637,400.0,0.98207462,0.38443416,0.85418755,436.69772,-9.2718239
178.82,-0.18556036,9.4176893,0.0,0,3.81795,400.0,0.98871076,-0.89108223,1.5985309,437.38867,-9.2718935
178.8224,0.023836819,9.4319363,0.0,0,4.2764363,400.0,0.99033719,0.067467585,2.3933833,438.07962,-9.2717094
178.8248,0.0030973391,9.4366255,0.0,0,4.7349229,400.0,0.99071258,0.0046258038,3.0911877,438.54504,-9.2718668
178.8272,0.11783987,9.4366846,0.0,0,5.1934094,400.0,0.99201065,0.59918725,3.6248121,438.89771,-9.2703648
178.8296,0.09150698,9.4317913,0.0,0,5.6518955,400.0,0.99219733,0.4888576,4.0645523,439.2504,-9.2706108
178.832,0.17662007,9.4256077,0.0,0,6.1103821,400.0,0.99024391,0.79138255,4.4918017,439.60306,-9.2693119
178.8344,0.13619244,9.4276447,0.0,0,6.5688682,400.0,0.98952144,0.6978997,4.9291844,439.90173,-9.2674208
178.8368,0.091507763,9.4313211,0.0,0,7.0273547,400.0,0.99006325,0.44133878,5.3726707,440.14645,-9.2670727
178.8392,0.0098667769,9.4285212,0.0,0,7.4858418,400.0,0.99048591,-0.018164169,5.8381615,440.39117,-9.266161
178.8416,0.12192771,9.4229288,0.0,0,7.9443283,400.0,0.99051768,0.58811808,6.3159838,440.63586,-9.2663126
178.844,0.0045141829,9.422101,0.0,0,8.4028139,400.0,0.98976731,-0.019192025,6.7982364,440.87338,-9.2668438
178.8464,0.052869074,9.4275055,0.0,0,8.8612995,400.0,0.98934239,0.17311184,7.2720647,441.0965,-9.2665834
178.8488,0.11616497,9.4305086,0.0,0,9.3197861,400.0,0.98957276,0.59973335,7.7483406,441.31961,-9.2655897
178.8512,-0.10118528,9.4330177,0.0,0,9.7782726,400.0,0.99127024,-0.50043869,8.2224417,441.54272,-9.265377
178.8536,0.085141428,9.4235277,0.0,0,10.236759,400.0,0.9907428,0.34659877,8.7013149,441.76227,-9.2657976
178.856,0.055342108,9.42101,0.0,0,10.695246,400.0,0.9896636,0.30132112,9.1767006,441.96378,-9.2658262
178.8584,-0.066163599,9.425827,0.0,0,11.153732,400.0,0.98939288,-0.39063722,9.635108,442.16531,-9.2651787
178.8608,0.096531406,9.4274035,0.0,0,11.612218,400.0,0.98933971,0.40905479,10.110241,442.36682,-9.2654085
178.8632,-0.017252652,9.4248009,0.0,0,12.070705,400.0,0.9897967,-0.054045364,10.582096,442.56836,-9.2657261
178.8656,-0.053106368,9.4227076,0.0,0,12.529191,400.0,0.99035341,-0.25615379,11.047621,442.7554,-9.2653999
178.868,0.05683862,9.4215403,0.0,0,12.987678,400.0,0.98979825,0.24612081,11.51241,442.94247,-9.2649212
178.8704,0.05704505,9.4250975,0.0,0,13.446164,400.0,0.98908055,0.32708365,11.968517,443.12952,-9.264596
178.8728,-0.094152547,9.4295959,0.0,0,13.904651,400.0,0.98935843,-0.49531791,12.422394,443.31656,-9.2648191
178.8752,0.076065682,9.4297705,0.0,0,14.363137,400.0,0.99050772,0.2673735,12.8925,443.46158,-9.2644663
178.8776,-0.0040226332,9.4215517,0.0,0,14.821624,400.0,0.99020278,0.053120486,13.379813,443.59818,-9.2641554
178.88,-0.031011388,9.4207926,0.0,0,15.28011,400.0,0.98985422,-0.15459499,13.857437,443.7348,-9.2648935
178.8824,0.066558704,9.4214764,0.0,0,15.738596,400.0,0.98870939,0.28489566,14.340701,443.8714,-9.2644024
178.8848,-0.073873617,9.4238586,0.0,0,16.197083,400.0,0.98864281,-0.27694696,14.806056,443.97922,-9.2630949
178.8872,-0.093428954,9.4241819,0.0,0,16.655569,400.0,0.9897154,-0.43234077,15.258644,444.07263,-9.2625341
178.8896,0.090642013,9.4193153,0.0,0,17.114056,400.0,0.98997605,0.34763223,15.721369,444.16605,-9.2636795
178.892,-0.046194158,9.4174051,0.0,0,17.572542,400.0,0.98910308,-0.19035028,16.178795,444.25946,-9.2650003
178.8944,-0.043131512,9.4223747,0.0,0,17.999401,400.0,0.98857492,-0.22593717,16.629524,444.3457,-9.2643909
178.8968,0.027359886,9.4270258,0.0,0,18.0,400.0,0.98882586,0.12009891,17.088684,444.42474,-9.2638197
178.8992,-0.059944715,9.4255257,0.0,0,18.0,400.0,0.98963928,-0.21997733,17.518948,444.50381,-9.264534
178.9016,0.048617613,9.4224977,0.0,0,18.0,400.0,0.99047041,0.14989577,17.890945,444.58286,-9.2637205
178.904,0.094772153,9.4202366,0.0,0,18.0,400.0,0.98975909,0.486462,18.202374,444.65952,-9.2659283
178.9064,0.16887541,9.4235773,0.0,0,18.0,400.0,0.98903179,0.79062623,18.417671,444.73138,-9.2685728
178.9088,0.47123489,9.4329243,0.0,0,18.0,400.0,0.99012941,2.2658162,18.50489,444.80322,-9.2723618
178.9112,0.59627998,9.4395514,0.0,0,18.0,400.0,0.99231201,2.8260963,18.465944,444.87509,-9.279254
178.9136,0.66669214,9.4366283,0.0,0,18.0,400.0,0.99279708,3.1058075,18.340416,444.94455,-9.2895899
178.916,0.63206035,9.4363184,0.0,0,18.0,400.0,0.99253607,2.991251,18.210188,445.00204,-9.3013611
178.9184,0.63835633,9.440239,0.0,0,18.0,400.0,0.99182028,3.0019808,18.101555,445.05951,-9.3165932
178.9208,0.55057263,9.4448071,0.0,0,18.0,400.0,0.99188542,2.6421468,18.049086,445.117,-9.3352137
178.9232,0.5708003,9.4419489,0.0,0,18.0,400.0,0.99249709,2.6691656,18.040161,445.1745,-9.3543596
178.9256,0.57913375,9.4348078,0.0,0,18.0,400.0,0.99272722,2.7279487,18.047392,445.20325,-9.3758831
178.928,0.62193233,9.4316454,0.0,0,18.0,400.0,0.99191922,2.9367826,18.067236,445.23199,-9.3952627
178.9304,0.59176677,9.4350042,0.0,0,18.0,400.0,0.99101925,2.8241248,18.088148,445.26074,-9.4154558
178.9328,0.55889744,9.438592,0.0,0,18.0,400.0,0.99128181,2.680829,18.112604,445.28949,-9.433157
178.9352,0.55497831,9.4378748,0.0,0,18.0,400.0,0.99203515,2.6107769,18.125956,445.3302,-9.4514637
178.9376,0.61421198,9.4337864,0.0,0,18.0,400.0,0.99220973,2.8882475,18.137356,445.37332,-9.4690294
178.94,0.60490984,9.4321499,0.0,0,18.0,400.0,0.99204344,2.8579421,18.141958,445.41644,-9.4870062
178.9424,0.57422644,9.4347286,0.0,0,18.0,400.0,0.99121463,2.7704926,18.142885,445.45956,-9.5056753
178.9448,0.54658657,9.4405031,0.0,0,18.0,400.0,0.99122715,2.6037085,18.139338,445.4931,-9.5230398
178.9472,0.60577381,9.4407568,0.0,0,18.0,400.0,0.99213719,2.8006458,18.133825,445.52185,-9.5422125
178.9496,0.6412164,9.4365101,0.0,0,18.0,400.0,0.99278247,3.0095148,18.136276,445.5506,-9.5591173
178.952,0.61677623,9.4311304,0.0,0,18.0,400.0,0.99199593,2.9085608,18.129288,445.57935,-9.5758562
178.9544,0.58128488,9.4328651,0.0,0,18.0,400.0,0.99090141,2.7659338,18.123417,445.59372,-9.5939188
178.9568,0.57144773,9.436286,0.0,0,18.0,400.0,0.99088353,2.7313228,18.125349,445.59372,-9.6111584
178.9592,0.62432945,9.4373827,0.0,0,18.0,400.0,0.99166375,2.8945265,18.121168,445.59372,-9.6292772
178.9616,0.65250212,9.4369717,0.0,0,18.0,400.0,0.99286205,3.0801163,18.121279,445.59372,-9.6448202
178.964,0.59759033,9.4348173,0.0,0,18.0,400.0,0.99239665,2.8323677,18.117001,445.58893,-9.6624746
178.9664,0.5731352,9.4359007,0.0,0,18.0,400.0,0.99139804,2.7140019,18.115517,445.57455,-9.6805353
178.9688,0.60269815,9.440752,0.0,0,18.0,400.0,0.99130183,2.8253062,18.118073,445.56018,-9.6977262
178.9712,0.65175331,9.4453354,0.0,0,18.0,400.0,0.99272865,3.0572784,18.108027,445.54581,-9.7151546
178.9736,0.63309413,9.4399595,0.0,0,18.0,400.0,0.99353975,2.9961548,18.109304,445.53143,-9.7343826
178.976,0.58279741,9.4347467,0.0,0,18.0,400.0,0.99265409,2.7738316,18.110048,445.51706,-9.7516918
178.9784,0.56665409,9.433917,0.0,0,18.0,400.0,0.99103421,2.68256,18.107119,445.50269,-9.7694759
178.9808,0.62219203,9.4374342,0.0,0,18.0,400.0,0.99121088,2.8961713,18.105425,445.48831,-9.7868481
178.9832,0.6490674,9.4391594,0.0,0,18.0,400.0,0.99181902,3.0948229,18.10758,445.47394,-9.8059034
178.9856,0.59122097,9.4353104,0.0,0,18.0,400.0,0.99233389,2.8357754,18.105831,445.45956,-9.8244305
178.988,0.56999689,9.4320526,0.0,0,18.0,400.0,0.99208724,2.6994987,18.101233,445.44519,-9.8421335
178.9904,0.59080875,9.4355307,0.0,0,18.0,400.0,0.99138302,2.7621076,18.09823,445.43082,-9.8591585
178.9928,0.64806914,9.4411201,0.0,0,18.0,400.0,0.9911505,3.0455101,18.103102,445.41644,-9.8762712
178.9952,0.64174932,9.442955,0.0,0,18.0,400.0,0.99231738,3.0596724,18.098778,445.39011,-9.8936825
178.9976,0.57134038,9.4360504,0.0,0,18.0,400.0,0.99251747,2.7173119,18.098099,445.36136,-9.9114304
179.0,0.56868804,9.4312658,0.0,0,18.0,400.0,0.9920938,2.6782846,18.096054,445.33261,-9.9294329
179.0024,0.6156733,9.4338827,0.0,0,18.0,400.0,0.99117148,2.8902259,18.102285,445.30386,-9.9460487
179.0048,0.65027136,9.4375849,0.0,0,18.0,400.0,0.99104416,3.0761261,18.101166,445.27512,-9.9632292
179.0072,0.61440665,9.4365072,0.0,0,18.0,400.0,0.99144316,2.9023159,18.095726,445.24637,-9.9819183
179.0096,0.56800038,9.4347057,0.0,0,18.0,400.0,0.99207979,2.6696415,18.094704,445.21762,-9.9997702
179.012,0.59278995,9.4312286,0.0,0,18.0,400.0,0.99190301,2.7911961,18.097223,445.18887,-10.017015
179.0144,0.63447016,9.4343214,0.0,0,18.0,400.0,0.99126613,2.9696701,18.096769,445.1745,-10.035808
179.0168,0.64587009,9.4409676,0.0,0,18.0,400.0,0.99121785,3.0370545,18.094069,445.1745,-10.054379
179.0192,0.57942301,9.4400682,0.0,0,18.0,400.0,0.99175805,2.7553239,18.089367,445.1745,-10.071996
179.0216,0.57112545,9.4347944,0.0,0,18.0,400.0,0.99233323,2.6684933,18.094393,445.1745,-10.089177
179.024,0.63882059,9.4313269,0.0,0,18.0,400.0,0.99209982,2.982348,18.091942,445.17212,-10.106652
179.0264,0.65667456,9.4341717,0.0,0,18.0,400.0,0.99113947,3.1050878,18.087151,445.16492,-10.125233
179.0288,0.63491911,9.4366951,0.0,0,18.0,400.0,0.99088448,3.039144,18.085737,445.15775,-10.143557
179.0312,0.58554226,9.4366665,0.0,0,18.0,400.0,0.99137121,2.7361634,18.085108,445.15057,-10.160857
179.0336,0.59886563,9.4336329,0.0,0,18.0,400.0,0.99189061,2.8132195,18.085674,445.13739,-10.178948
179.036,0.64963043,9.4292164,0.0,0,18.0,400.0,0.99159354,3.0782945,18.08415,445.09427,-10.197018
179.0384,0.66421801,9.4349918,0.0,0,18.0,400.0,0.99148363,3.1395988,18.087482,445.05115,-10.214648
179.0408,0.61374015,9.4426155,0.0,0,18.0,400.0,0.99173802,2.9188347,18.085476,445.00803,-10.229724
179.0432,0.59438747,9.4423332,0.0,0,18.0,400.0,0.99198562,2.7657948,18.083214,444.9649,-10.247208
179.0456,0.64570695,9.4361353,0.0,0,18.0,400.0,0.99239361,2.9976618,18.083326,444.91461,-10.264931
179.048,0.66857821,9.4313936,0.0,0,18.0,400.0,0.99216425,3.1777587,18.084623,444.86429,-10.282614
179.0504,0.6432246,9.4329615,0.0,0,18.0,400.0,0.99124342,3.0476377,18.085478,444.814,-10.301235
179.0528,0.58772618,9.4365273,0.0,0,18.0,400.0,0.99098313,2.8177798,18.084476,444.7637,-10.319065
179.0552,0.59518933,9.4362869,0.0,0,18.0,400.0,0.99116993,2.7748713,18.081749,444.73135,-10.337032
179.0576,0.6634596,9.4323778,0.0,0,18.0,400.0,0.99149293,3.0963204,18.082331,444.70261,-10.356005
179.06,0.66886675,9.4316349,0.0,0,18.0,400.0,0.99208856,3.1703725,18.077578,444.67389,-10.374038
179.0624,0.60330963,9.4340477,0.0,0,18.0,400.0,0.99142283,2.9185874,18.077684,444.64514,-10.391186
179.0648,0.58187628,9.4394016,0.0,0,18.0,400.0,0.99108857,2.7234738,18.07605,444.62598,-10.407642
179.0672,0.62947524,9.4407234,0.0,0,18.0,400.0,0.99171573,2.9586971,18.074814,444.6116,-10.426854
179.0696,0.67054015,9.4364862,0.0,0,18.0,400.0,0.99257267,3.0895467,18.073875,444.59723,-10.443452
179.072,0.64733166,9.4320297,0.0,0,18.0,400.0,0.99227232,3.058233,18.069479,444.58286,-10.461284
179.0744,0.58974653,9.4326763,0.0,0,18.0,400.0,0.99123806,2.8292093,18.074554,444.54694,-10.479839
179.0768,0.59568083,9.4356403,0.0,0,18.0,400.0,0.9907006,2.7887993,18.07535,444.48944,-10.496676
179.0792,0.64998734,9.4374523,0.0,0,18.0,400.0,0.99134469,3.0317986,18.072752,444.43195,-10.515011
179.0816,0.67505074,9.436759,0.0,0,18.0,400.0,0.9923197,3.1607311,18.072157,444.37445,-10.531759
179.084,0.61957598,9.4335108,0.0,0,18.0,400.0,0.99236983,2.929297,18.072651,444.31696,-10.549536
179.0864,0.57773769,9.4317875,0.0,0,18.0,400.0,0.99109226,2.7565515,18.075134,444.25946,-10.567506
179.0888,0.62510312,9.437892,0.0,0,18.0,400.0,0.99092942,2.9144571,18.070547,444.202,-10.585943
179.0912,0.66892922,9.4418907,0.0,0,18.0,400.0,0.99191272,3.1801746,18.071875,444.1445,-10.603961
179.0936,0.6695767,9.437727,0.0,0,18.0,400.0,0.99275422,3.1546206,18.067909,444.0918,-10.622663
179.096,0.60646677,9.4329758,0.0,0,18.0,400.0,0.99253619,2.8737061,18.070581,444.06305,-10.640002
179.0984,0.59138989,9.4336681,0.0,0,18.0,400.0,0.99153477,2.7573669,18.072247,444.0343,-10.656543
179.1008,0.6590513,9.4352589,0.0,0,18.0,400.0,0.99068248,3.072814,18.066978,444.00555,-10.673602
179.1032,0.68919206,9.4381895,0.0,0,18.0,400.0,0.99145252,3.2799926,18.067892,443.97681,-10.692046
179.1056,0.63763016,9.4356012,0.0,0,18.0,400.0,0.99192989,2.9894552,18.066879,443.94806,-10.71033
179.108,0.60579228,9.4307728,0.0,0,18.0,400.0,0.99189365,2.8326013,18.067564,443.91931,-10.729643
179.1104,0.62345099,9.4306316,0.0,0,18.0,400.0,0.99105334,2.9348896,18.066397,443.89059,-10.746826
179.1128,0.68613839,9.4396877,0.0,0,18.0,400.0,0.99130201,3.2236423,18.067089,443.86185,-10.763418
179.1152,0.68154103,9.443078,0.0,0,18.0,400.0,0.99195504,3.2241595,18.067427,443.82712,-10.782171
179.1176,0.61241686,9.4394503,0.0,0,18.0,400.0,0.99297625,2.8973873,18.063698,443.79117,-10.799745
179.12,0.60027903,9.4341669,0.0,0,18.0,400.0,0.99271917,2.8171611,18.063892,443.75525,-10.817355
179.1224,0.66111487,9.4310713,0.0,0,18.0,400.0,0.99108446,3.0890186,18.061443,443.7193,-10.83436
179.1248,0.68893403,9.433156,0.0,0,18.0,400.0,0.99017566,3.2674682,18.060196,443.66901,-10.851572
179.1272,0.65423518,9.4358597,0.0,0,18.0,400.0,0.99107146,3.1143639,18.058605,443.61151,-10.86932
179.1296,0.60068119,9.4334707,0.0,0,18.0,400.0,0.99164575,2.8293619,18.060083,443.55405,-10.886484
179.132,0.62296069,9.4307985,0.0,0,18.0,400.0,0.99189675,2.9178469,18.060337,443.49655,-10.905059
179.1344,0.68812358,9.4331856,0.0,0,18.0,400.0,0.99159265,3.2114937,18.059875,443.44263,-10.922306
179.1368,0.680821,9.4393063,0.0,0,18.0,400.0,0.99128342,3.221168,18.061869,443.3923,-10.940521
179.1392,0.61708295,9.4433146,0.0,0,18.0,400.0,0.9920035,2.9478245,18.054491,443.34198,-10.959253
179.1416,0.60149711,9.4367104,0.0,0,18.0,400.0,0.99218225,2.8528044,18.052509,443.29166,-10.978
179.144,0.65508145,9.4286041,0.0,0,18.0,400.0,0.99172062,3.04827,18.050381,443.24854,-10.995255
179.1464,0.69009274,9.4309444,0.0,0,18.0,400.0,0.99116617,3.2646618,18.054659,443.21973,-11.013052
179.1488,0.64770466,9.4356413,0.0,0,18.0,400.0,0.99086243,3.0913391,18.056259,443.19095,-11.031093
179.1512,0.60017323,9.4403801,0.0,0,18.0,400.0,0.99171573,2.8808954,18.057022,443.16214,-11.04768
179.1536,0.61550331,9.436821,0.0,0,18.0,400.0,0.99214429,2.880218,18.055048,443.13214,-11.06402
179.156,0.685498,9.4310293,0.0,0,18.0,400.0,0.9919197,3.2006688,18.054743,443.09616,-11.082646
179.1584,0.68350315,9.4310923,0.0,0,18.0,400.0,0.99129856,3.2709568,18.055368,443.06018,-11.100479
179.1608,0.62240905,9.4362078,0.0,0,18.0,400.0,0.99067122,2.9514339,18.051544,443.0242,-11.117869
179.1632,0.60188174,9.4392576,0.0,0,18.0,400.0,0.99118245,2.8609087,18.054131,442.98822,-11.136491
179.1656,0.64277315,9.4368658,0.0,0,18.0,400.0,0.9922744,2.9973996,18.052195,442.95224,-11.153692
179.168,0.7053535,9.432785,0.0,0,18.0,400.0,0.99237639,3.3019552,18.052135,442.91623,-11.170381
179.1704,0.67030078,9.4339056,0.0,0,18.0,400.0,0.99177635,3.214844,18.051424,442.88025,-11.190445
179.1728,0.61059731,9.4370041,0.0,0,18.0,400.0,0.99113262,2.9233465,18.053785,442.84427,-11.208367
179.1752,0.62319291,9.4383154,0.0,0,18.0,400.0,0.99135947,2.9207561,18.055149,442.80826,-11.22508
179.1776,0.67589372,9.4357805,0.0,0,18.0,400.0,0.99186343,3.1714191,18.050566,442.77228,-11.244247
179.18,0.69545454,9.4311838,0.0,0,18.0,400.0,0.99198526,3.2898724,18.049778,442.7363,-11.260061
179.1824,0.62739801,9.4301128,0.0,0,18.0,400.0,0.9911471,3.0395014,18.048695,442.70032,-11.278099
179.1848,0.60655689,9.4351273,0.0,0,18.0,400.0,0.99073189,2.8830388,18.051085,442.65955,-11.296229
179.1872,0.65053928,9.4405489,0.0,0,18.0,400.0,0.99144477,3.0623934,18.049616,442.61636,-11.31402
179.1896,0.70982617,9.4413548,0.0,0,18.0,400.0,0.9928357,3.3675406,18.046616,442.57318,-11.332946
179.192,0.67889369,9.4358215,0.0,0,18.0,400.0,0.99288177,3.2145948,18.049486,442.53,-11.349346
179.2941,0.63393629,9.4363232,0.0,0,18.0,17.344154,0.99172616,2.9996097,18.037493,440.27371,-11.468822
180.4941,0.54905772,9.4473171,0.0,0,18.0,7.588628e-16,0.99382597,2.5815833,17.99946,418.56723,-11.48196
181.6941,0.53789413,9.4549427,0.0,0,18.0,3.2805517000000004e-32,0.99519229,2.5288856,18.000624,403.39972,-11.481809
182.8941,0.53646713,9.462719,0.0,0,18.0,1.4012985e-45,0.99647856,2.5216384,17.998877,390.09894,-11.482421
184.0941,0.53079653,9.4694881,0.0,0,18.0,1.4012985e-45,0.99780679,2.4915996,18.000502,377.86093,-11.482847
185.2941,0.51379949,9.4759445,0.0,0,18.0,1.4012985e-45,0.99897498,2.4057016,17.99958,366.48163,-11.482066
186.4941,0.51235181,9.4822588,0.0,0,18.0,1.4012985e-45,1.000049,2.3929219,17.999699,355.66565,-11.482126
187.6941,0.52323472,9.4884424,0.0,0,18.0,1.4012985e-45,1.0012507,2.4461665,17.999929,345.30655,-11.481928
188.8941,0.51715201,9.4940252,0.0,0,18.0,1.4012985e-45,1.0022205,2.414026,18.000395,335.40317,-11.481845
190.0941,0.5230844,9.5002012,0.0,0,18.0,1.4012985e-45,1.0033118,2.4358263,17.99999,325.86798,-11.481891
191.2941,0.52634919,9.5052547,0.0,0,18.0,1.4012985e-45,1.0042758,2.4500179,17.999624,316.6604,-11.482709
192.4941,0.52221149,9.5103531,0.0,0,18.0,1.4012985e-45,1.0051911,2.4269762,17.999586,307.90005,-11.482464
193.6941,0.51540416,9.5157099,0.0,0,18.0,1.4012985e-45,1.0061717,2.3948944,18.001324,299.29767,-11.482292
194.8941,0.50841743,9.5200558,0.0,0,18.0,1.4012985e-45,1.0069726,2.361748,17.999882,291.17029,-11.482633
196.0941,0.52695727,9.5255594,0.0,0,18.0,1.4012985e-45,1.0079545,2.4417186,17.999857,283.05191,-11.482577
197.2941,0.50761467,9.5292292,0.0,0,18.0,1.4012985e-45,1.0086412,2.354043,18.00082,275.2941,-11.482606
198.4941,0.50555855,9.5341997,0.0,0,18.0,1.4012985e-45,1.0095423,2.3395967,17.998796,267.76147,-11.481836
199.6941,0.512546,9.5386562,0.0,0,18.0,1.4012985e-45,1.010352,2.3696694,18.000544,260.46976,-11.481906
200.8941,0.50619912,9.5423689,0.0,0,18.0,1.4012985e-45,1.0110285,2.3363011,17.998724,253.37425,-11.481687
202.0941,0.5082916,9.5463963,0.0,0,18.0,1.4012985e-45,1.0117474,2.3459964,18.000053,246.67525,-11.482552
203.2941,0.51499724,9.549634,0.0,0,18.0,1.4012985e-45,1.0123714,2.3773012,17.99955,240.08325,-11.482086
204.4941,0.50956917,9.5532017,0.0,0,18.0,1.4012985e-45,1.0130596,2.3478632,17.999788,233.51056,-11.482482
205.6941,0.51113594,9.5567732,0.0,0,18.0,1.4012985e-45,1.0136466,2.3566124,17.999069,227.24188,-11.482353
206.8941,0.50502765,9.5603161,0.0,0,18.0,1.4012985e-45,1.0143209,2.324249,17.998747,220.9493,-11.482423
208.0941,0.49635282,9.5640841,0.0,0,18.0,1.4012985e-45,1.0150855,2.2847896,17.99938,215.13895,-11.482437
209.2941,0.50702626,9.567522,0.0,0,18.0,1.4012985e-45,1.0155996,2.3308196,17.999279,209.41357,-11.482416
210.4941,0.50380564,9.5708466,0.0,0,18.0,1.4012985e-45,1.0162643,2.3139033,17.999043,203.87144,-11.482882
211.6941,0.49750859,9.5741291,0.0,0,18.0,1.4012985e-45,1.0169026,2.2831707,18.00033,198.50529,-11.48222
212.8941,0.50359339,9.5776272,0.0,0,18.0,1.4012985e-45,1.0174501,2.319124,18.000256,193.43262,-11.482436
214.0941,0.49826592,9.5807695,0.0,0,18.0,1.4012985e-45,1.0181028,2.2862325,18.000084,188.5157,-11.481938
215.2941,0.50239074,9.58428,0.0,0,18.0,1.4012985e-45,1.0188404,2.305604,18.000662,183.55223,-11.482329
216.4941,0.49174437,9.5870914,0.0,0,18.0,1.4012985e-45,1.0192043,2.2574272,18.000475,179.66599,-11.481578
217.6941,0.49529028,9.5904417,0.0,0,18.0,1.4012985e-45,1.0199212,2.2699223,18.000496,175.15437,-11.482043
218.8941,0.49108833,9.5930395,0.0,0,18.0,1.4012985e-45,1.0204192,2.2496345,17.999044,170.55219,-11.481591
220.0941,0.49437568,9.5965338,0.0,0,18.0,1.4012985e-45,1.020938,2.2659826,17.999464,166.33354,-11.481826
221.2941,0.50317067,9.5989838,0.0,0,18.0,1.4012985e-45,1.0215213,2.3056197,17.999195,162.12885,-11.48203
222.4941,0.49496827,9.6022739,0.0,0,18.0,1.4012985e-45,1.0221262,2.2668171,18.000998,155.79306,-11.481995
223.6941,0.50459456,9.6046944,0.0,0,18.0,1.4012985e-45,1.0224558,2.3062809,18.000162,151.466,-11.481984
224.8941,0.49782503,9.6072235,0.0,0,18.0,1.4012985e-45,1.0230078,2.2777753,17.999519,147.65828,-11.482315
226.0941,0.50954372,9.6093225,0.0,0,18.0,1.4012985e-45,1.0234146,2.3245568,17.998886,143.99393,-11.482238
227.2941,0.50451362,9.6120853,0.0,0,18.0,1.4012985e-45,1.0238696,2.3046994,18.000254,140.35106,-11.482786
228.4941,0.50482404,9.6145706,0.0,0,18.0,1.4012985e-45,1.0243696,2.3106852,17.999561,136.95461,-11.482248
229.6941,0.50257587,9.6171474,0.0,0,18.0,1.4012985e-45,1.0248259,2.2971652,17.999598,133.58885,-11.482472
230.8941,0.49283493,9.6189795,0.0,0,18.0,1.4012985e-45,1.0251553,2.2463422,18.000051,130.26918,-11.482167
232.0941,0.48247701,9.6210051,0.0,0,18.0,1.4012985e-45,1.0255575,2.2040992,18.000755,127.25285,-11.482099
233.2941,0.49685165,9.6233511,0.0,0,18.0,1.4012985e-45,1.0259705,2.2716503,18.000441,124.23761,-11.48207
234.4941,0.48634264,9.6249323,0.0,0,18.0,1.4012985e-45,1.0263015,2.217551,18.000328,121.16521,-11.482135
235.6941,0.48579085,9.6273546,0.0,0,18.0,1.4012985e-45,1.0267073,2.2175889,18.000219,118.36241,-11.481688
236.8941,0.48785716,9.6292706,0.0,0,18.0,1.4012985e-45,1.0270914,2.2265568,17.999153,115.54676,-11.4819
238.0941,0.48310894,9.6310692,0.0,0,18.0,1.4012985e-45,1.0274705,2.2008584,18.000244,112.83141,-11.482121
239.1941,0.48627514,9.6324806,0.0,0,18.0,1.4012985e-45,1.0276527,2.2115548,17.99971,110.44155,-11.481888