File: examples/dan-msc-case-studies/CS3/data/01 raw data/baron_test_142.csv
Time(sec),Force(kN),Jaw(mm),PowAngle(deg),Power(W),Pram,PTemp,Strain,Stress(MPa),Stroke(mm),TC1(C),wedge(mm)
0.0,1.2020745,-0.51066804,0.0,0,10.594783,0.0015533507,-0.033469789,15.818132,10.594971,36.613743,-9.1421089
2.1,1.0955399,-0.00065039151,0.0,0,10.594783,6.2156005,-3.4935911e-05,13.95365,10.594793,36.374268,-9.4857121
4.2,1.0517648,-0.00043066184,0.0,0,10.594783,12.515604,-2.6163052e-05,13.405803,10.595204,36.258183,-9.4825182
6.3,1.0331298,-0.00016955652,0.0,0,10.594783,18.815603,-2.0155747e-05,13.142613,10.594298,36.044548,-9.4791851
8.4,1.0201972,0.00016450255,0.0,0,10.594783,25.115606,-8.8154247e-06,12.982473,10.594617,35.864822,-9.4753132
10.5,1.0072057,0.00056620553,0.0,0,10.594783,31.415607,2.4919918e-05,12.826952,10.593925,35.674557,-9.4715576
12.6,0.99889332,0.0014388638,12.853282,0,10.594783,37.715607,8.7354507e-05,12.710437,10.59565,35.462273,-9.4681749
14.7,1.0007154,0.0012976445,38.479584,0,10.594783,44.015606,7.3890893e-05,12.734411,10.594216,36.047859,-9.4645958
16.8,1.0156633,-0.0015037125,50.02142,0,10.594783,50.31562,-0.00010764087,12.938592,10.5943,39.271938,-9.4616032
18.9,1.0447637,-0.0082558887,56.232243,0,10.594783,56.615627,-0.00054834341,13.306482,10.594583,45.644611,-9.4579077
21.0,1.0721149,-0.016912686,59.346252,0,10.594783,62.915615,-0.0011129475,13.651169,10.595076,54.289249,-9.4540215
23.1,1.1013224,-0.025568029,60.140419,0,10.594783,69.215637,-0.0016868406,14.061861,10.595588,64.425934,-9.4505129
25.2,1.1072369,-0.034097124,59.144413,0,10.594783,75.515617,-0.0022617213,14.128998,10.593775,75.088676,-9.4464273
27.3,1.1218997,-0.041210528,56.713032,0,10.594783,81.815613,-0.002737897,14.317584,10.594212,84.856361,-9.4425907
29.4,1.1319796,-0.046909541,53.090183,0,10.594783,88.115623,-0.0031215937,14.467377,10.594452,93.373749,-9.4393625
31.5,1.1141112,-0.050433271,49.637886,0,10.594783,94.415642,-0.0033579213,14.232079,10.595914,99.824493,-9.4360914
33.6,1.0869604,-0.053265899,47.955326,0,10.594783,100.71564,-0.0035377503,13.87835,10.595017,104.40722,-9.4325476
35.7,1.0830183,-0.055939816,48.811348,0,10.594783,107.01563,-0.0037227666,13.838781,10.594394,107.89161,-9.4285049
37.8,1.0767033,-0.059057023,51.914944,0,10.594783,113.31563,-0.0039354619,13.766498,10.593323,110.89629,-9.4246445
39.9,1.0917735,-0.063715838,55.231491,0,10.594783,119.61563,-0.0042486489,13.959683,10.594382,115.02432,-9.421216
42.0,1.1171095,-0.069804326,58.07188,0,10.594783,125.91564,-0.0046629636,14.281905,10.594501,120.53872,-9.4175692
44.1,1.1361424,-0.076995969,60.045998,0,10.594783,132.21562,-0.0051368284,14.543835,10.594757,127.35899,-9.4141579
46.2,1.142458,-0.084635749,60.713211,0,10.594783,138.51564,-0.0056320927,14.628856,10.594994,135.46973,-9.4108105
48.3,1.1546801,-0.092667781,60.536888,0,10.594783,144.81564,-0.0061667673,14.791432,10.594449,143.7684,-9.4077635
50.4,1.1554142,-0.098657951,59.353497,0,10.594783,151.11563,-0.0065395534,14.800358,10.595021,152.25372,-9.4040623
52.5,1.1557374,-0.10481249,58.338116,0,10.594783,157.41563,-0.0069388105,14.825921,10.594612,159.41814,-9.400816
54.6,1.1505989,-0.11006833,57.810066,0,10.594783,163.71565,-0.0073006414,14.760452,10.594626,165.23622,-9.396986
56.7,1.1606727,-0.11501517,57.896378,0,10.594783,170.01564,-0.007642536,14.886213,10.595284,170.48753,-9.3935757
58.8,1.1524078,-0.12032161,58.59008,0,10.594783,176.31564,-0.0079885973,14.802729,10.595402,175.4501,-9.3897371
60.9,1.1594435,-0.12631844,59.842525,0,10.594783,182.61565,-0.0083781499,14.877452,10.595994,180.65248,-9.3862171
63.0,1.1709974,-0.13229075,61.018036,0,10.594783,188.91565,-0.0087680398,15.029501,10.593651,186.28871,-9.3824539
65.1,1.1628402,-0.13958202,61.836079,0,10.594783,195.21565,-0.0092667323,14.953609,10.594679,193.03215,-9.3788137
67.2,1.1661006,-0.14703655,62.336418,0,10.594783,201.51566,-0.0097790267,15.002791,10.594941,199.5829,-9.3752108
69.3,1.1689293,-0.1537579,62.545135,0,10.594783,207.81566,-0.010217364,15.037193,10.595194,206.74899,-9.3715343
71.4,1.1772928,-0.16123223,62.545162,0,10.594783,214.11565,-0.010692257,15.14568,10.594044,213.77376,-9.3681297
73.5,1.1647323,-0.16727653,62.51815,0,10.594783,220.41565,-0.011085207,15.001325,10.594333,220.36301,-9.3642607
75.6,1.1625136,-0.17386042,61.91576,0,10.594783,226.71565,-0.011516901,14.972254,10.595104,227.40279,-9.3608732
77.7,1.1706972,-0.17953189,62.116692,0,10.594783,233.01566,-0.011873985,15.06675,10.594594,233.08093,-9.35812
79.8,1.1539736,-0.18639813,62.42746,0,10.594783,239.31566,-0.012352685,14.887546,10.595227,238.74825,-9.3551331
81.9,1.1654141,-0.19275375,63.320484,0,10.594783,245.61568,-0.012762623,15.039941,10.594502,243.96887,-9.3510885
84.0,1.1754602,-0.19991378,64.524132,0,10.594783,251.91566,-0.013235468,15.148828,10.595277,249.14891,-9.3469591
86.1,1.1713241,-0.20818503,65.115952,0,10.594783,258.21594,-0.01379237,15.146358,10.594922,255.83226,-9.3439703
88.2,1.1768359,-0.21688892,65.115974,0,10.594783,264.51566,-0.014376131,15.214118,10.593839,263.67657,-9.341363
90.3,1.1631831,-0.22374575,64.361542,0,10.594783,270.81567,-0.014821602,15.025967,10.595102,271.79187,-9.3377371
92.4,1.1747165,-0.22971056,63.369362,0,10.594783,277.11569,-0.015208772,15.194947,10.59442,279.27762,-9.3339643
94.5,1.1619786,-0.2368045,62.753914,0,10.594783,283.41568,-0.015649099,15.029687,10.59404,285.18832,-9.3299437
96.6,1.1586996,-0.24110502,62.551311,0,10.594783,289.71567,-0.015928967,14.989251,10.594667,290.75638,-9.326232
98.7,1.1678194,-0.24571539,62.962639,0,10.594783,296.01569,-0.016232181,15.105972,10.59619,295.74384,-9.3238029
100.8,1.1777484,-0.25236562,63.87698,0,10.594783,302.31567,-0.016682871,15.246542,10.594374,300.76465,-9.3207664
102.9,1.1682287,-0.2586394,64.740585,0,10.594783,308.61566,-0.017092045,15.130884,10.594877,306.43872,-9.3174543
105.0,1.1780175,-0.26549998,65.478027,0,10.594783,314.91571,-0.017547717,15.265466,10.59547,312.66092,-9.3129263
107.1,1.1753882,-0.27269375,65.841057,0,10.594783,321.2157,-0.018027442,15.246643,10.594582,319.44989,-9.3088884
109.2,1.1783261,-0.2796177,66.097733,0,10.594783,327.51569,-0.018488569,15.283241,10.593713,326.33603,-9.3053131
111.3,1.1697438,-0.28808454,66.018349,0,10.594783,333.81567,-0.019040158,15.163457,10.594289,333.33023,-9.3019638
113.4,1.1809767,-0.29509863,65.906868,0,10.594783,340.11569,-0.019483706,15.330509,10.595536,340.21802,-9.2988682
115.5,1.1686221,-0.30259091,65.788933,0,10.594783,346.41571,-0.01994705,15.188893,10.594373,346.78378,-9.2959766
117.6,1.1728532,-0.30876324,65.665291,0,10.594783,352.7157,-0.020367643,15.254819,10.594193,353.12354,-9.2925253
119.7,1.1760781,-0.31551126,65.665207,0,10.594783,359.01569,-0.020811852,15.289271,10.595092,359.11118,-9.2895231
121.8,1.1819836,-0.32181105,65.841057,0,10.594783,365.3157,-0.021222534,15.391168,10.595426,364.83026,-9.2856569
123.9,1.1673962,-0.3284944,66.330727,0,10.594783,371.61572,-0.021659488,15.200833,10.595075,370.56149,-9.2823601
126.0,1.1854374,-0.33563438,66.708977,0,10.594783,377.91574,-0.022158107,15.429796,10.595422,376.57425,-9.2783661
128.1,1.1764896,-0.34295514,67.169205,0,10.594783,384.2157,-0.02261911,15.334477,10.594335,382.83252,-9.2746782
130.2,1.179654,-0.3505581,67.443115,0,10.594783,390.51569,-0.023109777,15.394025,10.594647,389.23807,-9.2708588
132.3,1.1711576,-0.35882017,67.554924,0,10.594783,396.81573,-0.023624098,15.267,10.594648,395.9697,-9.268157
134.4,1.1939644,-0.36548769,66.357712,0,10.594783,399.99893,-0.024071261,15.567326,10.594572,402.76715,-9.2665024
136.5,1.1759342,-0.36920357,62.297638,0,10.594783,399.99893,-0.024314862,15.331138,10.595067,408.49088,-9.2660198
138.6,1.1443088,-0.36868244,56.484642,0,10.594783,399.99893,-0.0242735,14.940715,10.594671,411.71964,-9.2658911
140.7,1.0946532,-0.36576894,50.441006,0,10.594783,399.99893,-0.024105925,14.262223,10.594574,411.17477,-9.2661371
142.8,1.0528016,-0.358338,47.318775,0,10.594783,399.99893,-0.023628699,13.730998,10.595076,407.09698,-9.2657146
144.9,1.0287089,-0.35214916,49.629208,0,10.594783,399.99893,-0.023218403,13.41515,10.594769,401.12195,-9.2654762
147.0,1.0283415,-0.34879726,54.421894,0,10.594783,399.99893,-0.022977451,13.402332,10.595014,395.73367,-9.2652931
149.1,1.0589397,-0.3489812,58.849148,0,10.594783,399.99893,-0.022984535,13.79564,10.595088,392.82706,-9.2653971
151.2,1.078002,-0.35180667,61.688133,0,10.594783,399.99893,-0.023179138,14.053864,10.594228,392.88043,-9.2652035
153.3,1.1172562,-0.35688195,62.962639,0,10.594783,399.99893,-0.023497885,14.552266,10.595034,394.99539,-9.2650547
155.4,1.1500258,-0.36191398,62.75425,0,10.594783,399.99893,-0.023848252,15.00114,10.595149,398.40463,-9.2655382
157.5,1.1531008,-0.36583188,61.238239,0,10.594783,399.99893,-0.024116062,15.03078,10.595517,401.80954,-9.2650099
159.6,1.152409,-0.36752623,58.609314,0,10.594783,399.99893,-0.024213973,15.030976,10.593719,404.42813,-9.2647085
161.7,1.1296237,-0.36791199,55.85181,0,10.594783,399.99893,-0.024227703,14.737226,10.594999,405.39664,-9.2651587
163.8,1.1111556,-0.36624697,53.975834,0,10.594783,399.99893,-0.024115482,14.500603,10.595226,404.3819,-9.265152
165.9,1.0737102,-0.36422521,53.474728,0,10.594783,399.99893,-0.02399536,14.016496,10.594241,402.21722,-9.2649822
168.0,1.0727957,-0.36199862,54.62397,0,10.594783,399.99893,-0.023845579,13.994583,10.594979,399.58545,-9.2651644
170.1,1.0601974,-0.36181864,56.709919,0,10.594783,399.99893,-0.0238517,13.820879,10.595129,397.42715,-9.2652187
172.2,1.0868894,-0.36192811,58.577991,0,10.594783,399.99893,-0.023859367,14.171404,10.595003,396.62878,-9.264986
174.3,1.1024476,-0.36380574,59.635551,0,10.594783,399.99893,-0.023975775,14.369211,10.594282,397.0343,-9.2648964
176.4,1.1346766,-0.36615497,60.084225,0,10.594783,399.99893,-0.024099173,14.801568,10.595672,398.31421,-9.2651262
178.4634,1.1436278,-0.005656342,59.60088,0,10.594783,399.99893,-0.00037768405,14.550929,10.59442,399.88324,-9.2649937
178.6176,1.1614145,0.0051485086,23.410286,0,10.5948,1.8726909e-23,0.00041366546,14.700657,10.59438,399.92734,-9.2651663
178.6218,1.1446481,0.0077834041,0.0,0,10.5948,0.0,0.00042367878,14.511828,10.594698,399.88174,-9.2649031
178.626,1.1289641,0.0062027816,0.0,0,10.5948,0.0,0.00055706198,14.380268,10.594751,399.90707,-9.2638531
178.6302,1.1218897,0.0067117368,0.0,0,10.5948,0.0,0.00050630566,14.281392,10.593594,399.9324,-9.2657499
178.6344,1.119498,0.011302549,0.0,0,10.5948,0.0,0.00055007805,14.157162,10.597569,399.97522,-9.2654572
178.6386,1.1125015,0.0075272964,0.0,0,10.5948,0.0,0.00068039662,14.301121,10.592163,400.02591,-9.2651062
178.6428,1.1351433,0.0058938684,0.0,0,10.5948,0.0,0.00036200386,14.425821,10.59322,400.05664,-9.2649956
178.647,1.1312071,0.00754211,0.0,0,10.5948,0.0,0.00044292555,14.445521,10.592671,400.04398,-9.2658567
178.6512,1.1294525,0.0072102314,0.0,0,10.5948,0.0,0.00065548928,14.405382,10.595938,400.03131,-9.2662249
178.6554,1.1127075,0.0080628861,0.0,0,10.5948,0.0,0.00044217127,14.227595,10.596308,400.05429,-9.2655849
178.6596,1.1122252,0.011983425,0.0,0,10.5948,0.0,0.00067851803,14.151963,10.593731,400.07962,-9.266305
178.6638,1.1015035,0.0051782532,0.0,0,10.5948,0.0,0.00062224991,14.003944,10.594008,400.09784,-9.2650805
178.668,1.0993692,0.0073560309,0.0,0,10.533863,0.0,0.00038897348,13.917144,10.593742,400.11053,-9.2642908
178.6722,1.1034272,0.0079598827,0.0,0,10.470864,0.0,0.00049649528,14.020741,10.588539,400.12085,-9.2642155
178.6764,1.1258783,0.0071532652,0.0,0,10.407864,0.0,0.00061754044,14.264132,10.56085,400.12085,-9.2666454
178.6806,1.1080261,0.0091764973,0.0,0,10.344864,0.0,0.00049696403,14.098219,10.482328,400.12085,-9.265399
178.6848,1.1108171,0.010558362,0.0,0,10.281863,0.0,0.00065679953,14.200262,10.379494,400.12085,-9.2656908
178.689,1.0959344,0.0059983446,0.0,0,10.218863,0.0,0.00061090867,13.994678,10.290886,400.12085,-9.2651892
178.6932,1.0854596,0.0078946818,0.0,0,10.155864,0.0,0.00035995545,13.775411,10.229173,400.09888,-9.2650414
178.6974,1.0867845,0.0072924406,0.0,0,10.092864,0.0,0.00054247025,13.808226,10.183016,400.04822,-9.2648182
178.7016,1.0899179,0.0071036099,0.0,0,10.029863,0.0,0.00055123196,13.8229,10.125658,400.00259,-9.2657385
178.7058,1.1791112,0.010112843,0.0,0,9.9668636,0.0,0.00044024602,14.985706,10.067758,400.04062,-9.2649431
178.71,3.0903096,0.020200284,0.0,0,9.9038639,0.0,0.0014375967,38.954742,10.008371,400.07864,-9.2635365
178.7142,4.1765256,0.070555396,0.0,0,9.8408632,0.0,0.0047914814,52.900127,9.9393415,400.68594,-9.2622862
178.7184,4.5188832,0.1411415,0.0,0,9.7778635,0.0,0.0092572151,57.05368,9.8667068,401.56,-9.2615814
178.7226,4.6778255,0.21019021,0.0,0,9.7148628,0.0,0.01411929,58.712761,9.795413,403.98779,-9.2624407
178.7268,4.7494578,0.26968914,0.0,0,9.6518641,0.0,0.018198272,59.364147,9.7323256,409.95999,-9.2622547
178.731,4.815177,0.32977355,0.0,0,9.5888634,0.0,0.021950994,60.00106,9.6751175,415.93219,-9.2624578
178.7352,4.8771496,0.38692218,0.0,0,9.5258636,0.0,0.026216269,60.393036,9.6146936,424.21002,-9.2621975
178.7394,4.9438462,0.44484207,0.0,0,9.4633293,0.0,0.030124016,61.192249,9.5511837,432.66519,-9.2623301
178.7436,4.9833202,0.51280373,0.0,0,9.4018736,0.0,0.034571797,61.294422,9.4851789,438.61029,-9.2631369
178.7478,5.0004206,0.5778358,0.0,0,9.3404198,0.0,0.039351515,61.125618,9.418292,442.52139,-9.2634659
178.752,5.0238285,0.64358819,0.0,0,9.278965,0.0,0.043761987,61.272984,9.3525972,445.85886,-9.2625179
178.7562,5.0461001,0.70863795,0.0,0,9.2175112,0.0,0.048113022,61.253277,9.2883081,446.5141,-9.2634554
178.7604,5.0815501,0.76303297,0.0,0,9.1560564,0.0,0.052404743,61.353695,9.2272987,447.16937,-9.2633286
178.7646,5.1157975,0.81960952,0.0,0,9.0946016,0.0,0.056119144,61.594162,9.172473,447.41132,-9.2623348
178.7688,5.136838,0.88318533,0.0,0,9.0331469,0.0,0.060581919,61.558239,9.105896,447.54993,-9.2629986
178.773,5.1694469,0.94293135,0.0,0,8.971693,0.0,0.065140702,61.741924,9.0407372,447.71524,-9.2638149
178.7772,5.1840191,1.0073123,0.0,0,8.9102392,0.0,0.069305986,61.664368,8.9793024,447.91687,-9.2630939
178.7814,5.2025652,1.0720114,0.0,0,8.8487844,0.0,0.073869154,61.513954,8.9161577,448.11969,-9.2629089
178.7856,5.2357864,1.1263386,0.0,0,8.7873297,0.0,0.078319676,61.601223,8.8560495,448.3465,-9.2637062
178.7898,5.2773623,1.1855551,0.0,0,8.7270651,0.0,0.082168579,61.781586,8.7955379,448.5733,-9.2632856
178.794,5.3266935,1.2504449,0.0,0,8.6686182,0.0,0.086905807,62.165367,8.7299118,448.91013,-9.2639055
178.7982,5.333838,1.3067857,0.0,0,8.6101713,0.0,0.091270603,61.981976,8.6672277,449.30075,-9.2627096
178.8024,5.3301606,1.3695048,0.0,0,8.5517235,0.0,0.095467851,61.763939,8.6102467,449.6951,-9.2629805
178.8066,5.3160257,1.4256041,0.0,0,8.4932766,0.0,0.099756643,61.335674,8.5508432,450.09833,-9.2631645
178.8108,5.3563395,1.4785776,0.0,0,8.4348297,0.0,0.10401162,61.488392,8.4944229,450.50156,-9.2626371
178.815,5.4023304,1.5377882,0.0,0,8.3763819,0.0,0.10794525,61.597656,8.4347277,450.74268,-9.2631569
178.8192,5.4385958,1.5974201,0.0,0,8.317935,0.0,0.1126788,61.748047,8.3754501,450.96948,-9.2624283
178.8234,5.4797268,1.6566466,0.0,0,8.2594881,0.0,0.11712555,61.950996,8.3134336,451.20316,-9.2640915
178.8276,5.4835072,1.7191275,0.0,0,8.2010412,0.0,0.12141528,61.854279,8.255331,451.44257,-9.2626438
178.8318,5.5130939,1.7759335,0.0,0,8.1425943,0.0,0.12608151,61.775959,8.1959257,451.67358,-9.262907
178.836,5.5473456,1.8310323,0.0,0,8.0841465,0.0,0.13034399,62.02071,8.1380224,451.86261,-9.2631826
178.8402,5.5448818,1.892508,0.0,0,8.0270939,0.0,0.134642,61.794926,8.0721741,452.05164,-9.2632389
178.8444,5.5501513,1.9486234,0.0,0,7.9714851,0.0,0.13917112,61.498444,8.0208635,452.1012,-9.2625713
178.8486,5.5745888,2.0034769,0.0,0,7.9158773,0.0,0.14337963,61.512177,7.9621367,452.11377,-9.2632799
178.8528,5.6108689,2.0647004,0.0,0,7.8602695,0.0,0.14762262,61.591881,7.907517,452.14203,-9.2630167
178.857,5.6601915,2.1148157,0.0,0,7.8046613,0.0,0.15214871,61.864334,7.8480844,452.19244,-9.2633429
178.8612,5.6879807,2.1668549,0.0,0,7.7490535,0.0,0.15602444,61.863613,7.791831,452.2438,-9.2623272
178.8654,5.6889668,2.2248807,0.0,0,7.6934457,0.0,0.1603162,61.707806,7.7328205,452.31943,-9.2616434
178.8696,5.6900806,2.2763526,0.0,0,7.6378374,0.0,0.16472727,61.400539,7.6810179,452.39502,-9.2635393
178.8738,5.7305274,2.3334267,0.0,0,7.5822296,0.0,0.16900907,61.630058,7.6250539,452.37888,-9.2623911
178.878,5.756052,2.3924294,0.0,0,7.5266213,0.0,0.17329423,61.679962,7.5737081,452.31589,-9.2630091
178.8822,5.795608,2.4436076,0.0,0,7.4710135,0.0,0.17802198,61.720562,7.5130839,452.29248,-9.2627735
178.8864,5.8461027,2.495985,0.0,0,7.4154053,0.0,0.18188818,62.103573,7.4547653,452.36807,-9.2638559
178.8906,5.8807616,2.5548987,0.0,0,7.361393,0.0,0.18655671,62.133568,7.399127,452.4437,-9.2628908
178.8948,5.8725023,2.6091206,0.0,0,7.308507,0.0,0.19133551,61.827606,7.3417315,452.53076,-9.2620726
178.899,5.8713117,2.6650269,0.0,0,7.2556205,0.0,0.19551159,61.536388,7.2890563,452.61899,-9.2630863
178.9032,5.8371525,2.7172587,0.0,0,7.202734,0.0,0.19956961,60.97604,7.2386632,452.68704,-9.262496
178.9074,5.888453,2.7631102,0.0,0,7.1498475,0.0,0.20391269,61.179943,7.1915545,452.73743,-9.2641106
178.9116,5.9621458,2.8159297,0.0,0,7.096961,0.0,0.20780699,61.654446,7.1363802,452.79971,-9.2631893
178.9158,5.9980617,2.8720038,0.0,0,7.044075,0.0,0.21249494,61.755043,7.0813203,452.92572,-9.2632647
178.92,6.0336905,2.9206269,0.0,0,6.991188,0.0,0.21679129,61.764992,7.0279946,453.05176,-9.2624531
178.9242,6.0687118,2.9812467,0.0,0,6.938302,0.0,0.22129257,61.971844,6.9727907,453.20728,-9.2625198
178.9284,6.0679812,3.0349419,0.0,0,6.8854156,0.0,0.22592255,61.651283,6.9168072,453.37106,-9.2629738
178.9326,6.0821357,3.0807736,0.0,0,6.8325291,0.0,0.23015606,61.536369,6.8650298,453.57568,-9.2625256
178.9368,6.1155286,3.1345031,0.0,0,6.7796426,0.0,0.23416688,61.57835,6.8109055,453.8403,-9.2623272
178.941,6.1397114,3.1895747,0.0,0,6.728508,0.0,0.2390741,61.542732,6.759728,454.10202,-9.2637024
178.9452,6.1826158,3.2402949,0.0,0,6.6781921,0.0,0.24354769,61.62566,6.7015958,454.26587,-9.2631216
178.9494,6.1800833,3.2956038,0.0,0,6.6278758,0.0,0.24768715,61.475033,6.6543651,454.42969,-9.2629747
178.9536,6.1957946,3.344439,0.0,0,6.5775599,0.0,0.25231355,61.321014,6.6016259,454.57706,-9.2630587
178.9578,6.1870885,3.3860586,0.0,0,6.5272441,0.0,0.25607789,61.018669,6.5537176,454.71567,-9.2609386
178.962,6.200726,3.4367783,0.0,0,6.4769282,0.0,0.25990942,60.91486,6.5089459,453.71899,-9.263093
178.9662,6.2391691,3.4844093,0.0,0,6.4266124,0.0,0.26437679,61.020851,6.4558311,449.74719,-9.2621632
178.9704,6.3080206,3.5351813,0.0,0,6.376296,0.0,0.26887482,61.381828,6.4035373,445.77536,-9.2629137
178.9746,6.3464193,3.5944331,0.0,0,6.3259802,0.0,0.27340341,61.517815,6.352046,441.58789,-9.2618904
178.9788,6.3640661,3.6432672,0.0,0,6.2756648,0.0,0.27848297,61.27932,6.2974615,437.3764,-9.2624302
178.983,6.3956871,3.6877995,0.0,0,6.2253485,0.0,0.28230831,61.457684,6.2468648,435.36438,-9.2622347
178.9872,6.4153628,3.7402148,0.0,0,6.1750326,0.0,0.28652292,61.365852,6.1942015,435.35175,-9.2629814
178.9914,6.4160056,3.7887483,0.0,0,6.1266279,0.0,0.29131708,60.997826,6.1461182,435.32239,-9.2628775
178.9956,6.421545,3.837786,0.0,0,6.0787735,0.0,0.29545453,60.964951,6.1011429,435.19617,-9.26332
178.9998,6.4659581,3.8938518,0.0,0,6.0309186,0.0,0.30011848,60.986416,6.0490313,435.06998,-9.2616749
179.004,6.4947605,3.935503,0.0,0,5.9830642,0.0,0.30469009,60.99477,6.0052166,434.92432,-9.263155
179.0082,6.504859,3.9817445,0.0,0,5.9352088,0.0,0.30849281,60.857635,5.9538751,434.77286,-9.262373
179.0124,6.5437789,4.0327587,0.0,0,5.8873544,0.0,0.31294042,60.940269,5.9057617,434.6264,-9.2639189
179.0166,6.5589986,4.0769744,0.0,0,5.8394995,0.0,0.31749076,60.762589,5.8569808,434.48758,-9.2629471
179.0208,6.6034408,4.1255293,0.0,0,5.7916446,0.0,0.32140911,61.003792,5.8145447,434.35355,-9.2632475
179.025,6.5981488,4.176085,0.0,0,5.7437897,0.0,0.32594275,60.625401,5.764358,434.46713,-9.260601
179.0292,6.6103563,4.2175007,0.0,0,5.6959348,0.0,0.33052406,60.504185,5.7172556,434.58072,-9.2626362
179.0334,6.6661792,4.2660346,0.0,0,5.6480803,0.0,0.3343533,60.714619,5.6678209,435.00259,-9.2625198
179.0376,6.7131257,4.3170314,0.0,0,5.600225,0.0,0.33927527,60.882244,5.6192465,435.59576,-9.2630138
179.0418,6.7348547,4.3624654,0.0,0,5.5544,0.0,0.34394789,60.768223,5.5683861,436.2226,-9.2621899
179.046,6.7636604,4.4130387,0.0,0,5.5088716,0.0,0.34806663,60.836811,5.5254083,436.94196,-9.2616138
179.0502,6.768188,4.462286,0.0,0,5.4633436,0.0,0.35286331,60.552174,5.4721651,437.66132,-9.2621937
179.0544,6.7541447,4.4995036,0.0,0,5.4178157,0.0,0.35695392,60.274967,5.4300718,438.52679,-9.2630177
179.0586,6.8044357,4.5463605,0.0,0,5.3722878,0.0,0.36078882,60.427536,5.3841252,439.41025,-9.263484
179.0628,6.8161607,4.5916848,0.0,0,5.3267598,0.0,0.36548564,60.25219,5.3397856,440.2937,-9.261508
179.067,6.828229,4.6358652,0.0,0,5.2812319,0.0,0.37003875,59.971832,5.2907362,441.17715,-9.2611866
179.0712,6.8440056,4.6834002,0.0,0,5.2357039,0.0,0.37384504,59.928394,5.2487092,442.06052,-9.2629824
179.0754,6.9189391,4.7264862,0.0,0,5.1901755,0.0,0.37859288,60.276554,5.2088332,442.94342,-9.2623262
179.0796,7.025939,4.7691245,0.0,0,5.1446476,0.0,0.3828969,61.031689,5.1570492,443.82632,-9.2624216
179.0838,7.0512633,4.8236647,0.0,0,5.0991197,0.0,0.38769406,60.892605,5.1088624,444.53583,-9.2628441
179.088,6.9925008,4.8681459,0.0,0,5.0535922,0.0,0.39247471,60.143356,5.0625849,445.19116,-9.2636061
179.0922,7.0057249,4.909833,0.0,0,5.0102167,0.0,0.3966547,60.0182,5.0195413,445.75897,-9.262208
179.0964,7.0472031,4.9612741,0.0,0,4.9669147,0.0,0.40104234,60.106289,4.9738264,446.18741,-9.2620649
179.1006,7.0609231,5.000514,0.0,0,4.9236126,0.0,0.40575433,59.861816,4.9310665,446.61548,-9.2628279
179.1048,7.1068363,5.0419698,0.0,0,4.880311,0.0,0.40969086,60.03384,4.8849745,447.0061,-9.2621136
179.109,7.147737,5.0872698,0.0,0,4.8370085,0.0,0.41385433,60.168163,4.8436236,447.39676,-9.2622118
179.1132,7.1485157,5.1285625,0.0,0,4.7937069,0.0,0.41862559,59.895462,4.7990232,447.74747,-9.262742
179.1174,7.1613846,5.1692247,0.0,0,4.7504048,0.0,0.42261744,59.761086,4.7600355,448.0751,-9.2616005
179.1216,7.1916385,5.2188468,0.0,0,4.7071028,0.0,0.4269501,59.751251,4.7148786,448.39948,-9.2627831
179.1258,7.2169657,5.2579374,0.0,0,4.6638007,0.0,0.4319694,59.691383,4.6738186,448.71451,-9.2619457
179.13,7.2809515,5.2956524,0.0,0,4.6204991,0.0,0.43539238,59.935406,4.6300635,449.02951,-9.2637196
179.1342,7.3410006,5.3482904,0.0,0,4.5771966,0.0,0.4405182,60.15868,4.5868549,449.54437,-9.2641821
179.1384,7.3843465,5.3889494,0.0,0,4.5340271,0.0,0.44553736,60.165138,4.539083,450.08621,-9.2636862
179.1426,7.3863125,5.4341292,0.0,0,4.4928331,0.0,0.44963172,59.979584,4.4927649,450.55811,-9.2622833
179.1468,7.4047365,5.4815145,0.0,0,4.4516392,0.0,0.45434615,59.868118,4.4536791,450.96133,-9.2628708
179.151,7.3996015,5.5157394,0.0,0,4.4104452,0.0,0.45886317,59.668289,4.414855,451.34351,-9.2628126
179.1552,7.4036446,5.5547462,0.0,0,4.3692517,0.0,0.46224707,59.368656,4.3720164,451.58292,-9.26264
179.1594,7.434927,5.5990257,0.0,0,4.3280582,0.0,0.46707085,59.251984,4.3320065,451.82233,-9.2626629
179.1636,7.4485655,5.633203,0.0,0,4.2868648,0.0,0.47124788,59.18018,4.2909117,452.14709,-9.2634983
179.1678,7.5315261,5.6785393,0.0,0,4.2456713,0.0,0.47537574,59.599812,4.2557778,452.49994,-9.261363
179.172,7.6332083,5.7223277,0.0,0,4.2044773,0.0,0.48015565,60.138912,4.2098932,452.82431,-9.2622623
179.1762,7.6664672,5.7598052,0.0,0,4.1632838,0.0,0.48487169,60.088451,4.1682363,453.10153,-9.2631283
179.1804,7.6486955,5.8045669,0.0,0,4.1220903,0.0,0.48888898,59.744717,4.1250606,453.37875,-9.2621479
179.1846,7.6280322,5.8427391,0.0,0,4.0808969,0.0,0.49348897,59.327431,4.0882177,453.56778,-9.2634459
179.1888,7.6384478,5.8782153,0.0,0,4.0400209,0.0,0.49777675,59.089394,4.04985,453.75677,-9.2634192
179.193,7.7672791,5.9250193,0.0,0,4.0008435,0.0,0.50204521,59.762787,4.0064511,453.92221,-9.2635241
179.1972,7.8276491,5.9670429,0.0,0,3.9616656,0.0,0.50718361,60.009491,3.9667685,454.07343,-9.2624292
179.2014,7.848958,6.0035448,0.0,0,3.9224882,0.0,0.51152927,59.867439,3.920531,454.20905,-9.2619934
179.2056,7.8522515,6.0455656,0.0,0,3.8833106,0.0,0.51547694,59.704765,3.8868265,454.29724,-9.2631989
179.2098,7.8553228,6.0813003,0.0,0,3.8441329,0.0,0.52014244,59.467625,3.8452411,454.38544,-9.2622013
179.214,7.9026198,6.1198621,0.0,0,3.8049555,0.0,0.52443731,59.582054,3.8067119,454.17719,-9.2637386
179.2182,7.9448357,6.1653223,0.0,0,3.7657778,0.0,0.52860785,59.595551,3.7686071,453.92514,-9.262002
179.2224,7.9987321,6.2032228,0.0,0,3.7266002,0.0,0.53397727,59.72052,3.7284651,453.42352,-9.2631397
179.2266,8.0176363,6.2381153,0.0,0,3.6874225,0.0,0.53785104,59.594875,3.6897023,452.66745,-9.2623653
179.2308,8.0812845,6.2797632,0.0,0,3.6482451,0.0,0.54200369,59.855022,3.6507695,451.87689,-9.2629128
179.235,8.1029587,6.3161068,0.0,0,3.6090674,0.0,0.54692006,59.679123,3.6112182,450.83099,-9.2633362
179.2392,8.1714659,6.3542485,0.0,0,3.5703723,0.0,0.55099434,59.976032,3.5742488,449.78513,-9.2630358
179.2434,8.2535686,6.4035454,0.0,0,3.5331016,0.0,0.55594307,60.303009,3.5320342,446.74289,-9.2632294
179.2476,8.1930418,6.4381208,0.0,0,3.4958305,0.0,0.56120527,59.536526,3.4910331,443.00967,-9.263092
179.2518,8.1824102,6.4705815,0.0,0,3.4585598,0.0,0.56451535,59.233154,3.4559934,439.71109,-9.2633963
179.256,8.242301,6.5124788,0.0,0,3.4212892,0.0,0.56906796,59.443829,3.4200168,437.1633,-9.2633972
179.2602,8.3367481,6.5456872,0.0,0,3.3840184,0.0,0.57389355,59.765049,3.3810458,434.61554,-9.2619066
179.2644,8.4018736,6.5880537,0.0,0,3.3467472,0.0,0.57800466,60.022533,3.3463099,435.96634,-9.2623987
179.2686,8.4587278,6.6316504,0.0,0,3.3094764,0.0,0.58308041,60.177837,3.3055723,437.35461,-9.2628756
179.2728,8.4860401,6.662528,0.0,0,3.2722056,0.0,0.58787608,60.054409,3.2679203,438.64209,-9.2639103
179.277,8.4844141,6.697473,0.0,0,3.234935,0.0,0.59126085,59.835636,3.2309861,439.8663,-9.2626619
179.2812,8.4996052,6.7375445,0.0,0,3.1976643,0.0,0.59607792,59.647953,3.1970198,440.94925,-9.2638454
179.2854,8.5403919,6.770195,0.0,0,3.1603935,0.0,0.60085708,59.633591,3.1601391,441.58029,-9.2626839
179.2896,8.6054163,6.8116369,0.0,0,3.1237545,0.0,0.60473847,59.78149,3.1227839,442.21133,-9.2634792
179.2938,8.679327,6.8504939,0.0,0,3.0882978,0.0,0.60988897,60.057545,3.0827031,442.77673,-9.2623396
179.298,8.7176609,6.8803926,0.0,0,3.0528414,0.0,0.61429733,60.061974,3.0462682,443.33167,-9.2629089
179.3022,8.7628651,6.9172883,0.0,0,3.017385,0.0,0.61786366,60.150768,3.0095406,443.95987,-9.2612848
179.3064,8.7655916,6.9533982,0.0,0,2.9819286,0.0,0.62273383,59.879971,2.9775643,444.66574,-9.2620821
179.3106,8.7903843,6.9855623,0.0,0,2.9464724,0.0,0.627244,59.828892,2.9462981,445.33432,-9.2634659
179.3148,8.8420515,7.0268302,0.0,0,2.9110157,0.0,0.63128132,59.836365,2.9086835,445.69974,-9.2647772
179.319,8.8858604,7.0628037,0.0,0,2.8755593,0.0,0.63661683,59.836132,2.8758812,446.06516,-9.2618742
179.3232,8.9639683,7.0914388,0.0,0,2.8401029,0.0,0.64051938,60.151535,2.8404095,446.11639,-9.2627678
179.3274,9.0652552,7.1311693,0.0,0,2.8046467,0.0,0.64454281,60.606861,2.802731,446.05341,-9.2629404
179.3316,9.1392536,7.1678395,0.0,0,2.7691901,0.0,0.64996397,60.790421,2.7662053,446.08942,-9.2621088
179.3358,9.1819487,7.2022491,0.0,0,2.7337339,0.0,0.65453237,60.756214,2.7315845,446.30362,-9.2623978
179.34,9.2020044,7.2465057,0.0,0,2.6990452,0.0,0.65902632,60.636982,2.6942441,446.51782,-9.2633858
179.3442,9.1869211,7.2762423,0.0,0,2.665319,0.0,0.66416132,60.211105,2.659111,447.07816,-9.2621155
179.3484,9.2484503,7.3069401,0.0,0,2.631593,0.0,0.66789234,60.390846,2.6259265,447.6452,-9.2631721
179.3526,9.3208313,7.345427,0.0,0,2.597867,0.0,0.67225826,60.591423,2.5917685,448.28085,-9.2613029
179.3568,9.34758,7.3770556,0.0,0,2.564141,0.0,0.67731363,60.452969,2.5551751,448.9613,-9.2622013
179.361,9.4018888,7.4104362,0.0,0,2.5304151,0.0,0.68135476,60.513165,2.5235288,449.61874,-9.2624493
179.3652,9.4639807,7.4505763,0.0,0,2.4966891,0.0,0.68568748,60.762226,2.4914031,450.19836,-9.2625475
179.3694,9.5263453,7.4757471,0.0,0,2.4629631,0.0,0.69060254,60.852783,2.4571588,450.77802,-9.2628412
179.3736,9.5681257,7.509747,0.0,0,2.4292369,0.0,0.69445723,60.842751,2.4213641,450.93878,-9.2617588
179.3778,9.6427002,7.5471735,0.0,0,2.3955109,0.0,0.6989767,61.056488,2.3898959,451.02698,-9.2636728
179.382,9.7025595,7.5788698,0.0,0,2.3617849,0.0,0.70441037,61.079899,2.3533549,451.07318,-9.2620525
179.3862,9.7013159,7.6150212,0.0,0,2.328059,0.0,0.70826119,60.820011,2.3220809,451.07318,-9.2618818
179.3904,9.7965631,7.6528349,0.0,0,2.2952197,0.0,0.71307552,61.134178,2.2906482,451.0946,-9.2637653
179.3946,9.8969307,7.6795964,0.0,0,2.26314,0.0,0.71802735,61.512409,2.258105,451.30884,-9.2630005
179.3988,9.8829288,7.7120361,0.0,0,2.2310605,0.0,0.72147363,61.191669,2.223603,451.52304,-9.262413
179.403,9.8869419,7.7470427,0.0,0,2.198981,0.0,0.72629559,60.947826,2.1941969,451.68253,-9.2635231
179.4072,9.9051237,7.7717667,0.0,0,2.1669014,0.0,0.73077345,60.7621,2.1607311,451.82114,-9.262907
179.4114,9.9892864,7.8090115,0.0,0,2.1348217,0.0,0.73466557,61.027775,2.1319911,451.98166,-9.2633553
179.4156,10.147925,7.845026,0.0,0,2.102742,0.0,0.73978794,61.670208,2.0994987,452.18326,-9.2627344
179.4198,10.243092,7.8694835,0.0,0,2.0706627,0.0,0.74446952,61.920403,2.0657673,452.38486,-9.2623367
179.424,10.336624,7.9042096,0.0,0,2.038583,0.0,0.74801034,62.258408,2.031065,452.67218,-9.2625551
179.4282,10.408669,7.9442101,0.0,0,2.0065033,0.0,0.75413501,62.341217,1.9958053,452.96201,-9.2625132
179.4324,10.419168,7.9690866,0.0,0,1.9744238,0.0,0.75829262,62.158886,1.9621528,453.1261,-9.2618704
179.4366,10.432583,8.0118141,0.0,0,1.9423442,0.0,0.76315677,61.984818,1.9305022,453.20471,-9.2622013
179.4408,10.493158,8.041338,0.0,0,1.911255,0.0,0.76832205,61.959721,1.9003352,453.35648,-9.2633028
179.445,10.525726,8.066555,0.0,0,1.8807379,0.0,0.77221948,61.907635,1.8631266,453.67151,-9.2623796
179.4492,10.564515,8.0987825,0.0,0,1.8502207,0.0,0.77566272,61.943455,1.8397876,453.98654,-9.2627821
179.4534,10.620578,8.1296501,0.0,0,1.8197033,0.0,0.78106666,61.937199,1.8065695,454.07809,-9.2627096
179.4576,10.664756,8.1528225,0.0,0,1.7891862,0.0,0.78454167,61.963005,1.7847421,454.15372,-9.2610416
179.4618,10.809876,8.1913071,0.0,0,1.758669,0.0,0.78880113,62.51981,1.7506005,454.03976,-9.262373
179.466,10.909468,8.2196817,0.0,0,1.7281518,0.0,0.79436886,62.810295,1.7188412,453.77515,-9.2621202
179.4702,10.949942,8.2475243,0.0,0,1.6976346,0.0,0.79846412,62.735786,1.6842045,453.58804,-9.2613354
179.4744,11.022538,8.2826853,0.0,0,1.6671174,0.0,0.80258393,62.893166,1.6596718,453.75186,-9.2621727
179.4786,11.120125,8.3081932,0.0,0,1.6366003,0.0,0.80785263,63.126686,1.6269009,453.91565,-9.262454
179.4828,11.20342,8.340992,0.0,0,1.6060829,0.0,0.81215101,63.312382,1.5999302,453.86652,-9.2622623
179.487,11.298488,8.3790064,0.0,0,1.5755658,0.0,0.81674391,63.594692,1.5694848,453.76572,-9.2624445
179.4912,11.35218,8.4023476,0.0,0,1.5461327,0.0,0.82210505,63.56094,1.5381831,453.3139,-9.2622099
179.4954,11.299829,8.4312534,0.0,0,1.5171022,0.0,0.82566684,63.046272,1.509761,452.39404,-9.2630672
179.4996,11.28838,8.4612846,0.0,0,1.4880718,0.0,0.82972509,62.709259,1.4842887,451.50122,-9.2623749
179.5038,11.38194,8.4852219,0.0,0,1.4590415,0.0,0.83477175,62.854103,1.4544863,451.09796,-9.2624254
179.508,11.534727,8.5136766,0.0,0,1.430011,0.0,0.83806401,63.502331,1.427987,450.69473,-9.2637749
179.5122,11.694546,8.55058,0.0,0,1.4009807,0.0,0.84335899,64.022705,1.3971665,447.7836,-9.2623463
179.5164,11.802094,8.5729961,0.0,0,1.3719503,0.0,0.84845495,64.344482,1.3645301,443.67148,-9.2616539
179.5206,11.853373,8.6018162,0.0,0,1.3429198,0.0,0.85182416,64.401077,1.3352348,438.09912,-9.2632065
179.5248,11.904158,8.6359968,0.0,0,1.3138895,0.0,0.85698301,64.36985,1.3045589,429.11948,-9.2617455
179.529,11.974139,8.6593885,0.0,0,1.2848592,0.0,0.86186635,64.420868,1.2789661,420.13983,-9.261899
179.5332,12.090876,8.6945095,0.0,0,1.2558287,0.0,0.86602414,64.752151,1.2492491,415.91748,-9.263135
179.5374,12.234505,8.7283373,0.0,0,1.2267983,0.0,0.87164724,65.155609,1.2155498,412.08752,-9.2626925
179.5416,12.255682,8.7489367,0.0,0,1.1989383,0.0,0.87621373,64.981155,1.1844344,412.10748,-9.2617168
179.5458,12.235787,8.7792206,0.0,0,1.1713274,0.0,0.87952423,64.670624,1.158373,415.3078,-9.2622595
179.55,12.302796,8.806572,0.0,0,1.1437165,0.0,0.88461053,64.657883,1.1359388,418.44937,-9.2615776
179.5542,12.365335,8.8276978,0.0,0,1.1161058,0.0,0.88866717,64.773254,1.1090802,421.30676,-9.2627802
179.5584,12.434788,8.8601484,0.0,0,1.0884949,0.0,0.8922587,64.908669,1.0839105,424.16415,-9.2621326
179.5626,12.599264,8.8874207,0.0,0,1.0608841,0.0,0.89765108,65.317406,1.0561383,424.29681,-9.2627182
179.5668,12.747471,8.9098129,0.0,0,1.0332733,0.0,0.90222555,65.821434,1.0247673,423.72787,-9.2609158
179.571,12.893522,8.9427319,0.0,0,1.0056624,0.0,0.90596789,66.279572,0.99730021,423.49799,-9.2633581
179.5752,13.046455,8.9732075,0.0,0,0.97805184,0.0,0.91206282,66.673904,0.9662987,423.73822,-9.2622404
179.5794,13.046464,8.9970589,0.0,0,0.95044094,0.0,0.91620421,66.474953,0.94039845,424.02069,-9.2618675
179.5836,13.023104,9.0324945,0.0,0,0.92283016,0.0,0.9205358,66.043602,0.91306508,425.24704,-9.262085
179.5878,13.042216,9.0550079,0.0,0,0.89521939,0.0,0.92608327,65.786568,0.89010322,426.47342,-9.2623835
179.592,13.092787,9.0718822,0.0,0,0.86885226,0.0,0.92855042,65.864502,0.86053622,427.85001,-9.2624712
179.5962,13.206351,9.1018677,0.0,0,0.84259385,0.0,0.93253684,66.156235,0.83601278,429.30176,-9.2623396
179.6004,13.406887,9.1282492,0.0,0,0.81633544,0.0,0.93827468,66.727585,0.80709445,430.77182,-9.2614269
179.6046,13.55608,9.1514101,0.0,0,0.79007703,0.0,0.94198638,67.256386,0.78204679,432.28674,-9.2608938
179.6088,13.677723,9.1886082,0.0,0,0.76381862,0.0,0.94693422,67.526146,0.75406003,433.80167,-9.2608318
179.613,13.730927,9.2096119,0.0,0,0.73756027,0.0,0.95261753,67.428322,0.72491241,435.01617,-9.2615299
179.6172,13.783123,9.2326317,0.0,0,0.71130186,0.0,0.95557773,67.519936,0.70144451,436.20251,-9.2622852
179.6214,13.79958,9.2603941,0.0,0,0.68504345,0.0,0.96008307,67.249207,0.6746009,437.55182,-9.261755
179.6256,13.852028,9.2790356,0.0,0,0.6587851,0.0,0.96485788,67.191475,0.65033519,439.04108,-9.262516
179.6298,13.937352,9.306222,0.0,0,0.6325267,0.0,0.96819574,67.401474,0.62669992,440.36478,-9.2621412
179.634,14.11352,9.3362932,0.0,0,0.60626829,0.0,0.973167,67.924751,0.60158747,440.83176,-9.2625608
179.6382,14.319342,9.3546848,0.0,0,0.58003461,0.0,0.9782213,68.523422,0.57473648,441.29874,-9.2607756
179.6424,14.486824,9.3789854,0.0,0,0.55503875,0.0,0.98112231,69.210495,0.54709852,441.99344,-9.2610493
179.6466,14.449895,9.4124613,0.0,0,0.53004873,0.0,0.98705548,68.643173,0.52062732,442.75024,-9.2615328
179.6508,13.442867,9.4104471,0.0,0,0.50505871,0.0,0.98815525,63.751602,0.50551581,443.58435,-9.2629099
179.655,12.787328,9.4220934,0.0,0,0.48006868,0.0,0.98838782,60.596329,0.48660529,444.52994,-9.2629824
179.6592,12.399942,9.4299717,0.0,0,0.45507869,0.0,0.99023461,58.681278,0.47354934,445.45071,-9.2636786
179.6634,12.139297,9.427187,0.0,0,0.4300887,0.0,0.99130118,57.373852,0.45382479,445.65234,-9.2653646
179.6676,11.889535,9.434763,0.0,0,0.40509868,0.0,0.99081159,56.196384,0.433864,445.85397,-9.2645063
179.6718,11.516778,9.4394493,0.0,0,0.38010871,0.0,0.99222267,54.377674,0.41871852,445.91479,-9.2642994
179.676,11.074138,9.4330187,0.0,0,0.35511869,0.0,0.9921366,52.314835,0.41233695,445.90219,-9.2640762
179.6802,10.722334,9.4452238,0.0,0,0.33012873,0.0,0.9922967,50.591408,0.40679383,445.95685,-9.2652349
179.6844,10.476629,9.4455051,0.0,0,0.30513871,0.0,0.99349242,49.416161,0.40294886,446.18369,-9.2656136
179.6886,10.447915,9.4367828,0.0,0,0.28028375,0.0,0.99286509,49.308464,0.38779274,446.41049,-9.2640553
179.6928,10.615361,9.4464808,0.0,0,0.25652012,0.0,0.99270171,50.079361,0.36001915,446.64871,-9.2639532
179.697,10.85707,9.4469852,0.0,0,0.23275654,0.0,0.99395531,51.180721,0.32434604,446.88812,-9.2634983
179.7012,11.045659,9.447094,0.0,0,0.20899299,0.0,0.99437368,52.04845,0.29290661,447.13422,-9.2638674
179.7054,11.146988,9.4575377,0.0,0,0.18522939,0.0,0.99444592,52.45182,0.26204053,447.38623,-9.2626181
179.7096,11.171679,9.45679,0.0,0,0.16146579,0.0,0.99607497,52.563946,0.23506495,447.64209,-9.263341
179.7138,11.162586,9.4564991,0.0,0,0.13770218,0.0,0.99575579,52.504677,0.20710625,447.91931,-9.2640228
179.718,11.111867,9.4607458,0.0,0,0.11393858,0.0,0.99528033,52.286602,0.18313919,448.19653,-9.2632284
179.7222,11.034875,9.4619474,0.0,0,0.090174973,0.0,0.99702001,51.870956,0.1625303,448.41507,-9.2639542
179.7264,10.968491,9.4605465,0.0,0,0.066411369,0.0,0.99625695,51.574539,0.13894105,448.6167,-9.2644138
179.7306,10.914283,9.472908,0.0,0,0.042647772,0.0,0.99711484,51.24411,0.11799192,448.72253,-9.2637396
179.7348,10.870377,9.4681387,0.0,0,0.018884173,0.0,0.99830514,51.045597,0.098760001,448.68472,-9.2638149
179.739,10.827781,9.4674778,0.0,0,-0.0047604209,0.0,0.9973852,50.845051,0.081699632,448.64633,-9.2623987
179.7432,10.768126,9.4749212,0.0,0,-0.02794442,0.0,0.99801987,50.492668,0.060255185,448.58334,-9.263238
179.7474,10.691389,9.4708605,0.0,0,-0.051128417,0.0,0.99874592,50.16053,0.047398165,448.52032,-9.2631369
179.7516,10.597826,9.4754658,0.0,0,-0.074312419,0.0,0.99860197,49.708946,0.029863982,448.49814,-9.2640867
179.7558,10.496564,9.4833145,0.0,0,-0.097496413,0.0,0.99937826,49.256863,0.017135538,448.49814,-9.2637396
179.76,10.39672,9.4746304,0.0,0,0.20877577,400.0,0.99967968,48.696835,0.0053594681,448.50156,-9.2647896
179.7642,10.14665,9.4781542,0.0,0,0.96941304,400.0,0.99891692,47.633671,-0.0003588573,448.51416,-9.2631159
179.7684,7.3371859,9.4728212,0.0,0,1.7300493,400.0,0.99784613,34.642788,0.12359201,448.52676,-9.2654839
179.7726,2.2982197,9.4466696,0.0,0,2.4906862,400.0,0.9948501,11.127485,0.41561937,448.71985,-9.2711096
179.7768,0.13026361,9.4482632,0.0,0,3.2513227,400.0,0.99302959,0.62817907,1.292449,448.93408,-9.2717314
179.781,-0.11765787,9.446701,0.0,0,4.0119596,400.0,0.993016,-0.56415141,2.5506618,449.19409,-9.2712278
179.7852,0.032771073,9.4343443,0.0,0,4.7725964,400.0,0.99267358,0.094805986,3.4429324,449.49652,-9.2712603
179.7894,-0.014114598,9.4406776,0.0,0,5.5332332,400.0,0.9918474,-0.099936359,4.1711903,449.77194,-9.2706013
179.7936,-0.052526675,9.4420719,0.0,0,6.2938704,400.0,0.99266011,-0.2136801,4.8942323,449.88535,-9.2679424
179.7978,0.0027243097,9.4337845,0.0,0,7.0545073,400.0,0.99243915,0.019031294,5.6425529,449.99875,-9.2674599
179.802,0.068722039,9.4378099,0.0,0,7.8151436,400.0,0.99138433,0.39823508,6.4294295,450.06384,-9.2679501
179.8062,-0.13150974,9.4428072,0.0,0,8.5757809,400.0,0.99280858,-0.61761558,7.220798,450.11423,-9.2671671
179.8104,-0.083844982,9.4354057,0.0,0,9.3364182,400.0,0.9923622,-0.475238,8.0078964,450.17447,-9.266881
179.8146,0.10120948,9.4343071,0.0,0,10.097054,400.0,0.99055368,0.48109686,8.8025637,450.25009,-9.2656717
179.8188,-0.1476731,9.4347954,0.0,0,10.857692,400.0,0.99182504,-0.69641894,9.5788851,450.32605,-9.265131
179.823,0.026871797,9.4340878,0.0,0,11.618328,400.0,0.99214637,0.036775857,10.347531,450.42685,-9.2662325
179.8272,0.0014232228,9.4390526,0.0,0,12.378964,400.0,0.99102575,0.026585069,11.099991,450.52768,-9.2659283
179.8314,-0.10932788,9.4372511,0.0,0,13.139602,400.0,0.99242812,-0.47588965,11.82906,450.62848,-9.2651739
179.8356,0.028560871,9.4337559,0.0,0,13.900239,400.0,0.99169517,0.072208717,12.583354,450.72931,-9.2669706
179.8398,-0.069126844,9.4344797,0.0,0,14.660876,400.0,0.99057692,-0.25227171,13.352362,450.8136,-9.2641687
179.844,-0.12984166,9.4327765,0.0,0,15.421513,400.0,0.99151301,-0.65981811,14.109609,450.85141,-9.2656107
179.8482,0.085184358,9.4336929,0.0,0,16.18215,400.0,0.99174708,0.34929708,14.878599,450.88919,-9.2654715
179.8524,-0.056567233,9.4399691,0.0,0,16.942787,400.0,0.99107099,-0.26123974,15.640269,450.89352,-9.2649746
179.8566,-0.021390952,9.4341173,0.0,0,17.703424,400.0,0.99229741,-0.12383319,16.401012,450.89352,-9.2647181
179.8608,0.028947111,9.4307175,0.0,0,18.0,400.0,0.99087244,0.10332383,17.165283,450.91278,-9.2641954
179.865,-0.083477154,9.4372501,0.0,0,18.0,400.0,0.99114507,-0.30799526,17.868109,450.95059,-9.2644062
179.8692,-0.021134889,9.4352169,0.0,0,18.0,400.0,0.99254352,-0.11755741,18.345543,450.99173,-9.2688313
179.8734,0.25424176,9.4436674,0.0,0,18.0,400.0,0.99291134,1.1591723,18.480539,451.05475,-9.275568
179.8776,0.97939622,9.4631033,0.0,0,18.0,400.0,0.9956435,4.6512384,18.292074,451.11777,-9.2886314
179.8818,0.89073104,9.4608507,0.0,0,18.0,400.0,0.99720722,4.1794615,18.103876,451.15213,-9.3147631
179.886,0.87127692,9.458807,0.0,0,18.0,400.0,0.99558663,4.0911069,18.035269,451.17734,-9.344902
179.8902,0.87493604,9.4601183,0.0,0,18.0,400.0,0.99546856,4.1272082,18.050877,451.19772,-9.381526
179.8944,0.93794286,9.4551687,0.0,0,18.0,400.0,0.99626237,4.3470254,18.094204,451.21036,-9.4138813
179.8986,0.98216569,9.4583912,0.0,0,18.0,400.0,0.99531037,4.5812125,18.13117,451.22284,-9.4471989
179.9028,0.96549684,9.465189,0.0,0,18.0,400.0,0.99638486,4.570672,18.142178,451.21024,-9.4782887
179.907,0.93663323,9.4566278,0.0,0,18.0,400.0,0.9966042,4.435986,18.142838,451.19763,-9.5088987
179.9112,0.88698286,9.457613,0.0,0,18.0,400.0,0.99498934,4.2072287,18.137003,451.17709,-9.5410728
179.9154,0.86358303,9.4615049,0.0,0,18.0,400.0,0.99625993,4.0845966,18.132481,451.15189,-9.5713177
179.9196,0.87631965,9.4547815,0.0,0,18.0,400.0,0.99611109,4.0907197,18.124403,451.1235,-9.6004477
179.9238,0.9224695,9.4622831,0.0,0,18.0,400.0,0.99564373,4.2697034,18.121874,451.08569,-9.6320944
179.928,0.99495876,9.4623556,0.0,0,18.0,400.0,0.99649417,4.5860963,18.116589,451.04788,-9.6633883
179.9322,0.99797994,9.4560337,0.0,0,18.0,400.0,0.99634749,4.665072,18.112011,451.02115,-9.6949196
179.9364,0.97829145,9.4599199,0.0,0,18.0,400.0,0.99500829,4.636508,18.107677,450.99594,-9.7259016
179.9406,0.91660929,9.4606476,0.0,0,18.0,400.0,0.99656373,4.3399253,18.106995,450.98334,-9.7567301
179.9448,0.8762176,9.4564438,0.0,0,18.0,400.0,0.99611241,4.1314888,18.106493,450.98334,-9.7877512
179.949,0.85833305,9.4632339,0.0,0,18.0,400.0,0.99550205,4.0534406,18.102037,450.98022,-9.8202963
179.9532,0.90664798,9.4644222,0.0,0,18.0,400.0,0.99715292,4.1750989,18.100885,450.95502,-9.849617
179.9574,0.94969279,9.4571171,0.0,0,18.0,400.0,0.99610496,4.4055638,18.101709,450.92981,-9.8814583
179.9616,1.0058011,9.458128,0.0,0,18.0,400.0,0.99481225,4.7262659,18.099947,450.90463,-9.9120636
179.9658,0.98361629,9.4609661,0.0,0,18.0,400.0,0.99690479,4.6284142,18.101217,450.87943,-9.9440327
179.97,0.94266909,9.4574842,0.0,0,18.0,400.0,0.9957931,4.4652286,18.09371,450.85892,-9.9740658
179.9742,0.89415121,9.4657488,0.0,0,18.0,400.0,0.99589366,4.2312689,18.095591,450.84631,-10.004939
179.9784,0.85883933,9.4610128,0.0,0,18.0,400.0,0.9968859,4.0593972,18.093985,450.83371,-10.035218
179.9826,0.86955404,9.4599304,0.0,0,18.0,400.0,0.99617165,4.0967956,18.091648,450.78348,-10.0665
179.9868,0.94664508,9.4632015,0.0,0,18.0,400.0,0.9958111,4.4015694,18.089441,450.73306,-10.099189
179.991,0.98822075,9.4602966,0.0,0,18.0,400.0,0.99691099,4.6331806,18.089312,450.67487,-10.129191
179.9952,1.0284029,9.4603558,0.0,0,18.0,400.0,0.99598479,4.808651,18.086916,450.61185,-10.161056
179.9994,0.99581182,9.468812,0.0,0,18.0,400.0,0.99680674,4.7166004,18.085096,450.55801,-10.190382
180.0036,0.91077989,9.4615622,0.0,0,18.0,400.0,0.99735034,4.3248091,18.084623,450.53284,-10.222865
180.0078,0.88577175,9.4613543,0.0,0,18.0,400.0,0.99604189,4.1674752,18.083494,450.50763,-10.252601
180.012,0.87483549,9.4643602,0.0,0,18.0,400.0,0.99625874,4.1084881,18.079422,450.50427,-10.284779
180.0162,0.91269237,9.4590921,0.0,0,18.0,400.0,0.99683565,4.2396622,18.07728,450.50427,-10.315038
180.0204,0.98835152,9.463109,0.0,0,18.0,400.0,0.99599016,4.5991864,18.074703,450.47955,-10.346999
180.0246,1.0191504,9.465353,0.0,0,18.0,400.0,0.99629414,4.780057,18.079538,450.42917,-10.377494
180.0288,0.99364227,9.4608774,0.0,0,18.0,400.0,0.99748629,4.7092605,18.071499,450.37875,-10.410131
180.033,0.96725833,9.4602041,0.0,0,18.0,400.0,0.99545312,4.5762959,18.073597,450.32834,-10.437566
180.0372,0.8888641,9.4641199,0.0,0,18.0,400.0,0.99661744,4.2011104,18.074207,450.27795,-10.472027
180.0414,0.87972224,9.4601488,0.0,0,18.0,400.0,0.9967984,4.0993443,18.072136,450.24612,-10.501974
180.0456,0.89972275,9.4650526,0.0,0,18.0,400.0,0.99610072,4.1940632,18.077757,450.22092,-10.533639
180.0498,0.96532977,9.466424,0.0,0,18.0,400.0,0.99711108,4.4833341,18.071934,450.18658,-10.562828
180.054,1.0253983,9.4605446,0.0,0,18.0,400.0,0.99710649,4.757472,18.074265,450.1362,-10.594722
180.0582,1.0342346,9.4662695,0.0,0,18.0,400.0,0.99635506,4.8605709,18.070261,450.08582,-10.62571
180.0624,0.98226458,9.463871,0.0,0,18.0,400.0,0.99701709,4.6710625,18.070122,450.0354,-10.6573
180.0666,0.92731553,9.4616985,0.0,0,18.0,400.0,0.9971149,4.4033599,18.068874,449.98502,-10.689196
180.0708,0.8865332,9.4675035,0.0,0,18.0,400.0,0.99629748,4.2072005,18.067858,449.94995,-10.71911
180.075,0.88595134,9.4644032,0.0,0,18.0,400.0,0.99737006,4.1616087,18.067921,449.92474,-10.75024
180.0792,0.9272024,9.4612455,0.0,0,18.0,400.0,0.99701768,4.3055105,18.065138,449.89954,-10.779268
180.0834,1.0029001,9.4648132,0.0,0,18.0,400.0,0.99598831,4.6669989,18.06234,449.87433,-10.810239
180.0876,1.0365417,9.4633532,0.0,0,18.0,400.0,0.99736106,4.854351,18.061527,449.84912,-10.843359
180.0918,1.0118489,9.4611893,0.0,0,18.0,400.0,0.99668318,4.8073521,18.05802,449.82391,-10.874391
180.096,0.9564538,9.4709339,0.0,0,18.0,400.0,0.99677658,4.5467792,18.051384,449.79874,-10.905246
180.1002,0.89746827,9.4652834,0.0,0,18.0,400.0,0.99779338,4.225944,18.056005,449.77353,-10.937055
180.1044,0.88138694,9.4620171,0.0,0,18.0,400.0,0.9966166,4.1312041,18.053984,449.74832,-10.96893
180.1086,0.92756897,9.4661636,0.0,0,18.0,400.0,0.996387,4.3251462,18.056599,449.71783,-10.99682
180.1128,0.9900347,9.4631815,0.0,0,18.0,400.0,0.99760109,4.5795102,18.057173,449.64224,-11.027999
180.117,1.032577,9.4634476,0.0,0,18.0,400.0,0.99662596,4.8696513,18.05545,449.56662,-11.05813
180.1212,1.0437894,9.4727983,0.0,0,18.0,400.0,0.9973104,4.9268637,18.056477,449.5094,-11.091782
180.1254,0.98711997,9.4645643,0.0,0,18.0,400.0,0.99784935,4.6779718,18.054543,449.45898,-11.123878
180.1296,0.93019778,9.4641104,0.0,0,18.0,400.0,0.99658448,4.4480619,18.053556,449.41745,-11.152934
180.1338,0.89356321,9.4667931,0.0,0,18.0,400.0,0.99671912,4.2032962,18.053326,449.39224,-11.184968
180.138,0.89141202,9.4629974,0.0,0,18.0,400.0,0.99751264,4.1762223,18.050724,449.36707,-11.215528
180.1422,0.95275736,9.4674931,0.0,0,18.0,400.0,0.99700606,4.4462447,18.052986,449.31726,-11.247262
180.1464,1.0284318,9.4707756,0.0,0,18.0,400.0,0.99738634,4.8033748,18.048965,449.26688,-11.276069
180.1506,1.0388831,9.46558,0.0,0,18.0,400.0,0.99805379,4.8894401,18.05032,449.21646,-11.308371
180.1548,1.0321932,9.4644947,0.0,0,18.0,400.0,0.99616176,4.8729048,18.047363,449.16605,-11.339406
180.5581,0.90918618,9.4703598,0.0,0,18.0,0.0014183701,0.99794859,4.2650695,18.011448,436.48502,-11.482368
182.6581,0.84988534,9.4865065,0.0,0,18.0,3.2689678000000003e-32,1.0008465,3.9781275,17.99968,409.44537,-11.482047
184.7581,0.82058668,9.499548,0.0,0,18.0,1.4012985e-45,1.0031513,3.839823,18.000095,388.01013,-11.482347
186.8581,0.81264198,9.5110722,0.0,0,18.0,1.4012985e-45,1.0052997,3.7768433,17.99975,368.53497,-11.481445
188.9581,0.82553154,9.5217896,0.0,0,18.0,1.4012985e-45,1.0073657,3.8416219,17.999207,350.19009,-11.481399
191.0581,0.82005167,9.5325079,0.0,0,18.0,1.4012985e-45,1.0092473,3.8104692,18.000166,332.90945,-11.482428
193.1581,0.81355751,9.5423546,0.0,0,18.0,1.4012985e-45,1.0110294,3.7709689,17.999369,316.48978,-11.482015
195.2581,0.82827443,9.5521612,0.0,0,18.0,1.4012985e-45,1.0128767,3.8262472,17.999939,301.15988,-11.482404
197.3581,0.83523792,9.5609303,0.0,0,18.0,1.4012985e-45,1.0143809,3.86269,17.999884,286.84058,-11.482228
199.4581,0.82675833,9.5698576,0.0,0,18.0,1.4012985e-45,1.0160493,3.815742,17.999132,273.07825,-11.482558
201.5581,0.84187567,9.5781202,0.0,0,18.0,1.4012985e-45,1.0176568,3.8619893,18.000025,260.09546,-11.482385
203.6581,0.85590792,9.5863104,0.0,0,18.0,1.4012985e-45,1.0191318,3.9302089,18.000008,247.79979,-11.482504
205.7581,0.85231191,9.5941296,0.0,0,18.0,1.4012985e-45,1.020579,3.9180996,17.999424,236.22395,-11.482866
207.8581,0.86079657,9.6015005,0.0,0,18.0,1.4012985e-45,1.0219892,3.9371533,18.000298,225.41135,-11.482085
209.9581,0.88453984,9.6091728,0.0,0,18.0,1.4012985e-45,1.023296,4.0397396,17.99996,214.88994,-11.482005
212.0581,0.88287777,9.61625,0.0,0,18.0,1.4012985e-45,1.02461,4.0421062,17.99873,205.00682,-11.481761
214.1581,0.88272655,9.6223001,0.0,0,18.0,1.4012985e-45,1.0258468,4.0291629,18.000269,195.88513,-11.481804
216.2581,0.89985228,9.6283016,0.0,0,18.0,1.4012985e-45,1.0269436,4.0901165,17.999393,187.0835,-11.482139
218.3581,0.90740412,9.6345444,0.0,0,18.0,1.4012985e-45,1.0280426,4.1381316,18.000986,178.81607,-11.481567
220.4581,0.90111518,9.6404114,0.0,0,18.0,1.4012985e-45,1.0292027,4.1056366,18.000217,170.81877,-11.482183
222.5581,0.91666096,9.6457558,0.0,0,18.0,1.4012985e-45,1.0300958,4.1561928,18.000288,163.40254,-11.48211
224.6581,0.93179834,9.6509809,0.0,0,18.0,1.4012985e-45,1.0310781,4.2314873,17.999495,156.30785,-11.482248
226.7581,0.92391026,9.6557074,0.0,0,18.0,1.4012985e-45,1.0320871,4.1972895,18.000311,149.5842,-11.482652
228.8581,0.92489588,9.6606007,0.0,0,18.0,1.4012985e-45,1.0329554,4.1857605,18.001255,143.15709,-11.482174
230.9581,0.94732636,9.6648865,0.0,0,18.0,1.4012985e-45,1.0337784,4.284873,17.999453,137.20119,-11.482844
233.0581,0.93665135,9.6691084,0.0,0,18.0,1.4012985e-45,1.0345154,4.246892,17.99935,131.49614,-11.482524
235.1581,0.92854106,9.6730661,0.0,0,18.0,1.4012985e-45,1.0352079,4.1961164,17.999865,126.10152,-11.48273
237.2581,0.94594866,9.6771479,0.0,0,18.0,1.4012985e-45,1.0360737,4.2673569,17.999353,120.97697,-11.482377
239.3581,0.95167297,9.6805372,0.0,0,18.0,1.4012985e-45,1.0367106,4.3015628,17.999542,116.27112,-11.482224
240.1581,0.94829714,9.6823359,0.0,0,18.0,1.4012985e-45,1.037003,4.270853,17.999739,114.49277,-11.482341