File: examples/dan-msc-case-studies/CS3/data/01 raw data/baron_test_112.csv
Time(sec),Force(kN),Jaw(mm),PowAngle(deg),Power(W),Pram,PTemp,Strain,Stress(MPa),Stroke(mm),TC1(C),wedge(mm)
0.0,0.8825317,0.088006102,0.0,0,11.076097,0.00028035018,0.0058640717,11.161555,11.075929,22.655439,-9.1250191
1.1,0.83120728,-0.0035077767,0.0,0,11.076097,3.2158809,-0.00020266738,10.575304,11.076475,22.690487,-9.4937754
2.2,0.79942018,-0.0032959057,0.0,0,11.076097,6.5158792,-0.0002185271,10.172829,11.076143,22.653111,-9.4905186
3.3,0.78952408,-0.003225209,0.0,0,11.076097,9.8158827,-0.00021323774,10.063794,11.07553,22.648264,-9.4893084
4.4,0.76402986,-0.0030792132,0.0,0,11.076097,13.115882,-0.00022941263,9.7377501,11.076,22.631241,-9.4865112
5.5,0.75650644,-0.0034930464,0.0,0,11.076097,16.415882,-0.00022223256,9.6340914,11.075885,22.665546,-9.4854994
6.6,0.74324286,-0.0036512048,0.0,0,11.076097,19.715883,-0.00022384727,9.469595,11.075912,22.634369,-9.4831333
7.7,0.73019928,-0.0036591899,0.0,0,11.076097,23.015881,-0.00023202185,9.3110933,11.076056,22.620386,-9.4807882
8.8,0.72185153,-0.0031607093,20.974087,0,11.076097,26.31588,-0.00023291093,9.1923065,11.07574,22.690956,-9.4785509
9.9,0.71915716,-0.0038221872,32.788349,0,11.076097,29.615877,-0.00026479154,9.1707506,11.075739,23.441525,-9.4764128
11.0,0.73470217,-0.0058630379,40.418846,0,11.076097,32.91589,-0.00036935706,9.3610916,11.075603,24.989202,-9.4748945
12.1,0.74507254,-0.0086259451,45.293835,0,11.076097,36.215893,-0.00057781226,9.5009365,11.075952,27.495703,-9.4729414
13.2,0.75188214,-0.011412269,48.435032,0,11.076097,39.515888,-0.00076424715,9.572731,11.075615,31.031567,-9.4715996
14.3,0.75787359,-0.015043382,50.634346,0,11.076097,42.815891,-0.0010191809,9.660718,11.076557,35.264641,-9.4694901
15.4,0.77492571,-0.018954599,51.793106,0,11.076097,46.115887,-0.001240097,9.8806419,11.07625,40.007381,-9.4679298
16.5,0.78395754,-0.02289349,51.932369,0,11.076097,49.415882,-0.0015166621,9.9979095,11.075452,45.238232,-9.4658432
17.6,0.79542196,-0.026716381,51.569847,0,11.076097,52.715881,-0.0017718256,10.150769,11.076354,50.541805,-9.4639292
18.7,0.80181199,-0.030525671,50.439323,0,11.076097,56.015881,-0.0020612928,10.236629,11.07618,55.692844,-9.4618998
19.8,0.8092739,-0.034225006,48.947929,0,11.076097,59.315884,-0.0022782122,10.341934,11.075929,60.588078,-9.4600468
20.9,0.80116183,-0.03663462,47.505287,0,11.076097,62.615879,-0.0024257998,10.220292,11.076016,64.857704,-9.4580765
22.0,0.80945861,-0.038307212,46.123013,0,11.076097,65.915894,-0.0025384452,10.329662,11.075688,68.495674,-9.4561024
23.1,0.80162561,-0.040420055,45.120853,0,11.076097,69.215889,-0.0027118858,10.248558,11.075476,71.789032,-9.4538536
24.2,0.8022905,-0.042393535,44.604496,0,11.076097,72.515892,-0.0028312944,10.242841,11.076386,74.60685,-9.4523926
25.3,0.80404454,-0.044720739,44.555256,0,11.076097,75.815887,-0.0029522541,10.271173,11.076144,77.27018,-9.4501219
26.4,0.80543894,-0.046745852,44.637424,0,11.076097,79.115883,-0.0031084588,10.287973,11.075733,79.729492,-9.4482651
27.5,0.79134357,-0.047884684,45.615231,0,11.076097,82.415886,-0.0031900641,10.111358,11.076089,82.051346,-9.4466305
28.6,0.80118227,-0.050009377,46.959999,0,11.076097,85.715881,-0.0033450231,10.237921,11.076062,84.54248,-9.444437
29.7,0.80342519,-0.052585434,47.955242,0,11.076097,89.015877,-0.0034775285,10.269417,11.076673,87.14769,-9.4429607
30.8,0.80733418,-0.055066142,49.2257,0,11.076097,92.315887,-0.0036648251,10.320278,11.075905,90.118675,-9.44065
31.9,0.80395591,-0.059072964,50.042721,0,11.076097,95.615883,-0.0039193719,10.25537,11.076201,93.188911,-9.4388313
33.0,0.81304687,-0.060880568,50.82275,0,11.076097,98.915886,-0.0040712701,10.403232,11.075854,96.577133,-9.4365387
34.1,0.82464296,-0.064128384,51.569118,0,11.076097,102.21588,-0.0042581386,10.539989,11.076378,99.973106,-9.4347534
35.2,0.83546835,-0.066967018,51.929108,0,11.076097,105.51588,-0.0044338568,10.678292,11.07655,103.68563,-9.4335327
36.3,0.83857977,-0.070624031,51.932369,0,11.076097,108.8159,-0.0046865805,10.726128,11.075599,107.4808,-9.4310198
37.4,0.83864993,-0.074239001,51.934063,0,11.076097,112.11589,-0.0049490454,10.735885,11.076521,111.19216,-9.4293814
38.5,0.83098495,-0.076425619,51.932648,0,11.076097,115.41589,-0.0050886315,10.638714,11.075627,114.83092,-9.4275331
39.6,0.84318852,-0.079443581,51.932377,0,11.076097,118.71589,-0.0052537741,10.779701,11.076221,118.43765,-9.42591
40.7,0.85000169,-0.082164355,51.932377,0,11.076097,122.01589,-0.0054604895,10.881708,11.075572,121.85989,-9.4241524
41.8,0.85473228,-0.085161574,51.932377,0,11.076097,125.31589,-0.0056692311,10.946533,11.075493,125.30151,-9.421504
42.9,0.85920948,-0.089074917,51.932377,0,11.076097,128.61603,-0.0059407474,10.998718,11.075891,128.6046,-9.4204941
44.0,0.86068672,-0.091077007,51.932377,0,11.076097,131.91591,-0.0060317824,11.013243,11.075564,131.85837,-9.4182806
45.1,0.85676837,-0.093182407,51.932377,0,11.076097,135.2159,-0.0061989496,10.969076,11.076252,135.08493,-9.4163837
46.2,0.85566801,-0.096357763,52.281284,0,11.076097,138.51588,-0.0063984161,10.962449,11.076905,138.25009,-9.4146099
47.3,0.87019837,-0.098899841,52.616089,0,11.076097,141.81589,-0.0065964703,11.15319,11.076284,141.20616,-9.4126358
48.4,0.86148518,-0.10195053,52.946926,0,11.076097,145.11589,-0.0067532468,11.053744,11.076636,144.36342,-9.4106808
49.5,0.87288648,-0.10542111,53.31665,0,11.076097,148.41589,-0.0070079044,11.19061,11.07606,147.3956,-9.4087934
50.6,0.87739986,-0.10900097,53.657223,0,11.076097,151.7159,-0.0072318329,11.250415,11.075793,150.52214,-9.4069595
51.7,0.88192004,-0.11135072,53.975826,0,11.076097,155.01588,-0.0074147312,11.315535,11.076348,153.83302,-9.4051914
52.8,0.87291127,-0.11457442,54.305416,0,11.076097,158.31587,-0.0075999107,11.210427,11.076077,157.15797,-9.4034281
53.9,0.87464982,-0.11761931,54.624023,0,11.076097,161.61591,-0.007812636,11.224365,11.076418,160.57448,-9.4018745
55.0,0.88115156,-0.12070818,54.759449,0,11.076097,164.91589,-0.0080049727,11.314974,11.076408,164.07761,-9.4002323
56.1,0.87574708,-0.12387145,54.911064,0,11.076097,168.2159,-0.0082466146,11.244204,11.075598,167.54576,-9.3985243
57.2,0.88851327,-0.12665862,54.669495,0,11.076097,171.5159,-0.0084042167,11.422477,11.075788,171.20872,-9.3967962
58.3,0.88474214,-0.12979269,54.746574,0,11.076097,174.81589,-0.0085948445,11.360738,11.075943,174.60081,-9.3949957
59.4,0.89171708,-0.13292293,54.744961,0,11.076097,178.11589,-0.0088165523,11.449474,11.076674,177.9687,-9.3931131
60.5,0.89619219,-0.1358431,54.639877,0,11.076097,181.41589,-0.0090360017,11.523424,11.075909,181.3752,-9.3915539
61.6,0.8925702,-0.13969675,54.81398,0,11.076097,184.7159,-0.0092746122,11.485994,11.075538,184.67122,-9.3892775
62.7,0.89685297,-0.14367838,54.75769,0,11.076097,188.0159,-0.009508336,11.52465,11.075639,187.98164,-9.3876133
63.8,0.89478415,-0.14685307,54.799923,0,11.076097,191.31589,-0.0097348616,11.517034,11.075713,191.23987,-9.3858118
64.9,0.89071918,-0.14989264,54.931637,0,11.076097,194.61589,-0.0099622849,11.458117,11.07552,194.3719,-9.3836927
66.0,0.88610882,-0.15253288,54.998768,0,11.076097,197.91589,-0.01011722,11.394031,11.075583,197.59187,-9.3818388
67.1,0.88584864,-0.15546089,55.239254,0,11.076097,201.2159,-0.010292522,11.398958,11.075628,200.6971,-9.3800116
68.2,0.8843652,-0.1586428,55.535885,0,11.076097,204.5159,-0.010508546,11.366862,11.0756,203.82014,-9.3776121
69.3,0.88924021,-0.1616032,55.841343,0,11.076097,207.81589,-0.010741703,11.439297,11.07563,207.03676,-9.3763275
70.4,0.89529186,-0.16523123,56.095707,0,11.076097,211.11589,-0.01095635,11.520214,11.075727,210.26476,-9.3739805
71.5,0.89031672,-0.16881046,56.403046,0,11.076097,214.41589,-0.011171389,11.464601,11.075388,213.50266,-9.3724899
72.6,0.89702207,-0.17240368,56.425777,0,11.076097,217.71591,-0.011420676,11.550014,11.076185,216.91931,-9.3706131
73.7,0.89849013,-0.17556684,56.506622,0,11.076097,221.01591,-0.011653119,11.585943,11.076326,220.34459,-9.3686628
74.8,0.89816034,-0.1791919,56.674839,0,11.076097,224.3159,-0.011882269,11.577423,11.075875,223.79289,-9.3670511
75.9,0.89816415,-0.1827935,56.612801,0,11.076097,227.61592,-0.012088711,11.57083,11.076065,227.33209,-9.3652649
77.0,0.89524925,-0.1858907,56.573517,0,11.076097,230.91591,-0.012310734,11.54923,11.076348,230.73167,-9.3629913
78.1,0.90556192,-0.18903403,56.425785,0,11.076097,234.2159,-0.012545068,11.666808,11.075739,234.20543,-9.3614759
79.2,0.91039211,-0.19203484,56.425785,0,11.076097,237.51591,-0.01272087,11.746623,11.076046,237.48898,-9.3598299
80.3,0.9031347,-0.19529776,56.425785,0,11.076097,240.8159,-0.012905224,11.657493,11.075536,240.82503,-9.3581953
81.4,0.90881127,-0.19850062,56.527039,0,11.076097,244.11591,-0.013135951,11.711076,11.075758,244.00015,-9.3568754
82.5,0.90147722,-0.20198326,56.61515,0,11.076097,247.41591,-0.013401777,11.64147,11.076265,247.25119,-9.354475
83.6,0.91432345,-0.20509091,56.711422,0,11.076097,250.71591,-0.013585185,11.80113,11.075754,250.45949,-9.3527231
84.7,0.91469079,-0.20846778,56.811203,0,11.076097,254.0159,-0.013787128,11.807462,11.076257,253.58328,-9.3511219
85.8,0.90959752,-0.21149121,56.986084,0,11.076097,257.31616,-0.013991851,11.751401,11.076349,256.82916,-9.3492842
86.9,0.91927302,-0.21453097,57.259575,0,11.076097,260.61615,-0.014226543,11.877264,11.076159,259.96796,-9.3469572
88.0,0.91272944,-0.21857947,57.388432,0,11.076097,263.91589,-0.014462754,11.792573,11.075812,263.21207,-9.3449574
89.1,0.91525292,-0.22156794,57.535397,0,11.076097,267.21585,-0.014648302,11.825818,11.07543,266.47211,-9.3425283
90.2,0.91751754,-0.22538282,57.809978,0,11.076097,270.51587,-0.014909071,11.865103,11.07546,269.8526,-9.341136
91.3,0.91516531,-0.22826114,57.810051,0,11.076097,273.81589,-0.015118565,11.838905,11.076005,273.25021,-9.3395548
92.4,0.91709399,-0.23184212,57.810051,0,11.076097,277.11588,-0.01532966,11.861382,11.075925,276.66965,-9.3376265
93.5,0.91818792,-0.23535815,57.810143,0,11.076097,280.41586,-0.015546028,11.882156,11.07588,280.06073,-9.3357296
94.6,0.91632664,-0.23893926,58.07061,0,11.076097,283.71588,-0.015792424,11.863571,11.076085,283.41623,-9.33389
95.7,0.90742415,-0.24274753,57.810768,0,11.076097,287.0159,-0.016071618,11.764396,11.076933,286.86075,-9.3316545
96.8,0.91472149,-0.24664223,57.810066,0,11.076097,290.31592,-0.016304668,11.841396,11.076354,290.29276,-9.329874
97.9,0.91152859,-0.24990821,57.932571,0,11.076097,293.61591,-0.016511258,11.810506,11.074767,293.51025,-9.3283882
99.0,0.91247326,-0.25337949,57.895458,0,11.076097,296.91589,-0.016737223,11.82292,11.07672,296.85382,-9.3262796
100.1,0.91084182,-0.25705841,58.070686,0,11.076097,300.21588,-0.01701387,11.78966,11.074785,300.00021,-9.3241997
101.2,0.91464525,-0.26104876,58.073727,0,11.076097,303.5159,-0.01724082,11.855307,11.07561,303.33414,-9.3226776
102.3,0.90365237,-0.26447588,58.073727,0,11.076097,306.81589,-0.017478267,11.711219,11.075888,306.53894,-9.3207607
103.4,0.91099864,-0.26837337,58.337227,0,11.076097,310.11588,-0.017728031,11.810229,11.076951,309.72919,-9.3192434
104.5,0.91324276,-0.27177233,58.371841,0,11.076097,313.41586,-0.017980058,11.837066,11.076044,312.90707,-9.317461
105.6,0.91219556,-0.27602205,58.59008,0,11.076097,316.71588,-0.01821439,11.843963,11.076519,316.23309,-9.3159065
106.7,0.91514605,-0.27955177,58.781612,0,11.076097,320.01587,-0.018466448,11.8612,11.07597,319.41089,-9.3141041
107.8,0.92194229,-0.28413311,58.853752,0,11.076097,323.31589,-0.018752007,11.951066,11.075917,322.70761,-9.3118086
108.9,0.9258939,-0.28884381,59.106438,0,11.076097,326.61584,-0.019090515,12.0119,11.075986,325.95093,-9.3099375
110.0,0.92889172,-0.29218635,59.347561,0,11.076097,329.91562,-0.019273551,12.049293,11.075433,329.09503,-9.3079491
111.1,0.055854455,-0.30534104,58.082878,0,11.076097,329.99976,-0.020158105,0.72845417,11.076506,331.34033,-9.3076181
112.2,0.047524903,-0.30525863,56.992641,0,11.076097,329.99976,-0.020151451,0.62107331,11.07552,332.47214,-9.3076763
113.3,0.04034571,-0.30570018,56.129265,0,11.076097,329.99976,-0.020185972,0.51587564,11.07665,332.92929,-9.3076372
114.4,0.032044765,-0.30601677,55.535892,0,11.076097,329.99976,-0.02017509,0.40522954,11.077024,332.70416,-9.3078451
115.5,0.027242456,-0.30557707,55.239262,0,11.076097,329.99976,-0.02016221,0.35266683,11.076323,332.07849,-9.3081093
116.6,0.026490435,-0.30502036,55.307705,0,11.076097,329.99976,-0.020145316,0.34652951,11.07664,331.15805,-9.308033
117.7,0.022691343,-0.30487797,55.84325,0,11.076097,329.99976,-0.020130854,0.28837481,11.076423,330.17773,-9.3078232
118.8,0.025128722,-0.30497971,56.521721,0,11.076097,329.99976,-0.020107809,0.31695059,11.074958,329.06104,-9.3078108
119.9,0.029435413,-0.30527702,57.440437,0,11.076097,329.99976,-0.020134693,0.37201157,11.075637,328.10309,-9.3076973
121.0,0.035195392,-0.30543584,58.312012,0,11.076097,329.99976,-0.020182859,0.45896277,11.076102,327.45886,-9.3077478
122.1,0.039553501,-0.30574825,59.102913,0,11.076097,329.99976,-0.020178623,0.51424503,11.07642,327.15817,-9.307436
123.2,0.054457642,-0.30549616,59.600826,0,11.076097,329.99976,-0.020162055,0.69817805,11.075594,327.11642,-9.3075714
124.3,0.05766524,-0.30631074,60.084225,0,11.076097,329.99976,-0.020204663,0.74700731,11.07609,327.57205,-9.3072453
125.4,0.060785767,-0.30706644,60.084225,0,11.076097,329.99976,-0.020292219,0.78856593,11.075727,328.27652,-9.3068905
126.5,0.062094357,-0.30881757,59.997337,0,11.076097,329.99976,-0.02036212,0.813146,11.076197,329.11798,-9.3068094
127.6,0.061548699,-0.31010601,59.60487,0,11.076097,329.99976,-0.02045732,0.80149847,11.076365,330.01199,-9.3073053
128.7,0.066326506,-0.3113946,59.106899,0,11.076097,329.99976,-0.020542486,0.866355,11.076222,330.85544,-9.3072863
129.8,0.064045794,-0.3120026,58.508904,0,11.076097,329.99976,-0.020606795,0.84573185,11.074696,331.55182,-9.3071556
130.9,0.059898023,-0.31300256,57.817749,0,11.076097,329.99976,-0.020633101,0.77982002,11.076722,332.00266,-9.3073883
132.0,0.058357541,-0.31329477,57.260757,0,11.076097,329.99976,-0.020671107,0.76488304,11.07596,332.24188,-9.3073587
133.1,0.06416218,-0.31426436,56.711605,0,11.076097,329.99976,-0.02074497,0.83822471,11.076314,332.21182,-9.3072405
134.2,0.059330918,-0.31477824,56.213924,0,11.076097,329.99976,-0.020782465,0.79190195,11.075708,332.09192,-9.3065786
135.3,0.052675974,-0.31437233,55.847446,0,11.076097,329.99976,-0.020716783,0.68587661,11.075861,331.78513,-9.3071012
136.4,0.043384567,-0.31430584,55.84351,0,11.076097,329.99976,-0.020735335,0.57135552,11.077063,331.24991,-9.306325
137.5,0.038797915,-0.31428185,55.84351,0,11.076097,329.99976,-0.020762604,0.5076862,11.076192,330.73511,-9.3068571
138.6,0.028621843,-0.31468368,56.348354,0,11.076097,329.99976,-0.020765116,0.38815641,11.076166,329.92853,-9.306633
139.7,0.03183528,-0.31480294,56.711422,0,11.076097,329.99976,-0.020751707,0.41733488,11.075446,329.21976,-9.3064795
140.8,0.040517248,-0.31554016,57.415382,0,11.076097,329.99976,-0.020799723,0.54426259,11.076134,328.60764,-9.3066092
141.9,0.051114935,-0.31496516,58.051331,0,11.076097,329.99976,-0.020805093,0.67623061,11.076121,328.19818,-9.3066015
143.0,0.062179655,-0.31519863,58.499916,0,11.076097,329.99976,-0.020783393,0.82494295,11.075897,328.12234,-9.3067541
144.1,0.060333464,-0.31634012,58.59008,0,11.076097,329.99976,-0.020869793,0.79686135,11.07579,328.42606,-9.3067694
145.2,0.065783091,-0.31725785,58.590149,0,11.076097,329.99976,-0.020937148,0.85910189,11.075468,329.00534,-9.3067703
146.3,0.05723181,-0.31874776,58.590096,0,11.076097,329.99976,-0.021045676,0.76740915,11.075724,329.57208,-9.3068361
147.4,0.065401159,-0.31943139,58.33741,0,11.076097,329.99976,-0.021042489,0.84763408,11.076273,330.1571,-9.3068867
148.5,0.05729511,-0.32082728,57.810825,0,11.076097,329.99976,-0.021164678,0.74578959,11.075659,330.70407,-9.3066301
149.6,0.067257658,-0.32150519,57.535122,0,11.076097,329.99976,-0.021222057,0.86983323,11.075773,331.10498,-9.3066759
150.7,0.073007084,-0.32249153,56.911148,0,11.076097,329.99976,-0.021282941,0.9570415,11.075778,331.53024,-9.3067913
151.8,0.068201959,-0.3219882,56.425968,0,11.076097,329.99976,-0.02122673,0.89425164,11.075965,331.62671,-9.3066587
152.9,0.06230066,-0.3223207,56.129154,0,11.076097,329.99976,-0.021254349,0.81428766,11.075983,331.54099,-9.3064623
154.0,0.058382899,-0.32263601,55.84351,0,11.076097,329.99976,-0.021299073,0.76035452,11.07599,331.37979,-9.3061647
155.1,0.054401334,-0.050706454,55.688965,0,11.076097,329.99976,-0.0033279823,0.69941658,11.076262,331.06259,-9.306426
155.2817,0.21978706,0.042199012,26.265251,0,11.076099,1.5468354e-08,0.0031301884,2.811059,11.078931,331.13895,-9.3069534
155.2839,0.17959298,0.049063325,14.022869,0,11.076099,1.5449472e-23,0.0029226968,2.3256538,11.076898,331.15912,-9.3071241
155.2861,0.18478002,0.043873459,1.7804867,0,11.076099,1.5430615000000002e-38,0.0031340886,2.2675982,11.076026,331.17926,-9.3063383
155.2883,0.20055118,0.045278069,0.0,0,11.076099,0.0,0.002887178,2.5305574,11.077383,331.21664,-9.3064089
155.2905,0.20283991,0.043124884,0.0,0,11.076099,0.0,0.0031449988,2.6710751,11.076056,331.25696,-9.305747
155.2927,0.19137299,0.048145171,0.0,0,11.076099,0.0,0.0028825593,2.4129112,11.076082,331.29727,-9.3057861
155.2949,0.19099896,0.041803546,0.0,0,11.076099,0.0,0.0029793875,2.3972578,11.074564,331.33755,-9.3061295
155.2971,0.1942779,0.044969693,0.0,0,11.076099,0.0,0.0028679869,2.4671016,11.076861,331.35437,-9.3054295
155.2993,0.18894798,0.043104108,0.0,0,11.076099,0.0,0.0031188424,2.3274257,11.076523,331.32077,-9.3069801
155.3015,0.18846148,0.048360858,0.0,0,11.076099,0.0,0.0029313075,2.3892398,11.074,331.28717,-9.3057604
155.3037,0.19073622,0.040804408,0.0,0,11.076099,0.0,0.0029615308,2.4368422,11.076324,331.25357,-9.3063278
155.3059,0.18955731,0.044274349,0.0,0,11.076099,0.0,0.0028867819,2.4810283,11.076662,331.21997,-9.3066921
155.3081,0.21043299,0.043982297,0.0,0,11.076099,0.0,0.0032039538,2.67026,11.07601,331.1969,-9.3055696
155.3103,0.21544096,0.050823193,0.0,0,11.076099,0.0,0.0030388921,2.7460294,11.075501,331.17673,-9.3046694
155.3125,0.20873012,0.043421336,0.0,0,11.076099,0.0,0.0031168468,2.6440289,11.074052,331.15659,-9.3062344
155.3147,0.19780156,0.046118099,0.0,0,11.076099,0.0,0.0029511398,2.6294873,11.074786,331.13641,-9.3058853
155.3169,0.20349443,0.043554574,0.0,0,11.076099,0.0,0.0031596469,2.5408514,11.076986,331.11462,-9.3060799
155.3191,0.20357858,0.050137687,0.0,0,11.076099,0.0,0.0030992299,2.5453656,11.075106,331.08774,-9.3070059
155.3213,0.20273072,0.043690015,0.0,0,11.076099,0.0,0.0030517038,2.5651782,11.075763,331.06088,-9.3072386
155.3235,0.20656288,0.044668172,0.0,0,11.076099,0.0,0.0028851242,2.6386175,11.075315,331.03403,-9.3054867
155.3257,0.214834,0.042902458,0.0,0,11.076099,0.0,0.0031229702,2.7604306,11.076079,331.00714,-9.3056765
155.3279,0.22461464,0.051329229,0.0,0,11.076099,0.0,0.0031896818,2.8307965,11.077286,330.98981,-9.3050375
155.3301,0.21529423,0.044298623,0.0,0,11.076099,0.0,0.0031622222,2.853013,11.076695,330.97638,-9.3058901
155.3323,0.20038508,0.044666309,0.0,0,10.7659,0.0,0.0029082401,2.6627686,11.07507,330.96292,-9.3056068
155.3345,0.20829213,0.042237684,0.0,0,10.435007,0.0,0.0030555751,2.7197521,11.075893,330.94949,-9.3056288
155.3367,0.22966075,0.049974486,0.0,0,10.104115,0.0,0.0030994909,2.899344,11.021643,331.58936,-9.3069801
155.3389,0.19240144,0.044987865,0.0,0,9.7732229,0.0,0.0031237944,2.3933754,10.849587,335.3577,-9.3062954
155.3411,0.233683,0.046363246,0.0,0,9.4434061,0.0,0.0029700515,2.9611535,10.553467,339.12601,-9.3073902
155.3433,0.22426896,0.04413091,0.0,0,9.1214981,0.0,0.0031234967,2.8870025,10.16082,342.89435,-9.3076944
155.3455,6.7573051,0.42633149,0.0,0,8.7995939,0.0,0.02823774,82.965462,9.7456369,346.66269,-9.3004856
155.3477,8.2738743,0.76684481,0.0,0,8.491025,0.0,0.052434836,99.951485,9.3111124,350.85791,-9.29951
155.3499,8.6193733,1.1635346,0.0,0,8.1848736,0.0,0.080279529,101.01407,8.9015656,355.29703,-9.2990789
155.3521,8.6802349,1.525861,0.0,0,7.8872552,0.0,0.10691568,99.377579,8.5560417,359.73618,-9.2984018
155.3543,9.164443,1.8092895,0.0,0,7.5959754,0.0,0.12774637,102.47717,8.2466154,364.17529,-9.2983112
155.3565,9.2632046,2.1059692,0.0,0,7.3089876,0.0,0.1509611,101.53989,7.9378433,368.61444,-9.2982426
155.3587,9.4440622,2.3921218,0.0,0,7.0319633,0.0,0.17315619,101.08411,7.6513791,369.27942,-9.297657
155.3609,9.7909546,2.6475859,0.0,0,6.7554412,0.0,0.19400212,102.6915,7.3857236,369.10574,-9.2980528
155.3631,9.941987,2.9159386,0.0,0,6.4917617,0.0,0.21558341,102.03722,7.1171699,368.93204,-9.2978888
155.3653,10.230434,3.1747954,0.0,0,6.2282019,0.0,0.23756106,102.6172,6.8491974,368.75836,-9.2991495
155.3675,10.475062,3.4384565,0.0,0,5.9743834,0.0,0.2598469,102.81296,6.5791922,368.37436,-9.2979937
155.3697,10.676407,3.6953893,0.0,0,5.7237153,0.0,0.28252858,102.40636,6.3161197,367.45444,-9.2985134
155.3719,10.93716,3.9663601,0.0,0,5.4789333,0.0,0.30646914,102.51439,6.0550175,366.53455,-9.3001213
155.3741,11.199246,4.220623,0.0,0,5.2404532,0.0,0.33010253,102.41271,5.7890534,365.61462,-9.2994146
155.3763,11.470558,4.4802046,0.0,0,5.0044241,0.0,0.35427624,102.48177,5.5311871,364.69473,-9.2985191
155.3785,11.750899,4.730083,0.0,0,4.7776036,0.0,0.37851405,102.37386,5.2743654,364.51038,-9.2979174
155.3807,12.01252,4.9848037,0.0,0,4.5507836,0.0,0.40323913,102.16648,5.0292501,364.57718,-9.298707
155.3829,12.288145,5.2157097,0.0,0,4.3343177,0.0,0.42690915,102.04385,4.7919793,364.64398,-9.2986479
155.3851,12.562576,5.448184,0.0,0,4.1185412,0.0,0.45087034,101.8896,4.5569839,364.71078,-9.2992926
155.3873,12.837677,5.66818,0.0,0,3.9097853,0.0,0.47420326,101.75926,4.3338675,364.78735,-9.2977228
155.3895,13.135206,5.8916988,0.0,0,3.7045693,0.0,0.49832788,101.57043,4.1133304,364.90088,-9.298501
155.3917,13.463599,6.1001115,0.0,0,3.5032687,0.0,0.52153462,101.69629,3.8989959,365.0144,-9.2985859
155.3939,13.804569,6.3127999,0.0,0,3.3080406,0.0,0.54583895,101.75794,3.6923728,365.12793,-9.2992344
155.3961,14.166538,6.514956,0.0,0,3.1139498,0.0,0.56931841,101.96262,3.4853261,365.24146,-9.2990236
155.3983,14.544838,6.7187581,0.0,0,2.9282222,0.0,0.5935986,102.23734,3.2859843,365.17972,-9.2978325
155.4005,14.957161,6.909368,0.0,0,2.7424982,0.0,0.61693716,102.71431,3.0924287,365.03275,-9.2970018
155.4027,15.383508,7.1022515,0.0,0,2.5644472,0.0,0.64112937,103.08339,2.9006419,364.88577,-9.2969923
155.4049,15.808393,7.2844782,0.0,0,2.3877871,0.0,0.66428506,103.50146,2.7158384,364.7388,-9.2975178
155.4071,16.234245,7.4694843,0.0,0,2.2160761,0.0,0.68889415,103.82046,2.5340185,364.28094,-9.2978487
155.4093,16.733101,7.6425152,0.0,0,2.0480402,0.0,0.71174693,104.4712,2.3570993,361.8541,-9.2982016
155.4115,17.245409,7.8186789,0.0,0,1.8824683,0.0,0.73638165,105.09156,2.178123,359.42725,-9.2968035
155.4137,17.815338,7.9903178,0.0,0,1.7226163,0.0,0.76017421,106.01674,2.0140371,357.00043,-9.2958269
155.4159,18.394182,8.1634035,0.0,0,1.5630547,0.0,0.78559548,106.72388,1.8469995,354.57358,-9.2957535
155.4181,19.039656,8.3265409,0.0,0,1.4109212,0.0,0.809057,107.86868,1.6771916,351.34903,-9.2968731
155.4203,19.72102,8.4867067,0.0,0,1.2588573,0.0,0.834113,108.99071,1.5142034,347.59271,-9.2967176
155.4225,20.414082,8.6425505,0.0,0,1.1124123,0.0,0.85751671,110.23596,1.3560506,343.83636,-9.2943468
155.4247,21.156885,8.8003111,0.0,0,0.96778423,0.0,0.88350707,111.26159,1.1932584,340.08005,-9.2944212
155.4269,21.884306,8.9485121,0.0,0,0.82657719,0.0,0.90660107,112.48287,1.0396973,336.45905,-9.2936888
155.4291,22.682194,9.0913076,0.0,0,0.68903327,0.0,0.93173933,113.67026,0.8946833,334.82956,-9.29389
155.4313,23.482883,9.2321205,0.0,0,0.55288589,0.0,0.9548735,114.98716,0.75626981,333.20007,-9.2940321
155.4335,24.32247,9.3653612,0.0,0,0.42198581,0.0,0.97930324,116.20625,0.61333323,331.57056,-9.2931604
155.4357,22.527138,9.448451,0.0,0,0.29108578,0.0,0.99296951,106.44563,0.49399868,329.94107,-9.2941322
155.4379,21.283888,9.4609356,0.0,0,0.16620806,0.0,0.99661404,100.05309,0.45765057,330.21378,-9.2971163
155.4401,20.35313,9.4640427,0.0,0,0.041732047,0.0,0.99609894,95.737221,0.42918691,332.19189,-9.2984896
155.4423,19.876419,9.4772911,0.0,0,-0.080696523,0.0,0.99994344,93.110878,0.4000901,334.16998,-9.3000402
155.4445,19.812824,9.4837427,0.0,0,-0.20209251,0.0,0.99950612,92.815834,0.36113051,336.14807,-9.2980413
155.4467,20.014952,9.4832649,0.0,0,-0.32348853,0.0,1.0009488,93.668015,0.30523875,338.12619,-9.2966347
155.4489,20.144688,9.4886541,0.0,0,-0.44488451,0.0,1.000284,94.319794,0.24433589,340.95889,-9.296855
155.4511,20.106663,9.4944687,0.0,0,-0.56628054,0.0,1.0031685,93.908363,0.18264349,343.79941,-9.2973127
155.4533,20.002583,9.5006752,0.0,0,-0.68767649,0.0,1.0024596,93.46225,0.12761371,346.63995,-9.2997952
155.4555,19.814533,9.5023775,0.0,0,-0.80907249,0.0,1.004496,92.410942,0.083611876,349.48047,-9.2981405
155.4577,19.560667,9.5099325,0.0,0,-0.9304685,0.0,1.0040747,91.226814,0.048579682,351.73489,-9.2974939
155.4599,19.211882,9.5100956,0.0,0,-1.0518646,0.0,1.0062106,89.422554,0.023323847,353.28595,-9.2989616
155.4621,18.763435,9.5161028,0.0,0,-0.88153553,330.0,1.0053843,87.491455,0.01572833,354.83704,-9.2999096
155.4643,18.269152,9.5128794,0.0,0,-0.461256,330.0,1.0065398,85.036003,0.017539805,356.38812,-9.3013887
155.4665,17.818438,9.5142632,0.0,0,-0.040977143,330.0,1.0050091,83.044472,0.020646259,357.93921,-9.3013792
155.4687,17.433802,9.5147066,0.0,0,0.37930197,330.0,1.0070924,81.108299,0.022922341,359.16409,-9.3005857
155.4709,17.132521,9.520154,0.0,0,0.79958147,330.0,1.005972,79.81517,0.023766756,360.35989,-9.3010435
155.4731,16.870232,9.5128927,0.0,0,1.2198607,330.0,1.0067328,78.508781,0.025132675,361.55573,-9.3011999
155.4753,16.301085,9.515007,0.0,0,1.6401393,330.0,1.0050638,76.04882,0.039176483,362.75156,-9.3021536
155.4775,14.581646,9.5092478,0.0,0,2.0604191,330.0,1.0062363,68.061913,0.10721303,363.99771,-9.3035173
155.4797,11.88555,9.5061159,0.0,0,2.4806983,330.0,1.0032707,55.786453,0.23194785,365.32541,-9.3032255
155.4819,8.1190948,9.4844379,0.0,0,2.9009774,330.0,1.0014849,38.322647,0.42213428,366.65308,-9.3074789
155.4841,-0.16439706,9.3958054,0.0,0,3.3212564,330.0,0.98391956,-1.1028857,0.70922196,367.98077,-9.3161125
155.4863,0.15301338,9.2785454,0.0,0,3.7415357,330.0,0.96525216,0.56869316,1.3396562,369.30847,-9.3162689
155.4885,-0.095159926,9.1966505,0.0,0,4.1618147,330.0,0.94830513,-0.27762634,2.093421,370.31937,-9.3147936
155.4907,-0.20996623,9.1278162,0.0,0,4.5820942,330.0,0.93927521,-1.1985278,2.8035257,371.27237,-9.313591
155.4929,0.12916671,9.1029148,0.0,0,5.0023732,330.0,0.93293315,0.52315468,3.3780777,372.22537,-9.311017
155.4951,0.089806274,9.1087379,0.0,0,5.4226522,330.0,0.93555933,0.52493483,3.8087647,373.17834,-9.3112841
155.4973,-0.10621639,9.1467724,0.0,0,5.8429322,330.0,0.93966788,-0.56081498,4.2014728,373.97479,-9.3111553
155.4995,-0.048616502,9.1902237,0.0,0,6.2632108,330.0,0.94940591,-0.28386968,4.5772004,374.4213,-9.3110237
155.5017,-0.034427822,9.2621918,0.0,0,6.6834898,330.0,0.95965683,-0.20289259,4.9635715,374.86783,-9.3101482
155.5039,-0.014013538,9.3458157,0.0,0,7.1037698,330.0,0.97653049,-0.058046941,5.3601751,375.31433,-9.3096762
155.5061,-0.013961779,9.4602222,0.0,0,7.5240488,330.0,0.99434894,-0.021699412,5.7765961,375.76083,-9.3096161
155.5083,-0.160302,9.4655905,0.0,0,7.9443283,330.0,0.99848926,-0.77692103,6.2112947,376.31033,-9.3096552
155.5105,-0.12130616,9.4621744,0.0,0,8.3646069,330.0,0.99602705,-0.56492376,6.656311,376.89014,-9.3083448
155.5127,0.093985453,9.4683352,0.0,0,8.7848854,330.0,0.9987334,0.3166714,7.1038718,377.46994,-9.3085318
155.5149,-0.0091154044,9.4760408,0.0,0,9.2051649,330.0,0.99722749,0.12811132,7.5473218,378.04974,-9.3082657
155.5171,-0.15117431,9.4680624,0.0,0,9.6254444,330.0,0.99840814,-0.64027792,7.9706807,378.63895,-9.3070049
155.5193,-0.18837911,9.4753771,0.0,0,10.045724,330.0,0.99781919,-0.94252992,8.4058332,379.25854,-9.3083429
155.5215,-0.020043517,9.4705372,0.0,0,10.466002,330.0,0.99920446,-0.12365419,8.8397732,379.87814,-9.3075132
155.5237,-0.02407068,9.4796944,0.0,0,10.886282,330.0,0.99830824,-0.064770907,9.2752972,380.49774,-9.3068409
155.5259,-0.079542153,9.4714069,0.0,0,11.306561,330.0,0.99917668,-0.3773112,9.7051716,381.11734,-9.3056984
155.5281,-0.11460341,9.4785385,0.0,0,11.72684,330.0,0.99853331,-0.55028039,10.136728,381.27524,-9.3052206
155.5303,0.048762523,9.4669237,0.0,0,12.14712,330.0,0.99848336,0.16599594,10.573352,381.23523,-9.306118
155.5325,0.04311461,9.4795666,0.0,0,12.567399,330.0,0.99840206,0.21261045,11.012709,381.19525,-9.3055134
155.5347,-0.073890589,9.4685373,0.0,0,12.987678,330.0,0.998595,-0.28220871,11.441106,381.15527,-9.3061571
155.5369,-0.1279337,9.473958,0.0,0,13.407957,330.0,0.99780953,-0.55297256,11.861557,381.05969,-9.3066483
155.5391,-0.097174622,9.4688606,0.0,0,13.828236,330.0,0.9988724,-0.46229431,12.279086,380.68002,-9.3054943
155.5413,0.016234189,9.4782972,0.0,0,14.248516,330.0,0.99822176,0.016882887,12.700843,380.30032,-9.3067999
155.5435,0.020440442,9.4649515,0.0,0,14.668795,330.0,0.99784416,0.16358157,13.132771,379.92065,-9.3054724
155.5457,-0.10853986,9.4727573,0.0,0,15.089074,330.0,0.99760544,-0.51841688,13.567682,379.54095,-9.3052988
155.5479,-0.069725089,9.4646368,0.0,0,15.509354,330.0,0.99805558,-0.37249854,14.010408,379.5123,-9.3035192
155.5501,-0.0069754655,9.478817,0.0,0,15.929632,330.0,0.99839646,-0.11685345,14.440736,379.69226,-9.3039837
155.5523,0.019926585,9.4684896,0.0,0,16.349911,330.0,0.99846286,0.067846023,14.874516,379.87219,-9.3046093
155.5545,-0.12521535,9.4711542,0.0,0,16.770191,330.0,0.99731368,-0.47129273,15.288891,380.05212,-9.3038836
155.5567,-0.17938086,9.4681454,0.0,0,17.19047,330.0,0.99851489,-0.87985545,15.705311,380.2478,-9.3052416
155.5589,-0.070416018,9.4777651,0.0,0,17.61075,330.0,0.99838388,-0.37611198,16.1161,380.60089,-9.3046494
155.5611,0.024555635,9.4687252,0.0,0,17.999401,330.0,0.99833322,0.12754549,16.537262,380.95398,-9.3041306
155.5633,-0.094822556,9.4734087,0.0,0,18.0,330.0,0.99773288,-0.39847103,16.959877,381.30707,-9.3054047
155.5655,-0.094659641,9.4673843,0.0,0,18.0,330.0,0.99794829,-0.45852956,17.362404,381.66016,-9.3054457
155.5677,0.010235656,9.4789314,0.0,0,18.0,330.0,0.99874574,0.0097567355,17.730362,381.70288,-9.3053808
155.5699,-0.014155294,9.4674187,0.0,0,18.0,330.0,0.99797273,-0.026093299,18.053019,381.49628,-9.3061295
155.5721,-0.064411268,9.4765186,0.0,0,18.0,330.0,0.99859285,-0.24568078,18.307697,381.28967,-9.3085022
155.5743,-0.065780371,9.476263,0.0,0,18.0,330.0,0.99943298,-0.33097342,18.477705,381.0831,-9.3114729
155.5765,-0.06705074,9.48979,0.0,0,18.0,330.0,1.0007646,-0.33166796,18.53507,380.8714,-9.3171673
155.5787,-0.090783432,9.4880114,0.0,0,18.0,330.0,1.0015409,-0.47152945,18.488028,380.38504,-9.3230619
155.5809,-0.074508108,9.4986544,0.0,0,18.0,330.0,1.0026554,-0.40676785,18.371302,379.89865,-9.3321152
155.5831,-0.03376653,9.5029116,0.0,0,18.0,330.0,1.0041906,-0.23346853,18.239967,379.41229,-9.344079
155.5853,0.083350241,9.5267286,0.0,0,18.0,330.0,1.0074129,0.30837226,18.129335,378.9259,-9.3567219
155.5875,0.077519447,9.5320778,0.0,0,18.0,330.0,1.0094078,0.40440124,18.061956,378.80231,-9.3732529
155.5897,-0.023646023,9.5570011,0.0,0,18.0,330.0,1.0133806,-0.019303061,18.034485,379.06882,-9.3904877
155.5919,-0.11488004,9.5724096,0.0,0,18.0,330.0,1.0166667,-0.49400529,18.030798,379.33533,-9.4083853
155.5941,-0.14148359,9.5992699,0.0,0,18.0,330.0,1.0208613,-0.60999262,18.044197,379.60184,-9.4270658
155.5963,-0.16769207,9.6072283,0.0,0,18.0,330.0,1.0232471,-0.75038868,18.068045,379.86835,-9.4463148
155.5985,-0.11172605,9.6286469,0.0,0,18.0,330.0,1.0266868,-0.57020867,18.09214,380.46844,-9.4652233
155.6007,-0.021871576,9.6377144,0.0,0,18.0,330.0,1.0287818,-0.1912951,18.113855,381.0878,-9.481966
155.6029,0.041544203,9.6621418,0.0,0,18.0,330.0,1.0328274,0.15488018,18.131374,381.70715,-9.4977608
155.6051,0.055301804,9.6679764,0.0,0,18.0,330.0,1.0344954,0.24910694,18.14706,382.32651,-9.512558
155.6073,0.026655601,9.6924324,0.0,0,18.0,330.0,1.0388644,0.18228528,18.149632,382.72516,-9.5280552
155.6095,-0.061659146,9.7066364,0.0,0,18.0,330.0,1.0414619,-0.22435807,18.149885,382.80496,-9.5431051
155.6117,-0.14919512,9.7287722,0.0,0,18.0,330.0,1.0456774,-0.6034649,18.151424,382.88474,-9.5596619
155.6139,-0.13773648,9.734973,0.0,0,18.0,330.0,1.0468388,-0.65766323,18.144655,382.96454,-9.5747776
155.6161,-0.10934896,9.752903,0.0,0,18.0,330.0,1.0504068,-0.50034171,18.142216,383.04434,-9.5900393
155.6183,-0.060635921,9.7661896,0.0,0,18.0,330.0,1.0528269,-0.29638314,18.138102,383.08353,-9.6072588
155.6205,0.01604983,9.788435,0.0,0,18.0,330.0,1.057279,0.024501573,18.134336,383.11676,-9.6223345
155.6227,0.074844278,9.79636,0.0,0,18.0,330.0,1.0583959,0.30393475,18.132015,383.15002,-9.6395359
155.6249,0.05922826,9.8153305,0.0,0,18.0,330.0,1.0624999,0.28129676,18.129089,383.18326,-9.6542845
155.6271,-0.036832612,9.8299189,0.0,0,18.0,330.0,1.0647377,-0.080677174,18.130121,383.26572,-9.6691504
155.6293,-0.12687002,9.8520164,0.0,0,18.0,330.0,1.0696824,-0.50324875,18.12546,383.44522,-9.6851835
155.6315,-0.15084249,9.8657923,0.0,0,18.0,330.0,1.0715005,-0.68310118,18.122467,383.62476,-9.7029829
155.6337,-0.13183679,9.8810234,0.0,0,18.0,330.0,1.0754499,-0.57661217,18.119902,383.80429,-9.7198906
155.6359,-0.07901644,9.8933039,0.0,0,18.0,330.0,1.0770996,-0.37252793,18.116768,383.9838,-9.7347975
155.6381,0.0065131546,9.9162312,0.0,0,18.0,330.0,1.0824813,-0.040732216,18.11462,384.12079,-9.7496357
155.6403,0.058882318,9.9287577,0.0,0,18.0,330.0,1.0836438,0.2173662,18.112204,384.24713,-9.7673397
155.6425,0.070044138,9.9415054,0.0,0,18.0,330.0,1.0874047,0.31565771,18.113676,384.37347,-9.7826853
155.6447,0.0078894868,9.9552917,0.0,0,18.0,330.0,1.0890225,0.072633006,18.113338,384.49982,-9.7987738
155.6469,-0.095650136,9.9759264,0.0,0,18.0,330.0,1.0943617,-0.35383531,18.114286,384.56479,-9.81495
155.6491,-0.16006427,9.9937611,0.0,0,18.0,330.0,1.0964464,-0.65131068,18.111105,384.4584,-9.8315296
155.6513,-0.14992937,10.00687,0.0,0,18.0,330.0,1.1005349,-0.67547435,18.110043,384.35202,-9.8453751
155.6535,-0.09068311,10.020376,0.0,0,18.0,330.0,1.1018832,-0.42873642,18.108776,384.24564,-9.8626518
155.6557,-0.025170766,10.038383,0.0,0,18.0,330.0,1.1070451,-0.13785173,18.103905,384.13925,-9.8781319
155.6579,0.046175733,10.052264,0.0,0,18.0,330.0,1.1081079,0.13742603,18.103907,384.11023,-9.8945637
155.6601,0.068055518,10.067031,0.0,0,18.0,330.0,1.1130272,0.31118277,18.106686,384.11023,-9.9112396
155.6623,0.036751498,10.080936,0.0,0,18.0,330.0,1.1140976,0.22181359,18.103012,384.11023,-9.9274931
155.6645,-0.065804325,10.10225,0.0,0,18.0,330.0,1.1201622,-0.24065301,18.109835,384.11023,-9.9434099
155.6667,-0.14971191,10.123176,0.0,0,18.0,330.0,1.1223885,-0.55856454,18.104956,384.1369,-9.9592562
155.6689,-0.17005949,10.134658,0.0,0,18.0,330.0,1.1267853,-0.69854474,18.10376,384.27652,-9.9745464
155.6711,-0.12230563,10.150434,0.0,0,18.0,330.0,1.1281157,-0.55390304,18.10146,384.41614,-9.989398
155.6733,-0.028128395,10.164814,0.0,0,18.0,330.0,1.1331894,-0.19385397,18.096754,384.55579,-10.006065
155.6755,0.032811064,10.183118,0.0,0,18.0,330.0,1.1345563,0.084574372,18.095087,384.6954,-10.023047
155.6777,0.058312055,10.194469,0.0,0,18.0,330.0,1.1391149,0.21868867,18.098459,384.72623,-10.03902
155.6799,0.051535655,10.213783,0.0,0,18.0,330.0,1.1410581,0.21292421,18.096004,384.69965,-10.055125
155.6821,-0.003115583,10.2308,0.0,0,18.0,330.0,1.1471093,0.022250367,18.093285,384.67303,-10.070697
155.6843,-0.11355672,10.251094,0.0,0,18.0,330.0,1.1489093,-0.37856275,18.092941,384.64645,-10.086262
155.6865,-0.17067686,10.261023,0.0,0,18.0,330.0,1.1531638,-0.68792129,18.094757,384.63477,-10.102476
155.6887,-0.13694401,10.278564,0.0,0,18.0,330.0,1.1548203,-0.59817207,18.090637,384.73453,-10.119273
155.6909,-0.066496871,10.291327,0.0,0,18.0,330.0,1.1600716,-0.3298094,18.08848,384.83426,-10.135633
155.6931,0.019051675,10.310858,0.0,0,18.0,330.0,1.1612748,0.030373499,18.091179,384.93399,-10.149669
155.6953,0.067691699,10.318528,0.0,0,18.0,330.0,1.165659,0.25943145,18.090694,385.03372,-10.165571
155.6975,0.062787302,10.339652,0.0,0,18.0,330.0,1.1676965,0.26163432,18.084742,385.1683,-10.181746
155.6997,0.01323036,10.353537,0.0,0,18.0,330.0,1.1733179,0.090871677,18.083937,385.32788,-10.199551
155.7019,-0.079262957,10.37633,0.0,0,18.0,330.0,1.1752309,-0.24691828,18.090088,385.48746,-10.213386
155.7041,-0.15899746,10.385374,0.0,0,18.0,330.0,1.1801409,-0.57331181,18.08836,385.64703,-10.229497
155.7063,-0.16297171,10.406093,0.0,0,18.0,330.0,1.1818784,-0.66585791,18.084171,385.79785,-10.245126
155.7085,-0.087036252,10.417488,0.0,0,18.0,330.0,1.1873293,-0.41372117,18.082874,385.76462,-10.261526
155.7107,0.0078017409,10.439849,0.0,0,18.0,330.0,1.1888862,-0.024903409,18.083635,385.73138,-10.279135
155.7129,0.059430365,10.448061,0.0,0,18.0,330.0,1.193949,0.20685391,18.081879,385.69812,-10.294673
155.7151,0.062785834,10.469602,0.0,0,18.0,330.0,1.1958561,0.2187686,18.081396,385.66489,-10.310603
155.7173,0.023840105,10.479557,0.0,0,18.0,330.0,1.2009438,0.13856134,18.082918,385.58087,-10.324626
155.7195,-0.048799939,10.505023,0.0,0,18.0,330.0,1.2032272,-0.11573626,18.083117,385.44788,-10.34045
155.7217,-0.13383584,10.513214,0.0,0,18.0,330.0,1.2082285,-0.46218932,18.07939,385.31488,-10.358171
155.7239,-0.18132304,10.5355,0.0,0,18.0,330.0,1.2106175,-0.69815445,18.080515,385.18192,-10.374789
155.7261,-0.1253403,10.543403,0.0,0,18.0,330.0,1.2152883,-0.50292593,18.080763,385.04892,-10.389854
155.7283,-0.017194903,10.569011,0.0,0,18.0,330.0,1.2176383,-0.12839682,18.079119,385.21344,-10.405257
155.7305,0.05333915,10.573597,0.0,0,18.0,330.0,1.221923,0.13885905,18.078873,385.38632,-10.421206
155.7327,0.066779144,10.59409,0.0,0,18.0,330.0,1.223714,0.22503878,18.082071,385.5592,-10.437392
155.7349,0.03564186,10.604618,0.0,0,18.0,330.0,1.2290775,0.16782215,18.079596,385.73209,-10.453343
155.7371,-0.031356886,10.633832,0.0,0,18.0,330.0,1.2322664,-0.052825224,18.079702,385.88467,-10.469307
155.7393,-0.11642101,10.641605,0.0,0,18.0,330.0,1.2371945,-0.39525735,18.07711,386.01099,-10.484895
155.7415,-0.16545349,10.663898,0.0,0,18.0,330.0,1.2397423,-0.57074475,18.076609,386.13733,-10.500752
155.7437,-0.15989375,10.672469,0.0,0,18.0,330.0,1.2442985,-0.59366506,18.078051,386.26367,-10.518518
155.7459,-0.069776997,10.697215,0.0,0,18.0,330.0,1.2470932,-0.31468186,18.0762,386.39001,-10.535501
155.7481,0.043898772,10.702368,0.0,0,18.0,330.0,1.2512276,0.080589041,18.074577,386.45053,-10.551759
155.7503,0.071873054,10.72254,0.0,0,18.0,330.0,1.2534696,0.26033941,18.074242,386.50372,-10.565778
155.7525,0.0456421,10.732245,0.0,0,18.0,330.0,1.2583308,0.18198115,18.07337,386.55692,-10.581916
155.7547,0.0034602263,10.760979,0.0,0,18.0,330.0,1.2618381,0.044951335,18.073568,386.61011,-10.599225
155.7569,-0.084380448,10.76427,0.0,0,18.0,330.0,1.2658185,-0.2217194,18.075386,386.68021,-10.614418
155.7591,-0.15223354,10.788068,0.0,0,18.0,330.0,1.2690777,-0.48669288,18.073811,386.77997,-10.630225
155.7613,-0.1688647,10.798456,0.0,0,18.0,330.0,1.2741044,-0.62749761,18.071814,386.8797,-10.645253
155.7635,-0.094049655,10.82474,0.0,0,18.0,330.0,1.2773688,-0.39341527,18.068481,386.97943,-10.66022
155.7657,-0.0021084566,10.827848,0.0,0,18.0,330.0,1.2806563,-0.055434477,18.068388,387.07916,-10.677024
155.7679,0.065848604,10.849217,0.0,0,18.0,330.0,1.2835603,0.17294554,18.070906,387.0524,-10.692784
155.7701,0.080086701,10.859379,0.0,0,18.0,330.0,1.288429,0.26119363,18.068068,386.99921,-10.70956
155.7723,0.016381908,10.886126,0.0,0,18.0,330.0,1.2923243,0.077334754,18.060995,386.94601,-10.72507
155.7745,-0.062957488,10.894589,0.0,0,18.0,330.0,1.2966845,-0.1611573,18.064089,386.89282,-10.740021
155.7767,-0.13053492,10.917311,0.0,0,18.0,330.0,1.3002084,-0.40520012,18.066141,386.88025,-10.757274
155.7789,-0.16129377,10.926476,0.0,0,18.0,330.0,1.3047115,-0.54067779,18.061455,386.96667,-10.77303
155.7811,-0.13244124,10.952567,0.0,0,18.0,330.0,1.3085985,-0.49062023,18.063107,387.05313,-10.788651
155.7833,-0.032785099,10.958521,0.0,0,18.0,330.0,1.3122876,-0.19364426,18.059446,387.13956,-10.804491
155.7855,0.053301502,10.976966,0.0,0,18.0,330.0,1.3152635,0.17068627,18.061125,387.22601,-10.820738
155.7877,0.087544024,10.984988,0.0,0,18.0,330.0,1.3188102,0.27314225,18.058241,387.24722,-10.836115
155.7899,0.048684753,11.012297,0.0,0,18.0,330.0,1.3235009,0.19282536,18.062164,387.24722,-10.852584
155.7921,-0.043360498,11.021889,0.0,0,18.0,330.0,1.3278694,-0.10354453,18.062038,387.24722,-10.869005
155.7943,-0.11109602,11.044473,0.0,0,18.0,330.0,1.3320398,-0.31607214,18.060272,387.24722,-10.882634
155.7965,-0.14976364,11.053416,0.0,0,18.0,330.0,1.3357192,-0.50369537,18.062012,387.24722,-10.899862
155.7987,-0.15177959,11.078924,0.0,0,18.0,330.0,1.3406556,-0.52991247,18.061634,387.24722,-10.91734
155.8009,-0.071238123,11.086933,0.0,0,18.0,330.0,1.3442917,-0.31119454,18.06167,387.24722,-10.933744
155.8031,0.02938481,11.104102,0.0,0,18.0,330.0,1.3476269,0.047627091,18.064959,387.24722,-10.950802
155.8053,0.077964433,11.113419,0.0,0,18.0,330.0,1.3509699,0.24667691,18.058884,387.24722,-10.965006
155.8075,0.058149956,11.138443,0.0,0,18.0,330.0,1.3559673,0.21807522,18.056087,387.28348,-10.97935
155.8097,-0.00090994168,11.146174,0.0,0,18.0,330.0,1.3593931,0.042212851,18.059673,387.33667,-10.994932
155.8119,-0.098282434,11.169165,0.0,0,18.0,330.0,1.3646171,-0.27456874,18.056894,387.38986,-11.012435
155.8141,-0.15294552,11.179035,0.0,0,18.0,330.0,1.3674884,-0.47863567,18.056145,387.44308,-11.028329
155.8163,-0.15750192,11.206119,0.0,0,18.0,330.0,1.3741415,-0.51556003,18.05858,387.49142,-11.044592
155.8185,-0.097686365,11.212339,0.0,0,18.0,330.0,1.3764396,-0.36347342,18.058786,387.51138,-11.061038
155.8207,-0.0063101873,11.231002,0.0,0,18.0,330.0,1.381137,-0.064508669,18.056667,387.53131,-11.076097
155.8229,0.065473855,11.241154,0.0,0,18.0,330.0,1.383852,0.17266187,18.05781,387.55127,-11.092792
155.8251,0.068652891,11.267885,0.0,0,18.0,330.0,1.3907374,0.24052466,18.056713,387.57123,-11.109084
155.8273,0.022907417,11.275934,0.0,0,18.0,330.0,1.3933212,0.10542683,18.053722,387.66812,-11.124194
155.8295,-0.062213264,11.295904,0.0,0,18.0,330.0,1.39846,-0.13837947,18.055449,387.81439,-11.140885
155.8317,-0.15222244,11.308649,0.0,0,18.0,330.0,1.4019148,-0.44790131,18.05311,387.96069,-11.156327
155.8339,-0.16346487,11.333534,0.0,0,18.0,330.0,1.4087501,-0.52490336,18.052107,388.10696,-11.172303
155.8361,-0.11851199,11.342247,0.0,0,18.0,330.0,1.4108241,-0.40203977,18.052765,388.24744,-11.189805
155.8383,-0.048696857,11.357695,0.0,0,18.0,330.0,1.4156483,-0.19923912,18.051657,388.31393,-11.204453
155.8405,0.040655956,11.368715,0.0,0,18.0,330.0,1.4182975,0.087675571,18.054846,388.38043,-11.221487
155.8427,0.086559653,11.391434,0.0,0,18.0,330.0,1.4251672,0.28409067,18.048651,388.44693,-11.236382
155.8449,0.060027234,11.403175,0.0,0,18.0,330.0,1.4275464,0.20290868,18.049337,388.51343,-11.251456
155.8471,-0.036562305,11.422871,0.0,0,18.0,330.0,1.4337496,-0.070687018,18.048819,388.56207,-11.267014
155.8493,-0.13333686,11.435901,0.0,0,18.0,330.0,1.4363536,-0.3464193,18.050425,388.59534,-11.284534
155.8515,-0.16720533,11.457394,0.0,0,18.0,330.0,1.4437747,-0.48485804,18.049944,388.62857,-11.300133
155.8537,-0.13354388,11.47075,0.0,0,18.0,330.0,1.4460933,-0.42047578,18.04586,388.66183,-11.314656
155.8559,-0.0690016,11.482547,0.0,0,18.0,330.0,1.4508141,-0.25117227,18.048498,388.69507,-11.33076
155.8581,0.013671946,11.494594,0.0,0,18.0,330.0,1.4530305,-0.0054135709,18.050303,388.66846,-11.349032
155.8603,0.068574838,11.515706,0.0,0,18.0,330.0,1.4609118,0.20077999,18.05135,388.64188,-11.364439
156.6608,-0.039836187,11.630842,0.0,0,18.0,4.1213597e-09,1.4932328,-0.11100349,18.002052,378.82266,-11.482373
157.7608,-0.041281316,11.629033,0.0,0,18.0,4.116316e-24,1.4929821,-0.11842369,17.999773,368.68933,-11.482041
158.8608,-0.042674299,11.628947,0.0,0,18.0,4.111278e-39,1.492775,-0.12102903,17.999968,358.3725,-11.482559
159.9608,-0.043830339,11.62905,0.0,0,18.0,1.4012985e-45,1.4928699,-0.12429851,17.999556,349.17892,-11.482507
161.0608,-0.043702312,11.629171,0.0,0,18.0,1.4012985e-45,1.4927931,-0.12506658,17.999628,339.68515,-11.482626
162.1608,-0.043797638,11.628239,0.0,0,18.0,1.4012985e-45,1.4927068,-0.12338101,17.999731,330.17752,-11.48249
163.2608,-0.044862989,11.627695,0.0,0,18.0,1.4012985e-45,1.4924864,-0.12898903,17.999691,321.63907,-11.482011
164.3608,-0.044270217,11.628613,0.0,0,18.0,1.4012985e-45,1.4926063,-0.124663,17.999577,313.02173,-11.482217
165.4608,-0.044122119,11.62853,0.0,0,18.0,1.4012985e-45,1.492756,-0.12384417,18.000307,305.10593,-11.482538
166.5608,-0.044140346,11.628312,0.0,0,18.0,1.4012985e-45,1.4926385,-0.12496616,17.998983,296.25192,-11.482368
167.6608,-0.045113981,11.628123,0.0,0,18.0,1.4012985e-45,1.4926996,-0.12898842,17.999813,289.13333,-11.482448
168.7608,-0.043225031,11.628155,0.0,0,18.0,1.4012985e-45,1.4924426,-0.124835,18.000292,281.68091,-11.482244
169.8608,-0.045223869,11.628566,0.0,0,18.0,1.4012985e-45,1.4928734,-0.12712276,18.000715,274.55252,-11.482402
170.9608,-0.045699909,11.628738,0.0,0,18.0,1.4012985e-45,1.4927145,-0.13045536,18.000618,266.7912,-11.482277
172.0608,-0.045173395,11.629126,0.0,0,18.0,1.4012985e-45,1.492856,-0.13110106,17.999674,260.3656,-11.482031
173.1608,-0.044886556,11.628779,0.0,0,18.0,1.4012985e-45,1.4927292,-0.12711792,18.000713,253.22491,-11.482315
174.2608,-0.04371962,11.628669,0.0,0,18.0,1.4012985e-45,1.492817,-0.12440983,17.999998,247.03407,-11.482403
175.3608,-0.044420134,11.629043,0.0,0,18.0,1.4012985e-45,1.4929276,-0.12777093,18.000025,240.33417,-11.483076
176.4608,-0.044804193,11.629498,0.0,0,18.0,1.4012985e-45,1.4928273,-0.12832411,18.000237,234.4662,-11.483065
177.5608,-0.043984082,11.629052,0.0,0,18.0,1.4012985e-45,1.4929557,-0.12905397,18.000128,227.91426,-11.482752
178.6608,-0.045037452,11.629932,0.0,0,18.0,1.4012985e-45,1.4930307,-0.12831871,17.999756,222.2574,-11.482773
179.7608,-0.043999739,11.629229,0.0,0,18.0,1.4012985e-45,1.4928967,-0.12450741,18.000221,216.72676,-11.482683
180.8608,-0.042397734,11.629568,0.0,0,18.0,1.4012985e-45,1.4929308,-0.12256652,17.999811,211.73212,-11.482057
181.9608,-0.043600298,11.629357,0.0,0,18.0,1.4012985e-45,1.4930525,-0.12734294,18.00091,206.48145,-11.482168
183.0608,-0.043190986,11.629977,0.0,0,18.0,1.4012985e-45,1.4932042,-0.12447158,18.000065,201.62016,-11.482278
184.1608,-0.041901708,11.630114,0.0,0,18.0,1.4012985e-45,1.4930178,-0.12164991,17.999537,196.63101,-11.482573
185.2608,-0.042634863,11.630405,0.0,0,18.0,1.4012985e-45,1.4933929,-0.12610871,17.999542,191.83772,-11.482516
186.3608,-0.041361716,11.63109,0.0,0,18.0,1.4012985e-45,1.4934149,-0.11996949,17.999973,187.36325,-11.482578
187.4608,-0.041389816,11.630861,0.0,0,18.0,1.4012985e-45,1.493452,-0.12019385,17.999565,182.7972,-11.48259
188.5608,-0.041675713,11.631083,0.0,0,18.0,1.4012985e-45,1.4933546,-0.12020829,17.999634,178.06863,-11.482961
189.6608,-0.040956452,11.630983,0.0,0,18.0,1.4012985e-45,1.4935613,-0.12115074,18.000225,173.99358,-11.482864
190.7608,-0.041147858,11.631704,0.0,0,18.0,1.4012985e-45,1.4936428,-0.1183513,17.999584,169.89095,-11.483041
191.8608,-0.039683413,11.631915,0.0,0,18.0,1.4012985e-45,1.4935238,-0.11682304,17.99954,165.98228,-11.482564
192.9608,-0.039213743,11.631884,0.0,0,18.0,1.4012985e-45,1.493747,-0.11338602,18.000275,162.1171,-11.482719
194.0608,-0.039555743,11.631896,0.0,0,18.0,1.4012985e-45,1.4936655,-0.11594,17.999563,158.37234,-11.482491
195.1608,-0.040577482,11.6319,0.0,0,18.0,1.4012985e-45,1.4937932,-0.11861094,18.00012,154.7388,-11.482298
196.2608,-0.037552383,11.632116,0.0,0,18.0,1.4012985e-45,1.4935964,-0.1103932,17.999739,151.16853,-11.482044
197.3608,-0.038067881,11.631556,0.0,0,18.0,1.4012985e-45,1.4937435,-0.11032514,18.000223,147.6347,-11.482168
198.4608,-0.037194323,11.632459,0.0,0,18.0,1.4012985e-45,1.4938532,-0.11062027,18.00111,144.3972,-11.48225
199.5608,-0.036856938,11.632596,0.0,0,18.0,1.4012985e-45,1.4938087,-0.10483524,17.999287,141.22095,-11.481986
200.6608,-0.038016118,11.632486,0.0,0,18.0,1.4012985e-45,1.4938909,-0.11075151,18.000099,137.83684,-11.482582
201.7608,-0.036492772,11.633025,0.0,0,18.0,1.4012985e-45,1.4940479,-0.10878429,18.000299,134.86644,-11.482316
202.8608,-0.036489457,11.633401,0.0,0,18.0,1.4012985e-45,1.4942367,-0.10633787,17.999592,131.81261,-11.482586
203.9608,-0.037145074,11.633421,0.0,0,18.0,1.4012985e-45,1.4939792,-0.10597365,17.999969,128.81628,-11.48268
205.0608,-0.035782006,11.633294,0.0,0,18.0,1.4012985e-45,1.4942656,-0.10285151,17.999495,126.12307,-11.482425
206.1608,-0.03553975,11.634298,0.0,0,18.0,1.4012985e-45,1.4944319,-0.10212963,18.000204,123.19468,-11.482701
207.2608,-0.036213681,11.634316,0.0,0,18.0,1.4012985e-45,1.4943522,-0.10306711,17.99963,120.21949,-11.482833
208.3608,-0.034757923,11.634151,0.0,0,18.0,1.4012985e-45,1.4943776,-0.10071837,17.999586,117.6549,-11.482735
209.4608,-0.035290707,11.634459,0.0,0,18.0,1.4012985e-45,1.4944832,-0.10530654,17.999598,115.1114,-11.482622
210.5608,-0.036327675,11.634209,0.0,0,18.0,1.4012985e-45,1.4944725,-0.10350423,18.000162,112.81792,-11.482776
211.6608,-0.035281342,11.635167,0.0,0,18.0,1.4012985e-45,1.4945118,-0.10031411,18.000298,110.04996,-11.483012
212.7608,-0.034773931,11.635153,0.0,0,18.0,1.4012985e-45,1.4947988,-0.097251788,18.000448,107.94266,-11.483127
213.8608,-0.035263266,11.635639,0.0,0,18.0,1.4012985e-45,1.4948009,-0.10038782,17.999973,105.72693,-11.483175
214.9608,-0.035117883,11.636186,0.0,0,18.0,1.4012985e-45,1.4948961,-0.10002056,17.999943,103.22044,-11.483124
215.8608,-0.037282072,11.635875,0.0,0,18.0,1.4012985e-45,1.4947329,-0.10685644,17.999681,101.53619,-11.482709