File: examples/dan-msc-case-studies/CS3/data/01 raw data/baron_test_106.csv
Time(sec),Force(kN),Jaw(mm),PowAngle(deg),Power(W),Pram,PTemp,Strain,Stress(MPa),Stroke(mm),TC1(C),wedge(mm)
0.0,2.3757155,-0.018619316,0.0,0,11.076097,0.00047926401,-0.0012393696,30.267982,11.076779,23.279442,-9.1255302
1.1,2.2602179,-0.0043188534,0.0,0,11.076097,3.2161808,-0.0003012594,28.799911,11.075706,23.279865,-9.4895353
2.2,2.1870029,-0.0042482684,0.0,0,11.076097,6.5161829,-0.0003143854,27.854168,11.07552,23.244772,-9.4867611
3.3,2.1579823,-0.0046333815,0.0,0,11.076097,9.8161812,-0.00027277798,27.470917,11.075492,23.192041,-9.4862022
4.4,2.1155791,-0.0043709753,0.0,0,11.076097,13.116182,-0.00028446782,26.957041,11.076921,23.184603,-9.4837151
5.5,2.0903258,-0.004412435,0.0,0,11.076097,16.416183,-0.00032523408,26.623304,11.076097,23.23164,-9.4822731
6.6,2.0568695,-0.0050689355,0.0,0,11.076097,19.716183,-0.00030677067,26.204916,11.075027,23.226702,-9.4803572
7.7,2.0371132,-0.0054458654,0.0,0,11.076097,23.016184,-0.00034826057,25.966743,11.075742,23.204605,-9.4786386
8.8,2.0119779,-0.0053166235,17.999987,0,11.076097,26.316181,-0.00037303506,25.613359,11.075721,23.222126,-9.4763689
9.9,2.0092182,-0.0064057438,29.514999,0,11.076097,29.616184,-0.00040548589,25.600037,11.075021,24.492962,-9.4743481
11.0,2.0212431,-0.0084699336,35.603786,0,11.076097,32.916191,-0.00057130429,25.744921,11.076083,26.896774,-9.4726601
12.1,2.0344381,-0.011626146,39.876198,0,11.076097,36.21619,-0.00077545957,25.921312,11.075803,30.151548,-9.4711065
13.2,2.0414979,-0.014937025,42.285748,0,11.076097,39.51619,-0.0010014204,26.035667,11.07591,33.954121,-9.46943
14.3,2.0634239,-0.018592954,43.598888,0,11.076097,42.816189,-0.0012643377,26.296822,11.075873,38.158253,-9.4677038
15.4,2.0735555,-0.022912966,44.604424,0,11.076097,46.116184,-0.0015013047,26.429371,11.076539,42.486515,-9.4654722
16.5,2.0925639,-0.026394721,44.587132,0,11.076097,49.41618,-0.0017581668,26.699694,11.076094,47.134048,-9.463789
17.6,2.0981028,-0.030073715,43.853428,0,11.076097,52.716183,-0.0020387666,26.768188,11.077057,51.690289,-9.4615793
18.7,2.1014104,-0.033461932,42.979065,0,11.076097,56.016178,-0.0021931992,26.80764,11.075235,55.916283,-9.4598093
19.8,2.1135297,-0.036307711,42.396244,0,11.076097,59.316181,-0.0024026087,26.996077,11.075818,59.809559,-9.4580078
20.9,2.1190708,-0.038899139,41.668812,0,11.076097,62.616184,-0.0026196369,27.055996,11.076552,63.43103,-9.4565296
22.0,2.1174853,-0.041401356,41.198734,0,11.076097,65.916191,-0.0027214838,27.046961,11.075773,66.669113,-9.4548416
23.1,2.1246183,-0.043460466,41.198734,0,11.076097,69.216194,-0.0028797654,27.130678,11.075787,69.728447,-9.4529638
24.2,2.116941,-0.045904189,41.198734,0,11.076097,72.516182,-0.0030758225,27.031246,11.076097,72.748009,-9.4510822
25.3,2.115149,-0.048291016,41.802975,0,11.076097,75.816185,-0.0031920206,27.030869,11.077134,75.766891,-9.4490194
26.4,2.1244376,-0.050560802,41.840347,0,11.076097,79.11618,-0.0033542491,27.135214,11.076307,78.800552,-9.4472256
27.5,2.1183863,-0.053338546,42.395977,0,11.076097,82.416183,-0.0035514773,27.071903,11.076179,81.949371,-9.4452219
28.6,2.133183,-0.055218987,42.978512,0,11.076097,85.716187,-0.0036793142,27.268738,11.076142,85.020714,-9.4432592
29.7,2.1412652,-0.057729676,43.527824,0,11.076097,89.016174,-0.0038501848,27.34836,11.076377,88.169373,-9.4419088
30.8,2.133323,-0.060447637,44.017223,0,11.076097,92.316193,-0.0040085013,27.275251,11.075615,91.536278,-9.4398222
31.9,2.1538327,-0.063195288,44.077145,0,11.076097,95.61618,-0.0042142817,27.548788,11.076015,94.942276,-9.4380865
33.0,2.156877,-0.066637993,44.604488,0,11.076097,98.916191,-0.0044475393,27.583199,11.075849,98.177322,-9.4362488
34.1,2.1473567,-0.069387063,44.747215,0,11.076097,102.21619,-0.0045916624,27.466705,11.075704,101.45535,-9.433836
35.2,2.1617582,-0.071375251,45.090992,0,11.076097,105.5162,-0.0047632367,27.653704,11.076059,104.89809,-9.4322643
36.3,2.15815,-0.074226961,45.12085,0,11.076097,108.81619,-0.004956699,27.600855,11.075215,108.25669,-9.4302292
37.4,2.1619611,-0.07705418,45.12085,0,11.076097,112.11619,-0.0051031648,27.677303,11.076135,111.64858,-9.4281368
38.5,2.1710808,-0.079386063,45.592052,0,11.076097,115.4162,-0.0052987318,27.781012,11.075988,114.86418,-9.4265203
39.6,2.1718984,-0.081985295,45.679535,0,11.076097,118.71619,-0.0054840925,27.815266,11.075546,118.13886,-9.42449
40.7,2.1839705,-0.084867597,46.109619,0,11.076097,122.0162,-0.0056122118,27.986013,11.076859,121.3684,-9.42307
41.8,2.1921418,-0.087579116,46.390167,0,11.076097,125.31619,-0.0058299731,28.082724,11.076715,124.75192,-9.4212809
42.9,2.1989968,-0.089766905,46.582027,0,11.076097,128.61632,-0.0060089123,28.167782,11.076043,128.0896,-9.4199619
44.0,2.2143075,-0.093363486,46.630211,0,11.076097,131.9162,-0.0061806068,28.369028,11.075919,131.39853,-9.4183178
45.1,2.2241492,-0.09686707,46.954151,0,11.076097,135.21619,-0.0064478787,28.498259,11.075612,134.81482,-9.4168291
46.2,2.2265131,-0.09976577,47.05444,0,11.076097,138.51619,-0.0066548358,28.537724,11.075801,137.95665,-9.4150724
47.3,2.234983,-0.10201601,47.504883,0,11.076097,141.81618,-0.0067501054,28.646912,11.075703,141.16113,-9.4135847
48.4,2.2302206,-0.10506576,47.764923,0,11.076097,145.1162,-0.0069818171,28.613718,11.075578,144.43451,-9.4118586
49.5,2.2373383,-0.10810017,48.088505,0,11.076097,148.41618,-0.0072144917,28.714781,11.076469,147.62904,-9.4098816
50.6,2.250993,-0.11136236,48.278793,0,11.076097,151.71619,-0.0073624421,28.864529,11.075773,151.13205,-9.4082756
51.7,2.2555811,-0.11398412,48.383785,0,11.076097,155.0162,-0.0075779241,28.943031,11.075319,154.51909,-9.4065876
52.8,2.2625399,-0.11733089,48.809654,0,11.076097,158.31619,-0.0078220507,29.041868,11.07581,157.69374,-9.4049635
53.9,2.2752607,-0.12128836,48.812252,0,11.076097,161.6162,-0.008042004,29.197371,11.075969,161.12537,-9.4026413
55.0,2.2675118,-0.12472285,48.875977,0,11.076097,164.9162,-0.0082945749,29.112408,11.07682,164.47852,-9.4011431
56.1,2.2689784,-0.12721722,49.208401,0,11.076097,168.2162,-0.0084762787,29.142687,11.076466,167.76476,-9.3992414
57.2,2.2766035,-0.13039379,49.229733,0,11.076097,171.51619,-0.008630407,29.243282,11.0761,171.06361,-9.3974838
58.3,2.279201,-0.1327752,49.299339,0,11.076097,174.81618,-0.008821913,29.296144,11.076139,174.42343,-9.3954916
59.4,2.2820582,-0.13591741,49.361401,0,11.076097,178.1162,-0.0090469932,29.324305,11.077005,177.7476,-9.3938293
60.5,2.2864223,-0.13889048,49.636227,0,11.076097,181.41618,-0.0091980221,29.378696,11.07657,181.03473,-9.3918457
61.6,2.2829692,-0.14289622,49.851582,0,11.076097,184.7162,-0.0094949128,29.358517,11.076484,184.23889,-9.389596
62.7,2.3022604,-0.14664838,50.035938,0,11.076097,188.01619,-0.0097441832,29.578499,11.075909,187.62485,-9.3875103
63.8,2.2927783,-0.14910908,50.042721,0,11.076097,191.31619,-0.009886316,29.46583,11.076405,190.87041,-9.3855906
64.9,2.2958264,-0.15182522,50.246037,0,11.076097,194.61618,-0.010073424,29.524462,11.075327,194.18404,-9.3838062
66.0,2.3036726,-0.1551256,50.421902,0,11.076097,197.9162,-0.010309232,29.639643,11.075996,197.59924,-9.3822165
67.1,2.3043549,-0.15822981,50.433491,0,11.076097,201.21619,-0.010496646,29.665787,11.07597,201.05017,-9.3805761
68.2,2.3167236,-0.16065627,50.074951,0,11.076097,204.51619,-0.010665718,29.811268,11.075951,204.46167,-9.3786793
69.3,2.3134336,-0.16355659,50.100475,0,11.076097,207.81619,-0.010847691,29.778408,11.075812,207.77255,-9.3770151
70.4,2.3126214,-0.1683269,50.419907,0,11.076097,211.11621,-0.01115781,29.776131,11.075549,211.01129,-9.3752899
71.5,2.3195331,-0.16954769,50.438229,0,11.076097,214.41621,-0.011225227,29.863808,11.076356,214.22246,-9.3738003
72.6,2.3106024,-0.17242952,50.757965,0,11.076097,217.71622,-0.011413426,29.755342,11.076354,217.33556,-9.3718729
73.7,2.324666,-0.1750735,50.827881,0,11.076097,221.0162,-0.011607978,29.952099,11.075515,220.42459,-9.3700247
74.8,2.327641,-0.17849624,51.196285,0,11.076097,224.31621,-0.011808905,29.988552,11.075835,223.70578,-9.3681021
75.9,2.3263862,-0.18151249,51.197128,0,11.076097,227.61621,-0.012013202,29.984474,11.076175,227.05617,-9.3665953
77.0,2.3326862,-0.18384311,51.563992,0,11.076097,230.91621,-0.012209951,30.063507,11.077016,230.40033,-9.3648872
78.1,2.3314822,-0.18777519,51.56982,0,11.076097,234.21622,-0.012403112,30.057819,11.07625,233.79849,-9.3627892
79.2,2.3471599,-0.19208722,51.569828,0,11.076097,237.5162,-0.012702613,30.269444,11.075516,237.10612,-9.3617878
80.3,2.3565295,-0.19430451,51.56987,0,11.076097,240.81621,-0.012894615,30.389887,11.075706,240.5631,-9.3598366
81.4,2.343745,-0.19742118,51.571598,0,11.076097,244.11621,-0.013039388,30.228525,11.075884,243.9211,-9.3581266
82.5,2.3404405,-0.20040742,51.72327,0,11.076097,247.41621,-0.013269179,30.204416,11.07635,247.27559,-9.3562946
83.6,2.3393266,-0.20290913,51.892162,0,11.076097,250.7162,-0.013473362,30.19026,11.076719,250.51523,-9.3540564
84.7,2.3385084,-0.20630498,51.93235,0,11.076097,254.01619,-0.013631097,30.192059,11.076378,253.85847,-9.3520412
85.8,2.348321,-0.20896643,51.932369,0,11.076097,257.31647,-0.013843733,30.316591,11.075432,257.02646,-9.3501482
86.9,2.3459795,-0.21146062,52.088364,0,11.076097,260.61646,-0.01402203,30.298807,11.075396,260.30435,-9.3484392
88.0,2.3576601,-0.21459968,52.282806,0,11.076097,263.9162,-0.014180171,30.458609,11.07608,263.63745,-9.3470354
89.1,2.3603845,-0.21713422,52.283936,0,11.076097,267.21619,-0.014382654,30.494736,11.075915,266.97141,-9.345067
90.2,2.3583467,-0.21991581,52.293503,0,11.076097,270.51617,-0.014567807,30.459923,11.075891,270.1156,-9.3430834
91.3,2.3652925,-0.22287551,52.635494,0,11.076097,273.81622,-0.014755516,30.578279,11.076444,273.20544,-9.3416262
92.4,2.36654,-0.22608069,52.976051,0,11.076097,277.11618,-0.014952154,30.582987,11.076293,276.36835,-9.3404083
93.5,2.3686249,-0.22923534,53.226807,0,11.076097,280.4162,-0.015146028,30.630276,11.076951,279.7421,-9.3382874
94.6,2.3737438,-0.23310578,53.31665,0,11.076097,283.71622,-0.015444211,30.694435,11.076481,283.11487,-9.3361826
95.7,2.3728514,-0.23687157,53.357555,0,11.076097,287.0162,-0.015633715,30.680191,11.076836,286.46631,-9.3344126
96.8,2.3689649,-0.2401242,53.395412,0,11.076097,290.31619,-0.015868977,30.641756,11.076074,290.01312,-9.3321848
97.9,2.3718128,-0.24253455,53.318832,0,11.076097,293.61621,-0.016067086,30.681337,11.07533,293.53009,-9.3305206
99.0,2.3646371,-0.24485202,53.412842,0,11.076097,296.9162,-0.016144691,30.60416,11.076388,296.73978,-9.3290043
100.1,2.3654666,-0.24704514,53.316864,0,11.076097,299.99545,-0.016334087,30.621832,11.075693,300.18759,-9.3279657
101.2,0.051980015,-0.27829722,50.063873,0,11.076097,299.99905,-0.018415539,0.69306433,11.075818,303.68402,-9.3282032
102.3,0.043015562,-0.27826777,46.810356,0,11.076097,299.99905,-0.018362943,0.55155462,11.076418,305.44882,-9.3279228
103.4,0.023909559,-0.27814129,44.784088,0,11.076097,299.99905,-0.018384989,0.316807,11.075591,305.10706,-9.3281507
104.5,0.020592554,-0.27707076,44.604328,0,11.076097,299.99905,-0.018312741,0.29039389,11.076174,303.54385,-9.32833
105.6,0.013232337,-0.27625889,45.614143,0,11.076097,299.99905,-0.018240031,0.16599715,11.076004,301.39319,-9.3278255
106.7,0.0087937713,-0.27492186,47.645538,0,11.076097,299.99905,-0.018154582,0.12766217,11.075774,299.14481,-9.3277645
107.8,0.0094457958,-0.27412689,50.168697,0,11.076097,299.99905,-0.018100183,0.14018916,11.075794,296.93439,-9.3271751
108.9,0.0037015614,-0.27345136,52.956352,0,11.076097,299.99905,-0.018082226,0.032075405,11.076061,294.97598,-9.3268604
110.0,0.00058780902,-0.27311954,55.635227,0,11.076097,299.99905,-0.018022172,0.023214143,11.07485,293.27927,-9.3268232
111.1,0.0063074231,-0.27262259,58.06163,0,11.076097,299.99905,-0.017997621,0.088015258,11.076848,292.03192,-9.3267803
112.2,0.0017712611,-0.27222416,60.300484,0,11.076097,299.99905,-0.018009229,0.023893692,11.075934,291.31052,-9.3266335
113.3,0.0049567558,-0.27266935,62.159332,0,11.076097,299.99905,-0.017978124,0.068066858,11.076067,290.86761,-9.3262053
114.4,0.011744163,-0.27267033,63.770439,0,11.076097,299.99905,-0.018016178,0.14529662,11.076456,290.89447,-9.3264608
115.5,0.0121967,-0.27304617,65.112389,0,11.076097,299.99905,-0.018066455,0.14956531,11.076501,291.37494,-9.3262234
116.6,0.031885099,-0.27362421,65.995361,0,11.076097,299.99905,-0.018055517,0.42626929,11.075488,292.4733,-9.326664
117.7,0.042577863,-0.27440298,66.348351,0,11.076097,299.99905,-0.018127969,0.54797995,11.075455,294.41461,-9.3263521
118.8,0.039824534,-0.27652255,66.016884,0,11.076097,299.99905,-0.018268352,0.50997806,11.075832,297.06619,-9.3265181
119.9,0.044784471,-0.27882499,65.203522,0,11.076097,299.99905,-0.018420257,0.5735386,11.075855,299.90765,-9.3267708
121.0,0.042467009,-0.28077921,63.987602,0,11.076097,299.99905,-0.018519918,0.54509562,11.075783,302.56818,-9.3266354
122.1,0.049133278,-0.28192723,62.344688,0,11.076097,299.99905,-0.018597059,0.64727336,11.076203,304.89407,-9.327013
123.2,0.052757327,-0.2833961,60.377739,0,11.076097,299.99905,-0.018743763,0.68713403,11.076451,306.71628,-9.326827
124.3,0.048972219,-0.28431368,58.347336,0,11.076097,299.99905,-0.01872842,0.64334106,11.075393,307.84912,-9.3268633
125.4,0.050378732,-0.28405061,56.130909,0,11.076097,299.99905,-0.018753218,0.66968381,11.075821,308.33582,-9.3270893
126.5,0.038771436,-0.28413776,54.008671,0,11.076097,299.99905,-0.018801663,0.49865621,11.075594,308.09927,-9.3267822
127.6,0.02429349,-0.28428689,52.370029,0,11.076097,299.99905,-0.018742876,0.31507346,11.076025,307.19589,-9.3266144
128.7,0.022939054,-0.28369856,51.569828,0,11.076097,299.99905,-0.018746132,0.29771313,11.076401,305.64844,-9.3264666
129.8,0.013880488,-0.28316873,51.487461,0,11.076097,299.99905,-0.018711247,0.17308547,11.075575,303.79898,-9.3262768
130.9,0.006945739,-0.28250986,51.932346,0,11.076097,299.99905,-0.018664092,0.10230109,11.076091,301.74557,-9.3264828
132.0,0.0057577724,-0.28157943,53.275211,0,11.076097,299.99905,-0.018582832,0.076727845,11.075707,299.65021,-9.3265085
133.1,-0.0013887289,-0.28073138,54.863049,0,11.076097,299.99905,-0.018515198,-0.01452582,11.077147,297.79501,-9.3265944
134.2,0.00087253272,-0.28024212,56.649906,0,11.076097,299.99905,-0.018537762,0.017737117,11.075732,296.19086,-9.3263931
135.3,0.0016040105,-0.28049561,58.28228,0,11.076097,299.99905,-0.018489137,0.021597145,11.076521,294.9678,-9.3266869
136.4,-0.0022635681,-0.27991366,59.828537,0,11.076097,299.99905,-0.018489724,-0.021171128,11.075357,294.19693,-9.3263092
137.5,0.0014674127,-0.28020236,61.22187,0,11.076097,299.99905,-0.018544335,0.029134443,11.07611,293.83243,-9.3261213
138.6,0.005153493,-0.28052703,62.334568,0,11.076097,299.99905,-0.018513931,0.060128946,11.075803,293.93414,-9.3261271
139.7,0.010731588,-0.28085718,62.962639,0,11.076097,299.99905,-0.018560603,0.14057459,11.076035,294.70758,-9.326231
140.8,0.027473098,-0.28091633,63.369137,0,11.076097,299.99905,-0.018560523,0.36247414,11.076238,295.8396,-9.3261805
141.9,0.03665654,-0.28213435,63.369152,0,11.076097,299.99905,-0.018644338,0.46624017,11.076369,297.56473,-9.3260231
143.0,0.044860911,-0.28466183,62.754059,0,11.076097,299.99905,-0.018771403,0.58020025,11.075287,299.6055,-9.3259287
144.1,0.055268094,-0.28574124,61.698978,0,11.076097,299.99905,-0.018855758,0.70796669,11.076153,301.5444,-9.3262358
145.1321,0.1500489,-0.0049361368,60.570522,0,11.076097,299.99905,-0.00031447218,1.9059969,11.074777,303.20615,-9.3263779
145.2851,0.5274201,0.024231955,38.437157,0,11.076099,6.0865757e-10,0.0013284357,6.7002263,11.079433,303.71552,-9.3256941
145.2873,0.5609678,0.016647849,25.141275,0,11.076099,6.079146e-25,0.0013745354,7.1757989,11.073119,303.68845,-9.3257294
145.2895,0.53688657,0.020607464,11.845396,0,11.076099,6.0717282e-40,0.0011651095,6.9144397,11.073932,303.66138,-9.325737
145.2917,0.54569113,0.019243,0.0,0,11.076099,0.0,0.0015710257,6.9424953,11.079065,303.63873,-9.3255177
145.2939,0.55909276,0.023414377,0.0,0,11.076099,0.0,0.0012729053,7.0645304,11.076662,303.65228,-9.3257275
145.2961,0.55579269,0.017678514,0.0,0,11.076099,0.0,0.0013993821,7.0296121,11.071094,303.6658,-9.3264894
145.2983,0.55787712,0.021109989,0.0,0,11.076099,0.0,0.0012113437,7.2366447,11.07612,303.67935,-9.3251343
145.3005,0.56373554,0.019542594,0.0,0,11.076099,0.0,0.0015061025,7.1986599,11.077103,303.69287,-9.3250475
145.3027,0.57052487,0.022519691,0.0,0,11.076099,0.0,0.001174557,7.3087807,11.075475,303.7103,-9.3264933
145.3049,0.57587987,0.01742222,0.0,0,11.076099,0.0,0.001409095,7.2991438,11.073379,303.73059,-9.3266525
145.3071,0.58385199,0.020723121,0.0,0,11.076099,0.0,0.0012522849,7.4226179,11.077958,303.75092,-9.3260889
145.3093,0.58400363,0.021663718,0.0,0,11.076099,0.0,0.0016505249,7.4252839,11.077673,303.77121,-9.3257866
145.3115,0.58937877,0.023056261,0.0,0,11.076099,0.0,0.0013821877,7.4975791,11.075884,303.79102,-9.3270969
145.3137,0.59304589,0.018175829,0.0,0,11.076099,0.0,0.0013949919,7.6338725,11.073855,303.79779,-9.3269644
145.3159,0.5894255,0.019202251,0.0,0,11.076099,0.0,0.0011212229,7.5829692,11.078443,303.80457,-9.3258572
145.3181,0.59735358,0.02018718,0.0,0,11.076099,0.0,0.0015490354,7.5948892,11.076059,303.81131,-9.3258486
145.3203,0.60471874,0.023002308,0.0,0,11.076099,0.0,0.0012966098,7.6952291,11.074284,303.81808,-9.3256006
145.3225,0.59862757,0.018996809,0.0,0,11.076099,0.0,0.0013771765,7.590713,11.076062,303.81808,-9.3266382
145.3247,0.60407192,0.019801395,0.0,0,11.076099,0.0,0.0011242816,7.6984401,11.077173,303.81131,-9.3266001
145.3269,0.61513764,0.021618618,0.0,0,11.076099,0.0,0.0016405338,7.8556724,11.076362,303.80457,-9.3267775
145.3291,0.61617798,0.022887124,0.0,0,11.076099,0.0,0.0013451492,7.7988582,11.075203,303.79779,-9.3256445
145.3313,0.61688805,0.019578155,0.0,0,11.076099,0.0,0.0014663723,7.9052339,11.075934,303.79102,-9.3258152
145.3335,0.62361068,0.018270319,0.0,0,11.063763,0.0,0.0010956085,7.9812598,11.078125,303.79077,-9.3256445
145.3357,0.61800593,0.022201823,0.0,0,10.735819,0.0,0.0015938588,7.8739471,11.074656,303.79077,-9.3253775
145.3379,0.64244431,0.021897636,0.0,0,10.404927,0.0,0.0013357804,8.0808725,11.066495,303.79077,-9.3258162
145.3401,0.65719187,0.02067093,0.0,0,10.074035,0.0,0.0014570493,8.2730694,11.015206,303.79077,-9.3257256
145.3423,0.66361254,0.019550098,0.0,0,9.7431412,0.0,0.0012560305,8.4114246,10.83162,304.96451,-9.3263645
145.3445,0.66092914,0.021366224,0.0,0,9.4141388,0.0,0.0015353601,8.415616,10.530856,307.71158,-9.3270626
145.3467,0.64243543,0.02162018,0.0,0,9.0922346,0.0,0.0013627937,8.0778112,10.157172,310.45865,-9.3267517
145.3489,7.6005588,0.32934505,0.0,0,8.7703304,0.0,0.021533502,94.694542,9.7619228,313.20572,-9.3207254
145.3511,9.5797796,0.73057204,0.0,0,8.4631929,0.0,0.049573753,115.53593,9.2790232,315.95276,-9.3202248
145.3533,10.374702,1.1640983,0.0,0,8.1570415,0.0,0.080580615,121.41415,8.8360405,318.49026,-9.3172436
145.3555,10.52229,1.5067732,0.0,0,7.8607755,0.0,0.10527818,120.84965,8.4934368,321.00208,-9.3163404
145.3577,11.048433,1.7862546,0.0,0,7.5694952,0.0,0.12641253,123.67414,8.1801348,323.51389,-9.3168221
145.3599,11.260649,2.0853398,0.0,0,7.2838039,0.0,0.14928989,123.42735,7.8720093,326.02573,-9.317565
145.3621,11.487674,2.3633907,0.0,0,7.0067792,0.0,0.17101714,123.17589,7.6073537,327.65649,-9.3173008
145.3643,11.853835,2.6039541,0.0,0,6.7313671,0.0,0.19025557,124.52134,7.3491654,327.68338,-9.3180981
145.3665,12.14072,2.8595591,0.0,0,6.467802,0.0,0.21118262,125.11809,7.0881839,327.71024,-9.3185558
145.3687,12.422561,3.1206527,0.0,0,6.2042422,0.0,0.23289651,125.1539,6.8273292,327.73709,-9.3183708
145.3709,12.772916,3.3880167,0.0,0,5.9515953,0.0,0.25543922,125.85841,6.5610294,327.76398,-9.3186131
145.3731,13.038386,3.6415949,0.0,0,5.7009277,0.0,0.27779576,125.68201,6.2956066,328.07669,-9.3185616
145.3753,13.362571,3.9105246,0.0,0,5.4572535,0.0,0.30148163,125.81803,6.0333309,328.45288,-9.3188725
145.3775,13.679426,4.1650753,0.0,0,5.2187734,0.0,0.32499766,125.81378,5.7709789,328.8291,-9.3181419
145.3797,13.991756,4.4301491,0.0,0,4.9838042,0.0,0.3494651,125.60654,5.5088363,329.20532,-9.318203
145.3819,14.34635,4.6723375,0.0,0,4.7569842,0.0,0.3729662,125.71113,5.2592497,329.49066,-9.3191023
145.3841,14.695799,4.9234924,0.0,0,4.5305758,0.0,0.39721802,125.66412,5.01683,329.5444,-9.3182096
145.3863,15.078219,5.1565375,0.0,0,4.314702,0.0,0.4209902,125.95445,4.7770324,329.59818,-9.3179121
145.3885,15.431466,5.3928647,0.0,0,4.0989256,0.0,0.44478375,125.86463,4.542696,329.65192,-9.317255
145.3907,15.797895,5.6082678,0.0,0,3.8911293,0.0,0.46808136,125.92172,4.317555,329.70566,-9.3170643
145.3929,16.168972,5.8325362,0.0,0,3.6859133,0.0,0.49163592,125.89652,4.1018949,329.45892,-9.3178978
145.3951,16.584173,6.0399637,0.0,0,3.4855206,0.0,0.51512659,126.11663,3.8875599,329.10956,-9.3180046
145.3973,17.00296,6.2564955,0.0,0,3.2902927,0.0,0.53890777,126.22955,3.6777658,328.76022,-9.3178396
145.3995,17.455923,6.4521103,0.0,0,3.0970623,0.0,0.56230819,126.62183,3.475616,328.41089,-9.3178387
145.4017,17.936607,6.6578312,0.0,0,2.9113381,0.0,0.58585769,127.02354,3.2772684,328.04608,-9.316288
145.4039,18.460846,6.8449588,0.0,0,2.7256143,0.0,0.60956687,127.70675,3.0800581,327.62283,-9.3148851
145.4061,19.013538,7.0457234,0.0,0,2.5483873,0.0,0.63315529,128.46695,2.8868136,327.19958,-9.3162575
145.4083,19.569967,7.2260051,0.0,0,2.3717272,0.0,0.6573984,129.01721,2.7028532,326.77637,-9.3162956
145.4105,20.15472,7.4160099,0.0,0,2.2008004,0.0,0.68111074,129.83075,2.5182683,326.35312,-9.3150043
145.4127,20.764072,7.5896616,0.0,0,2.0327644,0.0,0.705571,130.44713,2.3334944,326.06094,-9.3150902
145.4149,21.420422,7.7744861,0.0,0,1.8679364,0.0,0.72918928,131.44511,2.1576641,325.83252,-9.3152771
145.4171,22.100973,7.9353838,0.0,0,1.7080843,0.0,0.7533232,132.42732,1.9860574,325.6041,-9.3148108
145.4193,22.847773,8.1089907,0.0,0,1.5491644,0.0,0.77670383,133.69202,1.8180916,325.37567,-9.3140287
145.4215,23.623415,8.2638292,0.0,0,1.3970973,0.0,0.80109209,134.9449,1.6589633,325.07761,-9.313982
145.4237,24.441574,8.433773,0.0,0,1.2450334,0.0,0.82452691,136.3606,1.4951949,324.33832,-9.314435
145.4259,25.291714,8.5743093,0.0,0,1.0992644,0.0,0.84822565,137.82083,1.3423785,323.59903,-9.3146353
145.4281,26.157042,8.7333851,0.0,0,0.95463634,0.0,0.87164116,139.23785,1.1912007,322.85977,-9.3131065
145.4303,27.070724,8.8728533,0.0,0,0.81407332,0.0,0.89610833,140.59784,1.042233,322.12048,-9.3108206
145.4325,28.037779,9.0221767,0.0,0,0.67652941,0.0,0.91835058,142.43312,0.89969677,321.35678,-9.3113985
145.4347,29.047939,9.1481667,0.0,0,0.54098594,0.0,0.94186842,144.10091,0.75750828,320.57678,-9.3108902
145.4369,30.067373,9.281971,0.0,0,0.41008592,0.0,0.96314025,146.01772,0.62246859,319.79678,-9.3093615
145.4391,30.095055,9.3921967,0.0,0,0.27942541,0.0,0.98507923,143.69737,0.49668133,319.01678,-9.3109398
145.4413,28.419559,9.4273577,0.0,0,0.15489216,0.0,0.98884022,134.95081,0.44395173,318.3288,-9.3136129
145.4435,27.101835,9.4255028,0.0,0,0.030416148,0.0,0.99125427,128.13234,0.41629541,318.99414,-9.3142414
145.4457,26.655725,9.4356251,0.0,0,-0.09173242,0.0,0.99066305,126.0538,0.38668761,319.65952,-9.3146648
145.4479,26.578173,9.4356413,0.0,0,-0.21312842,0.0,0.99282187,125.39561,0.34230965,320.32489,-9.3153677
145.4501,26.688936,9.4493532,0.0,0,-0.33452442,0.0,0.99282283,125.90916,0.28900003,320.99026,-9.3152895
145.4523,26.730087,9.4500208,0.0,0,-0.45592043,0.0,0.99553663,125.77651,0.22964443,321.92862,-9.3143253
145.4545,26.682278,9.4590425,0.0,0,-0.5773164,0.0,0.99485409,125.62888,0.17613356,323.11169,-9.3149748
145.4567,26.547434,9.4597197,0.0,0,-0.69871235,0.0,0.99720383,124.70777,0.1247799,324.2948,-9.3168497
145.4589,26.353811,9.4692106,0.0,0,-0.82010835,0.0,0.99646664,123.93069,0.081784725,325.47787,-9.3157721
145.4611,26.105879,9.4691534,0.0,0,-0.94150436,0.0,0.99888754,122.45096,0.046709206,326.66098,-9.3163738
145.4633,25.729553,9.4774628,0.0,0,-1.0629004,0.0,0.9982993,120.76585,0.02762926,327.47723,-9.3164721
145.4655,25.255852,9.4738092,0.0,0,-0.8433286,300.0,0.99961287,118.4146,0.015465376,328.29013,-9.3170319
145.4677,24.717091,9.4809837,0.0,0,-0.42304948,300.0,0.99878311,115.95958,0.021145727,329.10303,-9.3171873
145.4699,24.270668,9.472312,0.0,0,-0.0027700011,300.0,0.99934596,113.79411,0.025133001,329.91592,-9.3186321
145.4721,23.890594,9.4780569,0.0,0,0.41750887,300.0,0.99845648,112.13432,0.02985274,330.65552,-9.3187246
145.4743,23.603786,9.477109,0.0,0,0.83778799,300.0,1.0001432,110.57746,0.027643617,331.30719,-9.319418
145.4765,23.326725,9.478673,0.0,0,1.2580678,300.0,0.99852812,109.45874,0.028214609,331.95886,-9.3206396
145.4787,22.654882,9.473155,0.0,0,1.6783465,300.0,0.99949098,106.3096,0.042726874,332.6105,-9.3195963
145.4809,21.271276,9.472662,0.0,0,2.0986254,300.0,0.99753153,99.998466,0.10147574,333.26218,-9.3200083
145.4831,18.860823,9.466897,0.0,0,2.5189049,300.0,0.99814659,88.787186,0.20030494,334.03595,-9.3216143
145.4853,13.576618,9.4505072,0.0,0,2.9391842,300.0,0.99338752,64.614494,0.41624716,334.82062,-9.3268127
145.4875,0.30295539,9.2380714,0.0,0,3.3594635,300.0,0.95857638,1.2978303,0.86809087,335.60529,-9.3406916
145.4897,0.51000077,9.0970087,0.0,0,3.7797422,300.0,0.93228477,2.8588777,1.512069,336.38995,-9.3392696
145.4919,-0.37317964,9.0706816,0.0,0,4.2000217,300.0,0.92863709,-1.686565,2.2614152,336.33633,-9.3381462
145.4941,-0.09253788,9.1198683,0.0,0,4.6203008,300.0,0.93532962,-0.70131379,2.9282179,334.92551,-9.3403168
145.4963,0.065242462,9.2645435,0.0,0,5.0405803,300.0,0.96101576,0.31859231,3.448499,333.51471,-9.3378973
145.4985,-0.32711014,9.4889421,0.0,0,5.4608593,300.0,1.0009936,-1.2540983,3.856317,332.10388,-9.3365622
145.5007,0.10585608,9.4593439,0.0,0,5.8811388,300.0,0.99669152,0.11652944,4.2426734,330.69305,-9.3347769
145.5029,-0.068284303,9.446537,0.0,0,6.3014183,300.0,0.99356914,-0.068105116,4.626369,327.70691,-9.3329592
145.5051,-0.12413079,9.4315786,0.0,0,6.7216969,300.0,0.99187738,-0.56285626,5.0250416,324.4328,-9.3334427
145.5073,0.077170528,9.4159451,0.0,0,7.1419768,300.0,0.98815352,0.20649959,5.4305038,321.15869,-9.3321342
145.5095,0.032673351,9.4255505,0.0,0,7.5622554,300.0,0.98991984,0.16308969,5.8541274,317.88458,-9.3317385
145.5117,-0.15609403,9.4371128,0.0,0,7.9825354,300.0,0.99143142,-0.61689305,6.2913928,315.05594,-9.3295488
145.5139,-0.16442315,9.4365292,0.0,0,8.4028139,300.0,0.99208784,-0.78992516,6.7355294,313.22311,-9.3292799
145.5161,-0.014715343,9.4292078,0.0,0,8.8230925,300.0,0.99049616,-0.20042421,7.1839323,311.39026,-9.3293123
145.5183,0.10189734,9.4290113,0.0,0,9.243372,300.0,0.99074632,0.4964155,7.6264133,309.55743,-9.3287783
145.5205,-0.097076245,9.4293451,0.0,0,9.6636515,300.0,0.99043787,-0.38130942,8.0597095,307.72458,-9.3272343
145.5227,-0.15865217,9.4265165,0.0,0,10.083931,300.0,0.99012619,-0.74169612,8.4864988,307.33929,-9.3266096
145.5249,-0.10740791,9.4218616,0.0,0,10.50421,300.0,0.98921782,-0.54045928,8.917016,307.37973,-9.3267336
145.5271,0.014482411,9.4278002,0.0,0,10.924489,300.0,0.99017984,0.029905269,9.3570728,307.4202,-9.3269138
145.5293,-0.10673364,9.4232912,0.0,0,11.344769,300.0,0.98970109,-0.44754753,9.7873154,307.46063,-9.3257284
145.5315,-0.090623312,9.429883,0.0,0,11.765047,300.0,0.99044222,-0.43443966,10.223242,307.48038,-9.3262796
145.5337,-0.091817312,9.4202137,0.0,0,12.185327,300.0,0.9890188,-0.462733,10.651807,307.43317,-9.3247643
145.5359,-0.037328348,9.4314995,0.0,0,12.605606,300.0,0.99056298,-0.21304908,11.081697,307.38599,-9.3258791
145.5381,0.084435232,9.4204817,0.0,0,13.025885,300.0,0.9893049,0.4676269,11.512031,307.33881,-9.325655
145.5403,-0.10169824,9.4276514,0.0,0,13.446164,300.0,0.98994374,-0.36957601,11.922587,307.29163,-9.3245144
145.5425,-0.10028484,9.4227333,0.0,0,13.866444,300.0,0.9897247,-0.46801484,12.341546,306.73926,-9.3253107
145.5447,-0.051038783,9.4318342,0.0,0,14.286723,300.0,0.99029422,-0.27334923,12.769493,305.97037,-9.3255911
145.5469,0.0061017824,9.4224234,0.0,0,14.707002,300.0,0.98971874,0.054206014,13.202667,305.20148,-9.3241014
145.5491,-0.079510719,9.4269285,0.0,0,15.127281,300.0,0.98953259,-0.40988743,13.645107,304.43262,-9.3244467
145.5513,-0.1251545,9.4188662,0.0,0,15.547561,300.0,0.98915917,-0.59259301,14.077794,303.63232,-9.3243093
145.5535,-0.089285485,9.4298725,0.0,0,15.967839,300.0,0.98978806,-0.46378994,14.521407,302.67142,-9.3241091
145.5557,0.065285191,9.4188404,0.0,0,16.388119,300.0,0.98927891,0.31191468,14.955873,301.71054,-9.3252287
145.5579,-0.043497603,9.4245434,0.0,0,16.808399,300.0,0.98902267,-0.11294133,15.377336,300.74966,-9.3239384
145.5601,-0.15334667,9.4212217,0.0,0,17.228678,300.0,0.98996282,-0.70556301,15.791132,299.78879,-9.3240709
145.5623,-0.059573457,9.4306841,3.6216757,0,17.648958,300.0,0.98979568,-0.33068994,16.202799,298.64938,-9.3241091
145.5645,-0.077694967,9.4219322,9.3953323,0,17.999975,300.0,0.98986757,-0.42031676,16.616135,297.40396,-9.3254414
145.5667,0.059616022,9.4256687,15.16899,0,18.0,300.0,0.98902041,0.20910284,17.031183,296.15851,-9.3255424
145.5689,-0.10322822,9.4212542,20.942646,0,18.0,300.0,0.99021643,-0.45206311,17.43465,294.91306,-9.3251963
145.5711,-0.025670283,9.4344301,26.191408,0,18.0,300.0,0.99044263,-0.1656035,17.793358,293.71808,-9.3256693
145.5733,-0.0094534736,9.4224167,26.191408,0,18.0,300.0,0.99024463,-0.033370327,18.102346,293.02768,-9.3253822
145.5755,-0.037614081,9.4325981,26.191408,0,18.0,300.0,0.99016219,-0.12837207,18.333216,292.33728,-9.3274269
145.5777,-0.069043994,9.4279957,26.191408,0,18.0,300.0,0.99143362,-0.32963121,18.479025,291.64688,-9.3313274
145.5799,-0.099960953,9.44415,26.191408,0,18.0,300.0,0.99176371,-0.47768697,18.50762,290.95648,-9.3370495
145.5821,-0.076199733,9.4400206,27.225538,0,18.0,300.0,0.99350601,-0.36207783,18.44416,290.57385,-9.344655
145.5843,-0.043395758,9.4557323,29.090349,0,18.0,300.0,0.99441606,-0.1878126,18.319777,290.43848,-9.3546
145.5865,-0.080918387,9.4606581,30.955162,0,18.0,300.0,0.99754465,-0.35428497,18.204025,290.3031,-9.3673086
145.5887,-0.060723819,9.4862604,32.819977,0,18.0,300.0,0.99956858,-0.34536463,18.11709,290.16769,-9.3817787
145.5909,0.04489892,9.4926233,34.650879,0,18.0,300.0,1.0031166,0.12746979,18.065289,290.02936,-9.3989182
145.5931,0.076354973,9.5156374,34.650879,0,18.0,300.0,1.0050697,0.36611316,18.052134,289.7308,-9.4161777
145.5953,0.011811109,9.5279808,34.650879,0,18.0,300.0,1.0096427,0.10041995,18.051893,289.43225,-9.4331255
145.5975,-0.075079992,9.5570316,34.650879,0,18.0,300.0,1.012134,-0.28904411,18.060904,289.1337,-9.4532919
145.5997,-0.14591399,9.5632648,34.650879,0,18.0,300.0,1.0159605,-0.59159666,18.079092,288.83511,-9.4704742
145.6019,-0.16308597,9.5886765,35.138638,0,18.0,300.0,1.0184258,-0.75053126,18.097166,288.47784,-9.4870939
145.6041,-0.12837532,9.5998859,36.150967,0,18.0,300.0,1.0230104,-0.63590169,18.119305,288.05737,-9.5042114
145.6063,-0.036232825,9.6233692,37.163296,0,18.0,300.0,1.0244195,-0.26407397,18.13151,287.63693,-9.519208
145.6085,0.024385076,9.6273966,38.175621,0,18.0,300.0,1.0279962,0.047292914,18.133156,287.21646,-9.5347776
145.6107,0.071150228,9.6467314,39.187946,0,18.0,300.0,1.0291269,0.27145606,18.136267,286.79599,-9.5502319
145.6129,0.047367312,9.6589708,39.243164,0,18.0,300.0,1.0337533,0.23769334,18.133692,286.67017,-9.5645256
145.6151,-0.053799268,9.6837282,39.243164,0,18.0,300.0,1.0358088,-0.18739219,18.138414,286.56134,-9.5807133
145.6173,-0.11869962,9.6936464,39.243164,0,18.0,300.0,1.0403172,-0.48990089,18.13269,286.45251,-9.5965424
145.6195,-0.14500795,9.7129383,39.243164,0,18.0,300.0,1.0418141,-0.64895177,18.130396,286.34366,-9.612402
145.6217,-0.11997169,9.7234554,39.629562,0,18.0,300.0,1.0458882,-0.55579394,18.127131,286.05118,-9.6296568
145.6239,-0.076422162,9.7456188,40.574078,0,18.0,300.0,1.0477461,-0.4153201,18.126045,285.49341,-9.6438684
145.6261,0.00069533952,9.7538233,41.518593,0,18.0,300.0,1.0517327,-0.072986595,18.125069,284.93564,-9.6587954
145.6283,0.064805709,9.773284,42.463108,0,18.0,300.0,1.05321,0.24068023,18.121058,284.37784,-9.6742687
145.6305,0.064529352,9.7871628,43.407623,0,18.0,300.0,1.0580726,0.27893639,18.121439,283.82007,-9.6896105
145.6327,0.0061964355,9.8046703,43.527832,0,18.0,300.0,1.0590316,0.10870811,18.116148,283.16138,-9.7068424
145.6349,-0.099755444,9.8148785,43.527832,0,18.0,300.0,1.0631016,-0.35878968,18.117796,282.48798,-9.7223644
145.6371,-0.15327825,9.8353262,43.527832,0,18.0,300.0,1.0652239,-0.64592326,18.112276,281.81458,-9.7385454
145.6393,-0.14012586,9.8527298,43.527832,0,18.0,300.0,1.0705203,-0.61395681,18.111135,281.14117,-9.7542152
145.6415,-0.097272515,9.8723297,43.822727,0,18.0,300.0,1.0723201,-0.46935001,18.112621,280.61191,-9.7705421
145.6437,-0.027211275,9.8791714,44.699432,0,18.0,300.0,1.0754575,-0.18696193,18.109716,280.36703,-9.785471
145.6459,0.044475175,9.893589,45.576138,0,18.0,300.0,1.0766273,0.15311754,18.109863,280.12216,-9.8016024
145.6481,0.069666617,9.9123755,46.452843,0,18.0,300.0,1.082157,0.30840355,18.10935,279.87729,-9.817771
145.6503,0.035552364,9.9300051,47.329548,0,18.0,300.0,1.0838029,0.19145776,18.107014,279.63242,-9.8330164
145.6525,-0.052689981,9.9424849,47.504887,0,18.0,300.0,1.0879152,-0.16183352,18.104776,279.48547,-9.8499508
145.6547,-0.14217831,9.9606152,47.504887,0,18.0,300.0,1.0899719,-0.56899315,18.102966,279.36304,-9.865344
145.6569,-0.17259024,9.9817352,47.504887,0,18.0,300.0,1.0956582,-0.72958231,18.104652,279.2406,-9.8809252
145.6591,-0.11931468,9.9942179,47.504887,0,18.0,300.0,1.0966916,-0.51746881,18.104597,279.11816,-9.896883
145.6613,-0.04696903,10.007743,47.628754,0,18.0,300.0,1.1006647,-0.25432426,18.097961,278.94016,-9.9137239
145.6635,0.0097894697,10.020782,48.098587,0,18.0,300.0,1.1021585,-0.0020690234,18.101442,278.60684,-9.927516
145.6657,0.061446074,10.038795,48.568424,0,18.0,300.0,1.1069555,0.24449331,18.101923,278.27356,-9.9444246
145.6679,0.060121637,10.052121,49.038258,0,18.0,300.0,1.1086818,0.26549688,18.098213,277.94025,-9.9597387
145.6701,-0.0093250843,10.071863,49.508099,0,18.0,300.0,1.1132456,0.0035179814,18.092676,277.60696,-9.9753275
145.6723,-0.1102033,10.083939,49.63623,0,18.0,300.0,1.1151193,-0.38224733,18.097868,277.14996,-9.9911623
145.6745,-0.16880749,10.107484,49.63623,0,18.0,300.0,1.1204679,-0.66558534,18.097256,276.64664,-10.007207
145.6767,-0.14591265,10.118756,49.63623,0,18.0,300.0,1.1223488,-0.64340794,18.094097,276.14328,-10.024091
145.6789,-0.096078634,10.135943,49.63623,0,18.0,300.0,1.1262947,-0.42803589,18.095453,275.63992,-10.040818
145.6811,-0.0054587633,10.148051,49.762459,0,18.0,300.0,1.1285994,-0.038787995,18.091654,275.15863,-10.05593
145.6833,0.0440102,10.169004,50.423615,0,18.0,300.0,1.1329932,0.16202596,18.093628,274.77094,-10.071383
145.6855,0.062680103,10.178502,51.084778,0,18.0,300.0,1.1350099,0.25733885,18.089062,274.38321,-10.086952
145.6877,0.022749992,10.201168,51.745937,0,18.0,300.0,1.139611,0.15076645,18.091015,273.99548,-10.103158
145.6899,-0.058876034,10.21131,52.407101,0,18.0,300.0,1.1418036,-0.16360351,18.089563,273.60776,-10.11922
145.6921,-0.1566806,10.237678,52.635498,0,18.0,300.0,1.1468368,-0.53700536,18.090425,273.31778,-10.134937
145.6943,-0.16528668,10.244621,52.635498,0,18.0,300.0,1.1490259,-0.64038861,18.088587,273.07938,-10.149776
145.6965,-0.11559846,10.262115,52.635498,0,18.0,300.0,1.1522487,-0.51336706,18.088434,272.841,-10.166858
145.6987,-0.023683501,10.269762,52.635498,0,18.0,300.0,1.1544349,-0.14586934,18.088804,272.6026,-10.182238
145.7009,0.044405852,10.298324,52.687305,0,18.0,300.0,1.1593049,0.12788698,18.085829,272.35605,-10.197696
145.7031,0.062908821,10.303782,53.125656,0,18.0,300.0,1.1618508,0.25805873,18.084236,272.04846,-10.213819
145.7053,0.052670095,10.326278,53.564011,0,18.0,300.0,1.1654985,0.22121684,18.086796,271.74091,-10.229115
145.7075,-0.030175436,10.336209,54.002361,0,18.0,300.0,1.1685538,-0.041127343,18.085117,271.43332,-10.244495
145.7097,-0.1151126,10.35993,54.440716,0,18.0,300.0,1.172421,-0.38498679,18.082621,271.12576,-10.261087
145.7119,-0.17269564,10.369637,54.624023,0,18.0,300.0,1.1760778,-0.64638966,18.081738,270.84189,-10.277819
145.7141,-0.15166327,10.39212,54.624023,0,18.0,300.0,1.1795456,-0.62310892,18.079485,270.57504,-10.293583
145.7163,-0.067907907,10.400254,54.624023,0,18.0,300.0,1.1828957,-0.31222934,18.083296,270.3082,-10.310299
145.7185,0.040108811,10.424334,54.624023,0,18.0,300.0,1.1861273,0.078723133,18.081951,270.04135,-10.326875
145.7207,0.064418375,10.428858,54.639107,0,18.0,300.0,1.1891688,0.20541711,18.077269,269.77542,-10.341604
145.7229,0.049454417,10.451285,54.970901,0,18.0,300.0,1.1922396,0.20285538,18.077711,269.52911,-10.355994
145.7251,0.0065207644,10.461687,55.302689,0,18.0,300.0,1.1964395,0.050522394,18.076973,269.28281,-10.372409
145.7273,-0.083923571,10.489239,55.63448,0,18.0,300.0,1.2002486,-0.2613112,18.078815,269.03647,-10.38716
145.7295,-0.16018276,10.495283,55.966274,0,18.0,300.0,1.2040013,-0.58398718,18.077826,268.79016,-10.402507
145.7317,-0.16535228,10.520586,56.12915,0,18.0,300.0,1.2073611,-0.65273774,18.079741,268.47766,-10.419251
145.7339,-0.10826442,10.527351,56.12915,0,18.0,300.0,1.2114651,-0.44424799,18.07675,268.10135,-10.436053
145.7361,-0.013391244,10.551451,56.12915,0,18.0,300.0,1.2138855,-0.11463056,18.075869,267.72504,-10.452209
145.7383,0.059633888,10.556491,56.12915,0,18.0,300.0,1.2180352,0.19538063,18.075016,267.34872,-10.467548
145.7405,0.062112942,10.578823,56.12915,0,18.0,300.0,1.2202848,0.2250939,18.07913,266.97241,-10.483025
145.7427,0.0083284779,10.586876,56.546127,0,18.0,300.0,1.2252198,0.073351391,18.078094,266.6427,-10.497901
145.7449,-0.058988787,10.615774,56.974792,0,18.0,300.0,1.2281597,-0.16689503,18.075422,266.31427,-10.514358
145.7471,-0.11938407,10.622521,57.403458,0,18.0,300.0,1.2329378,-0.40130493,18.073793,265.98584,-10.53106
145.7493,-0.16788699,10.643416,57.832119,0,18.0,300.0,1.2349293,-0.60755801,18.07309,265.65744,-10.546502
145.7515,-0.14763217,10.653972,58.07373,0,18.0,300.0,1.2404193,-0.56663221,18.078741,265.32901,-10.562916
145.7537,-0.037256978,10.676794,58.07373,0,18.0,300.0,1.2421278,-0.22229858,18.070095,265.00058,-10.579627
145.7559,0.034075651,10.68053,58.07373,0,18.0,300.0,1.2466108,0.082193069,18.07168,264.67218,-10.595692
145.7581,0.073060714,10.701709,58.07373,0,18.0,300.0,1.2484508,0.26716003,18.072041,264.34375,-10.610041
145.7603,0.048956908,10.713299,58.07373,0,18.0,300.0,1.2541749,0.20745738,18.071636,264.01532,-10.625437
145.7625,-0.036894307,10.742732,58.42466,0,18.0,300.0,1.2574444,-0.071762554,18.069407,263.60684,-10.641984
145.7647,-0.11403754,10.75013,58.814575,0,18.0,300.0,1.2627931,-0.34938025,18.069099,263.18948,-10.658575
145.7669,-0.15339257,10.771344,59.204491,0,18.0,300.0,1.2645613,-0.53038549,18.069139,262.77213,-10.671986
145.7691,-0.1583966,10.780269,59.594406,0,18.0,300.0,1.2698175,-0.5978238,18.068689,262.35477,-10.688331
145.7713,-0.093106791,10.802529,59.842533,0,18.0,300.0,1.2715639,-0.35887733,18.065964,261.94238,-10.704267
145.7735,0.0094522014,10.8101,59.842533,0,18.0,300.0,1.2772117,-0.0032960137,18.065897,261.5387,-10.719918
145.7757,0.076041892,10.832003,59.842533,0,18.0,300.0,1.2789941,0.23845875,18.068331,261.13501,-10.735424
145.7779,0.063579075,10.842762,59.842533,0,18.0,300.0,1.284743,0.23810981,18.062307,260.73135,-10.751069
145.7801,0.003175416,10.864606,59.842533,0,18.0,300.0,1.2866728,0.078313887,18.058737,260.32767,-10.766988
145.7823,-0.075875573,10.87267,60.13905,0,18.0,300.0,1.2917736,-0.22946659,18.066538,259.99756,-10.783675
145.7845,-0.1429964,10.893095,60.497486,0,18.0,300.0,1.2941287,-0.47854182,18.062428,259.6828,-10.79789
145.7867,-0.14519654,10.909292,60.855915,0,18.0,300.0,1.3011569,-0.50107652,18.062056,259.36807,-10.814588
145.7889,-0.11575168,10.930337,61.214348,0,18.0,300.0,1.3028615,-0.43642116,18.063316,259.05331,-10.832252
145.7911,-0.031848624,10.936937,61.468506,0,18.0,300.0,1.3075514,-0.17684533,18.058849,258.76447,-10.847836
145.7933,0.062107086,10.953239,61.468506,0,18.0,300.0,1.3087647,0.18071857,18.06118,258.53867,-10.863881
145.7955,0.080725938,10.969478,61.468506,0,18.0,300.0,1.3156036,0.27912161,18.060246,258.3129,-10.877817
145.7977,0.029403508,10.988974,61.468506,0,18.0,300.0,1.3174009,0.13841572,18.059301,258.0871,-10.894551
145.7999,-0.061725084,11.001076,61.468506,0,18.0,300.0,1.3231016,-0.15284786,18.060736,257.86133,-10.910855
145.8021,-0.12471911,11.017572,61.682312,0,18.0,300.0,1.3247833,-0.36300606,18.06287,257.59378,-10.92734
145.8043,-0.16279083,11.033971,61.965668,0,18.0,300.0,1.3315088,-0.51816648,18.060822,257.31265,-10.942493
145.8065,-0.13618395,11.054505,62.24902,0,18.0,300.0,1.334188,-0.49931905,18.059258,257.03156,-10.959544
145.8087,-0.067769684,11.066374,62.532375,0,18.0,300.0,1.3397152,-0.26932287,18.059744,256.75043,-10.975659
145.8109,0.0168496,11.076845,62.753906,0,18.0,300.0,1.340286,-0.0055090603,18.057947,256.47668,-10.989388
145.8131,0.086696744,11.09295,62.753906,0,18.0,300.0,1.3461186,0.25881377,18.055508,256.22934,-11.004653
145.8153,0.061903208,11.110545,62.753906,0,18.0,300.0,1.3485962,0.23173414,18.05752,255.98201,-11.02029
145.8175,-0.013780471,11.129624,62.753906,0,18.0,300.0,1.3553367,0.013761036,18.056883,255.73468,-11.035911
145.8197,-0.10828705,11.144311,62.753906,0,18.0,300.0,1.3575174,-0.30506471,18.056608,255.48735,-11.052271
145.8219,-0.15522332,11.162656,62.907478,0,18.0,300.0,1.3639942,-0.49391243,18.055958,255.26308,-11.069341
145.8241,-0.16039111,11.176435,63.132702,0,18.0,300.0,1.3659756,-0.52437633,18.055206,255.04955,-11.08638
145.8263,-0.095342249,11.194974,63.357937,0,18.0,300.0,1.3724433,-0.34150052,18.056849,254.836,-11.102919
145.8285,0.00099332724,11.208274,63.583168,0,18.0,300.0,1.3745819,-0.039451703,18.052704,254.62247,-11.118797
145.8307,0.057445232,11.226284,63.775635,0,18.0,300.0,1.3804525,0.14019862,18.053776,254.40092,-11.13499
145.8329,0.08424063,11.235998,63.775635,0,18.0,300.0,1.3820412,0.24861646,18.053274,254.13229,-11.149873
145.8351,0.024643667,11.254521,63.775635,0,18.0,300.0,1.3877934,0.10434731,18.052805,253.86366,-11.164406
145.8373,-0.073481306,11.268744,63.775635,0,18.0,300.0,1.3910065,-0.18245965,18.052158,253.59502,-11.17942
145.8395,-0.15112136,11.293876,63.775635,0,18.0,300.0,1.3979903,-0.46748105,18.051762,253.32639,-11.195598
145.8417,-0.17128363,11.30373,63.880371,0,18.0,300.0,1.4005251,-0.5228191,18.052029,253.11649,-11.212294
145.8439,-0.13165253,11.31861,64.052322,0,18.0,300.0,1.4048065,-0.44496232,18.051048,252.94429,-11.228502
145.8461,-0.030232806,11.329461,64.224266,0,18.0,300.0,1.4077001,-0.13993758,18.047817,252.77209,-11.244583
145.8483,0.036344267,11.353214,64.396217,0,18.0,300.0,1.4137963,0.070153795,18.048412,252.59988,-11.25996
145.8505,0.077331208,11.360209,64.555664,0,18.0,300.0,1.4162031,0.21839668,18.047073,252.43019,-11.274766
145.8527,0.058542494,11.380298,64.555664,0,18.0,300.0,1.4215826,0.21458384,18.053242,252.29243,-11.289219
145.8549,-0.026825339,11.393732,64.555664,0,18.0,300.0,1.4256709,0.0042700814,18.047184,252.15468,-11.306872
145.8571,-0.12690778,11.419724,64.555664,0,18.0,300.0,1.4317433,-0.35574055,18.045609,252.01691,-11.323252
145.8593,-0.17704023,11.426908,64.555664,0,18.0,300.0,1.4350703,-0.53074771,18.045853,251.87915,-11.34024
145.8615,-0.14475653,11.446383,56.92276,0,18.0,300.0,1.4395123,-0.4597849,18.046921,251.69336,-11.356018
145.8637,-0.059329983,11.453393,42.692055,0,18.0,300.0,1.4427824,-0.22902958,18.043669,251.46605,-11.370926
146.764,-0.04802138,11.576999,0.0,0,18.0,1.6216742e-10,1.4773134,-0.13999739,18.001272,63.610722,-11.48484
147.864,-0.042168316,11.576811,0.0,0,18.0,1.6196896e-25,1.4776511,-0.12283401,18.000711,30.280691,-11.484281
148.964,-0.043430261,11.578094,0.0,0,18.0,1.617715e-40,1.4777249,-0.12812601,17.99983,26.072128,-11.484048
150.064,-0.047295358,11.578553,0.0,0,18.0,1.4012985e-45,1.4779979,-0.13421315,17.999723,25.321997,-11.484303
151.164,-0.041412514,11.579476,0.0,0,18.0,1.4012985e-45,1.4781976,-0.11864021,18.000437,25.181767,-11.485282
152.264,-0.047970064,11.579726,0.0,0,18.0,1.4012985e-45,1.4784325,-0.14022087,18.000832,25.099083,-11.485579
153.364,-0.046907403,11.579806,0.0,0,18.0,1.4012985e-45,1.4784751,-0.13507238,18.000256,24.97121,-11.485097
154.464,-0.042406924,11.579906,0.0,0,18.0,1.4012985e-45,1.4781104,-0.12480301,18.000345,24.970295,-11.484835
155.564,-0.049679156,11.579807,0.0,0,18.0,1.4012985e-45,1.4785883,-0.14572562,17.999638,24.860094,-11.484267
156.664,-0.044914525,11.579988,0.0,0,18.0,1.4012985e-45,1.4782934,-0.12993154,17.999134,24.806025,-11.484179
157.764,-0.046137352,11.58028,0.0,0,18.0,1.4012985e-45,1.4783847,-0.13814032,18.000708,24.770872,-11.48438
158.864,-0.049193259,11.581144,0.0,0,18.0,1.4012985e-45,1.4787213,-0.14221294,17.999519,24.731472,-11.484468
159.964,-0.043383121,11.58114,0.0,0,18.0,1.4012985e-45,1.4787724,-0.12453587,18.000416,24.739336,-11.484461
161.064,-0.048808925,11.58163,0.0,0,18.0,1.4012985e-45,1.4790841,-0.14263,17.999989,24.672306,-11.484633
162.164,-0.049028259,11.581635,0.0,0,18.0,1.4012985e-45,1.4786627,-0.14013362,17.999163,24.568935,-11.484769
163.264,-0.043549865,11.581897,0.0,0,18.0,1.4012985e-45,1.4791979,-0.12744534,18.000439,24.521849,-11.484484
164.364,-0.051018916,11.582586,0.0,0,18.0,1.4012985e-45,1.4790994,-0.14645074,18.000113,24.622541,-11.484578
165.464,-0.046588536,11.58271,0.0,0,18.0,1.4012985e-45,1.4791174,-0.13245995,17.999113,24.609606,-11.484847
166.564,-0.045596804,11.5825,0.0,0,18.0,1.4012985e-45,1.4792202,-0.13236229,17.99959,24.531176,-11.484739
167.664,-0.051316779,11.583072,0.0,0,18.0,1.4012985e-45,1.4792808,-0.14716901,17.999554,24.540836,-11.484679
168.764,-0.04467319,11.58285,0.0,0,18.0,1.4012985e-45,1.4794514,-0.12713723,18.000076,24.455051,-11.484718
169.864,-0.048165265,11.583685,0.0,0,18.0,1.4012985e-45,1.4793019,-0.14268914,17.998959,24.512724,-11.484563
170.964,-0.050183777,11.583075,0.0,0,18.0,1.4012985e-45,1.4795551,-0.14393446,17.999996,24.476082,-11.48455
172.064,-0.044240523,11.583587,0.0,0,18.0,1.4012985e-45,1.4794513,-0.12674238,18.000319,24.395634,-11.484351
173.164,-0.050744239,11.584398,0.0,0,18.0,1.4012985e-45,1.4795495,-0.14930114,18.000523,24.417782,-11.484519
174.264,-0.047968242,11.584636,0.0,0,18.0,1.4012985e-45,1.4798099,-0.13802163,17.999853,24.483831,-11.483856
175.364,-0.045984391,11.584771,0.0,0,18.0,1.4012985e-45,1.4797356,-0.13638559,17.999582,24.489237,-11.484059
176.464,-0.052546009,11.584661,0.0,0,18.0,1.4012985e-45,1.4799513,-0.14978565,17.999907,24.339567,-11.484218
177.564,-0.046018258,11.585128,0.0,0,18.0,1.4012985e-45,1.4797102,-0.1324432,17.999916,24.335209,-11.484151
178.664,-0.04984165,11.585454,0.0,0,18.0,1.4012985e-45,1.480219,-0.1468332,17.999868,24.334513,-11.484302
179.764,-0.051858526,11.586038,0.0,0,18.0,1.4012985e-45,1.4801792,-0.15147984,17.999603,24.337297,-11.484231
180.864,-0.044374879,11.586223,0.0,0,18.0,1.4012985e-45,1.4800608,-0.12922618,17.999983,24.306002,-11.484089
181.964,-0.052302416,11.586155,0.0,0,18.0,1.4012985e-45,1.4803087,-0.15215935,17.999954,24.187712,-11.484674
183.064,-0.049996752,11.58671,0.0,0,18.0,1.4012985e-45,1.480285,-0.14240418,18.000244,24.273184,-11.48496
184.164,-0.047707368,11.586308,0.0,0,18.0,1.4012985e-45,1.4804157,-0.13862447,17.999416,24.276112,-11.484506
185.264,-0.052211836,11.587153,0.0,0,18.0,1.4012985e-45,1.4803566,-0.15281971,18.000063,24.279152,-11.484629
186.364,-0.0462589,11.587267,0.0,0,18.0,1.4012985e-45,1.4807423,-0.13162321,17.999237,24.326891,-11.484546
187.464,-0.048881654,11.588067,0.0,0,18.0,1.4012985e-45,1.480798,-0.14563029,18.00017,24.230679,-11.484129
188.564,-0.052741665,11.587693,0.0,0,18.0,1.4012985e-45,1.480481,-0.15116221,18.001257,24.305841,-11.48419
189.664,-0.046661317,11.587652,0.0,0,18.0,1.4012985e-45,1.4807645,-0.13546887,18.000372,24.278418,-11.483685
190.764,-0.052033577,11.587368,0.0,0,18.0,1.4012985e-45,1.4804498,-0.15153213,18.000134,24.284735,-11.483559
191.864,-0.049090046,11.587715,0.0,0,18.0,1.4012985e-45,1.4808521,-0.1432098,18.000196,24.181496,-11.483403
192.964,-0.046451669,11.587956,0.0,0,18.0,1.4012985e-45,1.4805616,-0.13483866,17.999786,24.166252,-11.48346
194.064,-0.054541849,11.587701,0.0,0,18.0,1.4012985e-45,1.4808854,-0.15834446,18.000475,24.199608,-11.483398
195.164,-0.046442214,11.588778,0.0,0,18.0,1.4012985e-45,1.4809743,-0.13516295,17.999435,24.207907,-11.482784
196.264,-0.048750665,11.58875,0.0,0,18.0,1.4012985e-45,1.4808195,-0.1467797,17.998745,24.160412,-11.483372
197.364,-0.052833173,11.588923,0.0,0,18.0,1.4012985e-45,1.481096,-0.1518762,17.999603,24.117813,-11.483294
198.464,-0.04638109,11.588722,0.0,0,18.0,1.4012985e-45,1.4809293,-0.13189036,18.000343,24.136646,-11.482868
199.564,-0.052769035,11.588862,0.0,0,18.0,1.4012985e-45,1.4811761,-0.15463118,17.999222,24.247583,-11.482659
200.664,-0.049413648,11.589159,0.0,0,18.0,1.4012985e-45,1.4808693,-0.13868359,17.999298,24.128777,-11.483
201.764,-0.046746623,11.588895,0.0,0,18.0,1.4012985e-45,1.4812558,-0.13556798,18.000158,24.127192,-11.483018
202.864,-0.054107837,11.589383,0.0,0,18.0,1.4012985e-45,1.4811263,-0.15194559,17.999723,24.130089,-11.48315
203.964,-0.047514755,11.590227,0.0,0,18.0,1.4012985e-45,1.4812509,-0.13650863,18.000118,24.172419,-11.483262
205.064,-0.049570434,11.589972,0.0,0,18.0,1.4012985e-45,1.4814,-0.14353064,18.000423,24.045687,-11.482864
205.864,-0.04991873,11.589864,0.0,0,18.0,1.4012985e-45,1.4811999,-0.14815786,17.999096,24.164282,-11.483389