File: examples/dan-msc-case-studies/CS3/data/01 raw data/baron_test_071.csv
Time(sec),Force(kN),Jaw(mm),PowAngle(deg),Power(W),Pram,PTemp,Strain,Stress(MPa),Stroke(mm),TC1(C),wedge(mm)
0.0,0.90140522,0.43857718,0.0,0,10.594783,0.00096583861,0.029649289,11.128036,10.595376,24.618372,-9.1260386
2.2,0.81235105,-0.0018848175,0.0,0,10.594783,6.5158744,-0.00014156394,10.348295,10.596429,24.388563,-9.4919271
4.4,0.78149319,-0.0020323554,0.0,0,10.594783,13.115875,-0.00015074515,9.9504776,10.595168,24.403851,-9.4888611
6.6,0.75289255,-0.0024048337,0.0,0,10.594783,19.715876,-0.00015688468,9.583005,10.594314,24.376635,-9.4847574
8.8,0.73017538,-0.0022563052,10.717062,0,10.594783,26.31588,-0.00012529982,9.2894363,10.594959,24.434418,-9.4799166
11.0,0.75357127,-0.0041052024,32.845139,0,10.594783,32.915867,-0.00025421206,9.604248,10.5947,27.572529,-9.4768476
13.2,0.7621749,-0.010776144,34.948181,0,10.594783,39.515873,-0.00070704712,9.718009,10.595046,36.742538,-9.4730673
15.4,0.7605536,-0.014832675,34.638615,0,10.594783,46.115879,-0.00097730686,9.6765089,10.594655,45.077351,-9.4694586
17.6,0.76150823,-0.020011736,35.496826,0,10.594783,52.715889,-0.0013454173,9.7129278,10.594723,51.853233,-9.465169
19.8,0.76968312,-0.024476605,35.68755,0,10.594783,59.315891,-0.0016148648,9.8135967,10.59476,58.799019,-9.4612484
22.0,0.77247697,-0.029378688,36.309811,0,10.594783,65.915871,-0.001946817,9.860342,10.59462,65.531281,-9.4569693
24.2,0.77978474,-0.034714662,37.742985,0,10.594783,72.515877,-0.0023070055,9.9444628,10.595132,71.835304,-9.453414
26.4,0.77944678,-0.039288364,37.165951,0,10.594783,79.115883,-0.0026392199,9.958415,10.595379,78.913719,-9.4498701
28.6,0.78815395,-0.044290669,37.836388,0,10.594783,85.715897,-0.0029672231,10.064221,10.594586,85.489769,-9.4454288
30.8,0.79191703,-0.048250329,38.476204,0,10.594783,92.31588,-0.0032284607,10.112733,10.595031,91.924751,-9.4415369
33.0,0.79060555,-0.054104216,39.24316,0,10.594783,98.915878,-0.0036054985,10.10419,10.59487,98.304283,-9.4374018
35.2,0.80865169,-0.059085533,39.24316,0,10.594783,105.51588,-0.003929643,10.343608,10.594434,105.3163,-9.4338989
37.4,0.80257618,-0.064354829,39.24316,0,10.594783,112.11588,-0.0042588343,10.280491,10.594738,112.00594,-9.4300585
39.6,0.82054651,-0.069797494,39.254013,0,10.594783,118.71588,-0.0046160654,10.483366,10.593951,118.44542,-9.4258957
41.8,0.81302893,-0.074167237,39.924313,0,10.594783,125.31588,-0.0049167192,10.399223,10.594069,125.00298,-9.4217701
44.0,0.82383907,-0.07969296,40.572506,0,10.594783,131.91589,-0.0052984678,10.558328,10.594537,131.52731,-9.4182415
46.2,0.82815737,-0.086229227,40.6604,0,10.594783,138.51587,-0.0057322411,10.598735,10.594722,138.22079,-9.4144716
48.4,0.8356908,-0.089942902,40.271221,0,10.594783,145.11589,-0.0059743105,10.703575,10.5937,145.42523,-9.4109402
50.6,0.8369453,-0.094252147,40.946201,0,10.594783,151.7159,-0.0062631438,10.72404,10.594752,151.31013,-9.4069357
52.8,0.84382641,-0.10031622,41.802975,0,10.594783,158.31589,-0.006682063,10.816406,10.595439,157.6329,-9.4027185
55.0,0.8589558,-0.10716559,41.803089,0,10.594783,164.91588,-0.0071525536,11.006745,10.594561,164.5135,-9.3985519
57.2,0.8520143,-0.11005495,40.573269,0,10.594783,171.51588,-0.0073267929,10.917856,10.59576,171.95787,-9.3954325
59.4,0.85945636,-0.11584739,43.137363,0,10.594783,178.11589,-0.0077003855,11.044253,10.59457,176.98534,-9.3918829
61.6,0.86520672,-0.12203376,42.994633,0,10.594783,184.7159,-0.008093005,11.10499,10.594419,184.26657,-9.3879833
63.8,0.85929298,-0.1284364,43.527828,0,10.594783,191.3159,-0.0084983734,11.037444,10.595634,190.90739,-9.3838367
66.0,0.87839538,-0.13525026,43.223358,0,10.594783,197.91591,-0.0089514432,11.278105,10.594984,197.87575,-9.379899
68.2,0.88504922,-0.13881953,43.756775,0,10.594783,204.51591,-0.0092048673,11.378568,10.594958,204.1272,-9.3764868
70.4,0.88363725,-0.14568827,44.604488,0,10.594783,211.11591,-0.0096682301,11.367071,10.594766,210.48,-9.3726368
72.6,0.88076252,-0.15248922,45.12085,0,10.594783,217.7159,-0.010101218,11.329225,10.594816,217.23076,-9.3694506
74.8,0.90907067,-0.15824305,45.615231,0,10.594783,224.31589,-0.010488615,11.714922,10.595439,223.74307,-9.365881
77.0,0.90230179,-0.16482317,45.627907,0,10.594783,230.91588,-0.010932507,11.620168,10.593375,230.57106,-9.3616457
79.2,0.89353585,-0.17130174,46.109619,0,10.594783,237.51588,-0.011376688,11.498406,10.594243,237.1144,-9.357542
81.4,0.91264206,-0.17818603,46.581913,0,10.594783,244.11589,-0.011832844,11.760149,10.594552,243.72229,-9.3539591
83.6,0.90749353,-0.18530321,46.324585,0,10.594783,250.7159,-0.012294836,11.702484,10.594344,250.62561,-9.3503704
85.8,0.91079938,-0.19085647,46.568638,0,10.594783,257.31619,-0.01264241,11.738582,10.594404,257.27292,-9.3467188
88.0,0.90433347,-0.19779766,46.576012,0,10.594783,263.91589,-0.013076629,11.663463,10.595119,263.82135,-9.3432064
90.2,0.92042732,-0.20299004,46.800133,0,10.594783,270.5159,-0.013416884,11.885154,10.594821,270.25858,-9.3395033
92.4,0.90880752,-0.21056087,47.05444,0,10.594783,277.11588,-0.013927394,11.725124,10.595208,276.81784,-9.3355951
94.6,0.92357808,-0.21692561,47.504883,0,10.594783,283.71588,-0.014357391,11.926874,10.594177,283.32721,-9.3318233
96.8,0.91637707,-0.22450399,47.504883,0,10.594783,290.31589,-0.014853845,11.838013,10.594323,290.15735,-9.3278456
99.0,0.91983396,-0.23168714,47.504883,0,10.594783,296.91589,-0.015321942,11.891308,10.595028,296.86456,-9.3240013
101.2,0.9277283,-0.23987412,47.504883,0,10.594783,303.5159,-0.01584932,12.006047,10.596343,303.40479,-9.3200817
103.4,0.92315227,-0.24513502,47.952023,0,10.594783,310.11591,-0.016216269,11.943446,10.59438,309.90573,-9.3168888
105.6,0.92752421,-0.25348863,47.955318,0,10.594783,316.71588,-0.016775459,12.008888,10.595243,316.45212,-9.3132715
107.8,0.926085,-0.25865972,48.383785,0,10.594783,323.31592,-0.017104756,12.005671,10.593296,322.97284,-9.3093605
110.0,0.9433189,-0.26634392,48.812252,0,10.594783,329.91589,-0.017606637,12.218387,10.594985,329.50974,-9.3054876
112.2,0.93240374,-0.27218714,48.812294,0,10.594783,336.51587,-0.017977471,12.072099,10.594565,336.17075,-9.3020267
114.4,0.92523813,-0.279394,49.24696,0,10.594783,343.11588,-0.018425034,12.005699,10.594482,342.60062,-9.2977133
116.6,0.93329829,-0.28679273,49.63554,0,10.594783,349.71588,-0.018915903,12.112599,10.595296,349.40695,-9.2940493
118.8,0.94523048,-0.29351634,49.636227,0,10.594783,356.31592,-0.019368816,12.261063,10.59483,355.91824,-9.2905903
121.0,0.93466347,-0.30095476,49.749718,0,10.594783,362.91589,-0.019864986,12.140725,10.594367,362.76199,-9.2871027
123.2,0.92566121,-0.30755222,50.042721,0,10.594783,369.51593,-0.020288898,12.024145,10.595113,369.33551,-9.2832317
125.4,0.94707143,-0.3145113,50.050453,0,10.594783,376.11591,-0.020733431,12.328175,10.593488,375.88452,-9.2793474
127.6,0.92664427,-0.32260552,50.438229,0,10.594783,382.71591,-0.021293165,12.050734,10.594444,382.34033,-9.275156
129.8,0.93817478,-0.32890171,50.82275,0,10.594783,389.31589,-0.021708032,12.205542,10.595135,388.81918,-9.2719994
132.0,0.93010175,-0.33777657,51.059662,0,10.594783,395.91586,-0.022275312,12.109702,10.595649,395.48859,-9.2681694
134.2,0.95107985,-0.3441979,51.222778,0,10.594783,402.51587,-0.022687456,12.399841,10.593813,402.20901,-9.2641821
136.4,0.9378252,-0.35377508,51.567921,0,10.594783,409.11588,-0.023285413,12.223202,10.594956,408.80893,-9.261055
138.6,0.95741844,-0.36115053,51.278198,0,10.594783,415.71588,-0.023781376,12.471827,10.595269,415.65698,-9.2571621
140.8,0.94521558,-0.36834493,51.196293,0,10.594783,422.31589,-0.024259744,12.330671,10.594413,422.47723,-9.2537203
143.0,0.94818032,-0.3782796,51.3549,0,10.594783,428.91592,-0.024896329,12.37067,10.595515,428.84952,-9.2496185
145.2,0.94994688,-0.3830314,51.431213,0,10.594783,435.51593,-0.025203485,12.421063,10.595181,435.50809,-9.2458076
147.4,0.94364673,-0.39010206,51.387501,0,10.594783,442.11591,-0.025693275,12.287196,10.595585,442.095,-9.2420092
149.6,0.95643461,-0.39680499,51.300327,0,10.594783,448.71591,-0.026135437,12.503827,10.594594,448.78183,-9.2383242
151.8,0.063351035,-0.41309616,50.292458,0,10.594783,449.9989,-0.027188208,0.84260714,10.595309,450.79892,-9.2373867
154.0,0.072499603,-0.4144502,49.636234,0,10.594783,449.9989,-0.027252588,0.94029152,10.594933,450.9201,-9.2377815
156.2,0.067550175,-0.41231644,48.831799,0,10.594783,449.9989,-0.027105836,0.88155842,10.593763,450.85846,-9.2378769
158.4,0.055575956,-0.41247332,49.16938,0,10.594783,449.9989,-0.027112572,0.723306,10.595372,450.24387,-9.2380619
160.6,0.077896528,-0.41346329,49.636227,0,10.594783,449.9989,-0.027182747,1.0188673,10.594894,449.71313,-9.2379398
162.8,0.078256197,-0.41297144,49.787106,0,10.594783,449.9989,-0.027153272,1.0211791,10.594526,449.73663,-9.2377691
165.0,0.058397084,-0.41413486,49.636234,0,10.594783,449.9989,-0.027235124,0.75454462,10.595822,449.91852,-9.2365704
167.2,0.090978451,-0.41443652,49.636234,0,10.594783,449.9989,-0.027252097,1.1902356,10.594919,450.08896,-9.2369528
169.4,0.072008707,-0.41631037,49.22974,0,10.594783,449.9989,-0.027394764,0.94640321,10.595262,450.27893,-9.2367811
171.6,0.087368459,-0.41732851,49.22974,0,10.594783,449.9989,-0.027467078,1.1614014,10.595129,450.20947,-9.2367163
173.8,0.08590734,-0.41779119,49.22974,0,10.594783,449.9989,-0.027481323,1.1415988,10.594568,450.16995,-9.236824
176.0,0.099318534,-0.42071706,49.046257,0,10.594783,449.9989,-0.027653305,1.2882779,10.595373,450.13275,-9.2374449
178.2,0.080812559,-0.42003402,49.229733,0,10.594783,449.9989,-0.027573826,1.0401483,10.595531,450.05655,-9.2363348
180.4,0.10071439,-0.42233518,49.229733,0,10.594783,449.9989,-0.027751608,1.3213763,10.594989,450.08041,-9.2364311
182.6,0.091199227,-0.42182976,49.098827,0,10.594783,449.9989,-0.02773929,1.1902946,10.595091,450.0058,-9.2369776
184.8,0.090271033,-0.42337689,49.138607,0,10.594783,449.9989,-0.027822046,1.1715616,10.595028,450.01761,-9.2368517
187.0,0.087894365,-0.42361099,49.129745,0,10.594783,449.9989,-0.027847964,1.1499796,10.594915,450.02264,-9.2371693
189.2,0.093427464,-0.4241842,48.928623,0,10.594783,449.9989,-0.027913745,1.221117,10.594918,450.04379,-9.2366495
191.4,0.086507708,-0.42558426,49.037251,0,10.594783,449.9989,-0.027993182,1.1239241,10.594783,449.97888,-9.2364998
193.6,0.094313256,-0.42693672,49.10397,0,10.594783,449.9989,-0.028076241,1.242875,10.595168,450.01328,-9.2358885
195.2847,0.2128443,0.0015902814,48.812256,0,10.5948,0.0060101803,0.00039351839,2.6419783,10.59173,450.189,-9.2368507
195.2891,0.24636392,-0.0003247647,48.812256,0,10.5948,5.9955178e-33,0.00017271249,3.136627,10.598396,450.14938,-9.237133
195.2935,0.21148041,0.0027128183,45.975357,0,10.5948,0.0,0.00042942193,2.6780879,10.595798,450.11502,-9.235424
195.2979,0.27560952,0.0021026894,24.454924,0,10.5948,0.0,0.00029893039,3.5800421,10.594616,450.11502,-9.2364302
195.3023,0.22163968,0.0024895465,2.934489,0,10.5948,0.0,0.00040461411,2.9021728,10.594366,450.11502,-9.2378321
195.3067,0.2229511,0.0027496971,0.0,0,10.5948,0.0,0.00036222386,2.8349118,10.593223,450.08081,-9.2354088
195.3111,0.21762684,0.0017259213,0.0,0,10.5948,0.0,0.00032103391,2.7531991,10.594925,450.04123,-9.2359781
195.3155,0.21166447,0.0035505032,0.0,0,10.5948,0.0,0.00035643388,2.5851755,10.593001,450.01733,-9.2359056
195.3199,0.2164976,0.002118693,0.0,0,10.5948,0.0,0.00027629954,2.7636881,10.592537,450.00412,-9.2362833
195.3243,0.22657581,0.0037226158,0.0,0,10.5948,0.0,0.00034688727,2.9104943,10.594816,450.00388,-9.2368364
195.3287,0.21719113,0.0017577697,0.0,0,10.5948,0.0,0.00023676614,2.8279545,10.594899,450.03027,-9.2369118
195.3331,0.2193224,0.0037779445,0.0,0,10.5948,0.0,0.00034986748,2.6977885,10.594566,450.05902,-9.2362156
195.3375,0.2339271,0.003001522,0.0,0,10.542864,0.0,0.00028492007,2.9023428,10.593777,450.12503,-9.2348003
195.3419,0.23729643,0.0041273073,0.0,0,10.476864,0.0,0.00041280795,3.0460918,10.588931,450.19104,-9.2355728
195.3463,0.23999719,0.0044152187,0.0,0,10.410864,0.0,0.00032308578,3.0255334,10.562879,450.16309,-9.2370186
195.3507,0.22861767,0.0048017008,0.0,0,10.344864,0.0,0.00044945991,2.8773413,10.482615,450.11029,-9.236495
195.3551,0.23257625,0.0054944111,0.0,0,10.278863,0.0,0.00036277014,2.9755511,10.379228,450.0575,-9.2361965
195.3595,0.2431187,0.0052192598,0.0,0,10.212864,0.0,0.00034109375,3.1063747,10.289601,450.0047,-9.2367344
195.3639,0.23866041,0.0051169205,0.0,0,10.146863,0.0,0.00030751523,3.045588,10.227231,449.97876,-9.2355862
195.3683,0.22520834,0.0068531376,0.0,0,10.080864,0.0,0.00048780063,2.8792651,10.173509,450.03156,-9.2366304
195.3727,0.24254709,0.004947654,0.0,0,10.014863,0.0,0.00029873298,3.0651953,10.114665,450.08435,-9.2351599
195.3771,1.850996,0.029119492,0.0,0,9.948863,0.0,0.0018299675,23.198696,10.048857,450.44968,-9.2353468
195.3815,3.7452257,0.064609259,0.0,0,9.882863,0.0,0.0041828565,47.417385,9.9911137,450.81931,-9.2343512
195.3859,4.3381629,0.13518351,0.0,0,9.8168631,0.0,0.0089211371,54.754974,9.9134827,451.60608,-9.2327557
195.3903,4.600409,0.20524292,0.0,0,9.7508631,0.0,0.013594741,57.728291,9.8414164,452.55655,-9.23318
195.3947,4.7369633,0.27574313,0.0,0,9.6848631,0.0,0.018394254,59.195084,9.7687788,453.40012,-9.2329674
195.3991,4.8095369,0.34048334,0.0,0,9.6188631,0.0,0.022787049,59.829479,9.7010345,454.11298,-9.2333746
195.4035,4.8426666,0.40623152,0.0,0,9.5528631,0.0,0.027240826,59.947849,9.6361675,454.71063,-9.2331419
195.4079,4.8914795,0.46923527,0.0,0,9.4868631,0.0,0.031566735,60.269695,9.5686817,454.78983,-9.2330227
195.4123,4.9515061,0.53626144,0.0,0,9.4223585,0.0,0.036127429,60.699589,9.502615,454.86902,-9.2333918
195.4167,5.0176096,0.59638143,0.0,0,9.3579779,0.0,0.04036852,61.306606,9.4391384,455.05679,-9.2341423
195.4211,5.0405469,0.66851103,0.0,0,9.2935972,0.0,0.045329113,61.259293,9.3662071,455.25479,-9.2332697
195.4255,5.0319905,0.73140085,0.0,0,9.2292166,0.0,0.049741238,60.961884,9.3025103,455.53802,-9.2338943
195.4299,5.0740995,0.79562181,0.0,0,9.164835,0.0,0.054166149,61.194283,9.2357368,455.86807,-9.2343664
195.4343,5.1055574,0.8566817,0.0,0,9.1004553,0.0,0.058541253,61.291904,9.1732512,456.16821,-9.2332516
195.4387,5.1613183,0.92273486,0.0,0,9.0360737,0.0,0.063101619,61.715107,9.1080294,456.41901,-9.2339001
195.4431,5.1618567,0.98463279,0.0,0,8.971693,0.0,0.067621648,61.490944,9.0459909,456.66119,-9.2351284
195.4475,5.1972718,1.0528299,0.0,0,8.9073124,0.0,0.072398305,61.427303,8.9772482,456.83279,-9.2337551
195.4519,5.2545843,1.1123207,0.0,0,8.8429308,0.0,0.076818384,61.929699,8.9100046,457.00443,-9.2335854
195.4563,5.2642922,1.1807082,0.0,0,8.7785501,0.0,0.081612214,61.857887,8.8441734,457.07614,-9.2354975
195.4607,5.2831311,1.2402395,0.0,0,8.7159328,0.0,0.086084306,61.759899,8.7804737,457.12894,-9.2340717
195.4651,5.311636,1.3094254,0.0,0,8.6547022,0.0,0.090967953,61.786617,8.712513,457.13638,-9.2340679
195.4695,5.3331308,1.3669684,0.0,0,8.5934715,0.0,0.095326588,61.666607,8.6514692,457.10999,-9.235384
195.4739,5.3384271,1.430274,0.0,0,8.5322428,0.0,0.099807464,61.460571,8.5909176,456.64536,-9.2339458
195.4783,5.3414879,1.4840713,0.0,0,8.4710112,0.0,0.10398681,61.289757,8.5341978,455.18002,-9.2335443
195.4827,5.3828225,1.5463251,0.0,0,8.4097815,0.0,0.10840815,61.483299,8.4733276,453.72192,-9.2345781
195.4871,5.459496,1.6076477,0.0,0,8.3485498,0.0,0.11316113,61.980007,8.4094181,452.45462,-9.2341509
195.4915,5.4738984,1.6734658,0.0,0,8.2873201,0.0,0.11799335,61.948151,8.3443871,451.18729,-9.2338734
195.4959,5.4787164,1.7305984,0.0,0,8.2260895,0.0,0.12241194,61.75272,8.2833347,451.04562,-9.2332392
195.5003,5.4879293,1.7962483,0.0,0,8.1648588,0.0,0.12729016,61.591064,8.2209988,451.24365,-9.2337828
195.5047,5.5361719,1.8527435,0.0,0,8.1036291,0.0,0.13164189,61.823223,8.1563787,451.44827,-9.2324905
195.5091,5.5737958,1.9175085,0.0,0,8.0429821,0.0,0.13650475,61.990761,8.0979233,451.65948,-9.2334776
195.5135,5.5983524,1.9738489,0.0,0,7.984726,0.0,0.14092767,61.889839,8.0301704,451.91663,-9.2340155
195.5179,5.5871873,2.0392222,0.0,0,7.9264693,0.0,0.14594288,61.533913,7.9728203,452.32587,-9.2345295
195.5223,5.5965691,2.0911987,0.0,0,7.8682137,0.0,0.15001698,61.274952,7.9133263,452.73508,-9.2345066
195.5267,5.6473441,2.1527953,0.0,0,7.8099575,0.0,0.15477724,61.614532,7.858357,453.15704,-9.2334824
195.5311,5.6597347,2.2073665,0.0,0,7.7517014,0.0,0.15906861,61.512867,7.7955003,453.57947,-9.2345133
195.5355,5.6883016,2.268296,0.0,0,7.6934457,0.0,0.16385683,61.482899,7.7328811,453.94684,-9.2337513
195.5399,5.6851954,2.3200333,0.0,0,7.6351895,0.0,0.16808654,61.098713,7.677289,454.29007,-9.2340631
195.5443,5.7247519,2.3777575,0.0,0,7.5769334,0.0,0.17256878,61.279568,7.6224556,454.64456,-9.2331524
195.5487,5.7631078,2.4313204,0.0,0,7.5186772,0.0,0.1769031,61.503036,7.5681601,455.01419,-9.2339163
195.5531,5.8151836,2.4933531,0.0,0,7.4604211,0.0,0.18184075,61.764587,7.5092854,455.37543,-9.232583
195.5575,5.8724465,2.5536089,0.0,0,7.4021654,0.0,0.18667085,62.036911,7.4414887,455.69226,-9.2343159
195.5619,5.8910551,2.6186466,0.0,0,7.346283,0.0,0.19200933,61.89447,7.3814678,456.00906,-9.2345991
195.5663,5.8556194,2.6724801,0.0,0,7.2908783,0.0,0.19627111,61.288208,7.3224216,456.18478,-9.233427
195.5707,5.8380404,2.7255585,0.0,0,7.2354732,0.0,0.20079327,60.817356,7.2681093,456.3432,-9.2340765
195.5751,5.8665214,2.7769792,0.0,0,7.1800685,0.0,0.20481974,60.891117,7.2163887,456.51804,-9.2337351
195.5795,5.9263172,2.8335528,0.0,0,7.1246629,0.0,0.20957901,61.20639,7.1618547,456.70285,-9.2332821
195.5839,5.9671955,2.8856313,0.0,0,7.0692587,0.0,0.21383409,61.3862,7.1072745,456.9017,-9.2330151
195.5883,5.9901414,2.9411929,0.0,0,7.0138535,0.0,0.2185521,61.309238,7.0477347,457.12613,-9.2334023
195.5927,6.0185547,2.9999981,0.0,0,6.9584489,0.0,0.22333558,61.231396,6.990839,457.34824,-9.2336521
195.5971,6.0492296,3.0544605,0.0,0,6.9030442,0.0,0.22800535,61.243793,6.9340754,457.54626,-9.2333679
195.6015,6.0698433,3.1072083,0.0,0,6.8476396,0.0,0.23243023,61.298637,6.8783298,457.74426,-9.2336416
195.6059,6.0629525,3.1606557,0.0,0,6.7922344,0.0,0.23689906,60.92915,6.8247294,457.27264,-9.2343397
195.6103,6.100275,3.2139468,0.0,0,6.7380919,0.0,0.24145694,60.962009,6.7696013,456.65219,-9.2341127
195.6147,6.1347408,3.2685049,0.0,0,6.68538,0.0,0.24614641,61.035351,6.7139401,455.4509,-9.2342539
195.6191,6.1932268,3.3225842,0.0,0,6.632668,0.0,0.25073633,61.387589,6.6582537,453.77435,-9.2328863
195.6235,6.1837163,3.3766887,0.0,0,6.5799561,0.0,0.25543189,60.957466,6.6030507,452.33966,-9.2331743
195.6279,6.1692739,3.4263072,0.0,0,6.5272441,0.0,0.25968522,60.617779,6.5553422,451.52118,-9.2338076
195.6323,6.2327614,3.480365,0.0,0,6.4745321,0.0,0.26445138,60.922424,6.5017328,450.71478,-9.2337065
195.6367,6.2614698,3.5316532,0.0,0,6.4218202,0.0,0.26874316,61.023132,6.4521365,450.78076,-9.2333097
195.6411,6.3058352,3.5832977,0.0,0,6.3691082,0.0,0.27337393,61.0863,6.3974481,450.84677,-9.2341785
195.6455,6.3300033,3.6391888,0.0,0,6.3163962,0.0,0.27820441,61.068771,6.3401728,450.87341,-9.2338705
195.6499,6.3580399,3.6923332,0.0,0,6.2636843,0.0,0.28296968,60.929493,6.287137,450.88663,-9.2336969
195.6543,6.3785486,3.7461076,0.0,0,6.2109723,0.0,0.28765026,60.956928,6.2323122,450.99432,-9.2347059
195.6587,6.4368091,3.7972372,0.0,0,6.1585317,0.0,0.29225549,61.233242,6.1774359,451.20557,-9.2338276
195.6631,6.4149094,3.8543482,0.0,0,6.1083975,0.0,0.29724953,60.640621,6.1281891,451.43057,-9.2349958
195.6675,6.4311738,3.9032872,0.0,0,6.0582643,0.0,0.30165249,60.565273,6.0722361,451.70779,-9.2337885
195.6719,6.4735518,3.9554083,0.0,0,6.0081306,0.0,0.30632114,60.686901,6.0243912,451.98502,-9.2345018
195.6763,6.4911704,4.0037341,0.0,0,5.9579968,0.0,0.3106325,60.594978,5.9728537,452.37402,-9.2331991
195.6807,6.4571471,4.0539622,0.0,0,5.9078636,0.0,0.31524196,60.03347,5.9237595,452.77005,-9.2335939
195.6851,6.4538441,4.0973101,0.0,0,5.8577299,0.0,0.31924003,59.754311,5.8789043,452.8819,-9.2331867
195.6895,6.565526,4.143826,0.0,0,5.8075962,0.0,0.32342866,60.498852,5.8268099,452.8555,-9.2337303
195.6939,6.6127548,4.1954818,0.0,0,5.7574625,0.0,0.32821348,60.719013,5.7761302,451.97461,-9.2333937
195.6983,6.6281905,4.2479782,0.0,0,5.7073288,0.0,0.33299899,60.528652,5.7314043,449.83603,-9.2329969
195.7027,6.6625237,4.2956209,0.0,0,5.6571956,0.0,0.3374992,60.570045,5.6746988,447.79108,-9.2323189
195.7071,6.7082372,4.3478107,0.0,0,5.6070614,0.0,0.34234902,60.57943,5.6257124,446.33896,-9.2344303
195.7115,6.7413549,4.400095,0.0,0,5.5587354,0.0,0.34715563,60.671452,5.5765862,444.88684,-9.2338076
195.7159,6.7784076,4.4506269,0.0,0,5.5110397,0.0,0.35190061,60.686245,5.5240922,445.01633,-9.2334309
195.7203,6.7289782,4.5000362,0.0,0,5.4633436,0.0,0.3565765,60.032944,5.4746075,445.38596,-9.2339592
195.7247,6.7435622,4.5468097,0.0,0,5.4156475,0.0,0.36098099,59.817703,5.4288521,445.5972,-9.2325106
195.7291,6.8076215,4.5920901,0.0,0,5.3679519,0.0,0.36537969,60.150707,5.3792791,445.70279,-9.2333136
195.7335,6.8133941,4.6412992,0.0,0,5.3202558,0.0,0.37001058,59.986588,5.3387094,445.9223,-9.2331133
195.7379,6.8535576,4.6849637,0.0,0,5.2725596,0.0,0.37435761,59.967983,5.2879,446.37115,-9.2330894
195.7423,6.906455,4.7392983,0.0,0,5.224864,0.0,0.37942287,60.130058,5.2389274,446.82755,-9.2336092
195.7467,6.9632759,4.784565,0.0,0,5.1771674,0.0,0.38388929,60.392941,5.1897526,447.39517,-9.2344599
195.7511,6.9473963,4.8374443,0.0,0,5.1294718,0.0,0.38899192,59.977188,5.1413126,447.96283,-9.2328129
195.7555,6.9673672,4.8789353,0.0,0,5.0817757,0.0,0.39319485,59.874725,5.0957103,448.57474,-9.2340841
195.7599,6.9953094,4.9297085,0.0,0,5.0349607,0.0,0.39805186,59.822777,5.0474205,449.19806,-9.2333555
195.7643,7.1066103,4.9760532,0.0,0,4.9895968,0.0,0.40263715,60.435642,4.9987931,449.17139,-9.234663
195.7687,7.099875,5.0304365,0.0,0,4.9442329,0.0,0.40809885,60.135265,4.952342,448.84134,-9.2330952
195.7731,7.0633588,5.0724387,0.0,0,4.898869,0.0,0.41236445,59.544918,4.9008036,448.39117,-9.2333174
195.7775,7.0624328,5.1170011,0.0,0,4.8535047,0.0,0.41672584,59.303741,4.8621759,447.77075,-9.2335167
195.7819,7.1256423,5.161005,0.0,0,4.8081408,0.0,0.42115328,59.546268,4.8177142,447.25208,-9.2332897
195.7863,7.1639233,5.2068982,0.0,0,4.7627769,0.0,0.42567706,59.575191,4.7739077,447.33127,-9.2347412
195.7907,7.2119055,5.2505088,0.0,0,4.7174129,0.0,0.43036824,59.694443,4.7278428,447.41049,-9.2349987
195.7951,7.2296462,5.2972064,0.0,0,4.6720486,0.0,0.43503174,59.549381,4.6807551,447.39706,-9.2346764
195.7995,7.2709618,5.3415842,0.0,0,4.6266847,0.0,0.43971828,59.60083,4.6347976,447.37064,-9.2346478
195.8039,7.3086791,5.3887696,0.0,0,4.5813208,0.0,0.44445294,59.751213,4.5925894,447.56134,-9.2340879
195.8083,7.3317757,5.4304447,0.0,0,4.5359983,0.0,0.44901747,59.519699,4.5463557,447.89136,-9.2331009
195.8127,7.3518758,5.4804254,0.0,0,4.4928331,0.0,0.45397103,59.445747,4.5020547,448.26639,-9.2344484
195.8171,7.3999028,5.5189314,0.0,0,4.4496775,0.0,0.45832396,59.577175,4.4551802,448.72842,-9.2332344
195.8215,7.455884,5.5696716,0.0,0,4.4065223,0.0,0.46336317,59.700588,4.4138522,449.19333,-9.2346525
195.8259,7.4331937,5.6072907,0.0,0,4.3633671,0.0,0.46764001,59.308796,4.3676724,449.69498,-9.2335043
195.8303,7.4776454,5.6559815,0.0,0,4.3202119,0.0,0.47269991,59.363064,4.327867,450.19662,-9.2333431
195.8347,7.5150237,5.6931658,0.0,0,4.2770567,0.0,0.4769665,59.38958,4.2821741,450.74075,-9.231905
195.8391,7.576148,5.7442336,0.0,0,4.2339015,0.0,0.48225754,59.519508,4.2428784,451.2952,-9.2333956
195.8435,7.6142435,5.7813601,0.0,0,4.1907463,0.0,0.48642048,59.573944,4.1942921,451.61597,-9.2330647
195.8479,7.6431355,5.8314538,0.0,0,4.1475911,0.0,0.49181637,59.487827,4.1552801,451.7348,-9.2337542
195.8523,7.6885152,5.8716431,0.0,0,4.1044359,0.0,0.49631345,59.58717,4.1071587,451.73679,-9.2335157
195.8567,7.7609143,5.9196143,0.0,0,4.0612807,0.0,0.50135881,59.83876,4.0649915,451.41995,-9.2331572
195.8611,7.7914357,5.9601412,0.0,0,4.0194993,0.0,0.50614071,59.79232,4.0149226,451.10312,-9.2328129
195.8655,7.7445278,6.00666,0.0,0,3.9784563,0.0,0.51121867,59.158249,3.9747307,450.50906,-9.2344122
195.8699,7.7530141,6.0444136,0.0,0,3.9374132,0.0,0.51555276,58.903397,3.9350774,449.91501,-9.23382
195.8743,7.7979846,6.0867882,0.0,0,3.8963699,0.0,0.52018082,59.039619,3.8976912,449.18573,-9.2343464
195.8787,7.8673434,6.1223688,0.0,0,3.8553267,0.0,0.52430111,59.259884,3.8590157,448.40686,-9.2330475
195.8831,7.8704338,6.1644912,0.0,0,3.8142834,0.0,0.52900028,59.039711,3.8174739,447.88507,-9.2331524
195.8875,7.9262629,6.2032886,0.0,0,3.7732403,0.0,0.53351617,59.151825,3.7770691,447.66064,-9.2334881
195.8919,8.0282459,6.2497211,0.0,0,3.732197,0.0,0.53891432,59.626411,3.7349679,447.64523,-9.2331314
195.8963,8.1008062,6.2874293,0.0,0,3.6911538,0.0,0.5433768,59.884224,3.6917846,448.49011,-9.2330894
195.9007,8.1075754,6.3330922,0.0,0,3.6501107,0.0,0.54855365,59.656422,3.6507843,449.33499,-9.233717
195.9051,8.0933685,6.371007,0.0,0,3.6090674,0.0,0.55301481,59.236816,3.6074789,450.21655,-9.2339878
195.9095,8.1147976,6.414175,0.0,0,3.5685976,0.0,0.55815822,59.1702,3.568594,451.10101,-9.2330122
195.9139,8.1999178,6.4490809,0.0,0,3.5295517,0.0,0.56215739,59.445839,3.5305741,451.56784,-9.2329817
195.9183,8.2910614,6.4935327,0.0,0,3.4905062,0.0,0.56752491,59.865261,3.4877579,451.81866,-9.2343111
195.9227,8.2654886,6.532464,0.0,0,3.4514608,0.0,0.57206941,59.394917,3.4465566,452.03336,-9.2333269
195.9271,8.265851,6.5701437,0.0,0,3.412415,0.0,0.57661706,59.093765,3.4110901,452.19177,-9.2332392
195.9315,8.3507643,6.605092,0.0,0,3.3733692,0.0,0.58074695,59.476379,3.3724654,452.34534,-9.2339125
195.9359,8.4058743,6.6467524,0.0,0,3.3343236,0.0,0.58588022,59.535648,3.3353496,452.46414,-9.2341118
195.9403,8.4189167,6.681694,0.0,0,3.2952783,0.0,0.59011507,59.432003,3.2948639,452.58298,-9.2331953
195.9447,8.4789944,6.7248015,0.0,0,3.2562327,0.0,0.59529614,59.491478,3.2583735,450.86301,-9.233964
195.9491,8.5654955,6.7614627,0.0,0,3.2171869,0.0,0.59975404,59.765804,3.2138002,448.83005,-9.2333555
195.9535,8.5934734,6.7985864,0.0,0,3.1781414,0.0,0.60429174,59.761013,3.1763289,446.82031,-9.2343521
195.9579,8.6159182,6.8393922,0.0,0,3.1390958,0.0,0.60937321,59.702637,3.139236,444.82693,-9.2337627
195.9623,8.6697779,6.8769317,0.0,0,3.101805,0.0,0.614003,59.643456,3.1050079,442.14227,-9.2322531
195.9667,8.7504005,6.9151516,0.0,0,3.0646603,0.0,0.61860055,59.994766,3.0660536,437.97632,-9.2334862
195.9711,8.7997723,6.9552512,0.0,0,3.0275152,0.0,0.62368023,60.039917,3.0274498,433.89767,-9.2334156
195.9755,8.8541632,6.992641,0.0,0,2.9903708,0.0,0.62837213,60.117355,2.988636,431.47812,-9.2337971
195.9799,8.8218412,7.0332952,0.0,0,2.9532259,0.0,0.63348752,59.632549,2.9508059,429.05853,-9.2346859
195.9843,8.919837,7.0658884,0.0,0,2.916081,0.0,0.63744736,60.008381,2.9148557,429.73068,-9.2339134
195.9887,8.9572287,7.1059036,0.0,0,2.8789363,0.0,0.64273357,59.929844,2.8782053,431.26566,-9.233326
195.9931,8.9545584,7.1401162,0.0,0,2.8417914,0.0,0.64682609,59.674686,2.8429928,432.22952,-9.2354851
195.9975,9.0106306,7.1744471,0.0,0,2.8046467,0.0,0.6512934,59.832512,2.8047857,432.65262,-9.2347298
196.0019,9.127861,7.2129292,0.0,0,2.7675018,0.0,0.65617448,60.251541,2.7679222,433.22824,-9.2346678
196.0063,9.2156687,7.2514892,0.0,0,2.7303569,0.0,0.66129655,60.550667,2.728307,434.27277,-9.2327032
196.0107,9.2464857,7.2896295,0.0,0,2.694227,0.0,0.66594273,60.510262,2.6922858,435.31726,-9.2349834
196.0151,9.2907495,7.3273025,0.0,0,2.658895,0.0,0.67099863,60.522003,2.6552396,434.59158,-9.2341633
196.0195,9.3353157,7.3665476,0.0,0,2.6235631,0.0,0.67594171,60.461109,2.6158342,433.82474,-9.2334156
196.0239,9.4027958,7.3976898,0.0,0,2.5882311,0.0,0.6800856,60.625481,2.5816655,433.37665,-9.2326469
196.0283,9.4121284,7.4406905,0.0,0,2.5528989,0.0,0.6855092,60.387039,2.5456722,433.05933,-9.2344933
196.0327,9.4205418,7.470294,0.0,0,2.5175669,0.0,0.68953228,60.229591,2.5102277,433.68637,-9.234478
196.0371,9.4721136,7.5031395,0.0,0,2.482235,0.0,0.69389689,60.256832,2.4785101,435.51096,-9.2337799
196.0415,9.5786257,7.5397396,0.0,0,2.446903,0.0,0.69875163,60.60083,2.4464562,436.30481,-9.2339048
196.0459,9.665967,7.573596,0.0,0,2.411571,0.0,0.70324892,60.937405,2.4044359,432.16187,-9.2334127
196.0503,9.7026911,7.6104097,0.0,0,2.3762391,0.0,0.70810384,60.827309,2.3719625,428.01895,-9.2328463
196.0547,9.7488871,7.6462536,0.0,0,2.3409069,0.0,0.71304911,60.851444,2.3371,422.81119,-9.2338934
196.0591,9.8183212,7.6804838,0.0,0,2.3059127,0.0,0.71753621,61.003136,2.3039951,417.49106,-9.2344971
196.0635,9.8928623,7.716928,0.0,0,2.2723055,0.0,0.72248137,61.189419,2.2690387,416.58475,-9.2345543
196.0679,9.9435816,7.749094,0.0,0,2.2386985,0.0,0.7268253,61.236435,2.2321053,418.20062,-9.2344856
196.0723,10.000179,7.7872787,0.0,0,2.2050912,0.0,0.73218971,61.256275,2.1960826,420.00668,-9.2341747
196.0767,10.067123,7.8195534,0.0,0,2.171484,0.0,0.73665231,61.299126,2.1626084,422.1391,-9.2346582
196.0811,10.115775,7.8558006,0.0,0,2.1378767,0.0,0.74152118,61.354065,2.1303399,423.97351,-9.2344999
196.0855,10.129902,7.8870955,0.0,0,2.1042697,0.0,0.74582845,61.181889,2.0979404,423.12585,-9.2332325
196.0899,10.209054,7.9206719,0.0,0,2.0706627,0.0,0.75043923,61.37075,2.0645454,422.2782,-9.2341442
196.0943,10.306291,7.9508057,0.0,0,2.0370555,0.0,0.75480843,61.623848,2.0291688,421.97037,-9.2337284
196.0987,10.425823,7.9893789,0.0,0,2.0034482,0.0,0.76013869,62.031368,1.9981936,421.7717,-9.2337465
196.1031,10.516891,8.0214548,0.0,0,1.969841,0.0,0.7648316,62.329845,1.9654977,422.64056,-9.2342234
196.1075,10.547415,8.0612297,0.0,0,1.9362339,0.0,0.77021563,62.110954,1.9327116,424.33588,-9.2329397
196.1119,10.617681,8.0918388,0.0,0,1.9039891,0.0,0.77483535,62.251492,1.8964585,425.93707,-9.2332392
196.1163,10.704185,8.1304121,0.0,0,1.8720186,0.0,0.78026235,62.431477,1.860436,427.31378,-9.2336264
196.1207,10.702899,8.1578655,0.0,0,1.8400483,0.0,0.78430355,62.148438,1.8314997,428.65836,-9.2332172
196.1251,10.717021,8.1933098,0.0,0,1.8080778,0.0,0.78941983,62.024632,1.80125,428.85693,-9.2337399
196.1295,10.869657,8.2226133,0.0,0,1.7761074,0.0,0.7937749,62.572781,1.7685837,429.05548,-9.2325544
196.1339,10.927835,8.2589607,0.0,0,1.744137,0.0,0.79892838,62.583267,1.7334806,428.9628,-9.23316
196.1383,10.992575,8.2874622,0.0,0,1.7121667,0.0,0.80334234,62.686714,1.7021186,428.77771,-9.2333574
196.1427,11.026866,8.3209143,0.0,0,1.6801963,0.0,0.80805784,62.596127,1.6718603,429.2222,-9.2343636
196.1471,11.081705,8.3507385,0.0,0,1.6482258,0.0,0.81270504,62.601032,1.6402105,430.31958,-9.2325449
196.1515,11.192694,8.3837261,0.0,0,1.6162554,0.0,0.81745148,62.872944,1.6091679,431.30801,-9.2332315
196.1559,11.271778,8.4104443,0.0,0,1.5842849,0.0,0.82184881,63.078789,1.5796103,431.9162,-9.233366
196.1603,11.336652,8.4473038,0.0,0,1.5530447,0.0,0.82701242,63.149746,1.5477853,432.52438,-9.2331619
196.1647,11.401098,8.4736328,0.0,0,1.5226319,0.0,0.83147281,63.205948,1.5151633,430.65756,-9.2336111
196.1691,11.521396,8.5085611,0.0,0,1.4922191,0.0,0.83642632,63.542297,1.4877309,428.67288,-9.2340612
196.1735,11.627625,8.5348215,0.0,0,1.4618063,0.0,0.84093833,63.861328,1.4538603,427.10602,-9.2331848
196.1779,11.729332,8.5721998,0.0,0,1.4313934,0.0,0.84625399,64.050667,1.4225941,425.73007,-9.2325964
196.1823,11.7712,8.6015863,0.0,0,1.4009807,0.0,0.85123557,64.008667,1.3946207,425.30054,-9.2340097
196.1867,11.857543,8.633255,0.0,0,1.3705679,0.0,0.85596597,64.124969,1.3603727,426.18784,-9.2339935
196.1911,11.886885,8.6610994,0.0,0,1.3401551,0.0,0.86075354,63.992085,1.3341269,427.12064,-9.2330637
196.1955,11.969492,8.6924686,0.0,0,1.3097425,0.0,0.86539572,64.180878,1.3037894,428.31149,-9.2332115
196.1999,12.024391,8.7201471,0.0,0,1.2793295,0.0,0.869986,64.160362,1.2737037,429.50235,-9.2330265
196.2043,12.19021,8.7513771,0.0,0,1.2489167,0.0,0.87481493,64.715446,1.2429999,431.04218,-9.2326756
196.2087,12.326499,8.7785444,0.0,0,1.2186602,0.0,0.87948447,65.094048,1.2088794,432.62875,-9.2325706
196.2131,12.345142,8.8121529,0.0,0,1.1897346,0.0,0.88478315,64.874199,1.1823444,434.28027,-9.2331581
196.2175,12.411085,8.838026,0.0,0,1.160809,0.0,0.88921279,64.920845,1.1491934,435.97266,-9.2328062
196.2219,12.536929,8.8703604,0.0,0,1.1318834,0.0,0.89448053,65.256737,1.1227623,437.24936,-9.2342024
196.2263,12.608981,8.8973694,0.0,0,1.1029578,0.0,0.89905149,65.320198,1.0923947,437.73856,-9.233757
196.2307,12.614597,8.9291086,0.0,0,1.0740322,0.0,0.903997,65.053825,1.0618457,438.0694,-9.2348614
196.2351,12.655705,8.9505291,0.0,0,1.0451066,0.0,0.9079935,64.989777,1.0393507,436.50925,-9.2326307
196.2395,12.747159,8.978672,0.0,0,1.016181,0.0,0.91245514,65.159653,1.0117186,434.9491,-9.2338009
196.2439,12.915944,9.0037622,0.0,0,0.98725533,0.0,0.91705847,65.727127,0.98483223,433.88104,-9.2325058
196.2483,13.045645,9.0360899,0.0,0,0.95832974,0.0,0.92217964,66.023933,0.95117742,432.92911,-9.2326012
196.2527,13.134835,9.0584059,0.0,0,0.9294042,0.0,0.92619246,66.239998,0.92387199,432.97836,-9.2331295
196.2571,13.241999,9.0934486,0.0,0,0.90047854,0.0,0.93214953,66.378914,0.89419258,433.87744,-9.2324572
196.2615,13.409115,9.1170273,0.0,0,0.87260348,0.0,0.93622285,66.940742,0.86979711,434.24283,-9.23312
196.2659,13.497581,9.1484547,0.0,0,0.84509468,0.0,0.94179398,66.993309,0.83871973,433.18512,-9.2339344
196.2703,13.603641,9.1727772,0.0,0,0.81758583,0.0,0.94586712,67.258499,0.80834323,432.1265,-9.233201
196.2747,13.660251,9.2066069,0.0,0,0.79007703,0.0,0.95182723,67.119537,0.7804563,430.87042,-9.2328768
196.2791,13.762082,9.2284851,0.0,0,0.76256824,0.0,0.95551908,67.369995,0.75449795,429.61438,-9.2337112
196.2835,13.892755,9.2597284,0.0,0,0.73505944,0.0,0.96106893,67.669342,0.72418815,429.98422,-9.2323856
196.2879,13.915431,9.2841482,0.0,0,0.70755064,0.0,0.96534133,67.485664,0.70150858,430.93619,-9.2326488
196.2923,13.912698,9.3086529,0.0,0,0.68004191,0.0,0.96974564,67.1642,0.67310596,432.24097,-9.2339029
196.2967,14.030481,9.3328314,0.0,0,0.65253305,0.0,0.97418451,67.431511,0.64715183,433.94656,-9.233057
196.3011,14.249172,9.3613272,0.0,0,0.62502432,0.0,0.97938085,68.130661,0.61862928,435.69446,-9.2334318
196.3055,14.412203,9.3827057,0.0,0,0.59751546,0.0,0.98302394,68.659088,0.59263945,437.61157,-9.2333698
196.3099,14.514174,9.4159031,0.0,0,0.57050872,0.0,0.98921883,68.694801,0.56191069,439.52872,-9.2339115
196.3143,14.057794,9.432086,0.0,0,0.54432875,0.0,0.99206132,66.44397,0.54168493,440.79288,-9.2322264
196.3187,13.141153,9.4479561,0.0,0,0.51814872,0.0,0.9951039,61.901451,0.51899976,442.00928,-9.2352781
196.3231,12.639877,9.4487991,0.0,0,0.49196875,0.0,0.99519968,59.553654,0.50539774,442.29559,-9.23491
196.3275,12.292162,9.4549112,0.0,0,0.46578872,0.0,0.9963491,57.768272,0.48934811,442.1105,-9.2350655
196.3319,12.030322,9.4591722,0.0,0,0.43960872,0.0,0.9969157,56.560627,0.47107467,442.1813,-9.2355623
196.3363,11.684688,9.4631538,0.0,0,0.41342872,0.0,0.99782503,54.840584,0.44973704,442.64337,-9.2353792
196.3407,11.289144,9.4633884,0.0,0,0.38724869,0.0,0.99789536,53.013947,0.43620586,443.20129,-9.2354288
196.3451,10.886507,9.4670572,0.0,0,0.3610687,0.0,0.99845415,51.026043,0.42520815,444.41666,-9.235548
196.3495,10.595274,9.4656706,0.0,0,0.3348887,0.0,0.99808669,49.764526,0.42100009,445.63202,-9.2360592
196.3539,10.521852,9.4676056,0.0,0,0.3087087,0.0,0.99844158,49.342445,0.40481797,446.17755,-9.2355185
196.3583,10.519992,9.4715748,0.0,0,0.28255266,0.0,0.9989748,49.327805,0.38573834,446.61319,-9.2362728
196.3627,10.789749,9.4714842,0.0,0,0.25765175,0.0,0.99928528,50.551075,0.34935457,446.90063,-9.2355747
196.3671,10.97307,9.476079,0.0,0,0.23275654,0.0,0.99976635,51.39856,0.31933501,447.08542,-9.2336292
196.3715,11.105968,9.4787664,0.0,0,0.20786138,0.0,1.0003251,52.003475,0.28165561,447.24042,-9.2331495
196.3759,11.187246,9.483243,0.0,0,0.18296619,0.0,1.0008942,52.364853,0.25638288,447.33282,-9.234766
196.3803,11.194797,9.4839935,0.0,0,0.158071,0.0,1.0011343,52.361725,0.23035435,447.43317,-9.2348604
196.3847,11.142005,9.4873285,0.0,0,0.13317578,0.0,1.0016114,52.075302,0.20125353,447.67078,-9.2341452
196.3891,11.105685,9.4894085,0.0,0,0.10828058,0.0,1.0019144,51.86227,0.18127476,447.90842,-9.2337723
196.3935,11.059009,9.4909992,0.0,0,0.083385371,0.0,1.0023279,51.698795,0.15388744,448.03183,-9.2335567
196.3979,11.023679,9.4941635,0.0,0,0.058490172,0.0,1.0025845,51.4664,0.13134742,448.12424,-9.2346592
196.4023,10.959425,9.4983759,0.0,0,0.03359497,0.0,1.0033468,51.150883,0.11224037,448.20981,-9.2340269
196.4067,10.888253,9.4971552,0.0,0,0.008699771,0.0,1.0031464,50.851612,0.093054749,448.289,-9.2340269
196.4111,10.834826,9.5024109,0.0,0,-0.01580042,0.0,1.0038363,50.562382,0.073633142,448.41443,-9.2348728
196.4155,10.78046,9.5035477,0.0,0,-0.040088423,0.0,1.0039625,50.256943,0.056089763,448.67844,-9.2350645
196.4199,10.683968,9.5045662,0.0,0,-0.064376414,0.0,1.0041041,49.853714,0.040200006,448.94247,-9.2352238
196.4243,10.559718,9.5067749,0.0,0,-0.088664412,0.0,1.0044876,49.272072,0.025926769,449.2713,-9.2345667
196.4287,10.477633,9.508585,0.0,0,-0.044745188,449.55496,1.0047036,48.838547,0.014030835,449.60132,-9.2347136
196.4331,10.346453,9.5092812,0.0,0,0.752087,450.0,1.0048501,48.273487,0.0054084957,449.80887,-9.2333822
196.4375,8.5071707,9.5025616,0.0,0,1.5489452,450.0,1.0034434,39.86026,0.083465718,449.96729,-9.2355375
196.4419,4.4775047,9.4858274,0.0,0,2.3458035,450.0,1.0004553,21.207983,0.32895148,450.10806,-9.2401857
196.4463,-0.18843532,9.4371691,0.0,0,3.1426606,450.0,0.99140608,-0.81732464,1.0266,450.22687,-9.2432775
196.4507,0.17573255,9.4598093,0.0,0,3.939518,450.0,0.99520731,0.85926235,2.3714757,450.35037,-9.2418861
196.4551,-0.044818301,9.4673147,0.0,0,4.7363758,450.0,0.99659717,-0.16912216,3.3692031,450.49557,-9.2411079
196.4595,0.071743108,9.4609661,0.0,0,5.5332332,450.0,0.99562871,0.31302547,4.1383457,450.64078,-9.2405043
196.4639,0.0027103382,9.4645691,0.0,0,6.3300915,450.0,0.9959687,0.01361481,4.8725739,450.71399,-9.2407799
196.4683,0.076756828,9.459775,0.0,0,7.1269484,450.0,0.99519664,0.36785784,5.6318316,450.78,-9.239068
196.4727,-0.0039090901,9.4619942,0.0,0,7.9238062,450.0,0.99533689,-0.051175479,6.4485321,450.8291,-9.2383871
196.4771,-0.050953206,9.4588032,0.0,0,8.720664,450.0,0.99479902,-0.27507868,7.282742,450.86868,-9.2372046
196.4815,0.022929879,9.4617882,0.0,0,9.5175219,450.0,0.99525696,0.14037077,8.1162043,450.90829,-9.2368517
196.4859,0.035596352,9.4580822,0.0,0,10.31438,450.0,0.99464941,0.086550623,8.9339581,450.94788,-9.2376804
196.4903,-0.056150451,9.4615984,0.0,0,11.111238,450.0,0.99512291,-0.26478046,9.7442608,450.98886,-9.2378473
196.4947,0.024660263,9.4571381,0.0,0,11.908094,450.0,0.99459541,0.12045569,10.544722,451.04166,-9.2362099
196.4991,0.02276111,9.4614172,0.0,0,12.704952,450.0,0.99515986,0.096799225,11.355931,451.09448,-9.235322
196.5035,0.054380521,9.458518,0.0,0,13.50181,450.0,0.99480754,0.27090281,12.140684,451.16937,-9.2341948
196.5079,-0.0041387705,9.4587603,0.0,0,14.298667,450.0,0.99440706,-0.036940269,12.90565,451.24857,-9.2359324
196.5123,-0.05685991,9.4599276,0.0,0,15.095525,450.0,0.99499011,-0.29502955,13.692547,451.31277,-9.2353163
196.5167,0.05616359,9.4609528,0.0,0,15.892383,450.0,0.99486375,0.23402721,14.498123,451.3656,-9.2355366
196.5211,0.032381151,9.4591818,0.0,0,16.689241,450.0,0.99492395,0.11878532,15.308964,451.41049,-9.2353258
196.5255,0.057014722,9.4610643,0.0,0,17.486099,450.0,0.99509454,0.24363992,16.118029,451.43689,-9.235816
196.5299,-0.036713444,9.4573593,0.0,0,18.0,450.0,0.99469692,-0.11010386,16.916121,451.46411,-9.23456
196.5343,0.053899001,9.4617214,0.0,0,18.0,450.0,0.99512756,0.22699936,17.682404,451.51694,-9.2351961
196.5387,0.087074071,9.458827,0.0,0,18.0,450.0,0.99510139,0.41166535,18.25239,451.56973,-9.2386036
196.5431,0.22850537,9.4717407,0.0,0,18.0,450.0,0.99719715,1.070945,18.477589,451.62253,-9.2456141
196.5475,0.56492436,9.4768553,0.0,0,18.0,450.0,0.9983896,2.6805804,18.324821,451.67532,-9.2590752
196.5519,0.49509579,9.4811487,0.0,0,18.0,450.0,0.99876636,2.3428421,18.126894,451.73468,-9.2836943
196.5563,0.52826816,9.4724112,0.0,0,18.0,450.0,0.99752158,2.4971628,18.052668,451.80069,-9.3183384
196.5607,0.51288527,9.4756145,0.0,0,18.0,450.0,0.99789929,2.4206972,18.062584,451.8667,-9.3580828
196.5651,0.49209404,9.4711971,0.0,0,18.0,450.0,0.99747622,2.3333774,18.104162,451.93271,-9.3951826
196.5695,0.4840067,9.4747581,0.0,0,18.0,450.0,0.99790543,2.2882123,18.136595,451.99872,-9.4291258
196.5739,0.49724147,9.4696598,0.0,0,18.0,450.0,0.99738652,2.3440483,18.147383,452.03937,-9.4633045
196.5783,0.52357942,9.4732761,0.0,0,18.0,450.0,0.99789941,2.4332829,18.141138,452.07898,-9.4938154
196.5827,0.52446425,9.4705191,0.0,0,18.0,450.0,0.99762511,2.452594,18.13748,452.08209,-9.5274067
196.5871,0.50072485,9.4757404,0.0,0,18.0,450.0,0.99852902,2.3589993,18.135405,452.06891,-9.560998
196.5915,0.513367,9.4715757,0.0,0,18.0,450.0,0.99805629,2.4016514,18.128021,452.06128,-9.5929308
196.5959,0.53478032,9.4741125,0.0,0,18.0,450.0,0.99831903,2.5124466,18.119755,452.06128,-9.624548
196.6003,0.53600901,9.4693308,0.0,0,18.0,450.0,0.99768078,2.5341482,18.117249,452.06332,-9.6593142
196.6047,0.50101215,9.4745474,0.0,0,18.0,450.0,0.99873912,2.313442,18.117874,452.07651,-9.6924362
196.6091,0.51818579,9.4693594,0.0,0,18.0,450.0,0.99791443,2.3969429,18.113153,452.08972,-9.7252817
196.6135,0.5364722,9.4729643,0.0,0,18.0,450.0,0.99865013,2.4965396,18.108286,452.021,-9.7582655
196.6179,0.54074913,9.4684515,0.0,0,18.0,450.0,0.99786562,2.5096493,18.10446,451.9418,-9.7909508
196.6223,0.50868958,9.4746151,0.0,0,18.0,450.0,0.99909931,2.4062531,18.105885,451.87076,-9.8234777
196.6267,0.50776553,9.4678507,0.0,0,18.0,450.0,0.9980467,2.3987372,18.101463,451.80475,-9.8569021
196.6311,0.51780349,9.4674606,0.0,0,18.0,450.0,0.99813002,2.4435244,18.102278,451.76648,-9.8886976
196.6355,0.55168849,9.466567,0.0,0,18.0,450.0,0.99788511,2.5896013,18.095604,451.77966,-9.9209146
196.6399,0.52620488,9.4724636,0.0,0,18.0,450.0,0.99908906,2.4591293,18.09922,451.78964,-9.955781
196.6443,0.50269014,9.4674635,0.0,0,18.0,450.0,0.9980427,2.34284,18.096317,451.76324,-9.9869909
196.6487,0.52118087,9.4698515,0.0,0,18.0,450.0,0.99885732,2.4423368,18.098978,451.73685,-10.019477
196.6531,0.545627,9.468215,0.0,0,18.0,450.0,0.99840301,2.5584686,18.095297,451.71045,-10.054279
196.6575,0.53465921,9.4721956,0.0,0,18.0,450.0,0.99922919,2.5055606,18.096613,451.68402,-10.087912
196.6619,0.51811403,9.4672899,0.0,0,18.0,450.0,0.99838144,2.4298487,18.090982,451.67203,-10.121141
196.6663,0.52234238,9.4670486,0.0,0,18.0,450.0,0.99836713,2.4561107,18.089619,451.67203,-10.154228
196.6707,0.55483192,9.4672089,0.0,0,18.0,450.0,0.99835742,2.5891249,18.083303,451.67203,-10.186242
196.6751,0.54591691,9.4705114,0.0,0,18.0,450.0,0.999174,2.5670435,18.090349,451.67203,-10.219591
196.6795,0.5218029,9.467248,0.0,0,18.0,450.0,0.99852628,2.4460325,18.085049,451.67178,-10.253387
196.6839,0.52674878,9.4656286,0.0,0,18.0,450.0,0.99820572,2.4580858,18.088568,451.64539,-10.284064
196.6883,0.54655272,9.4673033,0.0,0,18.0,450.0,0.99853373,2.5777035,18.083462,451.61896,-10.316627
196.6927,0.54918629,9.468874,0.0,0,18.0,450.0,0.9989081,2.5892141,18.082491,451.58279,-10.350309
196.6971,0.52698636,9.4676838,0.0,0,18.0,450.0,0.99860269,2.4859242,18.082737,451.54318,-10.382998
196.7015,0.52347606,9.4673634,0.0,0,18.0,450.0,0.99851292,2.4487922,18.081388,451.49734,-10.416601
196.7059,0.55571932,9.4663448,0.0,0,18.0,450.0,0.99833488,2.5603201,18.080494,451.44455,-10.450939
196.7103,0.55118251,9.4675293,0.0,0,18.0,450.0,0.99860102,2.6172438,18.080664,451.39172,-10.48417
196.7147,0.53404725,9.4678802,0.0,0,18.0,450.0,0.99840724,2.5315509,18.077753,451.33893,-10.517191
196.7191,0.52578431,9.4667845,0.0,0,18.0,450.0,0.99830478,2.444699,18.076042,451.28613,-10.549126
196.7235,0.54492885,9.4653273,0.0,0,18.0,450.0,0.99793017,2.5089116,18.075029,451.25806,-10.580124
196.7279,0.56090134,9.4677191,0.0,0,18.0,450.0,0.99830258,2.6443558,18.071617,451.23166,-10.614415
196.7323,0.53708911,9.4691257,0.0,0,18.0,450.0,0.99844897,2.5415726,18.068766,451.2229,-10.647256
196.7367,0.52868605,9.467412,0.0,0,18.0,450.0,0.99808395,2.5316532,18.067209,451.2229,-10.680867
196.7411,0.5455851,9.4664164,0.0,0,18.0,450.0,0.99775541,2.5315158,18.069214,451.21234,-10.711886
196.7455,0.57304806,9.4670277,0.0,0,18.0,450.0,0.9980036,2.687403,18.065964,451.18594,-10.745053
196.7499,0.54355496,9.4703541,0.0,0,18.0,450.0,0.99831039,2.5690877,18.06481,451.15607,-10.779559
196.7543,0.54602295,9.4679546,0.0,0,18.0,450.0,0.99795723,2.575645,18.064007,451.10324,-10.813764
196.7587,0.53291398,9.4688835,0.0,0,18.0,450.0,0.9980576,2.5149367,18.064558,451.05045,-10.845868
196.7631,0.57498235,9.4714155,0.0,0,18.0,450.0,0.99821854,2.6964455,18.064817,450.99429,-10.876824
196.7675,0.55777639,9.4704208,0.0,0,18.0,450.0,0.99813277,2.652364,18.06426,450.93762,-10.910312
196.7719,0.53663439,9.4692173,0.0,0,18.0,450.0,0.99771076,2.5532806,18.06319,450.87396,-10.945295
196.7763,0.54184049,9.4689178,0.0,0,18.0,450.0,0.99771881,2.533946,18.064356,450.80795,-10.97784
196.7807,0.57605904,9.4686069,0.0,0,18.0,450.0,0.99754554,2.6841514,18.059212,450.75467,-11.00953
196.7851,0.55497748,9.4722071,0.0,0,18.0,450.0,0.99784791,2.6394227,18.058071,450.71506,-11.04355
196.7895,0.54700607,9.4708824,0.0,0,18.0,450.0,0.99783444,2.5524538,18.059011,450.66983,-11.07673
196.7939,0.54776829,9.4714422,0.0,0,18.0,450.0,0.99791133,2.5640633,18.057695,450.60382,-11.110168
196.7983,0.57476598,9.4697504,0.0,0,18.0,450.0,0.99734193,2.7233732,18.059067,450.53784,-11.14196
196.8027,0.58395743,9.474288,0.0,0,18.0,450.0,0.99807912,2.7408016,18.059586,450.44687,-11.174813
196.8071,0.55382192,9.4732122,0.0,0,18.0,450.0,0.99783802,2.6112037,18.053614,450.35443,-11.207345
196.8115,0.54860473,9.4740372,0.0,0,18.0,450.0,0.99783713,2.5801673,18.054649,450.29779,-11.241919
196.8159,0.57399744,9.4733658,0.0,0,18.0,450.0,0.99762219,2.6614814,18.054251,450.25821,-11.274551
196.8203,0.604083,9.4754648,0.0,0,18.0,450.0,0.99801844,2.7963872,18.048773,450.2402,-11.304728
196.8247,0.56344533,9.4739399,0.0,0,18.0,450.0,0.99780399,2.6534603,18.051119,450.25339,-11.340605
197.2282,0.52442336,9.4772644,0.0,0,18.0,0.0015956662,0.99924129,2.4590688,18.012257,438.86621,-11.482277
199.4282,0.50687754,9.4919472,0.0,0,18.0,1.5917635e-33,1.001862,2.3727427,17.999971,412.2811,-11.482183
201.6282,0.52612096,9.5036631,0.0,0,18.0,1.4012985e-45,1.0039527,2.4527767,17.999447,392.29236,-11.481662
203.8282,0.54305255,9.51509,0.0,0,18.0,1.4012985e-45,1.0060843,2.532918,17.999025,373.85703,-11.48136
206.0282,0.56263673,9.5249166,0.0,0,18.0,1.4012985e-45,1.007888,2.615485,18.000122,356.83957,-11.48176
208.2282,0.57599318,9.5350676,0.0,0,18.0,1.4012985e-45,1.0096649,2.6720023,18.000456,341.17899,-11.482302
210.4282,0.59080833,9.5448732,0.0,0,18.0,1.4012985e-45,1.0114173,2.743988,18.000282,325.77875,-11.481743
212.6282,0.60698682,9.5539894,0.0,0,18.0,1.4012985e-45,1.0131012,2.8036256,17.999424,310.70673,-11.482164
214.8282,0.61470646,9.5624905,0.0,0,18.0,1.4012985e-45,1.0147647,2.8380489,18.000935,296.7128,-11.481791
217.0282,0.63048291,9.5708361,0.0,0,18.0,1.4012985e-45,1.016371,2.9086757,17.999294,283.51685,-11.482262
219.2282,0.64465827,9.5793753,0.0,0,18.0,1.4012985e-45,1.0178678,2.9660642,17.999619,270.81805,-11.482069
221.4282,0.65245527,9.5873756,0.0,0,18.0,1.4012985e-45,1.0192944,2.9946692,17.99951,259.27417,-11.482398
223.6282,0.66227829,9.5947037,0.0,0,18.0,1.4012985e-45,1.0206847,3.0449302,17.99983,248.44931,-11.482091
225.8282,0.68186843,9.6020002,0.0,0,18.0,1.4012985e-45,1.0220993,3.1241796,18.001068,237.42532,-11.481637
228.0282,0.6858682,9.6092253,0.0,0,18.0,1.4012985e-45,1.0233243,3.1344726,17.999268,227.18517,-11.481525
230.2282,0.69479918,9.6163149,0.0,0,18.0,1.4012985e-45,1.024588,3.1801615,18.00013,217.77448,-11.481565
232.4282,0.71243954,9.622611,0.0,0,18.0,1.4012985e-45,1.0257763,3.2527745,17.998907,208.65057,-11.482082
234.6282,0.71292764,9.6287565,0.0,0,18.0,1.4012985e-45,1.0270228,3.2460649,17.999828,199.89383,-11.48149
236.8282,0.72027934,9.6342783,0.0,0,18.0,1.4012985e-45,1.0281049,3.2840419,17.999331,191.54303,-11.48065
239.0282,0.73498023,9.6402025,0.0,0,18.0,1.4012985e-45,1.0291678,3.344033,18.000271,183.84448,-11.480148
241.2282,0.73871315,9.6460485,0.0,0,18.0,1.4012985e-45,1.0301933,3.3530426,18.000198,176.20354,-11.480568
243.4282,0.74361241,9.6505566,0.0,0,18.0,1.4012985e-45,1.0310935,3.3818855,18.000046,169.01544,-11.481174
245.6282,0.7581926,9.6560993,0.0,0,18.0,1.4012985e-45,1.0321351,3.4382801,17.999336,162.15512,-11.482009
247.8282,0.76237845,9.6609068,0.0,0,18.0,1.4012985e-45,1.032922,3.450314,18.00016,155.62639,-11.482062
250.0282,0.76730347,9.665699,0.0,0,18.0,1.4012985e-45,1.0338017,3.4819572,18.00078,149.53592,-11.481208
252.2282,0.77586329,9.669838,0.0,0,18.0,1.4012985e-45,1.0346457,3.5168674,18.000074,143.68188,-11.480478
254.4282,0.77932394,9.6738787,0.0,0,18.0,1.4012985e-45,1.0354776,3.51459,18.000677,137.97595,-11.480491
256.6282,0.78111404,9.6784048,0.0,0,18.0,1.4012985e-45,1.0363803,3.5292778,17.999529,132.84644,-11.48035
256.8282,0.7915135,9.6788197,0.0,0,18.0,1.4012985e-45,1.0363185,3.5836821,18.000469,132.39104,-11.480492