File: examples/dan-msc-case-studies/CS3/data/01 raw data/baron_test_019.csv
Time(sec),Force(kN),Jaw(mm),PowAngle(deg),Power(W),Pram,PTemp,Strain,Stress(MPa),Stroke(mm),TC1(C),wedge(mm)
0.0,1.1854278,2.0362115,0.0,0,11.076097,0.00091757358,0.14633501,13.042318,11.076515,28.959297,-9.11625
1.2,1.1025978,-0.0027168915,0.0,0,11.076097,3.5158744,-0.00015707301,14.041498,11.075886,28.878767,-9.4857817
2.4,1.0570704,-0.0030745582,0.0,0,11.076097,7.1158757,-0.0001966881,13.447583,11.076405,28.762177,-9.4827957
3.6,1.0420785,-0.00340471,0.0,0,11.076097,10.715877,-0.00021691855,13.255629,11.076512,28.750643,-9.4812374
4.8,1.0196066,-0.0030122509,0.0,0,11.076097,14.315876,-0.00018620444,12.982748,11.075888,28.597273,-9.4796991
6.0,1.001176,-0.0031699126,0.0,0,11.076097,17.915878,-0.00022633332,12.741744,11.075822,28.519297,-9.4773903
7.2,0.99030542,-0.0029812634,0.0,0,11.076097,21.515879,-0.00019724845,12.62001,11.077549,28.488604,-9.475461
8.4,0.98828596,-0.0026194688,0.0,0,11.076097,25.115881,-0.00018411731,12.581044,11.076089,28.43623,-9.4730892
9.6,0.98307484,-0.0029630559,0.0,0,11.076097,28.715879,-0.00018680139,12.502554,11.075963,28.314919,-9.4710445
10.8,0.97544366,-0.0023055742,22.771612,0,11.076097,32.31588,-0.00016975144,12.42846,11.076393,28.298319,-9.4685764
12.0,0.98077041,-0.0024795355,36.151718,0,11.076097,35.915878,-0.00014497095,12.476592,11.076461,28.586964,-9.4670677
13.2,0.9828794,-0.0034674702,44.243294,0,11.076097,39.515877,-0.00021921073,12.513616,11.075214,29.870546,-9.4649801
14.4,1.0051322,-0.006367329,49.59597,0,11.076097,43.115871,-0.00042912789,12.79743,11.075647,32.526371,-9.4630632
15.6,1.0252014,-0.010010256,52.967537,0,11.076097,46.71587,-0.00066118198,13.051202,11.075982,36.418194,-9.4611034
16.8,1.0313798,-0.013748548,54.935574,0,11.076097,50.315868,-0.00093344232,13.13807,11.077239,41.545502,-9.4591484
18.0,1.045628,-0.01895776,55.838806,0,11.076097,53.915871,-0.0012654398,13.318272,11.075738,47.5378,-9.4569197
19.2,1.0593734,-0.023404555,55.499878,0,11.076097,57.515869,-0.0015785829,13.51175,11.075692,53.947884,-9.4551258
20.4,1.0657519,-0.028277751,53.999168,0,11.076097,61.115871,-0.0018687801,13.592503,11.075378,60.643353,-9.4528666
21.6,1.0695776,-0.03219885,51.939144,0,11.076097,64.715904,-0.0021463949,13.646833,11.075934,67.060486,-9.4510136
22.8,1.0772375,-0.03606974,49.233765,0,11.076097,68.315895,-0.0023828968,13.748758,11.074783,72.521507,-9.4483643
24.0,1.0695784,-0.038104754,46.209667,0,11.076097,71.915878,-0.0025332477,13.650344,11.075367,77.19207,-9.4466867
25.2,1.0589526,-0.039970711,43.560204,0,11.076097,75.515892,-0.0026682934,13.523094,11.075872,80.828117,-9.4444056
26.4,1.039698,-0.041703355,41.839401,0,11.076097,79.115868,-0.0027688891,13.274246,11.076552,83.551208,-9.4428988
27.6,1.0244915,-0.043295279,41.802982,0,11.076097,82.715897,-0.002887368,13.082787,11.076711,85.542679,-9.4401722
28.8,1.0174325,-0.044174593,42.972111,0,11.076097,86.31588,-0.0029347639,12.999851,11.07596,87.24469,-9.4386587
30.0,1.0097461,-0.045858089,45.113346,0,11.076097,89.915886,-0.0030594885,12.892365,11.075516,88.882751,-9.4367447
31.2,1.0124569,-0.047807608,47.814827,0,11.076097,93.515877,-0.0031666642,12.929359,11.076037,90.704788,-9.4351892
32.4,1.0223734,-0.050119728,50.041893,0,11.076097,97.115875,-0.0033337658,13.07372,11.076755,93.042046,-9.4329367
33.6,1.0397058,-0.052574765,52.279354,0,11.076097,100.71588,-0.0034827879,13.28477,11.077242,95.933586,-9.4310379
34.8,1.0523672,-0.055335652,53.932911,0,11.076097,104.31587,-0.0036741656,13.454113,11.075548,99.47303,-9.4288006
36.0,1.0527763,-0.058970217,54.931065,0,11.076097,107.91587,-0.0039224867,13.472857,11.076013,103.69875,-9.4268188
37.2,1.0612562,-0.063139156,55.239254,0,11.076097,111.51588,-0.0041957311,13.575366,11.076261,108.35023,-9.4246168
38.4,1.0714182,-0.066707827,55.239254,0,11.076097,115.11588,-0.0044531268,13.703252,11.075665,113.34736,-9.4226465
39.6,1.0848374,-0.070503324,54.624027,0,11.076097,118.71588,-0.0046953298,13.884997,11.075361,118.38338,-9.4204912
40.8,1.0795035,-0.07374423,53.658806,0,11.076097,122.31588,-0.0049294443,13.811181,11.07577,123.16989,-9.4181423
42.0,1.0821151,-0.077055663,52.637402,0,11.076097,125.91587,-0.0051110038,13.848344,11.076835,127.59638,-9.4160986
43.2,1.0880684,-0.080021508,51.771202,0,11.076097,129.51599,-0.005318074,13.938596,11.076008,131.61795,-9.4138393
44.4,1.0886992,-0.083061241,51.196293,0,11.076097,133.11588,-0.0055016214,13.93697,11.074734,135.16736,-9.4123573
45.6,1.0872161,-0.085040115,50.822758,0,11.076097,136.71588,-0.0056412886,13.92227,11.077032,138.31271,-9.4102793
46.8,1.0912753,-0.086567447,50.82275,0,11.076097,140.31589,-0.0057619647,13.974498,11.075453,141.21965,-9.4083738
48.0,1.0906948,-0.088967316,51.196285,0,11.076097,143.91586,-0.0059065158,13.970497,11.076626,143.97147,-9.4066248
49.2,1.0811335,-0.091099866,52.24699,0,11.076097,147.51588,-0.0060789543,13.847421,11.076092,146.64171,-9.4047232
50.4,1.0874481,-0.093850195,53.188889,0,11.076097,151.11588,-0.0062283208,13.939238,11.075785,149.39955,-9.4024687
51.6,1.0949376,-0.096544601,54.187664,0,11.076097,154.7159,-0.0064235101,14.048374,11.076801,152.4315,-9.4002352
52.8,1.0946368,-0.099767014,55.089115,0,11.076097,158.31589,-0.006609302,14.036861,11.076226,155.70427,-9.3982534
54.0,1.0952694,-0.10293619,55.843502,0,11.076097,161.91589,-0.0068363701,14.036633,11.076075,159.16791,-9.3961973
55.2,1.1099669,-0.10686262,56.425777,0,11.076097,165.51588,-0.0070775794,14.249305,11.076296,163.0446,-9.3940697
56.4,1.1079904,-0.1097394,56.982597,0,11.076097,169.11589,-0.0072780908,14.221062,11.075377,167.01439,-9.3920612
57.6,1.102645,-0.11307009,56.986084,0,11.076097,172.71588,-0.0075072828,14.14086,11.076246,171.19629,-9.3903236
58.8,1.1192541,-0.11686292,56.986084,0,11.076097,176.3159,-0.007754561,14.368132,11.076546,175.43666,-9.3882561
60.0,1.1191782,-0.12034918,56.716591,0,11.076097,179.91588,-0.0080044772,14.371627,11.076372,179.66759,-9.3857059
61.2,1.1190248,-0.12381892,56.425846,0,11.076097,183.5159,-0.0082110055,14.3667,11.076398,183.77768,-9.3845367
62.4,1.1233573,-0.1272708,56.129154,0,11.076097,187.11588,-0.0084614027,14.426837,11.0766,187.77931,-9.3823195
63.6,1.1300987,-0.13113515,55.843689,0,11.076097,190.7159,-0.0086796088,14.513452,11.075982,191.47688,-9.380702
64.8,1.1322761,-0.13296628,55.843121,0,11.076097,194.31589,-0.0088369595,14.547971,11.074716,195.00092,-9.3784513
66.0,1.1304797,-0.13617752,55.653767,0,11.076097,197.91591,-0.0090284636,14.528849,11.075293,198.40565,-9.3762732
67.2,1.1319866,-0.13929057,55.843506,0,11.076097,201.51588,-0.0092325443,14.565687,11.075466,201.56079,-9.3741512
68.4,1.1213775,-0.14261377,56.129147,0,11.076097,205.11589,-0.0094653992,14.424057,11.076569,204.80136,-9.371666
69.6,1.1341953,-0.14521976,56.425777,0,11.076097,208.7159,-0.0096318396,14.583258,11.076355,208.04137,-9.369895
70.8,1.1340179,-0.14828488,56.711422,0,11.076097,212.31589,-0.0098588802,14.591352,11.075351,211.46503,-9.3682156
72.0,1.130767,-0.15239556,57.260639,0,11.076097,215.91588,-0.010102041,14.53826,11.075855,214.7269,-9.3660402
73.2,1.148311,-0.1546462,57.657787,0,11.076097,219.5159,-0.010278278,14.769925,11.074663,218.18211,-9.364336
74.4,1.1436065,-0.15762113,58.072262,0,11.076097,223.11588,-0.010437603,14.726753,11.076402,221.70775,-9.3622684
75.6,1.1487404,-0.16116376,58.337276,0,11.076097,226.7159,-0.010692121,14.789175,11.075814,225.35301,-9.3605146
76.8,1.1379012,-0.16497113,58.59008,0,11.076097,230.31587,-0.010913846,14.650173,11.07653,229.04176,-9.3585901
78.0,1.1398786,-0.16807581,58.85215,0,11.076097,233.91588,-0.011133771,14.686729,11.075628,232.8418,-9.3564501
79.2,1.1307193,-0.17208578,58.853752,0,11.076097,237.51588,-0.011408603,14.547357,11.075733,236.67807,-9.3544292
80.4,1.1524904,-0.17580831,59.101185,0,11.076097,241.11586,-0.011639477,14.836883,11.076146,240.42868,-9.3523741
81.6,1.1514863,-0.17865118,59.041172,0,11.076097,244.71588,-0.011849864,14.832355,11.076614,244.32799,-9.3501368
82.8,1.1353346,-0.18224387,59.106438,0,11.076097,248.31589,-0.012072301,14.64496,11.075536,247.96681,-9.3477974
84.0,1.1363224,-0.1856394,59.106438,0,11.076097,251.91589,-0.012324888,14.646546,11.075948,251.72586,-9.3460035
85.2,1.1428634,-0.18926114,59.106438,0,11.076097,255.51588,-0.01253554,14.73843,11.075589,255.40407,-9.3438768
86.4,1.1466076,-0.19282375,59.106438,0,11.076097,259.11615,-0.012792602,14.778641,11.076227,259.01019,-9.3417969
87.6,1.1383848,-0.19679306,59.106438,0,11.076097,262.71588,-0.013009648,14.6739,11.07641,262.66074,-9.3404808
88.8,1.1487528,-0.19922374,59.106438,0,11.076097,266.31586,-0.013198099,14.820037,11.07511,266.27304,-9.3382549
90.0,1.1415334,-0.20256627,59.106438,0,11.076097,269.91589,-0.013392752,14.733065,11.077304,269.72104,-9.336525
91.2,1.1485821,-0.2056015,59.327488,0,11.076097,273.51587,-0.013605605,14.815158,11.07604,273.25079,-9.3343782
92.4,1.1434213,-0.20880549,59.348137,0,11.076097,277.11588,-0.013829457,14.771228,11.07627,276.68726,-9.3327618
93.6,1.1479733,-0.21157821,59.600826,0,11.076097,280.71591,-0.014006546,14.815211,11.076816,280.19974,-9.3306665
94.8,1.1449475,-0.21559197,59.842525,0,11.076097,284.31589,-0.01428563,14.783838,11.07654,283.57584,-9.3286791
96.0,1.1467462,-0.21775453,60.084145,0,11.076097,287.91592,-0.014403737,14.817399,11.075619,287.03009,-9.3263588
97.2,1.1407634,-0.22168036,60.313187,0,11.076097,291.5159,-0.014687326,14.742148,11.075011,290.62674,-9.3242912
98.4,1.1430992,-0.22519781,60.55402,0,11.076097,295.11591,-0.014884409,14.777764,11.076046,294.21497,-9.3225298
99.6,1.1424607,-0.22877006,60.556637,0,11.076097,298.71591,-0.015153249,14.772321,11.076182,297.87421,-9.3206186
100.8,1.1423954,-0.23289742,60.787098,0,11.076097,302.31592,-0.015379626,14.757502,11.076459,301.60291,-9.3182077
102.0,1.1504264,-0.23562968,60.787346,0,11.076097,305.91592,-0.015578541,14.877696,11.075055,305.39722,-9.3159561
103.2,1.1499734,-0.23863648,60.787388,0,11.076097,309.5159,-0.015780626,14.882123,11.07583,309.1254,-9.3144569
104.4,1.1458633,-0.24249244,60.931469,0,11.076097,313.11594,-0.016025566,14.83241,11.075053,312.75906,-9.3124418
105.6,1.1373869,-0.24566804,60.795071,0,11.076097,316.71591,-0.01625669,14.729952,11.075694,316.55966,-9.3102779
106.8,1.1444731,-0.24839018,60.787361,0,11.076097,320.31592,-0.01642097,14.807391,11.075234,320.21808,-9.3085747
108.0,1.1452823,-0.25298858,60.951031,0,11.076097,323.91592,-0.01674811,14.836536,11.075878,323.72708,-9.3062954
109.2,1.1446899,-0.25422984,61.018063,0,11.076097,327.51593,-0.016807096,14.815631,11.076416,327.29941,-9.3044214
110.4,1.144243,-0.25795528,61.018063,0,11.076097,331.11594,-0.017067363,14.816726,11.075837,330.84048,-9.3027697
111.6,1.1417968,-0.26119933,61.087662,0,11.076097,334.71588,-0.017240286,14.785587,11.076336,334.44135,-9.3005819
112.8,1.1521357,-0.26469052,61.301933,0,11.076097,338.31592,-0.017498119,14.918376,11.075617,337.76059,-9.2987347
114.0,1.1478133,-0.26661974,61.672314,0,11.076097,341.91589,-0.017605256,14.879651,11.075861,340.99878,-9.2966948
115.2,1.1431847,-0.27006286,61.907955,0,11.076097,345.51593,-0.017835889,14.813656,11.074948,344.47092,-9.295085
116.4,1.1316081,-0.27397135,62.116692,0,11.076097,349.11591,-0.018090703,14.684222,11.075848,348.06747,-9.2929735
117.6,1.1453413,-0.27738518,62.336174,0,11.076097,352.71591,-0.018316492,14.856702,11.075771,351.68524,-9.2907362
118.8,1.1428553,-0.27931979,62.519905,0,11.076097,356.31592,-0.018462369,14.821957,11.075186,355.42307,-9.2887115
120.0,1.1383392,-0.28307995,62.545162,0,11.076097,359.91589,-0.018696154,14.762351,11.074684,359.04855,-9.2866373
121.2,1.1485057,-0.28753889,62.691467,0,11.076097,363.5159,-0.019008448,14.90737,11.076976,362.828,-9.2848473
122.4,1.1450757,-0.28898504,62.549706,0,11.076097,367.11588,-0.019080454,14.875515,11.07617,366.8761,-9.2827835
123.6,1.1447321,-0.2921074,62.545177,0,11.076097,370.71591,-0.019310264,14.862069,11.076186,370.58347,-9.2807121
124.8,1.1515727,-0.29622933,62.360126,0,11.076097,374.31589,-0.019542474,14.947198,11.076425,374.57858,-9.2783594
126.0,1.1378669,-0.29822698,62.027443,0,11.076097,377.91589,-0.019685414,14.767471,11.07636,378.77478,-9.2760992
127.2,1.1423165,-0.30097029,61.798542,0,11.076097,381.5159,-0.019845644,14.837277,11.075679,382.42535,-9.2744713
128.4,1.1402963,-0.30316442,61.589947,0,11.076097,385.11591,-0.020001687,14.824493,11.075912,386.08734,-9.2723799
129.6,1.1268661,-0.30549863,61.468513,0,11.076097,388.71591,-0.020156117,14.650128,11.07646,389.56595,-9.2699556
130.8,1.1357865,-0.30747765,61.252563,0,11.076097,392.31589,-0.020270366,14.76103,11.076464,392.99182,-9.2681875
132.0,1.1406054,-0.30895519,61.423065,0,11.076097,395.91589,-0.020401474,14.832975,11.07567,396.24002,-9.2663832
133.2,1.13553,-0.31218407,61.468498,0,11.076097,399.5159,-0.020593438,14.780947,11.075826,399.57516,-9.2643347
134.4,1.1404969,-0.31574813,61.688229,0,11.076097,403.11591,-0.020839317,14.841145,11.075754,402.84924,-9.262311
135.6,1.148771,-0.31635743,61.901745,0,11.076097,406.71594,-0.020865235,14.949009,11.076881,406.18887,-9.2606516
136.8,1.1511892,-0.31882566,62.103325,0,11.076097,410.31592,-0.021049555,14.963208,11.076024,409.61743,-9.2592955
138.0,1.1491799,-0.32228178,62.335331,0,11.076097,413.91595,-0.021248069,14.96406,11.076014,413.02084,-9.2569284
139.2,1.1403447,-0.32429069,62.545162,0,11.076097,417.51593,-0.021389931,14.846071,11.075747,416.50729,-9.2543488
140.4,1.1428499,-0.32723129,62.753899,0,11.076097,421.11594,-0.021562394,14.883984,11.076285,420.07953,-9.2519951
141.6,1.1460038,-0.32961503,62.962639,0,11.076097,424.71591,-0.021740388,14.919418,11.075856,423.70703,-9.2496891
142.8,1.1433911,-0.33341208,63.081478,0,11.076097,428.31595,-0.021978246,14.903151,11.076671,427.44412,-9.2485008
144.0,1.1456079,-0.33753994,63.171383,0,11.076097,431.91592,-0.022244304,14.918731,11.077365,431.12064,-9.2466736
145.2,1.1570759,-0.33863887,63.312534,0,11.076097,435.51596,-0.022327838,15.066768,11.076025,434.83475,-9.2452335
146.4,1.1462768,-0.34226272,63.333778,0,11.076097,439.11594,-0.0225619,14.935247,11.076918,438.73358,-9.2435904
147.6,1.1637533,-0.34576946,63.171394,0,11.076097,442.71594,-0.022810804,15.168776,11.075871,442.64398,-9.2410078
148.8,1.1478928,-0.34857544,63.10994,0,11.076097,446.31592,-0.022963852,14.952021,11.075826,446.54132,-9.238924
150.0,1.150403,-0.35098252,62.96265,0,11.076097,449.91492,-0.023148503,14.986701,11.076723,450.26514,-9.2371702
151.2,1.1614667,-0.35302848,61.032845,0,11.076097,449.9989,-0.023245916,15.147729,11.074949,453.78986,-9.2364893
152.4,1.1452526,-0.35358512,58.388638,0,11.076097,449.9989,-0.023304317,14.917629,11.076688,456.67996,-9.2364511
153.6,1.1144485,-0.35451692,55.544518,0,11.076097,449.9989,-0.023340605,14.508746,11.07588,458.33508,-9.236125
154.8,1.110975,-0.35308743,52.739445,0,11.076097,449.9989,-0.023265574,14.477094,11.075503,458.5257,-9.2365608
156.0,1.0883217,-0.35103735,50.825142,0,11.076097,449.9989,-0.023132784,14.174031,11.074919,457.46091,-9.2368088
157.2,1.0634667,-0.34842813,50.042728,0,11.076097,449.9989,-0.02294915,13.860421,11.076385,455.46564,-9.2369709
158.4,1.0509181,-0.34662613,50.421181,0,11.076097,449.9989,-0.022866512,13.682009,11.075438,452.98578,-9.2371225
159.6,1.0337857,-0.34342843,51.566517,0,11.076097,449.9989,-0.022635885,13.462198,11.077308,450.59161,-9.2374334
160.8,1.0284954,-0.34276709,52.975475,0,11.076097,449.9989,-0.022613246,13.387668,11.075295,448.63644,-9.2366142
162.0,1.0282878,-0.34210518,54.569,0,11.076097,449.9989,-0.022547867,13.385295,11.075488,447.4115,-9.23664
163.2,1.0377185,-0.34201539,55.679539,0,11.076097,449.9989,-0.022567175,13.509507,11.075824,446.82446,-9.2361765
164.4,0.96073627,-0.34327301,56.694767,0,11.076097,449.9989,-0.022602765,12.508877,11.075853,446.81012,-9.2360935
165.6,0.87693924,-0.34527466,57.250179,0,11.076097,449.9989,-0.022762699,11.42089,11.075955,447.16245,-9.2360477
166.8,0.83564311,-0.34732735,57.446194,0,11.076097,449.9989,-0.022858186,10.889083,11.075932,447.88724,-9.2361841
168.0,0.77814341,-0.34803823,57.311886,0,11.076097,449.9989,-0.022939023,10.127779,11.074862,448.76764,-9.2362461
169.2,0.73106253,-0.35004586,57.07682,0,11.076097,449.9989,-0.02306255,9.5217514,11.075193,449.6131,-9.2363768
170.4,0.71866006,-0.35103741,56.711452,0,11.076097,449.9989,-0.02312292,9.3750906,11.075811,450.22766,-9.2364521
171.6,0.69239628,-0.35242245,56.425785,0,11.076097,449.9989,-0.023222443,9.029583,11.075089,450.55734,-9.2363281
172.8,0.68911237,-0.35206994,56.129154,0,11.076097,449.9989,-0.02319362,8.979001,11.074574,450.72589,-9.2363682
174.0,0.6700303,-0.35289049,56.09164,0,11.076097,449.9989,-0.023262808,8.7405806,11.076087,450.65817,-9.2365599
175.2,0.66188729,-0.35348099,55.84351,0,11.076097,449.9989,-0.023283748,8.6229591,11.075885,450.60858,-9.2366467
176.4,0.65250021,-0.35466662,55.84351,0,11.076097,449.9989,-0.023382511,8.4969578,11.076271,450.36557,-9.236311
177.6,0.65213907,-0.35303539,55.871235,0,11.076097,449.9989,-0.023243655,8.4890232,11.076559,450.18054,-9.2366734
178.8,0.6353125,-0.35425299,55.844681,0,11.076097,449.9989,-0.023364171,8.2766342,11.07628,450.09012,-9.2362938
180.0,0.63709253,-0.35541314,55.901535,0,11.076097,449.9989,-0.023395665,8.2947054,11.076324,450.01849,-9.2362089
181.2,0.635773,-0.35602152,56.125671,0,11.076097,449.9989,-0.023466699,8.2769451,11.077138,449.87622,-9.2364082
182.4,0.63120532,-0.35521159,56.129147,0,11.076097,449.9989,-0.023389222,8.2203226,11.075745,449.8035,-9.2359505
183.6,0.62988836,-0.35588592,56.159302,0,11.076097,449.9989,-0.023439514,8.2061939,11.075484,449.7424,-9.2363911
184.8,0.63092977,-0.3562665,56.425777,0,11.076097,449.9989,-0.023465957,8.2123804,11.076067,449.77753,-9.2361612
186.0,0.63138026,-0.35646087,56.352833,0,11.076097,449.9989,-0.023483677,8.2077332,11.075962,449.85349,-9.236124
187.2,0.62934178,-0.35752189,56.133499,0,11.076097,449.9989,-0.023563514,8.1970711,11.075372,450.04431,-9.2357149
188.4,0.62907588,-0.35813218,56.129154,0,11.076097,449.9989,-0.023595467,8.1944923,11.076042,450.17856,-9.2359571
189.6,0.63519645,-0.35965571,56.051739,0,11.076097,449.9989,-0.023708249,8.2776251,11.075779,450.24985,-9.2355375
190.8,0.63171548,-0.35869148,56.03817,0,11.076097,449.9989,-0.023628376,8.2382202,11.076683,450.17657,-9.2356958
192.0,0.62178689,-0.35959339,55.843941,0,11.076097,449.9989,-0.023703821,8.1072931,11.075674,450.21112,-9.235651
193.2,0.62598521,-0.36061761,55.84351,0,11.076097,449.9989,-0.023740819,8.1671457,11.075936,450.19046,-9.2359705
194.4,0.63248134,-0.36111996,55.84351,0,11.076097,449.9989,-0.023793507,8.2357655,11.07526,450.2496,-9.2358742
195.2805,0.62766683,0.010352691,0.0,0,11.076099,3.2081113,0.00045557108,7.9652581,11.081187,450.21204,-9.2362852
195.2829,0.608199,0.0082940161,0.0,0,11.076099,1.3868657000000002e-16,0.00059643423,7.737752,11.080276,450.32004,-9.2352247
195.2853,0.6062935,0.0044959844,0.0,0,11.076099,5.9954176e-33,0.00054117339,7.6720209,11.074149,450.42807,-9.2367964
195.2877,0.61609328,0.0035405727,0.0,0,11.076099,0.0,0.00029728553,7.8574929,11.072329,450.53607,-9.2351551
195.2901,0.62543029,0.0037574456,0.0,0,11.076099,0.0,6.2817548e-05,7.9044318,11.078444,450.6441,-9.2363138
195.2925,0.60385883,0.0060870331,0.0,0,11.076099,0.0,0.00027519578,7.6961641,11.077658,450.61475,-9.2356224
195.2949,0.6041792,0.0049603903,0.0,0,11.076099,0.0,0.00041296225,7.6524501,11.076406,450.57153,-9.2363853
195.2973,0.60130173,0.0033485952,0.0,0,11.076099,0.0,0.00044477382,7.6908951,11.072547,450.52835,-9.2353439
195.2997,0.60414785,0.0040590907,0.0,0,11.076099,0.0,0.00038663513,7.7033291,11.074633,450.48514,-9.2356195
195.3021,0.61043239,0.0073913238,0.0,0,11.076099,0.0,0.00029467736,7.751008,11.075847,450.45813,-9.2366915
195.3045,0.59255266,0.011034422,0.0,0,11.076099,0.0,0.00045011938,7.541707,11.075764,450.43652,-9.2363958
195.3069,0.59417903,0.0094829723,0.0,0,11.076099,0.0,0.00067237549,7.6086149,11.077041,450.41495,-9.2368155
195.3093,0.60227489,0.0040242872,0.0,0,11.076099,0.0,0.00057053519,7.6986308,11.074718,450.39334,-9.2362204
195.3117,0.6222676,0.0028315855,0.0,0,11.076099,0.0,0.00030834723,7.8415375,11.074023,450.38025,-9.2356844
195.3141,0.60466295,0.0026467186,0.0,0,11.076099,0.0,7.2295086e-05,7.7198124,11.073682,450.37305,-9.2355719
195.3165,0.61005962,0.0043454817,0.0,0,11.076099,0.0,0.00014092842,7.7133336,11.074763,450.36584,-9.2366419
195.3189,0.60008258,0.0054778005,0.0,0,11.076099,0.0,0.00039984548,7.7343769,11.073461,450.35864,-9.2352591
195.3213,0.60875893,0.0047658295,0.0,0,11.076099,0.0,0.00057541172,7.7751961,11.074786,450.35767,-9.2347355
195.3237,0.61283827,0.0055586933,0.0,0,11.076099,0.0,0.00054719904,7.8811803,11.079184,450.36487,-9.2368975
195.3261,0.58998311,0.0087887114,0.0,0,11.076099,0.0,0.00037596456,7.6111946,11.082093,450.37207,-9.2366476
195.3285,0.58740628,0.012039951,0.0,0,11.076099,0.0,0.00044213815,7.4106736,11.077245,450.37927,-9.2357302
195.3309,0.60155284,0.0088594491,0.0,0,10.976468,0.0,0.000547754,7.6644459,11.075646,450.38052,-9.235796
195.3333,0.60989338,0.0038883907,0.0,0,10.615494,0.0,0.0005427826,7.7901034,11.076253,450.36612,-9.2363806
195.3357,0.60569763,0.0030779394,0.0,0,10.254521,0.0,0.0003665527,7.6629906,11.059022,450.35175,-9.2362766
195.3381,0.60646641,0.0043551307,0.0,0,9.8935471,0.0,0.00018553474,7.7922974,10.930552,450.33734,-9.23666
195.3405,0.59070605,0.0047804127,0.0,0,9.5325737,0.0,0.00017274317,7.5432153,10.642867,450.38342,-9.2369947
195.3429,0.60992789,0.0046452759,0.0,0,9.1800261,0.0,0.0003142888,7.8278446,10.253021,450.88748,-9.2352467
195.3453,5.8870268,0.23934856,0.0,0,8.8288574,0.0,0.015312769,74.110588,9.8620167,451.39151,-9.2313919
195.3477,6.7949915,0.65109354,0.0,0,8.491025,0.0,0.044318605,81.916847,9.4081078,451.89557,-9.2324343
195.3501,7.0866714,1.0791786,0.0,0,8.1570406,0.0,0.074175246,83.755249,8.9585438,452.3996,-9.2315865
195.3525,7.3400149,1.4828528,0.0,0,7.8342953,0.0,0.10313894,84.223038,8.5702085,452.83463,-9.2314501
195.3549,7.6441979,1.8318968,0.0,0,7.5165353,0.0,0.12962487,85.499855,8.1982632,453.26666,-9.2309608
195.3573,7.7756414,2.1588242,0.0,0,7.2082515,0.0,0.15541661,84.633713,7.8456659,453.6987,-9.2316465
195.3597,8.0128651,2.4799349,0.0,0,6.9060431,0.0,0.18061052,85.080406,7.5136781,454.13074,-9.2308054
195.3621,8.2046995,2.7820132,0.0,0,6.6115613,0.0,0.20463826,85.106735,7.2134762,454.02127,-9.2310276
195.3645,8.4133205,3.0704801,0.0,0,6.3240414,0.0,0.228383,85.233032,6.9161477,453.77646,-9.2314644
195.3669,8.5664043,3.3573854,0.0,0,6.042748,0.0,0.25285169,84.655212,6.624464,453.53165,-9.2312632
195.3693,8.7730074,3.6367588,0.0,0,5.7692914,0.0,0.27757704,84.582695,6.3390055,453.28683,-9.2307892
195.3717,8.9774637,3.9140472,0.0,0,5.5006132,0.0,0.30229184,84.410614,6.0615792,453.6564,-9.2300367
195.3741,9.1869202,4.1927252,0.0,0,5.2404532,0.0,0.32728481,84.287453,5.783144,454.36908,-9.230587
195.3765,9.388648,4.4723468,0.0,0,4.9838037,0.0,0.35302919,83.917091,5.5018473,455.08176,-9.2305956
195.3789,9.6010323,4.7433624,0.0,0,4.7363639,0.0,0.37951276,83.652077,5.2303238,455.79446,-9.2302303
195.3813,9.840848,5.0073767,0.0,0,4.4912457,0.0,0.40624592,83.417824,4.9646707,456.10349,-9.2322578
195.3837,10.092149,5.2606091,0.0,0,4.2558532,0.0,0.43198684,83.34951,4.7018199,455.98108,-9.2302713
195.3861,10.31918,5.515132,0.0,0,4.0217257,0.0,0.45776653,83.096207,4.4491558,455.85867,-9.2298861
195.3885,10.554673,5.7664127,0.0,0,3.7978492,0.0,0.48428223,82.750313,4.1970673,455.73627,-9.2304192
195.3909,10.816863,6.0046611,0.0,0,3.5743496,0.0,0.51074946,82.631638,3.9562836,455.50156,-9.2310867
195.3933,11.095991,6.2309599,0.0,0,3.3612847,0.0,0.53673816,82.522507,3.7264533,455.03372,-9.2304525
195.3957,11.387178,6.4532099,0.0,0,3.1483085,0.0,0.56259817,82.593559,3.5055485,454.56586,-9.2309208
195.3981,11.703101,6.6738472,0.0,0,2.9451063,0.0,0.58807743,82.742645,3.2878475,454.09799,-9.2300348
195.4005,12.016154,6.8916979,0.0,0,2.7424982,0.0,0.61393714,82.748871,3.0725038,453.4812,-9.2297602
195.4029,12.372106,7.0986004,0.0,0,2.5483871,0.0,0.64005494,82.977638,2.8629134,452.11969,-9.2297602
195.4053,12.761479,7.2914171,0.0,0,2.3556671,0.0,0.66584951,83.430428,2.669719,450.75821,-9.2290859
195.4077,13.140453,7.4806137,0.0,0,2.170248,0.0,0.69092387,83.826843,2.4753134,449.3967,-9.2300673
195.4101,13.544477,7.6728044,0.0,0,1.986936,0.0,0.71597731,84.230118,2.2842896,448.03455,-9.2291126
195.4125,14.026447,7.8638678,0.0,0,1.8098083,0.0,0.74171048,85.023415,2.0945394,446.59442,-9.2296333
195.4149,14.567099,8.0483198,0.0,0,1.6354243,0.0,0.76814407,85.965477,1.9090369,445.1543,-9.2296019
195.4173,15.109234,8.2235384,0.0,0,1.4662172,0.0,0.7947973,86.84024,1.7274663,443.7142,-9.2294607
195.4197,15.679241,8.399725,0.0,0,1.3003292,0.0,0.82130212,87.750496,1.5526594,442.27408,-9.2276402
195.4221,16.280703,8.5781651,0.0,0,1.1387082,0.0,0.84779537,88.796997,1.3737717,441.2673,-9.2270432
195.4245,16.916302,8.7542562,0.0,0,0.98093224,0.0,0.87462878,89.780411,1.2001348,440.33698,-9.226265
195.4269,17.616634,8.9189405,0.0,0,0.82657719,0.0,0.90170521,90.941315,1.0344828,439.40668,-9.2269068
195.4293,18.331375,9.0729704,0.0,0,0.67652929,0.0,0.9288522,92.10405,0.87125331,438.47635,-9.2264271
195.4317,19.052422,9.2197285,0.0,0,0.52908581,0.0,0.95432705,93.386253,0.71464217,438.41364,-9.2266827
195.4341,19.025236,9.3651381,0.0,0,0.38628578,0.0,0.97894025,91.735611,0.56191647,438.73767,-9.2247152
195.4365,16.175665,9.3741684,0.0,0,0.24542005,0.0,0.98007149,77.567497,0.48721272,439.06171,-9.2276115
195.4389,14.960799,9.3729486,0.0,0,0.10962804,0.0,0.97985595,71.584846,0.44640979,439.38571,-9.2302666
195.4413,14.228097,9.3765326,0.0,0,-0.025516469,0.0,0.98170251,67.878944,0.42001554,440.72086,-9.2302608
195.4437,13.930217,9.3782291,0.0,0,-0.15794852,0.0,0.98243719,66.41172,0.38633204,442.94064,-9.2316904
195.4461,14.080643,9.3849878,0.0,0,-0.29038054,0.0,0.98273706,67.079948,0.33347178,445.16046,-9.2321119
195.4485,14.322101,9.3969412,0.0,0,-0.42281252,0.0,0.98361188,68.224289,0.26517284,447.38025,-9.2308931
195.4509,14.423756,9.4066677,0.0,0,-0.55524451,0.0,0.98551661,68.542267,0.20320989,449.06735,-9.2302389
195.4533,14.380003,9.4060192,0.0,0,-0.68767649,0.0,0.98675299,68.248215,0.13843773,449.86661,-9.2287045
195.4557,14.189799,9.403286,0.0,0,-0.82010847,0.0,0.98713046,67.361763,0.09057942,450.66586,-9.2296438
195.4581,13.880573,9.407196,0.0,0,-0.95254052,0.0,0.98669702,65.920135,0.053369783,451.46515,-9.2308264
195.4605,13.486533,9.4136219,0.0,0,-1.0849725,0.0,0.9868899,64.022522,0.029745294,452.21448,-9.230937
195.4629,13.016257,9.4174881,0.0,0,-0.72870666,450.0,0.98781705,61.751015,0.020408582,452.78333,-9.2318134
195.4653,12.504404,9.4187851,0.0,0,-0.27022031,450.0,0.9891035,59.23888,0.018878065,453.35217,-9.232398
195.4677,12.009313,9.4165316,0.0,0,0.18826602,450.0,0.98951519,56.887077,0.029501947,453.92102,-9.232666
195.4701,11.623147,9.4183893,0.0,0,0.64675242,450.0,0.98885185,55.097725,0.03304857,454.49112,-9.232769
195.4725,11.363653,9.4243393,0.0,0,1.105239,450.0,0.98870981,53.836521,0.034200694,455.08157,-9.2334471
195.4749,10.94411,9.4275522,0.0,0,1.5637254,450.0,0.98908293,51.869812,0.039293129,455.67203,-9.2336864
195.4773,9.7006311,9.4179039,0.0,0,2.0222118,450.0,0.98882639,46.116486,0.094375886,456.26248,-9.2337437
195.4797,6.8234034,9.4019337,0.0,0,2.4806983,450.0,0.98679805,32.65424,0.22982706,456.85294,-9.2355299
195.4821,2.8703086,9.3833847,0.0,0,2.9391847,450.0,0.9828437,14.086941,0.46885318,457.37839,-9.2399282
195.4845,0.10301741,9.3241282,0.0,0,3.3976712,450.0,0.9710753,0.73510933,0.92146748,457.89664,-9.2417994
195.4869,-0.25596544,9.3384838,0.0,0,3.8561575,450.0,0.97358215,-1.2761223,1.6624014,458.41486,-9.2424927
195.4893,0.052082751,9.3799391,0.0,0,4.3146439,450.0,0.98193455,0.24273556,2.4518156,458.93307,-9.2418003
195.4917,-0.094675325,9.3991652,0.0,0,4.7731299,450.0,0.98638678,-0.47938403,3.1414099,459.31769,-9.2408152
195.4941,0.046379168,9.3886919,0.0,0,5.2316165,450.0,0.98389691,0.27901331,3.6730187,459.65573,-9.2395716
195.4965,-0.085410506,9.3999672,0.0,0,5.6901031,450.0,0.98423487,-0.35604015,4.1065679,459.99377,-9.2396727
195.4989,0.006417789,9.3939104,0.0,0,6.1485891,450.0,0.98314625,0.029033558,4.539279,460.33182,-9.2388182
195.5013,0.07067094,9.3907738,0.0,0,6.6070752,450.0,0.98379523,0.30599445,4.9731412,460.60269,-9.237009
195.5037,-0.073965907,9.383028,0.0,0,7.0655622,450.0,0.98347819,-0.28360429,5.4100814,460.82562,-9.237711
195.5061,-0.037513174,9.3801565,0.0,0,7.5240488,450.0,0.98220646,-0.25840434,5.8826241,461.04855,-9.2371187
195.5085,0.14917794,9.3821478,0.0,0,7.9825354,450.0,0.98137009,0.71500468,6.3702331,461.27148,-9.2380276
195.5109,-0.15824088,9.387578,0.0,0,8.441021,450.0,0.98201913,-0.78335041,6.8505282,461.46078,-9.237896
195.5133,-0.016589232,9.385335,0.0,0,8.8995075,450.0,0.98302591,-0.21054487,7.3270302,461.60458,-9.2368345
195.5157,0.16839539,9.3801737,0.0,0,9.3579931,450.0,0.98304325,0.8802228,7.80898,461.74841,-9.2376604
195.5181,-0.17746523,9.3827877,0.0,0,9.8164806,450.0,0.98277044,-0.81574041,8.2749891,461.89221,-9.2370453
195.5205,0.060496628,9.3851624,0.0,0,10.274966,450.0,0.98183852,0.13935509,8.7458477,462.01877,-9.2375031
195.5229,0.05360594,9.3881578,0.0,0,10.733453,450.0,0.98195565,0.36326334,9.2169971,462.09787,-9.2355061
195.5253,-0.19758031,9.3879976,0.0,0,11.191939,450.0,0.98316264,-0.89777327,9.6723604,462.17697,-9.2358103
195.5277,0.049902681,9.3819427,0.0,0,11.650426,450.0,0.98325264,0.16570793,10.151461,462.25607,-9.2354994
195.5301,0.0037284184,9.3793516,0.0,0,12.108912,450.0,0.98222685,0.087617561,10.631917,462.33282,-9.2352247
195.5325,-0.16910712,9.3830156,0.0,0,12.567399,450.0,0.98178142,-0.82956505,11.096622,462.39038,-9.2356853
195.5349,0.052643556,9.3855858,0.0,0,13.025885,450.0,0.98180979,0.19749315,11.556961,462.44791,-9.2346373
195.5373,-0.0026489904,9.3826733,0.0,0,13.484371,450.0,0.98240781,0.027653381,12.012002,462.50543,-9.2347727
195.5397,-0.088194922,9.3819313,0.0,0,13.942858,450.0,0.98315817,-0.39601627,12.46839,462.56299,-9.2351274
195.5421,-0.0096101835,9.3804941,0.0,0,14.401344,450.0,0.98237008,-0.19358259,12.9381,462.62735,-9.235136
195.5445,0.04918189,9.3822727,0.0,0,14.859831,450.0,0.98141402,0.36922702,13.42017,462.69205,-9.2336483
195.5469,-0.17204435,9.3899794,0.0,0,15.318317,450.0,0.98213935,-0.79230303,13.905148,462.75677,-9.2350416
195.5493,0.086004771,9.3853531,0.0,0,15.776803,450.0,0.98241973,0.35450879,14.392416,462.82147,-9.234868
195.5517,-0.042359512,9.3764467,0.0,0,16.235291,450.0,0.98236072,-0.095143571,14.866892,462.87994,-9.2348375
195.5541,-0.12123351,9.3782454,0.0,0,16.693775,450.0,0.98223716,-0.61750531,15.32557,462.9368,-9.2349205
195.5565,0.049773518,9.3817596,0.0,0,17.152262,450.0,0.98161292,0.23046219,15.783877,462.99362,-9.2339668
195.5589,0.087922901,9.3849573,0.0,0,17.61075,450.0,0.9815498,0.43595302,16.233871,463.05048,-9.2332344
195.5613,-0.12887366,9.3845186,0.0,0,17.999975,450.0,0.98251033,-0.57373297,16.682789,463.09933,-9.233779
195.5637,0.045497891,9.3811617,0.0,0,18.0,450.0,0.98298639,0.15548716,17.14275,463.14249,-9.234726
195.5661,-0.030717555,9.377779,0.0,0,18.0,450.0,0.98190844,-0.10045686,17.568272,463.18564,-9.2336454
195.5685,-0.066700615,9.3834963,0.0,0,18.0,450.0,0.98186731,-0.33549288,17.936844,463.22879,-9.2352791
195.5709,0.099068232,9.3923836,0.0,0,18.0,450.0,0.98250663,0.45835885,18.235159,463.26584,-9.2365141
195.5733,-0.021126395,9.3944387,0.0,0,18.0,450.0,0.98403579,-0.0654753,18.429525,463.29459,-9.2394705
195.5757,0.23009761,9.3909941,0.0,0,18.0,450.0,0.98482013,1.0689986,18.497705,463.32333,-9.2435799
195.5781,0.44471043,9.3919706,0.0,0,18.0,450.0,0.98485631,2.1144683,18.44228,463.35211,-9.2513399
195.5805,0.4525753,9.3975067,0.0,0,18.0,450.0,0.98444706,2.1319885,18.310108,463.36554,-9.2606907
195.5829,0.43282217,9.4022989,0.0,0,18.0,450.0,0.98471165,2.1134751,18.199778,463.33676,-9.2734623
195.5853,0.43516254,9.4029074,0.0,0,18.0,450.0,0.98557919,2.0781612,18.107204,463.30801,-9.2910748
195.5877,0.39324236,9.4003563,0.0,0,18.0,450.0,0.98623812,1.9037155,18.060474,463.27924,-9.3092499
195.5901,0.3782993,9.3993225,0.0,0,18.0,450.0,0.98613948,1.7532676,18.044228,463.25204,-9.3285627
195.5925,0.39120865,9.3983784,0.0,0,18.0,450.0,0.98461008,1.8446267,18.052422,463.23767,-9.3492622
195.5949,0.4094263,9.402482,0.0,0,18.0,450.0,0.98441696,1.9477748,18.065601,463.22327,-9.3716125
195.5973,0.39346072,9.4011955,0.0,0,18.0,450.0,0.98493052,1.8500079,18.091093,463.20889,-9.3925791
195.5997,0.38200489,9.3984709,0.0,0,18.0,450.0,0.98601598,1.8197914,18.107422,463.19452,-9.4099665
195.6021,0.38045669,9.3959522,0.0,0,18.0,450.0,0.98563248,1.836913,18.128635,463.19379,-9.4277258
195.6045,0.4109804,9.3957281,0.0,0,18.0,450.0,0.98436648,1.9331282,18.139196,463.19379,-9.4437952
195.6069,0.41344881,9.3973846,0.0,0,18.0,450.0,0.98389906,1.9557528,18.142935,463.19379,-9.46241
195.6093,0.39603218,9.399333,0.0,0,18.0,450.0,0.98472416,1.8786916,18.144434,463.19379,-9.4805698
195.6117,0.38965091,9.3947706,0.0,0,18.0,450.0,0.98513466,1.8612597,18.140755,463.16531,-9.4977474
195.6141,0.41002449,9.3940268,0.0,0,18.0,450.0,0.98530364,1.9544222,18.136297,463.12936,-9.5162992
195.6165,0.42130604,9.3957624,0.0,0,18.0,450.0,0.98432618,1.9809791,18.131727,463.09338,-9.533185
195.6189,0.41594425,9.4023914,0.0,0,18.0,450.0,0.98432189,1.9901676,18.132784,463.05743,-9.5510492
195.6213,0.40093398,9.4035616,0.0,0,18.0,450.0,0.9852491,1.9276848,18.127348,463.03516,-9.5687752
195.6237,0.40675202,9.3973055,0.0,0,18.0,450.0,0.98564678,1.9017602,18.124159,463.02078,-9.5871325
195.6261,0.42301998,9.3897038,0.0,0,18.0,450.0,0.98470807,2.0178363,18.119539,463.00638,-9.6042528
195.6285,0.43297905,9.3932009,0.0,0,18.0,450.0,0.98401785,2.045449,18.11986,462.992,-9.6239157
195.6309,0.40569603,9.3979425,0.0,0,18.0,450.0,0.98401809,1.9564719,18.121014,462.98788,-9.6419468
195.6333,0.40230638,9.398756,0.0,0,18.0,450.0,0.98451912,1.901176,18.113764,462.99509,-9.6606455
195.6357,0.41454348,9.3953133,0.0,0,18.0,450.0,0.9851504,1.9773448,18.109755,463.00226,-9.6763153
195.6381,0.4317596,9.3946133,0.0,0,18.0,450.0,0.98546851,2.0572858,18.10862,463.00946,-9.6949844
195.6405,0.43434677,9.3969517,0.0,0,18.0,450.0,0.9846921,2.073467,18.108416,463.01666,-9.7131567
195.6429,0.40146142,9.4034166,0.0,0,18.0,450.0,0.98458964,1.9197601,18.106264,463.02383,-9.7317886
195.6453,0.40420097,9.4041681,0.0,0,18.0,450.0,0.98527592,1.9474524,18.106771,463.03104,-9.7484541
195.6477,0.41802013,9.3979874,0.0,0,18.0,450.0,0.9855606,1.9918677,18.105118,463.03824,-9.7651825
195.6501,0.42600974,9.3918276,0.0,0,18.0,450.0,0.9849723,2.0580347,18.105068,463.03973,-9.7841673
195.6525,0.42508391,9.3936539,0.0,0,18.0,450.0,0.98420209,2.0399737,18.101118,463.01096,-9.8023462
195.6549,0.40904635,9.3986692,0.0,0,18.0,450.0,0.98407859,1.9213688,18.100439,462.98221,-9.8201475
195.6573,0.41165841,9.3970385,0.0,0,18.0,450.0,0.98418164,1.9444227,18.100571,462.95343,-9.8367252
195.6597,0.42837894,9.3955555,0.0,0,18.0,450.0,0.9851222,2.0172215,18.098446,462.92468,-9.8545828
195.6621,0.43884832,9.3923264,0.0,0,18.0,450.0,0.98514408,2.0672269,18.097603,462.88873,-9.8753252
195.6645,0.38547587,9.3947525,0.0,0,18.0,450.0,0.98455244,1.8351191,18.097664,462.85275,-9.8940763
195.6669,0.40119752,9.4012518,0.0,0,18.0,450.0,0.98435724,1.9223297,18.097639,462.8168,-9.9114523
195.6693,0.41617653,9.4034157,0.0,0,18.0,450.0,0.98488551,1.9690977,18.097706,462.78085,-9.9289417
195.6717,0.41846976,9.3977051,0.0,0,18.0,450.0,0.98540854,2.0072181,18.097065,462.76303,-9.9474125
195.6741,0.41410375,9.3934031,0.0,0,18.0,450.0,0.98528838,2.006376,18.096228,462.74866,-9.966917
195.6765,0.38453373,9.3930321,0.0,0,18.0,450.0,0.98415941,1.8720481,18.096992,462.73428,-9.9836102
195.6789,0.40593019,9.3951759,0.0,0,18.0,450.0,0.9835071,1.8955189,18.093565,462.71988,-10.001019
195.6813,0.4311114,9.396843,0.0,0,18.0,450.0,0.9840464,2.0216646,18.094452,462.68585,-10.018013
195.6837,0.44328734,9.3941069,0.0,0,18.0,450.0,0.98458672,2.0935364,18.09116,462.64273,-10.035553
195.6861,0.40104848,9.3932915,0.0,0,18.0,450.0,0.98533565,1.9139329,18.095432,462.59958,-10.054624
195.6885,0.40142182,9.3939247,0.0,0,18.0,450.0,0.98441398,1.9269931,18.090015,462.55643,-10.073627
195.6909,0.42674592,9.3983364,0.0,0,18.0,450.0,0.98394114,1.9875606,18.087044,462.50574,-10.089688
195.6933,0.44478625,9.4013119,0.0,0,18.0,450.0,0.98448747,2.11586,18.086462,462.44821,-10.109033
195.6957,0.42662749,9.4010019,0.0,0,18.0,450.0,0.98582315,2.0512807,18.083786,462.39066,-10.127351
195.6981,0.41069788,9.3930635,0.0,0,18.0,450.0,0.98550779,1.9601616,18.087246,462.33313,-10.144999
195.7005,0.41797152,9.3919468,0.0,0,18.0,450.0,0.98409253,1.9986541,18.086021,462.28613,-10.161858
195.7029,0.44671455,9.3954468,0.0,0,18.0,450.0,0.98376703,2.1098332,18.079998,462.25739,-10.179606
195.7053,0.44720361,9.399333,0.0,0,18.0,450.0,0.98429734,2.0745749,18.08156,462.22864,-10.199448
195.7077,0.43365926,9.398737,0.0,0,18.0,450.0,0.98538065,2.05145,18.080446,462.19986,-10.217175
195.7101,0.41813666,9.3944025,0.0,0,18.0,450.0,0.98548359,2.0026429,18.079498,462.17111,-10.234524
195.7125,0.43949392,9.3917112,0.0,0,18.0,450.0,0.98431891,2.0795248,18.079517,462.14233,-10.250819
195.7149,0.45773318,9.3999739,0.0,0,18.0,450.0,0.984424,2.2075546,18.078873,462.11359,-10.26926
195.7173,0.44092298,9.4040642,0.0,0,18.0,450.0,0.9847964,2.1107843,18.078594,462.08481,-10.288109
195.7197,0.42796123,9.4002743,0.0,0,18.0,450.0,0.98551881,2.0231233,18.078266,462.05606,-10.307891
195.7221,0.43329534,9.3908262,0.0,0,18.0,450.0,0.98498797,2.0433004,18.081888,462.02728,-10.325228
195.7245,0.43627578,9.3892994,0.0,0,18.0,450.0,0.98386621,2.0441904,18.078079,461.99854,-10.34314
195.7269,0.44837838,9.3932247,0.0,0,18.0,450.0,0.9833957,2.1580749,18.077078,461.96979,-10.361008
195.7293,0.42726463,9.3974571,0.0,0,18.0,450.0,0.98398954,2.0781851,18.077074,461.94101,-10.380702
195.7317,0.41182774,9.3982582,0.0,0,18.0,450.0,0.98507887,1.972469,18.075161,461.91226,-10.397188
195.7341,0.42149609,9.3924923,0.0,0,18.0,450.0,0.98517978,2.0295403,18.07522,461.88348,-10.414752
195.7365,0.44586173,9.3929157,0.0,0,18.0,450.0,0.98433656,2.1044507,18.072971,461.85474,-10.432015
195.7389,0.44736147,9.3971872,0.0,0,18.0,450.0,0.98389137,2.1107702,18.076525,461.82596,-10.450806
195.7413,0.43022472,9.4011974,0.0,0,18.0,450.0,0.98425865,2.0229559,18.073481,461.79721,-10.467984
195.7437,0.42189494,9.3995533,0.0,0,18.0,450.0,0.9852885,1.9809697,18.072826,461.76843,-10.4874
195.7461,0.43185213,9.3931894,0.0,0,18.0,450.0,0.98538935,2.0375924,18.0732,461.73965,-10.503774
195.7485,0.45102301,9.3922987,0.0,0,18.0,450.0,0.98455918,2.1743507,18.074547,461.71091,-10.521641
195.7509,0.43594515,9.3960505,0.0,0,18.0,450.0,0.98390788,2.1106582,18.067966,461.68625,-10.539806
195.7533,0.41565129,9.3984652,0.0,0,18.0,450.0,0.98407596,1.995934,18.064434,461.66467,-10.558116
195.7557,0.43650708,9.3974915,0.0,0,18.0,450.0,0.98497492,2.0592062,18.069914,461.6431,-10.576424
195.7581,0.45609212,9.3925972,0.0,0,18.0,450.0,0.9851144,2.1495218,18.072363,461.62152,-10.594181
195.7605,0.46194032,9.3909063,0.0,0,18.0,450.0,0.98425853,2.1922693,18.068165,461.59396,-10.611959
195.7629,0.4371691,9.3966246,0.0,0,18.0,450.0,0.98392743,2.0738063,18.0683,461.55801,-10.630998
195.7653,0.42233813,9.4010267,0.0,0,18.0,450.0,0.98416007,2.0226495,18.066727,461.52206,-10.647531
195.7677,0.44704628,9.3987131,0.0,0,18.0,450.0,0.98477596,2.1057558,18.07025,461.48611,-10.665936
195.7701,0.4627786,9.3946896,0.0,0,18.0,450.0,0.98554784,2.1913207,18.066673,461.45016,-10.684901
195.7725,0.44484708,9.3938875,0.0,0,18.0,450.0,0.98498923,2.1533883,18.061823,461.41422,-10.704272
195.7749,0.4409532,9.3951664,0.0,0,18.0,450.0,0.98383135,2.0964119,18.067673,461.37823,-10.720482
195.7773,0.43800837,9.39746,0.0,0,18.0,450.0,0.983805,2.0595121,18.062901,461.34229,-10.738018
195.7797,0.46684441,9.3956327,0.0,0,18.0,450.0,0.98433924,2.1965711,18.062521,461.30777,-10.755816
195.7821,0.47598282,9.3920174,0.0,0,18.0,450.0,0.98486274,2.302707,18.06225,461.28619,-10.773438
195.7845,0.43207759,9.3926086,0.0,0,18.0,450.0,0.98471779,2.0660007,18.059845,461.26462,-10.791241
195.7869,0.43669331,9.3956251,0.0,0,18.0,450.0,0.98416013,2.0666132,18.061829,461.24304,-10.810877
195.7893,0.44544312,9.4024687,0.0,0,18.0,450.0,0.98425591,2.0932448,18.060246,461.22147,-10.827912
195.7917,0.46737468,9.3993931,0.0,0,18.0,450.0,0.98467094,2.2354884,18.058571,461.19315,-10.845665
195.7941,0.46185076,9.3923578,0.0,0,18.0,450.0,0.98495668,2.2022436,18.058119,461.16437,-10.863101
195.7965,0.44120902,9.3907213,0.0,0,18.0,450.0,0.98462451,2.0981855,18.060295,461.13562,-10.882589
195.7989,0.42614013,9.3928967,0.0,0,18.0,450.0,0.98369515,2.0597274,18.059168,461.10684,-10.901223
195.8013,0.46692285,9.3960295,0.0,0,18.0,450.0,0.98361301,2.1981962,18.061623,461.04993,-10.919247
195.8037,0.46675447,9.3972492,0.0,0,18.0,450.0,0.98443872,2.2314625,18.05806,460.9852,-10.935878
195.8061,0.44042116,9.3925734,0.0,0,18.0,450.0,0.98490691,2.0914705,18.053568,460.92047,-10.954729
195.8085,0.43238491,9.3928251,0.0,0,18.0,450.0,0.98489714,2.0734146,18.05537,460.85574,-10.973089
195.8109,0.43881816,9.3940554,0.0,0,18.0,450.0,0.98384821,2.0983725,18.055502,460.80453,-10.990258
195.8133,0.46439928,9.4000559,0.0,0,18.0,450.0,0.98385322,2.2011025,18.056398,460.76138,-11.009049
195.8157,0.46075472,9.401104,0.0,0,18.0,450.0,0.98488653,2.1761725,18.056068,460.71823,-11.026704
195.8181,0.43901071,9.3959131,0.0,0,18.0,450.0,0.98562747,2.0979161,18.053469,460.67511,-11.044202
195.8205,0.43501022,9.3919067,0.0,0,18.0,450.0,0.98498595,2.0271511,18.058353,460.64203,-11.061444
195.8229,0.45992765,9.3944569,0.0,0,18.0,450.0,0.98408049,2.1975217,18.059074,460.62045,-11.079938
195.8253,0.47062698,9.3971424,0.0,0,18.0,450.0,0.98377711,2.2537572,18.051512,460.59888,-11.098221
195.8277,0.44614732,9.3958082,0.0,0,18.0,450.0,0.98422104,2.1346972,18.051397,460.5773,-11.115916
195.8301,0.44100329,9.3910265,0.0,0,18.0,450.0,0.98455328,2.0839939,18.046671,460.5513,-11.134138
195.8325,0.44121706,9.3907948,0.0,0,18.0,450.0,0.98453116,2.0563097,18.048054,460.51532,-11.151675
195.8349,0.46936902,9.3949394,0.0,0,18.0,450.0,0.9840306,2.2436111,18.055431,460.47937,-11.169898
195.8373,0.46453646,9.4003534,0.0,0,18.0,450.0,0.98386717,2.2440536,18.048943,460.44342,-11.188976
195.8397,0.44306818,9.4013147,0.0,0,18.0,450.0,0.98475766,2.1244297,18.051191,460.40744,-11.204964
195.8421,0.44447473,9.3955908,0.0,0,18.0,450.0,0.9854123,2.0970402,18.045652,460.37149,-11.224273
195.8445,0.45659953,9.3915901,0.0,0,18.0,450.0,0.98498458,2.1355968,18.048676,460.33557,-11.239643
195.8469,0.47941595,9.3947039,0.0,0,18.0,450.0,0.98416001,2.2703981,18.050901,460.29962,-11.258812
195.8493,0.45796186,9.3985596,0.0,0,18.0,450.0,0.98401576,2.167088,18.044464,460.26367,-11.276273
195.8517,0.43961215,9.3988962,0.0,0,18.0,450.0,0.98468173,2.0893619,18.045942,460.23483,-11.295331
195.8541,0.45410305,9.3964863,0.0,0,18.0,450.0,0.98536277,2.1598463,18.044529,460.20605,-11.314494
195.8565,0.48355958,9.3930721,0.0,0,18.0,450.0,0.98506826,2.300241,18.044703,460.17731,-11.331641
195.8589,0.49381685,9.3938503,0.0,0,18.0,450.0,0.98405409,2.3048301,18.04472,460.14853,-11.350015
196.0608,0.42383733,9.3977156,0.0,0,18.0,0.85476655,0.98482966,2.0145323,18.024317,454.64075,-11.479154
197.2608,0.35265273,9.4085894,0.0,0,18.0,3.6951402e-17,0.98682493,1.6731234,18.000326,435.54047,-11.481037
198.4608,0.33739999,9.4170284,0.0,0,18.0,1.5974026e-33,0.98825699,1.5997578,18.000731,420.78448,-11.480584
199.6608,0.33206335,9.4246407,0.0,0,18.0,1.4012985e-45,0.98970574,1.5740204,18.000492,407.56979,-11.481579
200.8608,0.33232179,9.4321194,0.0,0,18.0,1.4012985e-45,0.99098772,1.5713172,17.999374,395.29083,-11.482108
202.0608,0.31754202,9.4383812,0.0,0,18.0,1.4012985e-45,0.99222487,1.4983282,17.999487,383.76614,-11.481484
203.2608,0.30451024,9.4450121,0.0,0,18.0,1.4012985e-45,0.99338216,1.4313024,17.99999,372.87558,-11.480948
204.4608,0.3181175,9.4510994,0.0,0,18.0,1.4012985e-45,0.99449551,1.5015247,18.000319,362.49353,-11.481859
205.6608,0.32048357,9.4573021,0.0,0,18.0,1.4012985e-45,0.99562484,1.5102297,17.999474,352.45822,-11.481757
206.8608,0.32676345,9.4634914,0.0,0,18.0,1.4012985e-45,0.99665827,1.5395418,18.000595,342.73535,-11.482177
208.0608,0.31693774,9.4694185,0.0,0,18.0,1.4012985e-45,0.99775147,1.4923704,18.000374,333.60815,-11.482108
209.2608,0.3216764,9.4748878,0.0,0,18.0,1.4012985e-45,0.99867326,1.508357,17.999783,324.46017,-11.482542
210.4608,0.31453997,9.4798698,0.0,0,18.0,1.4012985e-45,0.9996565,1.4765191,17.999187,315.78574,-11.482603
211.6608,0.30879775,9.4857607,0.0,0,18.0,1.4012985e-45,1.0006673,1.4465029,18.000618,307.23279,-11.48226
212.8608,0.30642655,9.4907389,0.0,0,18.0,1.4012985e-45,1.0016916,1.4323262,17.999023,299.04306,-11.481898
214.0608,0.30286607,9.4958773,0.0,0,18.0,1.4012985e-45,1.0025749,1.4178866,17.999338,291.02649,-11.481796
215.2608,0.29946476,9.4997044,0.0,0,18.0,1.4012985e-45,1.0032808,1.3971865,18.001106,283.25827,-11.481426
216.4608,0.31378311,9.5050726,0.0,0,18.0,1.4012985e-45,1.0042684,1.4690626,18.000385,275.82043,-11.481546
217.6608,0.32070088,9.5091896,0.0,0,18.0,1.4012985e-45,1.0049489,1.4985505,18.000164,268.40323,-11.481777
218.8608,0.31429288,9.5132751,0.0,0,18.0,1.4012985e-45,1.0057009,1.466508,17.998608,261.28342,-11.481977
220.0608,0.32374251,9.5165634,0.0,0,18.0,1.4012985e-45,1.0062603,1.5131078,17.999557,254.35652,-11.482124
221.2608,0.3206878,9.5201979,0.0,0,18.0,1.4012985e-45,1.0069739,1.4957018,18.001064,247.47313,-11.482542
222.4608,0.31780893,9.5239182,0.0,0,18.0,1.4012985e-45,1.0076144,1.4824473,17.999031,240.98605,-11.482396
223.6608,0.31349874,9.5270405,0.0,0,18.0,1.4012985e-45,1.0082761,1.4597856,17.999401,234.62129,-11.48233
224.8608,0.32116091,9.5309982,0.0,0,18.0,1.4012985e-45,1.0089895,1.4915416,17.999903,228.55669,-11.482502
226.0608,0.30335376,9.5341616,0.0,0,18.0,1.4012985e-45,1.0095615,1.4102315,18.000404,222.47498,-11.482038
227.2608,0.29926759,9.5385017,0.0,0,18.0,1.4012985e-45,1.0103924,1.3933101,18.000593,216.63744,-11.481768
228.4608,0.30546266,9.541523,0.0,0,18.0,1.4012985e-45,1.0108541,1.4191334,17.999987,210.7747,-11.481762
229.6608,0.30602419,9.5451641,0.0,0,18.0,1.4012985e-45,1.0115519,1.4188106,17.998047,205.26761,-11.481492
230.8608,0.30450225,9.5489912,0.0,0,18.0,1.4012985e-45,1.0121678,1.41294,17.999847,200.09532,-11.481283
232.0608,0.31254122,9.5523148,0.0,0,18.0,1.4012985e-45,1.0128658,1.4413592,17.999342,194.83354,-11.481037
233.2608,0.29842791,9.555892,0.0,0,18.0,1.4012985e-45,1.0134736,1.3803293,17.99968,189.80832,-11.480948
234.4608,0.31410953,9.5589056,0.0,0,18.0,1.4012985e-45,1.0141366,1.4539679,18.001019,185.01259,-11.481905
235.6608,0.31791648,9.5624266,0.0,0,18.0,1.4012985e-45,1.0147318,1.4688846,18.00024,180.29073,-11.481882
236.8608,0.31808555,9.565649,0.0,0,18.0,1.4012985e-45,1.0153834,1.4736576,18.000568,175.78304,-11.481997
238.0608,0.31260309,9.5686398,0.0,0,18.0,1.4012985e-45,1.0159076,1.4378811,18.000151,171.40669,-11.482026
239.2608,0.30617237,9.5715084,0.0,0,18.0,1.4012985e-45,1.0163661,1.410341,17.99926,167.21442,-11.482245
240.4608,0.30754745,9.575098,0.0,0,18.0,1.4012985e-45,1.017061,1.4169909,17.999117,163.16037,-11.482064
241.6608,0.30874196,9.5779886,0.0,0,18.0,1.4012985e-45,1.0175359,1.4199718,18.001144,159.6261,-11.482181
242.8608,0.30691838,9.5811558,0.0,0,18.0,1.4012985e-45,1.018163,1.4115821,18.000366,155.82898,-11.481768
244.0608,0.30120549,9.5834846,0.0,0,18.0,1.4012985e-45,1.0185109,1.3802539,18.000181,152.41972,-11.481958
245.2608,0.30122203,9.5865536,0.0,0,18.0,1.4012985e-45,1.0191734,1.3825194,17.999205,148.75287,-11.481452
246.4608,0.30377904,9.5888882,0.0,0,18.0,1.4012985e-45,1.0195446,1.3935659,17.999769,145.24072,-11.481543
247.6608,0.31356645,9.5915871,0.0,0,18.0,1.4012985e-45,1.0201335,1.4376702,17.999395,141.86664,-11.481373
248.8608,0.30222437,9.5935726,0.0,0,18.0,1.4012985e-45,1.0204744,1.3849742,18.0009,138.44444,-11.48145
250.0608,0.3034648,9.5965576,0.0,0,18.0,1.4012985e-45,1.0210683,1.3922278,17.999691,135.12903,-11.481032
251.2608,0.29437923,9.5987453,0.0,0,18.0,1.4012985e-45,1.0214746,1.3513234,18.000465,131.92056,-11.481246
252.4608,0.30865204,9.6010351,0.0,0,18.0,1.4012985e-45,1.0218532,1.410431,17.999044,128.87178,-11.481214
253.6608,0.29554212,9.6032343,0.0,0,18.0,1.4012985e-45,1.022287,1.3535898,17.999258,125.92636,-11.480796
254.8608,0.31316787,9.6059589,0.0,0,18.0,1.4012985e-45,1.0227153,1.4293022,18.000269,123.06319,-11.481727
255.8608,0.30691969,9.6076012,0.0,0,18.0,1.4012985e-45,1.0229909,1.4011552,18.000193,120.81701,-11.481562