File: examples/dan-msc-case-studies/CS3/data/01 raw data/baron_test_016.csv
Time(sec),Force(kN),Jaw(mm),PowAngle(deg),Power(W),Pram,PTemp,Strain,Stress(MPa),Stroke(mm),TC1(C),wedge(mm)
0.0,1.3633653,0.12528786,0.0,0,11.076097,0.0016543847,0.0084094349,17.22975,11.075448,25.183668,-9.1113472
1.2,1.2714326,0.0021143616,0.0,0,11.076097,3.5159016,0.0001226914,16.190086,11.076342,24.985147,-9.4802675
2.4,1.2579514,0.0018953255,0.0,0,11.076097,7.1159005,0.00012466303,16.018871,11.076153,24.956657,-9.4786615
3.6,1.2172979,0.0019180098,0.0,0,11.076097,10.715903,0.00012942373,15.504546,11.07613,24.916807,-9.4767361
4.8,1.1991932,0.0018095941,0.0,0,11.076097,14.315903,0.00011914891,15.264131,11.074849,24.889175,-9.4751501
6.0,1.18423,0.001576804,0.0,0,11.076097,17.915905,0.0001264609,15.0883,11.075522,24.829311,-9.4727774
7.2,1.1724665,0.0020698328,0.0,0,11.076097,21.515907,0.00011770828,14.943681,11.076391,24.798721,-9.470746
8.4,1.1675687,0.0018149198,0.0,0,11.076097,25.115908,0.0001188797,14.874649,11.075301,24.806456,-9.4686155
9.6,1.1633922,0.0022055488,21.937246,0,11.076097,28.71591,0.00013985446,14.81798,11.076496,24.779411,-9.4664164
10.8,1.1597842,0.0024634728,36.094086,0,11.076097,32.31591,0.00017304248,14.76885,11.075596,24.926567,-9.4650297
12.0,1.1766046,0.0016005727,44.855167,0,11.076097,35.915909,0.00012387811,14.994053,11.075526,25.802143,-9.4632206
13.2,1.1858016,-0.0024270606,50.797451,0,11.076097,39.515907,-0.00018306755,15.098427,11.07591,27.734093,-9.4610157
14.4,1.2041309,-0.0064753816,54.882587,0,11.076097,43.115906,-0.00043011713,15.351458,11.076457,31.093199,-9.4590006
15.6,1.2220517,-0.011503774,57.522091,0,11.076097,46.715904,-0.00077400194,15.569559,11.076118,35.678932,-9.4574509
16.8,1.2468289,-0.017231712,58.952011,0,11.076097,50.315903,-0.0011399196,15.907899,11.076064,41.192272,-9.4550562
18.0,1.2659342,-0.023260672,59.348137,0,11.076097,53.915909,-0.001533369,16.150282,11.076386,47.622234,-9.452879
19.2,1.2830462,-0.02920679,58.769768,0,11.076097,57.515911,-0.0019696946,16.381491,11.075984,54.608242,-9.451128
20.4,1.2937001,-0.03577077,57.263165,0,11.076097,61.115913,-0.0023812675,16.51687,11.075311,61.645813,-9.4494314
21.6,1.2972327,-0.040169042,54.862457,0,11.076097,64.715935,-0.0026806996,16.568438,11.076143,68.383507,-9.4470797
22.8,1.2959471,-0.043916162,51.593372,0,11.076097,68.315941,-0.0029132613,16.546104,11.076341,74.415245,-9.4450846
24.0,1.2980334,-0.046768095,47.528069,0,11.076097,71.915916,-0.0030946487,16.574823,11.076188,79.724297,-9.4435387
25.2,1.2836546,-0.048578631,43.118179,0,11.076097,75.515915,-0.0032451523,16.396126,11.076221,83.841286,-9.4415522
26.4,1.2692318,-0.049985308,39.270508,0,11.076097,79.115921,-0.0033320235,16.218716,11.075857,86.83725,-9.4398937
27.6,1.2465131,-0.050597921,37.089882,0,11.076097,82.715935,-0.003376601,15.916083,11.076249,88.67337,-9.4375248
28.8,1.2298832,-0.050223254,37.832321,0,11.076097,86.315926,-0.0033260901,15.718358,11.076496,89.704071,-9.4358358
30.0,1.2178162,-0.050770663,41.094212,0,11.076097,89.915932,-0.0033596882,15.551926,11.075742,90.104881,-9.4339247
31.2,1.2101698,-0.051616546,45.094791,0,11.076097,93.51593,-0.0034474265,15.460793,11.076241,90.636787,-9.431819
32.4,1.2115046,-0.053048123,49.488022,0,11.076097,97.115921,-0.0035295691,15.484404,11.075679,91.4739,-9.4293127
33.6,1.2310356,-0.055977236,53.306053,0,11.076097,100.71593,-0.003738093,15.734257,11.075583,93.021484,-9.4274368
34.8,1.2445015,-0.060512818,56.420677,0,11.076097,104.31592,-0.0040081651,15.898571,11.075371,95.429588,-9.4252748
36.0,1.2591959,-0.064584054,58.849075,0,11.076097,107.91592,-0.0042884923,16.099857,11.075894,98.85482,-9.4231529
37.2,1.2871366,-0.069327049,60.518257,0,11.076097,111.51591,-0.0046197302,16.456518,11.075876,103.2588,-9.4217377
38.4,1.30562,-0.074620858,61.360905,0,11.076097,115.11592,-0.0049589579,16.700735,11.075522,108.43256,-9.4197855
39.6,1.3187382,-0.080064811,61.468498,0,11.076097,118.71591,-0.0053426996,16.876331,11.077035,114.45598,-9.4177494
40.8,1.3245776,-0.087258756,60.805351,0,11.076097,122.31593,-0.0057935193,16.94433,11.075813,120.69621,-9.4158611
42.0,1.3224505,-0.091767743,59.606522,0,11.076097,125.91592,-0.0060781441,16.941292,11.075835,126.95183,-9.4140291
43.2,1.3208672,-0.096752957,57.854134,0,11.076097,129.51605,-0.0064452486,16.907763,11.075337,132.96025,-9.4123383
44.4,1.323918,-0.10065193,55.72839,0,11.076097,133.11592,-0.006675839,16.971668,11.075658,138.33493,-9.4100142
45.6,1.3185829,-0.10344902,53.334789,0,11.076097,136.71593,-0.0068891426,16.907835,11.0762,143.08502,-9.408102
46.8,1.306361,-0.10606879,50.885315,0,11.076097,140.31592,-0.0070404494,16.748119,11.075329,146.90874,-9.4060478
48.0,1.2910116,-0.10854634,49.110004,0,11.076097,143.91592,-0.007199815,16.549685,11.076457,149.88927,-9.404129
49.2,1.2744305,-0.10929067,48.371269,0,11.076097,147.51593,-0.0072650355,16.345547,11.076475,152.0507,-9.4017687
50.4,1.2684517,-0.11055563,48.383785,0,11.076097,151.11594,-0.0073371828,16.268124,11.075397,153.69025,-9.3998957
51.6,1.2542466,-0.11173437,50.027702,0,11.076097,154.71594,-0.0074415468,16.070932,11.0762,154.88655,-9.3976955
52.8,1.260491,-0.11348968,51.970184,0,11.076097,158.31593,-0.0075301728,16.168758,11.07545,156.17776,-9.3958731
54.0,1.2742618,-0.11559975,54.538246,0,11.076097,161.91594,-0.007672749,16.31897,11.075884,157.63245,-9.3940544
55.2,1.2928966,-0.11991084,56.714874,0,11.076097,165.51595,-0.0079745529,16.589668,11.075102,159.74944,-9.3921413
56.4,1.3075322,-0.12274002,58.84201,0,11.076097,169.11594,-0.0081383483,16.786745,11.075891,162.38562,-9.3903294
57.6,1.3232397,-0.12732887,60.434254,0,11.076097,172.71596,-0.0084703369,16.991259,11.07556,165.98485,-9.3883934
58.8,1.3283445,-0.13238467,61.618855,0,11.076097,176.31595,-0.0087729096,17.061787,11.075934,170.14229,-9.3867588
60.0,1.3259372,-0.1381696,62.116692,0,11.076097,179.91594,-0.0091605848,17.040447,11.076725,175.05101,-9.384697
61.2,1.3349254,-0.14348923,62.336418,0,11.076097,183.51596,-0.0095280707,17.150455,11.076008,180.26089,-9.3830814
62.4,1.332779,-0.1489214,61.910175,0,11.076097,187.11595,-0.0098677976,17.133213,11.076695,185.70609,-9.3812294
63.6,1.322395,-0.15385292,61.239964,0,11.076097,190.71596,-0.010215613,17.004629,11.076244,191.21529,-9.3784771
64.8,1.3350224,-0.15889607,60.087894,0,11.076097,194.31596,-0.010537,17.175825,11.074903,196.54826,-9.3770132
66.0,1.331961,-0.16384615,58.854633,0,11.076097,197.91595,-0.010859048,17.147766,11.075762,201.41216,-9.3748798
67.2,1.3184546,-0.16776019,57.364681,0,11.076097,201.51598,-0.011136387,16.964918,11.076118,205.82997,-9.3724823
68.4,1.3188562,-0.1698167,56.129551,0,11.076097,205.11597,-0.01124086,16.982159,11.076158,209.61319,-9.3706141
69.6,1.2999747,-0.17168029,55.239262,0,11.076097,208.71596,-0.01139277,16.75205,11.076208,212.73564,-9.3686333
70.8,1.3057193,-0.17338364,54.632717,0,11.076097,212.31596,-0.011487004,16.815138,11.075335,215.41989,-9.3665552
72.0,1.2857856,-0.17543697,54.931332,0,11.076097,215.91595,-0.011623946,16.556627,11.076665,217.57564,-9.3644228
73.2,1.2877551,-0.177435,55.535866,0,11.076097,219.51596,-0.011760146,16.58399,11.075475,219.60411,-9.3623867
74.4,1.2986355,-0.17953019,56.762981,0,11.076097,223.11597,-0.011883843,16.718771,11.0765,221.50267,-9.3606253
75.6,1.3124589,-0.18230169,58.073452,0,11.076097,226.71596,-0.012098992,16.893988,11.075686,223.74568,-9.3588524
76.8,1.3276911,-0.18553652,59.592621,0,11.076097,230.31596,-0.012285026,17.097578,11.07569,226.2762,-9.3572187
78.0,1.3371056,-0.18946096,60.783371,0,11.076097,233.91597,-0.012540041,17.249966,11.07569,229.29301,-9.355155
79.2,1.3420151,-0.19421543,61.688068,0,11.076097,237.51598,-0.012868446,17.308222,11.077298,233.01268,-9.3535328
80.4,1.3477808,-0.1995379,62.336418,0,11.076097,241.11597,-0.013199753,17.379282,11.075678,237.14436,-9.3520145
81.6,1.3423736,-0.20460373,62.545422,0,11.076097,244.71596,-0.013567865,17.324381,11.076767,241.80783,-9.3500042
82.8,1.3417054,-0.21033166,62.546043,0,11.076097,248.31596,-0.013918604,17.312346,11.075073,246.58064,-9.3479204
84.0,1.343932,-0.21530719,62.336433,0,11.076097,251.91595,-0.014248437,17.354177,11.07588,251.28049,-9.3459148
85.2,1.3432857,-0.21907221,61.75066,0,11.076097,255.51596,-0.014503686,17.351339,11.07525,256.10074,-9.3434534
86.4,1.342245,-0.22270828,61.172096,0,11.076097,259.11621,-0.01472474,17.351938,11.075808,260.67392,-9.3418312
87.6,1.3446946,-0.22552641,60.556648,0,11.076097,262.71597,-0.014945218,17.383549,11.075949,264.77679,-9.3389988
88.8,1.3400376,-0.2287655,59.843647,0,11.076097,266.31595,-0.015122322,17.306297,11.075537,268.69321,-9.3375187
90.0,1.3331237,-0.2320396,59.373169,0,11.076097,269.91595,-0.015345819,17.251265,11.076162,272.14276,-9.3350744
91.2,1.3366945,-0.23511565,59.109646,0,11.076097,273.51596,-0.015553805,17.30596,11.076721,275.23468,-9.333313
92.4,1.3323267,-0.23820122,59.106449,0,11.076097,277.11597,-0.015739832,17.237965,11.076079,278.23608,-9.3316889
93.6,1.3317729,-0.24122715,59.348137,0,11.076097,280.71597,-0.015971687,17.234453,11.07606,280.98199,-9.3299885
94.8,1.3345621,-0.24417149,59.842274,0,11.076097,284.31598,-0.016140804,17.278873,11.075414,283.81683,-9.3284979
96.0,1.3379149,-0.24792865,60.314846,0,11.076097,287.91599,-0.016392933,17.310778,11.07637,286.76944,-9.3259621
97.2,1.3421202,-0.25129777,60.787346,0,11.076097,291.51599,-0.016617309,17.377384,11.075271,289.85999,-9.3237791
98.4,1.3378363,-0.25616965,61.397808,0,11.076097,295.11594,-0.01691911,17.309824,11.076348,293.15381,-9.321702
99.6,1.3442137,-0.25881717,61.90731,0,11.076097,298.71597,-0.017123202,17.418388,11.074863,296.56479,-9.3196173
100.8,1.3438848,-0.26210585,62.239552,0,11.076097,302.31598,-0.017320933,17.406139,11.076513,300.30365,-9.3176842
102.0,1.3411897,-0.26629251,62.545162,0,11.076097,305.91599,-0.017587498,17.390522,11.076418,304.0192,-9.3158751
103.2,1.333443,-0.27104869,62.753899,0,11.076097,309.51599,-0.017907791,17.287622,11.075273,308.11279,-9.3143501
104.4,1.3413152,-0.27524123,62.753899,0,11.076097,313.116,-0.018169193,17.394459,11.075142,312.25723,-9.3129587
105.6,1.3383099,-0.27917275,62.545177,0,11.076097,316.71597,-0.018459165,17.36495,11.076331,316.48264,-9.3108835
106.8,1.3359265,-0.28327256,62.340054,0,11.076097,320.31598,-0.018710658,17.325716,11.076232,320.51749,-9.3081369
108.0,1.3413192,-0.28617856,62.116707,0,11.076097,323.91599,-0.018903097,17.39798,11.077533,324.58661,-9.3065586
109.2,1.345614,-0.29058671,61.907967,0,11.076097,327.51599,-0.019173034,17.457672,11.075815,328.40533,-9.3040752
110.4,1.3469502,-0.29408941,61.68824,0,11.076097,331.116,-0.019404937,17.500481,11.075889,332.03802,-9.3021889
111.6,1.3400575,-0.29564187,61.496346,0,11.076097,334.716,-0.019537747,17.408867,11.075831,335.44699,-9.2999449
112.8,1.3374869,-0.2982924,61.547039,0,11.076097,338.31601,-0.019691136,17.37396,11.075499,338.74524,-9.2975302
114.0,1.3447416,-0.3018755,61.688229,0,11.076097,341.91599,-0.019925287,17.472076,11.075324,341.81723,-9.2962122
115.2,1.3394645,-0.30543631,62.041573,0,11.076097,345.51599,-0.020151662,17.39991,11.075401,344.97852,-9.2946501
116.4,1.3385725,-0.30893794,62.336311,0,11.076097,349.11603,-0.020362372,17.391151,11.075873,348.21082,-9.2925711
117.6,1.3387359,-0.3125824,62.646763,0,11.076097,352.716,-0.020639762,17.408747,11.075788,351.50763,-9.2906151
118.8,1.3329937,-0.31654483,62.961182,0,11.076097,356.31601,-0.020881429,17.327845,11.07583,354.96844,-9.2889833
120.0,1.3459107,-0.31953555,63.273918,0,11.076097,359.91602,-0.021072462,17.505856,11.076274,358.46063,-9.2870121
121.2,1.3440222,-0.32498127,63.499081,0,11.076097,363.51602,-0.021424079,17.483467,11.075189,362.23532,-9.2851019
122.4,1.3545738,-0.32865703,63.775627,0,11.076097,367.116,-0.021671982,17.629173,11.076486,365.65436,-9.2830706
123.6,1.3406048,-0.33018473,63.973385,0,11.076097,370.716,-0.021799378,17.458559,11.07571,369.43045,-9.2805033
124.8,1.3405538,-0.33387059,64.171135,0,11.076097,374.31601,-0.022011084,17.462067,11.075794,373.04776,-9.2784357
126.0,1.3470652,-0.33788273,64.315941,0,11.076097,377.91599,-0.022279466,17.537846,11.075599,376.96326,-9.2766705
127.2,1.3382986,-0.34182751,64.252213,0,11.076097,381.51602,-0.022518374,17.43771,11.076104,380.98245,-9.2744789
128.4,1.3347522,-0.34578729,64.029388,0,11.076097,385.116,-0.02277163,17.387039,11.076427,385.20233,-9.2725286
129.6,1.3351946,-0.3488408,63.77565,0,11.076097,388.71597,-0.023013787,17.411381,11.077083,389.40796,-9.2708731
130.8,1.3303702,-0.35137799,63.369152,0,11.076097,392.31598,-0.023153333,17.330643,11.076187,393.53683,-9.2689333
132.0,1.3088385,-0.35335004,62.962788,0,11.076097,395.91599,-0.023272151,17.063742,11.075912,397.42792,-9.2669315
133.2,1.3054936,-0.35380691,62.545689,0,11.076097,399.51599,-0.023315391,17.030067,11.076164,401.2168,-9.2648602
134.4,1.3015761,-0.35605064,60.583103,0,11.076097,399.99893,-0.023443036,16.967169,11.07653,404.72955,-9.2647028
135.6,1.2851115,-0.35517895,57.825905,0,11.076097,399.99893,-0.023418546,16.755005,11.076238,407.535,-9.265049
136.8,1.2588937,-0.35142517,54.339794,0,11.076097,399.99893,-0.023157716,16.399017,11.075841,409.39899,-9.2650528
138.0,1.2312477,-0.34683543,50.833778,0,11.076097,399.99893,-0.022852393,16.046095,11.076334,409.93091,-9.2652464
139.2,1.2064135,-0.3417165,47.280006,0,11.076097,399.99893,-0.022537356,15.702005,11.075504,409.45474,-9.2651625
140.4,1.1836371,-0.33601254,45.144096,0,11.076097,399.99893,-0.022134885,15.425648,11.075655,407.56525,-9.2649937
141.6,1.1697578,-0.33071163,45.120853,0,11.076097,399.99893,-0.021819718,15.225208,11.076088,404.71573,-9.2653189
142.8,1.1478087,-0.32637984,47.048157,0,11.076097,399.99893,-0.021514047,14.940507,11.075863,401.29373,-9.265379
144.0,1.120592,-0.32341936,50.037205,0,11.076097,399.99893,-0.021320902,14.577556,11.076795,398.03598,-9.265111
145.2,1.0453793,-0.3229762,53.300251,0,11.076097,399.99893,-0.021308264,13.601345,11.075502,395.24197,-9.2651682
146.4,0.93402493,-0.32336971,56.083973,0,11.076097,399.99893,-0.021328725,12.14194,11.07655,393.51559,-9.2651806
147.6,0.79323792,-0.32739535,58.316101,0,11.076097,399.99893,-0.021597499,10.325456,11.075427,392.8168,-9.2647934
148.8,0.71214896,-0.32957774,59.832512,0,11.076097,399.99893,-0.021728089,9.2676029,11.076478,393.0835,-9.2649384
150.0,0.67030495,-0.33188766,60.786983,0,11.076097,399.99893,-0.021862378,8.7256317,11.074879,394.04663,-9.2649145
151.2,0.6523059,-0.33514717,61.237789,0,11.076097,399.99893,-0.022112677,8.5023909,11.076152,395.43387,-9.2646065
152.4,0.63873363,-0.33807528,61.237804,0,11.076097,399.99893,-0.022287011,8.3148594,11.07574,397.12515,-9.2646513
153.6,0.63015378,-0.34091705,60.81599,0,11.076097,399.99893,-0.022480037,8.2107277,11.076188,398.9772,-9.2646399
154.8,0.62420267,-0.34325534,60.136311,0,11.076097,399.99893,-0.02262665,8.1315556,11.075092,400.6282,-9.2646303
156.0,0.61608136,-0.34485304,59.049091,0,11.076097,399.99893,-0.022718713,8.0141964,11.076783,402.22516,-9.2644272
157.2,0.62159616,-0.34513128,57.810257,0,11.076097,399.99893,-0.02276174,8.0942211,11.075534,403.42426,-9.2643557
158.4,0.6207127,-0.34650782,56.175877,0,11.076097,399.99893,-0.022828491,8.0910482,11.075634,404.24591,-9.2646141
159.6,0.60336083,-0.34646222,54.931858,0,11.076097,399.99893,-0.022838224,7.8657699,11.076301,404.46103,-9.2647963
160.8,0.59107345,-0.34553155,53.67487,0,11.076097,399.99893,-0.022771057,7.7016449,11.076163,404.2251,-9.2645206
162.0,0.58707434,-0.34445128,52.976078,0,11.076097,399.99893,-0.022690928,7.6591024,11.076743,403.47198,-9.2649565
163.2,0.58075798,-0.3425431,52.636253,0,11.076097,399.99893,-0.022595363,7.5594406,11.076954,402.48718,-9.2648392
164.4,0.57199776,-0.3410587,52.97607,0,11.076097,399.99893,-0.022484962,7.4576812,11.077359,401.23737,-9.2649651
165.6,0.56742001,-0.34039721,53.65715,0,11.076097,399.99893,-0.0224347,7.3979297,11.075443,399.93781,-9.264677
166.8,0.568968,-0.33963478,54.622829,0,11.076097,399.99893,-0.022399954,7.4109211,11.076002,398.76468,-9.2646465
168.0,0.57912159,-0.33982676,55.535713,0,11.076097,399.99893,-0.022391662,7.5430045,11.076045,397.94995,-9.2650967
169.2,0.58154315,-0.3394638,56.703323,0,11.076097,399.99893,-0.022389269,7.5766497,11.076004,397.27319,-9.2648172
170.4,0.59902328,-0.34003788,57.524754,0,11.076097,399.99893,-0.022405647,7.7927208,11.075888,397.07974,-9.2652082
171.6,0.59816265,-0.34092951,58.165039,0,11.076097,399.99893,-0.02245504,7.798357,11.074745,397.14996,-9.2651176
172.8,0.60115492,-0.34174418,58.59008,0,11.076097,399.99893,-0.022548394,7.8362141,11.075448,397.47717,-9.2650557
174.0,0.60115284,-0.34360579,58.853752,0,11.076097,399.99893,-0.022636496,7.8417706,11.075935,398.08505,-9.2649488
175.2,0.60705823,-0.34515569,58.829014,0,11.076097,399.99893,-0.022746513,7.9024334,11.075921,399.01361,-9.2651224
176.4,0.6004976,-0.34669155,58.338516,0,11.076097,399.99893,-0.022845756,7.8174062,11.077002,399.9422,-9.2647514
177.6,0.60015321,-0.34743893,57.810837,0,11.076097,399.99893,-0.022883788,7.8210359,11.075612,400.83469,-9.2648516
178.619,0.62046629,0.0088051371,57.260742,0,11.076099,65.880898,0.0006698143,7.8994541,11.075732,401.53555,-9.2647457
178.6214,0.58536869,0.0093809105,57.260742,0,11.076099,2.8482205e-15,0.00074743014,7.2825141,11.076886,401.53555,-9.2653246
178.6238,0.61751652,0.0069886507,57.260742,0,11.076099,1.2312851e-31,0.00063775165,7.9452848,11.076539,401.53555,-9.2643404
178.6262,0.61198109,0.010068271,57.260742,0,11.076099,0.0,0.00069892831,7.791029,11.07531,401.53555,-9.2641773
178.6286,0.59843576,0.013127778,49.244221,0,11.076099,0.0,0.0005987258,7.6577001,11.075268,401.51871,-9.2636833
178.631,0.59632456,0.013572238,35.501644,0,11.076099,0.0,0.00069773837,7.5647583,11.074951,401.48981,-9.2637215
178.6334,0.61608309,0.01223206,21.759066,0,11.076099,0.0,0.00094842265,7.8186803,11.0785,401.46091,-9.2652216
178.6358,0.59870976,0.0089796335,8.016489,0,11.076099,0.0,0.00088530197,7.6587749,11.077292,401.43201,-9.265336
178.6382,0.59434438,0.006799181,0.0,0,11.076099,0.0,0.00047222394,7.6777058,11.072879,401.42117,-9.2639017
178.6406,0.61241525,0.0099314675,0.0,0,11.076099,0.0,0.00049206102,7.8340302,11.072883,401.43561,-9.2637949
178.643,0.60391223,0.011231317,0.0,0,11.076099,0.0,0.00056548783,7.6707096,11.074509,401.45007,-9.2646017
178.6454,0.59752643,0.0088420855,0.0,0,11.076099,0.0,0.00062593701,7.5900655,11.072785,401.46451,-9.2640905
178.6478,0.58274615,0.0074949097,0.0,0,11.076099,0.0,0.00071844133,7.4100924,11.072809,401.48077,-9.2646904
178.6502,0.59148645,0.0097994572,0.0,0,11.076099,0.0,0.00070578832,7.4442983,11.076324,401.50244,-9.2652884
178.6526,0.59885067,0.013853668,0.0,0,11.076099,0.0,0.00064426597,7.6893773,11.074526,401.52411,-9.2648268
178.655,0.59313595,0.015104247,0.0,0,11.076099,0.0,0.00077563664,7.626091,11.074778,401.54581,-9.2664766
178.6574,0.57745022,0.013027133,0.0,0,11.076099,0.0,0.0009194669,7.3935714,11.078169,401.56628,-9.2656574
178.6598,0.58391172,0.0069893948,0.0,0,11.076099,0.0,0.00074710767,7.4526167,11.077827,401.57349,-9.2645454
178.6622,0.58267635,0.0075450353,0.0,0,11.076099,0.0,0.00052669371,7.3910599,11.076122,401.58072,-9.2634077
178.6646,0.58949047,0.0097943638,0.0,0,11.076099,0.0,0.00047520173,7.5124726,11.075288,401.58795,-9.263896
178.667,0.58243507,0.011659353,0.0,0,11.076099,0.0,0.00065282173,7.3839679,11.073017,401.59515,-9.2653189
178.6694,0.57395786,0.0097537534,0.0,0,11.006544,0.0,0.00070602016,7.2853069,11.076534,401.5759,-9.2646246
178.6718,0.58536381,0.0067767622,0.0,0,10.645576,0.0,0.00067428884,7.374032,11.074018,401.5542,-9.2643566
178.6742,0.59559959,0.0085862428,0.0,0,10.284603,0.0,0.00060065946,7.5433111,11.059644,401.53253,-9.2646065
178.6766,0.59831983,0.0119062,0.0,0,9.9236288,0.0,0.00060133426,7.656168,10.943642,401.51086,-9.2647266
178.679,0.56639618,0.014685705,0.0,0,9.5626554,0.0,0.00073203736,7.1101227,10.665912,401.13699,-9.2649202
178.6814,0.58212882,0.010795343,0.0,0,9.2092905,0.0,0.00080981175,7.4526286,10.285954,400.64578,-9.2651615
178.6838,5.6743593,0.18140849,0.0,0,8.8581219,0.0,0.01170974,70.973694,9.8953762,400.15454,-9.2607384
178.6862,6.1970677,0.63821465,0.0,0,8.518857,0.0,0.042937048,74.622803,9.4339933,399.6633,-9.2615709
178.6886,6.8726635,1.0655276,0.0,0,8.1848736,0.0,0.073233634,81.319931,8.9860649,401.90271,-9.260416
178.691,7.1621351,1.4513452,0.0,0,7.8607755,0.0,0.10096997,82.364891,8.6058683,406.09256,-9.2606735
178.6934,7.5348339,1.794184,0.0,0,7.543015,0.0,0.12691154,84.517159,8.2326212,410.28241,-9.2609138
178.6958,7.6060176,2.1364932,0.0,0,7.2334356,0.0,0.15358743,83.059219,7.8771873,414.47226,-9.2605019
178.6982,7.8787694,2.4536369,0.0,0,6.9312277,0.0,0.17839503,83.893005,7.5491085,419.13065,-9.2594585
178.7006,8.0633039,2.7615519,0.0,0,6.6355219,0.0,0.20268361,83.789352,7.2413626,424.44504,-9.2599897
178.703,8.2744427,3.056632,0.0,0,6.3480015,0.0,0.22700386,84.004982,6.9438825,429.75946,-9.2609167
178.7054,8.4536657,3.3413219,0.0,0,6.065536,0.0,0.25167945,83.569611,6.649507,435.07385,-9.2606659
178.7078,8.6721516,3.6202376,0.0,0,5.792079,0.0,0.27623597,83.756294,6.3621025,439.20358,-9.2604513
178.7102,8.8451338,3.8951912,0.0,0,5.5222936,0.0,0.30045313,83.313583,6.0844865,439.77939,-9.2599697
178.7126,9.0913343,4.1704512,0.0,0,5.2621331,0.0,0.32513696,83.536369,5.8054433,440.35516,-9.2605991
178.715,9.324439,4.4453368,0.0,0,5.0044241,0.0,0.35080251,83.564125,5.5294485,440.93097,-9.2603703
178.7174,9.5263567,4.7127981,0.0,0,4.7569842,0.0,0.3767949,83.230186,5.2584677,441.44437,-9.2584267
178.7198,9.7277164,4.9755459,0.0,0,4.5108657,0.0,0.4030945,82.694016,4.9939651,441.27164,-9.2589321
178.7222,9.9754715,5.2330351,0.0,0,4.2754698,0.0,0.42882776,82.617523,4.735013,441.09888,-9.2589111
178.7246,10.206124,5.4865837,0.0,0,4.0404716,0.0,0.45456386,82.479568,4.4799666,440.92615,-9.2590923
178.727,10.485929,5.7376823,0.0,0,3.8165054,0.0,0.48090947,82.510979,4.2358356,440.75342,-9.2585468
178.7294,10.706233,5.9776115,0.0,0,3.5926332,0.0,0.50785106,81.956245,3.991292,440.09906,-9.2580328
178.7318,10.981902,6.2059097,0.0,0,3.3790326,0.0,0.53423333,81.928581,3.7532148,439.40091,-9.2579241
178.7342,11.268736,6.4321661,0.0,0,3.1660566,0.0,0.55998862,81.933357,3.5281579,438.70276,-9.2582636
178.7366,11.585752,6.6541538,0.0,0,2.9619906,0.0,0.58546454,82.070007,3.308079,438.00461,-9.2589817
178.739,11.892459,6.8719597,0.0,0,2.7593822,0.0,0.61169231,82.096977,3.0930264,438.24011,-9.2585154
178.7414,12.221902,7.0832782,0.0,0,2.5644474,0.0,0.63874018,82.066597,2.8818104,438.7868,-9.2573977
178.7438,12.561994,7.2844987,0.0,0,2.3717272,0.0,0.66506875,82.153511,2.6791599,439.33353,-9.2577524
178.7462,12.929848,7.4783177,0.0,0,2.1855242,0.0,0.69019884,82.516022,2.480154,439.88025,-9.2579861
178.7486,13.327586,7.6724935,0.0,0,2.0022123,0.0,0.71556002,82.903336,2.2862391,439.66299,-9.2575703
178.751,13.695201,7.8616266,0.0,0,1.8243403,0.0,0.74112815,83.129875,2.1042402,438.90009,-9.258111
178.7534,14.133161,8.0408096,0.0,0,1.6499563,0.0,0.76743066,83.480766,1.9190373,438.13715,-9.2580404
178.7558,14.626499,8.2137098,0.0,0,1.4800413,0.0,0.7936185,84.160515,1.7431535,437.37424,-9.2577343
178.7582,15.155424,8.3861351,0.0,0,1.3141534,0.0,0.81907654,84.979546,1.5650878,436.07764,-9.2569809
178.7606,15.681799,8.562109,0.0,0,1.1518564,0.0,0.84484214,85.716568,1.3959302,434.03384,-9.2562351
178.763,16.226112,8.734539,0.0,0,0.99408036,0.0,0.87173659,86.370071,1.2202445,431.99005,-9.25455
178.7654,16.857073,8.9013968,0.0,0,0.83908135,0.0,0.8995778,87.247154,1.0530576,429.94629,-9.2545099
178.7678,17.496441,9.0576372,0.0,0,0.68903339,0.0,0.92654622,88.123901,0.88713926,428.8327,-9.2540588
178.7702,18.174654,9.2121496,0.0,0,0.54098594,0.0,0.95255476,89.236443,0.72563839,430.50967,-9.2543316
178.7726,18.87042,9.3670902,0.0,0,0.39818591,0.0,0.9783619,90.283112,0.57103658,432.18668,-9.253293
178.775,16.097811,9.3987122,0.0,0,0.25673628,0.0,0.9833129,76.906006,0.47484186,433.86365,-9.2546272
178.7774,14.534286,9.4051723,0.0,0,0.12094415,0.0,0.98556852,69.068909,0.43021035,435.64725,-9.2574282
178.7798,13.721898,9.4007511,0.0,0,-0.014479235,0.0,0.98662537,65.221642,0.39853668,438.6037,-9.2576513
178.7822,13.358483,9.4033813,0.0,0,-0.14691243,0.0,0.98677939,63.417751,0.36160079,441.56012,-9.2597094
178.7846,13.436669,9.4105749,0.0,0,-0.27934441,0.0,0.98654479,63.778286,0.3173846,444.51657,-9.2614489
178.787,13.732285,9.4210491,0.0,0,-0.41177642,0.0,0.98802036,65.062393,0.25280428,447.47299,-9.2604761
178.7894,13.862278,9.4262238,0.0,0,-0.54420841,0.0,0.98983198,65.58242,0.18516721,448.91174,-9.2595997
178.7918,13.855385,9.4256868,0.0,0,-0.67664039,0.0,0.99092114,65.473862,0.11816149,450.21249,-9.2584782
178.7942,13.725377,9.4310484,0.0,0,-0.80907238,0.0,0.99155653,64.848946,0.069131434,451.51328,-9.2585888
178.7966,13.473441,9.4392109,0.0,0,-0.94150436,0.0,0.99174762,63.651543,0.022531247,452.81403,-9.2606592
178.799,13.117854,9.4489231,0.0,0,-1.0739365,0.0,0.99258155,61.950619,-0.0063433037,453.38174,-9.2599459
178.8014,12.658374,9.451354,0.0,0,-0.76691425,400.0,0.99408633,59.669788,-0.017245395,453.70514,-9.2599068
178.8038,12.181767,9.4444056,0.0,0,-0.3084279,400.0,0.99425566,57.427223,-0.020061931,454.0285,-9.2614088
178.8062,11.715674,9.4393454,0.0,0,0.15005845,400.0,0.99330622,55.262794,-0.015316892,454.3519,-9.2617731
178.8086,11.301724,9.4424925,0.0,0,0.60854483,400.0,0.99262071,53.382446,-0.012119012,454.73395,-9.2614365
178.811,11.003023,9.4496279,0.0,0,1.0670311,400.0,0.99330503,51.899014,-0.010377317,455.15793,-9.2625389
178.8134,10.547763,9.4479103,0.0,0,1.5255175,400.0,0.99373823,49.752724,-0.0009845203,455.58194,-9.2609539
178.8158,9.2415819,9.4403305,0.0,0,1.9840039,400.0,0.99356633,43.727673,0.0580654,456.00592,-9.2636328
178.8182,6.4159946,9.4299097,0.0,0,2.4424908,400.0,0.99151081,30.522747,0.20077467,456.44485,-9.2647142
178.8206,2.5633402,9.4157333,0.0,0,2.9009769,400.0,0.98786867,12.569504,0.44280806,456.90469,-9.2669458
178.823,0.14428501,9.372571,0.0,0,3.3594635,400.0,0.9789288,0.79707259,0.86872345,457.36456,-9.2693701
178.8254,-0.18352455,9.3889942,0.0,0,3.8179498,400.0,0.98272598,-0.86443889,1.6044878,457.82443,-9.2700186
178.8278,0.090617016,9.427454,0.0,0,4.2764363,400.0,0.99085808,0.4506959,2.3962438,458.25009,-9.2702103
178.8302,-0.058375247,9.4284945,0.0,0,4.7349229,400.0,0.99137974,-0.26529258,3.0951185,458.57327,-9.2708845
178.8326,-0.046165869,9.4209414,0.0,0,5.1934094,400.0,0.98892707,-0.062917098,3.6256716,458.89642,-9.2685175
178.835,-0.064576335,9.4253922,0.0,0,5.651895,400.0,0.98879039,-0.33572406,4.0653763,459.21957,-9.2679005
178.8374,0.11814106,9.4164677,0.0,0,6.1103816,400.0,0.9879325,0.59462011,4.4935908,459.53613,-9.2686129
178.8398,-0.064424239,9.4141436,0.0,0,6.5688682,400.0,0.98880053,-0.29293388,4.9160128,459.78015,-9.2683697
178.8422,-0.079126947,9.41084,0.0,0,7.0273547,400.0,0.9882347,-0.3662,5.3572769,460.02414,-9.2684221
178.8446,0.055446096,9.4131546,0.0,0,7.4858413,400.0,0.98738563,0.26197889,5.8241134,460.26813,-9.2672215
178.847,-0.012261261,9.4212732,0.0,0,7.9443278,400.0,0.98776996,0.039996702,6.3093963,460.51215,-9.2667494
178.8494,-0.13172866,9.4230604,0.0,0,8.4028139,400.0,0.98872513,-0.57908517,6.7806334,460.72983,-9.2664709
178.8518,0.094434433,9.4149332,0.0,0,8.8612995,400.0,0.98883516,0.34766835,7.2671809,460.94513,-9.2659874
178.8542,-0.10980391,9.4079485,0.0,0,9.3197861,400.0,0.98778838,-0.38909659,7.742218,461.16043,-9.265337
178.8566,-0.0966921,9.4145374,0.0,0,9.7782726,400.0,0.98773497,-0.55061442,8.2081423,461.3757,-9.2658358
178.859,0.10929435,9.4148502,0.0,0,10.236759,400.0,0.98696399,0.53369451,8.6879272,461.54257,-9.2638168
178.8614,-0.14112732,9.4159832,0.0,0,10.695246,400.0,0.98766071,-0.60617107,9.1535282,461.69327,-9.2639637
178.8638,-0.10771773,9.4119701,0.0,0,11.153732,400.0,0.98812443,-0.55962092,9.619627,461.84399,-9.2647924
178.8662,0.10918719,9.4066696,0.0,0,11.612218,400.0,0.98745447,0.50302464,10.098634,461.99469,-9.2637129
178.8686,-0.12932967,9.4111805,0.0,0,12.070705,400.0,0.98707104,-0.5019663,10.56971,462.1203,-9.262743
178.871,-0.071385279,9.417779,0.0,0,12.529191,400.0,0.98715115,-0.48342085,11.042109,462.22794,-9.263731
178.8734,0.091965184,9.4176483,0.0,0,12.987678,400.0,0.98751295,0.49793383,11.509133,462.3356,-9.2636251
178.8758,-0.19865248,9.4127712,0.0,0,13.446164,400.0,0.98850775,-0.86357415,11.960707,462.44324,-9.2636595
178.8782,-0.014177853,9.4086924,0.0,0,13.904651,400.0,0.98807561,-0.14235801,12.420559,462.53595,-9.2627144
178.8806,0.13088718,9.4069405,0.0,0,14.363137,400.0,0.98644334,0.64267588,12.896274,462.6077,-9.2622271
178.883,-0.23286735,9.4102011,0.0,0,14.821624,400.0,0.98592472,-1.0386919,13.367976,462.67947,-9.2617416
178.8854,-0.023342177,9.4126511,0.0,0,15.28011,400.0,0.98704743,-0.21892609,13.85041,462.75122,-9.2639084
178.8878,0.13421187,9.409235,0.0,0,15.738596,400.0,0.9878273,0.61880177,14.332026,462.8194,-9.2627039
178.8902,-0.18860556,9.4036903,0.0,0,16.197083,400.0,0.98700941,-0.85810459,14.800398,462.87683,-9.2617168
178.8926,-0.002145878,9.4079838,0.0,0,16.655569,400.0,0.9866429,-0.11011776,15.257655,462.93423,-9.2629566
178.895,0.027633145,9.4170618,0.0,0,17.114056,400.0,0.98704273,0.21052371,15.717865,462.99164,-9.2625217
178.8974,-0.18232282,9.4189148,0.0,0,17.572542,400.0,0.98770857,-0.85343736,16.158804,463.04727,-9.2617188
178.8998,0.079294279,9.4111032,0.0,0,17.999401,400.0,0.98809743,0.28390911,16.617558,463.08316,-9.2614546
178.9022,-0.00079842692,9.4038105,0.0,0,18.0,400.0,0.98725623,0.050314952,17.077406,463.11905,-9.2611942
178.9046,-0.16823082,9.4083252,0.0,0,18.0,400.0,0.98657781,-0.80501461,17.506273,463.15491,-9.2624454
178.907,0.051163893,9.4138765,0.0,0,18.0,400.0,0.98681313,0.25498238,17.887226,463.1908,-9.2637901
178.9094,-0.076270796,9.4178839,0.0,0,18.0,400.0,0.98773915,-0.3212561,18.201706,463.18719,-9.2645082
178.9118,0.019394832,9.4162912,0.0,0,18.0,400.0,0.98894298,0.070768684,18.413475,463.18002,-9.2681246
178.9142,0.08382228,9.4172831,0.0,0,18.0,400.0,0.98953873,0.40090671,18.508585,463.17285,-9.2730207
178.9166,0.32199803,9.4270258,0.0,0,18.0,400.0,0.99027932,1.4944155,18.470781,463.16568,-9.2795477
178.919,0.42078596,9.434844,0.0,0,18.0,400.0,0.99044377,2.022938,18.340181,463.18002,-9.2898865
178.9214,0.42032355,9.4372759,0.0,0,18.0,400.0,0.99117243,1.9484553,18.207909,463.20157,-9.3027697
178.9238,0.41760537,9.432333,0.0,0,18.0,400.0,0.99170732,1.9886048,18.109333,463.22308,-9.3170853
178.9262,0.40269336,9.427248,0.0,0,18.0,400.0,0.99139106,1.8972974,18.049067,463.24463,-9.3349762
178.9286,0.40411684,9.4257441,0.0,0,18.0,400.0,0.98994219,1.9264194,18.043142,463.26196,-9.3560028
178.931,0.35183486,9.4286366,0.0,0,18.0,400.0,0.98971009,1.6748009,18.048624,463.27634,-9.375062
178.9334,0.36903408,9.4308014,0.0,0,18.0,400.0,0.99020708,1.7615663,18.062822,463.29068,-9.3950043
178.9358,0.40347323,9.4263468,0.0,0,18.0,400.0,0.99063003,1.9178957,18.087044,463.30505,-9.4137144
178.9382,0.39961588,9.4243326,0.0,0,18.0,400.0,0.99078363,1.8881693,18.110878,463.3194,-9.4338827
178.9406,0.3673884,9.4280529,0.0,0,18.0,400.0,0.99052233,1.7266264,18.127357,463.33374,-9.4513302
178.943,0.38446996,9.433073,0.0,0,18.0,400.0,0.99021345,1.814096,18.134649,463.34808,-9.4681807
178.9454,0.38975909,9.4332819,0.0,0,18.0,400.0,0.99029607,1.8471289,18.137859,463.36243,-9.4846029
178.9478,0.40938073,9.4299793,0.0,0,18.0,400.0,0.99101579,1.944977,18.141487,463.3732,-9.5032177
178.9502,0.40237656,9.4243326,0.0,0,18.0,400.0,0.99085706,1.8900611,18.137239,463.3732,-9.5205994
178.9526,0.3794204,9.4257584,0.0,0,18.0,400.0,0.99033409,1.7963089,18.134584,463.3732,-9.5386267
178.955,0.39079168,9.4300165,0.0,0,18.0,400.0,0.98984021,1.8416672,18.131823,463.3732,-9.5563326
178.9574,0.40656114,9.4303761,0.0,0,18.0,400.0,0.98994017,1.9177707,18.130466,463.37021,-9.5724878
178.9598,0.42520413,9.4278107,0.0,0,18.0,400.0,0.99066049,2.0230949,18.129448,463.33432,-9.5900364
178.9622,0.38600159,9.4244547,0.0,0,18.0,400.0,0.99083477,1.8273566,18.127352,463.29843,-9.6105261
178.9646,0.37811044,9.4275026,0.0,0,18.0,400.0,0.99037349,1.8172102,18.126419,463.26257,-9.6271963
178.967,0.40447897,9.4318075,0.0,0,18.0,400.0,0.98996222,1.9180301,18.125038,463.22668,-9.6452322
178.9694,0.42253542,9.4367723,0.0,0,18.0,400.0,0.99070662,1.9926673,18.121132,463.21054,-9.6633301
178.9718,0.42366472,9.4345264,0.0,0,18.0,400.0,0.99195391,1.9616433,18.119486,463.19617,-9.6803684
178.9742,0.38452896,9.4271345,0.0,0,18.0,400.0,0.99138319,1.8045617,18.115211,463.18182,-9.6986656
178.9766,0.3921552,9.425004,0.0,0,18.0,400.0,0.99000227,1.8597937,18.114384,463.16748,-9.7157164
178.979,0.41963547,9.4290314,0.0,0,18.0,400.0,0.98958695,1.972332,18.107073,463.12619,-9.7333326
178.9814,0.42368114,9.4319115,0.0,0,18.0,400.0,0.99019819,1.9991107,18.108788,463.07596,-9.7520695
178.9838,0.40028796,9.4309645,0.0,0,18.0,400.0,0.99105662,1.8832589,18.108202,463.02573,-9.770072
178.9862,0.3854658,9.4272823,0.0,0,18.0,400.0,0.99137884,1.8216517,18.108093,462.97549,-9.7876577
178.9886,0.40749761,9.4288712,0.0,0,18.0,400.0,0.99076527,1.8928651,18.104517,462.93362,-9.8043213
178.991,0.42056191,9.4328127,0.0,0,18.0,400.0,0.99025398,1.9809623,18.100491,462.89774,-9.822051
178.9934,0.41822404,9.4363298,0.0,0,18.0,400.0,0.990659,2.0104179,18.102682,462.86188,-9.839798
178.9958,0.38493896,9.4340525,0.0,0,18.0,400.0,0.99161083,1.8151575,18.09758,462.82599,-9.8573322
178.9982,0.38406441,9.4274635,0.0,0,18.0,400.0,0.99124813,1.8280755,18.100319,462.80505,-9.8755159
179.0006,0.41408303,9.4245577,0.0,0,18.0,400.0,0.99025762,1.9648553,18.098734,462.80505,-9.893054
179.003,0.41151124,9.4262714,0.0,0,18.0,400.0,0.98919415,1.9717815,18.098633,462.80505,-9.9114161
179.0054,0.38558501,9.4323053,0.0,0,18.0,400.0,0.99024463,1.8338535,18.098742,462.80505,-9.9306536
179.0078,0.37711874,9.4292955,0.0,0,18.0,400.0,0.99087101,1.7648727,18.097509,462.80325,-9.9469976
179.0102,0.39576221,9.4247484,0.0,0,18.0,400.0,0.99083084,1.8284732,18.097034,462.79608,-9.9627094
179.0126,0.41599759,9.4276524,0.0,0,18.0,400.0,0.990713,1.962327,18.094275,462.78891,-9.9812202
179.015,0.40711698,9.4327946,0.0,0,18.0,400.0,0.9902482,1.9202704,18.096529,462.78174,-10.000546
179.0174,0.37302798,9.4374857,0.0,0,18.0,400.0,0.99062157,1.8096217,18.094233,462.77277,-10.019057
179.0198,0.38895762,9.4350939,0.0,0,18.0,400.0,0.99161756,1.8370218,18.09441,462.74405,-10.036542
179.0222,0.40869921,9.429307,0.0,0,18.0,400.0,0.99153072,1.9195505,18.095322,462.71533,-10.054245
179.0246,0.4212431,9.426239,0.0,0,18.0,400.0,0.9905473,2.0036931,18.093763,462.68661,-10.07154
179.027,0.40362194,9.4270029,0.0,0,18.0,400.0,0.98946953,1.9185313,18.093519,462.6579,-10.088894
179.0294,0.39206156,9.430192,0.0,0,18.0,400.0,0.98977661,1.8601326,18.089447,462.59631,-10.107482
179.0318,0.41265371,9.4288025,0.0,0,18.0,400.0,0.99074286,1.8979234,18.089861,462.53174,-10.12403
179.0342,0.43284497,9.4273949,0.0,0,18.0,400.0,0.99124825,2.0284648,18.089268,462.46713,-10.140686
179.0366,0.43381155,9.429409,0.0,0,18.0,400.0,0.99120849,2.0349004,18.08494,462.40256,-10.159727
179.039,0.40386623,9.435401,0.0,0,18.0,400.0,0.9908067,1.9260043,18.085451,462.34335,-10.177832
179.0414,0.40551442,9.4372663,0.0,0,18.0,400.0,0.99066693,1.8600026,18.08864,462.28595,-10.195756
179.0438,0.41667166,9.4348602,0.0,0,18.0,400.0,0.99143595,1.9732043,18.087482,462.22855,-10.211437
179.0462,0.43717259,9.4282923,0.0,0,18.0,400.0,0.99147648,2.0703826,18.084534,462.17114,-10.229516
179.0486,0.43242949,9.4275227,0.0,0,18.0,400.0,0.99089986,2.0782921,18.08363,462.13046,-10.249076
179.051,0.39872956,9.4281969,0.0,0,18.0,400.0,0.98971528,1.9141175,18.086624,462.10175,-10.266139
179.0534,0.41964296,9.4330721,0.0,0,18.0,400.0,0.99018931,1.987879,18.082199,462.07306,-10.282553
179.0558,0.43716103,9.4310398,0.0,0,18.0,400.0,0.99095273,2.0660107,18.081739,462.04434,-10.300148
179.0582,0.43785715,9.4265442,0.0,0,18.0,400.0,0.99109083,2.0643532,18.080912,462.02161,-10.31896
179.0606,0.42409196,9.4278173,0.0,0,18.0,400.0,0.9909656,1.9960662,18.082411,462.00726,-10.338
179.063,0.39864928,9.4320726,0.0,0,18.0,400.0,0.99034256,1.8775781,18.080482,461.99289,-10.355604
179.0654,0.42709821,9.4360428,0.0,0,18.0,400.0,0.99029714,1.9690894,18.080626,461.97855,-10.371722
179.0678,0.44258705,9.4352198,0.0,0,18.0,400.0,0.9915204,2.0975804,18.079666,461.95523,-10.38925
179.0702,0.43486062,9.428896,0.0,0,18.0,400.0,0.99149126,2.0568249,18.078287,461.905,-10.408862
179.0726,0.40574396,9.4241381,0.0,0,18.0,400.0,0.99052149,1.9490216,18.077984,461.85477,-10.424957
179.075,0.40476128,9.427577,0.0,0,18.0,400.0,0.98966867,1.9304993,18.076151,461.80453,-10.442646
179.0774,0.43196189,9.4313574,0.0,0,18.0,400.0,0.98993194,2.0575323,18.079178,461.75369,-10.459691
179.0798,0.44129789,9.4329929,0.0,0,18.0,400.0,0.99114847,2.0893507,18.07432,461.69629,-10.478095
179.0822,0.40917385,9.4288311,0.0,0,18.0,400.0,0.99154019,1.9257196,18.07217,461.63885,-10.496367
179.0846,0.40993583,9.426753,0.0,0,18.0,400.0,0.99080271,1.9440441,18.073713,461.58142,-10.514756
179.087,0.41874251,9.4319592,0.0,0,18.0,400.0,0.99039733,1.9301745,18.073595,461.52402,-10.531895
179.0894,0.44105566,9.4353189,0.0,0,18.0,400.0,0.99036682,2.0899804,18.071079,461.49292,-10.548094
179.0918,0.44213507,9.4350204,0.0,0,18.0,400.0,0.99120587,2.0656176,18.065874,461.46423,-10.566283
179.0942,0.40591329,9.4297667,0.0,0,18.0,400.0,0.99153697,1.9546764,18.070154,461.43552,-10.586337
179.0966,0.41446477,9.4240465,0.0,0,18.0,400.0,0.99046415,1.9271353,18.066959,461.40683,-10.603067
179.099,0.43638116,9.4255819,0.0,0,18.0,400.0,0.98955262,2.0490091,18.064878,461.37811,-10.620395
179.1014,0.4524098,9.4313641,0.0,0,18.0,400.0,0.98991138,2.1523471,18.069817,461.34943,-10.640124
179.1038,0.41508636,9.4327297,0.0,0,18.0,400.0,0.99095756,1.9869299,18.070379,461.32071,-10.657252
179.1062,0.41221681,9.4270163,0.0,0,18.0,400.0,0.9910354,1.9302202,18.063583,461.29199,-10.675543
179.1086,0.41988045,9.4263248,0.0,0,18.0,400.0,0.99085468,1.9412224,18.062878,461.26328,-10.693218
179.111,0.45057777,9.4296646,0.0,0,18.0,400.0,0.99005884,2.106493,18.065304,461.23456,-10.710819
179.1134,0.44352031,9.4359732,0.0,0,18.0,400.0,0.99025196,2.118582,18.068476,461.20587,-10.728915
179.1158,0.42095941,9.4360132,0.0,0,18.0,400.0,0.99130154,1.9926535,18.062939,461.17715,-10.746009
179.1182,0.43118045,9.4319077,0.0,0,18.0,400.0,0.99206442,2.0444336,18.064659,461.13947,-10.763527
179.1206,0.44478893,9.4266272,0.0,0,18.0,400.0,0.99101233,2.0946639,18.066858,461.08923,-10.781061
179.123,0.45742765,9.4313459,0.0,0,18.0,400.0,0.99056131,2.1538651,18.064213,461.039,-10.79931
179.1254,0.43525183,9.4339838,0.0,0,18.0,400.0,0.99031997,2.07353,18.06262,460.98877,-10.817377
179.1278,0.41962945,9.4308157,0.0,0,18.0,400.0,0.99065554,1.9741567,18.062965,460.94214,-10.83512
179.1302,0.42371994,9.425889,0.0,0,18.0,400.0,0.99088514,2.0029979,18.060757,460.90625,-10.850944
179.1326,0.46790537,9.4245062,0.0,0,18.0,400.0,0.99042797,2.1953864,18.061903,460.87039,-10.868015
179.135,0.4674907,9.4293118,0.0,0,18.0,400.0,0.99010241,2.1997805,18.061813,460.8345,-10.886269
179.1374,0.42664996,9.4355755,0.0,0,18.0,400.0,0.99028933,2.0362263,18.062504,460.79922,-10.90495
179.1398,0.42930621,9.4353447,0.0,0,18.0,400.0,0.99107832,2.0580668,18.062052,460.77051,-10.9246
179.1422,0.43578976,9.4289932,0.0,0,18.0,400.0,0.99142629,2.0193238,18.062805,460.74179,-10.939964
179.1446,0.4596242,9.4244022,0.0,0,18.0,400.0,0.99073648,2.1836343,18.061974,460.7131,-10.958755
179.147,0.44844091,9.4272861,0.0,0,18.0,400.0,0.98995692,2.1257401,18.06135,460.68439,-10.976312
179.1494,0.41880986,9.4326134,0.0,0,18.0,400.0,0.98997486,1.990854,18.056459,460.62936,-10.99429
179.1518,0.42463323,9.430563,0.0,0,18.0,400.0,0.99043441,2.0263448,18.058916,460.57196,-11.011695
179.1542,0.45629928,9.4263678,0.0,0,18.0,400.0,0.99076289,2.136054,18.059919,460.51453,-11.028802
179.1566,0.45359102,9.4244947,0.0,0,18.0,400.0,0.99057996,2.148473,18.058075,460.45709,-11.047674
179.159,0.43236557,9.42941,0.0,0,18.0,400.0,0.99023104,2.0654707,18.057892,460.38354,-11.065096
179.1614,0.41874468,9.4332819,0.0,0,18.0,400.0,0.99002713,1.984284,18.059326,460.3046,-11.081697
179.1638,0.44627878,9.4343319,0.0,0,18.0,400.0,0.99069375,2.0542977,18.05315,460.22568,-11.099066
179.1662,0.46383107,9.4295835,0.0,0,18.0,400.0,0.99133402,2.1749976,18.053663,460.14673,-11.118454
179.1686,0.4551768,9.4253931,0.0,0,18.0,400.0,0.99091941,2.1458378,18.052116,460.10547,-11.13641
179.171,0.42433968,9.4257374,0.0,0,18.0,400.0,0.98996776,2.0132165,18.052292,460.09109,-11.153335
179.1734,0.43430012,9.4299879,0.0,0,18.0,400.0,0.98973346,2.0419421,18.045801,460.07675,-11.17184
179.1758,0.45678064,9.4326963,0.0,0,18.0,400.0,0.9907189,2.1239946,18.048994,460.06238,-11.18963
179.1782,0.45794415,9.4291687,0.0,0,18.0,400.0,0.99111575,2.1933017,18.051853,460.04504,-11.206024
179.1806,0.44292763,9.4260387,0.0,0,18.0,400.0,0.99100065,2.1247907,18.051443,460.02353,-11.224043
179.183,0.43032035,9.4280176,0.0,0,18.0,400.0,0.99016082,2.00214,18.047274,460.00198,-11.242609
179.1854,0.44760308,9.433075,0.0,0,18.0,400.0,0.99011624,2.1157098,18.044504,459.98047,-11.258792
179.1878,0.47585618,9.4345284,0.0,0,18.0,400.0,0.99064022,2.2095976,18.044884,459.94818,-11.277064
179.1902,0.46360874,9.429286,0.0,0,18.0,400.0,0.99132466,2.2137368,18.045078,459.88358,-11.294888
179.1926,0.43863824,9.4253664,0.0,0,18.0,400.0,0.99092555,2.0722706,18.048519,459.819,-11.313789
179.195,0.43986225,9.4267378,0.0,0,18.0,400.0,0.99005353,2.0568373,18.050776,459.75439,-11.330124
179.1974,0.45602623,9.4296026,0.0,0,18.0,400.0,0.9896028,2.1686401,18.048187,459.6922,-11.347063
179.2995,0.43270355,9.4296846,0.0,0,18.0,17.344156,0.9906587,2.0444179,18.03628,457.53497,-11.468041
180.4995,0.3437286,9.4406433,0.0,0,18.0,7.5886285e-16,0.99254107,1.6261337,18.000589,436.4613,-11.480717
181.6995,0.33537582,9.4492579,0.0,0,18.0,3.2805517000000004e-32,0.99412698,1.5819169,17.999779,421.16727,-11.480872
182.8995,0.31393388,9.4567633,0.0,0,18.0,1.4012985e-45,0.99542874,1.4809729,17.999924,407.50964,-11.481802
184.0995,0.31264043,9.4639339,0.0,0,18.0,1.4012985e-45,0.99681264,1.4702963,18.000162,395.10059,-11.481968
185.2995,0.30213365,9.4704323,0.0,0,18.0,1.4012985e-45,0.99801254,1.4235921,17.999891,383.44772,-11.481421
186.4995,0.30749664,9.4776525,0.0,0,18.0,1.4012985e-45,0.99918383,1.4434131,18.000862,372.27078,-11.481356
187.6995,0.30673391,9.4838886,0.0,0,18.0,1.4012985e-45,1.0003718,1.435478,17.99938,361.63708,-11.481049
188.8995,0.30479541,9.4896164,0.0,0,18.0,1.4012985e-45,1.0014113,1.4310706,18.000416,351.31775,-11.481308
190.0995,0.30285153,9.4956474,0.0,0,18.0,1.4012985e-45,1.0025369,1.4135461,17.999722,341.65933,-11.481917
191.2995,0.3096256,9.5016575,0.0,0,18.0,1.4012985e-45,1.0036721,1.4512924,18.000401,332.28265,-11.482417
192.4995,0.30415463,9.5075293,0.0,0,18.0,1.4012985e-45,1.0045995,1.4195675,18.000219,323.04324,-11.482407
193.6995,0.30966258,9.5124474,0.0,0,18.0,1.4012985e-45,1.0055909,1.4473242,18.000002,314.26389,-11.482388
194.8995,0.30827346,9.5181522,0.0,0,18.0,1.4012985e-45,1.0066369,1.4344095,17.998434,305.69415,-11.482449
196.0995,0.3010186,9.5225887,0.0,0,18.0,1.4012985e-45,1.0074036,1.4003311,18.00103,297.44757,-11.482226
197.2995,0.30160621,9.5280285,0.0,0,18.0,1.4012985e-45,1.0083897,1.3973302,17.999325,289.40781,-11.481649
198.4995,0.29617405,9.5328751,0.0,0,18.0,1.4012985e-45,1.0092757,1.3813379,18.000669,281.66245,-11.481777
199.6995,0.30289128,9.537077,0.0,0,18.0,1.4012985e-45,1.0101264,1.4035921,18.000217,274.0318,-11.481881
200.8995,0.30113187,9.5410795,0.0,0,18.0,1.4012985e-45,1.0108639,1.3993111,17.999783,266.78912,-11.481993
202.0995,0.29982921,9.5457449,0.0,0,18.0,1.4012985e-45,1.0115786,1.3920373,17.998552,259.64813,-11.48228
203.2995,0.30446211,9.5494919,0.0,0,18.0,1.4012985e-45,1.01235,1.4174805,17.999973,252.67763,-11.482353
204.4995,0.30573267,9.5537968,0.0,0,18.0,1.4012985e-45,1.0131707,1.4162538,17.999058,246.05835,-11.482668
205.6995,0.31312412,9.5568724,0.0,0,18.0,1.4012985e-45,1.013707,1.4523734,17.999311,239.66208,-11.482809
206.8995,0.30600974,9.5597744,0.0,0,18.0,1.4012985e-45,1.0142448,1.4149618,17.999842,233.16296,-11.482649
208.0995,0.28946364,9.5637655,0.0,0,18.0,1.4012985e-45,1.0148956,1.3390238,17.9998,227.00223,-11.482276
209.2995,0.29455489,9.5667191,0.0,0,18.0,1.4012985e-45,1.0155559,1.3576283,18.000921,221.02339,-11.481894
210.4995,0.29093924,9.5701113,0.0,0,18.0,1.4012985e-45,1.0161679,1.3442627,18.000196,215.31294,-11.481835
211.6995,0.29636163,9.5736437,0.0,0,18.0,1.4012985e-45,1.0167285,1.3688875,18.000595,209.79027,-11.481528
212.8995,0.30193672,9.5773258,0.0,0,18.0,1.4012985e-45,1.0174634,1.3947518,18.00012,204.22426,-11.481859
214.0995,0.29712316,9.5806217,0.0,0,18.0,1.4012985e-45,1.0181124,1.3678401,17.999788,199.25728,-11.481751
215.2995,0.30583206,9.5842676,0.0,0,18.0,1.4012985e-45,1.0187552,1.4110441,18.001255,194.63319,-11.481967
216.4995,0.30169475,9.5873842,0.0,0,18.0,1.4012985e-45,1.0193231,1.387534,17.999254,189.71326,-11.481751
217.6995,0.30324945,9.5904942,0.0,0,18.0,1.4012985e-45,1.0198339,1.3915294,18.000074,184.90308,-11.481959
218.8995,0.29677179,9.5934114,0.0,0,18.0,1.4012985e-45,1.0204599,1.3647633,18.000402,180.38655,-11.481738
220.0995,0.29584584,9.5969391,0.0,0,18.0,1.4012985e-45,1.0211415,1.3620087,17.999924,175.72591,-11.482113
221.2995,0.29122478,9.6003084,0.0,0,18.0,1.4012985e-45,1.0216451,1.3378521,18.000328,171.36162,-11.482501
222.4995,0.30209529,9.6033297,0.0,0,18.0,1.4012985e-45,1.0222447,1.3853127,18.000418,167.14587,-11.482258
223.6995,0.29828519,9.605794,0.0,0,18.0,1.4012985e-45,1.0226965,1.3722074,18.000425,163.09685,-11.48261
224.8995,0.29699048,9.6084385,0.0,0,18.0,1.4012985e-45,1.0232524,1.3608001,17.999935,159.08101,-11.482178
226.0995,0.2893948,9.6114292,0.0,0,18.0,1.4012985e-45,1.0237902,1.3349413,18.000193,155.22748,-11.482329
227.2995,0.30868292,9.6141214,0.0,0,18.0,1.4012985e-45,1.0241902,1.4151853,17.999422,151.4319,-11.482631
228.4995,0.28775918,9.6172152,0.0,0,18.0,1.4012985e-45,1.0248499,1.3190355,18.000704,147.63698,-11.482224
229.6995,0.29990569,9.6191578,0.0,0,18.0,1.4012985e-45,1.0252627,1.3685718,17.999681,144.10881,-11.482692
230.8995,0.29734927,9.6220655,0.0,0,18.0,1.4012985e-45,1.0257447,1.3648058,17.999857,140.67844,-11.48266
232.0995,0.29094011,9.6240091,0.0,0,18.0,1.4012985e-45,1.0261004,1.3292791,18.001099,137.38007,-11.482255
233.2995,0.28757262,9.6268597,0.0,0,18.0,1.4012985e-45,1.026608,1.3185477,18.000683,134.12178,-11.48237
234.4995,0.29518372,9.6286106,0.0,0,18.0,1.4012985e-45,1.0270214,1.3452832,17.999903,130.80663,-11.482633
235.6995,0.28858727,9.6304207,0.0,0,18.0,1.4012985e-45,1.0273809,1.3194293,17.999577,127.78841,-11.482314
236.8995,0.28223619,9.6329412,0.0,0,18.0,1.4012985e-45,1.0277289,1.2889386,18.000618,124.82288,-11.482147
238.0995,0.2869395,9.6351089,0.0,0,18.0,1.4012985e-45,1.028183,1.3082104,17.99996,121.86033,-11.482132
239.1995,0.27921519,9.6365519,0.0,0,18.0,1.4012985e-45,1.0284787,1.2730887,18.000446,119.3431,-11.64364