File: examples/dan-msc-case-studies/CS3/data/01 raw data/baron_test_128.csv
Time(sec),Force(kN),Jaw(mm),PowAngle(deg),Power(W),Pram,PTemp,Strain,Stress(MPa),Stroke(mm),TC1(C),wedge(mm)
0.0,0.95342076,0.89447826,0.0,0,11.076097,0.0015406095,0.061481744,11.394678,11.076874,30.289679,-9.0741167
1.2,0.90502506,-0.0017637494,0.0,0,11.076097,3.5159011,-0.00011452023,11.532688,11.076362,29.791271,-9.4483795
2.4,0.91043431,-0.001625472,0.0,0,11.076097,7.1159024,-0.00011256948,11.582978,11.076174,29.441425,-9.4508362
3.6,0.9008022,-0.0018956658,0.0,0,11.076097,10.715902,-0.0001138256,11.472486,11.076205,29.15733,-9.4527464
4.8,0.88868433,-0.0015153299,0.0,0,11.076097,14.315903,-7.5546341e-05,11.322487,11.077389,29.016281,-9.4541464
6.0,0.86598647,-0.0016719206,0.0,0,11.076097,17.915905,-9.6206582e-05,11.025688,11.074526,28.869295,-9.453145
7.2,0.84674829,-0.0019037188,0.0,0,11.076097,21.515905,-0.00011994511,10.789797,11.075829,28.723345,-9.4519033
8.4,0.84006578,-0.0015566411,0.0,0,11.076097,25.115906,-0.00011506592,10.697347,11.076275,28.625784,-9.4511309
9.6,0.81645179,-0.00168033,0.0,0,11.076097,28.715908,-0.000124075,10.38139,11.075691,28.550714,-9.4492741
10.8,0.81681925,0.00052438996,21.599211,0,11.076097,32.315914,1.1711007e-05,10.406156,11.076405,28.516756,-9.4478474
12.0,0.82339925,0.00087309373,34.626118,0,11.076097,35.915913,3.0445854e-05,10.464395,11.076395,29.069382,-9.4461317
13.2,0.83772236,-0.0023905756,42.388042,0,11.076097,39.515907,-0.000164342,10.661496,11.07636,30.853689,-9.4445086
14.4,0.87397271,-0.0080519468,47.166901,0,11.076097,43.115902,-0.00052497006,11.139408,11.076428,34.038521,-9.4425316
15.6,0.89864212,-0.013681815,50.324131,0,11.076097,46.715904,-0.00091174984,11.451665,11.076845,38.215816,-9.4411688
16.8,0.91568267,-0.018631041,51.292439,0,11.076097,50.315907,-0.001235814,11.683695,11.075693,43.893143,-9.4392633
18.0,0.92130339,-0.024284657,51.56982,0,11.076097,53.915913,-0.0016206132,11.733829,11.076658,49.744354,-9.4374275
19.2,0.91842413,-0.030169485,50.823009,0,11.076097,57.515911,-0.0020005209,11.725564,11.076891,55.828693,-9.436326
20.4,0.92309213,-0.034835152,48.917492,0,11.076097,61.115913,-0.0023068835,11.775451,11.075977,61.806568,-9.4343748
21.6,0.91714567,-0.038613264,46.744381,0,11.076097,64.715927,-0.0025525617,11.688835,11.077545,67.133743,-9.4324808
22.8,0.91461402,-0.041276511,45.01881,0,11.076097,68.315926,-0.0027255435,11.698822,11.075397,71.308319,-9.4306068
24.0,0.91418767,-0.043730546,43.527859,0,11.076097,71.915939,-0.0029004689,11.657807,11.076519,74.926208,-9.4292049
25.2,0.91616172,-0.046544336,42.743343,0,11.076097,75.515915,-0.0031060688,11.695094,11.076281,77.869209,-9.4272308
26.4,0.91401786,-0.047769818,42.978401,0,11.076097,79.115929,-0.0031864501,11.679121,11.076105,80.399261,-9.4250736
27.6,0.92343074,-0.050104883,43.620365,0,11.076097,82.715919,-0.003351857,11.788645,11.07697,82.930725,-9.4237242
28.8,0.91952991,-0.052758612,45.120461,0,11.076097,86.315941,-0.0035245386,11.77259,11.076481,85.300957,-9.4216003
30.0,0.92382252,-0.056324109,46.8363,0,11.076097,89.915924,-0.003761749,11.797936,11.075988,87.892044,-9.419486
31.2,0.92271721,-0.059805874,48.382542,0,11.076097,93.515945,-0.0039851069,11.799916,11.076796,90.92054,-9.4182606
32.4,0.93181616,-0.064241283,49.743256,0,11.076097,97.115929,-0.0042685415,11.911678,11.075972,94.129036,-9.4161558
33.6,0.92918015,-0.069873706,50.822563,0,11.076097,100.71593,-0.0046476368,11.886642,11.075941,97.753029,-9.4146729
34.8,0.9275564,-0.072899088,51.196285,0,11.076097,104.31593,-0.0048520141,11.888081,11.076514,102.06211,-9.4127312
36.0,0.93266499,-0.076935723,51.196285,0,11.076097,107.91594,-0.0051087858,11.947646,11.076143,106.52057,-9.4115076
37.2,0.91895783,-0.081515364,51.196285,0,11.076097,111.51592,-0.0054193945,11.76358,11.076766,110.72322,-9.4094543
38.4,0.92109853,-0.085780531,50.822792,0,11.076097,115.11594,-0.0056997929,11.804719,11.07629,115.00358,-9.407835
39.6,0.92164528,-0.089557372,50.045113,0,11.076097,118.71593,-0.0059318342,11.80936,11.075994,119.40012,-9.4059381
40.8,0.92798239,-0.092783362,49.67374,0,11.076097,122.31593,-0.006149265,11.882757,11.075365,123.05761,-9.4041986
42.0,0.92709315,-0.097590476,49.636234,0,11.076097,125.91594,-0.0064758798,11.877101,11.075562,126.54527,-9.4019251
43.2,0.92819607,-0.099663094,49.636227,0,11.076097,129.51605,-0.0066200607,11.895579,11.076838,129.8091,-9.4002285
44.4,0.92853665,-0.10193246,49.839062,0,11.076097,133.11592,-0.0067856885,11.904769,11.075435,133.18944,-9.3985872
45.6,0.92696202,-0.10552337,50.43367,0,11.076097,136.71593,-0.007022501,11.872796,11.075526,136.27248,-9.3965836
46.8,0.91767102,-0.10869941,50.438644,0,11.076097,140.31592,-0.0072410032,11.776701,11.076767,139.86855,-9.3946991
48.0,0.92971551,-0.11213499,50.690105,0,11.076097,143.91592,-0.0074638319,11.931488,11.075828,143.49278,-9.3929806
49.2,0.91843402,-0.1154948,50.930798,0,11.076097,147.51593,-0.0076679909,11.786166,11.07592,146.88058,-9.3911762
50.4,0.92303938,-0.11909383,51.56876,0,11.076097,151.11594,-0.0079076467,11.832759,11.076167,150.20505,-9.3891039
51.6,0.92883825,-0.12267099,52.17717,0,11.076097,154.71594,-0.0081279185,11.931185,11.076489,153.4274,-9.3876352
52.8,0.93288964,-0.1278985,52.477554,0,11.076097,158.31593,-0.0084832329,11.987826,11.076776,157.00681,-9.3859348
54.0,0.93651682,-0.1313951,53.308445,0,11.076097,161.91592,-0.0087243663,12.025804,11.075782,160.30414,-9.3841782
55.2,0.93681484,-0.13418153,53.925388,0,11.076097,165.51595,-0.0089072259,12.034401,11.076945,163.80315,-9.3824558
56.4,0.93579406,-0.13833588,54.311626,0,11.076097,169.11594,-0.0091710798,12.024634,11.076815,167.35437,-9.3808727
57.6,0.93398309,-0.14305106,54.931465,0,11.076097,172.71594,-0.0094751203,12.006617,11.075358,170.96733,-9.379138
58.8,0.93318874,-0.14780433,55.239254,0,11.076097,176.31595,-0.0097767729,11.999431,11.074518,174.81091,-9.3772478
60.0,0.93025017,-0.15218556,55.535881,0,11.076097,179.91595,-0.010084226,11.966265,11.075967,178.63242,-9.3757477
61.2,0.93191922,-0.15696602,55.583664,0,11.076097,183.51593,-0.010411587,11.984824,11.07725,182.5153,-9.3738232
62.4,0.9310559,-0.16106117,55.643074,0,11.076097,187.11597,-0.010693427,11.981369,11.076059,186.40118,-9.3717413
63.6,0.92865711,-0.1652343,55.843506,0,11.076097,190.71594,-0.010971835,11.965111,11.076308,190.08647,-9.3698673
64.8,0.92574179,-0.1695639,55.843506,0,11.076097,194.31596,-0.011267721,11.929634,11.076604,194.01833,-9.3684168
66.0,0.9226855,-0.17421667,55.843506,0,11.076097,197.91595,-0.01157093,11.888693,11.076387,197.69223,-9.3662834
67.2,0.92844582,-0.17824583,55.835651,0,11.076097,201.51596,-0.011814281,11.978064,11.075356,201.51251,-9.3642187
68.4,0.92803413,-0.18289483,55.840435,0,11.076097,205.11597,-0.012112508,11.960776,11.076771,205.04768,-9.3623705
69.6,0.93337911,-0.18663211,55.782425,0,11.076097,208.71597,-0.012357501,12.029476,11.075559,208.72012,-9.3605499
70.8,0.92622668,-0.19098012,55.843506,0,11.076097,212.31595,-0.012637802,11.948013,11.076839,212.22006,-9.3587523
72.0,0.93975794,-0.19447385,55.843506,0,11.076097,215.91597,-0.012884622,12.109113,11.074591,215.88536,-9.3565054
73.2,0.92870849,-0.19782507,55.536034,0,11.076097,219.51595,-0.013109148,11.972252,11.07583,219.8736,-9.3547411
74.4,0.92964208,-0.20138836,55.132126,0,11.076097,223.11598,-0.013331765,12.002623,11.075755,223.93307,-9.3530493
75.6,0.93430388,-0.20439786,55.239243,0,11.076097,226.71596,-0.013527241,12.043809,11.076562,227.14722,-9.3512239
76.8,0.92720312,-0.20790774,55.462334,0,11.076097,230.31598,-0.013749152,11.961304,11.076257,230.23633,-9.3491049
78.0,0.92871028,-0.21141526,55.535885,0,11.076097,233.91595,-0.013974067,12.001984,11.077029,233.62952,-9.3473148
79.2,0.93189991,-0.21454376,55.843506,0,11.076097,237.51598,-0.014190077,12.041613,11.076233,237.04607,-9.3451071
80.4,0.92777359,-0.21792252,56.129147,0,11.076097,241.11597,-0.014435019,11.987397,11.075167,240.21481,-9.3434944
81.6,0.93723005,-0.22153594,56.425777,0,11.076097,244.71599,-0.014666378,12.111962,11.076158,243.90617,-9.3416977
82.8,0.93981194,-0.22494538,56.711422,0,11.076097,248.31596,-0.014904907,12.152163,11.076335,247.42519,-9.339921
84.0,0.93466151,-0.229121,56.98608,0,11.076097,251.91599,-0.015174526,12.082998,11.076869,250.97783,-9.3379822
85.2,0.93022603,-0.23280117,56.986904,0,11.076097,255.51598,-0.015407226,12.029035,11.07702,254.81985,-9.3361349
86.4,0.93919212,-0.23611754,57.01915,0,11.076097,259.11624,-0.01562787,12.146797,11.07563,258.64703,-9.3340111
87.6,0.94677424,-0.23961727,57.257843,0,11.076097,262.71597,-0.015838917,12.252582,11.075991,262.23904,-9.3322945
88.8,0.95159024,-0.24440496,57.260738,0,11.076097,266.31598,-0.016154941,12.311956,11.076282,265.82364,-9.3307552
90.0,0.94723612,-0.25007376,57.535397,0,11.076097,269.91599,-0.016527174,12.26818,11.075901,269.29849,-9.3289309
91.2,0.94488257,-0.25118014,57.810051,0,11.076097,273.51596,-0.016603418,12.225848,11.076363,272.77359,-9.3269644
92.4,0.93528682,-0.25604245,58.073727,0,11.076097,277.11597,-0.016920244,12.109928,11.076552,276.19653,-9.3256674
93.6,0.9354018,-0.25974354,58.339127,0,11.076097,280.71597,-0.017147074,12.103428,11.075604,279.62643,-9.3240414
94.8,0.94214165,-0.26298067,58.853752,0,11.076097,284.31598,-0.017359704,12.224208,11.076886,283.09897,-9.3216581
96.0,0.94467586,-0.26668519,59.106438,0,11.076097,287.91599,-0.017608421,12.241979,11.075816,286.73254,-9.3197002
97.2,0.9566347,-0.27399263,59.344692,0,11.076097,291.51596,-0.018101396,12.393549,11.07583,290.49249,-9.317626
98.4,0.94696617,-0.27634749,59.210644,0,11.076097,295.11597,-0.018261865,12.264633,11.075987,294.54495,-9.3163671
99.6,0.93642795,-0.28019407,59.106449,0,11.076097,298.716,-0.018522883,12.147725,11.076721,298.44366,-9.3145723
100.8,0.93549329,-0.28404438,58.853794,0,11.076097,302.31598,-0.018770356,12.146036,11.076361,302.63715,-9.3125544
102.0,0.94899243,-0.28696987,58.591583,0,11.076097,305.91595,-0.018970054,12.325751,11.075074,306.53174,-9.3104067
103.2,0.95087421,-0.29157531,58.59008,0,11.076097,309.51599,-0.019267073,12.344833,11.075725,310.00586,-9.3085041
104.4,0.94641149,-0.29528227,58.735195,0,11.076097,313.11597,-0.019476552,12.285881,11.075389,313.1286,-9.3061476
105.6,0.9333865,-0.29819781,58.853752,0,11.076097,316.716,-0.019671436,12.125133,11.076653,316.53909,-9.3047571
106.8,0.94355452,-0.30120146,59.106438,0,11.076097,320.31598,-0.019869924,12.264891,11.076056,319.89267,-9.3031645
108.0,0.95061219,-0.30398679,59.348087,0,11.076097,323.91599,-0.020062137,12.349917,11.076203,323.31967,-9.3015728
109.2,0.94543266,-0.31087738,59.574692,0,11.076097,327.51599,-0.020519383,12.278095,11.075363,326.76248,-9.2993612
110.4,0.94862479,-0.31277141,59.663166,0,11.076097,331.116,-0.020640416,12.316318,11.076166,330.37817,-9.2974634
111.6,0.93943208,-0.31649011,59.842525,0,11.076097,334.716,-0.020861857,12.210506,11.075064,333.9472,-9.2951908
112.8,0.95153415,-0.31954181,60.083897,0,11.076097,338.31601,-0.021050809,12.388946,11.076428,337.53616,-9.2932806
114.0,0.95689511,-0.3255209,60.314812,0,11.076097,341.91602,-0.021468667,12.446103,11.075628,341.08453,-9.291399
115.2,0.94332182,-0.32815933,60.314934,0,11.076097,345.51602,-0.021655003,12.275401,11.075451,344.80777,-9.289567
116.4,0.94994986,-0.33144376,60.337189,0,11.076097,349.116,-0.021864956,12.375546,11.076112,348.59518,-9.2878332
117.6,0.94322366,-0.33437127,60.392376,0,11.076097,352.716,-0.022069698,12.265793,11.075154,352.38083,-9.2858038
118.8,0.95163542,-0.34115046,60.513283,0,11.076097,356.31601,-0.022503644,12.39032,11.075806,356.02985,-9.2844353
120.0,0.93107253,-0.34270018,60.356613,0,11.076097,359.91602,-0.022605805,12.132915,11.076871,359.84546,-9.282753
121.2,0.93928307,-0.34562716,60.525402,0,11.076097,363.51602,-0.022784004,12.244164,11.076057,363.40546,-9.2807312
122.4,0.95460421,-0.34914079,60.556637,0,11.076097,367.11603,-0.02300407,12.431212,11.076177,366.95306,-9.2782907
123.6,0.94456494,-0.35282031,60.556637,0,11.076097,370.71603,-0.023232391,12.302726,11.075637,370.63257,-9.2763681
124.8,0.94117564,-0.35583937,60.08424,0,11.076097,374.31601,-0.023436811,12.267028,11.076715,375.09357,-9.2746143
126.0,0.94937468,-0.35774815,60.084183,0,11.076097,377.91602,-0.023566037,12.38872,11.075644,378.35245,-9.272089
127.2,0.94699067,-0.36407164,60.31424,0,11.076097,381.51602,-0.023979913,12.350877,11.076562,381.37082,-9.2704048
128.4,0.94668889,-0.36528915,60.787327,0,11.076097,385.11603,-0.024041615,12.349393,11.075934,384.12952,-9.2685738
129.6,0.94679105,-0.36836842,61.132729,0,11.076097,388.71603,-0.024243286,12.35614,11.076354,387.49542,-9.2670031
130.8,0.95665222,-0.37117589,61.468498,0,11.076097,392.31604,-0.024421196,12.487739,11.075869,390.83832,-9.265029
132.0,0.95282352,-0.37752312,61.468636,0,11.076097,395.91602,-0.024836753,12.440093,11.07605,395.19998,-9.2632647
133.2,0.93644065,-0.37968898,61.468498,0,11.076097,399.51602,-0.025016334,12.235733,11.075733,398.99036,-9.2611094
134.4,0.95940745,-0.38078958,59.929958,0,11.076097,399.99893,-0.025076782,12.544882,11.076136,402.45752,-9.2612228
135.6,0.96047896,-0.38436827,57.551685,0,11.076097,399.99893,-0.025326625,12.529721,11.075702,405.2482,-9.2613544
136.8,0.91264886,-0.38285795,54.970104,0,11.076097,399.99893,-0.025218341,11.912793,11.076113,406.77597,-9.2609463
138.0,0.90972686,-0.38100341,52.648438,0,11.076097,399.99893,-0.025087563,11.883698,11.075846,407.0947,-9.2610273
139.2,0.8951667,-0.37851033,50.876808,0,11.076097,399.99893,-0.024915777,11.686897,11.076153,406.32919,-9.2609682
140.4,0.87675816,-0.37745032,50.042728,0,11.076097,399.99893,-0.024835346,11.449406,11.074795,404.88708,-9.2607746
141.6,0.85984576,-0.37494087,49.81329,0,11.076097,399.99893,-0.02468933,11.217174,11.076575,403.25067,-9.2608576
142.8,0.8568598,-0.37301862,50.403809,0,11.076097,399.99893,-0.024564134,11.188572,11.077311,401.49966,-9.2610674
144.0,0.86292809,-0.37274116,51.196255,0,11.076097,399.99893,-0.024542669,11.264411,11.075925,400.00296,-9.2611275
145.2,0.86196369,-0.37182128,52.28315,0,11.076097,399.99893,-0.02447382,11.242868,11.07633,398.9201,-9.2608976
146.4,0.87029243,-0.3727572,53.311367,0,11.076097,399.99893,-0.024533415,11.370594,11.075727,398.19666,-9.2616291
147.6,0.8835476,-0.37238207,53.975815,0,11.076097,399.99893,-0.024499036,11.528493,11.076496,397.89218,-9.2612476
148.8,0.89351642,-0.37524742,54.623947,0,11.076097,399.99893,-0.024715191,11.659182,11.076247,397.96866,-9.2613087
150.0,0.89881235,-0.3750509,54.931637,0,11.076097,399.99893,-0.024699101,11.725639,11.075906,398.26007,-9.2613535
151.2,0.89961463,-0.37590852,55.239254,0,11.076097,399.99893,-0.024756383,11.727932,11.075784,398.69559,-9.2615347
152.4,0.91822493,-0.37588772,55.239254,0,11.076097,399.99893,-0.024766074,11.988403,11.075506,399.22766,-9.2616501
153.6,0.92006487,-0.38018557,54.931652,0,11.076097,399.99893,-0.025049586,12.002744,11.077267,399.72339,-9.2619143
154.8,0.92095119,-0.37917086,54.682968,0,11.076097,399.99893,-0.024974931,12.025375,11.075969,400.19342,-9.2623777
156.0,0.93588722,-0.37917402,54.305561,0,11.076097,399.99893,-0.024977233,12.215954,11.075985,400.46851,-9.262495
157.2,0.93682772,-0.37877631,53.976383,0,11.076097,399.99893,-0.024929194,12.235239,11.076802,400.74252,-9.2624063
158.4,0.92980069,-0.38140893,53.665184,0,11.076097,399.99893,-0.025084697,12.138925,11.076751,400.83539,-9.2627325
159.6,0.92353904,-0.38022056,53.470657,0,11.076097,399.99893,-0.025021052,12.052369,11.076344,400.85123,-9.2628365
160.8,0.91753876,-0.37979648,53.316654,0,11.076097,399.99893,-0.025010267,11.983563,11.076233,400.7471,-9.2626944
162.0,0.9285143,-0.37945682,53.31665,0,11.076097,399.99893,-0.024980724,12.126496,11.076537,400.56955,-9.2623959
163.2,0.91288298,-0.3809675,53.213238,0,11.076097,399.99893,-0.025058582,11.912882,11.075599,400.38062,-9.2621088
164.4,0.91120058,-0.38098666,53.259399,0,11.076097,399.99893,-0.025068207,11.914135,11.076243,400.26218,-9.2622623
165.6,0.91812539,-0.3805666,53.31665,0,11.076097,399.99893,-0.025043761,11.971466,11.077109,400.08566,-9.2621727
166.8,0.92876309,-0.38147163,53.31665,0,11.076097,399.99893,-0.025117189,12.132178,11.075524,399.9501,-9.262538
168.0,0.91633892,-0.381143,53.323956,0,11.076097,399.99893,-0.025105048,11.952703,11.076614,399.84448,-9.2622252
169.2,0.90759319,-0.3819606,53.657173,0,11.076097,399.99893,-0.025153397,11.853809,11.075377,399.77872,-9.2621059
170.4,0.93293911,-0.38136336,53.657223,0,11.076097,399.99893,-0.025120404,12.173249,11.076089,399.76117,-9.2620382
171.6,0.93995577,-0.38288817,53.657223,0,11.076097,399.99893,-0.025234085,12.276485,11.076421,399.77002,-9.2619371
172.8,0.92770767,-0.38273916,53.657223,0,11.076097,399.99893,-0.025201268,12.10507,11.076016,399.81717,-9.2616768
174.0,0.92747843,-0.38325769,53.725201,0,11.076097,399.99893,-0.025227692,12.111603,11.075522,399.81775,-9.2617283
175.2,0.93678129,-0.38289675,53.687199,0,11.076097,399.99893,-0.025194099,12.236582,11.075694,399.92575,-9.2622585
176.4,0.94939208,-0.38488647,53.65723,0,11.076097,399.99893,-0.025331557,12.414927,11.075178,399.95694,-9.2621946
177.6,0.9276185,-0.38413063,53.682785,0,11.076097,399.99893,-0.025285847,12.116743,11.075677,399.9295,-9.2618809
178.6313,0.93835253,0.019515332,16.386288,0,11.076099,65.880898,0.0013496337,11.97952,11.07828,400.00043,-9.2636089
178.6337,0.93993449,0.020999836,3.53426,0,11.076099,2.8482205e-15,0.0012239607,11.936288,11.078084,400.00043,-9.2625399
178.6361,0.94504136,0.024143225,0.0,0,11.076099,1.2312851e-31,0.0012159916,11.916508,11.073133,400.03702,-9.2610216
178.6385,0.94426727,0.022283619,0.0,0,11.076099,0.0,0.0014164964,12.009515,11.076703,400.08749,-9.262352
178.6409,0.92843044,0.018461635,0.0,0,11.076099,0.0,0.0015095829,11.829804,11.078517,400.13794,-9.2635498
178.6433,0.93020195,0.014743081,0.0,0,11.076099,0.0,0.0011621593,11.821572,11.076669,400.18842,-9.2633715
178.6457,0.92782384,0.016178643,0.0,0,11.076099,0.0,0.00096675329,11.784573,11.074286,400.19525,-9.2627697
178.6481,0.92635763,0.017855043,0.0,0,11.076099,0.0,0.0010326855,11.71385,11.079271,400.16641,-9.2631168
178.6505,0.93544662,0.017477363,0.0,0,11.076099,0.0,0.0011954664,11.93515,11.077271,400.13757,-9.2626181
178.6529,0.92274219,0.017817309,0.0,0,11.076099,0.0,0.0014486889,11.672326,11.077161,400.10876,-9.2644196
178.6553,0.91523826,0.017489264,0.0,0,11.076099,0.0,0.0013403251,11.716973,11.07507,400.07721,-9.2627821
178.6577,0.92842925,0.018396221,0.0,0,11.076099,0.0,0.0010614186,11.823856,11.076852,400.04117,-9.2636023
178.6601,0.93242466,0.022519464,0.0,0,11.076099,0.0,0.0010891678,11.859076,11.076807,400.00513,-9.2641554
178.6625,0.91903841,0.021527348,0.0,0,11.076099,0.0,0.0013807847,11.6335,11.0805,399.96909,-9.2654743
178.6649,0.90708596,0.018489044,0.0,0,11.076099,0.0,0.0015142233,11.537999,11.078835,399.94168,-9.2638826
178.6673,0.91403288,0.01642303,0.0,0,11.076099,0.0,0.0013111754,11.636347,11.077541,399.94888,-9.263032
178.6697,0.93295872,0.017735161,0.0,0,11.076099,0.0,0.0010778395,11.714995,11.076771,399.95612,-9.2640038
178.6721,0.91583675,0.019463738,0.0,0,11.076099,0.0,0.0011762182,11.704631,11.078635,399.96332,-9.2630901
178.6745,0.91493905,0.019073153,0.0,0,11.076099,0.0,0.0012384346,11.571229,11.078485,399.9707,-9.263093
178.6769,0.90828931,0.016922669,0.0,0,11.076099,0.0,0.0013527713,11.509587,11.075111,399.98511,-9.2625771
178.6793,0.9071908,0.015562756,0.0,0,11.076099,0.0,0.0012022345,11.473736,11.076015,399.99951,-9.2625179
178.6817,0.91273922,0.019290896,0.0,0,11.006544,0.0,0.0011658209,11.6079,11.077431,400.01395,-9.2622919
178.6841,0.9074468,0.023418499,0.0,0,10.645576,0.0,0.0011747353,11.555976,11.076274,400.02835,-9.2632017
178.6865,0.89155775,0.021523431,0.0,0,10.284603,0.0,0.0013819226,11.292162,11.064458,400.02438,-9.2635527
178.6889,0.90226203,0.017678201,0.0,0,9.9236288,0.0,0.0014579977,11.598026,10.951375,400.01718,-9.2621479
178.6913,0.90542197,0.01477347,0.0,0,9.5626554,0.0,0.0012411233,11.626003,10.684613,400.00998,-9.2611904
178.6937,0.92087597,0.016516797,0.0,0,9.2092905,0.0,0.00098218303,11.720695,10.308461,400.00278,-9.2631721
178.6961,0.88947773,0.019756395,0.0,0,8.8581219,0.0,0.0011692131,11.198732,9.8321943,403.6474,-9.2633324
178.6985,0.91183466,0.019714605,0.0,0,8.518857,0.0,0.0012729722,11.544801,9.3356047,409.05029,-9.2633133
178.7009,5.9452686,0.26228347,0.0,0,8.1848736,0.0,0.017273985,74.541641,8.9420042,414.45319,-9.2573805
178.7033,6.5576744,0.61270827,0.0,0,7.8607755,0.0,0.041641653,80.075371,8.5206108,419.85611,-9.257513
178.7057,6.7293,0.98654228,0.0,0,7.543015,0.0,0.067408316,80.288765,8.1524401,425.19446,-9.2576027
178.7081,6.8712263,1.3265703,0.0,0,7.2334356,0.0,0.091903746,79.456406,7.8256059,430.46826,-9.258007
178.7105,7.0418596,1.6069586,0.0,0,6.9312277,0.0,0.11276514,79.95208,7.5221138,435.74207,-9.2572956
178.7129,7.1689181,1.892271,0.0,0,6.6355219,0.0,0.13478683,79.776848,7.2299652,441.01587,-9.2573538
178.7153,7.3390498,2.1703885,0.0,0,6.3480015,0.0,0.15619123,80.066841,6.9446201,444.62695,-9.2567482
178.7177,7.5528669,2.4454823,0.0,0,6.065536,0.0,0.17743678,80.425575,6.6606894,444.78473,-9.2580204
178.7201,7.7513885,2.7307065,0.0,0,5.792079,0.0,0.20017691,80.700096,6.3758473,444.9425,-9.2586107
178.7225,7.9197917,3.004077,0.0,0,5.5222936,0.0,0.22307086,80.554283,6.099,445.10028,-9.2566013
178.7249,8.0937691,3.280746,0.0,0,5.2621331,0.0,0.24681386,80.525513,5.8172693,445.19025,-9.2560215
178.7273,8.2849865,3.5604856,0.0,0,5.0044241,0.0,0.27088121,80.429352,5.5342345,444.89587,-9.2578897
178.7297,8.4867487,3.8376303,0.0,0,4.7569842,0.0,0.29478237,80.443138,5.2596302,444.60153,-9.257781
178.7321,8.7126074,4.1120057,0.0,0,4.5108657,0.0,0.31932485,80.534424,4.9889884,444.30716,-9.2584543
178.7345,8.8865404,4.3716798,0.0,0,4.2754698,0.0,0.34397495,80.199516,4.7220392,444.01279,-9.2572374
178.7369,9.0588646,4.6171865,0.0,0,4.0404716,0.0,0.36795118,79.808258,4.4694819,442.3812,-9.2579298
178.7393,9.24545,4.860405,0.0,0,3.8165054,0.0,0.39167872,79.582329,4.2248621,440.7153,-9.256897
178.7417,9.4992313,5.0999599,0.0,0,3.5926332,0.0,0.41495234,79.746361,3.9852278,439.04944,-9.2573586
178.7441,9.7353096,5.3378606,0.0,0,3.3790326,0.0,0.43903613,79.831604,3.7493808,437.38354,-9.25737
178.7465,9.9525013,5.5641131,0.0,0,3.1660566,0.0,0.46306688,79.743652,3.5193357,436.11514,-9.2563429
178.7489,10.188717,5.7831511,0.0,0,2.9619906,0.0,0.48713487,79.677734,3.3014572,434.94611,-9.2558699
178.7513,10.469213,5.9962234,0.0,0,2.7593822,0.0,0.51045346,79.988579,3.0824327,433.77707,-9.2559423
178.7537,10.733934,6.2078042,0.0,0,2.5644474,0.0,0.53346258,80.096298,2.8752534,432.608,-9.2552795
178.7561,11.028601,6.4109821,0.0,0,2.3717272,0.0,0.55636525,80.459068,2.6782954,430.59906,-9.255415
178.7585,11.286224,6.6042609,0.0,0,2.1855242,0.0,0.57979017,80.462563,2.4803414,427.87943,-9.2550526
178.7609,11.590159,6.7887769,0.0,0,2.0022123,0.0,0.60287869,80.713158,2.2878654,425.15982,-9.2549257
178.7633,11.97649,6.9719534,0.0,0,1.8243403,0.0,0.62531763,81.584358,2.1043813,422.44019,-9.2549744
178.7657,12.350227,7.1577606,0.0,0,1.6499563,0.0,0.64787167,82.243973,1.9223078,418.84991,-9.2556219
178.7681,12.728409,7.3421149,0.0,0,1.4800413,0.0,0.67139578,82.768791,1.7429746,413.75589,-9.2550917
178.7705,13.162853,7.5225415,0.0,0,1.3141534,0.0,0.6956473,83.562233,1.5632473,408.66187,-9.2542505
178.7729,13.595056,7.6912088,0.0,0,1.1518564,0.0,0.71915787,84.302376,1.3896819,403.56781,-9.2537127
178.7753,14.103606,7.8608661,0.0,0,0.99408036,0.0,0.74272627,85.364281,1.2136723,399.5592,-9.2543182
178.7777,14.598595,8.0341644,0.0,0,0.83908135,0.0,0.76616424,86.330345,1.045941,400.12833,-9.2541208
178.7801,15.063758,8.2013493,0.0,0,0.68903339,0.0,0.78984743,87.018227,0.88151872,400.69742,-9.252389
178.7825,15.618913,8.3560638,0.0,0,0.54098594,0.0,0.81368625,88.064217,0.72825295,401.26651,-9.2532349
178.7849,16.171579,8.5003614,0.0,0,0.39818591,0.0,0.83692056,89.106178,0.57540661,401.88754,-9.2528801
178.7873,16.775812,8.6427841,0.0,0,0.25673628,0.0,0.85893381,90.425705,0.42900014,405.57202,-9.2533302
178.7897,17.4196,8.7872047,0.0,0,0.12094415,0.0,0.88074803,91.880341,0.28925347,409.25647,-9.2521095
178.7921,18.084957,8.9290047,0.0,0,-0.014479235,0.0,0.90314656,93.264145,0.14599523,412.94095,-9.2513828
178.7945,18.828741,9.0662622,0.0,0,-0.14691243,0.0,0.926907,94.788811,0.0069922493,416.6254,-9.2519398
178.7969,19.645826,9.1985645,0.0,0,-0.27934441,0.0,0.95062149,96.625481,-0.13033445,417.3299,-9.2516756
178.7993,20.493959,9.3311005,0.0,0,-0.41177642,0.0,0.9735074,98.526352,-0.26701573,417.47382,-9.2515373
178.8017,21.384907,9.466486,0.0,0,-0.54420841,0.0,0.99636221,100.45274,-0.40233395,417.61771,-9.2507114
178.8041,18.906979,9.5189486,0.0,0,-0.67664039,0.0,1.0053293,88.299774,-0.48845071,417.76163,-9.2532816
178.8065,16.967955,9.5342751,0.0,0,-0.80907238,0.0,1.0089613,78.903694,-0.52543819,418.23654,-9.2538776
178.8089,16.128469,9.5324459,0.0,0,-0.94150436,0.0,1.0102662,74.824371,-0.54753375,418.87695,-9.2550688
178.8113,15.725273,9.5346985,0.0,0,-1.0739365,0.0,1.0106343,72.843651,-0.57197243,419.51736,-9.2559795
178.8137,15.844757,9.5406485,0.0,0,-0.76691425,400.0,1.0104024,73.416809,-0.62000692,420.15778,-9.2544842
178.8161,16.021915,9.5526352,0.0,0,-0.3084279,400.0,1.0119746,74.223885,-0.68110991,421.45578,-9.2548046
178.8185,15.712355,9.5575171,0.0,0,0.15005845,400.0,1.0133605,72.630959,-0.7258665,423.43365,-9.255681
178.8209,14.834942,9.5537806,0.0,0,0.60854483,400.0,1.014106,68.621979,-0.73167443,425.41156,-9.2564926
178.8233,13.223403,9.5478792,0.0,0,1.0670311,400.0,1.0130123,61.330029,-0.68403214,427.38943,-9.2571726
178.8257,10.93183,9.5465469,0.0,0,1.5255175,400.0,1.0112637,50.8964,-0.59135067,428.81619,-9.2591543
178.8281,4.0046806,9.5220757,0.0,0,1.9840039,400.0,1.0062836,20.287231,-0.4326188,429.05365,-9.2636948
178.8305,-0.29955786,9.3723249,0.0,0,2.4424908,400.0,0.98026812,-1.4482865,0.053478893,429.29111,-9.2687216
178.8329,0.18717054,9.3194799,0.0,0,2.9009769,400.0,0.97226572,0.93587285,0.81575906,429.52853,-9.2691536
178.8353,-0.27392384,9.4033165,0.0,0,3.3594635,400.0,0.98634684,-1.1753217,1.573326,429.59488,-9.2687168
178.8377,3.0366838,9.4970379,0.0,0,3.8179498,400.0,1.0026863,14.683026,2.2002947,428.62439,-9.2643814
178.8401,-0.22430648,9.4790354,0.0,0,4.2764363,400.0,0.99809635,-0.87234908,2.673301,427.65387,-9.2660475
178.8425,0.9343127,9.4899883,0.0,0,4.7349229,400.0,1.0013961,4.4093533,3.1000679,426.68338,-9.2658529
178.8449,0.63767773,9.4888048,0.0,0,5.1934094,400.0,1.0020634,3.0098617,3.5248053,425.71289,-9.2652016
178.8473,0.60503751,9.4812765,0.0,0,5.651895,400.0,1.0009295,2.8384852,3.9526641,425.33276,-9.26513
178.8497,0.52967638,9.4873915,0.0,0,6.1103816,400.0,1.0006446,2.5064905,4.389143,424.97299,-9.2643757
178.8521,0.61574006,9.4867182,0.0,0,6.5688682,400.0,0.99936736,2.8184693,4.8510141,424.61319,-9.2643375
178.8545,0.63218582,9.4885616,0.0,0,7.0273547,400.0,1.0005833,2.9624043,5.3247066,424.25342,-9.2632236
178.8569,0.55513811,9.4824133,0.0,0,7.4858413,400.0,1.0013272,2.5957325,5.8037496,424.25821,-9.2642651
178.8593,0.60475969,9.4802284,0.0,0,7.9443278,400.0,1.0007958,2.8413656,6.293292,424.35895,-9.2633162
178.8617,0.5754534,9.4840717,0.0,0,8.4028139,400.0,0.99994659,2.6591482,6.7666111,424.45972,-9.2631884
178.8641,0.55530816,9.4858084,0.0,0,8.8612995,400.0,0.99972868,2.5958462,7.2496643,424.56046,-9.2619181
178.8665,0.58019066,9.4878578,0.0,0,9.3197861,400.0,1.0008118,2.7522228,7.7263331,424.78543,-9.2614841
178.8689,0.54543048,9.4824982,0.0,0,9.7782726,400.0,1.0011079,2.6011412,8.1993351,425.08762,-9.2612314
178.8713,0.54787034,9.4803562,0.0,0,10.236759,400.0,1.0006921,2.5594552,8.6781483,425.38983,-9.2628994
178.8737,0.5691731,9.4840994,0.0,0,10.695246,400.0,0.99996245,2.6553683,9.1441898,425.69205,-9.2612791
178.8761,0.55845547,9.4895248,0.0,0,11.153732,400.0,0.99987006,2.5948014,9.6085157,426.06409,-9.2613735
178.8785,0.5544349,9.4901514,0.0,0,11.612218,400.0,1.0009967,2.5875046,10.078661,426.52441,-9.2614765
178.8809,0.59157664,9.4848089,0.0,0,12.070705,400.0,1.0015744,2.8258259,10.540012,426.98474,-9.2613602
178.8833,0.54236478,9.481801,0.0,0,12.529191,400.0,1.0012192,2.569772,10.98914,427.44507,-9.2622433
178.8857,0.52784926,9.4822989,0.0,0,12.987678,400.0,0.99986708,2.5063636,11.458467,427.93405,-9.2615938
178.8881,0.60978174,9.4888773,0.0,0,13.446164,400.0,1.0002203,2.8826265,11.935731,428.50177,-9.2614422
178.8905,0.54752296,9.4917297,0.0,0,13.904651,400.0,1.0014319,2.5853209,12.404318,429.06949,-9.2608757
178.8929,0.61269164,9.4838457,0.0,0,14.363137,400.0,1.0013582,2.7952561,12.883076,429.63721,-9.2602787
178.8953,0.60452509,9.4816952,0.0,0,14.821624,400.0,1.0010021,2.8285985,13.345694,430.19305,-9.2596788
178.8977,0.58881748,9.4883289,0.0,0,15.28011,400.0,1.0006773,2.736253,13.806141,430.63123,-9.2608395
178.9001,0.56957799,9.4924507,0.0,0,15.738596,400.0,1.0004058,2.6631739,14.268538,431.0694,-9.2601051
178.9025,0.58650804,9.4921265,0.0,0,16.197083,400.0,1.001285,2.7399943,14.731625,431.50757,-9.2598934
178.9049,0.54661572,9.4870691,0.0,0,16.655569,400.0,1.0021117,2.6270766,15.182145,431.94571,-9.259203
178.9073,0.60493821,9.4794636,0.0,0,17.114056,400.0,1.0007826,2.8349476,15.64467,432.3378,-9.2585745
178.9097,0.60200959,9.4829159,0.0,0,17.572542,400.0,0.99992162,2.8652563,16.101715,432.72568,-9.2587366
178.9121,0.57852507,9.4890499,0.0,0,17.999401,400.0,1.0001807,2.6822512,16.555435,433.11356,-9.2599201
178.9145,0.56822711,9.4867907,0.0,0,18.0,400.0,1.0006193,2.6353307,17.019539,433.50143,-9.2598076
178.9169,0.59596843,9.4832048,0.0,0,18.0,400.0,1.0011435,2.7737744,17.447435,433.94257,-9.2604647
178.9193,0.60205704,9.4822931,0.0,0,18.0,400.0,1.0010737,2.8318832,17.833334,434.40228,-9.2618532
178.9217,0.62944913,9.4841661,0.0,0,18.0,400.0,0.99995804,2.9602132,18.164238,434.862,-9.2635813
178.9241,0.66404861,9.4918194,0.0,0,18.0,400.0,1.0002519,3.1209066,18.40309,435.32172,-9.2672968
178.9265,0.64755672,9.4927378,0.0,0,18.0,400.0,1.0013523,3.0029714,18.520452,435.79773,-9.2696123
178.9289,0.7686221,9.4855986,0.0,0,18.0,400.0,1.0018886,3.5276883,18.508812,436.28616,-9.274559
178.9313,0.68932503,9.4832287,0.0,0,18.0,400.0,1.0014108,3.2787061,18.389862,436.7746,-9.2854824
178.9337,0.72439873,9.4867115,0.0,0,18.0,400.0,1.0005677,3.3762493,18.248787,437.26303,-9.2974682
178.9361,0.68064958,9.490921,0.0,0,18.0,400.0,1.0005238,3.2276297,18.128206,437.70084,-9.3126707
178.9385,0.67257911,9.4880648,0.0,0,18.0,400.0,1.0009233,3.1213198,18.053801,438.06,-9.3293543
178.9409,0.67804426,9.4798498,0.0,0,18.0,400.0,1.0006441,3.1905336,18.026346,438.41916,-9.3496971
178.9433,0.71554226,9.4778576,0.0,0,18.0,400.0,1.0003533,3.3528156,18.031305,438.77829,-9.3698969
178.9457,0.66845506,9.4827051,0.0,0,18.0,400.0,0.99977183,3.1761913,18.052071,439.14056,-9.3928423
178.9481,0.65577197,9.4877396,0.0,0,18.0,400.0,0.99960554,3.0694003,18.082529,439.51407,-9.4116631
178.9505,0.66560066,9.4866991,0.0,0,18.0,400.0,1.0005059,3.0917761,18.105732,439.8876,-9.4294672
178.9529,0.71433407,9.4813948,0.0,0,18.0,400.0,1.0008196,3.291285,18.12126,440.26111,-9.4487495
178.9553,0.7103669,9.4774284,0.0,0,18.0,400.0,1.0002187,3.3446693,18.13681,440.63403,-9.467638
178.9577,0.689134,9.4796734,0.0,0,18.0,400.0,0.99934578,3.2436316,18.146368,440.99319,-9.4855289
178.9601,0.66505826,9.4831486,0.0,0,18.0,400.0,0.99924904,3.1071584,18.138597,441.35236,-9.5011749
178.9625,0.70985615,9.4822931,0.0,0,18.0,400.0,0.99974597,3.2942598,18.138643,441.71149,-9.5184088
178.9649,0.73515946,9.4786329,0.0,0,18.0,400.0,1.0003909,3.4347947,18.136665,442.07065,-9.5358343
178.9673,0.7042641,9.4780493,0.0,0,18.0,400.0,1.0003572,3.3384018,18.137667,442.35495,-9.5538731
178.9697,0.68142909,9.4832363,0.0,0,18.0,400.0,0.99995285,3.210073,18.131618,442.62775,-9.5714417
178.9721,0.69778764,9.4866791,0.0,0,18.0,400.0,0.99948204,3.2727273,18.130505,442.90054,-9.5879135
178.9745,0.72397178,9.4857521,0.0,0,18.0,400.0,1.0001417,3.3802378,18.128466,443.17334,-9.605566
178.9769,0.7518993,9.4814224,0.0,0,18.0,400.0,1.0008868,3.4978516,18.121155,443.43616,-9.6238737
178.9793,0.69336909,9.4783249,0.0,0,18.0,400.0,1.0004786,3.3002584,18.119675,443.69452,-9.641655
178.9817,0.67047435,9.4810228,0.0,0,18.0,400.0,0.99944311,3.1862702,18.119402,443.95288,-9.6577473
178.9841,0.71632606,9.4821491,0.0,0,18.0,400.0,0.99891382,3.3216782,18.118595,444.21124,-9.6752367
178.9865,0.7353825,9.485465,0.0,0,18.0,400.0,1.0003046,3.4455562,18.115158,444.48804,-9.6951618
178.9889,0.72160006,9.4829969,0.0,0,18.0,400.0,1.001087,3.4230716,18.111166,444.7821,-9.7122383
178.9913,0.68568069,9.4786425,0.0,0,18.0,400.0,1.0005287,3.2302737,18.11397,445.07614,-9.7314005
178.9937,0.67713958,9.4796906,0.0,0,18.0,400.0,0.99928457,3.2072663,18.106771,445.37021,-9.7497816
178.9961,0.71497542,9.487916,0.0,0,18.0,400.0,0.99952662,3.3488793,18.105091,445.64954,-9.7669878
178.9985,0.74261206,9.4884396,0.0,0,18.0,400.0,1.0006164,3.5136492,18.106644,445.90054,-9.7845392
179.0009,0.69257241,9.4830084,0.0,0,18.0,400.0,1.0011741,3.2181845,18.105339,446.15158,-9.8025761
179.0033,0.6662147,9.4769707,0.0,0,18.0,400.0,1.0002983,3.116848,18.106754,446.40259,-9.8194036
179.0057,0.69088018,9.4782133,0.0,0,18.0,400.0,0.99910617,3.2365553,18.105234,446.64404,-9.8372774
179.0081,0.71998125,9.483717,0.0,0,18.0,400.0,0.99926513,3.3940322,18.101707,446.83768,-9.8532104
179.0105,0.72164112,9.4858332,0.0,0,18.0,400.0,1.0002159,3.4117749,18.103899,447.03131,-9.8720732
179.0129,0.66838914,9.4805212,0.0,0,18.0,400.0,1.0005252,3.1496072,18.101616,447.22495,-9.8904161
179.0153,0.66692436,9.476615,0.0,0,18.0,400.0,1.0001001,3.1382923,18.101788,447.41858,-9.9091539
179.0177,0.7098937,9.4780321,0.0,0,18.0,400.0,0.9990977,3.3125868,18.101858,447.58377,-9.9264193
179.0201,0.72581208,9.4853563,0.0,0,18.0,400.0,0.9991799,3.4345088,18.102474,447.74872,-9.94522
179.0225,0.67493355,9.4886312,0.0,0,18.0,400.0,1.0005454,3.1815412,18.101709,447.9137,-9.9639845
179.0249,0.66563016,9.4818001,0.0,0,18.0,400.0,1.0009229,3.0937791,18.10491,448.07864,-9.9807367
179.0273,0.70052141,9.4756556,0.0,0,18.0,400.0,1.0000501,3.2766757,18.097176,448.21429,-9.9981432
179.0297,0.74294132,9.4777164,0.0,0,18.0,400.0,0.99910682,3.4376242,18.097973,448.34338,-10.01536
179.0321,0.73252755,9.4833012,0.0,0,18.0,400.0,0.99918979,3.4202249,18.094826,448.47247,-10.033791
179.0345,0.68572026,9.484787,0.0,0,18.0,400.0,1.0000702,3.1967292,18.097515,448.60156,-10.051279
179.0369,0.68178576,9.4786463,0.0,0,18.0,400.0,1.0004611,3.1687903,18.090635,448.72147,-10.06893
179.0393,0.74321246,9.4769726,0.0,0,18.0,400.0,1.000152,3.4314022,18.093445,448.83621,-10.084999
179.0417,0.75240058,9.4838209,0.0,0,18.0,400.0,1.0001618,3.5432644,18.092154,448.95096,-10.102574
179.0441,0.71651959,9.4885607,0.0,0,18.0,400.0,0.99976403,3.4127512,18.087271,449.06573,-10.121994
179.0465,0.69145083,9.486125,0.0,0,18.0,400.0,1.0000374,3.2396123,18.086378,449.18716,-10.138412
179.0489,0.71617281,9.4797487,0.0,0,18.0,400.0,1.0005413,3.3541474,18.083645,449.31625,-10.155663
179.0513,0.7657333,9.4758215,0.0,0,18.0,400.0,1.0000973,3.606087,18.086172,449.44534,-10.172818
179.0537,0.75976962,9.4797678,0.0,0,18.0,400.0,0.99934572,3.5619202,18.080572,449.57446,-10.191643
179.0561,0.70010394,9.4854527,0.0,0,18.0,400.0,0.99943912,3.3196912,18.081318,449.69937,-10.210478
179.0585,0.70119661,9.4851446,0.0,0,18.0,400.0,1.0001411,3.2413967,18.083532,449.81412,-10.227687
179.0609,0.74666375,9.4779625,0.0,0,18.0,400.0,1.0001116,3.4354622,18.082823,449.92886,-10.24638
179.0633,0.76360953,9.4770279,0.0,0,18.0,400.0,1.0002534,3.563977,18.079702,450.04361,-10.263402
179.0657,0.72500908,9.4821081,0.0,0,18.0,400.0,0.99968719,3.4191155,18.081186,450.15668,-10.280076
179.0681,0.68974096,9.4874058,0.0,0,18.0,400.0,0.99955487,3.2241533,18.081566,450.25708,-10.29793
179.0705,0.73039079,9.4875803,0.0,0,18.0,400.0,1.0002282,3.3871901,18.081364,450.35748,-10.315193
179.0729,0.75909615,9.4803696,0.0,0,18.0,400.0,1.000541,3.5467327,18.082827,450.45789,-10.33214
179.0753,0.75040203,9.4755754,0.0,0,18.0,400.0,1.0002012,3.5473809,18.080965,450.55829,-10.350987
179.0777,0.70585543,9.4759951,0.0,0,18.0,400.0,0.99885458,3.3211098,18.081081,450.67221,-10.36895
179.0801,0.68347031,9.4793062,0.0,0,18.0,400.0,0.99853456,3.2326515,18.081823,450.78696,-10.386208
179.0825,0.73220819,9.4811745,0.0,0,18.0,400.0,0.9994272,3.4310417,18.081228,450.9017,-10.403773
179.0849,0.75489658,9.4767256,0.0,0,18.0,400.0,0.9998998,3.5803399,18.076733,451.01648,-10.422508
179.0873,0.71632028,9.4757357,0.0,0,18.0,400.0,0.99986929,3.3718984,18.077446,451.10922,-10.439116
179.0897,0.68759674,9.4777842,0.0,0,18.0,400.0,0.99911886,3.1792879,18.07707,451.19528,-10.457105
179.0921,0.70741802,9.4834137,0.0,0,18.0,400.0,0.9988426,3.2924123,18.078209,451.28134,-10.474656
179.0945,0.75465828,9.4857693,0.0,0,18.0,400.0,0.99996853,3.5155807,18.075201,451.3674,-10.492378
179.0969,0.76615757,9.4821692,0.0,0,18.0,400.0,1.0009525,3.6032944,18.071386,451.42798,-10.510954
179.0993,0.69968867,9.4778051,0.0,0,18.0,400.0,1.0005103,3.2961888,18.07247,451.47104,-10.528597
179.1017,0.70169973,9.4784756,0.0,0,18.0,400.0,0.99922431,3.2502928,18.071533,451.51407,-10.547334
179.1041,0.73471314,9.481864,0.0,0,18.0,400.0,0.99895507,3.4234741,18.074312,451.5571,-10.564219
179.1065,0.77387196,9.4841347,0.0,0,18.0,400.0,0.99988109,3.6149673,18.066849,451.6091,-10.583148
179.1089,0.72137809,9.4809389,0.0,0,18.0,400.0,1.000668,3.4399893,18.068005,451.67365,-10.600733
179.1113,0.70294994,9.4773417,0.0,0,18.0,400.0,1.0001817,3.2695827,18.065659,451.73819,-10.618252
179.1137,0.71115988,9.4788303,0.0,0,18.0,400.0,0.9992978,3.3203659,18.068157,451.80273,-10.63615
179.1161,0.76740664,9.4857597,0.0,0,18.0,400.0,0.99924111,3.5897708,18.068222,451.87076,-10.6534
179.1185,0.76156187,9.4864807,0.0,0,18.0,400.0,1.0000658,3.5972359,18.065821,451.94965,-10.671483
179.1209,0.71354723,9.4806471,0.0,0,18.0,400.0,1.000742,3.3653226,18.065838,452.0285,-10.687575
179.1233,0.70611691,9.4739952,0.0,0,18.0,400.0,0.99980885,3.321239,18.067406,452.10739,-10.707006
179.1257,0.74720097,9.4763365,0.0,0,18.0,400.0,0.9989174,3.4851227,18.068035,452.18484,-10.724357
179.1281,0.77365875,9.4809771,0.0,0,18.0,400.0,0.99875444,3.6132491,18.062178,452.24225,-10.741872
179.1305,0.75202715,9.4811611,0.0,0,18.0,400.0,0.99919379,3.5590112,18.064474,452.29962,-10.758525
179.1329,0.71436673,9.4769917,0.0,0,18.0,400.0,0.9999156,3.3316894,18.063797,452.35699,-10.77686
179.1353,0.72329068,9.4740343,0.0,0,18.0,400.0,0.99973303,3.4003005,18.065813,452.41437,-10.795074
179.1377,0.77537435,9.477313,0.0,0,18.0,400.0,0.99905169,3.6098347,18.063631,452.45258,-10.812854
179.1401,0.7727403,9.4852924,0.0,0,18.0,400.0,0.99930435,3.612056,18.063847,452.48843,-10.829988
179.1425,0.72534323,9.4850492,0.0,0,18.0,400.0,0.99985236,3.395597,18.06328,452.52429,-10.848409
179.1449,0.71459615,9.4781027,0.0,0,18.0,400.0,1.0003695,3.2928739,18.061071,452.56015,-10.865647
179.1473,0.74505997,9.4727755,0.0,0,18.0,400.0,0.99960077,3.4710655,18.061487,452.5806,-10.883389
179.1497,0.77966166,9.4769783,0.0,0,18.0,400.0,0.99894321,3.68033,18.060539,452.59494,-10.901363
179.1521,0.75416946,9.4836531,0.0,0,18.0,400.0,0.99919045,3.5467529,18.060345,452.60928,-10.92003
179.1545,0.71221936,9.4817867,0.0,0,18.0,400.0,0.99943113,3.2843003,18.059475,452.62363,-10.938566
179.1569,0.71444666,9.4769564,0.0,0,18.0,400.0,0.99992353,3.3300245,18.060387,452.64572,-10.95709
179.1593,0.76739365,9.4761286,0.0,0,18.0,400.0,0.99996722,3.5568986,18.060068,452.67441,-10.974281
179.1617,0.77389717,9.47787,0.0,0,18.0,400.0,0.99918175,3.6632831,18.057934,452.70309,-10.993531
179.1641,0.71665645,9.4848661,0.0,0,18.0,400.0,0.99921244,3.3739619,18.051987,452.73178,-11.010478
179.1665,0.71491694,9.4860277,0.0,0,18.0,400.0,0.99997813,3.3376789,18.052011,452.75784,-11.026336
179.1689,0.75238925,9.4819717,0.0,0,18.0,400.0,1.0007377,3.4701786,18.053104,452.77936,-11.044209
179.1713,0.78561223,9.4773378,0.0,0,18.0,400.0,1.000393,3.6414628,18.054005,452.80087,-11.05976
179.1737,0.75863647,9.4792242,0.0,0,18.0,400.0,0.99933767,3.5621078,18.053942,452.82239,-11.080024
179.1761,0.7135852,9.4817295,0.0,0,18.0,400.0,0.99886912,3.3188496,18.047922,452.83841,-11.097617
179.1785,0.72893608,9.4823542,0.0,0,18.0,400.0,0.99960256,3.3782997,18.053486,452.83124,-11.115939
179.1809,0.77198046,9.4785566,0.0,0,18.0,400.0,1.0001693,3.6305051,18.053473,452.82407,-11.134625
179.1833,0.78341079,9.4779682,0.0,0,18.0,400.0,1.0003676,3.7057693,18.051929,452.81689,-11.15265
179.1857,0.7300182,9.4792929,0.0,0,18.0,400.0,0.99940979,3.464757,18.047886,452.80984,-11.169692
179.1881,0.71566063,9.4819527,0.0,0,18.0,400.0,0.99859595,3.3574209,18.049427,452.80984,-11.186618
179.1905,0.77017254,9.4821863,0.0,0,18.0,400.0,0.99930453,3.6050642,18.055494,452.80984,-11.204114
179.1929,0.79900146,9.4782887,0.0,0,18.0,400.0,1.0001528,3.7503541,18.051594,452.80984,-11.221935
179.1953,0.7802124,9.4741488,0.0,0,18.0,400.0,0.99997151,3.6291852,18.04962,452.80984,-11.241121
179.1977,0.74029762,9.4756737,0.0,0,18.0,400.0,0.99886459,3.4403837,18.047882,452.83398,-11.256775
179.2001,0.73552662,9.4805374,0.0,0,18.0,400.0,0.99861687,3.4323139,18.049274,452.86267,-11.275006
179.2025,0.78367198,9.4819479,0.0,0,18.0,400.0,0.99952781,3.6600137,18.050749,452.89139,-11.292723
179.2049,0.79094577,9.4790764,0.0,0,18.0,400.0,1.0001553,3.7202594,18.04792,452.92007,-11.310637
179.2073,0.73259699,9.4768209,0.0,0,18.0,400.0,1.00027,3.5002031,18.050978,452.93918,-11.329021
179.2097,0.71674538,9.4771166,0.0,0,18.0,400.0,0.99902403,3.3724957,18.049431,452.95352,-11.346288
179.3118,0.73862553,9.4791737,0.0,0,18.0,17.344156,0.99960417,3.4593887,18.037857,450.88019,-11.465625
180.5118,0.64949113,9.4918938,0.0,0,18.0,7.5886285e-16,1.0018308,3.0313327,17.999828,427.3338,-11.47898
181.7118,0.62654716,9.4996729,0.0,0,18.0,3.280552e-32,1.0032293,2.9289997,17.998569,413.4487,-11.478218
182.9118,0.63470805,9.5073671,0.0,0,18.0,1.4012985e-45,1.0046467,2.9604456,17.999527,401.72446,-11.479815
184.1118,0.616198,9.5144148,0.0,0,18.0,1.4012985e-45,1.0059583,2.8617969,17.999786,390.98636,-11.480167
185.3118,0.60971934,9.5213327,0.0,0,18.0,1.4012985e-45,1.0072588,2.8425813,17.999182,380.40729,-11.478818
186.5118,0.60918951,9.5277424,0.0,0,18.0,1.4012985e-45,1.0083978,2.8252761,17.999523,370.20618,-11.479162
187.7118,0.60405779,9.5337181,0.0,0,18.0,1.4012985e-45,1.0094274,2.8045802,18.000536,359.80176,-11.47897
188.9118,0.61622101,9.5392838,0.0,0,18.0,1.4012985e-45,1.0104096,2.8546617,17.999548,349.81226,-11.47934
190.1118,0.6128037,9.5448065,0.0,0,18.0,1.4012985e-45,1.0114112,2.8320632,17.999973,340.49954,-11.479889
191.3118,0.6211319,9.5508308,0.0,0,18.0,1.4012985e-45,1.012526,2.8711827,18.000338,332.15244,-11.480524
192.5118,0.61332589,9.5559187,0.0,0,18.0,1.4012985e-45,1.0135008,2.8326504,17.999271,323.50754,-11.481051
193.7118,0.59484839,9.5612907,0.0,0,18.0,1.4012985e-45,1.0145686,2.7499273,18.000225,315.13138,-11.480219
194.9118,0.60807842,9.5667429,0.0,0,18.0,1.4012985e-45,1.0155493,2.8063707,18.000025,306.75082,-11.480448
196.1118,0.5972591,9.5720491,0.0,0,18.0,1.4012985e-45,1.0164762,2.7501996,17.999277,298.46701,-11.480354
197.3118,0.60682416,9.5775089,0.0,0,18.0,1.4012985e-45,1.0174668,2.7967947,17.999802,290.71085,-11.480337
198.5118,0.59727651,9.5821152,0.0,0,18.0,1.4012985e-45,1.0183576,2.7385211,18.000088,283.01352,-11.479782
199.7118,0.61018896,9.586957,0.0,0,18.0,1.4012985e-45,1.0192779,2.8009269,18.002001,275.60999,-11.480398
200.9118,0.61185104,9.5913057,0.0,0,18.0,1.4012985e-45,1.0200865,2.8081093,18.000425,268.29672,-11.480387
202.1118,0.6033051,9.5961237,0.0,0,18.0,1.4012985e-45,1.0209459,2.7675967,18.000652,261.22421,-11.480579
203.3118,0.61663216,9.6005659,0.0,0,18.0,1.4012985e-45,1.0217263,2.828624,17.999722,254.35451,-11.480897
204.5118,0.60434002,9.6051569,0.0,0,18.0,1.4012985e-45,1.0225389,2.7607448,17.998003,247.65147,-11.480639
205.7118,0.59919155,9.6094732,0.0,0,18.0,1.4012985e-45,1.0233399,2.7446964,17.99996,241.20105,-11.480925
206.9118,0.60636836,9.6140318,0.0,0,18.0,1.4012985e-45,1.0242327,2.7641988,18.00028,235.00533,-11.481321
208.1118,0.57811701,9.6177721,0.0,0,18.0,1.4012985e-45,1.0249603,2.6396701,18.000448,229.02232,-11.480688
209.3118,0.58847839,9.6218042,0.0,0,18.0,1.4012985e-45,1.0257485,2.6887343,17.999367,223.07515,-11.480375
210.5118,0.58335882,9.6257401,0.0,0,18.0,1.4012985e-45,1.0264596,2.6599691,17.999496,217.36243,-11.480491
211.7118,0.59377867,9.6293383,0.0,0,18.0,1.4012985e-45,1.0270656,2.7125664,18.000265,211.6953,-11.480291
212.9118,0.59132582,9.6327333,0.0,0,18.0,1.4012985e-45,1.0277678,2.6900954,18.001131,206.33691,-11.480159
214.1118,0.58629179,9.6367283,0.0,0,18.0,1.4012985e-45,1.0285265,2.6681378,18.000212,201.06447,-11.480288
215.3118,0.59764612,9.6400614,0.0,0,18.0,1.4012985e-45,1.0291556,2.7233474,18.000965,196.10043,-11.480627
216.5118,0.58145148,9.6432152,0.0,0,18.0,1.4012985e-45,1.029706,2.6437252,17.999405,191.11739,-11.480131
217.7118,0.59167403,9.646904,0.0,0,18.0,1.4012985e-45,1.0303241,2.6961565,18.001034,186.38274,-11.480732
218.9118,0.59538221,9.6503839,0.0,0,18.0,1.4012985e-45,1.0309457,2.6999671,17.999901,181.74902,-11.480352
220.1118,0.58758688,9.6532593,0.0,0,18.0,1.4012985e-45,1.0314956,2.6698096,18.000418,177.24973,-11.480652
221.3118,0.60228026,9.6557798,0.0,0,18.0,1.4012985e-45,1.0319964,2.728035,17.999186,172.85654,-11.480521
222.5118,0.58301854,9.6584234,0.0,0,18.0,1.4012985e-45,1.0325458,2.6396015,17.999979,168.6844,-11.480864
223.7118,0.59253037,9.6616926,0.0,0,18.0,1.4012985e-45,1.0331978,2.6887715,17.999924,164.6731,-11.480524
224.9118,0.59411365,9.6644793,0.0,0,18.0,1.4012985e-45,1.0336928,2.6846292,17.999701,160.55956,-11.480847
226.1118,0.58522934,9.6670876,0.0,0,18.0,1.4012985e-45,1.0341398,2.6502273,18.00034,156.67139,-11.480683
227.3118,0.5965566,9.6700125,0.0,0,18.0,1.4012985e-45,1.0347008,2.6963315,18.000078,152.84959,-11.480986
228.5118,0.58966464,9.6726465,0.0,0,18.0,1.4012985e-45,1.0352411,2.664783,17.999859,149.25256,-11.480962
229.7118,0.59064895,9.6748199,0.0,0,18.0,1.4012985e-45,1.0356719,2.6761489,17.999729,145.59671,-11.48097
230.9118,0.59620297,9.6775303,0.0,0,18.0,1.4012985e-45,1.0361331,2.6884475,17.99979,142.19357,-11.481221
232.1118,0.59879583,9.6800079,0.0,0,18.0,1.4012985e-45,1.0365708,2.7038064,17.998562,138.79494,-11.481413
233.3118,0.59962267,9.6825056,0.0,0,18.0,1.4012985e-45,1.0369861,2.7002711,17.999182,135.5253,-11.481583
234.5118,0.58060843,9.6848507,0.0,0,18.0,1.4012985e-45,1.037413,2.6166306,18.00025,132.35718,-11.480999
235.7118,0.59340703,9.6869192,0.0,0,18.0,1.4012985e-45,1.0378377,2.6770871,17.998846,129.25966,-11.48152
236.9118,0.59295762,9.689085,0.0,0,18.0,1.4012985e-45,1.0382869,2.6681767,17.998581,126.25381,-11.481497
238.1118,0.58864129,9.6914158,0.0,0,18.0,1.4012985e-45,1.0387678,2.6553771,17.999689,123.38099,-11.481243
239.2118,0.59046054,9.6932735,0.0,0,18.0,1.4012985e-45,1.0390724,2.6595917,18.000685,120.75362,-11.481355