File: examples/dan-msc-case-studies/CS3/data/01 raw data/baron_test_070.csv
Time(sec),Force(kN),Jaw(mm),PowAngle(deg),Power(W),Pram,PTemp,Strain,Stress(MPa),Stroke(mm),TC1(C),wedge(mm)
0.0,0.90633911,0.46814761,0.0,0,10.594783,0.0015910695,0.031741329,11.166954,10.595592,24.526918,-9.1067142
2.2,0.82199532,0.004845018,0.0,0,10.594783,6.5158758,0.00033506003,10.459573,10.594399,24.461884,-9.4727869
4.4,0.79195249,0.0045054052,0.0,0,10.594783,13.115875,0.00031645357,10.088056,10.595166,24.414343,-9.4703636
6.6,0.76606739,0.0047136419,0.0,0,10.594783,19.715878,0.00030907904,9.7563162,10.595251,24.436897,-9.4664726
8.8,0.74709058,0.0046843071,10.945434,0,10.594783,26.315874,0.00031934562,9.5092182,10.594571,24.349054,-9.4626255
11.0,0.77272189,0.0026921083,33.769669,0,10.594783,32.915867,0.00015330578,9.8404093,10.595454,27.109652,-9.4598312
13.2,0.78943813,-0.0036418124,39.209023,0,10.594783,39.515873,-0.00025468998,10.062098,10.595102,35.048031,-9.4563494
15.4,0.81328285,-0.010686359,39.258072,0,10.594783,46.115883,-0.00068875967,10.370124,10.595773,44.2323,-9.4531755
17.6,0.81135386,-0.016922101,38.551029,0,10.594783,52.715889,-0.0011130081,10.350137,10.595552,52.279324,-9.4494352
19.8,0.81693923,-0.022312663,37.836918,0,10.594783,59.315891,-0.0014768156,10.419034,10.595281,59.46669,-9.4459372
22.0,0.82808501,-0.026932731,37.836918,0,10.594783,65.915871,-0.0018004077,10.570504,10.59526,65.904968,-9.4426823
24.2,0.83407694,-0.031972725,38.551022,0,10.594783,72.515892,-0.0021454806,10.631345,10.594935,72.243156,-9.4393892
26.4,0.83740544,-0.038353294,39.229023,0,10.594783,79.115891,-0.0025527042,10.682404,10.59479,78.820152,-9.4354343
28.6,0.8477335,-0.042562839,39.898251,0,10.594783,85.715889,-0.0028148375,10.828489,10.595461,85.231194,-9.4315681
30.8,0.85888445,-0.046998076,39.924313,0,10.594783,92.315887,-0.003130699,10.984188,10.594491,91.945641,-9.428196
33.0,0.86220527,-0.052274816,40.572506,0,10.594783,98.915886,-0.0034684129,11.010219,10.59454,98.497604,-9.4247217
35.2,0.8616448,-0.057549495,41.004715,0,10.594783,105.51588,-0.0038476717,11.016313,10.595964,105.13161,-9.4212217
37.4,0.8704797,-0.062873498,41.198727,0,10.594783,112.11588,-0.0041929558,11.12969,10.594232,111.80104,-9.4177256
39.6,0.8834753,-0.068561815,41.802975,0,10.594783,118.71588,-0.0045341616,11.30962,10.594678,118.31873,-9.4137716
41.8,0.8783049,-0.074332893,41.930725,0,10.594783,125.31589,-0.0049431855,11.231177,10.595244,124.95789,-9.4102774
44.0,0.88223851,-0.079805724,42.396236,0,10.594783,131.91589,-0.0052964701,11.287251,10.595689,131.55917,-9.4073753
46.2,0.88718086,-0.085533962,42.75222,0,10.594783,138.5159,-0.0056966953,11.363291,10.595261,138.19559,-9.4038067
48.4,0.89142162,-0.09185601,42.978512,0,10.594783,145.11589,-0.0061263763,11.430455,10.594905,144.85652,-9.3994598
50.6,0.89719588,-0.098235294,43.526913,0,10.594783,151.7159,-0.0065182517,11.48321,10.594504,151.37732,-9.3961992
52.8,0.89748406,-0.10493718,43.726959,0,10.594783,158.31589,-0.006959314,11.521773,10.594071,157.90645,-9.3928366
55.0,0.89381683,-0.11132319,44.077133,0,10.594783,164.91589,-0.0073841135,11.465375,10.594274,164.61946,-9.3889971
57.2,0.90540534,-0.11715955,44.077145,0,10.594783,171.51588,-0.007786809,11.62957,10.595196,171.2404,-9.3859444
59.4,0.89678115,-0.12377359,44.410931,0,10.594783,178.11588,-0.008237876,11.514547,10.593811,177.8714,-9.3816328
61.6,0.89585328,-0.13020192,44.604488,0,10.594783,184.7159,-0.0086255986,11.521379,10.595445,184.57401,-9.3784437
63.8,0.89760804,-0.1365069,44.798164,0,10.594783,191.31589,-0.0090436824,11.52988,10.595725,191.03262,-9.374958
66.0,0.9091534,-0.14253604,45.12085,0,10.594783,197.91589,-0.0094574736,11.669677,10.595045,197.61963,-9.3717175
68.2,0.91214931,-0.14849207,45.61517,0,10.594783,204.51588,-0.0098509369,11.72277,10.594941,204.18164,-9.367815
70.4,0.91584039,-0.15528983,45.615231,0,10.594783,211.11589,-0.010317145,11.776674,10.5945,210.86707,-9.363802
72.6,0.92433298,-0.16270937,45.842464,0,10.594783,217.71588,-0.010769202,11.903321,10.595077,217.45651,-9.3611488
74.8,0.92680931,-0.16957872,46.109428,0,10.594783,224.31589,-0.011222836,11.934126,10.594217,224.20343,-9.3578491
77.0,0.92466551,-0.17505588,46.107475,0,10.594783,230.91588,-0.011604786,11.901042,10.595166,230.79488,-9.3540192
79.2,0.92410034,-0.18017796,46.109619,0,10.594783,237.51588,-0.011948089,11.904859,10.594269,237.31189,-9.3505335
81.4,0.93019468,-0.18604763,46.582027,0,10.594783,244.11589,-0.012348719,12.013018,10.595882,243.73299,-9.3467436
83.6,0.93081397,-0.1918866,47.05415,0,10.594783,250.71591,-0.012696505,12.005629,10.595434,250.29204,-9.342597
85.8,0.92273563,-0.19823706,47.061203,0,10.594783,257.31619,-0.013119552,11.89997,10.593599,256.95288,-9.3393297
88.0,0.92277056,-0.20469972,47.504883,0,10.594783,263.91592,-0.013538215,11.928657,10.594941,263.66309,-9.3364887
90.2,0.92754179,-0.21174778,47.504883,0,10.594783,270.5159,-0.014031446,11.987488,10.595668,270.3602,-9.3326569
92.4,0.92519474,-0.21791483,47.504883,0,10.594783,277.11591,-0.014423421,11.963316,10.595937,276.89423,-9.3287048
94.6,0.92656273,-0.22513755,47.955318,0,10.594783,283.71588,-0.014871646,11.974477,10.595033,283.45313,-9.3251486
96.8,0.92481732,-0.23148021,47.955559,0,10.594783,290.31589,-0.015313225,11.975304,10.595225,290.01471,-9.3215771
99.0,0.92713529,-0.23825756,48.383785,0,10.594783,296.91586,-0.015752811,11.992747,10.595075,296.56082,-9.3187666
101.2,0.92674863,-0.2450036,48.812252,0,10.594783,303.51587,-0.01621595,11.996026,10.594341,303.18433,-9.3152924
103.4,0.92144847,-0.25223187,48.812252,0,10.594783,310.11591,-0.016663205,11.929333,10.594372,309.91122,-9.3115788
105.6,0.92346609,-0.25888476,48.936802,0,10.594783,316.71591,-0.017091868,11.959254,10.594509,316.46494,-9.3071833
107.8,0.93329948,-0.26571769,49.229733,0,10.594783,323.31592,-0.017554279,12.094851,10.594903,323.09546,-9.3038158
110.0,0.93268681,-0.2719861,49.468826,0,10.594783,329.91589,-0.017970178,12.088472,10.59426,329.59784,-9.3005848
112.2,0.92727178,-0.27879342,49.636227,0,10.594783,336.51587,-0.018435994,12.032053,10.594588,336.21326,-9.2972689
114.4,0.93520564,-0.28570297,50.042721,0,10.594783,343.11588,-0.018841704,12.127842,10.594197,342.72891,-9.2940712
116.6,0.93325126,-0.29241669,50.203144,0,10.594783,349.71588,-0.019299725,12.119014,10.59464,349.30676,-9.2897539
118.8,0.93636137,-0.3000589,50.469707,0,10.594783,356.31589,-0.01979241,12.161462,10.593263,355.89099,-9.2856674
121.0,0.93553114,-0.30744255,50.82275,0,10.594783,362.91589,-0.020302724,12.1494,10.594398,362.4971,-9.2828903
123.2,0.9374429,-0.31469697,50.824074,0,10.594783,369.51593,-0.020763399,12.198594,10.595739,369.19998,-9.2796116
125.4,0.93089157,-0.32214388,51.196285,0,10.594783,376.11591,-0.021226,12.107483,10.594245,375.87253,-9.2758408
127.6,0.9354465,-0.32991368,51.196285,0,10.594783,382.71594,-0.021749698,12.17616,10.594682,382.56931,-9.2722101
129.8,0.93179435,-0.33672741,51.321896,0,10.594783,389.31592,-0.022211136,12.133484,10.59501,389.11191,-9.2680101
132.0,0.93877584,-0.34342927,51.212097,0,10.594783,395.91589,-0.022650771,12.241143,10.595183,395.91714,-9.2646627
134.2,0.9333449,-0.35113719,51.2985,0,10.594783,402.5159,-0.023111809,12.171895,10.595095,402.46481,-9.2613401
136.4,0.93564111,-0.35836357,51.430489,0,10.594783,409.11588,-0.023608074,12.194263,10.594684,409.03125,-9.2581263
138.6,0.93874234,-0.36527261,51.569725,0,10.594783,415.71588,-0.024059182,12.241158,10.5954,415.60938,-9.2541924
140.8,0.93563086,-0.37179613,51.72538,0,10.594783,422.31592,-0.024511384,12.203216,10.595056,422.03128,-9.2501783
143.0,0.95200616,-0.37892398,51.932369,0,10.594783,428.91592,-0.024931205,12.425153,10.595212,428.55142,-9.2462969
145.2,0.95522124,-0.38761517,52.283936,0,10.594783,435.51593,-0.025485395,12.483834,10.594356,435.05539,-9.2427921
147.4,0.96609962,-0.39698744,52.34774,0,10.594783,442.11591,-0.026106592,12.624865,10.594945,441.85443,-9.2395039
149.6,0.97184575,-0.40339488,52.436668,0,10.594783,448.71591,-0.026571374,12.696954,10.594172,448.58142,-9.2360592
151.8,0.079038627,-0.41640526,51.181072,0,10.594783,449.9989,-0.027381597,1.0325725,10.594081,451.15573,-9.2355585
154.0,0.071574412,-0.41481403,50.438236,0,10.594783,449.9989,-0.027267385,0.93473965,10.595126,451.09293,-9.2351732
156.2,0.061073903,-0.41472244,50.042728,0,10.594783,449.9989,-0.027258387,0.80525529,10.595629,450.6731,-9.2348585
158.4,0.059880607,-0.41448981,50.437878,0,10.594783,449.9989,-0.027283801,0.7926091,10.594121,449.95636,-9.234622
160.6,0.079450548,-0.41518235,50.82275,0,10.594783,449.9989,-0.027298056,1.0421441,10.594363,449.55746,-9.2350855
162.8,0.072642215,-0.41646707,50.73386,0,10.594783,449.9989,-0.027367154,0.9514541,10.594935,449.95724,-9.2350845
165.0,0.067271382,-0.41750047,50.438236,0,10.594783,449.9989,-0.027437484,0.87917155,10.595444,450.23944,-9.2348719
167.2,0.082286201,-0.41821206,50.042732,0,10.594783,449.9989,-0.027526226,1.0891358,10.595407,450.32968,-9.234807
169.4,0.081245899,-0.41939086,49.888424,0,10.594783,449.9989,-0.027568597,1.0630679,10.594768,450.33057,-9.2351408
171.6,0.071399853,-0.42024153,50.042152,0,10.594783,449.9989,-0.027615005,0.94875461,10.595505,450.13708,-9.2349672
173.8,0.077935621,-0.42110452,50.042721,0,10.594783,449.9989,-0.027685611,1.0249348,10.595301,449.90839,-9.2346582
176.0,0.091567792,-0.42179862,50.186924,0,10.594783,449.9989,-0.027758421,1.2009565,10.593971,449.81573,-9.234972
178.2,0.088385992,-0.42297745,50.383335,0,10.594783,449.9989,-0.027812257,1.1680599,10.594554,449.89572,-9.2349472
180.4,0.09155599,-0.42371392,50.042728,0,10.594783,449.9989,-0.027836118,1.1872683,10.594828,450.08679,-9.2353125
182.6,0.092715546,-0.42435965,50.042728,0,10.594783,449.9989,-0.027885957,1.2184383,10.595364,450.0498,-9.2351704
184.8,0.099001482,-0.42589861,50.042728,0,10.594783,449.9989,-0.028024649,1.2935324,10.594888,450.14035,-9.2350788
187.0,0.097359449,-0.42840448,50.042728,0,10.594783,449.9989,-0.028157614,1.2551173,10.594748,449.97888,-9.2344179
189.2,0.093409054,-0.42847428,50.043987,0,10.594783,449.9989,-0.028141569,1.2217346,10.594959,449.89209,-9.2342196
191.4,0.096419901,-0.42792979,50.254299,0,10.594783,449.9989,-0.028120888,1.2614074,10.594359,449.90625,-9.2349806
193.6,0.089931905,-0.42916313,50.395966,0,10.594783,449.9989,-0.02824061,1.1789315,10.594061,449.95801,-9.2352428
195.2838,0.21011508,0.076636314,41.535366,0,10.5948,0.0060100802,0.0049944962,2.6373093,10.594768,449.99524,-9.2352715
195.2882,0.22412744,0.079329193,19.516565,0,10.5948,5.9954179e-33,0.0050498336,2.8704407,10.597319,449.99524,-9.2348175
195.2926,0.1942765,0.077199265,0.0,0,10.5948,0.0,0.0049991277,2.4697001,10.59659,449.99374,-9.2350168
195.297,0.18448225,0.079135701,0.0,0,10.5948,0.0,0.0051172436,2.2157843,10.5934,449.98059,-9.2366219
195.3014,0.20531489,0.076436341,0.0,0,10.5948,0.0,0.0050310139,2.6212587,10.597669,449.96744,-9.2364283
195.3058,0.19458754,0.079974532,0.0,0,10.5948,0.0,0.0051721968,2.4677436,10.591379,450.00964,-9.2350206
195.3102,0.18877842,0.076305322,0.0,0,10.5948,0.0,0.0050052907,2.4242456,10.595011,450.06232,-9.2348738
195.3146,0.19291189,0.0819223,0.0,0,10.5948,0.0,0.0053484086,2.3909476,10.591937,450.07758,-9.2342653
195.319,0.20956151,0.077064626,0.0,0,10.5948,0.0,0.0051733502,2.658833,10.594475,450.06439,-9.2359734
195.3234,0.20310427,0.080204129,0.0,0,10.5948,0.0,0.0052817492,2.6241708,10.592941,450.05511,-9.2350569
195.3278,0.2077456,0.078478985,0.0,0,10.5948,0.0,0.005231671,2.5853276,10.593719,450.05511,-9.2356844
195.3322,0.20722437,0.08147195,0.0,0,10.5948,0.0,0.0054297522,2.4930687,10.591687,450.05481,-9.2362642
195.3366,0.21981592,0.078255877,0.0,0,10.542864,0.0,0.0052682371,2.7106259,10.595078,450.04166,-9.2372856
195.341,0.21876021,0.080340482,0.0,0,10.476864,0.0,0.0053460225,2.7945406,10.585734,450.0285,-9.2352695
195.3454,0.20679615,0.07895723,0.0,0,10.410864,0.0,0.0053039179,2.687741,10.563968,449.99554,-9.2350721
195.3498,0.21516308,0.081099488,0.0,0,10.344864,0.0,0.005478438,2.688345,10.486517,449.95602,-9.2353487
195.3542,0.21386756,0.078024559,0.0,0,10.278863,0.0,0.0052274475,2.7538455,10.380173,449.93536,-9.2365341
195.3586,0.22217026,0.080625936,0.0,0,10.212864,0.0,0.0054941881,2.8248818,10.285661,449.93536,-9.2359295
195.363,0.2153237,0.077686518,0.0,0,10.146863,0.0,0.0052541164,2.6875715,10.224473,449.93805,-9.2350197
195.3674,0.22353469,0.080079809,0.0,0,10.080864,0.0,0.0054747197,2.8805614,10.174903,449.95123,-9.2352743
195.3718,0.2192867,0.077613823,0.0,0,10.014863,0.0,0.0053110342,2.8135295,10.119343,449.96445,-9.234889
195.3762,1.1960243,0.0956899,0.0,0,9.948863,0.0,0.0065511428,14.777973,10.052292,450.37045,-9.2350273
195.3806,3.4560492,0.12126872,0.0,0,9.882863,0.0,0.008170425,43.55965,9.9885988,450.80521,-9.2333746
195.385,4.0919695,0.19519429,0.0,0,9.8168631,0.0,0.013321304,51.389217,9.9121084,452.117,-9.2325115
195.3894,4.3379598,0.26223567,0.0,0,9.7508631,0.0,0.01777464,54.272781,9.835989,453.88239,-9.2319593
195.3938,4.4833732,0.32917163,0.0,0,9.6848631,0.0,0.022360075,55.826492,9.7691641,455.57648,-9.2325592
195.3982,4.5603828,0.39145148,0.0,0,9.6188631,0.0,0.026558397,56.541531,9.7074051,457.15735,-9.2317362
195.4026,4.6300492,0.45890227,0.0,0,9.5528631,0.0,0.031287763,57.140656,9.6391249,458.59592,-9.2319651
195.407,4.6826482,0.52465791,0.0,0,9.4868631,0.0,0.035736777,57.441895,9.5690994,458.92502,-9.2325773
195.4114,4.7247152,0.5871377,0.0,0,9.4223585,0.0,0.04017482,57.832855,9.505435,459.25409,-9.2344646
195.4158,4.7810254,0.6526162,0.0,0,9.3579779,0.0,0.044706609,58.263504,9.4372692,458.37595,-9.2332258
195.4202,4.7776237,0.71786642,0.0,0,9.2935972,0.0,0.04923955,57.894203,9.3718357,457.26938,-9.2312517
195.4246,4.8163567,0.78184289,0.0,0,9.2292166,0.0,0.053723853,58.113937,9.3051281,456.05814,-9.2335033
195.429,4.8595963,0.84732741,0.0,0,9.164835,0.0,0.05839885,58.388893,9.232461,454.76727,-9.2341833
195.4334,4.8696342,0.91137868,0.0,0,9.1004553,0.0,0.062888078,58.21899,9.1710796,453.95514,-9.2335539
195.4378,4.8628631,0.97175932,0.0,0,9.0360737,0.0,0.067249581,57.883289,9.1066599,454.28452,-9.2324972
195.4422,4.8903494,1.0339887,0.0,0,8.971693,0.0,0.071562149,57.888783,9.0466576,454.62555,-9.2345476
195.4466,4.9528408,1.0968984,0.0,0,8.9073124,0.0,0.076202065,58.438759,8.9824724,455.46872,-9.2337093
195.451,4.9932132,1.1621295,0.0,0,8.8429308,0.0,0.080808073,58.641361,8.9156237,456.31192,-9.2331924
195.4554,5.0172668,1.2278903,0.0,0,8.7785501,0.0,0.085579857,58.579498,8.8483887,456.8389,-9.2325907
195.4598,5.0202217,1.2944511,0.0,0,8.7159328,0.0,0.090392776,58.422604,8.7809467,457.2605,-9.2342396
195.4642,5.0271959,1.3570675,0.0,0,8.6547022,0.0,0.095029116,58.234673,8.7132044,457.56262,-9.2329788
195.4686,5.0767612,1.4190557,0.0,0,8.5934715,0.0,0.099509172,58.49836,8.6541786,457.73389,-9.2316771
195.473,5.0993376,1.4808673,0.0,0,8.5322428,0.0,0.1040325,58.550056,8.5877256,457.88089,-9.232007
195.4774,5.0727105,1.5441325,0.0,0,8.4710112,0.0,0.10870325,57.990616,8.5270481,457.93359,-9.2328491
195.4818,5.1159534,1.6028291,0.0,0,8.4097815,0.0,0.11317636,58.104763,8.4657173,457.98627,-9.2335119
195.4862,5.1327634,1.6623809,0.0,0,8.3485498,0.0,0.11749035,58.110088,8.4080458,457.58475,-9.2331285
195.4906,5.1886001,1.7228261,0.0,0,8.2873201,0.0,0.12200758,58.459839,8.3422527,457.14999,-9.232523
195.495,5.1599803,1.7827834,0.0,0,8.2260895,0.0,0.12651944,57.981739,8.286644,456.91495,-9.232666
195.4994,5.18994,1.840517,0.0,0,8.1648588,0.0,0.1308946,58.000229,8.2242565,456.7832,-9.2329035
195.5038,5.2686424,1.9043206,0.0,0,8.1036291,0.0,0.13575612,58.562424,8.1592007,456.71255,-9.2325563
195.5082,5.2975249,1.9673589,0.0,0,8.0429821,0.0,0.14051528,58.632137,8.0952311,456.73889,-9.2334709
195.5126,5.2785487,2.0302546,0.0,0,7.984726,0.0,0.1453646,58.119568,8.0312729,456.75027,-9.2335367
195.517,5.2754784,2.0870075,0.0,0,7.9264693,0.0,0.14969917,57.850338,7.9729652,456.64487,-9.2328529
195.5214,5.311893,2.1452227,0.0,0,7.8682137,0.0,0.15420817,57.909607,7.9166784,456.53946,-9.2307682
195.5258,5.3454027,2.2007034,0.0,0,7.8099575,0.0,0.15852706,58.087349,7.8575869,456.77753,-9.2320223
195.5302,5.3763618,2.2617655,0.0,0,7.7517014,0.0,0.16324325,58.1315,7.7997146,457.08054,-9.2331448
195.5346,5.3763881,2.3180237,0.0,0,7.6934457,0.0,0.16769202,57.815281,7.7360792,457.43597,-9.2325191
195.539,5.4233179,2.3769381,0.0,0,7.6351895,0.0,0.17237969,58.079605,7.680285,457.83121,-9.2319441
195.5434,5.4740109,2.4358714,0.0,0,7.5769334,0.0,0.1769754,58.441803,7.6159873,458.16806,-9.2329378
195.5478,5.4677806,2.4972999,0.0,0,7.5186772,0.0,0.1818698,58.065777,7.5626879,458.36566,-9.2336054
195.5522,5.4448013,2.5519965,0.0,0,7.4604211,0.0,0.18629409,57.508606,7.5019178,458.56445,-9.2320223
195.5566,5.5070643,2.6090662,0.0,0,7.4021654,0.0,0.19074205,57.900749,7.4484038,458.81451,-9.2344027
195.561,5.5895643,2.6673303,0.0,0,7.346283,0.0,0.1955727,58.597878,7.3853216,459.06458,-9.2329006
195.5654,5.5776677,2.7309277,0.0,0,7.2908783,0.0,0.20060518,58.097534,7.3244686,459.36389,-9.2323074
195.5698,5.5429373,2.7807384,0.0,0,7.2354732,0.0,0.20474742,57.599342,7.2686825,459.67966,-9.2325077
195.5742,5.5576196,2.8391516,0.0,0,7.1800685,0.0,0.20936352,57.432327,7.2125249,459.94519,-9.232543
195.5786,5.6114135,2.8870862,0.0,0,7.1246629,0.0,0.21342595,57.681591,7.1603923,460.1557,-9.232934
195.583,5.6423059,2.9443669,0.0,0,7.0692587,0.0,0.21807291,57.790764,7.1061416,460.31238,-9.2340193
195.5874,5.6657872,2.9971898,0.0,0,7.0138535,0.0,0.2225482,57.765385,7.0484538,460.25977,-9.2334604
195.5918,5.6868105,3.0564752,0.0,0,6.9584489,0.0,0.22740269,57.659096,6.9917912,460.20715,-9.2331152
195.5962,5.7387018,3.1099222,0.0,0,6.9030442,0.0,0.23195578,57.88258,6.9344869,459.35696,-9.2322817
195.6006,5.7512679,3.1687586,0.0,0,6.8476396,0.0,0.23681,57.802689,6.8801808,458.44846,-9.2311516
195.605,5.7642279,3.2194521,0.0,0,6.7922344,0.0,0.24131317,57.700855,6.8235993,457.17514,-9.231966
195.6094,5.780602,3.2779558,0.0,0,6.7380919,0.0,0.24602275,57.601093,6.7682233,455.7131,-9.2335081
195.6138,5.8305459,3.3303986,0.0,0,6.68538,0.0,0.25079784,57.761009,6.7099996,454.51056,-9.2321424
195.6182,5.847054,3.386878,0.0,0,6.632668,0.0,0.25540864,57.736763,6.6581855,453.72009,-9.2330275
195.6226,5.831646,3.4381785,0.0,0,6.5799561,0.0,0.26006639,57.265152,6.6024795,453.03741,-9.2314615
195.627,5.8452034,3.4924407,0.0,0,6.5272441,0.0,0.26463622,57.115181,6.5560403,453.1955,-9.2315931
195.6314,5.9210658,3.5423706,0.0,0,6.4745321,0.0,0.26902765,57.523129,6.4959245,453.35361,-9.2323971
195.6358,5.932148,3.5959051,0.0,0,6.4218202,0.0,0.27373156,57.36132,6.447978,453.48737,-9.2330055
195.6402,5.9514537,3.6456611,0.0,0,6.3691082,0.0,0.27822921,57.357666,6.3956146,453.61652,-9.2340965
195.6446,5.937736,3.6982994,0.0,0,6.3163962,0.0,0.28277251,56.975773,6.3439469,453.59552,-9.232028
195.649,6.0198712,3.7481205,0.0,0,6.2636843,0.0,0.28732455,57.527428,6.2883558,453.43741,-9.2325583
195.6534,6.0590463,3.8039684,0.0,0,6.2109723,0.0,0.29217595,57.584618,6.2361031,453.3913,-9.2328176
195.6578,6.0565014,3.8531954,0.0,0,6.1585317,0.0,0.29679295,57.359764,6.1827898,453.68115,-9.2319441
195.6622,6.080934,3.9073296,0.0,0,6.1083975,0.0,0.30158859,57.266674,6.133204,453.97101,-9.2319298
195.6666,6.1537237,3.9576745,0.0,0,6.0582643,0.0,0.30624223,57.652637,6.0792789,453.8746,-9.2314005
195.671,6.1762543,4.0183272,0.0,0,6.0081306,0.0,0.31162059,57.555843,6.0257969,453.7692,-9.2327242
195.6754,6.1453567,4.0630932,0.0,0,5.9579968,0.0,0.31585601,57.093777,5.9735341,453.23682,-9.2323399
195.6798,6.123138,4.1132364,0.0,0,5.9078636,0.0,0.32052302,56.599194,5.9274492,452.52539,-9.2327633
195.6842,6.1628389,4.1562319,0.0,0,5.8577299,0.0,0.32448918,56.712639,5.8793893,452.00168,-9.232523
195.6886,6.2248068,4.2081456,0.0,0,5.8075962,0.0,0.32927901,57.065617,5.8280654,451.72501,-9.2326918
195.693,6.2765951,4.2547908,0.0,0,5.7574625,0.0,0.33367854,57.286037,5.7798514,451.53848,-9.2329903
195.6974,6.3069873,4.3077879,0.0,0,5.7073288,0.0,0.33864534,57.225845,5.7284131,451.82834,-9.2319098
195.7018,6.3247352,4.3555341,0.0,0,5.6571956,0.0,0.34317055,57.076492,5.6744857,452.11819,-9.2311506
195.7062,6.3448524,4.4080849,0.0,0,5.6070614,0.0,0.34821895,57.0284,5.6259465,452.58319,-9.2318468
195.7106,6.4382105,4.4550595,0.0,0,5.5587354,0.0,0.35255161,57.543884,5.570869,453.07065,-9.2331991
195.715,6.3793149,4.5095882,0.0,0,5.5110397,0.0,0.35801196,56.84029,5.52387,453.47726,-9.23174
195.7194,6.3833938,4.5537019,0.0,0,5.4633436,0.0,0.36211199,56.581207,5.4734583,453.83298,-9.2319317
195.7238,6.4122915,4.6020908,0.0,0,5.4156475,0.0,0.36679676,56.54818,5.4284258,454.02701,-9.2316828
195.7282,6.4367499,4.6449814,0.0,0,5.3679519,0.0,0.37077957,56.592731,5.3829536,453.90845,-9.2317696
195.7326,6.4741335,4.6935472,0.0,0,5.3202558,0.0,0.37563631,56.642284,5.3380108,453.79166,-9.2331877
195.737,6.4863491,4.7385306,0.0,0,5.2725596,0.0,0.38005078,56.44347,5.2914257,453.69943,-9.232008
195.7414,6.6092968,4.7880297,0.0,0,5.224864,0.0,0.38496652,57.276173,5.2411361,453.60721,-9.2311544
195.7458,6.6509943,4.8413062,0.0,0,5.1771674,0.0,0.39013058,57.308704,5.187993,453.93417,-9.2318821
195.7502,6.6316614,4.8909683,0.0,0,5.1294718,0.0,0.3951287,56.849613,5.1399736,454.36896,-9.2323599
195.7546,6.5991421,4.9374332,0.0,0,5.0817757,0.0,0.39966443,56.360294,5.0954671,454.74173,-9.2332001
195.759,6.6233306,4.9799166,0.0,0,5.0349607,0.0,0.40394676,56.326183,5.0497313,455.05789,-9.2328463
195.7634,6.7132573,5.026505,0.0,0,4.9895968,0.0,0.40861675,56.799244,4.9989152,455.33127,-9.2317467
195.7678,6.7486501,5.0760102,0.0,0,4.9442329,0.0,0.4136349,56.812107,4.9528122,455.47623,-9.2311354
195.7722,6.7080545,5.1220107,0.0,0,4.898869,0.0,0.41807926,56.259388,4.9087534,455.62115,-9.2327337
195.7766,6.7600789,5.1641126,0.0,0,4.8535047,0.0,0.42253295,56.397144,4.86414,455.93347,-9.2323742
195.781,6.85431,5.2136931,0.0,0,4.8081408,0.0,0.4274765,56.907192,4.8171787,456.24966,-9.2318506
195.7854,6.8595233,5.2607007,0.0,0,4.7627769,0.0,0.4323231,56.703938,4.768579,456.58441,-9.2330465
195.7898,6.8424644,5.3063779,0.0,0,4.7174129,0.0,0.43695498,56.277401,4.7216415,456.92694,-9.2322521
195.7942,6.7952471,5.3474975,0.0,0,4.6720486,0.0,0.44130382,55.690422,4.681438,457.09882,-9.2331362
195.7986,6.8884554,5.3881683,0.0,0,4.6266847,0.0,0.44541183,56.145355,4.6394401,457.04611,-9.2314081
195.803,6.9743166,5.4336629,0.0,0,4.5813208,0.0,0.45019487,56.62772,4.5947695,456.95358,-9.2339659
195.8074,7.037159,5.4824529,0.0,0,4.5359983,0.0,0.45510426,56.785961,4.5464773,456.65057,-9.2327728
195.8118,7.017169,5.5275984,0.0,0,4.4928331,0.0,0.46001545,56.351868,4.4986262,456.34753,-9.2334194
195.8162,7.069334,5.5733685,0.0,0,4.4496775,0.0,0.46474755,56.522533,4.4557023,456.19632,-9.232688
195.8206,7.1046748,5.6161942,0.0,0,4.4065223,0.0,0.46923545,56.575909,4.4105868,456.06458,-9.2312908
195.825,7.0901504,5.6624069,0.0,0,4.3633671,0.0,0.47416377,56.235344,4.3676448,455.80347,-9.2319584
195.8294,7.1240239,5.7047281,0.0,0,4.3202119,0.0,0.47863454,56.165215,4.3239875,455.46094,-9.2331753
195.8338,7.1840506,5.7463126,0.0,0,4.2770567,0.0,0.48307779,56.395283,4.2791371,455.01959,-9.2322235
195.8382,7.2165613,5.7893977,0.0,0,4.2339015,0.0,0.48768994,56.417526,4.2353406,454.38721,-9.2318821
195.8426,7.2340927,5.8352675,0.0,0,4.1907463,0.0,0.49266785,56.263283,4.1975756,453.75214,-9.2306519
195.847,7.2861409,5.876092,0.0,0,4.1475911,0.0,0.4971098,56.416401,4.1547499,453.08023,-9.2319078
195.8514,7.3519506,5.9248457,0.0,0,4.1044359,0.0,0.50234663,56.640461,4.1069202,452.40833,-9.2327442
195.8558,7.4089599,5.964581,0.0,0,4.0612807,0.0,0.50674129,56.783508,4.0614352,452.12415,-9.2316418
195.8602,7.3827071,6.0128989,0.0,0,4.0194993,0.0,0.51206952,56.379696,4.017345,451.93973,-9.2325935
195.8646,7.3937297,6.0506234,0.0,0,3.9784563,0.0,0.51627588,56.176651,3.9774876,452.14783,-9.2303267
195.869,7.4355364,6.0982327,0.0,0,3.9374132,0.0,0.52148306,56.203102,3.9351199,452.71432,-9.2325468
195.8734,7.4839935,6.1336222,0.0,0,3.8963699,0.0,0.52551085,56.328529,3.8961146,453.11945,-9.2319231
195.8778,7.5130205,6.1774726,0.0,0,3.8553267,0.0,0.53037596,56.28569,3.8549566,453.04041,-9.2315865
195.8822,7.5116878,6.2162004,0.0,0,3.8142834,0.0,0.53475857,56.030827,3.8151977,452.96133,-9.2312984
195.8866,7.5912652,6.2595572,0.0,0,3.7732403,0.0,0.53953999,56.267868,3.7739735,451.06689,-9.232585
195.891,7.6586552,6.2977538,0.0,0,3.732197,0.0,0.54401416,56.562504,3.7328041,449.13022,-9.2320518
195.8954,7.6989341,6.3426061,0.0,0,3.6911538,0.0,0.54909611,56.612095,3.6943364,447.74118,-9.2315397
195.8998,7.7208157,6.3797946,0.0,0,3.6501107,0.0,0.5534429,56.465603,3.6544292,446.58182,-9.2316618
195.9042,7.7581205,6.4305987,0.0,0,3.6090674,0.0,0.55915105,56.458515,3.6078806,446.13358,-9.2322683
195.9086,7.7989197,6.4645553,0.0,0,3.5685976,0.0,0.56324899,56.520729,3.5689301,446.62103,-9.2313967
195.913,7.8248787,6.5084491,0.0,0,3.5295517,0.0,0.56826061,56.452538,3.5310049,447.08545,-9.2311716
195.9174,7.8262076,6.5431085,0.0,0,3.4905062,0.0,0.57242888,56.202301,3.4913034,447.42798,-9.2315702
195.9218,7.8883777,6.5827866,0.0,0,3.4514608,0.0,0.57700348,56.425667,3.4523544,447.77051,-9.2317095
195.9262,7.9394617,6.6215215,0.0,0,3.412415,0.0,0.58183348,56.497894,3.4131258,448.60352,-9.2309074
195.9306,8.0025558,6.6667018,0.0,0,3.3733692,0.0,0.58695537,56.669838,3.3743873,449.49939,-9.2317657
195.935,8.0265732,6.7001433,0.0,0,3.3343236,0.0,0.59125656,56.578102,3.333406,450.4761,-9.231966
195.9394,8.0330248,6.7426715,0.0,0,3.2952783,0.0,0.59606236,56.349926,3.2952235,451.50372,-9.2332687
195.9438,8.0830097,6.775147,0.0,0,3.2562327,0.0,0.60039681,56.435654,3.2582264,452.3472,-9.2314196
195.9482,8.2177181,6.8215876,0.0,0,3.2171869,0.0,0.60574722,57.122604,3.2191043,452.83469,-9.2324963
195.9526,8.2207584,6.8568726,0.0,0,3.1781414,0.0,0.61039114,56.863018,3.1792636,453.31137,-9.231698
195.957,8.2782211,6.9048986,0.0,0,3.1390958,0.0,0.61604816,56.96735,3.1372557,453.64075,-9.2312708
195.9614,8.3283253,6.9383111,0.0,0,3.101805,0.0,0.62038696,57.032047,3.1001995,453.97009,-9.232151
195.9658,8.3574705,6.9780011,0.0,0,3.0646603,0.0,0.62530881,56.916584,3.0650115,454.19467,-9.2320433
195.9702,8.4127445,7.0174265,0.0,0,3.0275152,0.0,0.63035792,57.054688,3.0249214,454.3923,-9.2307606
195.9746,8.349947,7.055584,0.0,0,2.9903708,0.0,0.635028,56.376984,2.9897912,454.43842,-9.2322187
195.979,8.400631,7.0838151,0.0,0,2.9532259,0.0,0.63874757,56.449966,2.9533892,454.34619,-9.2311859
195.9834,8.5187645,7.1247296,0.0,0,2.916081,0.0,0.64384335,57.019352,2.9170141,454.24741,-9.231883
195.9878,8.6033821,7.1605167,0.0,0,2.8789363,0.0,0.64851165,57.232681,2.8792815,454.12881,-9.2307606
195.9922,8.6221437,7.203371,0.0,0,2.8417914,0.0,0.65380514,57.074333,2.8401659,454.01022,-9.2316427
195.9966,8.6912746,7.2377028,0.0,0,2.8046467,0.0,0.65855092,57.257248,2.801652,453.9303,-9.2312231
196.001,8.7544937,7.2773275,0.0,0,2.7675018,0.0,0.66347587,57.458496,2.7664607,453.85123,-9.2310591
196.0054,8.8268242,7.3123045,0.0,0,2.7303569,0.0,0.66828227,57.592068,2.7242732,453.69794,-9.2314816
196.0098,8.8278608,7.352457,0.0,0,2.694227,0.0,0.6735844,57.324482,2.6904309,453.51349,-9.2319946
196.0142,8.8554487,7.3879485,0.0,0,2.658895,0.0,0.67821437,57.218811,2.6544373,453.51111,-9.2317295
196.0186,8.9245539,7.425786,0.0,0,2.6235628,0.0,0.6832701,57.36652,2.6158075,453.74823,-9.2319365
196.023,8.9182711,7.455349,0.0,0,2.5882308,0.0,0.68739575,57.102085,2.5843937,454.04199,-9.230546
196.0274,8.9938784,7.4932656,0.0,0,2.5528989,0.0,0.69236106,57.30611,2.5475628,454.63483,-9.2309504
196.0318,9.0831528,7.5248137,0.0,0,2.5175667,0.0,0.69670635,57.619267,2.510412,455.22769,-9.2324667
196.0362,9.1404457,7.5644937,0.0,0,2.482235,0.0,0.70219082,57.674713,2.4777117,455.68042,-9.2313023
196.0406,9.1847,7.5958481,0.0,0,2.4469028,0.0,0.70620543,57.714188,2.4420421,456.1152,-9.2313728
196.045,9.2247877,7.6326151,0.0,0,2.4115708,0.0,0.71132702,57.68449,2.4087675,456.48529,-9.2314425
196.0494,9.2794905,7.6652126,0.0,0,2.3762388,0.0,0.71587747,57.750874,2.3714151,456.81467,-9.2330275
196.0538,9.3730354,7.7009935,0.0,0,2.3409069,0.0,0.72085619,58.034328,2.3374515,457.11258,-9.2312136
196.0582,9.4642467,7.7374482,0.0,0,2.3059127,0.0,0.72574449,58.315651,2.3026433,457.3497,-9.2320385
196.0626,9.5346432,7.7756987,0.0,0,2.2723055,0.0,0.73110533,58.471008,2.2644124,457.57877,-9.2301579
196.067,9.5143862,7.8080416,0.0,0,2.2386985,0.0,0.73574412,58.076069,2.2277019,457.69733,-9.2309837
196.0714,9.5055027,7.8413463,0.0,0,2.2050912,0.0,0.74051487,57.720295,2.1958964,457.81589,-9.2328243
196.0758,9.5991325,7.8751745,0.0,0,2.171484,0.0,0.7450527,58.017033,2.1666214,456.92841,-9.2320518
196.0802,9.6788645,7.9060163,0.0,0,2.1378767,0.0,0.74955642,58.299507,2.1339474,455.78223,-9.2312803
196.0846,9.7413864,7.9373927,0.0,0,2.1042697,0.0,0.75398129,58.354301,2.0992322,452.63055,-9.2311058
196.089,9.8028612,7.9711604,0.0,0,2.0706627,0.0,0.75886786,58.447056,2.0673277,447.6478,-9.2317562
196.0934,9.9147387,8.0030756,0.0,0,2.0370555,0.0,0.76333398,58.774323,2.0322287,442.64478,-9.2304821
196.0978,10.027143,8.0394344,0.0,0,2.0034482,0.0,0.76868737,59.21003,1.9978158,437.58099,-9.231245
196.1022,10.065229,8.0753937,0.0,0,1.969841,0.0,0.77378964,59.116608,1.9669793,432.51718,-9.2306328
196.1066,10.116467,8.1107883,0.0,0,1.9362339,0.0,0.77890694,59.12603,1.9304087,430.97073,-9.2303677
196.111,10.177583,8.1433058,0.0,0,1.9039891,0.0,0.78360069,59.174522,1.8974724,429.50604,-9.2296715
196.1154,10.255984,8.1765575,0.0,0,1.8720186,0.0,0.78850478,59.33136,1.867842,429.51025,-9.2304077
196.1198,10.297622,8.2094307,0.0,0,1.8400483,0.0,0.7932505,59.32716,1.8302356,430.1304,-9.2320576
196.1242,10.358922,8.2422085,0.0,0,1.8080778,0.0,0.79815739,59.411591,1.8018312,431.25201,-9.2324352
196.1286,10.430161,8.2751503,0.0,0,1.7761074,0.0,0.80288404,59.457993,1.7650578,433.03336,-9.230732
196.133,10.475451,8.3050985,0.0,0,1.744137,0.0,0.80742335,59.446186,1.7371234,434.82309,-9.2311411
196.1374,10.468927,8.3354692,0.0,0,1.7121667,0.0,0.81191903,59.202217,1.7024281,436.65723,-9.2311029
196.1418,10.531369,8.3657513,0.0,0,1.6801963,0.0,0.8165074,59.286343,1.6749246,438.49133,-9.2304707
196.1462,10.646502,8.3947268,0.0,0,1.6482258,0.0,0.82066554,59.608547,1.643664,439.76407,-9.2319193
196.1506,10.806972,8.4300718,0.0,0,1.6162554,0.0,0.82600677,60.215279,1.6138418,440.96484,-9.2305822
196.155,10.940254,8.462739,0.0,0,1.5842849,0.0,0.83099377,60.688179,1.5810046,441.86588,-9.2304401
196.1594,10.996664,8.4968386,0.0,0,1.5530447,0.0,0.83597338,60.709011,1.5442871,442.57822,-9.2312984
196.1638,11.066929,8.5297089,0.0,0,1.5226319,0.0,0.84097219,60.758038,1.5100789,443.17361,-9.2315769
196.1682,11.080994,8.5606966,0.0,0,1.4922191,0.0,0.84566885,60.601212,1.4794122,443.54291,-9.2307558
196.1726,11.075214,8.5918589,0.0,0,1.4618063,0.0,0.85051697,60.210312,1.4492267,443.87262,-9.2302856
196.177,11.049394,8.6174707,0.0,0,1.4313934,0.0,0.85453165,59.887135,1.4264059,443.66171,-9.2312384
196.1814,11.189929,8.6490612,0.0,0,1.4009807,0.0,0.85940796,60.289959,1.3981527,443.45081,-9.2316618
196.1858,11.419044,8.6786709,0.0,0,1.3705679,0.0,0.8639282,61.235657,1.3634356,443.10342,-9.2308884
196.1902,11.60667,8.7141733,0.0,0,1.3401551,0.0,0.86944276,61.921062,1.329563,442.72095,-9.2303028
196.1946,11.600001,8.74401,0.0,0,1.3097425,0.0,0.87419134,61.638603,1.3008075,441.67621,-9.231986
196.199,11.592509,8.775033,0.0,0,1.2793295,0.0,0.87913293,61.229015,1.2666514,440.02679,-9.2313213
196.2034,11.614149,8.8031473,0.0,0,1.2489167,0.0,0.88369828,61.124584,1.2416172,438.17288,-9.2307758
196.2078,11.751116,8.8346262,0.0,0,1.2186602,0.0,0.88849527,61.523563,1.2136207,435.70538,-9.230485
196.2122,11.853562,8.8624153,0.0,0,1.1897346,0.0,0.89305085,61.787796,1.1853192,433.23792,-9.2300453
196.2166,11.953681,8.8927612,0.0,0,1.160809,0.0,0.89779598,62.027042,1.1537594,431.68597,-9.2314196
196.221,12.090896,8.9198713,0.0,0,1.1318834,0.0,0.90243161,62.410267,1.1199125,430.1553,-9.2294302
196.2254,12.111381,8.9532394,0.0,0,1.1029578,0.0,0.9076612,62.238075,1.0933769,429.73096,-9.2303028
196.2298,12.143653,8.9774246,0.0,0,1.0740322,0.0,0.91173911,62.154762,1.0658957,429.77054,-9.2303238
196.2342,12.171456,9.0070591,0.0,0,1.0451066,0.0,0.91664618,61.955956,1.0372212,430.26596,-9.2309818
196.2386,12.279403,9.0336733,0.0,0,1.016181,0.0,0.92106438,62.226311,1.0136315,431.36118,-9.2305479
196.243,12.444704,9.0640373,0.0,0,0.98725533,0.0,0.92590261,62.73732,0.97951812,432.45218,-9.2310467
196.2474,12.579527,9.090847,0.0,0,0.95832974,0.0,0.93061805,63.156506,0.95307654,433.52097,-9.2312164
196.2518,12.694961,9.121748,0.0,0,0.92940414,0.0,0.93566012,63.424347,0.92082608,434.58978,-9.2302809
196.2562,12.847079,9.1507378,0.0,0,0.90047848,0.0,0.94090462,63.822372,0.89180291,434.43054,-9.2296934
196.2606,12.979109,9.1827526,0.0,0,0.87260348,0.0,0.94585294,64.190887,0.86338043,434.11386,-9.2317047
196.265,13.029763,9.2088737,0.0,0,0.84509462,0.0,0.9506914,64.157654,0.83539379,433.27087,-9.230073
196.2694,12.998089,9.241168,0.0,0,0.81758583,0.0,0.95594972,63.642132,0.80400568,432.0965,-9.2303486
196.2738,13.043198,9.2630911,0.0,0,0.79007703,0.0,0.96022725,63.565357,0.77968013,431.13354,-9.2310085
196.2782,13.221535,9.2942247,0.0,0,0.76256824,0.0,0.96525872,64.075272,0.75417727,430.57935,-9.2310944
196.2826,13.33887,9.3149118,0.0,0,0.73505944,0.0,0.9692291,64.463943,0.72611219,430.0863,-9.2303438
196.287,13.419627,9.3480749,0.0,0,0.70755064,0.0,0.97471404,64.464813,0.69996595,430.42938,-9.230937
196.2914,13.502501,9.3700571,0.0,0,0.68004185,0.0,0.97905761,64.590309,0.67315036,430.77246,-9.2303772
196.2958,13.701343,9.4046659,0.0,0,0.65253305,0.0,0.98463809,65.143494,0.64444315,431.5354,-9.2301741
196.3002,13.865113,9.4264116,0.0,0,0.62502426,0.0,0.98917234,65.640869,0.61414957,432.40628,-9.2289047
196.3046,13.845553,9.4583654,0.0,0,0.59751546,0.0,0.99450517,65.197014,0.58669293,433.37372,-9.2298422
196.309,13.819376,9.4778843,0.0,0,0.57050872,0.0,0.99857968,64.844696,0.56339771,434.42935,-9.2316341
196.3134,13.996103,9.5058308,0.0,0,0.54432869,0.0,1.003373,65.308746,0.53617454,435.47177,-9.2303715
196.3178,14.21896,9.528801,0.0,0,0.51814872,0.0,1.0079694,66.082764,0.50979596,436.47461,-9.2303104
196.3222,13.338346,9.5445433,0.0,0,0.49196872,0.0,1.0106505,61.839901,0.48567837,437.47742,-9.2298918
196.3266,12.633962,9.5507965,0.0,0,0.46578872,0.0,1.0121325,58.465862,0.47267979,438.48026,-9.231904
196.331,12.23439,9.5577555,0.0,0,0.43960872,0.0,1.0132064,56.594513,0.45755813,439.48306,-9.2318602
196.3354,11.947854,9.5608091,0.0,0,0.41342869,0.0,1.014269,55.196301,0.4419398,440.56027,-9.2318945
196.3398,11.636119,9.567008,0.0,0,0.38724869,0.0,1.0150883,53.71246,0.42210954,441.66867,-9.2321215
196.3442,11.263882,9.5655251,0.0,0,0.36106867,0.0,1.0152736,51.977612,0.4046402,442.64008,-9.2332954
196.3486,10.85788,9.569665,0.0,0,0.33488867,0.0,1.0158653,50.067394,0.3959237,443.43115,-9.2340574
196.353,10.545527,9.5696316,0.0,0,0.3087087,0.0,1.0161731,48.626553,0.39538866,444.23474,-9.2334623
196.3574,10.394851,9.5728559,0.0,0,0.28255266,0.0,1.0166533,47.884342,0.38086361,445.10437,-9.232954
196.3618,10.402574,9.5687265,0.0,0,0.25765175,0.0,1.016099,47.955723,0.36559117,445.97397,-9.232688
196.3662,10.610951,9.5769491,0.0,0,0.23275654,0.0,1.0176971,48.811611,0.3312203,446.53989,-9.2313604
196.3706,10.838044,9.5754747,0.0,0,0.20786138,0.0,1.0175915,49.872322,0.29960042,447.06689,-9.231102
196.375,10.996574,9.5820656,0.0,0,0.18296619,0.0,1.0186627,50.56406,0.26429921,447.41602,-9.232851
196.3794,11.049523,9.5819063,0.0,0,0.15807098,0.0,1.0187436,50.821239,0.23371203,447.65317,-9.2315712
196.3838,11.039647,9.5850916,0.0,0,0.13317578,0.0,1.019528,50.707394,0.20248407,447.93521,-9.2313643
196.3882,11.014123,9.585865,0.0,0,0.10828056,0.0,1.019703,50.607307,0.17936179,448.30408,-9.2314243
196.3926,10.99029,9.5919209,0.0,0,0.083385363,0.0,1.0210005,50.392464,0.15331331,448.67029,-9.2323084
196.397,10.91493,9.5883074,0.0,0,0.058490161,0.0,1.0203146,50.131935,0.13174416,448.99966,-9.2326174
196.4014,10.846802,9.5962791,0.0,0,0.033594958,0.0,1.0220097,49.67506,0.10447998,449.32901,-9.2306376
196.4058,10.78303,9.5939283,0.0,0,0.0086997608,0.0,1.0214577,49.436214,0.08726237,449.60599,-9.2314072
196.4102,10.735383,9.5983248,0.0,0,-0.01580043,0.0,1.0225794,49.162926,0.066436045,449.86948,-9.2323503
196.4146,10.665911,9.5986147,0.0,0,-0.040088434,0.0,1.0225013,48.861176,0.047714256,450.13986,-9.2319746
196.419,10.552427,9.6002626,0.0,0,-0.064376429,0.0,1.0232016,48.31662,0.028208638,450.41653,-9.2324772
196.4234,10.453269,9.603034,0.0,0,-0.088664427,0.0,1.0233369,47.842842,0.014925121,450.68661,-9.2324018
196.4278,10.371133,9.6040382,0.0,0,-0.044744857,449.55496,1.0237699,47.465729,0.00088699366,450.93692,-9.2319441
196.4322,10.222268,9.6035442,0.0,0,0.75208735,450.0,1.023438,46.801113,-0.0094584972,451.18726,-9.2309465
196.4366,8.3224697,9.5972605,0.0,0,1.5489455,450.0,1.0226065,38.229736,0.07220979,451.50195,-9.2322798
196.441,4.2859702,9.5772314,0.0,0,2.3458037,450.0,1.0187331,19.923449,0.31735966,451.81815,-9.2366304
196.4454,-0.13129221,9.5267353,0.0,0,3.1426611,450.0,1.0093362,-0.60596073,0.99679506,452.14362,-9.239213
196.4498,0.068845183,9.5542631,0.0,0,3.9395185,450.0,1.0143082,0.30532902,2.3465087,452.47299,-9.2389488
196.4542,0.15150738,9.5586176,0.0,0,4.7363758,450.0,1.0152287,0.69294804,3.3323872,452.7739,-9.2388945
196.4586,0.090641543,9.5573463,0.0,0,5.5332332,450.0,1.0148139,0.37904409,4.0980973,453.03738,-9.2382374
196.463,0.013515823,9.557292,0.0,0,6.3300915,450.0,1.0150791,0.099002175,4.8411851,453.29669,-9.2372999
196.4674,0.02234152,9.5558119,0.0,0,7.1269488,450.0,1.0143625,0.15472257,5.611721,453.53384,-9.2355862
196.4718,0.090442061,9.5525379,0.0,0,7.9238062,450.0,1.0140212,0.43391794,6.4215412,453.771,-9.2351074
196.4762,0.012699659,9.556221,0.0,0,8.720664,450.0,1.0144589,0.08917962,7.262435,453.9848,-9.2364244
196.4806,0.032769155,9.5547485,0.0,0,9.5175228,450.0,1.0141761,0.11988651,8.095685,454.19559,-9.2343531
196.485,0.016639842,9.5526543,0.0,0,10.314381,450.0,1.0136799,0.10388947,8.9205866,454.35788,-9.2335215
196.4894,-0.014235608,9.552763,0.0,0,11.111238,450.0,1.0136549,-0.069007747,9.7310295,454.48962,-9.2334156
196.4938,0.0074824919,9.55334,0.0,0,11.908095,450.0,1.0135572,0.035716247,10.539804,454.61237,-9.2348166
196.4982,0.019745322,9.5499907,0.0,0,12.704953,450.0,1.0128542,0.1513216,11.330289,454.71777,-9.2345438
196.5026,0.047234003,9.5544081,0.0,0,13.501811,450.0,1.0136443,0.19576538,12.108048,454.82675,-9.234313
196.507,-0.020745784,9.5521622,0.0,0,14.298668,450.0,1.0130374,-0.12273714,12.885996,454.98486,-9.2344322
196.5114,0.0048957495,9.5551195,0.0,0,15.095526,450.0,1.013588,0.038140215,13.668897,455.14294,-9.2340202
196.5158,0.0030935914,9.5540552,0.0,0,15.892384,450.0,1.0132511,0.090764888,14.46177,455.25912,-9.2322664
196.5202,0.047187164,9.5566311,0.0,0,16.689241,450.0,1.0135638,0.1736913,15.276378,455.36453,-9.2341013
196.5246,0.016126018,9.5530701,0.0,0,17.486099,450.0,1.0129676,0.058242995,16.090469,455.44238,-9.234642
196.529,0.031183662,9.5574436,0.0,0,18.0,450.0,1.0136385,0.031811312,16.88419,455.49509,-9.2341728
196.5334,0.039960615,9.5520916,0.0,0,18.0,450.0,1.0125937,0.16625732,17.646448,455.55438,-9.2339783
196.5378,0.10146593,9.5582752,0.0,0,18.0,450.0,1.0136095,0.51407957,18.230501,455.63342,-9.2363825
196.5422,0.29764178,9.5646353,0.0,0,18.0,450.0,1.0147257,1.3633817,18.457943,455.71246,-9.2426901
196.5466,0.48635134,9.5737886,0.0,0,18.0,450.0,1.0162668,2.28386,18.326944,455.7915,-9.2584476
196.551,0.50120991,9.5723457,0.0,0,18.0,450.0,1.0160429,2.27897,18.140839,455.87057,-9.2838783
196.5554,0.52527964,9.5699434,0.0,0,18.0,450.0,1.0152482,2.4511521,18.064121,455.96817,-9.3176174
196.5598,0.50889963,9.5684862,0.0,0,18.0,450.0,1.0150421,2.3648252,18.072449,456.07358,-9.3556776
196.5642,0.46806553,9.5719604,0.0,0,18.0,450.0,1.0156245,2.1853967,18.107489,456.15622,-9.3948765
196.5686,0.48464438,9.5680637,0.0,0,18.0,450.0,1.0148345,2.2526956,18.130142,456.20892,-9.4299908
196.573,0.49464995,9.567399,0.0,0,18.0,450.0,1.0146482,2.3035467,18.135735,456.25323,-9.4609222
196.5774,0.51337421,9.5671711,0.0,0,18.0,450.0,1.0145183,2.3646717,18.138092,456.25323,-9.4933624
196.5818,0.49622515,9.5738649,0.0,0,18.0,450.0,1.0157207,2.2901349,18.134884,456.25323,-9.5254431
196.5862,0.49722701,9.5702658,0.0,0,18.0,450.0,1.0152634,2.3021133,18.129223,456.27658,-9.5574446
196.5906,0.50270218,9.5701561,0.0,0,18.0,450.0,1.0149691,2.3107061,18.126732,456.30292,-9.5907269
196.595,0.53017658,9.5691452,0.0,0,18.0,450.0,1.0149417,2.4716654,18.116835,456.31311,-9.6236992
196.5994,0.49802706,9.5739708,0.0,0,18.0,450.0,1.0154909,2.2640049,18.116323,456.31311,-9.6580839
196.6038,0.49083716,9.5708141,0.0,0,18.0,450.0,1.0152663,2.2750554,18.112022,456.30414,-9.6910152
196.6082,0.5063284,9.5731564,0.0,0,18.0,450.0,1.0154464,2.3706338,18.108055,456.27777,-9.7231846
196.6126,0.5225004,9.5692244,0.0,0,18.0,450.0,1.0151999,2.3958898,18.110392,456.25323,-9.7562647
196.617,0.50085205,9.5745115,0.0,0,18.0,450.0,1.0155588,2.3697159,18.109766,456.25323,-9.7879877
196.6214,0.48344597,9.5706377,0.0,0,18.0,450.0,1.0152186,2.2285073,18.108116,456.25323,-9.8227701
196.6258,0.50214565,9.5748243,0.0,0,18.0,450.0,1.0156366,2.3366973,18.1085,456.25323,-9.857933
196.6302,0.52418721,9.5704212,0.0,0,18.0,450.0,1.0153102,2.4157662,18.099035,456.25323,-9.8874569
196.6346,0.52580076,9.5784035,0.0,0,18.0,450.0,1.01626,2.4389095,18.101503,456.25323,-9.9202728
196.639,0.49437645,9.5734539,0.0,0,18.0,450.0,1.0158175,2.2584541,18.09955,456.25323,-9.954668
196.6434,0.50133932,9.5744762,0.0,0,18.0,450.0,1.0159307,2.3072317,18.098473,456.25864,-9.9875822
196.6478,0.53166944,9.5732822,0.0,0,18.0,450.0,1.0159012,2.4523027,18.099455,456.28497,-10.018803
196.6522,0.53268516,9.5751486,0.0,0,18.0,450.0,1.0160986,2.4618645,18.09362,456.31131,-10.052019
196.6566,0.51532781,9.5733566,0.0,0,18.0,450.0,1.0161827,2.3609116,18.091433,456.31311,-10.084368
196.661,0.51323158,9.5754452,0.0,0,18.0,450.0,1.0162305,2.3729074,18.093206,456.31311,-10.117764
196.6654,0.53085595,9.5691967,0.0,0,18.0,450.0,1.0154982,2.457128,18.094292,456.27838,-10.150179
196.6698,0.54967237,9.5772648,0.0,0,18.0,450.0,1.0167599,2.5428543,18.090124,456.22568,-10.181946
196.6742,0.52887785,9.5736132,0.0,0,18.0,450.0,1.0165548,2.450104,18.089825,456.18317,-10.215459
196.6786,0.51637238,9.5731697,0.0,0,18.0,450.0,1.0163224,2.4020617,18.085821,456.15683,-10.248552
196.683,0.52570963,9.5719547,0.0,0,18.0,450.0,1.0163449,2.4422803,18.08246,456.13345,-10.283298
196.6874,0.55429989,9.5734148,0.0,0,18.0,450.0,1.0164666,2.5437617,18.08193,456.13345,-10.316648
196.6918,0.52495837,9.5730743,0.0,0,18.0,450.0,1.0169262,2.4183753,18.08201,456.13345,-10.351537
196.6962,0.52830398,9.5748301,0.0,0,18.0,450.0,1.0170535,2.4048688,18.086582,456.08914,-10.383531
196.7006,0.52648246,9.5702972,0.0,0,18.0,450.0,1.0164251,2.4113631,18.0818,456.03644,-10.416354
196.705,0.55290151,9.5731382,0.0,0,18.0,450.0,1.0169563,2.5574088,18.082058,455.98373,-10.445676
196.7094,0.53735477,9.5709143,0.0,0,18.0,450.0,1.0166373,2.4677174,18.080805,455.93103,-10.480666
196.7138,0.51552403,9.5744314,0.0,0,18.0,450.0,1.0174404,2.3863628,18.078814,455.89392,-10.512971
196.7182,0.53734446,9.5681896,0.0,0,18.0,450.0,1.0163243,2.4263921,18.075373,455.89392,-10.546057
196.7226,0.55711865,9.5716209,0.0,0,18.0,450.0,1.017065,2.5773928,18.076206,455.89392,-10.578782
196.727,0.55820531,9.569706,0.0,0,18.0,450.0,1.0168302,2.5363021,18.073818,455.89392,-10.613064
196.7314,0.52827877,9.5744095,0.0,0,18.0,450.0,1.017853,2.4347262,18.072201,455.89392,-10.646041
196.7358,0.54122525,9.5687895,0.0,0,18.0,450.0,1.0167807,2.4407985,18.065952,455.91367,-10.67943
196.7402,0.56071693,9.5707769,0.0,0,18.0,450.0,1.017328,2.5622895,18.068628,455.94003,-10.71037
196.7446,0.54636526,9.5708895,0.0,0,18.0,450.0,1.0171347,2.5313649,18.068476,455.92865,-10.74185
196.749,0.54391193,9.5727243,0.0,0,18.0,450.0,1.0175457,2.516974,18.06415,455.87595,-10.776547
196.7534,0.5457955,9.5706873,0.0,0,18.0,450.0,1.0173646,2.5074801,18.063856,455.81787,-10.810699
196.7578,0.54547334,9.5698204,0.0,0,18.0,450.0,1.0172024,2.5155087,18.064945,455.73883,-10.845149
196.7622,0.56300831,9.5692959,0.0,0,18.0,450.0,1.0171857,2.6000996,18.063066,455.65979,-10.877227
196.7666,0.53681558,9.5704556,0.0,0,18.0,450.0,1.0173808,2.4474783,18.060783,455.64212,-10.908544
196.771,0.53776377,9.5694208,0.0,0,18.0,450.0,1.0172018,2.4299562,18.062418,455.62894,-10.94346
196.7754,0.55223805,9.5712223,0.0,0,18.0,450.0,1.0174361,2.5351174,18.060379,455.60709,-10.974277
196.7798,0.56101459,9.5651283,0.0,0,18.0,450.0,1.0163628,2.5881214,18.059326,455.58072,-11.00759
196.7842,0.53733802,9.5691442,0.0,0,18.0,450.0,1.0173719,2.5368712,18.060303,455.55945,-11.04092
196.7886,0.54120988,9.5695744,0.0,0,18.0,450.0,1.0171365,2.4894114,18.055172,455.5463,-11.071885
196.793,0.55139083,9.5668907,0.0,0,18.0,450.0,1.0168114,2.5367794,18.061134,455.52863,-11.106336
196.7974,0.57037199,9.5678387,0.0,0,18.0,450.0,1.0167773,2.6197264,18.054365,455.47592,-11.140164
196.8018,0.55900681,9.5701885,0.0,0,18.0,450.0,1.0173014,2.5793698,18.056973,455.42325,-11.173506
196.8062,0.54633713,9.5683708,0.0,0,18.0,450.0,1.0168359,2.5334666,18.051992,455.35947,-11.205718
196.8106,0.55270302,9.5690222,0.0,0,18.0,450.0,1.0169053,2.5514145,18.052626,455.29358,-11.237453
196.815,0.58500254,9.5673399,0.0,0,18.0,450.0,1.0164399,2.674942,18.050404,455.25015,-11.27072
196.8194,0.55890596,9.569375,0.0,0,18.0,450.0,1.0168597,2.5689132,18.051832,455.22382,-11.303402
196.8238,0.53858101,9.5707064,0.0,0,18.0,450.0,1.0168962,2.4811375,18.053175,455.20914,-11.337639
197.2273,0.51073235,9.5757332,0.0,0,18.0,0.001595666,1.017213,2.3516195,18.01338,440.12955,-11.480482
199.4273,0.51762885,9.5913239,0.0,0,18.0,1.5917635e-33,1.019959,2.3765905,17.99938,415.77255,-11.48028
201.6273,0.53164661,9.6031609,0.0,0,18.0,1.4012985e-45,1.0223032,2.4347301,18.000561,396.71771,-11.480822
203.8273,0.54260194,9.6144171,0.0,0,18.0,1.4012985e-45,1.0243264,2.4835553,17.999712,378.80576,-11.479997
206.0273,0.5652169,9.6250057,0.0,0,18.0,1.4012985e-45,1.0263658,2.5844202,17.999037,361.69415,-11.480579
208.2273,0.59070027,9.6358118,0.0,0,18.0,1.4012985e-45,1.028236,2.6897969,18.001284,345.37012,-11.480925
210.4273,0.59368867,9.6446238,0.0,0,18.0,1.4012985e-45,1.0299923,2.6958687,17.999531,329.8367,-11.480676
212.6273,0.60839862,9.6539307,0.0,0,18.0,1.4012985e-45,1.0316793,2.7651579,18.000566,315.04965,-11.480778
214.8273,0.63774329,9.6631203,0.0,0,18.0,1.4012985e-45,1.033455,2.8905613,18.001081,301.33609,-11.480611
217.0273,0.64221811,9.6720772,0.0,0,18.0,1.4012985e-45,1.0350182,2.9023669,18.000212,287.77158,-11.48069
219.2273,0.64215952,9.6803045,0.0,0,18.0,1.4012985e-45,1.0366888,2.900331,18.000986,275.02374,-11.481224
221.4273,0.66346967,9.6884813,0.0,0,18.0,1.4012985e-45,1.0381677,2.9946141,18.000227,263.04474,-11.481467
223.6273,0.67411745,9.6959343,0.0,0,18.0,1.4012985e-45,1.039637,3.0300612,17.999887,251.77928,-11.481004
225.8273,0.67996383,9.7031403,0.0,0,18.0,1.4012985e-45,1.0408622,3.0543354,18.000959,240.91794,-11.481133
228.0273,0.69001722,9.7105036,0.0,0,18.0,1.4012985e-45,1.0424061,3.1036918,18.000151,230.63748,-11.480216
230.2273,0.713301,9.717248,0.0,0,18.0,1.4012985e-45,1.0435984,3.2009957,17.999296,220.49149,-11.480127
232.4273,0.71927482,9.7240057,0.0,0,18.0,1.4012985e-45,1.0449313,3.2144628,17.999668,211.1456,-11.48109
234.6273,0.71402353,9.7306509,0.0,0,18.0,1.4012985e-45,1.0460474,3.1958501,18.001152,202.30768,-11.481233
236.8273,0.73321825,9.7364511,0.0,0,18.0,1.4012985e-45,1.0473264,3.2769415,18.000504,193.57556,-11.481858
239.0273,0.74034941,9.742424,0.0,0,18.0,1.4012985e-45,1.0483507,3.3007128,17.999922,185.31725,-11.480277
241.2273,0.74073058,9.7478704,0.0,0,18.0,1.4012985e-45,1.0494742,3.2985337,18.000599,177.65611,-11.479601
243.4273,0.75134403,9.7532349,0.0,0,18.0,1.4012985e-45,1.0503575,3.3489325,18.000294,170.30609,-11.479357
245.6273,0.76750535,9.7583055,0.0,0,18.0,1.4012985e-45,1.0515081,3.4201665,18.000559,163.51305,-11.479799
247.8273,0.77155334,9.7639418,0.0,0,18.0,1.4012985e-45,1.0524521,3.4296312,18.000345,156.98021,-11.481401
250.0273,0.76440012,9.7685976,0.0,0,18.0,1.4012985e-45,1.0533874,3.3931425,17.999537,150.76233,-11.481921
252.2273,0.78189409,9.7731781,0.0,0,18.0,1.4012985e-45,1.0541687,3.4710252,18.000446,144.60887,-11.482131
254.4273,0.78770614,9.7773056,0.0,0,18.0,1.4012985e-45,1.0551469,3.4936502,18.000067,139.06583,-11.480394
256.6273,0.78634876,9.7815199,0.0,0,18.0,1.4012985e-45,1.055837,3.4786813,18.00045,133.66356,-11.479756
256.8273,0.78696269,9.7826872,0.0,0,18.0,1.4012985e-45,1.0560955,3.4900417,18.000832,133.30064,-11.479654