File: examples/dan-msc-case-studies/CS3/data/01 raw data/baron_test_045.csv
Time(sec),Force(kN),Jaw(mm),PowAngle(deg),Power(W),Pram,PTemp,Strain,Stress(MPa),Stroke(mm),TC1(C),wedge(mm)
0.0,0.85307574,0.22979352,0.0,0,11.076097,0.0012849667,0.0154558,10.697555,11.077045,29.04096,-9.1426258
1.1,0.81226599,0.0047820597,0.0,0,11.076097,3.2158811,0.00032780389,10.345426,11.075583,29.005928,-9.4943991
2.2,0.7872197,0.0048314463,0.0,0,11.076097,6.5158834,0.00033548559,10.023361,11.077043,29.009258,-9.4917097
3.3,0.77027267,0.0049044099,0.0,0,11.076097,9.8158808,0.00034454124,9.8061924,11.075706,29.030767,-9.4903688
4.4,0.74729335,0.0047398969,0.0,0,11.076097,13.115881,0.00031877658,9.5131378,11.07587,29.038174,-9.4881945
5.5,0.73680234,0.004630846,0.0,0,11.076097,16.415884,0.00033566981,9.3663664,11.076816,28.973112,-9.4866514
6.6,0.7264632,0.0048558097,0.0,0,11.076097,19.715883,0.0003146028,9.2325697,11.075975,28.974041,-9.4840136
7.7,0.7099461,0.00446023,0.0,0,11.076097,23.015886,0.00031453761,9.0239868,11.07603,28.929581,-9.481884
8.8,0.70508653,0.004795426,0.0,0,11.076097,26.315884,0.00030095701,8.9742489,11.076438,28.906811,-9.4800282
9.9,0.70273554,0.0048060701,0.0,0,11.076097,29.615885,0.00033778144,8.9460106,11.075643,28.910927,-9.4784679
11.0,0.70109499,0.005313701,22.368587,0,11.076097,32.915882,0.00032463888,8.9272575,11.075956,28.984659,-9.476676
12.1,0.70502239,0.0047432226,34.443054,0,11.076097,36.215881,0.00032157442,8.9648056,11.076367,29.564943,-9.4750719
13.2,0.70711535,0.0027816468,41.177032,0,11.076097,39.515877,0.00016898706,9.0045843,11.075802,31.326069,-9.4732828
14.3,0.7201947,-0.00041701537,45.60643,0,11.076097,42.81588,-3.2572352e-05,9.1733274,11.076845,34.224449,-9.4711504
15.4,0.7305485,-0.0040457719,48.719967,0,11.076097,46.115879,-0.0002882691,9.3152847,11.076715,37.995415,-9.4692612
16.5,0.74018472,-0.0074428874,50.042698,0,11.076097,49.415874,-0.00050009566,9.4345427,11.076315,42.660526,-9.4674902
17.6,0.74836838,-0.010614094,50.544888,0,11.076097,52.715881,-0.00072697666,9.5378246,11.076194,47.870716,-9.4652138
18.7,0.75417012,-0.014379615,50.307491,0,11.076097,56.015881,-0.00095663953,9.632287,11.075854,53.248859,-9.4634104
19.8,0.75610787,-0.017637309,49.23027,0,11.076097,59.315884,-0.0011791155,9.6335068,11.076057,58.504013,-9.4615688
20.9,0.76200533,-0.020790143,47.955482,0,11.076097,62.615887,-0.0013824238,9.721261,11.075508,63.453495,-9.4599371
22.0,0.766563,-0.02361284,46.118084,0,11.076097,65.915886,-0.0015633167,9.7905512,11.076292,67.969887,-9.4580946
23.1,0.76227874,-0.025546582,44.605541,0,11.076097,69.215874,-0.0016882124,9.7290249,11.076161,71.856186,-9.4562664
24.2,0.75874507,-0.02771295,43.527836,0,11.076097,72.515884,-0.0018254161,9.6844578,11.07623,75.043884,-9.4544153
25.3,0.74830383,-0.029497376,42.978519,0,11.076097,75.815872,-0.0019744579,9.5568743,11.075835,77.736656,-9.4519539
26.4,0.74571264,-0.031539179,42.978512,0,11.076097,79.115875,-0.0020716174,9.5130186,11.075323,80.253914,-9.4500551
27.5,0.74213147,-0.033506364,43.954792,0,11.076097,82.415886,-0.0022450234,9.4828606,11.076734,82.558823,-9.4482117
28.6,0.7468788,-0.035947714,45.120506,0,11.076097,85.715889,-0.002367906,9.5330296,11.076246,84.747017,-9.4460487
29.7,0.75684631,-0.03754732,46.581161,0,11.076097,89.0159,-0.0025132182,9.6541595,11.076141,87.252304,-9.4445009
30.8,0.75782013,-0.039643671,47.952305,0,11.076097,92.315887,-0.0026178195,9.6903019,11.076141,90.041183,-9.4422827
31.9,0.76235968,-0.041984193,48.812252,0,11.076097,95.615906,-0.0028218322,9.7289038,11.07591,93.1129,-9.4406433
33.0,0.77161551,-0.044677641,49.636227,0,11.076097,98.915901,-0.0029677309,9.857151,11.07676,96.538429,-9.4389315
34.1,0.77473444,-0.047608335,50.43539,0,11.076097,102.2159,-0.0031960576,9.8841553,11.076194,100.06566,-9.4370146
35.2,0.77452922,-0.05077751,50.822556,0,11.076097,105.5159,-0.0033788604,9.8866816,11.076902,103.75068,-9.4349079
36.3,0.78796166,-0.053606309,50.82275,0,11.076097,108.8159,-0.0035769204,10.066839,11.076919,107.58002,-9.4334126
37.4,0.78847975,-0.056520164,50.736641,0,11.076097,112.11591,-0.0037515354,10.075565,11.076509,111.40729,-9.431592
38.5,0.79847503,-0.05933249,50.590073,0,11.076097,115.4159,-0.0039564958,10.208172,11.076517,115.04661,-9.4298239
39.6,0.79791814,-0.062312461,50.135937,0,11.076097,118.71589,-0.0041372771,10.208147,11.075242,118.85147,-9.4279041
40.7,0.79559594,-0.064782716,50.042728,0,11.076097,122.01589,-0.0042985892,10.172639,11.075853,122.32761,-9.4261761
41.8,0.80860442,-0.06760776,49.640148,0,11.076097,125.31589,-0.0044873469,10.332737,11.076351,125.77569,-9.4243202
42.9,0.81257194,-0.071001098,49.783161,0,11.076097,128.61601,-0.0046921726,10.390494,11.076443,128.92282,-9.4222164
44.0,0.80377471,-0.073249698,50.042713,0,11.076097,131.91586,-0.0048851958,10.278206,11.075661,131.97701,-9.4200764
45.1,0.81495768,-0.075476237,50.292934,0,11.076097,135.21588,-0.0050070328,10.432993,11.076159,134.91559,-9.4182673
46.2,0.81809664,-0.077466629,50.6129,0,11.076097,138.51587,-0.0051734443,10.473014,11.076104,137.93654,-9.4164076
47.3,0.8123492,-0.080359168,51.158707,0,11.076097,141.81589,-0.0053302743,10.402677,11.076249,140.85841,-9.4142599
48.4,0.81742638,-0.082438916,51.705856,0,11.076097,145.11589,-0.0055053313,10.472938,11.075737,143.82277,-9.4124823
49.5,0.82343465,-0.085698925,52.277676,0,11.076097,148.41589,-0.0056988425,10.536127,11.076746,147.04396,-9.4106922
50.6,0.81735426,-0.088434227,52.635372,0,11.076097,151.71591,-0.0058903522,10.47179,11.076492,150.42633,-9.4090986
51.7,0.82955301,-0.091397434,52.915192,0,11.076097,155.0159,-0.0060624364,10.617453,11.076853,153.83017,-9.4072742
52.8,0.83396024,-0.094156981,52.97607,0,11.076097,158.3159,-0.00626043,10.692662,11.075626,157.34683,-9.4056892
53.9,0.83523834,-0.097216643,53.316631,0,11.076097,161.61589,-0.0064487499,10.71586,11.077124,160.75137,-9.4038916
55.0,0.83338404,-0.10032278,53.31665,0,11.076097,164.91589,-0.0066605373,10.674459,11.077081,164.27365,-9.402092
56.1,0.83526981,-0.10332441,53.315937,0,11.076097,168.2159,-0.00685242,10.706496,11.0762,167.89221,-9.39991
57.2,0.83967185,-0.10659136,53.10239,0,11.076097,171.5159,-0.0070620319,10.769436,11.076423,171.36914,-9.3981457
58.3,0.83917481,-0.10915175,52.976086,0,11.076097,174.8159,-0.0072551384,10.765513,11.075293,174.81667,-9.3961267
59.4,0.84115827,-0.11204164,53.114273,0,11.076097,178.11591,-0.007419473,10.804156,11.076315,178.03145,-9.3943634
60.5,0.83852607,-0.11440748,53.31665,0,11.076097,181.41589,-0.0076175248,10.757152,11.076234,181.12556,-9.3919764
61.6,0.84527284,-0.11755396,53.325504,0,11.076097,184.7159,-0.007792986,10.860489,11.075879,184.36992,-9.390276
62.7,0.83455449,-0.12026838,53.657223,0,11.076097,188.01588,-0.0080054896,10.723195,11.075894,187.62692,-9.3883924
63.8,0.83838618,-0.12304003,53.974564,0,11.076097,191.31587,-0.0081687365,10.75478,11.076038,190.73167,-9.3867464
64.9,0.84328687,-0.12593162,54.267651,0,11.076097,194.61589,-0.008366771,10.818207,11.076317,193.78374,-9.3848219
66.0,0.84685916,-0.12907872,54.614792,0,11.076097,197.91589,-0.0085581271,10.889875,11.076238,197.00066,-9.3833723
67.1,0.84350723,-0.1322615,54.921871,0,11.076097,201.2159,-0.0087741604,10.844875,11.075676,200.21391,-9.3815126
68.2,0.84382552,-0.13504882,54.931637,0,11.076097,204.51591,-0.0089499578,10.835069,11.076696,203.74666,-9.3795834
69.3,0.8472234,-0.13841195,54.931969,0,11.076097,207.8159,-0.0091644377,10.88267,11.076329,207.12744,-9.3777809
70.4,0.8441456,-0.14137876,55.079353,0,11.076097,211.11591,-0.0093844635,10.84435,11.076135,210.65721,-9.3760509
71.5,0.84254253,-0.14475623,55.239159,0,11.076097,214.41591,-0.0095777139,10.835016,11.076556,214.0338,-9.3737583
72.6,0.84238333,-0.14766218,55.117599,0,11.076097,217.71591,-0.0098225055,10.840263,11.076638,217.52061,-9.3717442
73.7,0.84526968,-0.15109436,55.239254,0,11.076097,221.0159,-0.010018773,10.86157,11.076654,220.68677,-9.3699656
74.8,0.84772497,-0.15438712,55.239254,0,11.076097,224.3159,-0.010250861,10.906615,11.076782,224.15579,-9.3684349
75.9,0.85361296,-0.15810749,55.239254,0,11.076097,227.61591,-0.010493673,10.985779,11.076571,227.42404,-9.3667402
77.0,0.85931265,-0.16020954,55.353722,0,11.076097,230.91591,-0.010648883,11.067192,11.075366,230.70119,-9.3650274
78.1,0.86012501,-0.16286959,55.48584,0,11.076097,234.2159,-0.01079502,11.072301,11.075687,234.00192,-9.3633909
79.2,0.85640395,-0.16585921,55.535885,0,11.076097,237.5159,-0.011000562,11.031791,11.076533,237.15508,-9.3614826
80.3,0.85379398,-0.16912967,55.661858,0,11.076097,240.81589,-0.011201946,10.989167,11.075993,240.439,-9.3595018
81.4,0.85390663,-0.17255974,55.843506,0,11.076097,244.11589,-0.011418964,10.99681,11.076474,243.72108,-9.3578358
82.5,0.85758072,-0.1756551,55.843506,0,11.076097,247.41589,-0.011641978,11.054146,11.076248,247.16646,-9.355443
83.6,0.85873032,-0.17897157,55.843506,0,11.076097,250.7159,-0.011831341,11.057592,11.076314,250.46371,-9.3536005
84.7,0.85249704,-0.18191072,55.931572,0,11.076097,254.01588,-0.012072676,10.992118,11.076035,253.65483,-9.3518724
85.8,0.85659343,-0.18516955,56.129147,0,11.076097,257.31613,-0.012260394,11.042467,11.075736,256.98508,-9.3500938
86.9,0.86647981,-0.18844979,56.129147,0,11.076097,260.61615,-0.012499934,11.166876,11.075942,260.34616,-9.348464
88.0,0.87187654,-0.19250923,56.129147,0,11.076097,263.91589,-0.012746371,11.238276,11.076723,263.55573,-9.3466797
89.1,0.86883026,-0.19566268,56.146404,0,11.076097,267.21588,-0.012973728,11.2088,11.076312,266.92694,-9.3447332
90.2,0.86422276,-0.19830357,56.321941,0,11.076097,270.5159,-0.013122152,11.152582,11.076281,270.24323,-9.3430529
91.3,0.87181282,-0.2007264,56.425777,0,11.076097,273.81589,-0.013280916,11.248797,11.076121,273.48883,-9.3414717
92.4,0.8692286,-0.20336063,56.521515,0,11.076097,277.11594,-0.013465668,11.224195,11.075918,276.70877,-9.3392487
93.5,0.86433357,-0.20661065,56.71133,0,11.076097,280.41592,-0.013660634,11.165403,11.075512,280.06747,-9.3375387
94.6,0.86349797,-0.20975311,56.711422,0,11.076097,283.71591,-0.013895403,11.148535,11.076262,283.29276,-9.3351994
95.7,0.86772454,-0.21348488,56.986019,0,11.076097,287.01593,-0.01411201,11.203112,11.076544,286.51715,-9.3336296
96.8,0.86129683,-0.21670577,56.986084,0,11.076097,290.31589,-0.014362686,11.13489,11.076134,289.85522,-9.3313723
97.9,0.86561531,-0.22046706,57.198578,0,11.076097,293.61591,-0.014593433,11.181293,11.075468,293.14124,-9.3297386
99.0,0.85865623,-0.22434354,57.260738,0,11.076097,296.91589,-0.014852341,11.108474,11.076165,296.50424,-9.3276129
100.1,0.86854595,-0.22757325,57.017132,0,11.076097,299.99539,-0.015046303,11.236748,11.075973,299.98523,-9.3259354
101.2,0.065902986,-0.24189675,54.961639,0,11.076097,299.99905,-0.015993603,0.85084182,11.07668,302.92673,-9.3260851
102.3,0.057615422,-0.24179316,52.668022,0,11.076097,299.99905,-0.015977288,0.75256693,11.076108,304.71613,-9.3265123
103.4,0.04695753,-0.24145819,50.824276,0,11.076097,299.99905,-0.015942873,0.60962534,11.075862,305.11694,-9.3262939
104.5,0.037632518,-0.24084722,49.740551,0,11.076097,299.99905,-0.015937129,0.5039615,11.07553,304.33792,-9.326086
105.6,0.034931839,-0.23990358,49.852123,0,11.076097,299.99905,-0.015857305,0.43642396,11.07573,302.71957,-9.3260212
106.7,0.032673221,-0.23861881,50.972599,0,11.076097,299.99905,-0.015809668,0.42707193,11.075595,300.64691,-9.3264761
107.8,0.030892871,-0.23765081,52.626587,0,11.076097,299.99905,-0.015715573,0.39686224,11.074896,298.40247,-9.3261805
108.9,0.029648915,-0.23707519,54.774693,0,11.076097,299.99905,-0.015699394,0.36761078,11.075856,296.34064,-9.3262272
110.0,0.029766146,-0.2368703,56.97113,0,11.076097,299.99905,-0.01566004,0.37496114,11.075498,294.57178,-9.3260937
111.1,0.029781694,-0.23709708,59.084183,0,11.076097,299.99905,-0.015682491,0.37528861,11.076035,293.39435,-9.3256493
112.2,0.034710471,-0.2374208,60.784294,0,11.076097,299.99905,-0.015693504,0.4394289,11.076392,292.66705,-9.3258638
113.3,0.035693098,-0.23781675,62.42564,0,11.076097,299.99905,-0.015707009,0.44999057,11.076097,292.30154,-9.3251104
114.4,0.045857467,-0.23771453,63.577656,0,11.076097,299.99905,-0.015728274,0.58745205,11.075639,292.65085,-9.3251657
115.5,0.070221066,-0.23880197,64.35788,0,11.076097,299.99905,-0.015764559,0.912494,11.07583,293.65964,-9.3249693
116.6,0.071198881,-0.24078348,64.555656,0,11.076097,299.99905,-0.015945172,0.90713876,11.076299,295.48453,-9.325326
117.7,0.071897849,-0.24308106,64.175835,0,11.076097,299.99905,-0.016080171,0.92941046,11.076341,297.83057,-9.3245935
118.8,0.074555971,-0.24525616,63.369576,0,11.076097,299.99905,-0.01623431,0.95603603,11.075901,300.5162,-9.3250618
119.9,0.07506001,-0.24695727,61.927448,0,11.076097,299.99905,-0.01632688,0.96514845,11.076713,302.93512,-9.3248568
121.0,0.079445735,-0.24836518,60.250069,0,11.076097,299.99905,-0.01642089,1.0281824,11.075633,305.06641,-9.3249168
122.1,0.080494575,-0.24941486,58.099709,0,11.076097,299.99905,-0.016481161,1.0527399,11.076821,306.68298,-9.3250885
123.2,0.08012107,-0.24977346,55.858929,0,11.076097,299.99905,-0.016489286,1.040871,11.075836,307.63693,-9.3249178
124.3,0.066568576,-0.2499629,53.674572,0,11.076097,299.99905,-0.01654434,0.868384,11.076566,307.84326,-9.3247824
125.4,0.05497903,-0.24989732,51.757561,0,11.076097,299.99905,-0.016503727,0.72035134,11.075686,307.29941,-9.3248262
126.5,0.046334185,-0.24947837,50.446304,0,11.076097,299.99905,-0.016519291,0.60824132,11.075682,305.97473,-9.3250847
127.6,0.040268887,-0.24918041,50.438236,0,11.076097,299.99905,-0.016479673,0.52937788,11.075766,303.95068,-9.3249512
128.7,0.035305843,-0.24763842,51.453602,0,11.076097,299.99905,-0.016379476,0.45519987,11.075336,301.57016,-9.3254433
129.8,0.026169667,-0.24705611,53.025833,0,11.076097,299.99905,-0.016329255,0.33949623,11.076239,299.01984,-9.3252115
130.9,0.022343576,-0.24642648,55.233093,0,11.076097,299.99905,-0.016283086,0.30020234,11.07665,296.61255,-9.3248329
132.0,0.020424968,-0.24613923,57.674931,0,11.076097,299.99905,-0.016271895,0.2684207,11.07685,294.37729,-9.324523
133.1,0.018607918,-0.24607159,59.959354,0,11.076097,299.99905,-0.016244518,0.24036944,11.075808,292.68533,-9.3242369
134.2,0.020969601,-0.24618253,62.20166,0,11.076097,299.99905,-0.016300149,0.29005936,11.076256,291.27139,-9.3240862
135.3,0.02531104,-0.24673629,64.055634,0,11.076097,299.99905,-0.016311964,0.3370536,11.076114,290.66263,-9.3248434
136.4,0.021920649,-0.24621776,65.640923,0,11.076097,299.99905,-0.016303487,0.28931037,11.076822,290.47058,-9.3241014
137.5,0.041532319,-0.2463171,66.824608,0,11.076097,299.99905,-0.016279306,0.54781556,11.076499,291.07709,-9.3241806
138.6,0.061078042,-0.24858552,67.390045,0,11.076097,299.99905,-0.01644084,0.79409117,11.076113,292.98587,-9.323555
139.7,0.076898463,-0.25187835,66.979416,0,11.076097,299.99905,-0.016652774,1.0208491,11.075568,296.37354,-9.323576
140.8,0.088156462,-0.25623444,65.800941,0,11.076097,299.99905,-0.016928241,1.1472138,11.076446,300.50021,-9.3233738
141.9,0.089729205,-0.25871277,63.861401,0,11.076097,299.99905,-0.017115287,1.1721606,11.076376,304.51959,-9.324008
143.0,0.078100771,-0.26052597,61.26865,0,11.076097,299.99905,-0.017210837,1.0233476,11.076076,308.01471,-9.3240366
144.1,0.073263273,-0.26142427,58.066444,0,11.076097,299.99905,-0.017294781,0.95695895,11.076153,310.61588,-9.3240519
145.1316,0.072765604,-0.023882965,54.669613,0,11.076097,299.99905,-0.0015806997,0.90961558,11.075537,311.86459,-9.3238649
145.2835,0.15311362,0.018265788,25.102489,0,11.076099,6.0864735e-10,0.0012896162,2.0081313,11.079184,312.00534,-9.3232498
145.2857,0.14299136,0.020809682,13.251508,0,11.076099,6.0790445e-25,0.0012834428,1.7298137,11.076998,312.02548,-9.3240156
145.2879,0.15448418,0.016287148,1.4005291,0,11.076099,6.0716300999999994e-40,0.0011863844,2.0116384,11.077178,312.04562,-9.324049
145.2901,0.16318686,0.02382612,0.0,0,11.076099,0.0,0.0014405355,2.0610318,11.075944,312.048,-9.3254461
145.2923,0.15758918,0.019246023,0.0,0,11.076099,0.0,0.0013720531,1.9431142,11.075783,312.048,-9.3237143
145.2945,0.14981404,0.02020097,0.0,0,11.076099,0.0,0.0012658281,1.9312271,11.077686,312.048,-9.3233242
145.2967,0.13980556,0.016331386,0.0,0,11.076099,0.0,0.0011314785,1.7688105,11.074316,312.048,-9.3232393
145.2989,0.14267883,0.021920422,0.0,0,11.076099,0.0,0.0013651183,1.917292,11.076697,312.04581,-9.324317
145.3011,0.14494169,0.017574035,0.0,0,11.076099,0.0,0.001311115,1.8009487,11.075488,312.03909,-9.323555
145.3033,0.15256919,0.02074286,0.0,0,11.076099,0.0,0.0013485682,1.9290043,11.074958,312.03238,-9.3229017
145.3055,0.16916853,0.01691686,0.0,0,11.076099,0.0,0.0011338583,2.0138664,11.074369,312.02567,-9.322917
145.3077,0.16265538,0.022567518,0.0,0,11.076099,0.0,0.0014602124,2.1483076,11.076246,312.01895,-9.3229446
145.3099,0.16631733,0.018181903,0.0,0,11.076099,0.0,0.001258282,2.115936,11.074353,312.00705,-9.3240471
145.3121,0.16124138,0.021436488,0.0,0,11.076099,0.0,0.0013755412,2.0898027,11.075788,311.99362,-9.3233385
145.3143,0.15508056,0.018916277,0.0,0,11.076099,0.0,0.001307202,2.0073612,11.074582,311.98019,-9.3229589
145.3165,0.16125847,0.023795906,0.0,0,11.076099,0.0,0.0015347409,1.9768784,11.078477,311.96677,-9.3226299
145.3187,0.16312627,0.019456489,0.0,0,11.076099,0.0,0.001285988,2.0962858,11.075491,311.95773,-9.3228226
145.3209,0.15104133,0.019736126,0.0,0,11.076099,0.0,0.0013335512,1.9871216,11.0766,311.96445,-9.3232346
145.3231,0.17650716,0.019311858,0.0,0,11.076099,0.0,0.0012503813,2.2098105,11.072724,311.97116,-9.3228483
145.3253,0.17642938,0.022657692,0.0,0,11.076099,0.0,0.0015223839,2.342217,11.075047,311.97787,-9.3234682
145.3275,0.17899476,0.019600138,0.0,0,11.076099,0.0,0.0011949947,2.2567327,11.076493,311.98459,-9.3241148
145.3297,0.17443125,0.020663802,0.0,0,11.076099,0.0,0.0014680277,2.2460113,11.075635,312.01358,-9.323575
145.3319,0.17085947,0.019647956,0.0,0,11.063763,0.0,0.0012323861,2.2232988,11.076875,312.05386,-9.3236589
145.3341,0.16137032,0.02213027,0.0,0,10.735819,0.0,0.0015346342,1.9866343,11.077259,312.09418,-9.3236275
145.3363,0.17529961,0.021477964,0.0,0,10.404926,0.0,0.0012973805,2.1892295,11.071395,312.13446,-9.3228083
145.3385,0.19605979,0.021058636,0.0,0,10.074035,0.0,0.0014795362,2.4589756,11.012101,312.33563,-9.3221416
145.3407,0.18522121,0.021149009,0.0,0,9.7431412,0.0,0.0013289101,2.2752938,10.826535,313.85071,-9.3229618
145.3429,0.20805262,0.022476356,0.0,0,9.4141388,0.0,0.0016108281,2.7441056,10.518788,315.36575,-9.3227863
145.3451,0.17903022,0.021638738,0.0,0,9.0922337,0.0,0.0012699509,2.3531768,10.132268,316.88083,-9.3235855
145.3473,7.0734463,0.34742609,0.0,0,8.7703295,0.0,0.02300014,87.695107,9.744319,318.39587,-9.3180571
145.3495,9.2619295,0.67718643,0.0,0,8.4631929,0.0,0.045881379,112.02937,9.3339376,320.15952,-9.3170404
145.3517,9.905365,1.0577106,0.0,0,8.1570406,0.0,0.073018804,116.84392,8.9263115,322.1228,-9.3163338
145.3539,10.292136,1.4203268,0.0,0,7.860775,0.0,0.098840475,118.79254,8.5752439,324.08612,-9.3154898
145.3561,10.757193,1.7096245,0.0,0,7.5694952,0.0,0.12068662,121.1489,8.25278,326.04941,-9.3155174
145.3583,11.048606,2.0202518,0.0,0,7.2838035,0.0,0.14400601,121.94984,7.9302726,328.0127,-9.3156452
145.3605,11.262254,2.3220382,0.0,0,7.0067787,0.0,0.16797636,121.11473,7.6364508,328.58145,-9.3144007
145.3627,11.660517,2.5880349,0.0,0,6.7313666,0.0,0.18858768,122.9435,7.3611298,329.15021,-9.3160486
145.3649,11.866199,2.8485351,0.0,0,6.467802,0.0,0.21037111,122.39137,7.0870609,329.71899,-9.3155842
145.3671,12.130629,3.1119978,0.0,0,6.2042418,0.0,0.23197849,122.47265,6.8227472,330.28775,-9.3148041
145.3693,12.446588,3.3745747,0.0,0,5.9515953,0.0,0.25480112,122.82401,6.5572343,329.89609,-9.3157158
145.3715,12.712467,3.6386743,0.0,0,5.7009273,0.0,0.27703065,122.6823,6.2893562,328.30878,-9.3155441
145.3737,13.01235,3.8954434,0.0,0,5.457253,0.0,0.30067065,122.57539,6.0283513,326.72147,-9.3165197
145.3759,13.320472,4.1544309,0.0,0,5.2187734,0.0,0.32348779,122.7011,5.768878,325.13419,-9.3157988
145.3781,13.62495,4.4065437,0.0,0,4.9838037,0.0,0.34784585,122.46519,5.509316,323.54688,-9.3162813
145.3803,13.934011,4.6623287,0.0,0,4.7569838,0.0,0.3713682,122.33374,5.2606521,321.1882,-9.3164272
145.3825,14.247169,4.9009647,0.0,0,4.5305758,0.0,0.39563468,122.15106,5.0138421,318.73511,-9.3162289
145.3847,14.563496,5.1402035,0.0,0,4.3147016,0.0,0.41876391,121.97079,4.7753077,316.28198,-9.3155851
145.3869,14.877339,5.3725958,0.0,0,4.0989256,0.0,0.44357678,121.5697,4.5387359,313.82886,-9.3155279
145.3891,15.209,5.604187,0.0,0,3.8911293,0.0,0.46682423,121.44041,4.3129764,312.09927,-9.315382
145.3913,15.565201,5.8130183,0.0,0,3.6859133,0.0,0.49037868,121.28343,4.0973606,311.79712,-9.3149347
145.3935,15.942915,6.0263019,0.0,0,3.4855206,0.0,0.51287228,121.47105,3.8851831,311.49496,-9.3159142
145.3957,16.344286,6.2314095,0.0,0,3.2902927,0.0,0.5371058,121.52493,3.6785431,311.19284,-9.3151846
145.3979,16.775103,6.4443979,0.0,0,3.0970623,0.0,0.56022024,121.88903,3.4734719,310.89069,-9.3154612
145.4001,17.229887,6.6339774,0.0,0,2.9113381,0.0,0.58416462,122.29017,3.2720096,310.39426,-9.3140078
145.4023,17.704685,6.8382421,0.0,0,2.7256143,0.0,0.60757065,122.66817,3.0730295,309.84357,-9.3130627
145.4045,18.187733,7.0296378,0.0,0,2.5483871,0.0,0.63258517,122.96915,2.8816509,309.29291,-9.3144464
145.4067,18.689507,7.2289419,0.0,0,2.3717272,0.0,0.65635455,123.36538,2.6858547,308.74222,-9.3141346
145.4089,19.221134,7.4056206,0.0,0,2.2008002,0.0,0.68094414,123.76872,2.502141,308.09543,-9.3141737
145.4111,19.779345,7.5916219,0.0,0,2.0327642,0.0,0.70439738,124.40973,2.3260887,307.12186,-9.3141031
145.4133,20.390266,7.7609963,0.0,0,1.8679363,0.0,0.72896791,125.10247,2.1453667,306.14828,-9.3130951
145.4155,21.014761,7.9380231,0.0,0,1.7080842,0.0,0.75192398,126.05243,1.9826285,305.17471,-9.3128195
145.4177,21.661543,8.0931292,0.0,0,1.5491643,0.0,0.7760337,126.83025,1.8173416,304.20114,-9.3131552
145.4199,22.361877,8.2620344,0.0,0,1.3970972,0.0,0.79911858,127.96227,1.6517516,303.26117,-9.3125744
145.4221,23.084137,8.4155693,0.0,0,1.2450333,0.0,0.82379848,128.86047,1.4912637,302.33755,-9.3118324
145.4243,23.817261,8.5774965,0.0,0,1.0992643,0.0,0.84667486,130.00577,1.3402641,301.41397,-9.3122282
145.4265,24.59841,8.7155457,0.0,0,0.95463622,0.0,0.87052763,131.10292,1.190075,300.49036,-9.312583
145.4287,25.429262,8.8651495,0.0,0,0.8140732,0.0,0.89294654,132.4577,1.0416036,299.46555,-9.3110781
145.4309,26.283585,8.9978991,0.0,0,0.67652929,0.0,0.9164989,133.72279,0.89786422,297.68567,-9.3101959
145.4331,27.167038,9.139699,0.0,0,0.54098582,0.0,0.93827593,135.24716,0.7624867,295.90576,-9.310113
145.4353,28.085049,9.2543964,0.0,0,0.4100858,0.0,0.9601593,136.77795,0.63295686,294.12589,-9.3098068
145.4375,28.769299,9.385829,0.0,0,0.27942529,0.0,0.98173362,137.49857,0.50433016,292.34598,-9.3085947
145.4397,26.761087,9.4058857,0.0,0,0.15489206,0.0,0.98696625,127.02029,0.43902367,292.61978,-9.3104
145.4419,25.371016,9.4219398,0.0,0,0.030416043,0.0,0.98810565,120.30584,0.40562204,294.48349,-9.3118649
145.4441,24.890667,9.4162827,0.0,0,-0.091732524,0.0,0.98894715,117.9178,0.37292212,296.3472,-9.3133802
145.4463,24.789591,9.4311943,0.0,0,-0.21312852,0.0,0.99012798,117.27408,0.32740676,298.21091,-9.3142014
145.4485,24.855244,9.4290476,0.0,0,-0.33452454,0.0,0.99126017,117.45015,0.26872006,300.09332,-9.314537
145.4507,24.850763,9.4444342,0.0,0,-0.45592052,0.0,0.99245042,117.27285,0.21391664,304.01355,-9.3133869
145.4529,24.780981,9.4384232,0.0,0,-0.57731652,0.0,0.99269128,116.95558,0.15750323,307.93381,-9.3152056
145.4551,24.645596,9.4503984,0.0,0,-0.69871247,0.0,0.99391949,116.17816,0.10235132,311.85403,-9.3142691
145.4573,24.47559,9.4499121,0.0,0,-0.82010847,0.0,0.99482715,115.22766,0.061309367,315.77426,-9.3147287
145.4595,24.192984,9.4633875,0.0,0,-0.94150448,0.0,0.99591899,113.83891,0.031758342,318.6438,-9.315527
145.4617,23.857948,9.4570417,0.0,0,-1.0629005,0.0,0.99604511,112.25918,0.0075334478,320.25247,-9.3151598
145.4639,23.427315,9.4624577,0.0,0,-0.84332824,300.0,0.99609929,110.19042,-0.0035053664,321.86115,-9.3161888
145.4661,22.915583,9.4593115,0.0,0,-0.42304912,300.0,0.99647057,107.74257,-0.003906827,323.46985,-9.3154879
145.4683,22.401409,9.4705582,0.0,0,-0.0027696523,300.0,0.99719185,105.2802,0.0018125746,325.07852,-9.3157663
145.4705,21.990877,9.4591446,0.0,0,0.4175092,300.0,0.99634886,103.39262,0.0072684893,326.10056,-9.3173113
145.4727,21.679249,9.4642239,0.0,0,0.83778834,300.0,0.99643952,101.92377,0.0085975043,327.0574,-9.3171597
145.4749,21.426931,9.4601688,0.0,0,1.2580682,300.0,0.99636465,100.76485,0.0098869773,328.01428,-9.3175335
145.4771,20.633928,9.4679508,0.0,0,1.6783469,300.0,0.99714655,97.024529,0.029943887,328.97113,-9.3164511
145.4793,18.678301,9.4540586,0.0,0,2.0986257,300.0,0.99529165,88.147804,0.10885156,329.96942,-9.3189631
145.4815,15.248441,9.4488516,0.0,0,2.5189054,300.0,0.99389565,72.246368,0.25623569,331.04623,-9.3224487
145.4837,8.6091528,9.414588,0.0,0,2.9391847,300.0,0.98841655,42.07159,0.49179626,332.12305,-9.3266888
145.4859,0.3799414,9.2190075,0.0,0,3.3594637,300.0,0.95346284,2.0672781,0.90857911,333.19986,-9.3357201
145.4881,-0.29705468,9.0516768,0.0,0,3.7797427,300.0,0.92509788,-1.4229146,1.5953716,334.27667,-9.3363647
145.4903,-0.1005607,8.898241,0.0,0,4.2000222,300.0,0.90002012,-0.57226229,2.3530416,334.5177,-9.3362656
145.4925,-0.048323818,8.7572737,0.0,0,4.6203012,300.0,0.87686598,-0.16694529,3.0218904,334.53778,-9.3357487
145.4947,0.097741552,8.6713552,0.0,0,5.0405807,300.0,0.86328292,0.44709811,3.5384898,334.55786,-9.3344202
145.4969,-0.099268615,8.5895147,0.0,0,5.4608598,300.0,0.85027027,-0.47343168,3.9303148,334.57794,-9.3322411
145.4991,-0.13822091,8.550806,0.0,0,5.8811393,300.0,0.84427452,-0.7764951,4.3135242,334.50955,-9.3315706
145.5013,-0.011422937,8.5273848,0.0,0,6.3014183,300.0,0.84053314,-0.14231333,4.6837997,334.1554,-9.330719
145.5035,0.016021637,8.545764,0.0,0,6.7216969,300.0,0.84349263,0.024236243,5.0663648,333.80127,-9.3286753
145.5057,-0.0078666192,8.5641117,0.0,0,7.1419768,300.0,0.84604311,-0.1057978,5.4711061,333.44711,-9.3298712
145.5079,-0.025471574,8.6074562,0.0,0,7.5622559,300.0,0.85298675,-0.12162872,5.8971348,333.09296,-9.3280087
145.5101,-0.054897096,8.6593657,0.0,0,7.9825354,300.0,0.86048347,-0.31164822,6.3397207,333.46759,-9.3274269
145.5123,0.012979011,8.7327528,0.0,0,8.4028139,300.0,0.87285095,0.016909234,6.7904048,334.18231,-9.3279638
145.5145,0.065864779,8.8189478,0.0,0,8.8230925,300.0,0.88586318,0.31186363,7.2462411,334.89706,-9.3253412
145.5167,0.040622149,8.9138432,0.0,0,9.243372,300.0,0.90200406,0.3005861,7.6745658,335.61179,-9.3243055
145.5189,-0.17901585,9.0271082,0.0,0,9.6636515,300.0,0.92004907,-0.85068589,8.1058941,336.30695,-9.3246698
145.5211,-0.054945096,9.1505127,0.0,0,10.083931,300.0,0.94192344,-0.4111523,8.5370445,336.86789,-9.3256111
145.5233,0.14728412,9.2740269,0.0,0,10.50421,300.0,0.96193516,0.69317871,8.9644451,337.42886,-9.3256369
145.5255,-0.028253535,9.4219198,0.0,0,10.924489,300.0,0.98925215,-0.097363457,9.4037743,337.98984,-9.3255949
145.5277,0.018387882,9.3854227,0.0,0,11.344769,300.0,0.98248953,0.055146359,9.8357954,338.55081,-9.325573
145.5299,-0.050138298,9.3666048,0.0,0,11.765047,300.0,0.98037714,-0.38901851,10.267116,338.53445,-9.3246584
145.5321,0.10308845,9.3862543,0.0,0,12.185327,300.0,0.98184878,0.52765614,10.709065,338.08737,-9.324852
145.5343,0.071710505,9.4086056,0.0,0,12.605606,300.0,0.98721927,0.32361442,11.138107,337.64029,-9.3248978
145.5365,-0.10343933,9.4229517,0.0,0,13.025885,300.0,0.98868257,-0.40928048,11.563139,337.19321,-9.3243084
145.5387,-0.13267073,9.4242401,0.0,0,13.446164,300.0,0.99058729,-0.68598092,11.981688,336.73773,-9.3237562
145.5409,0.050487857,9.4220924,0.0,0,13.866444,300.0,0.98864526,0.18671964,12.391232,335.82883,-9.323041
145.5431,0.024331268,9.4213266,0.0,0,14.286723,300.0,0.98991048,0.074516177,12.81877,334.91992,-9.3224983
145.5453,0.003922089,9.4261007,0.0,0,14.707002,300.0,0.98910987,0.070137344,13.241811,334.01099,-9.3221912
145.5475,-0.1362624,9.4231768,0.0,0,15.127281,300.0,0.99037802,-0.61364317,13.68132,333.10208,-9.3230247
145.5497,-0.0030869569,9.4273252,0.0,0,15.547561,300.0,0.98922002,-0.098343141,14.125018,332.49356,-9.3236771
145.5519,0.05084556,9.4187698,0.0,0,15.967839,300.0,0.98951495,0.30590332,14.569113,332.2326,-9.3228617
145.5541,-0.0465228,9.4218273,0.0,0,16.388119,300.0,0.9882223,-0.11510415,15.005173,331.97165,-9.3235874
145.5563,-0.12906387,9.4186373,0.0,0,16.808399,300.0,0.98982877,-0.58913952,15.424454,331.71069,-9.3220339
145.5585,-0.038977094,9.4260855,0.0,0,17.228678,300.0,0.98868811,-0.23567969,15.838714,331.44974,-9.3227825
145.5607,0.0077020572,9.4162683,0.0,0,17.648958,300.0,0.98922777,0.0055609643,16.257996,331.97333,-9.3232708
145.5629,0.061009694,9.4235449,0.0,0,17.999975,300.0,0.98864943,0.30245095,16.669092,332.57535,-9.3222055
145.5651,-0.080858685,9.4164305,0.0,0,18.0,300.0,0.98945415,-0.31353188,17.079939,333.17737,-9.32199
145.5673,-0.06863185,9.4236689,0.0,0,18.0,300.0,0.98830897,-0.39197984,17.47209,333.77939,-9.3227015
145.5695,0.033980984,9.414916,0.0,0,18.0,300.0,0.9890821,0.15310679,17.833439,334.21777,-9.3223238
145.5717,-0.080605336,9.4247341,0.0,0,18.0,300.0,0.98871005,-0.35042793,18.136967,334.35831,-9.3230085
145.5739,-0.026371812,9.4242048,0.0,0,18.0,300.0,0.99093288,-0.14505999,18.366909,334.49881,-9.3262653
145.5761,-0.020578135,9.4336395,0.0,0,18.0,300.0,0.99003863,-0.091742069,18.495234,334.63934,-9.3300142
145.5783,-0.040752951,9.4295073,0.0,0,18.0,300.0,0.99176276,-0.18731254,18.514353,334.77985,-9.3352394
145.5805,-0.029954035,9.4421597,0.0,0,18.0,300.0,0.99193853,-0.16162106,18.436287,335.89142,-9.3423166
145.5827,0.04367929,9.4449682,0.0,0,18.0,300.0,0.9946503,0.14910509,18.312996,337.24576,-9.3504686
145.5849,0.096742034,9.4649773,0.0,0,18.0,300.0,0.99545336,0.451208,18.191534,338.6001,-9.3628378
145.5871,0.042998247,9.4709997,0.0,0,18.0,300.0,0.9990564,0.30487925,18.097486,339.95441,-9.3762321
145.5893,-0.05827342,9.491209,0.0,0,18.0,300.0,1.0007762,-0.20007245,18.040482,341.27609,-9.3904047
145.5915,-0.083638407,9.5044909,0.0,0,18.0,300.0,1.0053043,-0.3457303,18.031826,342.49744,-9.4094925
145.5937,-0.13134851,9.5363579,0.0,0,18.0,300.0,1.008375,-0.60689896,18.039526,343.71875,-9.4271832
145.5959,-0.1425776,9.5440464,0.0,0,18.0,300.0,1.0123334,-0.66673183,18.060556,344.94009,-9.446003
145.5981,-0.039710227,9.5622396,0.0,0,18.0,300.0,1.0138464,-0.23309168,18.085873,346.16141,-9.4654312
145.6003,0.052351832,9.5698309,0.0,0,18.0,300.0,1.0174215,0.1987052,18.115093,346.5343,-9.482481
145.6025,0.063369639,9.5996056,0.0,0,18.0,300.0,1.0203698,0.2549932,18.13126,346.52765,-9.4990702
145.6047,0.066723868,9.6063328,0.0,0,18.0,300.0,1.0237865,0.30606991,18.14592,346.52097,-9.5149755
145.6069,0.019702632,9.6284275,0.0,0,18.0,300.0,1.0258801,0.15864737,18.149244,346.51431,-9.529479
145.6091,-0.069000632,9.6377316,0.0,0,18.0,300.0,1.0297428,-0.23652939,18.151636,346.36752,-9.5452881
145.6113,-0.13663495,9.6654005,0.0,0,18.0,300.0,1.0324469,-0.60986429,18.151428,345.33344,-9.5630341
145.6135,-0.13875253,9.670886,0.0,0,18.0,300.0,1.0358312,-0.63960344,18.145964,344.29935,-9.5790367
145.6157,-0.048150789,9.6922569,0.0,0,18.0,300.0,1.0379753,-0.28206855,18.142689,343.26523,-9.5925064
145.6179,0.043039612,9.6992502,0.0,0,18.0,300.0,1.0412823,0.13022278,18.141113,342.23114,-9.6082621
145.6201,0.0695711,9.7245026,0.0,0,18.0,300.0,1.0437363,0.31227794,18.136312,341.68225,-9.6233406
145.6223,0.070226304,9.7279739,0.0,0,18.0,300.0,1.0463395,0.3294954,18.133408,341.48212,-9.6397505
145.6245,0.057250232,9.7494049,0.0,0,18.0,300.0,1.0488327,0.30177131,18.128784,341.28195,-9.6557827
145.6267,-0.034395531,9.7635565,0.0,0,18.0,300.0,1.0530477,-0.082023062,18.126944,341.08182,-9.6712742
145.6289,-0.12258822,9.7911568,0.0,0,18.0,300.0,1.0567496,-0.49160248,18.126324,340.89713,-9.6856527
145.6311,-0.14592646,9.7957716,0.0,0,18.0,300.0,1.0591358,-0.68997657,18.124201,341.26407,-9.7024727
145.6333,-0.078284495,9.8151207,0.0,0,18.0,300.0,1.0617034,-0.40510958,18.115849,341.63101,-9.7191477
145.6355,0.0029093446,9.8230047,0.0,0,18.0,300.0,1.064476,-0.022655074,18.117769,341.99792,-9.7338943
145.6377,0.072168574,9.8505859,0.0,0,18.0,300.0,1.0683076,0.28661171,18.117201,342.36487,-9.7492371
145.6399,0.081267819,9.8556595,0.0,0,18.0,300.0,1.0707741,0.33458865,18.112116,342.23981,-9.7645836
145.6421,0.054788776,9.8772926,0.0,0,18.0,300.0,1.0736248,0.25808737,18.113689,341.56598,-9.7805099
145.6443,0.0030496162,9.8876915,0.0,0,18.0,300.0,1.0767418,0.030569274,18.112734,340.89215,-9.7964659
145.6465,-0.092960134,9.9137926,0.0,0,18.0,300.0,1.0807669,-0.35729751,18.108137,340.21832,-9.8128929
145.6487,-0.14698745,9.9214449,0.0,0,18.0,300.0,1.0834849,-0.61366761,18.109041,339.54453,-9.8286352
145.6509,-0.10777394,9.9418106,0.0,0,18.0,300.0,1.0867416,-0.50105715,18.109159,339.84467,-9.8451643
145.6531,-0.017725203,9.9527092,0.0,0,18.0,300.0,1.0895157,-0.14500524,18.107634,340.23163,-9.861146
145.6553,0.061318643,9.9767208,0.0,0,18.0,300.0,1.0935338,0.22449058,18.104393,340.61859,-9.8766451
145.6575,0.077524714,9.9820852,0.0,0,18.0,300.0,1.0953058,0.34141782,18.103199,341.00552,-9.892868
145.6597,0.06902992,10.001857,0.0,0,18.0,300.0,1.09879,0.29840156,18.105953,341.51379,-9.9083672
145.6619,0.019916469,10.016707,0.0,0,18.0,300.0,1.102002,0.13963918,18.1014,342.23431,-9.9234648
145.6641,-0.05041638,10.038831,0.0,0,18.0,300.0,1.1061485,-0.16158572,18.103779,342.95483,-9.9408979
145.6663,-0.13461566,10.050467,0.0,0,18.0,300.0,1.1088033,-0.52849758,18.102861,343.67535,-9.9573126
145.6685,-0.1495399,10.066812,0.0,0,18.0,300.0,1.1123191,-0.66789925,18.106873,344.3959,-9.9735746
145.6707,-0.050635461,10.079456,0.0,0,18.0,300.0,1.1145955,-0.26490909,18.101862,344.90591,-9.9887209
145.6729,0.034508578,10.10183,0.0,0,18.0,300.0,1.1191519,0.11647111,18.096907,345.36624,-10.002601
145.6751,0.091257699,10.109844,0.0,0,18.0,300.0,1.120441,0.31795624,18.097656,345.82657,-10.018678
145.6773,0.082024232,10.125589,0.0,0,18.0,300.0,1.1243243,0.37947646,18.095982,346.2869,-10.033714
145.6795,0.040243361,10.13838,0.0,0,18.0,300.0,1.1263394,0.21590322,18.093454,346.65555,-10.04878
145.6817,-0.034976903,10.162593,0.0,0,18.0,300.0,1.1318488,-0.06797222,18.094469,346.75562,-10.065829
145.6839,-0.12097073,10.179198,0.0,0,18.0,300.0,1.1346295,-0.42688388,18.093813,346.85568,-10.082748
145.6861,-0.16123363,10.194933,0.0,0,18.0,300.0,1.1387146,-0.62085545,18.093302,346.95575,-10.098887
145.6883,-0.10240898,10.204741,0.0,0,18.0,300.0,1.1398729,-0.46498868,18.093042,347.05582,-10.115739
145.6905,0.02129606,10.224158,0.0,0,18.0,300.0,1.1451137,-0.0084332973,18.092421,347.16525,-10.13084
145.6927,0.085610203,10.239119,0.0,0,18.0,300.0,1.1469223,0.3262178,18.0916,347.27866,-10.147446
145.6949,0.085889392,10.254615,0.0,0,18.0,300.0,1.1513363,0.37566632,18.090372,347.39209,-10.162203
145.6971,0.057369698,10.269336,0.0,0,18.0,300.0,1.1533117,0.25851098,18.088715,347.50549,-10.17761
145.6993,-0.0073706685,10.289901,0.0,0,18.0,300.0,1.1591266,0.028171374,18.091238,347.59174,-10.193155
145.7015,-0.090866208,10.305274,0.0,0,18.0,300.0,1.1605563,-0.30128267,18.090784,347.51837,-10.208842
145.7037,-0.13928162,10.321035,0.0,0,18.0,300.0,1.165565,-0.5188936,18.08884,347.44498,-10.224305
145.7059,-0.1128608,10.335322,0.0,0,18.0,300.0,1.1669351,-0.49071455,18.086243,347.37158,-10.24161
145.7081,-0.021008624,10.349298,0.0,0,18.0,300.0,1.1719568,-0.1553358,18.088633,347.29822,-10.258539
145.7103,0.069230728,10.366716,0.0,0,18.0,300.0,1.1737636,0.20675881,18.085533,347.23663,-10.27286
145.7125,0.10596704,10.377918,0.0,0,18.0,300.0,1.1781359,0.36411062,18.08391,347.18326,-10.28905
145.7147,0.077269845,10.396711,0.0,0,18.0,300.0,1.1801927,0.31683481,18.081013,347.12988,-10.30452
145.7169,0.015495813,10.41205,0.0,0,18.0,300.0,1.1856582,0.11442424,18.083048,347.07651,-10.319448
145.7191,-0.069823451,10.433696,0.0,0,18.0,300.0,1.1879538,-0.21814722,18.084717,347.02606,-10.335913
145.7213,-0.13638915,10.443846,0.0,0,18.0,300.0,1.1926184,-0.5003323,18.082458,347.05273,-10.353133
145.7235,-0.13584663,10.461056,0.0,0,18.0,300.0,1.1941444,-0.55329764,18.085409,347.07944,-10.369818
145.7257,-0.066423662,10.475924,0.0,0,18.0,300.0,1.1999296,-0.31777573,18.08021,347.10611,-10.383805
145.7279,0.048399251,10.494637,0.0,0,18.0,300.0,1.2014821,0.12098159,18.082754,347.13281,-10.399106
145.7301,0.11066687,10.502259,0.0,0,18.0,300.0,1.2057078,0.38320488,18.078894,347.15948,-10.41473
145.7323,0.095443383,10.521365,0.0,0,18.0,300.0,1.2074215,0.37327841,18.079451,347.18619,-10.431965
145.7345,0.028710878,10.535045,0.0,0,18.0,300.0,1.2130563,0.15958218,18.08005,347.21286,-10.447951
145.7367,-0.039016839,10.560404,0.0,0,18.0,300.0,1.2160137,-0.087985665,18.082233,347.23956,-10.463512
145.7389,-0.11060029,10.569798,0.0,0,18.0,300.0,1.2210324,-0.38438603,18.078228,347.26624,-10.479651
145.7411,-0.14353642,10.589069,0.0,0,18.0,300.0,1.2227386,-0.52055544,18.078173,347.3548,-10.495752
145.7433,-0.096019886,10.60237,0.0,0,18.0,300.0,1.2282811,-0.39998427,18.079912,347.44818,-10.511998
145.7455,0.0081225783,10.622755,0.0,0,18.0,300.0,1.2302223,-0.053243,18.078091,347.5416,-10.527229
145.7477,0.083521672,10.628909,0.0,0,18.0,300.0,1.2345392,0.24885914,18.073771,347.63498,-10.543054
145.7499,0.097985126,10.647187,0.0,0,18.0,300.0,1.2359031,0.40213668,18.073606,347.69357,-10.55828
145.7521,0.06234926,10.661547,0.0,0,18.0,300.0,1.2421583,0.26824996,18.076702,347.69357,-10.573128
145.7543,-0.037225928,10.686922,0.0,0,18.0,300.0,1.2445108,-0.071903914,18.073997,347.69357,-10.587794
145.7565,-0.10566584,10.695262,0.0,0,18.0,300.0,1.2497185,-0.3423776,18.073797,347.69357,-10.603961
145.7587,-0.13479167,10.716999,0.0,0,18.0,300.0,1.2520224,-0.45803621,18.074587,347.69357,-10.620187
145.7609,-0.11483488,10.726581,0.0,0,18.0,300.0,1.257172,-0.45512077,18.074347,347.63898,-10.637955
145.7631,-0.01807636,10.751056,0.0,0,18.0,300.0,1.2594364,-0.159811,18.070538,347.57227,-10.653872
145.7653,0.06147423,10.754814,0.0,0,18.0,300.0,1.2637031,0.1765618,18.071266,347.50555,-10.67096
145.7675,0.10591009,10.775988,0.0,0,18.0,300.0,1.2660265,0.36458775,18.069065,347.43884,-10.684471
145.7697,0.090586789,10.787144,0.0,0,18.0,300.0,1.2715818,0.34863409,18.071352,347.39148,-10.701293
145.7719,0.013272217,10.814232,0.0,0,18.0,300.0,1.2743715,0.10035244,18.068161,347.39813,-10.716205
145.7741,-0.091207109,10.818483,0.0,0,18.0,300.0,1.278639,-0.23665377,18.070002,347.40482,-10.732381
145.7763,-0.14729212,10.840906,0.0,0,18.0,300.0,1.2815078,-0.46959683,18.06875,347.4115,-10.75045
145.7785,-0.1274242,10.849259,0.0,0,18.0,300.0,1.2865859,-0.4731507,18.064821,347.41815,-10.765943
145.7807,-0.051178437,10.87882,0.0,0,18.0,300.0,1.2901295,-0.22543114,18.069483,347.4816,-10.78085
145.7829,0.041136242,10.882195,0.0,0,18.0,300.0,1.2940671,0.088514641,18.066048,347.56833,-10.796823
145.7851,0.090217859,10.9051,0.0,0,18.0,300.0,1.2971271,0.27775982,18.066938,347.65506,-10.812737
145.7873,0.10730584,10.913213,0.0,0,18.0,300.0,1.3018227,0.37528735,18.063541,347.74179,-10.828573
145.7895,0.052240044,10.938725,0.0,0,18.0,300.0,1.3047968,0.21212359,18.063498,347.82852,-10.844848
145.7917,-0.052867476,10.944214,0.0,0,18.0,300.0,1.3090068,-0.10242341,18.067064,347.91525,-10.860457
145.7939,-0.13023867,10.968472,0.0,0,18.0,300.0,1.3127511,-0.43417427,18.065609,348.00198,-10.874438
145.7961,-0.13348426,10.979485,0.0,0,18.0,300.0,1.3180194,-0.4572711,18.063423,348.08871,-10.890327
145.7983,-0.073301218,11.00285,0.0,0,18.0,300.0,1.3208389,-0.27508643,18.059753,348.17545,-10.905972
145.8005,0.0026129996,11.008161,0.0,0,18.0,300.0,1.3249692,-0.020865766,18.062012,348.20615,-10.921153
145.8027,0.071694016,11.030668,0.0,0,18.0,300.0,1.3285688,0.2040769,18.06595,348.19946,-10.937642
145.8049,0.10131387,11.039182,0.0,0,18.0,300.0,1.3328278,0.31051117,18.058605,348.19278,-10.955809
145.8071,0.07595259,11.067576,0.0,0,18.0,300.0,1.3374252,0.29021755,18.057671,348.18613,-10.971643
145.8093,-0.005510807,11.072171,0.0,0,18.0,300.0,1.3406775,0.052990776,18.059708,348.17975,-10.986645
145.8115,-0.11070983,11.094361,0.0,0,18.0,300.0,1.3447496,-0.30172226,18.057732,348.17975,-11.001534
145.8137,-0.14368966,11.104495,0.0,0,18.0,300.0,1.3489019,-0.48572677,18.056332,348.17975,-11.0184
145.8159,-0.10634011,11.131902,0.0,0,18.0,300.0,1.3539833,-0.37436613,18.058947,348.17975,-11.034493
145.8181,-0.017130131,11.137404,0.0,0,18.0,300.0,1.3575301,-0.080381669,18.056269,348.17975,-11.051388
145.8203,0.064014494,11.155778,0.0,0,18.0,300.0,1.3607926,0.16737625,18.05776,348.19284,-11.065884
145.8225,0.08966288,11.163892,0.0,0,18.0,300.0,1.364185,0.29090354,18.05842,348.21954,-11.081809
145.8247,0.085491322,11.190216,0.0,0,18.0,300.0,1.3694147,0.31372339,18.059309,348.24622,-11.097583
145.8269,0.022024658,11.197729,0.0,0,18.0,300.0,1.3729522,0.1363951,18.058174,348.27292,-11.11305
145.8291,-0.078915931,11.22024,0.0,0,18.0,300.0,1.3779936,-0.2152203,18.054432,348.29959,-11.129869
145.8313,-0.14355128,11.23092,0.0,0,18.0,300.0,1.3814089,-0.45004022,18.055241,348.33252,-11.145393
145.8335,-0.13462554,11.25248,0.0,0,18.0,300.0,1.3865552,-0.45673883,18.058134,348.36588,-11.160715
145.8357,-0.03587947,11.260898,0.0,0,18.0,300.0,1.3894185,-0.17586111,18.055222,348.39923,-11.177273
145.8379,0.043328799,11.282488,0.0,0,18.0,300.0,1.3949361,0.077420346,18.054092,348.43259,-11.192029
145.8401,0.080256186,11.292295,0.0,0,18.0,300.0,1.3976547,0.23907606,18.054792,348.46085,-11.207113
145.8423,0.086667441,11.315242,0.0,0,18.0,300.0,1.4034766,0.27044156,18.051729,348.48087,-11.222367
145.8445,0.064559817,11.321733,0.0,0,18.0,300.0,1.4056,0.21770103,18.050016,348.50089,-11.238989
145.8467,-0.033135723,11.344656,0.0,0,18.0,300.0,1.4119538,-0.041553941,18.05316,348.5209,-11.256031
145.8489,-0.13404918,11.359297,0.0,0,18.0,300.0,1.4157109,-0.35430774,18.05006,348.54092,-11.272767
145.8511,-0.15069272,11.381054,0.0,0,18.0,300.0,1.4220662,-0.44433108,18.051161,348.1575,-11.288082
145.8533,-0.071024343,11.389498,0.0,0,18.0,300.0,1.4240519,-0.28916669,18.049068,347.68982,-11.302818
145.8555,0.022187356,11.403973,0.0,0,18.0,300.0,1.4283563,0.02332072,18.050743,347.22217,-11.31843
145.8577,0.082022488,11.417905,0.0,0,18.0,300.0,1.4315784,0.21456996,18.050858,346.75449,-11.333632
145.8599,0.096531235,11.439391,0.0,0,18.0,300.0,1.4385934,0.28476772,18.051291,346.48087,-11.350523
145.8621,0.069243856,11.452518,0.0,0,18.0,300.0,1.4411318,0.23915143,18.049215,346.48755,-11.365983
146.7624,-0.015649997,11.567147,0.0,0,18.0,1.621674e-10,1.4746884,-0.040930577,18.002304,327.01266,-11.482884
147.8624,-0.017658684,11.566133,0.0,0,18.0,1.6196895e-25,1.4744581,-0.048809052,18.000511,147.66594,-11.482301
148.9624,-0.017167512,11.566031,0.0,0,18.0,1.617715e-40,1.4744881,-0.047773555,17.999767,74.373924,-11.482631
150.0624,-0.018619729,11.566548,0.0,0,18.0,1.4012985e-45,1.4744296,-0.053253748,18.000301,41.205921,-11.482804
151.1624,-0.019748734,11.565825,0.0,0,18.0,1.4012985e-45,1.4743595,-0.055834971,17.999895,30.438169,-11.482776
152.2624,-0.018756917,11.566304,0.0,0,18.0,1.4012985e-45,1.4742868,-0.054024097,18.000063,26.815926,-11.482649
153.3624,-0.020139955,11.56631,0.0,0,18.0,1.4012985e-45,1.4743816,-0.058974229,18.000113,25.539371,-11.482207
154.4624,-0.019946605,11.566492,0.0,0,18.0,1.4012985e-45,1.4743999,-0.05605961,18.001482,25.079016,-11.482236
155.5624,-0.020501561,11.566095,0.0,0,18.0,1.4012985e-45,1.4744008,-0.056817729,18.000025,24.988356,-11.482287
156.6624,-0.020868601,11.565562,0.0,0,18.0,1.4012985e-45,1.4743062,-0.060140677,18.00012,24.900524,-11.482875
157.7624,-0.020615172,11.566358,0.0,0,18.0,1.4012985e-45,1.4744132,-0.058827337,18.000828,24.734125,-11.482906
158.8624,-0.022153446,11.565924,0.0,0,18.0,1.4012985e-45,1.4744275,-0.061628118,18.001295,24.773682,-11.482181
159.9624,-0.022432383,11.565924,0.0,0,18.0,1.4012985e-45,1.4741613,-0.066997983,18.00021,24.66441,-11.482664
161.0624,-0.021433244,11.566432,0.0,0,18.0,1.4012985e-45,1.4744227,-0.064718351,17.999844,24.55386,-11.482217
162.1624,-0.022267006,11.566871,0.0,0,18.0,1.4012985e-45,1.4744912,-0.063815556,18.000034,24.621964,-11.482244
163.2624,-0.02094359,11.566813,0.0,0,18.0,1.4012985e-45,1.4746187,-0.059046905,18.000299,24.623661,-11.482812
164.3624,-0.021018606,11.566693,0.0,0,18.0,1.4012985e-45,1.4746085,-0.061494462,18.00103,24.494631,-11.482944
165.4624,-0.021220222,11.566858,0.0,0,18.0,1.4012985e-45,1.4746379,-0.060140427,18.00139,24.527666,-11.482714
166.5624,-0.020828603,11.566651,0.0,0,18.0,1.4012985e-45,1.4746473,-0.061291739,18.000811,24.434965,-11.483194
167.6624,-0.021808667,11.567202,0.0,0,18.0,1.4012985e-45,1.4745735,-0.065395676,17.999981,24.406645,-11.482289
168.7624,-0.021421026,11.566802,0.0,0,18.0,1.4012985e-45,1.4745257,-0.063799918,17.999809,24.374971,-11.482291
169.8624,-0.019632913,11.567512,0.0,0,18.0,1.4012985e-45,1.4746521,-0.060240064,18.000042,24.454647,-11.48211
170.9624,-0.020692466,11.567181,0.0,0,18.0,1.4012985e-45,1.4746795,-0.060637996,18.000477,24.462906,-11.482122
172.0624,-0.019987965,11.566827,0.0,0,18.0,1.4012985e-45,1.4745655,-0.05969537,18.000959,24.420692,-11.482542
173.1624,-0.018560208,11.566816,0.0,0,18.0,1.4012985e-45,1.474663,-0.058326602,17.999722,24.292336,-11.48217
174.2624,-0.019343497,11.566423,0.0,0,18.0,1.4012985e-45,1.4745955,-0.05762082,18.000839,24.351767,-11.48279
175.3624,-0.018231379,11.567179,0.0,0,18.0,1.4012985e-45,1.4745864,-0.053723611,18.000103,24.210022,-11.482494
176.4624,-0.018955357,11.567321,0.0,0,18.0,1.4012985e-45,1.4747083,-0.059185706,18.000114,24.196928,-11.48257
177.5624,-0.01758834,11.567419,0.0,0,18.0,1.4012985e-45,1.4745946,-0.053145636,17.999456,24.298563,-11.482719
178.6624,-0.017728459,11.567709,0.0,0,18.0,1.4012985e-45,1.4748566,-0.055964999,18.00148,24.180347,-11.482548
179.7624,-0.016310997,11.567441,0.0,0,18.0,1.4012985e-45,1.4747624,-0.050671864,17.999483,24.198606,-11.482387
180.8624,-0.016672218,11.567611,0.0,0,18.0,1.4012985e-45,1.4748728,-0.047928382,17.999556,24.340244,-11.481995
181.9624,-0.017159816,11.567229,0.0,0,18.0,1.4012985e-45,1.4748399,-0.053827137,18.001156,24.207586,-11.481684
183.0624,-0.016785366,11.567375,0.0,0,18.0,1.4012985e-45,1.4746133,-0.05063853,18.00049,24.106083,-11.481638
184.1624,-0.015868533,11.567502,0.0,0,18.0,1.4012985e-45,1.4747844,-0.046444789,18.000679,24.128542,-11.481757
185.2624,-0.015421583,11.567546,0.0,0,18.0,1.4012985e-45,1.4746362,-0.045843881,17.999893,24.017561,-11.481604
186.3624,-0.015765961,11.567476,0.0,0,18.0,1.4012985e-45,1.4747411,-0.04443093,18.000538,24.137411,-11.482386
187.4624,-0.014667233,11.568151,0.0,0,18.0,1.4012985e-45,1.4749519,-0.042624649,18.000734,24.201508,-11.482276
188.5624,-0.013634576,11.567794,0.0,0,18.0,1.4012985e-45,1.4749255,-0.040856805,17.999966,24.17136,-11.482411
189.6624,-0.014350766,11.567945,0.0,0,18.0,1.4012985e-45,1.4750669,-0.042612858,18.000196,24.103638,-11.482672
190.7624,-0.012926832,11.568327,0.0,0,18.0,1.4012985e-45,1.4749997,-0.039613821,18.000845,24.060667,-11.48299
191.8624,-0.015629867,11.567873,0.0,0,18.0,1.4012985e-45,1.4749386,-0.045029119,17.999935,24.121614,-11.482755
192.9624,-0.015384962,11.568536,0.0,0,18.0,1.4012985e-45,1.4749426,-0.04427024,18.001047,24.061676,-11.482433
194.0624,-0.014482121,11.568611,0.0,0,18.0,1.4012985e-45,1.4750341,-0.042488348,17.999851,24.092854,-11.48177
195.1624,-0.014996703,11.568584,0.0,0,18.0,1.4012985e-45,1.4750468,-0.045257598,18.000448,24.050608,-11.482022
196.2624,-0.014425645,11.568323,0.0,0,18.0,1.4012985e-45,1.4751134,-0.041182764,17.999193,24.018461,-11.481986
197.3624,-0.014352107,11.568065,0.0,0,18.0,1.4012985e-45,1.4751005,-0.041045468,18.000246,23.923611,-11.481363
198.4624,-0.015293739,11.568388,0.0,0,18.0,1.4012985e-45,1.4749682,-0.046267193,17.99975,23.943403,-11.481428
199.5624,-0.013383059,11.568879,0.0,0,18.0,1.4012985e-45,1.4752228,-0.038435157,18.000282,24.009544,-11.481638
200.6624,-0.013247319,11.569565,0.0,0,18.0,1.4012985e-45,1.4752316,-0.031781271,18.000439,24.086594,-11.482118
201.7624,-0.015057799,11.569673,0.0,0,18.0,1.4012985e-45,1.4753217,-0.040004313,18.000885,23.993225,-11.482341
202.8624,-0.014389014,11.569754,0.0,0,18.0,1.4012985e-45,1.4753902,-0.042270601,17.999563,24.061829,-11.482213
203.9624,-0.015159923,11.570242,0.0,0,18.0,1.4012985e-45,1.4756789,-0.041964311,17.999847,23.936991,-11.482377
205.0624,-0.015134409,11.569849,0.0,0,18.0,1.4012985e-45,1.475566,-0.041987795,18.00024,23.980062,-11.482819
205.8624,-0.020715341,11.571053,0.0,0,18.0,1.4012985e-45,1.4756852,-0.055269558,17.999714,23.868475,-11.482789