File: examples/dan-msc-case-studies/CS3/data/01 raw data/baron_test_109.csv
Time(sec),Force(kN),Jaw(mm),PowAngle(deg),Power(W),Pram,PTemp,Strain,Stress(MPa),Stroke(mm),TC1(C),wedge(mm)
0.0,0.81295842,0.37252146,0.0,0,11.076097,0.0016696046,0.025157535,10.093539,11.075446,23.445713,-9.1256313
1.1,0.7789017,0.0058925198,0.0,0,11.076097,3.216182,0.00040853786,9.9120646,11.077232,23.38554,-9.4937401
2.2,0.76046449,0.0060197334,0.0,0,11.076097,6.5161824,0.00038736587,9.6714563,11.076997,23.369329,-9.4912329
3.3,0.74008346,0.0061397301,0.0,0,11.076097,9.8161821,0.00041096925,9.4160156,11.076474,23.377403,-9.4896679
4.4,0.71767199,0.0060245399,0.0,0,11.076097,13.116181,0.00040030613,9.1440392,11.077374,23.34725,-9.4876032
5.5,0.70415097,0.0057627037,0.0,0,11.076097,16.416187,0.00038364326,8.9704161,11.07601,23.395016,-9.4859066
6.6,0.69580454,0.00564628,0.0,0,11.076097,19.716185,0.00036277596,8.8482132,11.075548,23.365742,-9.4837532
7.7,0.68440634,0.0056860554,0.0,0,11.076097,23.016184,0.00038066308,8.7086277,11.075754,23.317741,-9.4817486
8.8,0.67399323,0.0062182141,17.426886,0,11.076097,26.316185,0.00042890754,8.5781403,11.07663,23.371964,-9.4793587
9.9,0.66889077,0.0067852628,31.692785,0,11.076097,29.616184,0.00042910883,8.5183859,11.076327,23.477983,-9.4775629
11.0,0.68559694,0.0049402895,41.076801,0,11.076097,32.91618,0.0003405078,8.7377834,11.076304,24.074368,-9.476162
12.1,0.70856351,0.0013217981,47.331703,0,11.076097,36.216175,0.00012233511,9.0388794,11.075106,25.702288,-9.4741468
13.2,0.72191149,-0.0034945444,51.548885,0,11.076097,39.516174,-0.00026200197,9.1989794,11.076513,28.457058,-9.4723635
14.3,0.74397373,-0.0094941119,54.302612,0,11.076097,42.816177,-0.00061845715,9.4860373,11.076392,32.327297,-9.4702749
15.4,0.76152897,-0.015066617,56.126682,0,11.076097,46.116177,-0.00097507489,9.7019939,11.0762,36.952946,-9.468277
16.5,0.77441102,-0.020063406,56.986065,0,11.076097,49.41618,-0.0013471779,9.8705139,11.076286,42.275967,-9.4662085
17.6,0.78252715,-0.02564422,56.986229,0,11.076097,52.716183,-0.0017100587,9.9805937,11.075425,48.004967,-9.4642982
18.7,0.78608489,-0.030532906,56.442211,0,11.076097,56.016186,-0.0020310895,10.042179,11.076177,53.890476,-9.4623718
19.8,0.78686583,-0.03552467,55.244656,0,11.076097,59.316196,-0.0023631235,10.057559,11.076499,59.542992,-9.4603491
20.9,0.79084206,-0.039742101,53.660385,0,11.076097,62.616196,-0.0026636298,10.080867,11.075701,64.923401,-9.4584141
22.0,0.79343802,-0.043135319,51.615417,0,11.076097,65.916176,-0.0028743537,10.125578,11.076173,69.707878,-9.4568186
23.1,0.78366828,-0.046321817,49.63792,0,11.076097,69.216179,-0.0030656231,10.019196,11.075846,73.945564,-9.4549637
24.2,0.79203254,-0.047846913,47.294041,0,11.076097,72.516174,-0.0032081546,10.132903,11.076224,77.682777,-9.4531193
25.3,0.78079849,-0.050039109,45.15609,0,11.076097,75.816185,-0.003329206,9.9755831,11.076042,80.855324,-9.4510794
26.4,0.76509666,-0.051532574,43.846546,0,11.076097,79.116188,-0.0034109852,9.7686386,11.076625,83.484207,-9.4492712
27.5,0.75095201,-0.0532845,43.527836,0,11.076097,82.416183,-0.0035694274,9.591485,11.075585,85.516418,-9.446887
28.6,0.74888122,-0.054621141,44.075474,0,11.076097,85.716194,-0.0036212243,9.5830698,11.076715,87.41539,-9.4453325
29.7,0.75216818,-0.055187386,45.120689,0,11.076097,89.01619,-0.0036541205,9.6051197,11.076405,89.065956,-9.4437551
30.8,0.74388558,-0.056958757,47.043789,0,11.076097,92.3162,-0.0038096081,9.5071898,11.075569,90.779343,-9.4415131
31.9,0.7628687,-0.059201665,49.202782,0,11.076097,95.616196,-0.0039300853,9.7640114,11.075862,92.736153,-9.4398098
33.0,0.76852518,-0.06189923,51.134251,0,11.076097,98.916199,-0.0041130404,9.8318701,11.077223,95.014511,-9.4378271
34.1,0.7878347,-0.064780019,52.963604,0,11.076097,102.2162,-0.0043037338,10.067529,11.07544,97.565079,-9.4356241
35.2,0.79978484,-0.06824711,54.608036,0,11.076097,105.5162,-0.0045512062,10.22749,11.076397,100.5479,-9.4338779
36.3,0.8035273,-0.071977846,55.801521,0,11.076097,108.81619,-0.0047804327,10.289263,11.076471,103.98509,-9.4318333
37.4,0.80454165,-0.076618999,56.608582,0,11.076097,112.11619,-0.0050765136,10.305925,11.076064,107.75682,-9.4300232
38.5,0.8088277,-0.081995875,57.259575,0,11.076097,115.41619,-0.0054789288,10.352473,11.075719,111.71552,-9.4280529
39.6,0.80471164,-0.087208122,57.535397,0,11.076097,118.71619,-0.0057861377,10.294998,11.076952,115.82738,-9.4260273
40.7,0.80356741,-0.090051986,57.535458,0,11.076097,122.01618,-0.0059689404,10.287354,11.076338,120.00836,-9.4240274
41.8,0.80174643,-0.094512969,57.535412,0,11.076097,125.31617,-0.0063003944,10.269574,11.076497,124.19543,-9.4225035
42.9,0.80608654,-0.098244749,57.260845,0,11.076097,128.6163,-0.0065127239,10.328718,11.075282,128.25221,-9.4205818
44.0,0.80212641,-0.10218564,56.846142,0,11.076097,131.91618,-0.006775605,10.292817,11.076707,132.30986,-9.419117
45.1,0.80251962,-0.10538547,56.425789,0,11.076097,135.21619,-0.0070158332,10.290619,11.076692,136.10703,-9.4172506
46.2,0.81111062,-0.10896668,55.849041,0,11.076097,138.51619,-0.0072368798,10.410082,11.076642,139.74265,-9.4153862
47.3,0.8072198,-0.11359012,55.535892,0,11.076097,141.81619,-0.0075502018,10.348658,11.076395,143.24417,-9.4139061
48.4,0.80547076,-0.11599636,55.239262,0,11.076097,145.11621,-0.0076915175,10.33512,11.076331,146.44148,-9.4120321
49.5,0.80233854,-0.11811288,54.974758,0,11.076097,148.4162,-0.0078553353,10.293742,11.07722,149.49188,-9.4102974
50.6,0.80057096,-0.12096336,54.931644,0,11.076097,151.71619,-0.0080327382,10.293081,11.076366,152.34384,-9.4082384
51.7,0.80695403,-0.12365945,55.239254,0,11.076097,155.0162,-0.008185721,10.361488,11.076835,155.12343,-9.4063454
52.8,0.80607218,-0.12635654,55.817829,0,11.076097,158.31619,-0.008405027,10.343232,11.076569,157.7562,-9.4044294
53.9,0.80429709,-0.12932864,56.178257,0,11.076097,161.6162,-0.0085696364,10.321225,11.07525,160.52759,-9.4021683
55.0,0.80511135,-0.13449717,56.801964,0,11.076097,164.9162,-0.008903414,10.350329,11.077381,163.38277,-9.4006157
56.1,0.81411546,-0.13717134,57.530853,0,11.076097,168.2162,-0.0091102859,10.465385,11.075722,166.28954,-9.3985929
57.2,0.79915822,-0.14033662,58.07156,0,11.076097,171.51619,-0.0093017686,10.2652,11.076706,169.41765,-9.396595
58.3,0.80808157,-0.14395986,58.589935,0,11.076097,174.81619,-0.0095390631,10.382381,11.075451,172.70467,-9.3948116
59.4,0.80435741,-0.14738026,59.004803,0,11.076097,178.11618,-0.0097830649,10.350496,11.076302,175.99261,-9.3925343
60.5,0.8174237,-0.15076967,59.345001,0,11.076097,181.41618,-0.010001637,10.526394,11.076645,179.51196,-9.3913422
61.6,0.81212449,-0.15715055,59.591194,0,11.076097,184.7162,-0.01042156,10.449062,11.076324,183.03584,-9.3892593
62.7,0.81427908,-0.1595583,59.619705,0,11.076097,188.01619,-0.010574453,10.468428,11.077082,186.69646,-9.3874855
63.8,0.80602378,-0.16308306,59.842464,0,11.076097,191.31619,-0.010823444,10.37719,11.076557,190.30731,-9.3855267
64.9,0.81760561,-0.16654535,59.842525,0,11.076097,194.6162,-0.011038204,10.536864,11.075871,193.94382,-9.3835926
66.0,0.81120336,-0.16980797,59.842525,0,11.076097,197.9162,-0.011239323,10.450997,11.077157,197.45793,-9.3820677
67.1,0.81753838,-0.17520837,59.842525,0,11.076097,201.2162,-0.011641365,10.518357,11.075431,200.9736,-9.3802176
68.2,0.80490637,-0.17775634,59.757202,0,11.076097,204.5162,-0.01177217,10.366538,11.076576,204.42673,-9.3784304
69.3,0.8158707,-0.18137096,59.720551,0,11.076097,207.81619,-0.011997361,10.510374,11.076027,207.81085,-9.3766775
70.4,0.82053953,-0.18404593,59.600838,0,11.076097,211.11621,-0.012207935,10.583995,11.076372,211.23349,-9.3745451
71.5,0.82439911,-0.18874273,59.600838,0,11.076097,214.4162,-0.012497434,10.630584,11.076782,214.46989,-9.3729181
72.6,0.80613112,-0.19188662,59.633179,0,11.076097,217.71622,-0.012709854,10.392682,11.076089,217.70853,-9.3709164
73.7,0.81378484,-0.1953491,59.842102,0,11.076097,221.0162,-0.012946977,10.491229,11.076715,220.84045,-9.3691368
74.8,0.81725085,-0.19852395,59.842525,0,11.076097,224.31619,-0.013162552,10.548406,11.076169,223.94064,-9.3672152
75.9,0.8209635,-0.20347236,60.084225,0,11.076097,227.6162,-0.013475765,10.601011,11.076063,227.07339,-9.3651352
77.0,0.81556261,-0.20608789,60.314934,0,11.076097,230.9162,-0.013627005,10.520729,11.076497,230.18208,-9.3637438
78.1,0.81043857,-0.20939323,60.556637,0,11.076097,234.2162,-0.013883941,10.458701,11.076849,233.28407,-9.3617325
79.2,0.81475604,-0.21204151,60.795036,0,11.076097,237.5162,-0.014028115,10.518654,11.076191,236.44324,-9.3599005
80.3,0.81929159,-0.21860385,61.16869,0,11.076097,240.81621,-0.014447271,10.577955,11.075752,239.64413,-9.3581152
81.4,0.81253052,-0.22048262,61.464375,0,11.076097,244.1162,-0.014606928,10.50537,11.075467,242.84882,-9.3561573
82.5,0.81479585,-0.22393712,61.688229,0,11.076097,247.4162,-0.014807658,10.527579,11.075914,246.11955,-9.3545094
83.6,0.82120895,-0.22686857,61.90794,0,11.076097,250.71619,-0.014997803,10.626196,11.075981,249.39571,-9.3525267
84.7,0.82277697,-0.23319447,62.249519,0,11.076097,254.0162,-0.015423203,10.628099,11.076605,252.58669,-9.3507967
85.8,0.81573391,-0.23545876,62.51511,0,11.076097,257.31644,-0.015580463,10.555889,11.076567,255.91815,-9.3488998
86.9,0.81634134,-0.23885429,62.704346,0,11.076097,260.61646,-0.015800925,10.562194,11.075888,259.39063,-9.3470726
88.0,0.82358122,-0.24351387,62.812756,0,11.076097,263.91623,-0.016095851,10.655666,11.076499,262.73886,-9.3450689
89.1,0.82186234,-0.24729703,62.962639,0,11.076097,267.21622,-0.01637407,10.629292,11.076724,266.1861,-9.3433723
90.2,0.81351715,-0.25154695,62.993366,0,11.076097,270.51624,-0.016619211,10.540823,11.076156,269.74454,-9.3415937
91.3,0.82471526,-0.25474524,63.168686,0,11.076097,273.81622,-0.016812172,10.689814,11.075852,273.15698,-9.3402739
92.4,0.82602894,-0.26089185,63.171383,0,11.076097,277.11621,-0.017265486,10.692179,11.076283,276.60315,-9.3380165
93.5,0.81275856,-0.26311618,63.171383,0,11.076097,280.4162,-0.017375939,10.532439,11.077683,280.00583,-9.3366737
94.6,0.81437796,-0.26671961,63.347485,0,11.076097,283.71619,-0.017616224,10.557218,11.076104,283.24951,-9.3342962
95.7,0.82787383,-0.26963741,63.369137,0,11.076097,287.0162,-0.017828744,10.741616,11.076242,286.63989,-9.332633
96.8,0.83051181,-0.2759603,63.369137,0,11.076097,290.31616,-0.018234324,10.764788,11.076665,289.95145,-9.3309202
97.9,0.81606966,-0.27788171,63.548244,0,11.076097,293.61618,-0.01835476,10.581679,11.075233,293.21219,-9.3291321
99.0,0.81223273,-0.28101259,63.577873,0,11.076097,296.9162,-0.018542651,10.533812,11.076552,296.38565,-9.3268995
100.1,0.82967788,-0.28372243,63.709019,0,11.076097,299.99542,-0.018754406,10.771965,11.075587,299.55524,-9.3255301
101.2,0.82727587,-0.28953883,62.16214,0,11.076097,299.99905,-0.019103734,10.738084,11.077379,302.65747,-9.3253927
102.3,0.81648481,-0.28995433,60.17099,0,11.076097,299.99905,-0.019118646,10.606572,11.075458,305.40845,-9.325428
103.4,0.81745058,-0.29052269,57.571079,0,11.076097,299.99905,-0.019195493,10.60838,11.075483,307.57797,-9.325346
104.5,0.81819397,-0.28999135,54.636917,0,11.076097,299.99905,-0.019140238,10.629188,11.076135,309.08759,-9.3252592
105.6,0.79258156,-0.29172808,51.396404,0,11.076097,299.99905,-0.019254141,10.296629,11.076888,309.73694,-9.3254375
106.7,0.76327932,-0.28885868,48.389252,0,11.076097,299.99905,-0.019069761,9.9056206,11.076216,309.55688,-9.3251696
107.8,0.75178999,-0.28637621,45.617149,0,11.076097,299.99905,-0.018926183,9.7547855,11.076918,308.55875,-9.3251915
108.9,0.73171782,-0.28328994,43.602242,0,11.076097,299.99905,-0.01870415,9.4903097,11.075643,306.93338,-9.3252878
110.0,0.7187345,-0.28074127,43.206196,0,11.076097,299.99905,-0.018529894,9.3165817,11.07646,304.82788,-9.3253374
111.1,0.70821166,-0.27912498,44.076569,0,11.076097,299.99905,-0.018454643,9.1782122,11.076496,302.48022,-9.3253803
112.2,0.69990277,-0.27696079,46.052826,0,11.076097,299.99905,-0.018287875,9.0755043,11.076046,300.1911,-9.3253298
113.3,0.69502211,-0.27631545,48.199211,0,11.076097,299.99905,-0.018242335,9.0141888,11.075717,298.1525,-9.3249493
114.4,0.69777,-0.2753197,50.434071,0,11.076097,299.99905,-0.018194444,9.0578632,11.076154,296.41583,-9.3251419
115.5,0.70653242,-0.27505669,52.633423,0,11.076097,299.99905,-0.018176565,9.1641026,11.076147,295.35852,-9.3248997
116.6,0.73560911,-0.2769897,54.589588,0,11.076097,299.99905,-0.018303592,9.54632,11.076141,294.6521,-9.3250694
117.7,0.73699111,-0.27868614,56.116898,0,11.076097,299.99905,-0.018382866,9.5707712,11.076586,294.45251,-9.324976
118.8,0.75024682,-0.27926213,57.256729,0,11.076097,299.99905,-0.018469686,9.7407446,11.075138,294.81204,-9.3248386
119.9,0.76157916,-0.28118855,57.892426,0,11.076097,299.99905,-0.018559853,9.8718233,11.076778,295.55914,-9.3247862
121.0,0.77295113,-0.28346846,58.337399,0,11.076097,299.99905,-0.018693728,10.017263,11.075776,296.55173,-9.3249998
122.1,0.79335552,-0.28481641,58.337399,0,11.076097,299.99905,-0.018815761,10.3149,11.075978,297.76501,-9.3251057
123.2,0.80296612,-0.2863037,58.073738,0,11.076097,299.99905,-0.018910101,10.42828,11.076202,299.01102,-9.3252916
124.3,0.81082934,-0.28943989,57.535412,0,11.076097,299.99905,-0.019114882,10.523737,11.075795,300.28659,-9.3249655
125.4,0.81182951,-0.29152066,56.52129,0,11.076097,299.99905,-0.01923223,10.543426,11.077491,301.49045,-9.3254042
126.5,0.80157381,-0.29072422,55.53606,0,11.076097,299.99905,-0.019221103,10.393821,11.07641,302.45837,-9.3248768
127.6,0.80422789,-0.29145756,54.305668,0,11.076097,299.99905,-0.019233458,10.445829,11.076546,303.26324,-9.3245306
128.7,0.79494232,-0.29154694,52.976154,0,11.076097,299.99905,-0.019230561,10.316692,11.075981,303.63861,-9.3246584
129.8,0.77758628,-0.29127437,51.717213,0,11.076097,299.99905,-0.019250279,10.093558,11.075728,303.73639,-9.3246365
130.9,0.76853836,-0.29060209,50.822758,0,11.076097,299.99905,-0.019179905,9.9681797,11.076579,303.55878,-9.3245583
132.0,0.76814157,-0.29021937,50.042728,0,11.076097,299.99905,-0.019152623,9.989501,11.07634,303.00845,-9.3248615
133.1,0.76162332,-0.29044634,49.636234,0,11.076097,299.99905,-0.019179327,9.8851986,11.076339,302.39987,-9.3246489
134.2,0.75598669,-0.29035422,49.636227,0,11.076097,299.99905,-0.01918483,9.7991571,11.076499,301.47223,-9.325037
135.3,0.7476728,-0.28885284,50.042416,0,11.076097,299.99905,-0.019070143,9.7192783,11.076402,300.59976,-9.3247671
136.4,0.74163735,-0.28855723,50.53392,0,11.076097,299.99905,-0.019028835,9.6335621,11.07596,299.73547,-9.3248739
137.5,0.73754299,-0.28821701,51.379841,0,11.076097,299.99905,-0.019048955,9.5701828,11.076446,299.01767,-9.3246756
138.6,0.74740589,-0.28829649,52.260586,0,11.076097,299.99905,-0.019022649,9.6988039,11.076676,298.38202,-9.3245859
139.7,0.76175082,-0.2885347,52.97604,0,11.076097,299.99905,-0.019030772,9.9006729,11.076673,297.96295,-9.324708
140.8,0.7642619,-0.2889713,53.717831,0,11.076097,299.99905,-0.019077845,9.9176111,11.07644,297.77597,-9.324357
141.9,0.77483028,-0.28912768,54.305416,0,11.076097,299.99905,-0.019097917,10.056738,11.076867,297.7879,-9.3247213
143.0,0.78731936,-0.29011345,54.917267,0,11.076097,299.99905,-0.019155376,10.219692,11.076033,297.95117,-9.3246508
144.1,0.78443342,-0.29140759,55.238903,0,11.076097,299.99905,-0.01922884,10.180691,11.075681,298.29858,-9.3245134
145.13,0.79625362,-0.017776065,55.239254,0,11.076097,299.99905,-0.0011770866,10.15726,11.076202,298.81677,-9.3243513
145.2943,0.80110586,0.02849935,6.6286345,0,11.076099,6.0865757e-10,0.0017376591,10.218632,11.074001,298.89758,-9.3244801
145.2965,0.79896057,0.021715017,0.0,0,11.076099,6.079146e-25,0.0015585794,10.144578,11.075213,298.90863,-9.3246965
145.2987,0.79556459,0.022732489,0.0,0,11.076099,6.0717282e-40,0.0014772034,10.150414,11.077768,298.90863,-9.3244801
145.3009,0.78114593,0.020764997,0.0,0,11.076099,0.0,0.0015019571,9.9304972,11.075011,298.90863,-9.3232393
145.3031,0.78124964,0.027169725,0.0,0,11.076099,0.0,0.0016806091,10.03582,11.076691,298.90863,-9.3235989
145.3053,0.78211486,0.021320103,0.0,0,11.076099,0.0,0.0014713643,9.9638109,11.077708,298.90863,-9.3238621
145.3075,0.78274196,0.023480546,0.0,0,11.076099,0.0,0.0015327871,9.886879,11.077724,298.91476,-9.3260078
145.3097,0.78605664,0.019268665,0.0,0,11.076099,0.0,0.0013619232,9.9516439,11.074636,298.92154,-9.3258305
145.3119,0.79178447,0.027507335,0.0,0,11.076099,0.0,0.001766863,10.05127,11.074038,298.92828,-9.3237352
145.3141,0.77728385,0.022288561,0.0,0,11.076099,0.0,0.0014943043,9.861125,11.077303,298.93503,-9.3239946
145.3163,0.77715576,0.022119902,0.0,0,11.076099,0.0,0.0015428399,9.9519024,11.076844,298.93689,-9.3239775
145.3185,0.77470177,0.020683594,0.0,0,11.076099,0.0,0.0013613894,9.7797899,11.074959,298.93011,-9.3233137
145.3207,0.76382917,0.02652704,0.0,0,11.076099,0.0,0.0017760247,9.7004948,11.078979,298.92337,-9.3247318
145.3229,0.76177621,0.024660103,0.0,0,11.076099,0.0,0.0015911226,9.7243891,11.076169,298.91663,-9.3251104
145.3251,0.77478063,0.023806255,0.0,0,11.076099,0.0,0.0016240166,9.7422628,11.076937,298.90985,-9.3242016
145.3273,0.77690315,0.021182796,0.0,0,11.076099,0.0,0.0013807232,9.807025,11.075502,298.90311,-9.3245363
145.3295,0.77901077,0.02541651,0.0,0,11.076099,0.0,0.0017989991,9.8152275,11.075627,298.89636,-9.3255148
145.3317,0.76900321,0.023564639,0.0,0,11.076099,0.0,0.0014651518,9.8166361,11.078321,298.88959,-9.3255644
145.3339,0.76420593,0.023402752,0.0,0,11.076099,0.0,0.0015932187,9.7250032,11.077147,298.88284,-9.3255424
145.3361,0.76919872,0.020601131,0.0,0,11.076099,0.0,0.0013157232,9.71453,11.076336,298.87793,-9.3238211
145.3383,0.75990331,0.025048211,0.0,0,11.076099,0.0,0.0018321292,9.6498718,11.079473,298.87793,-9.3242788
145.3405,0.74993819,0.024903433,0.0,0,11.076099,0.0,0.0015210159,9.5997887,11.076585,298.87793,-9.3247118
145.3427,0.75394034,0.021630693,0.0,0,11.063763,0.0,0.001559012,9.5708885,11.07683,298.87793,-9.3251276
145.3449,0.76205194,0.020663075,0.0,0,10.735819,0.0,0.001284664,9.614995,11.076203,298.87793,-9.3253565
145.3471,0.76900309,0.023204181,0.0,0,10.404927,0.0,0.0017284607,9.8305149,11.074598,298.89758,-9.3237457
145.3493,0.78424096,0.025274267,0.0,0,10.074035,0.0,0.0014719736,9.9563227,11.0133,298.92459,-9.3235598
145.3515,0.78816628,0.023267413,0.0,0,9.7431412,0.0,0.0016836715,10.018826,10.827592,298.9516,-9.3250103
145.3537,0.79311168,0.022009093,0.0,0,9.4141388,0.0,0.001268465,10.136242,10.532271,298.97864,-9.3242893
145.3559,0.74819911,0.023969216,0.0,0,9.0922346,0.0,0.0018159815,9.5686092,10.140884,299.62915,-9.3242931
145.3581,7.139379,0.34706253,0.0,0,8.7703304,0.0,0.02223869,88.603806,9.725565,303.08536,-9.3192635
145.3603,8.963728,0.73605204,0.0,0,8.4631929,0.0,0.050161533,107.94423,9.2637625,306.54156,-9.3182745
145.3625,9.5505352,1.1417271,0.0,0,8.1570415,0.0,0.078802146,112.05086,8.8392963,309.99777,-9.3175583
145.3647,9.8637762,1.4891715,0.0,0,7.8607755,0.0,0.10433657,113.44444,8.502883,313.45398,-9.3183146
145.3669,10.345064,1.7750915,0.0,0,7.5694952,0.0,0.12527037,115.9075,8.1884098,316.85037,-9.3177147
145.3691,10.53869,2.0645511,0.0,0,7.2838039,0.0,0.14793147,115.72131,7.8858171,320.21262,-9.3179197
145.3713,10.738339,2.3475294,0.0,0,7.0067792,0.0,0.16946967,115.38693,7.6099243,323.57483,-9.3175106
145.3735,11.075734,2.5964847,0.0,0,6.7313671,0.0,0.19004583,116.64983,7.3476462,326.93707,-9.3165426
145.3757,11.323376,2.8528559,0.0,0,6.467802,0.0,0.2102128,116.88517,7.0896454,329.82333,-9.3168106
145.3779,11.603233,3.1070125,0.0,0,6.2042422,0.0,0.23212759,117.05003,6.8282499,327.95038,-9.3184175
145.3801,11.926579,3.3706622,0.0,0,5.9515953,0.0,0.25376701,117.77594,6.5675635,326.07742,-9.317584
145.3823,12.193755,3.6294537,0.0,0,5.7009277,0.0,0.27700081,117.70248,6.3057876,324.20447,-9.3166838
145.3845,12.507672,3.8993199,0.0,0,5.4572535,0.0,0.30009627,117.84545,6.0398889,322.33151,-9.3168325
145.3867,12.774173,4.1510382,0.0,0,5.2187734,0.0,0.32403404,117.63204,5.7771535,321.04495,-9.317977
145.3889,13.088636,4.4156847,0.0,0,4.9838042,0.0,0.34780997,117.68774,5.514277,320.2471,-9.3181925
145.3911,13.417318,4.6675911,0.0,0,4.7569842,0.0,0.37286207,117.56752,5.2615914,319.44925,-9.3179607
145.3933,13.735199,4.9186497,0.0,0,4.5305758,0.0,0.39624169,117.6039,5.0111837,318.65137,-9.3177319
145.3955,14.032694,5.151814,0.0,0,4.314702,0.0,0.42080492,117.20772,4.7738724,317.85352,-9.3167706
145.3977,14.34217,5.3864312,0.0,0,4.0989256,0.0,0.44396713,117.11584,4.5389438,319.08282,-9.3168993
145.3999,14.685917,5.6064162,0.0,0,3.8911293,0.0,0.46817032,117.00227,4.3149314,320.31213,-9.3165379
145.4021,15.007342,5.8337812,0.0,0,3.6859133,0.0,0.49126676,116.87939,4.0926709,321.54144,-9.3161869
145.4043,15.366473,6.0382953,0.0,0,3.4855206,0.0,0.51526433,116.8584,3.8802552,322.77075,-9.3160868
145.4065,15.724564,6.2530413,0.0,0,3.2902927,0.0,0.53843355,116.79343,3.675976,322.55798,-9.3161459
145.4087,16.125946,6.4511909,0.0,0,3.0970623,0.0,0.56250232,116.88738,3.4718559,320.61472,-9.316165
145.4109,16.560375,6.6561499,0.0,0,2.9113381,0.0,0.58526736,117.39417,3.2721286,318.67148,-9.3156424
145.4131,16.988848,6.8429961,0.0,0,2.7256143,0.0,0.60950279,117.51527,3.0732982,316.72824,-9.3157606
145.4153,17.460779,7.0403934,0.0,0,2.5483873,0.0,0.63278186,118.02245,2.8852725,314.78497,-9.3150387
145.4175,17.933977,7.2251706,0.0,0,2.3717272,0.0,0.6575346,118.27637,2.6998441,311.85495,-9.3133965
145.4197,18.43236,7.4119763,0.0,0,2.2008004,0.0,0.68014634,118.79517,2.5178378,308.82623,-9.3150759
145.4219,18.945105,7.5818205,0.0,0,2.0327644,0.0,0.70441365,119.26379,2.3392088,305.79752,-9.3146353
145.4241,19.50655,7.7663426,0.0,0,1.8679364,0.0,0.72814888,119.89538,2.1607919,302.7688,-9.3148289
145.4263,20.110659,7.9293227,0.0,0,1.7080843,0.0,0.75258809,120.57495,1.9871501,300.41663,-9.3143034
145.4285,20.735386,8.1134272,0.0,0,1.5491644,0.0,0.77713859,121.31517,1.8174876,299.24832,-9.3138037
145.4307,21.412228,8.2654352,0.0,0,1.3970973,0.0,0.80102974,122.27161,1.6561335,298.08005,-9.3138924
145.4329,22.101873,8.4294872,0.0,0,1.2450334,0.0,0.82438248,123.30135,1.495398,296.91177,-9.3134327
145.4351,22.842293,8.5814037,0.0,0,1.0992644,0.0,0.84922016,124.29264,1.3346519,295.74347,-9.3129148
145.4373,23.603542,8.7449684,0.0,0,0.95463634,0.0,0.87335223,125.43045,1.1831961,296.13904,-9.3113279
145.4395,24.396015,8.8808374,0.0,0,0.81407332,0.0,0.89690447,126.59723,1.0326653,296.88211,-9.3105688
145.4417,25.183384,9.0297203,0.0,0,0.67652941,0.0,0.92017579,127.70664,0.88812566,297.62515,-9.3114853
145.4439,26.007938,9.1600513,0.0,0,0.54098594,0.0,0.94363785,128.80324,0.74656904,298.36823,-9.3113441
145.4461,26.860298,9.3007555,0.0,0,0.41008592,0.0,0.96640432,130.01096,0.61340451,299.45294,-9.3103495
145.4483,27.791912,9.4143429,0.0,0,0.27942541,0.0,0.98810536,131.64165,0.48707059,301.44873,-9.3089638
145.4505,26.068012,9.4499512,0.0,0,0.15489216,0.0,0.99377006,122.99844,0.40124968,303.44452,-9.3105955
145.4527,24.505745,9.4630022,0.0,0,0.030416148,0.0,0.99707341,115.24502,0.36612055,305.44031,-9.3115444
145.4549,23.798889,9.4704323,0.0,0,-0.09173242,0.0,0.99730945,111.77059,0.34212071,307.43613,-9.3145313
145.4571,23.469412,9.4709625,0.0,0,-0.21312842,0.0,0.99848753,110.1346,0.30836836,309.55005,-9.3151217
145.4593,23.561695,9.4824038,0.0,0,-0.33452442,0.0,0.99971324,110.3839,0.25664273,311.70831,-9.315382
145.4615,23.683464,9.4823933,0.0,0,-0.45592043,0.0,1.0004616,110.85071,0.19906291,313.86658,-9.3162384
145.4637,23.705971,9.4987745,0.0,0,-0.5773164,0.0,1.0026078,110.75884,0.14337577,316.02481,-9.3158522
145.4659,23.62335,9.4945173,0.0,0,-0.69871235,0.0,1.0027492,110.36636,0.087311201,318.14835,-9.3163862
145.4681,23.455238,9.5039358,0.0,0,-0.82010835,0.0,1.0038168,109.44649,0.03612715,320.1156,-9.3163652
145.4703,23.236282,9.5033236,0.0,0,-0.94150436,0.0,1.0040107,108.42966,0.001311913,322.08282,-9.3164978
145.4725,22.936897,9.5131798,0.0,0,-1.0629004,0.0,1.0054696,106.87416,-0.032041796,324.05008,-9.3167839
145.4747,22.540552,9.5069027,0.0,0,-0.8433286,300.0,1.004739,105.08851,-0.047987889,326.0173,-9.3167648
145.4769,22.026894,9.5117245,0.0,0,-0.42304948,300.0,1.0055943,102.60907,-0.049366385,327.58594,-9.3191261
145.4791,21.515732,9.5139141,0.0,0,-0.0027700011,300.0,1.0057127,100.26161,-0.04360377,328.92676,-9.3195543
145.4813,21.075092,9.5196896,0.0,0,0.41750887,300.0,1.0069724,98.05574,-0.034697425,330.26761,-9.3183575
145.4835,20.715862,9.5126476,0.0,0,0.83778799,300.0,1.0054871,96.549118,-0.036101654,331.60843,-9.318881
145.4857,20.424145,9.5129728,0.0,0,1.2580678,300.0,1.0057619,95.158569,-0.033719148,332.91016,-9.3186684
145.4879,19.574984,9.5119286,0.0,0,1.6783465,300.0,1.0051807,91.312767,-0.010399036,333.82095,-9.3199291
145.4901,17.979603,9.514019,0.0,0,2.0986254,300.0,1.0061213,83.86171,0.056196444,334.73175,-9.3221998
145.4923,14.745029,9.4978094,0.0,0,2.5189049,300.0,1.0026926,69.312828,0.18373889,335.64255,-9.3231115
145.4945,9.3461285,9.4780312,0.0,0,2.9391842,300.0,0.99983335,44.697735,0.39661601,336.55334,-9.3261356
145.4967,0.5364359,9.2895088,0.0,0,3.3594635,300.0,0.96560615,2.5895269,0.81991851,337.12415,-9.3362808
145.4989,-0.46923646,9.2016811,0.0,0,3.7797422,300.0,0.95073223,-1.9936172,1.4704958,337.41159,-9.3360157
145.5011,-0.23797257,9.1623707,0.0,0,4.2000217,300.0,0.94332647,-1.3779887,2.2290137,337.69904,-9.3367701
145.5033,0.21552105,9.1811457,0.0,0,4.6203008,300.0,0.94735181,0.94518274,2.9142706,337.98648,-9.3354597
145.5055,-0.11489002,9.291378,0.0,0,5.0405803,300.0,0.96516573,-0.5232178,3.4530332,338.27393,-9.3349619
145.5077,3.0195539,9.4439106,0.0,0,5.4608593,300.0,0.9936763,12.588781,3.8636434,338.18701,-9.333787
145.5099,0.13796343,9.3852158,0.0,0,5.8811388,300.0,0.98204756,0.44851318,4.2444444,338.10013,-9.3329782
145.5121,0.045290437,9.3753471,0.0,0,6.3014183,300.0,0.98161268,0.29595947,4.6281796,338.01321,-9.332099
145.5143,0.14203852,9.4246778,0.0,0,6.7216969,300.0,0.98860538,0.45870197,5.0122457,337.9263,-9.3315372
145.5165,0.064620152,9.4212284,0.0,0,7.1419768,300.0,0.99017245,0.48215771,5.4072042,337.87585,-9.3286457
145.5187,0.40908283,9.4237452,0.0,0,7.5622554,300.0,0.98857862,1.76087,5.8216848,337.86917,-9.3284225
145.5209,0.44171864,9.418457,0.0,0,7.9825354,300.0,0.98953712,2.0546145,6.2708955,337.86249,-9.3283701
145.5231,0.49514213,9.4229631,0.0,0,8.4028139,300.0,0.98838383,2.3437812,6.7206831,337.8558,-9.3278418
145.5253,0.47273052,9.4235249,0.0,0,8.8230925,300.0,0.99042141,2.2402849,7.1646981,337.84912,-9.3281813
145.5275,0.38866872,9.4283314,0.0,0,9.243372,300.0,0.98919618,1.8099674,7.5985117,337.9093,-9.3279276
145.5297,0.46714154,9.4209566,0.0,0,9.6636515,300.0,0.99005985,2.2006834,8.0429688,337.97614,-9.3260698
145.5319,0.50661802,9.4230528,0.0,0,10.083931,300.0,0.98849738,2.3402729,8.4729042,338.043,-9.3260593
145.5341,0.44224149,9.4228621,0.0,0,10.50421,300.0,0.99043077,2.0920434,8.9033241,338.10986,-9.3266621
145.5363,0.46349239,9.427454,0.0,0,10.924489,300.0,0.9889459,2.2470572,9.3330441,338.12323,-9.3261938
145.5385,0.44942662,9.4205751,0.0,0,11.344769,300.0,0.99010229,2.1377242,9.7589741,338.04303,-9.3251152
145.5407,0.48789349,9.422533,0.0,0,11.765047,300.0,0.98834127,2.2950985,10.197603,337.9628,-9.3245726
145.5429,0.48144364,9.4199896,0.0,0,12.185327,300.0,0.98997003,2.3435297,10.627394,337.88257,-9.3237457
145.5451,0.46593755,9.4295645,0.0,0,12.605606,300.0,0.98940766,2.1720722,11.065817,337.80237,-9.325695
145.5473,0.46660322,9.4170275,0.0,0,13.025885,300.0,0.98947603,2.247489,11.492021,337.71121,-9.3251696
145.5495,0.45056769,9.4254103,0.0,0,13.446164,300.0,0.98868865,2.1098228,11.908763,337.61761,-9.3253107
145.5517,0.50535035,9.4178209,0.0,0,13.866444,300.0,0.98975354,2.408967,12.326803,337.52402,-9.3225012
145.5539,0.4528667,9.4288607,0.0,0,14.286723,300.0,0.98914981,2.1547103,12.748358,337.43042,-9.3240919
145.5561,0.46273568,9.4227858,0.0,0,14.707002,300.0,0.99067199,2.2014246,13.184116,337.37329,-9.3252096
145.5583,0.48246014,9.4265146,0.0,0,15.127281,300.0,0.98897886,2.2858708,13.624713,337.41342,-9.3254032
145.5605,0.50428474,9.4197683,0.0,0,15.547561,300.0,0.99009866,2.3583367,14.059277,337.45352,-9.3241892
145.5627,0.49193603,9.4305773,0.0,0,15.967839,300.0,0.98929143,2.3595119,14.486333,337.49362,-9.3239956
145.5649,0.47949132,9.4173784,0.0,0,16.388119,300.0,0.989573,2.2630167,14.907063,337.53375,-9.3222008
145.5671,0.4723877,9.4250927,0.0,0,16.808399,300.0,0.98887289,2.2488048,15.330815,337.62732,-9.3228931
145.5693,0.48232839,9.4196043,0.0,0,17.228678,300.0,0.99016041,2.2342944,15.75178,337.74097,-9.3235464
145.5715,0.48152685,9.4300547,0.0,0,17.648958,300.0,0.9893502,2.3020527,16.173807,337.85461,-9.3236723
145.5737,0.45533177,9.4221506,0.0,0,17.999975,300.0,0.99026835,2.1894383,16.593046,337.96823,-9.3228197
145.5759,0.46541145,9.4277391,0.0,0,18.0,300.0,0.98931986,2.2422919,17.020975,338.08554,-9.3214779
145.5781,0.47130018,9.4175348,0.0,0,18.0,300.0,0.98970038,2.2568665,17.425394,338.21924,-9.322134
145.5803,0.50596327,9.4337578,0.0,0,18.0,300.0,0.99005908,2.383184,17.785492,338.35294,-9.3238201
145.5825,0.51162267,9.4175272,0.0,0,18.0,300.0,0.98946559,2.3784499,18.104284,338.48663,-9.3260956
145.5847,0.53188711,9.4262533,0.0,0,18.0,300.0,0.98907012,2.5221672,18.346495,338.62033,-9.3270426
145.5869,0.5484367,9.4202089,0.0,0,18.0,300.0,0.98994291,2.6296308,18.501532,338.7753,-9.3299618
145.5891,0.58173954,9.4320002,0.0,0,18.0,300.0,0.9897877,2.7632205,18.550142,338.94241,-9.3354969
145.5913,0.63250363,9.4211168,0.0,0,18.0,300.0,0.9900443,2.957164,18.490847,339.10953,-9.3417959
145.5935,0.61071122,9.427906,0.0,0,18.0,300.0,0.98945844,2.9240253,18.35651,339.27667,-9.3520651
145.5957,0.5624333,9.4193754,0.0,0,18.0,300.0,0.98973435,2.6708353,18.222916,339.44135,-9.3626442
145.5979,0.54543912,9.4298763,0.0,0,18.0,300.0,0.98970193,2.5839012,18.118793,339.58173,-9.3770561
145.6001,0.55125409,9.417201,0.0,0,18.0,300.0,0.98922914,2.5929506,18.054649,339.72214,-9.3941946
145.6023,0.5683313,9.4226913,0.0,0,18.0,300.0,0.98865777,2.6700168,18.037264,339.86252,-9.4104815
145.6045,0.56353921,9.412962,0.0,0,18.0,300.0,0.98831952,2.6516252,18.034367,340.0029,-9.4275427
145.6067,0.58096516,9.4246893,0.0,0,18.0,300.0,0.9886896,2.7629828,18.054729,340.10681,-9.4471283
145.6089,0.58015764,9.4148493,0.0,0,18.0,300.0,0.98850209,2.7484183,18.081474,340.18036,-9.4655857
145.6111,0.5715822,9.4205379,0.0,0,18.0,300.0,0.98852569,2.7324936,18.102848,340.25388,-9.4837904
145.6133,0.55929792,9.4165926,0.0,0,18.0,300.0,0.98873019,2.6797252,18.122208,340.32742,-9.5011625
145.6155,0.55537546,9.4250145,0.0,0,18.0,300.0,0.98905551,2.6371088,18.139053,340.40094,-9.5157824
145.6177,0.57050657,9.4152517,0.0,0,18.0,300.0,0.98849881,2.7113364,18.144775,340.5079,-9.5308237
145.6199,0.57441533,9.4203815,0.0,0,18.0,300.0,0.98868042,2.7060649,18.144142,340.61487,-9.5444078
145.6221,0.58478397,9.4152937,0.0,0,18.0,300.0,0.98823398,2.7853308,18.146027,340.7218,-9.5605669
145.6243,0.60093671,9.4259987,0.0,0,18.0,300.0,0.98951995,2.8478603,18.142582,340.82877,-9.5772219
145.6265,0.60775632,9.4162636,0.0,0,18.0,300.0,0.98844534,2.8824439,18.143923,340.94485,-9.5928459
145.6287,0.59812003,9.4212914,0.0,0,18.0,300.0,0.98904389,2.8397946,18.135754,341.07187,-9.6078176
145.6309,0.58441329,9.417779,0.0,0,18.0,300.0,0.98866427,2.7902863,18.133284,341.19888,-9.6240034
145.6331,0.57999748,9.4265223,0.0,0,18.0,300.0,0.98998493,2.7470329,18.131872,341.3259,-9.6400499
145.6353,0.57168174,9.4195757,0.0,0,18.0,300.0,0.98871303,2.6929705,18.128046,341.45291,-9.6557283
145.6375,0.56934911,9.418375,0.0,0,18.0,300.0,0.9885813,2.6980393,18.128601,341.57385,-9.6706934
145.6397,0.58526945,9.4161291,0.0,0,18.0,300.0,0.98798978,2.7641771,18.121794,341.69418,-9.6860094
145.6419,0.60833925,9.4224768,0.0,0,18.0,300.0,0.98947698,2.8467011,18.118151,341.81451,-9.7007971
145.6441,0.62452698,9.4173365,0.0,0,18.0,300.0,0.9882611,2.945895,18.116564,341.93484,-9.7162809
145.6463,0.61446989,9.4228945,0.0,0,18.0,300.0,0.98969507,2.9337916,18.115484,342.05273,-9.7345686
145.6485,0.5912829,9.4158878,0.0,0,18.0,300.0,0.98789722,2.8560357,18.116035,342.16638,-9.7511244
145.6507,0.58742648,9.42344,0.0,0,18.0,300.0,0.98975253,2.7897947,18.11437,342.28003,-9.7680283
145.6529,0.57231539,9.4168158,0.0,0,18.0,300.0,0.98783332,2.7104886,18.110416,342.39365,-9.7835407
145.6551,0.56737274,9.4161892,0.0,0,18.0,300.0,0.98861688,2.6971154,18.110514,342.50729,-9.7993956
145.6573,0.57398039,9.4162416,0.0,0,18.0,300.0,0.98794925,2.7641184,18.10885,342.61548,-9.8155642
145.6595,0.59524524,9.4229994,0.0,0,18.0,300.0,0.98999876,2.7836006,18.105118,342.72244,-9.8319426
145.6617,0.60280401,9.4208603,0.0,0,18.0,300.0,0.98837435,2.8537786,18.103159,342.82941,-9.8475542
145.6639,0.61704332,9.4162035,0.0,0,18.0,300.0,0.98865426,2.9167185,18.101809,342.93637,-9.862257
145.6661,0.59439188,9.4154291,0.0,0,18.0,300.0,0.98743898,2.8174694,18.10446,343.03604,-9.8776712
145.6683,0.57075053,9.4193888,0.0,0,18.0,300.0,0.989595,2.7094016,18.101448,343.11624,-9.8945255
145.6705,0.56269664,9.422368,0.0,0,18.0,300.0,0.98849118,2.6580834,18.09901,343.19647,-9.909749
145.6727,0.56605953,9.4176846,0.0,0,18.0,300.0,0.98916268,2.6917026,18.09841,343.2767,-9.9254789
145.6749,0.5636605,9.4192915,0.0,0,18.0,300.0,0.98799074,2.6826162,18.101616,343.3569,-9.9402847
145.6771,0.59022605,9.4223881,0.0,0,18.0,300.0,0.99029857,2.7768531,18.098959,343.43225,-9.9563904
145.6793,0.59715265,9.4214935,0.0,0,18.0,300.0,0.9881075,2.8298161,18.095911,343.5058,-9.9740858
145.6815,0.60263497,9.4165173,0.0,0,18.0,300.0,0.98902828,2.8881307,18.098351,343.57932,-9.9894114
145.6837,0.60863185,9.4190369,0.0,0,18.0,300.0,0.98784977,2.8814929,18.100216,343.65286,-10.005292
145.6859,0.58239305,9.420042,0.0,0,18.0,300.0,0.98993456,2.7741561,18.101532,343.73245,-10.020195
145.6881,0.57546115,9.4255943,0.0,0,18.0,300.0,0.98888409,2.7092805,18.091982,343.83942,-10.035913
145.6903,0.56487113,9.4168558,0.0,0,18.0,300.0,0.98919684,2.7069218,18.097057,343.94638,-10.052418
145.6925,0.57293123,9.4175406,0.0,0,18.0,300.0,0.98745304,2.7138114,18.096148,344.05334,-10.068023
145.6947,0.59128076,9.4182005,0.0,0,18.0,300.0,0.98969603,2.7612116,18.095522,344.16031,-10.083194
145.6969,0.60525739,9.4251299,0.0,0,18.0,300.0,0.98858249,2.8572054,18.093607,344.25449,-10.099144
145.6991,0.6343264,9.4162779,0.0,0,18.0,300.0,0.98916507,2.9863245,18.090801,344.3414,-10.113648
145.7013,0.6214385,9.4207392,0.0,0,18.0,300.0,0.9879142,2.9483149,18.092083,344.42831,-10.130102
145.7035,0.61772048,9.4175825,0.0,0,18.0,300.0,0.98970217,2.9215894,18.088619,344.5152,-10.147361
145.7057,0.58548856,9.4232712,0.0,0,18.0,300.0,0.98813874,2.7672625,18.086546,344.59967,-10.164658
145.7079,0.57902843,9.4174528,0.0,0,18.0,300.0,0.98963469,2.7671542,18.086008,344.65985,-10.179301
145.7101,0.58277023,9.4195709,0.0,0,18.0,300.0,0.98772228,2.7909877,18.086334,344.72,-10.193386
145.7123,0.58971673,9.4151688,0.0,0,18.0,300.0,0.98936671,2.7733076,18.08456,344.78015,-10.208418
145.7145,0.61052114,9.4234524,0.0,0,18.0,300.0,0.98800153,2.9031549,18.085295,344.84033,-10.225733
145.7167,0.63216758,9.4144497,0.0,0,18.0,300.0,0.98895353,2.9544501,18.084431,344.91873,-10.241094
145.7189,0.63930279,9.4238644,0.0,0,18.0,300.0,0.98838979,3.0286639,18.082756,345.01233,-10.258232
145.7211,0.61645013,9.4170675,0.0,0,18.0,300.0,0.98945946,2.9306116,18.084915,345.1059,-10.2737
145.7233,0.60435462,9.427289,0.0,0,18.0,300.0,0.98874098,2.894454,18.082708,345.19949,-10.290781
145.7255,0.57206166,9.4188051,0.0,0,18.0,300.0,0.9897216,2.7311044,18.084179,345.29309,-10.307632
145.7277,0.5772565,9.4221087,0.0,0,18.0,300.0,0.98825407,2.7444243,18.080978,345.38669,-10.323293
145.7299,0.57650942,9.4140682,0.0,0,18.0,300.0,0.98897803,2.7367463,18.079811,345.48029,-10.336279
145.7321,0.61332476,9.4256277,0.0,0,18.0,300.0,0.98848283,2.866641,18.080145,345.57385,-10.351807
145.7343,0.62274146,9.4173651,0.0,0,18.0,300.0,0.98956537,2.9184947,18.082653,345.66745,-10.368963
145.7365,0.63629884,9.4234142,0.0,0,18.0,300.0,0.98855978,2.9900503,18.080332,345.74283,-10.385162
145.7387,0.62286603,9.4186878,0.0,0,18.0,300.0,0.98971319,2.9591963,18.080124,345.7963,-10.402243
145.7409,0.60838389,9.4263668,0.0,0,18.0,300.0,0.98880589,2.9283364,18.078651,345.84976,-10.417295
145.7431,0.58250755,9.4177036,0.0,0,18.0,300.0,0.98945719,2.7800503,18.080853,345.90323,-10.430183
145.7453,0.57077616,9.4265366,0.0,0,18.0,300.0,0.98929369,2.7198813,18.076128,345.95673,-10.447642
145.7475,0.57487375,9.4178896,0.0,0,18.0,300.0,0.98960906,2.7113316,18.077116,346.01627,-10.463226
145.7497,0.58165914,9.4253988,0.0,0,18.0,300.0,0.9886744,2.7300215,18.078854,346.07645,-10.480446
145.7519,0.60310155,9.4140282,0.0,0,18.0,300.0,0.98859042,2.8729618,18.078712,346.1366,-10.495075
145.7541,0.63062239,9.4221869,0.0,0,18.0,300.0,0.98849559,2.9574928,18.07514,346.19675,-10.511092
145.7563,0.62940186,9.4171076,0.0,0,18.0,300.0,0.98940688,2.9868927,18.075081,346.26178,-10.525847
145.7585,0.62152332,9.4276896,0.0,0,18.0,300.0,0.98923808,2.9666052,18.073481,346.33533,-10.542683
145.7607,0.58376449,9.4184008,0.0,0,18.0,300.0,0.98938787,2.8028574,18.079523,346.40884,-10.558269
145.7629,0.58369946,9.4259081,0.0,0,18.0,300.0,0.98927373,2.7641239,18.077082,346.48236,-10.574364
145.7651,0.57617015,9.4142637,0.0,0,18.0,300.0,0.98867023,2.732816,18.07498,346.55591,-10.590633
145.7673,0.59144241,9.4236135,0.0,0,18.0,300.0,0.98872226,2.7746413,18.06995,346.61304,-10.606224
145.7695,0.6033023,9.416769,0.0,0,18.0,300.0,0.98877001,2.8436532,18.071733,346.6665,-10.622808
145.7717,0.63268214,9.4220886,0.0,0,18.0,300.0,0.98862875,2.9575777,18.070375,346.72,-10.639773
145.7739,0.64593518,9.4159784,0.0,0,18.0,300.0,0.98849976,3.04968,18.070829,346.77347,-10.655197
145.7761,0.6329512,9.4269123,0.0,0,18.0,300.0,0.98952782,3.0034721,18.072548,346.8233,-10.669462
145.7783,0.62180144,9.4197454,0.0,0,18.0,300.0,0.98922133,2.9495981,18.069221,346.86343,-10.685257
145.7805,0.59004664,9.4267426,0.0,0,18.0,300.0,0.98981041,2.8339379,18.067511,346.90353,-10.701779
145.7827,0.57897085,9.4182081,0.0,0,18.0,300.0,0.98883504,2.7317646,18.068941,346.94363,-10.717952
145.7849,0.58259749,9.4250803,0.0,0,18.0,300.0,0.98943275,2.7804098,18.069292,346.98376,-10.734129
145.7871,0.60285616,9.4187555,0.0,0,18.0,300.0,0.98893112,2.8489323,18.065668,347.02386,-10.748402
145.7893,0.63383657,9.4240856,0.0,0,18.0,300.0,0.98939008,2.9849811,18.062546,347.064,-10.763373
145.7915,0.64295846,9.4190407,0.0,0,18.0,300.0,0.98877895,3.0918984,18.06266,347.1041,-10.781283
145.7937,0.63527244,9.4278803,0.0,0,18.0,300.0,0.99009007,2.9969184,18.064981,347.14423,-10.797646
145.7959,0.63142467,9.4218941,0.0,0,18.0,300.0,0.98927772,2.9968493,18.062637,347.18283,-10.81319
145.7981,0.60496551,9.4238453,0.0,0,18.0,300.0,0.98940891,2.8158512,18.062489,347.21466,-10.829157
145.8003,0.59249473,9.4175091,0.0,0,18.0,300.0,0.98831481,2.8317494,18.06218,347.24649,-10.843702
145.8025,0.58193713,9.4257364,0.0,0,18.0,300.0,0.98999941,2.7333534,18.063797,347.27832,-10.85989
145.8047,0.59759796,9.4204311,0.0,0,18.0,300.0,0.9887715,2.8363943,18.063337,347.31015,-10.875841
145.8069,0.61634016,9.4204082,0.0,0,18.0,300.0,0.98914105,2.8968754,18.061949,347.35083,-10.892706
145.8091,0.6340279,9.4166927,0.0,0,18.0,300.0,0.98804188,3.0373738,18.059828,347.4043,-10.907722
145.8113,0.65457839,9.4262619,0.0,0,18.0,300.0,0.99029976,3.0761917,18.060566,347.45776,-10.923634
145.8135,0.63329262,9.422904,0.0,0,18.0,300.0,0.98892426,3.005389,18.060444,347.51126,-10.940448
145.8157,0.60574013,9.4196091,0.0,0,18.0,300.0,0.98899966,2.9043939,18.059643,347.56473,-10.956661
145.8179,0.59917748,9.4167519,0.0,0,18.0,300.0,0.98794162,2.8570671,18.05987,347.60666,-10.972222
145.8201,0.58155358,9.4204187,0.0,0,18.0,300.0,0.98951447,2.7546396,18.05868,347.64679,-10.98727
145.8223,0.58108938,9.41959,0.0,0,18.0,300.0,0.98829633,2.7605674,18.056326,347.68689,-11.001584
145.8245,0.6185196,9.4205637,0.0,0,18.0,300.0,0.98956627,2.8870184,18.057205,347.72702,-11.0183
145.8267,0.64082897,9.4206057,0.0,0,18.0,300.0,0.98825485,3.0601718,18.059969,347.75223,-11.034493
145.8289,0.64588964,9.4233332,0.0,0,18.0,300.0,0.98987538,3.0537019,18.057344,347.74554,-11.049767
145.8311,0.64718837,9.4235544,0.0,0,18.0,300.0,0.98870355,3.0797732,18.054342,347.73886,-11.065255
145.8333,0.61903071,9.4213476,0.0,0,18.0,300.0,0.98971957,2.9722447,18.052801,347.73218,-11.081717
145.8355,0.60663956,9.4228764,0.0,0,18.0,300.0,0.98863131,2.8654311,18.054871,347.72549,-11.097563
145.8377,0.59931052,9.423543,0.0,0,18.0,300.0,0.99052107,2.8073373,18.050859,347.72913,-11.112354
145.8399,0.58858317,9.4246092,0.0,0,18.0,300.0,0.98884302,2.8001916,18.054062,347.73581,-11.128573
145.8421,0.60469657,9.4175835,0.0,0,18.0,300.0,0.98923963,2.8268352,18.050127,347.74249,-11.1448
145.8443,0.64105201,9.420557,0.0,0,18.0,300.0,0.98800176,2.9871552,18.050663,347.74918,-11.160257
145.8465,0.65430599,9.4213715,0.0,0,18.0,300.0,0.99016905,3.0784729,18.049248,347.76193,-11.176481
145.8487,0.65063572,9.4262133,0.0,0,18.0,300.0,0.98877257,3.1010118,18.052904,347.79535,-11.192472
145.8509,0.64343303,9.4204578,0.0,0,18.0,300.0,0.98991621,3.0657063,18.054111,347.8288,-11.209515
145.8531,0.61724997,9.4222279,0.0,0,18.0,300.0,0.98831379,2.9260757,18.048414,347.86221,-11.223813
145.8553,0.59814388,9.4208422,0.0,0,18.0,300.0,0.99016768,2.8352284,18.049179,347.89563,-11.239854
145.8575,0.59550369,9.4254475,0.0,0,18.0,300.0,0.98882633,2.8401906,18.047112,347.93362,-11.256829
145.8597,0.59434474,9.416605,0.0,0,18.0,300.0,0.98938221,2.8095491,18.051252,347.97372,-11.273023
145.8619,0.62499261,9.4231377,0.0,0,18.0,300.0,0.98841953,2.9155378,18.053057,348.01385,-11.288397
145.8641,0.65298122,9.4210892,0.0,0,18.0,300.0,0.99010628,3.0802438,18.050127,348.05396,-11.303617
145.8663,0.66745126,9.4261389,0.0,0,18.0,300.0,0.98854226,3.1629713,18.048325,348.09042,-11.320049
145.8685,0.65644783,9.4180508,0.0,0,18.0,300.0,0.98963523,3.1059763,18.049389,348.10379,-11.334054
145.8707,0.6240446,9.4209328,0.0,0,18.0,300.0,0.98793942,2.9824994,18.047647,348.11716,-11.35025
145.8729,0.61303777,9.4189262,0.0,0,18.0,300.0,0.98997873,2.8907495,18.0513,348.13052,-11.367491
146.7732,0.569336,9.4272738,0.0,0,18.0,1.6216742e-10,0.99019212,2.692023,18.00029,322.00287,-11.483776
147.8732,0.54417223,9.4340286,0.0,0,18.0,1.6196896e-25,0.99146354,2.5735905,18.000177,305.61227,-11.483623
148.9732,0.52831626,9.4394522,0.0,0,18.0,1.617715e-40,0.99228674,2.4910383,17.999285,294.61072,-11.483349
150.0732,0.51543987,9.4447651,0.0,0,18.0,1.4012985e-45,0.99335533,2.4356542,18.000053,285.79727,-11.483705
151.1732,0.51104075,9.4496355,0.0,0,18.0,1.4012985e-45,0.99417925,2.4119737,17.999712,284.69495,-11.483689
152.2732,0.51309222,9.4544783,0.0,0,18.0,1.4012985e-45,0.99510193,2.4153094,18.000118,277.53226,-11.483448
153.3732,0.50502414,9.4590549,0.0,0,18.0,1.4012985e-45,0.99584705,2.3729084,17.999996,270.13757,-11.483271
154.4732,0.50341278,9.4633589,0.0,0,18.0,1.4012985e-45,0.99667376,2.3652034,17.999672,262.98288,-11.483301
155.5732,0.51219487,9.4672832,0.0,0,18.0,1.4012985e-45,0.99744284,2.4043798,17.999979,256.02148,-11.483348
156.6732,0.5109787,9.4714165,0.0,0,18.0,1.4012985e-45,0.9980337,2.3996816,18.001015,249.53867,-11.483492
157.7732,0.50924736,9.475935,0.0,0,18.0,1.4012985e-45,0.99898118,2.3856537,18.000162,242.66499,-11.48377
158.8732,0.50296366,9.4799004,0.0,0,18.0,1.4012985e-45,0.99964696,2.3572001,18.000645,236.50726,-11.483984
159.9732,0.50160295,9.4833431,0.0,0,18.0,1.4012985e-45,1.0002925,2.3511288,17.999422,230.39333,-11.484008
161.0732,0.5067637,9.4869194,0.0,0,18.0,1.4012985e-45,1.0008565,2.373138,18.000156,224.01027,-11.483902
162.1732,0.50270987,9.4905443,0.0,0,18.0,1.4012985e-45,1.001592,2.3476563,17.999184,218.13264,-11.483842
163.2732,0.4960306,9.4944344,0.0,0,18.0,1.4012985e-45,1.0023569,2.3128767,17.999323,211.28601,-11.483808
164.3732,0.50139123,9.4975471,0.0,0,18.0,1.4012985e-45,1.0027713,2.3438375,17.999825,204.17577,-11.483343
165.4732,0.50561583,9.5009089,0.0,0,18.0,1.4012985e-45,1.0035194,2.3627498,17.999475,198.48891,-11.483699
166.5732,0.49448225,9.5044947,0.0,0,18.0,1.4012985e-45,1.0041132,2.3057959,17.999453,192.87454,-11.483155
167.6732,0.49687845,9.5073452,0.0,0,18.0,1.4012985e-45,1.004654,2.3167446,18.001221,187.97708,-11.483791
168.7732,0.49743545,9.5104256,0.0,0,18.0,1.4012985e-45,1.0051353,2.3198807,18.000162,183.04915,-11.483578
169.8732,0.50231713,9.5135965,0.0,0,18.0,1.4012985e-45,1.0057857,2.3383279,17.999937,177.5663,-11.483767
170.9732,0.50486326,9.5158157,0.0,0,18.0,1.4012985e-45,1.0062511,2.3503985,18.000065,171.82149,-11.483694
172.0732,0.49655405,9.5189419,0.0,0,18.0,1.4012985e-45,1.0066909,2.3067911,17.999859,167.14999,-11.4835
173.1732,0.49501842,9.5227222,0.0,0,18.0,1.4012985e-45,1.0074673,2.3031034,17.998884,162.27498,-11.483655
174.2732,0.50130677,9.5254164,0.0,0,18.0,1.4012985e-45,1.0078923,2.3265591,17.999321,158.08875,-11.483815
175.3732,0.49777487,9.5276451,0.0,0,18.0,1.4012985e-45,1.0083922,2.3085644,18.001232,154.2654,-11.483703
176.4732,0.49319151,9.5302496,0.0,0,18.0,1.4012985e-45,1.0087367,2.2925606,18.000471,150.68599,-11.483486
177.5732,0.49325821,9.5329704,0.0,0,18.0,1.4012985e-45,1.0093424,2.2920828,17.998682,147.15981,-11.483924
178.6732,0.49938774,9.5355692,0.0,0,18.0,1.4012985e-45,1.0098498,2.3147273,18.0005,143.51189,-11.483818
179.7732,0.4997299,9.5381584,0.0,0,18.0,1.4012985e-45,1.0102028,2.3143945,18.000006,140.22575,-11.483871
180.8732,0.4867397,9.5405397,0.0,0,18.0,1.4012985e-45,1.0107393,2.2577353,18.000175,136.99663,-11.483845
181.9732,0.48936638,9.5423584,0.0,0,18.0,1.4012985e-45,1.0110052,2.2680418,18.000811,134.18535,-11.484
183.0732,0.49380925,9.5453558,0.0,0,18.0,1.4012985e-45,1.011644,2.2849281,18.001135,130.9563,-11.483724
184.1732,0.49501231,9.5475531,0.0,0,18.0,1.4012985e-45,1.0118977,2.2907147,17.999931,128.00049,-11.483658
185.2732,0.49504977,9.5498857,0.0,0,18.0,1.4012985e-45,1.0124594,2.2914901,18.000784,125.06032,-11.48358
186.3732,0.48923701,9.551198,0.0,0,18.0,1.4012985e-45,1.0127257,2.2665725,18.00013,122.60188,-11.48351
187.4732,0.49608034,9.5539627,0.0,0,18.0,1.4012985e-45,1.013111,2.29598,18.000204,119.89371,-11.483339
188.5732,0.49681124,9.5561895,0.0,0,18.0,1.4012985e-45,1.0135857,2.2900314,18.000658,117.08118,-11.483871
189.6732,0.48509786,9.5578966,0.0,0,18.0,1.4012985e-45,1.0138491,2.2384984,17.999741,114.38876,-11.483169
190.7732,0.49298868,9.559617,0.0,0,18.0,1.4012985e-45,1.0142629,2.2770145,17.999775,112.09151,-11.483607
191.8732,0.48936576,9.5618515,0.0,0,18.0,1.4012985e-45,1.0145432,2.2602775,18.000013,109.66082,-11.483486
192.9732,0.48917383,9.5638371,0.0,0,18.0,1.4012985e-45,1.0150311,2.2550364,18.000486,107.14271,-11.483121
194.0732,0.48223197,9.5652666,0.0,0,18.0,1.4012985e-45,1.0152683,2.2266653,18.000618,104.79335,-11.483107
195.1732,0.49390537,9.5670815,0.0,0,18.0,1.4012985e-45,1.0155452,2.2860491,17.9998,102.6152,-11.483294
196.2732,0.49605924,9.5689173,0.0,0,18.0,1.4012985e-45,1.0158731,2.2893035,17.999313,100.30163,-11.48336
197.3732,0.49384084,9.5703182,0.0,0,18.0,1.4012985e-45,1.0161637,2.2702672,17.999746,98.086929,-11.482742
198.4732,0.48342964,9.5715656,0.0,0,18.0,1.4012985e-45,1.0164666,2.2265644,17.99992,96.083183,-11.48306
199.5732,0.4866052,9.5738173,0.0,0,18.0,1.4012985e-45,1.0167471,2.2447195,17.999987,94.07164,-11.483118
200.6732,0.48984471,9.575181,0.0,0,18.0,1.4012985e-45,1.0171145,2.2559619,17.999924,92.28775,-11.482692
201.7732,0.48537081,9.5765858,0.0,0,18.0,1.4012985e-45,1.0173073,2.2316313,18.000677,90.215225,-11.482936
202.8732,0.48138449,9.5778322,0.0,0,18.0,1.4012985e-45,1.0175831,2.2168138,18.000151,88.418282,-11.482715
203.9732,0.48378348,9.5796824,0.0,0,18.0,1.4012985e-45,1.0178075,2.2293129,18.000038,86.67218,-11.48292
205.0732,0.48875609,9.5807076,0.0,0,18.0,1.4012985e-45,1.018149,2.2448897,17.999981,84.914581,-11.482745
205.8732,0.48738119,9.5818949,0.0,0,18.0,1.4012985e-45,1.0182773,2.242707,18.000626,83.732704,-11.482987