File: examples/dan-msc-case-studies/CS3/data/01 raw data/baron_test_122.csv
Time(sec),Force(kN),Jaw(mm),PowAngle(deg),Power(W),Pram,PTemp,Strain,Stress(MPa),Stroke(mm),TC1(C),wedge(mm)
0.0,1.0744121,0.30510122,0.0,0,11.076097,0.00014354833,0.020527404,13.41598,11.075773,23.814976,-9.1257524
1.2,1.0161275,-0.0025203307,0.0,0,11.076097,3.5159011,-0.00018033326,12.936458,11.077433,23.788065,-9.4950342
2.4,0.98019099,-0.0028445951,0.0,0,11.076097,7.115901,-0.00020840671,12.486165,11.075281,23.761909,-9.49195
3.6,0.96494615,-0.0027489653,0.0,0,11.076097,10.715899,-0.00020202193,12.297031,11.07691,23.745377,-9.4903507
4.8,0.9401232,-0.0025639506,0.0,0,11.076097,14.315902,-0.00018526294,11.967238,11.0749,23.747442,-9.4875345
6.0,0.92217803,-0.0031780223,0.0,0,11.076097,17.915905,-0.0002346121,11.748259,11.075889,23.724836,-9.4857893
7.2,0.90973413,-0.0031792542,0.0,0,11.076097,21.515905,-0.00023053506,11.57243,11.075488,23.643372,-9.4833498
8.4,0.89482796,-0.0031199427,7.7154298,0,11.076097,25.115904,-0.00023250814,11.395072,11.076392,23.667446,-9.4806318
9.6,0.89805734,-0.0021245906,26.806923,0,11.076097,28.715904,-0.00016097381,11.41515,11.075788,23.789515,-9.4790125
10.8,0.90473819,-0.0037865937,36.983643,0,11.076097,32.315903,-0.00027623973,11.531106,11.076083,25.164125,-9.4771175
12.0,0.92981356,-0.008134596,42.375401,0,11.076097,35.915913,-0.0005580521,11.829883,11.07606,28.279617,-9.4749947
13.2,0.93835604,-0.012686156,44.997025,0,11.076097,39.515911,-0.00086613948,11.945463,11.077137,32.960976,-9.4729023
14.4,0.94574976,-0.017819721,45.557339,0,11.076097,43.115917,-0.0012109948,12.066786,11.075921,38.6096,-9.4705896
15.6,0.96559173,-0.022898396,44.720604,0,11.076097,46.715916,-0.0015407668,12.300228,11.076912,44.374805,-9.4686785
16.8,0.97816133,-0.026473189,43.527878,0,11.076097,50.315914,-0.0017838264,12.490354,11.076811,49.924957,-9.466464
18.0,0.98066759,-0.029707422,41.434723,0,11.076097,53.91592,-0.0019908543,12.517725,11.075855,54.949181,-9.4639807
19.2,0.96950728,-0.032291908,39.257442,0,11.076097,57.515926,-0.002178635,12.376252,11.076609,59.546322,-9.4622593
20.4,0.96952897,-0.034659617,38.17841,0,11.076097,61.115929,-0.0023192251,12.384641,11.07637,62.991051,-9.4599972
21.6,0.95440286,-0.035539936,38.551022,0,11.076097,64.715919,-0.0023827623,12.173428,11.075122,65.529976,-9.457736
22.8,0.96409047,-0.038202349,40.325966,0,11.076097,68.315903,-0.0025545286,12.315754,11.075503,67.944725,-9.4554653
24.0,0.97009939,-0.040856253,41.801659,0,11.076097,71.915916,-0.0027348464,12.379146,11.075383,70.758987,-9.4534864
25.2,0.97160786,-0.04464687,42.97842,0,11.076097,75.5159,-0.002983636,12.407383,11.075857,74.020447,-9.4513054
26.4,0.98356718,-0.046389267,43.527267,0,11.076097,79.115913,-0.003089197,12.558696,11.075705,77.857208,-9.4494467
27.6,0.98153043,-0.049966801,44.577766,0,11.076097,82.715912,-0.0033353497,12.535109,11.076976,81.105415,-9.4473019
28.8,0.98949659,-0.053409755,45.182426,0,11.076097,86.315918,-0.0035558711,12.659567,11.076281,84.670586,-9.4447985
30.0,0.99841398,-0.058046009,45.716663,0,11.076097,89.915916,-0.0038740656,12.776919,11.07542,88.452171,-9.4425793
31.2,1.0046334,-0.05999431,46.107479,0,11.076097,93.51593,-0.0039971108,12.836966,11.076129,92.536903,-9.4406357
32.4,1.0018027,-0.064199358,45.615238,0,11.076097,97.115921,-0.0042746053,12.820643,11.075845,96.664719,-9.4378748
33.6,1.0122221,-0.067689367,45.437889,0,11.076097,100.71593,-0.0045068623,12.961305,11.076925,100.72166,-9.435709
34.8,1.0085523,-0.072002083,44.604645,0,11.076097,104.31592,-0.0047883452,12.885791,11.075607,104.84042,-9.4338837
36.0,1.0086809,-0.072973169,44.077152,0,11.076097,107.91594,-0.0048462274,12.92707,11.076297,108.71239,-9.4317999
37.2,1.0134196,-0.076011874,44.077152,0,11.076097,111.51592,-0.0050440691,12.959654,11.074365,111.99635,-9.4295816
38.4,1.0049455,-0.078406014,44.479481,0,11.076097,115.11594,-0.0052064937,12.864033,11.076207,115.18665,-9.4280787
39.6,1.0310041,-0.081232473,45.080688,0,11.076097,118.71592,-0.0053925472,13.195253,11.075546,118.36404,-9.4259472
40.8,1.0174837,-0.084202453,45.615231,0,11.076097,122.31595,-0.0055909432,13.042201,11.076331,121.52272,-9.4238758
42.0,1.0198929,-0.087313257,46.581978,0,11.076097,125.91593,-0.005796053,13.066646,11.076593,124.71823,-9.4217939
43.2,1.0300945,-0.091367505,47.504803,0,11.076097,129.51605,-0.0060629877,13.176528,11.075583,127.98251,-9.4197388
44.4,1.030019,-0.095274366,48.34338,0,11.076097,133.11594,-0.0063253739,13.20892,11.076128,131.50137,-9.4175634
45.6,1.0326893,-0.10082597,48.812218,0,11.076097,136.71591,-0.0066892207,13.211973,11.075786,135.20343,-9.4152536
46.8,1.0390342,-0.10253972,49.224964,0,11.076097,140.31595,-0.0068128239,13.335511,11.076088,138.98729,-9.4128895
48.0,1.0378416,-0.10723007,49.291172,0,11.076097,143.91592,-0.0071268729,13.305814,11.07612,142.86293,-9.4108486
49.2,1.0322074,-0.11229976,49.636227,0,11.076097,147.51595,-0.0074613686,13.240733,11.075357,146.6812,-9.4083385
50.4,1.0399135,-0.11641657,49.636227,0,11.076097,151.11594,-0.0077284658,13.323903,11.075737,150.50577,-9.4068604
51.6,1.0421562,-0.12177119,49.636524,0,11.076097,154.71594,-0.0080828751,13.378357,11.075719,154.27988,-9.4044399
52.8,1.0410436,-0.12315426,50.042721,0,11.076097,158.31595,-0.0081669614,13.372577,11.075509,157.81168,-9.4024296
54.0,1.0418075,-0.12783147,50.042721,0,11.076097,161.91595,-0.0084725209,13.37055,11.076507,161.46626,-9.4005604
55.2,1.0393435,-0.13284686,50.173634,0,11.076097,165.51595,-0.0087936083,13.359439,11.076329,165.10745,-9.3985291
56.4,1.037182,-0.13681911,50.438202,0,11.076097,169.11595,-0.0090622958,13.328832,11.077255,168.73114,-9.3964224
57.6,1.049278,-0.14147188,50.438229,0,11.076097,172.71596,-0.0093826512,13.485349,11.076715,172.40543,-9.3945522
58.8,1.0507722,-0.14427811,50.438229,0,11.076097,176.31596,-0.0095460275,13.514902,11.076099,175.94678,-9.3924761
60.0,1.0404524,-0.14861421,50.82275,0,11.076097,179.91595,-0.0098479325,13.38534,11.075556,179.57339,-9.3902855
61.2,1.0433359,-0.15267156,50.82275,0,11.076097,183.51596,-0.010116882,13.409295,11.075766,183.06874,-9.388298
62.4,1.0548087,-0.15778476,51.196285,0,11.076097,187.11597,-0.010467113,13.558857,11.076686,186.60388,-9.3860655
63.6,1.0455136,-0.15941314,51.569714,0,11.076097,190.71596,-0.010574381,13.454822,11.075338,189.99696,-9.3837099
64.8,1.0520781,-0.16463736,51.866356,0,11.076097,194.31595,-0.01092942,13.54262,11.076096,193.59508,-9.3816032
66.0,1.0399126,-0.16958874,51.932369,0,11.076097,197.91597,-0.011255966,13.393164,11.075833,197.24393,-9.3792667
67.2,1.0510384,-0.1760983,52.152515,0,11.076097,201.51595,-0.011679962,13.536686,11.075922,200.93553,-9.3773355
68.4,1.0536844,-0.177388,52.143955,0,11.076097,205.11595,-0.01177781,13.563041,11.076026,204.74438,-9.3750057
69.6,1.0506227,-0.18277951,52.091644,0,11.076097,208.71596,-0.012132923,13.546839,11.075404,208.51421,-9.3732271
70.8,1.0460795,-0.18771316,52.010639,0,11.076097,212.31595,-0.01245204,13.496621,11.075627,212.18542,-9.3710413
72.0,1.0572721,-0.19240637,52.263016,0,11.076097,215.91595,-0.012753851,13.635791,11.076207,215.76541,-9.3692455
73.2,1.0545783,-0.19462968,52.2626,0,11.076097,219.51596,-0.012905453,13.604148,11.076613,219.41887,-9.3671827
74.4,1.0449185,-0.19969191,52.244671,0,11.076097,223.11595,-0.013225879,13.486961,11.076292,223.03247,-9.3654327
75.6,1.0546991,-0.20389064,52.108593,0,11.076097,226.71596,-0.013488352,13.611156,11.076135,226.72031,-9.3639288
76.8,1.0468574,-0.20789041,52.283936,0,11.076097,230.31596,-0.013752047,13.497581,11.076709,230.16606,-9.3619032
78.0,1.0527812,-0.21316467,52.421608,0,11.076097,233.91595,-0.014095875,13.588672,11.075622,233.63609,-9.359889
79.2,1.0634137,-0.21540897,52.635494,0,11.076097,237.51598,-0.014260712,13.732267,11.076651,237.12933,-9.3581123
80.4,1.0588295,-0.2187786,52.635494,0,11.076097,241.11597,-0.014472859,13.685753,11.07575,240.65933,-9.3560143
81.6,1.0525421,-0.22353946,52.97607,0,11.076097,244.71597,-0.014793121,13.602886,11.076266,244.18152,-9.3539095
82.8,1.0533899,-0.22755694,53.197582,0,11.076097,248.31596,-0.015054886,13.624766,11.075872,247.6976,-9.3518019
84.0,1.0634234,-0.23157841,53.393116,0,11.076097,251.91599,-0.015325467,13.739839,11.076735,251.26463,-9.3496122
85.2,1.0626824,-0.23810521,53.657223,0,11.076097,255.51596,-0.015721714,13.765882,11.075853,254.90944,-9.3474569
86.4,1.0549964,-0.23963769,53.666588,0,11.076097,259.11627,-0.015827045,13.667489,11.076982,258.57117,-9.3452339
87.6,1.060915,-0.24363884,53.866207,0,11.076097,262.71597,-0.016092602,13.725024,11.076154,262.26563,-9.3433828
88.8,1.0568068,-0.24881716,53.975128,0,11.076097,266.31598,-0.016436623,13.695552,11.076077,265.94583,-9.3411398
90.0,1.0538399,-0.25295067,53.975826,0,11.076097,269.91599,-0.016712254,13.657755,11.076157,269.68878,-9.3392067
91.2,1.0530155,-0.25741273,53.975826,0,11.076097,273.51599,-0.017014896,13.643773,11.075654,273.22198,-9.3369722
92.4,1.0581217,-0.26058483,54.305412,0,11.076097,277.11597,-0.017223109,13.709535,11.076396,276.63867,-9.3352585
93.6,1.0656283,-0.26720744,54.59119,0,11.076097,280.716,-0.017666638,13.806204,11.07577,280.14383,-9.3329163
94.8,1.0721945,-0.26809299,54.624023,0,11.076097,284.31598,-0.017737888,13.90138,11.075601,283.74591,-9.3310499
96.0,1.0608225,-0.27213344,54.931637,0,11.076097,287.91602,-0.017989524,13.735417,11.075516,287.26587,-9.3287535
97.2,1.0603065,-0.27700439,55.199379,0,11.076097,291.51599,-0.01831669,13.744263,11.076024,290.79559,-9.3269148
98.4,1.0597724,-0.28152832,55.239326,0,11.076097,295.11603,-0.018617034,13.737866,11.075704,294.40469,-9.324626
99.6,1.0591776,-0.28588471,55.535885,0,11.076097,298.71597,-0.018887233,13.749767,11.076105,297.92584,-9.3226347
100.8,1.0722901,-0.29033101,55.843506,0,11.076097,302.31598,-0.019163743,13.921353,11.076348,301.5549,-9.3204451
102.0,1.0745767,-0.29620108,56.103397,0,11.076097,305.91602,-0.019556191,13.965852,11.075881,305.16876,-9.3186264
103.2,1.0693729,-0.29784161,56.129147,0,11.076097,309.51599,-0.019656843,13.904429,11.076416,308.91348,-9.3163738
104.4,1.0645065,-0.30330795,56.129147,0,11.076097,313.11597,-0.020009993,13.830173,11.075945,312.78046,-9.3148041
105.6,1.0654489,-0.30799732,55.947182,0,11.076097,316.716,-0.020325612,13.861776,11.075157,316.64319,-9.312192
106.8,1.0612196,-0.3127107,56.128548,0,11.076097,320.31598,-0.020634586,13.795425,11.075821,320.11697,-9.3108225
108.0,1.0630161,-0.31739452,56.129147,0,11.076097,323.91599,-0.02092753,13.822922,11.075874,323.63165,-9.3085423
109.2,1.0605905,-0.32064888,56.423569,0,11.076097,327.51599,-0.021128507,13.798494,11.076081,327.14517,-9.3066521
110.4,1.0674355,-0.32818735,56.425777,0,11.076097,331.116,-0.021620631,13.882831,11.075152,330.83844,-9.304781
111.6,1.0823072,-0.32930502,56.005215,0,11.076097,334.71597,-0.021707857,14.066745,11.075256,335.02237,-9.3027363
112.8,1.0773033,-0.33153117,56.129063,0,11.076097,338.31601,-0.0218463,14.018162,11.076687,338.46323,-9.3007717
114.0,1.0748538,-0.33614317,56.132759,0,11.076097,341.91599,-0.022148803,14.000948,11.075987,341.75433,-9.2984867
115.2,1.0673708,-0.34078184,56.664925,0,11.076097,345.51596,-0.022469435,13.914908,11.076302,344.93112,-9.2967911
116.4,1.0643423,-0.34557936,56.801235,0,11.076097,349.116,-0.02278891,13.851271,11.076286,348.41629,-9.2947769
117.6,1.0672257,-0.35023692,56.986084,0,11.076097,352.71597,-0.023091968,13.924422,11.076634,351.99881,-9.2927055
118.8,1.0673605,-0.35498074,57.253326,0,11.076097,356.31598,-0.023411963,13.909845,11.076949,355.65387,-9.2912788
120.0,1.0635843,-0.35959917,57.18586,0,11.076097,359.91599,-0.023701679,13.859029,11.076056,359.47241,-9.289403
121.2,1.0632766,-0.36331761,57.096687,0,11.076097,363.51599,-0.023938421,13.879631,11.075649,363.30692,-9.2864065
122.4,1.069896,-0.36770335,57.2458,0,11.076097,367.116,-0.024213843,13.961559,11.075948,366.90674,-9.2840853
123.6,1.0632749,-0.37205046,57.260738,0,11.076097,370.716,-0.024497453,13.86723,11.07651,370.35614,-9.2828178
124.8,1.0700678,-0.37565991,57.535397,0,11.076097,374.31601,-0.024750343,13.933978,11.075775,373.69705,-9.2816153
126.0,1.0713509,-0.37923622,57.810051,0,11.076097,377.91599,-0.02496862,13.976464,11.076509,377.22684,-9.2795601
127.2,1.0896378,-0.38329369,58.072269,0,11.076097,381.51599,-0.025237627,14.225211,11.076479,380.76706,-9.2768927
128.4,1.087281,-0.38775977,58.075035,0,11.076097,385.116,-0.025514454,14.184474,11.075883,384.39188,-9.2747402
129.6,1.0879279,-0.39346468,58.337399,0,11.076097,388.716,-0.025867423,14.218096,11.07709,388.03006,-9.2727013
130.8,1.0968568,-0.39946598,58.33741,0,11.076097,392.31604,-0.026246849,14.341471,11.076828,391.82233,-9.2710829
132.0,1.0906559,-0.40508956,58.352467,0,11.076097,395.91602,-0.026618686,14.266673,11.076315,395.53766,-9.2692995
133.2,1.086216,-0.40969151,58.432339,0,11.076097,399.51602,-0.026942318,14.225668,11.075766,399.23386,-9.2673454
134.4,1.0623398,-0.41269049,56.462021,0,11.076097,399.99893,-0.027147826,13.901728,11.075871,402.76517,-9.2672443
135.6,0.99055552,-0.41368124,53.819363,0,11.076097,399.99893,-0.027228238,12.966169,11.075119,405.26654,-9.2665453
136.8,0.87498349,-0.41353029,51.203339,0,11.076097,399.99893,-0.027210072,11.45066,11.076154,406.27176,-9.2668009
138.0,0.75994641,-0.41282514,49.238533,0,11.076097,399.99893,-0.027174762,9.9560919,11.076145,405.78238,-9.2667103
139.2,0.6874851,-0.41170421,48.383793,0,11.076097,399.99893,-0.027095115,8.9984131,11.076162,404.53903,-9.2665586
140.4,0.63797367,-0.40996015,48.228256,0,11.076097,399.99893,-0.026965767,8.340415,11.076032,402.93835,-9.2664833
141.6,0.61846471,-0.40857494,48.807472,0,11.076097,399.99893,-0.026863838,8.1014471,11.076303,401.27606,-9.2666903
142.8,0.6036942,-0.40766004,49.634876,0,11.076097,399.99893,-0.026801702,7.8827863,11.075607,399.98959,-9.266923
144.0,0.60350794,-0.40846434,50.438217,0,11.076097,399.99893,-0.026867507,7.8894539,11.075943,399.09915,-9.2669077
145.2,0.60274035,-0.40952799,51.196243,0,11.076097,399.99893,-0.026928248,7.8739839,11.075943,398.67999,-9.2667904
146.4,0.59754914,-0.41058522,51.79319,0,11.076097,399.99893,-0.026986204,7.8199501,11.076288,398.60361,-9.2667246
147.6,0.59773952,-0.41239405,52.139763,0,11.076097,399.99893,-0.027106335,7.8141656,11.075928,398.75024,-9.2665005
148.8,0.59646934,-0.41419211,52.283936,0,11.076097,399.99893,-0.027215747,7.8227305,11.075931,399.04477,-9.2670078
150.0,0.5979144,-0.41535076,52.283936,0,11.076097,399.99893,-0.027313769,7.8211598,11.075738,399.42682,-9.2669802
151.2,0.59120166,-0.4166204,52.283936,0,11.076097,399.99893,-0.027408062,7.7436762,11.076468,399.70328,-9.2670689
152.4,0.59174192,-0.41796002,52.03891,0,11.076097,399.99893,-0.027500363,7.7306437,11.075484,399.99438,-9.2665176
153.6,0.59042865,-0.41854587,51.823849,0,11.076097,399.99893,-0.027542355,7.7324238,11.075217,400.24957,-9.2663727
154.8,0.59215146,-0.41878816,51.569828,0,11.076097,399.99893,-0.027544759,7.7509909,11.0758,400.34894,-9.2668324
156.0,0.58860004,-0.42014825,51.202042,0,11.076097,399.99893,-0.02761036,7.696981,11.077276,400.5437,-9.2665396
157.2,0.59546202,-0.42208347,51.149143,0,11.076097,399.99893,-0.027717026,7.7917738,11.075441,400.62787,-9.2666788
158.4,0.59515083,-0.4234505,50.822784,0,11.076097,399.99893,-0.027828742,7.7761235,11.075743,400.56119,-9.2664518
159.6,0.60433352,-0.42418045,50.822758,0,11.076097,399.99893,-0.027889639,7.891315,11.076731,400.46936,-9.2659693
160.8,0.60259581,-0.4243165,50.822758,0,11.076097,399.99893,-0.027886469,7.8926444,11.075943,400.35193,-9.2661076
162.0,0.60042226,-0.42374763,50.495281,0,11.076097,399.99893,-0.027850535,7.8604183,11.075799,400.38834,-9.2660675
163.2,0.60149777,-0.42291284,50.614529,0,11.076097,399.99893,-0.027800426,7.8704219,11.076448,400.21786,-9.265954
164.4,0.60011798,-0.42236423,50.62838,0,11.076097,399.99893,-0.02777515,7.8670034,11.074994,400.07397,-9.2658453
165.6,0.60762346,-0.42249942,50.82275,0,11.076097,399.99893,-0.027788436,7.9649816,11.075897,399.93091,-9.265522
166.8,0.5988571,-0.42324555,50.82275,0,11.076097,399.99893,-0.027844109,7.8428273,11.0763,399.88239,-9.2660446
168.0,0.60011435,-0.42447925,50.82275,0,11.076097,399.99893,-0.027926099,7.870492,11.075642,399.9624,-9.2660179
169.2,0.60554242,-0.42543477,50.82275,0,11.076097,399.99893,-0.027972467,7.9418468,11.076377,400.02304,-9.2661772
170.4,0.59702998,-0.4264248,50.82275,0,11.076097,399.99893,-0.0280212,7.8269916,11.074441,400.12943,-9.2659264
171.6,0.59629029,-0.42686084,50.545795,0,11.076097,399.99893,-0.028054098,7.7894001,11.076099,400.14474,-9.2663517
172.8,0.59745359,-0.42738974,50.438923,0,11.076097,399.99893,-0.028100971,7.8274713,11.075976,400.08789,-9.2660255
174.0,0.59216022,-0.42815474,50.441105,0,11.076097,399.99893,-0.028135242,7.7425036,11.076789,400.09647,-9.2661142
175.2,0.58998013,-0.428803,50.694057,0,11.076097,399.99893,-0.02817174,7.7159085,11.076134,399.98856,-9.2660856
176.4,0.59968919,-0.42951605,50.82275,0,11.076097,399.99893,-0.028209677,7.8581109,11.075567,399.90204,-9.2664118
177.6,0.59566814,-0.42980838,50.82259,0,11.076097,399.99893,-0.028252643,7.8050938,11.076622,399.9473,-9.2661066
178.6136,0.63209367,0.01622607,50.438232,0,11.076099,65.857674,0.00083941454,8.0253963,11.077237,400.03021,-9.2654734
178.616,0.59476787,0.016626399,50.438023,0,11.076099,2.8472163e-15,0.00079583959,7.6914802,11.080947,400.00043,-9.2651749
178.6184,0.58202451,0.014934424,38.332848,0,11.076099,1.230851e-31,0.00094787293,7.4790111,11.078051,399.99319,-9.2655621
178.6208,0.68411589,0.012791178,26.227673,0,11.076099,0.0,0.0011704395,8.7696524,11.074752,399.98599,-9.2666836
178.6232,0.56550658,0.012137506,14.122495,0,11.076099,0.0,0.00092210952,7.2641296,11.073191,399.97876,-9.2656746
178.6256,0.58533078,0.010861943,2.0173178,0,11.076099,0.0,0.0006216843,7.4811044,11.076869,399.97153,-9.2652016
178.628,0.60176218,0.012702057,0.0,0,11.076099,0.0,0.00065717765,7.5720897,11.076226,399.9884,-9.2664738
178.6304,0.57926786,0.01322289,0.0,0,11.076099,0.0,0.00091959001,7.4127598,11.073469,400.01007,-9.2675295
178.6328,0.58327669,0.010060646,0.0,0,11.076099,0.0,0.00090745633,7.4078803,11.073665,400.03174,-9.2664719
178.6352,0.57932055,0.009044053,0.0,0,11.076099,0.0,0.00076168717,7.3658614,11.074744,400.05341,-9.2661829
178.6376,0.5793016,0.011056882,0.0,0,11.076099,0.0,0.00059911894,7.3475919,11.072047,400.0462,-9.2652197
178.64,0.57726002,0.015148048,0.0,0,11.076099,0.0,0.00072546536,7.3890853,11.075253,400.02451,-9.2659502
178.6424,0.57357824,0.015235686,0.0,0,11.076099,0.0,0.00090952677,7.3485327,11.073027,400.00284,-9.2671194
178.6448,0.57196867,0.012608932,0.0,0,11.076099,0.0,0.0010983421,7.2306309,11.074368,399.98117,-9.266942
178.6472,0.57279843,0.0091391029,0.0,0,11.076099,0.0,0.00076319976,7.2745767,11.073722,399.97394,-9.2651005
178.6496,0.57622761,0.0099731591,0.0,0,11.076099,0.0,0.0005397686,7.3115754,11.074843,399.98117,-9.2652884
178.652,0.56543362,0.011755079,0.0,0,11.076099,0.0,0.00059821398,7.1750307,11.073937,399.9884,-9.2664118
178.6544,0.56209487,0.011568489,0.0,0,11.076099,0.0,0.00077992032,7.1820235,11.077284,399.99561,-9.2661591
178.6568,0.56487119,0.011249747,0.0,0,11.076099,0.0,0.00091698224,7.1788526,11.074602,399.99561,-9.2654467
178.6592,0.56653607,0.010934296,0.0,0,11.076099,0.0,0.0008769221,7.2464838,11.077023,399.98117,-9.265337
178.6616,0.57113981,0.013059396,0.0,0,11.076099,0.0,0.00073335011,7.2925658,11.072975,399.96674,-9.2652721
178.664,0.55852473,0.01707574,0.0,0,11.006538,0.0,0.00079254259,7.120163,11.076951,399.95227,-9.2667007
178.6664,0.56119335,0.015868111,0.0,0,10.64557,0.0,0.00095449935,7.1592526,11.076054,399.94025,-9.2658777
178.6688,0.56570047,0.010597106,0.0,0,10.284596,0.0,0.0009632759,7.2095628,11.063803,399.94025,-9.2652855
178.6712,0.5827527,0.007465288,0.0,0,9.9236231,0.0,0.00069697323,7.3758354,10.943374,399.94025,-9.2668133
178.6736,0.54524237,0.010563888,0.0,0,9.5626488,0.0,0.00061980454,6.9012866,10.668807,399.94025,-9.2674637
178.676,0.58918118,0.012628728,0.0,0,9.2092848,0.0,0.0007228012,7.4645052,10.287664,399.94031,-9.2666912
178.6784,5.5694075,0.28442165,0.0,0,8.8581161,0.0,0.018084526,70.05912,9.8604889,404.18845,-9.2611713
178.6808,6.3102093,0.72019964,0.0,0,8.5188513,0.0,0.049159121,75.935265,9.3550224,408.43655,-9.2618427
178.6832,6.5032377,1.1720114,0.0,0,8.1848679,0.0,0.081167109,76.338074,8.8899698,412.68469,-9.2610111
178.6856,6.5397573,1.5670372,0.0,0,7.8607702,0.0,0.10964379,74.402,8.5199881,416.9328,-9.2619076
178.688,6.8575211,1.8797135,0.0,0,7.5430098,0.0,0.1329589,76.381096,8.1788559,420.32297,-9.2611313
178.6904,6.9261017,2.1938236,0.0,0,7.2334309,0.0,0.15765087,75.256157,7.8469658,423.54156,-9.2619915
178.6928,7.1070962,2.5023139,0.0,0,6.9312229,0.0,0.18245628,75.529907,7.5380836,426.76016,-9.2618208
178.6952,7.2566223,2.7913134,0.0,0,6.6355171,0.0,0.20580818,75.065445,7.2421627,429.97876,-9.2621403
178.6976,7.4954038,3.0789874,0.0,0,6.3479972,0.0,0.22909789,75.830635,6.9513202,429.85089,-9.2620554
178.7,7.6545162,3.369982,0.0,0,6.0655317,0.0,0.25375929,75.536339,6.6547508,428.04996,-9.2611847
178.7024,7.8282666,3.6597013,0.0,0,5.7920747,0.0,0.27931347,75.330826,6.3648319,426.24899,-9.2609291
178.7048,7.998558,3.9419804,0.0,0,5.5222898,0.0,0.30481318,74.994087,6.0828514,424.44803,-9.2609577
178.7072,8.1764364,4.2190666,0.0,0,5.2621293,0.0,0.33015126,74.786255,5.7980332,423.72403,-9.2612438
178.7096,8.403141,4.4978266,0.0,0,5.0044203,0.0,0.3558735,74.908455,5.5190196,424.07693,-9.2608147
178.712,8.5860071,4.7737255,0.0,0,4.7569804,0.0,0.38206756,74.637009,5.2493653,424.42987,-9.2604332
178.7144,8.7694588,5.0438943,0.0,0,4.5108619,0.0,0.40924537,74.080322,4.9817448,424.78278,-9.2619286
178.7168,8.9824533,5.3033581,0.0,0,4.275466,0.0,0.43634203,73.907707,4.7137208,425.80554,-9.2609558
178.7192,9.1931391,5.5568171,0.0,0,4.0404677,0.0,0.46275166,73.69339,4.4612942,428.16788,-9.2608299
178.7216,9.442625,5.8064833,0.0,0,3.8165019,0.0,0.48883724,73.681023,4.2090321,430.53024,-9.2612505
178.724,9.6563883,6.0425367,0.0,0,3.5926297,0.0,0.51460642,73.474083,3.9743724,432.89261,-9.2610006
178.7264,9.8503933,6.2720513,0.0,0,3.3790293,0.0,0.54098821,72.976723,3.7465646,435.13474,-9.2591677
178.7288,10.108057,6.4869084,0.0,0,3.1660533,0.0,0.56665987,73.00782,3.5271139,436.7757,-9.2595053
178.7312,10.384892,6.6984353,0.0,0,2.9619873,0.0,0.59167767,73.135727,3.3168633,438.41669,-9.2597084
178.7336,10.686996,6.9128327,0.0,0,2.7593791,0.0,0.6170249,73.411118,3.108845,440.05765,-9.2590647
178.736,10.987467,7.1239824,0.0,0,2.5644443,0.0,0.64289182,73.505859,2.9009106,441.69855,-9.2587624
178.7384,11.312177,7.326272,0.0,0,2.3717244,0.0,0.66967672,73.671463,2.7048976,437.52475,-9.2589045
178.7408,11.688154,7.523037,0.0,0,2.1855214,0.0,0.69659972,74.117073,2.4998047,433.35092,-9.2592745
178.7432,12.095509,7.7179708,0.0,0,2.0022092,0.0,0.72293222,74.701698,2.2994034,429.17712,-9.2589731
178.7456,12.494382,7.9144673,0.0,0,1.8243376,0.0,0.74909753,75.214287,2.1078591,425.00333,-9.2573977
178.748,12.89299,8.1068077,0.0,0,1.6499536,0.0,0.77634478,75.500076,1.918098,419.02341,-9.2583647
178.7504,13.328591,8.2883034,0.0,0,1.4800386,0.0,0.80365449,75.929756,1.7350862,412.68231,-9.2587662
178.7528,13.823707,8.4627876,0.0,0,1.3141507,0.0,0.83093184,76.636848,1.5579754,406.34122,-9.258213
178.7552,14.35632,8.6355381,0.0,0,1.1518539,0.0,0.85747212,77.527512,1.3835541,400.00012,-9.2583284
178.7576,14.859364,8.8099146,0.0,0,0.9940778,0.0,0.88423926,78.098343,1.2118925,396.57031,-9.2580156
178.76,15.443107,8.9800129,0.0,0,0.83907896,0.0,0.9112162,78.984848,1.0459995,394.59601,-9.2564516
178.7624,16.058716,9.1403313,0.0,0,0.68903095,0.0,0.93919283,79.892326,0.88416594,392.6217,-9.257946
178.7648,16.732159,9.2926197,0.0,0,0.54098368,0.0,0.96661502,80.949081,0.72500843,390.6474,-9.2562227
178.7672,17.416494,9.4389973,0.0,0,0.39818361,0.0,0.992706,82.086922,0.56922531,390.96149,-9.2561331
178.7696,15.094109,9.4872589,0.0,0,0.2567341,0.0,1.0002429,70.836243,0.47885138,393.56381,-9.2585258
178.772,13.543422,9.50949,0.0,0,0.12094197,0.0,1.0039936,63.246944,0.43570271,396.16614,-9.2602911
178.7744,12.848204,9.5120173,0.0,0,-0.014481357,0.0,1.0053201,59.923492,0.40848416,398.76846,-9.2598801
178.7768,12.483311,9.5153503,0.0,0,-0.14691454,0.0,1.0070546,58.077595,0.37882876,402.01282,-9.2606621
178.7792,12.525902,9.5158472,0.0,0,-0.27934653,0.0,1.0070482,58.251865,0.34212771,406.5412,-9.2592421
178.7816,12.831022,9.5252237,0.0,0,-0.41177854,0.0,1.0072992,59.658569,0.27757376,411.06955,-9.2610569
178.784,12.923089,9.5406885,0.0,0,-0.54421055,0.0,1.0093102,59.938156,0.20643355,415.59793,-9.2613211
178.7864,12.886191,9.5439653,0.0,0,-0.67664254,0.0,1.0107875,59.735023,0.14488307,419.83154,-9.2604828
178.7888,12.773089,9.544178,0.0,0,-0.80907446,0.0,1.0125252,59.052456,0.089565367,422.59149,-9.261878
178.7912,12.53624,9.5442381,0.0,0,-0.94150651,0.0,1.0123216,58.028137,0.049572006,425.35147,-9.2622623
178.7936,12.195749,9.5496101,0.0,0,-1.0739386,0.0,1.0119897,56.472813,0.01840331,428.11142,-9.2628136
178.796,11.719923,9.5583124,0.0,0,-0.76690692,400.0,1.0130607,54.247368,0.0057004988,430.87137,-9.2633572
178.7984,11.212474,9.5592909,0.0,0,-0.30842057,400.0,1.0138924,51.853664,0.0075388886,432.46228,-9.2625341
178.8008,10.805091,9.553669,0.0,0,0.15006579,400.0,1.0140587,49.937347,0.013414283,434.05322,-9.2618704
178.8032,10.484722,9.5526104,0.0,0,0.60855216,400.0,1.0137943,48.439724,0.014841864,435.64417,-9.2623234
178.8056,10.218942,9.5561037,0.0,0,1.0670385,400.0,1.0130548,47.259686,0.018094921,437.23508,-9.2630758
178.808,9.8176775,9.561595,0.0,0,1.5255249,400.0,1.0131199,45.390743,0.024074499,438.32788,-9.2651577
178.8104,8.7394972,9.557807,0.0,0,1.9840113,400.0,1.0133749,40.495033,0.071337976,439.32108,-9.2649527
178.8128,6.6713605,9.5414257,0.0,0,2.4424982,400.0,1.0119472,31.106382,0.18551674,440.31427,-9.2654953
178.8152,3.1763272,9.5177889,0.0,0,2.9009843,400.0,1.0076562,15.106477,0.39683488,441.30743,-9.2703857
178.8176,0.3403109,9.4364061,0.0,0,3.3594708,400.0,0.99180138,1.4876108,0.78617275,442.10367,-9.2727137
178.82,0.05858833,9.4201431,0.0,0,3.8179572,400.0,0.98765647,0.48761508,1.48409,442.80139,-9.2713375
178.8224,-0.12215609,9.4427567,0.0,0,4.2764435,400.0,0.99267602,-0.5724293,2.309324,443.49911,-9.2714415
178.8248,0.21230367,9.4886456,0.0,0,4.73493,400.0,1.0022889,1.0376582,3.0492761,444.19687,-9.2705202
178.8272,0.18543229,9.486866,0.0,0,5.1934166,400.0,1.0021476,0.80392402,3.6106064,444.7757,-9.2712488
178.8296,0.086879857,9.4929991,0.0,0,5.6519027,400.0,1.0014702,0.41087228,4.0451603,445.2356,-9.2697487
178.832,-0.011434199,9.5032043,0.0,0,6.1103892,400.0,1.0025767,-0.022798965,4.4708652,445.69553,-9.2684984
178.8344,-0.012436275,9.5020161,0.0,0,6.5688753,400.0,1.0032096,0.038175005,4.8920083,446.15543,-9.2684917
178.8368,-0.068186544,9.4936953,0.0,0,7.0273619,400.0,1.0032132,-0.33438262,5.3107867,446.57703,-9.2685719
178.8392,0.023177326,9.4867668,0.0,0,7.4858489,400.0,1.0019904,0.027397705,5.7519522,446.92197,-9.2682219
178.8416,0.10094968,9.4838181,0.0,0,7.9443355,400.0,1.0001078,0.42937836,6.2184072,447.26691,-9.2677689
178.844,-0.083010726,9.4897585,0.0,0,8.4028215,400.0,1.0005196,-0.35683176,6.6985888,447.61185,-9.2672138
178.8464,-0.064923815,9.4928675,0.0,0,8.8613071,400.0,1.0018151,-0.37613678,7.186276,447.93881,-9.2663746
178.8488,0.056848027,9.4883661,0.0,0,9.3197937,400.0,1.0022522,0.23532493,7.6758418,448.17596,-9.265336
178.8512,-0.081804216,9.488061,0.0,0,9.7782803,400.0,1.002167,-0.36047584,8.1559048,448.41312,-9.2659111
178.8536,-0.0041588424,9.4897842,0.0,0,10.236767,400.0,1.0010091,-0.024345953,8.6270676,448.65024,-9.2651949
178.856,0.023593903,9.4931011,0.0,0,10.695253,400.0,1.0004621,0.1471218,9.0996103,448.88739,-9.2650785
178.8584,-0.09241458,9.4923048,0.0,0,11.153739,400.0,1.0013604,-0.46929371,9.5604248,449.12454,-9.2665615
178.8608,-0.047026373,9.488946,0.0,0,11.612226,400.0,1.0023228,-0.28120738,10.029572,449.36169,-9.2648201
178.8632,0.081724487,9.4850531,0.0,0,12.070712,400.0,1.0017608,0.40635538,10.509859,449.59882,-9.2644367
178.8656,-0.13474183,9.4879637,0.0,0,12.529199,400.0,1.0007842,-0.62800479,10.972361,449.83597,-9.2645435
178.868,0.032388117,9.4917355,0.0,0,12.987685,400.0,1.0007437,0.046564586,11.44263,450.06113,-9.2660275
178.8704,0.0057606311,9.4916916,0.0,0,13.446172,400.0,1.001542,0.052799918,11.898798,450.28391,-9.2650938
178.8728,-0.057711232,9.4870338,0.0,0,13.904658,400.0,1.0019112,-0.21966776,12.35295,450.50668,-9.2652931
178.8752,0.01862728,9.4850416,0.0,0,14.363145,400.0,1.0014348,-0.021938398,12.820541,450.72946,-9.2646637
178.8776,0.020038029,9.4859085,0.0,0,14.821631,400.0,1.0003808,0.17328779,13.297081,450.9187,-9.2631969
178.88,-0.11200032,9.4943047,0.0,0,15.280118,400.0,1.0008966,-0.5663721,13.773023,451.09116,-9.2651529
178.8824,0.051022764,9.4921274,0.0,0,15.738604,400.0,1.001404,0.15438451,14.26035,451.26364,-9.2650127
178.8848,0.030964242,9.484498,0.0,0,16.19709,400.0,1.0014681,0.22610492,14.734605,451.4361,-9.2645607
178.8872,-0.10118283,9.4842262,0.0,0,16.655577,400.0,1.0015007,-0.51847589,15.186987,451.59421,-9.2649927
178.8896,0.037766773,9.48452,0.0,0,17.114063,400.0,1.00011,0.12479978,15.645278,451.73792,-9.2642851
178.892,-0.07669732,9.4868917,0.0,0,17.57255,400.0,0.99989849,-0.28324455,16.097881,451.88162,-9.2636776
178.8944,-0.048589185,9.4881945,0.0,0,17.999401,400.0,1.0008838,-0.27225631,16.547209,452.02536,-9.2647791
178.8968,0.039773338,9.484601,0.0,0,18.0,400.0,1.0014453,0.20356227,17.000576,452.16428,-9.2650061
178.8992,-0.099904142,9.4831553,0.0,0,18.0,400.0,1.0011938,-0.45145524,17.436892,452.29364,-9.2640305
178.9016,0.017194239,9.4868259,0.0,0,18.0,400.0,1.0004814,0.083123006,17.827492,452.42297,-9.265132
178.904,-0.042571671,9.497283,0.0,0,18.0,400.0,1.0012575,-0.20825237,18.151649,452.55234,-9.2661533
178.9064,0.10077247,9.4995785,0.0,0,18.0,400.0,1.0025893,0.4153266,18.385605,452.6745,-9.2696772
178.9088,0.20926806,9.4951696,0.0,0,18.0,400.0,1.003475,0.9938969,18.51339,452.76074,-9.2739401
178.9112,0.46905246,9.4954634,0.0,0,18.0,400.0,1.0035958,2.1039617,18.507805,452.84698,-9.2802763
178.9136,0.4070366,9.5002623,0.0,0,18.0,400.0,1.0030373,1.9416137,18.394176,452.9332,-9.2913666
178.916,0.35162538,9.5023632,0.0,0,18.0,400.0,1.0027611,1.6065634,18.255545,453.01944,-9.30334
178.9184,0.43410072,9.5009861,0.0,0,18.0,400.0,1.0032089,2.0320222,18.13937,453.09848,-9.3182783
178.9208,0.3899951,9.4964342,0.0,0,18.0,400.0,1.003477,1.8315631,18.066271,453.17755,-9.3358469
178.9232,0.38841334,9.4946165,0.0,0,18.0,400.0,1.0032551,1.7713403,18.037481,453.25659,-9.3558607
178.9256,0.33015862,9.4958353,0.0,0,18.0,400.0,1.0022964,1.5451567,18.039158,453.33563,-9.3761311
178.928,0.3629171,9.4984989,0.0,0,18.0,400.0,1.0017531,1.7055023,18.054178,453.42068,-9.3962431
178.9304,0.36933672,9.4980116,0.0,0,18.0,400.0,1.0023487,1.7080772,18.076077,453.50693,-9.4175634
178.9328,0.37657577,9.4943771,0.0,0,18.0,400.0,1.0032977,1.7776207,18.101593,453.59314,-9.4350014
178.9352,0.34901628,9.4907932,0.0,0,18.0,400.0,1.0027783,1.6513298,18.122793,453.67938,-9.4542046
178.9376,0.36133873,9.4910154,0.0,0,18.0,400.0,1.0016043,1.718492,18.131264,453.74646,-9.4714117
178.94,0.37917894,9.4976158,0.0,0,18.0,400.0,1.0017514,1.7422239,18.132771,453.80392,-9.4886427
178.9424,0.3902424,9.499198,0.0,0,18.0,400.0,1.0027292,1.8363574,18.136921,453.86142,-9.5057783
178.9448,0.38186648,9.4948368,0.0,0,18.0,400.0,1.0031676,1.8172724,18.133673,453.91888,-9.5242281
178.9472,0.36153579,9.4900866,0.0,0,18.0,400.0,1.0025543,1.6918381,18.131231,453.9584,-9.5420914
178.9496,0.36924577,9.4913464,0.0,0,18.0,400.0,1.0014869,1.7299278,18.128071,453.97998,-9.5588799
178.952,0.38846895,9.4983807,0.0,0,18.0,400.0,1.0015188,1.810376,18.126095,454.00153,-9.5763006
178.9544,0.39299679,9.5010099,0.0,0,18.0,400.0,1.0027947,1.8279464,18.125162,454.0231,-9.5926771
178.9568,0.37823185,9.4966564,0.0,0,18.0,400.0,1.0036664,1.7672846,18.117977,454.04944,-9.6111698
178.9592,0.35871354,9.490942,0.0,0,18.0,400.0,1.0029006,1.6820481,18.118,454.08539,-9.6283646
178.9616,0.3927502,9.4906797,0.0,0,18.0,400.0,1.001412,1.8014328,18.113024,454.12131,-9.6452703
178.964,0.39291033,9.4950447,0.0,0,18.0,400.0,1.0013181,1.8505638,18.110188,454.15726,-9.6634121
178.9664,0.39248589,9.4991398,0.0,0,18.0,400.0,1.0025663,1.8163946,18.110147,454.19318,-9.6820354
178.9688,0.36212808,9.4943914,0.0,0,18.0,400.0,1.0032654,1.7010417,18.106943,454.22913,-9.7000942
178.9712,0.37540296,9.4922571,0.0,0,18.0,400.0,1.0029089,1.7551805,18.105591,454.26505,-9.7170248
178.9736,0.39219686,9.4956684,0.0,0,18.0,400.0,1.0022117,1.7937638,18.10288,454.30099,-9.7343025
178.976,0.39206752,9.5021935,0.0,0,18.0,400.0,1.0023271,1.8319093,18.102396,454.33691,-9.753293
178.9784,0.36701745,9.5017471,0.0,0,18.0,400.0,1.0029465,1.7036749,18.101267,454.30099,-9.7718744
178.9808,0.37274861,9.495759,0.0,0,18.0,400.0,1.0034462,1.7470325,18.099022,454.26505,-9.7883101
178.9832,0.38001126,9.4899654,0.0,0,18.0,400.0,1.0026591,1.7394872,18.096743,454.22913,-9.8074865
178.9856,0.39224342,9.4930849,0.0,0,18.0,400.0,1.0017879,1.8658416,18.09944,454.19318,-9.8249893
178.988,0.38967273,9.4995737,0.0,0,18.0,400.0,1.0021421,1.8297771,18.096035,454.16324,-9.8434563
178.9904,0.34659088,9.4975424,0.0,0,18.0,400.0,1.0024285,1.6023158,18.092207,454.13449,-9.8611765
178.9928,0.36686641,9.4918308,0.0,0,18.0,400.0,1.0026596,1.7025334,18.093054,454.10577,-9.877718
178.9952,0.38799247,9.4901457,0.0,0,18.0,400.0,1.0025938,1.7998676,18.099712,454.07703,-9.8952732
178.9976,0.39624155,9.4960947,0.0,0,18.0,400.0,1.0023468,1.908119,18.094778,454.07224,-9.9125776
179.0,0.37064105,9.5013084,0.0,0,18.0,400.0,1.0020376,1.7591001,18.094238,454.07941,-9.9306536
179.0024,0.37068933,9.4983568,0.0,0,18.0,400.0,1.0023519,1.708676,18.091887,454.08661,-9.9465837
179.0048,0.37497675,9.4941044,0.0,0,18.0,400.0,1.0032103,1.749809,18.091415,454.09378,-9.965559
179.0072,0.39640552,9.4897404,0.0,0,18.0,400.0,1.0026417,1.8784822,18.092102,454.09738,-9.9825487
179.0096,0.3882983,9.4928293,0.0,0,18.0,400.0,1.001875,1.8502805,18.088785,454.09738,-10.000825
179.012,0.36060956,9.4983473,0.0,0,18.0,400.0,1.0018847,1.6804653,18.091246,454.09738,-10.019495
179.0144,0.37737605,9.496912,0.0,0,18.0,400.0,1.0023314,1.7659258,18.090767,454.09738,-10.036209
179.0168,0.40007079,9.4928303,0.0,0,18.0,400.0,1.0029265,1.8417213,18.090036,454.09259,-10.054211
179.0192,0.41283029,9.4914961,0.0,0,18.0,400.0,1.002735,1.9287126,18.088892,454.07822,-10.072368
179.0216,0.38744918,9.4982605,0.0,0,18.0,400.0,1.0026623,1.833968,18.090233,454.06384,-10.091021
179.024,0.37987038,9.5031548,0.0,0,18.0,400.0,1.0025915,1.7769074,18.085909,454.04947,-10.108625
179.0264,0.3848004,9.5020599,0.0,0,18.0,400.0,1.0029509,1.7774665,18.086645,454.03268,-10.127224
179.0288,0.41834283,9.4966917,0.0,0,18.0,400.0,1.0033991,1.9291121,18.084404,454.00394,-10.144038
179.0312,0.39419314,9.4930611,0.0,0,18.0,400.0,1.0033087,1.8772002,18.078983,453.97522,-10.161628
179.0336,0.3794255,9.4971561,0.0,0,18.0,400.0,1.0026149,1.7814052,18.082129,453.94647,-10.180009
179.036,0.38132018,9.4995861,0.0,0,18.0,400.0,1.0022528,1.7629229,18.079157,453.91772,-10.198659
179.0384,0.40341941,9.4994259,0.0,0,18.0,400.0,1.0027378,1.8683519,18.080738,453.90335,-10.216721
179.0408,0.41329759,9.4953699,0.0,0,18.0,400.0,1.0031801,1.9284211,18.083479,453.88898,-10.232797
179.0432,0.39519367,9.4929419,0.0,0,18.0,400.0,1.0030718,1.8725057,18.075012,453.8746,-10.251389
179.0456,0.37513658,9.4966269,0.0,0,18.0,400.0,1.002477,1.7159562,18.077492,453.86023,-10.268231
179.048,0.39353245,9.5012846,0.0,0,18.0,400.0,1.0022744,1.8547763,18.077217,453.84586,-10.286352
179.0504,0.40744105,9.5033588,0.0,0,18.0,400.0,1.003198,1.87826,18.077642,453.83148,-10.305037
179.0528,0.4019919,9.4995413,0.0,0,18.0,400.0,1.0042039,1.9057727,18.079586,453.81711,-10.322834
179.0552,0.36570981,9.4956255,0.0,0,18.0,400.0,1.0036938,1.7099143,18.077648,453.80273,-10.340957
179.0576,0.37557727,9.4944029,0.0,0,18.0,400.0,1.0021535,1.7149767,18.079174,453.78836,-10.356943
179.06,0.39350298,9.499176,0.0,0,18.0,400.0,1.0021434,1.7586033,18.07402,453.77399,-10.374431
179.0624,0.41400138,9.5001469,0.0,0,18.0,400.0,1.0026649,1.9357324,18.072424,453.75961,-10.393082
179.0648,0.39287013,9.496563,0.0,0,18.0,400.0,1.0035059,1.8666303,18.07379,453.74524,-10.411216
179.0672,0.37518767,9.4922562,0.0,0,18.0,400.0,1.0031915,1.741621,18.073885,453.72369,-10.428515
179.0696,0.37975386,9.4960642,0.0,0,18.0,400.0,1.0022709,1.7370338,18.07188,453.69495,-10.445434
179.072,0.41155431,9.5041428,0.0,0,18.0,400.0,1.0026221,1.911123,18.073196,453.6662,-10.463394
179.0744,0.41177422,9.5054655,0.0,0,18.0,400.0,1.0035194,1.9077159,18.072884,453.63745,-10.48069
179.0768,0.37507918,9.499258,0.0,0,18.0,400.0,1.0040756,1.7486647,18.072382,453.6087,-10.49926
179.0792,0.37369055,9.4928179,0.0,0,18.0,400.0,1.0033873,1.7607151,18.072111,453.57996,-10.516262
179.0816,0.41014877,9.4961653,0.0,0,18.0,400.0,1.0023654,1.8837955,18.071901,453.55121,-10.532285
179.084,0.43225929,9.5025816,0.0,0,18.0,400.0,1.0025684,1.9953319,18.07019,453.52246,-10.550901
179.0864,0.41310042,9.5041924,0.0,0,18.0,400.0,1.003379,1.9719535,18.067577,453.4949,-10.569571
179.0888,0.38126129,9.4992819,0.0,0,18.0,400.0,1.00405,1.7738168,18.069407,453.47336,-10.58741
179.0912,0.3871305,9.4953156,0.0,0,18.0,400.0,1.0035006,1.7885652,18.066595,453.45181,-10.604262
179.0936,0.41642052,9.4968729,0.0,0,18.0,400.0,1.0026351,1.9358109,18.068386,453.43024,-10.622041
179.096,0.42365929,9.503437,0.0,0,18.0,400.0,1.0025626,1.9840053,18.064306,453.40869,-10.640562
179.0984,0.38605428,9.5062122,0.0,0,18.0,400.0,1.0034498,1.8153878,18.063416,453.34402,-10.659624
179.1008,0.39002335,9.5008564,0.0,0,18.0,400.0,1.0042841,1.8301823,18.066162,453.27936,-10.676535
179.1032,0.39782846,9.4935246,0.0,0,18.0,400.0,1.003265,1.828271,18.060713,453.21466,-10.695079
179.1056,0.43646777,9.4945831,0.0,0,18.0,400.0,1.0022233,2.0325692,18.06077,453.14999,-10.712934
179.108,0.41633257,9.5006618,0.0,0,18.0,400.0,1.0024235,1.9522549,18.064199,453.10928,-10.730553
179.1104,0.37740999,9.5009804,0.0,0,18.0,400.0,1.0029346,1.7908126,18.062128,453.07333,-10.74799
179.1128,0.39132604,9.4954052,0.0,0,18.0,400.0,1.0031927,1.8153279,18.057245,453.03741,-10.765168
179.1152,0.41608259,9.493474,0.0,0,18.0,400.0,1.0030084,1.9320762,18.061716,453.00146,-10.780826
179.1176,0.42052302,9.49897,0.0,0,18.0,400.0,1.0030872,1.9721026,18.059067,452.98471,-10.800572
179.12,0.39100081,9.5046215,0.0,0,18.0,400.0,1.0027723,1.8244876,18.058903,452.97751,-10.818487
179.1224,0.39176598,9.5059233,0.0,0,18.0,400.0,1.0034401,1.8415604,18.057266,452.97034,-10.836061
179.1248,0.3919811,9.5010214,0.0,0,18.0,400.0,1.0044312,1.8195821,18.057598,452.96313,-10.853282
179.1272,0.43065694,9.4965591,0.0,0,18.0,400.0,1.0039593,2.0141077,18.059866,452.94516,-10.871021
179.1296,0.40544021,9.4972105,0.0,0,18.0,400.0,1.0026505,1.9295086,18.060125,452.91641,-10.888992
179.132,0.38426641,9.5023756,0.0,0,18.0,400.0,1.0026045,1.8186057,18.060289,452.8877,-10.906887
179.1344,0.37864995,9.5013638,0.0,0,18.0,400.0,1.0030208,1.77279,18.059374,452.85895,-10.925516
179.1368,0.42581534,9.4982882,0.0,0,18.0,400.0,1.0035431,1.9726849,18.05694,452.82062,-10.941602
179.1392,0.41735199,9.4951782,0.0,0,18.0,400.0,1.003594,1.9736173,18.054665,452.76312,-10.960855
179.1416,0.39854243,9.4995193,0.0,0,18.0,400.0,1.003239,1.8927196,18.058825,452.70566,-10.980116
179.144,0.38298509,9.5056314,0.0,0,18.0,400.0,1.0030934,1.7992033,18.058863,452.64816,-10.997855
179.1464,0.39660177,9.5052261,0.0,0,18.0,400.0,1.0034666,1.8734592,18.05537,452.59427,-11.014314
179.1488,0.44131586,9.5017595,0.0,0,18.0,400.0,1.0043246,2.0306878,18.055683,452.55832,-11.031124
179.1512,0.40854001,9.4968262,0.0,0,18.0,400.0,1.0040181,1.9291784,18.055943,452.5224,-11.048906
179.1536,0.38808271,9.4981022,0.0,0,18.0,400.0,1.0029711,1.8397138,18.055672,452.48645,-11.06748
179.156,0.38711914,9.501605,0.0,0,18.0,400.0,1.0026828,1.7756714,18.052334,452.45053,-11.08478
179.1584,0.42134708,9.5038805,0.0,0,18.0,400.0,1.0034297,1.9467036,18.053057,452.42899,-11.101724
179.1608,0.43891639,9.4994898,0.0,0,18.0,400.0,1.0039549,2.0674839,18.050873,452.40741,-11.118392
179.1632,0.4140695,9.4955101,0.0,0,18.0,400.0,1.0036703,1.949764,18.047785,452.38586,-11.136739
179.1656,0.39072692,9.499896,0.0,0,18.0,400.0,1.003284,1.8143513,18.049225,452.36432,-11.155119
179.168,0.41291225,9.5068941,0.0,0,18.0,400.0,1.003274,1.9309514,18.05043,452.32477,-11.173694
179.1704,0.42981666,9.5066347,0.0,0,18.0,400.0,1.0035582,1.9863932,18.047661,452.28165,-11.189669
179.1728,0.42508322,9.5023632,0.0,0,18.0,400.0,1.0045574,1.9949695,18.046843,452.23853,-11.210437
179.1752,0.39265838,9.4983435,0.0,0,18.0,400.0,1.0041655,1.8280889,18.044445,452.1954,-11.228483
179.1776,0.39387009,9.4982128,0.0,0,18.0,400.0,1.0028497,1.8519943,18.049196,452.14749,-11.245652
179.18,0.42049092,9.5014391,0.0,0,18.0,400.0,1.0024937,1.9098996,18.045555,452.0972,-11.261729
179.1824,0.44391695,9.5026655,0.0,0,18.0,400.0,1.0031691,2.0780272,18.045776,452.04688,-11.28
179.1848,0.42111608,9.500226,0.0,0,18.0,400.0,1.0039185,1.9787285,18.047289,451.99658,-11.298654
179.1872,0.39479885,9.4973459,0.0,0,18.0,400.0,1.0040621,1.8740966,18.044165,451.94989,-11.316843
179.1896,0.41909713,9.5007524,0.0,0,18.0,400.0,1.0034661,1.9102991,18.046701,451.90677,-11.332588
179.192,0.44319424,9.5065384,0.0,0,18.0,400.0,1.0031029,2.0530307,18.046108,451.86365,-11.349421
179.2941,0.40074366,9.5007896,0.0,0,18.0,17.344135,1.0035424,1.8710071,18.035316,448.85144,-11.469823
180.4941,0.33858305,9.5130491,0.0,0,18.0,7.588619e-16,1.005723,1.5763321,18.000214,422.8414,-11.481796
181.6941,0.31306136,9.5215588,0.0,0,18.0,3.2805479e-32,1.0072368,1.4548146,17.999151,408.47736,-11.482196
182.8941,0.29784518,9.5287018,0.0,0,18.0,1.4012985e-45,1.0085156,1.3857425,17.999804,396.24173,-11.483264
184.0941,0.29018423,9.5362062,0.0,0,18.0,1.4012985e-45,1.0099272,1.3392748,18.000275,384.9176,-11.483393
185.2941,0.28481251,9.5431213,0.0,0,18.0,1.4012985e-45,1.0112163,1.3177364,18.000141,373.85773,-11.482395
186.4941,0.28857434,9.5489521,0.0,0,18.0,1.4012985e-45,1.0122943,1.3305703,17.999659,363.62961,-11.482207
187.6941,0.28273737,9.5555744,0.0,0,18.0,1.4012985e-45,1.0134426,1.3087424,17.999075,353.58075,-11.482074
188.8941,0.28089237,9.5626707,0.0,0,18.0,1.4012985e-45,1.01472,1.2983854,17.99991,343.80847,-11.482314
190.0941,0.27878326,9.5681267,0.0,0,18.0,1.4012985e-45,1.0156982,1.2802585,18.000134,334.38959,-11.482785
191.2941,0.28057933,9.5739708,0.0,0,18.0,1.4012985e-45,1.0168008,1.2953175,17.999262,325.56927,-11.483451
192.4941,0.27763045,9.5802288,0.0,0,18.0,1.4012985e-45,1.0180283,1.2736853,17.999855,316.56403,-11.483633
193.6941,0.27777413,9.5864449,0.0,0,18.0,1.4012985e-45,1.0191735,1.2779809,18.000076,307.97787,-11.4834
194.8941,0.27751589,9.5914192,0.0,0,18.0,1.4012985e-45,1.0200448,1.2737339,18.00012,299.74747,-11.483479
196.0941,0.2736409,9.5971432,0.0,0,18.0,1.4012985e-45,1.021135,1.25737,17.999926,291.58771,-11.483129
197.2941,0.27619183,9.6026382,0.0,0,18.0,1.4012985e-45,1.0221941,1.2659581,18.000513,283.54883,-11.483058
198.4941,0.27221045,9.606863,0.0,0,18.0,1.4012985e-45,1.0229616,1.2462678,17.999771,275.83392,-11.48288
199.6941,0.27400309,9.6122255,0.0,0,18.0,1.4012985e-45,1.0239092,1.25762,18.000393,268.24435,-11.482849
200.8941,0.27226189,9.6174812,0.0,0,18.0,1.4012985e-45,1.0248312,1.2437546,18.000227,261.06821,-11.482195
202.0941,0.27265015,9.6222868,0.0,0,18.0,1.4012985e-45,1.0257185,1.2460295,17.999617,253.93178,-11.482276
203.2941,0.2718651,9.6267128,0.0,0,18.0,1.4012985e-45,1.0266002,1.2355691,17.999376,247.09869,-11.482603
204.4941,0.27337843,9.631217,0.0,0,18.0,1.4012985e-45,1.0274777,1.2482605,17.999746,240.53903,-11.482972
205.6941,0.27482101,9.6358976,0.0,0,18.0,1.4012985e-45,1.0283551,1.2527406,18.000853,234.04323,-11.482893
206.8941,0.26726297,9.6395931,0.0,0,18.0,1.4012985e-45,1.0290163,1.220644,17.999899,227.71733,-11.483128
208.0941,0.27093741,9.6438522,0.0,0,18.0,1.4012985e-45,1.0298184,1.2289943,18.000256,221.70367,-11.482799
209.2941,0.268085,9.6476536,0.0,0,18.0,1.4012985e-45,1.0305824,1.2164578,18.000013,215.89352,-11.482868
210.4941,0.26937053,9.6514368,0.0,0,18.0,1.4012985e-45,1.0312728,1.2269714,17.999922,210.16174,-11.483301
211.6941,0.26630515,9.6557989,0.0,0,18.0,1.4012985e-45,1.0320233,1.2072306,17.999914,204.63605,-11.483302
212.8941,0.26845875,9.6596317,0.0,0,18.0,1.4012985e-45,1.0326788,1.2166865,18.00013,199.33279,-11.483161
214.0941,0.26701996,9.6628866,0.0,0,18.0,1.4012985e-45,1.0333349,1.2071464,17.998766,194.21638,-11.482867
215.2941,0.26272056,9.6671495,0.0,0,18.0,1.4012985e-45,1.0341853,1.1830871,18.000313,189.25287,-11.482944
216.4941,0.26532766,9.67068,0.0,0,18.0,1.4012985e-45,1.0348587,1.1950356,17.999891,184.48624,-11.483347
217.6941,0.2624923,9.673749,0.0,0,18.0,1.4012985e-45,1.0353763,1.1897112,17.99905,179.77177,-11.483438
218.8941,0.26734921,9.6770926,0.0,0,18.0,1.4012985e-45,1.0360649,1.2057215,18.000143,175.20564,-11.483149
220.0941,0.26335642,9.6804104,0.0,0,18.0,1.4012985e-45,1.0367126,1.1891644,17.999277,170.88908,-11.483245
221.2941,0.26219043,9.6831636,0.0,0,18.0,1.4012985e-45,1.0371869,1.177061,17.999739,166.5661,-11.483262
222.4941,0.26284546,9.6864634,0.0,0,18.0,1.4012985e-45,1.0377275,1.1881238,17.999403,162.41478,-11.483686
223.6941,0.26006326,9.6896152,0.0,0,18.0,1.4012985e-45,1.0383153,1.1733434,18.000626,158.51741,-11.483348
224.8941,0.25628716,9.6926374,0.0,0,18.0,1.4012985e-45,1.0389673,1.1535188,17.998951,154.58191,-11.483299
226.0941,0.25951025,9.6952858,0.0,0,18.0,1.4012985e-45,1.0395011,1.1670302,18.000128,150.87617,-11.483351
227.2941,0.2635991,9.6981268,0.0,0,18.0,1.4012985e-45,1.0399873,1.1841679,17.999886,147.18097,-11.483505
228.4941,0.25884348,9.700757,0.0,0,18.0,1.4012985e-45,1.0404742,1.1672869,18.00029,143.64883,-11.483355
229.6941,0.26015788,9.7031784,0.0,0,18.0,1.4012985e-45,1.0410092,1.171342,18.000162,140.12842,-11.483193
230.8941,0.25309515,9.7053394,0.0,0,18.0,1.4012985e-45,1.0413716,1.1373645,18.000494,136.82797,-11.483015
232.0941,0.26276726,9.7077885,0.0,0,18.0,1.4012985e-45,1.0417606,1.1791486,17.999645,133.61037,-11.483342
233.2941,0.25815114,9.7107544,0.0,0,18.0,1.4012985e-45,1.0423231,1.1587852,17.99992,130.38069,-11.483006
234.4941,0.25734872,9.7130451,0.0,0,18.0,1.4012985e-45,1.0427811,1.1595722,17.999765,127.24062,-11.482944
235.6941,0.25315422,9.7152777,0.0,0,18.0,1.4012985e-45,1.0432853,1.136714,17.999445,124.23372,-11.482346
236.8941,0.25421536,9.7174273,0.0,0,18.0,1.4012985e-45,1.0436473,1.1404573,17.999973,121.36044,-11.482961
238.0941,0.25519621,9.7196207,0.0,0,18.0,1.4012985e-45,1.0440415,1.1361606,17.99976,118.67818,-11.482605
239.1941,0.25097549,9.7215128,0.0,0,18.0,1.4012985e-45,1.0443985,1.1201067,18.000097,116.08408,-11.48243