File: examples/dan-msc-case-studies/CS3/data/01 raw data/baron_test_114.csv
Time(sec),Force(kN),Jaw(mm),PowAngle(deg),Power(W),Pram,PTemp,Strain,Stress(MPa),Stroke(mm),TC1(C),wedge(mm)
0.0,1.0926489,0.00056547712,0.0,0,11.076097,0.0012585561,4.1985055e-05,13.919309,11.076454,23.280907,-9.1208792
1.1,1.0361263,-0.0011442037,0.0,0,11.076097,3.2158797,-7.3063078e-05,13.197878,11.076307,23.336699,-9.48631
2.2,0.99113059,-0.0019517075,0.0,0,11.076097,6.5158815,-0.00011972924,12.619071,11.077317,23.200224,-9.4828758
3.3,0.99970913,-0.0016542037,0.0,0,11.076097,9.8158808,-0.00011737171,12.737144,11.076403,23.229895,-9.48349
4.4,0.97487253,-0.0018322626,0.0,0,11.076097,13.115879,-0.00010750044,12.404792,11.076843,23.191675,-9.4809656
5.5,0.94295627,-0.0019093535,0.0,0,11.076097,16.415888,-9.7177137e-05,12.008193,11.075864,23.220329,-9.4784374
6.6,0.93595731,-0.0019047116,0.0,0,11.076097,19.715881,-0.00015293805,11.932579,11.076143,23.250582,-9.4765339
7.7,0.91792166,-0.0020068206,0.0,0,11.076097,23.015881,-0.00013549549,11.681532,11.075535,23.2616,-9.4747124
8.8,0.90836799,-0.0021534506,17.818247,0,11.076097,26.315884,-0.00013562076,11.564991,11.075775,23.262724,-9.4728079
9.9,0.91014278,-0.0022910037,31.564194,0,11.076097,29.615885,-0.00015822869,11.599028,11.075985,23.750885,-9.4706831
11.0,0.92397875,-0.003745035,39.016384,0,11.076097,32.915897,-0.00024450864,11.765365,11.076553,25.356876,-9.4692144
12.1,0.93622667,-0.0058987141,43.741722,0,11.076097,36.215893,-0.00040584392,11.935118,11.076185,28.166534,-9.4678288
13.2,0.95108008,-0.0092389919,46.581474,0,11.076097,39.515892,-0.0006035057,12.121004,11.077158,31.97691,-9.4662113
14.3,0.94668561,-0.013158691,48.374821,0,11.076097,42.815887,-0.00084476906,12.062745,11.076095,36.433212,-9.4638157
15.4,0.96185887,-0.016206432,49.04985,0,11.076097,46.115887,-0.0011051834,12.272243,11.075987,41.3228,-9.4623451
16.5,0.97850108,-0.019658826,48.81226,0,11.076097,49.415886,-0.0013123772,12.482519,11.075244,46.642242,-9.4605503
17.6,0.98426044,-0.022770388,48.017319,0,11.076097,52.715885,-0.0015116918,12.550675,11.076564,51.487381,-9.4584427
18.7,0.98849636,-0.026057562,47.081787,0,11.076097,56.015881,-0.0017434062,12.607392,11.076238,56.088184,-9.4563885
19.8,0.99926287,-0.029165313,46.109623,0,11.076097,59.31588,-0.0019348771,12.749124,11.075923,60.329556,-9.4547386
20.9,0.99672115,-0.031236142,45.093231,0,11.076097,62.615879,-0.0021023008,12.712244,11.076303,64.074852,-9.4531317
22.0,0.99516052,-0.033071999,44.244965,0,11.076097,65.915886,-0.0021956093,12.703775,11.07599,67.399834,-9.4520569
23.1,0.99577248,-0.035136275,44.077152,0,11.076097,69.215889,-0.0023113873,12.703482,11.076011,70.388275,-9.4504147
24.2,0.98745483,-0.036954779,44.603527,0,11.076097,72.515892,-0.0024867451,12.602643,11.075654,72.956955,-9.4481134
25.3,0.98334813,-0.039180957,45.119385,0,11.076097,75.81588,-0.0026115212,12.548545,11.076316,75.627045,-9.4462204
26.4,0.97997761,-0.041093964,45.854523,0,11.076097,79.115883,-0.0027317714,12.524726,11.075568,78.335915,-9.4435711
27.5,0.99043036,-0.043342412,46.582027,0,11.076097,82.415878,-0.0028846085,12.664521,11.076664,81.169998,-9.4424639
28.6,0.99862117,-0.045806929,47.504883,0,11.076097,85.715881,-0.0030303157,12.767346,11.076125,84.127449,-9.4400597
29.7,0.99609971,-0.048347313,48.326015,0,11.076097,89.015884,-0.0032286139,12.729439,11.07642,87.37336,-9.4382544
30.8,1.0096961,-0.051769949,48.812252,0,11.076097,92.31588,-0.0034294848,12.902577,11.076472,90.675751,-9.4364967
31.9,1.0171813,-0.05492406,49.229694,0,11.076097,95.615883,-0.0036261934,13.006622,11.076678,94.385544,-9.4351292
33.0,1.0153036,-0.056905162,49.229733,0,11.076097,98.915886,-0.0038048793,12.966886,11.07593,97.850403,-9.4334421
34.1,1.0148863,-0.059631638,49.23468,0,11.076097,102.21589,-0.0039709825,12.974413,11.075804,101.54293,-9.4314747
35.2,1.0258809,-0.062109638,49.22974,0,11.076097,105.5159,-0.0041263937,13.12497,11.075496,105.14916,-9.4298716
36.3,1.0133983,-0.064707741,49.229733,0,11.076097,108.81589,-0.0043188417,12.959048,11.076166,108.58805,-9.4275351
37.4,1.0262241,-0.067323618,49.229733,0,11.076097,112.11591,-0.0044702259,13.131892,11.076305,111.9054,-9.4259243
38.5,1.0320277,-0.069815286,49.39827,0,11.076097,115.41589,-0.0046560275,13.201415,11.075726,115.16637,-9.4241343
39.6,1.0295311,-0.072478168,49.636227,0,11.076097,118.7159,-0.0048045283,13.160373,11.076302,118.30727,-9.4230499
40.7,1.0318676,-0.07506419,49.767666,0,11.076097,122.0159,-0.004965595,13.205728,11.076287,121.58925,-9.4209671
41.8,1.0466616,-0.077033199,50.042721,0,11.076097,125.3159,-0.0051456429,13.385542,11.075959,124.78259,-9.4194679
42.9,1.0437952,-0.079936408,50.438229,0,11.076097,128.61603,-0.00531686,13.359854,11.075856,127.77708,-9.4176054
44.0,1.0418211,-0.082504734,50.82275,0,11.076097,131.91589,-0.0054698652,13.342225,11.075644,131.04137,-9.4156218
45.1,1.0450847,-0.085124992,51.196163,0,11.076097,135.21588,-0.0056789983,13.383678,11.076135,134.32033,-9.4138165
46.2,1.044643,-0.088257678,51.196285,0,11.076097,138.51588,-0.005875017,13.386784,11.075967,137.77251,-9.4118452
47.3,1.0533098,-0.090929739,51.56982,0,11.076097,141.81589,-0.0060481499,13.511576,11.076579,141.11473,-9.4102039
48.4,1.0539205,-0.093758032,51.693787,0,11.076097,145.11588,-0.0062256521,13.513896,11.076338,144.39146,-9.4077444
49.5,1.0587034,-0.096995831,51.930683,0,11.076097,148.41586,-0.0064302809,13.564729,11.075902,147.87679,-9.4059238
50.6,1.0611706,-0.099667445,51.932369,0,11.076097,151.71588,-0.0066503892,13.608059,11.076351,151.19255,-9.4038706
51.7,1.0527697,-0.10296363,52.169357,0,11.076097,155.01587,-0.0068368437,13.498641,11.076425,154.43704,-9.40207
52.8,1.0577781,-0.10596522,52.283936,0,11.076097,158.31589,-0.0070135915,13.558639,11.076124,157.68866,-9.4004936
53.9,1.0605496,-0.10841407,52.635014,0,11.076097,161.61589,-0.0072223931,13.616025,11.075726,161.00229,-9.398592
55.0,1.0566158,-0.11096715,52.635494,0,11.076097,164.91589,-0.0073717386,13.555853,11.076664,164.5126,-9.3972235
56.1,1.058558,-0.11371012,52.635494,0,11.076097,168.21591,-0.007540137,13.57273,11.075833,167.8481,-9.395566
57.2,1.0610245,-0.11660846,52.905865,0,11.076097,171.51591,-0.0077509801,13.608532,11.076282,171.06985,-9.3942699
58.3,1.0512277,-0.11967472,52.97607,0,11.076097,174.8159,-0.0079390118,13.489446,11.076368,174.44551,-9.3924656
59.4,1.0565394,-0.12187165,52.97607,0,11.076097,178.11589,-0.0081051607,13.568734,11.076019,177.7375,-9.3908596
60.5,1.0547704,-0.12492114,53.098705,0,11.076097,181.41589,-0.0082814423,13.54016,11.077242,181.00909,-9.3893681
61.6,1.061319,-0.12787534,53.31665,0,11.076097,184.7159,-0.0084514003,13.641773,11.076124,184.32736,-9.387641
62.7,1.059316,-0.13034102,53.387218,0,11.076097,188.0159,-0.0086740991,13.616971,11.076463,187.52811,-9.3860188
63.8,1.0600638,-0.13340977,53.657223,0,11.076097,191.31589,-0.008849266,13.621792,11.076078,190.75238,-9.3839111
64.9,1.0564668,-0.13683529,53.929489,0,11.076097,194.61591,-0.0090535115,13.575767,11.076377,193.98749,-9.3822851
66.0,1.0607917,-0.13910472,53.975826,0,11.076097,197.91589,-0.0092559084,13.642474,11.076534,197.29916,-9.3804092
67.1,1.066738,-0.14217229,54.262665,0,11.076097,201.2159,-0.0094398651,13.707909,11.075894,200.56653,-9.378336
68.2,1.0558923,-0.14545336,54.305416,0,11.076097,204.51588,-0.0096381111,13.590086,11.075878,203.90318,-9.3765078
69.3,1.0710665,-0.14857975,54.624023,0,11.076097,207.81587,-0.0098707816,13.792087,11.07653,207.11491,-9.3750086
70.4,1.0713743,-0.15246943,54.823837,0,11.076097,211.11589,-0.010116445,13.776254,11.076428,210.41507,-9.3732634
71.5,1.0645241,-0.15551265,54.931637,0,11.076097,214.41591,-0.010335177,13.699695,11.07646,213.70135,-9.3714943
72.6,1.0633297,-0.15890865,55.239254,0,11.076097,217.7159,-0.010526205,13.682392,11.076349,216.90707,-9.3694973
73.7,1.0670596,-0.1620461,55.535885,0,11.076097,221.01588,-0.010712908,13.72462,11.076253,220.11121,-9.3677931
74.8,1.066064,-0.1650165,55.843483,0,11.076097,224.3159,-0.010955931,13.71973,11.07621,223.43631,-9.365963
75.9,1.0687588,-0.16815625,56.10944,0,11.076097,227.61591,-0.011140301,13.768015,11.076257,226.72357,-9.3637409
77.0,1.0718625,-0.17154184,56.129147,0,11.076097,230.91591,-0.011340209,13.812837,11.076366,230.03479,-9.362318
78.1,1.0706419,-0.17412008,56.425777,0,11.076097,234.21591,-0.011569086,13.790803,11.076352,233.34317,-9.3605061
79.2,1.0709354,-0.17696488,56.475941,0,11.076097,237.5159,-0.011732099,13.801029,11.076647,236.85454,-9.3586845
80.3,1.0664442,-0.17976473,56.700169,0,11.076097,240.8159,-0.011905659,13.745553,11.075462,240.28809,-9.3561831
81.4,1.0684947,-0.18255863,56.711422,0,11.076097,244.11589,-0.01212386,13.786621,11.076204,243.70932,-9.355011
82.5,1.0677522,-0.18562657,56.711422,0,11.076097,247.41591,-0.012295429,13.754648,11.076248,247.11522,-9.3531532
83.6,1.0646693,-0.18870135,56.711422,0,11.076097,250.7159,-0.012501503,13.727015,11.076405,250.50432,-9.35145
84.7,1.0565137,-0.19159164,56.711422,0,11.076097,254.0159,-0.012699191,13.623549,11.076084,253.91437,-9.3491411
85.8,1.0709622,-0.19514079,56.711422,0,11.076097,257.31616,-0.01291764,13.830122,11.076121,257.25558,-9.3472347
86.9,1.0611069,-0.19818351,56.711422,0,11.076097,260.61615,-0.013147582,13.681295,11.076304,260.52734,-9.3458252
88.0,1.0595927,-0.20096949,56.711422,0,11.076097,263.91586,-0.013294755,13.672426,11.075664,263.88943,-9.3438129
89.1,1.067423,-0.20398381,56.711422,0,11.076097,267.21588,-0.013483368,13.782917,11.07619,267.16159,-9.3421688
90.2,1.0594362,-0.20669967,56.752537,0,11.076097,270.51587,-0.013710359,13.682105,11.075911,270.29684,-9.3403883
91.3,1.0642781,-0.20969792,56.986084,0,11.076097,273.81589,-0.013874725,13.746176,11.077158,273.42035,-9.3386889
92.4,1.0592784,-0.21276537,57.044647,0,11.076097,277.11584,-0.014052778,13.668758,11.076916,276.66653,-9.3369398
93.5,1.0661541,-0.216242,57.260738,0,11.076097,280.41586,-0.014335355,13.77202,11.0761,279.79425,-9.3346796
94.6,1.0735385,-0.21986528,57.535397,0,11.076097,283.71588,-0.014557173,13.869966,11.075956,283.03052,-9.3333549
95.7,1.0728242,-0.22196311,57.809921,0,11.076097,287.0159,-0.014668467,13.86329,11.075645,286.33942,-9.3309708
96.8,1.0634037,-0.22501951,57.810051,0,11.076097,290.31592,-0.014905034,13.741814,11.076509,289.7088,-9.3296432
97.9,1.0716562,-0.22815502,57.902931,0,11.076097,293.61594,-0.015100896,13.863235,11.07609,293.0762,-9.3277149
99.0,1.0653682,-0.23141998,58.073727,0,11.076097,296.91592,-0.015309937,13.777135,11.076693,296.42877,-9.3257875
100.1,1.0587816,-0.23505366,58.073727,0,11.076097,300.21591,-0.01554641,13.699169,11.076009,299.75128,-9.3240108
101.2,1.0704135,-0.23847432,58.073727,0,11.076097,303.51593,-0.015772386,13.841024,11.076335,303.18713,-9.3223085
102.3,1.0691276,-0.24288514,58.149109,0,11.076097,306.81592,-0.016070405,13.826955,11.075866,306.49805,-9.3202105
103.4,1.0702463,-0.2447744,58.283371,0,11.076097,310.11591,-0.016183358,13.868895,11.075549,309.83978,-9.3186789
104.5,1.0797226,-0.24776627,58.336987,0,11.076097,313.41589,-0.01636512,13.980302,11.076743,313.15298,-9.3171473
105.6,1.0711854,-0.25105414,58.337399,0,11.076097,316.71588,-0.016615961,13.863777,11.076058,316.57816,-9.3150692
106.7,1.0658709,-0.25450063,58.302925,0,11.076097,320.0159,-0.016806006,13.814941,11.076745,319.89578,-9.3135843
107.8,1.0622536,-0.25814211,58.337349,0,11.076097,323.31589,-0.017038763,13.753755,11.07592,323.20395,-9.3115511
108.9,1.0746505,-0.26192382,58.337399,0,11.076097,326.61588,-0.017332016,13.922759,11.0761,326.5336,-9.3100195
110.0,1.06767,-0.26541781,58.337399,0,11.076097,329.91461,-0.01753513,13.846212,11.075154,329.79895,-9.3077602
111.1,0.066426568,-0.27968594,56.484222,0,11.076097,329.99976,-0.018453175,0.85920376,11.07687,332.71692,-9.3083601
112.2,0.063385911,-0.27949846,54.202328,0,11.076097,329.99976,-0.018491499,0.82364953,11.076692,334.95563,-9.3082256
113.3,0.035787318,-0.27962884,51.93261,0,11.076097,329.99976,-0.018452976,0.47385529,11.076263,335.93259,-9.3080454
114.4,0.029388882,-0.27896458,50.181957,0,11.076097,329.99976,-0.018393699,0.38369149,11.076096,335.47983,-9.3080301
115.5,0.023447765,-0.27768344,50.008049,0,11.076097,329.99976,-0.01836592,0.29862267,11.076336,333.92215,-9.3082666
116.6,0.014073311,-0.27620232,50.795361,0,11.076097,329.99976,-0.018242853,0.19518703,11.076173,331.62134,-9.3080902
117.7,0.011021167,-0.27554423,52.582401,0,11.076097,329.99976,-0.018173175,0.14231576,11.075876,329.04736,-9.3075018
118.8,0.0067155594,-0.27389774,54.903484,0,11.076097,329.99976,-0.018119583,0.075009428,11.076789,326.50906,-9.3080235
119.9,0.004230916,-0.2735875,57.247635,0,11.076097,329.99976,-0.018068263,0.059797086,11.076653,324.36475,-9.3078556
121.0,0.0051483018,-0.27369618,59.578484,0,11.076097,329.99976,-0.0180643,0.071033791,11.077173,322.67783,-9.3079538
122.1,0.0055084466,-0.27266636,61.678059,0,11.076097,329.99976,-0.018042842,0.064943165,11.075477,321.50894,-9.307868
123.2,0.0065055531,-0.27253425,63.568409,0,11.076097,329.99976,-0.018012414,0.099988423,11.076224,320.91815,-9.3080044
124.3,0.0176998,-0.27234107,65.107773,0,11.076097,329.99976,-0.017981786,0.23300095,11.076235,320.88971,-9.3078833
125.4,0.027396193,-0.27234715,66.185081,0,11.076097,329.99976,-0.018005209,0.36451319,11.07595,321.69012,-9.3076925
126.5,0.04894549,-0.27419341,66.704895,0,11.076097,329.99976,-0.018118849,0.64066756,11.075926,323.50812,-9.3077431
127.6,0.054926254,-0.27664638,66.44342,0,11.076097,329.99976,-0.018271433,0.70868015,11.075855,326.22769,-9.3078241
128.7,0.056563281,-0.27892977,65.832031,0,11.076097,329.99976,-0.018435724,0.74387181,11.07647,329.22943,-9.3077154
129.8,0.062724724,-0.28134784,64.561531,0,11.076097,329.99976,-0.018584302,0.82426572,11.075731,332.27112,-9.3077068
130.9,0.066746816,-0.28324372,62.859604,0,11.076097,329.99976,-0.018700331,0.86791605,11.076079,334.89639,-9.3077059
132.0,0.057000991,-0.28403547,60.805897,0,11.076097,329.99976,-0.018761566,0.7448687,11.076241,336.9873,-9.3074198
133.1,0.063119262,-0.28456563,58.595741,0,11.076097,329.99976,-0.018794412,0.83789051,11.076299,338.32233,-9.307971
134.2,0.057782214,-0.28485987,56.205353,0,11.076097,329.99976,-0.018819446,0.72502869,11.075346,338.86804,-9.307539
135.3,0.035726476,-0.28473127,54.305576,0,11.076097,329.99976,-0.018812042,0.45446953,11.075796,338.41754,-9.3075514
136.4,0.028209116,-0.28426376,52.976158,0,11.076097,329.99976,-0.018773563,0.3744396,11.076138,337.07111,-9.307478
137.5,0.018425863,-0.283232,52.207767,0,11.076097,329.99976,-0.018707141,0.22329256,11.076437,335.38788,-9.3075666
138.6,0.0059175738,-0.28199455,52.411293,0,11.076097,329.99976,-0.018626217,0.087307028,11.075715,333.14648,-9.3076458
139.7,0.006072755,-0.2810308,53.653709,0,11.076097,329.99976,-0.018554276,0.08906813,11.076086,330.66318,-9.3076382
140.8,-0.00075450807,-0.28025281,55.437241,0,11.076097,329.99976,-0.018509872,-0.0091022607,11.076701,328.06677,-9.3076181
141.9,-0.004478266,-0.27944708,57.580502,0,11.076097,329.99976,-0.018451229,-0.042386234,11.075875,325.64841,-9.3075943
143.0,-0.0051708692,-0.27915102,59.881302,0,11.076097,329.99976,-0.018436642,-0.075329557,11.07661,323.42926,-9.3073092
144.1,-0.010508256,-0.27885064,62.154675,0,11.076097,329.99976,-0.018429426,-0.14983439,11.07588,321.66055,-9.3075209
145.2,-0.008797654,-0.27858216,64.312714,0,11.076097,329.99976,-0.018405156,-0.10317036,11.075698,320.35358,-9.3073263
146.3,-0.003875071,-0.27889884,66.128777,0,11.076097,329.99976,-0.01842268,-0.048985809,11.076247,319.65729,-9.3073816
147.4,-0.0067156893,-0.27850893,67.699013,0,11.076097,329.99976,-0.018399136,-0.089284174,11.076033,319.59915,-9.3070669
148.5,0.0070029851,-0.27865171,68.954201,0,11.076097,329.99976,-0.018409463,0.092476435,11.075727,320.03516,-9.307086
149.6,0.018833112,-0.27894953,69.859558,0,11.076097,329.99976,-0.018433712,0.25014621,11.075511,321.02518,-9.3074474
150.7,0.043722566,-0.28021118,70.158684,0,11.076097,329.99976,-0.018509829,0.58321744,11.075891,323.19974,-9.3070288
151.8,0.057504408,-0.2830691,69.86895,0,11.076097,329.99976,-0.01870556,0.74768788,11.076627,326.53714,-9.3069448
152.9,0.067499243,-0.28630099,68.828224,0,11.076097,329.99976,-0.01890729,0.88610512,11.075848,330.61124,-9.3071432
154.0,0.069463804,-0.28942797,67.127243,0,11.076097,329.99976,-0.01910397,0.91238141,11.075883,334.74744,-9.3074226
155.1,0.074947469,-0.03122648,64.883804,0,11.076097,329.99976,-0.0020804887,0.96647471,11.075686,338.39923,-9.3070621
155.2863,0.15083399,0.029871525,64.35791,0,11.076099,1.5468613e-08,0.0020337175,1.9625788,11.075458,338.83304,-9.3074055
155.2885,0.14753634,0.03555375,64.35791,0,11.076099,1.544973e-23,0.0022849231,1.7973322,11.076471,338.84641,-9.3072329
155.2907,0.13934767,0.031328049,55.347706,0,11.076099,1.5430874e-38,0.0021128671,1.7932711,11.075638,338.87253,-9.3068018
155.2929,0.18664588,0.034697417,41.188965,0,11.076099,0.0,0.002273259,2.3420537,11.076565,338.90594,-9.3069944
155.2951,0.16099603,0.030305728,27.030222,0,11.076099,0.0,0.0020657803,2.0509732,11.076837,338.93939,-9.3068962
155.2973,0.16606995,0.037433345,12.871481,0,11.076099,0.0,0.002469003,2.1005187,11.076602,338.97281,-9.3061743
155.2995,0.15841395,0.031496145,0.0,0,11.076099,0.0,0.0021633874,2.095542,11.076977,339.0032,-9.3073902
155.3017,0.15776493,0.033694662,0.0,0,11.076099,0.0,0.0022427554,2.0570979,11.07774,339.0032,-9.3078976
155.3039,0.151613,0.032564286,0.0,0,11.076099,0.0,0.002145451,1.8822755,11.078664,339.0032,-9.3083906
155.3061,0.15320425,0.03821779,0.0,0,11.076099,0.0,0.0025286481,1.9712888,11.074346,339.0032,-9.3080034
155.3083,0.15543167,0.032617137,0.0,0,11.076099,0.0,0.0022246344,1.9683565,11.077193,339.0032,-9.3071051
155.3105,0.15535289,0.033572409,0.0,0,11.076099,0.0,0.0022860535,1.9757694,11.07655,339.00684,-9.3077784
155.3127,0.16338862,0.031199526,0.0,0,11.076099,0.0,0.0020903174,2.0783319,11.077158,339.01352,-9.3068829
155.3149,0.18305646,0.035988092,0.0,0,11.076099,0.0,0.0023937419,2.1828833,11.075273,339.0202,-9.3065414
155.3171,0.18056352,0.03197106,0.0,0,11.076099,0.0,0.002140271,2.3328896,11.073504,339.02689,-9.3074341
155.3193,0.1807756,0.033361323,0.0,0,11.076099,0.0,0.0022258805,2.2065878,11.075528,339.03357,-9.3061152
155.3215,0.17092493,0.030957688,0.0,0,11.076099,0.0,0.0020271041,2.2511587,11.079596,339.05362,-9.3071012
155.3237,0.16685218,0.036730096,0.0,0,11.076099,0.0,0.0024948332,2.1356876,11.075034,339.0737,-9.3070393
155.3259,0.16397668,0.032638401,0.0,0,11.076099,0.0,0.0021830862,2.2175395,11.075826,339.09375,-9.3067436
155.3281,0.17166971,0.034939155,0.0,0,11.076099,0.0,0.0024123953,2.1190383,11.076196,339.1138,-9.3058958
155.3303,0.16961426,0.032740224,0.0,0,11.076099,0.0,0.0021932258,2.0943797,11.077498,339.13083,-9.3067589
155.3325,0.18040626,0.036640305,0.0,0,11.076099,0.0,0.0024599524,2.2606058,11.076858,339.1442,-9.3062096
155.3347,0.19803157,0.034196392,0.0,0,11.076099,0.0,0.0021978349,2.5291803,11.075413,339.15756,-9.305995
155.3369,0.19539168,0.035348281,0.0,0,10.765901,0.0,0.0024323098,2.5088158,11.076855,339.17093,-9.3063288
155.3391,0.1941119,0.03246022,0.0,0,10.435008,0.0,0.0021157884,2.456418,11.073035,339.1843,-9.3071156
155.3413,0.21715872,0.037314165,0.0,0,10.104116,0.0,0.0025623217,2.7022216,11.024508,339.72031,-9.3063421
155.3435,0.19190168,0.034759503,0.0,0,9.7732229,0.0,0.0022592356,2.461889,10.849427,340.30859,-9.3065567
155.3457,0.20921572,0.033893529,0.0,0,9.4434071,0.0,0.0023424844,2.6900637,10.560497,340.89688,-9.3071604
155.3479,0.18999642,0.033218075,0.0,0,9.1214981,0.0,0.0021216664,2.5007758,10.189861,341.48514,-9.30583
155.3501,6.8640771,0.33860567,0.0,0,8.7995939,0.0,0.022126049,85.258949,9.7818241,342.45471,-9.3022022
155.3523,8.5197964,0.75679612,0.0,0,8.4910259,0.0,0.051238775,102.71066,9.2872419,344.09155,-9.300601
155.3545,9.1600409,1.1873049,0.0,0,8.1848736,0.0,0.082298607,106.98129,8.8454494,345.72836,-9.2999058
155.3567,9.2897053,1.5477393,0.0,0,7.8872557,0.0,0.10825188,106.31407,8.4931631,347.3652,-9.299119
155.3589,9.748745,1.818234,0.0,0,7.5959754,0.0,0.12900177,109.00294,8.1874552,349.00201,-9.2989979
155.3611,9.8789482,2.10305,0.0,0,7.3089881,0.0,0.15050107,108.27303,7.8928356,350.25574,-9.2992239
155.3633,10.056952,2.3697569,0.0,0,7.0319633,0.0,0.17170773,107.85206,7.6308141,351.42429,-9.2996712
155.3655,10.361632,2.6128302,0.0,0,6.7554417,0.0,0.1909007,108.98978,7.3803358,352.59286,-9.2999945
155.3677,10.607566,2.8616877,0.0,0,6.4917622,0.0,0.21149728,109.25821,7.1270924,353.76141,-9.2996168
155.3699,10.844265,3.1176493,0.0,0,6.2282019,0.0,0.23244418,109.33016,6.8675718,354.7131,-9.2997894
155.3721,11.159906,3.3763716,0.0,0,5.9743834,0.0,0.25471121,110.0925,6.6052566,355.08646,-9.2997065
155.3743,11.420548,3.6478581,0.0,0,5.7237153,0.0,0.27800661,110.16586,6.334971,355.45984,-9.2997637
155.3765,11.709612,3.9238374,0.0,0,5.4789333,0.0,0.3030667,110.06367,6.0648623,355.83319,-9.2997227
155.3787,11.96611,4.193296,0.0,0,5.2404532,0.0,0.32713807,109.83189,5.7911167,356.20654,-9.2996674
155.3809,12.249725,4.4566426,0.0,0,5.0044241,0.0,0.35230467,109.60394,5.5265179,356.41507,-9.2998199
155.3831,12.541943,4.7082119,0.0,0,4.7776041,0.0,0.37599409,109.58466,5.2658114,356.56174,-9.3004675
155.3853,12.825057,4.9564528,0.0,0,4.5507841,0.0,0.40093043,109.29443,5.0212569,356.7084,-9.2999544
155.3875,13.106645,5.1915798,0.0,0,4.3343177,0.0,0.42400873,109.14703,4.7850723,356.8551,-9.2997265
155.3897,13.396709,5.4135208,0.0,0,4.1185417,0.0,0.44757557,108.94368,4.5613594,356.85388,-9.3002758
155.3919,13.706966,5.6344991,0.0,0,3.9097853,0.0,0.47037911,109.03444,4.3388476,356.18716,-9.2991295
155.3941,14.039765,5.8503461,0.0,0,3.7045693,0.0,0.4943029,109.01049,4.1236992,355.52045,-9.2989244
155.3963,14.345812,6.0613437,0.0,0,3.5032687,0.0,0.51677799,108.94536,3.9104333,354.85373,-9.300313
155.3985,14.684403,6.2690349,0.0,0,3.3080409,0.0,0.54107499,108.80437,3.7040834,354.18701,-9.3002939
155.4007,15.084338,6.4747887,0.0,0,3.11395,0.0,0.56414413,109.16821,3.500937,352.92468,-9.3004208
155.4029,15.495142,6.6812453,0.0,0,2.9282222,0.0,0.58957744,109.34875,3.2988105,351.32196,-9.3003864
155.4051,15.912553,6.8758574,0.0,0,2.7424984,0.0,0.61214519,109.78168,3.1017292,349.71927,-9.2984486
155.4073,16.349621,7.0657172,0.0,0,2.5644474,0.0,0.63692725,110.08558,2.9034274,348.11658,-9.2992458
155.4095,16.824072,7.2597899,0.0,0,2.3877873,0.0,0.66050482,110.58723,2.7169089,346.56662,-9.2981949
155.4117,17.319105,7.4433842,0.0,0,2.2160764,0.0,0.68578798,110.95808,2.5299134,345.54401,-9.2981539
155.4139,17.801706,7.6266403,0.0,0,2.0480404,0.0,0.70901215,111.50015,2.3507066,344.52142,-9.2977762
155.4161,18.327505,7.8009691,0.0,0,1.8824685,0.0,0.73429692,111.93886,2.17623,343.49881,-9.2976427
155.4183,18.911079,7.9760818,0.0,0,1.7226164,0.0,0.75756037,112.80354,1.9998779,342.47623,-9.2969379
155.4205,19.518764,8.14293,0.0,0,1.5630548,0.0,0.78301448,113.50469,1.8296149,341.05078,-9.2962627
155.4227,20.167154,8.3064976,0.0,0,1.4109213,0.0,0.80587095,114.6526,1.6640357,339.28964,-9.2964516
155.4249,20.84384,8.4663639,0.0,0,1.2588574,0.0,0.83154374,115.50063,1.5050632,337.52847,-9.2954082
155.4271,21.571581,8.6254587,0.0,0,1.1124125,0.0,0.85447842,116.79431,1.3432717,335.76733,-9.2950859
155.4293,22.319357,8.7758512,0.0,0,0.96778435,0.0,0.88022494,117.75444,1.1887444,334.00616,-9.2944155
155.4315,23.075382,8.9274826,0.0,0,0.82657731,0.0,0.90289599,119.04334,1.0405376,330.43106,-9.2945585
155.4337,23.873549,9.0630016,0.0,0,0.68903339,0.0,0.9272508,120.19137,0.89684343,326.85596,-9.2940674
155.4359,24.690947,9.2061281,0.0,0,0.55288601,0.0,0.94986641,121.53899,0.75515491,323.28082,-9.2932291
155.4381,25.58127,9.3402605,0.0,0,0.42198589,0.0,0.97542262,122.76099,0.61693597,319.70572,-9.2934179
155.4403,24.299702,9.4443045,0.0,0,0.29108587,0.0,0.9922201,115.04393,0.49468347,318.00253,-9.2936831
155.4425,23.097767,9.4517822,0.0,0,0.16620816,0.0,0.99569327,108.77325,0.44465131,318.54562,-9.2956781
155.4447,22.226141,9.4615355,0.0,0,0.041732151,0.0,0.99535722,104.58231,0.4190726,319.08871,-9.2970057
155.4469,21.645727,9.4725389,0.0,0,-0.080696426,0.0,0.99944824,101.45128,0.39090756,319.63181,-9.2981567
155.4491,21.474909,9.4791651,0.0,0,-0.20209241,0.0,0.99841869,100.73052,0.36133549,320.17487,-9.2983408
155.4513,21.657862,9.4780512,0.0,0,-0.32348844,0.0,1.0004112,101.41535,0.31051221,323.21304,-9.2993994
155.4535,21.822418,9.4868221,0.0,0,-0.44488442,0.0,0.99989247,102.21498,0.24881928,326.5007,-9.2996559
155.4557,21.832584,9.4910746,0.0,0,-0.56628042,0.0,1.0029936,101.94267,0.1866198,329.78836,-9.2986889
155.4579,21.732147,9.5045767,0.0,0,-0.68767637,0.0,1.0028046,101.53964,0.13322991,333.07602,-9.2982435
155.4601,21.561863,9.4998236,0.0,0,-0.80907238,0.0,1.0044248,100.58031,0.084905177,335.66699,-9.2988052
155.4623,21.319513,9.5081892,0.0,0,-0.93046838,0.0,1.0037962,99.480286,0.050117608,337.03882,-9.3003998
155.4645,20.969618,9.5080929,0.0,0,-1.0518645,0.0,1.0059272,97.684143,0.027324015,338.41064,-9.3016691
155.4667,20.508823,9.5136185,0.0,0,-0.88153589,330.0,1.0046097,95.677284,0.015124775,339.78247,-9.300786
155.4689,19.988377,9.5092993,0.0,0,-0.46125633,330.0,1.0061467,93.112007,0.020016827,341.15427,-9.3003511
155.4711,19.543055,9.5136375,0.0,0,-0.040977493,330.0,1.0047375,91.162086,0.023366584,342.10379,-9.3010139
155.4733,19.182304,9.5132694,0.0,0,0.37930161,330.0,1.0070828,89.240669,0.025621474,342.95944,-9.3001165
155.4755,18.895922,9.518301,0.0,0,0.79958111,330.0,1.0053096,88.078804,0.027382072,343.81512,-9.3007879
155.4777,18.639626,9.5106783,0.0,0,1.2198603,330.0,1.0065138,86.823059,0.02533054,344.67081,-9.3011951
155.4799,18.074568,9.5169296,0.0,0,1.640139,330.0,1.0053768,84.307907,0.039721131,345.50458,-9.3021984
155.4821,16.750755,9.5076675,0.0,0,2.0604188,330.0,1.006007,78.127823,0.092040434,346.28003,-9.3024588
155.4843,14.398285,9.505537,0.0,0,2.4806981,330.0,1.0029329,67.505547,0.19585949,347.05548,-9.3042574
155.4865,9.8698997,9.4831324,0.0,0,2.9009769,330.0,1.0014966,46.638203,0.40340012,347.83093,-9.3072453
155.4887,0.22760297,9.3380384,0.0,0,3.3212562,330.0,0.97433519,0.8893888,0.7829355,348.60638,-9.31633
155.4909,0.44938359,9.1707563,0.0,0,3.7415352,330.0,0.94699776,2.2590182,1.3972417,349.2356,-9.3162012
155.4931,-0.32942492,9.0625896,0.0,0,4.1618147,330.0,0.92567855,-1.4883146,2.1440046,349.81,-9.3175678
155.4953,-0.036488108,8.9630051,0.0,0,4.5820937,330.0,0.91163099,-0.38543996,2.848593,350.38437,-9.3168945
155.4975,0.091069013,8.9270477,0.0,0,5.0023732,330.0,0.90318698,0.6051302,3.404855,350.95877,-9.3150434
155.4997,-0.22456108,8.9270821,0.0,0,5.4226518,330.0,0.90532297,-1.0956105,3.819396,351.33997,-9.314374
155.5019,0.095587656,8.9456701,0.0,0,5.8429317,330.0,0.90614629,0.38465807,4.2081285,350.85199,-9.3147354
155.5041,0.031661615,8.9851341,0.0,0,6.2632103,330.0,0.91474116,0.28526697,4.593842,350.36398,-9.3123903
155.5063,-0.084257469,9.0579462,0.0,0,6.6834898,330.0,0.92478311,-0.41824347,4.9825387,349.87598,-9.3113489
155.5085,-0.064278133,9.1400576,0.0,0,7.1037693,330.0,0.94071984,-0.29973158,5.3759189,349.388,-9.309988
155.5107,-0.14082848,9.2611237,0.0,0,7.5240483,330.0,0.9589209,-0.6700722,5.7960105,348.90884,-9.3105154
155.5129,-0.082060739,9.3808146,0.0,0,7.9443278,330.0,0.98260605,-0.41381273,6.2287378,348.43472,-9.3104362
155.5151,0.18885478,9.4454565,0.0,0,8.3646069,330.0,0.99265641,0.66120225,6.6786518,347.9606,-9.3095188
155.5173,-0.11024951,9.4251556,0.0,0,8.7848854,330.0,0.99087566,-0.41347471,7.1265383,347.48648,-9.3088684
155.5195,-0.089567006,9.4581299,0.0,0,9.2051649,330.0,0.99414182,-0.4661178,7.5645628,347.11258,-9.3075752
155.5217,-0.1181907,9.4566936,0.0,0,9.6254444,330.0,0.9966681,-0.61270267,7.998126,347.74069,-9.3077297
155.5239,0.082569145,9.4652586,0.0,0,10.045724,330.0,0.99592716,0.38091865,8.4325285,348.3688,-9.3068895
155.5261,-0.10324641,9.4571819,0.0,0,10.466002,330.0,0.99692273,-0.43782213,8.8619576,348.99695,-9.3075638
155.5283,-0.16003552,9.4670677,0.0,0,10.886282,330.0,0.99592298,-0.68474007,9.2935667,349.62506,-9.307847
155.5305,-0.11720283,9.4529896,0.0,0,11.306561,330.0,0.99603236,-0.57979113,9.7289982,350.15097,-9.3077335
155.5327,-0.0042250226,9.4586716,0.0,0,11.72684,330.0,0.99480873,-0.029061174,10.167432,350.59177,-9.306016
155.5349,-0.043590035,9.4540997,0.0,0,12.14712,330.0,0.99617237,-0.18264866,10.599744,351.03253,-9.3056974
155.5371,-0.097262748,9.4641562,0.0,0,12.567399,330.0,0.99532908,-0.41639572,11.02614,351.47333,-9.3060246
155.5393,-0.076890223,9.4531679,0.0,0,12.987678,330.0,0.9960615,-0.36009076,11.450389,351.91409,-9.306406
155.5415,-0.02580741,9.4557199,0.0,0,13.407957,330.0,0.99439627,-0.12870257,11.866014,350.65759,-9.3065662
155.5437,0.00042169416,9.4512892,0.0,0,13.828236,330.0,0.99580258,0.017465999,12.285924,349.40109,-9.3053646
155.5459,-0.1024931,9.4619837,0.0,0,14.248516,330.0,0.99506676,-0.40335342,12.71592,348.14459,-9.3046932
155.5481,-0.086823292,9.4548874,0.0,0,14.668795,330.0,0.99642593,-0.45271254,13.146692,346.88809,-9.306057
155.5503,-0.051547673,9.4596119,0.0,0,15.089074,330.0,0.99505806,-0.22426194,13.587688,346.20273,-9.3038568
155.5525,0.0067644077,9.449687,0.0,0,15.509354,330.0,0.99549574,0.041480634,14.03559,346.20273,-9.3029757
155.5547,0.012993412,9.4610443,0.0,0,15.929632,330.0,0.994618,0.067847945,14.473515,346.20273,-9.3045826
155.5569,-0.038198687,9.4512873,0.0,0,16.349911,330.0,0.9955765,-0.17843889,14.895783,346.20273,-9.3065462
155.5591,-0.1054104,9.4568167,0.0,0,16.770191,330.0,0.99452853,-0.47919253,15.314645,346.20273,-9.3046532
155.5613,0.00513105,9.4500055,0.0,0,17.19047,330.0,0.99567407,0.013375926,15.731332,347.8299,-9.3050423
155.5635,-0.049969502,9.4621582,0.0,0,17.61075,330.0,0.99493027,-0.21948364,16.144423,349.61978,-9.3045511
155.5657,-0.10335355,9.4545174,0.0,0,17.999401,330.0,0.99620581,-0.481406,16.560221,351.40967,-9.3046703
155.5679,-0.08446297,9.4578085,0.0,0,18.0,330.0,0.99466801,-0.41186646,16.976196,353.19952,-9.3044567
155.5701,-0.1273056,9.4532299,0.0,0,18.0,330.0,0.99611044,-0.59027892,17.370539,354.22928,-9.3035126
155.5723,-0.035812844,9.465085,0.0,0,18.0,330.0,0.99569517,-0.2096785,17.745735,353.92889,-9.3060827
155.5745,-0.00051077496,9.4510288,0.0,0,18.0,330.0,0.99544144,-0.0068496978,18.068617,353.62851,-9.3074274
155.5767,-0.06240315,9.4611835,0.0,0,18.0,330.0,0.99532616,-0.27443588,18.320145,353.32809,-9.3090191
155.5789,-0.0063529359,9.4577122,0.0,0,18.0,330.0,0.99703091,-0.017248238,18.49157,353.02771,-9.3121281
155.5811,-0.064809024,9.4754992,0.0,0,18.0,330.0,0.99768382,-0.25144708,18.55312,351.50864,-9.3174496
155.5833,-0.17480193,9.4725924,0.0,0,18.0,330.0,0.99919623,-0.8372829,18.50733,349.71875,-9.324585
155.5855,-0.087904572,9.4882517,0.0,0,18.0,330.0,1.0004028,-0.46815512,18.377533,347.92886,-9.3346367
155.5877,-0.093319654,9.4954615,0.0,0,18.0,330.0,1.0034627,-0.42893085,18.239859,346.13901,-9.3454037
155.5899,-0.062357794,9.5162296,0.0,0,18.0,330.0,1.0049767,-0.29600853,18.131142,345.1647,-9.3607073
155.5921,0.010972224,9.5222845,0.0,0,18.0,330.0,1.0082595,-0.017657012,18.06024,346.36517,-9.3779621
155.5943,0.066681847,9.5467768,0.0,0,18.0,330.0,1.0110562,0.24740571,18.037926,347.56564,-9.3974352
155.5965,0.036248349,9.5589237,0.0,0,18.0,330.0,1.0150833,0.18518303,18.040049,348.76611,-9.4157934
155.5987,0.0025167917,9.5900135,0.0,0,18.0,330.0,1.0185655,0.034949198,18.053358,349.96658,-9.434412
155.6009,-0.088900819,9.5957174,0.0,0,18.0,330.0,1.02167,-0.29404119,18.081514,350.74612,-9.4508333
155.6031,-0.1603218,9.6198988,0.0,0,18.0,330.0,1.0245303,-0.69849646,18.099865,351.36783,-9.4668922
155.6053,-0.16918273,9.6257143,0.0,0,18.0,330.0,1.0274562,-0.802145,18.119862,351.98953,-9.4846907
155.6075,-0.092107587,9.6532526,0.0,0,18.0,330.0,1.0304462,-0.48981032,18.132309,352.61121,-9.5012188
155.6097,-0.0018890817,9.6577673,0.0,0,18.0,330.0,1.0333436,-0.065473847,18.139914,352.88702,-9.5169439
155.6119,0.038931899,9.6817398,0.0,0,18.0,330.0,1.0360812,0.14676762,18.139038,351.60632,-9.5316629
155.6141,0.060632635,9.6909513,0.0,0,18.0,330.0,1.039608,0.25708789,18.13875,350.32565,-9.5464344
155.6163,0.025851702,9.7150354,0.0,0,18.0,330.0,1.0420274,0.13936256,18.138065,349.04495,-9.5622864
155.6185,-0.057250481,9.7178831,0.0,0,18.0,330.0,1.0445305,-0.21088237,18.134651,347.76428,-9.5787773
155.6207,-0.13746071,9.7420216,0.0,0,18.0,330.0,1.0475509,-0.56235242,18.132784,347.80014,-9.5948868
155.6229,-0.1756873,9.7534637,0.0,0,18.0,330.0,1.0514182,-0.7716552,18.135061,348.58829,-9.6114864
155.6251,-0.10764826,9.7811251,0.0,0,18.0,330.0,1.054608,-0.54287982,18.128405,349.3764,-9.6272497
155.6273,-0.038289499,9.7840691,0.0,0,18.0,330.0,1.0572125,-0.24219407,18.128866,350.16455,-9.642025
155.6295,0.043814626,9.8064127,0.0,0,18.0,330.0,1.0597841,0.11031011,18.122652,350.88467,-9.6558714
155.6317,0.064174779,9.8146248,0.0,0,18.0,330.0,1.0628352,0.21982734,18.120983,350.9248,-9.6724234
155.6339,0.04615565,9.8405056,0.0,0,18.0,330.0,1.0661665,0.2402893,18.1215,350.9649,-9.6874638
155.6361,-0.021677922,9.8482218,0.0,0,18.0,330.0,1.0692142,-0.044696219,18.119682,351.005,-9.7034254
155.6383,-0.10945372,9.869154,0.0,0,18.0,330.0,1.071992,-0.39558151,18.115389,351.04514,-9.7194662
155.6405,-0.14213243,9.8812838,0.0,0,18.0,330.0,1.0757018,-0.65742159,18.108889,351.06335,-9.736063
155.6427,-0.15793276,9.9087591,0.0,0,18.0,330.0,1.0795331,-0.70837051,18.113226,351.06335,-9.75457
155.6449,-0.069307141,9.9130535,0.0,0,18.0,330.0,1.0819639,-0.36481673,18.108145,351.06335,-9.7706976
155.6471,0.020416919,9.9340992,0.0,0,18.0,330.0,1.0849333,0.043456633,18.106544,351.06335,-9.7877626
155.6493,0.047279749,9.9419689,0.0,0,18.0,330.0,1.0876737,0.19781999,18.10643,351.06335,-9.8038473
155.6515,0.043711968,9.9680023,0.0,0,18.0,330.0,1.09136,0.21202911,18.106289,351.63721,-9.818099
155.6537,0.013708834,9.9746132,0.0,0,18.0,330.0,1.0938902,0.10841779,18.104479,352.21109,-9.8342943
155.6559,-0.082273468,9.9981756,0.0,0,18.0,330.0,1.097587,-0.2702001,18.104456,352.78494,-9.8482714
155.6581,-0.13197443,10.00765,0.0,0,18.0,330.0,1.100421,-0.56230825,18.103905,353.3588,-9.8647108
155.6603,-0.1602473,10.032577,0.0,0,18.0,330.0,1.104296,-0.67112827,18.103363,353.58392,-9.881525
155.6625,-0.10818382,10.039521,0.0,0,18.0,330.0,1.1071167,-0.52970856,18.103985,353.39059,-9.8963146
155.6647,-0.014516843,10.058599,0.0,0,18.0,330.0,1.1099613,-0.15494716,18.102962,353.19724,-9.9130421
155.6669,0.058629274,10.066897,0.0,0,18.0,330.0,1.1124622,0.20635694,18.102516,353.00388,-9.9287901
155.6691,0.057282805,10.091665,0.0,0,18.0,330.0,1.1164377,0.23624483,18.103817,352.81055,-9.9433098
155.6713,0.0098634753,10.098993,0.0,0,18.0,330.0,1.1189361,0.078040048,18.101717,352.55054,-9.9588289
155.6735,-0.042353045,10.12028,0.0,0,18.0,330.0,1.1225704,-0.1083698,18.100775,352.28384,-9.9762535
155.6757,-0.11811993,10.132456,0.0,0,18.0,330.0,1.1257631,-0.43602073,18.10128,352.01715,-9.9926291
155.6779,-0.16017582,10.160826,0.0,0,18.0,330.0,1.1307162,-0.63598096,18.100431,351.75046,-10.008711
155.6801,-0.14465247,10.16663,0.0,0,18.0,330.0,1.1328846,-0.61621624,18.096235,351.85715,-10.025093
155.6823,-0.056718864,10.182693,0.0,0,18.0,330.0,1.1355969,-0.31335968,18.100304,352.61719,-10.042636
155.6845,0.03531976,10.194654,0.0,0,18.0,330.0,1.1385865,0.071996115,18.095568,353.37726,-10.056531
155.6867,0.070659839,10.223159,0.0,0,18.0,330.0,1.1437471,0.26737639,18.099617,354.1373,-10.072191
155.6889,0.036548469,10.228716,0.0,0,18.0,330.0,1.1455269,0.1762218,18.095581,354.89737,-10.088816
155.6911,-0.020630656,10.247356,0.0,0,18.0,330.0,1.1491401,-0.051048797,18.090574,355.0192,-10.104874
155.6933,-0.085961998,10.259488,0.0,0,18.0,330.0,1.1517487,-0.30551472,18.092596,354.99918,-10.12058
155.6955,-0.14190444,10.285718,0.0,0,18.0,330.0,1.1568925,-0.52329367,18.089846,354.97919,-10.138082
155.6977,-0.15679997,10.297198,0.0,0,18.0,330.0,1.1600096,-0.63106579,18.092604,354.9592,-10.153947
155.6999,-0.10191972,10.31594,0.0,0,18.0,330.0,1.1636224,-0.4509244,18.091841,354.72644,-10.170815
155.7021,0.0070469086,10.321651,0.0,0,18.0,330.0,1.1649661,-0.043192711,18.08979,353.92636,-10.187366
155.7043,0.066296943,10.346102,0.0,0,18.0,330.0,1.1701144,0.2338212,18.090176,353.12631,-10.202231
155.7065,0.071651295,10.354584,0.0,0,18.0,330.0,1.1722403,0.29623678,18.087992,352.32623,-10.218028
155.7087,0.012026415,10.375492,0.0,0,18.0,330.0,1.1764599,0.10072809,18.086142,351.52618,-10.231362
155.7109,-0.070803531,10.389191,0.0,0,18.0,330.0,1.1796284,-0.22667389,18.089125,351.53589,-10.248849
155.7131,-0.13845927,10.412189,0.0,0,18.0,330.0,1.1843873,-0.50255603,18.088961,351.84924,-10.264647
155.7153,-0.16016532,10.422006,0.0,0,18.0,330.0,1.1867582,-0.63039863,18.084154,352.1626,-10.280809
155.7175,-0.11356778,10.441016,0.0,0,18.0,330.0,1.1910567,-0.48698357,18.085297,352.47595,-10.297978
155.7197,-0.034354415,10.452624,0.0,0,18.0,330.0,1.193355,-0.16082871,18.085545,352.83295,-10.314365
155.7219,0.058098298,10.474116,0.0,0,18.0,330.0,1.1980432,0.18044214,18.084888,353.38632,-10.329424
155.7241,0.071846724,10.47975,0.0,0,18.0,330.0,1.1993402,0.26284015,18.080719,353.9397,-10.344682
155.7263,0.046828467,10.499946,0.0,0,18.0,330.0,1.2042431,0.19588974,18.085487,354.49307,-10.359608
155.7285,-0.047003008,10.511707,0.0,0,18.0,330.0,1.206272,-0.105751,18.081717,355.04645,-10.375478
155.7307,-0.11715537,10.537241,0.0,0,18.0,330.0,1.2123352,-0.41017568,18.081409,355.68893,-10.392422
155.7329,-0.15714629,10.548189,0.0,0,18.0,330.0,1.2143754,-0.57368577,18.07976,356.38232,-10.408995
155.7351,-0.13414247,10.565577,0.0,0,18.0,330.0,1.2186596,-0.53001392,18.078756,357.07571,-10.425626
155.7373,-0.082466021,10.576836,0.0,0,18.0,330.0,1.2208052,-0.35927334,18.079973,357.76913,-10.441478
155.7395,0.022982277,10.598557,0.0,0,18.0,330.0,1.2263964,0.046533331,18.078922,358.4039,-10.45727
155.7417,0.075018264,10.608098,0.0,0,18.0,330.0,1.227972,0.26993525,18.08215,358.45251,-10.473007
155.7439,0.059831463,10.627532,0.0,0,18.0,330.0,1.2330602,0.23163427,18.076612,358.50113,-10.488681
155.7461,-0.0070139952,10.639461,0.0,0,18.0,330.0,1.2351593,0.027982496,18.078682,358.54974,-10.503847
155.7483,-0.10397064,10.662325,0.0,0,18.0,330.0,1.2408315,-0.319621,18.077099,358.59836,-10.519444
155.7505,-0.16075812,10.674266,0.0,0,18.0,330.0,1.2430024,-0.56515729,18.072432,358.3934,-10.536936
155.7527,-0.16274835,10.692275,0.0,0,18.0,330.0,1.248082,-0.60621083,18.072977,358.09338,-10.552376
155.7549,-0.10290705,10.705432,0.0,0,18.0,330.0,1.250104,-0.43849456,18.075632,357.79337,-10.567644
155.7571,-0.014626184,10.726314,0.0,0,18.0,330.0,1.2560459,-0.12707399,18.071653,357.49335,-10.583942
155.7593,0.052921023,10.735276,0.0,0,18.0,330.0,1.2569423,0.16892867,18.073692,357.47568,-10.599212
155.7615,0.089170381,10.752682,0.0,0,18.0,330.0,1.2621219,0.31712896,18.071878,358.7287,-10.615837
155.7637,0.026965462,10.766846,0.0,0,18.0,330.0,1.2645068,0.15920617,18.07196,359.98175,-10.631946
155.7659,-0.058376692,10.786893,0.0,0,18.0,330.0,1.2702773,-0.13728355,18.070114,361.23477,-10.648471
155.7681,-0.15002663,10.801878,0.0,0,18.0,330.0,1.2725976,-0.51272994,18.068493,362.48779,-10.664323
155.7703,-0.16749328,10.818491,0.0,0,18.0,330.0,1.2780294,-0.60883057,18.069881,363.19379,-10.679161
155.7725,-0.12337973,10.831103,0.0,0,18.0,330.0,1.2796483,-0.45329863,18.068544,363.58713,-10.696788
155.7747,-0.037697725,10.850382,0.0,0,18.0,330.0,1.2858543,-0.1952192,18.069304,363.9805,-10.712509
155.7769,0.040183742,10.86433,0.0,0,18.0,330.0,1.2875049,0.096859053,18.067789,364.37387,-10.728295
155.7791,0.074305706,10.877689,0.0,0,18.0,330.0,1.2923427,0.23967814,18.066425,364.66119,-10.74404
155.7813,0.057357822,10.891278,0.0,0,18.0,330.0,1.2942163,0.24969687,18.067188,363.88821,-10.75822
155.7835,-0.016810903,10.91223,0.0,0,18.0,330.0,1.3009427,0.00075778324,18.065712,363.11523,-10.774545
155.7857,-0.12049208,10.931382,0.0,0,18.0,330.0,1.3036711,-0.35941109,18.066359,362.34225,-10.790942
155.7879,-0.17333743,10.947892,0.0,0,18.0,330.0,1.3094358,-0.5634225,18.066442,361.56924,-10.807871
155.7901,-0.14232965,10.960688,0.0,0,18.0,330.0,1.3110577,-0.51319343,18.062731,361.18881,-10.822997
155.7923,-0.075261645,10.976454,0.0,0,18.0,330.0,1.3169576,-0.30645442,18.062132,361.13547,-10.83923
155.7945,0.016503595,10.991762,0.0,0,18.0,330.0,1.3185239,0.0011903858,18.06382,361.08212,-10.855174
155.7967,0.060233928,11.004661,0.0,0,18.0,330.0,1.3238436,0.17320131,18.061155,361.02881,-10.871906
155.7989,0.070413351,11.020926,0.0,0,18.0,330.0,1.3258505,0.24848112,18.063353,360.97546,-10.888642
155.8011,0.019891832,11.039468,0.0,0,18.0,330.0,1.3326116,0.12347312,18.062471,360.46875,-10.903463
155.8033,-0.072351612,11.056022,0.0,0,18.0,330.0,1.3342955,-0.20778953,18.064333,359.96204,-10.920139
155.8055,-0.16462906,11.070293,0.0,0,18.0,330.0,1.3405542,-0.51367778,18.062273,359.45535,-10.936065
155.8077,-0.15679607,11.086694,0.0,0,18.0,330.0,1.342517,-0.53158063,18.060272,358.94864,-10.951494
155.8099,-0.094541617,11.103624,0.0,0,18.0,330.0,1.3492372,-0.34308913,18.057787,358.44797,-10.967863
155.8121,-0.023073236,11.11971,0.0,0,18.0,330.0,1.3506371,-0.12230817,18.057085,357.95462,-10.984171
155.8143,0.046680678,11.129495,0.0,0,18.0,330.0,1.3556482,0.098547265,18.060526,357.46124,-11.000396
155.8165,0.066214785,11.146953,0.0,0,18.0,330.0,1.3578813,0.22211978,18.055086,356.96786,-11.014607
155.8187,0.042821854,11.164139,0.0,0,18.0,330.0,1.3650033,0.171252,18.059784,356.47449,-11.031005
155.8209,-0.022719737,11.184164,0.0,0,18.0,330.0,1.3673699,-0.041951727,18.055197,356.22354,-11.046802
155.8231,-0.12386155,11.197429,0.0,0,18.0,330.0,1.3735623,-0.37002179,18.061266,355.99686,-11.06458
155.8253,-0.18003681,11.213963,0.0,0,18.0,330.0,1.3752849,-0.56704688,18.056448,355.77017,-11.081347
155.8275,-0.13848719,11.228768,0.0,0,18.0,330.0,1.3821454,-0.47556365,18.058762,355.54349,-11.09553
155.8297,-0.044616804,11.24745,0.0,0,18.0,330.0,1.3839301,-0.16251509,18.052937,355.41864,-11.110591
155.8319,0.032622442,11.255529,0.0,0,18.0,330.0,1.3892432,0.068276569,18.055735,355.47195,-11.127145
155.8341,0.070034571,11.269172,0.0,0,18.0,330.0,1.3899482,0.22151734,18.054062,355.5253,-11.142095
155.8363,0.05708788,11.287498,0.0,0,18.0,330.0,1.3981284,0.19334584,18.056503,355.57864,-11.157888
155.8385,0.0062088561,11.308885,0.0,0,18.0,330.0,1.4004592,0.036313713,18.054295,355.63196,-11.173253
155.8407,-0.090576999,11.321674,0.0,0,18.0,330.0,1.4067838,-0.23000823,18.055416,356.2308,-11.189653
155.8429,-0.15226929,11.341266,0.0,0,18.0,330.0,1.4090382,-0.45136952,18.051968,356.95087,-11.20761
155.8451,-0.17181674,11.354917,0.0,0,18.0,330.0,1.4163716,-0.54223508,18.055376,357.67093,-11.22483
155.8473,-0.09200602,11.374033,0.0,0,18.0,330.0,1.4179627,-0.3268171,18.05084,358.39099,-11.240363
155.8495,0.0031335664,11.384191,0.0,0,18.0,330.0,1.4244461,-0.042107821,18.050947,358.92014,-11.256491
155.8517,0.054936726,11.40385,0.0,0,18.0,330.0,1.4264976,0.16703117,18.053297,358.94012,-11.269926
155.8539,0.069668978,11.416781,0.0,0,18.0,330.0,1.4335159,0.21302746,18.051516,358.96011,-11.285511
155.8561,0.026429806,11.435755,0.0,0,18.0,330.0,1.4349475,0.095740341,18.053179,358.98013,-11.302312
155.8583,-0.060414106,11.446948,0.0,0,18.0,330.0,1.4420795,-0.13981028,18.050684,359.00012,-11.317617
155.8605,-0.13611014,11.466619,0.0,0,18.0,330.0,1.4438161,-0.36399809,18.049459,358.79224,-11.333843
155.8627,-0.17184545,11.480594,0.0,0,18.0,330.0,1.4518701,-0.49990457,18.04673,358.49887,-11.350161
155.8649,-0.13715376,11.502637,0.0,0,18.0,330.0,1.453925,-0.4514766,18.048223,358.20551,-11.367556
156.6654,-0.043391265,11.608377,0.0,0,18.0,4.1213597e-09,1.4869273,-0.1268737,18.002872,331.18784,-11.48278
157.7654,-0.042873584,11.608922,0.0,0,18.0,4.116316e-24,1.4867036,-0.12388135,18.000387,310.58041,-11.482065
158.8654,-0.038551044,11.608105,0.0,0,18.0,4.1112794e-39,1.4867501,-0.11046591,18.000143,301.02188,-11.482197
159.9654,-0.045131247,11.608507,0.0,0,18.0,1.4012985e-45,1.4869226,-0.12863824,18.000008,290.55478,-11.482458
161.0654,-0.044565272,11.609781,0.0,0,18.0,1.4012985e-45,1.4870063,-0.12667499,18.000725,281.7565,-11.48329
162.1654,-0.041026548,11.609204,0.0,0,18.0,1.4012985e-45,1.487097,-0.11799041,18.00041,273.82361,-11.483321
163.2654,-0.04770105,11.609244,0.0,0,18.0,1.4012985e-45,1.4870991,-0.13773745,18.000547,265.82632,-11.482691
164.3654,-0.043669816,11.609115,0.0,0,18.0,1.4012985e-45,1.4868174,-0.12088627,17.999773,257.70041,-11.482666
165.4654,-0.041647281,11.609195,0.0,0,18.0,1.4012985e-45,1.4871287,-0.11867792,18.000019,253.07213,-11.482476
166.5654,-0.048361257,11.609097,0.0,0,18.0,1.4012985e-45,1.4870323,-0.13885511,18.000233,245.02489,-11.482957
167.6654,-0.042713989,11.609908,0.0,0,18.0,1.4012985e-45,1.4870527,-0.12100682,18.000673,240.07095,-11.482955
168.7654,-0.042376768,11.610137,0.0,0,18.0,1.4012985e-45,1.4873757,-0.12427933,18.000511,233.09142,-11.483237
169.8654,-0.048332702,11.609681,0.0,0,18.0,1.4012985e-45,1.4871005,-0.13775347,17.999907,226.1982,-11.482388
170.9654,-0.042005558,11.610171,0.0,0,18.0,1.4012985e-45,1.4872012,-0.11995088,18.00102,222.08459,-11.482687
172.0654,-0.045537714,11.609492,0.0,0,18.0,1.4012985e-45,1.4871334,-0.13204286,17.999062,217.41826,-11.482409
173.1654,-0.047733489,11.610348,0.0,0,18.0,1.4012985e-45,1.4872763,-0.13698818,18.000227,211.76912,-11.482388
174.2654,-0.041381393,11.61094,0.0,0,18.0,1.4012985e-45,1.4874676,-0.11827403,18.000618,206.06371,-11.48267
175.3654,-0.046664353,11.61057,0.0,0,18.0,1.4012985e-45,1.4874334,-0.13545874,17.999949,200.20206,-11.482845
176.4654,-0.046597589,11.611557,0.0,0,18.0,1.4012985e-45,1.4876285,-0.13310981,17.999327,195.06459,-11.482965
177.5654,-0.041654754,11.611676,0.0,0,18.0,1.4012985e-45,1.4877363,-0.12214985,18.00016,192.44577,-11.483306
178.6654,-0.049486212,11.611915,0.0,0,18.0,1.4012985e-45,1.4877344,-0.14130148,18.000654,187.1983,-11.483159
179.7654,-0.044410095,11.612003,0.0,0,18.0,1.4012985e-45,1.4877229,-0.12615918,17.99913,182.34114,-11.482901
180.8654,-0.041988075,11.612497,0.0,0,18.0,1.4012985e-45,1.4880598,-0.1224341,17.999611,178.80803,-11.483253
181.9654,-0.049466182,11.612646,0.0,0,18.0,1.4012985e-45,1.4879118,-0.1416163,18.00057,175.00819,-11.483358
183.0654,-0.04377668,11.612343,0.0,0,18.0,1.4012985e-45,1.4878581,-0.12281716,17.999655,170.37447,-11.483024
184.1654,-0.042875879,11.612357,0.0,0,18.0,1.4012985e-45,1.4880749,-0.12450935,18.000784,166.715,-11.483103
185.2654,-0.049756791,11.61311,0.0,0,18.0,1.4012985e-45,1.4879361,-0.14248571,18.000322,162.91597,-11.482738
186.3654,-0.042696651,11.612945,0.0,0,18.0,1.4012985e-45,1.4881332,-0.12113622,18.000483,159.23132,-11.482515
187.4654,-0.045469299,11.612394,0.0,0,18.0,1.4012985e-45,1.4880881,-0.13150342,18.000137,155.73248,-11.482493
188.5654,-0.050121557,11.613341,0.0,0,18.0,1.4012985e-45,1.4880776,-0.14404884,18.000652,152.46532,-11.482606
189.6654,-0.042006534,11.613365,0.0,0,18.0,1.4012985e-45,1.4883238,-0.12039069,17.999924,148.68036,-11.482686
190.7654,-0.046702061,11.613756,0.0,0,18.0,1.4012985e-45,1.4884498,-0.13586658,18.000196,145.30341,-11.482798
191.8654,-0.048700403,11.613642,0.0,0,18.0,1.4012985e-45,1.4881922,-0.1368134,18.000027,142.32805,-11.48245
192.9654,-0.042584136,11.614041,0.0,0,18.0,1.4012985e-45,1.4885092,-0.12167955,18.000397,139.93164,-11.482235
194.0654,-0.049084179,11.613998,0.0,0,18.0,1.4012985e-45,1.4883854,-0.14253199,18.00037,136.41536,-11.482534
195.1654,-0.046547499,11.61461,0.0,0,18.0,1.4012985e-45,1.4885777,-0.1316364,18.000971,133.04112,-11.482782
196.2654,-0.043217938,11.614548,0.0,0,18.0,1.4012985e-45,1.4885721,-0.1253095,17.999708,130.15709,-11.482665
197.3654,-0.049416274,11.614655,0.0,0,18.0,1.4012985e-45,1.488534,-0.14345764,18.000017,127.75453,-11.482777
198.4654,-0.045740198,11.615074,0.0,0,18.0,1.4012985e-45,1.4888262,-0.12940831,17.999781,125.18738,-11.482998
199.5654,-0.044390228,11.615609,0.0,0,18.0,1.4012985e-45,1.4887629,-0.12857588,18.000212,121.61189,-11.483275
200.6654,-0.050619159,11.61543,0.0,0,18.0,1.4012985e-45,1.4887762,-0.14390503,17.999832,119.97028,-11.483006
201.7654,-0.043624673,11.615411,0.0,0,18.0,1.4012985e-45,1.488981,-0.12520066,18.000645,116.25073,-11.482793
202.8654,-0.045259334,11.616656,0.0,0,18.0,1.4012985e-45,1.4890159,-0.13326551,17.999941,114.05693,-11.483079
203.9654,-0.049987972,11.616333,0.0,0,18.0,1.4012985e-45,1.4891421,-0.1419767,18.000624,111.32166,-11.483076
205.0654,-0.043087903,11.615797,0.0,0,18.0,1.4012985e-45,1.4890792,-0.12317298,17.999603,109.23271,-11.482626
206.1654,-0.047751829,11.616052,0.0,0,18.0,1.4012985e-45,1.4888208,-0.13825767,17.99947,107.52541,-11.482718
207.2654,-0.050419871,11.615879,0.0,0,18.0,1.4012985e-45,1.4890736,-0.14023852,17.999903,105.64017,-11.48236
208.3654,-0.042952843,11.616554,0.0,0,18.0,1.4012985e-45,1.4892164,-0.1236775,18.000223,103.08322,-11.482055
209.4654,-0.049257204,11.616545,0.0,0,18.0,1.4012985e-45,1.4890661,-0.14220375,18.000181,100.61273,-11.482644
210.5654,-0.048778713,11.615973,0.0,0,18.0,1.4012985e-45,1.4890136,-0.14029452,18.000357,98.612816,-11.482268
211.6654,-0.043249737,11.61623,0.0,0,18.0,1.4012985e-45,1.488981,-0.12214941,17.999851,97.282356,-11.482496
212.7654,-0.051092345,11.616638,0.0,0,18.0,1.4012985e-45,1.4892387,-0.15014812,17.999422,95.325829,-11.482093
213.8654,-0.046780266,11.616894,0.0,0,18.0,1.4012985e-45,1.4891552,-0.13067326,18.000509,93.157753,-11.482184
214.9654,-0.04406707,11.616891,0.0,0,18.0,1.4012985e-45,1.4892198,-0.12774265,18.000586,91.190063,-11.482109
215.8654,-0.046000864,11.616997,0.0,0,18.0,1.4012985e-45,1.4894015,-0.13373311,17.999849,90.204376,-11.482253