File: examples/dan-msc-case-studies/CS3/data/01 raw data/baron_test_025.csv
Time(sec),Force(kN),Jaw(mm),PowAngle(deg),Power(W),Pram,PTemp,Strain,Stress(MPa),Stroke(mm),TC1(C),wedge(mm)
0.0,0.52638447,0.42292115,0.0,0,10.594783,0.00096584519,0.028611606,6.5172215,10.594726,35.409794,-9.1080418
2.2,0.43609408,7.9720267e-05,0.0,0,10.594783,6.5158749,9.2037999e-07,5.5530777,10.594179,34.984402,-9.4781523
4.4,0.40982577,0.00029403259,0.0,0,10.594783,13.115875,4.272702e-06,5.2199707,10.59542,34.871738,-9.4754868
6.6,0.38805628,0.00028351552,0.0,0,10.594783,19.715876,1.1353079e-05,4.9458513,10.594394,34.642433,-9.4717846
8.8,0.36664075,8.0807458e-06,0.0,0,10.594783,26.31588,2.5051452e-06,4.672801,10.595572,34.45858,-9.4676876
11.0,0.35847172,0.00049762882,0.0,0,10.594783,32.915867,3.4153141e-05,4.5637827,10.594841,34.290699,-9.4642982
13.2,0.35010064,0.00096211809,28.376278,0,10.594783,39.515873,8.3350729e-05,4.4621863,10.594588,34.143837,-9.4610205
15.4,0.34644476,0.00054578035,46.578392,0,10.594783,46.115879,3.2720975e-05,4.4166183,10.595314,35.284199,-9.4576845
17.6,0.38424939,-0.0020030227,56.11034,0,10.594783,52.715889,-0.00015125556,4.9040523,10.59455,39.521431,-9.4538441
19.8,0.40554884,-0.0085946135,61.4175,0,10.594783,59.315891,-0.00058512995,5.154757,10.594342,47.044319,-9.4501009
22.0,0.41845608,-0.016910356,63.951111,0,10.594783,65.915871,-0.0011159033,5.3145747,10.59446,56.937958,-9.4464998
24.2,0.44087917,-0.02464929,63.648403,0,10.594783,72.515877,-0.0016490545,5.6175313,10.594284,69.343018,-9.4436216
26.4,0.45884892,-0.032817315,61.707066,0,10.594783,79.115883,-0.0021729516,5.8605194,10.594187,81.069504,-9.4399176
28.6,0.4601388,-0.038677845,58.595325,0,10.594783,85.715897,-0.0025671511,5.8996205,10.595354,91.103271,-9.4356928
30.8,0.46981627,-0.042773094,54.83688,0,10.594783,92.31588,-0.0028650481,5.9976759,10.595162,98.874893,-9.4319515
33.0,0.446022,-0.046737209,52.283947,0,10.594783,98.915878,-0.0031254343,5.704545,10.595434,104.21369,-9.4286833
35.2,0.42051208,-0.048973404,51.83918,0,10.594783,105.51588,-0.0032535456,5.3719983,10.59493,107.98006,-9.4249249
37.4,0.41678607,-0.051221978,53.656975,0,10.594783,112.11588,-0.003407188,5.3361092,10.594095,111.10213,-9.4212656
39.6,0.41011712,-0.054806307,56.882687,0,10.594783,118.71588,-0.0036431944,5.2363172,10.593622,114.80676,-9.4170446
41.8,0.43853173,-0.058839805,60.069958,0,10.594783,125.31588,-0.0038950467,5.5928335,10.594837,119.61943,-9.4135609
44.0,0.45160949,-0.064883262,62.245945,0,10.594783,131.91589,-0.0043273997,5.7676277,10.59424,126.25404,-9.4104681
46.2,0.48006466,-0.071245216,63.36237,0,10.594783,138.51587,-0.0047538537,6.1412015,10.594073,134.56416,-9.4067249
48.4,0.48329568,-0.07765767,63.172352,0,10.594783,145.11589,-0.0051705269,6.1763177,10.594442,143.68517,-9.4025965
50.6,0.48460466,-0.083955407,62.359047,0,10.594783,151.7159,-0.005577683,6.2065315,10.594182,152.50784,-9.3993435
52.8,0.49196288,-0.089769065,61.30032,0,10.594783,158.31589,-0.0059675993,6.3007836,10.594157,160.34099,-9.3957949
55.0,0.48445135,-0.094912276,60.489208,0,10.594783,164.91588,-0.0062921098,6.2020664,10.595579,166.95831,-9.3922024
57.2,0.48294562,-0.099498525,60.084873,0,10.594783,171.51588,-0.0066125728,6.1907492,10.59316,172.75987,-9.3883247
59.4,0.48729217,-0.10327377,60.556637,0,10.594783,178.11589,-0.0068723918,6.2617059,10.594904,177.83694,-9.3847799
61.6,0.49062994,-0.1087311,61.468178,0,10.594783,184.7159,-0.007238904,6.290556,10.595632,183.37898,-9.3809566
63.8,0.48683089,-0.11326978,62.360176,0,10.594783,191.3159,-0.0075086951,6.2625246,10.594452,189.30093,-9.3772154
66.0,0.4991627,-0.11884519,63.351357,0,10.594783,197.91591,-0.0078899227,6.4080887,10.595228,195.64482,-9.3736029
68.2,0.50223845,-0.12482775,63.894718,0,10.594783,204.51591,-0.0082781147,6.4532838,10.595025,202.55264,-9.370472
70.4,0.50292391,-0.13144188,64.171135,0,10.594783,211.11591,-0.008710742,6.4543238,10.594346,209.80737,-9.3669825
72.6,0.49830258,-0.13714233,64.35656,0,10.594783,217.7159,-0.0091076512,6.4100084,10.594965,216.99117,-9.3632832
74.8,0.50004613,-0.14335485,64.21167,0,10.594783,224.31589,-0.0095243594,6.4380999,10.594481,224.1418,-9.359313
77.0,0.49911347,-0.14886704,64.300499,0,10.594783,230.91588,-0.0098861484,6.4139676,10.595046,230.76282,-9.3557119
79.2,0.49430397,-0.15524514,64.29538,0,10.594783,237.51588,-0.010283036,6.3539152,10.596045,237.36995,-9.3518066
81.4,0.50887078,-0.16115826,64.555473,0,10.594783,244.11589,-0.010694018,6.5702538,10.594563,243.62762,-9.3485641
83.6,0.50473183,-0.16669373,64.929192,0,10.594783,250.7159,-0.011044228,6.4918838,10.594694,249.82323,-9.3451519
85.8,0.49997351,-0.17265463,65.354668,0,10.594783,257.31619,-0.01142444,6.4456196,10.594538,256.1496,-9.3413668
88.0,0.50678015,-0.17874409,65.832771,0,10.594783,263.91589,-0.011851747,6.5405145,10.59416,262.65604,-9.3378515
90.2,0.50121641,-0.18399109,66.185425,0,10.594783,270.5159,-0.012200549,6.4614687,10.593951,269.29373,-9.3340969
92.4,0.51000351,-0.19013165,66.351242,0,10.594783,277.11588,-0.012607049,6.5859666,10.594153,276.28815,-9.3304996
94.6,0.51390439,-0.19676964,66.368416,0,10.594783,283.71588,-0.013033125,6.6276765,10.595134,283.28284,-9.3266039
96.8,0.50777656,-0.20310737,66.225266,0,10.594783,290.31589,-0.013443392,6.569521,10.595167,290.33398,-9.3235931
99.0,0.5031355,-0.20954801,66.231339,0,10.594783,296.91589,-0.01387586,6.4979138,10.595288,296.9064,-9.319912
101.2,0.50868821,-0.2152732,66.30751,0,10.594783,303.5159,-0.014238389,6.5675468,10.594573,303.42737,-9.3164968
103.4,0.50150377,-0.22163706,66.397026,0,10.594783,310.11591,-0.014661047,6.4681077,10.595532,309.85104,-9.3129492
105.6,0.50164509,-0.22848141,66.708977,0,10.594783,316.71588,-0.015130608,6.4886856,10.595965,315.98557,-9.3090849
107.8,0.50778472,-0.23366793,67.178001,0,10.594783,323.31592,-0.015461871,6.5639944,10.594986,322.26215,-9.3053179
110.0,0.51261842,-0.24040368,67.500862,0,10.594783,329.91589,-0.015906179,6.6232119,10.594197,328.80917,-9.3016138
112.2,0.51035672,-0.24658214,67.871895,0,10.594783,336.51587,-0.016294848,6.6079078,10.594511,335.33112,-9.2979927
114.4,0.50282288,-0.25379053,68.192131,0,10.594783,343.11588,-0.016776055,6.5028448,10.594504,341.78577,-9.2948828
116.6,0.51418549,-0.26099065,68.510742,0,10.594783,349.71588,-0.017251246,6.6598873,10.593885,348.59772,-9.2909756
118.8,0.51464236,-0.26729158,68.664543,0,10.594783,356.31592,-0.017647948,6.6679864,10.59446,355.46625,-9.2875671
121.0,0.51039976,-0.274445,68.818352,0,10.594783,362.91589,-0.018122174,6.6061139,10.59556,362.33038,-9.2838535
123.2,0.50941426,-0.28083262,68.964951,0,10.594783,369.51593,-0.018559538,6.6060214,10.59507,368.97208,-9.2803316
125.4,0.50170195,-0.28803414,69.125969,0,10.594783,376.11591,-0.019032456,6.5150099,10.595004,375.58777,-9.2763042
127.6,0.51502585,-0.29524228,68.972176,0,10.594783,382.71591,-0.019491678,6.6894655,10.594368,382.66812,-9.2725592
129.8,0.50232708,-0.30081972,68.932968,0,10.594783,389.31589,-0.019846048,6.5336237,10.594357,389.45523,-9.2686357
132.0,0.50153786,-0.30756018,68.97216,0,10.594783,395.91586,-0.020286478,6.5220561,10.595255,395.87982,-9.2655087
134.2,0.50333911,-0.31444007,69.125969,0,10.594783,402.51587,-0.020746462,6.5411444,10.594364,402.18088,-9.2616196
136.4,0.50379056,-0.32131183,69.268791,0,10.594783,409.11588,-0.021183444,6.5541506,10.594121,408.6427,-9.2582645
138.6,0.51726866,-0.32952189,69.422607,0,10.594783,415.71588,-0.021717208,6.7138634,10.595262,415.13696,-9.2547474
140.8,0.52251995,-0.33573687,69.650406,0,10.594783,422.31589,-0.022147072,6.8015547,10.594251,421.62878,-9.2513161
143.0,0.51116443,-0.34180027,69.809914,0,10.594783,428.91592,-0.022551369,6.6512079,10.595276,428.27328,-9.2475014
145.2,0.51053017,-0.3498145,70.015862,0,10.594783,435.51593,-0.023071583,6.674715,10.594888,434.61743,-9.2441387
147.4,0.50092047,-0.35757479,70.165192,0,10.594783,442.11591,-0.023569878,6.519093,10.59393,441.42261,-9.2403679
149.6,0.5080955,-0.36496082,70.301521,0,10.594783,448.71591,-0.024029095,6.6241746,10.594566,448.20358,-9.2368298
151.8,0.52169704,-0.37272939,68.29332,0,10.594783,449.9989,-0.024540216,6.8093648,10.594083,454.80325,-9.2358017
154.0,0.51681715,-0.37416786,64.400864,0,10.594783,449.9989,-0.024636021,6.7481413,10.594901,459.69034,-9.2358122
156.2,0.47550789,-0.37476078,59.419014,0,10.594783,449.9989,-0.024660567,6.2068386,10.594508,461.617,-9.2357054
158.4,0.44159552,-0.37286124,55.137424,0,10.594783,449.9989,-0.024546107,5.7565937,10.595681,459.95676,-9.2358112
160.6,0.41352639,-0.36767352,53.649994,0,10.594783,449.9989,-0.024206912,5.3880963,10.594755,455.5538,-9.235569
162.8,0.38366491,-0.36352041,55.488968,0,10.594783,449.9989,-0.023954775,4.9968204,10.594651,450.21274,-9.2354088
165.0,0.36014926,-0.36108461,59.013252,0,10.594783,449.9989,-0.023802146,4.6917377,10.593986,445.70706,-9.2353916
167.2,0.36089364,-0.3612451,62.11504,0,10.594783,449.9989,-0.023811487,4.7070866,10.595242,443.61774,-9.2352266
169.4,0.38197246,-0.36373109,64.357384,0,10.594783,449.9989,-0.023975771,4.9788947,10.594369,443.79132,-9.2358198
171.6,0.38136739,-0.36639133,65.302727,0,10.594783,449.9989,-0.024132343,4.9780741,10.594852,445.74634,-9.2362804
173.8,0.37851453,-0.37017313,65.313965,0,10.594783,449.9989,-0.024373338,4.9303546,10.593517,448.34283,-9.2357512
176.0,0.38975897,-0.37329519,64.449448,0,10.594783,449.9989,-0.024584608,5.093585,10.594225,450.99753,-9.2360077
178.2,0.38224325,-0.37543198,62.996967,0,10.594783,449.9989,-0.024719508,4.98033,10.594715,452.85971,-9.2360125
180.4,0.37024444,-0.37750992,61.469238,0,10.594783,449.9989,-0.024836209,4.830307,10.593915,453.547,-9.235322
182.6,0.3543044,-0.37602127,60.357536,0,10.594783,449.9989,-0.024737066,4.6263213,10.594771,453.05573,-9.2349691
184.8,0.35256165,-0.37593853,59.842541,0,10.594783,449.9989,-0.024740672,4.5962391,10.595551,451.97507,-9.234767
187.0,0.34457991,-0.37517565,60.084225,0,10.594783,449.9989,-0.024719261,4.4935303,10.595556,450.47394,-9.2345667
189.2,0.35797477,-0.37503839,60.787346,0,10.594783,449.9989,-0.024710502,4.6662788,10.595085,449.13443,-9.2356977
191.4,0.36163855,-0.37476704,61.688229,0,10.594783,449.9989,-0.024694407,4.7277775,10.594177,448.29077,-9.2359982
193.6,0.37935406,-0.3750698,62.336418,0,10.594783,449.9989,-0.024699075,4.9618721,10.595057,448.27069,-9.2361212
195.2809,0.38548136,0.012689487,0.0,0,10.5948,0.0060083978,0.00091168808,4.9016981,10.593701,448.57623,-9.2355728
195.2853,0.37291047,0.013701958,0.0,0,10.5948,5.9937399e-33,0.0011206894,4.6543064,10.594164,448.40463,-9.2349072
195.2897,0.36138797,0.011431569,0.0,0,10.5948,0.0,0.00088100182,4.5739894,10.593839,448.23303,-9.2351398
195.2941,0.35687259,0.011800189,0.0,0,10.5948,0.0,0.0009473798,4.6104822,10.594604,448.26205,-9.236269
195.2985,0.36615416,0.011500845,0.0,0,10.5948,0.0,0.00098114286,4.5793571,10.595645,448.34128,-9.2359219
195.3029,0.37067506,0.010626573,0.0,0,10.5948,0.0,0.00093412603,4.8028083,10.593465,448.42047,-9.2369175
195.3073,0.35750037,0.010364912,0.0,0,10.5948,0.0,0.00085469382,4.5520291,10.59537,448.49969,-9.235136
195.3117,0.35388768,0.011446212,0.0,0,10.5948,0.0,0.00097305304,4.5978761,10.596515,448.56149,-9.2371149
195.3161,0.36123961,0.011641614,0.0,0,10.5948,0.0,0.0009180943,4.5925126,10.59444,448.57471,-9.2358694
195.3205,0.3547838,0.011772862,0.0,0,10.5948,0.0,0.00084213959,4.5068746,10.593414,448.58789,-9.2360249
195.3249,0.33402205,0.011641176,0.0,0,10.5948,0.0,0.00083386683,4.285121,10.595167,448.56168,-9.2376623
195.3293,0.34829414,0.012561493,0.0,0,10.5948,0.0,0.0007948883,4.3585072,10.593644,448.53528,-9.2357388
195.3337,0.33691511,0.011696107,0.0,0,10.542863,0.0,0.00071482203,4.2305536,10.595593,448.56641,-9.2351303
195.3381,0.34902126,0.012045643,0.0,0,10.476863,0.0,0.00069061661,4.3765521,10.591096,448.61908,-9.2341938
195.3425,0.3377724,0.014650596,0.0,0,10.410863,0.0,0.00078375713,4.2926359,10.563938,448.66583,-9.2356663
195.3469,0.32766584,0.013010419,0.0,0,10.344863,0.0,0.00075925619,4.1843767,10.480404,448.70544,-9.2366152
195.3513,0.33776,0.017161563,0.0,0,10.278863,0.0,0.00087228912,4.3214035,10.375787,448.7352,-9.2375088
195.3557,0.34637952,0.012713643,0.0,0,10.212863,0.0,0.00070408743,4.4127393,10.2821,448.72198,-9.2362499
195.3601,0.34300333,0.01865031,0.0,0,10.146863,0.0,0.00093541713,4.3299055,10.229754,448.70877,-9.2363586
195.3645,0.33558163,0.012610248,0.0,0,10.080863,0.0,0.00071389659,4.3289313,10.176619,448.69559,-9.2363081
195.3689,0.33894902,0.016581364,0.0,0,10.014863,0.0,0.0009399479,4.3497043,10.119925,448.6824,-9.235714
195.3733,0.89173323,0.015901942,0.0,0,9.948863,0.0,0.00097762374,11.073676,10.051224,448.755,-9.2361603
195.3777,3.6100893,0.044309575,0.0,0,9.882863,0.0,0.0028065783,45.629105,9.993844,448.87381,-9.2348042
195.3821,4.7312999,0.10194287,0.0,0,9.8168631,0.0,0.0067343987,59.78878,9.9207726,449.23962,-9.2314348
195.3865,5.164762,0.17976439,0.0,0,9.7508631,0.0,0.012050366,64.868492,9.8366957,450.00528,-9.2318697
195.3909,5.3005695,0.24743557,0.0,0,9.6848621,0.0,0.01666327,66.406204,9.7624178,450.77094,-9.2329912
195.3953,5.3579144,0.30904832,0.0,0,9.6188631,0.0,0.020916486,66.801773,9.6992588,451.53662,-9.232646
195.3997,5.4174342,0.36529103,0.0,0,9.5528631,0.0,0.024732316,67.270256,9.6359587,452.30228,-9.2326117
195.4041,5.5539322,0.42955753,0.0,0,9.4868631,0.0,0.029200148,68.579903,9.5737982,452.66614,-9.2333412
195.4085,5.6162314,0.49602824,0.0,0,9.4223585,0.0,0.033754632,69.234535,9.5029078,452.95654,-9.2320433
195.4129,5.6539059,0.56186706,0.0,0,9.3579769,0.0,0.03840271,69.260239,9.4363613,453.24698,-9.234005
195.4173,5.6627312,0.62765884,0.0,0,9.2935963,0.0,0.042904515,69.126205,9.3712549,453.53738,-9.23318
195.4217,5.7411828,0.69428653,0.0,0,9.2292166,0.0,0.047569498,69.593819,9.3059464,453.76251,-9.232399
195.4261,5.7673769,0.75499147,0.0,0,9.164835,0.0,0.051737282,69.69413,9.2410412,453.84174,-9.233552
195.4305,5.7810373,0.81849682,0.0,0,9.1004543,0.0,0.056188639,69.604408,9.1738195,453.91666,-9.2339849
195.4349,5.8175249,0.88277191,0.0,0,9.0360737,0.0,0.060713161,69.70826,9.109416,453.89023,-9.2349596
195.4393,5.8627067,0.94566852,0.0,0,8.9716921,0.0,0.065082915,69.870918,9.045454,453.86383,-9.2328024
195.4437,5.9307399,1.0110722,0.0,0,8.9073124,0.0,0.069707245,70.469978,8.9777889,453.4906,-9.2336864
195.4481,5.9477406,1.0748289,0.0,0,8.8429308,0.0,0.074239589,70.381805,8.9127779,453.01535,-9.2335424
195.4525,5.989718,1.1433685,0.0,0,8.7785501,0.0,0.079007119,70.467232,8.8431654,452.63336,-9.2340784
195.4569,5.9859018,1.2059222,0.0,0,8.7159319,0.0,0.083598226,70.188583,8.780879,452.34293,-9.2330475
195.4613,6.055634,1.2727926,0.0,0,8.6547012,0.0,0.088391624,70.645996,8.7146368,452.22726,-9.232892
195.4657,6.0537491,1.3304722,0.0,0,8.5934715,0.0,0.092682332,70.26815,8.6506062,452.67609,-9.2326517
195.4701,6.0796771,1.3976358,0.0,0,8.5322418,0.0,0.097428098,70.269829,8.5881681,453.12494,-9.2328978
195.4745,6.1134515,1.4568022,0.0,0,8.4710112,0.0,0.10197534,70.300285,8.5191841,453.4971,-9.2339706
195.4789,6.1342473,1.5213445,0.0,0,8.4097805,0.0,0.1066539,70.107307,8.4579849,453.86673,-9.2337971
195.4833,6.1457682,1.5732442,0.0,0,8.3485489,0.0,0.11063148,70.024246,8.4026566,454.09772,-9.2336283
195.4877,6.1675816,1.6330761,0.0,0,8.2873192,0.0,0.11510126,69.977783,8.3481293,454.26935,-9.2327423
195.4921,6.2236199,1.6929153,0.0,0,8.2260885,0.0,0.11967667,70.282074,8.2869549,454.30414,-9.2337341
195.4965,6.2890043,1.7566532,0.0,0,8.1648579,0.0,0.12454154,70.671967,8.2213478,454.15894,-9.2324934
195.5009,6.3522077,1.8164936,0.0,0,8.1036282,0.0,0.129076,71.046204,8.1552773,453.98779,-9.2315416
195.5053,6.3472662,1.8822397,0.0,0,8.0429821,0.0,0.13429739,70.623375,8.0936813,453.68417,-9.2332602
195.5097,6.3568902,1.9401423,0.0,0,7.9847255,0.0,0.13859752,70.525429,8.0322914,453.38055,-9.233489
195.5141,6.3841391,2.0012984,0.0,0,7.9264688,0.0,0.14348304,70.372757,7.9686117,453.41974,-9.2344398
195.5185,6.3931785,2.0556815,0.0,0,7.8682132,0.0,0.14763309,70.295143,7.9107456,453.49896,-9.2334356
195.5229,6.4485569,2.1130645,0.0,0,7.809957,0.0,0.15217906,70.488739,7.8532171,453.78516,-9.2340279
195.5273,6.4206295,2.1687791,0.0,0,7.7517014,0.0,0.15637437,69.954147,7.7961397,454.1944,-9.2334223
195.5317,6.4675636,2.2226701,0.0,0,7.6934452,0.0,0.16066507,70.053383,7.7378068,454.61786,-9.2339811
195.5361,6.5497885,2.2816017,0.0,0,7.6351891,0.0,0.16517006,70.717789,7.6818919,455.06668,-9.2319212
195.5405,6.5831928,2.3381896,0.0,0,7.5769334,0.0,0.16953032,70.688828,7.6208115,455.50473,-9.2333918
195.5449,6.5954547,2.3993902,0.0,0,7.5186772,0.0,0.17439798,70.564507,7.5623555,455.83475,-9.2343349
195.5493,6.6124158,2.4573154,0.0,0,7.4604211,0.0,0.17890252,70.413216,7.5031295,456.16476,-9.2334795
195.5537,6.6471748,2.5164316,0.0,0,7.4021649,0.0,0.1835345,70.364754,7.4453759,456.4079,-9.232707
195.5581,6.70646,2.5721815,0.0,0,7.3462825,0.0,0.18792826,70.768547,7.3829684,456.63232,-9.2334661
195.5625,6.7407789,2.6345754,0.0,0,7.2908778,0.0,0.19276585,70.786568,7.324367,456.85675,-9.2330017
195.5669,6.7060738,2.6889737,0.0,0,7.2354727,0.0,0.19731779,70.113342,7.2657208,457.08118,-9.2348604
195.5713,6.697186,2.7466128,0.0,0,7.180068,0.0,0.20187649,69.648979,7.2132316,457.29425,-9.2333612
195.5757,6.753108,2.7919858,0.0,0,7.1246629,0.0,0.20574985,69.972412,7.1605458,457.47906,-9.2335567
195.5801,6.7927485,2.8542244,0.0,0,7.0692582,0.0,0.21055894,70.055038,7.1099501,457.66269,-9.2348137
195.5845,6.8192577,2.9047663,0.0,0,7.0138531,0.0,0.21494706,70.07309,7.0524368,457.78149,-9.2326221
195.5889,6.8949819,2.9655945,0.0,0,6.9584489,0.0,0.21982451,70.506248,6.9944797,457.9003,-9.2334204
195.5933,6.9200912,3.016485,0.0,0,6.9030442,0.0,0.2244079,70.464905,6.9332809,458.0191,-9.2319107
195.5977,6.8979321,3.0798593,0.0,0,6.8476396,0.0,0.2295597,69.856552,6.8773804,458.13791,-9.2333031
195.6021,6.8881307,3.1237762,0.0,0,6.7922339,0.0,0.23344466,69.489807,6.8259811,458.23126,-9.2325735
195.6065,6.9819117,3.183073,0.0,0,6.7380915,0.0,0.23845808,70.005539,6.7705345,458.29727,-9.2328072
195.6109,7.02104,3.2331204,0.0,0,6.6853795,0.0,0.24281204,70.108299,6.714366,458.31815,-9.2316399
195.6153,7.0326757,3.2893414,0.0,0,6.6326675,0.0,0.24771465,69.892128,6.6601214,458.17294,-9.233592
195.6197,7.0373039,3.3405161,0.0,0,6.5799556,0.0,0.25213766,69.773193,6.6056628,458.02774,-9.2334204
195.6241,7.0382338,3.3937881,0.0,0,6.5272436,0.0,0.2568413,69.283669,6.5515938,457.75772,-9.2332983
195.6285,7.1021385,3.4420903,0.0,0,6.4745321,0.0,0.26097989,69.623596,6.5027242,457.48053,-9.2324133
195.6329,7.1367021,3.4929106,0.0,0,6.4218197,0.0,0.26543522,69.711853,6.4476466,457.2301,-9.2332439
195.6373,7.1663084,3.5460505,0.0,0,6.3691077,0.0,0.27001011,69.725517,6.3964982,456.99249,-9.232729
195.6417,7.1598682,3.5999866,0.0,0,6.3163958,0.0,0.27478033,69.220268,6.3394208,456.80347,-9.2324905
195.6461,7.2220798,3.6513207,0.0,0,6.2636838,0.0,0.2791706,69.512772,6.2885976,456.68466,-9.2319155
195.6505,7.2443438,3.7020779,0.0,0,6.2109718,0.0,0.28362,69.460281,6.2342553,456.56955,-9.2317877
195.6549,7.261167,3.7568564,0.0,0,6.1585312,0.0,0.28840795,69.363045,6.1850033,456.47714,-9.2334862
195.6593,7.2853718,3.8038671,0.0,0,6.108397,0.0,0.29250076,69.221146,6.1288142,456.38474,-9.2334604
195.6637,7.3364072,3.8617442,0.0,0,6.0582638,0.0,0.2976093,69.304222,6.080729,456.47668,-9.2321882
195.6681,7.3880401,3.9094279,0.0,0,6.0081301,0.0,0.30175099,69.536804,6.0288663,456.59549,-9.2321863
195.6725,7.3680391,3.9634736,0.0,0,5.9579964,0.0,0.30658022,69.006439,5.976357,456.73026,-9.2326841
195.6769,7.353035,4.0109196,0.0,0,5.9078631,0.0,0.310783,68.616409,5.9256215,456.87549,-9.2324619
195.6813,7.412498,4.0623269,0.0,0,5.8577294,0.0,0.31542212,68.801208,5.8755856,456.97629,-9.2319241
195.6857,7.50138,4.1116309,0.0,0,5.8075957,0.0,0.32002184,69.265411,5.826632,456.98947,-9.230876
195.6901,7.5307355,4.1676602,0.0,0,5.757462,0.0,0.32491246,69.312248,5.7745266,457.01437,-9.2337027
195.6945,7.5221872,4.21311,0.0,0,5.7073283,0.0,0.32935527,68.882805,5.7249503,457.19919,-9.2327843
195.6989,7.5334668,4.266706,0.0,0,5.6571951,0.0,0.33423978,68.689064,5.6732888,457.384,-9.2334738
195.7033,7.6334243,4.311512,0.0,0,5.6070609,0.0,0.33856335,69.208725,5.6254306,457.53714,-9.2333908
195.7077,7.6595979,4.3672733,0.0,0,5.5587349,0.0,0.34373254,69.130775,5.5721865,457.68237,-9.2319279
195.7121,7.6646018,4.4130917,0.0,0,5.5110393,0.0,0.34830382,68.975159,5.5222602,457.75739,-9.2334852
195.7165,7.6299906,4.4652386,0.0,0,5.4633431,0.0,0.35325137,68.233749,5.4733515,457.77057,-9.2332926
195.7209,7.6316772,4.506989,0.0,0,5.415647,0.0,0.35740587,67.860886,5.4298215,457.80811,-9.2320986
195.7253,7.7222052,4.5530229,0.0,0,5.3679514,0.0,0.3618826,68.44606,5.3812275,457.91373,-9.2326927
195.7297,7.7318563,4.5957789,0.0,0,5.3202553,0.0,0.36601537,68.26609,5.3361726,458.01935,-9.232461
195.7341,7.7707863,4.6437936,0.0,0,5.2725592,0.0,0.37075573,68.283325,5.2880826,455.82526,-9.232852
195.7385,7.8165326,4.6899567,0.0,0,5.2248635,0.0,0.37524989,68.360481,5.242239,453.62067,-9.233098
195.7429,7.901063,4.7381754,0.0,0,5.1771669,0.0,0.38008699,68.893402,5.1943378,451.80972,-9.2322083
195.7473,7.903872,4.7866392,0.0,0,5.1294713,0.0,0.38480368,68.540855,5.1436191,450.14639,-9.2314358
195.7517,7.8886447,4.8326559,0.0,0,5.0817752,0.0,0.38930371,68.08815,5.0935578,449.61032,-9.2317219
195.7561,7.9853086,4.8819523,0.0,0,5.0349603,0.0,0.3940441,68.574669,5.0473208,450.40237,-9.2318277
195.7605,8.0399837,4.9308257,0.0,0,4.9895964,0.0,0.39876646,68.690857,5.0006313,451.09363,-9.2320814
195.7649,8.0442228,4.9775949,0.0,0,4.9442325,0.0,0.40335664,68.430412,4.9573579,451.35767,-9.2322397
195.7693,8.0219889,5.0226622,0.0,0,4.8988686,0.0,0.40768799,67.936813,4.9056273,451.6217,-9.2314854
195.7737,8.0819616,5.0690308,0.0,0,4.8535042,0.0,0.41235873,68.127136,4.8617325,451.94659,-9.2328691
195.7781,8.1372013,5.1131482,0.0,0,4.8081403,0.0,0.41672599,68.389145,4.8167348,452.27661,-9.2319088
195.7825,8.1942625,5.164031,0.0,0,4.7627764,0.0,0.42159864,68.413094,4.7703209,452.5116,-9.2324209
195.7869,8.1997766,5.207767,0.0,0,4.7174125,0.0,0.42604274,68.261078,4.7194748,452.69644,-9.2336702
195.7913,8.1641722,5.2549534,0.0,0,4.6720481,0.0,0.43085667,67.567841,4.6807599,452.88635,-9.2323875
195.7957,8.2358341,5.2965012,0.0,0,4.6266842,0.0,0.43512297,67.855637,4.6351714,453.08435,-9.2318287
195.8001,8.3147736,5.3465714,0.0,0,4.5813203,0.0,0.44012085,68.208672,4.5895882,453.3089,-9.2319088
195.8045,8.3876953,5.3871899,0.0,0,4.5359979,0.0,0.44450277,68.56649,4.5446234,453.73135,-9.2326632
195.8089,8.3873215,5.4406457,0.0,0,4.4928327,0.0,0.44985294,68.110512,4.4941583,454.15381,-9.2327538
195.8133,8.3810863,5.4788218,0.0,0,4.449677,0.0,0.45424578,67.790482,4.4558072,454.46402,-9.2323933
195.8177,8.4427938,5.5266223,0.0,0,4.4065218,0.0,0.45914379,67.879639,4.4122391,454.75443,-9.2334223
195.8221,8.4911566,5.5653882,0.0,0,4.3633666,0.0,0.46345404,67.958847,4.3664293,454.87589,-9.231163
195.8265,8.4729366,5.608705,0.0,0,4.3202114,0.0,0.46804273,67.546906,4.3235326,454.87589,-9.2333488
195.8309,8.5395832,5.6473126,0.0,0,4.2770562,0.0,0.47246641,67.766373,4.2798824,454.26309,-9.2308998
195.8353,8.6035433,5.6931577,0.0,0,4.233901,0.0,0.47740516,67.993088,4.2365031,452.30933,-9.2314816
195.8397,8.6595068,5.7333431,0.0,0,4.1907458,0.0,0.48182255,68.125206,4.1972651,450.37479,-9.2306223
195.8441,8.6691275,5.7772021,0.0,0,4.1475906,0.0,0.48681751,67.866058,4.1538043,448.84344,-9.2325964
195.8485,8.6921329,5.8165183,0.0,0,4.1044354,0.0,0.49101827,67.787506,4.1096148,447.31213,-9.2325611
195.8529,8.778266,5.8607483,0.0,0,4.0612803,0.0,0.49600017,68.072357,4.0660758,447.45334,-9.2316236
195.8573,8.8295097,5.9015598,0.0,0,4.0194988,0.0,0.50044477,68.187195,4.0262313,448.07379,-9.231864
195.8617,8.8740911,5.9454188,0.0,0,3.978456,0.0,0.50527132,68.174797,3.9805143,448.82864,-9.2318039
195.8661,8.8681135,5.9880185,0.0,0,3.9374127,0.0,0.50994992,67.77755,3.9390969,449.7131,-9.2308931
195.8705,8.9245176,6.028348,0.0,0,3.8963697,0.0,0.51440668,67.919052,3.8971295,450.65164,-9.2309647
195.8749,8.9783869,6.0701833,0.0,0,3.8553262,0.0,0.5188446,68.053627,3.8604586,451.76053,-9.2306042
195.8793,9.0767975,6.1136441,0.0,0,3.8142831,0.0,0.52366072,68.438721,3.8171968,452.86942,-9.2311964
195.8837,9.0704222,6.1613483,0.0,0,3.7732399,0.0,0.52888715,68.078697,3.7731724,453.49036,-9.2317276
195.8881,9.0737886,6.1975107,0.0,0,3.7321966,0.0,0.53286123,67.727753,3.7313485,454.09763,-9.2311449
195.8925,9.081274,6.2396874,0.0,0,3.6911535,0.0,0.5374617,67.529823,3.6943245,454.45377,-9.2304201
195.8969,9.174757,6.275804,0.0,0,3.6501102,0.0,0.54160959,67.961395,3.6540549,454.70459,-9.2320871
195.9013,9.2505779,6.3220334,0.0,0,3.609067,0.0,0.54669869,68.197296,3.6152716,454.86322,-9.2327538
195.9057,9.3471994,6.3639369,0.0,0,3.5685973,0.0,0.55155897,68.511894,3.5702314,454.90283,-9.2313099
195.9101,9.4248915,6.4087615,0.0,0,3.5295515,0.0,0.55665648,68.781494,3.5271916,454.94241,-9.2312698
195.9145,9.3674822,6.4468908,0.0,0,3.4905059,0.0,0.56124526,68.056946,3.4866602,454.98203,-9.2313948
195.9189,9.3517599,6.4886837,0.0,0,3.4514606,0.0,0.56587172,67.604462,3.452745,455.02161,-9.2312193
195.9233,9.421566,6.5209441,0.0,0,3.4124148,0.0,0.57003576,67.840424,3.4134431,454.17014,-9.2319078
195.9277,9.593585,6.5655427,0.0,0,3.373369,0.0,0.57526076,68.721962,3.375843,453.21967,-9.2311134
195.9321,9.5978184,6.6013956,0.0,0,3.3343234,0.0,0.57965857,68.484528,3.3358994,450.5834,-9.230546
195.9365,9.6284571,6.6418624,0.0,0,3.2952781,0.0,0.584683,68.349701,3.2931468,446.96481,-9.2316914
195.9409,9.6920033,6.6783881,0.0,0,3.2562325,0.0,0.58930928,68.441132,3.2551429,444.19165,-9.2325687
195.9453,9.7636671,6.7186036,0.0,0,3.2171867,0.0,0.59415489,68.593239,3.2128704,442.89795,-9.231535
195.9497,9.81392,6.754775,0.0,0,3.1781411,0.0,0.59865421,68.703354,3.1781912,441.89673,-9.2311163
195.9541,9.8547068,6.7925,0.0,0,3.1390955,0.0,0.60353976,68.600212,3.1368587,443.66718,-9.2308693
195.9585,9.8814764,6.8323183,0.0,0,3.1018047,0.0,0.60826302,68.496773,3.1014822,445.43762,-9.2291784
195.9629,9.9631529,6.8683305,0.0,0,3.0646601,0.0,0.61290538,68.670609,3.0604081,446.6171,-9.2306843
195.9673,10.051402,6.9042964,0.0,0,3.0275149,0.0,0.61730564,68.988792,3.0240784,447.67319,-9.2314787
195.9717,10.047037,6.9433389,0.0,0,2.9903705,0.0,0.622253,68.659355,2.9870284,448.73666,-9.231555
195.9761,10.074265,6.9781933,0.0,0,2.9532256,0.0,0.6263954,68.560318,2.9509652,449.80594,-9.2321196
195.9805,10.123711,7.012816,0.0,0,2.9160807,0.0,0.63069451,68.567513,2.9152002,450.80609,-9.2308378
195.9849,10.234221,7.0512276,0.0,0,2.8789361,0.0,0.63529032,69.045525,2.8810639,451.63776,-9.232605
195.9893,10.337554,7.0913458,0.0,0,2.8417912,0.0,0.64017135,69.381264,2.8410103,452.46252,-9.2299538
195.9937,10.392447,7.1295896,0.0,0,2.8046465,0.0,0.64493102,69.437515,2.8047013,452.99057,-9.2325335
195.9981,10.407609,7.1671925,0.0,0,2.7675016,0.0,0.64960158,69.128021,2.7685523,453.51862,-9.2305632
196.0025,10.475069,7.2050843,0.0,0,2.7303567,0.0,0.65425706,69.362793,2.7331481,454.01678,-9.2322035
196.0069,10.599094,7.242084,0.0,0,2.6942267,0.0,0.65875274,69.825783,2.6937728,454.50522,-9.2318115
196.0113,10.645609,7.2835941,0.0,0,2.6588948,0.0,0.66405386,69.76683,2.657321,454.64694,-9.2318611
196.0157,10.708003,7.3195662,0.0,0,2.6235626,0.0,0.6687445,69.887741,2.6175168,454.42252,-9.2318935
196.0201,10.777063,7.3598461,0.0,0,2.5882306,0.0,0.67375857,69.981628,2.5785875,454.15491,-9.2315168
196.0245,10.832027,7.3946767,0.0,0,2.5528986,0.0,0.67862302,69.904709,2.5439048,453.73248,-9.2319145
196.0289,10.823455,7.4306545,0.0,0,2.5175664,0.0,0.68315184,69.628105,2.5097258,453.31006,-9.2310896
196.0333,10.80794,7.4620028,0.0,0,2.4822347,0.0,0.68759382,69.183395,2.4746783,453.52722,-9.231925
196.0377,10.895103,7.4982533,0.0,0,2.4469025,0.0,0.6923148,69.433594,2.4424298,453.77805,-9.2312212
196.0421,11.02499,7.528583,0.0,0,2.4115705,0.0,0.69664246,69.932701,2.4121847,454.03784,-9.2318964
196.0465,11.117645,7.5661712,0.0,0,2.3762386,0.0,0.70164484,70.188515,2.3729818,454.30185,-9.2310915
196.0509,11.21685,7.595664,0.0,0,2.3409066,0.0,0.70597696,70.485741,2.3424091,452.31436,-9.2313223
196.0553,11.30129,7.6352649,0.0,0,2.3059125,0.0,0.71162379,70.591789,2.3019831,447.13525,-9.2312059
196.0597,11.358854,7.6680827,0.0,0,2.2723053,0.0,0.71608877,70.66053,2.2692795,442.21005,-9.2303495
196.0641,11.481276,7.704535,0.0,0,2.2386982,0.0,0.72123665,71.062149,2.23206,438.77628,-9.2318201
196.0685,11.500067,7.7367954,0.0,0,2.205091,0.0,0.72582185,70.873344,2.199451,435.34253,-9.2295742
196.0729,11.570346,7.7741795,0.0,0,2.1714838,0.0,0.7311545,70.892441,2.1615102,437.65802,-9.2314615
196.0773,11.606709,7.8023119,0.0,0,2.1378765,0.0,0.73499548,70.81649,2.1287186,440.77774,-9.230238
196.0817,11.632556,7.8353381,0.0,0,2.1042695,0.0,0.73963481,70.675903,2.0994925,443.15604,-9.2313251
196.0861,11.705036,7.8671207,0.0,0,2.0706625,0.0,0.74395084,70.834496,2.0668495,445.05847,-9.2315092
196.0905,11.802442,7.8984642,0.0,0,2.0370553,0.0,0.74840707,71.052261,2.0328326,446.72635,-9.2312155
196.0949,11.891543,7.9325452,0.0,0,2.003448,0.0,0.75304562,71.258621,2.0041494,447.94086,-9.2302656
196.0993,12.030655,7.9641328,0.0,0,1.9698408,0.0,0.75708628,71.815422,1.9709882,449.13614,-9.231554
196.1037,12.180786,8.0007343,0.0,0,1.9362336,0.0,0.76234841,72.374542,1.9363173,450.08664,-9.2316866
196.1081,12.243525,8.0371428,0.0,0,1.9039888,0.0,0.76723343,72.38205,1.8987558,451.03714,-9.2298155
196.1125,12.333785,8.0706005,0.0,0,1.8720183,0.0,0.77183187,72.557426,1.8628645,451.77518,-9.2303724
196.1169,12.377143,8.1068859,0.0,0,1.8400481,0.0,0.77702439,72.454178,1.8320476,452.46164,-9.2301331
196.1213,12.397545,8.1394482,0.0,0,1.8080776,0.0,0.78152925,72.241318,1.8013861,453.00647,-9.230134
196.1257,12.481177,8.1684799,0.0,0,1.7761072,0.0,0.78582215,72.455009,1.7701017,453.42889,-9.2308807
196.1301,12.594176,8.2034578,0.0,0,1.7441368,0.0,0.79053628,72.709427,1.7354252,453.75928,-9.2302523
196.1345,12.692358,8.2325315,0.0,0,1.7121664,0.0,0.79518414,72.945091,1.7026393,453.8385,-9.2306814
196.1389,12.754279,8.2697554,0.0,0,1.680196,0.0,0.80047768,73.002464,1.6755389,453.91772,-9.2299309
196.1433,12.841963,8.2945299,0.0,0,1.6482255,0.0,0.80465418,73.126755,1.6445334,454.08932,-9.2306643
196.1477,12.973933,8.3350353,0.0,0,1.6162552,0.0,0.81046075,73.374916,1.6083204,454.26093,-9.2306395
196.1521,13.125337,8.3602591,0.0,0,1.5842847,0.0,0.8145656,73.981209,1.5802616,454.50983,-9.2299929
196.1565,13.225867,8.3975515,0.0,0,1.5530444,0.0,0.82018894,74.131615,1.5483544,454.78705,-9.2297668
196.1609,13.293869,8.424221,0.0,0,1.5226318,0.0,0.82475191,74.230316,1.5141438,455.03979,-9.228754
196.1653,13.361126,8.4611921,0.0,0,1.492219,0.0,0.83042997,74.112213,1.4792035,455.26422,-9.2311106
196.1697,13.382062,8.4857435,0.0,0,1.4618061,0.0,0.83433729,73.930893,1.4549023,455.47314,-9.230545
196.1741,13.512517,8.5162315,0.0,0,1.4313933,0.0,0.8393693,74.321167,1.4210877,455.61838,-9.231163
196.1785,13.616074,8.5433111,0.0,0,1.4009806,0.0,0.84356093,74.607948,1.3925672,455.76361,-9.2303905
196.1829,13.653658,8.5754499,0.0,0,1.3705678,0.0,0.84867501,74.427803,1.3633585,455.87207,-9.2288427
196.1873,13.770464,8.5994987,0.0,0,1.3401549,0.0,0.85258454,74.703018,1.3318282,455.97766,-9.2296839
196.1917,13.963185,8.6329622,0.0,0,1.3097422,0.0,0.85790783,75.375465,1.3003591,453.19305,-9.2302876
196.1961,14.106293,8.660696,0.0,0,1.2793293,0.0,0.86202711,75.845047,1.2718858,448.91357,-9.2289181
196.2005,14.168372,8.6931114,0.0,0,1.2489165,0.0,0.86704528,75.793983,1.2379835,445.01141,-9.2302628
196.2049,14.215838,8.7222319,0.0,0,1.21866,0.0,0.87147862,75.685112,1.2104063,441.69717,-9.2302895
196.2093,14.37516,8.75179,0.0,0,1.1897343,0.0,0.87595773,76.201332,1.1801327,438.9715,-9.2303915
196.2137,14.531425,8.7802935,0.0,0,1.1608089,0.0,0.88051993,76.760208,1.1512532,440.4523,-9.2293825
196.2181,14.557867,8.812294,0.0,0,1.1318831,0.0,0.8854124,76.472618,1.1205214,441.93314,-9.2288399
196.2225,14.616432,8.8397245,0.0,0,1.1029577,0.0,0.8896147,76.445114,1.0974785,443.6044,-9.2289009
196.2269,14.789335,8.8710518,0.0,0,1.0740319,0.0,0.8946104,76.939018,1.0666193,445.30811,-9.2298155
196.2313,14.915709,8.9012747,0.0,0,1.0451064,0.0,0.89921737,77.237083,1.0357296,447.04236,-9.2303362
196.2357,14.963833,8.9278851,0.0,0,1.0161808,0.0,0.90361607,77.212585,1.0097409,448.79813,-9.2297411
196.2401,15.156054,8.9581423,0.0,0,0.98725516,0.0,0.90824628,77.861557,0.97863489,450.20526,-9.2306318
196.2445,15.34552,8.9880886,0.0,0,0.95832956,0.0,0.91345406,78.324173,0.94841295,450.86533,-9.2287817
196.2489,15.433298,9.0202122,0.0,0,0.92940396,0.0,0.91858351,78.413277,0.91902578,451.50095,-9.2292633
196.2533,15.452031,9.0455742,0.0,0,0.9004783,0.0,0.9229297,78.187912,0.88983184,451.67258,-9.2298498
196.2577,15.554031,9.0744743,0.0,0,0.8726033,0.0,0.92788202,78.290039,0.86287683,451.84418,-9.2300224
196.2621,15.774183,9.0984402,0.0,0,0.84509444,0.0,0.93216956,79.03196,0.83683938,451.24173,-9.2293167
196.2665,15.95195,9.1297998,0.0,0,0.81758565,0.0,0.93770516,79.49588,0.80405259,450.42328,-9.2296972
196.2709,15.924572,9.1524601,0.0,0,0.79007685,0.0,0.9419378,79.062958,0.77832144,449.80823,-9.229599
196.2753,15.924552,9.178113,0.0,0,0.76256806,0.0,0.94655454,78.706924,0.75391483,449.3858,-9.2292948
196.2797,16.117064,9.200676,0.0,0,0.73505926,0.0,0.95057696,79.306183,0.72884792,449.26794,-9.2285433
196.2841,16.360327,9.2284698,0.0,0,0.70755047,0.0,0.95586002,80.051735,0.70247561,450.0864,-9.2286949
196.2885,16.645061,9.2535534,0.0,0,0.68004167,0.0,0.96016741,81.118179,0.67276752,450.90488,-9.2300262
196.2929,16.705057,9.2836676,0.0,0,0.65253288,0.0,0.96570075,81.016182,0.63968682,451.56851,-9.2295389
196.2973,16.746733,9.3098574,0.0,0,0.62502408,0.0,0.97041029,80.815521,0.61581272,452.22858,-9.2292213
196.3017,16.80718,9.3361969,0.0,0,0.59751529,0.0,0.9749921,80.704369,0.58738691,452.69208,-9.2289257
196.3061,16.849478,9.3568344,0.0,0,0.57050854,0.0,0.97841346,80.625153,0.56356889,453.07489,-9.2293873
196.3105,17.002028,9.3803024,0.0,0,0.54432851,0.0,0.98274583,81.050346,0.54163086,453.40533,-9.2288113
196.3149,16.381418,9.3974371,0.0,0,0.51814854,0.0,0.98539096,77.896873,0.51703906,453.66934,-9.2295227
196.3193,15.633474,9.3966293,0.0,0,0.49196854,0.0,0.98518723,74.350761,0.5004459,453.94022,-9.2305956
196.3237,15.058619,9.404933,0.0,0,0.46578854,0.0,0.98648411,71.493073,0.48460597,454.24384,-9.2316027
196.3281,14.648948,9.4083519,0.0,0,0.43960854,0.0,0.98672831,69.537514,0.4661828,454.54745,-9.2326136
196.3325,14.236287,9.4157352,0.0,0,0.41342852,0.0,0.98778421,67.565826,0.44886383,454.81528,-9.231843
196.3369,13.687535,9.4153996,0.0,0,0.38724852,0.0,0.98758721,64.937347,0.43487206,455.07928,-9.2318258
196.3413,13.214071,9.4208803,0.0,0,0.36106849,0.0,0.98817605,62.630714,0.42748994,455.25998,-9.2312851
196.3457,12.855804,9.4193392,0.0,0,0.33488849,0.0,0.98786789,60.942348,0.42291895,455.39307,-9.2332487
196.3501,12.680285,9.4275217,0.0,0,0.30870852,0.0,0.98902535,60.050793,0.40961576,455.49512,-9.2320662
196.3545,12.670174,9.4253664,0.0,0,0.28255248,0.0,0.98890853,59.981861,0.38781878,455.54791,-9.2312059
196.3589,12.944526,9.433012,0.0,0,0.25765157,0.0,0.98990643,61.218475,0.34849218,455.60074,-9.231204
196.3633,13.156018,9.4333286,0.0,0,0.23275636,0.0,0.99046308,62.184399,0.31700346,455.65353,-9.2311382
196.3677,13.263659,9.4379807,0.0,0,0.2078612,0.0,0.99104577,62.687275,0.28439778,455.70633,-9.2301569
196.3721,13.277465,9.4380674,0.0,0,0.18296601,0.0,0.99160182,62.725674,0.2559855,455.66937,-9.2310181
196.3765,13.289684,9.4451017,0.0,0,0.1580708,0.0,0.99259353,62.704376,0.2256062,455.61658,-9.2290592
196.3809,13.286868,9.4407272,0.0,0,0.1331756,0.0,0.99241704,62.704681,0.20447028,455.50232,-9.2316122
196.3853,13.222128,9.4480591,0.0,0,0.10828039,0.0,0.99390841,62.322464,0.17887855,455.3439,-9.2311583
196.3897,13.145511,9.4426126,0.0,0,0.083385184,0.0,0.99339122,61.993847,0.15264958,455.20206,-9.2303667
196.3941,13.088612,9.4491167,0.0,0,0.058489989,0.0,0.99480772,61.626781,0.13218774,455.09647,-9.2295933
196.3985,13.043636,9.4476566,0.0,0,0.033594787,0.0,0.99462736,61.433849,0.11075617,454.99268,-9.2303505
196.4029,12.974772,9.4520168,0.0,0,0.0086995875,0.0,0.99561441,61.045727,0.087206744,454.92667,-9.2311296
196.4073,12.879753,9.4490776,0.0,0,-0.015800599,0.0,0.99512041,60.598854,0.075386457,454.86066,-9.2301855
196.4117,12.805308,9.4519405,0.0,0,-0.040088601,0.0,0.99570411,60.238892,0.051676236,454.81516,-9.2318535
196.4161,12.760307,9.4518337,0.0,0,-0.064376593,0.0,0.99569619,60.008633,0.039406426,454.77554,-9.2305498
196.4205,12.686802,9.4543095,0.0,0,-0.088664591,0.0,0.99603188,59.661472,0.022805091,454.74268,-9.2295332
196.4249,12.555757,9.4552727,0.0,0,-0.044739336,449.55508,0.99586844,59.07674,0.010890882,454.71628,-9.2302637
196.4293,12.378978,9.4573555,0.0,0,0.7520929,450.0,0.99597514,58.23708,-0.00051153958,454.68033,-9.2300262
196.4337,10.254787,9.4530954,0.0,0,1.548951,450.0,0.99507689,48.447632,0.080520935,454.61432,-9.2319231
196.4381,5.3639426,9.4377518,0.0,0,2.3458095,450.0,0.99196553,25.625044,0.33725291,454.54831,-9.2361746
196.4425,-0.17125317,9.3729038,0.0,0,3.1426666,450.0,0.98037332,-0.83690304,1.0556684,454.53366,-9.2411003
196.4469,0.055344343,9.3777246,0.0,0,3.9395239,450.0,0.98089153,0.26606956,2.3618252,454.52045,-9.2398167
196.4513,-0.083530121,9.4553318,0.0,0,4.7363815,450.0,0.99434537,-0.39943421,3.3404775,454.50726,-9.2403221
196.4557,0.017254384,9.4370565,0.0,0,5.5332389,450.0,0.99098063,0.16004771,4.1146345,454.49408,-9.240098
196.4601,-0.0535427,9.4377193,0.0,0,6.3300972,450.0,0.99098122,-0.28132313,4.8710532,454.46936,-9.2387695
196.4645,0.00057768245,9.4355822,0.0,0,7.1269546,450.0,0.99065417,-0.03304873,5.6679244,454.42975,-9.2373333
196.4689,-0.0057848217,9.4406586,0.0,0,7.9238119,450.0,0.99127865,-0.010933421,6.492588,454.38568,-9.2381496
196.4733,-0.052431736,9.433095,0.0,0,8.7206697,450.0,0.99053538,-0.32387361,7.3260555,454.31967,-9.2369413
196.4777,-0.087105677,9.4391899,0.0,0,9.5175285,450.0,0.99116403,-0.30474374,8.1502876,454.25366,-9.2348213
196.4821,-0.049128227,9.4339314,0.0,0,10.314386,450.0,0.99081033,-0.32302096,8.956871,454.19955,-9.235467
196.4865,0.060770005,9.4382629,0.0,0,11.111244,450.0,0.99147993,0.35680461,9.7812281,454.14676,-9.2344599
196.4909,-0.17838778,9.4327564,0.0,0,11.908101,450.0,0.99094659,-0.84427553,10.574499,454.11896,-9.235877
196.4953,0.00082199305,9.4344501,0.0,0,12.704959,450.0,0.99135828,0.022102591,11.376106,454.10577,-9.2343864
196.4997,-0.069466017,9.4318113,0.0,0,13.501817,450.0,0.991202,-0.36740324,12.144903,454.07816,-9.2353258
196.5041,0.01950117,9.4331312,0.0,0,14.298674,450.0,0.99200064,0.055933207,12.928911,454.02536,-9.2350187
196.5085,-0.13487294,9.4274187,0.0,0,15.095531,450.0,0.99088669,-0.55121243,13.729495,453.96878,-9.2329197
196.5129,0.1104259,9.4313164,0.0,0,15.892389,450.0,0.99183208,0.48062366,14.545821,453.87637,-9.2351418
196.5173,-0.1535909,9.4277058,0.0,0,16.689247,450.0,0.99128765,-0.66802764,15.350348,453.78397,-9.2334061
196.5217,0.06009407,9.427124,0.0,0,17.486105,450.0,0.99140465,0.24091505,16.146334,453.7243,-9.2326746
196.5261,-0.072059073,9.4283209,0.0,0,18.0,450.0,0.99135971,-0.31601632,16.944712,453.67151,-9.2342958
196.5305,-0.049474593,9.4270649,0.0,0,18.0,450.0,0.99128008,-0.25654799,17.697546,453.61871,-9.2335377
196.5349,-0.035959478,9.4301262,0.0,0,18.0,450.0,0.99153668,-0.15302241,18.261103,453.56589,-9.236496
196.5393,0.13694955,9.433567,0.0,0,18.0,450.0,0.99197972,0.62703449,18.465754,453.50156,-9.2431564
196.5437,0.28247884,9.4430351,0.0,0,18.0,450.0,0.99341297,1.3029774,18.306934,453.40915,-9.258357
196.5481,0.22652261,9.4407873,0.0,0,18.0,450.0,0.99265331,1.0689418,18.110426,453.31766,-9.2824173
196.5525,0.22945775,9.4422035,0.0,0,18.0,450.0,0.99270064,1.0826821,18.054502,453.26486,-9.3145132
196.5569,0.18511301,9.438446,0.0,0,18.0,450.0,0.99174064,0.85405922,18.063147,453.21207,-9.3527403
196.5613,0.21076909,9.4410992,0.0,0,18.0,450.0,0.99191445,1.0266078,18.099266,453.17917,-9.3893986
196.5657,0.2250655,9.4394836,0.0,0,18.0,450.0,0.99147981,1.0521102,18.127893,453.15277,-9.4228964
196.5701,0.20235954,9.4424706,0.0,0,18.0,450.0,0.99176162,0.96828884,18.136076,453.12637,-9.4567099
196.5745,0.19227152,9.4393053,0.0,0,18.0,450.0,0.99134558,0.9103024,18.13028,453.09998,-9.4894657
196.5789,0.21594554,9.4467974,0.0,0,18.0,450.0,0.99228948,0.99211866,18.127937,453.0563,-9.520956
196.5833,0.22062564,9.4415646,0.0,0,18.0,450.0,0.99171215,1.0243708,18.127609,452.95068,-9.5564651
196.5877,0.22227469,9.4463577,0.0,0,18.0,450.0,0.99225193,1.0902221,18.121819,452.84506,-9.5882759
196.5921,0.203187,9.4423542,0.0,0,18.0,450.0,0.99213231,0.96995956,18.115261,452.75198,-9.6219587
196.5965,0.21465747,9.4460669,0.0,0,18.0,450.0,0.99277413,0.99317193,18.111946,452.65958,-9.6529217
196.6009,0.22153868,9.4415998,0.0,0,18.0,450.0,0.99254531,1.03385,18.109219,452.62119,-9.6855278
196.6053,0.22903927,9.4475851,0.0,0,18.0,450.0,0.99363399,1.0853142,18.109329,452.608,-9.7196798
196.6097,0.20350754,9.4390106,0.0,0,18.0,450.0,0.99252367,0.97567379,18.100266,452.57294,-9.7536259
196.6141,0.20902365,9.4425926,0.0,0,18.0,450.0,0.99361265,1.0045973,18.098125,452.50693,-9.7875328
196.6185,0.21600531,9.4378042,0.0,0,18.0,450.0,0.99281007,0.97241038,18.100117,452.43518,-9.8178577
196.6229,0.22202107,9.4379416,0.0,0,18.0,450.0,0.99302101,1.0329088,18.095606,452.32956,-9.853054
196.6273,0.19859874,9.4358187,0.0,0,18.0,450.0,0.99267328,0.95242584,18.101095,452.22397,-9.8855886
196.6317,0.19727233,9.4370623,0.0,0,18.0,450.0,0.99317807,0.917319,18.095463,452.11835,-9.9160652
196.6361,0.22046393,9.4363737,0.0,0,18.0,450.0,0.99285811,1.0094702,18.092943,452.01273,-9.9470034
196.6405,0.22469965,9.4362278,0.0,0,18.0,450.0,0.99278879,1.0687311,18.094337,451.96341,-9.9818172
196.6449,0.20725244,9.4362154,0.0,0,18.0,450.0,0.9926098,1.0061287,18.094151,451.95023,-10.015582
196.6493,0.20473307,9.4356098,0.0,0,18.0,450.0,0.99239653,0.96372074,18.093174,451.92352,-10.049707
196.6537,0.21692596,9.4364214,0.0,0,18.0,450.0,0.99231619,1.0481457,18.08943,451.87073,-10.083307
196.6581,0.23136689,9.4359274,0.0,0,18.0,450.0,0.99188489,1.1304934,18.091995,451.81598,-10.114529
196.6625,0.23090146,9.4372816,0.0,0,18.0,450.0,0.99196833,1.1139077,18.086884,451.73679,-10.148397
196.6669,0.21585338,9.4361782,0.0,0,18.0,450.0,0.99128103,1.0298692,18.088102,451.65756,-10.181145
196.6713,0.23070085,9.4408503,0.0,0,18.0,450.0,0.99174142,1.0737836,18.081371,451.62085,-10.215405
196.6757,0.24131688,9.4391489,0.0,0,18.0,450.0,0.99146855,1.1155905,18.08312,451.59445,-10.246406
196.6801,0.24294452,9.4417543,0.0,0,18.0,450.0,0.99173033,1.1478274,18.079084,451.53973,-10.279549
196.6845,0.21176983,9.4396286,0.0,0,18.0,450.0,0.99152726,1.0069565,18.081781,451.46051,-10.313014
196.6889,0.2200069,9.4452562,0.0,0,18.0,450.0,0.99206084,1.0304266,18.077013,451.38837,-10.345659
196.6933,0.22630511,9.4426956,0.0,0,18.0,450.0,0.99212384,1.0333514,18.078453,451.33557,-10.378873
196.6977,0.25957873,9.4446821,0.0,0,18.0,450.0,0.99213088,1.1794176,18.077868,451.28278,-10.413087
196.7021,0.21215893,9.4403839,0.0,0,18.0,450.0,0.99177289,1.000208,18.075581,451.20358,-10.446645
196.7065,0.22593662,9.4446011,0.0,0,18.0,450.0,0.99251509,1.0355566,18.073698,451.12436,-10.479493
196.7109,0.22865607,9.4417486,0.0,0,18.0,450.0,0.99248981,1.0773427,18.070152,451.07413,-10.509545
196.7153,0.25224242,9.4432468,0.0,0,18.0,450.0,0.99285513,1.1874157,18.07069,451.03455,-10.542905
196.7197,0.23355262,9.4392567,0.0,0,18.0,450.0,0.99254638,1.1496673,18.072845,451.00107,-10.576323
196.7241,0.22404194,9.4425945,0.0,0,18.0,450.0,0.99339962,1.0391129,18.065777,450.97467,-10.608283
196.7285,0.23743117,9.4369326,0.0,0,18.0,450.0,0.992477,1.1023424,18.070421,450.94052,-10.641973
196.7329,0.26165882,9.4387655,0.0,0,18.0,450.0,0.99314815,1.2696804,18.06745,450.87451,-10.673475
196.7373,0.26552755,9.4355106,0.0,0,18.0,450.0,0.99268138,1.2631989,18.066652,450.8085,-10.709167
196.7417,0.23475057,9.4372883,0.0,0,18.0,450.0,0.99333125,1.1045003,18.062609,450.74249,-10.739803
196.7461,0.24302906,9.4336872,0.0,0,18.0,450.0,0.99243587,1.1365398,18.061853,450.67648,-10.773935
196.7505,0.26363862,9.4347324,0.0,0,18.0,450.0,0.99268174,1.1551251,18.06349,450.61047,-10.807463
196.7549,0.26506287,9.4334822,0.0,0,18.0,450.0,0.99231046,1.2690113,18.059319,450.54446,-10.839377
196.7593,0.23565219,9.4363413,0.0,0,18.0,450.0,0.99250913,1.101143,18.059027,450.48364,-10.871498
196.7637,0.2320998,9.4353933,0.0,0,18.0,450.0,0.99223816,1.0873154,18.058527,450.43085,-10.905138
196.7681,0.25517482,9.4327135,0.0,0,18.0,450.0,0.99141228,1.1924959,18.056099,450.37317,-10.936991
196.7725,0.26796654,9.4344158,0.0,0,18.0,450.0,0.9915576,1.2738771,18.054972,450.28076,-10.970877
196.7769,0.24957186,9.4352665,0.0,0,18.0,450.0,0.99123657,1.2102253,18.055309,450.18835,-11.00622
196.7813,0.24281371,9.438674,0.0,0,18.0,450.0,0.99164027,1.1375293,18.054678,450.11853,-11.038988
196.7857,0.26006627,9.4383898,0.0,0,18.0,450.0,0.99134016,1.2115999,18.055025,450.05252,-11.071819
196.7901,0.26498604,9.4387274,0.0,0,18.0,450.0,0.99113208,1.2681352,18.049831,450.00198,-11.101707
196.7945,0.26430282,9.4397697,0.0,0,18.0,450.0,0.99147987,1.256421,18.057251,449.96237,-11.137152
196.7989,0.23682165,9.4437809,0.0,0,18.0,450.0,0.9918431,1.0911496,18.053751,449.91437,-11.169428
196.8033,0.24327989,9.4393473,0.0,0,18.0,450.0,0.99140203,1.1535331,18.052498,449.84836,-11.200792
196.8077,0.278036,9.4434252,0.0,0,18.0,450.0,0.9918586,1.3206297,18.050245,449.78366,-11.235066
196.8121,0.27156159,9.4398956,0.0,0,18.0,450.0,0.99168617,1.2857001,18.050112,449.74408,-11.268895
196.8165,0.24886501,9.4447088,0.0,0,18.0,450.0,0.99241698,1.1598127,18.050398,449.70447,-11.302344
196.8209,0.24560687,9.4378719,0.0,0,18.0,450.0,0.99180657,1.1576122,18.046989,449.64423,-11.333362
197.2244,0.20498106,9.4404497,0.0,0,18.0,0.0015956647,0.99256545,0.97092891,18.011311,440.93347,-11.481991
199.4244,0.12991869,9.456727,0.0,0,18.0,1.5917621e-33,0.99547249,0.60949373,17.998808,413.79907,-11.480568
201.6244,0.096965469,9.4702234,0.0,0,18.0,1.4012985e-45,0.99790102,0.45243481,18.00065,392.02097,-11.481385
203.8244,0.093076482,9.4820261,0.0,0,18.0,1.4012985e-45,1.0000609,0.43157327,17.999603,372.12906,-11.47985
206.0244,0.10834136,9.4925547,0.0,0,18.0,1.4012985e-45,1.0020025,0.5067997,17.999224,353.64719,-11.481553
208.2244,0.10150128,9.5030041,0.0,0,18.0,1.4012985e-45,1.0038813,0.47424677,17.999943,336.49176,-11.481937
210.4244,0.082548052,9.5124378,0.0,0,18.0,1.4012985e-45,1.0055664,0.38168645,17.999302,320.19846,-11.480511
212.6244,0.084934026,9.5206318,0.0,0,18.0,1.4012985e-45,1.0070146,0.40055931,18.000301,304.81308,-11.479876
214.8244,0.10196985,9.5292044,0.0,0,18.0,1.4012985e-45,1.008549,0.47261679,17.999796,290.54974,-11.4813
217.0244,0.092346117,9.5377464,0.0,0,18.0,1.4012985e-45,1.0101519,0.42236102,17.999985,276.84879,-11.481433
219.2244,0.094561331,9.5452147,0.0,0,18.0,1.4012985e-45,1.0115596,0.43866235,17.999477,262.96481,-11.481437
221.4244,0.095208064,9.5529518,0.0,0,18.0,1.4012985e-45,1.0130109,0.43596497,18.000896,250.35414,-11.480618
223.6244,0.077405266,9.5596075,0.0,0,18.0,1.4012985e-45,1.0142156,0.35602099,17.999842,238.67093,-11.480696
225.8244,0.095736578,9.5666599,0.0,0,18.0,1.4012985e-45,1.0154855,0.435783,18.000101,227.54408,-11.481664
228.0244,0.092883103,9.5729027,0.0,0,18.0,1.4012985e-45,1.0166271,0.42479941,18.000237,217.03549,-11.482368
230.2244,0.072770335,9.5798635,0.0,0,18.0,1.4012985e-45,1.0179416,0.33881453,18.000418,207.01768,-11.481598
232.4244,0.071797036,9.5858011,0.0,0,18.0,1.4012985e-45,1.0190668,0.33209687,17.999792,197.38853,-11.480097
234.6244,0.066289164,9.5923376,0.0,0,18.0,1.4012985e-45,1.0202762,0.3019141,17.999968,188.49364,-11.479953
236.8244,0.082674958,9.5975237,0.0,0,18.0,1.4012985e-45,1.0212078,0.38113484,18.000122,180.04538,-11.480323
239.0244,0.090338789,9.6029615,0.0,0,18.0,1.4012985e-45,1.022179,0.41630581,18.000175,171.98337,-11.481187
241.2244,0.089096114,9.6081734,0.0,0,18.0,1.4012985e-45,1.0231133,0.40680727,17.999147,164.43344,-11.48203
243.4244,0.072323792,9.6128778,0.0,0,18.0,1.4012985e-45,1.0239803,0.33175051,18.000376,157.35747,-11.480883
245.6244,0.068934493,9.6175842,0.0,0,18.0,1.4012985e-45,1.0248796,0.3194977,18.000534,150.60173,-11.480391
247.8244,0.074005663,9.6221838,0.0,0,18.0,1.4012985e-45,1.0257013,0.33548933,17.999475,144.12555,-11.480092
250.0244,0.079385825,9.6266546,0.0,0,18.0,1.4012985e-45,1.0265832,0.36151946,17.999611,138.08339,-11.480927
252.2244,0.072186068,9.6311283,0.0,0,18.0,1.4012985e-45,1.0274286,0.32487714,17.999538,132.28607,-11.48164
254.4244,0.081903696,9.6348362,0.0,0,18.0,1.4012985e-45,1.0281562,0.37303826,18.000826,126.79615,-11.481808
256.6244,0.063297525,9.6388025,0.0,0,18.0,1.4012985e-45,1.0288767,0.28260508,18.000618,121.79282,-11.481657
256.8244,0.062419794,9.6393156,0.0,0,18.0,1.4012985e-45,1.0289495,0.28446493,17.99946,121.2683,-11.481317