File: examples/dan-msc-case-studies/CS3/data/01 raw data/baron_test_011.csv
Time(sec),Force(kN),Jaw(mm),PowAngle(deg),Power(W),Pram,PTemp,Strain,Stress(MPa),Stroke(mm),TC1(C),wedge(mm)
0.0,1.024448,0.18136559,0.0,0,11.076097,0.0016028705,0.012150821,12.890896,11.075373,28.103863,-9.1172323
1.1,0.94513607,0.0023249669,0.0,0,11.076097,3.2158816,0.0001617558,12.047221,11.075424,28.110407,-9.4876127
2.2,0.91318721,0.0023469809,0.0,0,11.076097,6.5158825,0.00014983611,11.610845,11.076428,28.051161,-9.4850931
3.3,0.90352935,0.0024383175,0.0,0,11.076097,9.8158798,0.0001622072,11.49637,11.076127,27.996067,-9.4834461
4.4,0.88058865,0.0023564931,0.0,0,11.076097,13.115883,0.00017274369,11.224854,11.075316,27.899395,-9.4820118
5.5,0.86492789,0.0023862857,0.0,0,11.076097,16.415884,0.00013945636,11.01888,11.076237,27.89624,-9.4800119
6.6,0.8610127,0.002363421,0.0,0,11.076097,19.715881,0.00017087669,10.957251,11.076705,27.907093,-9.4782686
7.7,0.85375178,0.0022190206,0.0,0,11.076097,23.015886,0.00016955505,10.873036,11.076063,27.846746,-9.4761257
8.8,0.8402037,0.0026322939,0.0,0,11.076097,26.315884,0.00015966645,10.704358,11.076407,27.778034,-9.4739361
9.9,0.84352106,0.0026147941,10.260418,0,11.076097,29.615883,0.00018444839,10.735093,11.075994,27.750553,-9.4719439
11.0,0.83765179,0.0026559993,27.359594,0,11.076097,32.915874,0.00019585871,10.652797,11.076215,28.062019,-9.4705181
12.1,0.84184825,0.0025900276,36.275608,0,11.076097,36.215874,0.00015336888,10.724177,11.075237,29.283907,-9.4685612
13.2,0.84208339,0.0017499996,42.086937,0,11.076097,39.515877,0.000120998,10.718348,11.075534,31.580307,-9.4668207
14.3,0.8584702,-0.00079921004,46.5448,0,11.076097,42.815884,-4.7049565e-05,10.931384,11.075714,34.27021,-9.4653196
15.4,0.86677611,-0.0035423597,49.651192,0,11.076097,46.115887,-0.00024628968,11.051957,11.075311,37.514889,-9.4638367
16.5,0.87570888,-0.0068411618,51.946316,0,11.076097,49.41589,-0.00045669309,11.160697,11.076478,41.387024,-9.4621153
17.6,0.88643748,-0.01034182,53.316105,0,11.076097,52.715893,-0.0006967404,11.286151,11.075616,45.97646,-9.4601364
18.7,0.89829844,-0.014063701,53.975826,0,11.076097,56.015896,-0.00092928309,11.44738,11.075973,50.832703,-9.4584484
19.8,0.89530176,-0.017856684,54.305416,0,11.076097,59.315895,-0.0011738164,11.417253,11.07677,55.703556,-9.4563379
20.9,0.90749276,-0.020960698,54.059975,0,11.076097,62.615894,-0.0014144363,11.576529,11.076863,60.490643,-9.4542103
22.0,0.9159736,-0.024226315,53.65723,0,11.076097,65.915878,-0.0015946109,11.678187,11.076645,65.182503,-9.4524536
23.1,0.91836876,-0.027290286,52.976078,0,11.076097,69.215889,-0.0017996175,11.741246,11.075582,69.513794,-9.4507742
24.2,0.91728151,-0.029710025,52.061523,0,11.076097,72.515884,-0.0019915549,11.725073,11.076189,73.658546,-9.4486494
25.3,0.92015082,-0.032289766,51.392673,0,11.076097,75.815895,-0.0021424682,11.741731,11.07689,77.354347,-9.4473858
26.4,0.92910159,-0.034773212,50.593609,0,11.076097,79.115891,-0.0023027512,11.865726,11.076564,80.909828,-9.4455252
27.5,0.91839045,-0.037114941,50.042728,0,11.076097,82.415894,-0.0024846294,11.722206,11.076054,84.120361,-9.4438152
28.6,0.91596067,-0.039709873,49.645695,0,11.076097,85.715904,-0.0026441666,11.700419,11.075926,87.14151,-9.4420195
29.7,0.92176646,-0.041902706,49.636234,0,11.076097,89.0159,-0.0027818843,11.764226,11.075832,90.05558,-9.4397964
30.8,0.91905928,-0.04389507,49.636234,0,11.076097,92.315903,-0.0029388019,11.749047,11.075168,92.927872,-9.4378433
31.9,0.90644228,-0.046312742,50.042721,0,11.076097,95.615898,-0.003084447,11.57431,11.075642,95.725113,-9.4357882
33.0,0.92317808,-0.048150826,50.438229,0,11.076097,98.915894,-0.0032128948,11.782966,11.075701,98.5466,-9.433959
34.1,0.92471009,-0.05018625,51.195663,0,11.076097,102.21589,-0.0033556451,11.826092,11.076336,101.30691,-9.4320374
35.2,0.91667736,-0.053036481,51.837017,0,11.076097,105.51589,-0.003530991,11.7159,11.076141,104.21291,-9.429863
36.3,0.93488771,-0.056288678,52.283936,0,11.076097,108.81589,-0.003742632,11.93572,11.07571,107.31279,-9.4282494
37.4,0.93830287,-0.058280673,52.969616,0,11.076097,112.11588,-0.0038794114,12.006854,11.076168,110.448,-9.4266796
38.5,0.93597704,-0.060341865,53.316624,0,11.076097,115.41589,-0.0040093306,11.982895,11.076122,113.82484,-9.4252291
39.6,0.93530041,-0.062956639,53.708588,0,11.076097,118.71589,-0.0041955211,11.965574,11.076852,117.14329,-9.4234495
40.7,0.93424952,-0.066063121,54.027355,0,11.076097,122.01588,-0.0043887552,11.945168,11.075942,120.59026,-9.4213886
41.8,0.94808567,-0.068661891,54.305416,0,11.076097,125.31588,-0.004555962,12.132393,11.07531,124.11327,-9.4200525
42.9,0.94071203,-0.071501672,54.624023,0,11.076097,128.616,-0.0047677346,12.039421,11.076429,127.39911,-9.4180288
44.0,0.94593155,-0.074163787,54.931637,0,11.076097,131.91589,-0.0049226205,12.097564,11.076409,130.75484,-9.416028
45.1,0.95342523,-0.077535599,55.239212,0,11.076097,135.21588,-0.0051415572,12.189524,11.076064,134.16545,-9.4142561
46.2,0.95267636,-0.080795132,55.2514,0,11.076097,138.5159,-0.0053774859,12.197619,11.075665,137.58559,-9.4124498
47.3,0.95739549,-0.083537146,55.535885,0,11.076097,141.81589,-0.0055437228,12.255246,11.076388,140.90759,-9.4105921
48.4,0.96350598,-0.085798763,55.772594,0,11.076097,145.11589,-0.0056861844,12.340747,11.075439,144.30058,-9.4086781
49.5,0.96693003,-0.08831805,55.843506,0,11.076097,148.41589,-0.0058841929,12.401991,11.075894,147.76204,-9.4070835
50.6,0.9674955,-0.091495991,55.991837,0,11.076097,151.71588,-0.0060709887,12.393051,11.075924,151.159,-9.4052448
51.7,0.96153015,-0.094523609,56.129147,0,11.076097,155.01588,-0.0062616519,12.314515,11.075664,154.37708,-9.4030037
52.8,0.96561182,-0.097295828,56.425655,0,11.076097,158.3159,-0.0064850841,12.376708,11.075822,157.6311,-9.4014225
53.9,0.96445441,-0.10003046,56.633404,0,11.076097,161.61589,-0.0066418233,12.366336,11.076979,160.86073,-9.399292
55.0,0.96760362,-0.10289107,56.894775,0,11.076097,164.91589,-0.0068108542,12.402803,11.07612,164.04935,-9.3977528
56.1,0.96887875,-0.10565963,57.127373,0,11.076097,168.2159,-0.00704036,12.436822,11.076169,167.21738,-9.39606
57.2,0.96987325,-0.10876029,57.426327,0,11.076097,171.51588,-0.0072121816,12.446452,11.0755,170.45381,-9.3943777
58.3,0.96671182,-0.11180635,57.688324,0,11.076097,174.81589,-0.0074029826,12.393201,11.076149,173.74942,-9.3926105
59.4,0.97371751,-0.11491086,58.007423,0,11.076097,178.11589,-0.0076468159,12.499555,11.076026,176.97101,-9.3910046
60.5,0.97646832,-0.11760983,58.307713,0,11.076097,181.41589,-0.0078010182,12.535869,11.076812,180.21274,-9.3890915
61.6,0.97695756,-0.12122506,58.436687,0,11.076097,184.7159,-0.0080203507,12.547365,11.076485,183.61781,-9.3874607
62.7,0.98980826,-0.12479812,58.59008,0,11.076097,188.0159,-0.0083039626,12.717193,11.075298,187.06242,-9.3856802
63.8,0.99276686,-0.12740287,58.853153,0,11.076097,191.3159,-0.0084593538,12.751715,11.076551,190.39574,-9.3838301
64.9,0.97945452,-0.12995817,58.853752,0,11.076097,194.61589,-0.0086061424,12.588313,11.075727,193.81651,-9.3818903
66.0,0.98135263,-0.1325939,59.106438,0,11.076097,197.91589,-0.0088213803,12.605141,11.076427,197.11905,-9.3801842
67.1,0.99615282,-0.13577321,59.348007,0,11.076097,201.2159,-0.0090073263,12.807909,11.076859,200.36028,-9.3786192
68.2,0.98658371,-0.13899428,59.582657,0,11.076097,204.51588,-0.009203977,12.6952,11.075423,203.62231,-9.376708
69.3,0.98425579,-0.1418236,59.695637,0,11.076097,207.8159,-0.0094266068,12.654602,11.075777,206.88895,-9.3747616
70.4,0.98010826,-0.14507344,59.842525,0,11.076097,211.11589,-0.0096146222,12.599171,11.076204,210.22954,-9.3729687
71.5,0.98765588,-0.14810334,60.084225,0,11.076097,214.41589,-0.0098044025,12.715428,11.075957,213.39838,-9.3711939
72.6,0.98144031,-0.15128748,60.314934,0,11.076097,217.7159,-0.010038401,12.624517,11.07542,216.71053,-9.368885
73.7,0.9994244,-0.15498137,60.556637,0,11.076097,221.0159,-0.010275839,12.841329,11.076798,219.96825,-9.3672762
74.8,0.9939748,-0.15686297,60.785843,0,11.076097,224.31589,-0.010388331,12.787683,11.075237,223.29068,-9.3656902
75.9,0.99718356,-0.1599973,61.009758,0,11.076097,227.61589,-0.010628227,12.832916,11.076208,226.54622,-9.3637228
77.0,0.98855895,-0.16353931,61.020924,0,11.076097,230.91589,-0.010829465,12.706356,11.07618,229.96736,-9.362072
78.1,0.99060249,-0.16731048,61.237789,0,11.076097,234.2159,-0.01106996,12.747623,11.076013,233.32582,-9.3598986
79.2,0.99359244,-0.17016672,61.412956,0,11.076097,237.5159,-0.011301736,12.812236,11.075049,236.71249,-9.3580446
80.3,0.99408555,-0.17440698,61.468498,0,11.076097,240.8159,-0.011542104,12.808993,11.076312,240.17886,-9.356472
81.4,1.0041215,-0.17816597,61.468498,0,11.076097,244.11589,-0.011796443,12.927334,11.075702,243.68806,-9.3547516
82.5,0.99473959,-0.17994884,61.504803,0,11.076097,247.41589,-0.011943437,12.824242,11.076134,246.96852,-9.3525887
83.6,0.99499136,-0.18337239,61.682949,0,11.076097,250.7159,-0.01214392,12.824893,11.074622,250.24794,-9.3508577
84.7,0.9929564,-0.18675964,61.688229,0,11.076097,254.0159,-0.012351201,12.786486,11.076553,253.62048,-9.3493252
85.8,0.99696314,-0.19017838,61.819252,0,11.076097,257.31616,-0.012614272,12.860401,11.076438,256.86517,-9.3472271
86.9,0.98676252,-0.19363406,61.847015,0,11.076097,260.61618,-0.012804734,12.74828,11.07566,260.26968,-9.3454056
88.0,0.98724449,-0.19712213,61.907955,0,11.076097,263.91589,-0.01303169,12.734184,11.076019,263.48718,-9.3438673
89.1,0.99331051,-0.20019752,62.116673,0,11.076097,267.21591,-0.013276917,12.826066,11.0761,266.63986,-9.3422699
90.2,0.99819046,-0.20325124,62.324589,0,11.076097,270.5159,-0.013447789,12.869904,11.075728,269.84476,-9.3401947
91.3,0.99641442,-0.20687297,62.440536,0,11.076097,273.81589,-0.013674125,12.866377,11.076227,272.97916,-9.3382759
92.4,0.99473488,-0.21093944,62.729195,0,11.076097,277.11591,-0.013973706,12.848577,11.078007,276.15366,-9.3368435
93.5,1.0094185,-0.21448357,62.962597,0,11.076097,280.41589,-0.014185461,13.023773,11.076491,279.26385,-9.3349915
94.6,1.0046142,-0.2180151,63.171383,0,11.076097,283.71591,-0.014408032,12.990501,11.076026,282.40912,-9.3328514
95.7,1.0025086,-0.22054277,63.369137,0,11.076097,287.0159,-0.014616538,12.951088,11.075742,285.80634,-9.3313637
96.8,1.0019276,-0.2237478,63.577873,0,11.076097,290.31589,-0.014795823,12.948061,11.075941,289.14404,-9.3294096
97.9,1.0026137,-0.22729926,63.775627,0,11.076097,293.61588,-0.015021129,12.978469,11.075756,292.57175,-9.3276052
99.0,0.99946582,-0.23109771,63.960556,0,11.076097,296.91589,-0.015295594,12.927244,11.075415,295.89658,-9.3258762
100.1,1.005205,-0.23470823,63.974709,0,11.076097,299.99542,-0.015520282,13.006703,11.076386,299.22177,-9.3242464
101.2,1.0050615,-0.2380794,62.573227,0,11.076097,299.99905,-0.015726076,13.009209,11.075772,302.35013,-9.3243618
102.3,1.0016381,-0.24013479,60.765713,0,11.076097,299.99905,-0.015899288,12.965294,11.076137,304.78644,-9.3237371
103.4,0.95952767,-0.24223572,58.819546,0,11.076097,299.99905,-0.016014285,12.410699,11.075503,306.51395,-9.3243952
104.5,0.87128109,-0.24417917,56.67223,0,11.076097,299.99905,-0.016135283,11.268219,11.076163,307.50531,-9.3238363
105.6,0.76242518,-0.24498601,54.453609,0,11.076097,299.99905,-0.016205622,9.8749304,11.074573,307.74658,-9.3237839
106.7,0.70592576,-0.24523145,52.496185,0,11.076097,299.99905,-0.016221765,9.1422396,11.07562,307.41443,-9.3243113
107.8,0.63398278,-0.24504839,50.845211,0,11.076097,299.99905,-0.016203864,8.2072048,11.075277,306.62622,-9.3246098
108.9,0.5935142,-0.24503163,49.637791,0,11.076097,299.99905,-0.016205721,7.6806207,11.076452,305.59634,-9.3239956
110.0,0.57038444,-0.24400188,48.752197,0,11.076097,299.99905,-0.016152499,7.3941369,11.07495,304.63788,-9.3241959
111.1,0.54646778,-0.24324684,48.310551,0,11.076097,299.99905,-0.016092164,7.0765285,11.076073,303.37854,-9.3241196
112.2,0.54101229,-0.2419461,48.80806,0,11.076097,299.99905,-0.015989989,7.0056219,11.075728,301.61282,-9.3238888
113.3,0.53533298,-0.24042997,50.014286,0,11.076097,299.99905,-0.015913896,6.9460392,11.076138,299.8985,-9.3242102
114.4,0.52422422,-0.2400686,51.196262,0,11.076097,299.99905,-0.015877914,6.7840619,11.075697,298.49786,-9.3240366
115.5,0.52086848,-0.2397479,52.63538,0,11.076097,299.99905,-0.015832985,6.7318649,11.075422,297.47702,-9.3234682
116.6,0.51720029,-0.23960663,53.970409,0,11.076097,299.99905,-0.015861832,6.7030854,11.076759,296.77203,-9.3239384
117.7,0.53085166,-0.23977028,54.931614,0,11.076097,299.99905,-0.015846301,6.8743839,11.075565,296.57666,-9.3240623
118.8,0.53633505,-0.24014831,55.843472,0,11.076097,299.99905,-0.015859403,6.9338112,11.075201,296.5665,-9.3236208
119.9,0.54592961,-0.24041377,56.626228,0,11.076097,299.99905,-0.015913578,7.0699754,11.076505,296.81049,-9.324069
121.0,0.54123616,-0.24136332,56.986084,0,11.076097,299.99905,-0.015953975,7.0130067,11.07553,297.26007,-9.324131
122.1,0.54075879,-0.24208653,57.407993,0,11.076097,299.99905,-0.015988201,6.9919105,11.076362,297.72595,-9.3240204
123.2,0.53981203,-0.24297501,57.535397,0,11.076097,299.99905,-0.016080281,6.9804444,11.076561,298.25333,-9.3238821
124.3,0.54320687,-0.24378172,57.535412,0,11.076097,299.99905,-0.016115468,7.0296516,11.076412,298.89322,-9.3239145
125.4,0.54408133,-0.24517132,57.535412,0,11.076097,299.99905,-0.016202064,7.0584803,11.076268,299.44818,-9.3237877
126.5,0.55440468,-0.24656354,57.260746,0,11.076097,299.99905,-0.016314128,7.1746454,11.075837,300.00266,-9.3235912
127.6,0.55057013,-0.24611531,56.986088,0,11.076097,299.99905,-0.016282931,7.1270499,11.076297,300.40344,-9.3236761
128.7,0.54970407,-0.24684615,56.608009,0,11.076097,299.99905,-0.016318731,7.1048899,11.075328,300.79089,-9.3238993
129.8,0.54986793,-0.24725324,56.31015,0,11.076097,299.99905,-0.01635325,7.1232824,11.075268,300.9577,-9.3235493
130.9,0.54926926,-0.24770978,55.930367,0,11.076097,299.99905,-0.016378935,7.1039987,11.075269,301.04037,-9.3234673
132.0,0.54984695,-0.24813691,55.569557,0,11.076097,299.99905,-0.016402248,7.1210647,11.076329,301.12646,-9.3237944
133.1,0.53987432,-0.24858503,55.245468,0,11.076097,299.99905,-0.016422052,6.989275,11.075415,301.08664,-9.3235674
134.2,0.54848796,-0.24914032,55.239262,0,11.076097,299.99905,-0.016489223,7.1057801,11.075929,300.92154,-9.3236656
135.3,0.55196303,-0.2486196,54.931644,0,11.076097,299.99905,-0.01643596,7.1521702,11.07566,300.8923,-9.3237925
136.4,0.53948283,-0.24851996,54.895683,0,11.076097,299.99905,-0.016408339,6.9858623,11.076294,300.73041,-9.3233957
137.5,0.54820645,-0.2487352,54.720818,0,11.076097,299.99905,-0.01646463,7.0904036,11.075035,300.58563,-9.323575
138.6,0.52958483,-0.24928169,54.736462,0,11.076097,299.99905,-0.016471602,6.8630667,11.076857,300.41687,-9.323452
139.7,0.54114455,-0.24957354,54.789173,0,11.076097,299.99905,-0.016476914,7.0174098,11.075874,300.18207,-9.3234158
140.8,0.54709488,-0.24941024,54.719246,0,11.076097,299.99905,-0.016500197,7.0736351,11.075525,300.14484,-9.3230762
141.9,0.54441983,-0.25062236,54.761845,0,11.076097,299.99905,-0.016567616,7.0437865,11.075429,300.08066,-9.3231602
143.0,0.55103618,-0.25038359,54.904461,0,11.076097,299.99905,-0.016553443,7.1391644,11.07509,299.9776,-9.3230925
144.1,0.54197776,-0.24994284,54.931637,0,11.076097,299.99905,-0.016517334,7.0152388,11.07667,299.8775,-9.3235102
145.13,0.55036199,-0.0093886638,54.931637,0,11.076097,299.99905,-0.0006033032,7.0199418,11.075671,299.86798,-9.3237734
145.2819,0.55633885,0.016653433,54.931641,0,11.076099,6.0864735e-10,0.0013978677,7.1137042,11.077797,299.82983,-9.3230457
145.2841,0.54325354,0.021621512,54.931641,0,11.076099,6.0790445e-25,0.0011644097,6.7285352,11.073332,299.80276,-9.3230791
145.2863,0.53178656,0.01551864,44.473663,0,11.076099,6.0716300999999994e-40,0.0012347103,6.7809691,11.079629,299.78738,-9.3233147
145.2885,0.54641825,0.019794449,32.364487,0,11.076099,0.0,0.0011299918,6.8795366,11.080051,299.77383,-9.3229589
145.2907,0.5494743,0.016389661,20.255306,0,11.076099,0.0,0.0013189928,6.9934821,11.07414,299.76031,-9.3235006
145.2929,0.54378718,0.022633214,8.1461296,0,11.076099,0.0,0.0012204024,6.8554411,11.076919,299.74677,-9.3241549
145.2951,0.55252403,0.016291309,0.0,0,11.076099,0.0,0.0012840728,7.0012426,11.073844,299.76868,-9.3247852
145.2973,0.54056716,0.018467464,0.0,0,11.076099,0.0,0.0010476384,6.9804406,11.079178,299.86343,-9.3246632
145.2995,0.51792163,0.014409813,0.0,0,11.076099,0.0,0.0012356793,6.598372,11.075433,299.95819,-9.3231688
145.3017,0.52378011,0.023146413,0.0,0,11.076099,0.0,0.0012983654,6.623354,11.073792,300.05298,-9.3237553
145.3039,0.52233332,0.016136236,0.0,0,11.076099,0.0,0.0011916059,6.5650001,11.074048,300.14774,-9.3234997
145.3061,0.51983023,0.018258492,0.0,0,11.076099,0.0,0.0010992257,6.5963845,11.078783,300.13544,-9.323019
145.3083,0.52614647,0.015188716,0.0,0,11.076099,0.0,0.0012213761,6.632678,11.077834,300.09482,-9.3214073
145.3105,0.52874219,0.022797247,0.0,0,11.076099,0.0,0.0013704532,6.7697754,11.073726,300.0542,-9.3229475
145.3127,0.53594804,0.017571468,0.0,0,11.076099,0.0,0.0012801718,6.8610001,11.071861,300.01361,-9.3231316
145.3149,0.52936482,0.019328767,0.0,0,11.076099,0.0,0.0011528616,6.6958442,11.07552,299.97989,-9.3231764
145.3171,0.5252558,0.015497798,0.0,0,11.076099,0.0,0.0011045905,6.6935124,11.073082,299.96637,-9.3228664
145.3193,0.51267946,0.021543022,0.0,0,11.076099,0.0,0.0012515431,6.488956,11.072191,299.95282,-9.3234539
145.3215,0.50939697,0.017979678,0.0,0,11.076099,0.0,0.0012358128,6.489511,11.074095,299.9393,-9.3227472
145.3237,0.51702344,0.018970504,0.0,0,11.076099,0.0,0.0012897344,6.5244336,11.072602,299.92575,-9.3228331
145.3259,0.5198856,0.015103945,0.0,0,11.076099,0.0,0.0010751996,6.6148582,11.073482,299.92194,-9.3231926
145.3281,0.52262199,0.021325585,0.0,0,11.076099,0.0,0.0013765231,6.5798135,11.073211,299.92194,-9.3233318
145.3303,0.52682143,0.017708214,0.0,0,11.063763,0.0,0.0011565298,6.7744288,11.078781,299.92194,-9.3234501
145.3325,0.52487636,0.017900297,0.0,0,10.735819,0.0,0.0012422985,6.8089318,11.075629,299.92194,-9.3236704
145.3347,0.52976388,0.015501965,0.0,0,10.404926,0.0,0.0010509761,6.7301979,11.068852,299.92685,-9.3235769
145.3369,0.52991402,0.020378193,0.0,0,10.074035,0.0,0.0014313683,6.7864704,11.010456,299.95392,-9.3251276
145.3391,0.52331883,0.017362699,0.0,0,9.7431412,0.0,0.0011492358,6.6521978,10.818575,299.98099,-9.3236818
145.3413,0.53707194,0.017795878,0.0,0,9.4141388,0.0,0.0012152162,6.9002204,10.52065,300.00806,-9.3233776
145.3435,0.50904608,0.015129849,0.0,0,9.0922337,0.0,0.00099548756,6.4440846,10.13953,300.03516,-9.3226051
145.3457,8.7140694,0.2892805,0.0,0,8.7703295,0.0,0.018996377,108.40438,9.7793188,301.19022,-9.3163071
145.3479,10.81319,0.63012481,0.0,0,8.4631929,0.0,0.042512625,131.13239,9.3885603,302.96494,-9.3157415
145.3501,11.770194,1.0017856,0.0,0,8.1570406,0.0,0.069021955,139.59227,8.9873552,304.73962,-9.3140888
145.3523,12.295153,1.3480507,0.0,0,7.860775,0.0,0.093553849,142.38394,8.6409988,306.51431,-9.3124008
145.3545,12.986159,1.6641711,0.0,0,7.5694952,0.0,0.11745645,146.76833,8.2946386,308.39249,-9.3126192
145.3567,13.430509,1.9904085,0.0,0,7.2838035,0.0,0.14171349,148.35881,7.9600163,311.11566,-9.3118801
145.3589,13.864589,2.2961526,0.0,0,7.0067787,0.0,0.16589913,149.45271,7.6442957,313.83881,-9.312438
145.3611,14.339737,2.5734785,0.0,0,6.7313666,0.0,0.18749569,151.30714,7.3515244,316.56198,-9.3127871
145.3633,14.710939,2.8545098,0.0,0,6.467802,0.0,0.21097995,151.66479,7.072391,319.28516,-9.3139973
145.3655,15.062582,3.1248779,0.0,0,6.2042418,0.0,0.2328185,151.87735,6.8031282,321.04196,-9.3131037
145.3677,15.468423,3.3760593,0.0,0,5.9515953,0.0,0.25482714,152.59036,6.532311,322.07788,-9.3127499
145.3699,15.815597,3.6353714,0.0,0,5.7009273,0.0,0.27684695,152.67023,6.2680306,323.11377,-9.3132982
145.3721,16.173618,3.8856776,0.0,0,5.457253,0.0,0.29990378,152.4948,6.0141134,324.14969,-9.314187
145.3743,16.562378,4.1429734,0.0,0,5.2187734,0.0,0.3223142,152.64159,5.7617874,325.17017,-9.3135881
145.3765,16.94129,4.3807096,0.0,0,4.9838037,0.0,0.3453916,152.65764,5.5084128,325.78152,-9.3135872
145.3787,17.335892,4.6292634,0.0,0,4.7569838,0.0,0.36819699,152.64705,5.2651601,326.39288,-9.3136177
145.3809,17.710096,4.8685856,0.0,0,4.5305758,0.0,0.39257631,152.23511,5.0249786,327.00424,-9.3141108
145.3831,18.095604,5.1099572,0.0,0,4.3147016,0.0,0.41545209,152.05176,4.78584,327.6156,-9.3130074
145.3853,18.485098,5.3283291,0.0,0,4.0989256,0.0,0.43889561,151.68311,4.557909,328.14969,-9.3137932
145.3875,18.902895,5.5582418,0.0,0,3.8911293,0.0,0.46200103,151.57028,4.3338203,328.60651,-9.3129349
145.3897,19.346987,5.7728996,0.0,0,3.6859133,0.0,0.48613307,151.48236,4.1055465,329.06335,-9.3133707
145.3919,19.82312,6.0019984,0.0,0,3.4855206,0.0,0.50997496,151.51189,3.8859284,329.52017,-9.3136721
145.3941,20.297693,6.2057309,0.0,0,3.2902927,0.0,0.53410488,151.3455,3.6724064,329.97702,-9.3121977
145.3963,20.802906,6.4206886,0.0,0,3.0970623,0.0,0.55782336,151.58621,3.4669309,330.21371,-9.3134289
145.3985,21.317173,6.6174998,0.0,0,2.9113381,0.0,0.58213246,151.52908,3.2621763,330.44214,-9.3121367
145.4007,21.842743,6.8201618,0.0,0,2.7256143,0.0,0.60521257,151.76282,3.0617714,330.67056,-9.3115473
145.4029,22.364426,6.9963942,0.0,0,2.5483871,0.0,0.62828034,151.9158,2.8739693,330.89896,-9.3110762
145.4051,22.902945,7.1837616,0.0,0,2.3717272,0.0,0.6510281,152.05629,2.6941333,331.07571,-9.3111582
145.4073,23.470774,7.3543305,0.0,0,2.2008002,0.0,0.67411321,152.20111,2.5189333,331.1832,-9.3109484
145.4095,24.085094,7.5338964,0.0,0,2.0327642,0.0,0.69674134,152.68622,2.3417382,331.29071,-9.3112526
145.4117,24.744741,7.6918445,0.0,0,1.8679363,0.0,0.7191087,153.40793,2.1746955,331.39819,-9.3111696
145.4139,25.402847,7.8613968,0.0,0,1.7080842,0.0,0.74178421,153.98157,2.0113704,331.50571,-9.3094425
145.4161,26.134838,8.0165892,0.0,0,1.5491643,0.0,0.76454091,154.83406,1.8437991,331.38574,-9.3097744
145.4183,26.874857,8.181695,0.0,0,1.3970972,0.0,0.78742069,155.65215,1.6885613,331.23795,-9.3096619
145.4205,27.649891,8.3249788,0.0,0,1.2450333,0.0,0.80979711,156.63707,1.5336896,331.09015,-9.309679
145.4227,28.462252,8.4835272,0.0,0,1.0992643,0.0,0.83293056,157.50478,1.3792254,330.94235,-9.3094988
145.4249,29.295547,8.6233225,0.0,0,0.95463622,0.0,0.85516906,158.54268,1.2279687,330.54205,-9.3082571
145.4271,30.190258,8.7727623,0.0,0,0.8140732,0.0,0.8782475,159.60176,1.0838171,329.68213,-9.3080587
145.4293,31.156363,8.9074078,0.0,0,0.67652929,0.0,0.90077138,161.03198,0.94215119,328.8222,-9.3070107
145.4315,32.190605,9.0504532,0.0,0,0.54098582,0.0,0.92434281,162.56575,0.79370528,327.96228,-9.3067799
145.4337,33.311768,9.1859732,0.0,0,0.4100858,0.0,0.94735777,164.31851,0.65059745,327.10236,-9.3064518
145.4359,34.467178,9.3281679,0.0,0,0.27942529,0.0,0.97212446,165.87808,0.51264584,326.74265,-9.3048468
145.4381,32.327221,9.3401375,0.0,0,0.15489206,0.0,0.97437811,155.62112,0.4283821,326.49408,-9.3063116
145.4403,30.961193,9.3518238,0.0,0,0.030416043,0.0,0.97697979,148.49753,0.37638077,326.24551,-9.3096991
145.4425,30.448235,9.3607874,0.0,0,-0.091732524,0.0,0.97810769,145.77774,0.33248046,325.99695,-9.3096991
145.4447,30.180315,9.3724899,0.0,0,-0.21312852,0.0,0.98077756,144.12375,0.278267,326.09863,-9.3111115
145.4469,30.101549,9.3756618,0.0,0,-0.33452454,0.0,0.98053592,143.79326,0.22600596,327.09293,-9.3104553
145.4491,30.035416,9.3806639,0.0,0,-0.45592052,0.0,0.98225015,143.23643,0.17117774,328.08719,-9.3106937
145.4513,29.948921,9.3843975,0.0,0,-0.57731652,0.0,0.98202533,142.85828,0.11867442,329.08148,-9.311389
145.4535,29.817368,9.3920078,0.0,0,-0.69871247,0.0,0.98462355,141.8551,0.07655666,330.07578,-9.3125992
145.4557,29.621861,9.3934555,0.0,0,-0.82010847,0.0,0.98339593,141.08763,0.036814969,330.85471,-9.3130436
145.4579,29.349525,9.3929186,0.0,0,-0.94150448,0.0,0.98461086,139.6102,0.0038540931,331.56009,-9.313426
145.4601,28.986246,9.398818,0.0,0,-1.0629005,0.0,0.98424494,137.95805,-0.013114219,332.26547,-9.3133535
145.4623,28.534369,9.4018583,0.0,0,-0.84332824,300.0,0.98664302,135.498,-0.019218495,332.97086,-9.3130817
145.4645,28.017809,9.4075031,0.0,0,-0.42304912,300.0,0.98571342,133.19318,-0.017614353,333.63962,-9.3137407
145.4667,27.509153,9.4015007,0.0,0,-0.0027696523,300.0,0.98631984,130.67731,-0.013881034,334.16989,-9.3138618
145.4689,27.073969,9.4038925,0.0,0,0.4175092,300.0,0.98491967,128.77077,-0.0066774497,334.70013,-9.3154945
145.4711,26.756157,9.4029961,0.0,0,0.83778834,300.0,0.98704201,126.99731,-0.0037382683,335.23041,-9.314291
145.4733,26.485626,9.4094343,0.0,0,1.2580682,300.0,0.98584062,125.83513,-0.003144857,335.76068,-9.3159409
145.4755,25.565844,9.401783,0.0,0,1.6783469,300.0,0.9867143,121.48325,0.01690283,336.13248,-9.3172503
145.4777,23.260717,9.4037199,0.0,0,2.0986257,300.0,0.98497468,110.92039,0.10228378,336.42719,-9.3178988
145.4799,19.515362,9.3862514,0.0,0,2.5189054,300.0,0.98403144,93.291328,0.25517908,336.72192,-9.3199825
145.4821,11.467588,9.3658638,0.0,0,2.9391847,300.0,0.97795218,56.432583,0.48932493,337.01663,-9.3257027
145.4843,0.37406051,9.1713495,0.0,0,3.3594637,300.0,0.94670737,1.8085618,0.88908333,337.28214,-9.3389349
145.4865,-0.26194885,9.0467911,0.0,0,3.7797427,300.0,0.92338485,-1.1296504,1.5807202,337.36252,-9.3401241
145.4887,-0.16174726,8.9542036,0.0,0,4.2000222,300.0,0.91005188,-0.90418929,2.3091168,337.4429,-9.3387785
145.4909,0.054397732,8.9114113,0.0,0,4.6203012,300.0,0.90031642,0.30651137,2.9648809,337.52328,-9.3362579
145.4931,0.056608878,8.9046373,0.0,0,5.0405807,300.0,0.901371,0.2372811,3.4883649,337.60367,-9.3354378
145.4953,0.048146084,8.9436274,0.0,0,5.4608598,300.0,0.90589714,0.24546488,3.9128366,337.57956,-9.3354368
145.4975,-0.13602152,9.0008888,0.0,0,5.8811393,300.0,0.91722143,-0.60885268,4.3020983,337.48581,-9.3338633
145.4997,-0.13715169,9.1077223,0.0,0,6.3014183,300.0,0.93302435,-0.75763494,4.6965017,337.39203,-9.333478
145.5019,-0.00031522242,9.2163906,0.0,0,6.7216969,300.0,0.95365065,-0.090027288,5.0948477,337.29825,-9.3316689
145.5041,3.7706823,9.3754616,0.0,0,7.1419768,300.0,0.97992313,16.386696,5.5134425,337.21939,-9.3297157
145.5063,0.11169928,9.2989559,0.0,0,7.5622559,300.0,0.96847647,0.48988372,5.9418592,337.36005,-9.3299618
145.5085,-0.16350879,9.2777147,0.0,0,7.9825354,300.0,0.96252245,-0.68137944,6.3731871,337.5007,-9.3279915
145.5107,-0.059370976,9.2701674,0.0,0,8.4028139,300.0,0.9631781,-0.44697893,6.8194504,337.64136,-9.328145
145.5129,0.25084269,9.3082542,0.0,0,8.8230925,300.0,0.96832639,1.2357048,7.2591233,337.78201,-9.3266096
145.5151,1.882498,9.3548117,0.0,0,9.243372,300.0,0.97791183,9.1587744,7.6941233,337.96506,-9.3254137
145.5173,-0.15010278,9.3408766,0.0,0,9.6636515,300.0,0.97404665,-0.68110496,8.1221905,338.1861,-9.3259935
145.5195,-0.0780534,9.3397799,0.0,0,10.083931,300.0,0.97499716,-0.52856046,8.5584431,338.40717,-9.3262901
145.5217,0.36381477,9.3499918,0.0,0,10.50421,300.0,0.97598523,1.8154114,8.9947424,338.6282,-9.3252354
145.5239,0.27110496,9.3422909,0.0,0,10.924489,300.0,0.97538584,1.3012213,9.4349194,338.84924,-9.3242426
145.5261,0.1224656,9.3560562,0.0,0,11.344769,300.0,0.97688967,0.59889942,9.8610106,338.93091,-9.3253689
145.5283,0.21611689,9.3464584,0.0,0,11.765047,300.0,0.97615379,1.0468777,10.291557,339.01129,-9.3237514
145.5305,0.22624519,9.3501873,0.0,0,12.185327,300.0,0.97633487,1.0966251,10.72451,339.09167,-9.323823
145.5327,0.25925973,9.3396807,0.0,0,12.605606,300.0,0.97465515,1.2806873,11.152732,339.17203,-9.323061
145.5349,0.25658378,9.3508577,0.0,0,13.025885,300.0,0.97628766,1.2674407,11.563636,339.23718,-9.3233519
145.5371,0.18970181,9.3457136,0.0,0,13.446164,300.0,0.97552419,0.89214683,11.974226,339.28409,-9.3238277
145.5393,0.21531178,9.3472166,0.0,0,13.866444,300.0,0.97606277,1.0270859,12.406988,339.33096,-9.3223934
145.5415,0.28471082,9.3438568,0.0,0,14.286723,300.0,0.97525805,1.3257712,12.844131,339.37787,-9.323287
145.5437,0.25528806,9.3491554,0.0,0,14.707002,300.0,0.9765836,1.2422909,13.281097,339.42474,-9.3238277
145.5459,0.24331571,9.3460875,0.0,0,15.127281,300.0,0.9754622,1.2037965,13.719827,339.45319,-9.3222408
145.5481,0.22379182,9.34725,0.0,0,15.547561,300.0,0.97637022,1.0020555,14.155278,339.47998,-9.3221235
145.5503,0.28774187,9.3444881,0.0,0,15.967839,300.0,0.97504371,1.3833498,14.600958,339.50677,-9.3215046
145.5525,0.29301775,9.3499699,0.0,0,16.388119,300.0,0.9768461,1.3974771,15.030404,339.53357,-9.3222113
145.5547,0.2527701,9.3483877,0.0,0,16.808399,300.0,0.97548884,1.2767068,15.443167,339.56549,-9.3230658
145.5569,0.22166127,9.3486156,0.0,0,17.228678,300.0,0.97667211,1.0604255,15.853037,339.60568,-9.3217249
145.5591,0.22608544,9.3482571,0.0,0,17.648958,300.0,0.97548026,1.0957487,16.268141,339.64587,-9.3226404
145.5613,0.30151635,9.3485708,0.0,0,17.999975,300.0,0.97683537,1.4228909,16.690334,339.68607,-9.3226757
145.5635,0.24069607,9.3474474,0.0,0,18.0,300.0,0.97493637,1.170769,17.104708,339.72623,-9.3221607
145.5657,0.23195927,9.3449192,0.0,0,18.0,300.0,0.97631305,1.1072025,17.497208,339.79474,-9.3212986
145.5679,0.27550662,9.3472376,0.0,0,18.0,300.0,0.97506183,1.2895015,17.853056,339.86844,-9.3215618
145.5701,0.26951453,9.3474598,0.0,0,18.0,300.0,0.97688234,1.3214135,18.14983,339.94211,-9.3225145
145.5723,0.30663085,9.3514814,0.0,0,18.0,300.0,0.97556967,1.4740815,18.364571,340.01581,-9.3256817
145.5745,0.33129448,9.3465595,0.0,0,18.0,300.0,0.97683328,1.5715774,18.486778,340.0874,-9.3281212
145.5767,0.3020097,9.3532696,0.0,0,18.0,300.0,0.97592312,1.438815,18.502705,340.15439,-9.3336372
145.5789,0.29742473,9.3461151,0.0,0,18.0,300.0,0.97688025,1.4374568,18.417067,340.22137,-9.3418093
145.5811,0.29552132,9.3506174,0.0,0,18.0,300.0,0.9753288,1.4117686,18.297987,340.28836,-9.352478
145.5833,0.3039903,9.3455582,0.0,0,18.0,300.0,0.97676951,1.4427726,18.178909,340.35535,-9.3634233
145.5855,0.31767839,9.3498297,0.0,0,18.0,300.0,0.97536254,1.5177805,18.088907,340.41199,-9.3774624
145.5877,0.32244408,9.342742,0.0,0,18.0,300.0,0.97633839,1.543224,18.053249,340.46558,-9.3926783
145.5899,0.31644037,9.3515482,0.0,0,18.0,300.0,0.9752143,1.4894311,18.042807,340.51913,-9.4101362
145.5921,0.32603869,9.3411474,0.0,0,18.0,300.0,0.97596306,1.5530404,18.048267,340.57272,-9.4274149
145.5943,0.3305814,9.3466349,0.0,0,18.0,300.0,0.97486591,1.6047639,18.067354,340.61996,-9.4451933
145.5965,0.2894302,9.3393106,0.0,0,18.0,300.0,0.97573429,1.432676,18.091845,340.64676,-9.4638786
145.5987,0.2834776,9.3502426,0.0,0,18.0,300.0,0.97487557,1.3899025,18.108374,340.67355,-9.4796171
145.6009,0.29437599,9.338541,0.0,0,18.0,300.0,0.97535658,1.3989136,18.126076,340.70035,-9.4968166
145.6031,0.2895723,9.3436127,0.0,0,18.0,300.0,0.97462434,1.3991125,18.13707,340.72714,-9.5122108
145.6053,0.28889269,9.3375683,0.0,0,18.0,300.0,0.97526699,1.3958987,18.144241,340.71643,-9.5267897
145.6075,0.31143016,9.3490505,0.0,0,18.0,300.0,0.97498244,1.4759337,18.144274,340.68964,-9.5435724
145.6097,0.35115293,9.3386841,0.0,0,18.0,300.0,0.97537798,1.6404915,18.14595,340.66284,-9.5577574
145.6119,0.34276676,9.3438101,0.0,0,18.0,300.0,0.97453952,1.6688206,18.143478,340.63605,-9.5741892
145.6141,0.3357746,9.3354149,0.0,0,18.0,300.0,0.97464955,1.6563357,18.141966,340.61365,-9.5904427
145.6163,0.31852299,9.3451118,0.0,0,18.0,300.0,0.97475964,1.5545044,18.132912,340.61365,-9.604497
145.6185,0.31320432,9.3391857,0.0,0,18.0,300.0,0.9751671,1.512076,18.130651,340.61365,-9.6210222
145.6207,0.30290118,9.3469839,0.0,0,18.0,300.0,0.97533226,1.498542,18.130934,340.61365,-9.6372004
145.6229,0.314374,9.3378668,0.0,0,18.0,300.0,0.97474796,1.5238253,18.125816,340.61365,-9.6531973
145.6251,0.33571789,9.3437624,0.0,0,18.0,300.0,0.97471029,1.5959854,18.125717,340.61365,-9.6691122
145.6273,0.3474876,9.3385277,0.0,0,18.0,300.0,0.97473741,1.6580691,18.123638,340.61365,-9.6839609
145.6295,0.36502588,9.3460855,0.0,0,18.0,300.0,0.97548497,1.7600877,18.122211,340.61365,-9.7017984
145.6317,0.35964072,9.3405647,0.0,0,18.0,300.0,0.97489452,1.7604064,18.120302,340.61365,-9.7185459
145.6339,0.33771759,9.3494101,0.0,0,18.0,300.0,0.97578722,1.6291745,18.118475,340.60999,-9.7333889
145.6361,0.3324447,9.3400478,0.0,0,18.0,300.0,0.97481203,1.5859585,18.113529,340.56979,-9.7498045
145.6383,0.31910351,9.3430996,0.0,0,18.0,300.0,0.97539872,1.5296078,18.113487,340.5296,-9.7640619
145.6405,0.3167854,9.3393688,0.0,0,18.0,300.0,0.97454989,1.5363901,18.106016,340.48944,-9.7807312
145.6427,0.33056864,9.3465385,0.0,0,18.0,300.0,0.9758966,1.5980115,18.107553,340.44925,-9.7959309
145.6449,0.33831069,9.3416462,0.0,0,18.0,300.0,0.97475392,1.5956671,18.112226,340.43134,-9.8121376
145.6471,0.3744427,9.3442421,0.0,0,18.0,300.0,0.97578907,1.80852,18.107405,340.43134,-9.8279037
145.6493,0.3691802,9.3396873,0.0,0,18.0,300.0,0.97426659,1.7924615,18.10577,340.43134,-9.8446112
145.6515,0.35369712,9.3453503,0.0,0,18.0,300.0,0.97600359,1.6783686,18.106201,340.43134,-9.8594646
145.6537,0.33454028,9.3436155,0.0,0,18.0,300.0,0.9746533,1.6221868,18.101656,340.4317,-9.8739204
145.6559,0.3170177,9.3412371,0.0,0,18.0,300.0,0.97540021,1.531882,18.102493,340.45178,-9.8898935
145.6581,0.30821279,9.340929,0.0,0,18.0,300.0,0.97425812,1.4619606,18.094965,340.47189,-9.9060173
145.6603,0.31015909,9.3424149,0.0,0,18.0,300.0,0.97580689,1.4502299,18.098194,340.49197,-9.9228573
145.6625,0.32472271,9.3432264,0.0,0,18.0,300.0,0.97445071,1.5737392,18.100189,340.51208,-9.9383669
145.6647,0.35467687,9.3386927,0.0,0,18.0,300.0,0.97509104,1.6649357,18.096661,340.52249,-9.9544992
145.6669,0.35555163,9.3375292,0.0,0,18.0,300.0,0.97338146,1.6899188,18.096378,340.52249,-9.9707289
145.6691,0.35732397,9.3398418,0.0,0,18.0,300.0,0.97552741,1.7111634,18.096075,340.52249,-9.9869156
145.6713,0.32331842,9.3442965,0.0,0,18.0,300.0,0.97439617,1.5543315,18.094454,340.52249,-10.0031
145.6735,0.30978814,9.3373976,0.0,0,18.0,300.0,0.97527546,1.5342352,18.092276,340.52249,-10.018133
145.6757,0.30203283,9.3405247,0.0,0,18.0,300.0,0.97388917,1.4439913,18.091494,340.51617,-10.03334
145.6779,0.30956519,9.3392239,0.0,0,18.0,300.0,0.97557437,1.4450305,18.094137,340.50946,-10.049043
145.6801,0.31233287,9.3452349,0.0,0,18.0,300.0,0.97427452,1.461375,18.095308,340.50278,-10.065963
145.6823,0.34759054,9.3365974,0.0,0,18.0,300.0,0.97516936,1.6330307,18.091822,340.49609,-10.080496
145.6845,0.3618772,9.3418255,0.0,0,18.0,300.0,0.9738704,1.7563345,18.091944,340.48392,-10.095767
145.6867,0.3641412,9.3386116,0.0,0,18.0,300.0,0.97551423,1.7283248,18.091969,340.46381,-10.113191
145.6889,0.34260124,9.3480768,0.0,0,18.0,300.0,0.97461778,1.6701205,18.092512,340.4437,-10.129682
145.6911,0.3282676,9.3357306,0.0,0,18.0,300.0,0.97516394,1.5967405,18.0879,340.42361,-10.145406
145.6933,0.3203429,9.3408537,0.0,0,18.0,300.0,0.97387046,1.5534781,18.086681,340.4035,-10.159948
145.6955,0.31511855,9.3366394,0.0,0,18.0,300.0,0.97528619,1.5450658,18.088072,340.38342,-10.17706
145.6977,0.31656533,9.3505554,0.0,0,18.0,300.0,0.97501636,1.5284984,18.088282,340.36331,-10.192348
145.6999,0.34904903,9.3373661,0.0,0,18.0,300.0,0.97532243,1.6581168,18.08777,340.34323,-10.20622
145.7021,0.37729278,9.3424158,0.0,0,18.0,300.0,0.97416842,1.7605984,18.084667,340.32315,-10.221909
145.7043,0.38882345,9.3386993,0.0,0,18.0,300.0,0.97549003,1.8646461,18.090261,340.30981,-10.238307
145.7065,0.38094267,9.3499308,0.0,0,18.0,300.0,0.97519588,1.8429012,18.084372,340.30981,-10.255522
145.7087,0.35826313,9.3385372,0.0,0,18.0,300.0,0.97524613,1.7753494,18.080866,340.30981,-10.271308
145.7109,0.33872262,9.3415833,0.0,0,18.0,300.0,0.97405589,1.6445639,18.081261,340.30981,-10.287892
145.7131,0.32647681,9.3326502,0.0,0,18.0,300.0,0.97436422,1.573984,18.081078,340.30981,-10.303551
145.7153,0.32066983,9.3475018,0.0,0,18.0,300.0,0.9750613,1.5562961,18.079193,340.30444,-10.319448
145.7175,0.34195897,9.3376102,0.0,0,18.0,300.0,0.97485846,1.6308205,18.081453,340.29776,-10.334088
145.7197,0.3785978,9.3430071,0.0,0,18.0,300.0,0.97449613,1.7939246,18.082016,340.29105,-10.349646
145.7219,0.3825551,9.3343601,0.0,0,18.0,300.0,0.97415656,1.8123461,18.080694,340.28436,-10.365504
145.7241,0.3922343,9.3473835,0.0,0,18.0,300.0,0.97521019,1.8864745,18.081665,340.27234,-10.38191
145.7263,0.35415301,9.3391619,0.0,0,18.0,300.0,0.97499794,1.7478013,18.078739,340.24554,-10.396786
145.7285,0.34313053,9.3410635,0.0,0,18.0,300.0,0.97451663,1.6691159,18.078243,340.21875,-10.413175
145.7307,0.32759488,9.3356609,0.0,0,18.0,300.0,0.97430044,1.5828824,18.077087,340.19196,-10.429039
145.7329,0.32802486,9.3456802,0.0,0,18.0,300.0,0.97518784,1.5561867,18.07832,340.16516,-10.445124
145.7351,0.33182025,9.3387804,0.0,0,18.0,300.0,0.97468716,1.5758349,18.075073,340.13837,-10.460443
145.7373,0.35350555,9.3408108,0.0,0,18.0,300.0,0.97466272,1.6848395,18.077284,340.11157,-10.476175
145.7395,0.37811109,9.3381166,0.0,0,18.0,300.0,0.97446299,1.8150624,18.076509,340.08478,-10.49218
145.7417,0.39414456,9.3452044,0.0,0,18.0,300.0,0.97540337,1.8718657,18.07222,340.05798,-10.506998
145.7439,0.37324721,9.3385668,0.0,0,18.0,300.0,0.97410339,1.8525761,18.072926,340.02737,-10.524072
145.7461,0.33898693,9.3407774,0.0,0,18.0,300.0,0.97483933,1.6551955,18.075981,339.98047,-10.541884
145.7483,0.32418028,9.3384266,0.0,0,18.0,300.0,0.97424078,1.5369774,18.074184,339.93359,-10.558479
145.7505,0.32658854,9.3439589,0.0,0,18.0,300.0,0.97565752,1.5683235,18.07295,339.88669,-10.573406
145.7527,0.32886893,9.3389702,0.0,0,18.0,300.0,0.97400707,1.570796,18.068687,339.83981,-10.588421
145.7549,0.34466934,9.3394756,0.0,0,18.0,300.0,0.97504109,1.6777112,18.068262,339.7973,-10.603972
145.7571,0.37919524,9.3381386,0.0,0,18.0,300.0,0.97386795,1.7990291,18.069778,339.75711,-10.620175
145.7593,0.37236699,9.3428106,0.0,0,18.0,300.0,0.9757387,1.7857529,18.067202,339.71692,-10.635002
145.7615,0.39170986,9.3409748,0.0,0,18.0,300.0,0.97409868,1.9183364,18.069496,339.67673,-10.65194
145.7637,0.36691359,9.3385696,0.0,0,18.0,300.0,0.97505563,1.7782665,18.070024,339.63892,-10.66837
145.7659,0.33469158,9.3382511,0.0,0,18.0,300.0,0.97345191,1.6141655,18.064333,339.61884,-10.683973
145.7681,0.32987794,9.3400373,0.0,0,18.0,300.0,0.97553343,1.5896314,18.067713,339.59872,-10.700457
145.7703,0.32184634,9.341424,0.0,0,18.0,300.0,0.97414249,1.56924,18.070282,339.57864,-10.716067
145.7725,0.34336954,9.3377428,0.0,0,18.0,300.0,0.97520947,1.6373001,18.062401,339.55853,-10.731636
145.7747,0.37380636,9.3415956,0.0,0,18.0,300.0,0.97386968,1.7894151,18.061501,339.54236,-10.746696
145.7769,0.39434993,9.338419,0.0,0,18.0,300.0,0.97531396,1.906696,18.063221,339.52896,-10.76304
145.7791,0.39487618,9.3416042,0.0,0,18.0,300.0,0.9737339,1.9320179,18.062128,339.51556,-10.778201
145.7813,0.37548462,9.3380041,0.0,0,18.0,300.0,0.97531986,1.8421192,18.060995,339.50217,-10.795209
145.7835,0.37003663,9.3439169,0.0,0,18.0,300.0,0.97430027,1.7997477,18.061504,339.48755,-10.809239
145.7857,0.33802232,9.3381281,0.0,0,18.0,300.0,0.97556496,1.6324674,18.063763,339.44736,-10.826344
145.7879,0.33371636,9.3456411,0.0,0,18.0,300.0,0.97434229,1.5935531,18.061508,339.40717,-10.842333
145.7901,0.34482905,9.3365545,0.0,0,18.0,300.0,0.9751659,1.6191663,18.059072,339.36697,-10.856973
145.7923,0.37121946,9.3416128,0.0,0,18.0,300.0,0.97399473,1.7357566,18.061527,339.32678,-10.874183
145.7945,0.3957774,9.33428,0.0,0,18.0,300.0,0.97485685,1.8945607,18.060734,339.25934,-10.890406
145.7967,0.41716936,9.3463516,0.0,0,18.0,300.0,0.97437108,2.0231211,18.059786,339.16556,-10.905163
145.7989,0.39750746,9.3383751,0.0,0,18.0,300.0,0.97541654,1.9231666,18.059875,339.07178,-10.919488
145.8011,0.37937739,9.3415337,0.0,0,18.0,300.0,0.97398829,1.8789999,18.060774,338.978,-10.935385
145.8033,0.34988189,9.3363981,0.0,0,18.0,300.0,0.97511059,1.7055277,18.063576,338.88422,-10.951762
145.8055,0.33770779,9.3462353,0.0,0,18.0,300.0,0.97443241,1.6360387,18.059109,338.823,-10.967516
145.8077,0.32109195,9.3337917,0.0,0,18.0,300.0,0.9745205,1.5623765,18.059065,338.76273,-10.982964
145.8099,0.34695953,9.3388243,0.0,0,18.0,300.0,0.97352678,1.6698947,18.058746,338.70242,-10.998643
145.8121,0.37344146,9.3350563,0.0,0,18.0,300.0,0.9749555,1.7616168,18.059824,338.64215,-11.015988
145.8143,0.40097663,9.3456001,0.0,0,18.0,300.0,0.97457671,1.9195695,18.058075,338.58478,-11.03136
145.8165,0.41025159,9.3352766,0.0,0,18.0,300.0,0.97467601,1.9798467,18.057283,338.53119,-11.047293
145.8187,0.37325451,9.3401194,0.0,0,18.0,300.0,0.97391993,1.8550905,18.052952,338.4776,-11.062963
145.8209,0.35840371,9.3329725,0.0,0,18.0,300.0,0.9741447,1.7640282,18.056961,338.42401,-11.078615
145.8231,0.34304151,9.3480434,0.0,0,18.0,300.0,0.97525758,1.6390451,18.054493,338.37045,-11.094742
145.8253,0.33340269,9.3379278,0.0,0,18.0,300.0,0.97488999,1.5621673,18.054989,338.31082,-11.110254
145.8275,0.34111792,9.3415232,0.0,0,18.0,300.0,0.97442174,1.5958987,18.053173,338.25055,-11.125307
145.8297,0.36955553,9.3351326,0.0,0,18.0,300.0,0.97427905,1.7559172,18.052015,338.19025,-11.14235
145.8319,0.40150696,9.3449554,0.0,0,18.0,300.0,0.97490704,1.9136251,18.053854,338.12997,-11.159195
145.8341,0.41076064,9.3357811,0.0,0,18.0,300.0,0.97428429,1.9945592,18.048092,338.08188,-11.174966
145.8363,0.39647079,9.3401642,0.0,0,18.0,300.0,0.97460335,1.9182557,18.054197,338.05508,-11.191875
145.8385,0.36532277,9.3358994,0.0,0,18.0,300.0,0.97417772,1.7583137,18.053444,338.02829,-11.207247
145.8407,0.3482326,9.3441792,0.0,0,18.0,300.0,0.97510898,1.680343,18.049509,338.0015,-11.222517
145.8429,0.33907714,9.3372068,0.0,0,18.0,300.0,0.97425389,1.6136323,18.046957,337.97473,-11.236441
145.8451,0.34116,9.3400507,0.0,0,18.0,300.0,0.97458261,1.6414821,18.049555,337.9313,-11.252456
145.8473,0.36348906,9.3367701,0.0,0,18.0,300.0,0.97397733,1.7208018,18.049948,337.8844,-11.269468
145.8495,0.40275279,9.3420544,0.0,0,18.0,300.0,0.97519308,1.9325184,18.047163,337.83752,-11.284127
145.8517,0.42468995,9.3384972,0.0,0,18.0,300.0,0.97408122,2.0009925,18.050657,337.79062,-11.30013
145.8539,0.4172197,9.3399916,0.0,0,18.0,300.0,0.97502095,1.9960839,18.042765,337.73596,-11.316767
145.8561,0.40295145,9.3382854,0.0,0,18.0,300.0,0.97398555,1.9374852,18.046728,337.66226,-11.332969
145.8583,0.36355907,9.3410759,0.0,0,18.0,300.0,0.97534019,1.7701807,18.04948,337.58859,-11.349672
145.8605,0.34436378,9.3387489,0.0,0,18.0,300.0,0.9738642,1.6605448,18.050032,337.51489,-11.366714
146.7608,0.31815913,9.3440485,0.0,0,18.0,1.621674e-10,0.97533566,1.5305021,18.001823,309.36395,-11.482565
147.8608,0.29812706,9.3495102,0.0,0,18.0,1.6196895e-25,0.97631437,1.4368807,18.000513,293.62659,-11.48171
148.9608,0.2890971,9.3545341,0.0,0,18.0,1.617715e-40,0.97719401,1.3851452,17.999977,282.11905,-11.482572
150.0608,0.28187197,9.3581314,0.0,0,18.0,1.4012985e-45,0.97787052,1.347032,17.999331,272.26968,-11.482731
151.1608,0.27131394,9.3628349,0.0,0,18.0,1.4012985e-45,0.97863549,1.3028003,18.000347,263.6868,-11.482773
152.2608,0.25444224,9.3660736,0.0,0,18.0,1.4012985e-45,0.97924966,1.2229106,18.000912,255.59763,-11.482295
153.3608,0.25879586,9.3696442,0.0,0,18.0,1.4012985e-45,0.97995234,1.2350045,18.000444,247.49438,-11.482274
154.4608,0.26563349,9.3737593,0.0,0,18.0,1.4012985e-45,0.98053724,1.2723883,17.999741,240.0703,-11.482024
155.5608,0.24927828,9.3763294,0.0,0,18.0,1.4012985e-45,0.98107624,1.1971713,17.999935,232.84055,-11.482803
156.6608,0.24997962,9.3793592,0.0,0,18.0,1.4012985e-45,0.98168564,1.1897227,17.998932,226.4104,-11.482892
157.7608,0.25550318,9.3824635,0.0,0,18.0,1.4012985e-45,0.98210639,1.223017,18.000626,219.93263,-11.482993
158.8608,0.24313596,9.3858604,0.0,0,18.0,1.4012985e-45,0.98278648,1.1626298,17.999285,213.60512,-11.482904
159.9608,0.24152906,9.3890905,0.0,0,18.0,1.4012985e-45,0.98335314,1.1516448,17.99938,207.99391,-11.482597
161.0608,0.2389285,9.3918324,0.0,0,18.0,1.4012985e-45,0.98378807,1.1364419,18.000935,202.30946,-11.482918
162.1608,0.25289604,9.3942223,0.0,0,18.0,1.4012985e-45,0.98423451,1.2047399,18.000233,196.52988,-11.482522
163.2608,0.2392589,9.3974609,0.0,0,18.0,1.4012985e-45,0.98480761,1.142465,18.000502,191.49776,-11.48266
164.3608,0.24113546,9.3999014,0.0,0,18.0,1.4012985e-45,0.98534286,1.1463392,18.000465,186.78468,-11.483031
165.4608,0.25035867,9.4030762,0.0,0,18.0,1.4012985e-45,0.98577917,1.1854377,17.999933,181.65994,-11.482363
166.5608,0.24474518,9.4054708,0.0,0,18.0,1.4012985e-45,0.98629886,1.1693449,18.000013,176.69914,-11.482848
167.6608,0.23598434,9.4081554,0.0,0,18.0,1.4012985e-45,0.98679036,1.1215415,17.999166,171.94942,-11.482745
168.7608,0.24799448,9.4109955,0.0,0,18.0,1.4012985e-45,0.98719919,1.1732577,17.99999,167.69879,-11.482784
169.8608,0.24785019,9.4128733,0.0,0,18.0,1.4012985e-45,0.98763376,1.1717563,18.000488,163.74475,-11.48315
170.9608,0.24926406,9.4158611,0.0,0,18.0,1.4012985e-45,0.98815399,1.1862707,17.999516,159.82103,-11.483351
172.0608,0.24124208,9.4184198,0.0,0,18.0,1.4012985e-45,0.9885605,1.1391785,18.001007,156.03392,-11.483283
173.1608,0.24466206,9.4204044,0.0,0,18.0,1.4012985e-45,0.98891246,1.1522093,17.999226,152.07318,-11.482795
174.2608,0.2496625,9.4229126,0.0,0,18.0,1.4012985e-45,0.9893778,1.1840065,17.999577,148.35591,-11.482882
175.3608,0.23772086,9.4248676,0.0,0,18.0,1.4012985e-45,0.98982447,1.1259102,18.000605,144.55928,-11.482571
176.4608,0.23692298,9.4278145,0.0,0,18.0,1.4012985e-45,0.99020755,1.1159532,18.000719,141.29228,-11.482705
177.5608,0.23604029,9.4295435,0.0,0,18.0,1.4012985e-45,0.99059004,1.1158458,18.000257,137.75441,-11.482285
178.6608,0.23073107,9.4316826,0.0,0,18.0,1.4012985e-45,0.99103111,1.0871128,18.000946,134.57423,-11.482041
179.7608,0.23330304,9.4337921,0.0,0,18.0,1.4012985e-45,0.9912892,1.1022763,17.999712,131.61359,-11.482207
180.8608,0.23209214,9.4359665,0.0,0,18.0,1.4012985e-45,0.99176645,1.0996855,17.998554,128.78842,-11.481803
181.9608,0.23181351,9.4374676,0.0,0,18.0,1.4012985e-45,0.99198526,1.0994502,17.999678,126.08743,-11.482277
183.0608,0.23990895,9.4397392,0.0,0,18.0,1.4012985e-45,0.99239767,1.1316383,18.000307,123.37444,-11.482417
184.1608,0.25499254,9.4419556,0.0,0,18.0,1.4012985e-45,0.99280608,1.2004308,18.000938,120.47297,-11.482113
185.2608,0.2455454,9.4436054,0.0,0,18.0,1.4012985e-45,0.99306375,1.1609195,17.999708,117.70238,-11.482077
186.3608,0.23270495,9.4453678,0.0,0,18.0,1.4012985e-45,0.99349207,1.1007957,18.000801,114.88037,-11.482568
187.4608,0.25519884,9.4474545,0.0,0,18.0,1.4012985e-45,0.99371636,1.2002928,17.999969,112.3658,-11.482488
188.5608,0.24263541,9.449338,0.0,0,18.0,1.4012985e-45,0.99414569,1.1467234,18.000031,110.06108,-11.482489
189.6608,0.23120007,9.4507494,0.0,0,18.0,1.4012985e-45,0.99445939,1.0883143,18.00038,107.61018,-11.482054
190.7608,0.23382166,9.4521399,0.0,0,18.0,1.4012985e-45,0.99457169,1.1027955,17.99984,105.15148,-11.482236
191.8608,0.24868108,9.4540253,0.0,0,18.0,1.4012985e-45,0.99502313,1.1700256,17.999525,102.78793,-11.482147
192.9608,0.23814099,9.4553623,0.0,0,18.0,1.4012985e-45,0.99521446,1.1222817,17.999292,100.31443,-11.482604
194.0608,0.25226995,9.4566135,0.0,0,18.0,1.4012985e-45,0.99547333,1.1902459,18.00004,98.022835,-11.482634
195.1608,0.2308978,9.4587717,0.0,0,18.0,1.4012985e-45,0.99577129,1.0852711,18.000122,95.884445,-11.482324
196.2608,0.2554566,9.4596987,0.0,0,18.0,1.4012985e-45,0.99601841,1.204548,17.999897,94.023026,-11.48303
197.3608,0.23325966,9.4607658,0.0,0,18.0,1.4012985e-45,0.99625462,1.0991967,17.999474,91.847511,-11.482745
198.4608,0.24781056,9.4628696,0.0,0,18.0,1.4012985e-45,0.99651361,1.1631286,17.99987,89.868279,-11.482965
199.5608,0.24585757,9.4633818,0.0,0,18.0,1.4012985e-45,0.99672818,1.1541959,18.000618,87.966591,-11.482848
200.6608,0.24083191,9.4651642,0.0,0,18.0,1.4012985e-45,0.99699897,1.1334924,18.000086,86.245697,-11.482814
201.7608,0.24055159,9.4666843,0.0,0,18.0,1.4012985e-45,0.9972446,1.1321906,17.999708,84.501617,-11.482749
202.8608,0.24271338,9.4681435,0.0,0,18.0,1.4012985e-45,0.99748087,1.1399028,17.99939,82.929108,-11.482667
203.9608,0.24150893,9.4691591,0.0,0,18.0,1.4012985e-45,0.99771577,1.1400994,18.00016,81.29821,-11.482617
205.0608,0.23074941,9.4701061,0.0,0,18.0,1.4012985e-45,0.99795735,1.08705,17.999731,79.745598,-11.482701
205.8608,0.2340537,9.4711266,0.0,0,18.0,1.4012985e-45,0.99802572,1.0953627,18.000441,78.657875,-11.482943