File: examples/dan-msc-case-studies/CS3/data/01 raw data/baron_test_143.csv
Time(sec),Force(kN),Jaw(mm),PowAngle(deg),Power(W),Pram,PTemp,Strain,Stress(MPa),Stroke(mm),TC1(C),wedge(mm)
0.0,1.2001189,0.33919984,0.0,0,10.594783,0.0013895386,0.022877313,14.953712,10.594597,27.165365,-9.1087971
2.1,1.099762,-0.0010292701,0.0,0,10.594783,6.2159014,-8.3245955e-05,13.993934,10.595516,27.050013,-9.4777584
4.2,1.0697441,-0.00087573304,0.0,0,10.594783,12.515903,-5.640326e-05,13.635253,10.594501,27.096302,-9.4749479
6.3,1.0379418,-0.0006413653,0.0,0,10.594783,18.815908,-6.2134954e-05,13.202409,10.59432,27.019533,-9.4712372
8.4,1.0274825,-0.000939511,0.0,0,10.594783,25.115904,-5.1663264e-05,13.082577,10.594954,27.017708,-9.4673882
10.5,1.0162804,0.00011405412,24.655565,0,10.594783,31.415911,-4.2396391e-06,12.944336,10.59523,26.918053,-9.4644127
12.6,1.0263029,-0.0011137233,43.468914,0,10.594783,37.715912,-5.9227437e-05,13.067486,10.594576,28.192513,-9.4611216
14.7,1.0477172,-0.0056042811,53.064526,0,10.594783,44.015919,-0.00035942154,13.347931,10.595057,32.350452,-9.4576359
16.8,1.0736358,-0.013787671,57.961506,0,10.594783,50.315918,-0.00092022715,13.690546,10.594332,39.839497,-9.4541397
18.9,1.0954958,-0.023629174,59.600826,0,10.594783,56.615913,-0.0015692248,13.960442,10.594388,50.02253,-9.4505243
21.0,1.1367861,-0.033223018,58.717606,0,10.594783,62.915909,-0.0022276544,14.528274,10.594177,61.425964,-9.4473324
23.1,1.1275923,-0.040529802,56.130074,0,10.594783,69.215919,-0.0026895432,14.413218,10.594579,71.922707,-9.4438305
25.2,1.1404887,-0.046539702,52.287426,0,10.594783,75.515907,-0.003114864,14.557557,10.595366,80.820908,-9.4404488
27.3,1.1302379,-0.050963435,48.384388,0,10.594783,81.815918,-0.0033707926,14.451012,10.594038,87.423607,-9.4369564
29.4,1.1092308,-0.053533193,46.109665,0,10.594783,88.115944,-0.0035626332,14.180207,10.594714,92.048279,-9.4332438
31.5,1.0988832,-0.055753093,47.333599,0,10.594783,94.415924,-0.0037003136,14.044343,10.59404,95.177597,-9.4296741
33.6,1.1010822,-0.058771692,50.614479,0,10.594783,100.71592,-0.0039010672,14.081377,10.594646,98.350754,-9.4261971
35.7,1.1144133,-0.063424632,53.975159,0,10.594783,107.01592,-0.0042328574,14.248763,10.594515,102.64828,-9.42311
37.8,1.1370944,-0.069067702,56.711124,0,10.594783,113.31593,-0.0045920024,14.545341,10.595077,108.31849,-9.4195604
39.9,1.1505424,-0.076162733,58.587685,0,10.594783,119.61594,-0.0050820969,14.737559,10.594452,115.32995,-9.4166374
42.0,1.153556,-0.083838716,59.106438,0,10.594783,125.91593,-0.0055722529,14.771145,10.59386,123.25884,-9.4124575
44.1,1.1661215,-0.090781793,58.853767,0,10.594783,132.21593,-0.0060474784,14.938763,10.595098,131.55833,-9.4089489
46.2,1.162186,-0.097962171,57.810081,0,10.594783,138.51591,-0.0064883581,14.89768,10.594882,139.48035,-9.4052372
48.3,1.1632955,-0.10382091,56.919025,0,10.594783,144.81595,-0.0069194594,14.896706,10.595157,146.38579,-9.4020262
50.4,1.1649449,-0.1093534,56.640461,0,10.594783,151.11594,-0.0072434507,14.946146,10.595245,152.1304,-9.3987045
52.5,1.1588367,-0.11421561,56.986084,0,10.594783,157.41594,-0.0075852084,14.863353,10.594643,157.12567,-9.3956223
54.6,1.1620238,-0.1194206,58.073635,0,10.594783,163.71593,-0.0079186894,14.89795,10.594259,162.32936,-9.3921041
56.7,1.1662532,-0.12510864,59.103828,0,10.594783,170.01593,-0.0082953172,14.980988,10.594703,168.16414,-9.3887777
58.8,1.1655084,-0.13085736,59.600613,0,10.594783,176.31595,-0.0086956825,14.97181,10.594964,174.83116,-9.3850555
60.9,1.174292,-0.13860495,59.842525,0,10.594783,182.61597,-0.0091923019,15.084251,10.594667,181.50441,-9.381115
63.0,1.1717229,-0.14394702,60.084225,0,10.594783,188.91594,-0.0095704971,15.079079,10.594147,188.09778,-9.3780937
65.1,1.1659003,-0.15116744,60.314934,0,10.594783,195.21594,-0.010018475,14.984906,10.594678,194.47636,-9.3747883
67.2,1.1697881,-0.15743655,60.824596,0,10.594783,201.51595,-0.010460933,15.051089,10.595193,200.45776,-9.3714676
69.3,1.166526,-0.16331317,61.330597,0,10.594783,207.81596,-0.01080881,15.023467,10.594737,206.70897,-9.3679562
71.4,1.176473,-0.17025632,61.688229,0,10.594783,214.11597,-0.01129705,15.134176,10.595036,213.17525,-9.364912
73.5,1.1748829,-0.17715953,61.907703,0,10.594783,220.41595,-0.011715263,15.138117,10.594007,219.68979,-9.3616695
75.6,1.1678935,-0.18316163,61.959358,0,10.594783,226.71594,-0.012137716,15.049029,10.594571,226.1893,-9.3581095
77.7,1.1617237,-0.18997376,62.116692,0,10.594783,233.01596,-0.01258307,14.966836,10.595072,232.52667,-9.3543854
79.8,1.1695688,-0.19626237,62.316883,0,10.594783,239.31598,-0.012999547,15.095417,10.594976,238.98689,-9.3507204
81.9,1.1652122,-0.20201333,62.753899,0,10.594783,245.61597,-0.013380291,15.042591,10.593862,244.46613,-9.3469429
84.0,1.1724668,-0.20865963,63.577873,0,10.594783,251.91595,-0.013810074,15.130556,10.59481,250.05708,-9.3437233
86.1,1.1779308,-0.21586169,64.324921,0,10.594783,258.21622,-0.014302609,15.224901,10.595248,256.32184,-9.3405066
88.2,1.1709489,-0.22357038,64.740585,0,10.594783,264.51593,-0.014801967,15.128862,10.59445,262.94507,-9.3371897
90.3,1.1815852,-0.23099993,64.742432,0,10.594783,270.81601,-0.015302896,15.268646,10.595081,270.00491,-9.3339624
92.4,1.1796274,-0.23934577,64.742439,0,10.594783,277.116,-0.015820518,15.254836,10.595229,276.8075,-9.3306007
94.5,1.1722716,-0.24616414,64.566353,0,10.594783,283.41592,-0.016290992,15.166942,10.594117,283.54953,-9.3274498
96.6,1.1737366,-0.25297102,64.359558,0,10.594783,289.71597,-0.016706958,15.182221,10.59494,290.13464,-9.3243856
98.7,1.1668576,-0.2594572,64.172897,0,10.594783,296.01599,-0.017159374,15.134086,10.594723,296.52057,-9.3208847
100.8,1.1658723,-0.26621288,64.17115,0,10.594783,302.31601,-0.017575826,15.102264,10.594972,302.58728,-9.3172579
102.9,1.1769933,-0.27177015,64.357895,0,10.594783,308.616,-0.017956456,15.256892,10.594631,308.49146,-9.313448
105.0,1.1783623,-0.27844429,64.742432,0,10.594783,314.91595,-0.018386476,15.295861,10.594771,314.13126,-9.3100348
107.1,1.1843338,-0.28679332,65.302116,0,10.594783,321.21597,-0.018937534,15.358167,10.594135,319.95963,-9.3063164
109.2,1.1833827,-0.29352802,65.665276,0,10.594783,327.51599,-0.019367626,15.352322,10.594481,326.21552,-9.303174
111.3,1.1770501,-0.29977304,66.016838,0,10.594783,333.81601,-0.019776989,15.292184,10.594533,332.63327,-9.2994175
113.4,1.1724066,-0.3083815,66.364395,0,10.594783,340.116,-0.020352438,15.241281,10.594725,338.96942,-9.2960339
115.5,1.1821008,-0.3158105,66.699173,0,10.594783,346.41595,-0.020825112,15.356631,10.593677,345.20596,-9.2926397
117.6,1.1768441,-0.32345787,66.884758,0,10.594783,352.716,-0.021348167,15.31324,10.594262,351.6243,-9.2891111
119.7,1.1775775,-0.33101285,67.200951,0,10.594783,359.01602,-0.021823352,15.318382,10.593984,358.01639,-9.2855749
121.8,1.1790792,-0.33884993,67.390129,0,10.594783,365.31601,-0.022356946,15.350197,10.594428,364.49515,-9.2823677
123.9,1.1785676,-0.3470768,67.554924,0,10.594783,371.616,-0.022875005,15.370139,10.594757,370.85583,-9.2790337
126.0,1.1773876,-0.35608062,67.554939,0,10.594783,377.91599,-0.023477243,15.341646,10.595595,377.57397,-9.2756681
128.1,1.1747676,-0.36377561,67.287689,0,10.594783,384.216,-0.023955975,15.331477,10.594113,384.69693,-9.2722797
130.2,1.1748263,-0.37081012,67.049568,0,10.594783,390.51602,-0.024433643,15.328102,10.594087,391.26495,-9.2686281
132.3,1.1794525,-0.37810731,66.887459,0,10.594783,396.81601,-0.024878684,15.383608,10.595025,397.31482,-9.2655916
134.4,1.182502,-0.38399965,65.694138,0,10.594783,399.99893,-0.02529273,15.469381,10.594209,403.17487,-9.2635002
136.5,1.1742982,-0.38753322,61.760593,0,10.594783,399.99893,-0.025489854,15.328692,10.59487,408.22458,-9.2635155
138.6,1.1416124,-0.38710126,56.474495,0,10.594783,399.99893,-0.025494764,14.899511,10.594801,410.79926,-9.2636395
140.7,1.1026832,-0.383838,51.040596,0,10.594783,399.99893,-0.025256976,14.400828,10.594479,410.27902,-9.2636318
142.8,1.0585982,-0.37733257,48.383793,0,10.594783,399.99893,-0.024854278,13.808948,10.594291,406.6059,-9.2637577
144.9,1.0415112,-0.37120014,49.850868,0,10.594783,399.99893,-0.02442907,13.587043,10.595233,401.42468,-9.2637615
147.0,1.0288301,-0.36763084,53.973434,0,10.594783,399.99893,-0.02420962,13.425921,10.594292,396.50412,-9.2635517
149.1,1.0558342,-0.36751136,58.330212,0,10.594783,399.99893,-0.024191458,13.759813,10.594064,393.47232,-9.2636395
151.2,1.0935709,-0.3693389,61.237305,0,10.594783,399.99893,-0.024328088,14.264678,10.59522,393.09412,-9.2639828
153.3,1.1202896,-0.37514961,62.753899,0,10.594783,399.99893,-0.024700129,14.615893,10.59471,394.73547,-9.2638597
155.4,1.1445091,-0.38070241,62.754814,0,10.594783,399.99893,-0.025052167,14.934209,10.594513,397.75003,-9.2637758
157.5,1.1559478,-0.3841683,61.513977,0,10.594783,399.99893,-0.025281429,15.102068,10.594577,401.104,-9.2636261
159.6,1.1610816,-0.38627446,59.348339,0,10.594783,399.99893,-0.025417596,15.173323,10.594084,403.86746,-9.2640228
161.7,1.1378596,-0.38624439,56.431374,0,10.594783,399.99893,-0.025423499,14.852729,10.59363,405.33286,-9.2636862
163.8,1.1319767,-0.38559487,53.976391,0,10.594783,399.99893,-0.025374671,14.784999,10.594155,404.99298,-9.2646751
165.9,1.0840251,-0.38278997,52.976078,0,10.594783,399.99893,-0.025186921,14.164178,10.593796,403.11179,-9.2630892
168.0,1.0660044,-0.38036376,53.31665,0,10.594783,399.99893,-0.025043506,13.89645,10.594554,400.77014,-9.263279
170.1,1.0647348,-0.37884352,55.224152,0,10.594783,399.99893,-0.024929198,13.895242,10.594302,398.36963,-9.2646599
172.2,1.06098,-0.3783713,57.355812,0,10.594783,399.99893,-0.024913967,13.847521,10.595058,396.71692,-9.2642403
174.3,1.0917656,-0.38096255,59.106312,0,10.594783,399.99893,-0.025060063,14.244222,10.595136,396.20663,-9.2634249
176.4,1.1113049,-0.38230136,60.27898,0,10.594783,399.99893,-0.025169475,14.516811,10.59439,396.93515,-9.263773
178.4633,1.12384,-0.0093575818,60.391548,0,10.594783,399.99893,-0.0006288485,14.322619,10.595048,398.41681,-9.2640562
178.6172,1.1649141,0.011281557,32.866184,0,10.5948,1.8726595e-23,0.00098568446,14.798896,10.595433,398.61584,-9.2644663
178.6214,1.1362764,0.010268149,7.5844779,0,10.5948,0.0,0.00056525005,14.451992,10.596046,398.61584,-9.2642145
178.6256,1.1466891,0.011756617,0.0,0,10.5948,0.0,0.00070374832,14.535091,10.594411,398.56287,-9.2646694
178.6298,1.1526873,0.0093191499,0.0,0,10.5948,0.0,0.00074510206,14.673962,10.59718,398.48715,-9.2634649
178.634,1.1424962,0.01254818,0.0,0,10.5948,0.0,0.00069313601,14.583867,10.597589,398.45111,-9.2633915
178.6382,1.1396878,0.014225277,0.0,0,10.5948,0.0,0.00083536224,14.536892,10.593647,398.50156,-9.2652607
178.6424,1.1166153,0.0087094828,0.0,0,10.5948,0.0,0.00082057237,14.151542,10.594847,398.55203,-9.2647438
178.6466,1.1095542,0.0095210252,0.0,0,10.5948,0.0,0.00047690573,14.174585,10.594364,398.60248,-9.266202
178.6508,1.1103958,0.010684676,0.0,0,10.5948,0.0,0.00072286185,14.080654,10.595444,398.65295,-9.2647867
178.655,1.1088885,0.0090918271,0.0,0,10.5948,0.0,0.0007353407,14.122752,10.594908,398.67603,-9.2633371
178.6592,1.1268815,0.01463203,0.0,0,10.5948,0.0,0.0007529236,14.28324,10.594907,398.67603,-9.2649069
178.6634,1.1295155,0.012605485,0.0,0,10.5948,0.0,0.00089057966,14.430149,10.594213,398.67206,-9.263814
178.6676,1.1063166,0.008118609,0.0,0,10.533863,0.0,0.00067563896,14.112653,10.59236,398.64685,-9.2641745
178.6718,1.0974792,0.012558249,0.0,0,10.470864,0.0,0.00070309814,14.058545,10.591775,398.62161,-9.2648373
178.676,1.0942717,0.0095628435,0.0,0,10.407864,0.0,0.00065605063,13.833537,10.557563,398.61584,-9.2647943
178.6802,1.0872101,0.010373713,0.0,0,10.344864,0.0,0.00077359955,13.815691,10.482746,398.61584,-9.2653894
178.6844,1.0961416,0.015413748,0.0,0,10.281863,0.0,0.00081057433,13.951714,10.374614,398.6207,-9.264267
178.6886,1.1012093,0.011162821,0.0,0,10.218863,0.0,0.00094106718,14.004854,10.291503,398.63333,-9.2637281
178.6928,1.1023085,0.0097104684,0.0,0,10.155864,0.0,0.00067652599,13.939907,10.230042,398.64594,-9.2644825
178.697,1.1100219,0.010921607,0.0,0,10.092864,0.0,0.00067028805,14.217783,10.177637,398.67117,-9.2635822
178.7012,1.0997393,0.0099619422,0.0,0,10.029863,0.0,0.00082791777,14.015662,10.125302,398.69638,-9.2654629
178.7054,1.5118753,0.012247834,0.0,0,9.9668636,0.0,0.00080317922,19.047283,10.067596,399.52765,-9.2656765
178.7096,3.6267598,0.036236502,0.0,0,9.9038639,0.0,0.0022136855,45.880154,10.013141,400.86505,-9.261919
178.7138,4.2265735,0.095873177,0.0,0,9.8408632,0.0,0.0065215854,53.350334,9.9436235,402.40433,-9.262064
178.718,4.5055866,0.16328171,0.0,0,9.7778635,0.0,0.010875382,56.800709,9.8682966,404.62488,-9.262187
178.7222,4.6337609,0.23076268,0.0,0,9.7148628,0.0,0.01538872,58.100937,9.8015957,406.84546,-9.2612066
178.7264,4.6904192,0.29286039,0.0,0,9.6518641,0.0,0.019900803,58.617722,9.7363586,408.24719,-9.2617407
178.7306,4.7579741,0.35574868,0.0,0,9.5888634,0.0,0.023849452,59.151028,9.6669788,409.49625,-9.261651
178.7348,4.8012714,0.42080671,0.0,0,9.5258636,0.0,0.028237855,59.403957,9.6048307,410.28391,-9.2603827
178.739,4.8572292,0.47630942,0.0,0,9.4633293,0.0,0.032405794,59.872856,9.5442705,410.52362,-9.2618389
178.7432,4.9047093,0.53516585,0.0,0,9.4018736,0.0,0.036157679,60.282055,9.4820662,410.91806,-9.2613029
178.7474,4.9546294,0.59858477,0.0,0,9.3404198,0.0,0.040659752,60.576958,9.4228153,413.32385,-9.2618742
178.7516,5.0155215,0.66250658,0.0,0,9.278965,0.0,0.045270726,61.068008,9.3576803,415.72961,-9.2623987
178.7558,5.0438113,0.73275054,0.0,0,9.2175112,0.0,0.04978133,61.128624,9.2881136,419.98166,-9.2634592
178.76,5.0178766,0.79563862,0.0,0,9.1560564,0.0,0.054447066,60.489418,9.2281017,425.07993,-9.2624187
178.7642,5.0008416,0.84868419,0.0,0,9.0946016,0.0,0.058470394,60.033112,9.1627541,429.55435,-9.2617474
178.7684,5.0602403,0.90812218,0.0,0,9.0331469,0.0,0.062227488,60.537895,9.1065617,432.57321,-9.2635632
178.7726,5.0932112,0.96505272,0.0,0,8.971693,0.0,0.066539951,60.737114,9.046669,435.59207,-9.2630882
178.7768,5.1791773,1.028592,0.0,0,8.9102392,0.0,0.071022205,61.345539,8.9815521,437.20697,-9.2613993
178.781,5.2045894,1.0967788,0.0,0,8.8487844,0.0,0.075586669,61.423611,8.9129639,438.69028,-9.2630787
178.7852,5.1965113,1.1556927,0.0,0,8.7873297,0.0,0.080263689,61.082237,8.849164,440.16016,-9.2631693
178.7894,5.1967454,1.2116946,0.0,0,8.7270651,0.0,0.084272966,60.856178,8.7906656,441.61813,-9.2611256
178.7936,5.2256088,1.2757049,0.0,0,8.6686182,0.0,0.088635534,60.952553,8.7317038,442.97726,-9.2633629
178.7978,5.2291436,1.3335147,0.0,0,8.6101713,0.0,0.093181677,60.598392,8.6679535,443.74332,-9.2634506
178.802,5.2414985,1.3888764,0.0,0,8.5517235,0.0,0.097203843,60.538288,8.608223,444.5094,-9.2623501
178.8062,5.2984829,1.4500824,0.0,0,8.4932766,0.0,0.10125463,60.810375,8.5548811,444.81897,-9.2626467
178.8104,5.3526478,1.5061462,0.0,0,8.4348297,0.0,0.10604574,61.371197,8.4934464,444.98212,-9.2625771
178.8146,5.3693089,1.5619656,0.0,0,8.3763819,0.0,0.10991187,61.243656,8.4309654,445.14529,-9.2614832
178.8188,5.3566952,1.6223073,0.0,0,8.317935,0.0,0.11428503,60.995251,8.3737841,445.30844,-9.263133
178.823,5.366796,1.6763601,0.0,0,8.2594881,0.0,0.11867975,60.715603,8.317503,445.47162,-9.2625103
178.8272,5.410398,1.7365241,0.0,0,8.2010412,0.0,0.12287823,60.881416,8.2620392,446.0925,-9.2631159
178.8314,5.4588079,1.7984253,0.0,0,8.1425943,0.0,0.12751451,61.185959,8.1997986,446.72006,-9.2616758
178.8356,5.4935031,1.8553427,0.0,0,8.0841465,0.0,0.13230504,61.267719,8.1417465,447.30994,-9.2625637
178.8398,5.5318279,1.912257,0.0,0,8.0270939,0.0,0.13620526,61.452408,8.0771694,447.87473,-9.2607298
178.844,5.5433626,1.9753455,0.0,0,7.9714851,0.0,0.14104554,61.289864,8.0162945,448.39917,-9.2617159
178.8482,5.5173874,2.0262163,0.0,0,7.9158773,0.0,0.1453632,60.798027,7.9641867,448.77567,-9.2621403
178.8524,5.5285988,2.085367,0.0,0,7.8602695,0.0,0.14941461,60.624756,7.904366,449.15219,-9.2630129
178.8566,5.5567689,2.14131,0.0,0,7.8046613,0.0,0.15388156,60.657867,7.8485761,449.28952,-9.2607851
178.8608,5.5919347,2.192956,0.0,0,7.7490535,0.0,0.15834931,60.778034,7.7928853,449.37738,-9.2632236
178.865,5.6407709,2.2494555,0.0,0,7.6934457,0.0,0.1622491,61.102833,7.7343016,449.44858,-9.2622299
178.8692,5.6653557,2.3067565,0.0,0,7.6378374,0.0,0.16693486,60.975971,7.6777568,449.49878,-9.262146
178.8734,5.677228,2.3596015,0.0,0,7.5822296,0.0,0.17134063,60.949787,7.624495,449.48587,-9.2618876
178.8776,5.7331233,2.4201956,0.0,0,7.5266213,0.0,0.17558022,61.219875,7.5679903,448.43161,-9.260829
178.8818,5.7176638,2.4752183,0.0,0,7.4710135,0.0,0.18039064,60.810745,7.5097079,447.37735,-9.2621021
178.886,5.7337613,2.5241408,0.0,0,7.4154053,0.0,0.18440577,60.731529,7.4532123,446.12082,-9.2618017
178.8902,5.7563605,2.5801606,0.0,0,7.361393,0.0,0.18844767,60.717644,7.3994594,444.76529,-9.2637587
178.8944,5.8039637,2.6319888,0.0,0,7.308507,0.0,0.19300282,60.868507,7.3436871,443.75403,-9.2621422
178.8986,5.8624783,2.6900256,0.0,0,7.2556205,0.0,0.19771653,61.278656,7.2887354,443.60342,-9.2617521
178.9028,5.8544207,2.7495115,0.0,0,7.202734,0.0,0.20206763,60.876514,7.2343063,443.45282,-9.263195
178.907,5.8205824,2.793313,0.0,0,7.1498475,0.0,0.20622976,60.395756,7.1841755,443.73148,-9.2614174
178.9112,5.8644109,2.8436046,0.0,0,7.096961,0.0,0.21010457,60.470608,7.1332483,444.05786,-9.2626953
178.9154,5.9010592,2.8967524,0.0,0,7.044075,0.0,0.21432438,60.665501,7.0788903,444.44873,-9.2607584
178.9196,5.9045739,2.9483564,0.0,0,6.991188,0.0,0.21910915,60.398254,7.0289912,444.90054,-9.261632
178.9238,5.9456491,3.0020545,0.0,0,6.938302,0.0,0.22331333,60.548763,6.9728146,445.35077,-9.2615337
178.928,5.9834132,3.0603054,0.0,0,6.8854156,0.0,0.22780001,60.557327,6.9216075,445.79004,-9.2616796
178.9322,6.0231419,3.1092112,0.0,0,6.8325291,0.0,0.232501,60.727707,6.8632627,446.22934,-9.2618761
178.9364,6.0388904,3.1597793,0.0,0,6.7796426,0.0,0.23639385,60.622711,6.8104787,446.54739,-9.2611284
178.9406,6.0608683,3.2135267,0.0,0,6.728508,0.0,0.24087945,60.61301,6.757,446.82352,-9.2622499
178.9448,6.0936561,3.2658055,0.0,0,6.6781921,0.0,0.2457809,60.731792,6.7031832,447.1579,-9.261878
178.949,6.0696139,3.3192596,0.0,0,6.6278758,0.0,0.2498758,60.191395,6.6542535,447.59717,-9.2615118
178.9532,6.0696249,3.3693449,0.0,0,6.5775599,0.0,0.25416681,59.906212,6.606564,448.03647,-9.2622347
178.9574,6.0984521,3.4123187,0.0,0,6.5272441,0.0,0.2584874,59.969959,6.551219,448.60983,-9.2619591
178.9616,6.1268473,3.4614935,0.0,0,6.4769282,0.0,0.2621184,60.034111,6.5110269,449.18716,-9.2617979
178.9658,6.2090163,3.5126166,0.0,0,6.4266124,0.0,0.26671091,60.557819,6.4535928,449.60275,-9.2624502
178.97,6.2196441,3.5593076,0.0,0,6.376296,0.0,0.27110079,60.425385,6.4031782,449.90399,-9.2622337
178.9742,6.2672772,3.6174679,0.0,0,6.3259802,0.0,0.27563268,60.549835,6.350255,450.2052,-9.2617159
178.9784,6.2708287,3.6707711,0.0,0,6.2756648,0.0,0.28067857,60.349857,6.2972765,450.50644,-9.2600832
178.9826,6.2307372,3.7142766,0.0,0,6.2253485,0.0,0.28478116,59.691124,6.2466922,450.80765,-9.2615767
178.9868,6.2761979,3.7645118,0.0,0,6.1750326,0.0,0.28868374,59.823303,6.1989961,450.68985,-9.2608347
178.991,6.3518214,3.8149977,0.0,0,6.1266279,0.0,0.29362258,60.305431,6.1462221,450.47647,-9.2618732
178.9952,6.3572125,3.8656762,0.0,0,6.0787735,0.0,0.29816839,60.052902,6.0985708,448.69101,-9.2615633
178.9994,6.3576751,3.9201512,0.0,0,6.0309186,0.0,0.30238619,59.793461,6.0501499,444.80942,-9.2615452
179.0036,6.3572035,3.9620333,0.0,0,5.9830642,0.0,0.30686477,59.55341,6.0024714,440.94397,-9.26229
179.0078,6.3675389,4.0043116,0.0,0,5.9352088,0.0,0.31060645,59.458244,5.9588342,437.43884,-9.2611246
179.012,6.4102859,4.053616,0.0,0,5.8873544,0.0,0.31468964,59.564468,5.9087644,433.93372,-9.2609749
179.0162,6.4686217,4.1033483,0.0,0,5.8394995,0.0,0.31978551,59.793915,5.8608575,432.47589,-9.2618608
179.0204,6.4677663,4.1493678,0.0,0,5.7916446,0.0,0.32388055,59.512272,5.808208,432.08621,-9.2625179
179.0246,6.539957,4.2048278,0.0,0,5.7437897,0.0,0.32849067,59.959644,5.7590241,431.85349,-9.2616673
179.0288,6.5444202,4.2489295,0.0,0,5.6959348,0.0,0.33334202,59.664684,5.7103949,432.04202,-9.2620525
179.033,6.5454974,4.291863,0.0,0,5.6480803,0.0,0.33703029,59.487606,5.663867,432.23059,-9.2614241
179.0372,6.5620356,4.3397818,0.0,0,5.600225,0.0,0.3412255,59.338802,5.6204429,432.98697,-9.2613087
179.0414,6.6134319,4.3844962,0.0,0,5.5544,0.0,0.34605005,59.603516,5.5732908,433.81659,-9.2616177
179.0456,6.6364326,4.4360323,0.0,0,5.5088716,0.0,0.35043153,59.503819,5.5213232,434.96048,-9.2627048
179.0498,6.6189442,4.4868355,0.0,0,5.4633436,0.0,0.35508749,59.079468,5.4765553,436.41864,-9.2630053
179.054,6.6222672,4.5245585,0.0,0,5.4178157,0.0,0.35940281,58.843552,5.4321461,437.82794,-9.2619724
179.0582,6.6960878,4.5698433,0.0,0,5.3722878,0.0,0.3631022,59.307995,5.3840051,438.8587,-9.2615623
179.0624,6.7147112,4.6162477,0.0,0,5.3267598,0.0,0.3676658,59.217373,5.3427205,439.88947,-9.2617941
179.0666,6.7369356,4.6590905,0.0,0,5.2812319,0.0,0.37231901,59.098579,5.2963772,440.00439,-9.2614279
179.0708,6.7719922,4.7068348,0.0,0,5.2357039,0.0,0.37624246,59.19738,5.2523103,439.77814,-9.2607117
179.075,6.7726111,4.7573414,0.0,0,5.1901755,0.0,0.38135582,58.904572,5.204186,439.71133,-9.2621803
179.0792,6.8069367,4.7934427,0.0,0,5.1446476,0.0,0.38540885,58.961399,5.1613898,439.95016,-9.2601919
179.0834,6.8710642,4.8458457,0.0,0,5.0991197,0.0,0.38965911,59.215691,5.1138091,440.189,-9.2615976
179.0876,6.9052405,4.8904853,0.0,0,5.0535922,0.0,0.39461142,59.271484,5.0676475,440.90909,-9.2613869
179.0918,6.9030161,4.9326663,0.0,0,5.0102167,0.0,0.39897373,59.023827,5.0183187,441.65073,-9.2606735
179.096,6.9202724,4.9824238,0.0,0,4.9669147,0.0,0.40328664,58.924824,4.9789891,442.43518,-9.2617531
179.1002,6.964952,5.0248885,0.0,0,4.9236126,0.0,0.40805125,59.00806,4.9321094,443.25174,-9.2616301
179.1044,6.9590259,5.0658674,0.0,0,4.880311,0.0,0.41241029,58.734028,4.8880572,444.0542,-9.2607002
179.1086,6.9367785,5.1110258,0.0,0,4.8370085,0.0,0.41621554,58.284164,4.8483691,444.7948,-9.2622509
179.1128,7.008637,5.1499639,0.0,0,4.7937069,0.0,0.42066509,58.574196,4.8046036,445.5354,-9.2630148
179.117,7.0628495,5.1945868,0.0,0,4.7504048,0.0,0.42525494,58.768295,4.7564545,446.06506,-9.2625971
179.1212,7.1180425,5.2452755,0.0,0,4.7071028,0.0,0.42965692,58.939777,4.7122316,446.54199,-9.2615166
179.1254,7.1370602,5.2859545,0.0,0,4.6638007,0.0,0.43487546,58.829086,4.6699653,446.97214,-9.2610321
179.1296,7.1001139,5.3258128,0.0,0,4.6204991,0.0,0.43860611,58.378624,4.6272364,447.33612,-9.2610407
179.1338,7.1425676,5.3689923,0.0,0,4.5771966,0.0,0.44273388,58.458023,4.5869188,447.70044,-9.260437
179.138,7.1807384,5.4111409,0.0,0,4.5340271,0.0,0.44776258,58.491634,4.5398836,448.07697,-9.2607622
179.1422,7.2115335,5.4552827,0.0,0,4.4928331,0.0,0.45197925,58.441143,4.5025935,448.45349,-9.263051
179.1464,7.2863708,5.5044966,0.0,0,4.4516392,0.0,0.45672065,58.706791,4.4553485,447.52231,-9.2609873
179.1506,7.2668304,5.5399599,0.0,0,4.4104452,0.0,0.4613921,58.364784,4.4148622,445.86465,-9.2601862
179.1548,7.2866082,5.5792871,0.0,0,4.3692517,0.0,0.46502188,58.221905,4.3763223,444.12302,-9.2615166
179.159,7.3367071,5.6226707,0.0,0,4.3280582,0.0,0.46955881,58.446198,4.3310227,442.13873,-9.2603216
179.1632,7.3494482,5.6590905,0.0,0,4.2868648,0.0,0.47416958,58.270645,4.2939019,440.15448,-9.2607193
179.1674,7.3745899,5.7050819,0.0,0,4.2456713,0.0,0.47820458,58.238811,4.2517042,440.01984,-9.2624321
179.1716,7.434021,5.7496691,0.0,0,4.2044773,0.0,0.48302829,58.313389,4.2094603,440.15811,-9.2615643
179.1758,7.4571676,5.7864838,0.0,0,4.1632838,0.0,0.48789567,58.253113,4.1647668,440.59555,-9.2614079
179.18,7.4745431,5.8268023,0.0,0,4.1220903,0.0,0.49140596,58.251858,4.1241984,441.34976,-9.2598801
179.1842,7.5378909,5.8708916,0.0,0,4.0808969,0.0,0.49638867,58.394566,4.0844045,442.10898,-9.2612514
179.1884,7.5974641,5.9064178,0.0,0,4.0400209,0.0,0.5008862,58.650341,4.0456424,442.91299,-9.2612782
179.1926,7.6137724,5.9563713,0.0,0,4.0008435,0.0,0.50544572,58.481724,4.0012794,443.71701,-9.2601824
179.1968,7.6088834,5.9966192,0.0,0,3.9616656,0.0,0.51032484,58.203609,3.9585571,444.45776,-9.2616262
179.201,7.5905523,6.0271249,0.0,0,3.9224882,0.0,0.51441783,57.842049,3.9195557,445.17322,-9.2614012
179.2052,7.6088223,6.0709262,0.0,0,3.8833106,0.0,0.5181905,57.701591,3.8864038,445.79794,-9.2614498
179.2094,7.7054858,6.1060352,0.0,0,3.8441329,0.0,0.52283537,58.133881,3.8489923,446.23721,-9.2608891
179.2136,7.7975225,6.1475267,0.0,0,3.8049555,0.0,0.52756393,58.533367,3.8107388,446.67648,-9.261282
179.2178,7.8497734,6.1942143,0.0,0,3.7657778,0.0,0.53190958,58.679207,3.7657077,446.87909,-9.2607298
179.222,7.8495579,6.2311659,0.0,0,3.7266002,0.0,0.53703272,58.438675,3.7260354,447.06735,-9.2610474
179.2262,7.8192658,6.265687,0.0,0,3.6874225,0.0,0.54095477,58.016285,3.6899443,447.41644,-9.2606115
179.2304,7.8171358,6.3051138,0.0,0,3.6482451,0.0,0.54483336,57.719185,3.6518257,447.89334,-9.2614956
179.2346,7.91956,6.3421364,0.0,0,3.6090674,0.0,0.5497548,58.155605,3.616292,448.43051,-9.2603331
179.2388,8.0293713,6.3818784,0.0,0,3.5703723,0.0,0.5542227,58.733288,3.570684,449.25885,-9.2607136
179.243,8.0279903,6.4314065,0.0,0,3.5331016,0.0,0.55924684,58.35815,3.5330441,450.08722,-9.2612953
179.2472,8.0325651,6.4635539,0.0,0,3.4958305,0.0,0.56422263,58.146477,3.4915307,450.88599,-9.2609339
179.2514,8.0421057,6.4976387,0.0,0,3.4585598,0.0,0.56761396,58.092972,3.4577315,451.6767,-9.2602911
179.2556,8.1025438,6.5365086,0.0,0,3.4212892,0.0,0.57190651,58.249615,3.4197602,452.34692,-9.261344
179.2598,8.1599388,6.5720124,0.0,0,3.3840184,0.0,0.57704276,58.319027,3.3844812,452.83636,-9.2616072
179.264,8.1543608,6.6122274,0.0,0,3.3467472,0.0,0.58102846,58.018353,3.3461485,453.32153,-9.2608356
179.2682,8.1537819,6.653079,0.0,0,3.3094764,0.0,0.58553523,57.800888,3.3094733,453.5098,-9.2619267
179.2724,8.271142,6.6863317,0.0,0,3.2722056,0.0,0.5907591,58.280537,3.2693257,453.69809,-9.2611275
179.2766,8.3463383,6.7235122,0.0,0,3.234935,0.0,0.59439212,58.613136,3.2326393,453.69702,-9.2606735
179.2808,8.3832798,6.7653642,0.0,0,3.1976643,0.0,0.59948355,58.565678,3.1939843,453.58405,-9.2603989
179.285,8.4222298,6.7972207,0.0,0,3.1603935,0.0,0.6040526,58.628105,3.1564541,453.52597,-9.2608833
179.2892,8.4314537,6.838975,0.0,0,3.1237545,0.0,0.60811758,58.428333,3.1220069,453.63892,-9.2617598
179.2934,8.4658785,6.8793721,0.0,0,3.0882978,0.0,0.61343455,58.365341,3.0863285,453.75186,-9.2611456
179.2976,8.4950943,6.9086895,0.0,0,3.0528414,0.0,0.6179415,58.30267,3.0491402,453.90787,-9.2601328
179.3018,8.5219584,6.9447837,0.0,0,3.017385,0.0,0.6211822,58.30761,3.0122249,454.07101,-9.2616682
179.306,8.5767975,6.9817934,0.0,0,2.9819286,0.0,0.62633967,58.341537,2.9784544,454.12177,-9.2603254
179.3102,8.6153793,7.011961,0.0,0,2.9464724,0.0,0.63052988,58.379566,2.9402373,454.04645,-9.2609348
179.3144,8.6448898,7.0543203,0.0,0,2.9110157,0.0,0.63472229,58.333538,2.9089322,453.95285,-9.2617512
179.3186,8.671545,7.0860529,0.0,0,2.8755593,0.0,0.63947839,58.263554,2.8744013,453.66418,-9.2601118
179.3228,8.7709961,7.1149874,0.0,0,2.8401029,0.0,0.6435827,58.70356,2.8422313,453.37555,-9.2606182
179.327,8.8759708,7.1595116,0.0,0,2.8046467,0.0,0.64811301,59.117794,2.8035471,452.91116,-9.2610159
179.3312,8.8996544,7.1938581,0.0,0,2.7691901,0.0,0.65338302,58.988499,2.7660427,452.37146,-9.2606688
179.3354,8.9161816,7.2295589,0.0,0,2.7337339,0.0,0.65793288,58.761673,2.73244,451.79547,-9.2620888
179.3396,8.9626923,7.2715712,0.0,0,2.6990449,0.0,0.66229624,58.851002,2.6976871,451.1402,-9.2602148
179.3438,9.0188732,7.3028231,0.0,0,2.665319,0.0,0.66767246,58.838966,2.6618378,450.41806,-9.2599669
179.348,9.0945578,7.3331504,0.0,0,2.631593,0.0,0.67132056,59.207603,2.6259356,449.36166,-9.2614346
179.3522,9.1317205,7.3728771,0.0,0,2.5978668,0.0,0.67572951,59.184231,2.589627,448.3053,-9.2594767
179.3564,9.1280794,7.4023585,0.0,0,2.5641408,0.0,0.68069834,58.792034,2.553216,447.44653,-9.2598953
179.3606,9.1133318,7.4377065,0.0,0,2.5304148,0.0,0.68481886,58.508068,2.5251532,446.64169,-9.2600126
179.3648,9.1757574,7.4763436,0.0,0,2.4966888,0.0,0.68912232,58.646313,2.4909246,446.28476,-9.2606535
179.369,9.2402964,7.5027103,0.0,0,2.4629629,0.0,0.69417948,58.796921,2.4597991,446.58658,-9.2616606
179.3732,9.3791828,7.5330667,0.0,0,2.4292369,0.0,0.69744706,59.409882,2.4228346,446.89468,-9.260623
179.3774,9.4607677,7.5727825,0.0,0,2.3955109,0.0,0.70238167,59.684357,2.3909073,447.4606,-9.2603445
179.3816,9.530509,7.6035933,0.0,0,2.3617849,0.0,0.70764619,59.832603,2.3552046,448.02652,-9.260355
179.3858,9.5580091,7.6439023,0.0,0,2.3280587,0.0,0.71196485,59.729317,2.3213897,448.03461,-9.2608118
179.39,9.5162954,7.6819248,0.0,0,2.2952197,0.0,0.71720642,59.1581,2.2894115,447.73279,-9.261879
179.3942,9.6013498,7.7042108,0.0,0,2.26314,0.0,0.72153729,59.400089,2.2554448,447.36838,-9.2618732
179.3984,9.6230927,7.7396879,0.0,0,2.2310605,0.0,0.72503042,59.348263,2.2245376,446.82764,-9.261096
179.4026,9.6351786,7.7717481,0.0,0,2.198981,0.0,0.72988772,59.100304,2.1935384,446.2869,-9.261446
179.4068,9.7318182,7.7966371,0.0,0,2.1669014,0.0,0.73407513,59.491879,2.1628058,446.42194,-9.2596645
179.411,9.8080683,7.8322306,0.0,0,2.1348217,0.0,0.73770124,59.743683,2.1289074,446.64828,-9.2600527
179.4152,9.8966455,7.8678517,0.0,0,2.102742,0.0,0.74337643,59.962982,2.1014981,446.98154,-9.2606106
179.4194,10.011752,7.8971891,0.0,0,2.0706627,0.0,0.74821115,60.326469,2.0656691,447.42169,-9.2603397
179.4236,9.9986601,7.9319258,0.0,0,2.038583,0.0,0.75184906,60.029926,2.0316341,447.83789,-9.2619581
179.4278,10.088997,7.9661446,0.0,0,2.0065033,0.0,0.75742745,60.185287,1.9968845,448.07684,-9.2600393
179.432,10.147518,7.9948411,0.0,0,1.9744238,0.0,0.76187396,60.266956,1.9665096,448.31577,-9.2623425
179.4362,10.187493,8.0329771,0.0,0,1.9423442,0.0,0.76593417,60.275932,1.9367511,448.87958,-9.2594395
179.4404,10.255312,8.0621424,0.0,0,1.911255,0.0,0.77140814,60.359432,1.9032294,449.55869,-9.2606258
179.4446,10.301613,8.0886669,0.0,0,1.8807379,0.0,0.77517331,60.419292,1.870334,450.17938,-9.2599525
179.4488,10.264697,8.1214237,0.0,0,1.8502207,0.0,0.77899939,59.999508,1.8460093,450.69501,-9.2610865
179.453,10.346334,8.1481857,0.0,0,1.8197033,0.0,0.78385085,60.109287,1.8137211,451.21063,-9.2615843
179.4572,10.476665,8.1788568,0.0,0,1.7891862,0.0,0.7881788,60.649689,1.7837846,451.272,-9.2604218
179.4614,10.578537,8.2182207,0.0,0,1.758669,0.0,0.79281771,60.948441,1.7513782,451.3223,-9.2595673
179.4656,10.66599,8.2412243,0.0,0,1.7281518,0.0,0.79799318,61.110889,1.721468,451.08066,-9.2606678
179.4698,10.71137,8.2733612,0.0,0,1.6976346,0.0,0.80181986,61.191288,1.6910961,450.6405,-9.2602377
179.474,10.750115,8.3084707,0.0,0,1.6671174,0.0,0.80669075,61.110565,1.6629217,450.11142,-9.2621698
179.4782,10.832353,8.333353,0.0,0,1.6366003,0.0,0.8116219,61.251503,1.6311357,449.25629,-9.2608662
179.4824,10.923781,8.3669281,0.0,0,1.6060829,0.0,0.81572217,61.550827,1.6001817,448.40112,-9.2619438
179.4866,10.982848,8.4048271,0.0,0,1.5755658,0.0,0.82096708,61.506561,1.569607,448.14331,-9.2598944
179.4908,11.083476,8.4259739,0.0,0,1.5461327,0.0,0.82571155,61.770142,1.5375823,448.00497,-9.2615128
179.495,11.159511,8.4622593,0.0,0,1.5171022,0.0,0.830073,61.900894,1.5080034,447.71304,-9.2595711
179.4992,11.210286,8.4908266,0.0,0,1.4880718,0.0,0.83444345,61.915436,1.476658,447.23517,-9.2602272
179.5034,11.214529,8.5180244,0.0,0,1.4590415,0.0,0.83979988,61.662003,1.4462745,446.68716,-9.2612638
179.5076,11.188809,8.5465136,0.0,0,1.430011,0.0,0.84263569,61.381901,1.4201723,445.22775,-9.259963
179.5118,11.236752,8.5778084,0.0,0,1.4009807,0.0,0.84791386,61.24472,1.3947552,443.76831,-9.2604895
179.516,11.359477,8.5947418,0.0,0,1.3719503,0.0,0.85181123,61.7019,1.3653668,443.29056,-9.2604189
179.5202,11.507241,8.6297102,0.0,0,1.3429198,0.0,0.85560739,62.249306,1.338994,443.25281,-9.2597685
179.5244,11.61341,8.65907,0.0,0,1.3138895,0.0,0.86117351,62.456234,1.3066761,443.50723,-9.2597084
179.5286,11.748652,8.6845036,0.0,0,1.2848592,0.0,0.86566615,62.934566,1.2784222,444.4133,-9.2606201
179.5328,11.835404,8.7243233,0.0,0,1.2558287,0.0,0.87031698,63.119259,1.2458861,445.31937,-9.2602415
179.537,11.850183,8.7506084,0.0,0,1.2267983,0.0,0.87568998,62.86311,1.2186007,444.68289,-9.2600384
179.5412,11.938603,8.772809,0.0,0,1.1989383,0.0,0.87975639,63.101574,1.1903439,443.92773,-9.2592573
179.5454,11.985702,8.8072882,0.0,0,1.1713274,0.0,0.88376606,63.080257,1.1616144,443.48282,-9.259903
179.5496,12.038467,8.8302774,0.0,0,1.1437165,0.0,0.88867593,62.950539,1.1328853,443.29419,-9.2607508
179.5538,12.144143,8.8591118,0.0,0,1.1161058,0.0,0.89332533,63.249466,1.1066821,443.19366,-9.2599049
179.558,12.252501,8.8936815,0.0,0,1.0884949,0.0,0.8975333,63.548828,1.0762669,443.53375,-9.2595463
179.5622,12.313407,8.9163265,0.0,0,1.0608841,0.0,0.90311438,63.535236,1.0504494,443.87384,-9.261384
179.5664,12.417157,8.9392586,0.0,0,1.0332733,0.0,0.90623081,63.850685,1.0242809,443.69968,-9.258749
179.5706,12.479403,8.9703598,0.0,0,1.0056624,0.0,0.91058767,63.937977,0.99893522,443.38528,-9.2615824
179.5748,12.539638,8.992775,0.0,0,0.97805178,0.0,0.91568679,63.926388,0.97174984,443.38647,-9.2597361
179.579,12.615243,9.0246725,0.0,0,0.95044094,0.0,0.92045385,64.005371,0.9396925,443.85187,-9.2590532
179.5832,12.706017,9.055954,0.0,0,0.9228301,0.0,0.92461127,64.148537,0.91389412,444.32593,-9.2597494
179.5874,12.803738,9.0783691,0.0,0,0.89521933,0.0,0.93047309,64.280861,0.88745391,445.15594,-9.2599087
179.5916,12.909379,9.1017084,0.0,0,0.86885226,0.0,0.93319595,64.648911,0.86192149,445.98596,-9.2594795
179.5958,13.02968,9.1329498,0.0,0,0.84259379,0.0,0.93797559,64.933952,0.83530802,446.74319,-9.2598906
179.6,13.086522,9.1548223,0.0,0,0.81633544,0.0,0.94341421,64.859299,0.80483443,447.46002,-9.2600508
179.6042,13.106598,9.1828251,0.0,0,0.79007703,0.0,0.94669616,64.784592,0.78266001,448.09451,-9.2608156
179.6084,13.108291,9.2112131,0.0,0,0.76381862,0.0,0.95157427,64.471107,0.75462669,448.49692,-9.2605
179.6126,13.25032,9.2290411,0.0,0,0.73756021,0.0,0.95618618,64.78447,0.72993249,448.89935,-9.2603292
179.6168,13.379568,9.25597,0.0,0,0.7113018,0.0,0.95911974,65.312134,0.70541537,449.05804,-9.2597075
179.621,13.533468,9.2848253,0.0,0,0.68504345,0.0,0.9647485,65.59407,0.67592371,449.18381,-9.259264
179.6252,13.636791,9.3029366,0.0,0,0.65878505,0.0,0.96897453,65.864754,0.65412176,449.32843,-9.2613821
179.6294,13.706707,9.337162,0.0,0,0.63252664,0.0,0.97312933,65.985046,0.62793589,449.49191,-9.2592516
179.6336,13.817374,9.3620882,0.0,0,0.60626823,0.0,0.97856331,66.13768,0.60097611,449.44424,-9.2601299
179.6378,13.93677,9.3798151,0.0,0,0.58003461,0.0,0.98267984,66.424614,0.57283282,447.83398,-9.2599754
179.642,14.020359,9.4110193,0.0,0,0.55503869,0.0,0.9862901,66.592148,0.55019259,446.22372,-9.2594872
179.6462,13.635284,9.4274645,0.0,0,0.53004867,0.0,0.99047935,64.534256,0.52294374,443.34003,-9.2602568
179.6504,13.00072,9.4283686,0.0,0,0.50505865,0.0,0.99117243,61.455769,0.50759274,440.00443,-9.2610636
179.6546,12.414486,9.4417725,0.0,0,0.48006868,0.0,0.9915306,58.665264,0.49000329,437.46426,-9.2615995
179.6588,12.057349,9.4438391,0.0,0,0.45507869,0.0,0.9935112,56.88298,0.47359586,436.35587,-9.2630959
179.663,11.814995,9.444458,0.0,0,0.4300887,0.0,0.99377102,55.652699,0.45503333,435.24747,-9.2617006
179.6672,11.540029,9.4534731,0.0,0,0.40509868,0.0,0.99398911,54.382088,0.43658611,436.05716,-9.2618389
179.6714,11.160549,9.4511995,0.0,0,0.38010868,0.0,0.99506581,52.553448,0.42317426,436.91364,-9.263196
179.6756,10.714639,9.4533482,0.0,0,0.35511869,0.0,0.99508363,50.443768,0.41303992,437.74014,-9.2639723
179.6798,10.359867,9.4620514,0.0,0,0.3301287,0.0,0.99516171,48.760799,0.41072598,438.54623,-9.2622929
179.684,10.122932,9.456461,0.0,0,0.30513871,0.0,0.99628425,47.632561,0.40470427,439.31995,-9.2630501
179.6882,10.104235,9.4573679,0.0,0,0.28028375,0.0,0.99573779,47.513748,0.38872731,439.97488,-9.2620134
179.6924,10.28211,9.461647,0.0,0,0.25652012,0.0,0.99564952,48.313877,0.36424565,440.62985,-9.2619152
179.6966,10.554355,9.4611139,0.0,0,0.23275654,0.0,0.99714845,49.551571,0.33022687,441.00143,-9.2626381
179.7008,10.725001,9.4660168,0.0,0,0.20899297,0.0,0.99701613,50.450943,0.29497963,441.31631,-9.2629328
179.705,10.818469,9.4735117,0.0,0,0.18522938,0.0,0.99777716,50.79903,0.26578018,441.51157,-9.2615786
179.7092,10.86322,9.4708157,0.0,0,0.16146578,0.0,0.99900168,50.937531,0.23527923,441.56192,-9.2600565
179.7134,10.854341,9.4708796,0.0,0,0.13770218,0.0,0.99764085,50.978107,0.20746121,441.61499,-9.261013
179.7176,10.836889,9.4783802,0.0,0,0.11393856,0.0,0.99894166,50.798054,0.18406139,441.70319,-9.2603102
179.7218,10.779921,9.4764748,0.0,0,0.090174966,0.0,1.0000703,50.528751,0.16161852,441.79135,-9.2610073
179.726,10.72204,9.483448,0.0,0,0.066411361,0.0,0.99954522,50.228565,0.13339059,441.923,-9.2607746
179.7302,10.640281,9.4901333,0.0,0,0.04264776,0.0,1.0012325,49.804901,0.11991189,442.07416,-9.2614126
179.7344,10.570785,9.4811363,0.0,0,0.018884161,0.0,1.0009356,49.491421,0.097084589,442.22922,-9.2617235
179.7386,10.493161,9.4855566,0.0,0,-0.0047604311,0.0,0.99994671,49.179153,0.078974992,442.39294,-9.2609634
179.7428,10.409422,9.4875603,0.0,0,-0.027944429,0.0,1.0011219,48.726265,0.062048905,442.55667,-9.260931
179.747,10.350838,9.4857082,0.0,0,-0.051128428,0.0,1.0016065,48.420586,0.041726455,442.89566,-9.2610865
179.7512,10.276913,9.4963923,0.0,0,-0.074312426,0.0,1.0014681,48.0797,0.030492082,443.24814,-9.2611885
179.7554,10.195202,9.4963808,0.0,0,-0.097496428,0.0,1.0028282,47.660305,0.015850261,443.55228,-9.2606544
179.7596,10.118348,9.4880648,0.0,0,0.2087761,400.0,1.0020688,47.28286,0.00082087918,443.8165,-9.2600708
179.7638,9.845026,9.4956703,0.0,0,0.96941334,400.0,1.0015508,46.160259,0.00063083862,444.07861,-9.261939
179.768,7.0617208,9.4876709,0.0,0,1.7300496,400.0,1.0014864,33.205181,0.1250512,444.33014,-9.2640209
179.7722,2.3116438,9.4655657,0.0,0,2.4906867,400.0,0.99772567,11.149077,0.40289551,444.58167,-9.2664824
179.7764,0.045026679,9.4645996,0.0,0,3.2513232,400.0,0.99520993,0.17664844,1.2445904,444.91223,-9.2694826
179.7806,0.077525213,9.4592514,0.0,0,4.01196,400.0,0.99659801,0.32897568,2.489495,445.26434,-9.2684107
179.7848,-0.19243395,9.4510775,0.0,0,4.7725964,400.0,0.9945215,-0.8558892,3.3941584,445.56555,-9.2675219
179.789,-0.040003333,9.4576912,0.0,0,5.5332332,400.0,0.99468428,-0.20576571,4.1257982,445.79193,-9.2675562
179.7932,-0.00030371029,9.4553051,0.0,0,6.2938709,400.0,0.99620867,-0.056525368,4.8575177,446.01709,-9.266571
179.7974,-0.18060051,9.4526157,0.0,0,7.0545073,400.0,0.99473637,-0.82295865,5.6014824,446.19315,-9.2662945
179.8016,0.020784063,9.4601326,0.0,0,7.8151441,400.0,0.99497634,-0.030578721,6.381021,446.36923,-9.2665272
179.8058,0.11559059,9.4508343,0.0,0,8.5757818,400.0,0.99558127,0.48359081,7.1864028,446.54529,-9.2661533
179.81,-0.19240235,9.448987,0.0,0,9.3364182,400.0,0.99370646,-0.84341788,7.975112,446.72134,-9.2645741
179.8142,0.023537366,9.4538813,0.0,0,10.097054,400.0,0.99414927,0.07323885,8.7612276,446.8941,-9.2646646
179.8184,0.012657669,9.4477606,0.0,0,10.857692,400.0,0.99490184,0.069908522,9.5425119,447.05759,-9.2644835
179.8226,-0.17982025,9.4499025,0.0,0,11.618328,400.0,0.99378216,-0.80100101,10.306436,447.22107,-9.2640257
179.8268,-0.031451438,9.457756,0.0,0,12.378965,400.0,0.99488193,-0.27181238,11.062955,447.37347,-9.261898
179.831,0.029772,9.4471674,0.0,0,13.139603,400.0,0.99502182,0.18593067,11.803948,447.52438,-9.2642078
179.8352,-0.14092477,9.4502277,0.0,0,13.90024,400.0,0.99365711,-0.60434866,12.548376,447.65015,-9.2629976
179.8394,0.021259449,9.4500656,0.0,0,14.660877,400.0,0.99405098,0.05475527,13.308315,447.75076,-9.263936
179.8436,-0.0081618251,9.4469872,0.0,0,15.421513,400.0,0.99464673,0.11712956,14.082523,447.85138,-9.2635117
179.8478,-0.15316619,9.4535561,0.0,0,16.18215,400.0,0.99392897,-0.73377335,14.837526,447.952,-9.2627964
179.852,0.072112672,9.4557533,0.0,0,16.942787,400.0,0.99509013,0.30192792,15.60878,448.05258,-9.2637262
179.8562,-0.12803201,9.4469299,0.0,0,17.703424,400.0,0.99461061,-0.52196181,16.366552,448.14389,-9.2633152
179.8604,-0.073722303,9.4496937,0.0,0,18.0,400.0,0.99338537,-0.36151335,17.122391,448.23193,-9.2633104
179.8646,0.062575549,9.4501381,0.0,0,18.0,400.0,0.99466419,0.25901651,17.824692,448.32443,-9.2634449
179.8688,-0.051016971,9.4525652,0.0,0,18.0,400.0,0.99523413,-0.27087381,18.313807,448.42505,-9.2667923
179.873,0.22051807,9.466259,0.0,0,18.0,400.0,0.99595398,1.029094,18.460924,448.52567,-9.2731552
179.8772,1.0288682,9.4744835,0.0,0,18.0,400.0,0.9990769,4.831594,18.300602,448.63855,-9.2884026
179.8814,0.99829465,9.4774256,0.0,0,18.0,400.0,0.99980301,4.7064385,18.120193,448.75174,-9.3106079
179.8856,1.000802,9.4820719,0.0,0,18.0,400.0,0.99904376,4.7000589,18.055838,448.85742,-9.3426208
179.8898,0.91893601,9.4791708,0.0,0,18.0,400.0,1.0000222,4.3664317,18.068079,448.95804,-9.3785925
179.894,0.8592726,9.4761858,0.0,0,18.0,400.0,0.9993335,4.0880814,18.097391,449.05597,-9.4137774
179.8982,0.84617198,9.4837599,0.0,0,18.0,400.0,0.99917197,3.9970469,18.124254,449.14401,-9.4455156
179.9024,0.86239201,9.4791098,0.0,0,18.0,400.0,1.0004096,4.0024581,18.130133,449.23203,-9.4761782
179.9066,0.91999757,9.4769049,0.0,0,18.0,400.0,0.99907702,4.3025174,18.130054,449.2467,-9.5063305
179.9108,0.96002501,9.4794474,0.0,0,18.0,400.0,0.99886107,4.489275,18.130444,449.2467,-9.5377636
179.915,0.99238509,9.4765749,0.0,0,18.0,400.0,0.99998802,4.6864376,18.127283,449.26947,-9.5695686
179.9192,0.96653944,9.477581,0.0,0,18.0,400.0,0.99914467,4.5513811,18.122974,449.31976,-9.5996246
179.9234,0.90328598,9.4855022,0.0,0,18.0,400.0,0.99987477,4.2715693,18.121946,449.37006,-9.6308107
179.9276,0.87229055,9.4772348,0.0,0,18.0,400.0,1.0004199,4.1383276,18.113026,449.42035,-9.6593752
179.9318,0.85725194,9.4762449,0.0,0,18.0,400.0,0.99856466,4.0084481,18.113079,449.47064,-9.6919546
179.936,0.8857193,9.4844074,0.0,0,18.0,400.0,0.99993896,4.1218905,18.111818,449.47754,-9.7228384
179.9402,0.97073573,9.4737358,0.0,0,18.0,400.0,0.99962294,4.5351634,18.109859,449.46497,-9.7531033
179.9444,1.0036124,9.4813185,0.0,0,18.0,400.0,0.99922585,4.6720982,18.108782,449.46408,-9.783905
179.9486,0.97311366,9.4862232,0.0,0,18.0,400.0,1.0005027,4.5753517,18.108429,449.48923,-9.8176823
179.9528,0.9267469,9.4766235,0.0,0,18.0,400.0,1.0002652,4.4067745,18.106449,449.51437,-9.8493605
179.957,0.87065417,9.4814167,0.0,0,18.0,400.0,0.99904948,4.0988836,18.102495,449.53952,-9.8793468
179.9612,0.85579127,9.4823055,0.0,0,18.0,400.0,0.99990159,3.9784155,18.095322,449.56467,-9.9094648
179.9654,0.87294948,9.4766846,0.0,0,18.0,400.0,0.99998593,4.061924,18.096598,449.56229,-9.9405775
179.9696,0.92968822,9.4851484,0.0,0,18.0,400.0,0.99953681,4.3030295,18.094612,449.53714,-9.9717607
179.9738,0.98584992,9.4838705,0.0,0,18.0,400.0,1.0005838,4.6073818,18.095448,449.51407,-10.003853
179.978,1.005017,9.4786091,0.0,0,18.0,400.0,1.0002496,4.7282219,18.094551,449.5015,-10.034372
179.9822,0.96215582,9.4828529,0.0,0,18.0,400.0,0.99934494,4.5353303,18.091858,449.48889,-10.065875
179.9864,0.91524279,9.4810352,0.0,0,18.0,400.0,1.0003227,4.2974105,18.093424,449.52576,-10.0948
179.9906,0.87029678,9.4785519,0.0,0,18.0,400.0,0.99995112,4.1113591,18.09285,449.57605,-10.127558
179.9948,0.8674835,9.4889441,0.0,0,18.0,400.0,1.0000659,4.0569849,18.09058,449.59583,-10.158079
179.999,0.93771291,9.4837799,0.0,0,18.0,400.0,1.0011536,4.3452902,18.090321,449.57068,-10.189563
180.0032,1.0076959,9.4798193,0.0,0,18.0,400.0,0.99976391,4.683342,18.086872,449.54492,-10.219924
180.0074,1.0225118,9.4847612,0.0,0,18.0,400.0,0.99975657,4.7685413,18.08309,449.4946,-10.251423
180.0116,0.99498999,9.4799204,0.0,0,18.0,400.0,1.0003208,4.6788721,18.084896,449.44431,-10.282763
180.0158,0.94030857,9.4829254,0.0,0,18.0,400.0,1.0002055,4.4380035,18.077703,449.4425,-10.31321
180.02,0.86598575,9.488368,0.0,0,18.0,400.0,1.0000432,4.1010933,18.081871,449.46765,-10.345742
180.0242,0.86131483,9.4836292,0.0,0,18.0,400.0,1.001287,4.0201845,18.079079,449.47961,-10.37727
180.0284,0.89671677,9.4807968,0.0,0,18.0,400.0,0.99957269,4.1620102,18.078009,449.45447,-10.407265
180.0326,0.96157676,9.4848919,0.0,0,18.0,400.0,0.9998855,4.4575019,18.07551,449.42932,-10.437035
180.0368,1.0189391,9.4786253,0.0,0,18.0,400.0,1.0004538,4.7010221,18.077261,449.35986,-10.468678
180.041,1.0229446,9.4849119,0.0,0,18.0,400.0,1.0001322,4.8120246,18.072275,449.28442,-10.49971
180.0452,0.96635717,9.4873123,0.0,0,18.0,400.0,1.0002192,4.5845928,18.073874,449.2467,-10.531056
180.0494,0.90871477,9.4834013,0.0,0,18.0,400.0,1.0014,4.2649803,18.071983,449.2467,-10.563144
180.0536,0.87578154,9.4832277,0.0,0,18.0,400.0,0.99978805,4.1149483,18.072639,449.2467,-10.593119
180.0578,0.8758347,9.4864712,0.0,0,18.0,400.0,1.0005654,4.0701094,18.067856,449.2467,-10.625086
180.062,0.95998579,9.4796772,0.0,0,18.0,400.0,1.0005597,4.443655,18.070063,449.2467,-10.654633
180.0662,1.0220677,9.4866819,0.0,0,18.0,400.0,1.0001497,4.7217393,18.066954,449.22812,-10.684457
180.0704,1.0251962,9.4891539,0.0,0,18.0,400.0,1.0011042,4.7965298,18.061642,449.20297,-10.716618
180.0746,1.0031418,9.4836073,0.0,0,18.0,400.0,1.0012736,4.7318864,18.05901,449.19128,-10.747751
180.0788,0.94046509,9.4839382,0.0,0,18.0,400.0,0.99940789,4.429389,18.062889,449.20386,-10.780092
180.083,0.88063455,9.4859276,0.0,0,18.0,400.0,1.0009779,4.1385036,18.05975,449.21643,-10.808344
180.0872,0.8839038,9.4816179,0.0,0,18.0,400.0,1.0006607,4.1620636,18.063099,449.21674,-10.840988
180.0914,0.91393203,9.4892387,0.0,0,18.0,400.0,1.0001307,4.2479029,18.058508,449.21674,-10.872578
180.0956,0.99994951,9.489563,0.0,0,18.0,400.0,1.0016806,4.6452684,18.061739,449.17184,-10.903321
180.0998,1.048815,9.4809361,0.0,0,18.0,400.0,1.0004908,4.8589716,18.058746,449.09637,-10.935544
180.104,1.0207398,9.4884758,0.0,0,18.0,400.0,1.0002812,4.8086157,18.059155,449.02094,-10.965634
180.1082,0.97071415,9.4847012,0.0,0,18.0,400.0,1.001022,4.5545597,18.058893,448.94547,-10.996875
180.1124,0.9065904,9.4833565,0.0,0,18.0,400.0,1.0006154,4.3153877,18.058716,448.87,-11.025924
180.1166,0.86875176,9.493679,0.0,0,18.0,400.0,1.0009414,4.1238742,18.056644,448.82599,-11.059153
180.1208,0.91082114,9.4863482,0.0,0,18.0,400.0,1.0016592,4.1880121,18.050627,448.78827,-11.088137
180.125,0.97282928,9.4829559,0.0,0,18.0,400.0,1.000248,4.4822612,18.053928,448.76193,-11.120211
180.1292,1.0324947,9.4887667,0.0,0,18.0,400.0,1.0005556,4.7853789,18.049393,448.74936,-11.14983
180.1334,1.0384799,9.482852,0.0,0,18.0,400.0,1.0009558,4.8616729,18.049795,448.73679,-11.182757
180.1376,1.0007226,9.4856062,0.0,0,18.0,400.0,1.0004848,4.7106729,18.04701,448.72418,-11.213243
180.1418,0.93353802,9.4923334,0.0,0,18.0,400.0,1.0009499,4.3906741,18.049841,448.71161,-11.246044
180.146,0.88855803,9.4815769,0.0,0,18.0,400.0,1.0011556,4.2192602,18.049189,448.7077,-11.276832
180.1502,0.89024484,9.4849148,0.0,0,18.0,400.0,1.0002718,4.1631646,18.048927,448.7077,-11.30654
180.1544,0.94303286,9.4843836,0.0,0,18.0,400.0,1.0001311,4.3418827,18.046093,448.70383,-11.337186
180.5577,0.90290582,9.4900808,0.0,0,18.0,0.0014183699,1.0014633,4.2240629,18.011019,432.31201,-11.481041
182.6577,0.838633,9.5059862,0.0,0,18.0,3.2689678000000003e-32,1.0044578,3.9113004,17.999035,405.11777,-11.480207
184.7577,0.83038133,9.5190268,0.0,0,18.0,1.4012985e-45,1.0067056,3.8633118,18.000429,382.62845,-11.48182
186.8577,0.82006085,9.5297947,0.0,0,18.0,1.4012985e-45,1.0087516,3.8139491,18.000311,361.90341,-11.480925
188.9577,0.8238669,9.5406494,0.0,0,18.0,1.4012985e-45,1.010659,3.8135533,17.999502,343.57288,-11.481372
191.0577,0.83186239,9.5505075,0.0,0,18.0,1.4012985e-45,1.0125159,3.8459668,17.999477,326.4216,-11.481351
193.1577,0.82267207,9.5607224,0.0,0,18.0,1.4012985e-45,1.0143335,3.8050053,18.000875,310.64197,-11.48153
195.2577,0.82487291,9.5701962,0.0,0,18.0,1.4012985e-45,1.0161494,3.7980855,18.000019,295.5304,-11.481106
197.3577,0.83764344,9.5791922,0.0,0,18.0,1.4012985e-45,1.0177665,3.8561757,17.999866,281.09677,-11.481445
199.4577,0.82856011,9.5878,0.0,0,18.0,1.4012985e-45,1.0194002,3.8164413,17.998058,267.56128,-11.481672
201.5577,0.8393594,9.5963726,0.0,0,18.0,1.4012985e-45,1.0209364,3.8466969,18.000231,254.9034,-11.48146
203.6577,0.85951966,9.6049299,0.0,0,18.0,1.4012985e-45,1.0225874,3.9379289,17.999767,242.96957,-11.482028
205.7577,0.84712148,9.6124353,0.0,0,18.0,1.4012985e-45,1.023952,3.8813374,18.000111,231.41582,-11.481462
207.8577,0.86659187,9.6195059,0.0,0,18.0,1.4012985e-45,1.0253184,3.9472177,18.000149,220.60936,-11.4813
209.9577,0.8793419,9.6261377,0.0,0,18.0,1.4012985e-45,1.0265125,4.0120344,17.999315,210.30992,-11.481186
212.0577,0.87166786,9.6328278,0.0,0,18.0,1.4012985e-45,1.0277703,3.9803581,17.999561,200.573,-11.48162
214.1577,0.88540673,9.6390085,0.0,0,18.0,1.4012985e-45,1.0289651,4.023458,18.001194,191.06709,-11.481969
216.2577,0.90246958,9.6449862,0.0,0,18.0,1.4012985e-45,1.0300106,4.1066942,17.999489,182.52896,-11.481554
218.3577,0.89530802,9.6515245,0.0,0,18.0,1.4012985e-45,1.031314,4.0698962,18.000059,174.29974,-11.481646
220.4577,0.90779352,9.6569672,0.0,0,18.0,1.4012985e-45,1.0322433,4.1134844,17.999718,166.55873,-11.481668
222.5577,0.92359984,9.6620274,0.0,0,18.0,1.4012985e-45,1.0332551,4.1837564,17.998955,159.18651,-11.481533
224.6577,0.91391999,9.6672468,0.0,0,18.0,1.4012985e-45,1.0341336,4.1477785,18.001011,152.23416,-11.481691
226.7577,0.92392159,9.6723452,0.0,0,18.0,1.4012985e-45,1.0351303,4.1685591,17.999947,145.52588,-11.481182
228.8577,0.93398237,9.677021,0.0,0,18.0,1.4012985e-45,1.0359286,4.225544,18.000292,139.41376,-11.481473
230.9577,0.92346466,9.680665,0.0,0,18.0,1.4012985e-45,1.0366755,4.1742334,17.999342,133.43127,-11.481256
233.0577,0.93542206,9.6857796,0.0,0,18.0,1.4012985e-45,1.0375965,4.211936,18.000967,127.89177,-11.481261
235.1577,0.94732875,9.6893063,0.0,0,18.0,1.4012985e-45,1.0383086,4.2752938,17.999716,122.58067,-11.481982
237.2577,0.92884147,9.6932211,0.0,0,18.0,1.4012985e-45,1.0390509,4.1939125,18.000099,117.41693,-11.481545
239.3577,0.94200397,9.6966925,0.0,0,18.0,1.4012985e-45,1.0397311,4.2296185,17.999863,112.73273,-11.481734
240.1577,0.93581057,9.6985912,0.0,0,18.0,1.4012985e-45,1.0400029,4.216639,18.00004,110.99706,-11.481702