File: examples/dan-msc-case-studies/CS3/data/01 raw data/baron_test_010.csv
Time(sec),Force(kN),Jaw(mm),PowAngle(deg),Power(W),Pram,PTemp,Strain,Stress(MPa),Stroke(mm),TC1(C),wedge(mm)
0.0,1.0541501,0.40965852,0.0,0,11.076097,0.0015882698,0.027714018,13.083482,11.077504,26.058634,-9.1123514
1.1,0.98874366,-0.0023873521,0.0,0,11.076097,3.2158828,-0.00014863969,12.590039,11.076612,25.992296,-9.4819412
2.2,0.95761168,-0.0023508326,0.0,0,11.076097,6.515883,-0.00016297802,12.205075,11.074659,26.021738,-9.4795198
3.3,0.93789089,-0.0023936934,0.0,0,11.076097,9.8158808,-0.00015007742,11.948687,11.075605,25.957041,-9.4780903
4.4,0.91905332,-0.002321891,0.0,0,11.076097,13.115884,-0.0001698112,11.701936,11.07622,25.949099,-9.4762211
5.5,0.91202348,-0.0024681715,0.0,0,11.076097,16.415882,-0.0001523305,11.610948,11.077032,25.859186,-9.4748259
6.6,0.89526534,-0.0022863867,0.0,0,11.076097,19.715881,-0.0001658189,11.414691,11.075488,25.814915,-9.472929
7.7,0.89087391,-0.0024018295,0.0,0,11.076097,23.015882,-0.00014279909,11.334974,11.076029,25.84341,-9.470789
8.8,0.88669819,-0.0020226189,0.0,0,11.076097,26.315886,-0.00012036032,11.280951,11.076288,25.819168,-9.4688568
9.9,0.88444752,-0.0016801172,21.659864,0,11.076097,29.615885,-0.00012157443,11.272996,11.076639,25.808287,-9.467351
11.0,0.88053221,-0.001701469,33.889015,0,11.076097,32.915874,-0.00011892413,11.221679,11.076683,26.356802,-9.4654913
12.1,0.87558335,-0.0018241403,41.060825,0,11.076097,36.215878,-0.00013878255,11.137709,11.076515,27.989864,-9.4639683
13.2,0.89892453,-0.0042808298,45.99773,0,11.076097,39.515881,-0.00026594033,11.451448,11.075636,30.650129,-9.4620762
14.3,0.90316176,-0.0067094937,49.225655,0,11.076097,42.815887,-0.00044430216,11.49968,11.075939,33.999863,-9.460659
15.4,0.91055828,-0.010214394,51.641701,0,11.076097,46.115894,-0.00067333103,11.597581,11.076138,37.844212,-9.4592791
16.5,0.92875928,-0.013588539,53.045063,0,11.076097,49.415894,-0.00090271828,11.836962,11.076242,42.411388,-9.4574451
17.6,0.92809838,-0.016987551,53.763294,0,11.076097,52.715893,-0.0011503291,11.830498,11.075742,47.322071,-9.4553375
18.7,0.93479919,-0.020892823,53.975826,0,11.076097,56.015892,-0.0013736365,11.911104,11.076796,52.384308,-9.453723
19.8,0.9551149,-0.024433406,53.58503,0,11.076097,59.315895,-0.0016354596,12.191321,11.07532,57.428192,-9.4519339
20.9,0.94852215,-0.027563276,52.647346,0,11.076097,62.615894,-0.0018188071,12.105729,11.076282,62.427799,-9.4499207
22.0,0.96019286,-0.030472184,51.583614,0,11.076097,65.915878,-0.0020217309,12.235496,11.076723,66.943039,-9.4484339
23.1,0.9611395,-0.033335574,50.781315,0,11.076097,69.215889,-0.0022336042,12.271873,11.075992,71.041,-9.4465656
24.2,0.96164095,-0.036314823,49.636402,0,11.076097,72.515884,-0.0024146414,12.284683,11.076382,74.782753,-9.4442024
25.3,0.96091962,-0.038659383,48.81226,0,11.076097,75.815887,-0.0025962146,12.268606,11.075551,78.108124,-9.4425077
26.4,0.95646936,-0.041401852,48.383793,0,11.076097,79.115891,-0.0027377622,12.195565,11.076648,81.086586,-9.4404869
27.5,0.96552414,-0.042995445,48.041782,0,11.076097,82.415901,-0.0028701865,12.324163,11.076691,83.845802,-9.439127
28.6,0.95553571,-0.044694193,48.383785,0,11.076097,85.715904,-0.0029606451,12.206392,11.076675,86.415703,-9.4372845
29.7,0.95580184,-0.046807274,48.812252,0,11.076097,89.015892,-0.0031061075,12.196674,11.076597,89.02034,-9.4355736
30.8,0.96223408,-0.048641775,49.286682,0,11.076097,92.315895,-0.0032537717,12.288028,11.077584,91.740448,-9.4339542
31.9,0.95870268,-0.050913297,50.042721,0,11.076097,95.615891,-0.0033850716,12.270522,11.076809,94.486351,-9.4323397
33.0,0.95570743,-0.05307037,51.087059,0,11.076097,98.915894,-0.0035488051,12.202991,11.075734,97.287346,-9.4305782
34.1,0.9685213,-0.055752881,51.666042,0,11.076097,102.21588,-0.0036851,12.361753,11.075974,100.34318,-9.4289274
35.2,0.97030866,-0.058141321,52.283936,0,11.076097,105.51588,-0.0038644178,12.409844,11.076604,103.5103,-9.427496
36.3,0.96347886,-0.061031029,52.97607,0,11.076097,108.81588,-0.0040482553,12.32611,11.075574,106.79673,-9.4254379
37.4,0.96906453,-0.063341916,53.556213,0,11.076097,112.11588,-0.0042062355,12.387809,11.075942,110.21179,-9.4236403
38.5,0.98260552,-0.066040494,53.877228,0,11.076097,115.41589,-0.0044108811,12.585474,11.076236,113.74007,-9.4222136
39.6,0.98261976,-0.068947412,54.300312,0,11.076097,118.71588,-0.0045748316,12.574264,11.076494,117.27829,-9.4202824
40.7,0.98530179,-0.071548201,54.305416,0,11.076097,122.01589,-0.0047753034,12.585704,11.076535,120.82426,-9.4183617
41.8,0.99730593,-0.074918628,54.459202,0,11.076097,125.31588,-0.0049581625,12.77336,11.076589,124.4338,-9.4165602
42.9,0.9925397,-0.077075593,54.624023,0,11.076097,128.616,-0.0051176157,12.712024,11.076509,127.90484,-9.4144459
44.0,0.99544394,-0.080347314,54.624023,0,11.076097,131.91591,-0.0053375498,12.738942,11.076148,131.44258,-9.4124222
45.1,1.0047405,-0.083762772,54.624023,0,11.076097,135.2159,-0.0055639916,12.860494,11.075771,134.7735,-9.4104614
46.2,1.0040891,-0.086849153,54.624123,0,11.076097,138.5159,-0.00579471,12.87503,11.0765,138.20929,-9.4087429
47.3,0.99238402,-0.089540966,54.870193,0,11.076097,141.81589,-0.0059421118,12.71564,11.07679,141.45374,-9.4068022
48.4,1.0027639,-0.091782108,54.875446,0,11.076097,145.11591,-0.0061259465,12.838089,11.076016,144.73618,-9.4057198
49.5,1.0044647,-0.094751753,54.931637,0,11.076097,148.41589,-0.0062783337,12.871315,11.076889,148.09962,-9.4038019
50.6,0.99939531,-0.096982576,55.237812,0,11.076097,151.71588,-0.0064394539,12.812891,11.076953,151.29051,-9.4018803
51.7,1.0043163,-0.1001478,55.281033,0,11.076097,155.0159,-0.0066420231,12.864679,11.076627,154.47897,-9.3995571
52.8,1.0047362,-0.10244153,55.616051,0,11.076097,158.31589,-0.0067940862,12.888263,11.075919,157.61076,-9.3977709
53.9,1.0075551,-0.10538638,55.893547,0,11.076097,161.61589,-0.0070123468,12.930107,11.076363,160.67769,-9.3962412
55.0,1.0159866,-0.10791089,56.129147,0,11.076097,164.91588,-0.007178802,13.02449,11.076226,164.01262,-9.3947315
56.1,1.0183654,-0.11115931,56.425766,0,11.076097,168.21588,-0.007396962,13.061168,11.076123,167.31494,-9.3931198
57.2,1.018455,-0.11521185,56.701359,0,11.076097,171.51588,-0.0076403199,13.076933,11.076989,170.61581,-9.390976
58.3,1.0170057,-0.11727761,56.711422,0,11.076097,174.81589,-0.0077922698,13.040466,11.076315,173.9442,-9.3896866
59.4,1.0112144,-0.12046695,56.974281,0,11.076097,178.11588,-0.0079739112,12.982265,11.075667,177.37167,-9.3880072
60.5,1.0142945,-0.12292185,57.139511,0,11.076097,181.41588,-0.0081515843,13.040091,11.076578,180.58696,-9.3858595
61.6,1.0083926,-0.12613317,57.260738,0,11.076097,184.7159,-0.0083759073,12.949303,11.077626,183.93172,-9.3840914
62.7,1.0206888,-0.12881209,57.535397,0,11.076097,188.0159,-0.0085443547,13.109068,11.076446,187.17674,-9.3822813
63.8,1.0229152,-0.13165924,57.786831,0,11.076097,191.3159,-0.0087627294,13.136602,11.075607,190.46526,-9.3805122
64.9,1.0160524,-0.13629811,57.810051,0,11.076097,194.61591,-0.0090510221,13.048454,11.075459,193.77066,-9.3784904
66.0,1.0196619,-0.13807738,58.073727,0,11.076097,197.91591,-0.0091807637,13.094151,11.077137,197.09077,-9.3767672
67.1,1.0197189,-0.14133924,58.286343,0,11.076097,201.2159,-0.009355587,13.115244,11.075478,200.45042,-9.3750515
68.2,1.02529,-0.14414109,58.337399,0,11.076097,204.51588,-0.009562131,13.186169,11.075957,203.78548,-9.3735085
69.3,1.0263177,-0.14703,58.590034,0,11.076097,207.8159,-0.0097387694,13.203272,11.076134,207.12946,-9.37187
70.4,1.0299844,-0.15005645,58.648006,0,11.076097,211.11589,-0.0099431286,13.24678,11.075884,210.40593,-9.37043
71.5,1.0258976,-0.15299833,58.853752,0,11.076097,214.41591,-0.010150551,13.213065,11.076288,213.60869,-9.3684683
72.6,1.0238967,-0.15742604,59.106438,0,11.076097,217.7159,-0.010436406,13.169515,11.076985,216.79723,-9.3666439
73.7,1.0311272,-0.15916109,59.348137,0,11.076097,221.0159,-0.010579091,13.25639,11.076931,219.95108,-9.365057
74.8,1.0179349,-0.16243233,59.600826,0,11.076097,224.31589,-0.01076287,13.115128,11.076443,223.22473,-9.3633881
75.9,1.0237113,-0.16523848,59.842525,0,11.076097,227.61591,-0.010969709,13.182893,11.075703,226.51253,-9.361434
77.0,1.0293865,-0.16838883,60.084225,0,11.076097,230.91589,-0.011145796,13.25198,11.075756,229.75414,-9.359478
78.1,1.0306172,-0.17142881,60.314934,0,11.076097,234.2159,-0.011358306,13.280794,11.07553,233.01471,-9.3573866
79.2,1.024109,-0.17462106,60.556637,0,11.076097,237.5159,-0.011566323,13.202917,11.076242,236.33955,-9.3557796
80.3,1.0268842,-0.1775429,60.787346,0,11.076097,240.8159,-0.01175741,13.221873,11.075714,239.71065,-9.3539515
81.4,1.0374442,-0.18085408,61.018063,0,11.076097,244.11591,-0.011993942,13.375169,11.075957,243.17616,-9.3522577
82.5,1.0272855,-0.18395512,61.018063,0,11.076097,247.41591,-0.012189911,13.244093,11.075612,246.61874,-9.350379
83.6,1.0304381,-0.18745954,61.103851,0,11.076097,250.7159,-0.012440532,13.284293,11.076042,250.08768,-9.3485899
84.7,1.0344539,-0.19067959,61.203449,0,11.076097,254.0159,-0.012616678,13.341479,11.07664,253.52232,-9.3470879
85.8,1.0337211,-0.19387411,61.237789,0,11.076097,257.31616,-0.012857737,13.346612,11.075284,256.92886,-9.3453245
86.9,1.0183144,-0.19755876,61.237549,0,11.076097,260.61618,-0.013060566,13.13594,11.076708,260.36023,-9.3432112
88.0,1.0350316,-0.20065071,61.237789,0,11.076097,263.91589,-0.013289471,13.356041,11.076003,263.62665,-9.341691
89.1,1.0303926,-0.20347105,61.468498,0,11.076097,267.21591,-0.013458837,13.309743,11.075937,266.70325,-9.3399706
90.2,1.0236346,-0.20677269,61.688229,0,11.076097,270.5159,-0.013677588,13.217603,11.07653,269.78223,-9.338316
91.3,1.0293412,-0.20978722,61.907955,0,11.076097,273.81589,-0.013884246,13.284318,11.076761,272.96219,-9.3367376
92.4,1.0369778,-0.21302865,62.116692,0,11.076097,277.11591,-0.014094724,13.39342,11.07608,276.14822,-9.3347797
93.5,1.0254607,-0.21644321,62.336418,0,11.076097,280.41592,-0.014342935,13.254788,11.076142,279.34708,-9.3334808
94.6,1.0255162,-0.21942416,62.545162,0,11.076097,283.71591,-0.014520788,13.246995,11.076591,282.59726,-9.3316011
95.7,1.0324597,-0.22260754,62.753899,0,11.076097,287.0159,-0.014746475,13.335442,11.076534,286.02539,-9.3297319
96.8,1.0243379,-0.22595398,62.933567,0,11.076097,290.31589,-0.014938245,13.252554,11.075897,289.31891,-9.3282604
97.9,1.0323113,-0.22870852,63.027874,0,11.076097,293.61588,-0.01515429,13.3434,11.077115,292.70856,-9.3263359
99.0,1.0316633,-0.23232581,63.171383,0,11.076097,296.91589,-0.015343721,13.330954,11.075536,295.92203,-9.3247452
100.1,1.0477023,-0.23652469,63.365932,0,11.076097,299.99539,-0.015646407,13.548731,11.076066,299.24692,-9.3230305
101.2,1.0448626,-0.23909053,61.7061,0,11.076097,299.99905,-0.015791869,13.510664,11.076508,302.51361,-9.323307
102.3,1.0324829,-0.2400493,59.86174,0,11.076097,299.99905,-0.015866531,13.342493,11.075994,304.97055,-9.3227472
103.4,1.0335379,-0.24087401,57.670559,0,11.076097,299.99905,-0.015916353,13.381635,11.076753,306.64246,-9.3227043
104.5,1.0256767,-0.24218501,55.432697,0,11.076097,299.99905,-0.016001416,13.270946,11.076183,307.62134,-9.3228378
105.6,1.0115945,-0.24216278,53.248886,0,11.076097,299.99905,-0.016018029,13.08163,11.077182,307.65405,-9.3228636
106.7,0.99460614,-0.24165569,51.203026,0,11.076097,299.99905,-0.015977688,12.872653,11.077163,307.26193,-9.3226719
107.8,0.97223419,-0.24145856,49.752361,0,11.076097,299.99905,-0.015981782,12.576096,11.074776,306.15375,-9.3225975
108.9,0.90890837,-0.24154867,49.028301,0,11.076097,299.99905,-0.015968412,11.75653,11.076024,304.8042,-9.3223782
110.0,0.80664939,-0.24081701,48.81226,0,11.076097,299.99905,-0.015946422,10.442637,11.077508,303.29483,-9.3223648
111.1,0.72906345,-0.24036679,49.229553,0,11.076097,299.99905,-0.015886303,9.448391,11.075116,301.76346,-9.3223782
112.2,0.67656016,-0.24027482,49.972069,0,11.076097,299.99905,-0.015909716,8.7541552,11.076004,300.4566,-9.3224392
113.3,0.65585726,-0.24022833,50.822529,0,11.076097,299.99905,-0.015863337,8.4748831,11.075926,299.30042,-9.3226871
114.4,0.6262874,-0.23987061,51.728912,0,11.076097,299.99905,-0.015866395,8.1114225,11.075924,298.55835,-9.3222837
115.5,0.61363274,-0.24003373,52.788696,0,11.076097,299.99905,-0.015850423,7.933857,11.075327,297.89053,-9.3220921
116.6,0.61083907,-0.24046111,53.631351,0,11.076097,299.99905,-0.015897617,7.8878441,11.075996,297.68546,-9.3219728
117.7,0.61200988,-0.23974995,54.30426,0,11.076097,299.99905,-0.015848186,7.9291434,11.076117,297.65576,-9.3217392
118.8,0.61976272,-0.24019052,54.927158,0,11.076097,299.99905,-0.015872601,8.019743,11.07647,297.7182,-9.3220444
119.9,0.60808283,-0.24070381,55.239254,0,11.076097,299.99905,-0.015916519,7.8507938,11.076781,297.84247,-9.3220673
121.0,0.60205132,-0.24152279,55.696774,0,11.076097,299.99905,-0.015958617,7.8052301,11.075498,298.12015,-9.3215876
122.1,0.61274475,-0.24277085,55.843506,0,11.076097,299.99905,-0.016064972,7.9313135,11.076314,298.55603,-9.3219442
123.2,0.61181676,-0.24252109,55.843506,0,11.076097,299.99905,-0.016039504,7.9078579,11.075883,299.00266,-9.3218737
124.3,0.61011118,-0.24334428,55.843506,0,11.076097,299.99905,-0.016099291,7.8893485,11.077326,299.50842,-9.3224058
125.4,0.60998529,-0.24427719,55.536213,0,11.076097,299.99905,-0.016150234,7.9090972,11.076111,299.89819,-9.3226376
126.5,0.61077559,-0.24451952,55.240868,0,11.076097,299.99905,-0.016190011,7.8993449,11.076779,300.32153,-9.3226318
127.6,0.60596746,-0.24600671,54.948254,0,11.076097,299.99905,-0.01625785,7.835156,11.075843,300.59183,-9.3224573
128.7,0.60586822,-0.24533738,54.745163,0,11.076097,299.99905,-0.016243238,7.8438177,11.075599,300.7579,-9.3223276
129.8,0.60644042,-0.24560905,54.621021,0,11.076097,299.99905,-0.016224716,7.8494468,11.07606,300.77524,-9.322114
130.9,0.60946816,-0.24629095,54.305424,0,11.076097,299.99905,-0.016300198,7.895865,11.075719,300.83429,-9.3218365
132.0,0.61732596,-0.24654464,53.976257,0,11.076097,299.99905,-0.016275497,7.9923692,11.076423,300.73853,-9.3218288
133.1,0.61773181,-0.24660143,53.975834,0,11.076097,299.99905,-0.016315123,8.0133171,11.077029,300.6311,-9.3224812
134.2,0.60679096,-0.24731694,53.975834,0,11.076097,299.99905,-0.016329266,7.8535161,11.076604,300.50214,-9.322258
135.3,0.60365713,-0.2469895,53.944496,0,11.076097,299.99905,-0.016333375,7.8159118,11.076016,300.36978,-9.3222151
136.4,0.61152208,-0.24687433,53.968079,0,11.076097,299.99905,-0.016307781,7.9195218,11.075767,300.25073,-9.3226013
137.5,0.63561195,-0.24694997,53.975826,0,11.076097,299.99905,-0.016326109,8.2264309,11.076262,300.12366,-9.3225136
138.6,0.67161632,-0.24737297,53.975826,0,11.076097,299.99905,-0.016347794,8.6934118,11.075379,299.97733,-9.321928
139.7,0.68552727,-0.24681962,54.139183,0,11.076097,299.99905,-0.016307054,8.883131,11.077096,299.8522,-9.3219519
140.8,0.70174825,-0.24697006,54.223724,0,11.076097,299.99905,-0.016332835,9.0909243,11.076928,299.7973,-9.3221035
141.9,0.70807707,-0.24760388,54.305416,0,11.076097,299.99905,-0.016359901,9.1574926,11.076656,299.80728,-9.3214588
143.0,0.72649276,-0.24688822,54.305416,0,11.076097,299.99905,-0.016328098,9.3815603,11.075591,299.63574,-9.3215456
144.1,0.72517663,-0.24726912,54.569191,0,11.076097,299.99905,-0.016340895,9.3884373,11.075864,299.63589,-9.3221226
145.13,0.73580414,-0.0050623976,54.624023,0,11.076097,299.99905,-0.00032777834,9.3787432,11.076035,299.69586,-9.3222589
145.2819,0.71158439,0.013829993,0.0,0,11.076099,6.0847699e-10,0.0010770927,9.0524864,11.072796,299.741,-9.3217726
145.2841,0.72677106,0.013095467,0.0,0,11.076099,6.077343e-25,0.00073437177,9.1412611,11.071596,299.80191,-9.3231611
145.2863,0.71525007,0.0098733343,0.0,0,11.076099,6.0699205e-40,0.00073293346,9.0523701,11.076045,299.86285,-9.3232861
145.2885,0.73625982,0.01044618,0.0,0,11.076099,0.0,0.0006133875,9.3433685,11.075378,299.92377,-9.3225012
145.2907,0.73888111,0.013265292,0.0,0,11.076099,0.0,0.0010328274,9.3590164,11.074187,299.98468,-9.3227701
145.2929,0.74228466,0.012208033,0.0,0,11.076099,0.0,0.00068108109,9.3969536,11.074225,299.98596,-9.3219376
145.2951,0.73191381,0.0090395808,0.0,0,11.076099,0.0,0.00072940311,9.2914591,11.071916,299.93182,-9.3217764
145.2973,0.72885638,0.0099379607,0.0,0,11.076099,0.0,0.0004530614,9.2273197,11.076402,299.87766,-9.321126
145.2995,0.7058087,0.010394935,0.0,0,11.076099,0.0,0.00092403014,8.9978018,11.078697,299.82352,-9.3210974
145.3017,0.69947582,0.013485054,0.0,0,11.076099,0.0,0.0007051935,8.9409819,11.075336,299.76935,-9.3213377
145.3039,0.69794333,0.010331174,0.0,0,11.076099,0.0,0.00084693433,8.9875326,11.074677,299.74179,-9.3213177
145.3061,0.71068996,0.0096220886,0.0,0,11.076099,0.0,0.00044921931,8.9763355,11.0799,299.71472,-9.3227224
145.3083,0.71699643,0.010392414,0.0,0,11.076099,0.0,0.00092147262,9.0808439,11.074269,299.68765,-9.3227081
145.3105,0.7132771,0.013463805,0.0,0,11.076099,0.0,0.00062541239,9.114975,11.080652,299.66058,-9.3231554
145.3127,0.70918298,0.0089360271,0.0,0,11.076099,0.0,0.00086272566,9.1084509,11.076761,299.64255,-9.3217201
145.3149,0.7076596,0.01043616,0.0,0,11.076099,0.0,0.00052670483,8.9879036,11.077838,299.63577,-9.321806
145.3171,0.70432198,0.010565764,0.0,0,11.076099,0.0,0.00096379832,8.9519043,11.074284,299.62903,-9.3219852
145.3193,0.68666673,0.016094089,0.0,0,11.076099,0.0,0.00075709756,8.7079134,11.071392,299.62225,-9.3225775
145.3215,0.68632734,0.0081489254,0.0,0,11.076099,0.0,0.00079643331,8.7850084,11.080378,299.61548,-9.323143
145.3237,0.70669138,0.010559694,0.0,0,11.076099,0.0,0.00050367281,8.9412737,11.074116,299.62103,-9.3222599
145.3259,0.71667969,0.008002202,0.0,0,11.076099,0.0,0.00080465933,9.1297035,11.074649,299.62778,-9.3218956
145.3281,0.72105187,0.014732014,0.0,0,11.076099,0.0,0.0006844083,9.1309032,11.078064,299.63455,-9.3216763
145.3303,0.72067517,0.009647347,0.0,0,11.063759,0.0,0.00081952865,9.2323341,11.078737,299.64133,-9.3217392
145.3325,0.71522111,0.010455233,0.0,0,10.735814,0.0,0.00055735389,9.2079315,11.078015,299.6481,-9.3232269
145.3347,0.7098664,0.0080381017,0.0,0,10.404922,0.0,0.00085212721,9.0617237,11.07215,299.65485,-9.3220549
145.3369,0.73693115,0.015427537,0.0,0,10.07403,0.0,0.00073033839,9.4214573,11.01231,299.66162,-9.3232059
145.3391,0.71950108,0.0081038373,0.0,0,9.7431364,0.0,0.00075371657,9.0841703,10.821887,299.6684,-9.3234501
145.3413,0.73083836,0.0099452045,0.0,0,9.414134,0.0,0.00057361851,9.2701597,10.51938,299.67517,-9.3232002
145.3435,0.72105539,0.0081099197,0.0,0,9.0922298,0.0,0.00079253386,9.1155968,10.140512,299.60834,-9.3219404
145.3457,9.3540573,0.26756766,0.0,0,8.7703257,0.0,0.017095178,116.72506,9.7941513,299.5271,-9.314229
145.3479,11.567461,0.62205493,0.0,0,8.4631882,0.0,0.042302791,140.23938,9.39112,299.44589,-9.3139391
145.3501,12.648984,0.98828793,0.0,0,8.1570368,0.0,0.067775838,150.21851,8.992465,299.36465,-9.3111553
145.3523,13.243125,1.3364506,0.0,0,7.8607712,0.0,0.093100332,153.46696,8.6332722,299.32202,-9.3111525
145.3545,13.937654,1.6571816,0.0,0,7.5694909,0.0,0.11651064,157.67763,8.2940054,299.36938,-9.3124237
145.3567,14.496958,1.9705451,0.0,0,7.2837996,0.0,0.14058946,160.33618,7.9622078,299.41678,-9.3116808
145.3589,14.970233,2.2844465,0.0,0,7.0067749,0.0,0.16458765,161.63477,7.6464915,299.46417,-9.310812
145.3611,15.464876,2.5598395,0.0,0,6.7313633,0.0,0.18671572,163.31084,7.352406,299.51154,-9.3098068
145.3633,15.891273,2.8452477,0.0,0,6.4677982,0.0,0.20965901,164.06374,7.0708604,299.85355,-9.3116083
145.3655,16.248289,3.1039686,0.0,0,6.2042384,0.0,0.23162319,164.02153,6.8030267,300.28674,-9.3121586
145.3677,16.667032,3.3617949,0.0,0,5.951592,0.0,0.25337881,164.67876,6.5391417,300.71994,-9.3123856
145.3699,17.055813,3.613796,0.0,0,5.7009239,0.0,0.27534476,164.85213,6.2783346,301.15314,-9.311039
145.3721,17.478428,3.872582,0.0,0,5.4572496,0.0,0.29803246,165.09778,6.0246363,301.63077,-9.3123398
145.3743,17.890097,4.1159325,0.0,0,5.21877,0.0,0.32036182,165.21408,5.7717681,302.2594,-9.3134546
145.3765,18.328564,4.3706632,0.0,0,4.9838009,0.0,0.34400225,165.33386,5.520052,302.88803,-9.3131046
145.3787,18.750767,4.6159143,0.0,0,4.7569809,0.0,0.36735502,165.31583,5.2688842,303.51666,-9.3119717
145.3809,19.187336,4.8712068,0.0,0,4.5305729,0.0,0.39221272,165.01604,5.021893,304.14532,-9.3118105
145.3831,19.605246,5.1029301,0.0,0,4.3146987,0.0,0.41535783,164.71445,4.7801609,304.74048,-9.3111973
145.3853,20.059399,5.3391485,0.0,0,4.0989227,0.0,0.43966579,164.46292,4.5419044,305.32071,-9.3113155
145.3875,20.510651,5.5665035,0.0,0,3.8911264,0.0,0.46318969,164.36186,4.3115983,305.90091,-9.3124065
145.3897,21.009752,5.7881694,0.0,0,3.6859105,0.0,0.48736033,164.22456,4.0899954,306.48111,-9.3112726
145.3919,21.506166,6.0012546,0.0,0,3.4855177,0.0,0.51034939,164.25612,3.873656,307.08731,-9.3101416
145.3941,22.022144,6.205442,0.0,0,3.2902899,0.0,0.53370762,164.32027,3.6653433,307.83557,-9.3107347
145.3963,22.548672,6.4042668,0.0,0,3.0970597,0.0,0.55607039,164.57954,3.4653611,308.58386,-9.3102884
145.3985,23.089434,6.6021209,0.0,0,2.9113355,0.0,0.57997352,164.50983,3.2689068,309.33212,-9.3098288
145.4007,23.629641,6.7872314,0.0,0,2.7256117,0.0,0.60150874,164.81232,3.0816617,310.08041,-9.3100548
145.4029,24.206522,6.9695115,0.0,0,2.5483847,0.0,0.62480116,164.91086,2.891588,310.25772,-9.3104448
145.4051,24.804497,7.1536736,0.0,0,2.3717248,0.0,0.64708304,165.31813,2.7119181,310.08246,-9.3092728
145.4073,25.449368,7.3285928,0.0,0,2.2007978,0.0,0.67065728,165.59212,2.5294862,309.9072,-9.3095093
145.4095,26.10989,7.5014353,0.0,0,2.0327621,0.0,0.6922431,166.29376,2.3564215,309.7319,-9.3096428
145.4117,26.785976,7.6652532,0.0,0,1.867934,0.0,0.71569371,166.61929,2.189899,309.48932,-9.3101912
145.4139,27.520624,7.8306947,0.0,0,1.708082,0.0,0.73719144,167.55093,2.0205576,308.49146,-9.3091145
145.4161,28.25614,7.9879169,0.0,0,1.5491621,0.0,0.76085538,168.01576,1.8595406,307.49359,-9.3080158
145.4183,29.025166,8.1460276,0.0,0,1.3970951,0.0,0.78189528,169.01617,1.7028861,306.49573,-9.3069553
145.4205,29.825689,8.2916832,0.0,0,1.2450311,0.0,0.80506128,169.70183,1.5498914,305.49786,-9.3072214
145.4227,30.648819,8.4444551,0.0,0,1.0992622,0.0,0.82659084,170.72194,1.3964359,304.20313,-9.3073483
145.4249,31.579891,8.5930767,0.0,0,0.95463419,0.0,0.85133559,171.55045,1.2452875,302.66107,-9.3068237
145.4271,32.541378,8.7466192,0.0,0,0.8140713,0.0,0.87349433,172.88396,1.0945822,301.11899,-9.3059177
145.4293,33.572853,8.8862791,0.0,0,0.67652738,0.0,0.89828598,174.01102,0.94374114,299.5769,-9.3050642
145.4315,34.667988,9.0310841,0.0,0,0.54098403,0.0,0.92007631,175.78783,0.79574829,298.05142,-9.3041725
145.4337,35.854324,9.1647568,0.0,0,0.41008398,0.0,0.9448666,177.29553,0.65001875,298.32797,-9.3045511
145.4359,37.164055,9.3164291,0.0,0,0.27942356,0.0,0.96878272,179.48207,0.50468647,298.60452,-9.3037148
145.4381,34.990486,9.3334551,0.0,0,0.15489033,0.0,0.97444683,168.3243,0.41604462,298.88107,-9.3044081
145.4403,33.734085,9.3474569,0.0,0,0.030414317,0.0,0.97495914,162.10876,0.36384174,299.15762,-9.3069658
145.4425,33.258232,9.3498859,0.0,0,-0.091734208,0.0,0.97769451,159.32028,0.32091027,300.28421,-9.307539
145.4447,32.966293,9.3689318,0.0,0,-0.21313021,0.0,0.97841954,157.79594,0.27220353,302.35886,-9.3083792
145.4469,32.868587,9.3668289,0.0,0,-0.33452621,0.0,0.98042309,157.0329,0.22169678,304.4335,-9.3099632
145.4491,32.812897,9.3781643,0.0,0,-0.45592222,0.0,0.98047197,156.75241,0.1689366,306.50812,-9.3085241
145.4513,32.748543,9.373642,0.0,0,-0.57731819,0.0,0.9817872,156.23798,0.11545569,308.58276,-9.309453
145.4535,32.637924,9.3889675,0.0,0,-0.69871414,0.0,0.98209578,155.6562,0.075756021,309.65527,-9.3109531
145.4557,32.456264,9.3836336,0.0,0,-0.82011014,0.0,0.9831636,154.60529,0.037571486,310.65973,-9.3107901
145.4579,32.198372,9.3919716,0.0,0,-0.94150615,0.0,0.98324686,153.39258,0.011240435,311.66415,-9.3118086
145.4601,31.852955,9.3899012,0.0,0,-1.0629022,0.0,0.98439413,151.58759,-0.0078924354,312.66861,-9.3109426
145.4623,31.399878,9.4029779,0.0,0,-0.8433224,300.0,0.98508179,149.33797,-0.017124239,313.50854,-9.3122892
145.4645,30.877501,9.3924713,0.0,0,-0.42304331,300.0,0.98451406,146.97229,-0.014189882,314.10175,-9.3126545
145.4667,30.352945,9.3961964,0.0,0,-0.0027638213,300.0,0.98390388,144.53252,-0.010519206,314.69498,-9.312294
145.4689,29.937527,9.3907299,0.0,0,0.41751504,300.0,0.98420328,142.47092,-0.0047760596,315.28818,-9.3123045
145.4711,29.625826,9.4021912,0.0,0,0.83779418,300.0,0.98497307,140.90182,-0.0053223162,315.88141,-9.3120079
145.4733,29.364725,9.39538,0.0,0,1.258074,300.0,0.9849202,139.64639,-0.0032872546,316.2301,-9.3117008
145.4755,28.437927,9.4012394,0.0,0,1.6783527,300.0,0.98516369,135.29231,0.018028179,316.54019,-9.3122549
145.4777,26.051935,9.3887386,0.0,0,2.0986316,300.0,0.98372298,124.37337,0.10270832,316.85031,-9.3159237
145.4799,22.145548,9.3850441,0.0,0,2.5189111,300.0,0.98212034,105.97344,0.26713622,317.1604,-9.3183355
145.4821,12.277713,9.3401098,0.0,0,2.9391904,300.0,0.97537011,61.184998,0.50012326,317.17264,-9.3239679
145.4843,0.37323481,9.1512489,0.0,0,3.3594697,300.0,0.94210714,1.9311739,0.9112286,316.57269,-9.3366919
145.4865,-0.35034341,9.0419397,0.0,0,3.7797484,300.0,0.92347991,-1.680523,1.5998092,315.97272,-9.3379908
145.4887,-0.062278602,9.0113554,0.0,0,4.2000279,300.0,0.91830605,-0.53976136,2.3204131,315.37274,-9.338397
145.4909,0.12141443,9.0412416,0.0,0,4.620307,300.0,0.92281091,0.64918816,2.9701252,314.77277,-9.3372707
145.4931,0.68620479,9.1502075,0.0,0,5.0405865,300.0,0.94134158,3.392226,3.4919577,314.70065,-9.33428
145.4953,0.94604039,9.2110147,0.0,0,5.4608655,300.0,0.95174515,4.7000165,3.9123709,314.76807,-9.3310766
145.4975,0.40727594,9.2125387,0.0,0,5.881145,300.0,0.95282292,2.1125505,4.3077154,314.83548,-9.3319817
145.4997,0.47044605,9.2097168,0.0,0,6.3014245,300.0,0.95151675,2.222558,4.6989703,314.90289,-9.3316469
145.5019,0.52160484,9.2042294,0.0,0,6.7217031,300.0,0.95113426,2.6625919,5.102828,315.20706,-9.3302145
145.5041,0.47444803,9.1975365,0.0,0,7.141983,300.0,0.94926333,2.3201413,5.5145502,316.20447,-9.3277187
145.5063,0.44029629,9.2060213,0.0,0,7.5622616,300.0,0.95184666,2.1992724,5.9394245,317.20187,-9.327096
145.5085,0.48393971,9.2054195,0.0,0,7.9825416,300.0,0.95045656,2.3638358,6.3745198,318.19925,-9.3267603
145.5107,0.59808892,9.2015438,0.0,0,8.4028206,300.0,0.95086211,2.9640718,6.826931,319.19666,-9.3270683
145.5129,0.47323361,9.2034369,0.0,0,8.8230991,300.0,0.94996762,2.3857338,7.2608566,319.77713,-9.3274813
145.5151,0.39716423,9.2070036,0.0,0,9.2433786,300.0,0.95221573,1.9671028,7.6895781,320.19403,-9.3259211
145.5173,0.45411596,9.2090092,0.0,0,9.6636581,300.0,0.95099461,2.181313,8.122632,320.61093,-9.3250084
145.5195,0.52693188,9.2012386,0.0,0,10.083938,300.0,0.95128739,2.544399,8.5660038,321.0278,-9.324192
145.5217,0.51045758,9.2019024,0.0,0,10.504216,300.0,0.94963408,2.5559318,8.9965925,321.42142,-9.3240356
145.5239,0.43601024,9.2045126,0.0,0,10.924496,300.0,0.95200813,2.1533375,9.4259968,321.71033,-9.3230762
145.5261,0.4803561,9.2078381,0.0,0,11.344774,300.0,0.95060533,2.3406034,9.8554964,321.99921,-9.3233871
145.5283,0.52589148,9.2015209,0.0,0,11.765054,300.0,0.95152712,2.5597093,10.296053,322.28809,-9.3223486
145.5305,0.5032059,9.2051497,0.0,0,12.185333,300.0,0.95012176,2.478822,10.73088,322.57697,-9.3229837
145.5327,0.4601205,9.2003851,0.0,0,12.605613,300.0,0.9513272,2.2775352,11.153486,322.76611,-9.3233652
145.5349,0.41419283,9.210886,0.0,0,13.025891,300.0,0.95104015,2.0124757,11.570203,322.90045,-9.323349
145.5371,0.51262254,9.2016649,0.0,0,13.446171,300.0,0.95161176,2.4479911,11.986008,323.03482,-9.3216486
145.5393,0.53339511,9.2062187,0.0,0,13.866449,300.0,0.95032316,2.685441,12.410645,323.16919,-9.3207474
145.5415,0.48067558,9.2038755,0.0,0,14.28673,300.0,0.952025,2.3279009,12.829962,323.29767,-9.3213243
145.5437,0.45088908,9.2091579,0.0,0,14.707008,300.0,0.95051908,2.2426648,13.263863,323.3783,-9.3210468
145.5459,0.5078615,9.202013,0.0,0,15.127288,300.0,0.9516539,2.4765081,13.706046,323.45892,-9.3217039
145.5481,0.51213771,9.205245,0.0,0,15.547566,300.0,0.95012844,2.6175692,14.158101,323.53955,-9.3206892
145.5503,0.52802896,9.2010422,0.0,0,15.967846,300.0,0.95152354,2.6371655,14.593522,323.62015,-9.3198614
145.5525,0.48535365,9.2138805,0.0,0,16.388126,300.0,0.95114172,2.3858449,15.021392,323.6777,-9.3208427
145.5547,0.4548547,9.2036896,0.0,0,16.808405,300.0,0.95185274,2.2365892,15.442234,323.71799,-9.3212337
145.5569,0.57323313,9.208559,0.0,0,17.228683,300.0,0.95090175,2.7864604,15.86529,323.7583,-9.3222218
145.5591,0.53909409,9.2021847,0.0,0,17.648964,300.0,0.95164311,2.6670368,16.28377,323.79861,-9.3217945
145.5613,0.49357417,9.2120237,0.0,0,17.999975,300.0,0.95104641,2.4368587,16.691204,323.83551,-9.3209543
145.5635,0.47501558,9.2012405,0.0,0,18.0,300.0,0.95138705,2.3605115,17.102343,323.78177,-9.3198929
145.5657,0.51108479,9.2087116,0.0,0,18.0,300.0,0.9509173,2.4790571,17.500412,323.728,-9.3200579
145.5679,0.55756783,9.1989756,0.0,0,18.0,300.0,0.95100385,2.774791,17.852724,323.67426,-9.3210373
145.5701,0.4931826,9.214922,0.0,0,18.0,300.0,0.9517194,2.5010645,18.13835,323.62051,-9.3218393
145.5723,0.57511789,9.2037268,0.0,0,18.0,300.0,0.95157421,2.7725246,18.352791,323.52982,-9.323925
145.5745,0.59801847,9.2110128,0.0,0,18.0,300.0,0.95148098,2.9103401,18.462442,323.40216,-9.3281651
145.5767,0.59088892,9.2017918,0.0,0,18.0,300.0,0.95115685,2.8768854,18.467979,323.27451,-9.3335571
145.5789,0.57134992,9.2101183,0.0,0,18.0,300.0,0.95115989,2.8465025,18.393332,323.14688,-9.3417721
145.5811,0.57474905,9.2023916,0.0,0,18.0,300.0,0.95116258,2.8090844,18.277082,323.01923,-9.3500156
145.5833,0.62194782,9.2082911,0.0,0,18.0,300.0,0.95119935,3.018816,18.170731,322.91748,-9.3610907
145.5855,0.62269419,9.2022934,0.0,0,18.0,300.0,0.95111436,3.0913815,18.09931,322.81671,-9.3755875
145.5877,0.59287554,9.2110081,0.0,0,18.0,300.0,0.95161653,2.9490085,18.065718,322.71594,-9.3909378
145.5899,0.58438504,9.1992579,0.0,0,18.0,300.0,0.95042384,2.8792431,18.061846,322.61517,-9.4075661
145.5921,0.57807797,9.2034597,0.0,0,18.0,300.0,0.95065391,2.8638611,18.066282,322.52588,-9.4278603
145.5943,0.55695403,9.1985998,0.0,0,18.0,300.0,0.95015466,2.7247651,18.076622,322.452,-9.4452744
145.5965,0.57188261,9.2062464,0.0,0,18.0,300.0,0.95107073,2.8434448,18.096807,322.37808,-9.4634085
145.5987,0.581725,9.1997423,0.0,0,18.0,300.0,0.95028722,2.8827646,18.112469,322.3042,-9.4780569
145.6009,0.59827262,9.2014351,0.0,0,18.0,300.0,0.95064008,2.9619832,18.127386,322.23029,-9.4942122
145.6031,0.5803085,9.1995935,0.0,0,18.0,300.0,0.95012289,2.8551438,18.136335,322.18033,-9.5100756
145.6053,0.6063779,9.2061214,0.0,0,18.0,300.0,0.95134115,2.9600854,18.145622,322.1333,-9.5253077
145.6075,0.60146987,9.1989212,0.0,0,18.0,300.0,0.94972724,2.9615462,18.140934,322.08627,-9.539957
145.6097,0.60988504,9.2016706,0.0,0,18.0,300.0,0.95080304,3.0150726,18.134846,322.03928,-9.5551834
145.6119,0.594051,9.2015314,0.0,0,18.0,300.0,0.9501211,2.9275324,18.140823,322.00415,-9.5735064
145.6141,0.5978964,9.20362,0.0,0,18.0,300.0,0.951307,2.9604788,18.138966,321.99069,-9.5895872
145.6163,0.60180682,9.2004299,0.0,0,18.0,300.0,0.94964969,2.9878111,18.133234,321.97726,-9.6069317
145.6185,0.60401177,9.1985378,0.0,0,18.0,300.0,0.9505114,2.9729624,18.130995,321.96384,-9.622118
145.6207,0.61705709,9.2000122,0.0,0,18.0,300.0,0.94959152,3.0593405,18.128349,321.95038,-9.6361046
145.6229,0.63453376,9.2025213,0.0,0,18.0,300.0,0.95135659,3.1539266,18.12714,321.92596,-9.6531906
145.6251,0.63422501,9.2016497,0.0,0,18.0,300.0,0.94970554,3.1053553,18.123276,321.89908,-9.6690302
145.6273,0.62194198,9.2013702,0.0,0,18.0,300.0,0.9511013,3.0582132,18.124121,321.87222,-9.684514
145.6295,0.60512149,9.2027273,0.0,0,18.0,300.0,0.9499082,2.9988399,18.121838,321.84534,-9.7000828
145.6317,0.61104047,9.2058573,0.0,0,18.0,300.0,0.9519918,3.0098245,18.116913,321.82416,-9.7155762
145.6339,0.61028308,9.2062578,0.0,0,18.0,300.0,0.95032161,2.9908218,18.11392,321.81744,-9.7312088
145.6361,0.62967181,9.2010851,0.0,0,18.0,300.0,0.95127761,3.1090043,18.112772,321.8107,-9.7471552
145.6383,0.61827719,9.2029219,0.0,0,18.0,300.0,0.94957989,3.0465033,18.114727,321.80399,-9.7620497
145.6405,0.62636673,9.2003441,0.0,0,18.0,300.0,0.95125198,3.0985217,18.110535,321.79727,-9.7779207
145.6427,0.63358968,9.2042837,0.0,0,18.0,300.0,0.94978666,3.1053696,18.106447,321.79556,-9.7931271
145.6449,0.64383358,9.1961594,0.0,0,18.0,300.0,0.95065087,3.1754732,18.107773,321.79556,-9.8082113
145.6471,0.61480135,9.2039289,0.0,0,18.0,300.0,0.94994652,3.0611444,18.108404,321.79556,-9.8247252
145.6493,0.62840337,9.2006226,0.0,0,18.0,300.0,0.9514026,3.0757544,18.104853,321.79556,-9.8413477
145.6515,0.61127448,9.2085505,0.0,0,18.0,300.0,0.95046121,3.0202408,18.108444,321.78714,-9.8574638
145.6537,0.62161124,9.1994629,0.0,0,18.0,300.0,0.95127785,3.0622451,18.101316,321.74683,-9.8727407
145.6559,0.62854874,9.2048597,0.0,0,18.0,300.0,0.95018214,3.0826757,18.099716,321.70651,-9.8876534
145.6581,0.62656051,9.1973352,0.0,0,18.0,300.0,0.95093173,3.0717006,18.098286,321.6662,-9.9047298
145.6603,0.61576331,9.2071171,0.0,0,18.0,300.0,0.95011926,3.0322967,18.100445,321.62589,-9.9199314
145.6625,0.63359123,9.199769,0.0,0,18.0,300.0,0.9511416,3.1316822,18.09831,321.59464,-9.9358892
145.6647,0.6366685,9.2060356,0.0,0,18.0,300.0,0.95026243,3.1317868,18.0984,321.56775,-9.9509773
145.6669,0.62127656,9.1980505,0.0,0,18.0,300.0,0.95101845,3.0450625,18.0973,321.54086,-9.9683418
145.6691,0.60322845,9.2089863,0.0,0,18.0,300.0,0.95056325,2.9978366,18.097511,321.51401,-9.9856081
145.6713,0.60614955,9.1974106,0.0,0,18.0,300.0,0.95075446,2.9618351,18.103388,321.4917,-10.001259
145.6735,0.61427844,9.2057095,0.0,0,18.0,300.0,0.95025831,3.0101953,18.096891,321.49841,-10.016594
145.6757,0.62531835,9.1975117,0.0,0,18.0,300.0,0.95082515,3.0437901,18.093838,321.50513,-10.032222
145.6779,0.63539326,9.206995,0.0,0,18.0,300.0,0.95034492,3.0965488,18.093096,321.51187,-10.047806
145.6801,0.62909758,9.1997566,0.0,0,18.0,300.0,0.95106852,3.1155212,18.09679,321.51859,-10.06397
145.6823,0.63097507,9.2057142,0.0,0,18.0,300.0,0.95043534,3.1317818,18.09314,321.52127,-10.081272
145.6845,0.63227242,9.1957026,0.0,0,18.0,300.0,0.95026231,3.1122894,18.094765,321.52127,-10.09624
145.6867,0.61748606,9.2083092,0.0,0,18.0,300.0,0.95072442,3.0363407,18.096693,321.52127,-10.111578
145.6889,0.62525409,9.1990137,0.0,0,18.0,300.0,0.95060027,3.0774906,18.093266,321.52127,-10.126893
145.6911,0.62246597,9.2054291,0.0,0,18.0,300.0,0.95064592,3.0665836,18.090961,321.52042,-10.142085
145.6933,0.63528007,9.2003126,0.0,0,18.0,300.0,0.95077193,3.1150837,18.092125,321.50699,-10.158147
145.6955,0.64468741,9.2093782,0.0,0,18.0,300.0,0.95117486,3.1544909,18.087685,321.49356,-10.173656
145.6977,0.65867209,9.1985769,0.0,0,18.0,300.0,0.95019233,3.1801963,18.089075,321.4801,-10.19053
145.6999,0.65424472,9.203125,0.0,0,18.0,300.0,0.95048487,3.2216206,18.082979,321.46667,-10.206099
145.7021,0.6509974,9.1972752,0.0,0,18.0,300.0,0.94999874,3.2146497,18.087881,321.46033,-10.221992
145.7043,0.66387618,9.2080364,0.0,0,18.0,300.0,0.95115328,3.2332284,18.091003,321.46033,-10.238473
145.7065,0.644548,9.2029209,0.0,0,18.0,300.0,0.95096332,3.1648088,18.084412,321.46033,-10.255268
145.7087,0.6464076,9.207284,0.0,0,18.0,300.0,0.95141643,3.1990621,18.083387,321.46033,-10.271425
145.7109,0.64633101,9.2002573,0.0,0,18.0,300.0,0.95034516,3.1453404,18.083563,321.46033,-10.285551
145.7131,0.66049773,9.2082138,0.0,0,18.0,300.0,0.95162439,3.2439446,18.082388,321.46033,-10.301588
145.7153,0.66101414,9.2016783,0.0,0,18.0,300.0,0.95037884,3.2410212,18.079702,321.46033,-10.316687
145.7175,0.67371017,9.2038088,0.0,0,18.0,300.0,0.95108116,3.3170309,18.077839,321.46033,-10.332561
145.7197,0.65886784,9.1983805,0.0,0,18.0,300.0,0.94976699,3.2687638,18.079197,321.46033,-10.348931
145.7219,0.66173941,9.2054605,0.0,0,18.0,300.0,0.95156115,3.2150552,18.082438,321.46033,-10.366091
145.7241,0.66210955,9.2044163,0.0,0,18.0,300.0,0.95051998,3.2257679,18.080891,321.46033,-10.381706
145.7263,0.64162743,9.2018089,0.0,0,18.0,300.0,0.95084888,3.1895022,18.081291,321.46033,-10.396763
145.7285,0.63824803,9.2000246,0.0,0,18.0,300.0,0.94980115,3.1370342,18.07966,321.46033,-10.412305
145.7307,0.65172935,9.2021208,0.0,0,18.0,300.0,0.95134437,3.2008424,18.076332,321.46033,-10.427991
145.7329,0.64958096,9.2017984,0.0,0,18.0,300.0,0.94978952,3.204793,18.076294,321.448,-10.443474
145.7351,0.67057884,9.2013273,0.0,0,18.0,300.0,0.95100909,3.2552385,18.077665,321.43454,-10.460284
145.7373,0.65152001,9.2010202,0.0,0,18.0,300.0,0.94971555,3.2272611,18.078596,321.42111,-10.476119
145.7395,0.66089916,9.2026167,0.0,0,18.0,300.0,0.95142776,3.2526946,18.078176,321.40765,-10.490919
145.7417,0.64937115,9.201808,0.0,0,18.0,300.0,0.94964719,3.2503066,18.076044,321.3891,-10.508558
145.7439,0.63965803,9.1987486,0.0,0,18.0,300.0,0.95088494,3.1504805,18.07761,321.36221,-10.523618
145.7461,0.64860183,9.2024727,0.0,0,18.0,300.0,0.9498235,3.1989839,18.074993,321.33536,-10.540902
145.7483,0.65257478,9.2013626,0.0,0,18.0,300.0,0.95161659,3.1942039,18.073391,321.30847,-10.555976
145.7505,0.64577603,9.2049274,0.0,0,18.0,300.0,0.94994563,3.1743352,18.072208,321.28162,-10.571688
145.7527,0.66486311,9.1980572,0.0,0,18.0,300.0,0.95089537,3.2434528,18.074345,321.25473,-10.586555
145.7549,0.67071569,9.203063,0.0,0,18.0,300.0,0.94970155,3.3067987,18.069895,321.22787,-10.602008
145.7571,0.66807652,9.2006273,0.0,0,18.0,300.0,0.95145571,3.2999735,18.071959,321.20099,-10.617601
145.7593,0.65265596,9.2063866,0.0,0,18.0,300.0,0.95021719,3.2029114,18.073248,321.1741,-10.635011
145.7615,0.64599907,9.1969757,0.0,0,18.0,300.0,0.95080405,3.1771677,18.076017,321.14725,-10.651412
145.7637,0.66249579,9.2042198,0.0,0,18.0,300.0,0.94995296,3.3062229,18.071787,321.12036,-10.666056
145.7659,0.66476697,9.1993608,0.0,0,18.0,300.0,0.95138282,3.2576923,18.068169,321.09348,-10.68227
145.7681,0.66495425,9.2080641,0.0,0,18.0,300.0,0.95017886,3.2436681,18.06624,321.06662,-10.696822
145.7703,0.66532773,9.1963978,0.0,0,18.0,300.0,0.95062649,3.2585149,18.069555,321.03973,-10.712055
145.7725,0.67976254,9.2028646,0.0,0,18.0,300.0,0.94979209,3.3280594,18.066263,321.03363,-10.727907
145.7747,0.69092649,9.1990852,0.0,0,18.0,300.0,0.95129812,3.3916929,18.064665,321.03363,-10.743835
145.7769,0.67951721,9.208518,0.0,0,18.0,300.0,0.95028931,3.3287773,18.067249,321.03363,-10.760065
145.7791,0.66019779,9.1966448,0.0,0,18.0,300.0,0.9506489,3.2596614,18.065016,321.03363,-10.775224
145.7813,0.67556119,9.2048502,0.0,0,18.0,300.0,0.95028329,3.3132904,18.069147,321.02905,-10.791699
145.7835,0.6737693,9.1997967,0.0,0,18.0,300.0,0.95124578,3.2965255,18.068682,320.99545,-10.808366
145.7857,0.67744112,9.2118769,0.0,0,18.0,300.0,0.95107907,3.3238959,18.067171,320.96188,-10.824407
145.7879,0.66903251,9.1976328,0.0,0,18.0,300.0,0.95057553,3.2917469,18.061659,320.92831,-10.841019
145.7901,0.70730346,9.2020502,0.0,0,18.0,300.0,0.94976074,3.4216392,18.059113,320.89471,-10.857025
145.7923,0.69604677,9.1979418,0.0,0,18.0,300.0,0.95058173,3.4146895,18.061464,320.87726,-10.871311
145.7945,0.68578786,9.2078524,0.0,0,18.0,300.0,0.95064402,3.3945317,18.061468,320.87054,-10.887338
145.7967,0.681615,9.2000771,0.0,0,18.0,300.0,0.95091408,3.3522453,18.06152,320.8638,-10.903191
145.7989,0.67841774,9.205286,0.0,0,18.0,300.0,0.95057434,3.3603585,18.059704,320.85709,-10.918759
145.8011,0.67441219,9.1972752,0.0,0,18.0,300.0,0.95029724,3.3220172,18.061331,320.85251,-10.935442
145.8033,0.69657713,9.2071447,0.0,0,18.0,300.0,0.95082742,3.4126382,18.061161,320.87939,-10.953165
145.8055,0.65996814,9.198041,0.0,0,18.0,300.0,0.95035416,3.2883315,18.060326,320.90625,-10.968342
145.8077,0.68199235,9.2043037,0.0,0,18.0,300.0,0.95060849,3.3706114,18.059053,320.93314,-10.98277
145.8099,0.69497895,9.1992474,0.0,0,18.0,300.0,0.95035392,3.423759,18.057293,320.96002,-10.997682
145.8121,0.69572455,9.2074966,0.0,0,18.0,300.0,0.95102048,3.4281948,18.057768,320.9621,-11.01342
145.8143,0.68535829,9.1994858,0.0,0,18.0,300.0,0.95036447,3.376719,18.055511,320.94193,-11.029688
145.8165,0.68993086,9.2038994,0.0,0,18.0,300.0,0.95076805,3.3773868,18.057404,320.92178,-11.046363
145.8187,0.66784722,9.198987,0.0,0,18.0,300.0,0.95009243,3.3080871,18.059208,320.90161,-11.062376
145.8209,0.68516862,9.2071486,0.0,0,18.0,300.0,0.95130861,3.3416455,18.056976,320.88147,-11.078207
145.8231,0.6860497,9.2001314,0.0,0,18.0,300.0,0.95008093,3.3605838,18.054958,320.85464,-11.094245
145.8253,0.6914435,9.201931,0.0,0,18.0,300.0,0.9506132,3.3656292,18.056351,320.82779,-11.109825
145.8275,0.68863815,9.2008162,0.0,0,18.0,300.0,0.95016927,3.3968041,18.05583,320.8009,-11.125049
145.8297,0.708085,9.2060051,0.0,0,18.0,300.0,0.9516328,3.4870806,18.056129,320.77402,-11.140111
145.8319,0.69361991,9.2013998,0.0,0,18.0,300.0,0.95022774,3.4477711,18.052729,320.74716,-11.157347
145.8341,0.68604279,9.2015381,0.0,0,18.0,300.0,0.95088595,3.3890455,18.050123,320.72028,-11.174665
145.8363,0.68968576,9.2012672,0.0,0,18.0,300.0,0.94999814,3.3924139,18.05497,320.69339,-11.189947
145.8385,0.68515313,9.2046967,0.0,0,18.0,300.0,0.95141256,3.3756163,18.053013,320.66653,-11.207294
145.8407,0.68482584,9.2021017,0.0,0,18.0,300.0,0.94978142,3.3782251,18.054043,320.63965,-11.221741
145.8429,0.69476986,9.2016754,0.0,0,18.0,300.0,0.95108092,3.4212785,18.050686,320.63129,-11.236458
145.8451,0.70480627,9.1997929,0.0,0,18.0,300.0,0.94952518,3.4621246,18.048227,320.62457,-11.251424
145.8473,0.71713871,9.2037277,0.0,0,18.0,300.0,0.95161676,3.5039487,18.052597,320.61786,-11.267373
145.8495,0.71145672,9.2050934,0.0,0,18.0,300.0,0.95027757,3.5431926,18.045809,320.61115,-11.282936
145.8517,0.70255613,9.2005386,0.0,0,18.0,300.0,0.951226,3.4786947,18.047701,320.60699,-11.298377
145.8539,0.70320427,9.2016296,0.0,0,18.0,300.0,0.94968075,3.4722326,18.045425,320.60699,-11.314786
145.8561,0.70636201,9.2037601,0.0,0,18.0,300.0,0.95170015,3.4845316,18.044792,320.60699,-11.330557
145.8583,0.7126658,9.2077341,0.0,0,18.0,300.0,0.95051181,3.5156355,18.048058,320.60699,-11.348309
145.8605,0.70080751,9.1981525,0.0,0,18.0,300.0,0.95082283,3.4437032,18.049852,320.60699,-11.36319
146.7608,0.68220842,9.2125711,0.0,0,18.0,1.6216725e-10,0.95241827,3.3499146,18.001749,309.85803,-11.481083
147.8608,0.71086317,9.2223663,0.0,0,18.0,1.6196878999999998e-25,0.95408517,3.4866536,18.000668,298.5976,-11.48019
148.9608,0.72046226,9.229188,0.0,0,18.0,1.617701e-40,0.95529723,3.5291388,17.999908,288.66107,-11.480605
150.0608,0.7343275,9.235218,0.0,0,18.0,1.4012985e-45,0.95630109,3.5914621,17.999901,279.5564,-11.480957
151.1608,0.72342032,9.239852,0.0,0,18.0,1.4012985e-45,0.95713675,3.5414505,18.000771,270.97702,-11.481328
152.2608,0.72125065,9.2446833,0.0,0,18.0,1.4012985e-45,0.95792061,3.5249186,17.999474,262.76114,-11.480989
153.3608,0.73693174,9.2491961,0.0,0,18.0,1.4012985e-45,0.95874119,3.6010947,17.999434,255.22281,-11.480633
154.4608,0.73170114,9.2531023,0.0,0,18.0,1.4012985e-45,0.95936465,3.5766177,18.000599,247.7981,-11.480768
155.5608,0.73562944,9.2569809,0.0,0,18.0,1.4012985e-45,0.96006906,3.5820622,17.999821,240.53789,-11.480906
156.6608,0.74488711,9.2603645,0.0,0,18.0,1.4012985e-45,0.96062195,3.6283925,17.999475,233.62006,-11.480882
157.7608,0.749515,9.2642765,0.0,0,18.0,1.4012985e-45,0.96133137,3.6541531,18.001133,227.06522,-11.481418
158.8608,0.75101423,9.267561,0.0,0,18.0,1.4012985e-45,0.96183902,3.6586351,18.000748,220.90907,-11.481717
159.9608,0.74995214,9.2705898,0.0,0,18.0,1.4012985e-45,0.96243399,3.6434503,17.999319,215.08717,-11.481336
161.0608,0.75686085,9.2738028,0.0,0,18.0,1.4012985e-45,0.96291727,3.6753373,17.999382,209.487,-11.481386
162.1608,0.75368148,9.27666,0.0,0,18.0,1.4012985e-45,0.96346796,3.6637313,17.999918,203.96346,-11.481184
163.2608,0.75821078,9.2793436,0.0,0,18.0,1.4012985e-45,0.96388692,3.6772821,17.999971,198.67546,-11.481578
164.3608,0.76092929,9.2823763,0.0,0,18.0,1.4012985e-45,0.96448481,3.6939988,18.000492,193.7065,-11.480772
165.4608,0.76395875,9.2848825,0.0,0,18.0,1.4012985e-45,0.96486723,3.7031486,17.99995,188.78773,-11.480601
166.5608,0.77400154,9.2876244,0.0,0,18.0,1.4012985e-45,0.96539778,3.7534835,18.000898,183.91356,-11.480973
167.6608,0.77916735,9.2903633,0.0,0,18.0,1.4012985e-45,0.96583313,3.7750833,18.000385,179.40924,-11.480941
168.7608,0.78518265,9.2928152,0.0,0,18.0,1.4012985e-45,0.96632618,3.8058987,18.000229,174.85582,-11.48108
169.8608,0.78231108,9.2948809,0.0,0,18.0,1.4012985e-45,0.96662199,3.7907317,18.001499,170.3777,-11.481428
170.9608,0.79240727,9.2977562,0.0,0,18.0,1.4012985e-45,0.96719527,3.8300984,18.000071,166.25685,-11.481625
172.0608,0.79782951,9.3000069,0.0,0,18.0,1.4012985e-45,0.96751654,3.8623605,18.000027,162.09921,-11.481549
173.1608,0.7935096,9.3027143,0.0,0,18.0,1.4012985e-45,0.96804619,3.8377857,18.000938,158.26401,-11.481795
174.2608,0.79858267,9.3046532,0.0,0,18.0,1.4012985e-45,0.96832967,3.8564777,18.000702,154.38885,-11.481834
175.3608,0.79666764,9.3068962,0.0,0,18.0,1.4012985e-45,0.96881616,3.8521478,18.000248,150.70396,-11.481536
176.4608,0.79762226,9.3095531,0.0,0,18.0,1.4012985e-45,0.96919096,3.8552604,18.001194,146.99333,-11.481076
177.5608,0.80545622,9.3116627,0.0,0,18.0,1.4012985e-45,0.96966827,3.8945711,18.000263,143.52592,-11.480937
178.6608,0.81586528,9.3134365,0.0,0,18.0,1.4012985e-45,0.96988159,3.9390335,18.000153,140.07191,-11.480827
179.7608,0.81677866,9.3151464,0.0,0,18.0,1.4012985e-45,0.97025043,3.9450877,17.999708,136.75131,-11.480919
180.8608,0.8114695,9.3173637,0.0,0,18.0,1.4012985e-45,0.97057694,3.9153802,17.998949,133.59053,-11.480615
181.9608,0.82688832,9.319561,0.0,0,18.0,1.4012985e-45,0.97104138,3.9876134,18.000111,130.53839,-11.48078
183.0608,0.82152849,9.3213377,0.0,0,18.0,1.4012985e-45,0.97128499,3.9609582,17.999857,127.47816,-11.480689
184.1608,0.82136017,9.3231411,0.0,0,18.0,1.4012985e-45,0.97166556,3.9581902,18.001068,124.48634,-11.480877
185.2608,0.82338661,9.3249979,0.0,0,18.0,1.4012985e-45,0.97192615,3.9640808,17.999708,121.63631,-11.48068
186.3608,0.84088892,9.3266678,0.0,0,18.0,1.4012985e-45,0.97229004,4.0503817,18.0007,118.82786,-11.480953
187.4608,0.84162748,9.3285456,0.0,0,18.0,1.4012985e-45,0.9725306,4.0523729,17.999838,116.18966,-11.48121
188.5608,0.84390998,9.3307333,0.0,0,18.0,1.4012985e-45,0.97298324,4.0669723,17.999031,113.57299,-11.481048
189.6608,0.84625942,9.332099,0.0,0,18.0,1.4012985e-45,0.97314286,4.0678329,17.999817,111.0475,-11.481228
190.7608,0.85720503,9.3336449,0.0,0,18.0,1.4012985e-45,0.97351682,4.1240687,17.999941,108.57379,-11.481533
191.8608,0.84898466,9.3358135,0.0,0,18.0,1.4012985e-45,0.97381324,4.0828691,18.000439,106.13468,-11.481434
192.9608,0.85488051,9.3364763,0.0,0,18.0,1.4012985e-45,0.97400063,4.1069322,18.000065,103.88774,-11.481394
194.0608,0.85536432,9.3389959,0.0,0,18.0,1.4012985e-45,0.97435665,4.1136136,18.000021,101.68093,-11.481542
195.1608,0.86047256,9.3394747,0.0,0,18.0,1.4012985e-45,0.97451299,4.1359916,17.999638,99.43856,-11.48202
196.2608,0.85501939,9.3414173,0.0,0,18.0,1.4012985e-45,0.97481537,4.1066575,18.000313,97.355225,-11.481571
197.3608,0.86008525,9.342864,0.0,0,18.0,1.4012985e-45,0.97510982,4.131804,17.999502,95.286484,-11.481504
198.4608,0.86429763,9.3440399,0.0,0,18.0,1.4012985e-45,0.9752897,4.1476722,17.999743,93.320152,-11.48223
199.5608,0.86190164,9.3454933,0.0,0,18.0,1.4012985e-45,0.97558153,4.1355805,17.999607,91.246735,-11.481833
200.6608,0.86699367,9.3470125,0.0,0,18.0,1.4012985e-45,0.97580767,4.1562972,18.00041,89.519234,-11.481932
201.7608,0.86024624,9.3482027,0.0,0,18.0,1.4012985e-45,0.97609252,4.1292,18.000843,87.738167,-11.481715
202.8608,0.85985678,9.3495235,0.0,0,18.0,1.4012985e-45,0.97629446,4.1272736,18.001156,85.982864,-11.482018
203.9608,0.8502807,9.3510036,0.0,0,18.0,1.4012985e-45,0.97661227,4.0734282,18.000788,84.2892,-11.481761
205.0608,0.87178063,9.3523254,0.0,0,18.0,1.4012985e-45,0.97682226,4.1809611,17.99954,82.569748,-11.481786
205.8608,0.86022133,9.3524885,0.0,0,18.0,1.4012985e-45,0.97685421,4.1212168,17.999855,81.33226,-11.481453