File: examples/dan-msc-case-studies/CS3/data/01 raw data/baron_test_147.csv
Time(sec),Force(kN),Jaw(mm),PowAngle(deg),Power(W),Pram,PTemp,Strain,Stress(MPa),Stroke(mm),TC1(C),wedge(mm)
0.0,1.1882045,0.16540511,0.0,0,10.594783,0.0014138959,0.011089307,14.988212,10.594305,29.110798,-9.109251
2.2,1.0695493,0.0030566195,0.0,0,10.594783,6.5158749,0.00022605552,13.601446,10.594901,29.011312,-9.4768257
4.4,1.0428586,0.0035846408,0.0,0,10.594783,13.115875,0.00023745673,13.263943,10.595369,28.976765,-9.4735918
6.6,1.0245749,0.0037466967,0.0,0,10.594783,19.715878,0.00025846303,13.047891,10.595036,28.839815,-9.4699688
8.8,1.004939,0.0039996756,0.0,0,10.594783,26.315874,0.00024760049,12.802333,10.595415,28.756641,-9.4664946
11.0,0.98901349,0.0046321373,23.319527,0,10.594783,32.915886,0.00028931812,12.59429,10.594862,28.769268,-9.4625731
13.2,1.0176644,0.0032021042,42.952721,0,10.594783,39.515884,0.00021890568,12.942107,10.594712,30.412151,-9.4596586
15.4,1.0464891,-0.0032271333,51.755592,0,10.594783,46.115879,-0.00019314511,13.333062,10.594865,35.863277,-9.4560995
17.6,1.0709704,-0.013310462,55.701393,0,10.594783,52.715881,-0.00088377116,13.667318,10.595458,44.631653,-9.4522572
19.8,1.0923647,-0.023884377,56.129364,0,10.594783,59.315876,-0.0015842404,13.946464,10.594365,55.591492,-9.4482183
22.0,1.109303,-0.03344512,53.659115,0,10.594783,65.915894,-0.0022412019,14.156315,10.59516,67.303757,-9.444602
24.2,1.1130165,-0.040460974,48.081238,0,10.594783,72.515884,-0.0026972359,14.199135,10.595253,77.916847,-9.4410467
26.4,1.0926824,-0.044412572,42.396992,0,10.594783,79.115875,-0.0029322098,13.950164,10.595527,84.973885,-9.4375324
28.6,1.0751214,-0.045633473,40.572514,0,10.594783,85.715874,-0.0030410027,13.735321,10.594833,89.093147,-9.4344606
30.8,1.0499818,-0.048101202,43.526756,0,10.594783,92.31588,-0.0031929282,13.406934,10.594323,91.718857,-9.4302139
33.0,1.0733507,-0.05229333,48.844822,0,10.594783,98.915871,-0.0034988122,13.708632,10.595375,94.863235,-9.4263935
35.2,1.0985265,-0.058240574,53.314045,0,10.594783,105.51588,-0.003882627,14.026163,10.594194,100.06809,-9.4227905
37.4,1.1164142,-0.06669458,55.239254,0,10.594783,112.11588,-0.0044150488,14.281157,10.59492,107.87094,-9.4189053
39.6,1.13315,-0.074588276,55.535885,0,10.594783,118.71589,-0.0049595498,14.510845,10.595128,116.80191,-9.4156771
41.8,1.130233,-0.082005017,53.332523,0,10.594783,125.31589,-0.0054423106,14.44597,10.594995,126.85394,-9.4121037
44.0,1.1406729,-0.08747483,51.569969,0,10.594783,131.91588,-0.0058293655,14.594082,10.594787,134.37491,-9.4090252
46.2,1.1312498,-0.091528416,50.042728,0,10.594783,138.51588,-0.0060981312,14.486985,10.594718,140.73621,-9.4049978
48.4,1.1326638,-0.095902607,50.042862,0,10.594783,145.11589,-0.0063452306,14.529869,10.594712,145.85718,-9.4013624
50.6,1.1275953,-0.099848427,51.523289,0,10.594783,151.71587,-0.0066325911,14.46659,10.59498,150.76396,-9.3971767
52.8,1.1415436,-0.10572764,53.657223,0,10.594783,158.31587,-0.0070175142,14.649509,10.594068,155.79652,-9.3938866
55.0,1.1397533,-0.1120014,55.044643,0,10.594783,164.91589,-0.0074646808,14.605892,10.594289,162.53999,-9.3903418
57.2,1.156298,-0.11983505,55.843445,0,10.594783,171.51588,-0.0079565719,14.861544,10.594617,169.65804,-9.3869572
59.4,1.1486278,-0.12598392,56.425777,0,10.594783,178.11588,-0.0083496561,14.751309,10.594199,176.61343,-9.383091
61.6,1.1465679,-0.13379531,56.711422,0,10.594783,184.71588,-0.0088637304,14.731634,10.594314,183.83427,-9.3792582
63.8,1.1486462,-0.14105505,56.920334,0,10.594783,191.31589,-0.0093781939,14.75144,10.594488,190.78513,-9.3750782
66.0,1.1515979,-0.14773609,56.133583,0,10.594783,197.91589,-0.0098066097,14.818525,10.594445,198.43373,-9.3720417
68.2,1.1489998,-0.15370181,55.987095,0,10.594783,204.51588,-0.010176023,14.781643,10.594668,205.00928,-9.368947
70.4,1.1355302,-0.15929694,55.84351,0,10.594783,211.11589,-0.010561342,14.613435,10.594483,211.64954,-9.3654404
72.6,1.1409041,-0.16472217,56.087788,0,10.594783,217.71588,-0.01095044,14.674279,10.594307,217.54933,-9.3615866
74.8,1.1514435,-0.17087094,56.711422,0,10.594783,224.31589,-0.011341495,14.815392,10.594454,223.43967,-9.3577394
77.0,1.1461051,-0.17740996,57.609421,0,10.594783,230.91589,-0.011739637,14.761744,10.594275,229.41377,-9.3535194
79.2,1.1411847,-0.18376878,58.337399,0,10.594783,237.5159,-0.012170711,14.702242,10.5946,235.97137,-9.3501768
81.4,1.1484131,-0.19043189,58.948154,0,10.594783,244.11589,-0.012632092,14.810265,10.594954,242.70999,-9.3471937
83.6,1.1503643,-0.19721508,59.047253,0,10.594783,250.7159,-0.01305538,14.834586,10.59511,250.08089,-9.3439569
85.8,1.1578339,-0.20375019,59.348137,0,10.594783,257.31616,-0.013477318,14.940553,10.595448,256.52942,-9.3408422
88.0,1.1603525,-0.21131188,59.684433,0,10.594783,263.91586,-0.013984086,15.006209,10.595594,263.15262,-9.3367605
90.2,1.1622148,-0.21889189,60.314934,0,10.594783,270.51587,-0.014510529,15.013166,10.595383,269.30847,-9.3325377
92.4,1.1595794,-0.22535995,60.787346,0,10.594783,277.11584,-0.014889865,14.986032,10.595666,275.90906,-9.3290062
94.6,1.1541957,-0.23280959,60.787361,0,10.594783,283.71588,-0.015411637,14.912942,10.594467,283.29141,-9.3256502
96.8,1.1531166,-0.23949845,60.77018,0,10.594783,290.31589,-0.015850512,14.90432,10.59452,290.2233,-9.3222914
99.0,1.1532294,-0.24600191,60.551369,0,10.594783,296.91589,-0.016278323,14.933399,10.594962,297.17188,-9.3190689
101.2,1.1504947,-0.2523576,60.382648,0,10.594783,303.51593,-0.016666204,14.896233,10.594432,303.67239,-9.3154039
103.4,1.158051,-0.2578907,60.787346,0,10.594783,310.11591,-0.01704108,14.97865,10.59429,309.64307,-9.3119535
105.6,1.1562488,-0.26420262,61.468273,0,10.594783,316.71588,-0.017478192,14.97722,10.594867,315.57343,-9.307785
107.8,1.1656326,-0.27180904,62.116199,0,10.594783,323.31586,-0.017934594,15.117879,10.594875,321.71912,-9.3044176
110.0,1.1554221,-0.28004557,62.545162,0,10.594783,329.91586,-0.018499758,15.002669,10.594178,328.44858,-9.3005848
112.2,1.1606529,-0.28765213,62.459976,0,10.594783,336.5159,-0.019018482,15.051042,10.594336,336.22479,-9.2969847
114.4,1.1615613,-0.29313734,62.181858,0,10.594783,343.11591,-0.019348163,15.061168,10.594715,343.35193,-9.293539
116.6,1.1581459,-0.2996414,62.116707,0,10.594783,349.71591,-0.0197834,15.039484,10.595037,349.97067,-9.2900639
118.8,1.1539946,-0.30530512,61.907967,0,10.594783,356.31592,-0.020159369,14.996977,10.594825,356.53653,-9.2868052
121.0,1.1514322,-0.31122324,61.907967,0,10.594783,362.91592,-0.020540951,14.978443,10.594396,363.05783,-9.2831621
123.2,1.1583258,-0.31710294,62.336372,0,10.594783,369.51593,-0.020911964,15.063464,10.595199,369.01266,-9.2801189
125.4,1.15852,-0.32277092,62.336433,0,10.594783,376.11588,-0.021285171,15.057142,10.594296,375.9343,-9.2763014
127.6,1.165556,-0.32805821,62.753899,0,10.594783,382.71588,-0.021649688,15.170704,10.594216,382.04358,-9.2730894
129.8,1.1696109,-0.33505964,62.545189,0,10.594783,389.31589,-0.022085158,15.229723,10.594482,389.30865,-9.269433
132.0,1.1676899,-0.3416869,62.285282,0,10.594783,395.91586,-0.022514764,15.200705,10.595213,396.56052,-9.2659416
134.2,1.1574879,-0.34428486,61.741879,0,10.594783,402.5159,-0.022703385,15.063953,10.59432,403.4722,-9.2623644
136.4,1.1522247,-0.35001168,61.688229,0,10.594783,409.11594,-0.023050863,15.008606,10.594927,409.4144,-9.2584648
138.6,1.1571227,-0.35477382,62.429295,0,10.594783,415.71594,-0.023374373,15.090248,10.594439,414.73462,-9.2547665
140.8,1.1505547,-0.36056739,63.386063,0,10.594783,422.31592,-0.023761706,15.002389,10.594975,420.22455,-9.250885
143.0,1.1662832,-0.36695555,63.937019,0,10.594783,428.91589,-0.024159189,15.22662,10.594398,427.42599,-9.2473373
145.2,1.1680907,-0.37421638,64.555656,0,10.594783,435.5159,-0.024634678,15.230134,10.594859,433.62885,-9.2436028
147.4,1.1569564,-0.38053173,64.469261,0,10.594783,442.11591,-0.025059687,15.100991,10.595405,441.75143,-9.2401686
149.6,1.1583862,-0.3851915,63.775642,0,10.594783,448.71591,-0.025352199,15.128207,10.59464,449.69116,-9.2365866
151.8,1.1713775,-0.3886835,60.5462,0,10.594783,449.9989,-0.025589997,15.303473,10.594766,455.78891,-9.2357407
154.0,1.1211069,-0.38827786,55.850185,0,10.594783,449.9989,-0.025554219,14.64869,10.594431,458.4664,-9.2360382
156.2,1.0844555,-0.38469431,51.570229,0,10.594783,449.9989,-0.025317807,14.152103,10.595189,457.6933,-9.235322
158.4,1.0540184,-0.37905097,50.042728,0,10.594783,449.9989,-0.024980195,13.758673,10.59511,454.21204,-9.2354746
160.6,1.0354326,-0.37473238,51.931961,0,10.594783,449.9989,-0.024665959,13.515692,10.594406,449.98663,-9.2356243
162.8,1.0330547,-0.37372467,54.931015,0,10.594783,449.9989,-0.02460433,13.487196,10.594946,446.94571,-9.2355404
165.0,1.0645722,-0.37359205,57.370129,0,10.594783,449.9989,-0.024622831,13.886374,10.595351,446.03845,-9.2356825
167.2,1.0942584,-0.37633669,58.608994,0,10.594783,449.9989,-0.024763439,14.287123,10.594527,446.75107,-9.2355442
169.4,1.1092819,-0.37803185,58.855522,0,10.594783,449.9989,-0.02488371,14.469203,10.594871,448.29236,-9.2355871
171.6,1.1139234,-0.38152191,58.590096,0,10.594783,449.9989,-0.025124373,14.552849,10.594349,449.84189,-9.2359123
173.8,1.1268322,-0.38261336,57.535648,0,10.594783,449.9989,-0.025187332,14.737411,10.59437,451.26929,-9.235651
176.0,1.1164033,-0.38266966,56.243305,0,10.594783,449.9989,-0.025209457,14.556413,10.59485,452.02908,-9.2354069
178.2,1.099306,-0.38399747,54.946972,0,10.594783,449.9989,-0.025268469,14.352787,10.594389,452.02298,-9.2355537
180.4,1.0874964,-0.38248116,54.931644,0,10.594783,449.9989,-0.025163049,14.202391,10.595261,450.82706,-9.2357292
182.6,1.0815568,-0.38187861,55.535885,0,10.594783,449.9989,-0.025154466,14.119522,10.595101,449.75342,-9.2357798
184.8,1.0789143,-0.3826417,56.129147,0,10.594783,449.9989,-0.025174906,14.080288,10.59444,449.18246,-9.2355299
187.0,1.0982877,-0.3831709,56.711422,0,10.594783,449.9989,-0.025222436,14.3284,10.594276,449.00519,-9.2356796
189.2,1.1142818,-0.3836095,57.069801,0,10.594783,449.9989,-0.02526306,14.535628,10.594305,449.21884,-9.2354307
191.4,1.1162244,-0.38453612,56.986088,0,10.594783,449.9989,-0.025321804,14.578911,10.595932,449.74503,-9.235323
193.6,1.1327593,-0.38516074,56.71143,0,10.594783,449.9989,-0.025374038,14.790411,10.594979,450.36877,-9.2359343
195.2807,1.1349398,0.014004798,56.12915,0,10.5948,0.13885607,0.00065916555,14.447552,10.596416,450.81659,-9.2356224
195.2851,1.1292963,0.0092581147,56.12915,0,10.5948,1.3851730000000002e-31,0.00045983173,14.393892,10.594183,450.77707,-9.2355766
195.2895,1.1076305,0.015012559,52.199986,0,10.5948,0.0,0.00072776788,14.186219,10.593662,450.74384,-9.2361526
195.2939,1.1654602,0.010131801,27.50316,0,10.5948,0.0,0.00059408863,14.804849,10.594429,450.74384,-9.2370796
195.2983,1.139284,0.015488206,2.8063345,0,10.5948,0.0,0.00079186895,14.467679,10.594832,450.74384,-9.2371826
195.3027,1.1289403,0.010862048,0.0,0,10.5948,0.0,0.00059380074,14.405201,10.594171,450.76718,-9.2348738
195.3071,1.1040599,0.013733503,0.0,0,10.5948,0.0,0.00067993015,14.02327,10.597532,450.79352,-9.2359161
195.3115,1.1103516,0.0098705767,0.0,0,10.5948,0.0,0.00056781515,14.092994,10.59351,450.77136,-9.2352104
195.3159,1.1248565,0.01376264,0.0,0,10.5948,0.0,0.00076355354,14.249326,10.594604,450.71866,-9.2349911
195.3203,1.1133358,0.0099710114,0.0,0,10.5948,0.0,0.0006107823,14.216263,10.594772,450.6929,-9.235795
195.3247,1.0856394,0.014637344,0.0,0,10.5948,0.0,0.00082650164,13.883049,10.593956,450.71927,-9.2356958
195.3291,1.0991057,0.010068501,0.0,0,10.5948,0.0,0.00069085375,13.82544,10.594754,450.74384,-9.2364149
195.3335,1.1161314,0.014445544,0.0,0,10.545863,0.0,0.00082904095,14.16035,10.59384,450.74384,-9.2343445
195.3379,1.102915,0.010595241,0.0,0,10.479863,0.0,0.00069616653,13.99414,10.590419,450.74384,-9.2347364
195.3423,1.0876939,0.013721784,0.0,0,10.413863,0.0,0.00077837595,13.831416,10.55899,450.72287,-9.2356138
195.3467,1.0719857,0.01093305,0.0,0,10.347863,0.0,0.00076667336,13.709242,10.482944,450.6965,-9.2356558
195.3511,1.0895654,0.013020647,0.0,0,10.281863,0.0,0.00081210828,13.706897,10.375422,450.70459,-9.2350922
195.3555,1.0913805,0.011372041,0.0,0,10.215863,0.0,0.00074483687,13.902357,10.290449,450.74411,-9.2358236
195.3599,1.0797364,0.012944703,0.0,0,10.149863,0.0,0.00085678708,13.717507,10.23325,450.77045,-9.235652
195.3643,1.0605276,0.0108658,0.0,0,10.083863,0.0,0.00079237728,13.5569,10.183541,450.75729,-9.2350893
195.3687,1.0878211,0.013073518,0.0,0,10.017863,0.0,0.00090960605,13.76691,10.119793,450.74414,-9.2361212
195.3731,1.5473102,0.012534711,0.0,0,9.9518633,0.0,0.00089811167,19.426556,10.051425,451.91547,-9.2361174
195.3775,3.6951807,0.041789871,0.0,0,9.8858633,0.0,0.0028605699,46.802376,9.9843435,453.11435,-9.2344446
195.3819,4.190599,0.10775981,0.0,0,9.8198633,0.0,0.0072037526,52.912849,9.9148102,455.15732,-9.2326775
195.3863,4.4355989,0.17801952,0.0,0,9.7538633,0.0,0.012006494,55.825562,9.8379011,457.55426,-9.2324772
195.3907,4.5206418,0.2419641,0.0,0,9.6878624,0.0,0.016347984,56.682652,9.7735634,459.638,-9.2324476
195.3951,4.5794287,0.3054899,0.0,0,9.6218634,0.0,0.020704998,57.096279,9.707077,461.30963,-9.2326498
195.3995,4.6738143,0.36576629,0.0,0,9.5558634,0.0,0.024735795,58.020359,9.6428738,462.85767,-9.2328424
195.4039,4.7410955,0.43703783,0.0,0,9.4898634,0.0,0.029713495,58.638039,9.5706968,463.75235,-9.2318649
195.4083,4.7654076,0.50342494,0.0,0,9.4252853,0.0,0.034176406,58.631889,9.5015974,464.64706,-9.2343025
195.4127,4.7463002,0.56731755,0.0,0,9.3609047,0.0,0.038744301,58.16272,9.438117,465.28516,-9.2348442
195.4171,4.7877502,0.62933999,0.0,0,9.2965231,0.0,0.043023083,58.568016,9.3753347,465.89038,-9.234642
195.4215,4.8426046,0.69365734,0.0,0,9.2321424,0.0,0.047534317,58.730022,9.3093071,466.38257,-9.2345104
195.4259,4.8883791,0.75589198,0.0,0,9.1677618,0.0,0.051931493,59.143238,9.2420111,466.80362,-9.2352972
195.4303,4.8954577,0.8267985,0.0,0,9.1033812,0.0,0.056898549,58.833073,9.1745701,467.15289,-9.2342968
195.4347,4.9081235,0.8902142,0.0,0,9.0390005,0.0,0.061307378,58.810421,9.1102428,467.36337,-9.2343884
195.4391,4.9370637,0.951379,0.0,0,8.9746189,0.0,0.065684415,58.830616,9.0442371,467.56763,-9.2341843
195.4435,4.9546494,1.0110589,0.0,0,8.9102392,0.0,0.069984347,58.877636,8.9826069,467.68604,-9.2335291
195.4479,5.0081592,1.07558,0.0,0,8.8458576,0.0,0.074617647,59.193768,8.917572,467.80444,-9.2316799
195.4523,5.0125704,1.1422088,0.0,0,8.781476,0.0,0.079297803,58.96138,8.8517981,467.99612,-9.2348413
195.4567,5.057384,1.2047095,0.0,0,8.7187157,0.0,0.084017277,59.142368,8.7819099,468.20663,-9.2335615
195.4611,5.0789895,1.2717491,0.0,0,8.657486,0.0,0.088716775,59.215546,8.7147713,468.36899,-9.2339954
195.4655,5.0684438,1.3289655,0.0,0,8.5962553,0.0,0.093065128,58.769093,8.6562128,468.48743,-9.2335663
195.4699,5.052629,1.3897797,0.0,0,8.5350256,0.0,0.097431585,58.364063,8.5947475,468.25388,-9.2335796
195.4743,5.1138515,1.4494164,0.0,0,8.4737949,0.0,0.10184482,58.720806,8.5358753,466.96448,-9.2340336
195.4787,5.1493626,1.510506,0.0,0,8.4125643,0.0,0.106322,59.018246,8.471468,465.67508,-9.2324944
195.4831,5.1782312,1.5728189,0.0,0,8.3513327,0.0,0.11086241,59.002171,8.4059172,464.43713,-9.2327757
195.4875,5.1802411,1.6375049,0.0,0,8.290103,0.0,0.11568922,58.70208,8.3448286,463.20035,-9.2336674
195.4919,5.1917272,1.6960583,0.0,0,8.2288723,0.0,0.12001202,58.624733,8.2847824,463.06671,-9.232955
195.4963,5.2309394,1.7565892,0.0,0,8.1676426,0.0,0.1245952,58.837116,8.2251816,463.39563,-9.233674
195.5007,5.2558656,1.8177681,0.0,0,8.1064119,0.0,0.12926096,58.851967,8.1646461,463.76434,-9.2341261
195.5051,5.2721715,1.8818139,0.0,0,8.0456295,0.0,0.13403077,58.708275,8.096571,464.18536,-9.2324486
195.5095,5.2874203,1.9406222,0.0,0,7.9873738,0.0,0.1385465,58.576408,8.0366068,464.58804,-9.2340908
195.5139,5.3464637,2.0039575,0.0,0,7.9291172,0.0,0.14335749,58.928165,7.9727364,464.89371,-9.2338085
195.5183,5.3154302,2.0580935,0.0,0,7.8708615,0.0,0.14749506,58.4263,7.9154844,465.19937,-9.2346745
195.5227,5.3042631,2.1151168,0.0,0,7.8126054,0.0,0.15192603,57.962944,7.8591189,465.45441,-9.2332277
195.5271,5.3442092,2.16787,0.0,0,7.7543492,0.0,0.15602221,58.186119,7.8046589,465.70438,-9.2327423
195.5315,5.3954401,2.2291656,0.0,0,7.696094,0.0,0.1607949,58.461876,7.7451477,466.01297,-9.2341843
195.5359,5.4335961,2.2848058,0.0,0,7.6378374,0.0,0.16513266,58.695248,7.6834183,466.35507,-9.2345829
195.5403,5.4456396,2.3481293,0.0,0,7.5795817,0.0,0.1701041,58.519691,7.6250315,466.51056,-9.2336426
195.5447,5.461441,2.4057202,0.0,0,7.5213251,0.0,0.17464663,58.362297,7.5646529,466.33951,-9.2339706
195.5491,5.4956355,2.4674363,0.0,0,7.4630694,0.0,0.1795222,58.402939,7.4998431,466.08356,-9.2319098
195.5535,5.5192261,2.5215895,0.0,0,7.4048128,0.0,0.18388014,58.495708,7.4456439,464.97836,-9.2339058
195.5579,5.5049958,2.5816054,0.0,0,7.3488011,0.0,0.18865773,58.049797,7.3884139,463.87317,-9.2330627
195.5623,5.511292,2.6339164,0.0,0,7.2933965,0.0,0.19277892,57.942181,7.3303022,463.0694,-9.2324085
195.5667,5.5332665,2.689904,0.0,0,7.2379913,0.0,0.19733892,57.787632,7.2742395,462.33258,-9.2335196
195.5711,5.5970001,2.7447748,0.0,0,7.1825867,0.0,0.20186922,58.213425,7.2209654,462.05508,-9.2332354
195.5755,5.6076765,2.805547,0.0,0,7.1271815,0.0,0.20670307,58.060699,7.163229,462.16037,-9.2349424
195.5799,5.6329679,2.8561857,0.0,0,7.0717773,0.0,0.21101628,58.068848,7.1093969,462.27997,-9.2327957
195.5843,5.6665678,2.9187279,0.0,0,7.0163722,0.0,0.21599871,58.094124,7.0484223,462.43784,-9.2325201
195.5887,5.6705689,2.9703276,0.0,0,6.9609675,0.0,0.22040054,57.922089,6.9944663,462.59573,-9.2341499
195.5931,5.6977677,3.0298038,0.0,0,6.9055629,0.0,0.22515595,57.956902,6.9388452,462.77994,-9.2327528
195.5975,5.7132483,3.0812714,0.0,0,6.8501582,0.0,0.22958493,57.810253,6.8796377,462.96414,-9.2340174
195.6019,5.7181826,3.1397409,0.0,0,6.7947526,0.0,0.23432319,57.564022,6.8280268,463.29187,-9.2331476
195.6063,5.7758956,3.1867788,0.0,0,6.7404881,0.0,0.23867595,57.93008,6.7710562,463.6734,-9.2331467
195.6107,5.8178554,3.2498496,0.0,0,6.6877761,0.0,0.24369778,57.995033,6.7141547,464.02505,-9.233593
195.6151,5.8045855,3.297992,0.0,0,6.6350636,0.0,0.24807668,57.704102,6.6598496,464.34082,-9.2346067
195.6195,5.8012147,3.357507,0.0,0,6.5823522,0.0,0.25294644,57.307823,6.6052594,464.65182,-9.2342606
195.6239,5.796608,3.4028728,0.0,0,6.5296402,0.0,0.25704071,56.994076,6.5530548,464.94128,-9.2353783
195.6283,5.8338614,3.4556804,0.0,0,6.4769282,0.0,0.2614446,57.202641,6.5027385,465.23074,-9.2326498
195.6327,5.860002,3.5030165,0.0,0,6.4242163,0.0,0.26571035,57.20248,6.4521556,465.65176,-9.2332935
195.6371,5.8822722,3.5574436,0.0,0,6.3715043,0.0,0.27032802,57.140327,6.4025626,466.08594,-9.232645
195.6415,5.945488,3.6086187,0.0,0,6.3187923,0.0,0.27498356,57.465298,6.3478136,466.41965,-9.2336302
195.6459,5.9724565,3.666754,0.0,0,6.2660804,0.0,0.27995846,57.471184,6.2950873,466.69595,-9.2349453
195.6503,5.9896111,3.7147386,0.0,0,6.2133684,0.0,0.28430781,57.455456,6.2355113,466.89569,-9.2316074
195.6547,5.9914546,3.7714503,0.0,0,6.1608109,0.0,0.28923529,57.080563,6.183733,466.96149,-9.2348661
195.6591,6.0115242,3.8205545,0.0,0,6.1106763,0.0,0.29381898,57.041439,6.1352053,467.0488,-9.2332792
195.6635,6.0632648,3.8742435,0.0,0,6.0605431,0.0,0.29862976,57.25946,6.0800619,467.35141,-9.2340641
195.6679,6.071981,3.9238873,0.0,0,6.0104094,0.0,0.30316237,56.963211,6.0300283,467.65402,-9.233057
195.6723,6.0645676,3.9764113,0.0,0,5.9602757,0.0,0.30790204,56.76878,5.9790359,467.98892,-9.2326508
195.6767,6.0500216,4.0207987,0.0,0,5.9101424,0.0,0.31207025,56.380344,5.9277411,468.33102,-9.234973
195.6811,6.1138945,4.0741796,0.0,0,5.8600087,0.0,0.31681892,56.677132,5.8809376,468.40756,-9.2340851
195.6855,6.1618361,4.1193333,0.0,0,5.809875,0.0,0.32111683,56.830791,5.8295398,468.26285,-9.2333775
195.6899,6.1948137,4.174933,0.0,0,5.7597413,0.0,0.32616374,56.983566,5.7773914,468.15759,-9.2341166
195.6943,6.1786542,4.2238827,0.0,0,5.7096076,0.0,0.33076295,56.515747,5.7237511,468.15759,-9.2342329
195.6987,6.1793776,4.2725096,0.0,0,5.6594744,0.0,0.33534414,56.216923,5.6781116,468.15759,-9.2327347
195.7031,6.2360802,4.3167286,0.0,0,5.6093407,0.0,0.33949858,56.544441,5.6299767,468.39441,-9.2336149
195.7075,6.2990837,4.369616,0.0,0,5.5609035,0.0,0.34455925,56.902626,5.5773702,468.63126,-9.2334499
195.7119,6.2520285,4.4166384,0.0,0,5.5132074,0.0,0.34887978,56.158199,5.5283914,468.69583,-9.2329283
195.7163,6.2894516,4.469234,0.0,0,5.4655118,0.0,0.35398802,56.123341,5.4771857,468.69583,-9.2352829
195.7207,6.3436499,4.5117393,0.0,0,5.4178157,0.0,0.35795519,56.468098,5.4295592,468.58221,-9.2331514
195.7251,6.384007,4.563756,0.0,0,5.3701196,0.0,0.36310408,56.484917,5.3817711,468.33221,-9.2321644
195.7295,6.3682075,4.611073,0.0,0,5.3224235,0.0,0.36763656,56.215908,5.3312321,468.04636,-9.2327232
195.7339,6.3592858,4.6581683,0.0,0,5.2747283,0.0,0.37213311,55.773079,5.2878594,467.59903,-9.2327089
195.7383,6.3997159,4.7013922,0.0,0,5.2270317,0.0,0.37641472,55.891254,5.2391686,467.1517,-9.2342939
195.7427,6.4499583,4.7461996,0.0,0,5.1793361,0.0,0.38086775,56.12672,5.1976147,467.02728,-9.2335272
195.7471,6.4871407,4.7966566,0.0,0,5.13164,0.0,0.38566855,56.101524,5.1463451,466.93518,-9.2341452
195.7515,6.5008831,4.8429594,0.0,0,5.0839438,0.0,0.3903119,56.006306,5.0995693,467.18634,-9.2321472
195.7559,6.6121721,4.8923674,0.0,0,5.0370226,0.0,0.39517105,56.635365,5.0482693,467.6337,-9.2324543
195.7603,6.6165962,4.9445162,0.0,0,4.9916592,0.0,0.40037096,56.534286,5.0001669,468.01407,-9.2333326
195.7647,6.5788193,4.99224,0.0,0,4.9462948,0.0,0.40500593,55.897903,4.9505053,468.27719,-9.2335377
195.7691,6.5570898,5.034646,0.0,0,4.9009309,0.0,0.40949485,55.434093,4.9078774,468.27237,-9.2332697
195.7735,6.6011424,5.0787444,0.0,0,4.8555665,0.0,0.41375875,55.511108,4.8614922,465.58768,-9.2327833
195.7779,6.6086297,5.1212678,0.0,0,4.8102031,0.0,0.41810104,55.369164,4.8198805,462.90298,-9.2315645
195.7823,6.6271839,5.1626139,0.0,0,4.7648387,0.0,0.4222118,55.33836,4.7776303,459.00018,-9.2342787
195.7867,6.6874943,5.2049623,0.0,0,4.7194748,0.0,0.42667595,55.598541,4.7374015,454.82666,-9.2328672
195.7911,6.7621775,5.257237,0.0,0,4.6741109,0.0,0.43173531,55.838562,4.6875277,451.93076,-9.2337456
195.7955,6.826735,5.2998915,0.0,0,4.628747,0.0,0.43627015,56.171474,4.6369753,450.09946,-9.2335138
195.7999,6.8307438,5.3527212,0.0,0,4.5833831,0.0,0.44164756,55.958157,4.59162,448.80353,-9.2333202
195.8043,6.8227997,5.3956466,0.0,0,4.5380187,0.0,0.44608325,55.656689,4.5462427,448.9353,-9.2337036
195.8087,6.8428359,5.4461861,0.0,0,4.4947944,0.0,0.45135462,55.432381,4.4982443,449.06705,-9.2330761
195.8131,6.8815346,5.4852881,0.0,0,4.4516392,0.0,0.45540404,55.534798,4.4554958,450.39771,-9.2337065
195.8175,6.887537,5.5291977,0.0,0,4.408484,0.0,0.46008527,55.368832,4.4076133,451.72833,-9.2342911
195.8219,6.8867288,5.5718312,0.0,0,4.3653288,0.0,0.46446082,55.115429,4.3680382,453.18353,-9.2328625
195.8263,6.8820739,5.6116786,0.0,0,4.3221736,0.0,0.46866056,54.817329,4.3279724,454.68546,-9.2355347
195.8307,6.9752827,5.6542101,0.0,0,4.2790184,0.0,0.47313327,55.370125,4.2843661,455.91788,-9.2342558
195.8351,7.0435438,5.6991687,0.0,0,4.2358632,0.0,0.47793907,55.580437,4.2401614,456.8269,-9.2334633
195.8395,7.0253177,5.7407475,0.0,0,4.192708,0.0,0.482418,55.211235,4.201231,457.64734,-9.2342196
195.8439,7.0512614,5.7849193,0.0,0,4.1495528,0.0,0.48718816,55.192642,4.1544251,458.06888,-9.2335711
195.8483,7.1285172,5.8268843,0.0,0,4.1063976,0.0,0.49166673,55.512161,4.1104088,458.49042,-9.2338028
195.8527,7.1939726,5.8749251,0.0,0,4.0632424,0.0,0.49679318,55.764023,4.0685186,458.82788,-9.2339945
195.8571,7.2018027,5.9169464,0.0,0,4.0213647,0.0,0.50143397,55.582409,4.0246816,459.15689,-9.2352438
195.8615,7.2048049,5.9653945,0.0,0,3.9803219,0.0,0.50663286,55.331619,3.9783871,459.78729,-9.2341089
195.8659,7.2032356,6.0047159,0.0,0,3.9392786,0.0,0.51114655,54.975616,3.9357316,460.58987,-9.2323399
195.8703,7.1682558,6.0449281,0.0,0,3.8982356,0.0,0.51549137,54.510651,3.9011054,461.39725,-9.2342863
195.8747,7.2458606,6.0806417,0.0,0,3.8571923,0.0,0.51939678,54.903324,3.863013,462.21298,-9.2334108
195.8791,7.3118205,6.1244593,0.0,0,3.816149,0.0,0.52432603,55.103207,3.8189073,463.01318,-9.234642
195.8835,7.3832297,6.1659441,0.0,0,3.775106,0.0,0.52913505,55.36639,3.7785876,463.65787,-9.2335892
195.8879,7.4373374,6.2117434,0.0,0,3.7340627,0.0,0.53419203,55.480881,3.7336042,464.30258,-9.2330961
195.8923,7.4584341,6.2526159,0.0,0,3.6930194,0.0,0.53880018,55.385475,3.6899762,464.99036,-9.2336597
195.8967,7.4396996,6.2964215,0.0,0,3.6519761,0.0,0.54375547,55.030041,3.6491451,465.68768,-9.2331972
195.9011,7.4404035,6.3335257,0.0,0,3.6109331,0.0,0.54803705,54.726017,3.6101213,466.25583,-9.2338505
195.9055,7.4599104,6.3733048,0.0,0,3.5703723,0.0,0.55257225,54.670555,3.5734406,466.71631,-9.2337084
195.9099,7.5788579,6.4109206,0.0,0,3.5313265,0.0,0.55700952,55.240864,3.5343504,467.14093,-9.2329054
195.9143,7.6360974,6.4558883,0.0,0,3.492281,0.0,0.56213087,55.43539,3.494477,467.46985,-9.2348118
195.9187,7.6424947,6.4951115,0.0,0,3.4532356,0.0,0.56685108,55.187935,3.4518318,467.79877,-9.2335882
195.9231,7.698925,6.5399837,0.0,0,3.4141898,0.0,0.57199746,55.319595,3.4075823,468.12769,-9.2335348
195.9275,7.6912622,6.5755696,0.0,0,3.375144,0.0,0.57641423,55.006405,3.3703022,468.4566,-9.2329006
195.9319,7.6927133,6.6173964,0.0,0,3.3360984,0.0,0.58114433,54.808689,3.333308,468.59418,-9.2332716
195.9363,7.6752095,6.6493974,0.0,0,3.2970531,0.0,0.58530635,54.449619,3.2951181,468.65994,-9.2349882
195.9407,7.7832408,6.6920571,0.0,0,3.2580075,0.0,0.59006864,54.93325,3.260005,468.3071,-9.2342281
195.9451,7.9207711,6.72473,0.0,0,3.218962,0.0,0.59436351,55.663033,3.2177935,467.45187,-9.2335215
195.9495,7.9608431,6.7723613,0.0,0,3.1799161,0.0,0.59987599,55.638508,3.1818769,466.52731,-9.2322206
195.9539,7.9547524,6.8103051,0.0,0,3.1408706,0.0,0.60481828,55.353458,3.1374002,465.29053,-9.2337704
195.9583,7.9505935,6.8516355,0.0,0,3.1034935,0.0,0.60956889,54.973431,3.0997996,464.05377,-9.2328987
195.9627,7.9793816,6.8837485,0.0,0,3.0663486,0.0,0.61390775,54.977383,3.0637343,463.63037,-9.2333803
195.9671,8.0514908,6.9250708,0.0,0,3.0292039,0.0,0.61881959,55.233425,3.0224993,463.28827,-9.2330122
195.9715,8.0584469,6.9584637,0.0,0,2.9920592,0.0,0.62307686,55.064171,2.9863067,463.15552,-9.234189
195.9759,8.0862989,7.0001597,0.0,0,2.9549143,0.0,0.62804878,54.907711,2.9481277,463.14233,-9.2338181
195.9803,8.1435423,7.0311708,0.0,0,2.9177694,0.0,0.63231379,55.079243,2.9155595,463.18658,-9.2330379
195.9847,8.2240553,7.0724306,0.0,0,2.8806245,0.0,0.63734788,55.32196,2.8796053,463.33133,-9.2346497
195.9891,8.2592754,7.1043491,0.0,0,2.8434799,0.0,0.6415177,55.393337,2.8443854,463.53345,-9.2345276
195.9935,8.2992859,7.1467085,0.0,0,2.806335,0.0,0.64683831,55.327805,2.8036819,464.30975,-9.233799
195.9979,8.4034777,7.1816998,0.0,0,2.7691901,0.0,0.65146494,55.762978,2.7697532,465.08603,-9.2343102
196.0023,8.4483557,7.2262502,0.0,0,2.7320457,0.0,0.65712726,55.757263,2.726455,465.7977,-9.2342777
196.0067,8.4222069,7.2564588,0.0,0,2.695833,0.0,0.66122025,55.423683,2.6952295,466.49503,-9.2326756
196.0111,8.4399309,7.2980881,0.0,0,2.660501,0.0,0.66663593,55.201107,2.6554637,466.99139,-9.232954
196.0155,8.5173731,7.3280344,0.0,0,2.625169,0.0,0.67059118,55.425247,2.6210356,467.32031,-9.2344742
196.0199,8.603631,7.3679433,0.0,0,2.5898368,0.0,0.67590368,55.693752,2.5842354,467.57388,-9.2338552
196.0243,8.6116877,7.3995938,0.0,0,2.5545049,0.0,0.68012154,55.528011,2.5486021,467.62653,-9.2334843
196.0287,8.6066189,7.4380221,0.0,0,2.5191729,0.0,0.68523878,55.301437,2.5134964,467.67914,-9.2346945
196.0331,8.6367311,7.469502,0.0,0,2.4838407,0.0,0.68939549,55.20269,2.4791448,467.75809,-9.2344933
196.0375,8.7668028,7.505322,0.0,0,2.4485087,0.0,0.69433218,55.709785,2.4455688,467.83704,-9.2322216
196.0419,8.8425875,7.5390854,0.0,0,2.4131768,0.0,0.69881314,56.037735,2.4111578,468.08823,-9.2342548
196.0463,8.8903446,7.5779386,0.0,0,2.3778448,0.0,0.70410526,55.974346,2.3711808,468.40399,-9.2347565
196.0507,8.9132881,7.6120048,0.0,0,2.3425128,0.0,0.70870203,55.84626,2.3361764,468.20544,-9.2353745
196.0551,8.9903421,7.6464925,0.0,0,2.3074405,0.0,0.71349853,56.082172,2.2981625,467.38968,-9.2336817
196.0595,9.0747929,7.6809144,0.0,0,2.2738333,0.0,0.71811062,56.345291,2.2686477,465.78622,-9.2334518
196.0639,9.037797,7.7185707,0.0,0,2.240226,0.0,0.72335446,55.847927,2.2350791,460.63797,-9.235322
196.0683,9.1087093,7.7480011,0.0,0,2.206619,0.0,0.72737366,56.039726,2.2004204,455.48972,-9.232645
196.0727,9.1474676,7.7832937,0.0,0,2.1730118,0.0,0.73248547,55.930145,2.1646116,448.06039,-9.2354527
196.0771,9.1993971,7.8157649,0.0,0,2.1394045,0.0,0.73690438,56.056129,2.1327782,440.40295,-9.2335415
196.0815,9.2167206,7.847846,0.0,0,2.1057973,0.0,0.74131268,55.965984,2.1020184,434.46887,-9.2348242
196.0859,9.2799711,7.8805838,0.0,0,2.0721903,0.0,0.74594951,56.036411,2.0723412,429.51956,-9.2331476
196.0903,9.4091692,7.9159017,0.0,0,2.038583,0.0,0.7510041,56.545326,2.0343022,426.58115,-9.2335796
196.0947,9.5061302,7.9486189,0.0,0,2.0049758,0.0,0.75545973,56.824612,1.9986689,427.16174,-9.2350092
196.0991,9.5459957,7.9829559,0.0,0,1.9713686,0.0,0.76053113,56.858414,1.9624562,427.91882,-9.2328396
196.1035,9.5297489,8.0163212,0.0,0,1.9377614,0.0,0.76513577,56.453465,1.9330902,430.44098,-9.2330189
196.1079,9.5976353,8.0496244,0.0,0,1.9054422,0.0,0.76996058,56.560173,1.9009063,432.96313,-9.23283
196.1123,9.683959,8.0799208,0.0,0,1.8734717,0.0,0.77422369,56.822945,1.866852,434.05869,-9.2340097
196.1167,9.7686567,8.1155787,0.0,0,1.8415015,0.0,0.77946448,57.048931,1.8347551,434.83719,-9.2333355
196.1211,9.7527723,8.1465797,0.0,0,1.8095311,0.0,0.78386724,56.760685,1.7996689,435.3638,-9.2339182
196.1255,9.8126869,8.1762314,0.0,0,1.7775607,0.0,0.78819203,56.783154,1.7699672,435.68048,-9.2325668
196.1299,9.8855343,8.2109699,0.0,0,1.7455902,0.0,0.79311252,56.901077,1.7379646,436.21667,-9.2327051
196.1343,9.9503918,8.2400398,0.0,0,1.7136198,0.0,0.7975775,57.072422,1.7078059,437.33829,-9.232914
196.1387,9.9886045,8.2731047,0.0,0,1.6816494,0.0,0.80229431,57.032425,1.6791197,438.45987,-9.2336874
196.1431,10.068333,8.3032112,0.0,0,1.6496789,0.0,0.80668139,57.216377,1.6489872,440.99191,-9.2329817
196.1475,10.256684,8.3365211,0.0,0,1.6177086,0.0,0.81163049,57.96944,1.6128839,443.52396,-9.2345343
196.1519,10.355667,8.3726521,0.0,0,1.5857382,0.0,0.81693417,58.253674,1.5828454,445.76733,-9.2331533
196.1563,10.402616,8.4056911,0.0,0,1.5544271,0.0,0.82194084,58.242863,1.5471667,447.90244,-9.2335281
196.1607,10.406983,8.4396687,0.0,0,1.5240144,0.0,0.82708573,57.974957,1.5142196,449.71381,-9.2334929
196.1651,10.495719,8.4723396,0.0,0,1.4936016,0.0,0.83192229,58.121773,1.480763,451.13669,-9.2339411
196.1695,10.557823,8.5035248,0.0,0,1.4631886,0.0,0.83678079,58.235363,1.451776,452.50684,-9.2328329
196.1739,10.579856,8.5349083,0.0,0,1.4327759,0.0,0.84148252,58.081795,1.4209411,453.63986,-9.2339649
196.1783,10.53819,8.5610514,0.0,0,1.4023631,0.0,0.84562314,57.560253,1.392115,454.77286,-9.2351313
196.1827,10.592154,8.5943718,0.0,0,1.3719503,0.0,0.85057586,57.565155,1.3639952,455.48669,-9.2340384
196.1871,10.741988,8.6177158,0.0,0,1.3415375,0.0,0.85415256,58.174519,1.333737,456.15863,-9.2336712
196.1915,10.8799,8.6502876,0.0,0,1.3111248,0.0,0.85921061,58.657001,1.3047216,456.47839,-9.2320557
196.1959,11.008725,8.6806726,0.0,0,1.2807119,0.0,0.86389977,59.073406,1.2746485,456.59698,-9.2339478
196.2003,11.093903,8.7153215,0.0,0,1.2502991,0.0,0.86922097,59.202259,1.2397012,456.6868,-9.2344542
196.2047,11.167389,8.7445183,0.0,0,1.2199754,0.0,0.87399328,59.295139,1.2081317,456.72632,-9.2332001
196.2091,11.147263,8.7780771,0.0,0,1.1910495,0.0,0.87918729,58.957188,1.182606,456.80539,-9.2335005
196.2135,11.130551,8.8017082,0.0,0,1.1621238,0.0,0.88301331,58.600044,1.1509291,457.27966,-9.2328434
196.2179,11.173018,8.8322544,0.0,0,1.1331981,0.0,0.88788509,58.552132,1.1252832,457.75394,-9.2327337
196.2223,11.345156,8.8550348,0.0,0,1.1042726,0.0,0.89169747,59.169952,1.1013124,458.26035,-9.2352657
196.2267,11.50076,8.8904486,0.0,0,1.0753471,0.0,0.89713991,59.692406,1.0715418,458.7739,-9.2346849
196.2311,11.592414,8.9169197,0.0,0,1.0464214,0.0,0.90155542,59.958664,1.0439239,459.05042,-9.2341347
196.2355,11.68406,8.9507923,0.0,0,1.0174959,0.0,0.90714127,60.013016,1.0095007,459.12939,-9.2325716
196.2399,11.785228,8.9781361,0.0,0,0.98857015,0.0,0.91176987,60.264359,0.97821182,459.1402,-9.2332735
196.2443,11.808395,9.012044,0.0,0,0.9596445,0.0,0.9170115,60.097965,0.95043856,458.96918,-9.2339458
196.2487,11.812329,9.0344219,0.0,0,0.93071896,0.0,0.92119002,59.920147,0.92212552,458.79813,-9.2329664
196.2531,11.828604,9.0642633,0.0,0,0.9017933,0.0,0.92587346,59.710651,0.8953141,458.98233,-9.2328825
196.2575,11.943254,9.0871124,0.0,0,0.87385386,0.0,0.93007916,59.956371,0.86540884,459.16653,-9.2329159
196.2619,12.154753,9.118988,0.0,0,0.84634501,0.0,0.93519127,60.724625,0.83951443,459.32202,-9.2324305
196.2663,12.296538,9.1430845,0.0,0,0.81883621,0.0,0.93978417,61.198849,0.80973685,459.46677,-9.2331285
196.2707,12.363897,9.1779709,0.0,0,0.79132742,0.0,0.94540715,61.171059,0.77646881,459.64139,-9.2329016
196.2751,12.363789,9.2038879,0.0,0,0.76381862,0.0,0.94999003,60.85466,0.74822676,459.8519,-9.2338667
196.2795,12.421268,9.2339411,0.0,0,0.73630983,0.0,0.95504791,60.838543,0.72349864,460.11743,-9.2329664
196.2839,12.390918,9.2539778,0.0,0,0.70880103,0.0,0.95892507,60.466194,0.69798994,460.63055,-9.2330275
196.2883,12.432836,9.2811012,0.0,0,0.68129224,0.0,0.96352422,60.440125,0.67794728,461.14368,-9.2342901
196.2927,12.638316,9.3017597,0.0,0,0.65378344,0.0,0.96736062,61.096333,0.64916587,461.60898,-9.2338886
196.2971,12.862728,9.3324194,0.0,0,0.62627465,0.0,0.97256613,61.884644,0.62136543,462.06946,-9.234086
196.3015,13.002072,9.3588476,0.0,0,0.59876585,0.0,0.97742915,62.286613,0.59268636,461.60031,-9.233037
196.3059,13.050789,9.3890924,0.0,0,0.57169873,0.0,0.98276603,62.194481,0.56275755,460.59998,-9.2325363
196.3103,13.017347,9.4104433,0.0,0,0.5455187,0.0,0.98687738,61.840508,0.53692746,459.18771,-9.2327576
196.3147,12.057421,9.4193611,0.0,0,0.51933873,0.0,0.98827738,57.175053,0.52052122,457.0546,-9.233285
196.3191,11.469856,9.4175034,0.0,0,0.4931587,0.0,0.98841226,54.335529,0.49847025,455.02917,-9.2346029
196.3235,11.055481,9.4297523,0.0,0,0.46697873,0.0,0.99039298,52.284286,0.49003163,454.0806,-9.2357302
196.3279,10.80336,9.429924,0.0,0,0.4407987,0.0,0.99063277,51.074036,0.46736664,453.13202,-9.2349873
196.3323,10.564641,9.4344215,0.0,0,0.41461873,0.0,0.99152064,49.935379,0.45059094,453.13202,-9.2328634
196.3367,10.275353,9.4366484,0.0,0,0.38843867,0.0,0.99198157,48.563869,0.42905724,453.3428,-9.2358255
196.3411,9.8895693,9.4396706,0.0,0,0.36225867,0.0,0.99268669,46.687099,0.41512045,453.82669,-9.2346087
196.3455,9.4862432,9.4372129,0.0,0,0.33607867,0.0,0.99235243,44.800392,0.41255206,454.53812,-9.2361116
196.3499,9.2296009,9.4419804,0.0,0,0.30989867,0.0,0.99325651,43.540478,0.40598345,455.228,-9.2342968
196.3543,9.219491,9.437685,0.0,0,0.28371871,0.0,0.99260867,43.487209,0.38835323,455.86038,-9.235652
196.3587,9.4136639,9.443574,0.0,0,0.25878334,0.0,0.99386376,44.35191,0.36291355,456.49277,-9.236125
196.3631,9.6624432,9.4444885,0.0,0,0.23388813,0.0,0.99389583,45.53656,0.32691586,456.70358,-9.2351093
196.3675,9.8210535,9.4506702,0.0,0,0.20899297,0.0,0.99505985,46.230061,0.29540536,456.91437,-9.234293
196.3719,9.8989773,9.4484034,0.0,0,0.18409778,0.0,0.99478322,46.607616,0.26412341,457.04849,-9.2331734
196.3763,9.9500217,9.4562912,0.0,0,0.15920259,0.0,0.99610049,46.804794,0.23033085,457.15387,-9.2340117
196.3807,9.9506569,9.4524641,0.0,0,0.13430737,0.0,0.99552679,46.880161,0.2056729,457.27124,-9.235117
196.3851,9.9060202,9.461853,0.0,0,0.10941217,0.0,0.99724507,46.495125,0.17892778,457.40302,-9.2344465
196.3895,9.853797,9.4554844,0.0,0,0.084516957,0.0,0.99624389,46.311378,0.15473929,457.55151,-9.2360306
196.3939,9.8304663,9.4620209,0.0,0,0.059621762,0.0,0.99752653,46.14716,0.13283473,457.77551,-9.2342243
196.3983,9.7621326,9.4616356,0.0,0,0.03472656,0.0,0.99726796,45.88588,0.10953108,457.99948,-9.2337322
196.4027,9.6647348,9.4661646,0.0,0,0.0098313605,0.0,0.99817371,45.358479,0.088726968,458.19949,-9.2353983
196.4071,9.5669422,9.4636211,0.0,0,-0.014696431,0.0,0.99770725,44.887653,0.068484455,458.39709,-9.2335167
196.4115,9.4965372,9.4683218,0.0,0,-0.038984429,0.0,0.99883759,44.521183,0.054805458,458.56949,-9.2345028
196.4159,9.4201069,9.4676208,0.0,0,-0.063272424,0.0,0.99855828,44.204941,0.039148021,458.72748,-9.2348938
196.4203,9.3203669,9.471837,0.0,0,-0.087560423,0.0,0.99920273,43.673954,0.021265049,458.89499,-9.233119
196.4247,9.197094,9.4710226,0.0,0,-0.080417641,439.71793,0.99888211,43.138203,0.0099904761,459.07919,-9.2339487
196.4291,9.0692139,9.4738398,0.0,0,0.71586639,450.0,0.9997465,42.5149,-0.0008532689,459.27298,-9.2335634
196.4335,7.2493095,9.4694328,0.0,0,1.5127245,450.0,0.99855173,34.180927,0.073565125,459.56244,-9.2365103
196.4379,2.8907413,9.4515753,0.0,0,2.3095829,450.0,0.99538577,13.773668,0.32816622,459.8519,-9.2385397
196.4423,-0.0048810854,9.4423132,0.0,0,3.1064401,450.0,0.99391556,-0.046227992,0.96558136,460.1629,-9.2423544
196.4467,-0.090165898,9.4342432,0.0,0,3.9032979,450.0,0.99227691,-0.44676596,2.3190765,460.47867,-9.2413826
196.4511,-0.037352495,9.4317408,0.0,0,4.7001553,450.0,0.99172252,-0.038245939,3.3246262,460.737,-9.2396622
196.4555,-0.084299117,9.4306879,0.0,0,5.4970126,450.0,0.99147302,-0.35955051,4.097156,460.94751,-9.2374697
196.4599,0.020783253,9.4320688,0.0,0,6.2938709,450.0,0.99169618,0.048983775,4.8657713,461.12933,-9.2383852
196.4643,-0.017226595,9.4323997,0.0,0,7.0907278,450.0,0.991615,-0.02920742,5.6539683,461.23459,-9.2397699
196.4687,-0.013971276,9.4286928,0.0,0,7.8875856,450.0,0.99085391,-0.068772338,6.478581,461.33984,-9.2375526
196.4731,-0.14398773,9.4338245,0.0,0,8.6844435,450.0,0.99152637,-0.62256956,7.3053923,461.43195,-9.2366714
196.4775,-0.076933645,9.4322052,0.0,0,9.4813023,450.0,0.99128717,-0.41733831,8.1277246,461.52405,-9.2365866
196.4819,0.010195924,9.4281206,0.0,0,10.278159,450.0,0.9903934,0.16054848,8.944541,461.64487,-9.2359695
196.4863,0.025395539,9.4324398,0.0,0,11.075017,450.0,0.99120134,0.045036744,9.7602024,461.77643,-9.2366953
196.4907,-0.027101127,9.4291096,0.0,0,11.871875,450.0,0.99047476,-0.10573242,10.576743,461.914,-9.236393
196.4951,-0.044487037,9.4318352,0.0,0,12.668732,450.0,0.99101245,-0.26450297,11.362474,462.05872,-9.2358313
196.4995,0.0071391012,9.4303675,0.0,0,13.46559,450.0,0.9904604,0.038760141,12.131345,462.20105,-9.2353764
196.5039,-0.016794875,9.430397,0.0,0,14.262447,450.0,0.99029034,-0.08182209,12.917465,462.33261,-9.2354183
196.5083,0.042903211,9.432456,0.0,0,15.059305,450.0,0.99078631,0.21360053,13.722249,462.46417,-9.2359533
196.5127,-0.16130462,9.4321203,0.0,0,15.856163,450.0,0.99052197,-0.74822909,14.530613,462.54788,-9.235589
196.5171,0.026315235,9.4321861,0.0,0,16.653021,450.0,0.99060327,0.10576805,15.330469,462.62683,-9.2352524
196.5215,-0.038203582,9.4321966,0.0,0,17.449879,450.0,0.99038845,-0.16961017,16.123306,462.73166,-9.2345495
196.5259,-0.028893879,9.4306574,0.0,0,18.0,450.0,0.99019504,-0.096204862,16.928579,462.85129,-9.235507
196.5303,-0.033870433,9.4337864,0.0,0,18.0,450.0,0.99067813,-0.1360414,17.682377,462.9501,-9.2357063
196.5347,-0.042839073,9.4333954,0.0,0,18.0,450.0,0.99049622,-0.18851073,18.247459,463.01587,-9.2374182
196.5391,0.05560277,9.4445467,0.0,0,18.0,450.0,0.99232048,0.17200731,18.456301,463.07867,-9.2452888
196.5435,0.64644605,9.4538279,0.0,0,18.0,450.0,0.99427855,3.0596485,18.309458,463.11813,-9.2593727
196.5479,0.99916548,9.4691191,0.0,0,18.0,450.0,0.99660361,4.6779113,18.128782,463.15759,-9.285059
196.5523,0.87160629,9.4682055,0.0,0,18.0,450.0,0.99681491,4.1825085,18.055429,463.21921,-9.3180799
196.5567,0.83326942,9.4683809,0.0,0,18.0,450.0,0.99651551,3.9327226,18.067888,463.285,-9.3541107
196.5611,0.88586366,9.4677696,0.0,0,18.0,450.0,0.99658185,4.117444,18.110371,463.34329,-9.3908968
196.5655,0.96991038,9.4710388,0.0,0,18.0,450.0,0.99677676,4.5267167,18.135855,463.3959,-9.4248123
196.5699,0.9054029,9.4640017,0.0,0,18.0,450.0,0.9960053,4.3213568,18.147602,463.44077,-9.4573212
196.5743,0.84986633,9.4712772,0.0,0,18.0,450.0,0.99696571,3.9935381,18.14246,463.46707,-9.4907513
196.5787,0.87484413,9.466733,0.0,0,18.0,450.0,0.99651402,4.0698152,18.139477,463.4931,-9.5233917
196.5831,0.9549244,9.4721975,0.0,0,18.0,450.0,0.99693996,4.478487,18.13467,463.50626,-9.5559416
196.5875,0.94883847,9.4657898,0.0,0,18.0,450.0,0.99642944,4.5084333,18.127623,463.51941,-9.5900736
196.5919,0.8523736,9.4721804,0.0,0,18.0,450.0,0.99706119,4.0313168,18.118521,463.52271,-9.6236553
196.5963,0.86152864,9.4685898,0.0,0,18.0,450.0,0.99698859,4.000277,18.116863,463.52271,-9.6546402
196.6007,0.95811385,9.4736605,0.0,0,18.0,450.0,0.99751759,4.4605126,18.115307,463.50388,-9.6886358
196.6051,0.9620561,9.4675083,0.0,0,18.0,450.0,0.99680817,4.5472965,18.115669,463.46439,-9.7225628
196.6095,0.87330967,9.4737873,0.0,0,18.0,450.0,0.99772817,4.1137824,18.107506,463.4303,-9.7525911
196.6139,0.85628372,9.4675999,0.0,0,18.0,450.0,0.99694419,4.0032244,18.10634,463.41714,-9.7868862
196.6183,0.93979794,9.4711485,0.0,0,18.0,450.0,0.99728465,4.3663359,18.108274,463.40399,-9.8189087
196.6227,0.9820711,9.4695082,0.0,0,18.0,450.0,0.99728608,4.645401,18.106279,463.41537,-9.8530092
196.6271,0.89245141,9.4722662,0.0,0,18.0,450.0,0.99763376,4.2329149,18.105394,463.42853,-9.8878498
196.6315,0.8372004,9.4680367,0.0,0,18.0,450.0,0.99723345,3.9304457,18.101347,463.39835,-9.9197311
196.6359,0.91377395,9.4707794,0.0,0,18.0,450.0,0.99750197,4.2427249,18.097828,463.3457,-9.9514399
196.6403,0.99159104,9.4675446,0.0,0,18.0,450.0,0.99729031,4.6683626,18.096851,463.30832,-9.9858131
196.6447,0.93235755,9.4726791,0.0,0,18.0,450.0,0.99801308,4.3919964,18.098238,463.29517,-10.018074
196.6491,0.84776431,9.4659691,0.0,0,18.0,450.0,0.99717999,4.0176039,18.097773,463.285,-10.050529
196.6535,0.90612835,9.4692554,0.0,0,18.0,450.0,0.99794513,4.2145834,18.093218,463.29816,-10.083786
196.6579,0.99541992,9.4692469,0.0,0,18.0,450.0,0.99785614,4.6915283,18.092421,463.31131,-10.116631
196.6623,0.97263354,9.4679193,0.0,0,18.0,450.0,0.99779648,4.595232,18.09145,463.28021,-10.149352
196.6667,0.88012993,9.4677429,0.0,0,18.0,450.0,0.99775308,4.1796269,18.082653,463.24075,-10.180486
196.6711,0.88038063,9.4691792,0.0,0,18.0,450.0,0.99818951,4.112154,18.085615,463.20874,-10.213398
196.6755,0.99826306,9.4661779,0.0,0,18.0,450.0,0.99745297,4.6348548,18.083046,463.18243,-10.247746
196.6799,0.98461956,9.4680843,0.0,0,18.0,450.0,0.99815178,4.6481838,18.080393,463.16,-10.282364
196.6843,0.89226717,9.4647751,0.0,0,18.0,450.0,0.99728781,4.2329965,18.078611,463.14682,-10.31519
196.6887,0.86201304,9.4694767,0.0,0,18.0,450.0,0.99846011,4.0538502,18.07983,463.13309,-10.346087
196.6931,0.96832359,9.4638596,0.0,0,18.0,450.0,0.99728817,4.5050163,18.080366,463.0936,-10.379403
196.6975,0.99872059,9.467598,0.0,0,18.0,450.0,0.99827057,4.673636,18.080263,463.05411,-10.412378
196.7019,0.91690928,9.4645243,0.0,0,18.0,450.0,0.99766344,4.3591785,18.076784,462.98505,-10.444557
196.7063,0.85217363,9.4675903,0.0,0,18.0,450.0,0.99844158,4.0201077,18.078083,462.90613,-10.479473
196.7107,0.94915998,9.4639702,0.0,0,18.0,450.0,0.99766821,4.3861108,18.075203,462.85858,-10.512432
196.7151,1.0214217,9.4669342,0.0,0,18.0,450.0,0.99833137,4.8025937,18.074932,462.84543,-10.544206
196.7195,0.94519365,9.4638042,0.0,0,18.0,450.0,0.99756753,4.4829865,18.072596,462.83496,-10.577921
196.7239,0.85809273,9.4646835,0.0,0,18.0,450.0,0.99797726,4.0687652,18.069969,462.83496,-10.610467
196.7283,0.93550098,9.4645529,0.0,0,18.0,450.0,0.99793065,4.3258739,18.066217,462.83496,-10.642292
196.7327,1.0299648,9.4627638,0.0,0,18.0,450.0,0.99761695,4.8368011,18.070822,462.79819,-10.676622
196.7371,0.98030895,9.4619017,0.0,0,18.0,450.0,0.99744898,4.6475863,18.068642,462.7587,-10.71103
196.7415,0.88848108,9.4637117,0.0,0,18.0,450.0,0.9977926,4.2037096,18.063936,462.71054,-10.742563
196.7459,0.89799964,9.4617758,0.0,0,18.0,450.0,0.99738646,4.1656013,18.062548,462.6579,-10.77492
196.7503,1.0261841,9.463438,0.0,0,18.0,450.0,0.99779618,4.7951894,18.063469,462.61035,-10.807038
196.7547,1.0048367,9.4638309,0.0,0,18.0,450.0,0.99770153,4.7765503,18.064014,462.57089,-10.842001
196.7591,0.90485257,9.4641743,0.0,0,18.0,450.0,0.99769628,4.27002,18.062349,462.53293,-10.873296
196.7635,0.88190198,9.4637032,0.0,0,18.0,450.0,0.99760354,4.109107,18.061634,462.50662,-10.906706
196.7679,1.0031306,9.4629192,0.0,0,18.0,450.0,0.9974367,4.7028508,18.062319,462.48032,-10.93955
196.7723,1.034326,9.4628057,0.0,0,18.0,450.0,0.99721628,4.8543577,18.059195,462.43188,-10.972313
196.7767,0.92138004,9.461483,0.0,0,18.0,450.0,0.997006,4.3834133,18.059536,462.37924,-11.005696
196.7811,0.89328277,9.4620056,0.0,0,18.0,450.0,0.9970541,4.1737151,18.058619,462.31168,-11.038477
196.7855,0.97773379,9.4628725,0.0,0,18.0,450.0,0.9970082,4.5842299,18.05599,462.23273,-11.070552
196.7899,1.0469577,9.463686,0.0,0,18.0,450.0,0.99729103,4.9381142,18.057987,462.16547,-11.104104
196.7943,0.95236868,9.4629879,0.0,0,18.0,450.0,0.99673688,4.5255108,18.052731,462.12598,-11.137909
196.7987,0.88517004,9.4642944,0.0,0,18.0,450.0,0.99714357,4.1809955,18.052979,462.0874,-11.170142
196.8031,0.96626765,9.4644413,0.0,0,18.0,450.0,0.99699867,4.4656658,18.046549,462.0874,-11.20226
196.8075,1.0462216,9.4643002,0.0,0,18.0,450.0,0.99695128,4.9236345,18.051594,462.0874,-11.236461
196.8119,0.98116869,9.4659958,0.0,0,18.0,450.0,0.99712336,4.6178255,18.051735,462.07755,-11.270066
196.8163,0.89689565,9.4644165,0.0,0,18.0,450.0,0.99681908,4.2278619,18.050371,462.06436,-11.303391
196.8207,0.94105595,9.4644861,0.0,0,18.0,450.0,0.99671072,4.3723083,18.045643,462.02609,-11.335526
197.1244,0.901039,9.4697924,0.0,0,18.0,0.036866054,0.9977631,4.2209511,18.016926,451.88184,-11.481328
199.3244,0.83214486,9.4887466,0.0,0,18.0,3.6775893e-32,1.001263,3.8853538,17.998991,421.85065,-11.480908
201.5244,0.81702614,9.5037575,0.0,0,18.0,1.4012985e-45,1.0039468,3.8144777,18.00016,399.06674,-11.481582
203.7244,0.79849476,9.5166311,0.0,0,18.0,1.4012985e-45,1.0064107,3.7160692,17.999411,377.81329,-11.480701
205.9244,0.80602151,9.5290251,0.0,0,18.0,1.4012985e-45,1.0086515,3.7462306,17.999231,358.45245,-11.481765
208.1244,0.80323821,9.5404558,0.0,0,18.0,1.4012985e-45,1.0106634,3.7186236,17.999187,339.69458,-11.481777
210.3244,0.81736934,9.5515213,0.0,0,18.0,1.4012985e-45,1.0126725,3.777808,17.99958,322.09467,-11.481381
212.5244,0.81419921,9.5616589,0.0,0,18.0,1.4012985e-45,1.0145136,3.7596412,17.998947,305.43619,-11.481514
214.7244,0.82401544,9.570961,0.0,0,18.0,1.4012985e-45,1.0163554,3.8060784,17.999569,289.76837,-11.481923
216.9244,0.82917988,9.5803633,0.0,0,18.0,1.4012985e-45,1.0180203,3.8172319,17.999634,275.07336,-11.481648
219.1244,0.85484523,9.5899105,0.0,0,18.0,1.4012985e-45,1.0198288,3.9201572,18.000288,261.1626,-11.481915
221.3244,0.85737938,9.5991631,0.0,0,18.0,1.4012985e-45,1.0215552,3.9243591,17.999746,248.05243,-11.481891
223.5244,0.85982138,9.6076365,0.0,0,18.0,1.4012985e-45,1.023043,3.9403744,17.999006,235.74083,-11.48173
225.7244,0.8480463,9.6150503,0.0,0,18.0,1.4012985e-45,1.0244243,3.8826671,17.999144,224.06076,-11.481067
227.9244,0.85950047,9.6229239,0.0,0,18.0,1.4012985e-45,1.0258005,3.9174407,18.000738,213.3542,-11.480707
230.1244,0.88371408,9.6299725,0.0,0,18.0,1.4012985e-45,1.0272292,4.0215168,17.9993,202.87561,-11.481202
232.3244,0.90851641,9.6365643,0.0,0,18.0,1.4012985e-45,1.0284148,4.1336484,18.00021,193.12234,-11.48196
234.5244,0.9099527,9.643095,0.0,0,18.0,1.4012985e-45,1.0297207,4.1432204,18.000175,183.968,-11.482088
236.7244,0.89568728,9.6495943,0.0,0,18.0,1.4012985e-45,1.0309157,4.072907,18.000242,175.36156,-11.481967
238.9244,0.9027136,9.6554041,0.0,0,18.0,1.4012985e-45,1.0320134,4.0947938,17.999027,167.28387,-11.481771
241.1244,0.92568928,9.6610479,0.0,0,18.0,1.4012985e-45,1.0330737,4.185215,17.999844,160.04984,-11.481486
243.3244,0.92973977,9.6657429,0.0,0,18.0,1.4012985e-45,1.0338937,4.2065115,18.000832,152.99443,-11.480673
245.5244,0.93128926,9.6714296,0.0,0,18.0,1.4012985e-45,1.0349842,4.217237,18.000444,146.19177,-11.481235
247.7244,0.93120199,9.6759796,0.0,0,18.0,1.4012985e-45,1.0357612,4.2087054,18.000628,139.66243,-11.481428
249.9244,0.92177385,9.6805334,0.0,0,18.0,1.4012985e-45,1.0366765,4.1605306,17.999268,133.45628,-11.481206
252.1244,0.94830132,9.6847744,0.0,0,18.0,1.4012985e-45,1.0374029,4.269937,18.001175,127.6909,-11.481681
254.3244,0.95996565,9.6892939,0.0,0,18.0,1.4012985e-45,1.0383004,4.325789,17.999054,122.3147,-11.481744
256.5244,0.95022374,9.6931305,0.0,0,18.0,1.4012985e-45,1.038959,4.2853217,18.00021,117.14777,-11.481642
256.8244,0.93942004,9.6935091,0.0,0,18.0,1.4012985e-45,1.0391309,4.2272573,17.998611,116.54711,-11.546189