File: examples/dan-msc-case-studies/CS3/data/01 raw data/baron_test_129.csv
Time(sec),Force(kN),Jaw(mm),PowAngle(deg),Power(W),Pram,PTemp,Strain,Stress(MPa),Stroke(mm),TC1(C),wedge(mm)
0.0,1.1432579,-0.77479595,0.0,0,11.076097,3.2850396e-05,-0.050370324,15.31165,11.076459,24.618408,-9.1252298
1.2,1.0776004,0.00021520743,0.0,0,11.076097,3.5158758,3.1470481e-05,13.721019,11.075544,24.642889,-9.491703
2.4,1.0455346,0.00012896105,0.0,0,11.076097,7.1158748,4.5080592e-06,13.315827,11.076632,24.592838,-9.4895115
3.6,1.022831,9.2761664e-05,0.0,0,11.076097,10.715875,6.0855773e-06,13.031667,11.076354,24.580557,-9.4877119
4.8,1.0021987,7.678305e-05,0.0,0,11.076097,14.315875,-1.4192507e-05,12.752277,11.076023,24.50074,-9.4857187
6.0,0.98344362,8.6075102e-05,0.0,0,11.076097,17.915876,7.1644831e-06,12.524159,11.076449,24.563362,-9.4831877
7.2,0.97922528,-0.00036428956,0.0,0,11.076097,21.515877,-1.5386866e-05,12.473361,11.077119,24.48369,-9.4813538
8.4,0.96672857,0.00010746724,0.0,0,11.076097,25.115877,7.8760013e-06,12.30879,11.076308,24.582554,-9.4791746
9.6,0.9546268,6.2394545e-05,23.186279,0,11.076097,28.715878,-8.0562668e-06,12.145631,11.076197,24.576061,-9.4770803
10.8,0.9595654,-0.00088395824,33.765953,0,11.076097,32.31588,-7.5029166e-05,12.225595,11.076338,26.122282,-9.475152
12.0,0.96878117,-0.0036625657,39.337147,0,11.076097,35.91589,-0.00023047935,12.336559,11.07587,29.156425,-9.4730072
13.2,0.98074174,-0.007249251,42.396187,0,11.076097,39.515884,-0.00047428141,12.500993,11.075395,33.405148,-9.4705544
14.4,0.99567842,-0.01139172,44.077141,0,11.076097,43.115883,-0.00074779062,12.680067,11.075603,38.2164,-9.4682989
15.6,0.99548852,-0.016284557,44.604488,0,11.076097,46.715881,-0.001102346,12.67936,11.07496,43.349545,-9.466176
16.8,1.0037388,-0.018909669,44.077236,0,11.076097,50.31588,-0.0012644954,12.80185,11.075834,48.544136,-9.4643431
18.0,1.0100439,-0.021925272,43.057552,0,11.076097,53.915874,-0.0014352708,12.87177,11.075767,53.45393,-9.4620314
19.2,1.0085195,-0.024628894,42.396244,0,11.076097,57.515869,-0.0016356963,12.846944,11.076,57.802094,-9.4597864
20.4,1.0144764,-0.027231196,41.803265,0,11.076097,61.115871,-0.0018194612,12.934284,11.076417,61.70166,-9.4578505
21.6,1.0055387,-0.029280553,41.57095,0,11.076097,64.715897,-0.0019737771,12.822932,11.075434,65.250443,-9.4556608
22.8,1.0119125,-0.032570001,41.802731,0,11.076097,68.315887,-0.0021562541,12.919414,11.076111,68.623146,-9.4535885
24.0,1.0068655,-0.03469146,41.802975,0,11.076097,71.915886,-0.0023064474,12.846726,11.075675,71.999542,-9.4515553
25.2,1.005401,-0.036668882,42.396236,0,11.076097,75.515892,-0.0024290327,12.822577,11.076647,75.230652,-9.4490347
26.4,1.0089527,-0.03917338,42.852066,0,11.076097,79.115891,-0.0026262037,12.883949,11.076347,78.656639,-9.4468584
27.6,1.0075635,-0.041615795,43.227047,0,11.076097,82.715889,-0.002783986,12.872588,11.076953,82.040176,-9.4447842
28.8,1.0233244,-0.044623427,44.030315,0,11.076097,86.315887,-0.0029588034,13.070971,11.075522,85.421906,-9.4426098
30.0,1.0170138,-0.047400694,44.077145,0,11.076097,89.915886,-0.0031553274,12.989052,11.075959,89.084526,-9.4406776
31.2,1.01333,-0.049856663,44.604488,0,11.076097,93.515884,-0.0033140418,12.943165,11.076286,92.702141,-9.4384298
32.4,1.0182287,-0.052518785,45.041466,0,11.076097,97.115898,-0.00351979,13.002366,11.076281,96.418419,-9.4363461
33.6,1.025476,-0.055229619,45.12085,0,11.076097,100.71588,-0.0036625231,13.100185,11.076495,99.983383,-9.4344778
34.8,1.0329411,-0.058386475,45.615231,0,11.076097,104.31589,-0.0038894492,13.197484,11.076637,103.68471,-9.4322472
36.0,1.0418105,-0.061682705,45.615231,0,11.076097,107.91588,-0.0041008447,13.322078,11.076288,107.41958,-9.430727
37.2,1.0283335,-0.064644061,46.109619,0,11.076097,111.51589,-0.0043163896,13.154119,11.076391,110.93595,-9.4279251
38.4,1.031523,-0.067570291,46.109619,0,11.076097,115.11587,-0.0045022499,13.178699,11.075274,114.61232,-9.425643
39.6,1.046483,-0.070256658,46.582027,0,11.076097,118.7159,-0.0046579964,13.385336,11.075379,118.0975,-9.4241514
40.8,1.0551161,-0.074448757,47.026241,0,11.076097,122.31588,-0.0049479632,13.50439,11.07613,121.64728,-9.422143
42.0,1.0504354,-0.076677874,47.199074,0,11.076097,125.91588,-0.0050991769,13.423576,11.075993,125.11822,-9.4196215
43.2,1.0475802,-0.079413727,47.630909,0,11.076097,129.51599,-0.0052983537,13.405188,11.074971,128.64935,-9.4173441
44.4,1.0510166,-0.082752913,47.955318,0,11.076097,133.11588,-0.005493077,13.443953,11.07655,132.31561,-9.4154758
45.6,1.0595431,-0.085627139,48.381794,0,11.076097,136.71588,-0.0056936424,13.55721,11.07601,135.95825,-9.4137573
46.8,1.071283,-0.089007892,48.383793,0,11.076097,140.31587,-0.0059181163,13.728682,11.076962,139.63884,-9.4117041
48.0,1.0726994,-0.092573792,48.812252,0,11.076097,143.91588,-0.0061702924,13.725234,11.075999,143.24121,-9.409481
49.2,1.0639417,-0.095448062,48.812252,0,11.076097,147.51588,-0.0063423836,13.633576,11.076129,147.02431,-9.407361
50.4,1.0664225,-0.098286703,48.822075,0,11.076097,151.11589,-0.0065235798,13.665414,11.076441,150.62004,-9.4056473
51.6,1.0720853,-0.10148168,49.229733,0,11.076097,154.71588,-0.0067315423,13.75364,11.076053,154.21187,-9.4032202
52.8,1.083109,-0.10392068,49.633827,0,11.076097,158.31589,-0.006918137,13.878164,11.076274,157.69914,-9.4012146
54.0,1.0793314,-0.10905868,49.637741,0,11.076097,161.91588,-0.007257448,13.831112,11.077114,161.28473,-9.3993578
55.2,1.0794531,-0.11101576,50.042721,0,11.076097,165.51588,-0.0073651341,13.830246,11.074936,164.86737,-9.3973341
56.4,1.0802324,-0.11384446,50.155205,0,11.076097,169.11589,-0.0075546368,13.858736,11.075131,168.47702,-9.3953543
57.6,1.0864562,-0.11703233,50.438229,0,11.076097,172.71588,-0.0077668838,13.937834,11.076537,172.17574,-9.3935957
58.8,1.0890303,-0.12022432,50.456104,0,11.076097,176.31587,-0.0079955505,13.965621,11.076099,175.81082,-9.3912296
60.0,1.0841088,-0.12346835,50.669029,0,11.076097,179.91588,-0.0081904149,13.927611,11.076054,179.48216,-9.3886585
61.2,1.0845323,-0.12833001,50.82275,0,11.076097,183.51588,-0.0085219881,13.937771,11.077205,182.97327,-9.3867149
62.4,1.0866152,-0.13056622,51.196114,0,11.076097,187.11589,-0.0086592203,13.967628,11.07471,186.64151,-9.385088
63.6,1.0888637,-0.1331026,51.196285,0,11.076097,190.7159,-0.0088497857,13.984742,11.07664,190.19485,-9.3830299
64.8,1.0862621,-0.13612671,51.559402,0,11.076097,194.31589,-0.0090160435,13.960047,11.075815,193.78215,-9.3808441
66.0,1.0921459,-0.13901463,51.56982,0,11.076097,197.91589,-0.0092168152,14.043229,11.075928,197.45241,-9.378767
67.2,1.0973781,-0.14427251,51.806068,0,11.076097,201.5159,-0.0095712375,14.116372,11.076466,200.99748,-9.3770313
68.4,1.0893371,-0.1458405,51.932369,0,11.076097,205.11589,-0.0097031994,13.995513,11.075657,204.6077,-9.3750486
69.6,1.0920604,-0.14926775,52.274326,0,11.076097,208.7159,-0.0099066263,14.045421,11.07641,208.14331,-9.3728743
70.8,1.0855277,-0.15233012,52.330273,0,11.076097,212.31589,-0.010092121,13.958336,11.075689,211.73639,-9.3705292
72.0,1.093418,-0.15540007,52.635494,0,11.076097,215.91589,-0.010291974,14.07005,11.07613,215.26891,-9.3684149
73.2,1.1000985,-0.16030888,52.708702,0,11.076097,219.5159,-0.010647432,14.157664,11.07611,218.99579,-9.3664722
74.4,1.0984304,-0.16270553,52.97607,0,11.076097,223.11589,-0.010796409,14.139074,11.075765,222.59981,-9.3645287
75.6,1.0931665,-0.16617176,52.976078,0,11.076097,226.7159,-0.011007234,14.076443,11.075499,226.31743,-9.3626595
76.8,1.0918502,-0.16960756,53.291504,0,11.076097,230.3159,-0.011238897,14.065185,11.075488,229.84532,-9.3602324
78.0,1.0903414,-0.17241991,53.31665,0,11.076097,233.91591,-0.01144399,14.052575,11.075968,233.51759,-9.358017
79.2,1.1021361,-0.17622285,53.487171,0,11.076097,237.51588,-0.011698115,14.202547,11.0769,237.05942,-9.3562622
80.4,1.1025794,-0.18153605,53.657223,0,11.076097,241.11589,-0.012012646,14.202171,11.076723,240.72742,-9.3539848
81.6,1.0882297,-0.18365948,53.728981,0,11.076097,244.7159,-0.012160501,14.039668,11.076063,244.22395,-9.3518248
82.8,1.0908993,-0.18631974,53.975826,0,11.076097,248.3159,-0.012359423,14.054037,11.075839,247.81152,-9.3502264
84.0,1.0936781,-0.18967836,54.266033,0,11.076097,251.91589,-0.012582071,14.109329,11.075693,251.36714,-9.3481627
85.2,1.1006738,-0.19321337,54.305416,0,11.076097,255.51588,-0.012779726,14.201243,11.076045,255.08249,-9.3462944
86.4,1.1006649,-0.19666252,54.305416,0,11.076097,259.11615,-0.0130228,14.193221,11.075362,258.79059,-9.3440418
87.6,1.0930705,-0.20208655,54.305424,0,11.076097,262.71591,-0.013375874,14.096284,11.075497,262.37491,-9.3418989
88.8,1.0870346,-0.20371456,54.623379,0,11.076097,266.31589,-0.013504287,14.025445,11.076413,265.92227,-9.3400831
90.0,1.0931791,-0.20729706,54.624023,0,11.076097,269.91589,-0.013712624,14.106685,11.076376,269.44922,-9.3380947
91.2,1.0883695,-0.21074176,54.93082,0,11.076097,273.5159,-0.013953841,14.050101,11.076139,273.10211,-9.3359556
92.4,1.093743,-0.21379389,54.931637,0,11.076097,277.11591,-0.014151073,14.121076,11.07617,276.60101,-9.3339176
93.6,1.0951166,-0.21702521,55.226185,0,11.076097,280.71588,-0.014385266,14.139257,11.075658,280.21445,-9.3320093
94.8,1.1022646,-0.22152998,55.239262,0,11.076097,284.31589,-0.014652777,14.237312,11.075912,283.78317,-9.3296947
96.0,1.0964597,-0.22601168,55.535885,0,11.076097,287.91589,-0.014957126,14.173868,11.076536,287.41464,-9.3276539
97.2,1.0907208,-0.22885638,55.535885,0,11.076097,291.5159,-0.015139385,14.103565,11.07605,291.04703,-9.3254833
98.4,1.0952044,-0.23175187,55.618881,0,11.076097,295.11591,-0.015348269,14.163401,11.07544,294.74045,-9.3236513
99.6,1.0922508,-0.23524915,55.843498,0,11.076097,298.71588,-0.015549266,14.120937,11.075904,298.35324,-9.3216801
100.8,1.101269,-0.23752341,55.843506,0,11.076097,302.31592,-0.015713107,14.240945,11.076369,302.03113,-9.3198404
102.0,1.10203,-0.24168698,56.044727,0,11.076097,305.91589,-0.015986348,14.258512,11.076832,305.4332,-9.3174973
103.2,1.1023273,-0.24560025,56.129147,0,11.076097,309.51593,-0.016253436,14.262203,11.076417,309.00729,-9.3152027
104.4,1.0905784,-0.24838683,56.425777,0,11.076097,313.11591,-0.016416207,14.127218,11.075435,312.49252,-9.3130436
105.6,1.0963899,-0.25140661,56.708107,0,11.076097,316.71594,-0.016615547,14.213504,11.075873,316.07935,-9.3112631
106.8,1.0964292,-0.25477517,56.711422,0,11.076097,320.31589,-0.016827075,14.205094,11.075875,319.68912,-9.3094921
108.0,1.1065078,-0.25790039,56.986084,0,11.076097,323.91592,-0.017070079,14.326907,11.0762,323.25711,-9.3081799
109.2,1.1022338,-0.26430857,57.162758,0,11.076097,327.5159,-0.017453995,14.266675,11.075745,326.83087,-9.3055878
110.4,1.0950788,-0.26617089,57.260738,0,11.076097,331.11594,-0.01759053,14.186264,11.07636,330.44183,-9.3033581
111.6,1.0922167,-0.27015141,57.535397,0,11.076097,334.71591,-0.017844187,14.171452,11.075916,334.02435,-9.3013144
112.8,1.085324,-0.27302852,57.633682,0,11.076097,338.31595,-0.018054651,14.086468,11.076719,337.65118,-9.2987623
114.0,1.1014065,-0.27686921,57.822243,0,11.076097,341.91592,-0.018278927,14.280868,11.075782,341.14706,-9.2971048
115.2,1.104352,-0.27984813,58.073727,0,11.076097,345.51593,-0.018486101,14.332238,11.075949,344.73364,-9.2951498
116.4,1.1060599,-0.28383261,58.337242,0,11.076097,349.11591,-0.018742513,14.357873,11.076716,348.31329,-9.2935658
117.6,1.0980066,-0.2893624,58.33741,0,11.076097,352.71591,-0.019127334,14.251417,11.076183,352.03549,-9.2915001
118.8,1.1033056,-0.29232952,58.560459,0,11.076097,356.31592,-0.019283043,14.318092,11.076138,355.73901,-9.2894983
120.0,1.0918564,-0.29505748,58.59008,0,11.076097,359.91592,-0.019481894,14.164267,11.075713,359.47272,-9.2874117
121.2,1.0891412,-0.29838997,58.59008,0,11.076097,363.51587,-0.019689376,14.130963,11.075299,363.08502,-9.285183
122.4,1.0940862,-0.30190307,58.697712,0,11.076097,367.11588,-0.019946504,14.217756,11.075562,366.73462,-9.283288
123.6,1.0902301,-0.30594137,58.853752,0,11.076097,370.71588,-0.020179456,14.172002,11.07628,370.27563,-9.2808733
124.8,1.1045096,-0.30936313,58.853752,0,11.076097,374.31589,-0.0204187,14.352257,11.076118,373.96866,-9.2792253
126.0,1.099418,-0.31258264,58.922752,0,11.076097,377.91589,-0.02062129,14.298624,11.075568,377.62091,-9.2772503
127.2,1.1011623,-0.31565326,59.100132,0,11.076097,381.51587,-0.020844011,14.329389,11.075806,381.14172,-9.2753944
128.4,1.1003368,-0.31952944,59.106438,0,11.076097,385.11588,-0.021063277,14.316477,11.075896,384.81046,-9.2731934
129.6,1.1072901,-0.32257503,59.156578,0,11.076097,388.71591,-0.021285955,14.397398,11.076955,388.37106,-9.2716084
130.8,1.107682,-0.3260994,59.348137,0,11.076097,392.31589,-0.021509029,14.417839,11.076044,391.84256,-9.2696533
132.0,1.1032511,-0.33033866,59.522327,0,11.076097,395.91589,-0.021800136,14.364969,11.075953,395.4259,-9.2669592
133.2,1.1051331,-0.33471173,59.600826,0,11.076097,399.5159,-0.022054549,14.392607,11.076302,399.02396,-9.2652493
134.4,1.1057223,-0.33905637,59.84066,0,11.076097,403.11591,-0.022346817,14.399318,11.076434,402.52829,-9.2630835
135.6,1.1101979,-0.34262139,59.842525,0,11.076097,406.71588,-0.022599572,14.460397,11.076184,406.18976,-9.2610521
136.8,1.1071317,-0.3461625,60.084225,0,11.076097,410.31589,-0.022823574,14.412446,11.07595,409.73755,-9.2589016
138.0,1.0997189,-0.34950206,60.174896,0,11.076097,413.91589,-0.023017075,14.315989,11.076137,413.27643,-9.2568016
139.2,1.1050186,-0.35292795,60.314934,0,11.076097,417.5159,-0.02324314,14.395881,11.07624,416.77353,-9.2552538
140.4,1.1117502,-0.35625678,60.556637,0,11.076097,421.11591,-0.023493042,14.485108,11.076001,420.362,-9.2533808
141.6,1.1057228,-0.35967568,60.785591,0,11.076097,424.71591,-0.023705466,14.412491,11.0758,423.96988,-9.2508755
142.8,1.1048902,-0.3630532,60.787346,0,11.076097,428.31592,-0.023914987,14.394913,11.075964,427.75235,-9.2487326
144.0,1.1050291,-0.36592749,60.856842,0,11.076097,431.91589,-0.024104824,14.401751,11.076763,431.42697,-9.2466116
145.2,1.114177,-0.36837494,60.787392,0,11.076097,435.51593,-0.024284169,14.53522,11.075608,435.25003,-9.2443743
146.4,1.1087697,-0.37136969,60.787361,0,11.076097,439.11591,-0.024465626,14.477793,11.075806,438.98273,-9.2424784
147.6,1.1118836,-0.37388095,60.787361,0,11.076097,442.71594,-0.024625536,14.508205,11.074501,442.73245,-9.2411375
148.8,1.1013516,-0.37656975,60.787361,0,11.076097,446.31592,-0.024798131,14.367535,11.077372,446.33359,-9.2392159
150.0,1.1047775,-0.37897441,60.787361,0,11.076097,449.91489,-0.024975006,14.441035,11.075219,449.78824,-9.2371893
151.2,1.1106313,-0.38104254,58.878815,0,11.076097,449.9989,-0.025078114,14.493019,11.075998,453.16833,-9.2367764
152.4,1.0927945,-0.38104442,56.883186,0,11.076097,449.9989,-0.025090128,14.282402,11.075758,455.02222,-9.2366886
153.6,1.0799474,-0.3810381,54.934025,0,11.076097,449.9989,-0.025084808,14.104884,11.076522,455.7348,-9.2364712
154.8,1.0689459,-0.38041648,53.320343,0,11.076097,449.9989,-0.025066333,13.953916,11.075031,455.57452,-9.2362957
156.0,1.0528672,-0.37937966,52.284996,0,11.076097,449.9989,-0.02496898,13.74748,11.074807,454.61859,-9.2358942
157.2,0.98042792,-0.37927198,51.859333,0,11.076097,449.9989,-0.024977606,12.794635,11.076305,453.46439,-9.2362213
158.4,0.86697984,-0.38004696,51.809769,0,11.076097,449.9989,-0.025043,11.309994,11.076691,452.14044,-9.2367992
159.6,0.79263377,-0.38099825,52.283936,0,11.076097,449.9989,-0.025099045,10.33788,11.075775,450.73138,-9.2368698
160.8,0.73126107,-0.38101199,52.97607,0,11.076097,449.9989,-0.025061905,9.5349407,11.075439,449.63547,-9.2366219
162.0,0.70116788,-0.38040975,53.657219,0,11.076097,449.9989,-0.02503611,9.1510544,11.076656,448.92349,-9.2366476
163.2,0.68494946,-0.37976027,54.305416,0,11.076097,449.9989,-0.025017096,8.9420099,11.076687,448.52295,-9.2369823
164.4,0.66516191,-0.38121122,54.931637,0,11.076097,449.9989,-0.02509957,8.6899977,11.075709,448.41544,-9.236536
165.6,0.67343241,-0.38184726,55.290855,0,11.076097,449.9989,-0.025131233,8.7976522,11.075679,448.49847,-9.2363396
166.8,0.66936672,-0.38298619,55.535885,0,11.076097,449.9989,-0.025209283,8.7588511,11.076432,448.75479,-9.2363224
168.0,0.6612047,-0.38400349,55.789005,0,11.076097,449.9989,-0.025289692,8.6506462,11.075925,449.04648,-9.2364025
169.2,0.65184808,-0.38532081,55.537247,0,11.076097,449.9989,-0.025352327,8.5097799,11.076169,449.5098,-9.2360373
170.4,0.64067799,-0.38620394,55.535892,0,11.076097,449.9989,-0.025420902,8.3698721,11.075609,449.7338,-9.2361078
171.6,0.63399291,-0.38711834,55.535892,0,11.076097,449.9989,-0.025488971,8.2750578,11.075488,449.8898,-9.2362938
172.8,0.62597644,-0.38798729,55.420929,0,11.076097,449.9989,-0.02554783,8.171587,11.076103,450.11969,-9.2363396
174.0,0.61393619,-0.38869527,55.239262,0,11.076097,449.9989,-0.025566699,8.0167713,11.076082,450.30914,-9.2365236
175.2,0.60623592,-0.38924837,54.934376,0,11.076097,449.9989,-0.025604539,7.9196119,11.075607,450.50391,-9.2365475
176.4,0.60588485,-0.3896043,54.931644,0,11.076097,449.9989,-0.025652606,7.9162498,11.075845,450.42273,-9.2364454
177.6,0.60810065,-0.39003348,54.639809,0,11.076097,449.9989,-0.025668619,7.9460382,11.075842,450.47928,-9.2368622
178.8,0.5974462,-0.39050651,54.624176,0,11.076097,449.9989,-0.025697576,7.798481,11.077025,450.29266,-9.2365885
180.0,0.5941211,-0.39092845,54.74234,0,11.076097,449.9989,-0.025723467,7.7563028,11.075887,450.15921,-9.2365122
181.2,0.59596872,-0.39133257,54.68758,0,11.076097,449.9989,-0.025769114,7.8010254,11.075723,450.21097,-9.2368135
182.4,0.59444374,-0.39151123,54.624027,0,11.076097,449.9989,-0.025753718,7.7670364,11.076419,450.06186,-9.2368431
183.6,0.58512783,-0.39222738,54.624252,0,11.076097,449.9989,-0.025808694,7.648654,11.076672,450.01929,-9.2367325
184.8,0.58679992,-0.39283219,54.707329,0,11.076097,449.9989,-0.025859395,7.6638999,11.07624,449.94241,-9.2363758
186.0,0.58934021,-0.39446279,54.624027,0,11.076097,449.9989,-0.025967386,7.7009459,11.075621,450.12869,-9.2365131
187.2,0.58697557,-0.39700001,54.435886,0,11.076097,449.9989,-0.026113845,7.6743069,11.075926,450.3689,-9.2364511
188.4,0.59076804,-0.39623347,54.305424,0,11.076097,449.9989,-0.026049225,7.7263393,11.075991,450.51147,-9.2362795
189.6,0.5748933,-0.39655146,53.975834,0,11.076097,449.9989,-0.026110122,7.5117612,11.076297,450.48602,-9.2360058
190.8,0.578637,-0.3968896,53.895947,0,11.076097,449.9989,-0.02610963,7.5616827,11.076241,450.53531,-9.2361307
192.0,0.57257015,-0.39675826,53.65723,0,11.076097,449.9989,-0.026102602,7.4733973,11.07593,450.43405,-9.235919
193.2,0.57881171,-0.39701292,53.65723,0,11.076097,449.9989,-0.026118968,7.5679359,11.076267,450.24725,-9.2360458
194.4,0.58914918,-0.3988736,53.975735,0,11.076097,449.9989,-0.0262575,7.6976395,11.076109,450.06509,-9.2359238
195.2844,0.5737704,0.0060585197,53.97583,0,11.076099,74.116028,0.0006929441,7.2589455,11.078108,450.05511,-9.2366571
195.2868,0.57463139,0.011318387,53.97583,0,11.076099,3.204249e-15,0.00069287821,7.3512092,11.081294,450.05511,-9.2354317
195.2892,0.57373625,0.012365339,50.528236,0,11.076099,1.3851963e-31,0.00061991694,7.2374945,11.074345,450.05511,-9.236002
195.2916,0.57583159,0.013357173,37.599895,0,11.076099,0.0,0.00078786124,7.2889147,11.073364,450.05511,-9.2360153
195.294,0.61282051,0.01056233,24.671551,0,11.076099,0.0,0.00082167512,7.864562,11.074925,450.05511,-9.235939
195.2964,0.56416798,0.012249283,11.743207,0,11.076099,0.0,0.0010672236,7.1212502,11.074291,450.05511,-9.2354393
195.2988,0.58070797,0.012641938,0.0,0,11.076099,0.0,0.0008237313,7.3019705,11.077686,450.05643,-9.2362566
195.3012,0.57999378,0.016582554,0.0,0,11.076099,0.0,0.00081606448,7.3946452,11.07766,450.07077,-9.2362471
195.3036,0.57364899,0.016840786,0.0,0,11.076099,0.0,0.00094998267,7.2486019,11.078368,450.08511,-9.2371979
195.306,0.57030094,0.013507177,0.0,0,11.076099,0.0,0.0010701847,7.1964769,11.075363,450.09949,-9.2358341
195.3084,0.55300426,0.010132281,0.0,0,11.076099,0.0,0.00092403725,7.053165,11.077784,450.11383,-9.2366886
195.3108,0.54943699,0.0098709092,0.0,0,11.076099,0.0,0.00063732662,7.010797,11.076116,450.08871,-9.2376728
195.3132,0.56199384,0.012862949,0.0,0,11.076099,0.0,0.00062771625,7.1236706,11.075453,450.06003,-9.236762
195.3156,0.55424827,0.012756352,0.0,0,11.076099,0.0,0.0007378821,6.9950242,11.072095,450.03134,-9.2371902
195.318,0.54902631,0.0092928568,0.0,0,11.076099,0.0,0.0007856423,6.984055,11.077548,450.00266,-9.2365704
195.3204,0.55144346,0.010342924,0.0,0,11.076099,0.0,0.00093334675,6.9802494,11.073669,450.00589,-9.2349796
195.3228,0.55494684,0.011807491,0.0,0,11.076099,0.0,0.00075179111,7.0112982,11.072602,450.0202,-9.235075
195.3252,0.5568139,0.01680523,0.0,0,11.076099,0.0,0.00079200708,7.1340113,11.071682,450.03455,-9.2357998
195.3276,0.54756021,0.017529871,0.0,0,11.076099,0.0,0.00095775485,6.9316983,11.076901,450.04889,-9.2369576
195.33,0.53632611,0.013516374,0.0,0,11.076099,0.0,0.0010753976,6.760181,11.07558,450.06323,-9.2366667
195.3324,0.54311585,0.0098205265,0.0,0,11.076099,0.0,0.00093976082,6.846405,11.073109,450.07761,-9.2359514
195.3348,0.55191416,0.010240337,0.0,0,11.006544,0.0,0.00066730159,7.0376763,11.073318,450.09195,-9.2353992
195.3372,0.55103987,0.011717086,0.0,0,10.645576,0.0,0.00063840166,6.9831858,11.073528,450.10629,-9.2365437
195.3396,0.54740089,0.011843679,0.0,0,10.284603,0.0,0.00071421161,6.9416504,11.062348,450.23019,-9.2372494
195.342,0.57362878,0.0093890699,0.0,0,9.9236288,0.0,0.00082522549,7.212666,10.945752,450.52423,-9.2363691
195.3444,0.5157848,0.010355243,0.0,0,9.5626554,0.0,0.00088576844,6.518414,10.671566,450.81827,-9.2356281
195.3468,0.57621896,0.01284117,0.0,0,9.2092905,0.0,0.00080392434,7.3145318,10.291785,451.1123,-9.235281
195.3492,5.1334548,0.19070092,0.0,0,8.8581219,0.0,0.011699676,63.746681,9.8614082,451.26495,-9.2325106
195.3516,5.5096312,0.70991552,0.0,0,8.518857,0.0,0.047774035,66.045929,9.3247814,450.90637,-9.2323818
195.354,5.968699,1.1517605,0.0,0,8.1848736,0.0,0.079924569,70.004799,8.8617926,450.54776,-9.2322865
195.3564,6.0848498,1.5226593,0.0,0,7.8607755,0.0,0.10681789,69.924751,8.4940853,450.18918,-9.2310534
195.3588,6.4046297,1.8338636,0.0,0,7.543015,0.0,0.12987317,71.72049,8.1577625,449.77435,-9.2323694
195.3612,6.403451,2.1461225,0.0,0,7.2334356,0.0,0.15382069,69.830086,7.8319864,448.06653,-9.2319584
195.3636,6.6424637,2.4367359,0.0,0,6.9312277,0.0,0.17679948,70.764458,7.536694,446.3587,-9.2313738
195.366,6.7114911,2.7209332,0.0,0,6.6355219,0.0,0.20001876,69.941536,7.254992,444.65088,-9.2312412
195.3684,6.9387789,2.9948804,0.0,0,6.3480015,0.0,0.22258726,70.819832,6.972436,442.94305,-9.2314148
195.3708,7.0706654,3.2813323,0.0,0,6.065536,0.0,0.24636935,70.303032,6.6834822,440.7114,-9.23277
195.3732,7.2843351,3.5823491,0.0,0,5.792079,0.0,0.27189997,70.610664,6.3899832,438.39914,-9.2322006
195.3756,7.5095921,3.8695443,0.0,0,5.5222936,0.0,0.29770339,70.958694,6.0978246,436.08691,-9.2325764
195.378,7.6633134,4.1540484,0.0,0,5.2621331,0.0,0.32425866,70.594261,5.8083472,433.77466,-9.2321243
195.3804,7.8433466,4.4343419,0.0,0,5.0044241,0.0,0.35041279,70.276306,5.5204248,430.19006,-9.2309694
195.3828,8.0421991,4.7124906,0.0,0,4.7569842,0.0,0.37656298,70.268486,5.2395277,426.0383,-9.2323313
195.3852,8.2337227,4.9878716,0.0,0,4.5108657,0.0,0.40340739,70.030701,4.9741373,421.88654,-9.2324133
195.3876,8.4311771,5.2455449,0.0,0,4.2754698,0.0,0.42969105,69.845436,4.7117257,417.73477,-9.2319593
195.39,8.6043272,5.4915805,0.0,0,4.0404716,0.0,0.45587137,69.516998,4.4626427,414.34793,-9.2311831
195.3924,8.7998104,5.732779,0.0,0,3.8165054,0.0,0.48162037,69.1894,4.2211947,411.6767,-9.2316055
195.3948,9.0202856,5.9666495,0.0,0,3.5926332,0.0,0.5063951,69.110123,3.9882159,409.00546,-9.2316742
195.3972,9.2497358,6.1944866,0.0,0,3.3790326,0.0,0.53156692,69.193748,3.762321,406.33423,-9.2319994
195.3996,9.4810371,6.4164691,0.0,0,3.1660566,0.0,0.55752909,69.114647,3.5436127,403.34372,-9.2300873
195.402,9.7322769,6.6268191,0.0,0,2.9619906,0.0,0.58330494,69.127434,3.3316264,399.73798,-9.2302551
195.4044,10.017279,6.8377166,0.0,0,2.7593822,0.0,0.6086992,69.35981,3.1141043,396.13223,-9.2303801
195.4068,10.358036,7.0497847,0.0,0,2.5644474,0.0,0.63412112,69.917572,2.9035144,392.52649,-9.2306213
195.4092,10.68996,7.2614717,0.0,0,2.3717272,0.0,0.66086626,70.249649,2.7010906,388.67694,-9.2303171
195.4116,11.020458,7.4659305,0.0,0,2.1855242,0.0,0.6881389,70.523689,2.4966543,383.60855,-9.2305908
195.414,11.37105,7.663506,0.0,0,2.0022123,0.0,0.71546108,70.76767,2.2946577,378.54013,-9.2298851
195.4164,11.764567,7.8568101,0.0,0,1.8243403,0.0,0.7420941,71.239273,2.1013246,373.47171,-9.2294874
195.4188,12.170657,8.0453901,0.0,0,1.6499563,0.0,0.7678144,71.886917,1.9133435,368.40332,-9.2294283
195.4212,12.579419,8.2337303,0.0,0,1.4800413,0.0,0.79459822,72.322571,1.7366358,370.39084,-9.2294636
195.4236,13.023809,8.4112835,0.0,0,1.3141534,0.0,0.82187086,72.858154,1.5592933,372.43768,-9.229229
195.426,13.509356,8.5753469,0.0,0,1.1518564,0.0,0.84823507,73.612053,1.3863194,374.4845,-9.2279835
195.4284,14.048684,8.7410231,0.0,0,0.99408036,0.0,0.87436986,74.57811,1.214528,376.53131,-9.2287884
195.4308,14.620369,8.9069052,0.0,0,0.83908135,0.0,0.89997864,75.637726,1.0531914,376.871,-9.2280149
195.4332,15.172812,9.0688229,0.0,0,0.68903339,0.0,0.92644286,76.47728,0.89007568,376.82742,-9.2273922
195.4356,15.800683,9.2237778,0.0,0,0.54098594,0.0,0.95376277,77.464417,0.73383814,376.78387,-9.2264633
195.438,16.49581,9.3752804,0.0,0,0.39818591,0.0,0.9816187,78.616501,0.5739972,376.74033,-9.2255154
195.4404,14.571649,9.4264574,0.0,0,0.25673628,0.0,0.99095374,69.007027,0.47065091,375.797,-9.2281418
195.4428,12.973954,9.4504061,0.0,0,0.12094415,0.0,0.99356508,61.198223,0.42408553,374.3512,-9.2300644
195.4452,12.305867,9.4577103,0.0,0,-0.014479235,0.0,0.99422556,58.063133,0.39457053,372.9054,-9.2301044
195.4476,11.861188,9.4654713,0.0,0,-0.14691243,0.0,0.99675733,55.752129,0.36595708,371.45956,-9.2308702
195.45,11.830321,9.461669,0.0,0,-0.27934441,0.0,0.9974972,55.564903,0.32604358,372.17819,-9.2305269
195.4524,12.153555,9.4646397,0.0,0,-0.41177642,0.0,0.99772888,57.042595,0.26681471,375.37045,-9.2317591
195.4548,12.315574,9.4756556,0.0,0,-0.54420841,0.0,0.99828786,57.783817,0.1950534,378.56274,-9.2316847
195.4572,12.296251,9.4853888,0.0,0,-0.67664039,0.0,0.99976575,57.630775,0.13692157,381.755,-9.2311192
195.4596,12.145371,9.4902067,0.0,0,-0.80907238,0.0,1.0014857,56.815502,0.080227256,384.72012,-9.2309761
195.462,11.915969,9.4905663,0.0,0,-0.94150436,0.0,1.0026437,55.675892,0.037504774,387.13367,-9.2308359
195.4644,11.590217,9.4919739,0.0,0,-1.0739365,0.0,1.0025187,54.163136,0.0089238426,389.54721,-9.2312288
195.4668,11.145784,9.4988098,0.0,0,-0.76691425,450.0,1.0025121,52.141071,-0.0022685602,391.96075,-9.2301788
195.4692,10.626229,9.5065002,1.7708161,0,-0.3084279,450.0,1.0030574,49.655113,-0.0012393979,394.32761,-9.2327719
195.4716,10.194238,9.5045233,16.949053,0,0.15005845,450.0,1.0039134,47.595039,0.0029674668,396.34103,-9.2335901
195.474,9.882616,9.498435,32.127293,0,0.60854483,450.0,1.0042381,46.131798,0.0093958359,398.35446,-9.2332115
195.4764,9.6708708,9.4948969,47.305531,0,1.0670311,450.0,1.0029887,45.170345,0.010322719,400.36789,-9.2326126
195.4788,9.2675905,9.4968662,62.483765,0,1.5255175,450.0,1.002008,43.38485,0.016012276,402.38132,-9.2332106
195.4812,8.1348953,9.4957809,63.369144,0,1.9840039,450.0,1.0016599,38.145943,0.065209061,404.0806,-9.2333593
195.4836,5.9112849,9.4809523,63.369144,0,2.4424908,450.0,1.000061,27.927225,0.1787571,405.76038,-9.2357702
195.486,2.3855891,9.4674625,63.369144,0,2.9009769,450.0,0.99855769,11.55202,0.4001441,407.44019,-9.2379169
195.4884,0.32329753,9.3826752,63.369144,0,3.3594635,450.0,0.98289633,1.6312064,0.83354115,409.12,-9.2399282
195.4908,-0.22615537,9.3848648,62.396729,0,3.8179498,450.0,0.98155671,-0.93072087,1.5283793,410.40677,-9.2402945
195.4932,0.034148797,9.4078512,61.128368,0,4.2764363,450.0,0.98553133,0.12760773,2.3378553,411.57391,-9.2409687
195.4956,-0.055051543,9.4318056,59.860004,0,4.7349229,450.0,0.99064678,-0.16995206,3.0649319,412.74109,-9.2393894
195.498,0.041057337,9.4360294,58.591644,0,5.1934094,450.0,0.99315166,0.19506794,3.6063938,413.90823,-9.2386713
195.5004,-0.14346936,9.440383,58.07373,0,5.651895,450.0,0.99324405,-0.66146821,4.0348873,415.09155,-9.2384577
195.5028,-0.022550469,9.4460659,58.07373,0,6.1103816,450.0,0.99290442,-0.12786198,4.450449,416.28604,-9.2375317
195.5052,-0.036233768,9.4510536,58.07373,0,6.5688682,450.0,0.99354285,-0.15103294,4.869545,417.4805,-9.2385664
195.5076,-0.03905718,9.4424553,58.07373,0,7.0273547,450.0,0.99301076,-0.11954195,5.2953124,418.67499,-9.2386465
195.51,-0.069818914,9.4351358,57.564983,0,7.4858413,450.0,0.99279499,-0.3288101,5.752027,419.75854,-9.2373905
195.5124,0.041163791,9.4319096,56.343987,0,7.9443278,450.0,0.99157083,0.14766413,6.2338314,420.68677,-9.2359409
195.5148,-0.11340398,9.4320478,55.12299,0,8.4028139,450.0,0.99018764,-0.52468204,6.7141619,421.61502,-9.2355328
195.5172,-0.022826919,9.4417591,53.901997,0,8.8612995,450.0,0.99140644,-0.16748652,7.1999073,422.54324,-9.2364464
195.5196,0.037288006,9.4413757,52.976074,0,9.3197861,450.0,0.99277788,0.16654006,7.6839933,423.42624,-9.2361593
195.522,-0.1934047,9.4362917,52.976074,0,9.7782726,450.0,0.99301982,-0.86694455,8.1503429,424.16718,-9.2374783
195.5244,0.036689699,9.4321852,52.976074,0,10.236759,450.0,0.99163204,0.10915519,8.6191063,424.90814,-9.235981
195.5268,0.022720337,9.4360151,52.976074,0,10.695246,450.0,0.99108666,0.16756292,9.0901155,425.64908,-9.2345524
195.5292,-0.11220583,9.437664,52.902744,0,11.153732,450.0,0.99116361,-0.53594404,9.5629892,426.38522,-9.2344866
195.5316,-0.022547279,9.4373264,51.802795,0,11.612218,450.0,0.99216193,-0.13296767,10.045518,427.05414,-9.2353439
195.534,0.0016670922,9.430974,50.702847,0,12.070705,450.0,0.99210662,0.063718453,10.521452,427.72302,-9.2350216
195.5364,-0.10217728,9.4332409,49.602898,0,12.529191,450.0,0.99170655,-0.53593838,10.988269,428.39194,-9.234952
195.5388,0.046325374,9.4366741,48.502949,0,12.987678,450.0,0.99109924,0.24362022,11.446431,429.06085,-9.2350245
195.5412,0.0048432183,9.4403458,48.383789,0,13.446164,450.0,0.99122363,0.075823538,11.901747,429.6713,-9.2345686
195.5436,-0.16292468,9.4383717,48.383789,0,13.904651,450.0,0.99208647,-0.72706401,12.354523,430.27466,-9.2344646
195.546,-0.00041628542,9.4302349,48.383789,0,14.363137,450.0,0.99212408,-0.092444479,12.813518,430.87802,-9.2343512
195.5484,0.064053044,9.4298258,48.383789,0,14.821624,450.0,0.99101478,0.31188092,13.302293,431.48138,-9.234498
195.5508,-0.13489944,9.4330788,47.644524,0,15.28011,450.0,0.99049109,-0.63702089,13.788437,432.03842,-9.2340565
195.5532,0.039842177,9.437623,46.612995,0,15.738596,450.0,0.9912675,0.18621375,14.274137,432.57718,-9.2336454
195.5556,-0.071245112,9.4354057,45.581463,0,16.197083,450.0,0.9917562,-0.27271786,14.74954,433.11591,-9.234334
195.558,-0.069261529,9.4317913,44.549934,0,16.655569,450.0,0.99204522,-0.37639108,15.197582,433.65463,-9.234108
195.5604,0.089157768,9.4312592,44.077148,0,17.114056,450.0,0.9913168,0.32157984,15.655843,434.13501,-9.2329798
195.5628,-0.048920907,9.4356155,44.077148,0,17.572542,450.0,0.99057794,-0.10877286,16.104259,434.56598,-9.2332602
195.5652,-0.076369792,9.4398308,44.077148,0,17.999401,450.0,0.99106634,-0.39262581,16.549225,434.99695,-9.2344704
195.5676,-0.0055038081,9.4379921,44.077148,0,18.0,450.0,0.9923538,-0.045309875,17.015125,435.42792,-9.2356281
195.57,-0.010147934,9.4314375,43.712425,0,18.0,450.0,0.99218959,-0.035122015,17.443577,435.85098,-9.2333794
195.5724,-0.056553748,9.4315634,42.717739,0,18.0,450.0,0.99110645,-0.24411151,17.83795,436.26044,-9.2338257
195.5748,-0.046601072,9.4338942,41.723049,0,18.0,450.0,0.9905085,-0.15366906,18.167278,436.66986,-9.2355623
195.5772,-0.024998195,9.4410257,40.728355,0,18.0,450.0,0.99181902,-0.12082971,18.402685,437.07928,-9.240324
195.5796,0.018240575,9.4420033,39.924316,0,18.0,450.0,0.99311066,0.061546095,18.526121,437.46808,-9.2450314
195.582,0.25135997,9.4442186,39.924316,0,18.0,450.0,0.99446553,1.1189064,18.528391,437.76978,-9.2524099
195.5844,0.41574779,9.4514627,39.924316,0,18.0,450.0,0.99489188,2.0148718,18.409088,438.07144,-9.2596645
195.5868,0.41062486,9.4592752,39.924316,0,18.0,450.0,0.99500859,1.9071473,18.257006,438.37314,-9.2733879
195.5892,0.34200352,9.4652376,39.906639,0,18.0,450.0,0.99574596,1.682544,18.13381,438.67676,-9.2895927
195.5916,0.34036928,9.4581261,38.846165,0,18.0,450.0,0.99611187,1.6007301,18.05802,439.09335,-9.3087301
195.594,0.35115242,9.4439182,37.78569,0,18.0,450.0,0.99461192,1.6545029,18.030062,439.50998,-9.3272066
195.5964,0.32707801,9.4459028,36.725212,0,18.0,450.0,0.99389231,1.5087432,18.032326,439.92661,-9.3485346
195.5988,0.31931946,9.4520454,35.664738,0,18.0,450.0,0.99375427,1.5555202,18.052589,440.3432,-9.3704205
195.6012,0.32316747,9.4524126,35.49683,0,18.0,450.0,0.99405921,1.516431,18.074787,440.66913,-9.390316
195.6036,0.32455841,9.4476013,35.49683,0,18.0,450.0,0.99428254,1.5507773,18.099537,440.978,-9.4088974
195.606,0.36024997,9.4456244,35.49683,0,18.0,450.0,0.9946093,1.6913635,18.124537,441.28687,-9.4247494
195.6084,0.36272451,9.4479208,35.49683,0,18.0,450.0,0.99416959,1.7355565,18.139074,441.5957,-9.4440279
195.6108,0.33592558,9.4535761,34.919662,0,18.0,450.0,0.99395031,1.6240807,18.14327,441.86627,-9.4620066
195.6132,0.3413094,9.4569225,34.053913,0,18.0,450.0,0.99440527,1.5911376,18.142313,442.11768,-9.4788399
195.6156,0.35971546,9.451581,33.188164,0,18.0,450.0,0.99507403,1.6686157,18.141211,442.36908,-9.4962473
195.618,0.37728965,9.4497156,32.322414,0,18.0,450.0,0.99532831,1.7491113,18.140005,442.62048,-9.5139074
195.6204,0.37634179,9.4481268,31.882326,0,18.0,450.0,0.99408638,1.7457212,18.138454,442.87177,-9.5335913
195.6228,0.32368559,9.4521036,31.882326,0,18.0,450.0,0.99371928,1.5248926,18.131485,443.12289,-9.5507374
195.6252,0.31227031,9.4508066,31.882326,0,18.0,450.0,0.99355674,1.4699638,18.130743,443.37402,-9.5665417
195.6276,0.37639558,9.4506712,31.882326,0,18.0,450.0,0.99479812,1.7424405,18.126728,443.62518,-9.5844107
195.63,0.38713324,9.4502039,31.547342,0,18.0,450.0,0.99554402,1.840891,18.121773,443.86496,-9.6042204
195.6324,0.34500962,9.4494638,30.489496,0,18.0,450.0,0.99426186,1.593333,18.119976,444.0802,-9.6223745
195.6348,0.38346657,9.4516964,29.43165,0,18.0,450.0,0.99344552,1.7770307,18.113094,444.29544,-9.6422052
195.6372,0.32665479,9.4563074,28.373804,0,18.0,450.0,0.9941923,1.4903816,18.112772,444.51068,-9.6585817
195.6396,0.38423032,9.4536486,27.46582,0,18.0,450.0,0.99547255,1.7820601,18.110092,444.71777,-9.6768665
195.642,0.36723247,9.4496412,27.46582,0,18.0,450.0,0.99548537,1.7546887,18.109076,444.87558,-9.6947012
195.6444,0.32713827,9.4492397,27.46582,0,18.0,450.0,0.99426711,1.5234805,18.111338,445.03336,-9.7137804
195.6468,0.34764194,9.4547014,27.46582,0,18.0,450.0,0.99413514,1.6389174,18.106825,445.19113,-9.7307758
195.6492,0.36687255,9.4534864,27.46582,0,18.0,450.0,0.99411058,1.716594,18.106947,445.34894,-9.7483034
195.6516,0.36957005,9.4519053,26.514462,0,18.0,450.0,0.99498594,1.7490065,18.102695,445.53445,-9.7663488
195.654,0.34299904,9.4480925,25.530296,0,18.0,450.0,0.99511218,1.6435926,18.101923,445.72092,-9.7864408
195.6564,0.32798716,9.4500523,24.546133,0,18.0,450.0,0.99450237,1.5657017,18.099436,445.90738,-9.8038464
195.6588,0.32464188,9.4558372,23.561968,0,18.0,450.0,0.99416149,1.5410542,18.104179,446.09384,-9.8213911
195.6612,0.37715128,9.4586945,23.356934,0,18.0,450.0,0.99493241,1.7630931,18.099987,446.26895,-9.8387384
195.6636,0.35861424,9.4541044,23.356934,0,18.0,450.0,0.99560529,1.6941382,18.098417,446.44107,-9.8573093
195.666,0.32245582,9.4490442,23.356934,0,18.0,450.0,0.99546283,1.514122,18.098673,446.61322,-9.8756428
195.6684,0.32544333,9.4497118,23.356934,0,18.0,450.0,0.99445558,1.5245104,18.099602,446.78534,-9.893301
195.6708,0.36380643,9.452776,22.587759,0,18.0,450.0,0.99375135,1.7104594,18.097149,446.94861,-9.9102297
195.6732,0.37731057,9.4542294,21.34045,0,18.0,450.0,0.99430358,1.7621032,18.096148,447.10638,-9.9273281
195.6756,0.37976629,9.4522629,20.09314,0,18.0,450.0,0.99510503,1.800889,18.098249,447.26416,-9.9457016
195.678,0.33571506,9.4493227,18.845829,0,18.0,450.0,0.99538636,1.5588757,18.097378,447.42194,-9.9650545
195.6804,0.34540692,9.4489813,18.149414,0,18.0,450.0,0.99434108,1.6227199,18.098537,447.56387,-9.9826498
195.6828,0.38493678,9.456418,18.149414,0,18.0,450.0,0.99418485,1.8052305,18.096487,447.68579,-10.000379
195.6852,0.36357591,9.4595003,18.149414,0,18.0,450.0,0.99501973,1.7438285,18.091652,447.80771,-10.017643
195.6876,0.35714993,9.4556627,18.149414,0,18.0,450.0,0.99593359,1.681854,18.089867,447.92963,-10.036481
195.69,0.34012273,9.4466391,18.016087,0,18.0,450.0,0.99498689,1.6067967,18.091047,448.04773,-10.054381
195.6924,0.37058291,9.4483643,17.516111,0,18.0,450.0,0.99392003,1.7347931,18.089899,448.1553,-10.072135
195.6948,0.39479348,9.4550304,17.016134,0,18.0,450.0,0.99414599,1.8530459,18.086473,448.26291,-10.089983
195.6972,0.35863045,9.4574766,16.516157,0,18.0,450.0,0.99499476,1.7098505,18.089825,448.37048,-10.109142
195.6996,0.34690332,9.4541302,16.062012,0,18.0,450.0,0.99569952,1.6575705,18.090015,448.48004,-10.127281
195.702,0.36126015,9.4505625,16.062012,0,18.0,450.0,0.99548644,1.6986625,18.087347,448.60913,-10.143091
195.7044,0.38891491,9.4546032,16.062012,0,18.0,450.0,0.99503398,1.8290958,18.0874,448.73822,-10.161873
195.7068,0.39787051,9.459178,16.062012,0,18.0,450.0,0.99466485,1.9058,18.083275,448.86731,-10.179199
195.7092,0.35201976,9.4604597,16.062012,0,18.0,450.0,0.99516976,1.6700653,18.082335,448.9964,-10.197504
195.7116,0.3544288,9.4526873,14.9693,0,18.0,450.0,0.99550951,1.6781619,18.077326,449.10574,-10.216503
195.714,0.38357544,9.4463511,13.77725,0,18.0,450.0,0.99498022,1.7426896,18.078066,449.21335,-10.234176
195.7164,0.40433007,9.4508142,12.585201,0,18.0,450.0,0.99443799,1.9290991,18.080603,449.32092,-10.250883
195.7188,0.36864075,9.4588242,11.393152,0,18.0,450.0,0.99473101,1.7374352,18.078375,449.4285,-10.269226
195.7212,0.3514331,9.4569712,11.085205,0,18.0,450.0,0.99488318,1.6689831,18.079378,449.48822,-10.288185
195.7236,0.35169783,9.4532976,11.085205,0,18.0,450.0,0.99554551,1.6227014,18.075468,449.53122,-10.306511
195.726,0.38235241,9.4495745,11.085205,0,18.0,450.0,0.99522573,1.8058277,18.080473,449.57425,-10.323421
195.7284,0.39401367,9.4523697,11.085205,0,18.0,450.0,0.99457991,1.8656976,18.075096,449.61728,-10.34128
195.7308,0.33555016,9.4569397,10.180073,0,18.0,450.0,0.99433982,1.6031268,18.081589,449.68469,-10.359967
195.7332,0.34549642,9.45823,8.5827789,0,18.0,450.0,0.99496883,1.6465451,18.079271,449.77075,-10.377487
195.7356,0.37287548,9.4539509,6.985486,0,18.0,450.0,0.99576068,1.723374,18.082062,449.85681,-10.395603
195.738,0.38687232,9.449213,5.3881927,0,18.0,450.0,0.99531156,1.8300672,18.078211,449.94287,-10.414344
195.7404,0.34988299,9.4502611,4.4165039,0,18.0,450.0,0.9941256,1.671525,18.075989,450.02051,-10.432667
195.7428,0.35425013,9.4540644,4.4165039,0,18.0,450.0,0.99407351,1.6676861,18.0751,450.08508,-10.449008
195.7452,0.34353623,9.4550953,4.4165039,0,18.0,450.0,0.99453211,1.6066594,18.073864,450.14963,-10.467333
195.7476,0.3950792,9.4512281,4.4165039,0,18.0,450.0,0.99525881,1.8397821,18.076529,450.21417,-10.485071
195.75,0.38148275,9.449049,4.1917906,0,18.0,450.0,0.99501079,1.7854704,18.070759,450.27844,-10.503407
195.7524,0.3667801,9.4518032,3.1546474,0,18.0,450.0,0.99441612,1.708997,18.069235,450.34174,-10.521621
195.7548,0.36323294,9.4559937,2.1175044,0,18.0,450.0,0.99392486,1.6958475,18.071632,450.405,-10.540298
195.7572,0.36939922,9.4580622,1.0803612,0,18.0,450.0,0.99497551,1.7486206,18.07181,450.46829,-10.557837
195.7596,0.40610278,9.4542427,0.043218262,0,18.0,450.0,0.99581802,1.9049461,18.072994,450.53159,-10.576553
195.762,0.37848416,9.4499426,0.0,0,18.0,450.0,0.99547869,1.77911,18.06633,450.56171,-10.594429
195.7644,0.35715169,9.4516773,0.0,0,18.0,450.0,0.9945153,1.6793233,18.070616,450.59039,-10.610267
195.7668,0.3615272,9.4551907,0.0,0,18.0,450.0,0.99405038,1.7511344,18.070023,450.61908,-10.629189
195.7692,0.40645552,9.4572172,0.0,0,18.0,450.0,0.99501127,1.9119816,18.066462,450.64777,-10.647641
195.7716,0.39435637,9.4487286,0.0,0,18.0,450.0,0.99497223,1.863277,18.059891,450.70456,-10.66499
195.774,0.36065155,9.4475489,0.0,0,18.0,450.0,0.99506009,1.7331431,18.064728,450.7691,-10.682669
195.7764,0.36320069,9.4502249,0.0,0,18.0,450.0,0.99407709,1.6963176,18.064545,450.83365,-10.700066
195.7788,0.3954829,9.4553223,0.0,0,18.0,450.0,0.99393147,1.8480121,18.062565,450.89819,-10.71798
195.7812,0.40996256,9.4591293,0.0,0,18.0,450.0,0.99516606,1.9326437,18.060884,450.95837,-10.735413
195.7836,0.38407797,9.4565792,0.0,0,18.0,450.0,0.99626666,1.8264835,18.059999,451.01575,-10.75549
195.786,0.36776078,9.4488678,0.0,0,18.0,450.0,0.99505973,1.7242446,18.05756,451.07312,-10.773787
195.7884,0.35994783,9.4474173,0.0,0,18.0,450.0,0.99344039,1.7191775,18.059414,451.13052,-10.791888
195.7908,0.40144464,9.4529819,0.0,0,18.0,450.0,0.99377859,1.8833554,18.059725,451.18167,-10.810833
195.7932,0.39350754,9.4571629,0.0,0,18.0,450.0,0.99522161,1.863346,18.06069,451.2247,-10.828962
195.7956,0.37219033,9.4516087,0.0,0,18.0,450.0,0.99531567,1.7518365,18.062193,451.26773,-10.846399
195.798,0.3575801,9.4472523,0.0,0,18.0,450.0,0.99463326,1.6906217,18.061296,451.31073,-10.863366
195.8004,0.38436875,9.4496593,0.0,0,18.0,450.0,0.99375021,1.7911797,18.058512,451.34821,-10.880614
195.8028,0.42029756,9.4565506,0.0,0,18.0,450.0,0.99389589,1.9762456,18.060043,451.36972,-10.899278
195.8052,0.38217449,9.4548435,0.0,0,18.0,450.0,0.9945066,1.8107768,18.058533,451.39124,-10.917853
195.8076,0.36546433,9.4485216,0.0,0,18.0,450.0,0.99506986,1.7254614,18.055628,451.41278,-10.934604
195.81,0.36358935,9.4442787,0.0,0,18.0,450.0,0.99450123,1.7312284,18.058138,451.4325,-10.953567
195.8124,0.40182427,9.4490938,0.0,0,18.0,450.0,0.99368978,1.8893721,18.056412,451.4325,-10.971545
195.8148,0.40916649,9.4563169,0.0,0,18.0,450.0,0.99428332,1.9528568,18.056435,451.4325,-10.989381
195.8172,0.37656695,9.4554796,0.0,0,18.0,450.0,0.99498934,1.7501525,18.05522,451.4325,-11.008779
195.8196,0.36733735,9.4477167,0.0,0,18.0,450.0,0.99479771,1.7161834,18.050808,451.4325,-11.025237
195.822,0.3880839,9.4458885,0.0,0,18.0,450.0,0.99432015,1.761569,18.052139,451.48462,-11.044077
195.8244,0.42112043,9.4496479,0.0,0,18.0,450.0,0.99375403,1.9864163,18.050632,451.54199,-11.061103
195.8268,0.3997435,9.4550829,0.0,0,18.0,450.0,0.99381703,1.88478,18.048428,451.59937,-11.080278
195.8292,0.3699412,9.4556103,0.0,0,18.0,450.0,0.99478692,1.7587286,18.04837,451.65674,-11.096697
195.8316,0.36887687,9.450305,0.0,0,18.0,450.0,0.99534851,1.7392668,18.048794,451.69305,-11.114269
195.834,0.41392848,9.4457769,0.0,0,18.0,450.0,0.99458522,1.9216613,18.051491,451.72177,-11.133082
195.8364,0.41364667,9.4497633,0.0,0,18.0,450.0,0.99382788,1.9565332,18.05365,451.75046,-11.151422
195.8388,0.37274659,9.4570055,0.0,0,18.0,450.0,0.99452835,1.757475,18.050961,451.77914,-11.169918
195.8412,0.37363255,9.456049,0.0,0,18.0,450.0,0.99511927,1.7384446,18.046782,451.79181,-11.187185
195.8436,0.39307308,9.4499655,0.0,0,18.0,450.0,0.99519682,1.817191,18.049562,451.79181,-11.204684
195.846,0.42664462,9.4483719,0.0,0,18.0,450.0,0.99483037,2.0119896,18.047138,451.79181,-11.224654
195.8484,0.3990519,9.4506483,0.0,0,18.0,450.0,0.99387085,1.9373974,18.048212,451.79181,-11.242492
195.8508,0.37747589,9.45578,0.0,0,18.0,450.0,0.99387693,1.7729814,18.045568,451.80005,-11.259305
195.8532,0.36681664,9.4528704,0.0,0,18.0,450.0,0.99450964,1.7101961,18.045994,451.82156,-11.275039
195.8556,0.43184787,9.4466915,0.0,0,18.0,450.0,0.99474102,2.0078313,18.05228,451.84308,-11.292867
195.858,0.41391027,9.4456224,0.0,0,18.0,450.0,0.99432945,1.9805501,18.05155,451.86459,-11.311515
195.8604,0.38756725,9.4488773,0.0,0,18.0,450.0,0.99351144,1.8457853,18.049139,451.88162,-11.329785
195.8628,0.3700892,9.4524727,0.0,0,18.0,450.0,0.99367505,1.7570703,18.045355,451.88162,-11.348277
195.9649,0.38447881,9.4508963,0.0,0,18.0,19.512173,0.99445277,1.8132017,18.036945,449.53168,-11.468133
197.1649,0.3170293,9.4620028,0.0,0,18.0,8.5372038e-16,0.99643195,1.4924397,18.000725,423.13571,-11.480874
198.3649,0.29618064,9.4702044,0.0,0,18.0,3.6906185000000005e-32,0.99787563,1.3894227,17.998968,408.64157,-11.481035
199.5649,0.27820539,9.4776506,0.0,0,18.0,1.4012985e-45,0.99923748,1.3049654,17.999596,396.34909,-11.481857
200.7649,0.27073601,9.4843168,0.0,0,18.0,1.4012985e-45,1.0004714,1.2721145,18.000921,385.08963,-11.48216
201.9649,0.27446952,9.4909964,0.0,0,18.0,1.4012985e-45,1.0017277,1.2834077,18.00024,374.16833,-11.481379
203.1649,0.26908955,9.4978533,0.0,0,18.0,1.4012985e-45,1.0028232,1.2584853,17.998808,364.08844,-11.481027
204.3649,0.26723191,9.5037918,0.0,0,18.0,1.4012985e-45,1.0040343,1.2430264,17.999565,354.1337,-11.481288
205.5649,0.26170981,9.5096922,0.0,0,18.0,1.4012985e-45,1.0050539,1.2201011,18.000164,344.48459,-11.481764
206.7649,0.26477164,9.515749,0.0,0,18.0,1.4012985e-45,1.0061992,1.2365211,17.999939,334.94202,-11.481655
207.9649,0.26863551,9.5218906,0.0,0,18.0,1.4012985e-45,1.0072408,1.2442839,17.999681,325.74448,-11.481536
209.1649,0.26475745,9.5268326,0.0,0,18.0,1.4012985e-45,1.0082572,1.2263557,18.000988,317.04083,-11.481481
210.3649,0.26561156,9.5325365,0.0,0,18.0,1.4012985e-45,1.0092636,1.2362807,18.000006,308.45035,-11.481793
211.5649,0.26273713,9.5382404,0.0,0,18.0,1.4012985e-45,1.0102531,1.2206237,17.999676,299.78223,-11.481776
212.7649,0.2662479,9.5431194,0.0,0,18.0,1.4012985e-45,1.0111781,1.230001,17.999796,291.62698,-11.482195
213.9649,0.26514494,9.5481682,0.0,0,18.0,1.4012985e-45,1.012086,1.2270138,18.00029,283.61255,-11.481866
215.1649,0.26298338,9.5529652,0.0,0,18.0,1.4012985e-45,1.0130187,1.2143289,18.001589,275.94598,-11.48225
216.3649,0.26378691,9.5582542,0.0,0,18.0,1.4012985e-45,1.0138861,1.2206584,17.999269,268.43668,-11.482225
217.5649,0.25760752,9.5627117,0.0,0,18.0,1.4012985e-45,1.0148261,1.1888087,18.000048,261.15277,-11.481538
218.7649,0.26018929,9.5677958,0.0,0,18.0,1.4012985e-45,1.0157216,1.1958942,18.000017,254.01585,-11.481459
219.9649,0.26111293,9.5726852,0.0,0,18.0,1.4012985e-45,1.0165834,1.204623,18.000616,247.22276,-11.481527
221.1649,0.25192219,9.576436,0.0,0,18.0,1.4012985e-45,1.0172818,1.1537114,17.999908,240.40904,-11.481381
222.3649,0.25506258,9.5804939,0.0,0,18.0,1.4012985e-45,1.0180646,1.1748083,18.000391,233.82634,-11.48157
223.5649,0.25749302,9.5852394,0.0,0,18.0,1.4012985e-45,1.0189679,1.1809589,18.000099,227.65475,-11.481637
224.7649,0.26009473,9.5889454,0.0,0,18.0,1.4012985e-45,1.0195347,1.1911243,17.999874,221.52745,-11.481597
225.9649,0.25309101,9.5928297,0.0,0,18.0,1.4012985e-45,1.0203823,1.1570908,18.000378,215.79202,-11.481806
227.1649,0.25306267,9.5967913,0.0,0,18.0,1.4012985e-45,1.0210364,1.1612153,17.999949,210.02769,-11.481848
228.3649,0.25717211,9.6009951,0.0,0,18.0,1.4012985e-45,1.0218434,1.1786823,18.000135,204.39146,-11.482217
229.5649,0.25907537,9.6044903,0.0,0,18.0,1.4012985e-45,1.0224522,1.1861764,18.00024,198.91428,-11.482066
230.7649,0.25192386,9.6078291,0.0,0,18.0,1.4012985e-45,1.0231639,1.1503053,17.999176,193.57529,-11.48236
231.9649,0.25271353,9.6116209,0.0,0,18.0,1.4012985e-45,1.0238445,1.1566589,17.999622,188.64369,-11.482414
233.1649,0.24692197,9.6153946,0.0,0,18.0,1.4012985e-45,1.0244262,1.1312664,18.000549,183.87373,-11.482269
234.3649,0.25843099,9.618187,0.0,0,18.0,1.4012985e-45,1.0250645,1.1763315,17.999563,179.07919,-11.48185
235.5649,0.25219828,9.6210814,0.0,0,18.0,1.4012985e-45,1.0255315,1.1533166,17.999332,174.55215,-11.481769
236.7649,0.25064665,9.6242552,0.0,0,18.0,1.4012985e-45,1.0261869,1.1400523,17.999994,170.09874,-11.481727
237.9649,0.24328965,9.627388,0.0,0,18.0,1.4012985e-45,1.0267012,1.1104746,17.999563,165.69374,-11.481391
239.1649,0.25362751,9.6303215,0.0,0,18.0,1.4012985e-45,1.0273179,1.1575847,18.00004,161.3735,-11.481684
240.3649,0.25103033,9.6329451,0.0,0,18.0,1.4012985e-45,1.0278051,1.1407075,17.999937,157.52159,-11.481866
241.5649,0.25307828,9.6360025,0.0,0,18.0,1.4012985e-45,1.0283052,1.1490909,18.00005,153.65349,-11.482254
242.7649,0.24591009,9.639081,0.0,0,18.0,1.4012985e-45,1.0289863,1.118812,17.999676,149.98431,-11.482183
243.9649,0.25016245,9.6409073,0.0,0,18.0,1.4012985e-45,1.029237,1.1380799,17.999968,146.10547,-11.482282
245.1649,0.24357174,9.6441021,0.0,0,18.0,1.4012985e-45,1.0298718,1.105274,17.998865,142.64635,-11.48243
246.3649,0.24501777,9.6462011,0.0,0,18.0,1.4012985e-45,1.0301976,1.1138588,17.999449,139.20032,-11.482554
247.5649,0.23998454,9.6488047,0.0,0,18.0,1.4012985e-45,1.0307558,1.0892203,17.999538,135.84193,-11.482723
248.7649,0.24541225,9.6509962,0.0,0,18.0,1.4012985e-45,1.031159,1.1126605,18.000868,132.66724,-11.482648
249.9649,0.24227396,9.6533222,0.0,0,18.0,1.4012985e-45,1.0315256,1.1033528,17.998951,129.46016,-11.482089
251.1649,0.23921236,9.6559267,0.0,0,18.0,1.4012985e-45,1.0321008,1.0834242,17.999733,126.3811,-11.481681
252.3649,0.23976575,9.6584568,0.0,0,18.0,1.4012985e-45,1.0325081,1.0876001,17.99971,123.4376,-11.481511
253.5649,0.23941413,9.6606932,0.0,0,18.0,1.4012985e-45,1.0329647,1.0853423,17.999962,120.57948,-11.481192
254.7649,0.24809155,9.6624746,0.0,0,18.0,1.4012985e-45,1.0332336,1.1243441,17.999311,117.70675,-11.481617
255.8649,0.24295849,9.6643801,0.0,0,18.0,1.4012985e-45,1.0336361,1.1034933,17.999048,115.1563,-11.48163