File: examples/dan-msc-case-studies/CS4/data/01 raw data/hyde_test_011.csv
Time(sec),Force(kN),Jaw(mm),PowAngle(deg),PTemp,Strain,Stress(MPa),TC1(C),TC2(C),TC3(C),TC4(C)
0.0,4.6263,-9.9763,0.0,0.0,-0.78034,5.4962,24.019,24.247,24.514,24.31
0.6,4.5929,0.0094051,0.0,1.6204,0.001111,5.4505,24.05,24.318,24.553,24.388
1.2,4.5718,0.011043,0.0,3.4204,0.0012214,5.4266,24.048,24.322,24.508,24.345
1.8,4.538,0.011128,0.0,5.2204,0.0013744,5.3868,24.049,24.3,24.502,24.358
2.4,4.5113,0.011478,0.0,7.0204,0.0012471,5.3534,24.017,24.357,24.508,24.348
3.0,4.4926,0.0118,0.0,8.8204,0.0012673,5.3323,24.056,24.364,24.543,24.354
3.6,4.4798,0.011688,0.0,10.62,0.0013268,5.3166,24.004,24.35,24.546,24.347
4.2,4.4638,0.011475,0.0,12.42,0.0013924,5.2979,24.083,24.333,24.488,24.371
4.8,4.4627,0.011848,0.0,14.22,0.0013387,5.2962,24.022,24.277,24.512,24.355
5.3688,4.4508,0.011971,0.0,15.927,0.0012827,5.2813,24.072,24.345,24.505,24.327
5.9688,4.439,0.011894,0.0,17.727,0.0013399,5.2668,24.055,24.345,24.51,24.331
6.5688,4.4371,0.011808,0.0,19.527,0.0013076,5.2654,24.054,24.333,24.536,24.389
7.1688,4.432,0.011862,0.0,21.327,0.0014619,5.2586,23.994,24.346,24.523,24.351
7.7688,4.4336,0.012233,0.0,23.127,0.0013407,5.2595,24.029,24.306,24.559,24.327
8.3688,4.4277,0.012438,8.9943,24.927,0.0013386,5.253,24.03,24.35,24.482,24.358
8.9688,4.4241,0.013106,26.081,26.727,0.0014987,5.2489,24.048,24.363,24.544,24.344
9.5688,4.4391,0.013316,35.697,28.527,0.0015895,5.2663,24.421,24.721,24.537,24.443
10.1688,4.4511,0.013573,40.953,30.327,0.001577,5.2811,25.444,25.673,24.542,25.04
10.6665,4.4625,0.013614,43.439,31.82,0.001467,5.2965,26.885,26.794,24.564,26.095
11.2665,4.4677,0.013393,44.452,33.62,0.0015188,5.3024,29.297,28.626,24.675,28.233
11.8665,4.4748,0.01289,44.223,35.42,0.0015173,5.3103,32.1,37.72,24.951,31.038
12.4665,4.477,0.012814,43.417,37.22,0.0014897,5.3132,34.92,37.954,25.319,34.136
13.0665,4.4729,0.012749,42.505,39.02,0.0013463,5.3078,37.563,37.954,25.783,37.461
13.6665,4.4784,0.012268,41.594,40.82,0.0014212,5.3141,40.008,37.892,26.323,40.716
14.2665,4.4649,0.012394,40.753,42.62,0.0013947,5.2984,42.322,40.156,27.02,43.845
14.8665,4.4601,0.012391,39.94,44.42,0.0014656,5.292,44.457,42.361,27.856,46.746
15.4665,4.4464,0.012426,39.69,46.22,0.0013395,5.2756,46.361,44.512,28.742,49.465
16.0665,4.4529,0.010543,39.246,48.02,0.0012724,5.2831,48.251,46.492,29.836,51.968
16.6665,4.4543,0.0098306,39.537,49.82,0.0010437,5.2845,49.924,48.484,30.875,54.221
17.2665,4.4598,0.010041,39.612,51.62,0.0011272,5.2911,51.634,50.44,32.033,56.4
17.8665,4.4576,0.0097853,39.913,53.42,0.0010871,5.2889,53.393,52.332,33.283,58.505
18.4665,4.4568,0.0095781,40.169,55.22,0.0011836,5.2882,55.128,54.228,34.522,60.632
19.0665,4.4543,0.009441,40.086,57.02,0.0010779,5.285,56.938,56.335,35.831,62.709
19.6665,4.4535,0.0092956,40.127,58.82,0.00096833,5.284,58.722,58.516,37.113,64.86
20.2665,4.4611,0.0084928,40.283,60.62,0.00097689,5.2945,60.571,60.668,38.59,66.937
20.8665,4.4577,0.008444,39.954,62.42,0.00099208,5.2898,62.422,63.014,40.011,69.069
21.4665,4.4598,0.0078642,40.122,64.22,0.00094606,5.2935,64.23,65.235,41.482,71.096
22.0665,4.4611,0.0075635,39.927,66.02,0.00078679,5.2941,66.056,67.424,42.982,73.196
22.6665,4.4698,0.006787,40.065,67.82,0.0008466,5.3052,67.806,69.527,44.457,75.252
23.2665,4.4686,0.0067291,40.193,69.62,0.00070828,5.3038,69.618,71.645,46.043,77.178
23.8665,4.4765,0.0064738,39.958,71.42,0.00072573,5.3134,71.457,73.777,47.591,79.292
24.4665,4.4664,0.0058499,39.984,73.22,0.00064288,5.3013,73.249,75.964,49.148,81.251
25.0665,4.4732,0.0052388,39.996,75.02,0.0006862,5.3093,75.08,78.018,50.736,83.294
25.6665,4.4786,0.0049924,39.989,76.82,0.00057032,5.3153,76.919,79.986,52.309,85.276
26.2665,4.4827,0.0042533,40.097,78.62,0.00039221,5.3207,78.677,81.905,53.907,87.216
26.8665,4.4907,0.002474,39.875,80.42,0.00029767,5.3293,80.542,83.803,55.544,89.042
27.4665,4.4969,0.0013017,39.859,82.22,0.00013068,5.3372,82.32,85.774,57.222,91.043
28.0665,4.5043,0.00052923,39.722,84.02,0.00012477,5.3454,84.132,87.758,58.923,92.947
28.6665,4.5065,0.00038631,39.74,85.82,-1.7859e-06,5.3479,85.915,89.611,60.597,94.811
29.2665,4.5158,-2.067e-05,39.924,87.62,9.6723e-05,5.359,87.639,91.414,62.257,96.638
29.8665,4.5178,0.00016082,39.695,89.42,-3.9909e-05,5.3609,89.538,93.254,64.02,98.536
30.4665,4.5142,-2.1801e-05,39.924,91.22,-5.9984e-05,5.3571,91.253,95.012,65.658,100.36
31.0665,4.5235,-0.00080878,40.086,93.02,-8.3508e-05,5.3666,93.014,96.697,67.391,102.18
31.6665,4.5256,-0.0012291,40.36,94.82,-7.8439e-05,5.3697,94.735,98.419,69.077,104.05
32.2665,4.5284,-0.0018959,40.398,96.62,-0.00014958,5.3733,96.555,100.08,70.768,105.85
32.8665,4.5235,-0.0024952,40.572,98.42,-0.00036635,5.3673,98.289,101.82,72.476,107.76
33.4665,4.522,-0.003543,40.618,100.22,-0.00034183,5.365,100.16,103.55,74.191,109.7
34.0665,4.5271,-0.004121,40.572,102.02,-0.00052776,5.3717,101.97,105.28,75.919,111.56
34.6665,4.5324,-0.0047751,40.573,103.82,-0.00052627,5.377,103.8,107.14,77.681,113.55
35.2665,4.5303,-0.0055757,40.741,105.62,-0.00065073,5.3757,105.52,108.93,79.355,115.4
35.8665,4.5372,-0.0064009,40.573,107.42,-0.00062316,5.3841,107.38,110.67,81.116,117.2
36.4665,4.5455,-0.0070249,40.648,109.22,-0.0007684,5.394,109.19,112.64,82.912,119.09
37.0665,4.5407,-0.0075716,40.916,111.02,-0.00094469,5.3882,110.91,114.69,84.614,121.02
37.6665,4.5426,-0.008559,41.101,112.84,-0.00096689,5.3898,112.7,116.67,86.428,122.9
38.1053,4.5515,-0.009166,41.171,114.14,-0.0010597,5.4003,114.01,118.17,87.685,124.25
38.7053,4.5471,-0.010165,41.032,115.94,-0.0010425,5.3955,115.89,120.07,89.48,126.21
39.3053,4.5566,-0.01054,41.098,117.74,-0.0011631,5.4064,117.72,121.9,91.266,128.15
39.9053,4.5508,-0.011163,41.036,119.54,-0.001351,5.4002,119.51,123.78,93.035,130.09
40.5053,4.5556,-0.012356,41.187,121.34,-0.0013534,5.4059,121.28,125.56,94.787,131.98
41.1053,4.5588,-0.012895,41.134,123.14,-0.0014941,5.4098,123.11,127.22,96.555,133.83
41.7053,4.563,-0.013861,41.254,124.94,-0.0015213,5.4152,124.83,128.96,98.344,135.69
42.3053,4.5655,-0.014558,41.545,126.74,-0.0016708,5.4177,126.61,130.65,100.07,137.52
42.9053,4.5674,-0.015845,41.792,128.54,-0.0016849,5.4203,128.34,132.48,101.88,139.42
43.5053,4.5713,-0.016346,41.701,130.34,-0.0018257,5.425,130.21,134.32,103.71,141.26
44.1053,4.5757,-0.01683,41.803,132.14,-0.001997,5.4308,132.03,136.21,105.52,143.2
44.7053,4.5737,-0.018252,41.387,133.94,-0.0020051,5.4287,133.96,138.03,107.33,145.22
45.3053,4.5754,-0.018904,41.604,135.74,-0.0021817,5.4308,135.73,139.87,109.15,147.14
45.9053,4.5831,-0.019973,41.48,137.54,-0.0022211,5.4402,137.57,141.69,110.97,149.05
46.5053,4.585,-0.020749,41.348,139.34,-0.0023617,5.4423,139.39,143.59,112.79,150.86
47.1053,4.5851,-0.021985,41.595,141.14,-0.0023839,5.4431,141.15,145.29,114.58,152.7
47.7053,4.5913,-0.022655,41.658,142.94,-0.0025059,5.449,142.91,147.13,116.35,154.57
48.3053,4.5924,-0.023339,41.594,144.74,-0.0027175,5.4512,144.72,148.92,118.19,156.44
48.9053,4.5972,-0.024785,41.628,146.54,-0.002736,5.4559,146.53,150.72,119.95,158.22
49.5053,4.6006,-0.025473,41.802,148.34,-0.0029288,5.4593,148.3,152.63,121.83,160.14
50.1053,4.6043,-0.026635,41.871,150.14,-0.0030344,5.4645,150.1,154.38,123.61,161.9
50.7053,4.6039,-0.027801,41.857,151.94,-0.0031323,5.4625,151.87,156.21,125.44,163.77
51.3053,4.6028,-0.028547,41.805,153.74,-0.0031709,5.4616,153.71,158.16,127.22,165.59
51.9053,4.6052,-0.029438,42.197,155.54,-0.0032479,5.4648,155.42,159.96,129.01,167.46
52.5053,4.6072,-0.030273,42.29,157.34,-0.0034532,5.4669,157.23,161.79,130.81,169.35
53.1053,4.6055,-0.031734,42.395,159.14,-0.0034744,5.464,158.95,163.59,132.59,171.22
53.7053,4.5989,-0.032322,42.567,160.94,-0.0036878,5.4571,160.76,165.48,134.37,173.13
54.3053,4.6015,-0.033369,42.374,162.74,-0.0038474,5.4593,162.7,167.35,136.24,175.05
54.9053,4.6032,-0.034937,42.445,164.54,-0.0039321,5.4615,164.48,169.24,138.0,176.94
55.5053,4.5994,-0.035563,42.514,166.34,-0.0040305,5.4573,166.27,171.06,139.84,178.9
56.1053,4.5991,-0.036781,42.396,168.14,-0.004102,5.4568,168.13,172.88,141.55,180.76
56.7053,4.5995,-0.037635,42.514,169.94,-0.0042742,5.458,169.87,174.73,143.33,182.75
57.3053,4.5967,-0.039067,42.396,171.74,-0.0043087,5.4547,171.76,176.58,145.2,184.66
57.9053,4.5915,-0.040016,42.397,173.54,-0.0044662,5.4499,173.55,178.6,147.01,186.55
58.5053,4.5978,-0.040668,42.529,175.34,-0.004678,5.4572,175.28,180.46,148.74,188.47
59.1053,4.5903,-0.042497,42.41,177.14,-0.0047203,5.4474,177.14,182.35,150.52,190.36
59.7053,4.5954,-0.043087,42.461,178.94,-0.0049024,5.4544,178.92,184.22,152.33,192.28
60.3053,4.5978,-0.043995,42.613,180.74,-0.0049999,5.4575,180.71,186.11,154.12,194.12
60.9053,4.6044,-0.045328,42.485,182.54,-0.005073,5.465,182.55,187.99,156.01,196.08
61.5053,4.5974,-0.046273,42.595,184.34,-0.0051911,5.4577,184.3,189.95,157.78,197.94
62.1053,4.6011,-0.047385,42.524,186.14,-0.0052834,5.4615,186.11,192.05,159.64,199.81
62.7053,4.6028,-0.048553,42.683,187.94,-0.0055073,5.4634,187.89,194.07,161.47,201.75
63.3053,4.603,-0.050028,42.747,189.74,-0.0055465,5.4636,189.65,196.13,163.32,203.67
63.9053,4.6009,-0.050982,42.958,191.54,-0.0057069,5.461,191.46,198.13,165.11,205.54
64.5053,4.6078,-0.05192,42.977,193.34,-0.0059493,5.4683,193.29,200.29,166.95,207.53
65.1053,4.6034,-0.053499,42.858,195.14,-0.0059538,5.464,195.1,202.25,168.86,209.54
65.7053,4.6049,-0.054548,42.934,196.94,-0.0061995,5.4652,196.9,204.45,170.74,211.5
66.3053,4.6071,-0.055602,42.944,198.74,-0.0063241,5.4679,198.64,206.48,172.6,213.35
66.9053,4.6097,-0.05732,42.996,200.54,-0.0064311,5.4705,200.44,208.52,174.49,215.31
67.5053,4.6052,-0.058275,43.207,202.34,-0.0065666,5.4649,202.2,210.54,176.29,217.24
68.1053,4.6012,-0.05959,43.065,204.14,-0.0066707,5.4602,204.09,212.8,178.21,219.23
68.7053,4.6043,-0.060857,42.99,205.94,-0.0068607,5.4638,205.9,214.89,180.05,221.2
69.3053,4.5991,-0.062324,43.167,207.74,-0.0069185,5.4566,207.71,217.11,181.88,223.2
69.9053,4.6003,-0.063624,43.035,209.54,-0.0070783,5.458,209.52,219.29,183.74,225.11
70.3263,4.6108,-0.06444,43.416,210.81,-0.0073129,5.471,210.74,220.83,185.07,226.42
70.9263,4.6079,-0.065668,43.195,212.6,-0.0074792,5.4676,212.59,223.07,186.96,228.39
71.5263,4.6018,-0.067755,43.206,214.4,-0.0075956,5.4594,214.4,225.31,188.85,230.37
72.1263,4.6003,-0.069123,43.399,216.2,-0.0078304,5.4581,216.2,227.53,190.72,232.39
72.7263,4.5999,-0.07073,43.292,218.0,-0.0079767,5.4575,217.98,229.76,192.63,234.31
73.3263,4.6027,-0.07208,43.22,219.8,-0.0081152,5.4594,219.82,232.09,194.51,236.24
73.9263,4.6025,-0.073126,43.399,221.6,-0.0081991,5.4608,221.55,234.37,196.36,238.15
74.5263,4.6035,-0.074301,43.586,223.4,-0.0083021,5.4622,223.32,236.8,198.19,240.06
75.1263,4.6028,-0.07602,43.574,225.2,-0.0085742,5.461,225.15,239.07,200.02,242.0
75.7263,4.6011,-0.078478,43.528,227.0,-0.008719,5.4598,226.95,241.61,201.88,243.92
76.3263,4.5974,-0.080423,43.558,228.8,-0.0089828,5.4558,228.72,244.13,203.71,245.83
76.9263,4.6041,-0.081531,43.64,230.6,-0.009238,5.464,230.52,246.6,205.65,247.72
77.5263,4.605,-0.082455,43.859,232.4,-0.0091767,5.4656,232.29,249.02,207.5,249.7
78.1263,4.6031,-0.081966,43.897,234.2,-0.0092354,5.463,234.09,251.44,209.33,251.63
78.7263,4.6079,-0.082012,43.776,236.0,-0.0093355,5.468,235.95,253.85,211.13,253.66
79.3263,4.6087,-0.083324,43.574,237.8,-0.0092969,5.4709,237.83,256.3,213.02,255.69
79.9263,4.6104,-0.084395,43.655,239.6,-0.0095367,5.473,239.62,258.66,214.82,257.69
80.5263,4.611,-0.085723,43.759,241.4,-0.0097101,5.4733,241.39,261.02,216.64,259.64
81.1263,4.609,-0.087899,43.689,243.2,-0.0098329,5.4708,243.17,263.28,218.39,261.53
81.7263,4.6153,-0.089351,43.823,245.0,-0.010105,5.4791,244.97,265.5,220.29,263.48
82.3263,4.6143,-0.091002,43.867,246.8,-0.010276,5.4775,246.79,267.8,222.1,265.45
82.9263,4.6154,-0.092719,43.567,248.6,-0.010406,5.478,248.68,270.1,223.94,267.51
83.5263,4.6153,-0.09416,43.62,250.4,-0.010605,5.4772,250.41,272.17,225.69,269.45
84.1263,4.6131,-0.095641,43.943,252.2,-0.010746,5.4743,252.17,274.29,227.54,271.45
84.7263,4.6146,-0.097295,43.721,254.0,-0.010925,5.4764,254.05,276.42,229.31,273.44
85.3263,4.6091,-0.098724,43.716,255.8,-0.011073,5.4692,255.86,278.41,231.13,275.46
85.9263,4.6046,-0.10036,43.627,257.6,-0.011232,5.4636,257.64,280.35,232.96,277.42
86.5263,4.611,-0.10162,43.77,259.4,-0.011435,5.4713,259.42,282.28,234.77,279.32
87.1263,4.6117,-0.10345,44.049,261.2,-0.011565,5.4724,261.14,284.32,236.54,281.23
87.7263,4.6064,-0.10542,43.869,263.0,-0.011781,5.4656,263.02,286.41,238.43,283.23
88.3263,4.6065,-0.10643,43.915,264.8,-0.012003,5.4644,264.78,288.59,240.31,285.21
88.9263,4.6085,-0.10876,43.638,266.6,-0.012108,5.4679,266.68,290.66,242.14,287.24
89.5263,4.612,-0.1117,43.895,268.4,-0.012478,5.472,268.39,292.82,243.98,289.18
90.1263,4.6124,-0.11308,44.067,270.2,-0.012777,5.4721,270.18,295.01,245.82,291.09
90.7263,4.6096,-0.11323,43.962,272.0,-0.012625,5.4698,271.98,297.18,247.74,293.01
91.3263,4.6056,-0.11251,43.996,273.8,-0.012607,5.4657,273.78,299.46,249.6,294.98
91.9263,4.6067,-0.11281,44.062,275.6,-0.01273,5.466,275.52,301.64,251.56,296.95
92.5263,4.6072,-0.11519,44.078,277.4,-0.012817,5.4678,277.33,304.19,253.51,298.9
93.1263,4.6067,-0.11697,44.197,279.2,-0.013115,5.4675,279.12,307.38,255.41,300.87
93.7263,4.6084,-0.11864,44.151,281.0,-0.013395,5.4708,280.96,310.08,257.35,302.91
94.3263,4.6071,-0.12131,44.175,282.8,-0.013519,5.4693,282.76,312.43,259.29,304.96
94.9263,4.6109,-0.12262,44.164,284.6,-0.013773,5.4736,284.61,314.38,261.25,307.08
95.5263,4.6124,-0.12424,44.089,286.4,-0.014028,5.4759,286.43,316.23,263.24,309.16
96.1263,4.6085,-0.12658,44.074,288.2,-0.014126,5.471,288.27,318.55,265.29,311.24
96.7263,4.6105,-0.1277,44.029,290.0,-0.014365,5.4727,290.05,320.86,267.33,313.26
97.3263,4.6131,-0.12914,44.078,291.8,-0.014578,5.4752,291.82,323.31,269.45,315.27
97.9263,4.6109,-0.13131,44.191,293.6,-0.014664,5.4739,293.58,325.59,271.81,317.31
98.5263,4.615,-0.13276,44.209,295.4,-0.014933,5.4781,295.35,327.87,274.53,319.21
99.1263,4.6148,-0.13463,44.324,297.2,-0.015178,5.4773,297.12,330.12,282.39,321.2
99.7263,4.6171,-0.1362,44.469,299.0,-0.015232,5.4796,298.91,332.61,296.29,323.24
100.3263,4.6174,-0.13798,44.483,300.8,-0.015518,5.479,300.75,335.05,304.05,325.34
100.9263,4.6224,-0.14147,44.319,302.6,-0.015912,5.4852,302.6,337.34,310.15,327.48
101.5263,4.6197,-0.1441,44.343,304.4,-0.016122,5.4818,304.4,339.51,314.96,329.56
102.1263,4.6231,-0.14379,44.484,306.2,-0.016196,5.4854,306.16,341.66,318.72,331.62
102.7263,4.6215,-0.14317,44.604,308.0,-0.016149,5.4829,307.88,343.85,319.62,333.78
103.1483,4.6232,-0.14305,44.438,309.27,-0.016017,5.4863,309.3,345.53,320.76,335.3
103.7483,4.6206,-0.14435,43.806,311.07,-0.016171,5.4828,311.3,347.59,323.72,337.45
104.3483,4.6174,-0.14622,43.639,312.87,-0.016349,5.4799,313.11,349.39,325.68,339.38
104.9483,4.6228,-0.1481,42.377,314.67,-0.016551,5.485,315.39,351.29,328.11,341.15
105.5483,4.6128,-0.14919,41.884,316.47,-0.016722,5.4739,317.25,352.39,330.44,342.76
106.1483,4.6201,-0.15098,42.315,318.27,-0.016867,5.4824,318.68,353.36,332.32,343.88
106.7483,4.6197,-0.15295,43.162,320.07,-0.017077,5.4816,320.09,354.67,334.26,344.9
107.3483,4.6194,-0.1546,43.732,321.87,-0.017328,5.4812,321.65,356.3,336.17,346.21
107.9483,4.616,-0.15667,44.076,323.67,-0.017497,5.4772,323.34,358.08,338.15,347.67
108.5483,4.613,-0.15884,44.455,325.47,-0.01774,5.4733,325.08,359.87,340.05,349.47
109.1483,4.5828,-0.16058,44.596,327.27,-0.018001,5.4382,326.89,361.9,341.61,351.45
109.7483,4.4254,-0.16373,44.604,329.07,-0.018285,5.2517,328.79,363.93,343.43,353.55
110.3483,4.2666,-0.1662,44.91,330.87,-0.018559,5.0633,330.53,366.11,345.55,355.68
110.9483,4.0895,-0.16975,45.12,332.67,-0.019019,4.8536,332.31,368.38,347.69,357.85
111.5483,3.9294,-0.17296,44.551,334.47,-0.019305,4.6642,334.45,370.82,350.13,360.08
112.1483,3.8142,-0.17599,44.82,336.27,-0.019655,4.5257,336.11,373.12,352.1,362.39
112.7483,3.7621,-0.17755,44.61,338.07,-0.019883,4.4655,338.07,375.28,354.18,364.6
113.3483,3.7254,-0.18034,44.227,339.87,-0.020117,4.4221,340.04,377.27,356.13,366.73
113.9483,3.6942,-0.18426,44.721,341.67,-0.020527,4.3849,341.58,379.23,358.08,368.69
114.5483,3.6945,-0.18719,44.963,343.47,-0.020947,4.3857,343.3,381.32,360.16,370.61
115.1483,3.7001,-0.18776,45.153,345.27,-0.021006,4.3924,344.98,383.57,362.8,372.66
115.7483,3.6936,-0.18719,45.499,347.07,-0.020928,4.3847,346.75,385.92,365.02,374.77
116.3483,3.6593,-0.18818,46.05,348.87,-0.021056,4.3447,348.38,388.37,367.01,376.99
116.9483,3.5497,-0.19017,42.581,350.0,-0.02123,4.2137,351.05,390.29,369.13,379.42
117.5483,3.4295,-0.19184,39.824,350.0,-0.021406,4.0713,351.87,390.86,371.55,381.33
118.1483,3.354,-0.19297,37.567,350.0,-0.021577,3.9806,352.2,390.14,373.25,381.94
118.7483,3.336,-0.19379,37.373,350.0,-0.021645,3.9592,351.71,388.87,375.18,381.57
119.3483,3.338,-0.19525,38.224,350.0,-0.021818,3.9606,351.14,388.03,375.76,380.59
119.9483,3.337,-0.19637,37.754,350.0,-0.02196,3.9597,351.06,386.64,376.22,379.77
120.5483,3.3385,-0.19711,37.202,350.0,-0.022035,3.9606,350.97,386.53,376.25,379.0
121.1483,3.337,-0.19761,36.717,350.0,-0.022098,3.9589,350.92,385.54,376.02,378.17
121.7483,3.3431,-0.19849,36.933,350.0,-0.022188,3.9667,350.7,384.39,376.11,377.2
122.3483,3.3417,-0.19985,37.702,350.0,-0.022382,3.9647,350.29,383.45,375.63,376.17
122.9483,3.3507,-0.20105,36.864,350.0,-0.022492,3.9749,350.49,382.63,375.35,375.24
123.5483,3.354,-0.2028,37.446,350.0,-0.022668,3.9792,350.18,381.99,374.93,374.49
124.1483,3.3594,-0.20082,38.194,350.0,-0.022522,3.9855,350.0,381.44,374.4,373.68
124.7483,3.3555,-0.20132,37.892,350.0,-0.022562,3.9808,350.1,381.18,373.89,373.11
125.3483,3.3608,-0.20274,37.526,350.0,-0.022636,3.9881,350.15,380.64,373.47,372.66
125.9483,3.3534,-0.2035,36.866,350.0,-0.022804,3.9794,350.33,379.85,373.06,372.08
126.5483,3.36,-0.20449,37.669,350.0,-0.022938,3.987,350.0,379.22,372.54,371.48
127.1483,3.3612,-0.2063,38.808,350.0,-0.023004,3.99,349.65,379.14,371.67,370.79
127.7483,3.3633,-0.20686,38.583,350.0,-0.02317,3.9923,349.76,379.16,371.42,370.44
128.3483,3.3616,-0.20795,38.089,350.0,-0.02333,3.9901,349.95,379.27,371.13,370.33
128.9483,3.3499,-0.20962,33.262,350.0,-0.02335,3.9763,350.0,378.81,370.85,370.28
129.5483,3.3265,-0.20693,31.531,350.0,-0.023154,3.9493,348.9,376.38,370.32,369.61
130.1483,3.3283,-0.20686,33.711,350.0,-0.023192,3.9524,347.63,374.31,369.72,368.11
130.7483,3.3466,-0.20834,33.363,350.0,-0.023163,3.9724,347.02,372.99,368.79,366.44
131.3483,3.3395,-0.20865,32.691,350.0,-0.023287,3.9644,346.3,371.54,367.79,365.02
131.9483,3.3358,-0.20886,32.301,350.0,-0.023397,3.9597,345.54,369.93,366.87,363.56
132.5483,3.3395,-0.20965,32.859,350.0,-0.023325,3.9641,344.7,368.08,365.63,362.05
133.1483,3.3485,-0.21082,34.559,350.0,-0.023502,3.9742,344.08,366.99,364.52,360.59
133.7483,3.3515,-0.21264,34.387,350.0,-0.023782,3.9776,343.75,366.27,363.3,359.44
134.3483,3.3654,-0.2112,34.984,350.0,-0.023558,3.9937,343.35,365.77,362.19,358.47
134.9483,3.3674,-0.21066,32.062,350.0,-0.023478,3.9956,342.98,364.88,361.2,357.62
135.4733,3.3425,-0.21116,32.952,350.0,-0.023599,3.9659,342.22,363.51,360.2,356.8
136.0733,3.3462,-0.21147,29.21,350.0,-0.023637,3.971,341.46,362.36,359.15,355.64
136.6733,3.3232,-0.21174,29.033,350.0,-0.023621,3.9443,340.36,360.02,357.84,354.32
137.2733,3.3194,-0.21124,23.011,350.0,-0.023586,3.9398,338.75,356.83,356.44,352.65
137.8733,3.3063,-0.21129,21.944,350.0,-0.02361,3.9239,336.78,352.94,354.98,350.55
138.4733,3.2996,-0.21198,26.255,350.0,-0.023711,3.9152,334.85,350.1,353.36,348.0
139.0733,3.3134,-0.21231,31.751,350.0,-0.023786,3.9336,333.71,348.72,351.61,345.54
139.6733,3.326,-0.2122,33.078,350.0,-0.023667,3.9477,333.52,348.46,349.87,343.66
140.2733,3.3454,-0.21319,37.33,350.0,-0.023871,3.972,333.51,348.7,348.36,342.46
140.8733,3.3724,-0.2151,39.314,350.0,-0.024115,4.0038,334.61,350.82,347.12,341.93
141.4091,3.3744,-0.21643,38.143,350.0,-0.024123,4.0038,335.86,352.35,346.43,342.45
142.0091,3.3775,-0.21703,38.219,350.0,-0.024278,4.0072,336.78,353.58,345.84,343.27
142.6091,3.3842,-0.21837,39.182,350.0,-0.024486,4.0142,337.54,354.79,345.51,344.11
143.2091,3.383,-0.22209,40.427,350.0,-0.024692,4.0132,338.52,356.53,345.42,345.06
143.8091,3.3902,-0.22007,45.055,350.0,-0.024567,4.0229,340.1,359.05,345.73,346.28
144.4091,3.3932,-0.22222,47.551,350.0,-0.024865,4.026,343.48,364.1,346.45,348.24
145.0091,3.3784,-0.22484,43.469,350.0,-0.025014,4.0093,346.78,368.32,347.69,351.58
145.6091,3.3757,-0.22614,42.192,350.0,-0.025196,4.0052,349.06,371.66,349.35,355.01
146.2091,3.3618,-0.22683,38.978,350.0,-0.025333,3.9899,350.19,372.97,350.93,357.96
146.8091,3.3634,-0.22731,37.396,350.0,-0.025368,3.9918,350.48,373.11,352.59,359.91
147.4091,3.3603,-0.22798,36.196,350.0,-0.025468,3.9877,350.56,372.68,353.95,360.93
148.0091,3.334,-0.22737,26.556,350.0,-0.025369,3.956,350.3,371.14,355.17,361.36
148.6091,3.3312,-0.2277,31.081,350.0,-0.025495,3.9529,348.64,367.76,355.82,360.64
149.2091,3.338,-0.22665,33.72,350.0,-0.02539,3.9628,347.7,366.65,356.2,359.17
149.8091,3.359,-0.22839,34.296,350.0,-0.025421,3.9867,347.46,366.16,356.33,358.03
150.4091,3.3663,-0.22878,34.153,350.0,-0.025538,3.9958,347.35,365.6,356.33,357.2
151.0091,3.3761,-0.22966,34.484,350.0,-0.025685,4.0082,347.24,365.22,356.24,356.48
151.6091,3.3818,-0.23094,34.648,350.0,-0.02568,4.0146,347.07,364.8,356.05,355.95
152.2091,3.3789,-0.23145,35.018,350.0,-0.025787,4.0109,347.01,364.5,355.83,355.52
152.8091,3.373,-0.23219,35.107,350.0,-0.025931,4.0045,346.96,364.35,355.58,355.15
153.4091,3.3801,-0.23352,35.28,350.0,-0.026043,4.0117,346.97,364.23,355.41,354.83
154.0091,3.3807,-0.23571,35.161,350.0,-0.026313,4.0124,346.96,364.08,355.13,354.62
154.6091,3.3814,-0.23474,35.34,350.0,-0.026202,4.0134,346.98,364.05,354.94,354.45
155.2091,3.3902,-0.23385,35.34,350.0,-0.026157,4.0234,346.92,363.96,354.68,354.28
155.8091,3.3883,-0.23466,35.302,350.0,-0.026277,4.0206,346.99,363.93,354.49,354.16
156.4091,3.3907,-0.23604,35.393,350.0,-0.026259,4.0232,346.92,363.82,354.27,354.03
157.0091,3.3873,-0.23649,35.49,350.0,-0.02636,4.0193,346.95,363.76,354.12,353.94
157.6091,3.3816,-0.23732,35.497,350.0,-0.026539,4.0121,346.98,363.76,353.98,353.79
158.2091,3.3838,-0.2382,35.257,350.0,-0.02651,4.0147,347.03,363.72,353.83,353.74
158.8091,3.3839,-0.23871,35.404,350.0,-0.026592,4.0142,347.03,363.64,353.71,353.65
159.4091,3.3692,-0.23994,35.132,350.0,-0.026764,3.9977,347.06,363.47,353.56,353.6
160.0091,3.1655,-0.24159,34.795,350.0,-0.026992,3.7553,347.09,363.34,353.41,353.45
160.6091,2.9436,-0.24531,35.292,350.0,-0.02744,3.4933,347.0,363.31,353.27,353.31
161.2091,2.7617,-0.24539,35.094,350.0,-0.027338,3.2765,347.01,363.13,353.2,353.24
161.7968,2.6699,-0.036888,35.08,350.0,-0.0041365,3.1695,346.97,362.98,353.13,353.16
161.9504,2.6469,0.0063646,0.0,1.6578,0.00090539,3.1322,347.07,362.91,353.18,353.21
161.9534,2.6831,0.0071122,0.0,0.00013442,0.00058115,3.1807,347.02,362.91,353.12,353.15
161.9564,2.6511,0.0077706,0.0,1.09e-08,0.00077516,3.1472,346.96,362.91,353.07,353.1
161.9594,2.6893,0.0071095,0.0,8.8381e-13,0.00099003,3.1911,346.91,362.91,353.01,353.04
161.9624,2.6428,0.0065465,0.0,7.1665e-17,0.00078467,3.1339,346.9,362.93,353.01,353.04
161.9654,2.6922,0.0066742,0.0,5.811e-21,0.00036925,3.1892,346.89,362.95,353.01,353.04
161.9684,2.6452,0.0064598,0.0,4.7119e-25,0.00026378,3.1326,346.88,362.97,353.01,353.04
161.9714,2.6779,0.0053218,0.0,3.8207000000000005e-29,0.00062778,3.1896,346.89,362.98,353.01,353.06
161.9744,2.6385,0.0031215,0.0,3.0981000000000005e-33,0.00081216,3.1319,346.93,362.98,353.02,353.11
161.9774,2.6853,0.0047146,0.0,2.5121e-37,0.0010683,3.1864,346.97,362.98,353.03,353.15
161.9804,2.6451,0.0063077,0.0,2.0369000000000002e-41,0.00076998,3.1325,346.99,362.97,353.04,353.19
161.9834,2.6697,0.0079137,0.0,1.4013e-45,0.00066924,3.1747,346.98,362.93,353.04,353.19
161.9864,2.6394,0.0069557,0.0,0.0,0.00079477,3.1288,346.97,362.89,353.04,353.19
161.9894,2.6646,0.0064747,0.0,0.0,0.0010253,3.1664,346.97,362.86,353.04,353.19
161.9924,2.6386,0.0069196,0.0,0.0,0.0006141,3.1207,346.97,362.84,353.05,353.16
161.9954,2.6593,0.0070499,0.0,0.0,0.00034571,3.1675,346.98,362.82,353.07,353.14
161.9984,2.6399,0.0059272,0.0,0.0,0.0002389,3.1344,346.99,362.8,353.09,353.11
162.0014,2.6543,0.0046602,0.0,0.0,0.00055749,3.1496,346.98,362.81,353.11,353.1
162.0044,2.6471,0.0044701,0.0,0.0,0.00098834,3.1373,346.97,362.85,353.12,353.1
162.0074,2.6494,0.0055693,0.0,0.0,0.0010575,3.1515,346.95,362.89,353.14,353.1
162.0104,2.6399,0.006537,0.0,0.0,0.00075681,3.1396,346.93,362.92,353.15,353.1
162.0134,2.6481,0.007753,0.0,0.0,0.00065784,3.147,346.9,362.94,353.13,353.1
162.0164,5.0264,0.0068366,0.0,0.0,0.00095386,6.0241,346.87,362.96,353.12,353.1
162.0194,13.848,0.059492,0.0,0.0,0.0067746,16.372,346.84,362.97,353.1,353.1
162.0224,26.736,0.14412,0.0,0.0,0.016262,31.391,347.77,363.85,353.1,353.03
162.0254,44.003,0.21541,0.0,0.0,0.024015,51.783,348.77,364.79,353.11,352.96
162.0284,62.34,0.26978,0.0,0.0,0.030476,73.614,349.77,365.74,353.12,352.88
162.0314,74.394,0.31744,0.0,0.0,0.036434,88.039,351.33,367.4,353.13,352.82
162.0344,84.575,0.47103,0.0,0.0,0.054546,100.14,353.26,369.54,353.13,352.77
162.0374,93.3,0.75085,0.0,0.0,0.087815,110.55,355.19,371.69,353.13,352.71
162.0404,97.251,1.0889,0.0,0.0,0.12921,115.35,356.94,373.66,353.11,352.67
162.0434,99.348,1.4169,0.0,0.0,0.17153,117.86,358.18,375.15,353.07,352.67
162.0464,100.43,1.7173,0.0,0.0,0.21241,119.16,359.42,376.64,353.02,352.67
162.0494,100.72,1.9747,0.0,0.0,0.24827,119.52,360.66,378.13,352.98,352.67
162.0524,100.62,2.1931,0.0,0.0,0.27894,119.41,361.33,378.75,353.0,352.65
162.0554,100.33,2.3825,0.0,0.0,0.30625,119.04,361.97,379.31,353.03,352.62
162.0584,100.39,2.5513,0.0,0.0,0.33173,119.12,362.61,379.88,353.06,352.59
162.0614,100.62,2.7145,0.0,0.0,0.35785,119.39,363.25,380.46,353.08,352.6
162.0644,101.15,2.8865,0.0,0.0,0.38528,120.01,363.88,381.06,353.1,352.64
162.0674,101.67,3.0597,0.0,0.0,0.41283,120.63,364.52,381.66,353.11,352.68
162.0704,102.19,3.2426,0.0,0.0,0.4423,121.25,365.14,382.25,353.13,352.72
162.0734,102.52,3.4207,0.0,0.0,0.47246,121.65,365.7,382.81,353.15,352.8
162.0764,102.81,3.5924,0.0,0.0,0.5032,122.0,366.27,383.37,353.17,352.87
162.0794,102.97,3.7577,0.0,0.0,0.53275,122.18,366.83,383.94,353.19,352.94
162.0824,103.1,3.9203,0.0,0.0,0.56155,122.35,367.39,384.41,353.23,352.94
162.0854,103.17,4.0763,0.0,0.0,0.59062,122.42,367.96,384.88,353.28,352.94
162.0884,103.21,4.2282,0.0,0.0,0.62073,122.48,368.52,385.36,353.32,352.94
162.0914,103.24,4.3713,0.0,0.0,0.6503,122.5,369.09,385.79,353.33,352.96
162.0944,103.25,4.5097,0.0,0.0,0.67907,122.53,369.66,386.21,353.31,352.97
162.0974,103.29,4.6499,0.0,0.0,0.70756,122.56,370.24,386.63,353.29,352.99
162.1004,103.32,4.7886,0.0,0.0,0.73632,122.61,370.78,387.02,353.27,353.01
162.1034,103.36,4.9193,0.0,0.0,0.76532,122.64,371.27,387.38,353.23,353.03
162.1064,103.39,5.0471,0.0,0.0,0.79542,122.69,371.76,387.73,353.19,353.05
162.1094,103.45,5.1702,0.0,0.0,0.82364,122.75,372.25,388.08,353.16,353.07
162.1124,103.51,5.2917,0.0,0.0,0.85123,122.83,372.6,388.45,353.14,353.06
162.1154,103.58,5.4135,0.0,0.0,0.8806,122.91,372.95,388.81,353.12,353.05
162.1184,103.59,5.5277,0.0,0.0,0.91027,122.93,373.29,389.17,353.1,353.04
162.1214,103.62,5.6371,0.0,0.0,0.93983,122.96,373.55,389.49,353.1,353.02
162.1244,103.67,5.7468,0.0,0.0,0.96912,123.03,373.76,389.79,353.1,353.01
162.1274,103.73,5.8535,0.0,0.0,0.99672,123.09,373.97,390.09,353.1,352.99
162.1304,103.74,5.9591,0.0,0.0,1.0251,123.1,374.13,390.33,353.1,352.97
162.1334,103.84,6.0592,0.0,0.0,1.0543,123.22,374.21,390.44,353.1,352.95
162.1364,103.9,6.1542,0.0,0.0,1.0832,123.3,374.28,390.55,353.1,352.93
162.1394,104.03,6.2503,0.0,0.0,1.111,123.45,374.35,390.66,353.1,352.91
162.1424,104.05,6.3447,0.0,0.0,1.1385,123.47,374.35,390.54,353.11,352.91
162.1454,104.16,6.4364,0.0,0.0,1.1673,123.61,374.35,390.42,353.11,352.91
162.1484,104.32,6.5224,0.0,0.0,1.1969,123.79,374.35,390.3,353.12,352.91
162.1514,104.56,6.6066,0.0,0.0,1.2267,124.08,374.24,390.02,353.13,352.91
162.1544,104.66,6.6878,0.0,0.0,1.2543,124.19,374.08,389.66,353.13,352.9
162.1574,104.92,6.7722,0.0,0.0,1.2816,124.51,373.91,389.29,353.13,352.89
162.1604,105.15,6.8517,0.0,0.0,1.3091,124.77,373.6,388.82,353.13,352.87
162.1634,105.45,6.9282,0.0,0.0,1.3387,125.13,372.99,388.13,353.15,352.83
162.1664,105.63,7.0008,0.0,0.0,1.3673,125.35,372.38,387.44,353.17,352.8
162.1694,101.38,7.0674,0.0,0.0,1.3914,120.45,371.76,386.75,353.19,352.76
162.1724,96.244,7.0947,0.0,0.0,1.4005,114.31,370.92,385.95,353.18,352.81
162.1754,93.115,7.1055,0.0,0.0,1.4052,110.56,370.07,385.15,353.17,352.85
162.1784,90.848,7.1161,0.0,0.0,1.4113,107.85,369.23,384.35,353.16,352.9
162.1814,89.173,7.1188,0.0,0.0,1.4143,105.85,368.47,383.63,353.14,352.94
162.1844,87.745,7.1266,0.0,0.0,1.417,104.15,367.74,382.93,353.11,352.98
162.1874,86.575,7.1358,0.0,0.0,1.4183,102.76,367.01,382.23,353.08,353.01
162.1904,85.437,7.1405,0.0,0.0,1.4197,101.41,366.31,381.54,353.08,353.04
162.1934,84.445,7.1447,0.0,0.0,1.4234,100.23,365.67,380.88,353.1,353.04
162.1964,83.412,7.1466,0.0,0.0,1.4247,98.999,365.02,380.22,353.13,353.04
162.1994,82.388,7.15,0.0,0.0,1.4238,97.789,364.38,379.56,353.16,353.04
162.2024,81.219,7.1532,0.0,0.0,1.4236,96.409,363.81,378.99,353.19,353.05
162.2054,79.392,7.154,0.0,0.0,1.4243,94.262,363.25,378.41,353.21,353.07
162.2084,75.434,7.1501,0.0,0.0,1.4255,89.632,362.68,377.84,353.24,353.09
162.2114,68.751,7.1403,0.0,0.0,1.4233,81.83,362.38,377.52,353.23,353.07
162.2144,23.54,7.0396,0.0,0.0,1.3832,29.023,362.19,377.3,353.2,353.03
162.2174,0.9707,6.956,0.0,0.0,1.3481,1.0073,362.0,377.08,353.17,353.0
162.2204,2.2851,6.9871,0.0,0.0,1.3601,2.7314,361.92,376.99,353.16,352.97
162.2234,2.2898,6.9827,0.0,0.0,1.3608,2.7419,362.02,377.1,353.17,352.97
162.2264,2.0949,6.9811,0.0,0.0,1.36,2.4653,362.12,377.21,353.18,352.97
162.2294,2.2163,6.9783,0.0,0.0,1.3568,2.6397,362.22,377.32,353.19,352.98
162.2324,2.2375,6.9791,0.0,0.0,1.3559,2.6305,362.32,377.39,353.24,353.03
162.2354,2.1121,6.977,0.0,0.0,1.3563,2.5267,362.42,377.46,353.28,353.09
162.2384,2.3027,6.9724,0.0,0.0,1.3568,2.7161,362.52,377.54,353.33,353.14
162.2414,2.1987,6.9726,0.0,0.0,1.3581,2.6125,362.6,377.57,353.32,353.16
162.2444,2.2438,6.9739,0.0,0.0,1.3569,2.6387,362.68,377.59,353.29,353.16
162.2474,2.183,6.9779,0.0,0.0,1.3566,2.5944,362.75,377.61,353.26,353.16
162.2504,2.2163,6.9781,0.0,0.0,1.3571,2.6189,362.8,377.62,353.23,353.13
162.2534,2.1633,6.9757,0.0,0.0,1.3583,2.5811,362.82,377.62,353.2,353.05
162.2564,2.2577,6.9757,0.0,0.0,1.358,2.6694,362.84,377.62,353.16,352.98
162.2594,2.1796,6.9786,0.0,0.0,1.3562,2.587,362.86,377.62,353.13,352.91
162.2624,2.226,6.9785,0.0,0.0,1.3554,2.6296,362.88,377.67,353.17,352.91
162.2654,2.1774,6.9766,0.0,0.0,1.3565,2.5855,362.91,377.73,353.2,352.91
162.2684,2.2398,6.9745,0.0,0.0,1.3578,2.6468,362.94,377.78,353.24,352.91
162.2714,2.1756,6.9725,0.0,0.0,1.358,2.5894,362.97,377.85,353.26,352.94
162.2744,2.2592,6.9755,0.0,0.0,1.3573,2.6827,362.99,377.92,353.28,352.98
162.2774,2.1987,6.9782,0.0,0.0,1.3564,2.6063,363.02,378.0,353.3,353.01
162.2804,2.2557,6.9766,0.0,0.0,1.3568,2.6803,363.04,378.04,353.3,353.04
162.2834,2.1973,6.9752,0.0,0.0,1.3581,2.6084,363.04,378.03,353.3,353.06
162.2864,2.2773,6.976,0.0,0.0,1.3576,2.7028,363.04,378.02,353.29,353.08
162.2894,2.2155,6.9782,0.0,0.0,1.3563,2.6272,363.04,378.01,353.28,353.1
162.2924,2.2445,6.9795,0.0,0.0,1.3559,2.6662,363.04,378.01,353.26,353.12
162.2954,2.1857,6.9778,0.0,0.0,1.3573,2.5888,363.04,378.01,353.24,353.13
162.2984,2.2996,6.9755,0.0,0.0,1.3585,2.733,363.04,378.01,353.22,353.15
162.3014,2.2574,6.9759,0.0,0.0,1.3587,2.6755,363.02,378.02,353.2,353.16
162.3044,2.3681,6.9776,0.0,0.0,1.3577,2.8117,363.0,378.02,353.18,353.16
162.3074,2.3481,6.9793,0.0,0.0,1.357,2.7893,362.99,378.03,353.17,353.16
162.3104,2.406,6.9795,0.0,0.0,1.3584,2.8663,362.96,378.02,353.17,353.16
162.3134,2.4068,6.9786,0.0,0.0,1.3596,2.8493,362.92,377.99,353.21,353.16
162.3164,2.4475,6.9801,0.0,0.0,1.3587,2.9247,362.89,377.95,353.25,353.16
162.3194,2.3912,6.9785,0.0,0.0,1.3556,2.8133,362.85,377.91,353.28,353.16
162.3224,2.4656,6.98,0.0,0.0,1.3563,2.9552,362.81,377.87,353.3,353.16
162.3254,2.3343,6.9752,0.0,0.0,1.357,2.7362,362.78,377.82,353.32,353.16
162.3284,2.429,6.976,0.0,0.0,1.3591,2.9121,362.74,377.78,353.33,353.16
162.3314,2.3811,6.9749,0.0,0.0,1.3585,2.8044,362.7,377.75,353.34,353.17
162.3344,2.3899,6.9784,0.0,0.0,1.3574,2.8725,362.65,377.73,353.34,353.19
162.3374,2.4238,6.9758,0.0,0.0,1.3557,2.8416,362.61,377.72,353.34,353.21
162.3404,2.3928,6.9772,0.0,0.0,1.358,2.8844,362.56,377.69,353.34,353.23
162.3434,2.4547,6.9764,0.0,0.0,1.3585,2.8841,362.5,377.67,353.34,353.24
162.3464,2.3657,6.9778,0.0,0.0,1.3572,2.842,362.45,377.64,353.34,353.26
162.3494,2.5023,6.9773,0.0,0.0,1.3552,2.9353,362.4,377.61,353.34,353.28
162.3524,2.3484,6.9792,0.0,0.0,1.3566,2.819,362.37,377.58,353.36,353.27
162.3554,2.5115,6.9751,0.0,0.0,1.3572,2.9512,362.34,377.56,353.38,353.26
162.3584,2.322,6.9743,0.0,0.0,1.3585,2.7786,362.31,377.53,353.4,353.25
162.3614,2.5275,6.9766,0.0,0.0,1.3586,2.977,362.28,377.52,353.41,353.23
162.3644,2.3068,6.978,0.0,0.0,1.3573,2.7685,362.24,377.51,353.43,353.21
162.3674,2.5403,6.9787,0.0,0.0,1.357,2.9924,362.21,377.5,353.45,353.2
162.3704,2.2918,6.9778,0.0,0.0,1.3588,2.7418,362.15,377.48,353.45,353.19
162.3734,2.5592,6.9793,0.0,0.0,1.3593,3.0188,362.08,377.45,353.43,353.2
162.3764,2.2966,6.9804,0.0,0.0,1.3579,2.7335,362.01,377.43,353.41,353.21
162.3794,2.5613,6.9822,0.0,0.0,1.3567,3.0256,361.94,377.39,353.4,353.22
162.3824,2.291,6.9802,0.0,0.0,1.357,2.7235,361.91,377.33,353.39,353.24
162.3854,2.5656,6.9782,0.0,0.0,1.3586,3.0309,361.89,377.27,353.38,353.26
162.3884,2.2834,6.9763,0.0,0.0,1.3596,2.7085,361.86,377.2,353.37,353.27
162.3914,2.5665,6.9777,0.0,0.0,1.359,3.0415,361.81,377.16,353.38,353.28
162.3944,2.2868,6.9793,0.0,0.0,1.3572,2.7134,361.75,377.13,353.4,353.28
162.3974,2.557,6.9807,0.0,0.0,1.358,3.0392,361.7,377.09,353.42,353.28
162.4004,2.3151,6.9776,0.0,0.0,1.3586,2.733,361.63,377.05,353.44,353.28
162.4034,2.5484,6.9789,0.0,0.0,1.3593,3.0431,361.54,377.02,353.46,353.28
162.4064,2.3206,6.98,0.0,0.0,1.3572,2.7447,361.44,376.98,353.48,353.28
162.4094,2.5499,6.9819,0.0,0.0,1.3564,3.0281,361.36,376.94,353.49,353.28
162.4124,2.3527,6.9807,0.0,0.0,1.3578,2.7748,361.29,376.85,353.48,353.3
162.4154,2.529,6.9788,0.0,0.0,1.3592,3.0268,361.23,376.77,353.47,353.32
162.4184,2.3788,6.9761,0.0,0.0,1.3593,2.796,361.17,376.69,353.46,353.34
162.4214,2.5176,6.9794,0.0,0.0,1.3589,3.012,361.09,376.62,353.45,353.34
162.4244,2.4017,6.981,0.0,0.0,1.3579,2.8273,361.01,376.54,353.44,353.34
162.4274,2.4892,6.9815,0.0,0.0,1.3585,2.9889,360.92,376.47,353.43,353.34
162.4304,2.4353,6.9783,0.0,0.0,1.3592,2.8595,360.86,376.4,353.43,353.35
162.4334,2.4543,6.9805,0.0,0.0,1.3595,2.9453,360.81,376.33,353.44,353.37
162.4364,2.4673,6.9815,0.0,0.0,1.3574,2.8938,360.77,376.25,353.45,353.38
162.4394,2.4445,6.9851,0.0,0.0,1.3579,2.9319,360.73,376.18,353.46,353.4
162.4424,2.482,6.9814,0.0,0.0,1.3583,2.9211,360.69,376.1,353.45,353.42
162.4454,2.4163,6.9804,0.0,0.0,1.3603,2.9028,360.65,376.01,353.44,353.44
162.4484,2.5067,6.9773,0.0,0.0,1.3596,2.9472,360.62,375.93,353.43,353.46
162.4514,2.3851,6.9811,0.0,0.0,1.359,2.8628,360.55,375.89,353.41,353.46
162.4544,2.5303,6.9824,0.0,0.0,1.3578,2.975,360.48,375.85,353.4,353.46
162.4574,2.368,6.9814,0.0,0.0,1.3587,2.8359,360.4,375.82,353.38,353.46
162.4604,2.5376,6.9794,0.0,0.0,1.3597,2.9854,360.32,375.78,353.36,353.47
162.4634,2.3532,6.9798,0.0,0.0,1.3588,2.8202,360.23,375.75,353.35,353.5
162.4664,2.5609,6.9813,0.0,0.0,1.3568,3.0183,360.14,375.71,353.35,353.53
162.4694,2.3452,6.983,0.0,0.0,1.3574,2.7963,360.05,375.67,353.34,353.55
162.4724,2.5914,6.9795,0.0,0.0,1.3583,3.0592,359.98,375.6,353.35,353.56
162.4754,2.3346,6.9779,0.0,0.0,1.3599,2.7818,359.9,375.54,353.36,353.57
162.4784,2.5996,6.98,0.0,0.0,1.3604,3.0727,359.83,375.48,353.37,353.58
162.4814,2.336,6.9816,0.0,0.0,1.3589,2.7615,359.76,375.38,353.39,353.59
162.4844,2.6107,6.9814,0.0,0.0,1.3579,3.0883,359.69,375.28,353.4,353.6
162.4874,2.3325,6.9795,0.0,0.0,1.3584,2.768,359.61,375.18,353.42,353.61
162.4904,2.608,6.9802,0.0,0.0,1.3599,3.1009,359.53,375.09,353.43,353.62
162.4934,2.3396,6.9806,0.0,0.0,1.3586,2.7617,359.44,375.01,353.43,353.63
162.4964,2.6217,6.9826,0.0,0.0,1.3571,3.1056,359.35,374.93,353.43,353.63
162.4994,2.353,6.9816,0.0,0.0,1.357,2.7792,359.27,374.86,353.43,353.64
162.5024,2.6032,6.9802,0.0,0.0,1.359,3.1011,359.21,374.82,353.45,353.63
162.5054,2.3639,6.978,0.0,0.0,1.3599,2.7889,359.16,374.78,353.47,353.62
162.5084,2.5903,6.9791,0.0,0.0,1.3594,3.0884,359.1,374.75,353.49,353.61
162.5114,2.3907,6.9811,0.0,0.0,1.3586,2.8211,359.03,374.68,353.51,353.61
162.5144,2.5725,6.9834,0.0,0.0,1.3587,3.0723,358.96,374.6,353.52,353.61
162.5174,2.4113,6.9809,0.0,0.0,1.3597,2.8417,358.88,374.53,353.54,353.61
162.5204,2.5576,6.9821,0.0,0.0,1.3607,3.0565,358.8,374.45,353.54,353.65
162.5234,2.4289,6.9809,0.0,0.0,1.3584,2.8605,358.71,374.36,353.52,353.71
162.5264,2.5293,6.9842,0.0,0.0,1.3579,3.0258,358.62,374.27,353.5,353.78
162.5294,2.4581,6.9836,0.0,0.0,1.358,2.8864,358.53,374.19,353.49,353.82
162.5324,2.5028,6.982,0.0,0.0,1.3602,3.0084,358.46,374.17,353.5,353.82
162.5354,2.4849,6.9778,0.0,0.0,1.3601,2.9233,358.39,374.14,353.51,353.82
162.5384,2.487,6.9804,0.0,0.0,1.36,2.9866,358.31,374.11,353.52,353.82
162.5414,2.5068,6.9801,0.0,0.0,1.3577,2.94,358.26,374.06,353.54,353.81
162.5444,2.4628,6.9828,0.0,0.0,1.3584,2.9596,358.2,374.0,353.56,353.79
162.5474,2.5396,6.9816,0.0,0.0,1.3601,2.9938,358.15,373.95,353.57,353.77
162.5504,2.4399,6.9821,0.0,0.0,1.3606,2.9283,358.08,373.87,353.57,353.78
162.5534,2.5614,6.9839,0.0,0.0,1.3587,3.0112,358.01,373.78,353.55,353.82
162.5564,2.4179,6.9857,0.0,0.0,1.3583,2.8949,357.94,373.69,353.53,353.86
162.5594,2.5785,6.9821,0.0,0.0,1.3582,3.042,357.86,373.61,353.52,353.88
162.5624,2.3981,6.9805,0.0,0.0,1.3599,2.8738,357.77,373.56,353.51,353.86
162.5654,2.6009,6.978,0.0,0.0,1.3602,3.0651,357.68,373.5,353.5,353.84
162.5684,2.3884,6.9806,0.0,0.0,1.3596,2.8492,357.59,373.45,353.49,353.82
162.5714,2.6229,6.983,0.0,0.0,1.3586,3.0904,357.49,373.37,353.49,353.84
162.5744,2.3772,6.9841,0.0,0.0,1.3593,2.8326,357.4,373.3,353.49,353.86
162.5774,2.6345,6.9826,0.0,0.0,1.3607,3.1133,357.31,373.23,353.49,353.88
162.5804,2.3743,6.982,0.0,0.0,1.3607,2.8231,357.22,373.14,353.5,353.9
162.5834,2.6468,6.9836,0.0,0.0,1.3586,3.1375,357.13,373.05,353.52,353.91
162.5864,2.3698,6.9858,0.0,0.0,1.3579,2.8155,357.04,372.96,353.54,353.93
162.5894,2.6372,6.9852,0.0,0.0,1.3595,3.1214,356.96,372.87,353.56,353.94
162.5924,2.376,6.981,0.0,0.0,1.3603,2.8228,356.9,372.78,353.6,353.93
162.595,2.3509,6.9834,0.0,0.0,1.3592,2.7872,356.86,372.7,353.63,353.92
163.195,2.438,6.9849,0.0,0.0,1.3603,2.893,342.75,357.24,347.68,346.11
163.795,2.3883,6.9861,0.0,0.0,1.3608,2.8345,330.84,343.65,318.68,339.62
164.395,2.3215,6.9875,0.0,0.0,1.3613,2.7555,322.2,333.38,307.36,333.52
164.995,2.2746,6.9891,0.0,0.0,1.3619,2.6991,315.03,324.82,299.97,327.12
165.595,2.2514,6.9907,0.0,0.0,1.3623,2.6733,308.8,317.54,293.14,320.57
166.0215,2.2312,6.9914,0.0,0.0,1.3628,2.6502,304.55,312.7,289.39,316.04
166.6215,2.2067,6.9932,0.0,0.0,1.3633,2.6199,298.87,306.03,282.78,309.53
167.2215,2.1837,6.9944,0.0,0.0,1.3637,2.5928,293.56,300.08,276.86,303.13
167.8215,2.1885,6.9956,0.0,0.0,1.3646,2.5993,288.35,294.24,270.82,296.86
168.4215,2.19,6.997,0.0,0.0,1.3649,2.6001,283.31,288.83,264.91,291.06
169.0215,2.1929,6.9981,0.0,0.0,1.365,2.6044,278.62,283.45,259.81,285.37
169.6215,2.1875,6.9991,0.0,0.0,1.366,2.5968,274.18,278.34,253.96,279.85
170.2215,2.1932,6.9999,0.0,0.0,1.3663,2.6035,269.64,273.39,248.96,274.54
170.8215,2.1985,7.0014,0.0,0.0,1.3665,2.609,265.43,268.75,244.67,269.43
171.4215,2.1883,7.0026,0.0,0.0,1.3668,2.5968,261.36,264.36,240.42,264.37
172.0215,2.1875,7.0034,0.0,0.0,1.3671,2.5951,257.35,259.99,236.11,259.5
172.6215,2.1832,7.0037,0.0,0.0,1.3677,2.59,253.3,255.71,232.44,255.11
173.2215,2.1913,7.0057,0.0,0.0,1.3682,2.6002,249.61,251.7,228.45,250.58
173.8215,2.1861,7.0065,0.0,0.0,1.3682,2.5934,245.88,247.95,214.8,246.18
174.4215,2.1855,7.0066,0.0,0.0,1.3689,2.5925,242.35,244.09,211.23,241.98
175.0215,2.1869,7.0081,0.0,0.0,1.3694,2.5945,238.84,240.32,207.61,238.01
175.6215,2.1803,7.0091,0.0,0.0,1.3695,2.5872,235.36,236.9,203.72,234.08
176.2215,2.1871,7.0103,0.0,0.0,1.3698,2.5952,232.01,233.28,199.59,230.11
176.8215,2.1914,7.0111,0.0,0.0,1.37,2.601,228.71,229.71,196.33,226.3
177.4215,2.19,7.0116,0.0,0.0,1.3708,2.5998,225.49,226.49,193.24,222.7
178.0215,2.1805,7.0131,0.0,0.0,1.371,2.588,222.36,223.41,190.99,219.14
178.6215,2.1846,7.014,0.0,0.0,1.3711,2.5928,219.29,220.19,188.41,215.77
179.2215,2.1888,7.0148,0.0,0.0,1.3719,2.598,216.33,217.01,185.76,212.31
179.8215,2.1846,7.0157,0.0,0.0,1.3723,2.5934,213.49,213.96,183.36,209.21
180.4215,2.1796,7.0165,0.0,0.0,1.3724,2.587,210.55,211.03,180.77,205.98
181.0215,2.1799,7.0177,0.0,0.0,1.3725,2.5885,207.71,208.13,178.05,202.89
181.6215,2.182,7.0189,0.0,0.0,1.373,2.5905,204.9,205.41,175.59,199.84
182.2215,2.1878,7.0195,0.0,0.0,1.3739,2.5979,202.25,202.57,172.77,196.87
182.8215,2.1825,7.0209,0.0,0.0,1.3742,2.5915,199.57,199.98,170.49,193.97
183.4215,2.1831,7.0221,0.0,0.0,1.3742,2.5922,197.05,197.39,167.49,191.17
184.0215,2.1825,7.0229,0.0,0.0,1.3749,2.5908,194.4,194.81,165.18,188.46
184.6215,2.181,7.0241,0.0,0.0,1.3754,2.5888,191.94,192.26,162.1,185.73
185.2215,2.1831,7.025,0.0,0.0,1.3757,2.5906,189.6,189.97,160.01,183.13
185.8215,2.1799,7.0268,0.0,0.0,1.376,2.5868,187.16,187.39,157.84,180.56
186.4215,2.1762,7.0274,0.0,0.0,1.3761,2.582,184.73,185.09,155.67,178.1
187.0215,2.1766,7.0282,0.0,0.0,1.3772,2.5832,182.57,182.84,153.7,175.73
187.6215,2.1748,7.0297,0.0,0.0,1.3776,2.5802,180.35,180.69,151.81,173.43
188.2215,2.1732,7.031,0.0,0.0,1.3778,2.5779,178.08,178.45,149.76,171.04
188.8215,2.1728,7.0322,0.0,0.0,1.3782,2.5784,175.96,176.23,147.61,168.69
189.4215,2.1669,7.0331,0.0,0.0,1.3785,2.5714,173.82,174.09,145.64,166.52
190.0215,2.1624,7.0339,0.0,0.0,1.3793,2.5655,171.69,172.06,143.6,164.35
190.6215,2.1586,7.0356,0.0,0.0,1.3798,2.5609,169.71,170.01,141.44,162.24
191.2215,2.1621,7.0366,0.0,0.0,1.3798,2.5657,167.72,168.05,139.77,160.14
191.8215,2.1621,7.0378,0.0,0.0,1.3807,2.5655,165.72,166.07,138.25,158.21
192.4215,2.1553,7.0392,0.0,0.0,1.3811,2.5584,163.86,164.18,136.75,156.23
193.0215,2.161,7.04,0.0,0.0,1.3815,2.5653,162.03,162.3,135.15,154.25
193.6215,2.1619,7.0415,0.0,0.0,1.3818,2.5657,160.16,160.42,133.6,152.31
194.2215,2.1596,7.0429,0.0,0.0,1.3821,2.5624,158.46,158.67,132.05,150.49
194.8215,2.1548,7.0435,0.0,0.0,1.3831,2.5576,156.62,156.73,130.44,148.7
195.4215,2.1549,7.0448,0.0,0.0,1.3835,2.558,154.91,155.09,128.85,146.88
196.0215,2.1548,7.0458,0.0,0.0,1.3837,2.558,153.16,153.41,127.46,145.11
196.6215,2.1495,7.0471,0.0,0.0,1.3839,2.552,151.53,151.64,125.96,143.48
197.2215,2.1489,7.0483,0.0,0.0,1.3842,2.5506,149.83,150.1,124.64,141.8
197.8215,2.1489,7.0493,0.0,0.0,1.3852,2.5505,148.26,148.43,123.26,140.12
198.226,2.1519,7.05,0.0,0.0,1.3856,2.5538,147.11,147.24,122.29,139.07
198.826,2.15,7.0515,0.0,0.0,1.3859,2.5527,145.57,145.7,120.78,137.39
199.426,2.1457,7.0523,0.0,0.0,1.3859,2.5468,144.07,144.31,119.61,135.99
200.026,2.152,7.0536,0.0,0.0,1.3867,2.5544,142.47,142.81,118.2,134.32
200.626,2.146,7.055,0.0,0.0,1.3872,2.5475,140.99,141.27,116.78,132.76
201.226,2.1506,7.0561,0.0,0.0,1.3879,2.5522,139.46,139.88,115.67,131.39
201.826,2.143,7.0567,0.0,0.0,1.3878,2.5435,138.02,138.29,114.39,129.9
202.426,2.1453,7.0586,0.0,0.0,1.3883,2.546,136.62,136.97,113.07,128.46
203.026,2.147,7.0594,0.0,0.0,1.389,2.5471,135.22,135.58,111.82,127.05
203.626,2.144,7.0604,0.0,0.0,1.3894,2.5438,133.83,134.28,110.68,125.78
204.226,2.1409,7.0614,0.0,0.0,1.3898,2.5402,132.47,132.97,109.55,124.4
204.826,2.1404,7.0628,0.0,0.0,1.3901,2.5395,131.1,131.45,108.35,123.05
205.426,2.1432,7.0639,0.0,0.0,1.3903,2.5423,129.78,130.21,107.04,121.7
206.026,2.1386,7.0643,0.0,0.0,1.391,2.5371,128.55,128.81,105.93,120.41
206.626,2.137,7.0656,0.0,0.0,1.3915,2.5348,127.28,127.67,104.92,119.2
207.226,2.1294,7.0663,0.0,0.0,1.3917,2.5268,125.99,126.35,103.91,117.97
207.826,2.0692,7.0693,0.0,0.0,1.3925,2.4578,125.18,125.58,103.96,118.63
208.426,2.0652,7.0681,0.0,0.0,1.3919,2.4512,125.51,125.73,108.76,120.12
209.026,2.1898,7.0649,0.0,0.0,1.3913,2.5984,125.63,125.79,111.35,120.59
209.426,2.0553,7.0646,0.0,0.0,1.3911,2.439,125.68,125.86,112.61,120.88