File: examples/dan-msc-case-studies/CS4/data/01 raw data/hyde_test_005.csv
Time(sec),Force(kN),Jaw(mm),PowAngle(deg),PTemp,Strain,Stress(MPa),TC1(C),TC2(C),TC3(C),TC4(C)
0.0,4.103,-9.876,0.0,0.0040875,-0.76956,4.8738,24.581,24.954,24.841,24.612
1.0,3.9788,-0.0026758,0.0,2.8207,-0.00028547,4.7199,24.516,24.994,24.753,24.592
2.0,3.9244,-0.0024976,0.0,5.8207,-0.0002582,4.6583,24.612,24.989,24.673,24.555
2.9759,3.9034,-0.0022398,0.0,8.7484,-0.0002722,4.6305,24.525,24.948,24.705,24.543
3.9759,3.8607,-0.0022901,0.0,11.748,-0.00027531,4.5819,24.519,24.969,24.721,24.56
4.9759,3.8479,-0.0022776,0.0,14.748,-0.00026803,4.5662,24.536,24.949,24.714,24.498
5.9759,3.8179,-0.0023106,0.0,17.748,-0.00027407,4.5303,24.524,25.007,24.713,24.524
6.9759,3.7963,-0.0022482,0.0,20.748,-0.00026653,4.5061,24.522,24.951,24.728,24.498
7.9759,3.7839,-0.0021728,0.0,23.748,-0.00025205,4.4893,24.556,24.992,24.702,24.553
8.9759,3.7727,-0.0019725,21.607,26.748,-0.00022061,4.4782,24.7,25.146,24.77,24.559
9.9286,3.8022,-0.00257,28.957,29.607,-0.00027426,4.5111,27.217,28.038,25.821,25.193
10.9286,3.8074,-0.0028113,29.467,32.607,-0.00030919,4.5189,30.923,37.951,27.754,27.047
11.9286,3.8254,-0.0034249,30.576,35.607,-0.00039183,4.5399,34.228,37.954,30.047,29.51
12.9286,3.8203,-0.0035911,31.024,38.607,-0.00038877,4.5332,37.633,38.822,32.572,32.177
13.9286,3.8276,-0.0041555,30.884,41.607,-0.00049558,4.543,40.971,42.138,35.217,34.931
14.9286,3.8217,-0.0065006,31.247,44.607,-0.00074028,4.534,44.137,45.122,37.895,37.814
15.9286,3.8114,-0.0075315,31.094,47.607,-0.00085485,4.5242,47.377,48.009,40.611,40.678
16.9286,3.8239,-0.0084328,31.64,50.607,-0.00096507,4.537,50.341,50.625,43.291,43.628
17.9286,3.8166,-0.0094939,31.817,53.607,-0.0010745,4.5297,53.465,53.352,46.16,46.48
18.9286,3.8281,-0.010432,31.816,56.607,-0.0011866,4.544,56.444,55.924,48.999,49.381
19.9286,3.8352,-0.011431,31.897,59.607,-0.0012937,4.5505,59.462,58.448,51.887,52.232
20.9286,3.8379,-0.012146,32.26,62.607,-0.0013676,4.555,62.48,61.003,54.83,55.156
21.9286,3.8485,-0.012702,33.017,65.607,-0.0014495,4.5669,65.394,63.386,57.74,58.076
22.9286,3.846,-0.013446,32.811,68.607,-0.0015334,4.5639,68.443,66.011,60.61,60.881
23.9286,3.8585,-0.015222,33.188,71.607,-0.0017322,4.5792,71.476,68.594,63.619,63.859
24.9286,3.8578,-0.015821,33.719,74.607,-0.0017653,4.5766,74.457,71.109,66.62,66.801
25.9286,3.8553,-0.015232,33.36,77.607,-0.0017322,4.5756,77.523,73.638,69.631,69.806
26.9286,3.8678,-0.018871,33.837,80.607,-0.0021662,4.59,80.494,76.187,72.596,72.704
27.9286,3.8591,-0.021514,33.772,83.607,-0.0024275,4.5795,83.542,78.757,75.748,75.652
28.9286,3.8784,-0.022805,34.005,86.607,-0.0025551,4.6042,86.438,81.187,78.776,78.61
29.9286,3.8687,-0.024389,34.238,89.607,-0.002739,4.5897,89.491,83.936,81.821,81.572
30.9286,3.8705,-0.025777,34.306,92.607,-0.002891,4.5945,92.529,86.484,84.833,84.614
31.9286,3.8887,-0.027131,34.651,95.607,-0.0030392,4.6143,95.51,89.162,87.837,87.586
32.9286,3.8749,-0.028478,35.107,98.607,-0.0031889,4.5986,98.441,91.722,90.87,90.49
33.9286,3.885,-0.029954,34.688,101.61,-0.0033508,4.6111,101.56,94.452,93.97,93.54
34.9286,3.8843,-0.031481,34.911,104.61,-0.0035218,4.6085,104.54,97.08,96.96,96.479
35.8134,3.8911,-0.032815,34.933,107.26,-0.003671,4.6166,107.26,99.512,99.65,99.226
36.8134,3.8803,-0.034351,35.469,110.26,-0.0038475,4.6068,110.2,102.36,102.75,102.22
37.8134,3.88,-0.035975,35.515,113.26,-0.0040184,4.6042,113.15,104.97,105.82,105.23
38.8134,3.8885,-0.037454,35.507,116.26,-0.0042024,4.6138,116.22,107.76,108.85,108.22
39.8134,3.8829,-0.039096,35.563,119.26,-0.0043706,4.6076,119.2,110.45,111.9,111.2
40.8134,3.8914,-0.040751,35.962,122.26,-0.004551,4.6169,122.18,113.25,114.87,114.18
41.8134,3.8741,-0.042537,35.999,125.26,-0.0047565,4.5986,125.19,116.12,117.89,117.18
42.8134,3.8937,-0.044248,36.31,128.26,-0.0049459,4.6205,128.11,119.04,120.95,120.12
43.8134,3.8806,-0.045863,36.272,131.26,-0.0051167,4.6033,131.21,121.86,124.04,123.18
44.8134,3.8837,-0.047774,36.831,134.26,-0.0053292,4.6102,134.11,124.76,126.95,126.2
45.8134,3.8922,-0.049448,36.811,137.26,-0.0055111,4.6172,137.15,127.7,129.99,129.24
46.8134,3.8813,-0.051272,36.96,140.26,-0.0057137,4.606,140.12,130.61,133.04,132.29
47.8134,3.8958,-0.053101,37.038,143.26,-0.005914,4.6231,143.17,133.53,136.05,135.35
48.8134,3.8868,-0.054936,37.195,146.26,-0.0061143,4.6121,146.13,136.45,138.99,138.35
49.8134,3.8927,-0.056699,37.628,149.26,-0.0063156,4.6201,149.07,139.5,141.97,141.33
50.8134,3.8983,-0.054284,37.737,152.26,-0.0060784,4.6246,152.14,142.42,144.94,144.33
51.8134,3.8827,-0.057995,37.834,155.26,-0.0064054,4.6083,155.17,145.38,148.09,147.34
52.8134,3.9028,-0.060459,32.962,158.26,-0.0067354,4.6305,157.58,147.83,150.77,150.26
53.8134,3.8951,-0.061811,37.966,161.26,-0.0068648,4.6221,158.83,149.13,152.75,152.12
54.8134,3.8999,-0.065095,37.534,164.26,-0.0072291,4.6284,162.15,152.5,155.43,154.69
55.8134,3.9013,-0.067662,37.896,167.26,-0.007524,4.6289,165.05,155.42,158.14,157.48
56.8134,3.8929,-0.069727,38.005,170.26,-0.00775,4.6206,168.15,158.51,161.1,160.4
57.8134,3.8998,-0.071549,38.332,173.26,-0.0079615,4.6277,171.11,161.54,164.02,163.38
58.8134,3.8904,-0.072104,37.998,176.26,-0.008069,4.6158,174.29,164.59,167.03,166.38
59.8134,3.9007,-0.073532,38.105,179.26,-0.0081555,4.63,177.2,167.51,170.04,169.4
60.8134,3.9027,-0.075056,37.885,182.26,-0.0083541,4.6306,180.29,170.44,172.97,172.32
61.8134,3.8926,-0.078726,38.108,185.26,-0.0087601,4.6206,183.27,173.29,175.98,175.26
62.8134,3.9021,-0.08143,38.247,188.26,-0.0090544,4.6311,186.26,175.99,178.91,178.23
63.8134,3.8963,-0.083588,38.144,191.26,-0.0092955,4.6229,189.25,178.97,181.8,181.11
64.8134,3.8977,-0.085673,37.921,194.26,-0.0095382,4.6265,192.35,181.86,184.79,184.07
65.8134,3.9015,-0.086057,38.536,197.26,-0.0096341,4.6287,195.21,184.58,187.64,187.0
66.8134,3.8926,-0.086884,38.266,200.26,-0.0096343,4.6208,198.27,187.58,190.76,190.01
67.7451,3.9,-0.089806,38.557,203.07,-0.010044,4.6275,201.0,190.1,193.53,192.75
68.7451,3.9021,-0.092255,38.477,206.06,-0.010269,4.6324,204.04,192.97,196.6,195.66
69.7451,3.9113,-0.095865,38.99,209.06,-0.010678,4.6414,206.92,195.69,199.55,198.54
70.7451,3.8964,-0.098448,38.921,212.06,-0.010972,4.6246,209.96,198.55,202.69,201.52
71.7451,3.8966,-0.10104,39.029,215.06,-0.011261,4.6248,212.97,201.55,205.76,204.51
72.7451,3.8981,-0.10319,38.63,218.06,-0.011487,4.6256,216.08,204.34,208.89,207.53
73.7451,3.8973,-0.10425,38.744,221.06,-0.011648,4.6263,219.11,207.17,211.92,210.48
74.7451,3.908,-0.10453,39.154,224.06,-0.011599,4.6372,222.01,209.86,214.95,213.5
75.7021,3.909,-0.10779,39.106,226.93,-0.012027,4.6404,224.89,212.57,217.79,216.34
76.7021,3.9101,-0.11049,39.17,229.93,-0.012295,4.6402,227.92,215.37,220.81,219.28
77.7021,3.8966,-0.1143,39.279,232.93,-0.012718,4.6241,230.89,218.23,223.85,222.19
78.7021,3.9039,-0.11725,39.243,235.93,-0.013047,4.6344,233.9,221.08,226.76,225.14
79.7021,3.898,-0.11967,39.145,238.93,-0.013321,4.625,236.94,223.74,229.74,228.13
80.7021,3.9001,-0.12213,39.439,241.93,-0.013592,4.6304,239.9,226.51,232.87,231.13
81.7021,3.908,-0.12396,39.261,244.93,-0.013815,4.6363,242.92,229.31,235.97,234.09
82.7021,3.9014,-0.12109,39.296,247.93,-0.013453,4.6306,246.0,232.17,239.07,237.0
83.7021,3.913,-0.12836,39.366,250.93,-0.014268,4.6443,248.97,235.0,242.1,240.0
84.7021,3.9135,-0.12929,39.915,253.93,-0.014387,4.6432,251.84,237.7,245.09,242.96
85.7021,3.9166,-0.13214,39.504,256.93,-0.014678,4.6495,254.94,240.44,248.15,245.91
86.7021,3.9899,-0.13504,39.458,259.93,-0.015003,4.7345,257.91,243.22,251.09,248.9
87.7021,4.0659,-0.13715,39.638,262.93,-0.015236,4.8249,260.91,245.83,254.11,251.75
88.7021,4.1567,-0.13923,39.742,265.93,-0.015452,4.9347,263.91,248.52,257.13,254.63
89.7021,4.1957,-0.14138,40.07,268.93,-0.015689,4.9783,266.82,251.16,259.98,257.45
90.7021,4.2317,-0.14352,40.099,271.93,-0.015919,5.0229,269.83,253.86,262.85,260.26
91.7021,4.2627,-0.14598,40.473,274.93,-0.016198,5.0573,272.8,256.72,265.89,263.13
92.7021,4.2682,-0.14844,40.443,277.93,-0.016462,5.066,275.87,259.6,268.89,266.17
93.7021,4.3031,-0.15088,40.314,280.93,-0.016734,5.1075,278.91,262.34,272.0,269.14
94.7021,4.3081,-0.14871,40.557,283.93,-0.016571,5.1114,281.8,264.99,274.96,272.11
95.7021,4.3261,-0.15067,40.569,286.93,-0.016677,5.135,284.88,267.75,278.02,275.13
96.7021,4.3485,-0.1579,40.331,289.93,-0.017502,5.1591,287.99,270.55,281.11,278.1
97.7021,4.3559,-0.15915,40.563,292.93,-0.017672,5.1686,290.91,273.06,284.04,280.97
98.7021,4.3844,-0.16135,40.514,295.93,-0.017889,5.2048,293.92,275.77,287.09,283.96
99.7021,4.3921,-0.16559,40.345,298.93,-0.018353,5.2107,296.98,278.52,290.18,286.95
100.5827,4.3991,-0.16866,35.898,300.0,-0.018698,5.2191,299.38,280.28,292.48,289.42
101.5827,4.3851,-0.16997,36.151,300.0,-0.018843,5.2055,298.8,279.33,292.84,290.45
102.5827,4.4055,-0.17196,35.622,300.0,-0.019076,5.2284,298.68,279.12,292.92,290.37
103.5827,4.4009,-0.17347,35.582,300.0,-0.019247,5.221,298.44,278.9,292.73,290.19
104.5827,4.4116,-0.17507,35.496,300.0,-0.019431,5.2374,298.36,278.76,292.58,290.02
105.5827,4.4345,-0.17801,40.548,300.0,-0.01976,5.2601,298.75,279.16,292.9,289.83
106.5827,4.4263,-0.17467,35.086,300.0,-0.019436,5.2535,301.05,280.97,294.4,291.16
107.5827,4.4458,-0.17963,35.28,300.0,-0.019931,5.2755,300.85,280.61,294.44,291.57
108.441,4.4549,-0.18,36.31,300.0,-0.019961,5.286,301.19,280.84,294.75,291.68
109.441,4.4461,-0.18347,34.674,300.0,-0.020354,5.2758,302.09,281.5,295.41,292.21
110.441,4.4722,-0.18629,37.033,300.0,-0.02066,5.3085,302.5,281.85,295.82,292.59
111.441,4.4729,-0.18877,36.32,300.0,-0.020937,5.3074,304.15,283.11,297.0,293.5
112.441,4.4731,-0.1905,36.238,300.0,-0.021113,5.3094,304.97,283.77,297.91,294.45
113.441,4.4931,-0.19208,35.505,300.0,-0.021282,5.3307,305.76,284.4,298.53,295.14
114.441,4.4944,-0.18974,35.14,300.0,-0.021059,5.3328,306.53,285.0,299.14,295.72
115.441,4.5087,-0.1939,36.288,300.0,-0.02145,5.3515,306.71,285.21,299.47,296.21
116.441,4.5166,-0.19478,35.727,300.0,-0.021563,5.3586,307.69,286.26,300.23,296.74
117.441,4.5109,-0.19723,35.209,300.0,-0.021823,5.3539,307.89,286.51,300.41,297.26
118.441,4.5261,-0.20015,36.33,300.0,-0.022151,5.3707,308.46,287.13,300.84,297.55
119.441,4.5288,-0.20243,37.421,300.0,-0.022412,5.3737,309.63,288.21,301.81,298.29
120.441,4.5338,-0.20351,35.498,300.0,-0.022535,5.3814,310.85,289.5,302.71,299.26
121.441,4.541,-0.20234,37.095,300.0,-0.022465,5.3876,311.66,290.35,303.41,300.02
122.441,4.5447,-0.20588,36.291,300.0,-0.022793,5.3953,313.2,291.97,304.52,301.05
123.441,4.5634,-0.20661,36.432,300.0,-0.022865,5.4144,314.06,293.02,305.44,302.07
124.441,4.5456,-0.20981,35.185,300.0,-0.023226,5.3951,314.82,294.01,306.19,302.99
125.441,4.5653,-0.21163,36.926,300.0,-0.023446,5.4191,315.16,294.52,306.8,303.65
126.441,4.5632,-0.21321,37.125,300.0,-0.023621,5.4144,316.2,295.92,307.71,304.5
127.441,4.5671,-0.20962,37.726,300.0,-0.023286,5.4204,317.85,298.3,309.19,305.81
128.441,4.5343,-0.21293,29.519,300.0,-0.02359,5.3805,316.95,298.24,309.42,307.15
129.441,4.5271,-0.21276,29.772,300.0,-0.023578,5.3724,313.51,296.38,307.66,305.9
130.441,4.5384,-0.21427,30.479,300.0,-0.023732,5.3872,311.23,295.12,305.87,304.12
131.441,4.5596,-0.21558,32.842,300.0,-0.023883,5.4093,310.16,294.64,304.59,302.62
132.441,4.5435,-0.21609,28.601,300.0,-0.023925,5.3935,310.0,294.65,303.92,301.85
133.4147,4.5353,-0.21632,31.326,300.0,-0.023941,5.3807,307.79,293.18,302.47,300.75
134.4147,4.5512,-0.21395,31.449,300.0,-0.023651,5.4012,307.26,292.93,301.62,299.64
135.4147,4.5457,-0.21565,30.41,300.0,-0.023878,5.3945,306.22,292.15,300.6,298.82
136.4147,4.558,-0.21789,32.193,300.0,-0.024117,5.4076,305.93,292.0,299.98,297.98
137.4147,4.5651,-0.21949,32.349,300.0,-0.024299,5.419,305.87,291.98,299.7,297.68
138.4147,4.5673,-0.22065,32.281,300.0,-0.024432,5.4185,305.98,292.05,299.58,297.58
139.4147,4.5546,-0.22162,32.241,300.0,-0.024542,5.406,306.01,292.15,299.51,297.45
140.4147,4.5759,-0.22165,32.636,300.0,-0.024595,5.431,305.97,292.15,299.45,297.41
141.3839,4.5785,-0.22161,32.378,300.0,-0.024503,5.4337,306.09,292.28,299.42,297.39
142.3839,4.5996,-0.22233,32.524,300.0,-0.02461,5.4591,306.07,292.26,299.34,297.39
143.3839,4.5981,-0.22489,31.973,300.0,-0.024905,5.4555,306.16,292.35,299.35,297.42
144.3839,4.6011,-0.22626,32.191,300.0,-0.025054,5.4616,306.1,292.38,299.3,297.33
145.2833,4.6107,0.032463,1.5329,152.6,0.0033055,5.4625,306.15,292.52,299.43,297.34
145.28495,4.6414,0.029532,0.0,0.00016607,0.0028313,5.5055,306.15,292.54,299.42,297.38
145.2866,4.6139,0.024499,0.0,2.0458e-11,0.0033514,5.4785,306.15,292.56,299.41,297.43
145.28825,4.5811,0.027806,0.0,2.3825e-18,0.0028527,5.4328,306.16,292.58,299.4,297.48
145.2899,4.5578,0.02847,0.0,2.6751e-25,0.0028965,5.4256,306.16,292.6,299.39,297.53
145.29155,4.5692,0.033585,0.0,4.8903e-32,0.0044889,5.4322,306.17,292.62,299.38,297.58
145.2932,4.6525,0.031893,0.0,1.4263999999999998e-38,0.0026605,5.5375,306.17,292.64,299.37,297.63
145.29485,4.6324,0.026526,0.0,2.8026e-45,0.0034854,5.4976,306.18,292.63,299.37,297.62
145.2965,4.6128,0.024637,0.0,0.0,0.0026392,5.471,306.18,292.6,299.37,297.57
145.29815,4.5729,0.028749,0.0,0.0,0.0028728,5.4168,306.19,292.58,299.37,297.51
145.2998,4.5603,0.025791,0.0,0.0,0.0033123,5.4007,306.2,292.55,299.37,297.46
145.30145,4.5946,0.024363,0.0,0.0,0.0025295,5.445,306.2,292.53,299.37,297.41
145.3031,4.6251,0.030384,0.0,0.0,0.0033961,5.4845,306.21,292.5,299.37,297.36
145.30475,4.6292,0.024896,0.0,0.0,0.0027428,5.4887,306.21,292.48,299.37,297.34
145.3064,4.5986,0.028166,0.0,0.0,0.0033667,5.4388,306.21,292.46,299.36,297.34
145.30805,4.57,0.02886,0.0,0.0,0.0029036,5.4208,306.21,292.44,299.36,297.34
145.3097,4.5484,0.024364,0.0,0.0,0.0029188,5.4133,306.21,292.42,299.35,297.34
145.31135,4.5696,0.028129,0.0,0.0,0.0032745,5.4344,306.21,292.4,299.35,297.34
145.313,4.6082,0.027082,0.0,0.0,0.0026414,5.4799,306.21,292.38,299.34,297.34
145.31465,4.6233,0.024362,0.0,0.0,0.0037547,5.4852,306.21,292.38,299.34,297.35
145.3163,4.5941,0.029399,0.0,0.0,0.0025054,5.4335,306.22,292.39,299.34,297.36
145.31795,4.5609,0.026402,0.0,0.0,0.0030821,5.4043,306.22,292.41,299.34,297.37
145.3196,4.5546,0.02527,0.0,0.0,0.0032265,5.4127,306.23,292.42,299.34,297.38
145.32125,4.5863,0.02989,0.0,0.0,0.0027687,5.4571,306.23,292.44,299.34,297.39
145.3229,4.6182,0.025428,0.0,0.0,0.0036212,5.4758,306.24,292.45,299.34,297.4
145.32455,4.6256,0.026376,0.0,0.0,0.0025533,5.4742,306.24,292.46,299.33,297.4
145.3262,4.5991,0.02903,0.0,0.0,0.0032529,5.4464,306.23,292.46,299.32,297.4
145.32785,4.5743,0.024441,0.0,0.0,0.0030583,5.4328,306.23,292.46,299.31,297.4
145.3295,4.5735,0.027508,0.0,0.0,0.0028478,5.4241,306.22,292.46,299.3,297.4
145.33115,4.584,0.02882,0.0,0.0,0.0034793,5.4495,306.21,292.46,299.29,297.4
145.3328,4.6208,0.024747,0.0,0.0,0.0025942,5.4899,306.21,292.46,299.28,297.4
145.33445,4.6261,0.028979,0.0,0.0,0.0032097,5.4921,306.29,292.47,299.28,297.4
145.3361,4.5985,0.027266,0.0,0.0,0.0028694,5.4565,306.46,292.51,299.28,297.38
145.33775,4.5897,0.024393,0.0,0.0,0.0030837,5.4394,306.63,292.54,299.28,297.37
145.3394,4.5999,0.029964,0.0,0.0,0.0031102,5.4555,306.8,292.57,299.28,297.35
145.34105,4.6162,0.02666,0.0,0.0,0.0027432,5.482,306.97,292.6,299.28,297.34
145.3427,4.6038,0.025963,0.0,0.0,0.0034687,5.4631,307.15,292.63,299.28,297.32
145.34435,4.6132,0.029707,0.0,0.0,0.0024915,5.4781,307.97,293.26,299.29,297.29
145.346,5.8571,0.033314,0.0,0.0,0.0041323,6.3652,309.71,294.73,299.32,297.25
145.34765,32.107,0.16583,0.0,0.0,0.017903,36.663,311.45,296.2,299.35,297.21
145.3493,56.392,0.19599,0.0,0.0,0.020904,65.756,313.18,297.67,299.38,297.17
145.35095,79.094,0.33527,0.0,0.0,0.03857,93.251,314.92,299.14,299.41,297.13
145.3526,90.07,0.44355,0.0,0.0,0.049546,106.45,316.66,300.61,299.44,297.09
145.35425,99.802,0.60046,0.0,0.0,0.0691,118.05,318.54,302.33,299.45,297.07
145.3559,110.12,0.82096,0.0,0.0,0.09484,130.38,320.68,304.49,299.42,297.07
145.35755,115.0,1.0759,0.0,0.0,0.12606,136.33,322.82,306.65,299.39,297.08
145.3592,119.14,1.3637,0.0,0.0,0.16316,141.27,324.96,308.81,299.36,297.08
145.36085,121.7,1.6565,0.0,0.0,0.20126,144.32,327.1,310.96,299.33,297.09
145.3625,123.64,1.9607,0.0,0.0,0.24285,146.66,329.24,313.12,299.3,297.09
145.36415,125.23,2.2387,0.0,0.0,0.28161,148.54,331.1,315.13,299.27,297.1
145.3658,126.72,2.52,0.0,0.0,0.32351,150.29,332.36,316.81,299.23,297.11
145.36745,127.9,2.7918,0.0,0.0,0.36349,151.7,333.63,318.5,299.19,297.12
145.3691,128.94,3.0521,0.0,0.0,0.40586,152.93,334.89,320.18,299.16,297.13
145.37075,129.83,3.3116,0.0,0.0,0.44777,154.03,336.15,321.87,299.12,297.14
145.3724,130.83,3.5673,0.0,0.0,0.49007,155.21,337.41,323.56,299.09,297.15
145.37405,131.71,3.8133,0.0,0.0,0.53594,156.23,338.73,325.29,299.08,297.16
145.3757,132.49,4.0643,0.0,0.0,0.58026,157.18,340.2,327.17,299.13,297.16
145.37735,133.16,4.3111,0.0,0.0,0.62904,157.97,341.67,329.05,299.18,297.16
145.379,133.64,4.5523,0.0,0.0,0.67796,158.56,343.13,330.93,299.23,297.16
145.38065,134.15,4.8013,0.0,0.0,0.72742,159.18,344.6,332.81,299.28,297.16
145.3823,134.6,5.0415,0.0,0.0,0.78268,159.73,346.07,334.68,299.33,297.16
145.38395,134.95,5.2799,0.0,0.0,0.8363,160.13,347.44,336.4,299.37,297.16
145.3856,135.26,5.5228,0.0,0.0,0.89551,160.5,348.5,337.58,299.39,297.17
145.38725,135.49,5.7546,0.0,0.0,0.95482,160.77,349.56,338.76,299.41,297.18
145.3889,135.91,5.989,0.0,0.0,1.0176,161.25,350.62,339.93,299.43,297.19
145.39055,136.3,6.2228,0.0,0.0,1.0847,161.73,351.68,341.11,299.45,297.2
145.3922,136.87,6.4427,0.0,0.0,1.1519,162.41,352.74,342.29,299.48,297.21
145.39385,137.42,6.672,0.0,0.0,1.2249,163.06,353.58,343.19,299.49,297.22
145.3955,138.13,6.8873,0.0,0.0,1.2969,163.89,353.38,342.78,299.48,297.2
145.39715,139.01,7.0936,0.0,0.0,1.3763,164.91,353.19,342.37,299.47,297.18
145.3988,139.98,7.2993,0.0,0.0,1.4562,166.07,352.99,341.96,299.46,297.16
145.40045,141.08,7.4929,0.0,0.0,1.5371,167.37,352.79,341.56,299.45,297.14
145.4021,141.21,7.6684,0.0,0.0,1.621,168.07,352.6,341.15,299.44,297.11
145.40375,129.09,7.6989,0.0,0.0,1.6316,153.38,352.32,340.65,299.43,297.1
145.4054,125.13,7.725,0.0,0.0,1.6531,148.77,351.45,339.5,299.46,297.11
145.40705,122.4,7.7315,0.0,0.0,1.6518,145.35,350.58,338.36,299.5,297.12
145.4087,120.0,7.7417,0.0,0.0,1.655,142.47,349.71,337.21,299.53,297.13
145.41035,118.03,7.7478,0.0,0.0,1.6597,140.13,348.84,336.06,299.56,297.14
145.412,116.12,7.7507,0.0,0.0,1.6589,137.87,347.98,334.92,299.59,297.15
145.41365,114.38,7.7602,0.0,0.0,1.6677,135.77,347.12,333.79,299.62,297.16
145.4153,112.69,7.7566,0.0,0.0,1.6654,133.8,346.36,332.95,299.63,297.18
145.41695,111.3,7.7646,0.0,0.0,1.6669,132.13,345.61,332.1,299.65,297.2
145.4186,110.05,7.7687,0.0,0.0,1.6683,130.64,344.86,331.26,299.66,297.22
145.42025,109.02,7.7661,0.0,0.0,1.6703,129.41,344.1,330.41,299.68,297.24
145.4219,108.1,7.7726,0.0,0.0,1.6728,128.32,343.35,329.56,299.69,297.26
145.42355,107.28,7.7728,0.0,0.0,1.6686,127.33,342.6,328.73,299.71,297.28
145.4252,106.51,7.7686,0.0,0.0,1.6738,126.44,342.12,328.19,299.73,297.29
145.42685,105.79,7.7755,0.0,0.0,1.6703,125.57,341.63,327.65,299.76,297.3
145.4285,105.05,7.7723,0.0,0.0,1.6756,124.71,341.14,327.11,299.78,297.31
145.43015,104.02,7.7741,0.0,0.0,1.6742,123.5,340.66,326.57,299.81,297.32
145.4318,102.23,7.7762,0.0,0.0,1.669,121.42,340.17,326.03,299.83,297.33
145.43345,99.516,7.7689,0.0,0.0,1.6721,118.25,339.68,325.49,299.86,297.34
145.4351,96.302,7.7684,0.0,0.0,1.6678,114.43,339.6,325.33,299.92,297.35
145.43675,84.558,7.7472,0.0,0.0,1.6617,101.58,339.53,325.17,299.97,297.36
145.4384,49.817,7.6736,0.0,0.0,1.6269,60.2,339.46,325.02,300.03,297.37
145.44005,18.397,7.598,0.0,0.0,1.5872,22.945,339.39,324.86,300.08,297.38
145.4417,0.79334,7.5112,0.0,0.0,1.5506,1.0161,339.32,324.7,300.14,297.39
145.44335,5.7889,7.5536,0.0,0.0,1.5678,6.9317,339.25,324.55,300.19,297.4
145.445,3.3665,7.5398,0.0,0.0,1.5615,3.9055,339.34,324.52,300.2,297.39
145.44665,4.2193,7.5435,0.0,0.0,1.5623,4.9989,339.43,324.51,300.2,297.36
145.4483,3.5957,7.5444,0.0,0.0,1.5651,4.1708,339.53,324.49,300.2,297.34
145.44995,3.7018,7.5539,0.0,0.0,1.5689,4.445,339.62,324.48,300.2,297.32
145.4516,4.1908,7.555,0.0,0.0,1.5694,4.9838,339.72,324.46,300.2,297.3
145.45325,3.9471,7.5537,0.0,0.0,1.5692,4.6554,339.81,324.45,300.2,297.28
145.4549,4.0298,7.5553,0.0,0.0,1.5656,4.7718,339.88,324.44,300.19,297.26
145.45655,3.8586,7.5501,0.0,0.0,1.5694,4.5623,339.94,324.43,300.18,297.24
145.4582,3.8933,7.5535,0.0,0.0,1.5673,4.6218,340.0,324.42,300.17,297.22
145.45985,4.0303,7.5521,0.0,0.0,1.5663,4.7775,340.06,324.41,300.16,297.2
145.4615,4.0173,7.5446,0.0,0.0,1.5659,4.7636,340.12,324.4,300.15,297.18
145.46315,3.974,7.5476,0.0,0.0,1.562,4.7025,340.18,324.39,300.14,297.16
145.4648,3.9043,7.5473,0.0,0.0,1.5683,4.6024,340.19,324.4,300.17,297.17
145.46645,3.9097,7.547,0.0,0.0,1.5666,4.6354,340.19,324.42,300.2,297.18
145.4681,3.9157,7.5531,0.0,0.0,1.5663,4.6368,340.19,324.44,300.24,297.19
145.46975,3.9348,7.5499,0.0,0.0,1.5662,4.6751,340.19,324.46,300.27,297.2
145.4714,3.9606,7.5476,0.0,0.0,1.5649,4.7049,340.19,324.48,300.31,297.21
145.47305,3.9596,7.5503,0.0,0.0,1.5685,4.6907,340.19,324.5,300.34,297.22
145.4747,3.8937,7.5457,0.0,0.0,1.5647,4.6201,340.16,324.5,300.38,297.24
145.47635,3.9024,7.5488,0.0,0.0,1.567,4.6305,340.13,324.48,300.42,297.26
145.478,3.9481,7.5516,0.0,0.0,1.5657,4.6936,340.1,324.47,300.45,297.28
145.47965,3.9738,7.5464,0.0,0.0,1.568,4.7293,340.07,324.45,300.49,297.3
145.4813,3.9975,7.5513,0.0,0.0,1.5675,4.754,340.04,324.44,300.52,297.32
145.48295,3.9694,7.5503,0.0,0.0,1.5636,4.693,340.01,324.42,300.56,297.34
145.4846,3.9312,7.5464,0.0,0.0,1.5675,4.6422,339.96,324.36,300.58,297.34
145.48625,3.8936,7.5511,0.0,0.0,1.5652,4.6227,339.9,324.28,300.6,297.34
145.4879,3.943,7.5495,0.0,0.0,1.569,4.6733,339.84,324.2,300.62,297.34
145.48955,3.9814,7.5462,0.0,0.0,1.5671,4.7157,339.78,324.12,300.64,297.34
145.4912,3.9369,7.5499,0.0,0.0,1.5632,4.6732,339.72,324.03,300.66,297.34
145.49285,3.9099,7.5461,0.0,0.0,1.5668,4.6381,339.66,323.95,300.68,297.34
145.4945,3.8896,7.5494,0.0,0.0,1.564,4.6089,339.59,323.86,300.7,297.34
145.49615,3.9239,7.5519,0.0,0.0,1.5682,4.6665,339.51,323.76,300.72,297.34
145.4978,3.9271,7.5476,0.0,0.0,1.5664,4.6697,339.43,323.66,300.74,297.34
145.49945,3.9648,7.5486,0.0,0.0,1.5649,4.6998,339.34,323.56,300.76,297.34
145.5011,4.0237,7.5495,0.0,0.0,1.5669,4.782,339.26,323.46,300.78,297.34
145.50275,3.9846,7.5437,0.0,0.0,1.5649,4.7248,339.18,323.36,300.81,297.34
145.5044,3.9234,7.5508,0.0,0.0,1.567,4.6472,339.13,323.26,300.82,297.35
145.50605,3.9143,7.55,0.0,0.0,1.564,4.6665,339.1,323.18,300.83,297.36
145.5077,3.9354,7.546,0.0,0.0,1.5665,4.6801,339.06,323.09,300.84,297.37
145.50935,3.9946,7.5507,0.0,0.0,1.5667,4.7583,339.03,323.01,300.85,297.38
145.511,4.0228,7.5499,0.0,0.0,1.5662,4.7803,338.99,322.92,300.86,297.39
145.51265,4.0158,7.5467,0.0,0.0,1.5671,4.7732,338.96,322.84,300.87,297.4
145.5143,3.9604,7.5525,0.0,0.0,1.5637,4.6847,338.92,322.73,300.87,297.4
145.51595,3.9685,7.5477,0.0,0.0,1.5693,4.7182,338.89,322.62,300.87,297.4
145.5176,3.9725,7.5505,0.0,0.0,1.567,4.7185,338.86,322.5,300.87,297.4
145.51925,4.0191,7.5522,0.0,0.0,1.5663,4.7642,338.83,322.38,300.87,297.4
145.5209,4.0796,7.5485,0.0,0.0,1.5669,4.842,338.8,322.27,300.87,297.4
145.52255,4.0829,7.5506,0.0,0.0,1.5644,4.8385,338.77,322.15,300.87,297.4
145.5242,4.1066,7.5507,0.0,0.0,1.5695,4.8612,338.73,322.04,300.89,297.4
145.52585,4.1113,7.5468,0.0,0.0,1.5669,4.8833,338.68,321.92,300.92,297.4
145.5275,4.1266,7.554,0.0,0.0,1.5672,4.9163,338.63,321.81,300.95,297.4
145.52915,4.2513,7.5534,0.0,0.0,1.5672,5.0531,338.58,321.69,300.98,297.4
145.5308,4.2574,7.5496,0.0,0.0,1.5667,5.0425,338.53,321.57,301.01,297.4
145.53245,4.232,7.5527,0.0,0.0,1.5689,4.9914,338.48,321.46,301.04,297.4
145.5341,4.1541,7.55,0.0,0.0,1.5653,4.9136,338.42,321.35,301.08,297.4
145.53575,4.134,7.5494,0.0,0.0,1.5679,4.9155,338.36,321.24,301.12,297.39
145.5374,4.2208,7.5545,0.0,0.0,1.566,5.024,338.29,321.14,301.16,297.38
145.53905,4.3544,7.5501,0.0,0.0,1.5707,5.1876,338.23,321.03,301.2,297.37
145.5407,4.3962,7.5542,0.0,0.0,1.5696,5.2069,338.16,320.92,301.24,297.36
145.54235,4.2669,7.5547,0.0,0.0,1.5653,5.0207,338.1,320.82,301.28,297.35
145.544,4.098,7.5494,0.0,0.0,1.5683,4.8469,338.03,320.71,301.31,297.34
145.54565,4.1039,7.554,0.0,0.0,1.5663,4.8859,337.96,320.58,301.31,297.34
145.5473,4.2099,7.5551,0.0,0.0,1.5707,5.0222,337.89,320.46,301.32,297.34
145.54895,4.3284,7.5485,0.0,0.0,1.5684,5.1371,337.82,320.34,301.32,297.34
145.5506,4.3402,7.5538,0.0,0.0,1.5652,5.1421,337.75,320.22,301.33,297.34
145.55225,4.2346,7.55,0.0,0.0,1.5677,5.0011,337.68,320.1,301.33,297.34
145.5539,4.1041,7.5506,0.0,0.0,1.5658,4.8582,337.6,319.97,301.34,297.35
145.55555,4.1014,7.5545,0.0,0.0,1.5695,4.8785,337.5,319.82,301.35,297.36
145.5572,4.2038,7.5533,0.0,0.0,1.5679,5.0221,337.41,319.68,301.36,297.37
145.55885,4.3394,7.5512,0.0,0.0,1.5673,5.1533,337.31,319.53,301.37,297.38
145.5605,4.345,7.5532,0.0,0.0,1.5681,5.1343,337.22,319.38,301.38,297.39
145.56215,4.2437,7.5476,0.0,0.0,1.5666,5.0072,337.12,319.24,301.39,297.4
145.5638,4.1136,7.5506,0.0,0.0,1.5679,4.8746,337.02,319.1,301.4,297.4
145.56545,4.1072,7.5531,0.0,0.0,1.5654,4.8979,336.93,318.96,301.4,297.4
145.5671,4.2321,7.5495,0.0,0.0,1.5688,5.0526,336.83,318.83,301.41,297.4
145.56875,4.3389,7.553,0.0,0.0,1.5674,5.1637,336.74,318.7,301.41,297.4
145.5704,4.3396,7.5525,0.0,0.0,1.5669,5.1256,336.64,318.57,301.42,297.4
145.57205,4.2254,7.5453,0.0,0.0,1.567,4.9726,336.55,318.44,301.42,297.4
145.5737,4.1102,7.5513,0.0,0.0,1.5635,4.8608,336.46,318.3,301.43,297.41
145.57535,4.1153,7.5503,0.0,0.0,1.5697,4.8872,336.4,318.16,301.43,297.41
145.577,4.2385,7.5505,0.0,0.0,1.5678,5.055,336.34,318.01,301.44,297.42
145.57865,4.3426,7.5541,0.0,0.0,1.5673,5.161,336.28,317.86,301.44,297.42
145.5803,4.338,7.55,0.0,0.0,1.5667,5.1404,336.22,317.72,301.45,297.43
145.58195,4.2341,7.5498,0.0,0.0,1.5643,4.9804,336.16,317.57,301.45,297.43
145.5836,4.1009,7.552,0.0,0.0,1.5691,4.8654,336.11,317.42,301.46,297.44
145.58525,4.1067,7.548,0.0,0.0,1.567,4.8966,336.06,317.26,301.49,297.44
145.5869,4.2332,7.5531,0.0,0.0,1.5682,5.044,336.01,317.11,301.51,297.45
145.58855,4.3518,7.5543,0.0,0.0,1.567,5.1776,335.97,316.95,301.54,297.45
145.5902,4.3376,7.5483,0.0,0.0,1.5677,5.1193,335.92,316.79,301.57,297.46
145.59185,4.2174,7.5539,0.0,0.0,1.5687,4.9832,335.88,316.64,301.59,297.46
145.5935,4.1058,7.5525,0.0,0.0,1.5651,4.8575,335.83,316.48,301.61,297.47
145.59515,4.1042,7.5489,0.0,0.0,1.5686,4.9014,335.77,316.35,301.63,297.49
145.5968,4.24,7.556,0.0,0.0,1.5667,5.0625,335.71,316.21,301.64,297.51
145.59845,4.3452,7.5514,0.0,0.0,1.5706,5.1741,335.65,316.08,301.66,297.53
145.6001,4.3374,7.5512,0.0,0.0,1.5688,5.1317,335.59,315.94,301.67,297.55
145.60175,4.2357,7.5536,0.0,0.0,1.565,4.9936,335.53,315.8,301.69,297.57
145.6034,4.1226,7.5497,0.0,0.0,1.5684,4.872,335.47,315.66,301.7,297.59
145.60505,4.1301,7.5548,0.0,0.0,1.5663,4.9141,335.39,315.52,301.71,297.61
145.6067,4.2402,7.5559,0.0,0.0,1.5706,5.0625,335.3,315.38,301.71,297.62
145.60835,4.3543,7.5501,0.0,0.0,1.5682,5.1784,335.22,315.24,301.72,297.64
145.61,4.3347,7.5542,0.0,0.0,1.5665,5.1349,335.14,315.1,301.72,297.65
145.61165,4.2244,7.5523,0.0,0.0,1.5683,5.0019,335.06,314.96,301.73,297.67
145.6133,4.1342,7.5505,0.0,0.0,1.5669,4.9016,334.98,314.81,301.74,297.68
145.61495,4.1399,7.5572,0.0,0.0,1.5701,4.9301,334.89,314.67,301.75,297.67
145.6166,4.251,7.5572,0.0,0.0,1.5682,5.0724,334.79,314.52,301.77,297.67
145.61825,4.3685,7.5529,0.0,0.0,1.5689,5.1914,334.69,314.37,301.78,297.66
145.6199,4.3631,7.5551,0.0,0.0,1.5687,5.1498,334.6,314.23,301.8,297.66
145.62155,4.2353,7.5516,0.0,0.0,1.5679,4.9995,334.5,314.08,301.81,297.65
145.6232,4.1464,7.5511,0.0,0.0,1.5686,4.9222,334.41,313.94,301.83,297.65
145.62485,4.1676,7.556,0.0,0.0,1.5658,4.9614,334.31,313.82,301.85,297.65
145.6265,4.2781,7.5525,0.0,0.0,1.5707,5.0993,334.2,313.69,301.88,297.65
145.62815,4.3924,7.5563,0.0,0.0,1.5685,5.2297,334.1,313.57,301.9,297.65
145.6298,4.3511,7.5565,0.0,0.0,1.5683,5.1499,334.0,313.45,301.93,297.65
145.63145,4.2601,7.5502,0.0,0.0,1.5683,5.0221,333.9,313.33,301.95,297.65
145.6331,4.1485,7.5547,0.0,0.0,1.5655,4.9247,333.8,313.21,301.98,297.65
145.63475,4.1688,7.5549,0.0,0.0,1.5711,4.962,333.73,313.09,301.97,297.66
145.6364,4.3031,7.5519,0.0,0.0,1.5689,5.1351,333.65,312.97,301.97,297.67
145.63805,4.3766,7.5571,0.0,0.0,1.5689,5.1972,333.58,312.84,301.96,297.68
145.6397,4.3805,7.5536,0.0,0.0,1.5677,5.1813,333.5,312.72,301.96,297.69
145.64135,4.2529,7.5525,0.0,0.0,1.5665,5.0287,333.42,312.6,301.95,297.7
145.643,4.1547,7.5555,0.0,0.0,1.57,4.9298,333.35,312.48,301.95,297.71
145.64465,4.1933,7.5528,0.0,0.0,1.5676,5.0101,333.29,312.33,301.96,297.73
145.6463,4.2903,7.554,0.0,0.0,1.5697,5.1105,333.23,312.19,301.98,297.74
145.64795,4.3917,7.5567,0.0,0.0,1.5671,5.2192,333.17,312.04,301.99,297.76
145.6496,4.3764,7.5499,0.0,0.0,1.5704,5.165,333.11,311.89,302.01,297.77
145.65125,4.2297,7.5547,0.0,0.0,1.5698,4.9908,333.05,311.75,302.02,297.79
145.6529,4.1524,7.5556,0.0,0.0,1.5663,4.9168,332.99,311.6,302.04,297.8
145.65455,4.1735,7.5513,0.0,0.0,1.5693,4.9739,332.91,311.47,302.06,297.82
145.6562,4.2969,7.5561,0.0,0.0,1.5667,5.1305,332.83,311.34,302.09,297.84
145.65785,4.3886,7.5545,0.0,0.0,1.5715,5.2039,332.75,311.21,302.11,297.86
145.6595,4.3646,7.5497,0.0,0.0,1.5691,5.1597,332.66,311.07,302.14,297.88
145.66115,4.252,7.5556,0.0,0.0,1.5655,5.0191,332.58,310.94,302.17,297.9
145.6628,4.1458,7.5505,0.0,0.0,1.5685,4.914,332.5,310.81,302.19,297.92
145.66445,4.1843,7.5541,0.0,0.0,1.5672,4.9859,332.41,310.69,302.2,297.93
145.6661,4.3006,7.5583,0.0,0.0,1.5714,5.1265,332.3,310.58,302.2,297.94
145.66775,4.4011,7.553,0.0,0.0,1.5683,5.229,332.2,310.46,302.21,297.94
145.6694,4.3811,7.5544,0.0,0.0,1.5678,5.1765,332.1,310.34,302.21,297.95
145.67105,4.2369,7.5538,0.0,0.0,1.5684,5.0086,332.0,310.23,302.22,297.95
145.6727,4.1499,7.5494,0.0,0.0,1.5678,4.9254,331.9,310.11,302.22,297.96
145.67435,4.1825,7.557,0.0,0.0,1.5704,4.9896,331.81,309.99,302.22,297.96
145.676,4.3097,7.5572,0.0,0.0,1.5673,5.1428,331.72,309.86,302.22,297.96
145.67765,4.4013,7.5534,0.0,0.0,1.5699,5.2207,331.63,309.73,302.22,297.96
145.6793,4.3725,7.5561,0.0,0.0,1.5687,5.1709,331.54,309.61,302.22,297.96
145.68095,4.2624,7.5542,0.0,0.0,1.5687,5.0357,331.45,309.48,302.22,297.96
145.6826,4.1679,7.551,0.0,0.0,1.5686,4.9526,331.36,309.36,302.22,297.96
145.68425,4.192,7.5576,0.0,0.0,1.5663,5.0141,331.28,309.22,302.22,297.96
145.6859,4.3318,7.5539,0.0,0.0,1.5717,5.1835,331.21,309.08,302.22,297.97
145.68755,4.4127,7.5555,0.0,0.0,1.569,5.2389,331.14,308.93,302.21,297.98
145.6892,4.3844,7.5562,0.0,0.0,1.5684,5.1837,331.07,308.79,302.21,298.0
145.69085,4.2592,7.5523,0.0,0.0,1.5682,5.0266,331.0,308.65,302.2,298.01
145.6925,4.1767,7.5554,0.0,0.0,1.566,4.9474,330.93,308.51,302.2,298.02
145.69415,4.2119,7.5565,0.0,0.0,1.571,5.0212,330.85,308.4,302.21,298.03
145.6958,4.3412,7.5514,0.0,0.0,1.5691,5.1733,330.78,308.3,302.22,298.05
145.69745,4.4231,7.5565,0.0,0.0,1.5694,5.2436,330.7,308.19,302.24,298.07
145.6991,4.3823,7.5554,0.0,0.0,1.5674,5.1806,330.63,308.09,302.25,298.09
145.70075,4.2707,7.5516,0.0,0.0,1.5687,5.0432,330.55,307.99,302.27,298.11
145.7024,4.1862,7.5582,0.0,0.0,1.5704,4.9539,330.48,307.89,302.28,298.13
145.70405,4.2284,7.5561,0.0,0.0,1.5674,5.0652,330.4,307.79,302.3,298.15
145.7057,4.3461,7.5545,0.0,0.0,1.5703,5.2016,330.32,307.68,302.32,298.16
145.70735,4.4337,7.5571,0.0,0.0,1.5658,5.2702,330.24,307.57,302.34,298.17
145.709,4.3927,7.5526,0.0,0.0,1.5714,5.1923,330.15,307.47,302.36,298.18
145.71065,4.261,7.5549,0.0,0.0,1.57,5.0174,330.07,307.36,302.38,298.19
145.7123,4.1959,7.5557,0.0,0.0,1.5664,4.982,329.99,307.26,302.4,298.2
145.71395,4.2423,7.5542,0.0,0.0,1.5703,5.0507,329.92,307.14,302.41,298.2
145.7156,4.3666,7.5573,0.0,0.0,1.5671,5.2103,329.84,307.01,302.42,298.2
145.71725,4.4427,7.5584,0.0,0.0,1.5721,5.2752,329.76,306.88,302.42,298.2
145.7189,4.3906,7.5514,0.0,0.0,1.5692,5.2004,329.69,306.76,302.43,298.2
145.72055,4.2611,7.5558,0.0,0.0,1.5672,5.041,329.61,306.63,302.43,298.2
145.7222,4.1926,7.5547,0.0,0.0,1.5696,4.9787,329.54,306.51,302.44,298.2
145.72385,4.2383,7.5536,0.0,0.0,1.5679,5.047,329.46,306.38,302.45,298.21
145.7255,4.3687,7.5595,0.0,0.0,1.5719,5.2088,329.38,306.26,302.46,298.21
145.72715,4.4373,7.5551,0.0,0.0,1.5682,5.2623,329.3,306.14,302.47,298.22
145.7288,4.399,7.5539,0.0,0.0,1.5684,5.1948,329.22,306.02,302.48,298.22
145.73045,4.2567,7.5559,0.0,0.0,1.569,5.0288,329.14,305.9,302.49,298.23
145.7321,4.1977,7.5519,0.0,0.0,1.5688,4.9917,329.06,305.78,302.5,298.23
145.73375,4.2482,7.5554,0.0,0.0,1.5701,5.0696,328.98,305.66,302.5,298.25
145.7354,4.3823,7.5582,0.0,0.0,1.5668,5.221,328.92,305.56,302.51,298.28
145.73705,4.4431,7.5525,0.0,0.0,1.5702,5.2688,328.85,305.45,302.51,298.31
145.7387,4.3909,7.5573,0.0,0.0,1.5684,5.1882,328.79,305.34,302.52,298.34
145.74035,4.2695,7.5557,0.0,0.0,1.569,5.0416,328.72,305.24,302.52,298.37
145.742,4.1935,7.5521,0.0,0.0,1.5691,4.9638,328.66,305.13,302.53,298.4
145.74365,4.2475,7.5583,0.0,0.0,1.5662,5.0656,328.58,305.02,302.53,298.43
145.7453,4.3827,7.5558,0.0,0.0,1.5714,5.2256,328.49,304.91,302.54,298.45
145.74695,4.4394,7.5539,0.0,0.0,1.5688,5.2611,328.4,304.8,302.54,298.48
145.7486,4.4004,7.558,0.0,0.0,1.5695,5.2009,328.31,304.69,302.55,298.51
145.75025,4.2668,7.5536,0.0,0.0,1.5682,5.0495,328.22,304.58,302.55,298.53
145.7519,4.1987,7.5551,0.0,0.0,1.5669,4.9836,328.13,304.47,302.56,298.56
145.75355,4.2586,7.5586,0.0,0.0,1.5713,5.0878,328.03,304.34,302.57,298.58
145.7552,4.3833,7.554,0.0,0.0,1.5688,5.2187,327.92,304.21,302.58,298.59
145.75685,4.459,7.5564,0.0,0.0,1.5702,5.3007,327.82,304.07,302.6,298.6
145.7585,4.39,7.5562,0.0,0.0,1.5675,5.169,327.71,303.93,302.61,298.61
145.76015,4.2853,7.5512,0.0,0.0,1.5705,5.0547,327.6,303.8,302.63,298.62
145.7618,4.2144,7.558,0.0,0.0,1.57,5.0155,327.5,303.66,302.65,298.63
145.76345,4.282,7.5585,0.0,0.0,1.5684,5.1245,327.41,303.53,302.65,298.63
145.7651,4.4141,7.5544,0.0,0.0,1.57,5.2811,327.35,303.42,302.65,298.63
145.76675,4.4624,7.5581,0.0,0.0,1.5667,5.3075,327.29,303.31,302.64,298.63
145.7684,4.4016,7.5545,0.0,0.0,1.5717,5.1857,327.23,303.2,302.64,298.63
145.77005,4.2757,7.5528,0.0,0.0,1.5694,5.0487,327.17,303.09,302.63,298.63
145.7717,4.2135,7.5578,0.0,0.0,1.5676,4.9953,327.11,302.97,302.63,298.63
145.77335,4.2747,7.5537,0.0,0.0,1.5696,5.1002,327.05,302.87,302.63,298.63
145.775,4.4268,7.5584,0.0,0.0,1.5676,5.2616,326.99,302.77,302.64,298.63
145.77665,4.4727,7.5588,0.0,0.0,1.5718,5.2979,326.93,302.68,302.66,298.63
145.7783,4.4128,7.553,0.0,0.0,1.5688,5.2232,326.87,302.58,302.67,298.63
145.77995,4.2992,7.5553,0.0,0.0,1.5679,5.0817,326.81,302.48,302.69,298.63
145.7816,4.237,7.5569,0.0,0.0,1.57,5.0377,326.75,302.39,302.71,298.63
145.78325,4.2881,7.5526,0.0,0.0,1.5688,5.1163,326.68,302.29,302.72,298.64
145.7849,4.4314,7.5607,0.0,0.0,1.5714,5.2784,326.6,302.21,302.74,298.67
145.78655,4.4798,7.5578,0.0,0.0,1.5684,5.3056,326.52,302.13,302.75,298.7
145.7882,4.3993,7.5533,0.0,0.0,1.5691,5.1984,326.44,302.05,302.77,298.73
145.78985,4.2898,7.5578,0.0,0.0,1.5693,5.0797,326.36,301.97,302.78,298.76
145.7915,4.2404,7.5542,0.0,0.0,1.5695,5.0358,326.28,301.89,302.8,298.79
145.79315,4.3077,7.5558,0.0,0.0,1.5708,5.1312,326.2,301.81,302.81,298.82
145.7948,4.4375,7.5587,0.0,0.0,1.5665,5.2878,326.11,301.73,302.81,298.85
145.79645,4.4874,7.5537,0.0,0.0,1.5717,5.3212,326.03,301.64,302.81,298.88
145.7981,4.404,7.5568,0.0,0.0,1.5686,5.1942,325.95,301.56,302.81,298.92
145.79975,4.2945,7.5575,0.0,0.0,1.5701,5.0764,325.87,301.48,302.81,298.95
145.8014,4.2426,7.554,0.0,0.0,1.5692,5.0314,325.79,301.4,302.81,298.98
145.80305,4.3171,7.558,0.0,0.0,1.5669,5.1352,325.71,301.32,302.81,299.0
145.8047,4.4509,7.5585,0.0,0.0,1.572,5.3012,325.63,301.23,302.81,298.99
145.80635,4.484,7.552,0.0,0.0,1.569,5.312,325.55,301.15,302.81,298.98
145.808,4.4311,7.5577,0.0,0.0,1.5699,5.2265,325.47,301.06,302.81,298.97
145.80965,4.293,7.5544,0.0,0.0,1.5683,5.0771,325.39,300.97,302.81,298.96
145.8113,4.2351,7.5553,0.0,0.0,1.569,5.0327,325.31,300.89,302.81,298.95
145.81295,4.3227,7.5593,0.0,0.0,1.5716,5.1635,325.23,300.8,302.81,298.94
146.41343,4.2803,7.5597,0.0,0.0,1.5711,5.0792,305.32,280.77,302.14,295.68
147.41343,4.1902,7.5633,0.0,0.0,1.5727,4.9714,286.03,266.24,294.83,287.8
148.41343,4.129,7.567,0.0,0.0,1.5744,4.9002,274.42,256.94,285.39,278.26
149.239,4.1355,7.5696,0.0,0.0,1.5756,4.9103,266.44,250.57,277.25,270.28
150.239,4.0872,7.5727,0.0,0.0,1.577,4.85,257.69,243.52,267.61,260.91
151.239,4.1091,7.5763,0.0,0.0,1.5787,4.8756,250.0,237.05,258.62,252.24
152.239,4.1287,7.5792,0.0,0.0,1.58,4.9007,242.83,230.9,250.03,244.01
153.239,4.1254,7.5816,0.0,0.0,1.5811,4.8945,236.05,224.8,241.9,236.19
154.239,4.1452,7.5842,0.0,0.0,1.5823,4.9202,229.53,219.14,234.26,228.88
155.239,4.1642,7.5862,0.0,0.0,1.5831,4.9414,223.43,213.57,227.06,221.89
156.239,4.1572,7.5883,0.0,0.0,1.5841,4.933,217.57,208.3,220.25,215.27
157.239,4.1806,7.5902,0.0,0.0,1.585,4.9623,212.08,203.38,213.88,209.0
158.239,4.1778,7.5918,0.0,0.0,1.5857,4.9573,206.63,198.44,207.79,203.0
159.239,4.1885,7.5935,0.0,0.0,1.5865,4.9714,201.57,193.74,202.03,197.46
160.239,4.2116,7.5951,0.0,0.0,1.5872,4.9969,196.63,189.28,196.63,192.14
161.239,4.2023,7.5965,0.0,0.0,1.5879,4.9875,191.84,185.0,191.4,187.06
162.239,4.214,7.5979,0.0,0.0,1.5884,5.0007,187.47,180.89,186.46,182.12
163.239,4.2105,7.5992,0.0,0.0,1.589,4.9946,183.01,176.83,181.74,177.56
164.239,4.2094,7.6006,0.0,0.0,1.5896,4.9954,179.04,173.02,177.28,173.25
165.239,4.2206,7.6017,0.0,0.0,1.5901,5.0079,174.94,169.38,172.99,169.0
166.239,4.2044,7.603,0.0,0.0,1.5907,4.989,171.15,165.91,168.99,165.06
167.239,4.2276,7.6043,0.0,0.0,1.5913,5.0174,167.41,162.39,165.04,161.14
168.239,4.2214,7.6055,0.0,0.0,1.5919,5.008,163.79,159.03,161.21,157.43
169.239,4.2109,7.607,0.0,0.0,1.5925,4.9987,160.38,155.68,157.66,153.92
170.239,4.2304,7.6083,0.0,0.0,1.5932,5.0199,157.1,152.6,154.09,150.44
171.239,4.225,7.6095,0.0,0.0,1.5938,5.0136,154.0,149.64,150.8,147.24
172.239,4.2292,7.6109,0.0,0.0,1.5945,5.0196,150.79,146.7,147.58,144.03
173.239,4.2232,7.6122,0.0,0.0,1.5951,5.0103,147.86,143.89,144.41,141.06
174.239,4.2345,7.6137,0.0,0.0,1.5958,5.026,144.94,141.21,141.38,138.06
175.239,4.2387,7.6149,0.0,0.0,1.5964,5.0285,142.11,138.54,138.53,135.25
176.239,4.2277,7.6163,0.0,0.0,1.597,5.0171,139.36,135.91,135.76,132.45
177.239,4.228,7.6176,0.0,0.0,1.5976,5.018,136.77,133.59,133.04,129.84
178.239,4.229,7.6188,0.0,0.0,1.5982,5.0172,134.23,131.12,130.52,127.31
179.2124,4.2287,7.6204,0.0,0.0,1.5987,5.019,131.73,128.81,128.04,124.91
180.2124,4.2378,7.6214,0.0,0.0,1.5993,5.0273,129.41,126.55,125.69,122.56
181.2124,4.229,7.6227,0.0,0.0,1.5999,5.0197,127.09,124.33,123.21,120.19
182.0763,4.231,7.6236,0.0,0.0,1.6004,5.0222,125.18,122.54,121.33,118.38
183.0763,4.2399,7.625,0.0,0.0,1.6011,5.0315,122.97,120.42,119.01,116.19
184.0763,4.2239,7.6262,0.0,0.0,1.6017,5.0117,120.85,118.44,116.9,114.05
185.0763,4.238,7.6275,0.0,0.0,1.6023,5.0314,118.71,116.39,114.84,112.01
186.0763,4.2441,7.6287,0.0,0.0,1.6028,5.0357,116.77,114.5,112.88,110.06
187.0763,4.2382,7.6302,0.0,0.0,1.6034,5.0306,114.71,112.51,110.86,108.06
188.0763,4.2489,7.6314,0.0,0.0,1.604,5.0419,112.81,110.8,109.03,106.34
189.0763,4.242,7.6327,0.0,0.0,1.6046,5.0334,110.9,109.03,107.1,104.44
190.0763,4.2566,7.634,0.0,0.0,1.6053,5.0533,109.12,107.39,105.38,102.74
191.0763,4.2593,7.6352,0.0,0.0,1.6058,5.0538,107.36,105.69,103.61,101.01
192.0763,4.2428,7.6363,0.0,0.0,1.6063,5.0355,105.74,104.07,101.96,99.409
193.0763,4.2542,7.6373,0.0,0.0,1.6067,5.0471,103.96,102.51,100.28,97.814
194.0763,4.246,7.6383,0.0,0.0,1.6072,5.0385,102.42,100.96,98.793,96.362
195.0763,4.2445,7.6394,0.0,0.0,1.6077,5.0382,100.78,99.405,97.223,94.79
196.0763,4.2577,7.6406,0.0,0.0,1.6082,5.0512,99.305,97.989,95.794,93.399
197.0763,4.2373,7.6417,0.0,0.0,1.6087,5.029,97.79,96.58,94.336,91.916
198.0763,4.2556,7.6428,0.0,0.0,1.6092,5.0506,96.411,95.215,92.884,90.575
199.0763,4.2448,7.6437,0.0,0.0,1.6096,5.0359,95.079,93.848,91.502,89.324
200.0763,4.2435,7.645,0.0,0.0,1.6103,5.0367,93.575,92.477,90.153,87.96
201.0763,4.2566,7.6458,0.0,0.0,1.6106,5.0505,92.283,91.275,88.925,86.761
202.0763,4.2491,7.6468,0.0,0.0,1.6111,5.0428,90.985,90.002,87.647,85.525
203.0763,4.2677,7.648,0.0,0.0,1.6117,5.0641,89.745,88.853,86.501,84.374
204.0763,4.2578,7.649,0.0,0.0,1.6122,5.0515,88.504,87.543,85.309,83.18
205.0763,4.2621,7.65,0.0,0.0,1.6127,5.0588,87.277,86.436,84.108,82.077
206.0763,4.1323,7.6522,0.0,0.0,1.6138,4.9038,86.429,85.631,83.069,82.008
207.0763,4.449,7.6513,0.0,0.0,1.6134,5.2802,86.719,86.095,83.402,83.087
207.6763,4.1395,7.6513,0.0,0.0,1.6132,4.9125,86.83,86.139,83.641,83.294