File: examples/dan-msc-case-studies/CS4/data/01 raw data/hyde_test_039.csv
Time(sec),Force(kN),Jaw(mm),PowAngle(deg),PTemp,Strain,Stress(MPa),TC1(C),TC2(C),TC3(C)
0.0,3.5101,0.0018172,0.0,7.4951e-06,0.00023047,10.667,19.288,19.655,19.361
0.8,3.4727,0.0020677,0.0,2.2211,0.00022117,10.532,19.215,19.634,19.447
1.6,3.4467,0.0020386,0.0,4.6211,0.00023648,10.458,19.267,19.644,19.461
2.4,3.4219,0.0022609,0.0,7.0211,0.00024075,10.38,19.232,19.648,19.401
3.2,3.4101,0.0022847,0.0,9.4211,0.00024457,10.346,19.223,19.615,19.421
4.0,3.3939,0.0024025,0.0,11.821,0.00028076,10.293,19.193,19.644,19.457
4.8,3.3865,0.0022976,0.0,14.221,0.0002528,10.274,19.211,19.644,19.469
5.6,3.3677,0.0024,0.0,16.621,0.00026273,10.214,19.25,19.681,19.473
6.3878,3.372,0.0024075,0.0,18.985,0.00025022,10.227,19.237,19.603,19.462
7.1878,3.3707,0.0035487,22.335,21.384,0.00039444,10.226,19.269,20.086,19.67
7.9878,3.4073,0.001672,31.837,23.784,0.00017403,10.334,20.675,26.101,24.297
8.7878,3.4124,0.00045177,27.493,26.184,4.3813e-05,10.353,24.835,36.031,32.742
9.5878,3.3836,0.0014054,12.672,28.584,0.00016602,10.263,29.353,37.943,36.065
10.3878,3.3778,0.0017321,16.519,30.984,0.00019075,10.248,31.188,36.465,35.043
11.1878,3.3846,0.00099254,25.286,33.384,0.00010983,10.265,32.424,37.179,35.383
11.9878,3.4054,-0.00073843,30.313,35.784,-5.921e-05,10.331,34.251,42.052,39.327
12.7878,3.4215,-0.001574,26.991,38.184,-0.00017478,10.378,37.693,48.07,45.209
13.5295,3.4183,-0.0018938,23.196,40.41,-0.00020686,10.37,40.638,50.201,47.666
14.3295,3.4231,-0.002357,22.058,42.81,-0.00025945,10.385,43.101,50.83,48.516
15.1295,3.4319,-0.002823,26.984,45.21,-0.00030873,10.409,44.697,52.054,49.419
15.9295,3.4407,-0.0043461,29.416,47.61,-0.00048398,10.436,46.831,56.165,53.041
16.7295,3.4389,-0.0050065,26.296,50.01,-0.00053776,10.433,50.018,60.507,57.456
17.5295,3.4346,-0.0053739,24.415,52.41,-0.0005917,10.421,52.731,62.113,59.33
18.3295,3.4301,-0.0060295,26.274,54.81,-0.00066222,10.406,54.677,63.27,60.426
19.1295,3.4459,-0.0074569,29.603,57.21,-0.00082162,10.451,56.566,66.237,63.042
19.9295,3.4481,-0.0081254,27.228,59.61,-0.0008977,10.462,59.643,70.576,67.296
20.7295,3.4407,-0.0087357,25.123,62.01,-0.00094973,10.434,62.358,72.203,69.233
21.5295,3.4515,-0.0093477,27.2,64.41,-0.0010331,10.474,64.326,73.554,70.479
22.3295,3.4525,-0.010752,29.326,66.81,-0.0011643,10.473,66.372,76.781,73.273
23.1295,3.4589,-0.011939,27.991,69.21,-0.001318,10.494,69.195,80.777,77.238
23.9295,3.4367,-0.012599,26.08,71.61,-0.0013783,10.423,71.902,82.628,79.417
24.7295,3.462,-0.013353,27.243,74.01,-0.0014733,10.502,74.007,84.095,80.784
25.5295,3.4572,-0.015192,28.708,76.41,-0.0016776,10.485,76.155,87.222,83.511
26.3295,3.4613,-0.017011,27.959,78.81,-0.0018722,10.501,78.804,90.213,86.631
27.1295,3.4504,-0.017916,27.417,81.21,-0.0019735,10.467,81.377,92.477,88.915
27.9295,3.4601,-0.018295,29.248,83.61,-0.0020007,10.498,83.348,94.06,90.44
28.7295,3.448,-0.019209,29.41,86.01,-0.0021172,10.46,85.835,97.275,93.544
29.5295,3.4532,-0.019688,28.78,88.41,-0.0021549,10.475,88.434,99.934,96.153
30.3295,3.4471,-0.020664,28.822,90.81,-0.0022752,10.459,90.759,102.11,98.384
31.1295,3.4578,-0.02176,29.481,93.21,-0.0023825,10.487,93.052,104.56,100.67
31.9295,3.4516,-0.023075,29.794,95.61,-0.0025399,10.471,95.5,107.52,103.48
32.72951,3.4568,-0.024093,29.785,98.01,-0.0026463,10.484,97.975,110.04,106.09
33.52951,3.453,-0.02478,28.542,100.41,-0.0027094,10.478,100.59,112.26,108.49
34.32951,3.4528,-0.025957,29.734,102.81,-0.00285,10.474,102.75,114.02,110.14
35.12951,3.4542,-0.027227,30.407,105.21,-0.0029852,10.481,104.98,117.04,112.87
35.92951,3.4496,-0.028359,29.577,107.61,-0.003105,10.464,107.66,119.95,115.87
36.72951,3.4643,-0.029225,29.103,110.01,-0.0031945,10.511,110.08,121.88,117.88
37.52951,3.4573,-0.03023,29.886,112.41,-0.0033167,10.487,112.31,124.07,120.01
38.32951,3.4609,-0.03174,30.815,114.81,-0.0034649,10.501,114.65,126.83,122.63
39.0236,3.4505,-0.032683,29.875,116.89,-0.0035924,10.466,116.89,129.36,125.11
39.8236,3.4529,-0.033774,29.667,119.29,-0.0037081,10.476,119.4,131.52,127.37
40.6236,3.4432,-0.034493,28.548,121.69,-0.0037767,10.448,121.99,132.53,128.75
41.4236,3.4674,-0.035604,31.759,124.09,-0.0039057,10.52,123.64,134.26,129.96
42.2236,3.4623,-0.037379,30.919,126.49,-0.0040956,10.503,126.3,137.69,133.35
43.0236,3.6311,-0.037688,30.008,128.89,-0.0041414,11.015,128.93,139.97,135.83
43.8236,4.1571,-0.033545,30.965,131.29,-0.0036945,12.611,131.09,141.96,137.72
44.6236,4.5511,-0.029721,29.692,133.69,-0.003247,13.805,133.84,144.79,140.55
45.4236,4.8174,-0.027785,30.339,136.09,-0.0030406,14.616,136.1,146.68,142.49
46.2236,5.0984,-0.025473,30.28,138.49,-0.002786,15.464,138.55,149.48,145.18
47.0236,5.3407,-0.023179,30.175,140.89,-0.0025341,16.202,140.93,151.72,147.41
47.8236,5.4454,-0.022627,30.663,143.29,-0.0024812,16.516,143.23,153.86,149.58
48.6236,5.4159,-0.023146,30.291,145.69,-0.0025285,16.432,145.73,156.52,152.01
49.4236,5.3546,-0.024121,29.298,148.09,-0.0026371,16.243,148.31,158.81,154.43
50.2236,5.2279,-0.026224,30.674,150.49,-0.0028723,15.862,150.42,161.02,156.45
51.0236,4.8811,-0.028947,30.413,152.89,-0.0031681,14.805,152.94,163.84,159.13
51.8236,4.5486,-0.031379,30.399,155.29,-0.003429,13.799,155.29,166.14,161.54
52.6236,4.2721,-0.033826,30.92,157.69,-0.003703,12.958,157.62,168.71,163.92
53.4236,4.1157,-0.035709,30.968,160.09,-0.0039114,12.485,160.08,171.1,166.33
54.2236,4.0687,-0.037278,31.277,162.49,-0.0040757,12.345,162.41,173.58,168.82
55.0236,4.0529,-0.038535,31.626,164.89,-0.0042319,12.293,164.8,175.97,171.29
55.8236,4.0263,-0.040115,31.149,167.29,-0.0044027,12.216,167.22,178.42,173.68
56.6236,4.0062,-0.041788,31.821,169.69,-0.0045637,12.151,169.6,180.91,176.08
57.4236,3.9803,-0.043216,31.332,172.09,-0.0047297,12.077,172.1,183.43,178.73
58.22361,3.9649,-0.04492,31.898,174.49,-0.0049257,12.028,174.41,185.76,180.92
59.02361,3.9274,-0.046636,31.657,176.89,-0.0051108,11.915,176.93,188.39,183.55
59.82361,3.7457,-0.048876,31.67,179.29,-0.0053521,11.36,179.26,190.8,185.97
60.62361,3.5617,-0.051391,31.862,181.69,-0.0056392,10.809,181.6,193.27,188.41
61.42361,3.5149,-0.053198,31.853,184.09,-0.0058428,10.663,184.07,195.74,190.88
62.22361,3.5251,-0.054579,31.882,186.49,-0.0059841,10.694,186.47,198.14,193.34
63.02361,3.4152,-0.056729,31.975,188.89,-0.0062114,10.358,188.87,200.76,195.85
63.82361,3.3097,-0.058714,31.465,191.29,-0.0064476,10.041,191.37,203.33,198.47
64.62361,3.1427,-0.060752,31.626,193.69,-0.0066642,9.5353,193.74,205.66,200.85
65.42361,3.0111,-0.062834,32.095,196.09,-0.0069082,9.1333,196.05,208.13,203.3
66.22361,2.8926,-0.065093,32.253,198.49,-0.007131,8.7749,198.46,210.63,205.79
67.02361,2.7872,-0.067184,32.406,200.89,-0.0073641,8.4542,200.8,212.96,208.23
67.82361,2.6981,-0.069166,32.235,203.29,-0.0075886,8.1868,203.28,215.53,210.76
68.62361,2.6548,-0.070942,32.318,205.69,-0.0077807,8.0511,205.66,217.89,213.18
69.42361,2.6671,-0.072565,32.029,208.09,-0.0079701,8.0904,208.11,220.46,215.67
70.22361,2.6807,-0.074246,32.394,210.49,-0.0081474,8.1295,210.5,223.0,218.16
71.02361,2.7051,-0.076388,32.833,212.89,-0.0083668,8.2077,212.84,225.46,220.68
71.7506,2.7061,-0.077689,32.854,215.07,-0.0085204,8.2089,214.99,227.65,222.85
72.5506,2.7073,-0.079769,33.698,217.47,-0.0087471,8.2136,217.22,230.07,225.29
73.3506,2.704,-0.081359,32.71,219.87,-0.0088922,8.2033,219.9,232.7,228.03
74.1506,2.7143,-0.083348,33.51,222.27,-0.0091185,8.2364,222.14,234.95,230.25
74.9506,2.7164,-0.084887,33.061,224.67,-0.0092962,8.2393,224.63,237.56,232.98
75.6321,2.7164,-0.086157,33.607,226.72,-0.0094339,8.2433,226.59,239.46,234.84
76.4321,2.7224,-0.087973,33.542,229.12,-0.0096185,8.2586,229.09,242.15,237.54
77.2321,2.727,-0.089345,33.804,231.52,-0.0097678,8.2755,231.43,244.37,239.85
78.0321,2.7245,-0.090967,34.224,233.92,-0.0099643,8.2633,233.79,246.85,242.31
78.8321,2.7278,-0.09191,34.155,236.32,-0.010076,8.2769,236.24,249.41,244.84
79.6321,2.7292,-0.092342,34.163,238.72,-0.010134,8.2772,238.57,251.73,247.16
80.4321,2.7341,-0.093306,34.205,241.12,-0.01022,8.2937,241.11,254.42,249.86
81.2321,2.7271,-0.09444,34.369,243.52,-0.010332,8.2753,243.46,256.72,252.25
82.0321,2.7181,-0.09515,31.848,245.92,-0.010398,8.2436,245.43,258.01,253.95
82.8321,2.7301,-0.096502,33.854,248.32,-0.010553,8.2813,246.39,259.03,254.54
83.6321,2.7205,-0.097581,32.375,250.72,-0.010667,8.25,247.8,260.18,255.99
84.4321,2.7184,-0.098681,33.029,253.12,-0.010776,8.2499,248.75,261.02,256.73
85.2321,2.7312,-0.099714,33.689,255.52,-0.010881,8.2862,249.71,261.92,257.66
86.0321,2.725,-0.10109,33.652,257.92,-0.01103,8.2674,251.12,263.51,259.37
86.8321,2.7279,-0.10332,34.771,260.32,-0.011278,8.2749,253.33,266.75,262.27
87.6321,2.7232,-0.1046,33.991,262.72,-0.011427,8.2629,255.98,269.38,265.06
88.4321,2.7197,-0.10693,34.416,265.12,-0.01168,8.247,258.33,271.98,267.49
89.2321,2.7362,-0.11045,34.386,267.52,-0.012043,8.3025,260.78,274.53,270.14
90.0321,2.7224,-0.11058,34.125,269.92,-0.012098,8.2604,263.23,277.0,272.6
90.8321,2.7329,-0.11024,34.25,272.32,-0.012039,8.2917,265.61,279.39,275.04
91.6321,2.7276,-0.11188,34.385,274.72,-0.012225,8.2746,268.02,281.97,277.47
92.4321,2.7313,-0.11375,33.97,277.12,-0.012438,8.2846,270.49,284.38,279.93
93.2321,2.7236,-0.11535,34.613,279.52,-0.012608,8.2639,272.8,286.86,282.36
94.0321,2.731,-0.11717,34.403,281.92,-0.012806,8.2843,275.22,289.3,284.86
94.83211,2.7219,-0.11893,34.61,284.32,-0.012996,8.2595,277.58,291.82,287.36
95.63211,2.7286,-0.12123,34.533,286.72,-0.013245,8.2745,280.06,294.25,289.84
96.43211,2.7316,-0.12531,34.807,289.12,-0.013668,8.2892,282.34,296.61,292.19
97.23211,2.7388,-0.12401,34.838,291.52,-0.013571,8.3051,284.77,299.04,294.69
98.03211,2.7376,-0.12466,34.678,293.92,-0.013619,8.3059,287.2,301.42,297.12
98.83211,2.7285,-0.12673,34.75,296.32,-0.013838,8.2748,289.64,303.88,299.62
99.63211,2.7288,-0.12864,35.051,298.72,-0.014044,8.2795,291.99,306.3,302.04
100.43211,2.7241,-0.1302,34.738,301.12,-0.014209,8.2637,294.48,308.77,304.59
101.23211,2.7299,-0.13197,35.118,303.52,-0.014394,8.2821,296.82,311.27,306.91
102.03211,2.7209,-0.1345,35.015,305.92,-0.014667,8.2508,299.22,313.68,309.41
102.83211,2.7388,-0.13839,35.306,308.32,-0.015074,8.3084,301.61,316.12,311.83
103.63211,2.7369,-0.1365,35.231,310.72,-0.014907,8.3054,304.02,318.36,314.18
104.3748,2.7231,-0.13714,34.334,312.95,-0.014966,8.2613,306.47,320.23,316.16
105.1748,2.7348,-0.13878,34.841,315.35,-0.015144,8.2949,308.66,321.43,317.56
105.9148,2.7279,-0.14049,34.701,317.57,-0.01533,8.273,310.91,323.72,319.69
106.7148,2.7286,-0.14205,34.784,319.97,-0.015502,8.2799,313.29,326.01,322.0
107.5148,2.7243,-0.14374,34.736,322.37,-0.015691,8.2621,315.67,328.25,324.25
108.3148,2.7237,-0.14561,34.683,324.77,-0.015888,8.262,318.12,329.98,326.25
109.1148,2.7309,-0.14895,34.652,327.17,-0.016228,8.2837,320.55,332.15,328.4
109.9148,2.7352,-0.14986,34.795,329.57,-0.016355,8.2974,322.9,334.26,330.56
110.7148,2.7326,-0.14865,35.315,331.97,-0.01621,8.289,325.24,335.94,332.35
111.5148,2.7339,-0.15011,35.297,334.37,-0.016353,8.2944,327.63,338.13,334.42
112.3148,2.7335,-0.15185,35.052,336.77,-0.016553,8.2925,330.1,340.23,336.7
113.1148,2.7369,-0.15328,35.301,339.17,-0.016714,8.3025,332.46,342.38,338.98
113.9148,2.7263,-0.15508,35.208,341.57,-0.016908,8.2723,334.87,344.64,341.21
114.7148,2.7256,-0.15651,35.072,343.97,-0.017077,8.2651,337.32,346.9,343.6
115.5148,2.7213,-0.15808,35.387,346.37,-0.017224,8.2559,339.65,349.31,345.93
116.3148,2.7326,-0.16076,35.262,348.77,-0.017499,8.2852,342.1,351.65,348.44
117.1148,2.7356,-0.16436,35.37,351.17,-0.017905,8.3012,344.42,353.89,350.72
117.9148,2.7389,-0.16239,35.517,353.57,-0.017724,8.3084,346.91,356.21,353.11
118.7148,2.7366,-0.16267,36.027,355.97,-0.017735,8.3042,349.19,358.31,355.27
119.5148,2.7314,-0.16441,35.506,358.37,-0.017917,8.2838,351.7,360.64,357.7
120.3148,2.7343,-0.16603,35.846,360.77,-0.018097,8.2949,354.05,362.72,359.98
121.1148,2.7288,-0.16768,35.975,363.17,-0.018267,8.278,356.42,364.88,362.25
121.9148,2.7316,-0.16897,35.775,365.57,-0.018393,8.2886,358.88,367.18,364.59
122.7148,2.7225,-0.17052,35.918,367.97,-0.018581,8.2615,361.26,369.36,366.87
123.5148,2.7335,-0.17237,36.286,370.37,-0.018775,8.29,363.6,371.47,369.11
124.3148,2.7358,-0.17552,36.025,372.77,-0.019096,8.3007,366.07,373.73,371.5
125.1148,2.7325,-0.17761,36.078,375.17,-0.019354,8.2894,368.49,375.88,373.81
125.91481,2.7324,-0.17528,36.048,377.57,-0.019082,8.2911,370.93,378.21,376.25
126.71481,2.7293,-0.17628,36.277,379.97,-0.019198,8.2792,373.2,380.18,378.39
127.51481,2.7331,-0.17798,36.099,382.37,-0.019381,8.2936,375.72,382.5,380.72
128.31481,2.7248,-0.17951,36.02,384.77,-0.019553,8.2642,378.13,384.61,382.99
129.11481,2.7322,-0.18078,36.328,387.17,-0.019677,8.2895,380.45,386.6,385.13
129.91481,2.7248,-0.182,36.315,389.57,-0.019813,8.2646,382.86,388.75,387.31
130.71481,2.7273,-0.18322,36.282,391.97,-0.019945,8.2763,385.26,390.91,389.64
131.51481,2.718,-0.18673,36.468,394.37,-0.020327,8.2439,389.47,396.0,393.89
132.31481,2.736,-0.18837,37.259,396.77,-0.020474,8.2974,391.55,396.7,395.77
133.11481,2.7329,-0.19129,36.527,399.17,-0.020817,8.2924,394.22,399.13,398.43
133.91481,2.7134,-0.18756,34.535,400.0,-0.020438,8.2279,395.57,399.34,399.45
134.71481,2.7119,-0.18664,35.474,400.0,-0.020327,8.229,395.23,399.18,398.89
135.51481,2.7088,-0.18676,35.477,400.0,-0.020317,8.2165,395.11,398.67,398.59
136.31481,2.7055,-0.18714,34.933,400.0,-0.020379,8.2086,395.21,398.65,398.67
137.0001,2.7053,-0.1874,35.046,400.0,-0.020402,8.2045,395.15,398.65,398.61
137.8001,2.7023,-0.18767,35.306,400.0,-0.020426,8.1997,395.05,398.51,398.5
138.6001,2.7006,-0.18794,35.332,400.0,-0.020448,8.1914,395.04,398.49,398.46
139.4001,2.7049,-0.18828,35.494,400.0,-0.02049,8.2065,395.24,398.82,398.75
140.2001,2.7006,-0.18919,33.803,400.0,-0.020589,8.1885,396.45,399.85,399.98
141.0001,2.7142,-0.19174,35.178,400.0,-0.020834,8.234,396.02,399.63,399.6
141.8001,2.7186,-0.19068,34.779,400.0,-0.020785,8.2456,396.07,399.64,399.62
142.6001,2.7348,-0.18805,34.837,400.0,-0.020492,8.2968,396.09,399.83,399.77
143.4001,2.7342,-0.1881,34.794,400.0,-0.020463,8.2945,396.08,400.01,399.94
144.2001,2.7381,-0.18857,34.663,400.0,-0.020528,8.3045,396.2,400.29,400.31
145.0001,2.7125,-0.18932,34.72,400.0,-0.020619,8.2321,396.54,401.0,400.78
145.8001,2.7291,-0.18988,35.767,400.0,-0.020658,8.2788,396.82,401.96,401.41
146.6001,2.6994,-0.18998,35.325,400.0,-0.020693,8.1922,396.95,401.87,401.76
147.4001,2.7025,-0.19014,34.695,400.0,-0.020696,8.1974,397.07,402.33,402.2
148.2001,2.7166,-0.19117,34.783,400.0,-0.020789,8.2421,397.03,402.52,402.43
149.0001,2.7241,-0.19434,34.979,400.0,-0.021133,8.2635,396.98,402.79,402.6
149.8001,2.7301,-0.19204,34.612,400.0,-0.020928,8.281,397.11,402.95,402.91
150.6001,2.7298,-0.18961,34.395,400.0,-0.020641,8.2803,397.1,403.03,403.01
151.4001,2.7435,-0.18967,34.139,400.0,-0.020651,8.3247,397.12,403.17,403.13
152.2001,2.7266,-0.19,34.063,400.0,-0.020674,8.273,397.06,403.1,403.15
153.0001,2.7373,-0.19053,34.401,400.0,-0.02074,8.3034,397.03,403.13,403.12
153.8001,2.7267,-0.19059,33.954,400.0,-0.020752,8.2716,397.08,403.1,403.08
154.6001,2.7291,-0.19059,33.797,400.0,-0.020742,8.2763,397.09,402.98,403.05
155.4001,2.7201,-0.1907,34.008,400.0,-0.020754,8.2526,397.05,402.85,403.02
156.20011,2.7166,-0.19142,34.045,400.0,-0.020821,8.241,397.01,402.72,402.87
157.00011,2.7193,-0.19299,33.871,400.0,-0.020985,8.2485,397.07,402.56,402.79
157.80011,2.7192,-0.19391,33.795,400.0,-0.021125,8.2457,397.08,402.52,402.77
158.60011,2.7146,-0.18995,33.786,400.0,-0.020697,8.2383,397.06,402.37,402.6
159.40011,2.715,-0.18989,33.771,400.0,-0.02067,8.2341,397.08,402.29,402.55
160.20011,2.7128,-0.19007,33.772,400.0,-0.020674,8.2325,397.08,402.09,402.3
161.00011,2.7077,-0.19053,33.719,400.0,-0.020734,8.2126,397.07,401.93,402.18
161.80011,2.7023,-0.19058,33.755,400.0,-0.020736,8.2019,396.95,401.52,401.96
162.60011,2.6975,-0.19061,33.54,400.0,-0.020749,8.1839,397.08,401.6,401.94
163.40011,2.6973,-0.19061,33.676,400.0,-0.020729,8.183,396.99,401.25,401.65
164.20011,2.6962,-0.19166,34.165,400.0,-0.020863,8.1788,396.84,400.86,401.3
165.00011,2.6952,-0.19394,33.679,400.0,-0.021073,8.1758,397.0,400.93,401.46
165.80011,2.6868,-0.19229,33.767,400.0,-0.020967,8.1522,397.01,400.75,401.21
166.60011,2.6948,-0.1897,33.962,400.0,-0.020651,8.1728,396.92,400.51,401.08
167.40011,2.6969,-0.18958,33.803,400.0,-0.020635,8.1821,396.96,400.48,401.07
168.20011,2.6889,-0.19013,34.223,400.0,-0.0207,8.1526,396.92,400.29,400.81
169.00011,2.6855,-0.19013,33.81,400.0,-0.020697,8.1486,397.05,400.22,400.85
169.7425,2.6876,-0.19026,33.854,400.0,-0.02069,8.1547,397.03,400.19,400.8
170.5425,2.6749,-0.19111,34.603,400.0,-0.020809,8.1106,396.87,399.91,400.54
171.3425,2.6975,-0.19445,33.991,400.0,-0.021151,8.1836,397.01,399.86,400.55
172.1425,2.6894,-0.18926,34.074,400.0,-0.020612,8.1579,396.97,399.77,400.41
172.9425,2.6829,-0.18969,33.772,400.0,-0.020641,8.1396,396.99,399.7,400.32
173.7425,2.6713,-0.1903,34.338,400.0,-0.020723,8.1029,396.93,399.55,400.09
174.5425,2.6777,-0.19024,33.847,400.0,-0.020703,8.1224,397.04,399.51,400.18
175.3425,2.6752,-0.19109,33.683,400.0,-0.020798,8.1163,397.06,399.41,400.16
176.1425,2.6869,-0.19415,33.421,400.0,-0.021139,8.1501,397.1,399.31,400.04
176.9425,2.6924,-0.18926,33.151,400.0,-0.020614,8.1708,397.12,399.26,400.05
177.6106,2.6917,-0.18934,33.046,400.0,-0.020598,8.1646,397.09,399.1,399.82
178.4106,2.6777,-0.023595,32.862,400.0,-0.0025685,8.1232,397.16,399.1,399.91
178.62006,2.728,0.0086963,0.0,0.7631,0.0016379,8.2539,396.86,398.62,399.62
178.62138,2.6735,0.0053799,0.0,3.9597e-06,0.00072285,8.1007,396.89,398.62,399.64
178.6227,2.6703,0.0052772,0.0,1.4636e-11,0.0012391,8.0975,396.91,398.62,399.66
178.62402,2.6196,0.0085731,0.0,4.7357e-17,0.0010772,7.9275,396.93,398.62,399.67
178.62534,2.7354,0.0017869,0.0,1.4297999999999998e-22,0.00069872,8.2896,396.96,398.62,399.69
178.62666,2.656,0.010493,0.0,4.1344e-28,0.0019412,8.0963,396.98,398.62,399.7
178.62798,2.7224,0.010137,0.0,1.1618e-33,0.00074641,8.2561,397.01,398.62,399.72
178.6293,2.6732,0.011236,0.0,3.1923e-39,0.0014852,8.0728,397.01,398.62,399.72
178.63062,2.6565,0.013072,0.0,9.8091e-45,0.0007447,8.0702,396.98,398.63,399.69
178.63194,2.7112,0.0090901,0.0,0.0,0.0011806,8.2354,396.94,398.63,399.65
178.63326,2.6852,0.010721,0.0,0.0,0.00096007,8.1136,396.91,398.64,399.62
178.63458,2.6581,0.010884,0.0,0.0,0.00064358,8.0643,396.88,398.65,399.59
178.6359,2.7133,0.01191,0.0,0.0,0.0016441,8.2152,396.85,398.66,399.56
178.63722,2.6712,0.0080745,0.0,0.0,0.00023711,8.0969,396.82,398.67,399.53
178.63854,2.645,0.010475,0.0,0.0,0.0020738,8.0261,396.78,398.67,399.49
178.63986,2.6996,0.0092934,0.0,0.0,0.000575,8.1996,396.79,398.68,399.5
178.64118,2.6654,0.0092108,0.0,0.0,0.0018581,8.0589,396.79,398.68,399.5
178.6425,2.6446,0.0041669,0.0,0.0,0.00093794,8.0025,396.8,398.68,399.51
178.64382,2.6888,0.0047057,0.0,0.0,0.0016089,8.1824,396.81,398.68,399.52
178.64514,2.6774,0.005629,0.0,0.0,0.0010799,8.0883,396.82,398.68,399.53
178.64646,2.6406,0.0068719,0.0,0.0,0.00075682,8.0015,396.83,398.68,399.54
178.64778,2.688,0.0071859,0.0,0.0,0.001167,8.1703,396.83,398.68,399.54
178.6491,2.6739,0.0070756,0.0,0.0,0.00075106,8.0712,396.84,398.67,399.55
178.65042,2.6304,0.010365,0.0,0.0,0.00064377,7.9677,396.84,398.67,399.55
178.65174,2.6871,0.011778,0.0,0.0,0.001344,8.1849,396.85,398.66,399.55
178.65306,2.6784,0.009023,0.0,0.0,0.00016353,8.1077,396.85,398.65,399.55
178.65438,2.6307,0.010367,0.0,0.0,0.0017572,7.9695,396.86,398.64,399.55
178.6557,2.6824,0.010465,0.0,0.0,-0.00027771,8.124,396.86,398.63,399.55
178.65702,2.674,0.012181,0.0,0.0,0.0018241,8.0897,396.86,398.63,399.55
178.65834,2.6226,0.0081063,0.0,0.0,0.00016361,7.9833,396.87,398.62,399.55
178.65966,2.6713,0.01092,0.0,0.0,0.0016021,8.1067,396.87,398.6,399.54
178.66098,2.6681,0.0082462,0.0,0.0,0.00044766,8.1027,396.87,398.59,399.53
178.6623,2.6231,0.010093,0.0,0.0,0.0011107,7.9563,396.87,398.57,399.52
178.66362,2.6579,0.0037704,0.0,0.0,0.00094424,8.0842,396.87,398.56,399.5
178.66494,2.6726,0.0034745,0.0,0.0,0.00075546,8.0822,396.87,398.54,399.49
178.66626,2.6108,0.0066698,0.0,0.0,0.00094872,7.9055,396.87,398.52,399.48
178.66758,2.66,0.0084935,0.0,0.0,0.00071635,8.0831,396.87,398.51,399.47
178.6689,2.6742,0.0080866,0.0,0.0,0.00064243,8.0883,396.92,398.52,399.45
178.67022,2.6219,0.0090829,0.0,0.0,0.0012793,7.9473,397.27,398.7,399.42
178.67154,2.6478,0.0096433,0.0,0.0,-6.2724e-05,8.0393,397.61,398.87,399.39
178.67286,2.6776,0.012973,0.0,0.0,0.0016775,8.1272,397.96,399.05,399.36
178.67418,2.6244,0.01069,0.0,0.0,-5.7648e-05,7.9591,398.31,399.22,399.33
178.6755,2.6965,0.0096304,0.0,0.0,0.0014851,8.202,398.65,399.4,399.29
178.67682,2.6949,0.010078,0.0,0.0,0.00035958,8.1441,399.0,399.57,399.26
178.67813,2.5841,0.012413,0.0,0.0,0.0011996,7.83,399.35,399.75,399.23
178.67945,2.6806,0.0088057,0.0,0.0,0.00076961,8.1822,400.26,400.72,399.2
178.68077,2.6953,0.0090393,0.0,0.0,0.0007554,8.1587,401.58,402.25,399.17
178.68209,3.0048,0.0092526,0.0,0.0,0.0014619,8.7323,402.91,403.78,399.15
178.68341,14.627,0.057172,0.0,0.0,0.0057709,41.036,404.23,405.31,399.12
178.68473,28.045,0.20944,0.0,0.0,0.02274,85.328,405.55,406.84,399.09
178.68605,32.238,0.49794,0.0,0.0,0.054971,97.524,406.87,408.38,399.06
178.68737,32.802,0.78576,0.0,0.0,0.088964,99.276,408.19,409.91,399.03
178.68869,33.526,1.0745,0.0,0.0,0.12383,101.65,409.52,411.44,399.01
178.69001,33.982,1.3763,0.0,0.0,0.1606,103.09,411.0,413.2,399.01
178.69133,34.003,1.6796,0.0,0.0,0.20073,103.22,412.48,414.96,399.02
178.69265,34.028,1.9803,0.0,0.0,0.24019,103.19,413.97,416.72,399.02
178.69397,33.971,2.29,0.0,0.0,0.28382,103.1,415.45,418.47,399.02
178.69529,34.029,2.5904,0.0,0.0,0.32741,103.23,416.93,420.23,399.03
178.69661,34.192,2.8903,0.0,0.0,0.37183,103.66,418.42,421.99,399.03
178.69793,34.312,3.1827,0.0,0.0,0.42023,104.06,419.9,423.75,399.04
178.69925,34.525,3.4778,0.0,0.0,0.46615,104.67,421.11,424.99,399.05
178.70057,34.72,3.7682,0.0,0.0,0.51867,105.29,422.0,425.64,399.08
178.70189,34.942,4.054,0.0,0.0,0.56814,105.95,422.9,426.29,399.12
178.70321,35.171,4.3365,0.0,0.0,0.62385,106.63,423.79,426.95,399.15
178.70453,35.413,4.6225,0.0,0.0,0.67968,107.4,424.68,427.6,399.18
178.70585,35.645,4.8949,0.0,0.0,0.73681,108.09,425.58,428.25,399.21
178.70717,35.827,5.1655,0.0,0.0,0.79883,108.64,426.47,428.9,399.24
178.70849,36.039,5.4336,0.0,0.0,0.85781,109.31,427.36,429.55,399.27
178.70981,36.196,5.6975,0.0,0.0,0.92553,109.76,427.47,429.44,399.3
178.71113,36.262,5.9524,0.0,0.0,0.99025,109.97,427.49,429.25,399.32
178.71245,36.337,6.1899,0.0,0.0,1.0569,110.22,427.51,429.06,399.34
178.71377,36.428,6.4122,0.0,0.0,1.1238,110.49,427.53,428.87,399.36
178.71509,36.492,6.6229,0.0,0.0,1.1865,110.69,427.55,428.68,399.38
178.71641,36.43,6.8113,0.0,0.0,1.2548,110.51,427.57,428.49,399.4
178.71773,36.399,6.9726,0.0,0.0,1.3058,110.4,427.59,428.3,399.42
178.71905,36.296,7.1219,0.0,0.0,1.3703,110.13,427.25,427.8,399.43
178.72037,36.157,7.2528,0.0,0.0,1.409,109.66,426.2,426.72,399.43
178.72169,36.037,7.3696,0.0,0.0,1.4655,109.31,425.16,425.64,399.44
178.72301,35.865,7.4599,0.0,0.0,1.5037,108.79,424.12,424.56,399.44
178.72433,35.828,7.5541,0.0,0.0,1.5459,108.68,423.08,423.48,399.45
178.72565,35.846,7.6339,0.0,0.0,1.5835,108.72,422.04,422.4,399.45
178.72697,35.938,7.7223,0.0,0.0,1.6212,109.09,421.0,421.32,399.45
178.72829,31.948,7.717,0.0,0.0,1.6257,96.972,419.96,420.24,399.46
178.72961,30.312,7.7333,0.0,0.0,1.6307,92.138,418.85,419.09,399.47
178.73093,29.092,7.7491,0.0,0.0,1.6357,88.276,417.72,417.92,399.48
178.73225,28.458,7.7546,0.0,0.0,1.6408,86.292,416.58,416.75,399.49
178.73357,27.949,7.7531,0.0,0.0,1.6348,84.782,415.45,415.58,399.5
178.73489,27.684,7.7567,0.0,0.0,1.6465,84.01,414.32,414.42,399.52
178.73621,27.567,7.7602,0.0,0.0,1.6374,83.653,413.18,413.25,399.53
178.73753,27.432,7.7678,0.0,0.0,1.6504,83.21,412.05,412.08,399.54
178.73885,27.281,7.7692,0.0,0.0,1.6446,82.788,411.02,411.0,399.55
178.74017,27.056,7.773,0.0,0.0,1.6507,82.122,410.33,410.23,399.56
178.74149,26.662,7.7811,0.0,0.0,1.6535,80.938,409.65,409.46,399.57
178.74281,26.173,7.7828,0.0,0.0,1.6502,79.445,408.96,408.69,399.57
178.74413,25.55,7.776,0.0,0.0,1.6564,77.636,408.28,407.92,399.58
178.74545,24.54,7.7725,0.0,0.0,1.6501,74.57,407.59,407.16,399.59
178.74677,23.287,7.7751,0.0,0.0,1.6554,70.811,406.91,406.39,399.6
178.74809,21.723,7.7717,0.0,0.0,1.6502,66.102,406.22,405.62,399.61
178.74941,19.802,7.77,0.0,0.0,1.6514,60.381,405.85,405.22,399.62
178.75073,17.639,7.7615,0.0,0.0,1.6505,53.845,405.63,405.0,399.64
178.75205,14.775,7.7645,0.0,0.0,1.644,45.33,405.41,404.79,399.66
178.75337,6.8835,7.7677,0.0,0.0,1.6512,22.951,405.19,404.57,399.68
178.75469,-0.27521,7.723,0.0,0.0,1.6223,-0.98562,404.97,404.36,399.7
178.75601,3.6151,7.7635,0.0,0.0,1.6487,11.262,404.75,404.14,399.72
178.75733,1.9622,7.7561,0.0,0.0,1.6423,5.9295,404.53,403.93,399.74
178.75865,2.1361,7.7689,0.0,0.0,1.6456,6.4188,404.34,403.75,399.76
178.75997,2.3381,7.7648,0.0,0.0,1.6494,7.1612,404.35,403.88,399.79
178.76129,2.3092,7.7597,0.0,0.0,1.6404,6.8702,404.36,404.01,399.83
178.76261,2.1945,7.7553,0.0,0.0,1.6469,6.637,404.37,404.14,399.86
178.76393,2.269,7.7529,0.0,0.0,1.6364,6.8617,404.38,404.27,399.89
178.76525,2.2689,7.7462,0.0,0.0,1.642,6.8931,404.4,404.4,399.92
178.76657,2.1519,7.7426,0.0,0.0,1.6383,6.5579,404.41,404.53,399.95
178.76789,2.2787,7.746,0.0,0.0,1.6406,6.9725,404.42,404.67,399.99
178.76921,2.2039,7.7509,0.0,0.0,1.6431,6.6492,404.41,404.81,400.02
178.77053,2.114,7.7532,0.0,0.0,1.6399,6.4493,404.38,404.95,400.05
178.77185,2.2379,7.7525,0.0,0.0,1.6442,6.8257,404.34,405.1,400.08
178.77317,2.191,7.7526,0.0,0.0,1.639,6.5937,404.31,405.25,400.11
178.77449,2.1508,7.7544,0.0,0.0,1.639,6.5147,404.28,405.39,400.14
178.77581,2.2495,7.7562,0.0,0.0,1.6417,6.855,404.25,405.54,400.18
178.77713,2.2496,7.7501,0.0,0.0,1.6354,6.75,404.22,405.69,400.21
178.77845,2.1038,7.7533,0.0,0.0,1.6449,6.3728,404.19,405.84,400.24
178.77977,2.1571,7.7545,0.0,0.0,1.6326,6.5702,404.1,405.88,400.26
178.78109,2.2378,7.7575,0.0,0.0,1.6458,6.7746,404.0,405.93,400.27
178.78241,2.1578,7.7538,0.0,0.0,1.6365,6.5197,403.91,405.97,400.29
178.78373,2.1512,7.7548,0.0,0.0,1.6428,6.541,403.82,406.01,400.3
178.78505,2.2327,7.7544,0.0,0.0,1.6368,6.778,403.73,406.06,400.32
178.78637,2.1991,7.7563,0.0,0.0,1.6402,6.6724,403.64,406.1,400.34
178.78769,2.1441,7.747,0.0,0.0,1.6415,6.5041,403.55,406.15,400.35
178.78901,2.2351,7.7487,0.0,0.0,1.6386,6.7805,403.44,406.17,400.36
178.79033,2.1733,7.7495,0.0,0.0,1.6411,6.5861,403.31,406.18,400.37
178.79165,2.1473,7.7531,0.0,0.0,1.6386,6.5162,403.18,406.19,400.38
178.79296,2.2008,7.7522,0.0,0.0,1.6387,6.6742,403.06,406.2,400.39
178.79428,2.1591,7.7524,0.0,0.0,1.6425,6.5726,402.93,406.21,400.4
178.7956,2.2102,7.7569,0.0,0.0,1.636,6.7278,402.8,406.21,400.4
178.79692,2.295,7.7587,0.0,0.0,1.6458,6.9162,402.68,406.22,400.41
178.79824,2.1799,7.7546,0.0,0.0,1.6351,6.6197,402.55,406.23,400.42
178.79956,2.1936,7.7527,0.0,0.0,1.6442,6.6864,402.4,406.23,400.46
178.80088,2.2884,7.756,0.0,0.0,1.6377,6.9261,402.25,406.24,400.51
178.8022,2.2076,7.7586,0.0,0.0,1.642,6.6486,402.1,406.24,400.56
178.80352,2.158,7.7557,0.0,0.0,1.6418,6.5552,401.95,406.25,400.61
178.80484,2.2832,7.7545,0.0,0.0,1.6391,6.9336,401.79,406.25,400.65
178.80616,2.2343,7.7557,0.0,0.0,1.6449,6.7447,401.64,406.25,400.7
178.80748,2.1961,7.7573,0.0,0.0,1.6395,6.6973,401.49,406.26,400.75
178.8088,2.2945,7.751,0.0,0.0,1.6469,6.9878,401.33,406.26,400.8
178.81012,2.2446,7.7487,0.0,0.0,1.6427,6.7938,401.15,406.26,400.84
178.81144,2.1833,7.7511,0.0,0.0,1.6413,6.6161,400.97,406.26,400.89
178.81276,2.2577,7.7568,0.0,0.0,1.6456,6.8738,400.8,406.26,400.94
178.81408,2.2346,7.7545,0.0,0.0,1.6395,6.7804,400.62,406.26,400.99
178.8154,2.2318,7.7566,0.0,0.0,1.6471,6.7799,400.44,406.26,401.04
178.81672,2.2933,7.7567,0.0,0.0,1.6398,6.9548,400.26,406.26,401.08
178.81804,2.2284,7.7607,0.0,0.0,1.6451,6.7341,400.08,406.26,401.13
178.81936,2.1987,7.7576,0.0,0.0,1.6424,6.7037,399.91,406.24,401.15
178.82068,2.2882,7.7547,0.0,0.0,1.6421,6.9433,399.74,406.21,401.16
178.822,2.2213,7.7552,0.0,0.0,1.6457,6.7036,399.57,406.17,401.18
178.82332,2.2415,7.7592,0.0,0.0,1.6382,6.8252,399.41,406.14,401.19
178.82464,2.2444,7.757,0.0,0.0,1.6471,6.7881,399.24,406.11,401.2
178.82596,2.1952,7.7547,0.0,0.0,1.6386,6.6409,399.07,406.08,401.21
178.82728,2.2201,7.7557,0.0,0.0,1.6472,6.7655,398.91,406.05,401.22
178.8286,2.2493,7.7548,0.0,0.0,1.6417,6.808,398.74,406.01,401.24
178.82992,2.2199,7.7542,0.0,0.0,1.6428,6.7338,398.55,405.92,401.26
178.83124,2.2258,7.7479,0.0,0.0,1.6444,6.7186,398.37,405.83,401.28
178.83256,2.2567,7.7509,0.0,0.0,1.64,6.8346,398.19,405.74,401.3
178.83388,2.221,7.7556,0.0,0.0,1.6439,6.7157,398.0,405.66,401.32
178.8352,2.1662,7.7562,0.0,0.0,1.6405,6.5785,397.82,405.57,401.34
178.83652,2.2499,7.7557,0.0,0.0,1.6413,6.8623,397.64,405.48,401.36
178.83784,2.248,7.756,0.0,0.0,1.6419,6.7834,397.45,405.39,401.38
178.83916,2.2065,7.7577,0.0,0.0,1.6367,6.6859,397.25,405.3,401.4
178.84048,2.2396,7.7588,0.0,0.0,1.6461,6.7917,397.04,405.2,401.42
178.8418,2.2569,7.7546,0.0,0.0,1.6358,6.847,396.82,405.1,401.45
178.84312,2.2493,7.7559,0.0,0.0,1.6466,6.839,396.6,405.0,401.47
178.84444,2.2865,7.7598,0.0,0.0,1.6352,6.931,396.39,404.9,401.5
178.84576,2.3176,7.7595,0.0,0.0,1.6439,7.029,396.17,404.8,401.52
178.84708,2.2793,7.7561,0.0,0.0,1.6409,6.9121,395.96,404.7,401.54
178.8484,2.3991,7.7549,0.0,0.0,1.6409,7.2784,395.75,404.6,401.57
178.84972,2.3491,7.756,0.0,0.0,1.6432,7.1058,395.57,404.53,401.6
178.85104,2.3008,7.7542,0.0,0.0,1.6397,7.0021,395.39,404.45,401.64
178.85236,2.3717,7.7511,0.0,0.0,1.6431,7.212,395.22,404.38,401.67
178.85368,2.4319,7.7507,0.0,0.0,1.64,7.3648,395.04,404.3,401.71
178.855,2.3108,7.757,0.0,0.0,1.6401,6.9933,394.87,404.22,401.75
178.85632,2.3755,7.7603,0.0,0.0,1.6434,7.2871,394.69,404.15,401.78
178.85764,2.495,7.757,0.0,0.0,1.6379,7.5364,394.52,404.07,401.82
178.85896,2.3185,7.7562,0.0,0.0,1.6461,7.0234,394.34,403.98,401.85
178.86028,2.3799,7.7578,0.0,0.0,1.6368,7.2656,394.16,403.88,401.87
178.8616,2.5103,7.7596,0.0,0.0,1.6459,7.5473,393.98,403.78,401.9
178.86292,2.2886,7.7555,0.0,0.0,1.639,6.8954,393.8,403.67,401.92
178.86424,2.3735,7.7544,0.0,0.0,1.6419,7.2251,393.62,403.57,401.94
178.86556,2.5157,7.7594,0.0,0.0,1.6429,7.5751,393.44,403.47,401.97
178.86688,2.2533,7.7602,0.0,0.0,1.6398,6.8299,393.26,403.36,401.99
178.8682,2.3647,7.7535,0.0,0.0,1.6463,7.2906,393.08,403.26,402.02
178.86952,2.5012,7.7538,0.0,0.0,1.6398,7.5325,392.9,403.13,402.03
178.87084,2.2733,7.7519,0.0,0.0,1.6443,6.8747,392.71,403.01,402.05
178.87216,2.365,7.7547,0.0,0.0,1.6425,7.2488,392.52,402.88,402.06
178.87348,2.4977,7.7515,0.0,0.0,1.6438,7.5048,392.33,402.75,402.08
178.8748,2.2786,7.7495,0.0,0.0,1.6448,6.8555,392.15,402.62,402.1
178.87612,2.3679,7.7566,0.0,0.0,1.6404,7.255,391.96,402.5,402.11
178.87744,2.5315,7.758,0.0,0.0,1.6455,7.6548,391.77,402.37,402.13
178.87876,2.2873,7.7587,0.0,0.0,1.6405,6.895,391.58,402.25,402.15
178.88008,2.3467,7.7546,0.0,0.0,1.6448,7.2131,391.39,402.15,402.18
178.8814,2.526,7.7559,0.0,0.0,1.642,7.6425,391.2,402.04,402.2
178.88272,2.3052,7.7589,0.0,0.0,1.6407,6.9585,391.01,401.94,402.23
178.88404,2.338,7.7555,0.0,0.0,1.6455,7.1469,390.82,401.84,402.26
178.88536,2.5397,7.7547,0.0,0.0,1.638,7.6694,390.62,401.73,402.29
178.88668,2.3126,7.7579,0.0,0.0,1.6477,6.955,390.43,401.63,402.31
178.888,2.3333,7.7611,0.0,0.0,1.6394,7.1368,390.24,401.53,402.34
178.88932,2.5492,7.7566,0.0,0.0,1.6469,7.7431,390.06,401.41,402.37
178.89064,2.3369,7.7515,0.0,0.0,1.641,7.0435,389.87,401.3,402.39
178.89196,2.3254,7.7529,0.0,0.0,1.6435,7.1475,389.69,401.18,402.42
178.89328,2.5482,7.7534,0.0,0.0,1.6437,7.7397,389.51,401.07,402.44
178.8946,2.3548,7.752,0.0,0.0,1.6399,7.0719,389.32,400.95,402.46
178.89592,2.3072,7.7506,0.0,0.0,1.6435,7.0681,389.14,400.84,402.49
178.89724,2.5407,7.7541,0.0,0.0,1.6392,7.6716,388.96,400.72,402.51
178.89856,2.3779,7.7589,0.0,0.0,1.6404,7.1035,388.77,400.6,402.53
178.89988,2.2969,7.7574,0.0,0.0,1.6426,7.0275,388.6,400.46,402.56
178.9012,2.5399,7.7556,0.0,0.0,1.6374,7.7049,388.43,400.31,402.58
178.90252,2.3886,7.7537,0.0,0.0,1.6441,7.1852,388.26,400.17,402.61
178.90384,2.2854,7.7583,0.0,0.0,1.6349,6.9937,388.09,400.03,402.63
178.90516,2.5139,7.7562,0.0,0.0,1.6457,7.6452,387.92,399.88,402.65
178.90648,2.4012,7.7555,0.0,0.0,1.637,7.2101,387.75,399.74,402.68
178.90779,2.278,7.7557,0.0,0.0,1.6432,6.9632,387.57,399.6,402.7
178.90911,2.5272,7.7609,0.0,0.0,1.6396,7.6879,387.41,399.46,402.72
178.91043,2.392,7.7543,0.0,0.0,1.6391,7.1919,387.24,399.34,402.74
178.91175,2.254,7.7527,0.0,0.0,1.6435,6.8901,387.08,399.21,402.75
178.91307,2.4988,7.7483,0.0,0.0,1.6374,7.652,386.92,399.08,402.77
178.91439,2.4108,7.7556,0.0,0.0,1.6441,7.2286,386.75,398.95,402.78
178.91571,2.2689,7.7521,0.0,0.0,1.6384,6.9116,386.59,398.83,402.8
178.91703,2.4938,7.7525,0.0,0.0,1.6399,7.5971,386.43,398.7,402.82
178.91835,2.4149,7.7531,0.0,0.0,1.643,7.2538,386.26,398.57,402.83
178.91967,2.259,7.7577,0.0,0.0,1.6362,6.8627,386.11,398.46,402.85
178.92099,2.4936,7.7607,0.0,0.0,1.6462,7.6663,385.96,398.35,402.87
178.92231,2.4368,7.756,0.0,0.0,1.6366,7.3382,385.81,398.24,402.89
178.92363,2.2376,7.7521,0.0,0.0,1.6436,6.7876,385.66,398.13,402.91
178.92495,2.4693,7.7605,0.0,0.0,1.6402,7.5592,385.51,398.02,402.93
178.92627,2.4413,7.7572,0.0,0.0,1.6422,7.3387,385.35,397.9,402.95
178.92759,2.246,7.7553,0.0,0.0,1.6423,6.8324,385.2,397.79,402.97
178.92891,2.4497,7.7546,0.0,0.0,1.6388,7.4912,385.05,397.68,402.99
178.93023,2.4667,7.7584,0.0,0.0,1.6461,7.3797,384.89,397.56,403.01
178.93155,2.2312,7.7537,0.0,0.0,1.6376,6.7788,384.73,397.45,403.02
178.93287,2.4598,7.752,0.0,0.0,1.6487,7.5537,384.57,397.33,403.04
178.93419,2.5057,7.7471,0.0,0.0,1.641,7.5473,384.41,397.22,403.05
178.93551,2.2539,7.7543,0.0,0.0,1.6426,6.837,384.25,397.1,403.07
178.93683,2.433,7.7536,0.0,0.0,1.6439,7.4701,384.09,396.99,403.08
178.93815,2.4961,7.7562,0.0,0.0,1.6416,7.5057,383.93,396.87,403.1
178.93947,2.2789,7.7506,0.0,0.0,1.6445,6.885,383.78,396.74,403.11
178.94079,2.4227,7.76,0.0,0.0,1.641,7.4194,383.63,396.61,403.12
178.94211,2.5084,7.7576,0.0,0.0,1.6434,7.5672,383.49,396.49,403.14
178.94343,2.2659,7.7576,0.0,0.0,1.6431,6.8305,383.34,396.36,403.15
178.94475,2.4081,7.754,0.0,0.0,1.6411,7.4402,383.19,396.23,403.16
178.94607,2.5183,7.7589,0.0,0.0,1.6469,7.6054,383.04,396.1,403.17
178.94739,2.3009,7.7579,0.0,0.0,1.638,6.951,382.9,395.98,403.18
178.94871,2.4032,7.7589,0.0,0.0,1.6481,7.3558,382.75,395.85,403.19
178.95003,2.5284,7.7554,0.0,0.0,1.6382,7.6062,382.61,395.73,403.2
178.95135,2.2968,7.757,0.0,0.0,1.6469,6.9445,382.46,395.6,403.21
178.95267,2.4095,7.7579,0.0,0.0,1.6421,7.3807,382.32,395.48,403.22
178.95399,2.5627,7.7545,0.0,0.0,1.6438,7.725,382.18,395.36,403.23
178.95531,2.3042,7.747,0.0,0.0,1.644,6.9599,382.03,395.23,403.23
178.95663,2.3838,7.7546,0.0,0.0,1.6419,7.3691,381.89,395.11,403.24
178.95795,2.5572,7.7586,0.0,0.0,1.6451,7.7234,381.75,394.98,403.25
178.95927,2.328,7.7562,0.0,0.0,1.6408,7.013,381.59,394.87,403.25
178.96059,2.3785,7.757,0.0,0.0,1.6418,7.2433,381.44,394.75,403.25
178.96191,2.546,7.758,0.0,0.0,1.6427,7.7131,381.29,394.64,403.25
178.96323,2.3308,7.7601,0.0,0.0,1.6379,6.9956,381.14,394.52,403.25
178.96455,2.3453,7.7585,0.0,0.0,1.646,7.1722,380.99,394.41,403.25
178.96587,2.5761,7.7567,0.0,0.0,1.6358,7.806,380.84,394.29,403.25
178.96719,2.3519,7.7559,0.0,0.0,1.6465,7.0691,380.68,394.17,403.25
178.96851,2.3294,7.7607,0.0,0.0,1.6361,7.1341,380.54,394.05,403.25
178.96983,2.5561,7.7612,0.0,0.0,1.6452,7.7791,380.4,393.93,403.27
178.97115,2.3574,7.7557,0.0,0.0,1.641,7.1105,380.26,393.8,403.28
178.97247,2.3393,7.7555,0.0,0.0,1.6411,7.1686,380.13,393.67,403.29
178.97379,2.5578,7.7572,0.0,0.0,1.6437,7.7726,379.99,393.54,403.3
178.97511,2.3801,7.7542,0.0,0.0,1.6395,7.1557,379.86,393.42,403.31
178.97643,2.3118,7.7482,0.0,0.0,1.6426,7.0622,379.72,393.29,403.33
178.97775,2.5605,7.7526,0.0,0.0,1.6404,7.7614,379.58,393.16,403.34
178.97907,2.4025,7.7566,0.0,0.0,1.6408,7.2291,379.46,393.03,403.35
178.98039,2.3107,7.759,0.0,0.0,1.6438,7.0744,379.34,392.91,403.37
178.98171,2.5435,7.7565,0.0,0.0,1.6379,7.7383,379.22,392.78,403.39
178.98303,2.3962,7.7579,0.0,0.0,1.6469,7.1955,379.1,392.65,403.4
178.98435,2.3078,7.7582,0.0,0.0,1.6368,7.0354,378.98,392.52,403.42
178.98567,2.5396,7.7598,0.0,0.0,1.6472,7.7199,378.86,392.4,403.43
178.98699,2.4081,7.7572,0.0,0.0,1.6404,7.2225,378.74,392.27,403.45
178.98831,2.3047,7.7547,0.0,0.0,1.6423,7.0337,378.62,392.14,403.46
178.98963,2.5275,7.7628,0.0,0.0,1.6446,7.7301,378.48,392.0,403.46
178.99095,2.4432,7.7611,0.0,0.0,1.6407,7.3261,378.35,391.87,403.46
178.99227,2.3063,7.7565,0.0,0.0,1.6474,7.0185,378.21,391.73,403.46
178.99359,2.5163,7.7572,0.0,0.0,1.641,7.6689,378.07,391.6,403.46
178.99491,2.4495,7.7545,0.0,0.0,1.645,7.3614,377.94,391.46,403.46
178.99623,2.2861,7.7581,0.0,0.0,1.6445,6.949,377.8,391.32,403.46
178.99755,2.5185,7.7504,0.0,0.0,1.6451,7.7037,377.67,391.19,403.46
178.99887,2.4544,7.7537,0.0,0.0,1.6467,7.3769,377.54,391.06,403.47
179.00019,2.27,7.7566,0.0,0.0,1.6401,6.9129,377.42,390.94,403.49
179.00151,2.505,7.7608,0.0,0.0,1.6473,7.6424,377.3,390.82,403.5
179.00283,2.474,7.7584,0.0,0.0,1.6413,7.4529,377.18,390.7,403.52
179.00415,2.2952,7.757,0.0,0.0,1.6456,6.9683,377.06,390.58,403.54
179.00547,2.4832,7.7585,0.0,0.0,1.6426,7.5654,376.94,390.46,403.55
179.00679,2.4962,7.7606,0.0,0.0,1.6415,7.4783,376.82,390.35,403.57
179.00811,2.282,7.7577,0.0,0.0,1.6469,6.9302,376.7,390.23,403.58
179.00943,2.485,7.756,0.0,0.0,1.6382,7.6239,376.6,390.12,403.6
179.01075,2.5109,7.7622,0.0,0.0,1.6489,7.549,376.49,390.01,403.62
179.01207,2.277,7.7602,0.0,0.0,1.6391,6.9068,376.39,389.9,403.64
179.01339,2.4701,7.7596,0.0,0.0,1.6485,7.5624,376.29,389.8,403.66
179.01471,2.5237,7.7531,0.0,0.0,1.641,7.5583,376.18,389.69,403.68
179.01603,2.3054,7.7573,0.0,0.0,1.6455,6.9744,376.08,389.58,403.7
179.01735,2.4446,7.7541,0.0,0.0,1.6439,7.5065,375.97,389.47,403.72
179.01867,2.5266,7.7559,0.0,0.0,1.6423,7.5684,375.86,389.36,403.73
179.01999,2.3085,7.7514,0.0,0.0,1.6438,6.9624,375.75,389.24,403.72
179.02131,2.4409,7.7574,0.0,0.0,1.6406,7.5545,375.63,389.12,403.71
179.02262,2.561,7.761,0.0,0.0,1.6421,7.6808,375.52,389.0,403.7
179.02394,2.3139,7.7609,0.0,0.0,1.6446,6.9871,375.4,388.88,403.7
179.02526,2.4325,7.7577,0.0,0.0,1.6387,7.4425,375.28,388.76,403.69
179.02658,2.5475,7.7587,0.0,0.0,1.646,7.6705,375.17,388.64,403.68
179.0279,2.3182,7.761,0.0,0.0,1.6359,6.9877,375.05,388.52,403.67
179.02922,2.4211,7.7611,0.0,0.0,1.6477,7.4115,374.94,388.41,403.67
179.03054,2.5618,7.7565,0.0,0.0,1.6378,7.7457,374.83,388.3,403.66
179.03186,2.3231,7.7624,0.0,0.0,1.6458,7.025,374.72,388.19,403.66
179.03318,2.419,7.7622,0.0,0.0,1.6395,7.4907,374.6,388.07,403.66
179.0345,2.599,7.761,0.0,0.0,1.6428,7.8234,374.49,387.96,403.65
179.03582,2.3474,7.754,0.0,0.0,1.6437,7.0881,374.38,387.85,403.65
179.03714,2.4042,7.7556,0.0,0.0,1.6409,7.3773,374.27,387.74,403.65
179.03846,2.5739,7.7576,0.0,0.0,1.6451,7.7745,374.16,387.63,403.65
179.03978,2.3555,7.7563,0.0,0.0,1.6407,7.0732,374.06,387.53,403.65
179.0411,2.3903,7.7544,0.0,0.0,1.6415,7.3079,373.95,387.42,403.66
179.04242,2.5819,7.7571,0.0,0.0,1.6454,7.8183,373.85,387.32,403.67
179.04374,2.3639,7.7624,0.0,0.0,1.6389,7.1474,373.74,387.22,403.68
179.04506,2.3575,7.7607,0.0,0.0,1.647,7.239,373.64,387.11,403.69
179.04638,2.5912,7.7597,0.0,0.0,1.6388,7.8554,373.54,387.01,403.69
179.0477,2.381,7.7589,0.0,0.0,1.6471,7.1745,373.43,386.9,403.7
179.04902,2.3639,7.7603,0.0,0.0,1.6411,7.253,373.33,386.81,403.71
179.05034,2.5747,7.7631,0.0,0.0,1.6457,7.8193,373.23,386.72,403.72
179.05166,2.3924,7.7585,0.0,0.0,1.6441,7.1754,373.13,386.63,403.73
179.05298,2.3662,7.7599,0.0,0.0,1.6414,7.2447,373.03,386.53,403.73
179.0543,2.5846,7.7629,0.0,0.0,1.6486,7.8797,372.93,386.44,403.74
179.05562,2.4083,7.7619,0.0,0.0,1.6415,7.2519,372.83,386.35,403.75
179.05694,2.3342,7.7534,0.0,0.0,1.6494,7.1827,372.73,386.26,403.76
179.05826,2.5724,7.7551,0.0,0.0,1.6443,7.8161,372.63,386.17,403.76
179.05958,2.4239,7.7565,0.0,0.0,1.6441,7.2908,372.52,386.07,403.75
179.0609,2.3442,7.7588,0.0,0.0,1.6469,7.1265,372.4,385.98,403.74
179.06222,2.5577,7.7569,0.0,0.0,1.6429,7.7976,372.29,385.88,403.72
179.06354,2.422,7.7571,0.0,0.0,1.6479,7.2639,372.18,385.78,403.71
179.06486,2.3136,7.7622,0.0,0.0,1.6422,7.0753,372.07,385.69,403.7
179.06618,2.5695,7.7636,0.0,0.0,1.6462,7.8592,371.96,385.59,403.69
179.0675,2.4501,7.7599,0.0,0.0,1.6442,7.3616,371.85,385.5,403.68
179.06882,2.3282,7.7573,0.0,0.0,1.6425,7.136,371.73,385.4,403.66
179.07014,2.555,7.7625,0.0,0.0,1.648,7.7755,371.61,385.29,403.65
179.07146,2.467,7.7625,0.0,0.0,1.64,7.4079,371.5,385.19,403.64
179.07278,2.3299,7.76,0.0,0.0,1.6491,7.0827,371.38,385.08,403.63
179.0741,2.5508,7.7605,0.0,0.0,1.6392,7.7859,371.27,384.98,403.62
179.07542,2.4788,7.7599,0.0,0.0,1.6477,7.4649,371.15,384.88,403.6
179.07674,2.3271,7.7612,0.0,0.0,1.6431,7.0522,371.03,384.77,403.59
179.07806,2.5538,7.7558,0.0,0.0,1.6454,7.8311,370.92,384.67,403.58
179.07938,2.5082,7.7527,0.0,0.0,1.6456,7.5357,370.83,384.57,403.6
179.0807,2.3187,7.7566,0.0,0.0,1.6423,7.0552,370.73,384.46,403.61
179.08202,2.5259,7.7582,0.0,0.0,1.6454,7.7018,370.63,384.36,403.62
179.08334,2.5148,7.7588,0.0,0.0,1.6424,7.5514,370.54,384.25,403.63
179.08466,2.3228,7.7562,0.0,0.0,1.642,7.0311,370.44,384.15,403.64
179.08598,2.5122,7.7626,0.0,0.0,1.6439,7.6986,370.35,384.05,403.66
179.0873,2.5358,7.7629,0.0,0.0,1.6388,7.6003,370.25,383.94,403.67
179.08862,2.3121,7.7608,0.0,0.0,1.6469,6.9991,370.16,383.84,403.67
179.08994,2.505,7.7585,0.0,0.0,1.6373,7.6748,370.08,383.75,403.65
179.09126,2.5547,7.7596,0.0,0.0,1.6477,7.6918,369.99,383.65,403.64
179.09258,2.3372,7.7641,0.0,0.0,1.638,7.0967,369.91,383.56,403.63
179.0939,2.4813,7.7592,0.0,0.0,1.6449,7.6011,369.82,383.46,403.62
179.09522,2.5527,7.7623,0.0,0.0,1.6439,7.6921,369.74,383.37,403.61
179.09654,2.3309,7.7574,0.0,0.0,1.6413,7.0777,369.66,383.27,403.59
179.09786,2.4837,7.7631,0.0,0.0,1.6462,7.6398,369.57,383.17,403.58
179.09918,2.5693,7.7547,0.0,0.0,1.6398,7.7189,369.49,383.09,403.57
179.1005,2.3248,7.7538,0.0,0.0,1.6459,7.0236,369.41,383.0,403.57
179.10182,2.472,7.7544,0.0,0.0,1.6415,7.5705,369.33,382.91,403.56
179.10314,2.5776,7.7609,0.0,0.0,1.6437,7.7446,369.25,382.82,403.55
179.10446,2.3452,7.76,0.0,0.0,1.645,7.0567,369.17,382.74,403.54
179.10578,2.4616,7.7585,0.0,0.0,1.6397,7.514,369.09,382.65,403.53
179.1071,2.5774,7.7622,0.0,0.0,1.6485,7.7728,369.01,382.56,403.53
179.10842,2.3547,7.7621,0.0,0.0,1.6384,7.1035,368.93,382.47,403.52
179.10974,2.4432,7.7624,0.0,0.0,1.6489,7.5135,368.85,382.37,403.52
179.11106,2.5926,7.7596,0.0,0.0,1.6418,7.8608,368.77,382.27,403.51
179.11238,2.3525,7.7587,0.0,0.0,1.6439,7.11,368.69,382.17,403.51
179.1137,2.427,7.7643,0.0,0.0,1.6454,7.4625,368.61,382.07,403.5
179.11502,2.6014,7.7628,0.0,0.0,1.6416,7.8631,368.53,381.97,403.5
179.11634,2.3805,7.7587,0.0,0.0,1.6487,7.1559,368.45,381.87,403.5
179.11766,2.4228,7.7587,0.0,0.0,1.6414,7.3966,368.37,381.77,403.49
179.11898,2.6026,7.7613,0.0,0.0,1.6485,7.867,368.29,381.67,403.48
179.1203,2.382,7.7575,0.0,0.0,1.6438,7.1645,368.21,381.58,403.46
179.12162,2.4018,7.7537,0.0,0.0,1.6482,7.4322,368.13,381.48,403.45
179.12294,2.6131,7.7539,0.0,0.0,1.648,7.9291,368.05,381.38,403.43
179.12426,2.3967,7.7592,0.0,0.0,1.6421,7.2395,367.97,381.29,403.41
179.12558,2.3797,7.7612,0.0,0.0,1.6479,7.3148,367.89,381.19,403.4
179.1269,2.5975,7.761,0.0,0.0,1.6427,7.8816,367.81,381.1,403.38
179.12822,2.4181,7.76,0.0,0.0,1.6464,7.2496,367.73,381.0,403.37
179.12954,2.3731,7.7626,0.0,0.0,1.6443,7.2624,367.64,380.91,403.36
179.13086,2.5953,7.7631,0.0,0.0,1.6425,7.8601,367.56,380.82,403.35
179.13218,2.4193,7.7609,0.0,0.0,1.6487,7.3085,367.47,380.73,403.35
179.1335,2.3662,7.7593,0.0,0.0,1.6388,7.2844,367.38,380.63,403.34
179.33443,2.4388,7.7616,0.0,0.0,1.6449,7.3959,359.88,371.65,400.09
180.13443,2.3229,7.7669,0.0,0.0,1.6475,7.0434,301.24,315.97,297.56
180.93443,2.2423,7.7736,0.0,0.0,1.6509,6.807,251.95,255.41,231.94
181.73443,2.197,7.7892,0.0,0.0,1.6585,6.664,159.88,111.09,190.62
182.53443,2.1774,7.8135,0.0,0.0,1.6707,6.6072,81.466,73.411,92.646
183.33443,2.1455,7.8323,0.0,0.0,1.6801,6.5084,58.735,56.89,46.983
184.13444,2.1359,7.8431,0.0,0.0,1.6856,6.4762,45.723,45.258,34.784
184.93444,2.1034,7.8486,0.0,0.0,1.6884,6.3839,37.646,39.001,29.305
185.73444,2.0931,7.8551,0.0,0.0,1.6918,6.3475,32.871,37.457,26.501
186.53444,2.085,7.8608,0.0,0.0,1.6948,6.3265,30.09,37.458,24.703
187.33444,2.0912,7.8661,0.0,0.0,1.6973,6.3402,27.345,28.395,23.263
188.0934,2.0985,7.8701,0.0,0.0,1.6995,6.3632,25.806,26.659,22.275
188.8934,2.0917,7.8738,0.0,0.0,1.7014,6.3459,24.147,25.32,21.232
189.6934,2.0853,7.8757,0.0,0.0,1.7024,6.3248,27.127,27.963,22.873
190.4934,2.0809,7.8776,0.0,0.0,1.7034,6.3132,29.645,37.439,25.579
191.2934,2.2862,7.8787,0.0,0.0,1.7039,6.9353,31.666,37.458,27.992
192.0934,2.0617,7.8799,0.0,0.0,1.7046,6.2559,33.205,37.458,29.931
192.8934,2.3099,7.8808,0.0,0.0,1.705,7.0075,34.456,37.458,31.524
193.6934,2.0677,7.8865,0.0,0.0,1.7079,6.272,35.377,37.458,32.867
194.4934,2.0423,7.8857,0.0,0.0,1.7076,6.1955,36.152,36.934,33.919
195.2934,2.1187,7.8859,0.0,0.0,1.7077,6.4265,36.745,37.501,34.211
196.0934,2.1101,7.8865,0.0,0.0,1.708,6.4017,37.15,37.931,35.39