File: examples/dan-msc-case-studies/CS4/data/01 raw data/hyde_test_012.csv
Time(sec),Force(kN),Jaw(mm),PowAngle(deg),PTemp,Strain,Stress(MPa),TC1(C),TC2(C),TC3(C),TC4(C)
0.0,3.8553,-10.451,0.0,0.0,-0.79985,4.5664,25.408,25.733,25.985,26.002
0.6,3.7935,0.0010739,0.0,1.6207,0.00017027,4.5016,25.343,25.777,25.905,25.889
1.2,3.7604,0.0031381,0.0,3.4207,0.00035957,4.4613,25.391,25.764,25.891,25.885
1.8,3.7388,0.0033619,0.0,5.2207,0.00035964,4.4363,25.409,25.755,25.916,25.805
2.4,3.7124,0.0033471,0.0,7.0207,0.00038396,4.4048,25.36,25.738,25.909,25.843
3.0,3.6913,0.0034971,0.0,8.8207,0.00036952,4.3806,25.3,25.741,25.898,25.839
3.6,3.6846,0.0035175,0.0,10.621,0.00040003,4.373,25.291,25.711,25.93,25.82
4.2,3.6695,0.0036431,0.0,12.421,0.00039107,4.3556,25.371,25.749,25.899,25.863
4.8,3.6554,0.0036816,0.0,14.221,0.00040925,4.339,25.289,25.712,25.876,25.823
5.3682,3.6538,0.0036444,0.0,15.93,0.00042818,4.3361,25.357,25.724,25.908,25.841
5.9682,3.6445,0.0037361,0.0,17.725,0.00039899,4.3259,25.339,25.764,25.866,25.768
6.5682,3.6427,0.0037921,0.0,19.525,0.00042257,4.3234,25.341,25.765,25.893,25.834
7.1682,3.6344,0.0040067,0.0,21.325,0.00042795,4.3146,25.29,25.722,25.906,25.829
7.7682,3.6264,0.0038393,0.0,23.125,0.0004317,4.3046,25.371,25.769,25.903,25.825
8.3682,3.6257,0.0040362,0.0,24.925,0.0004401,4.3032,25.306,25.708,25.908,25.816
8.9682,3.6225,0.0040452,14.798,26.725,0.00045572,4.2996,25.354,25.813,25.913,25.85
9.5682,3.6221,0.0047389,29.135,28.525,0.00050404,4.2996,25.471,25.918,25.873,25.822
10.1682,3.6295,0.0050886,35.252,30.325,0.00056796,4.3081,26.489,26.886,25.974,25.988
10.768,3.6324,0.0051924,37.754,32.125,0.0005647,4.3117,28.488,28.763,26.223,26.558
11.368,3.6346,0.0043199,38.555,33.925,0.00048542,4.3128,30.759,37.672,26.547,27.5
11.968,3.6301,0.0044015,39.237,35.725,0.00046658,4.3078,33.033,38.327,27.023,28.776
12.568,3.6329,0.0041571,39.589,37.525,0.00046365,4.3104,35.281,38.327,27.581,30.172
13.168,3.6352,0.0039027,39.743,39.325,0.00041804,4.3133,37.525,38.196,28.306,31.857
13.768,3.6323,0.0037093,39.873,41.125,0.00041671,4.3099,39.674,39.43,29.103,33.511
14.368,3.6407,0.0034718,39.562,42.925,0.00036391,4.3191,41.894,41.509,29.933,35.29
14.968,3.6354,0.0025716,39.358,44.725,0.00029544,4.3131,43.933,43.418,30.902,37.115
15.568,3.6467,0.0027798,39.252,46.525,0.00028041,4.3264,45.944,45.32,31.972,38.939
16.168,3.6435,0.0025295,39.274,48.325,0.00028728,4.3228,47.883,47.18,33.045,40.762
16.768,3.6379,0.0022622,39.288,50.125,0.00023844,4.3168,49.785,49.048,34.19,42.61
17.368,3.6309,0.0021288,39.235,51.925,0.00023831,4.3084,51.695,50.981,35.448,44.454
17.968,3.6459,0.0018493,39.243,53.725,0.00018088,4.3272,53.553,52.872,36.682,46.245
18.568,3.6421,0.00074336,39.197,55.525,9.2982e-05,4.3216,55.446,54.733,38.053,48.145
19.168,3.6406,0.00074552,39.186,57.325,6.5091e-05,4.3209,57.239,56.564,39.453,49.963
19.768,3.6423,0.00037057,39.413,59.125,4.1588e-05,4.3235,58.976,58.366,40.825,51.827
20.368,3.633,0.00016998,39.283,60.925,-6.8753e-06,4.3121,60.851,60.144,42.291,53.64
20.968,3.6425,-5.2751e-05,39.597,62.725,3.8007e-06,4.3247,62.603,61.916,43.735,55.529
21.568,3.6453,-0.00022626,39.478,64.525,-4.1914e-05,4.3268,64.422,63.772,45.183,57.359
22.168,3.6448,-0.0020231,39.631,66.325,-0.00021558,4.3264,66.237,65.499,46.692,59.262
22.768,3.6424,-0.0019968,39.794,68.125,-0.00024278,4.3236,68.038,67.406,48.201,61.144
23.368,3.6412,-0.0023668,39.923,69.925,-0.0002581,4.3213,69.815,69.193,49.795,63.099
23.968,3.6477,-0.0025052,39.924,71.725,-0.00029906,4.33,71.654,71.053,51.35,65.069
24.568,3.6478,-0.0027984,40.02,73.525,-0.00031119,4.3291,73.405,72.892,52.964,66.967
25.168,3.6517,-0.002757,40.175,75.325,-0.00032859,4.333,75.202,74.71,54.61,68.972
25.768,3.6539,-0.0048171,40.163,77.125,-0.00054125,4.336,77.024,76.631,56.295,71.005
26.368,3.6531,-0.0043754,40.425,78.925,-0.00051093,4.3341,78.809,78.4,57.968,73.039
26.968,3.6533,-0.0052975,40.489,80.725,-0.0005865,4.3349,80.629,80.269,59.692,75.057
27.568,3.6546,-0.0056428,40.3,82.525,-0.00064822,4.3362,82.477,82.134,61.492,77.21
28.168,3.665,-0.0061015,40.572,84.325,-0.00067356,4.3472,84.197,83.909,63.225,79.213
28.768,3.664,-0.0061009,40.825,86.125,-0.00069165,4.3476,85.947,85.858,64.965,81.266
29.368,3.6754,-0.0080196,40.699,87.925,-0.00089886,4.3604,87.795,87.766,66.687,83.328
29.968,3.6749,-0.0078079,40.924,89.725,-0.00089026,4.3597,89.581,89.652,68.471,85.357
30.568,3.68,-0.0086644,40.909,91.525,-0.00095707,4.3664,91.409,91.497,70.29,87.446
31.168,3.685,-0.0092373,41.053,93.325,-0.0010443,4.372,93.247,93.547,72.085,89.478
31.768,3.6903,-0.009524,41.066,95.125,-0.0010468,4.3799,95.101,95.423,73.981,91.665
32.368,3.6937,-0.0098565,41.191,96.925,-0.001111,4.3829,96.888,97.239,75.836,93.73
32.968,3.6925,-0.01225,41.27,98.725,-0.0013495,4.3825,98.592,99.096,77.764,95.844
33.568,3.6975,-0.012116,41.2,100.52,-0.0013554,4.3887,100.43,101.13,79.744,97.982
34.168,3.7005,-0.012351,41.36,102.32,-0.0013622,4.3935,102.21,102.98,81.697,100.03
34.768,3.7036,-0.013076,41.732,104.12,-0.0014533,4.3964,103.96,104.83,83.743,102.1
35.368,3.7012,-0.01344,41.77,105.92,-0.0014825,4.3937,105.77,106.68,85.76,104.17
35.968,3.7166,-0.014158,41.742,107.72,-0.0015867,4.411,107.57,108.59,87.763,106.29
36.568,3.7154,-0.015399,41.688,109.52,-0.0016875,4.4098,109.44,110.43,89.743,108.38
37.168,3.718,-0.016282,41.668,111.32,-0.001812,4.4128,111.3,112.23,91.852,110.45
37.768,3.7244,-0.016941,41.823,113.12,-0.001864,4.4197,113.03,114.09,93.849,112.52
38.2948,3.7357,-0.017434,41.814,114.71,-0.0019365,4.435,114.62,115.74,95.656,114.31
38.8948,3.7352,-0.017691,41.883,116.51,-0.0019922,4.4336,116.41,117.55,97.736,116.36
39.4948,3.7445,-0.018856,42.144,118.31,-0.0020995,4.4447,118.21,119.35,99.755,118.37
40.0948,3.747,-0.019708,42.388,120.11,-0.0021919,4.4475,119.95,121.23,101.72,120.4
40.6948,3.7483,-0.020976,42.267,121.91,-0.0023154,4.4491,121.87,123.08,103.67,122.4
41.2948,3.7528,-0.021731,42.135,123.71,-0.0024221,4.4541,123.72,124.91,105.5,124.48
41.8948,3.7525,-0.022182,42.204,125.51,-0.0024556,4.4537,125.5,126.69,107.47,126.49
42.4948,3.7497,-0.022621,42.396,127.31,-0.0025181,4.45,127.23,128.44,109.39,128.51
43.0948,3.7625,-0.024584,42.473,129.11,-0.0027457,4.4644,129.02,130.24,111.34,130.54
43.5108,3.7603,-0.025219,42.401,130.35,-0.0027873,4.4612,130.25,131.57,112.7,131.82
44.1108,3.7534,-0.025906,42.398,132.15,-0.0029112,4.4538,132.11,133.39,114.58,133.87
44.7108,3.7622,-0.026996,42.491,133.95,-0.0030068,4.4631,133.88,135.21,116.5,135.87
45.3108,3.7652,-0.027399,42.66,135.75,-0.0030842,4.467,135.65,136.99,118.39,137.89
45.9108,3.7728,-0.027938,42.57,137.55,-0.0031132,4.4768,137.49,138.87,120.37,139.85
46.5108,3.7787,-0.030218,42.775,139.35,-0.0034093,4.4838,139.31,140.71,122.34,141.8
47.1108,3.7804,-0.030382,42.974,141.15,-0.0033961,4.4852,141.02,142.46,124.33,143.81
47.7108,3.7778,-0.031638,42.949,142.95,-0.0035537,4.4832,142.87,144.43,126.28,145.74
48.3108,3.7841,-0.032382,42.934,144.75,-0.0035965,4.4917,144.65,146.23,128.27,147.77
48.9108,3.7907,-0.032723,42.729,146.55,-0.0036601,4.499,146.55,148.11,130.25,149.7
49.5108,3.7935,-0.033613,42.971,148.35,-0.0037424,4.5031,148.26,149.95,132.23,151.68
50.1108,3.7847,-0.035015,42.983,150.15,-0.0038959,4.4913,150.12,151.85,134.15,153.58
50.7108,3.7847,-0.036315,43.157,151.95,-0.0040323,4.4927,151.82,153.74,136.07,155.5
51.3108,3.7852,-0.037201,43.031,153.75,-0.0041452,4.4927,153.64,155.47,137.99,157.41
51.9108,3.7864,-0.037763,43.415,155.55,-0.0041878,4.4944,155.39,157.26,139.91,159.34
52.5108,3.7883,-0.038434,43.201,157.35,-0.0042636,4.498,157.31,159.32,141.85,161.32
53.1108,3.7854,-0.040572,43.452,159.15,-0.0044938,4.4933,159.05,161.15,143.79,163.27
53.7108,3.7823,-0.041701,43.576,160.95,-0.0046108,4.4894,160.81,163.0,145.71,165.22
54.3108,3.784,-0.042553,43.421,162.75,-0.0047553,4.4912,162.71,164.94,147.67,167.29
54.9108,3.7832,-0.043197,43.645,164.55,-0.0047795,4.4907,164.43,166.76,149.63,169.26
55.5108,3.78,-0.043365,44.026,166.35,-0.0048533,4.4858,166.13,168.6,151.44,171.21
56.1108,3.7813,-0.046567,43.635,168.15,-0.0051336,4.4862,168.1,170.53,153.48,173.22
56.7108,3.7858,-0.046909,43.848,169.95,-0.005245,4.4916,169.84,172.32,155.34,175.11
57.3108,3.7847,-0.048184,44.071,171.75,-0.0053457,4.4894,171.62,174.24,157.29,177.02
57.9108,3.7923,-0.04889,44.077,173.55,-0.0054601,4.4995,173.44,176.01,159.25,178.88
58.5108,3.7893,-0.049282,44.077,175.35,-0.0054751,4.4956,175.23,177.87,161.23,180.82
59.1108,3.7929,-0.052524,44.193,177.15,-0.005878,4.5004,177.02,179.73,163.11,182.72
59.7108,3.7971,-0.052306,44.279,178.95,-0.0058363,4.5052,178.85,181.61,165.01,184.67
60.3108,3.7903,-0.053754,44.184,180.75,-0.006,4.4977,180.66,183.37,166.95,186.64
60.9108,3.7916,-0.054758,44.254,182.55,-0.0060915,4.5001,182.46,185.27,168.85,188.55
61.5108,3.7924,-0.055208,44.57,184.35,-0.0061516,4.5002,184.25,187.07,170.81,190.52
62.1108,3.8035,-0.055807,44.583,186.15,-0.0062107,4.5145,186.03,188.83,172.73,192.43
62.7108,3.7947,-0.059347,44.547,187.95,-0.0065965,4.5038,187.9,190.68,174.7,194.39
63.3108,3.7947,-0.05973,44.456,189.75,-0.0066306,4.5044,189.72,192.55,176.73,196.35
63.9108,3.7976,-0.060692,44.592,191.55,-0.0067469,4.5086,191.42,194.27,178.71,198.27
64.5108,3.7938,-0.061593,44.849,193.35,-0.0068481,4.5029,193.21,196.18,180.66,200.17
65.1108,3.799,-0.062463,44.735,195.15,-0.006919,4.5092,195.08,198.01,182.55,202.13
65.7108,3.7914,-0.062808,44.595,196.95,-0.0069915,4.5008,196.99,199.93,184.5,204.18
66.3108,3.7919,-0.066964,44.489,198.75,-0.0074085,4.5008,198.82,201.81,186.44,206.14
66.9108,3.7892,-0.066431,44.604,200.55,-0.007423,4.4977,200.55,203.6,188.39,208.03
67.5108,3.7859,-0.067883,44.56,202.35,-0.0075073,4.494,202.37,205.53,190.28,209.93
68.1108,3.7874,-0.068747,44.636,204.15,-0.0076692,4.4951,204.15,207.34,192.23,211.94
68.7108,3.7865,-0.069554,44.608,205.95,-0.0077065,4.4944,205.93,209.26,194.05,213.84
69.3108,3.7919,-0.069872,44.563,207.75,-0.0077998,4.5,207.8,211.06,195.97,215.83
69.9108,3.7514,-0.073841,44.528,209.55,-0.0082019,4.4509,209.61,212.82,197.85,217.78
70.5108,3.6338,-0.074314,44.598,211.36,-0.0082598,4.3121,211.36,214.74,199.71,219.71
70.9298,3.5701,-0.075606,44.619,212.61,-0.008395,4.2368,212.66,216.0,201.0,221.13
71.5298,3.4965,-0.077044,44.712,214.41,-0.0085893,4.1487,214.33,217.92,202.89,223.08
72.1298,3.4418,-0.078148,44.786,216.21,-0.0086981,4.0837,216.17,219.85,204.79,225.0
72.7298,3.3938,-0.078824,44.725,218.01,-0.0087758,4.0274,217.99,221.73,206.75,227.03
73.3298,3.3582,-0.082915,44.822,219.81,-0.0091974,3.9847,219.81,223.63,208.72,228.97
73.9298,3.3245,-0.082889,45.166,221.61,-0.009211,3.9451,221.5,225.42,210.68,230.96
74.5298,3.2799,-0.084443,45.174,223.41,-0.009371,3.8929,223.36,227.31,212.62,232.99
75.1298,3.2177,-0.085829,45.318,225.21,-0.0095307,3.82,225.09,229.16,214.58,234.85
75.7298,3.1507,-0.08667,45.332,227.01,-0.0096061,3.7401,226.89,231.01,216.52,236.87
76.3298,3.0946,-0.087915,45.448,228.81,-0.0097561,3.6735,228.65,232.82,218.49,238.79
76.9298,3.0415,-0.091747,45.538,230.61,-0.01017,3.6099,230.44,234.77,220.48,240.74
77.5298,2.9896,-0.092663,45.522,232.41,-0.010251,3.5486,232.3,236.73,222.47,242.75
78.1298,2.934,-0.0939,45.615,234.21,-0.010454,3.4836,234.1,238.57,224.43,244.81
78.7298,2.8798,-0.095539,45.615,236.01,-0.010571,3.4183,235.87,240.44,226.36,246.82
79.3298,2.7879,-0.096329,45.689,237.81,-0.01072,3.309,237.69,242.37,228.4,248.86
79.9298,2.6969,-0.097711,45.795,239.61,-0.010848,3.2026,239.51,244.4,230.38,250.93
80.5298,2.6167,-0.1023,45.655,241.41,-0.011372,3.1055,241.35,246.28,232.36,253.02
81.1298,2.5537,-0.10267,45.636,243.21,-0.011407,3.0303,243.24,248.18,234.46,255.12
81.7298,2.4996,-0.10414,45.619,245.01,-0.011575,2.9668,245.08,250.15,236.47,257.11
82.3298,2.4541,-0.10575,45.616,246.81,-0.011713,2.9118,246.84,251.91,238.41,259.09
82.9298,2.417,-0.10683,45.34,248.61,-0.01185,2.8684,248.78,253.77,240.53,261.1
83.5298,2.3864,-0.10728,45.544,250.41,-0.011891,2.8312,250.52,255.57,242.51,262.96
84.1298,2.3666,-0.11079,45.803,252.21,-0.012291,2.8076,252.19,257.57,244.41,264.8
84.7298,2.3365,-0.11193,45.628,254.01,-0.012397,2.771,254.0,259.35,246.31,266.78
85.3298,2.3218,-0.11412,45.771,255.81,-0.012619,2.755,255.77,261.19,248.27,268.66
85.9298,2.3089,-0.11567,45.641,257.61,-0.012862,2.7399,257.61,263.02,250.26,270.65
86.5298,2.2979,-0.11763,45.816,259.41,-0.013014,2.7272,259.39,265.01,252.17,272.59
87.1298,2.2922,-0.11878,45.831,261.21,-0.013204,2.7195,261.2,266.84,254.25,274.59
87.7298,2.2867,-0.11933,45.771,263.01,-0.013214,2.7137,262.99,268.81,256.13,276.57
88.3298,2.2766,-0.12346,45.772,264.81,-0.013729,2.7013,264.8,270.89,258.09,278.55
88.9298,2.2703,-0.12413,45.655,266.61,-0.013744,2.6944,266.66,272.83,260.08,280.57
89.5298,2.2636,-0.1267,45.723,268.41,-0.01406,2.6871,268.42,274.91,262.07,282.63
90.1298,2.2614,-0.12814,46.004,270.21,-0.014199,2.6858,270.18,276.97,264.06,284.66
90.7298,2.2563,-0.12988,45.732,272.01,-0.0144,2.6782,272.06,279.05,266.09,286.76
91.3298,2.2543,-0.13077,45.914,273.81,-0.014479,2.6776,273.78,281.09,268.05,288.8
91.9298,2.2546,-0.1316,46.11,275.61,-0.014561,2.6778,275.49,283.24,270.11,290.82
92.5298,2.2542,-0.13531,46.11,277.41,-0.015036,2.6762,277.38,285.39,272.22,292.88
93.1298,2.2467,-0.13615,45.733,279.21,-0.015029,2.6671,279.29,287.68,274.25,294.97
93.7298,2.2445,-0.13866,46.019,281.01,-0.015388,2.6648,281.06,289.74,276.35,297.1
94.3298,2.2436,-0.14043,46.028,282.81,-0.015542,2.6639,282.84,291.88,278.36,299.26
94.9298,2.2442,-0.14176,45.909,284.61,-0.015728,2.6649,284.68,294.03,280.47,301.34
95.5298,2.2458,-0.14314,45.755,286.41,-0.015846,2.6656,286.51,296.16,282.55,303.48
96.1298,2.244,-0.14383,45.638,288.21,-0.015937,2.6634,288.33,298.07,284.6,305.46
96.7298,2.2421,-0.14711,45.615,290.01,-0.01631,2.6605,290.16,299.93,286.73,307.52
97.3298,2.2473,-0.14937,45.682,291.81,-0.016516,2.6665,291.86,301.83,288.86,309.47
97.9298,2.2426,-0.1509,45.624,293.61,-0.016698,2.6598,293.72,303.65,290.91,311.36
98.5298,2.2404,-0.15263,45.617,295.41,-0.016868,2.658,295.49,305.6,293.11,313.23
99.1298,2.2481,-0.15408,45.66,297.21,-0.017074,2.6673,297.28,307.52,295.34,315.15
99.7298,2.2508,-0.15579,45.621,299.01,-0.017207,2.6717,299.1,309.5,297.54,317.05
100.3298,2.2531,-0.15631,45.821,300.81,-0.017333,2.6736,300.81,311.5,299.81,318.86
100.9298,2.2519,-0.15735,45.997,302.61,-0.017407,2.6722,302.61,313.55,302.07,320.65
101.5298,2.2526,-0.16233,45.776,304.41,-0.017995,2.6732,304.41,315.55,304.46,322.53
102.1298,2.2511,-0.16247,45.674,306.21,-0.017947,2.671,306.26,317.43,306.85,324.45
102.7298,2.2441,-0.16505,45.716,308.01,-0.018285,2.664,308.09,318.97,309.33,326.3
103.1518,2.2442,-0.16618,45.669,309.28,-0.018375,2.665,309.33,320.29,311.08,327.64
103.7518,2.2437,-0.16788,45.742,311.08,-0.018578,2.6641,311.17,322.08,313.47,329.47
104.3518,2.2457,-0.16931,45.752,312.88,-0.018714,2.6662,312.95,323.9,315.72,331.28
104.9518,2.2481,-0.17088,45.523,314.68,-0.018887,2.6685,314.82,325.73,318.03,333.17
105.5518,2.2481,-0.17181,45.63,316.48,-0.019013,2.669,316.53,327.5,320.79,334.97
106.1518,2.2453,-0.17271,45.748,318.28,-0.019069,2.6656,318.31,329.34,322.82,336.83
106.7518,2.249,-0.17561,45.616,320.08,-0.01948,2.6695,320.12,331.19,326.0,338.66
107.3518,2.2455,-0.17997,45.527,321.88,-0.019877,2.6646,322.04,333.36,329.27,340.66
107.9518,2.2451,-0.17813,45.574,323.68,-0.019723,2.6637,323.74,335.18,331.57,342.47
108.5518,2.2446,-0.1816,45.915,325.48,-0.020069,2.6631,325.41,337.06,334.35,344.37
109.1518,2.2456,-0.18331,46.085,327.28,-0.020285,2.6644,327.12,339.13,336.98,346.27
109.7518,2.2468,-0.18505,46.136,329.08,-0.020442,2.6648,328.93,341.36,339.57,348.22
110.3518,2.2485,-0.18676,45.799,330.88,-0.020635,2.6686,330.95,343.55,341.92,350.24
110.9518,2.2534,-0.18763,46.009,332.68,-0.020731,2.6737,332.64,345.61,344.09,352.28
111.5518,2.253,-0.18828,45.768,334.48,-0.020775,2.6734,334.52,347.68,346.41,354.28
112.1518,2.2576,-0.19097,45.776,336.28,-0.021163,2.6783,336.39,349.49,348.31,356.31
112.7518,2.2572,-0.19522,45.585,338.08,-0.021537,2.6779,338.26,351.17,349.88,358.27
113.3518,2.2511,-0.19389,45.49,339.88,-0.021469,2.6716,340.03,353.03,351.22,360.19
113.9518,2.2512,-0.19702,46.014,341.68,-0.02176,2.6723,341.57,354.96,352.84,362.07
114.5518,2.2518,-0.19887,46.109,343.48,-0.021975,2.674,343.31,357.28,353.83,363.96
115.1518,2.2532,-0.20026,46.167,345.28,-0.022109,2.675,345.12,359.74,355.31,365.97
115.7518,2.2541,-0.20179,46.292,347.08,-0.022269,2.6766,346.93,362.03,356.56,368.08
116.3518,2.2509,-0.20241,46.027,348.88,-0.022366,2.672,348.88,363.97,358.11,370.18
116.9518,2.2548,-0.20401,44.55,350.0,-0.022511,2.6779,350.69,365.79,359.75,372.33
117.5518,2.246,-0.20756,41.344,350.0,-0.022944,2.6663,351.81,366.92,361.27,374.13
118.1518,2.2319,-0.20506,39.588,350.0,-0.022647,2.651,352.01,367.1,362.39,374.98
118.7518,2.2351,-0.20631,38.868,350.0,-0.022795,2.6544,351.77,366.72,362.73,374.95
119.3518,2.2388,-0.20672,38.929,350.0,-0.022819,2.6577,351.39,366.32,362.76,374.26
119.9518,2.2391,-0.20722,39.274,350.0,-0.022877,2.6584,350.96,366.06,362.57,373.52
120.5518,2.2411,-0.20765,39.849,350.0,-0.022912,2.6605,350.62,365.84,362.22,372.82
121.1518,2.251,-0.20807,40.153,350.0,-0.022951,2.6709,350.38,365.85,361.74,372.23
121.7518,2.2478,-0.20801,40.45,350.0,-0.022982,2.6681,350.24,365.98,361.3,371.8
122.3518,2.2488,-0.20978,40.363,350.0,-0.023154,2.668,350.21,366.18,360.96,371.59
122.9518,2.253,-0.21268,40.569,350.0,-0.023502,2.6725,350.11,366.45,360.63,371.47
123.5518,2.2505,-0.21086,40.518,350.0,-0.023288,2.6694,350.04,366.61,360.34,371.32
124.1518,2.2505,-0.21305,40.469,350.0,-0.023536,2.6699,350.04,366.88,360.19,371.27
124.7518,2.2558,-0.21379,40.576,350.0,-0.023588,2.6749,350.02,367.24,360.07,371.23
125.3518,2.2557,-0.2146,40.425,350.0,-0.023684,2.6765,350.08,367.53,359.99,371.11
125.9518,2.2571,-0.215,40.422,350.0,-0.02375,2.6778,350.1,367.84,359.9,371.21
126.5518,2.2548,-0.2158,40.373,350.0,-0.023788,2.6752,350.09,368.12,359.83,371.22
127.1518,2.257,-0.216,39.967,350.0,-0.023868,2.6775,350.16,368.35,359.77,371.16
127.7518,2.2591,-0.21638,40.256,350.0,-0.023875,2.6811,350.09,368.63,359.72,371.07
128.3518,2.2548,-0.2166,39.926,350.0,-0.02393,2.6766,350.14,368.9,359.68,371.1
128.9518,2.2271,-0.21826,39.924,350.0,-0.024105,2.6432,350.09,369.1,359.59,371.08
129.5518,2.0462,-0.22261,39.925,350.0,-0.024567,2.4291,350.13,369.51,359.5,370.97
130.1518,1.8323,-0.22389,39.258,350.0,-0.024667,2.1759,350.31,369.81,359.49,370.97
130.7518,1.652,-0.22577,38.555,350.0,-0.024888,1.9614,350.53,370.1,359.46,370.98
131.3518,1.5195,-0.22833,37.629,350.0,-0.025213,1.8054,350.62,370.03,359.25,370.65
131.9518,1.4776,-0.22962,37.607,350.0,-0.025315,1.7548,350.51,370.03,358.92,370.17
132.5518,1.4576,-0.23035,37.991,350.0,-0.025434,1.7309,350.28,370.01,358.43,369.56
133.1518,1.4167,-0.23159,38.535,350.0,-0.025536,1.6819,350.1,370.07,358.03,369.02
133.7518,1.3785,-0.23292,38.861,350.0,-0.025691,1.6364,349.95,370.55,357.67,368.57
134.3518,1.3567,-0.23374,38.766,350.0,-0.025768,1.6103,350.01,371.0,357.27,368.26
134.9518,1.3425,-0.23458,38.91,350.0,-0.025835,1.5936,349.94,371.55,356.82,368.05
135.5518,1.3282,-0.23499,39.057,350.0,-0.025938,1.577,349.93,372.05,356.5,367.87
136.0858,1.3333,-0.23537,39.185,350.0,-0.025972,1.5836,349.93,372.57,356.37,367.78
136.6858,1.3316,-0.23601,39.243,350.0,-0.025987,1.5811,349.88,373.07,356.18,367.63
137.2858,1.3418,-0.23638,39.531,350.0,-0.02609,1.5933,349.82,373.76,355.97,367.58
137.8858,1.3363,-0.23717,39.486,350.0,-0.026161,1.5871,349.84,374.44,355.81,367.59
138.4858,1.3432,-0.23863,39.743,350.0,-0.026337,1.5938,349.85,375.13,355.75,367.6
139.0858,1.3457,-0.24035,39.923,350.0,-0.026493,1.5973,349.86,375.85,355.66,367.62
139.6858,1.3484,-0.2418,39.997,350.0,-0.026634,1.6005,349.81,376.75,355.58,367.76
140.2858,1.3504,-0.24227,40.078,350.0,-0.026717,1.6019,349.73,377.63,355.51,367.84
140.8858,1.3477,-0.24261,40.34,350.0,-0.026699,1.5985,349.79,378.61,355.5,367.96
141.4858,1.3473,-0.24267,39.875,350.0,-0.026752,1.5983,349.83,379.66,355.51,368.18
142.0858,1.3493,-0.24234,37.217,350.0,-0.026706,1.5999,349.51,379.57,355.53,368.33
142.5313,1.3561,-0.24266,38.173,350.0,-0.026727,1.6091,349.06,379.28,355.52,368.19
143.1313,1.3522,-0.24291,37.575,350.0,-0.026782,1.6055,348.63,379.32,355.2,367.82
143.7313,1.3484,-0.24349,35.576,350.0,-0.026814,1.6011,348.08,378.85,354.89,367.41
144.3313,1.3258,-0.2433,25.004,350.0,-0.02682,1.5742,346.76,375.51,354.38,366.68
144.9313,1.3313,-0.24392,32.519,350.0,-0.026881,1.5804,344.56,372.24,353.39,365.06
145.5313,1.3474,-0.24519,35.45,350.0,-0.02699,1.6004,343.65,372.25,352.14,363.26
146.1313,1.3509,-0.24582,36.795,350.0,-0.027126,1.6045,343.35,373.04,351.05,361.91
146.7313,1.3602,-0.24664,42.153,350.0,-0.0272,1.6148,343.82,376.17,350.19,361.09
147.3313,1.3573,-0.24668,40.122,350.0,-0.027221,1.6121,344.96,379.21,349.85,361.15
147.9313,1.355,-0.24679,39.378,350.0,-0.027191,1.6091,345.28,380.63,349.82,361.73
148.5313,1.3521,-0.24746,37.823,350.0,-0.027257,1.6051,345.21,380.96,349.75,362.13
149.1313,1.3484,-0.2483,38.694,350.0,-0.027377,1.6005,344.92,381.51,349.72,362.29
149.7313,1.3542,-0.24919,39.144,350.0,-0.027427,1.6077,344.82,382.57,349.65,362.47
150.3313,1.3543,-0.24994,38.549,350.0,-0.027563,1.6074,344.71,383.4,349.54,362.61
150.9313,1.3494,-0.25096,39.072,350.0,-0.027647,1.602,344.65,384.43,349.56,362.74
151.5313,1.3551,-0.25169,39.243,350.0,-0.027751,1.6089,344.61,385.66,349.58,362.98
152.1313,1.3542,-0.2526,39.243,350.0,-0.027824,1.6063,344.62,386.91,349.63,363.32
152.7313,1.3569,-0.25344,39.287,350.0,-0.027897,1.6098,344.64,388.13,349.75,363.64
153.3313,1.3602,-0.254,39.249,350.0,-0.028013,1.6133,344.66,389.42,349.88,364.1
153.9313,1.36,-0.2549,39.243,350.0,-0.028075,1.614,344.73,390.68,350.09,364.53
154.5313,1.36,-0.25571,39.24,350.0,-0.028199,1.6139,344.77,391.97,350.3,365.05
155.1313,1.357,-0.25575,38.856,350.0,-0.028148,1.6103,344.87,393.09,350.56,365.53
155.7313,1.3609,-0.25828,38.774,350.0,-0.02844,1.615,344.91,394.13,350.83,365.99
156.3313,1.3581,-0.25713,38.564,350.0,-0.028355,1.6121,344.91,395.07,351.15,366.47
156.9313,1.3562,-0.25723,38.43,350.0,-0.028307,1.6101,344.96,396.11,351.36,366.92
157.5313,1.3629,-0.25817,38.069,350.0,-0.028452,1.6195,345.01,396.91,351.72,367.3
158.1313,1.3591,-0.25937,37.9,350.0,-0.028563,1.6133,345.02,397.52,351.97,367.67
158.7313,1.3592,-0.26027,37.607,350.0,-0.028672,1.614,345.06,398.14,352.21,368.03
159.3313,1.3523,-0.26099,37.411,350.0,-0.028749,1.6061,345.06,398.81,352.56,368.3
159.9313,1.3559,-0.26178,36.943,350.0,-0.028804,1.6103,345.11,399.08,352.8,368.56
160.5313,1.3501,-0.26204,37.09,350.0,-0.028886,1.6029,345.02,399.46,352.99,368.86
161.1313,1.3527,-0.26227,36.886,350.0,-0.028871,1.6064,345.06,399.84,353.16,368.98
161.7313,1.3535,-0.14002,36.347,350.0,-0.015427,1.6063,345.1,399.99,353.31,369.11
161.9478,1.3614,0.035854,0.0,38.288,0.0041462,1.6123,345.04,400.16,353.33,369.2
161.9508,1.3572,0.034561,0.0,0.0031048,0.0039531,1.611,345.06,400.13,353.32,369.18
161.9538,1.3651,0.036591,0.0,2.5176e-07,0.0037511,1.6221,345.08,400.09,353.31,369.15
161.9568,1.3277,0.035925,0.0,2.0414e-11,0.0036121,1.5829,345.08,400.1,353.34,369.15
161.9598,1.3728,0.034077,0.0,1.6553e-15,0.0037697,1.6252,345.08,400.11,353.36,369.15
161.9628,1.3287,0.031399,0.0,1.3422e-19,0.0039022,1.5777,345.08,400.12,353.39,369.15
161.9658,1.3673,0.033006,0.0,1.0882999999999999e-23,0.0040929,1.619,345.07,400.12,353.4,369.16
161.9688,1.3328,0.03473,0.0,8.825e-28,0.0040105,1.5821,345.05,400.12,353.4,369.18
161.9718,1.3701,0.036422,0.0,7.1558e-32,0.0039432,1.6266,345.03,400.12,353.4,369.2
161.9748,1.3313,0.035343,0.0,5.8024e-36,0.0041018,1.5809,345.03,400.11,353.4,369.21
161.9778,1.3677,0.034903,0.0,4.7049e-40,0.003929,1.6254,345.07,400.07,353.39,369.21
161.9808,1.3352,0.034806,0.0,3.7835e-44,0.0035075,1.5826,345.11,400.04,353.38,369.21
161.9838,1.3695,0.034969,0.0,0.0,0.003515,1.6238,345.14,400.0,353.37,369.21
161.9868,1.3372,0.033346,0.0,0.0,0.0038149,1.5765,345.16,400.0,353.38,369.19
161.9898,1.3545,0.032621,0.0,0.0,0.0040056,1.6146,345.18,400.0,353.39,369.17
161.9928,1.3281,0.033442,0.0,0.0,0.0041032,1.5755,345.2,400.0,353.4,369.16
161.9958,1.3528,0.035314,0.0,0.0,0.0039233,1.6026,345.18,399.88,353.59,369.14
161.9988,1.3323,0.035795,0.0,0.0,0.0038997,1.5805,345.14,399.72,353.87,369.12
162.0018,1.3535,0.036183,0.0,0.0,0.0040765,1.6056,345.1,399.56,354.14,369.1
162.0048,1.337,0.035804,0.0,0.0,0.0040028,1.5886,345.11,399.28,354.41,369.11
162.0078,1.348,0.036064,0.0,0.0,0.0037154,1.6038,345.18,398.81,354.66,369.17
162.0108,3.2538,0.059233,0.0,0.0,0.0061499,3.7094,345.25,398.34,354.92,369.22
162.0138,20.024,0.15699,0.0,0.0,0.018016,23.387,345.35,397.99,355.17,369.27
162.0168,41.319,0.26664,0.0,0.0,0.030231,48.514,345.75,399.69,355.43,369.23
162.0198,60.073,0.32659,0.0,0.0,0.03731,70.974,346.15,401.38,355.68,369.2
162.0228,70.521,0.378,0.0,0.0,0.042712,83.464,346.55,403.07,355.94,369.16
162.0258,80.586,0.54135,0.0,0.0,0.061315,95.432,347.89,405.23,356.17,369.13
162.0288,88.985,0.82113,0.0,0.0,0.094925,105.45,349.57,407.57,356.38,369.1
162.0318,92.574,1.1619,0.0,0.0,0.13679,109.79,351.25,409.9,356.6,369.08
162.0348,94.413,1.4945,0.0,0.0,0.17904,112.01,352.96,411.52,356.7,369.06
162.0378,95.147,1.807,0.0,0.0,0.22112,112.9,354.71,412.08,356.62,369.06
162.0408,95.509,2.0782,0.0,0.0,0.25925,113.33,356.46,412.64,356.54,369.06
162.0438,95.279,2.3125,0.0,0.0,0.29321,113.07,358.12,413.19,356.45,369.05
162.0468,95.171,2.5181,0.0,0.0,0.3231,112.94,358.84,413.65,356.3,368.97
162.0498,95.05,2.7071,0.0,0.0,0.35104,112.8,359.56,414.11,356.16,368.89
162.0528,95.305,2.8862,0.0,0.0,0.37891,113.09,360.28,414.57,356.01,368.81
162.0558,95.682,3.066,0.0,0.0,0.4076,113.53,360.95,415.07,355.9,368.77
162.0588,96.278,3.2536,0.0,0.0,0.43753,114.23,361.59,415.59,355.8,368.76
162.0618,96.75,3.4428,0.0,0.0,0.46865,114.8,362.24,416.1,355.7,368.74
162.0648,97.222,3.6313,0.0,0.0,0.50142,115.37,362.83,416.59,355.74,368.74
162.0678,97.52,3.8158,0.0,0.0,0.53485,115.72,363.35,417.04,355.98,368.78
162.0708,97.775,3.9943,0.0,0.0,0.56794,116.02,363.87,417.49,356.22,368.82
162.0738,97.865,4.165,0.0,0.0,0.59954,116.13,364.38,417.93,356.46,368.86
162.0768,97.963,4.3327,0.0,0.0,0.63125,116.25,364.81,418.27,356.78,368.93
162.0798,98.051,4.49,0.0,0.0,0.66273,116.35,365.24,418.6,357.1,369.0
162.0828,98.236,4.6432,0.0,0.0,0.69442,116.57,365.67,418.94,357.42,369.07
162.0858,98.336,4.7942,0.0,0.0,0.72522,116.68,366.14,419.3,357.59,369.08
162.0888,98.5,4.9437,0.0,0.0,0.7568,116.89,366.63,419.68,357.72,369.06
162.0918,98.596,5.0858,0.0,0.0,0.78921,116.99,367.13,420.06,357.84,369.04
162.0948,98.748,5.2261,0.0,0.0,0.82236,117.18,367.62,420.43,357.9,369.02
162.0978,98.927,5.3643,0.0,0.0,0.85522,117.38,368.13,420.8,357.88,369.0
162.1008,99.121,5.5016,0.0,0.0,0.88758,117.62,368.64,421.16,357.85,368.99
162.1038,99.191,5.6326,0.0,0.0,0.91956,117.7,369.13,421.49,357.82,368.97
162.1068,99.283,5.7588,0.0,0.0,0.95296,117.81,369.42,421.65,357.82,369.0
162.1098,99.344,5.8795,0.0,0.0,0.98493,117.89,369.71,421.8,357.82,369.03
162.1128,99.504,5.9985,0.0,0.0,1.0162,118.08,370.0,421.95,357.82,369.05
162.1158,99.704,6.1145,0.0,0.0,1.0479,118.31,370.1,421.96,358.11,369.07
162.1188,99.907,6.2263,0.0,0.0,1.081,118.56,370.16,421.92,358.46,369.09
162.1218,100.14,6.3359,0.0,0.0,1.115,118.83,370.21,421.88,358.82,369.11
162.1248,100.37,6.4454,0.0,0.0,1.1489,119.11,370.18,421.83,359.21,369.12
162.1278,100.61,6.5522,0.0,0.0,1.1809,119.38,370.05,421.76,359.66,369.13
162.1308,100.76,6.6562,0.0,0.0,1.2142,119.57,369.93,421.69,360.11,369.14
162.1338,100.97,6.754,0.0,0.0,1.2483,119.82,369.78,421.6,360.5,369.15
162.1368,101.14,6.847,0.0,0.0,1.2803,120.02,369.48,421.43,360.58,369.13
162.1398,101.48,6.9404,0.0,0.0,1.311,120.41,369.19,421.26,360.67,369.11
162.1428,101.71,7.0304,0.0,0.0,1.3433,120.7,368.9,421.09,360.75,369.09
162.1458,102.09,7.1152,0.0,0.0,1.3768,121.14,368.58,420.81,360.66,369.11
162.1488,102.4,7.1989,0.0,0.0,1.411,121.5,368.26,420.51,360.53,369.12
162.1518,102.86,7.2853,0.0,0.0,1.4454,122.05,367.93,420.22,360.4,369.14
162.1548,103.24,7.366,0.0,0.0,1.4765,122.5,367.48,419.79,360.21,369.16
162.1578,103.91,7.4454,0.0,0.0,1.5093,123.29,366.89,419.24,359.95,369.18
162.1608,104.43,7.5215,0.0,0.0,1.5443,123.92,366.31,418.69,359.68,369.2
162.1638,104.99,7.5956,0.0,0.0,1.5769,124.58,365.67,418.1,359.48,369.21
162.1668,103.79,7.6669,0.0,0.0,1.6071,123.31,364.7,417.3,359.64,369.19
162.1698,98.387,7.7198,0.0,0.0,1.6323,116.87,363.74,416.49,359.79,369.17
162.1728,94.23,7.7325,0.0,0.0,1.6414,111.9,362.77,415.69,359.95,369.15
162.1758,91.601,7.7419,0.0,0.0,1.6482,108.74,361.82,414.89,360.35,369.12
162.1788,89.655,7.7497,0.0,0.0,1.6511,106.44,360.87,414.08,360.79,369.08
162.1818,88.157,7.7587,0.0,0.0,1.6528,104.64,359.93,413.28,361.24,369.05
162.1848,86.834,7.7658,0.0,0.0,1.6565,103.08,359.04,412.51,361.52,369.05
162.1878,85.721,7.7697,0.0,0.0,1.6605,101.75,358.2,411.76,361.65,369.08
162.1908,84.642,7.7735,0.0,0.0,1.6611,100.46,357.36,411.02,361.78,369.12
162.1938,83.662,7.7787,0.0,0.0,1.6613,99.293,356.53,410.3,361.82,369.15
162.1968,82.607,7.7814,0.0,0.0,1.6627,98.053,355.75,409.65,361.48,369.17
162.1998,81.543,7.7812,0.0,0.0,1.6652,96.785,354.96,408.99,361.13,369.19
162.2028,80.039,7.7818,0.0,0.0,1.6676,95.032,354.18,408.34,360.78,369.21
162.2058,76.014,7.7809,0.0,0.0,1.6658,90.346,353.75,407.92,360.15,369.18
162.2088,69.508,7.7757,0.0,0.0,1.6613,82.701,353.39,407.54,359.47,369.14
162.2118,27.829,7.6859,0.0,0.0,1.6193,34.073,353.03,407.16,358.78,369.11
162.2148,0.027153,7.583,0.0,0.0,1.5732,0.086898,352.91,407.0,358.28,369.1
162.2178,1.0793,7.6155,0.0,0.0,1.586,1.4133,353.01,407.04,357.95,369.12
162.2208,0.69246,7.6149,0.0,0.0,1.5833,0.83576,353.11,407.08,357.61,369.14
162.2238,0.97975,7.6157,0.0,0.0,1.5843,1.1502,353.22,407.13,357.34,369.15
162.2268,1.0165,7.6138,0.0,0.0,1.5855,1.1603,353.38,407.29,357.33,369.17
162.2298,1.1089,7.6121,0.0,0.0,1.5868,1.3175,353.55,407.44,357.32,369.19
162.2328,1.0104,7.6108,0.0,0.0,1.5851,1.1926,353.71,407.6,357.31,369.21
162.2358,0.9722,7.6124,0.0,0.0,1.5838,1.1706,353.87,407.7,357.72,369.21
162.2388,1.0114,7.6133,0.0,0.0,1.5851,1.1857,354.02,407.8,358.2,369.21
162.2418,0.95622,7.6136,0.0,0.0,1.5862,1.1507,354.18,407.9,358.67,369.21
162.2448,1.0442,7.6142,0.0,0.0,1.5848,1.2306,354.33,408.02,359.09,369.22
162.2478,1.0185,7.6157,0.0,0.0,1.5837,1.2124,354.49,408.16,359.48,369.24
162.2508,0.99857,7.6135,0.0,0.0,1.5839,1.1759,354.64,408.29,359.86,369.26
162.2538,0.98306,7.6111,0.0,0.0,1.5852,1.1712,354.79,408.42,360.12,369.28
162.2568,0.99502,7.61,0.0,0.0,1.586,1.1789,354.9,408.5,359.96,369.29
162.2598,1.0154,7.614,0.0,0.0,1.5863,1.213,355.01,408.58,359.79,369.31
162.2628,1.0611,7.6156,0.0,0.0,1.5854,1.2442,355.11,408.66,359.63,369.33
162.2658,0.9771,7.6151,0.0,0.0,1.5866,1.1619,355.17,408.68,359.13,369.33
162.2688,1.0392,7.6146,0.0,0.0,1.587,1.2306,355.21,408.69,358.59,369.33
162.2718,0.99078,7.6166,0.0,0.0,1.5857,1.1783,355.26,408.7,358.06,369.33
162.2748,1.0237,7.6162,0.0,0.0,1.584,1.2088,355.3,408.7,357.54,369.31
162.2778,0.98856,7.6166,0.0,0.0,1.585,1.185,355.34,408.71,357.05,369.28
162.2808,1.0607,7.6141,0.0,0.0,1.587,1.2591,355.37,408.72,356.56,369.24
162.2838,1.006,7.614,0.0,0.0,1.5876,1.1941,355.41,408.74,356.22,369.21
162.2868,1.0658,7.6159,0.0,0.0,1.5864,1.2536,355.47,408.76,356.37,369.21
162.2898,1.0019,7.618,0.0,0.0,1.5859,1.1662,355.52,408.79,356.51,369.21
162.2928,1.0117,7.6172,0.0,0.0,1.5874,1.202,355.58,408.82,356.66,369.21
162.2958,1.02,7.6162,0.0,0.0,1.5875,1.2122,355.61,408.85,357.05,369.26
162.2988,1.1044,7.6167,0.0,0.0,1.5852,1.3028,355.65,408.89,357.46,369.32
162.3018,1.0475,7.6174,0.0,0.0,1.5846,1.238,355.69,408.93,357.87,369.37
162.3048,1.1382,7.6142,0.0,0.0,1.585,1.3431,355.75,408.94,358.13,369.4
162.3078,1.0945,7.6119,0.0,0.0,1.5863,1.2996,355.82,408.94,358.28,369.42
162.3108,1.2129,7.6134,0.0,0.0,1.5873,1.4355,355.89,408.94,358.44,369.44
162.3138,1.1293,7.6159,0.0,0.0,1.5863,1.3271,355.95,408.94,358.4,369.45
162.3168,1.2401,7.6171,0.0,0.0,1.5863,1.4867,355.97,408.94,357.82,369.45
162.3198,1.1026,7.617,0.0,0.0,1.5875,1.2937,355.99,408.94,357.23,369.45
162.3228,1.2699,7.6155,0.0,0.0,1.5871,1.5249,356.0,408.94,356.65,369.45
162.3258,1.101,7.6137,0.0,0.0,1.5837,1.2893,355.98,408.94,356.06,369.46
162.3288,1.2423,7.615,0.0,0.0,1.5835,1.4997,355.95,408.94,355.47,369.47
162.3318,1.1107,7.6128,0.0,0.0,1.5846,1.2969,355.93,408.94,354.87,369.48
162.3348,1.2223,7.6134,0.0,0.0,1.5874,1.4669,355.91,408.94,354.61,369.46
162.3378,1.1324,7.6124,0.0,0.0,1.5866,1.3154,355.91,408.94,354.57,369.42
162.3408,1.2049,7.6153,0.0,0.0,1.5857,1.4601,355.91,408.94,354.52,369.39
162.3438,1.1518,7.6134,0.0,0.0,1.5842,1.3372,355.91,408.93,354.55,369.36
162.3468,1.1843,7.6143,0.0,0.0,1.5868,1.4403,355.9,408.91,354.77,369.35
162.3498,1.1726,7.6122,0.0,0.0,1.5851,1.3602,355.89,408.88,354.99,369.34
162.3528,1.1626,7.6143,0.0,0.0,1.5834,1.4127,355.88,408.85,355.21,369.33
162.3558,1.2081,7.6131,0.0,0.0,1.583,1.4079,355.87,408.81,355.38,369.38
162.3588,1.1493,7.612,0.0,0.0,1.5846,1.3983,355.85,408.76,355.56,369.44
162.3618,1.2355,7.6113,0.0,0.0,1.5864,1.4355,355.83,408.72,355.73,369.49
162.3648,1.1125,7.6128,0.0,0.0,1.5865,1.3492,355.8,408.67,355.76,369.52
162.3678,1.2448,7.6143,0.0,0.0,1.585,1.4584,355.76,408.61,355.72,369.53
162.3708,1.1059,7.6147,0.0,0.0,1.585,1.3254,355.73,408.56,355.67,369.54
162.3738,1.2612,7.6134,0.0,0.0,1.5867,1.4745,355.7,408.49,355.64,369.55
162.3768,1.0785,7.6138,0.0,0.0,1.5856,1.2956,355.68,408.39,355.64,369.57
162.3798,1.2845,7.6158,0.0,0.0,1.5841,1.5108,355.66,408.29,355.64,369.59
162.3828,1.0621,7.6153,0.0,0.0,1.5839,1.2698,355.64,408.19,355.64,369.6
162.3858,1.2958,7.6143,0.0,0.0,1.5861,1.5171,355.62,408.13,355.56,369.61
162.3888,1.0597,7.6111,0.0,0.0,1.5869,1.2666,355.59,408.08,355.48,369.62
162.3918,1.287,7.6127,0.0,0.0,1.5863,1.5194,355.56,408.03,355.4,369.63
162.3948,1.0652,7.6156,0.0,0.0,1.5854,1.2683,355.52,407.98,355.3,369.62
162.3978,1.2988,7.6152,0.0,0.0,1.5857,1.5414,355.46,407.95,355.19,369.6
162.4008,1.0608,7.6128,0.0,0.0,1.586,1.2502,355.41,407.91,355.08,369.59
162.4038,1.3044,7.614,0.0,0.0,1.5854,1.5491,355.36,407.86,355.0,369.58
162.4068,1.0772,7.6151,0.0,0.0,1.5839,1.2769,355.33,407.78,354.99,369.6
162.4098,1.3039,7.6152,0.0,0.0,1.5839,1.5475,355.31,407.7,354.98,369.62
162.4128,1.086,7.6128,0.0,0.0,1.5858,1.2889,355.28,407.62,354.98,369.63
162.4158,1.2855,7.612,0.0,0.0,1.5867,1.5447,355.22,407.56,355.33,369.63
162.4188,1.0969,7.6119,0.0,0.0,1.5856,1.2828,355.17,407.51,355.68,369.63
162.4218,1.2889,7.6159,0.0,0.0,1.585,1.5453,355.11,407.45,356.04,369.63
162.4248,1.1184,7.6155,0.0,0.0,1.5858,1.3092,355.07,407.42,356.36,369.66
162.4278,1.2592,7.6153,0.0,0.0,1.5873,1.5115,355.04,407.41,356.66,369.7
162.4308,1.1347,7.614,0.0,0.0,1.5847,1.3221,355.0,407.39,356.96,369.73
162.4338,1.2463,7.6152,0.0,0.0,1.5834,1.5051,354.96,407.35,357.1,369.76
162.4368,1.1464,7.6138,0.0,0.0,1.5836,1.3468,354.93,407.29,356.92,369.78
162.4398,1.231,7.6137,0.0,0.0,1.5867,1.4865,354.89,407.23,356.75,369.8
162.4428,1.1684,7.6103,0.0,0.0,1.586,1.3659,354.85,407.16,356.58,369.82
162.4458,1.1958,7.6147,0.0,0.0,1.5864,1.4481,354.74,407.07,356.41,369.78
162.4488,1.1958,7.615,0.0,0.0,1.5848,1.3886,354.63,406.98,356.23,369.74
162.4518,1.1669,7.6153,0.0,0.0,1.5861,1.4235,354.52,406.89,356.06,369.71
162.4548,1.2124,7.6148,0.0,0.0,1.5868,1.4182,354.45,406.81,356.09,369.7
162.4578,1.1517,7.6165,0.0,0.0,1.5853,1.389,354.4,406.73,356.22,369.7
162.4608,1.2378,7.6155,0.0,0.0,1.5836,1.4432,354.34,406.64,356.35,369.7
162.4638,1.1267,7.6152,0.0,0.0,1.5847,1.3646,354.3,406.57,356.53,369.71
162.4668,1.2677,7.6131,0.0,0.0,1.5863,1.4804,354.26,406.49,356.81,369.74
162.4698,1.112,7.6134,0.0,0.0,1.5871,1.3414,354.22,406.42,357.1,369.78
162.4728,1.2693,7.6143,0.0,0.0,1.5858,1.4869,354.18,406.35,357.37,369.82
162.4758,1.1028,7.615,0.0,0.0,1.5849,1.323,354.12,406.29,357.37,369.83
162.4788,1.307,7.6149,0.0,0.0,1.5865,1.5389,354.06,406.22,357.37,369.85
162.4818,1.0887,7.6126,0.0,0.0,1.5861,1.3023,353.99,406.16,357.37,369.87
162.4848,1.3197,7.6146,0.0,0.0,1.5841,1.5573,353.94,406.08,357.25,369.85
162.4878,1.0757,7.6169,0.0,0.0,1.5843,1.2973,353.88,406.0,357.09,369.81
162.4908,1.3109,7.6155,0.0,0.0,1.5856,1.5522,353.83,405.92,356.93,369.78
162.4938,1.0911,7.6131,0.0,0.0,1.5869,1.3048,353.76,405.85,356.8,369.76
162.4968,1.328,7.6126,0.0,0.0,1.587,1.5703,353.68,405.8,356.75,369.76
162.4998,1.0901,7.6131,0.0,0.0,1.585,1.3002,353.6,405.74,356.69,369.76
162.5028,1.3264,7.6161,0.0,0.0,1.5851,1.5829,353.52,405.69,356.64,369.76
162.5058,1.0921,7.6141,0.0,0.0,1.5864,1.2826,353.42,405.65,356.66,369.79
162.5088,1.3126,7.615,0.0,0.0,1.5868,1.5596,353.33,405.62,356.68,369.83
162.5118,1.1016,7.6156,0.0,0.0,1.5847,1.3029,353.24,405.58,356.7,369.87
162.5148,1.2973,7.6166,0.0,0.0,1.5842,1.5524,353.18,405.5,356.71,369.88
162.5178,1.1123,7.6133,0.0,0.0,1.5849,1.307,353.12,405.41,356.72,369.88
162.5208,1.2959,7.613,0.0,0.0,1.5872,1.5537,353.07,405.32,356.73,369.88
162.5238,1.1221,7.6115,0.0,0.0,1.5863,1.3154,353.01,405.24,356.79,369.88
162.5268,1.2742,7.6156,0.0,0.0,1.5859,1.5359,352.96,405.17,356.94,369.89
162.5298,1.1489,7.6163,0.0,0.0,1.5858,1.3466,352.9,405.09,357.08,369.9
162.5328,1.2602,7.6155,0.0,0.0,1.5874,1.5179,352.85,405.02,357.24,369.91
162.5358,1.1714,7.6136,0.0,0.0,1.586,1.3713,352.79,404.94,357.51,369.93
162.5388,1.2278,7.6158,0.0,0.0,1.5843,1.487,352.74,404.86,357.78,369.94
162.5418,1.1928,7.6137,0.0,0.0,1.583,1.3874,352.69,404.78,358.06,369.96
162.5448,1.21,7.6134,0.0,0.0,1.5853,1.4626,352.62,404.63,358.13,369.96
162.5478,1.2142,7.6112,0.0,0.0,1.5867,1.4177,352.54,404.46,358.13,369.95
162.5508,1.1864,7.6125,0.0,0.0,1.5866,1.438,352.47,404.28,358.13,369.94
162.5538,1.2453,7.6143,0.0,0.0,1.585,1.4622,352.4,404.14,358.05,369.94
162.5568,1.1703,7.6152,0.0,0.0,1.5853,1.4088,352.33,404.03,357.88,369.96
162.5598,1.275,7.614,0.0,0.0,1.5866,1.4854,352.25,403.92,357.71,369.98
162.5628,1.1415,7.6147,0.0,0.0,1.5861,1.3868,352.18,403.82,357.54,370.0
162.5658,1.2905,7.615,0.0,0.0,1.5841,1.5091,352.11,403.78,357.44,370.04
162.5688,1.1267,7.6151,0.0,0.0,1.5843,1.3495,352.03,403.75,357.34,370.07
162.5718,1.296,7.6121,0.0,0.0,1.5851,1.5286,351.96,403.71,357.24,370.11
162.5748,1.1243,7.612,0.0,0.0,1.5869,1.3495,351.87,403.65,357.37,370.13
162.5778,1.3252,7.6137,0.0,0.0,1.5866,1.554,351.78,403.59,357.57,370.13
162.5808,1.1075,7.6147,0.0,0.0,1.5849,1.3269,351.69,403.53,357.77,370.14
162.5838,1.3306,7.6153,0.0,0.0,1.5854,1.5738,351.62,403.46,358.02,370.14
162.5868,1.1004,7.6148,0.0,0.0,1.587,1.3122,351.56,403.39,358.32,370.12
162.5898,1.3297,7.6159,0.0,0.0,1.5859,1.5632,351.51,403.32,358.62,370.1
162.5928,1.1054,7.6171,0.0,0.0,1.5846,1.3145,351.46,403.25,358.88,370.09
162.9933,1.169,7.6161,0.0,0.0,1.5864,1.3881,342.78,392.17,361.02,365.38
163.5933,1.1311,7.6181,0.0,0.0,1.5873,1.3417,322.49,362.67,339.96,318.7
164.1933,1.0963,7.6233,0.0,0.0,1.5897,1.3007,297.62,334.29,306.51,308.16
164.7933,1.0739,7.6204,0.0,0.0,1.5883,1.275,278.5,310.77,293.03,296.8
165.3933,1.0581,7.6249,0.0,0.0,1.5906,1.2549,261.65,289.45,276.35,283.59
165.9933,1.0483,7.6297,0.0,0.0,1.5925,1.2438,245.8,267.76,256.09,271.31
166.5933,1.0451,7.6331,0.0,0.0,1.5942,1.2387,229.21,245.37,223.17,262.07
167.1457,1.0396,7.636,0.0,0.0,1.5954,1.2338,213.8,212.08,208.96,246.87
167.7457,1.0382,7.6391,0.0,0.0,1.5969,1.2317,184.92,180.76,201.66,229.25
168.3457,1.0272,7.6419,0.0,0.0,1.5982,1.2182,163.59,152.73,181.6,195.84
168.9457,0.9874,7.6429,0.0,0.0,1.5988,1.1715,145.45,125.64,147.27,110.2
169.5457,0.94629,7.6464,0.0,0.0,1.6005,1.1228,123.55,109.92,111.06,81.541
170.1457,0.93748,7.6491,0.0,0.0,1.6015,1.1134,98.452,95.058,80.045,64.575
170.7457,0.94511,7.6503,0.0,0.0,1.6021,1.1213,87.879,89.392,61.723,55.305
171.3457,0.93652,7.651,0.0,0.0,1.6024,1.1118,78.96,81.178,52.56,48.438
171.9457,0.92544,7.6522,0.0,0.0,1.6032,1.0984,71.596,74.596,46.917,44.047
172.5457,0.91725,7.655,0.0,0.0,1.6045,1.0878,65.572,68.479,43.048,40.298
173.1457,0.81387,7.6634,0.0,0.0,1.6081,0.96563,64.108,68.045,42.959,43.492
173.7457,0.94162,7.6684,0.0,0.0,1.6107,1.1174,64.988,70.044,45.395,47.231
174.3457,0.80199,7.6712,0.0,0.0,1.6118,0.95194,66.94,72.094,47.863,49.4
174.5457,0.79984,7.6729,0.0,0.0,1.6125,0.94919,67.547,72.55,48.775,50.46