File: examples/dan-msc-case-studies/CS4/data/01 raw data/hyde_test_029.csv
Time(sec),Force(kN),Jaw(mm),PowAngle(deg),PTemp,Strain,Stress(MPa),TC1(C),TC2(C),TC3(C)
0.0,7.3613,0.0011983,0.0,4.5078e-05,0.00015584,22.34,20.301,20.898,21.092
0.6,7.3378,0.0016592,0.0,1.621,0.00019707,22.256,20.345,20.896,21.116
1.2,7.2879,0.0015283,0.0,3.421,0.00020843,22.108,20.318,20.842,21.128
1.8,7.2829,0.0017589,0.0,5.221,0.00016715,22.09,20.328,20.841,21.117
2.4,7.2409,0.0014557,0.0,7.021,0.00027526,21.967,20.384,20.878,21.163
3.0,7.2314,0.0017006,0.0,8.821,0.00019839,21.934,20.305,20.884,21.114
3.6,7.2184,0.0019867,0.0,10.621,0.00012767,21.901,20.334,20.885,21.099
4.2,7.2068,0.0016398,0.0,12.421,0.00022482,21.86,20.357,20.852,21.135
4.8,7.1729,0.0017878,0.0,14.221,0.00015337,21.762,20.308,20.859,21.128
5.4,7.1644,0.0018526,0.0,16.021,0.00019029,21.729,20.351,20.818,21.106
6.0,7.1513,0.0017878,0.0,17.821,0.00019645,21.696,20.33,20.893,21.061
6.6,7.1438,0.0017253,0.0,19.621,0.00024827,21.665,20.454,20.945,21.222
7.2,7.126,0.0024088,11.358,21.421,0.00030453,21.621,20.339,20.926,21.114
7.8,7.1338,0.0026305,22.86,23.221,0.00023709,21.636,21.14,22.12,22.167
8.309,7.1314,0.001915,23.357,24.76,0.00017006,21.631,22.965,24.22,24.29
8.909,7.163,0.0014177,22.748,26.548,0.00018583,21.73,25.259,26.516,26.72
9.509,7.1563,0.00037768,23.347,28.348,9.4871e-06,21.706,27.273,28.576,28.832
10.109,7.1792,0.00024929,23.354,30.148,4.7014e-05,21.778,29.263,37.235,30.734
10.709,7.1678,-0.00019661,24.437,31.948,-2.7738e-05,21.744,31.096,37.272,32.531
11.309,7.1836,-0.0011872,24.812,33.748,-5.195e-05,21.79,33.001,37.272,34.542
11.909,7.1683,-0.0022424,24.968,35.548,-0.0002074,21.742,34.956,36.886,36.381
12.509,7.1859,-0.0022777,25.454,37.348,-0.00030778,21.796,36.737,38.228,38.241
13.109,7.184,-0.0033045,24.869,39.148,-0.00028488,21.794,38.812,40.346,40.375
13.6117,7.2023,-0.0035164,26.203,40.656,-0.00043298,21.847,40.152,41.599,41.643
14.2117,7.1968,-0.0041194,26.288,42.456,-0.00047541,21.831,42.054,43.573,43.604
14.8117,7.2156,-0.0058803,26.45,44.256,-0.00064167,21.89,43.933,45.334,45.521
15.4117,7.2009,-0.005874,26.518,46.056,-0.00059733,21.843,45.828,47.192,47.353
16.0117,7.2239,-0.0064677,26.788,47.856,-0.00066085,21.912,47.615,49.083,49.199
16.6117,7.2158,-0.0066953,26.771,49.656,-0.00076575,21.888,49.489,50.932,51.074
17.2117,7.2378,-0.0078723,26.724,51.456,-0.00075335,21.955,51.328,52.712,52.854
17.8117,7.2304,-0.0091284,27.465,53.256,-0.0010139,21.934,53.057,54.551,54.678
18.4117,7.2431,-0.0091363,27.667,55.056,-0.001084,21.969,54.897,56.315,56.507
19.0117,7.2242,-0.010282,27.634,56.856,-0.0010966,21.916,56.818,58.232,58.461
19.6117,7.2524,-0.0105,28.645,58.656,-0.0011799,22.0,58.415,59.825,60.071
20.2117,7.2399,-0.011523,28.978,60.456,-0.0012455,21.966,60.176,61.602,61.939
20.8117,7.2441,-0.013267,28.657,62.256,-0.0014558,21.971,62.102,63.532,63.987
21.4117,7.2441,-0.013281,29.068,64.056,-0.0013779,21.977,63.9,65.328,65.827
22.0117,7.255,-0.013951,29.134,65.856,-0.0014737,22.003,65.703,67.128,67.647
22.6117,7.2423,-0.014424,29.468,67.656,-0.0016404,21.975,67.526,69.029,69.551
23.2117,7.255,-0.015636,28.731,69.456,-0.0016328,22.004,69.507,71.038,71.662
23.8117,7.2512,-0.017028,29.534,71.256,-0.0019201,21.997,71.123,72.579,73.228
24.4117,7.2497,-0.017596,29.385,73.056,-0.0019956,21.986,72.976,74.587,75.284
25.0117,7.2533,-0.018194,29.515,74.856,-0.001978,22.007,74.797,76.415,77.156
25.6117,7.26,-0.018826,29.087,76.656,-0.0020625,22.019,76.617,78.201,79.087
26.2117,7.2539,-0.019707,29.449,78.456,-0.0021296,22.009,78.436,80.011,80.911
26.8117,7.2579,-0.020515,30.288,80.256,-0.0022487,22.01,80.06,81.691,82.62
27.4117,7.2619,-0.022532,29.577,82.056,-0.0024072,22.032,82.053,83.676,84.596
28.0117,7.2562,-0.023304,29.77,83.856,-0.0024977,22.005,83.814,85.508,86.527
28.6117,7.2568,-0.023306,29.774,85.656,-0.0025955,22.017,85.621,87.468,88.466
29.2117,7.2585,-0.024661,29.519,87.456,-0.0026107,22.015,87.444,89.253,90.297
29.8117,7.2566,-0.025156,29.526,89.256,-0.0027796,22.015,89.297,91.182,92.289
30.4117,7.2583,-0.025994,30.131,91.056,-0.0029116,22.011,91.011,92.938,94.022
31.0117,7.2648,-0.028137,30.351,92.856,-0.0030571,22.041,92.775,94.672,95.94
31.6117,7.2587,-0.029123,30.506,94.656,-0.0032232,22.013,94.558,96.529,97.788
32.2117,7.2538,-0.029078,30.364,96.456,-0.0031854,22.008,96.384,98.406,99.676
32.81171,7.252,-0.030117,30.666,98.256,-0.003282,21.995,98.206,100.37,101.67
33.41171,7.2628,-0.031166,30.682,100.06,-0.0033521,22.035,100.0,102.17,103.54
34.01171,7.2565,-0.031881,30.79,101.86,-0.0034319,22.009,101.79,104.03,105.47
34.61171,7.2679,-0.032774,30.873,103.66,-0.003618,22.048,103.53,105.81,107.26
35.21171,7.2566,-0.035894,31.078,105.46,-0.003817,22.011,105.33,107.68,109.16
35.81171,7.2597,-0.035326,30.931,107.26,-0.0038532,22.021,107.2,109.43,111.06
36.41171,7.2538,-0.035734,30.872,109.06,-0.0039877,22.002,109.02,111.31,113.0
37.01171,7.2646,-0.037163,30.937,110.86,-0.0040087,22.036,110.81,113.19,114.81
37.61171,7.2456,-0.037983,31.21,112.66,-0.0041932,21.979,112.6,115.09,116.69
38.21171,7.2633,-0.038777,31.054,114.46,-0.0042822,22.032,114.42,116.91,118.5
38.81171,7.2577,-0.04078,31.55,116.26,-0.0044489,22.014,116.21,118.7,120.43
39.41171,7.2706,-0.042532,31.282,118.06,-0.0046133,22.056,118.0,120.52,122.3
40.01171,7.2497,-0.042189,30.997,119.86,-0.0045659,21.994,119.93,122.43,124.27
40.61171,7.2686,-0.04318,31.456,121.66,-0.0047334,22.049,121.67,124.12,126.02
41.1411,7.2648,-0.043986,31.246,123.24,-0.00483,22.032,123.26,125.75,127.69
41.7411,7.2583,-0.045203,31.559,125.04,-0.0048308,22.02,124.99,127.5,129.55
42.3411,7.2665,-0.045793,31.711,126.84,-0.0050124,22.041,126.78,129.28,131.35
42.9411,7.2526,-0.048603,31.352,128.64,-0.0053999,22.002,128.7,131.27,133.41
43.5411,7.2638,-0.049031,31.531,130.44,-0.0053106,22.029,130.42,132.98,135.07
44.1411,7.2554,-0.049375,31.867,132.24,-0.0054509,22.014,132.2,134.75,137.0
44.6166,7.2553,-0.050306,31.852,133.67,-0.0054459,22.005,133.66,136.29,138.56
45.2166,7.2636,-0.05104,31.577,135.47,-0.0055732,22.038,135.51,138.15,140.39
45.8166,7.2551,-0.052164,31.607,137.27,-0.0056196,22.003,137.31,139.98,142.28
46.4166,7.2734,-0.053589,32.173,139.07,-0.0058127,22.065,138.92,141.55,143.98
47.0166,7.2607,-0.055482,31.876,140.87,-0.0060979,22.02,140.86,143.5,146.08
47.6166,7.2638,-0.05566,31.444,142.67,-0.0059843,22.037,142.76,145.49,148.05
48.2166,7.2539,-0.05618,31.518,144.47,-0.0061373,22.003,144.55,147.25,149.87
48.8166,7.2704,-0.057438,32.653,146.27,-0.0063466,22.056,146.14,148.9,151.52
49.4166,7.2526,-0.058718,32.425,148.07,-0.0063651,21.998,147.92,150.76,153.39
50.0166,7.2788,-0.060346,31.895,149.87,-0.006636,22.08,149.9,152.78,155.53
50.6166,7.2591,-0.061601,32.422,151.67,-0.0067572,22.018,151.59,154.47,157.24
51.2166,7.2701,-0.062181,32.259,153.47,-0.0067592,22.053,153.44,156.4,159.28
51.8166,7.2574,-0.062996,32.667,155.27,-0.0068527,22.014,155.24,158.37,161.15
52.4166,7.2748,-0.06412,32.799,157.07,-0.0069473,22.068,157.05,160.24,163.05
53.0166,7.2608,-0.065012,32.915,158.87,-0.0071065,22.026,158.78,162.11,164.96
53.6166,7.275,-0.068635,33.154,160.67,-0.0074232,22.067,160.52,163.92,166.76
54.2166,7.2552,-0.06805,32.875,162.47,-0.007358,22.01,162.46,165.94,168.85
54.8166,7.2692,-0.068456,32.761,164.27,-0.0075074,22.05,164.26,167.86,170.77
55.4166,7.259,-0.070138,33.18,166.07,-0.0075412,22.022,165.97,169.62,172.55
56.0166,7.2738,-0.070588,32.922,167.87,-0.007686,22.062,167.81,171.52,174.52
56.6166,7.2661,-0.072153,33.247,169.67,-0.007961,22.045,169.64,173.37,176.46
57.2166,7.273,-0.074997,33.149,171.47,-0.0081077,22.06,171.43,175.22,178.36
57.8166,7.2562,-0.074367,33.192,173.27,-0.0081408,22.013,173.25,177.14,180.19
58.4166,7.2728,-0.07524,33.765,175.07,-0.0082688,22.06,174.91,178.89,181.9
59.0166,7.2665,-0.07684,33.461,176.87,-0.0083518,22.047,176.82,180.91,183.96
59.6166,7.2742,-0.077466,33.214,178.67,-0.008467,22.063,178.69,182.86,185.92
60.2166,7.2629,-0.081257,33.196,180.47,-0.008856,22.037,180.51,184.8,187.91
60.8166,7.2633,-0.080354,33.441,182.27,-0.0087309,22.028,182.23,186.52,189.62
61.4166,7.2643,-0.081374,33.44,184.07,-0.0088186,22.04,184.05,188.46,191.59
62.0166,7.2689,-0.082299,33.339,185.87,-0.0089212,22.043,185.85,190.35,193.47
62.6166,7.2691,-0.083119,33.673,187.67,-0.0090782,22.055,187.63,192.14,195.33
63.2166,7.2727,-0.086418,33.769,189.47,-0.0093344,22.057,189.42,194.0,197.26
63.81661,7.2671,-0.086563,33.526,191.27,-0.0093744,22.046,191.3,195.92,199.26
64.41661,7.2683,-0.086726,34.161,193.07,-0.0095026,22.041,192.86,197.45,200.74
65.01661,7.2718,-0.088264,33.512,194.87,-0.0095122,22.062,194.88,199.48,202.83
65.61661,7.2723,-0.088977,33.931,196.67,-0.0097069,22.055,196.64,201.32,204.7
66.21661,7.2761,-0.091569,33.784,198.47,-0.010066,22.075,198.43,203.19,206.68
66.81661,7.2661,-0.092932,33.808,200.27,-0.010074,22.035,200.23,205.15,208.56
67.41661,7.271,-0.093035,34.122,202.07,-0.010178,22.06,201.98,206.83,210.3
68.01661,7.265,-0.094059,34.093,203.87,-0.010291,22.036,203.81,208.68,212.22
68.61661,7.2774,-0.095121,33.94,205.67,-0.010343,22.079,205.66,210.59,214.13
69.21661,7.2719,-0.096944,34.38,207.47,-0.010563,22.055,207.42,212.41,216.0
69.81661,7.2815,-0.099006,34.329,209.27,-0.01073,22.09,209.24,214.23,217.87
70.41661,7.2615,-0.099149,34.503,211.07,-0.010783,22.024,210.97,216.05,219.74
71.01661,7.2764,-0.10046,34.626,212.87,-0.010865,22.075,212.77,217.91,221.65
71.61661,7.2684,-0.10103,33.738,214.67,-0.010956,22.046,214.8,220.0,223.85
72.21661,7.2884,-0.1024,35.052,216.47,-0.01119,22.112,216.28,221.5,225.3
72.81661,7.2713,-0.10675,34.651,218.27,-0.0115,22.056,218.2,223.54,227.33
73.41661,7.2728,-0.1054,34.735,220.07,-0.011438,22.062,219.98,225.43,229.26
73.966,7.2771,-0.10611,34.568,221.72,-0.011553,22.078,221.68,227.09,231.06
74.566,7.2633,-0.10717,33.998,223.52,-0.011746,22.029,223.62,229.05,233.01
75.166,7.281,-0.10877,34.92,225.32,-0.011774,22.088,225.22,230.78,234.66
75.7082,7.288,-0.11032,34.749,226.95,-0.01208,22.108,226.9,232.52,236.53
76.3082,7.2704,-0.11308,35.395,228.75,-0.01236,22.052,228.59,234.31,238.35
76.9082,7.2758,-0.11282,35.043,230.55,-0.012277,22.073,230.48,236.23,240.26
77.5082,7.2619,-0.1138,34.591,232.35,-0.012417,22.028,232.43,238.16,242.29
78.1082,7.2753,-0.11486,35.287,234.15,-0.012502,22.07,234.05,239.78,244.03
78.7082,7.2701,-0.11596,34.886,235.95,-0.012609,22.052,235.93,241.67,245.9
79.3082,7.2868,-0.11878,35.478,237.75,-0.012895,22.103,237.62,243.38,247.59
79.9082,7.2699,-0.1207,35.253,239.55,-0.013067,22.054,239.54,245.42,249.71
80.5082,7.2794,-0.1202,34.848,241.35,-0.013076,22.078,241.43,247.22,251.55
81.1082,7.269,-0.12158,34.972,243.15,-0.01314,22.052,243.17,249.02,253.33
81.7082,7.285,-0.1223,35.038,244.95,-0.013248,22.099,244.98,250.85,255.2
82.3082,7.2686,-0.1233,35.407,246.75,-0.013437,22.052,246.73,252.61,257.05
82.9082,7.2874,-0.1269,34.96,248.55,-0.013701,22.102,248.62,254.52,259.07
83.5082,7.2677,-0.12722,35.06,250.35,-0.013786,22.048,250.37,256.36,260.81
84.1082,7.2787,-0.12759,35.391,252.15,-0.013922,22.076,252.15,258.12,262.72
84.7082,7.2707,-0.12911,35.665,253.95,-0.013936,22.059,253.83,259.92,264.47
85.3082,7.2813,-0.12994,35.231,255.75,-0.014126,22.086,255.76,261.82,266.47
85.9082,7.2639,-0.1306,34.515,257.55,-0.014272,22.039,257.74,263.76,268.48
86.5082,7.2786,-0.13582,35.041,259.35,-0.014711,22.076,259.38,265.34,270.0
87.1082,7.2658,-0.13431,35.479,261.15,-0.014628,22.043,261.1,267.18,271.88
87.7082,7.2737,-0.13471,35.125,262.95,-0.014707,22.058,263.03,269.19,273.96
88.3082,7.2729,-0.13648,35.497,264.75,-0.014789,22.067,264.69,270.82,275.62
88.9082,7.2855,-0.13684,35.709,266.55,-0.014911,22.096,266.44,272.66,277.42
89.5082,7.2809,-0.1389,34.988,268.35,-0.015162,22.091,268.4,274.52,279.46
90.1082,7.2773,-0.14127,34.511,270.15,-0.015315,22.072,270.34,276.46,281.38
90.7082,7.2676,-0.14103,35.251,271.95,-0.015334,22.052,271.93,278.06,282.97
91.3082,7.2775,-0.14199,35.83,273.75,-0.015428,22.074,273.58,279.66,284.58
91.9082,7.279,-0.14306,35.202,275.55,-0.01552,22.086,275.55,281.79,286.74
92.5082,7.2822,-0.14399,35.495,277.35,-0.015601,22.087,277.3,283.48,288.45
93.1082,7.2793,-0.14893,35.558,279.15,-0.016137,22.085,279.02,285.29,290.3
93.7082,7.273,-0.1471,36.07,280.95,-0.015974,22.058,280.74,287.03,292.06
94.30821,7.2794,-0.14807,35.456,282.75,-0.016011,22.085,282.7,289.05,294.12
94.90821,7.2722,-0.14897,35.509,284.55,-0.016117,22.058,284.52,290.79,296.0
95.50821,7.282,-0.14928,35.419,286.35,-0.016226,22.092,286.35,292.59,297.79
96.10821,7.2742,-0.15299,35.196,288.15,-0.016531,22.061,288.24,294.53,299.65
96.70821,7.2847,-0.15312,35.678,289.95,-0.016567,22.097,289.91,296.22,301.27
97.30821,7.2699,-0.15338,35.932,291.75,-0.016686,22.05,291.66,297.91,303.07
97.90821,7.2819,-0.15494,35.694,293.55,-0.016707,22.09,293.53,299.79,304.99
98.50821,7.2705,-0.15517,35.799,295.35,-0.016818,22.053,295.34,301.74,306.96
99.10821,7.2913,-0.15675,35.312,297.15,-0.017091,22.119,297.27,303.62,308.8
99.70821,7.2796,-0.15949,35.809,298.95,-0.017205,22.08,298.93,305.28,310.43
100.30821,7.2639,-0.15818,34.333,300.0,-0.017182,22.034,300.38,306.85,311.9
100.90821,7.254,-0.15804,33.631,300.0,-0.017225,22.003,300.44,306.89,311.55
101.50821,7.2726,-0.15829,33.464,300.0,-0.017126,22.062,300.4,306.73,310.99
102.10821,7.2692,-0.15847,33.637,300.0,-0.017244,22.051,300.27,306.42,310.68
102.70821,7.2832,-0.16053,33.605,300.0,-0.017466,22.093,300.23,306.27,310.54
103.30821,7.2452,-0.15913,32.847,300.0,-0.017221,21.977,300.3,306.36,310.5
103.90821,7.2809,-0.15919,33.404,300.0,-0.017309,22.085,300.18,306.14,310.28
104.50821,7.2644,-0.15903,33.105,300.0,-0.017311,22.037,300.19,306.09,310.18
105.10821,7.2804,-0.1598,33.406,300.0,-0.01733,22.083,300.11,306.07,310.06
105.70821,7.27,-0.16135,33.146,300.0,-0.017506,22.057,300.1,305.95,309.87
106.2913,7.2708,-0.15991,33.699,300.0,-0.017368,22.05,299.96,305.74,309.63
106.8913,7.2704,-0.15993,32.794,300.0,-0.017354,22.06,300.13,305.94,309.84
107.3196,7.2717,-0.15998,33.336,300.0,-0.01739,22.064,300.08,305.8,309.7
107.9196,7.2606,-0.16,32.889,300.0,-0.017295,22.02,300.12,305.89,309.67
108.5196,7.2741,-0.16348,32.941,300.0,-0.017692,22.071,300.07,305.74,309.52
109.1196,7.2709,-0.16057,33.186,300.0,-0.017468,22.051,299.99,305.6,309.35
109.7196,7.2585,-0.16111,32.624,300.0,-0.017402,22.022,300.07,305.78,309.51
110.3196,7.2706,-0.16066,32.655,300.0,-0.017407,22.048,300.09,305.69,309.36
110.9196,7.2769,-0.16039,32.883,300.0,-0.017464,22.078,300.01,305.63,309.28
111.5196,7.2698,-0.16388,32.065,300.0,-0.017684,22.048,300.24,305.8,309.49
112.1196,7.2613,-0.16136,32.627,300.0,-0.017483,22.03,300.04,305.61,309.22
112.7196,7.2687,-0.16134,32.809,300.0,-0.017563,22.044,300.05,305.57,309.17
113.3196,7.2802,-0.16175,32.508,300.0,-0.01747,22.088,300.08,305.57,309.17
113.9196,7.2736,-0.16121,32.591,300.0,-0.017487,22.06,300.02,305.5,309.09
114.5196,7.2703,-0.16451,32.695,300.0,-0.017925,22.056,300.03,305.43,309.05
115.1196,7.2585,-0.16257,32.701,300.0,-0.017561,22.016,300.01,305.39,308.88
115.7196,7.2802,-0.16223,32.544,300.0,-0.017615,22.087,300.06,305.39,308.94
116.3196,7.2672,-0.16187,32.66,300.0,-0.017635,22.041,300.01,305.35,308.8
116.9196,7.2853,-0.16216,32.704,300.0,-0.017522,22.103,299.96,305.31,308.83
117.5196,7.2705,-0.16445,32.467,300.0,-0.01789,22.053,300.07,305.4,308.93
118.1196,7.2884,-0.163,32.622,300.0,-0.017755,22.108,300.02,305.23,308.73
118.7196,7.2585,-0.16288,31.882,300.0,-0.017617,22.015,300.15,305.33,308.85
119.3196,7.2816,-0.16282,32.185,300.0,-0.017701,22.086,300.1,305.28,308.71
119.9196,7.2636,-0.16225,32.054,300.0,-0.017675,22.034,300.05,305.14,308.62
120.5196,7.2859,-0.16351,31.927,300.0,-0.017696,22.097,300.05,305.24,308.59
121.1196,7.2673,-0.16425,31.971,300.0,-0.017852,22.045,300.06,305.1,308.55
121.7196,7.2706,-0.16309,31.889,300.0,-0.017758,22.054,300.02,305.05,308.53
122.3196,7.2645,-0.16341,31.998,300.0,-0.017678,22.036,300.06,305.04,308.44
122.9196,7.276,-0.16286,31.872,300.0,-0.017704,22.068,300.15,305.26,308.7
123.5196,7.2725,-0.16282,31.695,300.0,-0.017728,22.063,300.12,305.13,308.5
124.1196,7.2788,-0.16599,31.802,300.0,-0.017956,22.076,300.13,305.06,308.45
124.7196,7.2611,-0.1634,31.881,300.0,-0.017756,22.029,300.01,305.04,308.42
125.3196,7.2669,-0.16347,31.889,300.0,-0.017777,22.041,300.05,305.0,308.37
125.91961,7.2653,-0.16378,31.904,300.0,-0.017731,22.044,300.03,304.93,308.31
126.51961,7.2788,-0.16305,31.354,300.0,-0.01772,22.075,300.14,305.06,308.45
127.11961,7.262,-0.16647,31.882,300.0,-0.018099,22.032,299.99,304.84,308.19
127.71961,7.2735,-0.16415,32.342,300.0,-0.017777,22.059,299.93,304.71,308.07
128.31961,7.2651,-0.16378,32.034,300.0,-0.017788,22.042,299.98,304.83,308.18
128.91961,7.2761,-0.16356,32.395,300.0,-0.017779,22.066,299.95,304.75,308.07
129.51961,7.261,-0.16361,32.037,300.0,-0.01772,22.028,300.0,304.7,308.11
130.11961,7.2766,-0.16423,32.334,300.0,-0.017843,22.068,299.94,304.73,308.05
130.71961,7.2687,-0.16562,31.774,300.0,-0.017978,22.051,300.08,304.75,308.18
131.31961,7.2671,-0.16432,31.907,300.0,-0.017804,22.038,300.04,304.72,308.05
131.91961,7.2733,-0.16414,32.314,300.0,-0.0178,22.068,299.97,304.66,307.95
132.51961,7.2702,-0.16387,31.93,300.0,-0.01777,22.048,300.02,304.7,308.05
133.11961,7.2731,-0.16396,32.04,300.0,-0.017758,22.068,299.99,304.66,308.0
133.71961,7.2698,-0.16567,31.89,300.0,-0.017974,22.046,300.0,304.64,307.95
134.31961,7.2773,-0.16539,32.073,300.0,-0.017906,22.077,299.96,304.52,308.0
134.91961,7.2645,-0.16458,31.936,300.0,-0.017833,22.031,300.03,304.66,307.94
135.51961,7.2738,-0.16436,31.879,300.0,-0.017795,22.069,300.01,304.63,307.97
136.11961,7.2724,-0.16419,31.882,300.0,-0.017783,22.056,300.05,304.69,308.0
136.71961,7.2761,-0.16406,32.015,300.0,-0.017779,22.078,300.0,304.53,307.93
137.31961,7.2857,-0.16631,31.94,300.0,-0.018022,22.095,299.98,304.54,307.88
137.91961,7.2756,-0.16556,31.633,300.0,-0.017923,22.072,300.05,304.61,307.93
138.51961,7.2559,-0.16487,31.755,300.0,-0.017868,22.008,300.05,304.58,307.93
138.9201,7.2538,-0.16469,31.452,300.0,-0.017917,22.009,300.09,304.64,307.89
139.5201,7.2776,-0.16479,31.873,300.0,-0.017785,22.073,300.0,304.49,307.84
140.1201,7.261,-0.16438,31.431,300.0,-0.017805,22.028,300.1,304.62,307.93
140.7201,7.2649,-0.16607,31.739,300.0,-0.018079,22.033,300.02,304.5,307.81
141.3201,7.2613,-0.16622,31.649,300.0,-0.017932,22.028,300.01,304.5,307.76
141.9201,7.2769,-0.16485,31.596,300.0,-0.017861,22.069,300.05,304.6,307.86
142.5201,7.2718,-0.16496,31.665,300.0,-0.017964,22.062,300.02,304.42,307.73
143.1201,7.271,-0.1649,31.741,300.0,-0.017802,22.05,300.02,304.46,307.75
143.7201,7.2685,-0.16464,31.279,300.0,-0.017849,22.054,300.06,304.46,307.69
144.3201,7.2619,-0.16725,31.924,300.0,-0.018181,22.024,299.99,304.34,307.58
144.9201,7.2606,-0.16546,31.885,300.0,-0.017864,22.029,299.91,304.35,307.57
145.2861,7.229,0.011947,0.0,236.25,0.0014174,21.928,300.05,304.53,307.76
145.2891,7.3088,0.01268,0.0,0.01946,0.0010092,22.216,300.07,304.53,307.76
145.2921,7.2175,0.013784,0.0,1.5862e-06,0.00093455,21.854,300.09,304.53,307.75
145.2951,7.2803,0.011658,0.0,1.2928e-10,0.00094088,22.135,300.1,304.53,307.74
145.2981,7.2379,0.010269,0.0,1.0536e-14,0.001229,21.925,300.09,304.5,307.73
145.3011,7.2522,0.0095162,0.0,8.587300000000001e-19,0.0015507,22.036,300.07,304.47,307.72
145.3041,7.2559,0.010121,0.0,6.963099999999999e-23,0.0014582,21.975,300.05,304.45,307.71
145.3071,7.2216,0.011519,0.0,5.6748e-27,0.0012164,21.942,300.05,304.43,307.7
145.3101,7.2748,0.012998,0.0,4.6248e-31,0.0012972,22.049,300.07,304.43,307.69
145.3131,7.2019,0.011703,0.0,3.7689000000000004e-35,0.0015473,21.886,300.09,304.43,307.68
145.3161,7.2952,0.011051,0.0,3.0714e-39,0.0013796,22.099,300.1,304.44,307.68
145.3191,7.1732,0.011882,0.0,2.5082999999999998e-43,0.00091193,21.786,300.1,304.47,307.69
145.3221,7.3003,0.01192,0.0,0.0,0.00071219,22.141,300.09,304.49,307.69
145.3251,7.1559,0.011778,0.0,0.0,0.0010223,21.716,300.08,304.52,307.7
145.3281,7.3017,0.010659,0.0,0.0,0.0013959,22.14,300.05,304.55,307.71
145.3311,7.1473,0.0095255,0.0,0.0,0.0015311,21.684,300.01,304.57,307.72
145.3341,7.2976,0.0096018,0.0,0.0,0.0014037,22.155,299.97,304.6,307.73
145.3371,7.1637,0.012164,0.0,0.0,0.0013112,21.721,299.94,304.6,307.72
145.3401,7.2844,0.01203,0.0,0.0,0.001233,22.126,299.93,304.56,307.7
145.3431,7.1848,0.010882,0.0,0.0,0.0014542,21.774,299.91,304.53,307.67
145.3461,7.2224,0.01053,0.0,0.0,0.0013262,21.944,299.94,304.55,307.63
145.3491,7.2214,0.012888,0.0,0.0,0.00095222,21.883,300.39,305.03,307.55
145.3521,18.612,0.036488,0.0,0.0,0.0037217,54.921,300.84,305.5,307.47
145.35509,35.103,0.25437,0.0,0.0,0.027444,105.93,301.29,305.98,307.39
145.35809,40.742,0.49855,0.0,0.0,0.055541,123.28,302.5,306.86,307.31
145.36109,43.346,0.76931,0.0,0.0,0.087375,131.43,303.92,307.87,307.22
145.36409,44.58,1.0364,0.0,0.0,0.11922,135.2,305.35,308.87,307.14
145.36709,45.165,1.2863,0.0,0.0,0.14977,136.96,307.02,309.87,307.09
145.37009,45.411,1.5247,0.0,0.0,0.18011,137.71,309.0,310.85,307.09
145.37309,45.688,1.756,0.0,0.0,0.21072,138.6,310.98,311.84,307.09
145.37609,45.921,1.9842,0.0,0.0,0.24115,139.26,312.95,312.83,307.1
145.37909,46.215,2.2197,0.0,0.0,0.27294,140.19,314.67,313.87,307.14
145.38209,46.467,2.459,0.0,0.0,0.30697,140.92,316.4,314.92,307.19
145.38509,46.732,2.6951,0.0,0.0,0.34229,141.75,318.12,315.96,307.23
145.38809,46.958,2.9212,0.0,0.0,0.37736,142.42,319.43,317.04,307.26
145.39109,47.169,3.1427,0.0,0.0,0.41223,143.08,320.58,318.15,307.28
145.39409,47.353,3.3501,0.0,0.0,0.44498,143.61,321.73,319.25,307.3
145.39709,47.513,3.5453,0.0,0.0,0.477,144.13,322.71,320.33,307.33
145.40009,47.696,3.7321,0.0,0.0,0.5095,144.65,323.42,321.36,307.37
145.40309,47.88,3.9112,0.0,0.0,0.5416,145.24,324.13,322.39,307.42
145.40609,48.109,4.091,0.0,0.0,0.57376,145.91,324.83,323.41,307.46
145.40909,48.285,4.2679,0.0,0.0,0.60571,146.45,325.42,324.15,307.55
145.41209,48.484,4.4413,0.0,0.0,0.63923,147.05,326.0,324.88,307.63
145.41509,48.588,4.6106,0.0,0.0,0.67393,147.36,326.58,325.62,307.71
145.41809,48.733,4.7691,0.0,0.0,0.70788,147.8,327.06,326.18,307.77
145.42109,48.832,4.9298,0.0,0.0,0.74152,148.14,327.5,326.65,307.83
145.42409,48.963,5.088,0.0,0.0,0.7748,148.52,327.94,327.12,307.88
145.42709,48.977,5.2381,0.0,0.0,0.80795,148.57,328.31,327.53,307.94
145.43009,49.085,5.3801,0.0,0.0,0.84188,148.89,328.56,327.82,308.02
145.43309,49.133,5.52,0.0,0.0,0.87587,149.03,328.8,328.12,308.09
145.43609,49.278,5.6616,0.0,0.0,0.90952,149.47,329.05,328.41,308.16
145.43909,49.313,5.8009,0.0,0.0,0.94359,149.59,329.32,328.49,308.26
145.44209,49.384,5.9353,0.0,0.0,0.97915,149.8,329.59,328.57,308.35
145.44509,49.391,6.0639,0.0,0.0,1.0158,149.81,329.87,328.65,308.44
145.44809,49.424,6.1864,0.0,0.0,1.0515,149.91,330.11,328.64,308.54
145.45109,49.46,6.3082,0.0,0.0,1.0864,150.01,330.32,328.58,308.65
145.45409,49.535,6.4276,0.0,0.0,1.1201,150.26,330.54,328.51,308.76
145.45709,49.589,6.5433,0.0,0.0,1.1553,150.38,330.72,328.46,308.87
145.46009,49.653,6.6555,0.0,0.0,1.193,150.62,330.8,328.41,308.98
145.46309,49.682,6.7652,0.0,0.0,1.2296,150.69,330.88,328.36,309.09
145.46609,49.774,6.8733,0.0,0.0,1.264,150.97,330.97,328.32,309.2
145.46909,49.923,6.9767,0.0,0.0,1.2987,151.41,330.82,328.27,309.29
145.47209,50.032,7.076,0.0,0.0,1.3357,151.76,330.67,328.23,309.38
145.47509,50.198,7.1706,0.0,0.0,1.3736,152.24,330.51,328.18,309.47
145.47809,50.321,7.2637,0.0,0.0,1.4119,152.63,330.16,328.09,309.57
145.48109,50.497,7.3576,0.0,0.0,1.448,153.16,329.67,327.97,309.66
145.48409,50.649,7.4486,0.0,0.0,1.4836,153.64,329.19,327.86,309.75
145.48709,50.827,7.5378,0.0,0.0,1.5215,154.18,328.66,327.72,309.84
145.49009,50.939,7.6215,0.0,0.0,1.5617,154.52,328.01,327.55,309.92
145.49308,51.187,7.7018,0.0,0.0,1.5988,155.27,327.35,327.38,310.0
145.49608,51.379,7.7837,0.0,0.0,1.6345,155.83,326.7,327.2,310.08
145.49908,50.539,7.8531,0.0,0.0,1.6672,153.68,325.52,327.06,310.17
145.50208,47.807,7.8521,0.0,0.0,1.6685,145.18,324.29,326.93,310.25
145.50508,46.381,7.8527,0.0,0.0,1.6723,140.72,323.06,326.79,310.33
145.50808,45.475,7.8562,0.0,0.0,1.6756,137.97,321.61,326.69,310.43
145.51108,45.038,7.8585,0.0,0.0,1.6745,136.62,320.0,326.6,310.54
145.51408,44.791,7.8658,0.0,0.0,1.6757,135.87,318.38,326.52,310.65
145.51708,44.708,7.8716,0.0,0.0,1.679,135.61,316.83,326.43,310.75
145.52008,44.61,7.8745,0.0,0.0,1.6836,135.31,315.51,326.32,310.84
145.52308,44.342,7.8784,0.0,0.0,1.6851,134.53,314.18,326.22,310.94
145.52608,42.849,7.8786,0.0,0.0,1.6811,130.11,312.86,326.11,311.03
145.52908,39.252,7.8759,0.0,0.0,1.6791,119.35,311.95,325.95,311.08
145.53208,32.387,7.8673,0.0,0.0,1.6766,99.155,311.1,325.79,311.12
145.53508,4.9199,7.7854,0.0,0.0,1.6399,15.37,310.25,325.62,311.17
145.53808,5.6246,7.7929,0.0,0.0,1.6447,17.083,309.75,325.45,311.21
145.54108,6.2429,7.7937,0.0,0.0,1.6422,18.862,309.58,325.28,311.23
145.54408,6.3224,7.7944,0.0,0.0,1.6404,19.123,309.41,325.11,311.26
145.54708,6.2991,7.7965,0.0,0.0,1.6424,19.14,309.29,324.94,311.3
145.55008,6.2678,7.7947,0.0,0.0,1.6442,18.962,309.45,324.78,311.4
145.55308,6.1931,7.795,0.0,0.0,1.6429,18.83,309.6,324.63,311.5
145.55608,6.3196,7.7964,0.0,0.0,1.6403,19.146,309.76,324.47,311.6
145.55908,6.1689,7.7962,0.0,0.0,1.6395,18.723,309.79,324.36,311.72
145.56208,6.2975,7.7949,0.0,0.0,1.6418,19.117,309.8,324.25,311.84
145.56508,6.1647,7.7915,0.0,0.0,1.6432,18.718,309.81,324.14,311.96
145.56808,6.2662,7.7925,0.0,0.0,1.6435,19.021,309.77,324.02,312.06
145.57108,6.1612,7.7935,0.0,0.0,1.6416,18.672,309.68,323.91,312.14
145.57408,6.28,7.7968,0.0,0.0,1.6418,19.084,309.59,323.79,312.22
145.57708,6.1737,7.7959,0.0,0.0,1.6425,18.708,309.49,323.66,312.3
145.58008,6.3052,7.7978,0.0,0.0,1.6458,19.123,309.31,323.49,312.39
145.58308,6.1994,7.7949,0.0,0.0,1.6425,18.761,309.14,323.31,312.47
145.58608,6.2353,7.797,0.0,0.0,1.6402,18.977,308.96,323.14,312.55
145.58908,6.2539,7.7973,0.0,0.0,1.6402,18.936,308.74,322.98,312.61
145.59208,6.196,7.797,0.0,0.0,1.6431,18.846,308.5,322.83,312.67
145.59508,6.3089,7.7939,0.0,0.0,1.6445,19.094,308.27,322.67,312.72
145.59808,6.2082,7.794,0.0,0.0,1.6442,18.85,308.02,322.51,312.78
145.60108,6.339,7.7974,0.0,0.0,1.6427,19.213,307.78,322.35,312.84
145.60408,6.1868,7.7993,0.0,0.0,1.6427,18.795,307.53,322.19,312.91
145.60708,6.3117,7.7977,0.0,0.0,1.644,19.153,307.28,322.03,312.97
145.61008,6.2184,7.7974,0.0,0.0,1.6454,18.855,306.98,321.89,313.05
145.61308,6.3396,7.7968,0.0,0.0,1.643,19.221,306.68,321.75,313.12
145.61608,6.2122,7.7981,0.0,0.0,1.6405,18.834,306.37,321.62,313.19
145.61908,6.2972,7.7974,0.0,0.0,1.6407,19.125,306.07,321.5,313.27
145.62208,6.2572,7.7963,0.0,0.0,1.6434,18.99,305.75,321.39,313.34
145.62508,6.3585,7.7951,0.0,0.0,1.6455,19.296,305.44,321.28,313.41
145.62808,6.3616,7.7952,0.0,0.0,1.6449,19.275,305.13,321.16,313.48
145.63107,6.5548,7.7982,0.0,0.0,1.6426,19.916,304.8,321.02,313.54
145.63407,6.4713,7.8011,0.0,0.0,1.6435,19.566,304.47,320.89,313.61
145.63707,6.582,7.7994,0.0,0.0,1.6461,19.985,304.14,320.75,313.67
145.64007,6.5106,7.7977,0.0,0.0,1.6456,19.701,303.83,320.61,313.7
145.64307,6.5668,7.8006,0.0,0.0,1.6443,19.945,303.52,320.48,313.73
145.64607,6.5276,7.8005,0.0,0.0,1.6417,19.731,303.21,320.34,313.75
145.64907,6.5568,7.8003,0.0,0.0,1.6427,19.94,302.91,320.2,313.78
145.65207,6.535,7.796,0.0,0.0,1.644,19.751,302.63,320.05,313.81
145.65507,6.5157,7.7934,0.0,0.0,1.6448,19.851,302.34,319.91,313.83
145.65807,6.585,7.7958,0.0,0.0,1.6445,19.93,302.06,319.77,313.87
145.66107,6.49,7.7991,0.0,0.0,1.6431,19.764,301.76,319.64,313.91
145.66407,6.6064,7.8006,0.0,0.0,1.6439,19.999,301.47,319.51,313.96
145.66707,6.4672,7.8,0.0,0.0,1.6463,19.644,301.18,319.38,314.01
145.67007,6.6512,7.801,0.0,0.0,1.6472,20.146,300.88,319.24,314.05
145.67307,6.4723,7.8005,0.0,0.0,1.6435,19.668,300.59,319.09,314.1
145.67607,6.6609,7.8027,0.0,0.0,1.6421,20.198,300.3,318.95,314.14
145.67907,6.4617,7.802,0.0,0.0,1.6439,19.599,299.98,318.78,314.18
145.68207,6.6812,7.8002,0.0,0.0,1.6467,20.254,299.66,318.61,314.2
145.68507,6.4651,7.7965,0.0,0.0,1.646,19.609,299.34,318.43,314.23
145.68807,6.6678,7.7984,0.0,0.0,1.6453,20.264,299.02,318.28,314.26
145.69107,6.4899,7.7997,0.0,0.0,1.6434,19.642,298.69,318.16,314.29
145.69407,6.644,7.8011,0.0,0.0,1.6442,20.201,298.36,318.04,314.31
145.69707,6.5228,7.7982,0.0,0.0,1.6458,19.726,298.03,317.92,314.34
145.70007,6.6164,7.7998,0.0,0.0,1.6462,20.126,297.76,317.82,314.36
145.70307,6.5602,7.7991,0.0,0.0,1.6423,19.853,297.49,317.72,314.38
145.70607,6.5709,7.8024,0.0,0.0,1.6421,20.017,297.23,317.62,314.4
145.70907,6.5955,7.8014,0.0,0.0,1.6438,19.956,296.96,317.47,314.44
145.71207,6.5349,7.7991,0.0,0.0,1.6463,19.884,296.69,317.29,314.49
145.71507,6.6382,7.7983,0.0,0.0,1.6465,20.091,296.43,317.1,314.55
145.71807,6.5067,7.8005,0.0,0.0,1.6457,19.8,296.15,316.92,314.6
145.72107,6.6652,7.8039,0.0,0.0,1.6449,20.171,295.86,316.76,314.63
145.72407,6.4915,7.8046,0.0,0.0,1.6464,19.74,295.57,316.6,314.67
145.72707,6.6913,7.8029,0.0,0.0,1.6478,20.264,295.27,316.43,314.71
145.73007,6.4798,7.801,0.0,0.0,1.6465,19.684,295.02,316.35,314.71
145.73307,6.7016,7.8048,0.0,0.0,1.6444,20.31,294.78,316.28,314.71
145.73607,6.4971,7.8035,0.0,0.0,1.6431,19.701,294.53,316.21,314.71
145.73907,6.6954,7.8026,0.0,0.0,1.6454,20.32,294.29,316.12,314.72
145.74207,6.5259,7.7984,0.0,0.0,1.6466,19.77,294.05,316.02,314.75
145.74507,6.7009,7.8015,0.0,0.0,1.6482,20.356,293.81,315.92,314.78
145.74807,6.5474,7.8037,0.0,0.0,1.6466,19.817,293.57,315.81,314.8
145.75107,6.6706,7.8047,0.0,0.0,1.6452,20.291,293.33,315.69,314.79
145.75407,6.5881,7.8025,0.0,0.0,1.6458,19.931,293.09,315.57,314.78
145.75707,6.6411,7.8026,0.0,0.0,1.6479,20.217,292.85,315.45,314.77
145.76007,6.6277,7.8028,0.0,0.0,1.6465,20.063,292.6,315.34,314.81
145.76307,6.6177,7.8052,0.0,0.0,1.6442,20.143,292.34,315.23,314.86
145.76607,6.6424,7.8042,0.0,0.0,1.6438,20.097,292.09,315.13,314.9
145.76906,6.5573,7.8027,0.0,0.0,1.6461,19.946,291.82,315.0,314.93
145.77206,6.6818,7.8006,0.0,0.0,1.6479,20.221,291.54,314.86,314.95
145.77506,6.5343,7.7991,0.0,0.0,1.6467,19.866,291.27,314.73,314.97
145.77806,6.7073,7.8032,0.0,0.0,1.6457,20.289,291.0,314.59,314.98
145.78106,6.5333,7.8041,0.0,0.0,1.6453,19.835,290.78,314.47,314.94
145.78406,6.7226,7.8061,0.0,0.0,1.6483,20.358,290.56,314.36,314.9
145.78706,6.5344,7.8016,0.0,0.0,1.6477,19.813,290.34,314.24,314.87
145.79006,6.7409,7.8046,0.0,0.0,1.6468,20.454,290.14,314.12,314.87
145.79306,6.5401,7.8038,0.0,0.0,1.6435,19.822,289.94,314.0,314.88
145.79606,6.7431,7.806,0.0,0.0,1.6444,20.468,289.74,313.88,314.89
145.79906,6.572,7.8041,0.0,0.0,1.6472,19.91,289.52,313.77,314.89
145.80206,6.7184,7.8037,0.0,0.0,1.6495,20.426,289.29,313.66,314.89
145.80506,6.5862,7.8024,0.0,0.0,1.648,19.927,289.06,313.55,314.89
145.80806,6.7045,7.8064,0.0,0.0,1.6471,20.396,288.84,313.44,314.89
145.81106,6.6186,7.8054,0.0,0.0,1.646,20.034,288.63,313.33,314.87
145.81406,6.6648,7.8058,0.0,0.0,1.6486,20.3,288.43,313.22,314.85
145.81706,6.6656,7.804,0.0,0.0,1.6483,20.141,288.23,313.11,314.83
145.82006,6.62,7.8045,0.0,0.0,1.6463,20.142,288.03,312.98,314.85
145.82306,6.7068,7.8062,0.0,0.0,1.6443,20.294,287.84,312.84,314.86
145.82606,6.5917,7.8055,0.0,0.0,1.6448,20.071,287.65,312.7,314.88
145.82906,6.7338,7.8028,0.0,0.0,1.6469,20.386,287.46,312.58,314.91
145.83206,6.5731,7.8,0.0,0.0,1.6477,19.983,287.29,312.48,314.96
145.83506,6.7607,7.8022,0.0,0.0,1.6472,20.456,287.11,312.38,315.0
145.83806,6.5549,7.8042,0.0,0.0,1.6456,19.915,286.94,312.28,315.05
145.84106,6.7781,7.8061,0.0,0.0,1.6463,20.539,286.76,312.2,315.07
145.84406,6.5649,7.8041,0.0,0.0,1.6481,19.897,286.59,312.12,315.08
145.84706,6.773,7.8043,0.0,0.0,1.6485,20.555,286.41,312.04,315.1
145.85006,6.5784,7.8062,0.0,0.0,1.646,19.924,286.22,311.94,315.11
145.85306,6.7639,7.8071,0.0,0.0,1.6443,20.546,286.03,311.84,315.12
145.85606,6.5998,7.8052,0.0,0.0,1.6445,19.985,285.84,311.74,315.13
145.85906,6.7473,7.8055,0.0,0.0,1.6487,20.521,285.63,311.63,315.12
145.86206,6.6512,7.8022,0.0,0.0,1.649,20.135,285.42,311.52,315.1
145.86506,6.7096,7.8042,0.0,0.0,1.6482,20.429,285.21,311.42,315.07
145.86806,6.6891,7.8061,0.0,0.0,1.6463,20.25,285.0,311.31,315.04
145.87106,6.6803,7.8059,0.0,0.0,1.6468,20.329,284.81,311.22,315.01
145.87406,6.7212,7.8038,0.0,0.0,1.6484,20.344,284.61,311.12,314.97
145.87706,6.6593,7.804,0.0,0.0,1.6484,20.257,284.42,311.03,314.93
145.88006,6.7594,7.8061,0.0,0.0,1.6455,20.44,284.25,310.93,314.92
145.88306,6.6284,7.8076,0.0,0.0,1.6447,20.143,284.09,310.83,314.92
145.88606,6.79,7.8045,0.0,0.0,1.6452,20.555,283.94,310.73,314.92
145.88906,6.6106,7.8036,0.0,0.0,1.6481,20.077,283.78,310.63,314.92
145.89206,6.808,7.8027,0.0,0.0,1.6487,20.633,283.62,310.52,314.9
145.89506,6.6171,7.8038,0.0,0.0,1.6473,20.069,283.47,310.41,314.88
145.89806,6.8211,7.8056,0.0,0.0,1.6457,20.683,283.31,310.3,314.86
145.90106,6.6216,7.8052,0.0,0.0,1.6468,20.083,283.15,310.21,314.84
145.90406,6.819,7.8057,0.0,0.0,1.6495,20.698,283.0,310.12,314.82
145.90705,6.6311,7.8051,0.0,0.0,1.6487,20.088,282.84,310.03,314.81
145.91005,6.7953,7.8073,0.0,0.0,1.6462,20.655,282.7,309.94,314.81
145.91305,6.6599,7.8088,0.0,0.0,1.6457,20.161,282.56,309.86,314.82
145.91605,6.782,7.8076,0.0,0.0,1.6474,20.617,282.42,309.78,314.82
146.1176,6.6793,7.8062,0.0,0.0,1.6477,20.259,276.47,305.61,311.37
146.7176,6.5359,7.8094,0.0,0.0,1.6493,19.825,255.3,267.68,223.7
147.3176,6.447,7.8138,0.0,0.0,1.6515,19.556,231.34,220.4,182.95
147.9176,6.4172,7.8144,0.0,0.0,1.6517,19.465,198.57,116.62,157.29
148.5176,6.4117,7.8238,0.0,0.0,1.6564,19.449,149.69,62.333,104.93
149.0602,6.4126,7.8332,0.0,0.0,1.661,19.45,113.09,44.198,53.971
149.6602,6.3997,7.8452,0.0,0.0,1.6672,19.416,76.614,37.834,34.764
150.2602,6.4024,7.854,0.0,0.0,1.6714,19.418,59.016,28.947,28.152
150.8602,6.38,7.8607,0.0,0.0,1.6748,19.357,48.842,26.434,25.76
151.4602,6.383,7.866,0.0,0.0,1.6777,19.361,42.35,24.57,23.864
152.0602,6.3634,7.8707,0.0,0.0,1.6797,19.308,37.638,23.537,22.925
152.6602,6.3541,7.8744,0.0,0.0,1.6817,19.271,34.663,22.89,22.558
153.2602,6.3342,7.878,0.0,0.0,1.6838,19.218,32.259,22.23,21.916
153.8602,6.3274,7.8809,0.0,0.0,1.6848,19.191,30.248,21.757,21.51
154.4602,6.3229,7.8839,0.0,0.0,1.6866,19.182,28.672,21.307,21.16
155.0602,6.3302,7.8865,0.0,0.0,1.6881,19.202,27.493,21.033,21.065
155.6602,6.328,7.8893,0.0,0.0,1.689,19.198,26.135,20.597,20.573
156.2602,6.331,7.8916,0.0,0.0,1.6906,19.201,25.262,20.564,20.565
156.8602,6.3266,7.8934,0.0,0.0,1.6916,19.197,24.459,20.36,20.492
157.4602,6.3311,7.8952,0.0,0.0,1.692,19.201,23.874,20.22,20.445
157.9331,6.3331,7.8964,0.0,0.0,1.6933,19.211,23.403,20.176,20.259
158.5331,6.3275,7.8985,0.0,0.0,1.6941,19.191,22.875,20.054,20.24
159.1331,6.336,7.8999,0.0,0.0,1.6943,19.222,22.494,19.944,20.146
159.7331,6.3298,7.9008,0.0,0.0,1.6956,19.201,22.029,19.843,20.069
160.3331,6.333,7.902,0.0,0.0,1.6959,19.214,21.733,19.837,20.017
160.9331,6.3345,7.9038,0.0,0.0,1.6962,19.215,21.22,19.56,19.814
161.5331,6.3291,7.9046,0.0,0.0,1.6975,19.2,21.008,19.559,19.768
162.1331,6.3253,7.9059,0.0,0.0,1.698,19.187,20.935,19.74,19.901
162.7331,6.3374,7.9071,0.0,0.0,1.6979,19.225,20.664,19.435,19.698
163.3331,6.3253,7.9072,0.0,0.0,1.6988,19.186,20.487,19.22,19.633
163.9331,6.3424,7.9083,0.0,0.0,1.6992,19.237,20.584,19.32,19.784
164.5331,6.3263,7.9088,0.0,0.0,1.6988,19.192,20.583,19.229,19.823
165.1331,6.3455,7.9088,0.0,0.0,1.6996,19.247,20.732,19.328,19.874
165.7331,6.33,7.9091,0.0,0.0,1.6996,19.201,20.837,19.439,19.963
166.3331,6.334,7.9094,0.0,0.0,1.6991,19.212,20.924,19.557,20.089
166.9331,6.3294,7.9096,0.0,0.0,1.7,19.204,21.051,19.649,20.122
167.5331,6.3377,7.9101,0.0,0.0,1.7002,19.223,21.095,19.829,20.327
168.1331,6.3255,7.91,0.0,0.0,1.6994,19.189,21.132,19.922,20.385
168.7331,6.3297,7.9101,0.0,0.0,1.7002,19.199,21.221,19.994,20.58
169.3331,6.3394,7.9106,0.0,0.0,1.7004,19.232,21.214,20.077,20.562
169.9331,6.3246,7.9108,0.0,0.0,1.6999,19.187,21.229,20.071,20.606
170.5331,6.3283,7.9107,0.0,0.0,1.7005,19.197,21.203,20.105,20.64
171.1331,6.3351,7.9109,0.0,0.0,1.7006,19.217,20.978,19.923,20.482
171.7331,6.3298,7.9111,0.0,0.0,1.7,19.203,20.949,19.941,20.45
172.3331,6.3336,7.9109,0.0,0.0,1.7006,19.212,20.927,19.943,20.473
172.9331,6.334,7.9112,0.0,0.0,1.7008,19.218,20.826,19.909,20.439
173.5331,6.3256,7.9114,0.0,0.0,1.7002,19.186,20.878,19.97,20.458
174.1331,6.3261,7.9112,0.0,0.0,1.7008,19.194,20.776,19.969,20.41
174.7331,6.3209,7.9112,0.0,0.0,1.7008,19.171,20.745,20.054,20.464
175.3331,6.3341,7.9115,0.0,0.0,1.7003,19.217,20.704,20.027,20.365
175.9331,6.3641,7.9115,0.0,0.0,1.7008,19.3,20.663,19.956,20.412
176.53311,6.42,7.9112,0.0,0.0,1.7007,19.475,20.734,20.296,20.602
177.13311,6.3568,7.9116,0.0,0.0,1.7003,19.279,20.817,20.506,20.852
177.73311,6.3265,7.9109,0.0,0.0,1.7005,19.192,20.946,20.646,20.927
178.33311,6.3803,7.9115,0.0,0.0,1.7009,19.353,20.962,20.78,21.039
178.93311,6.268,7.9108,0.0,0.0,1.6999,19.015,20.987,20.75,21.042
179.53311,6.2993,7.91,0.0,0.0,1.7,19.11,21.091,20.956,21.241
180.13311,6.251,7.9116,0.0,0.0,1.701,18.963,21.259,21.181,21.498
180.73311,6.2529,7.9121,0.0,0.0,1.7007,18.968,21.19,21.179,21.454
181.33311,6.1568,7.9111,0.0,0.0,1.7002,18.678,21.202,21.23,21.496
181.93311,6.1075,7.9102,0.0,0.0,1.7001,18.529,21.465,21.448,21.659
182.53311,6.0688,7.9105,0.0,0.0,1.7004,18.411,21.563,21.639,21.853
182.73311,5.2939,7.9061,0.0,0.0,1.6975,16.063,21.422,21.526,21.753