File: examples/dan-msc-case-studies/CS4/data/01 raw data/hyde_test_035.csv
Time(sec),Force(kN),Jaw(mm),PowAngle(deg),PTemp,Strain,Stress(MPa),Stroke(mm),TC1(C),TC2(C),TC3(C),wedge(mm)
0.0,3.3405,0.22392,0.0,0.0048042,0.024756,10.151,22.872,23.178,23.298,23.018,-7.661
2.0,3.2758,0.00027108,0.0,5.8208,5.108e-05,9.9374,22.873,23.203,23.355,23.087,-7.7812
4.0,3.2225,-5.5596e-05,0.0,11.821,-7.9215e-06,9.7787,22.873,23.156,23.426,23.082,-7.7801
6.0,3.2128,-0.00042854,0.0,17.821,-1.8777e-05,9.747,22.873,23.229,23.332,22.991,-7.7797
8.0,3.1966,-0.00025622,6.4761,23.821,-1.8552e-05,9.7005,22.873,23.191,23.35,23.06,-7.7801
10.0,3.2091,-0.00077495,33.283,29.821,-6.4309e-05,9.7333,22.873,27.175,25.291,26.346,-7.7794
12.0,3.2099,-0.0031138,33.588,35.821,-0.00032497,9.7396,22.874,34.56,37.359,32.996,-7.778
14.0,3.2205,-0.0044038,29.013,41.821,-0.00046678,9.7687,22.873,42.135,38.13,40.237,-7.7776
16.0,3.2142,-0.006189,30.769,47.844,-0.00064381,9.7572,22.873,47.777,43.998,45.742,-7.7766
17.8536,3.2316,-0.0081934,31.779,53.382,-0.00087205,9.8026,22.873,53.253,49.458,51.155,-7.7763
19.8536,3.238,-0.010195,31.88,59.382,-0.0010988,9.8264,22.873,59.3,55.296,57.045,-7.7761
21.8536,3.24,-0.011703,31.882,65.382,-0.0012712,9.8284,22.874,65.293,61.305,62.967,-7.7753
23.8536,3.2455,-0.014,32.086,71.382,-0.0015233,9.849,22.874,71.361,67.272,69.074,-7.7748
25.8536,3.2598,-0.016169,31.991,77.382,-0.0017521,9.8892,22.874,77.398,73.425,75.007,-7.7745
27.8536,3.2613,-0.018307,32.001,83.382,-0.002007,9.8987,22.873,83.407,79.449,81.055,-7.7737
29.8536,3.2757,-0.021183,32.478,89.382,-0.0023095,9.9338,22.873,89.393,85.707,87.074,-7.7734
31.8536,3.2767,-0.023096,32.371,95.382,-0.0025257,9.944,22.873,95.384,91.919,93.086,-7.7727
33.8536,3.2911,-0.025853,32.459,101.38,-0.0028045,9.9809,22.873,101.41,98.169,99.191,-7.7725
35.8536,3.2982,-0.02755,32.479,107.38,-0.0030178,10.009,22.873,107.41,104.37,105.24,-7.7719
37.8536,3.2938,-0.030385,32.586,113.38,-0.0033204,9.9915,22.873,113.36,110.43,111.09,-7.7712
39.7143,3.3051,-0.032837,32.709,118.96,-0.0035824,10.029,22.873,118.99,116.26,116.76,-7.7709
41.659,3.3075,-0.035629,33.397,124.8,-0.0038876,10.037,22.873,124.67,122.29,122.39,-7.7704
43.659,3.3136,-0.038627,32.936,130.8,-0.0042119,10.051,22.873,130.77,128.52,128.54,-7.7696
45.659,3.3172,-0.041913,33.093,136.8,-0.0045697,10.065,22.873,136.78,134.68,134.54,-7.7692
47.659,3.3217,-0.044522,33.005,142.8,-0.0048358,10.075,22.873,142.79,140.91,140.47,-7.7688
49.659,3.3242,-0.047734,33.114,148.8,-0.0052117,10.088,22.872,148.81,146.91,146.46,-7.7683
51.659,3.3244,-0.051287,33.188,154.8,-0.0055775,10.081,22.873,154.83,153.07,152.38,-7.7677
53.659,3.334,-0.055501,33.157,160.8,-0.0060753,10.116,22.873,160.86,159.37,158.41,-7.7691
55.659,3.3195,-0.057993,33.271,166.8,-0.0063045,10.069,22.873,166.88,165.52,164.34,-7.7682
57.659,3.3142,-0.060976,33.396,172.8,-0.006662,10.058,22.874,172.87,171.58,170.3,-7.7677
59.659,3.3258,-0.064106,33.769,178.8,-0.006987,10.087,22.874,178.83,177.59,176.22,-7.7666
61.659,3.328,-0.068439,33.489,184.8,-0.0074823,10.098,22.874,184.9,183.74,182.26,-7.7664
63.5597,3.3339,-0.07321,33.952,190.5,-0.0079697,10.114,22.873,190.48,189.48,187.84,-7.7664
65.5597,3.3216,-0.07498,33.802,196.5,-0.0081631,10.076,22.874,196.48,195.53,193.87,-7.7654
67.5597,3.3289,-0.0784,33.833,202.5,-0.0085363,10.095,22.872,202.5,201.45,199.88,-7.7649
69.5597,3.3227,-0.081654,34.107,208.5,-0.0089022,10.079,22.873,208.48,207.2,205.69,-7.7646
71.5597,3.332,-0.085062,33.796,214.5,-0.0092501,10.105,22.874,214.54,212.99,211.72,-7.7639
73.4484,3.3297,-0.089319,33.767,220.17,-0.0097415,10.099,22.873,220.2,218.6,217.36,-7.7637
75.4484,3.3344,-0.093689,33.733,226.17,-0.010219,10.117,22.873,226.16,224.34,223.27,-7.7629
77.4484,3.3293,-0.095828,33.729,232.17,-0.010477,10.099,22.874,232.15,230.02,229.11,-7.7623
79.4484,3.3444,-0.098283,33.523,238.17,-0.010712,10.147,22.874,238.19,235.73,235.07,-7.7622
81.4484,3.3306,-0.10196,33.518,244.17,-0.011118,10.102,22.873,244.27,241.48,241.07,-7.7617
83.4484,3.3361,-0.10576,34.02,250.17,-0.011518,10.123,22.873,250.15,247.27,246.95,-7.7613
85.4484,3.3286,-0.10965,33.917,256.17,-0.011944,10.097,22.873,256.19,253.05,252.9,-7.7608
87.3177,3.3339,-0.11353,33.865,261.77,-0.012337,10.116,22.873,261.82,258.48,258.49,-7.7603
89.3177,3.3375,-0.11968,33.926,267.77,-0.013044,10.124,22.873,267.82,264.39,264.63,-7.7598
91.3177,3.3431,-0.12049,34.178,273.77,-0.01309,10.142,22.873,273.83,270.35,270.49,-7.7596
93.3177,3.3297,-0.12441,34.311,279.77,-0.013545,10.1,22.874,279.78,276.19,276.44,-7.7589
95.3177,3.348,-0.13027,34.233,285.77,-0.014138,10.158,22.873,285.8,282.09,282.46,-7.7584
97.3177,3.3372,-0.13184,34.203,291.77,-0.014363,10.124,22.874,291.83,287.95,288.3,-7.758
99.3177,3.3387,-0.13628,34.553,297.77,-0.014817,10.13,22.873,297.74,293.73,294.12,-7.7577
101.3177,3.344,-0.14118,34.019,303.77,-0.015392,10.144,22.873,303.77,299.52,299.92,-7.7572
103.3177,3.3431,-0.14381,33.772,309.77,-0.015632,10.143,22.873,309.85,305.2,305.79,-7.7565
105.3177,3.3354,-0.14872,33.695,315.77,-0.016169,10.117,22.873,315.91,311.28,311.49,-7.756
107.3177,3.3427,-0.15107,34.17,321.77,-0.016414,10.142,22.874,321.73,317.54,316.67,-7.7555
109.1687,3.3322,-0.15499,33.777,327.34,-0.01683,10.112,22.873,327.34,322.57,321.77,-7.755
111.1687,3.3507,-0.1584,33.954,333.33,-0.017214,10.165,22.872,333.34,328.28,327.65,-7.7544
113.1687,3.3359,-0.16259,33.99,339.33,-0.017655,10.121,22.874,339.37,334.0,333.45,-7.754
115.1687,3.3498,-0.16886,33.779,345.33,-0.018349,10.164,22.873,345.38,339.7,339.22,-7.7533
117.1687,3.3391,-0.16959,33.803,351.33,-0.018429,10.131,22.873,351.41,345.55,344.86,-7.7526
119.1687,3.3396,-0.17405,33.785,357.33,-0.018882,10.131,22.873,357.41,351.44,350.61,-7.752
121.1687,3.1847,-0.17753,34.091,363.33,-0.019299,9.6625,22.873,363.35,357.41,356.31,-7.7514
123.1687,2.971,-0.18329,34.238,369.33,-0.019883,9.0139,22.872,369.35,363.3,362.19,-7.7509
125.1687,2.9151,-0.18819,34.522,375.33,-0.020435,8.8422,22.874,375.34,369.27,368.17,-7.7503
127.1687,2.9048,-0.19076,34.467,381.33,-0.020687,8.8126,22.874,381.3,375.29,373.96,-7.7501
129.1687,2.8881,-0.19522,34.592,387.33,-0.021174,8.7641,22.873,387.33,381.21,379.77,-7.7493
131.1687,2.8991,-0.19915,34.781,393.33,-0.021588,8.7934,22.873,393.31,387.44,385.94,-7.7489
133.017,2.9013,-0.20104,34.556,398.87,-0.021809,8.8034,22.872,398.94,392.99,391.51,-7.7483
134.8562,2.8938,-0.20164,33.545,400.0,-0.021878,8.7781,22.872,400.15,395.46,393.42,-7.7482
136.8562,2.9027,-0.20208,32.865,400.0,-0.021907,8.8083,22.873,400.15,396.18,393.71,-7.748
138.8562,2.8944,-0.20274,32.899,400.0,-0.021988,8.779,22.873,400.05,396.48,393.84,-7.7482
140.8562,2.9054,-0.20531,32.819,400.0,-0.02222,8.816,22.873,400.04,396.77,393.86,-7.748
142.8562,2.8999,-0.20395,32.763,400.0,-0.02212,8.794,22.872,400.01,397.05,393.96,-7.7481
144.8562,2.9214,-0.20266,32.62,400.0,-0.021991,8.8665,22.873,401.55,398.68,395.25,-7.7481
146.8562,2.9081,-0.20319,32.06,400.0,-0.022021,8.8209,22.873,402.72,400.16,396.94,-7.7479
148.8562,2.9044,-0.20335,32.839,400.0,-0.022072,8.812,22.873,402.18,400.52,397.09,-7.7478
150.8562,2.8915,-0.20282,31.853,400.0,-0.021991,8.7704,22.872,400.9,399.81,396.32,-7.7477
152.8562,2.8997,-0.20312,31.879,400.0,-0.022036,8.7987,22.872,400.44,399.63,396.22,-7.7478
154.8562,2.8955,-0.20327,31.827,400.0,-0.022026,8.7843,22.872,400.45,400.06,396.64,-7.7478
156.7779,2.8982,-0.20335,31.516,400.0,-0.022029,8.7927,22.872,400.45,400.56,397.12,-7.7477
158.7779,2.9025,-0.20312,31.54,400.0,-0.022046,8.8082,22.872,400.43,400.9,397.46,-7.7478
160.7779,2.9008,-0.20356,31.52,400.0,-0.022072,8.8,22.872,400.42,400.85,397.74,-7.7476
162.7779,2.9066,-0.2044,31.303,400.0,-0.022205,8.819,22.872,400.43,401.09,398.19,-7.7477
164.7429,2.9067,-0.20794,30.91,400.0,-0.022547,8.8212,22.872,400.5,401.29,398.34,-7.7476
166.7429,2.9002,-0.20707,30.957,400.0,-0.022438,8.7954,22.873,400.44,401.24,398.34,-7.7476
168.7429,2.8981,-0.20513,31.096,400.0,-0.022232,8.7926,22.873,400.39,401.11,398.24,-7.7476
170.7429,2.889,-0.2055,30.999,400.0,-0.022306,8.762,22.872,400.43,401.03,398.17,-7.7477
172.7429,2.8933,-0.20531,30.872,400.0,-0.022244,8.7808,22.873,400.45,400.81,398.1,-7.7477
174.7429,2.8876,-0.20523,30.331,400.0,-0.022247,8.7572,22.871,400.5,400.7,398.14,-7.7475
176.7429,2.8836,-0.20502,30.263,400.0,-0.022229,8.7501,22.871,400.48,400.56,398.05,-7.7475
178.6179,2.8984,-0.0014541,30.721,400.0,-0.00066321,8.7918,22.876,400.34,400.28,397.8,-7.7459
178.6189,2.8722,0.0070818,30.829,400.0,-5.4275e-05,8.7122,22.873,400.34,400.27,397.8,-7.7472
178.6199,2.9516,0.0068156,30.872,400.0,0.0011554,8.8997,22.867,400.33,400.27,397.8,-7.7478
178.6209,2.8647,0.0051072,30.872,400.0,0.001073,8.6736,22.875,400.34,400.28,397.8,-7.7493
178.6219,2.9209,0.015623,30.872,400.0,0.0005549,8.8948,22.868,400.34,400.29,397.8,-7.747
178.6229,2.8463,-0.0041505,30.872,400.0,0.0006984,8.6484,22.874,400.34,400.29,397.79,-7.7488
178.6239,2.9144,0.012554,30.872,400.0,0.00044984,8.8766,22.87,400.35,400.3,397.79,-7.7458
178.6249,2.8451,0.011888,30.872,400.0,0.0014895,8.6326,22.872,400.35,400.31,397.79,-7.7487
178.6259,2.8033,0.00034592,30.872,400.0,-5.8146e-05,8.5733,22.877,400.35,400.31,397.78,-7.7486
178.6269,2.878,0.0091266,30.872,400.0,0.00092301,8.7071,22.874,400.35,400.32,397.78,-7.7479
178.6279,2.9418,0.0047186,30.872,400.0,0.0013489,8.9637,22.876,400.36,400.32,397.78,-7.7479
178.6289,2.8585,0.014914,30.872,400.0,0.00034794,8.6843,22.873,400.36,400.33,397.77,-7.7472
178.6299,2.9067,-0.00039272,30.872,400.0,0.0012301,8.8357,22.868,400.36,400.34,397.77,-7.748
178.6309,2.8586,0.0064059,30.872,400.0,0.00047673,8.6711,22.868,400.36,400.34,397.78,-7.7472
178.6319,2.8999,0.015823,30.872,400.0,0.0012877,8.7972,22.872,400.36,400.35,397.78,-7.7478
178.6329,2.8459,-0.005022,30.872,400.0,-9.8689e-05,8.6349,22.876,400.36,400.35,397.78,-7.748
178.6339,2.8871,0.011353,30.872,400.0,0.00053859,8.7792,22.876,400.36,400.36,397.79,-7.7457
178.6349,2.8643,0.0058758,30.872,400.0,0.0017138,8.6914,22.874,400.36,400.37,397.79,-7.7487
178.6359,3.0307,0.004532,30.872,400.0,-0.00061467,9.1304,22.868,400.36,400.37,397.79,-7.7466
178.6369,2.8652,-0.0039241,30.872,400.0,0.00069887,8.6714,22.87,400.36,400.38,397.8,-7.7472
178.6379,2.8658,-0.0007832,30.872,400.0,6.6557e-05,8.6992,22.874,400.36,400.38,397.8,-7.7478
178.6389,2.9043,0.015878,30.872,400.0,0.00076796,8.7714,22.868,400.36,400.39,397.8,-7.7473
178.6399,2.9008,-0.0057272,30.872,400.0,0.00051352,8.8226,22.868,400.36,400.38,397.81,-7.7478
178.6409,2.879,0.013364,30.872,400.0,0.00069233,8.7327,22.876,400.36,400.37,397.81,-7.7484
178.6419,2.8803,0.0098905,30.872,400.0,0.0015621,8.7405,22.872,400.36,400.36,397.82,-7.7479
178.6429,2.8849,0.0027005,30.872,400.0,-0.00037422,8.7327,22.87,400.36,400.35,397.82,-7.7473
178.6439,2.8747,0.0080507,30.872,400.0,0.0011362,8.7811,22.87,400.36,400.34,397.83,-7.7471
178.6449,2.8727,0.0037915,30.872,400.0,0.0010918,8.73,22.872,400.36,400.32,397.84,-7.7486
178.6459,2.7473,0.011706,30.872,400.0,0.00012065,8.3734,22.876,400.36,400.31,397.84,-7.7464
178.6469,2.9061,-0.0040533,30.872,400.0,0.00083979,8.8434,22.87,400.36,400.3,397.85,-7.7486
178.6479,2.9207,0.011118,30.872,400.0,0.00050106,8.879,22.868,400.36,400.29,397.85,-7.7472
178.6489,2.8849,0.016247,30.872,400.0,0.0016805,8.7326,22.872,400.36,400.28,397.86,-7.748
178.6499,2.8536,-0.0016821,30.872,400.0,-0.00012243,8.6813,22.876,400.37,400.27,397.86,-7.7456
178.6509,2.8913,0.011128,30.872,400.0,0.0009132,8.7484,22.87,400.37,400.27,397.85,-7.7486
178.6519,2.8533,0.0049947,30.872,400.0,0.0015301,8.6764,22.878,400.38,400.27,397.85,-7.7472
178.6529,2.8844,0.0072347,30.872,400.0,-0.00045118,8.7303,22.87,400.38,400.27,397.84,-7.7471
178.6539,2.8587,0.0016923,30.872,400.0,0.0012856,8.6738,22.867,400.39,400.27,397.84,-7.7486
178.6549,2.8982,0.0064616,30.872,400.0,0.00044018,8.7736,22.87,400.4,400.27,397.83,-7.7472
178.6559,2.9654,0.013045,30.872,400.0,0.00055532,8.9819,22.868,400.4,400.27,397.82,-7.7472
178.6569,2.8918,-0.010858,30.872,400.0,-0.00046734,8.7558,22.877,400.41,400.27,397.82,-7.7473
178.6579,2.8251,0.0058279,30.872,400.0,-0.00015675,8.5738,22.87,400.41,400.27,397.81,-7.7472
178.6589,2.9198,0.0080747,30.872,400.0,0.00179,8.8894,22.87,400.42,400.27,397.81,-7.7487
178.6599,2.8663,0.0074535,30.872,400.0,-0.0003077,8.7174,22.87,400.42,400.28,397.8,-7.7471
178.6609,2.9197,0.0042091,30.872,400.0,0.0012293,8.8715,22.874,400.42,400.29,397.8,-7.7479
178.6619,2.8586,0.0064228,30.872,400.0,0.0010849,8.6764,22.868,400.42,400.29,397.8,-7.7472
178.6629,2.9134,0.014929,30.872,400.0,0.00053445,8.8377,22.87,400.42,400.3,397.79,-7.7471
178.6639,2.8591,-0.0048777,30.872,400.0,0.00070857,8.6896,22.872,400.42,400.31,397.79,-7.7473
178.6649,2.9247,0.013304,30.872,400.0,0.00056171,8.8509,22.878,400.42,400.32,397.79,-7.7471
178.6659,2.7336,0.0078862,30.872,400.0,0.0016087,8.3271,22.87,400.42,400.33,397.78,-7.747
178.6669,2.9412,0.0008108,30.872,400.0,-0.00029098,8.9847,22.878,400.42,400.34,397.78,-7.7486
178.6679,2.8814,0.00874,30.872,400.0,0.001311,8.7973,22.87,400.42,400.35,397.78,-7.7485
178.6689,2.9076,0.0070157,30.872,400.0,0.0015511,8.8536,22.876,400.42,400.36,397.77,-7.7479
178.6699,2.8525,0.012554,29.019,400.0,0.00012682,8.6738,22.872,400.59,400.59,397.77,-7.7474
178.6709,2.9339,-0.0017578,25.932,400.0,0.0011093,8.9307,22.87,400.87,400.96,397.77,-7.7465
178.6719,2.8471,0.0083441,22.845,400.0,0.00038243,8.6812,22.852,401.16,401.34,397.77,-7.7487
178.6729,2.9653,0.013874,19.758,400.0,0.0013962,8.9559,22.807,401.44,401.72,397.77,-7.7472
178.6739,2.8058,-0.0037272,16.67,400.0,-0.00021724,8.5269,22.722,401.72,402.09,397.77,-7.7472
178.6749,3.329,0.01092,13.583,400.0,0.00083793,10.057,22.544,402.01,402.47,397.77,-7.7465
178.6759,2.8412,0.0018917,10.496,400.0,0.0012549,8.6592,22.066,402.29,402.84,397.77,-7.7472
178.6769,3.014,0.0050187,7.4089,400.0,-0.00067642,9.1356,21.347,402.57,403.22,397.77,-7.7472
178.6779,2.7518,-0.0039001,4.3217,400.0,0.00061594,8.3528,20.379,402.86,403.6,397.77,-7.7486
178.6789,2.9335,0.0098417,1.2346,400.0,0.0010771,8.9126,19.286,403.14,403.97,397.77,-7.7479
178.6799,2.7916,0.01451,0.0,400.0,0.00072739,8.4736,18.088,404.34,405.23,397.79,-7.7471
178.6809,2.8867,-0.0053107,0.0,400.0,0.00024515,8.794,16.875,406.15,407.08,397.83,-7.7486
178.6819,2.704,0.01109,0.0,400.0,0.00034345,8.1989,15.679,407.95,408.92,397.87,-7.7471
178.6829,2.8952,0.0048227,0.0,400.0,0.0013147,8.7176,14.526,409.76,410.77,397.9,-7.7502
178.6839,2.785,-0.0012559,0.0,400.0,-0.00081644,8.4707,13.442,411.57,412.61,397.94,-7.7472
178.6849,2.8996,0.005375,0.0,392.82,0.0011989,8.8124,12.435,413.38,414.46,397.98,-7.7495
178.6859,2.6984,-0.0024591,0.0,367.82,0.00028531,8.232,11.497,415.19,416.3,398.01,-7.7472
178.6869,2.8866,0.013471,0.0,342.82,0.0004494,8.7452,10.604,417.0,418.15,398.05,-7.7473
178.6879,2.8974,-0.010907,0.0,317.82,0.00015862,8.764,9.7612,418.81,419.99,398.08,-7.7472
178.6889,2.764,0.0095602,0.0,292.82,0.00025097,8.397,8.9226,420.62,421.84,398.12,-7.7488
178.6899,22.52,0.14666,0.0,267.82,0.014955,62.96,8.1864,422.31,423.45,398.12,-7.7471
178.6909,36.803,0.61337,0.0,242.82,0.065784,111.09,7.6343,423.91,424.91,398.1,-7.7133
178.6919,35.768,1.5568,0.0,217.82,0.18332,108.26,6.8489,425.52,426.37,398.07,-7.7225
178.6929,35.23,2.1142,0.0,192.82,0.25963,107.53,6.1638,427.13,427.83,398.05,-7.7113
178.6939,37.377,2.7578,0.0,167.82,0.34872,112.91,5.5779,428.73,429.29,398.02,-7.7194
178.6949,35.045,3.4945,0.0,142.82,0.46994,106.53,4.8922,430.34,430.75,398.0,-7.7162
178.6959,37.327,3.8995,0.0,117.82,0.53781,113.19,4.3053,431.95,432.21,397.98,-7.7161
178.6969,36.255,4.5227,0.0,92.816,0.65554,109.72,3.7893,433.55,433.67,397.95,-7.7177
178.6979,37.094,5.0197,0.0,67.816,0.76103,112.7,3.2591,435.16,435.13,397.93,-7.7146
178.6989,36.943,5.4188,0.0,42.816,0.84997,111.85,2.8151,436.77,436.59,397.9,-7.7154
178.6999,36.753,5.8032,0.0,17.816,0.94985,111.55,2.4425,437.04,436.74,397.88,-7.716
178.7009,36.882,6.1407,0.0,2.5613e-05,1.0343,111.87,2.0867,436.43,436.01,397.87,-7.7163
178.7019,36.003,6.4129,0.0,5.910400000000001e-19,1.122,109.19,1.7869,435.81,435.29,397.85,-7.7206
178.7029,36.363,6.6754,0.0,1.3639e-32,1.2016,110.39,1.5233,435.2,434.57,397.84,-7.7176
178.7039,36.378,6.9109,0.0,0.0,1.2779,110.28,1.2949,434.58,433.84,397.82,-7.7193
178.7049,36.614,7.1202,0.0,0.0,1.3629,111.04,1.0745,433.97,433.12,397.81,-7.7192
178.7059,37.166,7.3611,0.0,0.0,1.447,112.71,0.85802,433.35,432.4,397.79,-7.7193
178.7069,37.193,7.5679,0.0,0.0,1.5459,112.77,0.64851,432.74,431.67,397.78,-7.7194
178.7079,30.831,7.6838,0.0,0.0,1.5916,94.808,0.4446,432.12,430.95,397.76,-7.7208
178.7089,29.623,7.7063,0.0,0.0,1.6103,90.357,0.39901,431.51,430.23,397.75,-7.73
178.7099,28.698,7.7273,0.0,0.0,1.6206,87.609,0.34386,430.55,429.21,397.74,-7.73
178.7109,28.446,7.7351,0.0,0.0,1.6123,86.384,0.29857,429.37,427.99,397.73,-7.7299
178.7119,28.023,7.7162,0.0,0.0,1.6196,85.247,0.25025,428.19,426.77,397.72,-7.7333
178.7129,27.825,7.7372,0.0,0.0,1.6148,84.722,0.20356,427.01,425.55,397.71,-7.7331
178.7139,27.664,7.7212,0.0,0.0,1.6165,83.992,0.16142,425.83,424.33,397.7,-7.7341
178.7149,27.37,7.74,0.0,0.0,1.6239,83.144,0.11939,424.65,423.11,397.69,-7.7334
178.7159,27.142,7.7591,0.0,0.0,1.63,82.39,0.08243,423.47,421.89,397.68,-7.7347
178.7169,26.574,7.7419,0.0,0.0,1.6311,80.586,0.054978,422.29,420.67,397.67,-7.7348
178.7179,25.794,7.7655,0.0,0.0,1.6266,78.292,0.050568,421.11,419.46,397.67,-7.7349
178.7189,25.281,7.7506,0.0,0.0,1.6353,76.79,0.054603,419.93,418.24,397.66,-7.7363
178.7199,24.77,7.749,0.0,0.0,1.6253,75.198,0.05918,418.98,417.25,397.65,-7.7379
178.7209,24.371,7.7663,0.0,0.0,1.6334,73.902,0.067901,418.17,416.42,397.65,-7.7357
178.7219,24.058,7.7294,0.0,0.0,1.6227,73.027,0.05746,417.37,415.59,397.64,-7.7378
178.7229,23.942,7.7565,0.0,0.0,1.6248,72.655,0.063521,416.56,414.76,397.64,-7.7379
178.7239,23.676,7.755,0.0,0.0,1.6369,71.806,0.063416,415.76,413.93,397.64,-7.7393
178.7249,23.373,7.7593,0.0,0.0,1.6261,70.924,0.059015,414.95,413.1,397.64,-7.7395
178.7259,23.166,7.756,0.0,0.0,1.6358,70.235,0.062071,414.15,412.27,397.63,-7.738
178.7269,22.991,7.7524,0.0,0.0,1.6308,69.726,0.061903,413.34,411.44,397.63,-7.7407
178.7279,22.808,7.7696,0.0,0.0,1.6305,69.208,0.055363,412.53,410.61,397.63,-7.7394
178.7289,22.681,7.7481,0.0,0.0,1.6345,68.81,0.057436,411.73,409.78,397.62,-7.7394
178.7299,22.51,7.7708,0.0,0.0,1.631,68.296,0.05684,411.04,409.08,397.63,-7.741
178.7309,22.357,7.7629,0.0,0.0,1.6387,67.848,0.061127,410.43,408.46,397.63,-7.7394
178.7319,22.253,7.7519,0.0,0.0,1.6259,67.505,0.059371,409.83,407.85,397.64,-7.7402
178.7329,22.139,7.7679,0.0,0.0,1.638,67.189,0.05917,409.22,407.23,397.64,-7.741
178.7339,21.961,7.7597,0.0,0.0,1.6377,66.583,0.061781,408.61,406.61,397.65,-7.7397
178.7349,21.888,7.7769,0.0,0.0,1.6321,66.413,0.063755,408.0,406.0,397.66,-7.7411
178.7359,21.759,7.7453,0.0,0.0,1.6349,66.02,0.059491,407.39,405.38,397.66,-7.7418
178.7369,21.631,7.7621,0.0,0.0,1.6288,65.655,0.061118,406.79,404.76,397.67,-7.7419
178.7379,21.509,7.771,0.0,0.0,1.6388,65.265,0.056689,406.18,404.15,397.67,-7.7424
178.7389,21.387,7.7518,0.0,0.0,1.6303,64.891,0.058563,405.57,403.53,397.68,-7.741
178.7399,21.317,7.7726,0.0,0.0,1.6351,64.628,0.056914,405.03,402.99,397.69,-7.7426
178.7409,21.196,7.7579,0.0,0.0,1.6384,64.279,0.056845,404.53,402.5,397.7,-7.7418
178.7419,21.102,7.765,0.0,0.0,1.6276,64.048,0.059021,404.04,402.01,397.71,-7.7423
178.7429,20.994,7.7607,0.0,0.0,1.6405,63.721,0.054801,403.54,401.53,397.72,-7.741
178.7439,20.925,7.7627,0.0,0.0,1.6335,63.472,0.054867,403.04,401.04,397.72,-7.7418
178.7449,20.798,7.776,0.0,0.0,1.6369,63.105,0.056913,402.55,400.55,397.73,-7.7426
178.7459,20.728,7.7461,0.0,0.0,1.6321,62.876,0.055166,402.05,400.06,397.74,-7.7417
178.7469,20.614,7.7701,0.0,0.0,1.6306,62.535,0.057114,401.55,399.57,397.75,-7.7439
178.7479,20.573,7.7642,0.0,0.0,1.6414,62.406,0.058726,401.06,399.09,397.76,-7.7424
178.7489,20.459,7.7627,0.0,0.0,1.6284,62.06,0.056892,400.56,398.6,397.77,-7.7432
178.7499,20.411,7.7632,0.0,0.0,1.6373,61.931,0.059161,400.22,398.25,397.79,-7.7426
178.7509,20.294,7.759,0.0,0.0,1.635,61.543,0.057301,399.98,398.0,397.81,-7.741
178.7519,20.228,7.7765,0.0,0.0,1.6332,61.381,0.059572,399.74,397.75,397.84,-7.744
178.7529,20.091,7.749,0.0,0.0,1.6358,60.914,0.055148,399.49,397.49,397.86,-7.741
178.7539,19.984,7.7747,0.0,0.0,1.6323,60.606,0.059276,399.25,397.24,397.88,-7.7425
178.7549,19.626,7.7643,0.0,0.0,1.6393,59.543,0.068464,399.01,396.99,397.91,-7.7411
178.7559,19.041,7.7516,0.0,0.0,1.627,57.848,0.086906,398.77,396.73,397.93,-7.744
178.7569,18.018,7.7665,0.0,0.0,1.635,54.735,0.11763,398.53,396.48,397.96,-7.7454
178.7579,16.82,7.7486,0.0,0.0,1.6338,51.103,0.17028,398.29,396.23,397.98,-7.7441
178.7589,15.379,7.7593,0.0,0.0,1.6241,46.783,0.23098,398.05,395.98,398.0,-7.7472
178.7599,13.768,7.7325,0.0,0.0,1.6276,41.887,0.3008,397.97,395.9,398.03,-7.7473
178.7609,12.068,7.7401,0.0,0.0,1.6193,36.751,0.37283,398.0,395.96,398.05,-7.7515
178.7619,9.8789,7.7438,0.0,0.0,1.6248,30.166,0.44943,398.03,396.01,398.08,-7.7502
178.7629,3.9045,7.6885,0.0,0.0,1.6029,12.819,0.55584,398.06,396.06,398.1,-7.752
178.7639,-0.4863,7.6252,0.0,0.0,1.5651,-1.7175,0.84507,398.09,396.11,398.12,-7.7619
178.7649,0.40532,7.6636,0.0,0.0,1.5925,0.81468,1.2041,398.12,396.16,398.15,-7.758
178.7659,3.4361,7.6622,0.0,0.0,1.5797,10.392,1.5561,398.15,396.21,398.17,-7.7602
178.7669,3.012,7.6858,0.0,0.0,1.6034,9.4717,1.9235,398.18,396.26,398.2,-7.758
178.7679,1.9326,7.6472,0.0,0.0,1.5792,5.7252,2.3159,398.21,396.31,398.22,-7.758
178.7689,2.124,7.6959,0.0,0.0,1.5971,6.5635,2.691,398.24,396.37,398.24,-7.758
178.7699,2.6571,7.6637,0.0,0.0,1.5927,7.9878,3.0728,398.29,396.49,398.27,-7.7573
178.7709,2.5904,7.6995,0.0,0.0,1.5965,7.9029,3.4031,398.36,396.65,398.28,-7.7593
178.7719,2.2667,7.6864,0.0,0.0,1.6029,6.8344,3.7235,398.43,396.82,398.3,-7.7564
178.7729,2.4939,7.698,0.0,0.0,1.5966,7.5766,3.9888,398.49,396.98,398.32,-7.7565
178.7739,2.4712,7.6909,0.0,0.0,1.6024,7.4843,4.2266,398.56,397.15,398.34,-7.7549
178.7749,2.2601,7.6944,0.0,0.0,1.6055,6.9402,4.4173,398.63,397.31,398.36,-7.7572
178.7759,2.5305,7.709,0.0,0.0,1.601,7.6305,4.6146,398.69,397.48,398.37,-7.7541
178.7769,2.2589,7.6792,0.0,0.0,1.6021,6.8887,4.7917,398.76,397.65,398.39,-7.7549
178.7779,2.5584,7.7007,0.0,0.0,1.599,7.7532,4.9673,398.82,397.81,398.41,-7.7535
178.7789,2.1932,7.7058,0.0,0.0,1.6094,6.6347,5.1545,398.89,397.98,398.43,-7.7547
178.7799,2.5841,7.6828,0.0,0.0,1.595,7.8846,5.3339,398.93,398.12,398.46,-7.7535
178.7809,2.3204,7.7065,0.0,0.0,1.6055,7.0068,5.5193,398.96,398.25,398.49,-7.7519
178.7819,2.3678,7.6889,0.0,0.0,1.6052,7.2358,5.6941,398.98,398.38,398.53,-7.7548
178.7829,2.4332,7.6949,0.0,0.0,1.5938,7.4228,5.8773,399.0,398.51,398.57,-7.7533
178.7839,2.3533,7.6905,0.0,0.0,1.607,7.1925,6.0493,399.03,398.64,398.6,-7.7533
178.7849,2.4713,7.6954,0.0,0.0,1.5992,7.476,6.2261,399.05,398.77,398.64,-7.7518
178.7859,2.3319,7.7021,0.0,0.0,1.603,7.0816,6.3959,399.08,398.9,398.67,-7.7511
178.7869,2.4882,7.679,0.0,0.0,1.5982,7.464,6.5601,399.1,399.03,398.71,-7.7531
178.7879,2.3331,7.7045,0.0,0.0,1.6003,7.1245,6.7442,399.12,399.16,398.75,-7.7518
178.7889,2.5578,7.6923,0.0,0.0,1.6077,7.7334,6.9123,399.15,399.29,398.78,-7.7503
178.7899,2.2982,7.6964,0.0,0.0,1.5959,7.0047,7.0888,399.17,399.37,398.82,-7.7517
178.7909,2.5073,7.6903,0.0,0.0,1.6046,7.6075,7.2581,399.19,399.42,398.86,-7.7503
178.7919,2.3746,7.6887,0.0,0.0,1.5996,7.1457,7.4243,399.2,399.46,398.91,-7.7502
178.7929,2.4875,7.7093,0.0,0.0,1.6025,7.5772,7.5979,399.22,399.51,398.95,-7.7498
178.7939,2.3182,7.6798,0.0,0.0,1.6014,7.0557,7.7632,399.24,399.56,398.99,-7.7503
178.7949,2.5197,7.7049,0.0,0.0,1.5994,7.6512,7.9328,399.26,399.61,399.03,-7.7502
178.7959,2.3695,7.6956,0.0,0.0,1.6067,7.1477,8.1004,399.28,399.66,399.07,-7.7503
178.7969,2.5115,7.688,0.0,0.0,1.5946,7.6104,8.2731,399.29,399.7,399.12,-7.7473
178.7979,2.371,7.7013,0.0,0.0,1.6057,7.1996,8.4399,399.31,399.75,399.16,-7.7502
178.7989,2.4937,7.6885,0.0,0.0,1.6036,7.5948,8.6094,399.33,399.8,399.2,-7.7495
178.7999,2.366,7.7072,0.0,0.0,1.5995,7.2045,8.7857,399.33,399.84,399.23,-7.7487
178.8009,2.5527,7.6809,0.0,0.0,1.6039,7.7365,8.9577,399.31,399.86,399.25,-7.7494
178.8019,2.3568,7.697,0.0,0.0,1.5978,7.135,9.1301,399.3,399.89,399.27,-7.7487
178.8029,2.5143,7.703,0.0,0.0,1.6068,7.6328,9.3063,399.28,399.92,399.29,-7.7489
178.8039,2.4438,7.6819,0.0,0.0,1.5967,7.3743,9.4792,399.27,399.94,399.31,-7.7473
178.8049,2.4853,7.7039,0.0,0.0,1.603,7.5204,9.6495,399.25,399.97,399.34,-7.7486
178.8059,2.4575,7.6912,0.0,0.0,1.6061,7.4206,9.8191,399.24,400.0,399.36,-7.7487
178.8069,2.4307,7.6981,0.0,0.0,1.5948,7.3307,9.9933,399.22,400.03,399.38,-7.7472
178.8079,2.5139,7.6903,0.0,0.0,1.6067,7.6438,10.17,399.21,400.05,399.4,-7.7495
178.8089,2.4193,7.6927,0.0,0.0,1.5992,7.3539,10.335,399.19,400.08,399.42,-7.747
178.8099,2.4805,7.7048,0.0,0.0,1.6029,7.5279,10.515,399.16,400.09,399.44,-7.7472
178.8109,2.513,7.6786,0.0,0.0,1.5994,7.6362,10.682,399.1,400.08,399.46,-7.7479
178.8119,2.419,7.7042,0.0,0.0,1.5991,7.3431,10.849,399.05,400.07,399.48,-7.7471
178.8129,2.5813,7.6898,0.0,0.0,1.6058,7.8416,11.023,398.99,400.06,399.5,-7.7487
178.8139,2.3709,7.6919,0.0,0.0,1.5942,7.1919,11.199,398.94,400.05,399.53,-7.7458
178.8149,2.5742,7.6899,0.0,0.0,1.6034,7.7903,11.365,398.88,400.04,399.55,-7.7472
178.8159,2.4179,7.6863,0.0,0.0,1.6005,7.3175,11.541,398.83,400.03,399.57,-7.7465
178.8169,2.5672,7.7017,0.0,0.0,1.5992,7.7827,11.714,398.78,400.02,399.59,-7.7472
178.8179,2.4064,7.6761,0.0,0.0,1.6004,7.3359,11.887,398.72,400.01,399.61,-7.7486
178.8189,2.5597,7.6981,0.0,0.0,1.5971,7.788,12.058,398.67,400.0,399.63,-7.7471
178.8199,2.3796,7.6952,0.0,0.0,1.6052,7.2405,12.225,398.62,399.97,399.65,-7.7471
178.8209,2.542,7.684,0.0,0.0,1.5946,7.7487,12.397,398.57,399.92,399.68,-7.7456
178.8219,2.4048,7.6963,0.0,0.0,1.6028,7.2947,12.565,398.52,399.88,399.7,-7.7457
178.8229,2.5128,7.6862,0.0,0.0,1.6025,7.6052,12.741,398.47,399.83,399.73,-7.7457
178.8239,2.4264,7.701,0.0,0.0,1.596,7.366,12.904,398.42,399.78,399.75,-7.7457
178.8249,2.5667,7.6799,0.0,0.0,1.6029,7.7826,13.051,398.38,399.73,399.77,-7.7456
178.8259,2.3931,7.6956,0.0,0.0,1.5979,7.2949,13.197,398.33,399.68,399.8,-7.7465
178.8269,2.5996,7.6996,0.0,0.0,1.6039,7.8693,13.337,398.28,399.63,399.82,-7.7472
178.8279,2.3849,7.6753,0.0,0.0,1.5951,7.2382,13.455,398.23,399.59,399.85,-7.7487
178.8289,2.5836,7.7011,0.0,0.0,1.6004,7.8878,13.553,398.18,399.54,399.87,-7.7472
178.8299,2.4546,7.6846,0.0,0.0,1.6038,7.5,13.632,398.13,399.51,399.89,-7.7516
178.8309,2.6004,7.6938,0.0,0.0,1.5938,7.8723,13.691,398.08,399.5,399.91,-7.7487
178.8319,2.525,7.6854,0.0,0.0,1.604,7.623,13.728,398.03,399.49,399.93,-7.7518
178.8329,2.5953,7.6876,0.0,0.0,1.5981,7.875,13.735,397.98,399.48,399.96,-7.7533
178.8339,2.4851,7.7028,0.0,0.0,1.6004,7.5336,13.73,397.93,399.46,399.98,-7.7548
178.8349,2.6312,7.6748,0.0,0.0,1.5981,8.0216,13.689,397.88,399.45,400.0,-7.7565
178.8359,2.4934,7.699,0.0,0.0,1.5974,7.5879,13.624,397.83,399.44,400.02,-7.7588
178.8369,2.6791,7.6895,0.0,0.0,1.6046,8.1856,13.528,397.78,399.43,400.04,-7.7626
178.8379,2.4829,7.69,0.0,0.0,1.5942,7.4716,13.421,397.72,399.42,400.06,-7.7672
178.8389,2.6708,7.6926,0.0,0.0,1.6038,8.129,13.287,397.67,399.4,400.08,-7.7674
178.8399,2.4846,7.6831,0.0,0.0,1.5987,7.5233,13.15,397.6,399.37,400.1,-7.772
178.8409,2.6308,7.7058,0.0,0.0,1.5991,8.0087,13.013,397.52,399.33,400.12,-7.7782
178.8419,2.5091,7.673,0.0,0.0,1.5991,7.5412,12.892,397.44,399.29,400.15,-7.7813
178.8429,2.5969,7.7012,0.0,0.0,1.598,7.9058,12.785,397.36,399.25,400.17,-7.7888
178.8439,2.4896,7.6919,0.0,0.0,1.6032,7.5075,12.709,397.28,399.2,400.19,-7.7935
178.8449,2.6045,7.6812,0.0,0.0,1.5943,7.9289,12.681,397.2,399.16,400.21,-7.7997
178.8459,2.4909,7.6953,0.0,0.0,1.6013,7.5439,12.674,397.12,399.12,400.23,-7.806
178.8469,2.6138,7.6834,0.0,0.0,1.6023,8.0186,12.689,397.03,399.08,400.25,-7.8137
178.8479,2.5003,7.6979,0.0,0.0,1.5944,7.4923,12.734,396.95,399.04,400.27,-7.8192
178.8489,2.593,7.6814,0.0,0.0,1.6034,7.9392,12.784,396.87,398.99,400.29,-7.8269
178.8499,2.5947,7.6867,0.0,0.0,1.5947,7.7614,12.872,396.8,398.92,400.32,-7.836
178.8509,2.4652,7.7008,0.0,0.0,1.6033,7.5543,12.951,396.73,398.83,400.34,-7.8422
178.8519,2.6589,7.6731,0.0,0.0,1.5943,8.0288,13.032,396.66,398.74,400.36,-7.8501
178.8529,2.4424,7.6999,0.0,0.0,1.5984,7.4441,13.104,396.59,398.65,400.39,-7.8571
178.8539,2.6726,7.6828,0.0,0.0,1.6025,8.0772,13.165,396.52,398.56,400.41,-7.8656
178.8549,2.4882,7.6899,0.0,0.0,1.5921,7.5746,13.211,396.45,398.47,400.44,-7.8704
178.8559,2.6052,7.685,0.0,0.0,1.6028,7.8723,13.237,396.38,398.38,400.46,-7.8781
178.8569,2.5355,7.6862,0.0,0.0,1.5979,7.7026,13.249,396.31,398.29,400.48,-7.8859
178.8579,2.5517,7.6979,0.0,0.0,1.5976,7.7132,13.251,396.24,398.2,400.51,-7.8922
178.8589,2.5982,7.6735,0.0,0.0,1.5982,7.9469,13.229,396.17,398.11,400.53,-7.8999
178.8599,2.5431,7.6964,0.0,0.0,1.5957,7.6641,13.196,396.1,398.03,400.56,-7.9068
178.8609,2.5377,7.6912,0.0,0.0,1.6058,7.7777,13.156,396.03,397.95,400.59,-7.9138
178.8619,2.5846,7.6848,0.0,0.0,1.5925,7.8057,13.107,395.97,397.87,400.62,-7.9229
178.8629,2.5146,7.6937,0.0,0.0,1.6028,7.6413,13.059,395.9,397.79,400.65,-7.9291
178.8639,2.5915,7.6828,0.0,0.0,1.6003,7.8133,13.016,395.83,397.71,400.68,-7.9341
178.8649,2.4836,7.7035,0.0,0.0,1.5982,7.6181,12.977,395.76,397.64,400.71,-7.9419
178.8659,2.6193,7.676,0.0,0.0,1.6007,7.9291,12.952,395.69,397.56,400.74,-7.9481
178.8669,2.4685,7.7005,0.0,0.0,1.5981,7.5182,12.938,395.62,397.48,400.77,-7.9558
178.8679,2.6531,7.6948,0.0,0.0,1.6039,8.0364,12.931,395.55,397.4,400.8,-7.9634
178.8689,2.4839,7.6786,0.0,0.0,1.5945,7.6003,12.937,395.48,397.32,400.83,-7.9696
178.8699,2.6528,7.6993,0.0,0.0,1.6012,8.0317,12.946,395.39,397.24,400.85,-7.9772
178.8709,2.4685,7.6844,0.0,0.0,1.6039,7.5181,12.958,395.29,397.16,400.87,-7.9843
178.8719,2.6923,7.6926,0.0,0.0,1.5922,8.0983,12.987,395.19,397.08,400.89,-7.9927
178.8729,2.4287,7.6841,0.0,0.0,1.6039,7.4155,13.002,395.08,397.0,400.91,-7.9973
178.8739,2.7067,7.6879,0.0,0.0,1.5971,8.1518,13.025,394.98,396.92,400.93,-8.0052
178.8749,2.447,7.6996,0.0,0.0,1.6012,7.4488,13.048,394.88,396.84,400.94,-8.0099
178.8759,2.7218,7.6758,0.0,0.0,1.597,8.2495,13.065,394.77,396.75,400.96,-8.0175
178.8769,2.455,7.6975,0.0,0.0,1.5968,7.508,13.086,394.67,396.67,400.98,-8.0238
178.8779,2.7228,7.688,0.0,0.0,1.6045,8.2835,13.098,394.57,396.59,401.0,-8.0301
178.8789,2.4527,7.6894,0.0,0.0,1.5924,7.4283,13.104,394.47,396.51,401.02,-8.0362
178.8799,2.7303,7.6899,0.0,0.0,1.6035,8.3115,13.109,394.37,396.43,401.03,-8.0439
178.8809,2.4544,7.6829,0.0,0.0,1.5981,7.4849,13.107,394.28,396.34,401.04,-8.0516
178.8819,2.762,7.7022,0.0,0.0,1.5985,8.3549,13.107,394.19,396.26,401.05,-8.0564
178.8829,2.46,7.6753,0.0,0.0,1.6001,7.485,13.1,394.1,396.17,401.06,-8.0627
178.8839,2.7496,7.6972,0.0,0.0,1.5962,8.3368,13.087,394.01,396.09,401.07,-8.0711
178.8849,2.4718,7.6937,0.0,0.0,1.6048,7.4669,13.084,393.92,396.0,401.07,-8.0793
178.8859,2.7503,7.6821,0.0,0.0,1.5925,8.3373,13.072,393.83,395.92,401.08,-8.0842
178.8869,2.4469,7.6942,0.0,0.0,1.6024,7.4459,13.061,393.74,395.84,401.09,-8.0906
178.8879,2.7452,7.6839,0.0,0.0,1.6016,8.3757,13.052,393.65,395.75,401.1,-8.0982
178.8889,2.4676,7.6987,0.0,0.0,1.5951,7.516,13.042,393.56,395.67,401.11,-8.1044
178.8899,2.7582,7.6783,0.0,0.0,1.6019,8.3988,13.042,393.47,395.58,401.13,-8.1098
178.8909,2.4668,7.6939,0.0,0.0,1.5961,7.5003,13.037,393.4,395.5,401.16,-8.116
178.8919,2.7565,7.6989,0.0,0.0,1.6039,8.3422,13.035,393.32,395.41,401.18,-8.1238
178.8929,2.4775,7.675,0.0,0.0,1.5934,7.4843,13.031,393.24,395.33,401.21,-8.1301
178.8939,2.7446,7.7019,0.0,0.0,1.6012,8.3471,13.033,393.16,395.24,401.24,-8.1355
178.8949,2.4859,7.6836,0.0,0.0,1.6032,7.5493,13.033,393.08,395.16,401.27,-8.1455
178.8959,2.7454,7.6944,0.0,0.0,1.5934,8.3654,13.035,393.0,395.08,401.29,-8.1502
178.8969,2.4724,7.6847,0.0,0.0,1.6034,7.5107,13.037,392.93,394.99,401.32,-8.1587
178.8979,2.7454,7.6875,0.0,0.0,1.5977,8.3655,13.043,392.85,394.91,401.35,-8.164
178.8989,2.5049,7.7015,0.0,0.0,1.6007,7.5772,13.042,392.77,394.82,401.37,-8.1719
178.8999,2.7243,7.674,0.0,0.0,1.5977,8.2834,13.042,392.68,394.73,401.4,-8.1794
178.9009,2.5045,7.6996,0.0,0.0,1.597,7.5769,13.042,392.59,394.62,401.42,-8.1857
178.9019,2.7298,7.689,0.0,0.0,1.6054,8.2703,13.047,392.5,394.52,401.44,-8.1912
178.9029,2.5187,7.6858,0.0,0.0,1.5914,7.6179,13.045,392.41,394.42,401.46,-8.1999
178.9039,2.7244,7.6899,0.0,0.0,1.6036,8.268,13.047,392.32,394.32,401.48,-8.206
178.9049,2.5119,7.6802,0.0,0.0,1.5983,7.6106,13.053,392.23,394.21,401.5,-8.2135
178.9059,2.6865,7.7028,0.0,0.0,1.5979,8.2087,13.055,392.14,394.11,401.52,-8.2198
178.9069,2.5194,7.6716,0.0,0.0,1.5995,7.6515,13.059,392.05,394.01,401.55,-8.2262
178.9079,2.6919,7.6959,0.0,0.0,1.5961,8.2039,13.049,391.96,393.91,401.57,-8.2338
178.9089,2.5315,7.6935,0.0,0.0,1.604,7.6698,13.051,391.87,393.8,401.59,-8.24
178.9099,2.6482,7.6795,0.0,0.0,1.5929,8.1472,13.054,391.79,393.7,401.6,-8.2477
178.9109,2.5436,7.6968,0.0,0.0,1.6021,7.6743,13.056,391.71,393.61,401.6,-8.2539
178.9119,2.6449,7.6839,0.0,0.0,1.6017,8.0545,13.048,391.63,393.51,401.6,-8.2602
178.9129,2.558,7.6972,0.0,0.0,1.5947,7.7239,13.056,391.55,393.42,401.61,-8.2663
178.9139,2.63,7.6806,0.0,0.0,1.6031,7.9905,13.054,391.47,393.32,401.61,-8.2729
178.9149,2.5591,7.6904,0.0,0.0,1.5959,7.7697,13.054,391.39,393.22,401.61,-8.2817
178.9159,2.6236,7.6994,0.0,0.0,1.6029,7.9835,13.056,391.31,393.13,401.62,-8.288
178.9169,2.5715,7.6738,0.0,0.0,1.594,7.7901,13.049,391.24,393.03,401.62,-8.2943
178.9179,2.6164,7.7002,0.0,0.0,1.5994,7.9471,13.056,391.16,392.93,401.62,-8.3013
178.9189,2.5789,7.6829,0.0,0.0,1.6027,7.8082,13.05,391.08,392.84,401.62,-8.3082
178.9199,2.5775,7.6915,0.0,0.0,1.5931,7.8674,13.05,391.0,392.73,401.63,-8.3159
178.9209,2.598,7.6851,0.0,0.0,1.6033,7.8312,13.048,390.91,392.63,401.65,-8.3213
178.9219,2.5704,7.6861,0.0,0.0,1.5974,7.8444,13.049,390.83,392.52,401.66,-8.3299
178.9229,2.6114,7.7004,0.0,0.0,1.5994,7.8724,13.049,390.74,392.42,401.68,-8.3346
178.9239,2.5446,7.6728,0.0,0.0,1.598,7.7829,13.049,390.66,392.31,401.7,-8.3422
178.9249,2.6193,7.698,0.0,0.0,1.5964,7.9313,13.059,390.57,392.21,401.71,-8.3486
178.9259,2.5371,7.6889,0.0,0.0,1.605,7.7442,13.06,390.49,392.1,401.73,-8.3548
178.9269,2.6385,7.6822,0.0,0.0,1.5907,7.9725,13.051,390.41,391.99,401.74,-8.3625
178.9279,2.5281,7.6947,0.0,0.0,1.6038,7.6825,13.049,390.32,391.89,401.76,-8.3702
178.9289,2.6389,7.6811,0.0,0.0,1.5987,7.9616,13.052,390.24,391.78,401.77,-8.375
178.9299,2.5094,7.7011,0.0,0.0,1.5967,7.6617,13.051,390.15,391.68,401.78,-8.384
178.9309,2.6658,7.6754,0.0,0.0,1.6005,8.0414,13.049,390.05,391.58,401.8,-8.3903
178.9319,2.4954,7.6967,0.0,0.0,1.5965,7.6024,13.05,389.96,391.48,401.81,-8.3973
178.9329,2.6743,7.6977,0.0,0.0,1.6046,8.1031,13.046,389.87,391.38,401.82,-8.4005
178.9339,2.4893,7.6784,0.0,0.0,1.5939,7.593,13.047,389.77,391.28,401.83,-8.4091
178.9349,2.7056,7.6972,0.0,0.0,1.6007,8.1648,13.049,389.68,391.18,401.84,-8.4138
178.9359,2.4947,7.6843,0.0,0.0,1.6033,7.5952,13.047,389.59,391.08,401.86,-8.4222
178.9369,2.7069,7.6949,0.0,0.0,1.5935,8.1806,13.047,389.49,390.99,401.87,-8.4299
178.9379,2.488,7.682,0.0,0.0,1.6033,7.577,13.052,389.4,390.89,401.88,-8.4339
178.9389,2.7269,7.6893,0.0,0.0,1.5966,8.2268,13.047,389.31,390.79,401.89,-8.4438
178.9399,2.4811,7.6982,0.0,0.0,1.6012,7.5492,13.056,389.21,390.7,401.91,-8.4509
178.9409,2.7229,7.6763,0.0,0.0,1.5964,8.2677,13.049,389.12,390.61,401.92,-8.457
178.9419,2.4808,7.7,0.0,0.0,1.5985,7.531,13.049,389.03,390.53,401.94,-8.4647
178.9429,2.7421,7.6859,0.0,0.0,1.6043,8.3088,13.053,388.94,390.44,401.95,-8.4704
178.9439,2.468,7.6917,0.0,0.0,1.5934,7.5285,13.055,388.85,390.36,401.97,-8.4795
178.9449,2.7488,7.6886,0.0,0.0,1.6035,8.3163,13.055,388.76,390.27,401.98,-8.4857
178.9459,2.4531,7.6865,0.0,0.0,1.5986,7.4596,13.054,388.67,390.19,402.0,-8.492
178.9469,2.7485,7.7039,0.0,0.0,1.5998,8.316,13.049,388.58,390.1,402.01,-8.4996
178.9479,2.4666,7.6768,0.0,0.0,1.6007,7.5053,13.052,388.49,390.02,402.03,-8.5058
178.9489,2.7618,7.7002,0.0,0.0,1.5972,8.3574,13.053,388.4,389.94,402.04,-8.5105
178.9499,2.4604,7.6954,0.0,0.0,1.6062,7.4801,13.051,388.31,389.85,402.06,-8.5197
178.9509,2.7515,7.6859,0.0,0.0,1.5941,8.3783,13.055,388.23,389.76,402.08,-8.5245
178.9519,2.4725,7.6945,0.0,0.0,1.6031,7.4796,13.055,388.14,389.67,402.1,-8.5321
178.9529,2.7627,7.6868,0.0,0.0,1.6026,8.3422,13.051,388.06,389.58,402.12,-8.5384
178.9539,2.4793,7.7034,0.0,0.0,1.5974,7.5206,13.054,387.97,389.49,402.14,-8.5454
178.9549,2.7648,7.6793,0.0,0.0,1.603,8.424,13.047,387.89,389.39,402.17,-8.5511
178.9559,2.498,7.6999,0.0,0.0,1.5982,7.539,13.056,387.81,389.3,402.19,-8.5594
178.9569,2.7649,7.6998,0.0,0.0,1.6047,8.4037,13.054,387.72,389.21,402.21,-8.5647
178.9579,2.499,7.6796,0.0,0.0,1.5956,7.5594,13.049,387.64,389.12,402.23,-8.5725
178.9589,2.7643,7.7037,0.0,0.0,1.6027,8.386,13.049,387.55,389.03,402.25,-8.5764
178.9599,2.4853,7.6882,0.0,0.0,1.6047,7.5205,13.049,387.47,388.94,402.27,-8.5865
178.9609,2.7527,7.6965,0.0,0.0,1.5937,8.3862,13.051,387.39,388.86,402.29,-8.5911
178.9619,2.5057,7.6866,0.0,0.0,1.6054,7.5954,13.049,387.31,388.77,402.3,-8.5989
178.9629,2.7511,7.6919,0.0,0.0,1.5988,8.3655,13.051,387.23,388.68,402.32,-8.6066
178.9639,2.5192,7.7032,0.0,0.0,1.602,7.6362,13.055,387.14,388.59,402.34,-8.6127
178.9649,2.7312,7.68,0.0,0.0,1.5997,8.3112,13.049,387.06,388.51,402.36,-8.6205
178.9659,2.512,7.7035,0.0,0.0,1.5992,7.6,13.049,386.98,388.42,402.38,-8.6274
178.9669,2.7125,7.6919,0.0,0.0,1.6061,8.2728,13.051,386.9,388.33,402.4,-8.6328
178.9679,2.5367,7.6928,0.0,0.0,1.5949,7.6517,13.049,386.82,388.24,402.41,-8.6379
178.9689,2.7244,7.6953,0.0,0.0,1.6057,8.2705,13.049,386.74,388.16,402.43,-8.6483
178.9699,2.5268,7.6863,0.0,0.0,1.6006,7.67,13.055,386.64,388.07,402.44,-8.6536
178.9709,2.7115,7.7076,0.0,0.0,1.6011,8.2547,13.051,386.55,387.98,402.45,-8.6601
178.9719,2.5567,7.6784,0.0,0.0,1.6018,7.6929,13.049,386.45,387.89,402.46,-8.6672
178.9729,2.6934,7.7034,0.0,0.0,1.5989,8.2344,13.053,386.35,387.81,402.47,-8.6726
178.9739,2.5577,7.6947,0.0,0.0,1.6061,7.7154,13.051,386.25,387.72,402.48,-8.6817
178.9749,2.6852,7.6862,0.0,0.0,1.5954,8.1729,13.056,386.15,387.63,402.49,-8.6887
178.9759,2.5847,7.6987,0.0,0.0,1.6036,7.8132,13.055,386.05,387.54,402.5,-8.6942
178.9769,2.6777,7.6864,0.0,0.0,1.6035,8.1318,13.055,385.95,387.46,402.51,-8.7004
178.9779,2.5792,7.7033,0.0,0.0,1.5969,7.811,13.047,385.85,387.37,402.52,-8.7081
178.9789,2.6579,7.6822,0.0,0.0,1.6036,8.0931,13.051,385.75,387.28,402.53,-8.7143
178.9799,2.6047,7.6949,0.0,0.0,1.5975,7.8565,13.06,385.65,387.2,402.54,-8.7221
178.9809,2.6501,7.7041,0.0,0.0,1.6055,8.0319,13.049,385.55,387.12,402.55,-8.7269
178.9819,2.612,7.6784,0.0,0.0,1.5965,7.8906,13.053,385.45,387.04,402.57,-8.7367
178.9829,2.6251,7.7056,0.0,0.0,1.6018,8.0111,13.049,385.35,386.95,402.58,-8.7422
178.9839,2.6318,7.689,0.0,0.0,1.6053,7.9365,13.053,385.25,386.87,402.6,-8.75
178.9849,2.6184,7.6961,0.0,0.0,1.5949,7.9906,13.052,385.15,386.79,402.61,-8.7564
178.9859,2.6269,7.687,0.0,0.0,1.6048,7.9548,13.051,385.05,386.71,402.63,-8.7638
178.9869,2.5987,7.69,0.0,0.0,1.5996,7.9627,13.053,384.95,386.63,402.64,-8.7702
178.9879,2.6721,7.7038,0.0,0.0,1.6018,8.0547,13.053,384.85,386.55,402.66,-8.7764
178.9889,2.5972,7.6781,0.0,0.0,1.6002,7.906,13.049,384.75,386.47,402.67,-8.7827
178.9899,2.6652,7.7026,0.0,0.0,1.5982,8.021,13.047,384.66,386.37,402.69,-8.7902
178.9909,2.5898,7.6935,0.0,0.0,1.6068,7.8809,13.045,384.58,386.28,402.7,-8.798
178.9919,2.68,7.6898,0.0,0.0,1.5938,8.0984,13.047,384.5,386.18,402.71,-8.8028
178.9929,2.5646,7.6957,0.0,0.0,1.605,7.8626,13.051,384.42,386.09,402.72,-8.8105
178.9939,2.693,7.6855,0.0,0.0,1.6002,8.1237,13.048,384.34,385.99,402.73,-8.8167
178.9949,2.5561,7.7073,0.0,0.0,1.5996,7.7827,13.051,384.26,385.89,402.75,-8.8245
178.9959,2.7149,7.6769,0.0,0.0,1.6012,8.2217,13.053,384.18,385.8,402.76,-8.832
178.9969,2.5439,7.7013,0.0,0.0,1.5986,7.7779,13.053,384.09,385.7,402.77,-8.837
178.9979,2.7153,7.6973,0.0,0.0,1.6058,8.2444,13.049,384.01,385.6,402.78,-8.8445
178.9989,2.5421,7.6814,0.0,0.0,1.5949,7.7392,13.051,383.93,385.51,402.79,-8.8509
178.9999,2.7392,7.7028,0.0,0.0,1.6042,8.2422,13.051,383.86,385.42,402.8,-8.8577
179.0009,2.5288,7.6873,0.0,0.0,1.6041,7.6955,13.051,383.78,385.33,402.8,-8.8661
179.0019,2.7476,7.7011,0.0,0.0,1.5959,8.2906,13.049,383.71,385.25,402.8,-8.8716
179.0029,2.5223,7.6831,0.0,0.0,1.6048,7.6774,13.049,383.64,385.16,402.8,-8.8786
179.0039,2.755,7.6929,0.0,0.0,1.5976,8.3161,13.047,383.57,385.08,402.8,-8.8834
179.0049,2.507,7.7069,0.0,0.0,1.6056,7.5951,13.051,383.49,384.99,402.8,-8.8934
179.0059,2.7486,7.6772,0.0,0.0,1.5971,8.3269,13.045,383.42,384.91,402.8,-8.8973
179.0069,2.5008,7.704,0.0,0.0,1.6009,7.6107,13.045,383.35,384.83,402.8,-8.9065
179.0079,2.7695,7.6914,0.0,0.0,1.6065,8.3936,13.051,383.28,384.74,402.8,-8.9127
179.0089,2.4878,7.6931,0.0,0.0,1.5936,7.5719,13.055,383.2,384.66,402.8,-8.9195
179.0099,2.7492,7.6935,0.0,0.0,1.6065,8.3213,13.05,383.13,384.57,402.81,-8.9267
179.0109,2.5015,7.6873,0.0,0.0,1.5995,7.6286,13.051,383.05,384.49,402.83,-8.9315
179.0119,2.776,7.7049,0.0,0.0,1.6009,8.3987,13.051,382.98,384.4,402.85,-8.9391
179.0129,2.5006,7.679,0.0,0.0,1.6011,7.6008,13.049,382.9,384.32,402.86,-8.9482
179.0139,2.7588,7.7005,0.0,0.0,1.5979,8.4191,13.053,382.83,384.23,402.88,-8.9531
179.0149,2.493,7.695,0.0,0.0,1.6071,7.5485,13.055,382.75,384.15,402.9,-8.9608
179.0159,2.7845,7.688,0.0,0.0,1.5946,8.4603,13.054,382.68,384.07,402.92,-8.9661
179.0169,2.5051,7.6961,0.0,0.0,1.6043,7.5666,13.047,382.6,383.98,402.94,-8.9741
179.0179,2.77,7.6897,0.0,0.0,1.6033,8.4012,13.047,382.53,383.9,402.96,-8.9795
179.0189,2.4926,7.705,0.0,0.0,1.5986,7.5594,13.049,382.45,383.81,402.97,-8.9866
179.0199,2.7775,7.6799,0.0,0.0,1.6025,8.4424,13.051,382.38,383.73,402.98,-8.9925
179.0209,2.5114,7.7007,0.0,0.0,1.5988,7.5667,13.051,382.31,383.64,402.99,-9.0002
179.0219,2.7662,7.7009,0.0,0.0,1.6062,8.4402,13.055,382.23,383.56,403.0,-9.0057
179.0229,2.5248,7.6814,0.0,0.0,1.595,7.6231,13.051,382.16,383.47,403.0,-9.0135
179.0239,2.7773,7.7054,0.0,0.0,1.6038,8.4271,13.049,382.09,383.39,403.01,-9.0203
179.0249,2.5315,7.6868,0.0,0.0,1.6047,7.6388,13.049,382.02,383.31,403.01,-9.0267
179.0259,2.7597,7.6997,0.0,0.0,1.5958,8.4428,13.045,381.94,383.22,403.02,-9.0343
179.0269,2.5125,7.6881,0.0,0.0,1.6061,7.6136,13.049,381.87,383.14,403.03,-9.0406
179.0279,2.7515,7.697,0.0,0.0,1.6003,8.3477,13.049,381.8,383.05,403.03,-9.0483
179.0289,2.5374,7.7041,0.0,0.0,1.6028,7.6364,13.051,381.73,382.97,403.04,-9.0538
179.0299,2.7519,7.6813,0.0,0.0,1.5998,8.3887,13.051,381.66,382.9,403.04,-9.0623
179.0309,2.5448,7.7059,0.0,0.0,1.6004,7.6797,13.051,381.59,382.83,403.05,-9.0686
179.0319,2.7454,7.6922,0.0,0.0,1.607,8.3478,13.049,381.52,382.77,403.05,-9.0747
179.0329,2.5464,7.6949,0.0,0.0,1.5952,7.734,13.049,381.46,382.71,403.05,-9.0827
179.0339,2.7325,7.6955,0.0,0.0,1.6068,8.3318,13.047,381.39,382.64,403.05,-9.0893
179.0349,2.5529,7.689,0.0,0.0,1.6007,7.7389,13.055,381.32,382.58,403.06,-9.095
179.0359,2.7269,7.7094,0.0,0.0,1.6026,8.332,13.049,381.26,382.52,403.06,-9.1004
179.0369,2.5858,7.6798,0.0,0.0,1.6019,7.8315,13.049,381.19,382.45,403.06,-9.1103
179.0379,2.7133,7.7058,0.0,0.0,1.6006,8.2959,13.051,381.13,382.39,403.07,-9.1164
179.0389,2.6104,7.6985,0.0,0.0,1.6076,7.8546,13.045,381.06,382.33,403.07,-9.1228
179.0399,2.7117,7.689,0.0,0.0,1.5957,8.2524,13.049,380.98,382.26,403.08,-9.1305
179.0409,2.6064,7.7026,0.0,0.0,1.6057,7.9112,13.049,380.9,382.18,403.09,-9.1351
179.0419,2.6992,7.6909,0.0,0.0,1.605,8.2296,13.053,380.81,382.11,403.11,-9.1444
179.0429,2.6325,7.7026,0.0,0.0,1.5971,7.9367,13.049,380.73,382.04,403.12,-9.1493
179.0439,2.6985,7.6877,0.0,0.0,1.6067,8.2294,13.049,380.64,381.97,403.14,-9.1577
179.0449,2.6389,7.6965,0.0,0.0,1.5982,7.9596,13.049,380.56,381.89,403.15,-9.1638
179.0459,2.659,7.7074,0.0,0.0,1.6076,8.1141,13.049,380.47,381.82,403.17,-9.1708
179.0469,2.6587,7.6822,0.0,0.0,1.5978,8.0006,13.049,380.39,381.75,403.19,-9.1757
179.0479,2.6655,7.7066,0.0,0.0,1.6032,8.1318,13.049,380.3,381.68,403.2,-9.1847
179.0489,2.6657,7.6928,0.0,0.0,1.6071,8.0392,13.055,380.22,381.6,403.22,-9.1894
179.0499,2.6385,7.7028,0.0,0.0,1.5975,8.0524,13.051,380.14,381.54,403.23,-9.198
179.0509,2.6927,7.6878,0.0,0.0,1.6049,8.1211,13.045,380.05,381.47,403.24,-9.2026
179.0519,2.6313,7.6962,0.0,0.0,1.6024,8.0339,13.056,379.97,381.41,403.25,-9.2142
179.0529,2.7065,7.7076,0.0,0.0,1.6029,8.1804,13.049,379.89,381.35,403.26,-9.2172
179.0539,2.611,7.6809,0.0,0.0,1.6006,7.9545,13.047,379.81,381.28,403.28,-9.2249
179.0549,2.6889,7.7068,0.0,0.0,1.6013,8.1937,13.049,379.73,381.22,403.29,-9.2329
179.0559,2.6236,7.695,0.0,0.0,1.6077,7.9906,13.043,379.65,381.16,403.3,-9.2382
179.0569,2.7207,7.692,0.0,0.0,1.5946,8.2241,13.053,379.57,381.09,403.31,-9.2452
179.0579,2.5917,7.7004,0.0,0.0,1.6075,7.9265,13.053,379.48,381.03,403.32,-9.2513
179.0589,2.7343,7.6893,0.0,0.0,1.6017,8.2652,13.049,379.4,380.97,403.34,-9.2591
179.0599,2.5758,7.7091,0.0,0.0,1.6012,7.8238,13.049,379.33,380.9,403.35,-9.2647
179.0609,2.7549,7.6824,0.0,0.0,1.6042,8.3423,13.047,379.27,380.82,403.35,-9.2723
179.0619,2.563,7.7013,0.0,0.0,1.5986,7.8057,13.045,379.21,380.74,403.36,-9.2793
179.0629,2.7595,7.7027,0.0,0.0,1.6084,8.2907,13.049,379.15,380.67,403.36,-9.2848
179.0639,2.5501,7.6857,0.0,0.0,1.5958,7.7646,13.049,379.09,380.59,403.37,-9.2924
179.0649,2.7618,7.7014,0.0,0.0,1.6039,8.3428,13.052,379.03,380.52,403.38,-9.2972
179.0659,2.5564,7.694,0.0,0.0,1.6064,7.7959,13.051,378.97,380.44,403.38,-9.3049
179.0669,2.7624,7.7003,0.0,0.0,1.5958,8.3679,13.053,378.91,380.37,403.39,-9.3126
179.0679,2.5359,7.6877,0.0,0.0,1.6067,7.7186,13.055,378.85,380.29,403.39,-9.3186
179.0689,2.7679,7.6981,0.0,0.0,1.5995,8.3523,13.051,378.79,380.22,403.4,-9.3267
179.0699,2.5356,7.7054,0.0,0.0,1.6049,7.7185,13.047,378.72,380.14,403.4,-9.3321
179.0709,2.7815,7.6832,0.0,0.0,1.599,8.3939,13.047,378.65,380.06,403.4,-9.339
179.0719,2.5268,7.7033,0.0,0.0,1.6009,7.6493,13.049,378.58,379.99,403.39,-9.3482
179.0729,2.7893,7.6936,0.0,0.0,1.6075,8.4324,13.045,378.51,379.91,403.39,-9.3528
179.0739,2.5155,7.6977,0.0,0.0,1.5958,7.6721,13.047,378.44,379.84,403.39,-9.362
179.0749,2.7966,7.6913,0.0,0.0,1.6055,8.4757,13.049,378.38,379.76,403.38,-9.3683
179.0759,2.5152,7.6917,0.0,0.0,1.6003,7.6494,13.049,378.31,379.69,403.38,-9.3733
179.0769,2.7954,7.7081,0.0,0.0,1.6024,8.442,13.047,378.24,379.61,403.38,-9.3823
179.0779,2.5263,7.6803,0.0,0.0,1.6009,7.6492,13.048,378.17,379.54,403.38,-9.3886
179.0789,2.7904,7.7043,0.0,0.0,1.5996,8.4627,13.047,378.1,379.46,403.37,-9.3933
179.0799,2.5195,7.6987,0.0,0.0,1.6086,7.6262,13.047,378.02,379.39,403.37,-9.404
179.0809,2.7967,7.6899,0.0,0.0,1.594,8.4472,13.05,377.95,379.32,403.37,-9.4072
179.0819,2.5195,7.7001,0.0,0.0,1.6067,7.6285,13.052,377.87,379.25,403.36,-9.4136
179.0829,2.8039,7.6904,0.0,0.0,1.6031,8.4885,13.049,377.8,379.18,403.36,-9.4232
179.0839,2.5465,7.705,0.0,0.0,1.5986,7.7059,13.055,377.72,379.11,403.36,-9.4288
179.0849,2.7965,7.6862,0.0,0.0,1.6058,8.4501,13.055,377.65,379.04,403.35,-9.4336
179.0859,2.521,7.6999,0.0,0.0,1.5982,7.68,13.055,377.57,378.97,403.35,-9.4429
179.0869,2.8091,7.7041,0.0,0.0,1.6082,8.4657,13.052,377.49,378.9,403.35,-9.4497
179.0879,2.5459,7.6867,0.0,0.0,1.5972,7.7005,13.047,377.42,378.83,403.35,-9.4553
179.0889,2.8034,7.7034,0.0,0.0,1.6036,8.4708,13.051,377.34,378.76,403.34,-9.4629
179.0899,2.5523,7.6913,0.0,0.0,1.6066,7.7163,13.051,377.26,378.69,403.34,-9.4707
179.0909,2.785,7.7028,0.0,0.0,1.5972,8.4502,13.047,377.18,378.62,403.34,-9.4761
179.0919,2.5607,7.6868,0.0,0.0,1.6062,7.762,13.053,377.1,378.55,403.33,-9.4832
179.0929,2.7791,7.6963,0.0,0.0,1.6003,8.4734,13.055,377.02,378.47,403.33,-9.4893
179.0939,2.5535,7.7066,0.0,0.0,1.6045,7.7412,13.051,376.94,378.4,403.33,-9.4957
179.0949,2.7853,7.6823,0.0,0.0,1.6007,8.4527,13.049,376.86,378.33,403.32,-9.5033
179.0959,2.5784,7.706,0.0,0.0,1.6007,7.7644,13.049,376.77,378.26,403.32,-9.5095
179.0969,2.7835,7.6945,0.0,0.0,1.6082,8.4167,13.052,376.69,378.18,403.32,-9.5171
179.0979,2.5743,7.6956,0.0,0.0,1.5953,7.8209,13.049,376.61,378.11,403.32,-9.525
179.0989,2.765,7.6973,0.0,0.0,1.6079,8.3938,13.055,376.53,378.04,403.31,-9.5311
179.0999,2.5981,7.6904,0.0,0.0,1.6007,7.821,13.053,376.45,377.97,403.31,-9.5373
179.1009,2.7544,7.7109,0.0,0.0,1.6032,8.4322,13.049,376.38,377.91,403.31,-9.5451
179.1019,2.6197,7.6807,0.0,0.0,1.6024,7.9212,13.051,376.31,377.84,403.31,-9.5506
179.1029,2.7397,7.7072,0.0,0.0,1.6006,8.3552,13.056,376.24,377.78,403.31,-9.5576
179.1039,2.6201,7.6973,0.0,0.0,1.6084,7.9547,13.049,376.16,377.72,403.31,-9.5637
179.1049,2.7331,7.6936,0.0,0.0,1.5975,8.3394,13.049,376.09,377.65,403.31,-9.5715
179.1059,2.6524,7.7021,0.0,0.0,1.6063,8.0185,13.049,376.02,377.59,403.31,-9.5769
179.1069,2.7061,7.6907,0.0,0.0,1.6044,8.2551,13.047,375.95,377.53,403.31,-9.5846
179.1079,2.6392,7.7066,0.0,0.0,1.5992,7.9644,13.051,375.87,377.46,403.31,-9.5924
179.1089,2.712,7.6863,0.0,0.0,1.6064,8.2503,13.052,375.8,377.4,403.31,-9.5972
179.1099,2.673,7.7,0.0,0.0,1.5986,8.0777,13.049,375.74,377.33,403.31,-9.6041
179.1109,2.6867,7.7062,0.0,0.0,1.6083,8.2296,13.057,375.67,377.27,403.32,-9.6126
179.1119,2.6801,7.6843,0.0,0.0,1.5981,8.0984,13.047,375.61,377.2,403.32,-9.6174
179.1129,2.6782,7.7099,0.0,0.0,1.6053,8.1549,13.049,375.55,377.13,403.32,-9.6257
179.1139,2.6996,7.6914,0.0,0.0,1.6069,8.1442,13.049,375.49,377.07,403.33,-9.6327
179.1149,2.672,7.7029,0.0,0.0,1.5977,8.1548,13.049,375.43,377.0,403.33,-9.6381
179.1159,2.7196,7.6927,0.0,0.0,1.6079,8.1853,13.051,375.37,376.93,403.33,-9.6467
179.1169,2.6389,7.695,0.0,0.0,1.6,8.0728,13.047,375.31,376.87,403.33,-9.6529
179.1179,2.7209,7.7102,0.0,0.0,1.6053,8.2418,13.043,375.25,376.8,403.34,-9.6604
179.1189,2.6499,7.6855,0.0,0.0,1.6026,8.05,13.056,375.19,376.74,403.34,-9.6682
180.3193,2.5512,7.7065,0.0,0.0,1.6073,7.7406,13.051,326.81,324.16,112.83,-9.7849
182.3193,2.5456,7.726,0.0,0.0,1.6165,7.7201,13.052,239.68,220.92,84.003,-9.7841
184.3193,2.4403,7.7661,0.0,0.0,1.6357,7.4038,13.052,90.877,83.085,43.186,-9.7844
186.161,2.456,7.7886,0.0,0.0,1.6468,7.4512,13.052,58.319,54.615,30.431,-9.7859
188.161,2.474,7.8045,0.0,0.0,1.6545,7.5058,13.052,44.238,41.952,27.331,-9.7857
190.161,2.4123,7.8127,0.0,0.0,1.6587,7.3177,13.158,43.947,42.64,32.521,-9.7367
190.961,2.4088,7.8144,0.0,0.0,1.6595,7.3097,13.135,46.027,45.099,36.125,-9.6898