File: examples/dan-msc-case-studies/CS4/data/01 raw data/hyde_test_008.csv
Time(sec),Force(kN),Jaw(mm),PowAngle(deg),PTemp,Strain,Stress(MPa),TC1(C),TC2(C),TC3(C)
0.0,2.4374,0.010153,0.0,0.0059532,0.0011521,7.3892,20.793,21.892,21.471
1.6,2.3382,0.010948,0.0,4.621,0.0012054,7.095,20.88,21.764,21.496
3.2,2.3845,0.011578,0.0,9.421,0.0012222,7.2336,20.857,21.845,21.501
4.8,2.4303,0.011808,0.0,14.221,0.0013235,7.3712,20.798,21.817,21.49
6.2347,2.4755,0.012266,0.0,18.525,0.0013342,7.5124,20.584,21.605,21.29
7.8347,2.6929,0.014536,22.952,23.325,0.0016141,8.1696,21.157,22.675,21.759
9.4347,3.05,0.016717,22.999,28.125,0.001847,9.2503,27.096,29.502,27.713
11.0347,2.9454,0.014287,23.223,32.925,0.0016107,8.9342,32.424,38.554,33.02
12.6347,2.7188,0.011567,23.47,37.725,0.0012404,8.2499,37.531,40.258,38.043
14.2347,2.6797,0.0095139,24.046,42.525,0.001006,8.1309,42.48,45.086,42.971
15.8347,2.6839,0.0077344,25.903,47.325,0.0008785,8.1423,47.158,49.922,47.565
17.4347,2.6732,0.0058548,26.888,52.125,0.0006416,8.1077,51.907,54.653,52.309
19.0347,2.6655,0.0038384,27.255,56.925,0.00049102,8.0843,56.765,59.465,57.166
20.6347,2.6661,0.001573,28.468,61.725,0.00017149,8.0886,61.428,64.062,61.71
22.2347,2.6702,-0.00079078,27.605,66.525,-0.00013086,8.1038,66.379,69.027,66.719
23.8347,2.6808,-0.0031171,28.738,71.325,-0.00034554,8.1324,71.079,73.979,71.662
25.43471,2.6795,-0.0038101,28.347,76.125,-0.00043746,8.1276,76.059,79.065,76.666
27.03471,2.4999,-0.0067302,28.673,80.925,-0.00070409,7.5825,80.786,83.83,81.523
28.63471,2.2396,-0.010202,29.258,85.725,-0.0010938,6.7965,85.557,88.21,86.347
30.23471,2.1777,-0.012621,29.178,90.525,-0.0014092,6.6093,90.442,93.493,91.392
31.83471,2.0895,-0.015493,28.974,95.325,-0.0017441,6.3403,95.346,98.629,96.546
33.43471,2.0204,-0.01801,29.626,100.13,-0.0019597,6.127,100.1,103.61,101.42
35.03471,1.9752,-0.020732,29.796,104.93,-0.0022813,5.9893,104.85,108.16,106.2
36.63471,1.9572,-0.023465,30.233,109.73,-0.0025307,5.9387,109.66,112.81,110.97
38.1534,1.9466,-0.025835,30.262,114.28,-0.0028172,5.902,114.26,117.32,115.65
39.7534,1.9392,-0.028368,30.529,119.08,-0.0031122,5.8842,119.05,121.72,120.29
41.3534,1.9346,-0.031173,30.587,123.88,-0.0033635,5.8728,123.88,126.34,125.12
42.9534,1.938,-0.03345,31.008,128.68,-0.0036668,5.8784,128.62,130.9,129.9
44.4916,1.9293,-0.036107,31.32,133.3,-0.0039924,5.8541,133.19,135.44,134.45
46.0916,1.9334,-0.03875,31.149,138.1,-0.0042225,5.8672,138.06,140.35,139.36
47.6916,1.9307,-0.041157,31.45,142.9,-0.0045253,5.855,142.85,144.95,144.21
49.2916,1.9295,-0.043726,31.786,147.7,-0.0047354,5.8533,147.67,149.59,149.04
50.8916,1.925,-0.046442,31.71,152.5,-0.0050792,5.8415,152.47,154.28,153.81
52.4916,1.9287,-0.048723,31.804,157.3,-0.0053752,5.8525,157.33,159.17,158.62
54.0916,1.9302,-0.051625,31.851,162.1,-0.0057001,5.8568,162.15,164.1,163.57
55.6916,1.9321,-0.056461,32.74,166.9,-0.0061736,5.8606,166.74,168.29,167.97
57.2916,1.9289,-0.058758,31.987,171.7,-0.0064445,5.8485,171.7,173.27,172.83
58.8916,1.9161,-0.060322,31.82,176.5,-0.0065625,5.8126,176.67,178.4,178.07
60.4916,1.9181,-0.063295,32.352,181.3,-0.0069024,5.8214,181.33,182.71,182.66
62.0916,1.9204,-0.065817,32.849,186.1,-0.0072285,5.8286,186.04,187.28,187.27
63.69161,1.9243,-0.068327,33.04,190.9,-0.0075251,5.8374,190.92,192.14,192.27
65.29161,1.9242,-0.071624,33.66,195.7,-0.0078199,5.835,195.59,196.66,196.88
66.89161,1.9163,-0.074382,33.028,200.5,-0.0081371,5.8109,200.51,201.54,201.88
68.49161,1.922,-0.077377,32.887,205.3,-0.0084417,5.8337,205.37,206.2,206.75
70.09161,1.9246,-0.082054,33.769,210.1,-0.0089439,5.8387,209.97,210.61,211.17
71.5993,1.9235,-0.086091,34.151,214.62,-0.0094417,5.8389,214.47,214.93,215.64
73.1993,1.9258,-0.08906,33.824,219.42,-0.0096825,5.843,219.39,219.69,220.46
74.7993,1.9228,-0.091173,33.875,224.22,-0.0099146,5.8295,224.2,224.5,225.28
76.2894,1.9145,-0.092973,33.942,228.69,-0.010171,5.8054,228.68,228.79,229.81
77.8894,1.9063,-0.095339,33.777,233.49,-0.010385,5.7857,233.48,233.36,234.49
79.4894,1.9119,-0.098334,33.768,238.29,-0.010759,5.8021,238.32,237.92,239.19
81.0894,1.9183,-0.10107,33.774,243.09,-0.010995,5.8179,243.13,242.63,244.03
82.6894,1.9161,-0.10421,33.773,247.89,-0.011378,5.8114,247.91,247.24,248.71
84.2894,1.912,-0.10695,34.031,252.69,-0.011719,5.8012,252.7,251.9,253.53
85.8894,1.9057,-0.11034,34.105,257.49,-0.01208,5.7859,257.49,256.68,258.41
87.4894,1.9141,-0.11434,34.575,262.29,-0.012457,5.8049,262.26,261.32,263.15
89.0894,1.9211,-0.11806,34.366,267.09,-0.012894,5.8282,267.08,265.81,267.9
90.6894,1.9236,-0.12245,34.651,271.89,-0.013307,5.8331,271.83,270.51,272.59
92.2894,1.9206,-0.12581,34.539,276.69,-0.013702,5.8242,276.66,274.95,277.31
93.88941,1.9159,-0.12784,34.612,281.49,-0.014006,5.8125,281.51,279.74,282.22
95.48941,1.922,-0.12901,34.878,286.29,-0.014152,5.832,286.25,284.55,287.09
97.08941,1.9244,-0.13158,34.602,291.09,-0.014341,5.8396,291.12,289.14,291.8
98.68941,1.9272,-0.13441,34.545,295.89,-0.014678,5.8464,296.0,293.88,296.72
100.28941,1.9202,-0.13773,34.637,300.69,-0.015006,5.8251,300.68,298.36,301.23
101.88941,1.9177,-0.14114,34.684,305.49,-0.015345,5.8175,305.53,303.07,306.07
103.4335,1.9219,-0.14422,34.806,310.12,-0.015709,5.8286,310.1,307.19,310.35
105.0335,1.9167,-0.14759,34.473,314.92,-0.016126,5.8141,315.06,312.04,315.33
106.5872,1.9241,-0.15074,34.613,319.58,-0.016384,5.8387,319.6,316.08,319.49
108.1872,1.9258,-0.15377,34.652,324.38,-0.016794,5.8424,324.41,320.76,324.13
109.7872,1.9231,-0.15872,34.65,329.18,-0.017386,5.8324,329.22,325.68,328.94
111.3872,1.9232,-0.16461,34.777,333.98,-0.017935,5.8336,333.93,330.42,333.65
112.9872,2.0303,-0.16355,35.186,338.78,-0.017793,6.1667,338.71,335.0,338.45
114.5872,2.1437,-0.16506,35.247,343.58,-0.018006,6.5028,343.5,339.83,343.34
116.1872,2.409,-0.16567,35.249,348.38,-0.018003,7.3078,348.38,344.74,348.17
117.7872,2.4828,-0.16506,34.847,350.0,-0.017949,7.5303,349.88,345.33,348.95
119.3872,2.4995,-0.16894,33.661,350.0,-0.01841,7.5806,350.07,345.83,349.28
120.9872,2.4834,-0.16638,33.622,350.0,-0.018181,7.5363,350.06,345.91,349.24
122.5872,2.5024,-0.16674,33.16,350.0,-0.018189,7.5927,350.08,346.04,349.25
124.1872,2.5358,-0.17086,33.813,350.0,-0.018619,7.6921,351.37,348.97,350.99
125.78721,2.5217,-0.16807,32.056,350.0,-0.018332,7.648,351.72,348.08,350.94
127.38721,2.5064,-0.16874,32.558,350.0,-0.01834,7.6052,351.54,347.5,350.55
128.98721,2.5113,-0.17132,32.822,350.0,-0.018639,7.6195,351.36,347.26,350.35
130.58721,2.5322,-0.1706,34.518,350.0,-0.018598,7.6855,351.58,347.85,350.57
132.18721,2.5347,-0.1698,32.956,350.0,-0.018543,7.6869,351.96,347.95,350.71
133.78721,2.5361,-0.17269,32.199,350.0,-0.018837,7.6882,353.72,348.94,352.35
135.38721,2.5331,-0.17175,33.095,350.0,-0.018687,7.6814,353.46,349.14,352.22
136.8008,2.5327,-0.17163,33.027,350.0,-0.018722,7.6807,353.5,349.38,352.26
138.4008,2.5268,-0.17251,32.742,350.0,-0.018767,7.6654,353.58,349.51,352.32
140.0008,2.5287,-0.1722,32.823,350.0,-0.018776,7.6735,353.5,349.45,352.28
141.6008,2.4958,-0.17338,32.433,350.0,-0.018864,7.574,353.51,349.26,352.17
143.2008,2.5069,-0.1734,32.296,350.0,-0.018819,7.6056,353.56,349.37,352.15
144.8008,2.4895,-0.17405,31.94,350.0,-0.01896,7.5509,353.62,349.56,352.31
146.4008,2.4943,-0.17369,32.317,350.0,-0.018964,7.5643,353.56,349.53,352.22
148.0008,2.4827,-0.17483,33.281,350.0,-0.019096,7.5338,352.59,349.04,351.33
149.6008,2.47,-0.17746,30.794,350.0,-0.019332,7.496,352.58,348.34,351.18
151.2008,2.4788,-0.17414,31.994,350.0,-0.01895,7.5184,351.75,347.72,350.29
152.8008,2.4819,-0.17573,32.7,350.0,-0.01915,7.5253,351.69,347.78,350.3
154.4008,2.484,-0.17453,32.849,350.0,-0.018983,7.5324,351.67,347.86,350.32
156.00081,2.4672,-0.1757,32.695,350.0,-0.019081,7.4852,351.65,347.84,350.34
157.60081,2.4969,-0.17461,32.235,350.0,-0.019007,7.5781,351.77,347.87,350.37
159.20081,2.4929,-0.17535,32.256,350.0,-0.019118,7.5647,351.76,347.76,350.34
160.80081,2.4812,-0.17492,32.345,350.0,-0.019104,7.5258,351.77,347.67,350.29
161.9529,2.4845,0.03196,0.0,2.1211,0.0022868,7.4995,351.59,347.61,350.41
161.9537,2.4663,0.027563,0.0,3.0867e-11,0.003635,7.4881,351.58,347.58,350.43
161.9545,2.4304,0.026493,0.0,4.2442e-22,0.0039541,7.3325,351.57,347.54,350.44
161.9553,2.4511,0.037691,0.0,5.9439e-33,0.0030994,7.4804,351.55,347.51,350.46
161.9561,2.4371,0.027806,0.0,7.987399999999999e-44,0.0029153,7.373,351.56,347.53,350.45
161.9569,2.5436,0.013997,0.0,0.0,0.0026902,7.6636,351.57,347.54,350.44
161.95769,2.4746,0.039719,0.0,0.0,0.0039439,7.532,351.59,347.56,350.44
161.95849,2.4556,0.037024,0.0,0.0,0.0033092,7.4067,351.6,347.58,350.43
161.95929,2.4956,0.021859,0.0,0.0,0.0026232,7.5862,351.61,347.6,350.42
161.96009,2.4243,0.030618,0.0,0.0,0.004148,7.3567,351.62,347.61,350.42
161.96089,2.5109,0.034927,0.0,0.0,0.0035473,7.5735,351.63,347.63,350.41
161.96169,2.4466,0.030525,0.0,0.0,0.0025647,7.427,351.65,347.65,350.4
161.96249,2.4558,0.026644,0.0,0.0,0.0038376,7.4456,351.66,347.66,350.39
161.96329,2.4882,0.026249,0.0,0.0,0.0035187,7.5867,351.67,347.68,350.39
161.96409,2.4129,0.036621,0.0,0.0,0.0029221,7.3633,351.68,347.7,350.38
161.96489,2.5055,0.029636,0.0,0.0,0.0034937,7.6086,351.7,347.71,350.37
161.96569,2.4281,0.021003,0.0,0.0,0.0033367,7.3835,351.71,347.73,350.37
161.96649,2.4607,0.037243,0.0,0.0,0.003369,7.4583,351.71,347.73,350.36
161.96728,2.486,0.034319,0.0,0.0,0.0030311,7.5369,351.72,347.74,350.36
161.96808,2.4104,0.022096,0.0,0.0,0.0027857,7.315,351.73,347.74,350.35
161.96888,2.4979,0.033642,0.0,0.0,0.004062,7.5615,351.73,347.75,350.35
161.96968,2.4172,0.032685,0.0,0.0,0.0031429,7.3734,351.74,347.75,350.34
161.97048,2.4581,0.028071,0.0,0.0,0.0026061,7.4811,351.75,347.76,350.34
161.97128,2.4803,0.026797,0.0,0.0,0.0038888,7.5037,351.76,347.76,350.33
161.97208,2.4229,0.028443,0.0,0.0,0.0035215,7.3288,351.76,347.76,350.33
161.97288,2.5116,0.034001,0.0,0.0,0.0027714,7.6225,351.77,347.77,350.32
161.97368,2.4153,0.027203,0.0,0.0,0.0033927,7.3369,351.78,347.77,350.32
161.97448,2.4621,0.025647,0.0,0.0,0.0034893,7.4708,351.78,347.78,350.31
161.97528,2.4534,0.036516,0.0,0.0,0.0033677,7.4677,351.79,347.78,350.31
161.97608,2.4228,0.03095,0.0,0.0,0.0029779,7.3353,351.79,347.79,350.31
161.97688,2.4911,0.023709,0.0,0.0,0.003069,7.5602,351.79,347.79,350.31
161.97767,2.403,0.034298,0.0,0.0,0.0038763,7.3237,351.79,347.79,350.31
161.97847,2.4743,0.031706,0.0,0.0,0.0030059,7.4778,351.78,347.79,350.31
161.97927,2.4494,0.027087,0.0,0.0,0.0026997,7.4419,351.78,347.8,350.31
161.98007,2.4297,0.029642,0.0,0.0,0.0040326,7.3734,351.78,347.8,350.31
161.98087,2.4865,0.030327,0.0,0.0,0.0032821,7.5567,351.78,347.8,350.31
161.98167,2.4045,0.032651,0.0,0.0,0.0028482,7.282,351.77,347.8,350.31
161.98247,2.4753,0.026275,0.0,0.0,0.003531,7.5311,351.77,347.81,350.31
161.98327,2.4385,0.028075,0.0,0.0,0.0034836,7.3762,351.77,347.81,350.31
161.98407,2.4357,0.035665,0.0,0.0,0.0032357,7.374,351.77,347.81,350.31
161.98487,2.4932,0.029254,0.0,0.0,0.0029384,7.5778,351.76,347.81,350.31
161.98567,2.4094,0.02532,0.0,0.0,0.0031404,7.3229,351.77,347.82,350.31
161.98647,2.4985,0.037457,0.0,0.0,0.0039017,7.5517,351.78,347.82,350.31
161.98726,2.4342,0.031506,0.0,0.0,0.0030132,7.3655,351.79,347.82,350.31
161.98806,2.4462,0.02602,0.0,0.0,0.0028451,7.4008,351.8,347.82,350.31
161.98886,2.4765,0.03149,0.0,0.0,0.0040561,7.5064,351.8,347.82,350.32
161.98966,2.4055,0.032037,0.0,0.0,0.0033639,7.2776,351.81,347.82,350.32
161.99046,2.4898,0.028415,0.0,0.0,0.002766,7.5499,351.82,347.82,350.32
161.99126,2.4121,0.024488,0.0,0.0,0.0034853,7.3291,351.83,347.82,350.32
161.99206,2.4501,0.030143,0.0,0.0,0.003381,7.4337,351.84,347.82,350.33
161.99286,2.472,0.037357,0.0,0.0,0.0034015,7.5002,351.85,347.82,350.33
161.99366,2.4138,0.026416,0.0,0.0,0.0030966,7.3038,351.86,347.82,350.33
161.99446,2.4898,0.025949,0.0,0.0,0.0032349,7.5593,351.87,347.82,350.33
161.99526,2.4018,0.037439,0.0,0.0,0.0035618,7.2961,351.88,347.82,350.34
161.99606,2.4583,0.029288,0.0,0.0,0.0029101,7.4355,351.88,347.81,350.34
161.99685,2.4611,0.025669,0.0,0.0,0.0031001,7.443,351.88,347.81,350.33
161.99765,2.4085,0.032793,0.0,0.0,0.0038738,7.3124,351.88,347.8,350.33
161.99845,2.4823,0.033042,0.0,0.0,0.0032945,7.5103,351.88,347.8,350.33
161.99925,2.4015,0.027539,0.0,0.0,0.0030829,7.2866,351.88,347.79,350.33
162.00005,2.4684,0.027101,0.0,0.0,0.0037601,7.4733,351.88,347.79,350.32
162.00085,2.4453,0.032855,0.0,0.0,0.0034653,7.4063,351.88,347.78,350.32
162.00165,2.4138,0.033191,0.0,0.0,0.0031736,7.2942,351.88,347.78,350.32
162.00245,2.4846,0.021937,0.0,0.0,0.0030463,7.5118,351.88,347.77,350.32
162.00325,2.3827,0.028794,0.0,0.0,0.0033035,7.2668,351.88,347.77,350.31
162.00405,2.4713,0.036911,0.0,0.0,0.0034248,7.4826,351.88,347.76,350.31
162.00485,2.4216,0.026446,0.0,0.0,0.0029125,7.4041,351.88,347.76,350.31
162.00565,2.4305,0.027488,0.0,0.0,0.0033454,7.3613,352.26,348.11,350.31
162.00644,2.5265,0.034843,0.0,0.0,0.0038436,7.6629,353.59,349.37,350.3
162.00724,2.3928,0.030428,0.0,0.0,0.0029691,7.2281,354.93,350.63,350.3
162.00804,2.5222,0.028338,0.0,0.0,0.0032121,7.6416,356.26,351.88,350.3
162.00884,2.4035,0.028395,0.0,0.0,0.003852,7.3138,357.6,353.14,350.3
162.00964,2.8316,0.03327,0.0,0.0,0.003247,8.5363,358.93,354.4,350.29
162.01044,2.5572,0.034883,0.0,0.0,0.0034521,7.8216,360.27,355.66,350.29
162.01124,2.3155,0.020525,0.0,0.0,0.0031025,6.938,361.6,356.92,350.29
162.01204,2.7,0.035792,0.0,0.0,0.0038463,8.2032,362.94,358.18,350.29
162.01284,2.2908,0.034072,0.0,0.0,0.0031269,6.9759,364.27,359.43,350.28
162.01364,2.4759,0.027335,0.0,0.0,0.0031236,7.4993,365.6,360.69,350.28
162.01444,2.3698,0.030352,0.0,0.0,0.003703,7.2089,366.94,361.95,350.28
162.01524,2.4836,0.034289,0.0,0.0,0.0033739,7.4913,368.27,363.21,350.28
162.01603,2.3504,0.028023,0.0,0.0,0.0027634,7.124,369.9,365.04,350.28
162.01683,2.4717,0.025827,0.0,0.0,0.0033652,7.4677,371.63,367.07,350.28
162.01763,2.3658,0.030718,0.0,0.0,0.0038687,7.2333,373.36,369.1,350.28
162.01843,2.3347,0.026286,0.0,0.0,0.0022945,7.0468,375.09,371.13,350.28
162.01923,2.4715,0.031232,0.0,0.0,0.003336,7.5426,376.82,373.17,350.28
162.02003,2.276,0.022974,0.0,0.0,0.0034763,6.9435,378.55,375.2,350.28
162.02083,2.4817,0.031288,0.0,0.0,0.002967,7.5179,380.28,377.23,350.28
162.02163,2.359,0.032793,0.0,0.0,0.0030968,7.2271,382.0,379.26,350.28
162.02243,2.359,0.021265,0.0,0.0,0.0029237,7.1496,383.73,381.29,350.28
162.02323,2.4523,0.030843,0.0,0.0,0.0035215,7.4245,385.46,383.32,350.28
162.02403,5.2748,0.039908,0.0,0.0,0.0035495,14.178,387.19,385.35,350.28
162.02483,35.98,0.32084,0.0,0.0,0.034631,108.42,388.92,387.38,350.28
162.02562,39.899,0.96101,0.0,0.0,0.10838,122.0,390.29,389.06,350.28
162.02642,41.929,1.4947,0.0,0.0,0.17612,126.78,390.25,389.38,350.28
162.02722,42.248,2.0102,0.0,0.0,0.24358,128.72,390.21,389.7,350.28
162.02802,42.093,2.4126,0.0,0.0,0.3015,127.25,390.17,390.03,350.28
162.02882,43.058,2.98,0.0,0.0,0.38791,130.92,390.13,390.35,350.29
162.02962,41.82,3.5012,0.0,0.0,0.46946,126.75,390.09,390.67,350.29
162.03042,43.986,3.8308,0.0,0.0,0.52856,133.45,390.05,390.99,350.29
162.03122,43.674,4.261,0.0,0.0,0.60894,132.3,390.02,391.32,350.29
162.03202,44.83,4.6719,0.0,0.0,0.68911,135.97,389.98,391.64,350.3
162.03282,44.231,5.0744,0.0,0.0,0.77356,134.12,389.94,391.96,350.3
162.03362,45.01,5.3697,0.0,0.0,0.84409,136.54,389.9,392.28,350.3
162.03442,44.904,5.6647,0.0,0.0,0.91792,136.16,389.86,392.61,350.3
162.03522,45.045,5.9864,0.0,0.0,1.0006,136.58,389.82,392.93,350.31
162.03601,44.761,6.2196,0.0,0.0,1.0637,135.79,389.38,392.51,350.3
162.03681,45.225,6.4565,0.0,0.0,1.1405,137.13,388.74,391.72,350.3
162.03761,45.127,6.6803,0.0,0.0,1.2128,136.92,388.09,390.94,350.29
162.03841,45.389,6.8949,0.0,0.0,1.2781,137.66,387.45,390.15,350.29
162.03921,45.57,7.0606,0.0,0.0,1.3424,138.24,386.8,389.36,350.28
162.04001,45.929,7.2444,0.0,0.0,1.4202,139.23,386.16,388.58,350.28
162.04081,46.376,7.4249,0.0,0.0,1.4866,140.6,385.51,387.79,350.27
162.04161,41.445,7.5716,0.0,0.0,1.5495,126.32,384.87,387.0,350.27
162.04241,39.312,7.4547,0.0,0.0,1.505,118.45,384.22,386.22,350.26
162.04321,37.55,7.537,0.0,0.0,1.5465,113.73,383.58,385.43,350.26
162.04401,36.82,7.5297,0.0,0.0,1.5322,111.73,382.93,384.64,350.26
162.04481,36.313,7.5104,0.0,0.0,1.5246,110.13,382.29,383.86,350.25
162.0456,36.678,7.5458,0.0,0.0,1.5503,111.49,381.68,383.09,350.25
162.0464,36.557,7.534,0.0,0.0,1.5409,110.73,381.3,382.45,350.26
162.0472,35.255,7.5521,0.0,0.0,1.5393,106.9,380.93,381.81,350.28
162.048,35.373,7.5532,0.0,0.0,1.5484,107.29,380.56,381.17,350.29
162.0488,34.572,7.538,0.0,0.0,1.548,104.92,380.19,380.53,350.31
162.0496,34.548,7.5678,0.0,0.0,1.549,104.96,379.82,379.9,350.32
162.0504,34.271,7.5667,0.0,0.0,1.5475,103.98,379.45,379.26,350.34
162.0512,33.818,7.5427,0.0,0.0,1.548,102.52,379.08,378.62,350.35
162.052,33.322,7.575,0.0,0.0,1.56,101.13,378.71,377.98,350.36
162.0528,33.028,7.5778,0.0,0.0,1.552,100.24,378.34,377.34,350.38
162.0536,32.643,7.5607,0.0,0.0,1.5479,99.049,377.96,376.7,350.39
162.0544,32.356,7.5686,0.0,0.0,1.5603,98.244,377.59,376.07,350.41
162.05519,31.996,7.5684,0.0,0.0,1.555,97.096,377.22,375.43,350.42
162.05599,31.618,7.5707,0.0,0.0,1.5486,95.958,376.98,375.01,350.45
162.05679,31.258,7.5652,0.0,0.0,1.5556,94.829,376.83,374.73,350.49
162.05759,30.967,7.5609,0.0,0.0,1.5567,93.933,376.68,374.46,350.54
162.05839,30.609,7.581,0.0,0.0,1.5536,92.847,376.53,374.19,350.58
162.05919,30.347,7.574,0.0,0.0,1.5532,92.102,376.39,373.92,350.62
162.05999,29.993,7.5584,0.0,0.0,1.5549,91.033,376.24,373.64,350.66
162.06079,29.608,7.5792,0.0,0.0,1.5592,89.862,376.09,373.37,350.7
162.06159,29.045,7.5783,0.0,0.0,1.5528,88.138,375.94,373.1,350.74
162.06239,28.219,7.5619,0.0,0.0,1.5512,85.684,375.79,372.83,350.78
162.06319,27.31,7.5714,0.0,0.0,1.5607,82.967,375.64,372.55,350.82
162.06399,25.736,7.5728,0.0,0.0,1.5549,78.109,375.49,372.28,350.86
162.06478,23.844,7.5634,0.0,0.0,1.5469,72.453,375.34,372.01,350.91
162.06558,21.428,7.5558,0.0,0.0,1.5525,65.16,375.2,371.75,350.94
162.06638,18.726,7.5502,0.0,0.0,1.5494,57.085,375.21,371.75,350.93
162.06718,14.275,7.5595,0.0,0.0,1.544,44.08,375.22,371.75,350.92
162.06798,1.0591,7.5176,0.0,0.0,1.5321,4.4215,375.23,371.75,350.91
162.06878,-0.30226,7.4254,0.0,0.0,1.4968,-1.1319,375.25,371.75,350.9
162.06958,0.088707,7.4353,0.0,0.0,1.4928,0.51287,375.26,371.75,350.9
162.07038,-0.62353,7.4975,0.0,0.0,1.5175,-2.0114,375.27,371.75,350.89
162.07118,4.8805,7.5395,0.0,0.0,1.5421,13.682,375.28,371.75,350.88
162.07198,4.6888,7.5591,0.0,0.0,1.5532,14.943,375.29,371.75,350.87
162.07278,0.47335,7.543,0.0,0.0,1.5405,1.4017,375.31,371.75,350.86
162.07358,1.9294,7.5464,0.0,0.0,1.5404,5.6033,375.32,371.75,350.85
162.07437,2.8457,7.5463,0.0,0.0,1.5489,8.7423,375.33,371.75,350.84
162.07517,1.145,7.5457,0.0,0.0,1.5461,3.497,375.34,371.75,350.83
162.07597,2.2025,7.5519,0.0,0.0,1.5408,6.4734,375.35,371.74,350.82
162.07677,3.0709,7.541,0.0,0.0,1.543,9.3419,375.36,371.71,350.82
162.07757,1.6642,7.5354,0.0,0.0,1.5431,5.2408,375.37,371.69,350.82
162.07837,1.4539,7.5377,0.0,0.0,1.5365,4.2414,375.38,371.67,350.82
162.07917,2.9785,7.5401,0.0,0.0,1.5383,9.0627,375.39,371.64,350.82
162.07997,1.7606,7.525,0.0,0.0,1.5367,5.461,375.4,371.62,350.82
162.08077,1.9673,7.524,0.0,0.0,1.536,5.8607,375.41,371.59,350.82
162.08157,2.4219,7.5309,0.0,0.0,1.5344,7.4075,375.42,371.57,350.82
162.08237,1.9464,7.5169,0.0,0.0,1.5296,5.9162,375.43,371.55,350.82
162.08317,2.0281,7.5201,0.0,0.0,1.5359,6.1037,375.44,371.52,350.82
162.08397,2.2363,7.5267,0.0,0.0,1.5352,6.7793,375.45,371.5,350.82
162.08476,2.0858,7.5271,0.0,0.0,1.5317,6.3989,375.46,371.47,350.82
162.08556,1.8883,7.5202,0.0,0.0,1.5352,5.7061,375.47,371.45,350.82
162.08636,2.2563,7.5245,0.0,0.0,1.5364,6.85,375.45,371.39,350.85
162.08716,2.0075,7.5352,0.0,0.0,1.5349,6.1065,375.43,371.33,350.88
162.08796,2.0215,7.5285,0.0,0.0,1.5344,6.104,375.4,371.27,350.92
162.08876,2.0254,7.5236,0.0,0.0,1.5369,6.1157,375.38,371.21,350.95
162.08956,2.1042,7.5359,0.0,0.0,1.5385,6.3984,375.36,371.15,350.98
162.09036,2.0414,7.534,0.0,0.0,1.5356,6.2056,375.34,371.09,351.01
162.09116,2.0501,7.5269,0.0,0.0,1.5357,6.2237,375.32,371.03,351.04
162.09196,2.0277,7.5274,0.0,0.0,1.5387,6.1465,375.3,370.97,351.07
162.09276,2.0688,7.531,0.0,0.0,1.5353,6.2426,375.27,370.91,351.11
162.09356,2.0694,7.5301,0.0,0.0,1.5345,6.2664,375.25,370.85,351.14
162.09435,2.0557,7.5214,0.0,0.0,1.537,6.2153,375.23,370.79,351.17
162.09515,2.0736,7.5258,0.0,0.0,1.5359,6.2986,375.21,370.73,351.2
162.09595,1.9782,7.5335,0.0,0.0,1.534,6.0017,375.18,370.67,351.22
162.09675,2.0421,7.5231,0.0,0.0,1.5348,6.1971,375.14,370.63,351.23
162.09755,2.0219,7.5229,0.0,0.0,1.5359,6.1413,375.1,370.59,351.25
162.09835,2.009,7.5312,0.0,0.0,1.5352,6.1016,375.06,370.54,351.26
162.09915,2.049,7.5296,0.0,0.0,1.5345,6.2129,375.02,370.5,351.27
162.09995,1.9712,7.5264,0.0,0.0,1.5371,5.9927,374.97,370.46,351.28
162.10075,2.0113,7.5278,0.0,0.0,1.5376,6.0992,374.93,370.41,351.29
162.10155,2.0043,7.5323,0.0,0.0,1.5352,6.0915,374.89,370.37,351.31
162.10235,1.9988,7.5287,0.0,0.0,1.5356,6.0164,374.85,370.33,351.32
162.10315,2.0379,7.5222,0.0,0.0,1.5373,6.1938,374.81,370.28,351.33
162.10394,1.9604,7.5302,0.0,0.0,1.5355,5.95,374.77,370.24,351.34
162.10474,2.062,7.532,0.0,0.0,1.5345,6.2571,374.73,370.2,351.36
162.10554,2.0184,7.5213,0.0,0.0,1.5359,6.1512,374.69,370.15,351.37
162.10634,2.0007,7.526,0.0,0.0,1.5361,6.056,374.63,370.15,351.39
162.10714,2.0388,7.534,0.0,0.0,1.5346,6.1792,374.57,370.16,351.41
162.10794,1.9996,7.5222,0.0,0.0,1.5325,6.0529,374.51,370.16,351.42
162.10874,2.0019,7.5246,0.0,0.0,1.5367,6.052,374.45,370.17,351.44
162.10954,2.0277,7.5319,0.0,0.0,1.5376,6.1558,374.39,370.17,351.46
162.11034,2.0014,7.5305,0.0,0.0,1.533,6.103,374.33,370.18,351.48
162.11114,1.9907,7.5239,0.0,0.0,1.5355,6.0134,374.27,370.18,351.5
162.11194,2.0133,7.5246,0.0,0.0,1.5384,6.0806,374.21,370.19,351.52
162.11274,2.0273,7.5319,0.0,0.0,1.5345,6.1389,374.15,370.19,351.54
162.11353,1.9742,7.5291,0.0,0.0,1.5344,6.0035,374.09,370.2,351.56
162.11433,2.0119,7.5191,0.0,0.0,1.5363,6.1215,374.03,370.2,351.58
162.11513,2.0222,7.5317,0.0,0.0,1.5372,6.1437,373.97,370.21,351.6
162.11593,1.9322,7.5348,0.0,0.0,1.5347,5.8253,373.9,370.19,351.62
162.11673,2.129,7.519,0.0,0.0,1.5327,6.457,373.83,370.13,351.65
162.11753,1.9099,7.5248,0.0,0.0,1.537,5.8133,373.76,370.08,351.67
162.11833,2.1243,7.5351,0.0,0.0,1.5374,6.4294,373.68,370.02,351.7
162.11913,1.9371,7.525,0.0,0.0,1.5308,5.8947,373.61,369.97,351.73
162.11993,2.0748,7.5243,0.0,0.0,1.5369,6.2311,373.54,369.91,351.75
162.12073,2.0578,7.5271,0.0,0.0,1.5387,6.2903,373.47,369.86,351.78
162.12153,1.9639,7.5321,0.0,0.0,1.5327,5.9404,373.39,369.8,351.81
162.12233,2.1195,7.5284,0.0,0.0,1.5363,6.4423,373.32,369.75,351.83
162.12312,1.9177,7.5214,0.0,0.0,1.5387,5.8336,373.25,369.69,351.86
162.12392,2.1289,7.533,0.0,0.0,1.5353,6.4547,373.18,369.63,351.89
162.12472,1.997,7.537,0.0,0.0,1.5353,6.0928,373.11,369.58,351.91
162.12552,2.0282,7.5208,0.0,0.0,1.5354,6.1641,373.03,369.52,351.94
162.12632,2.0845,7.5313,0.0,0.0,1.5397,6.3269,372.97,369.48,351.97
162.12712,2.025,7.5375,0.0,0.0,1.5358,6.1306,372.92,369.44,351.99
162.12792,2.0808,7.5256,0.0,0.0,1.5321,6.3455,372.86,369.4,352.02
162.12872,2.0702,7.5234,0.0,0.0,1.5386,6.2698,372.81,369.37,352.05
162.12952,2.0464,7.5318,0.0,0.0,1.5389,6.2142,372.75,369.33,352.07
162.13032,2.1099,7.5312,0.0,0.0,1.532,6.4096,372.7,369.29,352.1
162.13112,2.0222,7.5251,0.0,0.0,1.5359,6.1314,372.64,369.25,352.13
162.13192,2.1412,7.5234,0.0,0.0,1.54,6.4908,372.59,369.21,352.15
162.13271,2.0664,7.537,0.0,0.0,1.5356,6.2848,372.53,369.17,352.18
162.13351,2.0903,7.5314,0.0,0.0,1.5336,6.3453,372.48,369.13,352.21
162.13431,2.0998,7.5178,0.0,0.0,1.5362,6.3877,372.42,369.1,352.23
162.13511,2.0417,7.5346,0.0,0.0,1.5395,6.2215,372.36,369.06,352.26
162.13591,2.1685,7.5391,0.0,0.0,1.5352,6.5817,372.31,369.02,352.28
162.13671,1.9927,7.5215,0.0,0.0,1.5323,6.0483,372.25,368.97,352.31
162.13751,2.138,7.5263,0.0,0.0,1.5401,6.414,372.19,368.92,352.33
162.13831,2.1117,7.5352,0.0,0.0,1.5388,6.4004,372.13,368.87,352.36
162.13911,2.031,7.5312,0.0,0.0,1.5312,6.1039,372.08,368.82,352.38
162.13991,2.2159,7.5225,0.0,0.0,1.5368,6.7393,372.02,368.77,352.41
162.14071,2.0286,7.5247,0.0,0.0,1.5402,6.2231,371.96,368.73,352.43
162.14151,2.1261,7.5417,0.0,0.0,1.5352,6.4068,371.9,368.68,352.45
162.14231,2.1871,7.5293,0.0,0.0,1.534,6.6569,371.85,368.63,352.48
162.1431,2.0449,7.5132,0.0,0.0,1.5361,6.1658,371.79,368.58,352.5
162.1439,2.2347,7.5409,0.0,0.0,1.5404,6.753,371.73,368.53,352.53
162.1447,2.0596,7.5368,0.0,0.0,1.5339,6.2338,371.67,368.49,352.55
162.1455,2.2149,7.5163,0.0,0.0,1.5318,6.7096,371.61,368.44,352.57
162.1463,2.115,7.5314,0.0,0.0,1.5429,6.4394,371.55,368.36,352.6
162.1471,2.1544,7.5396,0.0,0.0,1.5391,6.5601,371.49,368.28,352.62
162.1479,2.1876,7.5268,0.0,0.0,1.53,6.6245,371.43,368.19,352.65
162.1487,2.1388,7.5237,0.0,0.0,1.5392,6.4578,371.37,368.11,352.67
162.1495,2.2212,7.5288,0.0,0.0,1.5398,6.7333,371.31,368.02,352.7
162.1503,2.1663,7.5397,0.0,0.0,1.5333,6.5551,371.25,367.94,352.72
162.1511,2.1878,7.5267,0.0,0.0,1.5352,6.63,371.19,367.86,352.74
162.1519,2.188,7.5178,0.0,0.0,1.5385,6.6367,371.13,367.77,352.77
162.15269,2.2241,7.5397,0.0,0.0,1.537,6.7805,371.07,367.69,352.79
162.15349,2.2205,7.5336,0.0,0.0,1.5331,6.7391,371.01,367.6,352.82
162.15429,2.2122,7.5166,0.0,0.0,1.5345,6.6909,370.95,367.52,352.84
162.15509,2.2307,7.5308,0.0,0.0,1.5408,6.7879,370.89,367.43,352.86
162.15589,2.2039,7.538,0.0,0.0,1.5362,6.7076,370.83,367.35,352.89
162.15669,2.1935,7.5264,0.0,0.0,1.5315,6.6404,370.76,367.26,352.92
162.15749,2.2611,7.5227,0.0,0.0,1.5391,6.9081,370.7,367.17,352.96
162.15829,2.177,7.5294,0.0,0.0,1.5385,6.5853,370.63,367.09,352.99
162.15909,2.2412,7.5379,0.0,0.0,1.5334,6.7988,370.57,367.0,353.03
162.15989,2.277,7.5251,0.0,0.0,1.5362,6.899,370.5,366.91,353.06
162.16069,2.1428,7.521,0.0,0.0,1.5383,6.4671,370.44,366.83,353.09
162.16149,2.3257,7.5405,0.0,0.0,1.5372,7.0521,370.37,366.74,353.13
162.16228,2.2079,7.5328,0.0,0.0,1.5343,6.679,370.31,366.65,353.16
162.16308,2.2188,7.5174,0.0,0.0,1.5356,6.7262,370.24,366.57,353.2
162.16388,2.2974,7.5341,0.0,0.0,1.5397,6.956,370.18,366.48,353.23
162.16468,2.1609,7.5336,0.0,0.0,1.5336,6.5554,370.11,366.39,353.26
162.16548,2.3362,7.5241,0.0,0.0,1.5332,7.0894,370.05,366.31,353.3
162.16628,2.1278,7.527,0.0,0.0,1.5397,6.4957,369.98,366.23,353.33
162.16708,2.2967,7.5289,0.0,0.0,1.5362,6.9189,369.92,366.15,353.35
162.16788,2.2524,7.5291,0.0,0.0,1.5313,6.8859,369.85,366.08,353.38
162.16868,2.1193,7.5216,0.0,0.0,1.5366,6.4034,369.79,366.0,353.41
162.16948,2.366,7.5255,0.0,0.0,1.5385,7.1838,369.72,365.93,353.43
162.17028,2.0716,7.5336,0.0,0.0,1.5331,6.3179,369.66,365.85,353.46
162.17108,2.3025,7.5271,0.0,0.0,1.5339,6.9718,369.59,365.78,353.49
162.17187,2.1962,7.5197,0.0,0.0,1.5364,6.6922,369.53,365.7,353.51
162.17267,2.0867,7.5325,0.0,0.0,1.5372,6.2914,369.46,365.63,353.54
162.17347,2.3592,7.5287,0.0,0.0,1.532,7.1795,369.4,365.55,353.57
162.17427,2.0441,7.5178,0.0,0.0,1.5325,6.2139,369.33,365.48,353.59
162.17507,2.2875,7.529,0.0,0.0,1.54,6.9383,369.27,365.4,353.62
162.17587,2.1471,7.5296,0.0,0.0,1.535,6.5786,369.2,365.33,353.65
162.17667,2.1705,7.5243,0.0,0.0,1.5312,6.5425,369.14,365.28,353.67
162.17747,2.3077,7.523,0.0,0.0,1.5375,7.0025,369.07,365.24,353.7
162.17827,2.026,7.5235,0.0,0.0,1.5357,6.1567,369.01,365.19,353.72
162.17907,2.3286,7.5326,0.0,0.0,1.5335,7.0409,368.94,365.14,353.75
162.17987,2.0882,7.5227,0.0,0.0,1.5348,6.3838,368.88,365.09,353.78
162.18067,2.1794,7.5184,0.0,0.0,1.5352,6.5709,368.81,365.04,353.8
162.18146,2.2694,7.5358,0.0,0.0,1.5368,6.9508,368.75,364.99,353.83
162.18226,2.0333,7.5269,0.0,0.0,1.5324,6.1472,368.68,364.95,353.86
162.18306,2.3503,7.5196,0.0,0.0,1.5344,7.0898,368.62,364.9,353.88
162.18386,2.0646,7.5286,0.0,0.0,1.5379,6.3259,368.55,364.85,353.91
162.18466,2.2155,7.5294,0.0,0.0,1.5335,6.6936,368.49,364.8,353.94
162.18546,2.2434,7.5258,0.0,0.0,1.5337,6.8321,368.42,364.75,353.96
162.18626,2.0574,7.522,0.0,0.0,1.5375,6.2159,368.34,364.7,353.99
162.18706,2.3393,7.5274,0.0,0.0,1.5353,7.0667,368.24,364.64,354.01
162.18786,2.0537,7.53,0.0,0.0,1.5328,6.2744,368.15,364.58,354.03
162.18866,2.2425,7.519,0.0,0.0,1.5344,6.7727,368.06,364.52,354.05
162.18946,2.2357,7.5248,0.0,0.0,1.5366,6.799,367.96,364.47,354.07
162.19026,2.0694,7.5324,0.0,0.0,1.5338,6.2442,367.87,364.41,354.1
162.19106,2.3567,7.524,0.0,0.0,1.5325,7.1504,367.77,364.35,354.12
162.19185,2.0233,7.5205,0.0,0.0,1.5353,6.1805,367.68,364.29,354.14
162.19265,2.3049,7.5326,0.0,0.0,1.5377,6.9619,367.59,364.23,354.16
162.19345,2.1796,7.527,0.0,0.0,1.5328,6.6437,367.49,364.18,354.18
162.19425,2.1115,7.5199,0.0,0.0,1.5326,6.3678,367.4,364.12,354.21
162.19505,2.3412,7.5287,0.0,0.0,1.5397,7.1166,367.3,364.06,354.23
162.19585,2.0391,7.5289,0.0,0.0,1.5346,6.1801,367.21,364.0,354.25
162.19665,2.3139,7.5258,0.0,0.0,1.532,6.99,367.11,363.91,354.26
162.19745,2.1311,7.5208,0.0,0.0,1.5369,6.4979,367.01,363.83,354.28
162.19825,2.1354,7.5281,0.0,0.0,1.5362,6.4522,366.91,363.74,354.29
162.19905,2.3266,7.533,0.0,0.0,1.5338,7.0813,366.81,363.65,354.31
162.19985,2.0296,7.5184,0.0,0.0,1.5325,6.1729,366.72,363.57,354.32
162.20065,2.3407,7.5253,0.0,0.0,1.5371,7.0792,366.62,363.48,354.34
162.20144,2.1306,7.5343,0.0,0.0,1.5369,6.4955,366.52,363.39,354.35
162.20224,2.1691,7.5221,0.0,0.0,1.5307,6.5526,366.42,363.3,354.36
162.20304,2.3215,7.5239,0.0,0.0,1.5359,7.0631,366.32,363.22,354.38
162.20384,2.0593,7.5265,0.0,0.0,1.538,6.2543,366.22,363.13,354.39
162.20464,2.3703,7.5294,0.0,0.0,1.5333,7.191,366.12,363.04,354.41
162.20544,2.1242,7.5248,0.0,0.0,1.5338,6.4629,366.02,362.96,354.42
162.20624,2.2593,7.5197,0.0,0.0,1.5371,6.8035,365.93,362.87,354.44
162.20704,2.2788,7.5318,0.0,0.0,1.5358,6.956,365.85,362.78,354.47
162.20784,2.0798,7.5287,0.0,0.0,1.5328,6.2858,365.77,362.69,354.5
162.20864,2.393,7.5171,0.0,0.0,1.5336,7.2621,365.69,362.6,354.53
162.20944,2.0724,7.5262,0.0,0.0,1.5367,6.3197,365.6,362.51,354.56
162.21024,2.2786,7.5343,0.0,0.0,1.5354,6.8821,365.52,362.42,354.59
162.21103,2.2653,7.522,0.0,0.0,1.5317,6.9069,365.44,362.33,354.62
162.21183,2.0827,7.5217,0.0,0.0,1.5359,6.3124,365.36,362.24,354.65
162.21263,2.4045,7.5312,0.0,0.0,1.5381,7.2881,365.28,362.15,354.68
162.21343,2.0661,7.5255,0.0,0.0,1.531,6.3021,365.19,362.06,354.71
162.21423,2.315,7.5222,0.0,0.0,1.5348,6.9933,365.11,361.97,354.73
162.21503,2.2506,7.5221,0.0,0.0,1.538,6.8663,365.03,361.88,354.76
162.21583,2.1393,7.5308,0.0,0.0,1.5338,6.4544,364.95,361.79,354.79
162.21663,2.395,7.5285,0.0,0.0,1.5338,7.2532,364.87,361.72,354.81
162.21743,2.0779,7.5168,0.0,0.0,1.5354,6.3386,364.8,361.65,354.84
162.21823,2.3637,7.5292,0.0,0.0,1.5366,7.1405,364.72,361.58,354.86
162.21903,2.2064,7.5339,0.0,0.0,1.5343,6.7404,364.65,361.5,354.88
162.21983,2.1956,7.5177,0.0,0.0,1.5314,6.6438,364.57,361.43,354.9
162.22062,2.3851,7.5256,0.0,0.0,1.5383,7.2686,364.5,361.36,354.92
162.22142,2.0779,7.5318,0.0,0.0,1.5365,6.2962,364.42,361.29,354.95
162.22222,2.3972,7.5254,0.0,0.0,1.5311,7.2555,364.35,361.21,354.97
162.22302,2.1822,7.5206,0.0,0.0,1.5359,6.6985,364.27,361.14,354.99
162.22382,2.2039,7.5245,0.0,0.0,1.5385,6.6586,364.2,361.07,355.01
162.22462,2.3761,7.5335,0.0,0.0,1.5331,7.2136,364.12,361.0,355.03
162.22542,2.0899,7.5226,0.0,0.0,1.5328,6.334,364.05,360.92,355.05
162.22622,2.4096,7.5172,0.0,0.0,1.5369,7.2708,363.97,360.85,355.07
162.22702,2.1458,7.5335,0.0,0.0,1.5365,6.5509,363.89,360.79,355.09
162.22782,2.2698,7.532,0.0,0.0,1.5326,6.8514,363.81,360.72,355.11
162.22862,2.3278,7.514,0.0,0.0,1.5323,7.1073,363.73,360.65,355.12
162.22942,2.096,7.5268,0.0,0.0,1.5386,6.3525,363.65,360.58,355.14
162.23021,2.413,7.5369,0.0,0.0,1.5362,7.3441,363.57,360.52,355.16
162.23101,2.1261,7.521,0.0,0.0,1.5293,6.4743,363.49,360.45,355.17
162.23181,2.3068,7.5218,0.0,0.0,1.5375,6.9613,363.41,360.38,355.19
162.23261,2.3196,7.5288,0.0,0.0,1.5394,7.0875,363.33,360.31,355.21
162.23341,2.1026,7.531,0.0,0.0,1.5305,6.3359,363.25,360.25,355.23
162.23421,2.4198,7.5207,0.0,0.0,1.5348,7.3681,363.17,360.18,355.24
162.23501,2.0884,7.5181,0.0,0.0,1.5382,6.3936,363.09,360.11,355.26
162.23581,2.3242,7.536,0.0,0.0,1.5351,7.0168,363.01,360.04,355.28
162.23661,2.2681,7.532,0.0,0.0,1.5328,6.9273,362.94,359.97,355.29
162.23741,2.1162,7.5117,0.0,0.0,1.5327,6.4158,362.87,359.9,355.31
162.23821,2.4101,7.5327,0.0,0.0,1.5396,7.299,362.8,359.82,355.33
162.23901,2.0867,7.5341,0.0,0.0,1.533,6.3164,362.73,359.75,355.34
162.2398,2.3574,7.5165,0.0,0.0,1.5288,7.1326,362.66,359.68,355.36
162.2406,2.2113,7.5223,0.0,0.0,1.539,6.7745,362.59,359.61,355.38
162.2414,2.1722,7.5303,0.0,0.0,1.5379,6.5415,362.52,359.53,355.39
162.2422,2.3978,7.5284,0.0,0.0,1.5293,7.2769,362.45,359.46,355.41
162.243,2.0479,7.5181,0.0,0.0,1.5342,6.2529,362.38,359.39,355.43
162.2438,2.3699,7.5211,0.0,0.0,1.5393,7.1942,362.31,359.32,355.45
162.2446,2.1602,7.5377,0.0,0.0,1.5337,6.6559,362.24,359.24,355.46
162.2454,2.1862,7.5251,0.0,0.0,1.531,6.635,362.17,359.17,355.48
162.2462,2.361,7.5121,0.0,0.0,1.5355,7.2007,362.1,359.1,355.5
162.247,2.0525,7.5352,0.0,0.0,1.5392,6.2092,362.03,359.02,355.51
162.2478,2.4002,7.5342,0.0,0.0,1.5324,7.2187,361.97,358.95,355.52
162.2486,2.1523,7.5153,0.0,0.0,1.5303,6.5452,361.9,358.87,355.54
162.2494,2.2345,7.5243,0.0,0.0,1.5398,6.7134,361.83,358.8,355.55
162.25019,2.3356,7.5346,0.0,0.0,1.5376,7.1283,361.76,358.72,355.57
162.25099,2.058,7.5258,0.0,0.0,1.5289,6.2228,361.7,358.65,355.58
162.25179,2.3945,7.5205,0.0,0.0,1.5371,7.227,361.63,358.57,355.6
162.25259,2.0919,7.5212,0.0,0.0,1.5376,6.3559,361.56,358.5,355.61
162.25339,2.2551,7.5351,0.0,0.0,1.5322,6.8342,361.49,358.42,355.63
162.25419,2.2895,7.5231,0.0,0.0,1.5326,6.9492,361.43,358.35,355.64
162.25499,2.0667,7.5122,0.0,0.0,1.5348,6.2282,361.36,358.27,355.66
162.25579,2.3749,7.5365,0.0,0.0,1.5377,7.1816,361.29,358.2,355.67
162.25659,2.0595,7.5304,0.0,0.0,1.5319,6.2853,361.22,358.13,355.69
162.25739,2.2723,7.5131,0.0,0.0,1.5314,6.8568,361.15,358.07,355.7
162.25819,2.2417,7.525,0.0,0.0,1.5385,6.8301,361.08,358.01,355.72
162.25899,2.0877,7.5298,0.0,0.0,1.5345,6.3174,361.01,357.95,355.74
162.25978,2.3741,7.5232,0.0,0.0,1.5301,7.2259,360.94,357.88,355.75
162.26058,2.0571,7.5199,0.0,0.0,1.537,6.2523,360.87,357.82,355.77
162.26138,2.3118,7.523,0.0,0.0,1.5363,6.9678,360.8,357.76,355.79
162.26218,2.1913,7.5348,0.0,0.0,1.5326,6.7082,360.73,357.69,355.8
162.26298,2.1117,7.5208,0.0,0.0,1.5339,6.3841,360.66,357.63,355.82
162.26378,2.3639,7.5162,0.0,0.0,1.5355,7.1778,360.59,357.57,355.84
162.26458,2.0392,7.5335,0.0,0.0,1.5352,6.1852,360.52,357.51,355.86
162.26538,2.3375,7.5287,0.0,0.0,1.5326,7.0595,360.45,357.44,355.87
162.26618,2.1626,7.5147,0.0,0.0,1.5327,6.6412,360.38,357.38,355.89
162.26698,2.1457,7.5279,0.0,0.0,1.5376,6.4825,360.29,357.3,355.91
162.26778,2.3395,7.5316,0.0,0.0,1.5343,7.1377,360.21,357.23,355.93
162.26858,2.0532,7.5214,0.0,0.0,1.5315,6.2488,360.13,357.15,355.95
162.26937,2.3591,7.5226,0.0,0.0,1.5381,7.1379,360.05,357.08,355.97
162.27017,2.1459,7.525,0.0,0.0,1.5352,6.5233,359.96,357.0,355.99
162.27097,2.1947,7.5293,0.0,0.0,1.5315,6.6078,359.88,356.93,356.01
162.27177,2.3391,7.5245,0.0,0.0,1.537,7.1021,359.8,356.85,356.03
162.27257,2.0482,7.5196,0.0,0.0,1.5356,6.2215,359.72,356.78,356.04
162.27337,2.3934,7.5335,0.0,0.0,1.5341,7.2703,359.64,356.7,356.06
162.27417,2.1151,7.5266,0.0,0.0,1.5332,6.4484,359.55,356.63,356.08
162.27497,2.2419,7.5176,0.0,0.0,1.5347,6.7499,359.47,356.55,356.1
162.27577,2.2941,7.5333,0.0,0.0,1.5378,6.9892,359.39,356.48,356.12
162.27657,2.0935,7.5288,0.0,0.0,1.5328,6.322,359.31,356.4,356.14
162.27737,2.4006,7.522,0.0,0.0,1.5329,7.2409,359.22,356.32,356.15
162.27817,2.0873,7.5254,0.0,0.0,1.539,6.3913,359.14,356.24,356.16
162.27896,2.2918,7.5275,0.0,0.0,1.5344,6.9178,359.06,356.16,356.17
162.27976,2.28,7.529,0.0,0.0,1.5333,6.9477,358.98,356.08,356.18
162.28056,2.1285,7.5209,0.0,0.0,1.5363,6.4235,358.9,356.0,356.2
162.28136,2.4066,7.5271,0.0,0.0,1.5368,7.3232,358.81,355.92,356.21
162.28216,2.0861,7.5339,0.0,0.0,1.5346,6.3422,358.73,355.84,356.22
162.28296,2.3367,7.5228,0.0,0.0,1.5336,7.0427,358.65,355.76,356.23
162.28376,2.2464,7.522,0.0,0.0,1.5355,6.8671,358.57,355.68,356.24
162.28456,2.1476,7.5349,0.0,0.0,1.537,6.46,358.49,355.6,356.26
162.28536,2.4043,7.5267,0.0,0.0,1.5325,7.3031,358.4,355.52,356.27
162.28616,2.0832,7.5221,0.0,0.0,1.5345,6.3243,358.32,355.45,356.28
162.28696,2.3748,7.5309,0.0,0.0,1.5398,7.162,358.26,355.38,356.3
162.28776,2.2131,7.5294,0.0,0.0,1.5345,6.7616,358.19,355.32,356.32
162.28855,2.1773,7.5234,0.0,0.0,1.5325,6.5651,358.13,355.26,356.34
162.28935,2.3829,7.5243,0.0,0.0,1.5388,7.2894,358.06,355.19,356.36
162.29015,2.0804,7.5288,0.0,0.0,1.5358,6.3219,358.0,355.13,356.38
162.29095,2.4065,7.5311,0.0,0.0,1.5338,7.2719,357.93,355.07,356.4
162.29175,2.1635,7.5237,0.0,0.0,1.5363,6.5986,357.87,355.01,356.42
162.29255,2.2393,7.5262,0.0,0.0,1.5367,6.7505,357.8,354.94,356.44
162.29335,2.3668,7.5336,0.0,0.0,1.5352,7.2139,357.74,354.88,356.46
162.29415,2.0927,7.5255,0.0,0.0,1.5332,6.3465,357.67,354.82,356.48
162.29495,2.4271,7.5251,0.0,0.0,1.5367,7.3562,357.61,354.75,356.5
162.29575,2.1586,7.5316,0.0,0.0,1.5381,6.5874,357.54,354.69,356.51
162.29655,2.2671,7.5292,0.0,0.0,1.5334,6.8482,357.47,354.64,356.53
162.29735,2.342,7.528,0.0,0.0,1.5366,7.1631,357.4,354.58,356.54
162.29815,2.1113,7.524,0.0,0.0,1.5384,6.4021,357.33,354.53,356.55
162.29894,2.4319,7.5297,0.0,0.0,1.5344,7.3976,357.25,354.48,356.57
162.29974,2.1357,7.5299,0.0,0.0,1.5344,6.492,357.18,354.42,356.58
162.30054,2.3106,7.5201,0.0,0.0,1.5365,6.9733,357.11,354.37,356.59
162.30134,2.294,7.5294,0.0,0.0,1.5367,7.009,357.04,354.32,356.6
162.30214,2.126,7.5351,0.0,0.0,1.5349,6.4006,356.96,354.26,356.61
162.30294,2.4358,7.5228,0.0,0.0,1.5341,7.3883,356.89,354.21,356.63
162.30374,2.0991,7.5251,0.0,0.0,1.5376,6.4116,356.82,354.16,356.64
162.30454,2.3556,7.5332,0.0,0.0,1.5369,7.1019,356.75,354.1,356.65
162.30534,2.2864,7.5279,0.0,0.0,1.5331,6.9816,356.67,354.05,356.66
162.30614,2.1668,7.5238,0.0,0.0,1.536,6.5466,356.6,354.0,356.67
162.30694,2.4385,7.5282,0.0,0.0,1.5391,7.3906,356.53,353.93,356.68
162.30774,2.1036,7.5301,0.0,0.0,1.5334,6.3975,356.47,353.86,356.69
162.30853,2.3845,7.5268,0.0,0.0,1.5342,7.2018,356.4,353.79,356.69
162.30933,2.2434,7.5232,0.0,0.0,1.5388,6.8513,356.33,353.72,356.7
162.31013,2.2066,7.5302,0.0,0.0,1.5354,6.6525,356.26,353.66,356.71
162.31093,2.405,7.5336,0.0,0.0,1.534,7.3335,356.2,353.59,356.72
162.31173,2.0933,7.5197,0.0,0.0,1.5347,6.3443,356.13,353.52,356.72
162.31253,2.408,7.5263,0.0,0.0,1.538,7.2896,356.06,353.45,356.73
162.31333,2.1984,7.5343,0.0,0.0,1.5354,6.711,355.99,353.39,356.74
162.31413,2.2338,7.524,0.0,0.0,1.5324,6.7399,355.92,353.32,356.75
162.31493,2.3879,7.5254,0.0,0.0,1.5379,7.2839,355.86,353.25,356.75
162.31573,2.0877,7.5285,0.0,0.0,1.5379,6.3626,355.79,353.18,356.76
162.31653,2.4212,7.5323,0.0,0.0,1.5333,7.3087,355.72,353.12,356.77
162.31733,2.1786,7.5246,0.0,0.0,1.5354,6.6229,355.66,353.05,356.78
162.31812,2.2518,7.5189,0.0,0.0,1.5372,6.7936,355.6,352.98,356.79
162.31892,2.366,7.5366,0.0,0.0,1.5359,7.2154,355.54,352.91,356.8
162.31972,2.1038,7.5304,0.0,0.0,1.5339,6.3762,355.47,352.84,356.81
162.32052,2.4299,7.5161,0.0,0.0,1.5352,7.3645,355.41,352.78,356.82
162.32132,2.1315,7.5312,0.0,0.0,1.5378,6.4945,355.35,352.71,356.83
162.32212,2.3033,7.5371,0.0,0.0,1.5355,6.9612,355.28,352.64,356.84
162.32292,2.3154,7.5198,0.0,0.0,1.532,7.0444,355.22,352.57,356.85
162.32372,2.114,7.521,0.0,0.0,1.5371,6.3968,355.16,352.51,356.86
162.32452,2.4227,7.5341,0.0,0.0,1.5383,7.3107,355.1,352.44,356.87
162.32532,2.1009,7.5279,0.0,0.0,1.531,6.4275,355.03,352.37,356.88
162.32612,2.3347,7.5211,0.0,0.0,1.5356,7.0407,354.97,352.3,356.89
162.32692,2.2783,7.5234,0.0,0.0,1.5388,6.9438,354.9,352.26,356.9
162.32771,2.1382,7.5371,0.0,0.0,1.534,6.4448,354.83,352.21,356.91
162.32851,2.4137,7.5293,0.0,0.0,1.5344,7.369,354.76,352.16,356.93
162.32931,2.0875,7.5118,0.0,0.0,1.5345,6.3724,354.69,352.11,356.94
162.33011,2.3515,7.5355,0.0,0.0,1.5379,7.092,354.62,352.06,356.96
162.33091,2.2395,7.5382,0.0,0.0,1.535,6.841,354.55,352.01,356.97
162.33171,2.1764,7.5118,0.0,0.0,1.5301,6.5742,354.48,351.97,356.99
162.33251,2.3914,7.5293,0.0,0.0,1.5406,7.3065,354.41,351.92,357.0
162.33331,2.0808,7.5352,0.0,0.0,1.5371,6.3155,354.34,351.87,357.02
162.33411,2.3781,7.5237,0.0,0.0,1.5285,7.2178,354.27,351.82,357.03
162.33491,2.2066,7.5211,0.0,0.0,1.5378,6.7225,354.2,351.77,357.04
162.33571,2.1948,7.5243,0.0,0.0,1.5381,6.6096,354.13,351.72,357.06
162.33651,2.3838,7.5367,0.0,0.0,1.5327,7.2561,354.06,351.67,357.07
162.3373,2.0793,7.5242,0.0,0.0,1.5345,6.3084,353.99,351.62,357.08
162.3381,2.3853,7.5159,0.0,0.0,1.538,7.261,353.92,351.57,357.09
162.3389,2.1499,7.5385,0.0,0.0,1.5366,6.5718,353.86,351.52,357.1
162.3397,2.2288,7.5322,0.0,0.0,1.5319,6.7647,353.79,351.47,357.11
162.3405,2.3513,7.5132,0.0,0.0,1.5334,7.1434,353.72,351.42,357.12
162.3413,2.0846,7.53,0.0,0.0,1.5405,6.29,353.65,351.37,357.13
162.3421,2.4029,7.5385,0.0,0.0,1.5354,7.268,353.59,351.32,357.14
162.3429,2.1229,7.5222,0.0,0.0,1.5303,6.4566,353.52,351.27,357.15
162.3437,2.284,7.5209,0.0,0.0,1.5389,6.8741,353.45,351.22,357.16
162.3445,2.3077,7.5281,0.0,0.0,1.5383,7.0287,353.38,351.17,357.17
162.3453,2.0968,7.5322,0.0,0.0,1.5304,6.3226,353.32,351.12,357.18
162.3461,2.4114,7.5223,0.0,0.0,1.5356,7.3075,353.25,351.07,357.19
162.34689,2.1069,7.519,0.0,0.0,1.5384,6.4305,353.2,351.0,357.19
162.34769,2.303,7.5374,0.0,0.0,1.5349,6.9147,353.15,350.93,357.19
162.34849,2.2857,7.532,0.0,0.0,1.5335,7.0103,353.1,350.86,357.19
162.34929,2.1282,7.5123,0.0,0.0,1.5338,6.3956,353.04,350.79,357.19
162.35009,2.4067,7.5346,0.0,0.0,1.5407,7.3143,352.99,350.71,357.19
162.35089,2.0886,7.5369,0.0,0.0,1.5346,6.3431,352.94,350.64,357.19
162.35169,2.3554,7.5195,0.0,0.0,1.5305,7.1126,352.89,350.57,357.19
162.35249,2.2401,7.5241,0.0,0.0,1.5393,6.8404,352.84,350.5,357.19
162.35329,2.172,7.5314,0.0,0.0,1.5374,6.5261,352.79,350.43,357.19
162.35409,2.4139,7.5331,0.0,0.0,1.532,7.3601,352.74,350.36,357.19
162.35489,2.0818,7.52,0.0,0.0,1.5353,6.3405,352.69,350.29,357.19
162.35569,2.3633,7.5216,0.0,0.0,1.5374,7.162,352.64,350.22,357.19
162.35649,2.2061,7.5393,0.0,0.0,1.5356,6.7239,352.59,350.15,357.19
162.35728,2.1851,7.527,0.0,0.0,1.5331,6.6169,352.53,350.08,357.19
162.35808,2.4017,7.5158,0.0,0.0,1.5352,7.3165,352.48,350.0,357.2
162.35888,2.0953,7.5368,0.0,0.0,1.5391,6.2868,352.43,349.93,357.2
162.35968,2.4001,7.5345,0.0,0.0,1.5338,7.277,352.37,349.85,357.21
162.36048,2.1768,7.5173,0.0,0.0,1.5319,6.6133,352.32,349.78,357.21
162.36128,2.2399,7.5267,0.0,0.0,1.5393,6.7691,352.27,349.7,357.22
162.36208,2.3732,7.5378,0.0,0.0,1.5384,7.2249,352.21,349.63,357.22
162.36288,2.1025,7.5271,0.0,0.0,1.5317,6.4052,352.16,349.55,357.23
162.36368,2.4276,7.5209,0.0,0.0,1.5373,7.3469,352.11,349.47,357.23
162.36448,2.1503,7.5294,0.0,0.0,1.5387,6.5794,352.06,349.4,357.24
162.36528,2.291,7.5358,0.0,0.0,1.5337,6.9331,352.0,349.32,357.24
162.36608,2.3442,7.5226,0.0,0.0,1.5342,7.1827,351.95,349.25,357.25
162.36687,2.132,7.5192,0.0,0.0,1.5364,6.444,351.88,349.19,357.25
162.36767,2.4523,7.5398,0.0,0.0,1.5389,7.422,351.81,349.14,357.25
162.36847,2.1272,7.5299,0.0,0.0,1.5331,6.476,351.74,349.08,357.25
162.36927,2.3295,7.5176,0.0,0.0,1.5334,7.0277,351.67,349.02,357.26
162.37007,2.3227,7.5321,0.0,0.0,1.5397,7.1007,351.6,348.97,357.26
162.37087,2.1598,7.5337,0.0,0.0,1.5356,6.5143,351.53,348.91,357.26
162.37167,2.4571,7.5271,0.0,0.0,1.5332,7.4711,351.46,348.86,357.26
162.37247,2.1278,7.5241,0.0,0.0,1.5387,6.4632,351.39,348.8,357.27
162.37327,2.377,7.5301,0.0,0.0,1.5372,7.1595,351.32,348.75,357.27
162.37407,2.2825,7.5359,0.0,0.0,1.5344,7.0001,351.25,348.69,357.27
162.37487,2.1931,7.5206,0.0,0.0,1.5353,6.6,351.18,348.63,357.27
162.37567,2.4416,7.5243,0.0,0.0,1.5379,7.4148,351.11,348.58,357.28
162.37646,2.1153,7.5393,0.0,0.0,1.5374,6.4303,351.04,348.53,357.28
162.37726,2.4055,7.5289,0.0,0.0,1.5342,7.276,350.98,348.49,357.29
162.37806,2.2475,7.5197,0.0,0.0,1.5351,6.8714,350.91,348.45,357.3
162.37886,2.2243,7.5335,0.0,0.0,1.5391,6.6781,350.84,348.41,357.31
162.37966,2.4347,7.5325,0.0,0.0,1.5349,7.4158,350.78,348.36,357.32
162.38046,2.1172,7.5232,0.0,0.0,1.5335,6.4444,350.71,348.32,357.33
162.38126,2.433,7.5288,0.0,0.0,1.5402,7.3489,350.65,348.28,357.34
162.38206,2.2208,7.5305,0.0,0.0,1.536,6.777,350.58,348.24,357.35
162.38286,2.2569,7.5293,0.0,0.0,1.5332,6.817,350.52,348.2,357.36
162.38366,2.4103,7.5262,0.0,0.0,1.5386,7.3206,350.45,348.16,357.37
162.38446,2.1207,7.526,0.0,0.0,1.5368,6.4437,350.39,348.12,357.38
162.38526,2.4578,7.5355,0.0,0.0,1.5353,7.4413,350.32,348.08,357.39
162.38605,2.1961,7.5263,0.0,0.0,1.5352,6.7196,350.26,348.03,357.4
162.38685,2.2955,7.5245,0.0,0.0,1.5368,6.9412,350.2,347.98,357.41
162.38765,2.3791,7.5355,0.0,0.0,1.5382,7.2534,350.15,347.92,357.42
162.38845,2.1307,7.5267,0.0,0.0,1.5327,6.4678,350.1,347.86,357.43
162.38925,2.455,7.526,0.0,0.0,1.5363,7.4501,350.05,347.8,357.44
162.39005,2.1565,7.53,0.0,0.0,1.5394,6.5704,350.0,347.75,357.45
162.39085,2.3324,7.5297,0.0,0.0,1.5339,7.0084,349.95,347.69,357.46
162.39165,2.3276,7.5298,0.0,0.0,1.5349,7.1196,349.9,347.63,357.47
162.39245,2.1421,7.5222,0.0,0.0,1.5377,6.4913,349.85,347.57,357.48
162.39325,2.4504,7.5312,0.0,0.0,1.5367,7.3978,349.8,347.51,357.48
162.39405,2.1273,7.5343,0.0,0.0,1.5348,6.5122,349.75,347.46,357.49
162.39485,2.3584,7.5219,0.0,0.0,1.5348,7.1166,349.69,347.4,357.5
162.39564,2.3001,7.5294,0.0,0.0,1.5383,7.0145,349.64,347.34,357.51
162.39644,2.1661,7.537,0.0,0.0,1.5369,6.5266,349.59,347.28,357.52
162.39724,2.4332,7.5244,0.0,0.0,1.5326,7.3879,349.54,347.22,357.52
162.39804,2.1104,7.5256,0.0,0.0,1.5375,6.4447,349.49,347.16,357.53
162.39884,2.3826,7.5342,0.0,0.0,1.5399,7.215,349.44,347.11,357.53
162.39964,2.2621,7.5284,0.0,0.0,1.5334,6.8802,349.39,347.05,357.53
162.40044,2.1909,7.5227,0.0,0.0,1.534,6.6175,349.34,346.99,357.53
162.40124,2.4224,7.5271,0.0,0.0,1.5397,7.3621,349.29,346.93,357.54
162.40204,2.1034,7.5334,0.0,0.0,1.5364,6.3977,349.24,346.87,357.54
162.40284,2.4064,7.5279,0.0,0.0,1.5336,7.2767,349.19,346.82,357.54
162.40364,2.2076,7.5209,0.0,0.0,1.5362,6.7435,349.13,346.76,357.54
162.40444,2.2289,7.5323,0.0,0.0,1.5383,6.7048,349.08,346.7,357.55
162.40524,2.396,7.5379,0.0,0.0,1.5366,7.3252,349.03,346.64,357.55
162.40603,2.1069,7.5179,0.0,0.0,1.5319,6.4016,348.98,346.58,357.55
162.40683,2.427,7.5275,0.0,0.0,1.5392,7.3221,348.93,346.53,357.56
162.40763,2.1942,7.5381,0.0,0.0,1.5396,6.6962,348.87,346.48,357.56
162.40843,2.2631,7.5253,0.0,0.0,1.5311,6.8192,348.81,346.44,357.57
162.40923,2.3748,7.5234,0.0,0.0,1.5362,7.2275,348.75,346.39,357.58
162.41003,2.1169,7.5298,0.0,0.0,1.5403,6.4103,348.69,346.34,357.59
162.41083,2.4264,7.5329,0.0,0.0,1.5344,7.3589,348.63,346.29,357.59
162.41163,2.1662,7.5268,0.0,0.0,1.5337,6.6196,348.58,346.24,357.6
162.41243,2.2995,7.5218,0.0,0.0,1.5385,6.9759,348.52,346.19,357.61
162.41323,2.3442,7.5346,0.0,0.0,1.5373,7.1518,348.46,346.14,357.61
162.41403,2.1389,7.5322,0.0,0.0,1.5333,6.4539,348.4,346.1,357.62
162.41483,2.4558,7.5211,0.0,0.0,1.5346,7.4109,348.34,346.05,357.63
162.41562,2.1325,7.53,0.0,0.0,1.5399,6.4816,348.29,346.0,357.64
162.41642,2.3433,7.5369,0.0,0.0,1.537,7.0795,348.23,345.95,357.64
162.41722,2.3128,7.5258,0.0,0.0,1.5321,7.0588,348.17,345.92,357.64
162.41802,2.1608,7.5245,0.0,0.0,1.5379,6.5416,348.12,345.88,357.64
162.41882,2.4375,7.5313,0.0,0.0,1.5402,7.3931,348.07,345.84,357.64
162.41962,2.1187,7.5324,0.0,0.0,1.5323,6.4925,348.02,345.81,357.64
162.42042,2.3754,7.5257,0.0,0.0,1.5357,7.1544,347.96,345.77,357.64
162.42122,2.2846,7.5233,0.0,0.0,1.5399,6.9855,347.91,345.74,357.64
162.42202,2.1914,7.536,0.0,0.0,1.5358,6.6226,347.86,345.7,357.64
162.42282,2.4288,7.5327,0.0,0.0,1.534,7.3873,347.8,345.66,357.64
162.42362,2.1177,7.5155,0.0,0.0,1.5341,6.3993,347.75,345.63,357.64
162.42442,2.4105,7.534,0.0,0.0,1.5403,7.2384,347.7,345.59,357.64
162.42521,2.2379,7.5386,0.0,0.0,1.5358,6.8394,347.64,345.55,357.64
162.42601,2.2348,7.5203,0.0,0.0,1.5307,6.727,347.59,345.52,357.64
162.42681,2.4228,7.5278,0.0,0.0,1.5409,7.358,347.54,345.48,357.64
162.42761,2.1212,7.5321,0.0,0.0,1.5389,6.4339,347.48,345.44,357.65
162.42841,2.4329,7.5328,0.0,0.0,1.5316,7.3827,347.43,345.39,357.65
162.42921,2.2071,7.5258,0.0,0.0,1.5374,6.74,347.38,345.35,357.65
162.43001,2.2704,7.5214,0.0,0.0,1.5395,6.8539,347.32,345.31,357.65
162.43081,2.4087,7.539,0.0,0.0,1.5355,7.3343,347.27,345.27,357.66
162.43161,2.1294,7.5325,0.0,0.0,1.5351,6.4722,347.22,345.23,357.66
162.43241,2.4522,7.5159,0.0,0.0,1.5369,7.4311,347.16,345.19,357.66
162.43321,2.1803,7.5366,0.0,0.0,1.5393,6.6269,347.11,345.15,357.66
162.43401,2.3103,7.5387,0.0,0.0,1.5343,6.9902,347.06,345.11,357.67
162.4348,2.3721,7.5176,0.0,0.0,1.5317,7.2784,347.0,345.07,357.67
162.4356,2.1414,7.5274,0.0,0.0,1.5414,6.5089,346.95,345.02,357.67
162.4364,2.4647,7.5365,0.0,0.0,1.5384,7.4727,346.9,344.98,357.67
162.4372,2.1541,7.5289,0.0,0.0,1.5302,6.5124,346.84,344.92,357.67
162.438,2.3542,7.5242,0.0,0.0,1.5388,7.0857,346.79,344.87,357.67
162.4388,2.346,7.5283,0.0,0.0,1.5411,7.132,346.74,344.81,357.67
162.6394,2.2696,7.5319,0.0,0.0,1.5368,6.8753,336.74,332.85,346.27
164.2394,2.1125,7.5417,0.0,0.0,1.5417,6.4037,210.49,156.65,194.49
165.8394,1.9382,7.5784,0.0,0.0,1.5586,5.8818,61.894,53.312,61.598
167.4394,1.9436,7.5959,0.0,0.0,1.5664,5.8994,36.304,39.32,30.177
168.9661,1.9388,7.6052,0.0,0.0,1.5709,5.883,28.97,29.639,25.263
170.5661,1.938,7.6132,0.0,0.0,1.5745,5.882,25.166,26.407,23.132
172.1661,1.9406,7.6198,0.0,0.0,1.5773,5.8874,23.565,24.748,22.386
173.7661,1.9679,7.6238,0.0,0.0,1.579,5.9665,27.649,29.178,25.174
175.3661,1.8998,7.6275,0.0,0.0,1.5809,5.7658,30.395,31.769,28.156
176.9661,1.9051,7.6349,0.0,0.0,1.5845,5.7817,32.335,39.506,30.673
178.5661,1.9666,7.6357,0.0,0.0,1.5848,5.9666,33.622,39.506,32.494
179.3661,1.9645,7.6366,0.0,0.0,1.585,5.9581,34.052,39.506,33.178