File: examples/dan-msc-case-studies/CS4/data/01 raw data/hyde_test_003.csv
Time(sec),Force(kN),Jaw(mm),PowAngle(deg),PTemp,Strain,Stress(MPa),TC1(C),TC2(C),TC3(C)
0.0,6.5276,0.000127,0.0,0.0024083,2.8574e-06,7.4483,20.874,21.738,21.118
0.6,6.3738,0.00067194,0.0,1.621,6.2173e-05,7.2731,20.837,21.647,21.026
1.2,6.347,0.00079436,0.0,3.421,5.8777e-05,7.2428,20.884,21.686,21.07
1.8,6.2918,0.00074281,0.0,5.221,5.0921e-05,7.1786,21.013,21.84,21.282
2.4,6.2474,0.00066589,0.0,7.021,4.6392e-05,7.1307,20.853,21.615,21.026
3.0,6.2228,0.00064015,0.0,8.821,4.6885e-05,7.0993,21.006,21.776,21.176
3.6,6.1893,0.00056234,0.0,10.621,2.0341e-05,7.0644,20.834,21.685,21.073
4.2,6.1755,0.00065347,0.0,12.421,1.261e-05,7.0456,20.841,21.657,21.033
4.8,6.1516,0.00071554,0.0,14.221,-1.3976e-05,7.0197,20.785,21.637,21.066
5.4,6.1516,0.00065266,0.0,16.021,-2.209e-05,7.019,20.847,21.668,21.05
6.0,6.1171,0.00063115,0.0,17.821,-3.1111e-05,6.9799,20.832,21.648,21.066
6.6,6.1252,0.00067738,0.0,19.621,-1.549e-05,6.9902,20.827,21.712,21.092
7.2,6.1054,0.0006655,4.5228,21.421,-7.8225e-06,6.9658,20.835,21.677,21.078
7.8,6.1141,0.0012219,23.927,23.221,5.2602e-05,6.9783,20.884,21.738,21.081
8.2813,6.1128,0.0002815,31.982,24.684,-3.9937e-05,6.9728,21.201,22.339,21.229
8.8813,6.1123,0.00010889,37.129,26.465,-5.0057e-05,6.9754,22.464,24.325,21.971
9.4813,6.1118,-0.00079799,38.108,28.265,-0.00016507,6.9721,24.805,27.285,23.578
10.0813,6.0926,-0.0014163,36.732,30.065,-0.00022068,6.9528,27.756,30.443,25.818
10.6813,6.1064,-0.0021406,35.374,31.865,-0.00028336,6.9668,30.425,39.296,28.057
11.2813,6.0938,-0.002334,33.689,33.665,-0.00029498,6.9534,32.949,39.346,30.299
11.8813,6.0977,-0.0020695,33.423,35.465,-0.00024471,6.9589,34.951,39.32,32.194
12.4813,6.0796,-0.0026693,33.431,37.265,-0.00029011,6.9361,36.88,39.32,33.989
13.0813,6.0872,-0.0028043,33.247,39.065,-0.00029724,6.9481,38.774,39.627,35.82
13.6776,6.0896,-0.0042129,34.615,40.854,-0.0004341,6.9465,40.333,40.997,37.223
14.2776,6.084,-0.0040265,34.868,42.654,-0.00042329,6.9439,42.201,42.846,38.804
14.8776,6.0903,-0.0039244,34.7,44.454,-0.00040021,6.9485,44.131,44.596,40.55
15.4776,6.078,-0.0045294,34.644,46.254,-0.00046379,6.936,46.059,46.384,42.268
16.0776,6.094,-0.0049964,34.639,48.054,-0.00050799,6.9535,47.887,48.168,44.023
16.6776,6.0806,-0.005844,34.655,49.854,-0.00060606,6.9378,49.724,49.793,45.742
17.2776,6.0912,-0.0066452,34.613,51.654,-0.00070738,6.9512,51.525,51.566,47.613
17.8776,6.0849,-0.0058053,35.51,53.454,-0.00060137,6.9421,53.135,53.1,49.013
18.4776,6.0901,-0.0066261,35.829,55.254,-0.00068329,6.9512,54.972,54.931,50.743
19.0776,6.0904,-0.007463,35.831,57.054,-0.00076664,6.9474,56.805,56.819,52.487
19.6776,6.085,-0.0082204,35.423,58.854,-0.00084362,6.9455,58.757,58.678,54.351
20.2776,6.0929,-0.0095089,36.132,60.654,-0.0010136,6.9511,60.426,60.246,55.979
20.8776,6.0797,-0.008626,36.077,62.454,-0.00089058,6.9378,62.32,62.009,57.731
21.4776,6.0953,-0.0092499,36.115,64.254,-0.00096088,6.9553,64.132,63.764,59.508
22.0776,6.0876,-0.0098119,36.145,66.054,-0.0010223,6.9459,65.929,65.583,61.325
22.6776,6.1017,-0.011008,36.301,67.854,-0.0011457,6.9633,67.792,67.28,63.127
23.2776,6.0906,-0.011767,36.354,69.654,-0.0012484,6.9483,69.517,69.005,64.951
23.8776,6.0908,-0.011283,36.799,71.454,-0.0011695,6.951,71.273,70.793,66.742
24.4776,6.0921,-0.012078,36.431,73.254,-0.0012638,6.9494,73.174,72.533,68.578
25.0776,6.0944,-0.012686,36.464,75.054,-0.0013335,6.9554,75.034,74.374,70.389
25.6776,6.1191,-0.013756,36.346,76.854,-0.0014465,6.9818,76.846,76.122,72.259
26.2776,6.1017,-0.014372,36.415,78.654,-0.0015254,6.9631,78.647,77.818,74.047
26.8776,6.1181,-0.014072,36.856,80.454,-0.0014913,6.9814,80.358,79.486,75.812
27.4776,6.102,-0.014886,36.668,82.254,-0.0015805,6.9622,82.191,81.293,77.663
28.0776,6.1104,-0.015815,36.822,84.054,-0.0016715,6.9734,83.989,82.975,79.475
28.6776,6.1128,-0.017177,36.802,85.854,-0.0018313,6.9738,85.843,84.859,81.401
29.2776,6.1128,-0.017419,36.764,87.654,-0.0018692,6.9767,87.625,86.619,83.293
29.8776,6.1193,-0.017448,37.577,89.454,-0.0018738,6.9815,89.219,88.108,84.89
30.4776,6.1149,-0.01861,37.752,91.254,-0.001997,6.9789,91.036,90.026,86.747
31.0776,6.1362,-0.019182,37.409,93.054,-0.0020779,7.0009,92.98,91.84,88.641
31.6776,6.1307,-0.020791,37.305,94.854,-0.0022405,6.9951,94.825,93.612,90.579
32.2776,6.1415,-0.020985,37.621,96.654,-0.0022951,7.0087,96.598,95.283,92.472
32.8776,6.1292,-0.021135,37.66,98.454,-0.0022987,6.992,98.386,96.931,94.367
33.47761,6.138,-0.022256,37.778,100.25,-0.0024281,7.0053,100.19,98.659,96.252
34.07761,6.1483,-0.023024,37.83,102.05,-0.0025142,7.0134,101.95,100.4,98.169
34.67761,6.1567,-0.025107,37.283,103.85,-0.0027374,7.0261,103.94,102.41,100.23
35.27761,6.1754,-0.02463,38.113,105.65,-0.0027332,7.045,105.51,103.75,101.83
35.87761,6.1714,-0.025229,37.341,107.45,-0.0027845,7.0423,107.56,105.72,103.9
36.47761,6.1859,-0.026259,37.871,109.25,-0.0029287,7.0591,109.19,107.26,105.57
37.07761,6.1785,-0.027217,38.033,111.05,-0.003062,7.0497,110.97,108.98,107.45
37.67761,6.1985,-0.029153,37.875,112.85,-0.0032996,7.0736,112.85,110.61,109.41
38.27761,6.1969,-0.029302,38.05,114.65,-0.0033577,7.0697,114.66,112.35,111.27
38.87761,6.1977,-0.029371,38.182,116.45,-0.0033315,7.0737,116.42,114.02,113.19
39.47761,6.1992,-0.030687,38.094,118.25,-0.0034703,7.0727,118.25,115.7,115.02
40.07761,6.1978,-0.031982,38.313,120.05,-0.0036079,7.0725,120.02,117.39,116.84
40.67761,6.2163,-0.033491,38.597,121.85,-0.0037646,7.092,121.81,119.06,118.73
41.1137,6.2216,-0.035742,38.397,123.16,-0.0039075,7.099,123.18,120.23,120.03
41.7137,6.2114,-0.034168,38.741,124.96,-0.0036925,7.0871,124.86,121.85,121.91
42.3137,6.2222,-0.035591,38.623,126.76,-0.0038358,7.102,126.7,123.44,123.71
42.9137,6.2168,-0.036813,38.514,128.56,-0.00397,7.0927,128.54,125.1,125.58
43.5137,6.2245,-0.038185,39.174,130.36,-0.0041309,7.1034,130.2,126.55,127.38
44.1137,6.2337,-0.040862,39.154,132.16,-0.0044714,7.1109,132.04,128.45,129.3
44.7137,6.2334,-0.039079,39.296,133.96,-0.0042897,7.114,133.84,130.21,131.11
45.3137,6.246,-0.040636,39.144,135.76,-0.0044618,7.1266,135.68,131.93,133.0
45.9137,6.2356,-0.041573,39.254,137.56,-0.0045664,7.1154,137.53,133.54,134.93
46.5137,6.2511,-0.043372,39.291,139.36,-0.0047663,7.133,139.33,135.17,136.71
47.1137,6.245,-0.045324,39.35,141.16,-0.0050345,7.1246,141.09,136.77,138.54
47.7137,6.2492,-0.044163,39.336,142.96,-0.0048989,7.1315,142.93,138.41,140.35
48.3137,6.2518,-0.045634,39.616,144.76,-0.0051036,7.1318,144.67,140.08,142.14
48.9137,6.2399,-0.046829,39.182,146.56,-0.0052533,7.1225,146.64,141.84,144.15
49.5137,6.2497,-0.049081,39.614,148.36,-0.0054977,7.1302,148.28,143.2,145.74
50.1137,6.2571,-0.049255,39.212,150.16,-0.0055364,7.1408,150.24,145.0,147.77
50.7137,6.2709,-0.04978,39.448,151.96,-0.0055719,7.1553,151.89,146.25,149.37
51.3137,6.2624,-0.051432,39.416,153.76,-0.0057449,7.1448,153.83,147.97,151.29
51.9137,6.2743,-0.052757,39.703,155.56,-0.0058484,7.1603,155.47,149.52,153.01
52.5137,6.2726,-0.055637,39.43,157.36,-0.0061227,7.1566,157.4,151.05,154.77
53.1137,6.2839,-0.054389,40.078,159.16,-0.0059875,7.1725,158.97,152.64,156.42
53.7137,6.2806,-0.0557,39.782,160.96,-0.0061278,7.1651,160.9,154.26,158.32
54.3137,6.2749,-0.057036,39.517,162.76,-0.0062895,7.1621,162.81,155.85,160.11
54.9137,6.2879,-0.058149,39.094,164.56,-0.0064159,7.1733,164.75,157.6,162.15
55.5137,6.2801,-0.062065,39.243,166.36,-0.0068394,7.1665,166.55,159.25,163.9
56.1137,6.2843,-0.060148,39.752,168.16,-0.006671,7.1702,168.14,160.54,165.39
56.7137,6.2837,-0.061762,39.798,169.96,-0.006905,7.1704,169.91,162.09,167.06
57.3137,6.2915,-0.063289,39.957,171.76,-0.0071061,7.1797,171.67,163.59,168.8
57.9137,6.2749,-0.064383,39.553,173.56,-0.0072191,7.159,173.66,165.22,170.67
58.5137,6.2886,-0.068486,39.906,175.36,-0.0076663,7.1771,175.32,166.72,172.24
59.1137,6.2953,-0.066102,39.887,177.16,-0.00742,7.1826,177.08,168.14,174.03
59.7137,6.2869,-0.067541,39.265,178.96,-0.0075644,7.1755,179.13,169.89,175.9
60.3137,6.2967,-0.06935,40.329,180.76,-0.0077297,7.1842,180.61,171.13,177.36
60.91371,6.2795,-0.070424,39.526,182.56,-0.0078364,7.1662,182.68,172.87,179.35
61.51371,6.2973,-0.074798,40.373,184.36,-0.0083139,7.1865,184.22,174.12,180.82
62.11371,6.2859,-0.072468,40.116,186.16,-0.0080571,7.1719,186.11,175.6,182.54
62.71371,6.2965,-0.074153,40.049,187.96,-0.0082118,7.1857,187.96,177.05,184.37
63.31371,6.2876,-0.075965,40.054,189.76,-0.0083964,7.1735,189.78,178.59,186.08
63.91371,6.2891,-0.077144,39.828,191.56,-0.0085415,7.1782,191.57,180.14,187.73
64.51371,6.2975,-0.081695,40.117,193.36,-0.0090427,7.1845,193.37,181.59,189.44
65.11371,6.29,-0.07944,40.184,195.16,-0.0087745,7.1782,195.12,183.02,191.1
65.71371,6.3005,-0.081112,40.134,196.96,-0.0089311,7.1896,196.94,184.43,192.81
66.31371,6.2821,-0.082765,39.876,198.76,-0.0091031,7.1686,198.86,185.98,194.64
66.91371,6.295,-0.084185,39.729,200.56,-0.0092216,7.1841,200.69,187.51,196.39
67.51371,6.2921,-0.088359,40.424,202.36,-0.0096657,7.179,202.24,188.71,197.86
68.11371,6.2971,-0.085936,40.572,204.16,-0.0094351,7.1878,204.05,190.12,199.47
68.71371,6.2886,-0.087911,40.383,205.96,-0.0096713,7.1748,205.93,191.59,201.24
69.31371,6.2927,-0.089209,40.202,207.76,-0.0098414,7.182,207.77,193.14,203.02
69.91371,6.3016,-0.091048,40.272,209.56,-0.010062,7.1895,209.54,194.49,204.59
70.51371,6.2929,-0.095084,39.892,211.36,-0.010575,7.1816,211.51,196.11,206.54
71.11371,6.3087,-0.09257,40.548,213.16,-0.010319,7.1983,213.08,197.33,207.9
71.71371,6.2914,-0.094465,40.304,214.96,-0.010502,7.1802,214.93,198.76,209.63
72.31371,6.3024,-0.095907,39.51,216.76,-0.010639,7.1928,216.99,200.44,211.56
72.91371,6.2862,-0.097285,39.814,218.56,-0.010735,7.1722,218.7,201.84,213.12
73.51371,6.2925,-0.10193,40.217,220.37,-0.011187,7.1816,220.27,203.13,214.7
73.9466,6.2999,-0.099929,40.569,221.66,-0.011,7.1901,221.54,204.12,215.82
74.5466,6.3029,-0.1009,40.565,223.46,-0.011119,7.1915,223.3,205.45,217.34
75.1466,6.2902,-0.1029,39.793,225.26,-0.01137,7.1794,225.41,207.1,219.27
75.7466,6.3022,-0.10413,39.925,227.06,-0.011567,7.1909,227.22,208.51,221.01
76.3466,6.296,-0.1066,40.481,228.86,-0.01185,7.1836,228.79,209.76,222.56
76.9466,6.3063,-0.10788,40.814,230.66,-0.012003,7.1962,230.47,211.1,224.06
77.5466,6.299,-0.10795,40.62,232.46,-0.01195,7.187,232.38,212.5,225.78
78.1466,6.3014,-0.11001,40.595,234.26,-0.012129,7.1923,234.27,213.96,227.46
78.7466,6.2944,-0.11143,39.887,236.06,-0.012277,7.1815,236.31,215.63,229.39
79.3466,6.3012,-0.11436,40.885,237.86,-0.012608,7.1914,237.78,216.79,230.72
79.9466,6.3126,-0.11486,40.315,239.66,-0.012698,7.202,239.73,218.39,232.58
80.5466,6.2905,-0.11522,40.783,241.46,-0.012804,7.1788,241.39,219.66,234.08
81.1466,6.3292,-0.11718,40.303,243.26,-0.013041,7.2242,243.32,221.24,235.9
81.7466,6.2931,-0.11909,41.622,245.06,-0.013257,7.1809,244.99,222.52,237.44
82.3466,6.3227,-0.12182,40.71,246.86,-0.013544,7.2141,247.31,224.34,239.43
82.9466,6.3045,-0.12316,40.497,248.66,-0.013689,7.1934,249.44,225.93,241.45
83.5466,6.3081,-0.12352,41.701,250.46,-0.013683,7.1997,251.2,227.25,243.17
84.1466,6.3053,-0.12603,41.345,252.26,-0.013937,7.1934,253.54,229.08,245.27
84.7466,6.3096,-0.12801,41.722,254.06,-0.014127,7.2029,255.85,230.8,247.36
85.3466,6.3094,-0.13035,40.893,255.86,-0.014401,7.198,258.22,232.55,249.53
85.9466,6.3023,-0.13433,39.944,257.66,-0.014834,7.1931,260.27,234.1,251.51
86.5466,6.324,-0.13162,40.73,259.46,-0.014485,7.2164,261.75,235.41,253.0
87.1466,6.3062,-0.13378,40.341,261.26,-0.014671,7.195,263.63,237.01,254.75
87.7466,6.3059,-0.13539,40.603,263.06,-0.014842,7.1967,265.33,238.41,256.27
88.3466,6.3077,-0.13708,40.797,264.86,-0.015084,7.1968,267.06,239.82,257.81
88.9466,6.3112,-0.14168,41.282,266.66,-0.015594,7.2031,268.67,241.07,259.29
89.5466,6.308,-0.13943,40.764,268.46,-0.015474,7.1966,270.77,242.71,261.13
90.1466,6.3012,-0.14118,40.882,270.26,-0.015641,7.1915,272.48,244.14,262.84
90.7466,6.3151,-0.14315,40.976,272.06,-0.015837,7.2067,274.24,245.62,264.37
91.3466,6.2966,-0.14471,41.091,273.86,-0.015973,7.1852,276.0,247.1,265.99
91.9466,6.3155,-0.14929,41.112,275.66,-0.016418,7.2075,277.88,248.6,267.76
92.5466,6.3035,-0.14694,41.08,277.46,-0.016211,7.1908,279.68,250.02,269.45
93.14661,6.302,-0.1493,41.129,279.26,-0.016464,7.1919,281.51,251.44,271.12
93.74661,6.3024,-0.151,40.759,281.06,-0.016745,7.1897,283.4,252.95,272.92
94.34661,6.3046,-0.15315,41.206,282.86,-0.016982,7.1948,285.08,254.4,274.58
94.94661,6.3196,-0.158,41.257,284.66,-0.017533,7.2106,286.85,255.76,276.16
95.54661,6.3069,-0.15492,40.981,286.46,-0.017138,7.1974,288.75,257.36,277.96
96.14661,6.3279,-0.15759,40.617,288.26,-0.017416,7.2214,290.6,258.77,279.68
96.74661,6.3255,-0.1597,40.855,290.06,-0.017606,7.2191,292.35,260.28,281.33
97.34661,6.3162,-0.16209,40.867,291.86,-0.017889,7.2079,294.18,261.76,283.07
97.94661,6.3088,-0.1647,40.726,293.66,-0.018169,7.1987,296.02,263.21,284.77
98.54661,6.3176,-0.16413,41.31,295.46,-0.018044,7.2105,297.56,264.49,286.27
99.14661,6.3136,-0.16648,40.786,297.26,-0.018265,7.2037,299.6,266.15,288.19
99.74661,6.3133,-0.16827,40.62,299.06,-0.018492,7.2056,301.4,267.62,289.91
100.34661,6.319,-0.16991,38.966,300.0,-0.018711,7.2091,302.93,268.86,291.33
100.94661,6.2838,-0.17017,33.975,300.0,-0.018828,7.171,304.09,270.21,292.73
101.54661,6.3109,-0.16763,34.705,300.0,-0.01855,7.203,303.5,270.56,292.55
102.14661,6.3175,-0.16879,35.807,300.0,-0.018657,7.2099,302.93,271.13,292.05
102.74661,6.3185,-0.17035,37.381,300.0,-0.018744,7.2103,302.6,271.63,291.62
103.34661,6.3081,-0.17174,36.97,300.0,-0.018905,7.1971,302.76,272.36,291.65
103.94661,6.3151,-0.17484,37.787,300.0,-0.019275,7.2067,302.94,272.85,291.88
104.54661,6.3137,-0.17261,36.5,300.0,-0.019107,7.2027,303.63,273.77,292.51
105.14661,6.3079,-0.17411,36.611,300.0,-0.01928,7.1992,303.9,274.41,292.88
105.74661,6.3105,-0.1754,36.542,300.0,-0.019429,7.1996,304.19,275.07,293.25
106.2725,6.3109,-0.17649,35.986,300.0,-0.019406,7.1989,304.46,275.6,293.59
106.8725,6.3047,-0.18021,35.954,300.0,-0.019834,7.1951,304.55,276.09,293.82
107.4725,6.3216,-0.17692,36.486,300.0,-0.019514,7.213,304.61,276.59,293.98
108.0725,6.3055,-0.17882,36.787,300.0,-0.0198,7.1945,304.93,277.19,294.31
108.6725,6.3118,-0.18029,37.077,300.0,-0.019965,7.2025,305.4,277.8,294.78
109.2725,6.3048,-0.18099,35.58,300.0,-0.020021,7.1932,305.94,278.43,295.34
109.8725,6.3088,-0.18327,35.978,300.0,-0.020211,7.1991,306.12,278.92,295.78
110.4725,6.3161,-0.18368,36.151,300.0,-0.020276,7.2058,306.28,279.44,296.04
111.0725,6.3154,-0.18353,36.318,300.0,-0.020236,7.2073,306.65,279.95,296.37
111.6725,6.3248,-0.1848,35.222,300.0,-0.020324,7.2161,307.02,280.48,296.8
112.2725,6.3023,-0.18541,34.66,300.0,-0.020368,7.1914,307.1,280.82,297.03
112.8725,6.3147,-0.18605,34.608,300.0,-0.020406,7.2045,306.93,281.18,296.99
113.4725,6.31,-0.1874,35.526,300.0,-0.020602,7.1996,306.77,281.49,296.95
114.0725,6.3235,-0.19024,35.502,300.0,-0.020994,7.2162,306.81,281.86,297.03
114.6725,6.3175,-0.18749,35.62,300.0,-0.020731,7.207,307.09,282.22,297.27
115.2725,6.3157,-0.18891,34.764,300.0,-0.020855,7.2085,307.33,282.69,297.54
115.8592,6.3072,-0.18948,34.538,300.0,-0.020837,7.1958,307.37,283.06,297.71
116.4592,6.3032,-0.19036,34.766,300.0,-0.020949,7.1932,307.21,283.32,297.68
117.0592,6.3161,-0.19127,34.782,300.0,-0.021055,7.2059,307.13,283.63,297.68
117.6592,6.3154,-0.19517,36.098,300.0,-0.021566,7.2078,307.27,283.98,297.77
118.2592,6.3206,-0.19314,34.842,300.0,-0.021394,7.212,307.7,284.48,298.18
118.8592,6.3105,-0.19323,35.515,300.0,-0.021333,7.2,307.68,284.63,298.28
119.4592,6.3171,-0.19425,34.8,300.0,-0.021429,7.208,307.96,285.1,298.7
120.0592,6.2961,-0.19523,34.425,300.0,-0.021494,7.1834,308.0,285.28,298.71
120.6592,6.3186,-0.19653,35.718,300.0,-0.021641,7.2115,307.89,285.6,298.74
121.2592,6.318,-0.19777,35.096,300.0,-0.021718,7.2079,308.1,285.94,298.95
121.8592,6.3409,-0.19925,34.47,300.0,-0.02186,7.2373,308.28,286.33,299.23
122.4592,6.3213,-0.1974,34.713,300.0,-0.021686,7.2113,308.22,286.5,299.28
123.0592,6.32,-0.19903,35.774,300.0,-0.021911,7.2128,308.27,286.82,299.29
123.6592,6.3244,-0.19967,34.667,300.0,-0.02206,7.216,308.63,287.2,299.64
124.2592,6.3106,-0.20011,34.013,300.0,-0.02209,7.2007,308.77,287.47,299.82
124.8592,6.3272,-0.2017,34.238,300.0,-0.022166,7.2196,308.64,287.65,299.83
125.4592,6.3155,-0.20298,35.771,300.0,-0.022344,7.2051,308.53,287.8,299.84
126.0592,6.3237,-0.20181,34.813,300.0,-0.022218,7.2168,308.84,288.27,300.1
126.6592,6.3186,-0.20367,37.015,300.0,-0.022514,7.2083,309.12,288.73,300.37
127.2592,6.3142,-0.20444,35.052,300.0,-0.022606,7.2072,309.83,289.12,300.9
127.8592,6.3133,-0.20472,33.277,300.0,-0.022581,7.2025,310.17,289.48,301.38
128.4592,6.308,-0.20714,33.66,300.0,-0.022793,7.1992,309.94,289.61,301.39
129.0592,6.3262,-0.2059,34.581,300.0,-0.022684,7.2176,309.77,289.79,301.27
129.6592,6.3146,-0.2065,34.548,300.0,-0.022694,7.2058,309.75,290.0,301.31
130.2592,6.3139,-0.20742,33.672,300.0,-0.022755,7.2045,309.84,290.2,301.45
130.8592,6.3068,-0.20822,34.607,300.0,-0.022844,7.1959,309.67,290.35,301.33
131.4592,6.3218,-0.20917,33.858,300.0,-0.022986,7.2145,309.78,290.56,301.44
132.0592,6.3217,-0.21199,33.721,300.0,-0.023396,7.2113,309.82,290.8,301.52
132.6592,6.3144,-0.20891,33.728,300.0,-0.023052,7.2061,309.78,291.01,301.6
133.2592,6.3249,-0.20995,34.107,300.0,-0.02307,7.216,309.74,291.12,301.58
133.8592,6.3143,-0.21098,34.143,300.0,-0.023187,7.2051,309.69,291.32,301.62
134.4592,6.3219,-0.21178,33.848,300.0,-0.023307,7.213,309.74,291.52,301.7
135.05921,6.3063,-0.21312,33.703,300.0,-0.023538,7.1951,309.78,291.69,301.78
135.65921,6.3263,-0.21285,32.411,300.0,-0.02354,7.2189,309.74,291.87,301.8
136.25921,6.3195,-0.21225,32.834,300.0,-0.023399,7.2098,309.5,291.8,301.69
136.85921,6.3231,-0.21359,34.112,300.0,-0.023518,7.2167,309.19,291.82,301.4
137.45921,6.3141,-0.21465,33.901,300.0,-0.023628,7.2031,309.19,292.04,301.47
138.05921,6.3154,-0.21553,33.669,300.0,-0.023664,7.2074,309.31,292.2,301.55
138.65921,6.3246,-0.2186,33.017,300.0,-0.023961,7.216,309.44,292.42,301.69
139.119,6.3168,-0.21536,32.855,300.0,-0.023739,7.2102,309.45,292.47,301.78
139.719,6.3252,-0.21617,33.092,300.0,-0.023762,7.2152,309.37,292.54,301.75
140.319,6.3275,-0.21723,33.069,300.0,-0.023877,7.2227,309.35,292.63,301.79
140.919,6.3256,-0.21794,33.105,300.0,-0.023915,7.2173,309.33,292.85,301.82
141.519,6.3219,-0.21906,33.221,300.0,-0.024024,7.2143,309.32,293.0,301.82
142.119,6.3262,-0.2219,32.977,300.0,-0.024379,7.2174,309.37,293.13,301.91
142.719,6.3137,-0.21859,33.073,300.0,-0.024124,7.2038,309.34,293.19,301.95
143.319,6.3355,-0.21955,33.266,300.0,-0.024194,7.2306,309.31,293.31,301.93
143.919,6.3199,-0.22051,33.019,300.0,-0.024239,7.2101,309.32,293.46,301.99
144.519,6.3244,-0.22115,32.736,300.0,-0.024293,7.2181,309.39,293.6,302.1
145.119,6.3291,-0.012031,32.887,300.0,-0.0013818,7.2203,309.36,293.7,302.08
145.2871,6.3823,0.015308,24.215,10.334,0.001887,7.2833,309.26,293.66,301.96
145.2901,6.2893,0.016661,14.632,0.0008423,0.0017211,7.1649,309.25,293.66,301.95
145.2931,6.3951,0.014923,5.049,6.8653e-08,0.00091291,7.306,309.24,293.66,301.93
145.2961,6.2997,0.0161,0.0,5.5956e-12,0.0012265,7.1743,309.29,293.65,301.94
145.2991,6.3345,0.014602,0.0,4.5605e-16,0.001653,7.244,309.4,293.63,301.99
145.3021,6.3296,0.01231,0.0,3.7168e-20,0.0018176,7.2093,309.51,293.61,302.03
145.3051,6.313,0.012817,0.0,3.0291e-24,0.001928,7.222,309.59,293.6,302.07
145.3081,6.3461,0.014067,0.0,2.4685999999999997e-28,0.0016211,7.2284,309.52,293.59,302.09
145.3111,6.2885,0.014993,0.0,2.0118e-32,0.0015901,7.1895,309.44,293.58,302.11
145.3141,6.3625,0.015654,0.0,1.6394e-36,0.0017705,7.2557,309.37,293.57,302.13
145.3171,6.2646,0.015451,0.0,1.3294e-40,0.0019189,7.1627,309.39,293.6,302.15
145.3201,6.3769,0.016231,0.0,9.8091e-45,0.0016267,7.2618,309.44,293.63,302.17
145.3231,6.2608,0.016329,0.0,0.0,0.0011913,7.146,309.49,293.67,302.18
145.3261,6.3825,0.016284,0.0,0.0,0.0013445,7.2777,309.47,293.7,302.19
145.3291,6.244,0.014828,0.0,0.0,0.0016399,7.136,309.4,293.73,302.18
145.3321,6.3748,0.013405,0.0,0.0,0.002009,7.2737,309.33,293.76,302.17
145.3351,6.2495,0.012497,0.0,0.0,0.0019236,7.1341,309.26,293.79,302.16
145.3381,6.3658,0.014613,0.0,0.0,0.0016788,7.2669,309.21,293.81,302.17
145.3411,6.2673,0.015006,0.0,0.0,0.0015509,7.1465,309.17,293.84,302.18
145.3441,6.3434,0.014334,0.0,0.0,0.0018036,7.2439,309.12,293.87,302.19
145.3471,6.2447,0.01581,0.0,0.0,0.001872,7.1077,309.17,293.86,302.17
145.3501,6.2898,0.014535,0.0,0.0,0.001385,7.1982,309.25,293.84,302.14
145.3531,25.533,0.11344,0.0,0.0,0.011849,28.44,309.32,293.82,302.12
145.35609,47.15,0.1718,0.0,0.0,0.018785,53.453,309.36,293.82,302.07
145.35909,64.233,0.24156,0.0,0.0,0.027148,73.003,309.36,293.83,302.02
145.36209,76.851,0.31314,0.0,0.0,0.035646,87.393,309.36,293.83,301.96
145.36509,89.862,0.47463,0.0,0.0,0.054071,102.24,309.37,293.91,301.91
145.36809,103.78,0.734,0.0,0.0,0.084169,118.16,309.44,294.28,301.86
145.37109,111.33,1.0593,0.0,0.0,0.12358,126.94,309.52,294.65,301.82
145.37409,114.5,1.3986,0.0,0.0,0.16678,130.6,309.59,295.02,301.77
145.37709,116.43,1.7088,0.0,0.0,0.20766,132.81,310.26,296.5,301.72
145.38009,117.62,1.994,0.0,0.0,0.24618,134.18,311.02,298.17,301.68
145.38309,118.53,2.2358,0.0,0.0,0.27959,135.22,311.78,299.84,301.63
145.38609,119.04,2.4501,0.0,0.0,0.31097,135.8,312.88,301.67,301.62
145.38909,119.57,2.6424,0.0,0.0,0.34037,136.42,314.26,303.64,301.62
145.39209,120.05,2.8235,0.0,0.0,0.36876,136.95,315.65,305.62,301.63
145.39509,120.7,3.0092,0.0,0.0,0.39747,137.72,316.98,307.38,301.64
145.39809,121.35,3.1943,0.0,0.0,0.42648,138.44,318.05,308.35,301.64
145.40109,122.04,3.388,0.0,0.0,0.45816,139.24,319.13,309.31,301.64
145.40409,122.62,3.5761,0.0,0.0,0.49064,139.9,320.2,310.28,301.64
145.40709,123.09,3.763,0.0,0.0,0.52356,140.44,320.94,311.01,301.64
145.41009,123.43,3.9442,0.0,0.0,0.55524,140.83,321.64,311.71,301.64
145.41309,123.74,4.1182,0.0,0.0,0.58689,141.19,322.34,312.41,301.64
145.41609,123.99,4.2862,0.0,0.0,0.61901,141.47,322.96,313.17,301.66
145.41909,124.21,4.4454,0.0,0.0,0.65133,141.72,323.52,313.99,301.7
145.42209,124.48,4.5974,0.0,0.0,0.68284,142.03,324.07,314.81,301.74
145.42509,124.63,4.7517,0.0,0.0,0.71456,142.2,324.59,315.69,301.76
145.42809,124.86,4.8984,0.0,0.0,0.74479,142.47,324.93,316.78,301.75
145.43109,124.99,5.0442,0.0,0.0,0.77652,142.6,325.28,317.87,301.74
145.43409,125.23,5.1825,0.0,0.0,0.80835,142.89,325.63,318.97,301.73
145.43709,125.42,5.3198,0.0,0.0,0.84081,143.1,325.84,319.98,301.73
145.44009,125.58,5.4574,0.0,0.0,0.87213,143.28,326.03,320.97,301.73
145.44309,125.49,5.5894,0.0,0.0,0.90345,143.19,326.22,321.97,301.73
145.44609,125.54,5.7197,0.0,0.0,0.93682,143.24,326.36,322.7,301.74
145.44909,125.54,5.8409,0.0,0.0,0.97014,143.24,326.46,323.21,301.76
145.45209,125.59,5.9612,0.0,0.0,1.0034,143.3,326.56,323.72,301.78
145.45509,125.64,6.0777,0.0,0.0,1.0348,143.35,326.64,324.18,301.8
145.45809,125.78,6.1902,0.0,0.0,1.0654,143.52,326.65,324.46,301.81
145.46109,126.01,6.2996,0.0,0.0,1.0969,143.76,326.66,324.75,301.82
145.46409,126.23,6.4063,0.0,0.0,1.1303,144.02,326.67,325.03,301.82
145.46709,126.46,6.5096,0.0,0.0,1.1625,144.29,326.68,325.11,301.86
145.47009,126.71,6.6174,0.0,0.0,1.195,144.58,326.69,325.16,301.9
145.47309,126.95,6.7169,0.0,0.0,1.226,144.84,326.7,325.22,301.93
145.47609,127.14,6.8155,0.0,0.0,1.2598,145.07,326.71,325.17,301.96
145.47909,127.39,6.9076,0.0,0.0,1.294,145.35,326.72,325.06,301.99
145.48209,127.64,7.0021,0.0,0.0,1.3295,145.63,326.73,324.95,302.02
145.48509,128.0,7.0941,0.0,0.0,1.3626,146.04,326.74,324.36,302.05
145.48809,128.31,7.1835,0.0,0.0,1.3944,146.4,326.74,322.41,302.08
145.49109,128.73,7.2699,0.0,0.0,1.428,146.88,326.75,320.45,302.1
145.49408,129.11,7.3518,0.0,0.0,1.4632,147.31,326.76,318.5,302.13
145.49708,129.57,7.4305,0.0,0.0,1.4961,147.83,326.81,318.44,302.13
145.50008,129.95,7.5082,0.0,0.0,1.5268,148.27,326.85,318.51,302.13
145.50308,130.51,7.5825,0.0,0.0,1.5571,148.9,326.9,318.58,302.13
145.50608,131.03,7.656,0.0,0.0,1.5917,149.49,326.89,319.66,302.14
145.50908,127.82,7.6962,0.0,0.0,1.6137,145.97,326.86,321.37,302.16
145.51208,123.58,7.6949,0.0,0.0,1.6157,141.11,326.82,323.09,302.18
145.51508,120.39,7.7022,0.0,0.0,1.6176,137.43,326.78,324.15,302.19
145.51808,117.89,7.7106,0.0,0.0,1.6189,134.57,326.71,323.53,302.18
145.52108,116.04,7.7177,0.0,0.0,1.6219,132.45,326.65,322.9,302.17
145.52408,114.05,7.719,0.0,0.0,1.625,130.19,326.58,322.28,302.16
145.52708,110.61,7.7215,0.0,0.0,1.6265,126.32,326.57,321.62,302.16
145.53008,99.811,7.7247,0.0,0.0,1.6252,114.4,326.56,320.96,302.16
145.53308,50.505,7.6438,0.0,0.0,1.5864,58.8,326.55,320.3,302.16
145.53608,7.7597,7.5268,0.0,0.0,1.5356,9.4518,326.53,319.78,302.16
145.53908,5.4624,7.5219,0.0,0.0,1.5354,6.4013,326.49,319.33,302.15
145.54208,5.218,7.5077,0.0,0.0,1.5309,6.0144,326.45,318.88,302.14
145.54508,5.047,7.512,0.0,0.0,1.5312,5.7836,326.4,318.51,302.13
145.54808,5.4806,7.5147,0.0,0.0,1.5302,6.2263,326.32,318.36,302.13
145.55108,5.446,7.5162,0.0,0.0,1.5308,6.2334,326.24,318.2,302.13
145.55408,5.559,7.5161,0.0,0.0,1.5328,6.3179,326.16,318.05,302.13
145.55708,5.3963,7.5129,0.0,0.0,1.5318,6.1611,326.11,318.0,302.17
145.56008,5.5061,7.513,0.0,0.0,1.5292,6.2673,326.06,317.95,302.21
145.56308,5.3337,7.5157,0.0,0.0,1.5285,6.0845,326.02,317.91,302.24
145.56608,5.4525,7.5162,0.0,0.0,1.5298,6.2214,325.96,317.82,302.27
145.56908,5.3517,7.5154,0.0,0.0,1.5323,6.1047,325.9,317.72,302.29
145.57208,5.481,7.5128,0.0,0.0,1.5333,6.2628,325.83,317.62,302.3
145.57508,5.3556,7.514,0.0,0.0,1.5322,6.0991,325.76,317.51,302.32
145.57808,5.4451,7.5155,0.0,0.0,1.5306,6.232,325.67,317.36,302.34
145.58108,5.4174,7.5182,0.0,0.0,1.5317,6.1679,325.58,317.21,302.36
145.58408,5.4334,7.5172,0.0,0.0,1.5336,6.1994,325.48,317.06,302.38
145.58708,5.4237,7.5151,0.0,0.0,1.5327,6.1716,325.42,316.91,302.36
145.59008,5.4086,7.5147,0.0,0.0,1.53,6.1831,325.36,316.75,302.34
145.59308,5.4904,7.5157,0.0,0.0,1.5287,6.2446,325.29,316.6,302.32
145.59608,5.414,7.5153,0.0,0.0,1.5299,6.1929,325.22,316.45,302.33
145.59908,5.506,7.5147,0.0,0.0,1.532,6.2697,325.15,316.31,302.35
145.60208,5.4101,7.5139,0.0,0.0,1.5336,6.1741,325.07,316.18,302.37
145.60508,5.4657,7.5139,0.0,0.0,1.5324,6.2403,324.99,316.04,302.38
145.60808,5.423,7.5165,0.0,0.0,1.5309,6.1944,324.89,315.91,302.4
145.61108,5.5087,7.5183,0.0,0.0,1.5318,6.2751,324.79,315.78,302.42
145.61408,5.4165,7.5183,0.0,0.0,1.5345,6.1686,324.69,315.65,302.44
145.61708,5.5179,7.5156,0.0,0.0,1.5331,6.3081,324.62,315.53,302.48
145.62008,5.4512,7.5181,0.0,0.0,1.531,6.2048,324.54,315.4,302.51
145.62308,5.5018,7.5202,0.0,0.0,1.5304,6.284,324.47,315.27,302.55
145.62608,5.5152,7.518,0.0,0.0,1.5311,6.2779,324.44,315.1,302.57
145.62908,5.6189,7.5159,0.0,0.0,1.5328,6.4238,324.43,314.9,302.58
145.63207,5.5642,7.5136,0.0,0.0,1.5335,6.3428,324.42,314.71,302.59
145.63507,5.6922,7.5166,0.0,0.0,1.5329,6.5197,324.4,314.51,302.6
145.63807,5.7027,7.5205,0.0,0.0,1.5322,6.4908,324.37,314.3,302.62
145.64107,5.7061,7.5224,0.0,0.0,1.5339,6.5151,324.33,314.09,302.64
145.64407,5.6931,7.519,0.0,0.0,1.5348,6.47,324.29,313.88,302.66
145.64707,5.7009,7.5182,0.0,0.0,1.5339,6.5236,324.22,313.74,302.71
145.65007,5.7524,7.518,0.0,0.0,1.5314,6.5326,324.15,313.6,302.77
145.65307,5.6564,7.5208,0.0,0.0,1.5309,6.4719,324.07,313.46,302.82
145.65607,5.7761,7.5181,0.0,0.0,1.5312,6.5714,324.0,313.33,302.86
145.65907,5.6134,7.5162,0.0,0.0,1.5331,6.4278,323.93,313.19,302.89
145.66207,5.8252,7.5166,0.0,0.0,1.5347,6.6297,323.85,313.05,302.91
145.66507,5.6117,7.5183,0.0,0.0,1.5338,6.4196,323.78,312.89,302.93
145.66807,5.8684,7.5236,0.0,0.0,1.5335,6.6762,323.72,312.7,302.94
145.67107,5.6134,7.5207,0.0,0.0,1.5329,6.4031,323.65,312.51,302.95
145.67407,5.8715,7.5212,0.0,0.0,1.5354,6.6945,323.59,312.31,302.96
145.67707,5.619,7.5183,0.0,0.0,1.5341,6.4085,323.53,312.11,302.97
145.68007,5.8594,7.5211,0.0,0.0,1.5325,6.6906,323.46,311.91,302.98
145.68307,5.6416,7.5191,0.0,0.0,1.5302,6.4249,323.4,311.71,302.99
145.68607,5.8361,7.5196,0.0,0.0,1.5321,6.676,323.31,311.48,302.99
145.68907,5.669,7.5154,0.0,0.0,1.5324,6.4529,323.22,311.25,302.98
145.69207,5.796,7.5177,0.0,0.0,1.5351,6.6354,323.13,311.02,302.97
145.69507,5.7166,7.5163,0.0,0.0,1.5325,6.5055,323.05,310.8,302.97
145.69807,5.7432,7.5209,0.0,0.0,1.5326,6.5877,323.0,310.59,302.99
145.70107,5.7626,7.5202,0.0,0.0,1.5326,6.5509,322.94,310.38,303.01
145.70407,5.7165,7.5201,0.0,0.0,1.5352,6.5465,322.89,310.17,303.03
145.70707,5.795,7.5198,0.0,0.0,1.5344,6.5853,322.85,310.05,303.08
145.71007,5.6735,7.522,0.0,0.0,1.5326,6.4974,322.82,309.94,303.14
145.71307,5.8449,7.5228,0.0,0.0,1.5316,6.6502,322.78,309.82,303.19
145.71607,5.6561,7.5209,0.0,0.0,1.5327,6.4696,322.73,309.66,303.21
145.71907,5.8637,7.5198,0.0,0.0,1.5347,6.686,322.68,309.48,303.22
145.72207,5.6339,7.5171,0.0,0.0,1.5349,6.4371,322.62,309.31,303.23
145.72507,5.868,7.5199,0.0,0.0,1.5345,6.697,322.56,309.1,303.24
145.72807,5.6505,7.5208,0.0,0.0,1.5327,6.4489,322.5,308.87,303.25
145.73107,5.8853,7.523,0.0,0.0,1.5337,6.7151,322.43,308.63,303.26
145.73407,5.6716,7.5212,0.0,0.0,1.5355,6.4534,322.37,308.39,303.27
145.73707,5.8897,7.5235,0.0,0.0,1.536,6.7305,322.3,308.24,303.32
145.74007,5.702,7.5223,0.0,0.0,1.5327,6.4937,322.24,308.08,303.37
145.74307,5.8617,7.5241,0.0,0.0,1.5323,6.7139,322.18,307.93,303.41
145.74607,5.7473,7.5213,0.0,0.0,1.5326,6.5311,322.11,307.8,303.46
145.74907,5.826,7.5201,0.0,0.0,1.5351,6.6694,322.03,307.69,303.5
145.75207,5.7765,7.5186,0.0,0.0,1.5357,6.5682,321.96,307.58,303.55
145.75507,5.7648,7.5234,0.0,0.0,1.5357,6.6078,321.89,307.46,303.58
145.75807,5.8168,7.5232,0.0,0.0,1.5338,6.6119,321.84,307.31,303.59
145.76107,5.7294,7.5234,0.0,0.0,1.5345,6.5655,321.78,307.16,303.6
145.76407,5.853,7.5204,0.0,0.0,1.535,6.6619,321.73,307.02,303.61
145.76707,5.7002,7.5205,0.0,0.0,1.5347,6.5276,321.7,306.87,303.62
145.77006,5.8755,7.5234,0.0,0.0,1.5331,6.6839,321.68,306.72,303.63
145.77306,5.6781,7.5219,0.0,0.0,1.5319,6.4913,321.65,306.58,303.64
145.77606,5.8977,7.5233,0.0,0.0,1.5338,6.718,321.58,306.43,303.66
145.77906,5.6761,7.5193,0.0,0.0,1.5346,6.4797,321.5,306.28,303.69
145.78206,5.9107,7.519,0.0,0.0,1.5355,6.7347,321.41,306.13,303.71
145.78506,5.6906,7.5198,0.0,0.0,1.5341,6.4846,321.34,305.98,303.75
145.78806,5.9063,7.5243,0.0,0.0,1.5338,6.7401,321.29,305.81,303.78
145.79106,5.7098,7.5237,0.0,0.0,1.5347,6.5029,321.23,305.65,303.82
145.79406,5.8987,7.5235,0.0,0.0,1.5364,6.7456,321.18,305.48,303.85
145.79706,5.7493,7.5202,0.0,0.0,1.5345,6.5394,321.17,305.33,303.86
145.80006,5.8771,7.5243,0.0,0.0,1.5335,6.7274,321.15,305.17,303.87
145.80306,5.7991,7.524,0.0,0.0,1.5325,6.5934,321.13,305.02,303.88
145.80606,5.8103,7.5246,0.0,0.0,1.5344,6.657,321.05,304.85,303.9
145.80906,5.8416,7.5206,0.0,0.0,1.5352,6.6422,320.96,304.69,303.92
145.81206,5.7839,7.5198,0.0,0.0,1.5363,6.633,320.87,304.52,303.93
145.81506,5.8798,7.5223,0.0,0.0,1.535,6.6945,320.79,304.36,303.97
145.81806,5.733,7.5239,0.0,0.0,1.5338,6.5676,320.73,304.2,304.04
145.82106,5.9058,7.5235,0.0,0.0,1.5344,6.7258,320.66,304.05,304.1
145.82406,5.7186,7.5219,0.0,0.0,1.536,6.5471,320.6,303.89,304.16
145.82706,5.9354,7.523,0.0,0.0,1.5358,6.7508,320.54,303.74,304.19
145.83006,5.707,7.5232,0.0,0.0,1.5331,6.5165,320.49,303.6,304.22
145.83306,5.946,7.5265,0.0,0.0,1.5335,6.7769,320.43,303.45,304.25
145.83606,5.7118,7.523,0.0,0.0,1.5338,6.5135,320.37,303.33,304.23
145.83906,5.9547,7.5204,0.0,0.0,1.5353,6.7959,320.31,303.22,304.22
145.84206,5.7189,7.519,0.0,0.0,1.5354,6.5319,320.24,303.11,304.2
145.84506,5.9267,7.5222,0.0,0.0,1.5348,6.7827,320.19,303.01,304.2
145.84806,5.7748,7.5217,0.0,0.0,1.533,6.5635,320.16,302.92,304.22
145.85106,5.9034,7.5246,0.0,0.0,1.5348,6.7652,320.12,302.82,304.23
145.85406,5.799,7.5202,0.0,0.0,1.5353,6.5978,320.08,302.73,304.26
145.85706,5.8705,7.5238,0.0,0.0,1.5357,6.7206,320.01,302.6,304.31
145.86006,5.8375,7.5229,0.0,0.0,1.5328,6.6464,319.95,302.47,304.37
145.86306,5.8261,7.5244,0.0,0.0,1.5328,6.6785,319.89,302.34,304.42
145.86606,5.8892,7.5224,0.0,0.0,1.5333,6.7062,319.84,302.2,304.45
145.86906,5.7833,7.5193,0.0,0.0,1.5348,6.6241,319.79,302.06,304.47
145.87206,5.9292,7.5197,0.0,0.0,1.5357,6.7452,319.75,301.92,304.49
145.87506,5.7618,7.5213,0.0,0.0,1.5345,6.5988,319.69,301.79,304.5
145.87806,5.9461,7.5243,0.0,0.0,1.5338,6.7645,319.64,301.67,304.52
145.88106,5.7544,7.5224,0.0,0.0,1.5343,6.5722,319.58,301.55,304.54
145.88406,5.9753,7.5221,0.0,0.0,1.536,6.8054,319.52,301.44,304.56
145.88706,5.747,7.5205,0.0,0.0,1.5345,6.5566,319.44,301.37,304.6
145.89006,5.9793,7.5227,0.0,0.0,1.5327,6.8232,319.36,301.3,304.64
145.89306,5.7564,7.5216,0.0,0.0,1.5315,6.5603,319.28,301.22,304.67
145.89606,5.9683,7.5215,0.0,0.0,1.5332,6.8181,319.23,301.09,304.69
145.89906,5.7936,7.5182,0.0,0.0,1.5345,6.594,319.18,300.95,304.7
145.90206,5.9687,7.52,0.0,0.0,1.5357,6.8247,319.13,300.82,304.7
145.90506,5.8116,7.5221,0.0,0.0,1.5344,6.6163,319.1,300.66,304.72
145.90805,5.9266,7.526,0.0,0.0,1.5347,6.7822,319.07,300.48,304.74
145.91105,5.8498,7.5241,0.0,0.0,1.535,6.6546,319.04,300.31,304.76
145.91405,5.8731,7.5236,0.0,0.0,1.5365,6.7284,319.01,300.14,304.78
145.91705,5.9007,7.5223,0.0,0.0,1.5349,6.707,318.96,300.02,304.85
146.3179,5.8171,7.5249,0.0,0.0,1.5356,6.6375,313.18,288.22,302.19
146.9179,5.7354,7.5266,0.0,0.0,1.5363,6.5453,294.92,158.12,250.56
147.5179,5.6404,7.5272,0.0,0.0,1.5366,6.437,275.99,127.35,231.2
148.1179,5.6013,7.5285,0.0,0.0,1.5372,6.3921,259.84,103.62,208.69
148.6499,5.5715,7.53,0.0,0.0,1.5378,6.3579,245.92,87.307,190.53
149.2499,5.5639,7.5365,0.0,0.0,1.5408,6.3492,231.23,74.969,181.52
149.8499,5.5369,7.5459,0.0,0.0,1.5452,6.3168,214.5,66.388,156.37
150.4499,5.519,7.5557,0.0,0.0,1.5495,6.2986,193.92,61.158,111.51
151.0499,5.4574,7.5589,0.0,0.0,1.5505,6.2273,142.27,57.377,70.008
151.6499,5.4566,7.5659,0.0,0.0,1.5532,6.2274,111.91,51.28,51.346
152.2499,5.4427,7.5725,0.0,0.0,1.5565,6.2101,91.983,48.565,39.39
152.8499,5.4413,7.5773,0.0,0.0,1.559,6.2092,72.591,45.175,34.812
153.4499,5.4356,7.5814,0.0,0.0,1.5607,6.2015,60.323,42.599,31.528
154.0499,5.4317,7.5852,0.0,0.0,1.5619,6.1977,51.741,41.614,29.474
154.6499,5.4362,7.59,0.0,0.0,1.5639,6.2031,46.365,41.616,27.748
155.2499,5.4336,7.594,0.0,0.0,1.5659,6.1997,42.222,41.558,26.926
155.8499,5.441,7.5985,0.0,0.0,1.5682,6.2088,39.286,34.196,26.038
156.4012,5.551,7.6016,0.0,0.0,1.5697,6.3336,38.774,41.587,27.96
157.0012,5.4774,7.606,0.0,0.0,1.5719,6.2496,40.876,42.182,30.722
157.6012,5.4511,7.6097,0.0,0.0,1.5735,6.2209,42.376,44.384,33.339
158.2012,5.4629,7.6133,0.0,0.0,1.5748,6.2332,43.525,46.008,35.815
158.8012,5.416,7.6163,0.0,0.0,1.5759,6.1799,44.592,47.358,38.039
159.4012,5.6896,7.62,0.0,0.0,1.578,6.4924,45.558,48.576,40.049
160.0012,5.4124,7.625,0.0,0.0,1.5805,6.1759,46.59,49.551,41.928
160.6012,5.4126,7.6271,0.0,0.0,1.581,6.1764,47.417,50.369,43.583
161.2012,5.3436,7.6287,0.0,0.0,1.5814,6.0966,48.222,51.092,45.159
161.8012,5.318,7.6307,0.0,0.0,1.5824,6.0676,48.944,51.666,46.568
162.4012,5.3061,7.6318,0.0,0.0,1.5831,6.0551,49.754,52.346,47.902
162.8012,5.3015,7.6328,0.0,0.0,1.5837,6.0502,50.156,52.708,48.617