File: examples/dan-msc-case-studies/CS4/data/01 raw data/hyde_test_021.csv
Time(sec),Force(kN),Jaw(mm),PowAngle(deg),PTemp,Strain,Stress(MPa),TC1(C),TC2(C),TC3(C)
0.0,2.8872,-0.0028533,0.0,0.0052399,-0.00037243,8.7814,19.424,20.146,20.052
1.6,2.8121,-0.0025183,0.0,4.621,-0.0003069,8.5347,19.523,20.254,20.042
3.2,2.7747,-0.002468,0.0,9.421,-0.0002834,8.4169,19.482,20.213,20.015
4.8,2.7493,-0.0024124,0.0,14.221,-0.00025562,8.3409,19.417,20.199,19.973
6.2211,2.7232,-0.0021208,0.0,18.484,-0.00025283,8.2615,19.418,20.201,20.003
7.8211,2.7267,-0.0014573,27.062,23.284,-0.00017374,8.2716,21.403,21.302,21.442
9.4211,2.7367,-0.0031278,26.527,28.084,-0.00033163,8.306,27.22,25.028,26.003
11.0211,2.7459,-0.0041851,26.889,32.884,-0.00046092,8.3323,32.581,28.932,30.547
12.6211,2.7666,-0.0053844,26.87,37.684,-0.00061995,8.3952,37.661,37.272,35.135
14.2211,2.7857,-0.0068949,27.089,42.484,-0.00078659,8.4527,42.69,37.614,39.663
15.8211,2.7454,-0.0087131,27.466,47.284,-0.00094122,8.3291,47.498,41.831,44.256
17.4211,2.7918,-0.010893,27.786,52.084,-0.0011604,8.4689,52.326,45.978,48.812
19.0211,2.7997,-0.011558,27.586,56.884,-0.001222,8.4922,57.27,50.491,53.431
20.6211,2.7943,-0.013292,28.309,61.684,-0.0014643,8.4754,62.116,54.781,58.099
22.2211,2.8017,-0.015983,28.908,66.484,-0.0017674,8.4979,66.793,59.066,62.712
23.8211,2.8055,-0.016679,29.476,71.284,-0.0018209,8.5072,71.564,63.399,67.288
25.42111,2.8064,-0.018343,29.151,76.084,-0.002028,8.5121,76.452,67.733,71.979
27.02111,2.8146,-0.021683,29.28,80.884,-0.0023727,8.5355,81.269,72.01,76.576
28.62111,2.8046,-0.022473,29.508,85.684,-0.0024295,8.5052,86.062,76.411,81.24
30.22111,2.794,-0.024426,29.908,90.484,-0.0026289,8.4754,90.798,80.633,85.709
31.82111,2.8044,-0.026293,29.79,95.284,-0.0028834,8.5071,95.592,84.862,90.306
33.42111,2.8022,-0.028795,27.112,100.08,-0.0031464,8.4989,100.31,89.102,94.828
35.02111,2.8043,-0.030039,28.99,104.88,-0.0033041,8.5077,104.34,92.863,98.81
36.62111,2.8061,-0.032234,29.795,109.68,-0.0035157,8.513,108.99,96.776,103.06
38.1401,2.8043,-0.03422,30.232,114.24,-0.0037045,8.5044,113.53,100.96,107.43
39.7401,2.8282,-0.036867,30.833,119.04,-0.0040007,8.5761,118.28,105.14,111.95
41.3401,4.2597,-0.02982,30.846,123.84,-0.0032714,12.921,123.16,109.96,116.8
42.9401,5.0232,-0.023432,30.065,128.64,-0.0025909,15.238,128.07,115.98,122.12
44.475,5.4057,-0.022363,30.29,133.25,-0.0023959,16.399,132.63,121.21,126.85
46.075,5.5084,-0.023203,30.182,138.05,-0.0025674,16.705,137.43,126.4,131.8
47.675,5.8236,-0.023949,31.649,142.85,-0.0026259,17.663,141.88,131.16,136.35
49.275,5.697,-0.027359,30.064,147.65,-0.0029763,17.278,147.07,136.26,141.52
50.875,4.9679,-0.030971,29.534,152.45,-0.0033601,15.066,151.99,141.03,146.4
52.475,4.3806,-0.034227,30.619,157.25,-0.003754,13.287,156.61,145.58,150.84
54.075,4.2266,-0.037718,31.885,162.05,-0.0041456,12.819,161.22,150.03,155.47
55.675,3.9418,-0.041268,30.644,166.85,-0.0044791,11.959,166.26,154.91,160.47
57.275,3.5048,-0.045901,31.865,171.65,-0.0049703,10.632,170.82,159.13,164.8
58.875,3.0293,-0.051244,31.894,176.45,-0.0055982,9.1908,175.68,163.4,169.42
60.475,2.8748,-0.05234,32.547,181.25,-0.0057397,8.7256,180.38,167.43,173.84
62.075,2.8448,-0.055708,32.145,186.05,-0.0060374,8.6323,185.33,171.38,178.39
63.67501,2.8316,-0.058648,32.411,190.85,-0.0064097,8.5918,190.15,175.39,182.87
65.27501,2.8243,-0.063704,32.808,195.65,-0.0069591,8.568,194.87,179.36,187.25
66.87501,2.8162,-0.064712,32.623,200.45,-0.0070287,8.546,199.77,183.56,191.88
68.47501,2.8362,-0.067767,33.306,205.25,-0.0073909,8.6022,204.45,187.52,196.3
70.07501,3.0759,-0.070393,32.951,210.05,-0.0076748,9.3311,209.37,191.75,200.89
71.5764,3.7627,-0.07037,31.985,214.55,-0.0076343,11.415,214.14,196.11,205.51
73.1764,4.1352,-0.072516,34.12,219.35,-0.007929,12.544,218.34,200.46,209.69
74.7638,4.2691,-0.07588,33.061,224.11,-0.0082899,12.946,223.36,205.36,214.66
76.3638,4.7205,-0.076366,32.851,228.91,-0.0082882,14.319,228.28,210.02,219.73
77.9638,4.9499,-0.079066,35.098,233.71,-0.0086341,15.011,233.11,214.94,224.6
79.5638,5.0088,-0.08444,32.735,238.51,-0.0092192,15.191,238.73,220.43,230.29
81.1638,5.0242,-0.084217,32.873,243.31,-0.0091211,15.237,243.5,225.26,235.06
82.7638,5.0323,-0.087444,34.007,248.11,-0.0095069,15.262,248.05,229.94,239.68
84.3638,5.046,-0.090368,32.574,252.91,-0.0098508,15.307,253.2,234.84,244.75
85.9638,5.0658,-0.093103,33.225,257.71,-0.010129,15.368,257.85,239.38,249.48
87.5638,5.0841,-0.097429,33.607,262.51,-0.010614,15.422,262.6,244.08,254.14
89.1638,5.1071,-0.098435,34.231,267.31,-0.010675,15.496,267.32,248.68,258.92
90.7638,5.1064,-0.10119,33.738,272.11,-0.011016,15.494,272.27,253.39,263.74
92.3638,5.1383,-0.10355,33.983,276.91,-0.011265,15.589,277.04,258.19,268.51
93.9638,5.142,-0.10706,33.689,281.71,-0.011648,15.605,281.95,262.94,273.45
95.56381,5.1562,-0.10838,33.447,286.51,-0.011821,15.646,286.76,267.74,278.1
97.16381,5.1601,-0.112,33.422,291.31,-0.012131,15.655,291.58,272.38,282.85
98.76381,5.179,-0.11385,34.509,296.11,-0.012368,15.71,296.15,277.03,287.43
100.36381,5.0864,-0.11657,31.13,300.0,-0.012644,15.428,300.9,281.56,292.02
101.96381,5.3318,-0.11552,33.217,300.0,-0.012567,16.173,300.1,282.44,291.55
103.4057,5.7152,-0.1151,31.761,300.0,-0.012472,17.339,300.39,283.19,292.0
105.0057,6.4643,-0.11134,32.401,300.0,-0.012098,19.612,300.14,283.64,291.98
106.6057,6.6579,-0.11186,31.5,300.0,-0.012117,20.198,300.22,284.13,292.19
108.2057,6.6463,-0.11004,30.317,300.0,-0.011972,20.164,300.47,284.72,292.57
109.8057,6.7448,-0.11274,31.605,300.0,-0.012227,20.466,300.1,284.92,292.33
111.4057,7.0422,-0.10907,31.561,300.0,-0.011879,21.365,300.08,285.1,292.47
113.0057,7.2199,-0.1116,32.811,300.0,-0.012119,21.906,300.03,285.46,292.6
114.6057,7.296,-0.10833,31.605,300.0,-0.0118,22.133,302.0,287.15,294.41
116.2057,7.353,-0.11109,30.96,300.0,-0.012066,22.307,302.75,288.09,295.25
117.8057,7.3888,-0.10866,32.875,300.0,-0.011837,22.413,304.2,289.58,296.75
119.4057,7.3918,-0.11202,31.885,300.0,-0.012175,22.42,305.86,291.32,298.47
121.0057,7.391,-0.10887,30.97,300.0,-0.011855,22.416,307.84,293.15,300.42
122.60571,7.3989,-0.11351,32.613,300.0,-0.01234,22.439,308.94,294.64,301.58
124.20571,7.3865,-0.10899,29.981,300.0,-0.011877,22.401,310.58,296.14,303.16
125.80571,7.406,-0.11374,32.034,300.0,-0.012359,22.46,310.49,296.73,303.31
127.40571,7.3897,-0.10928,31.963,300.0,-0.011897,22.411,311.54,297.87,304.51
129.00571,7.3962,-0.1117,31.064,300.0,-0.012102,22.433,311.71,298.37,304.79
130.60571,7.3826,-0.1079,29.699,300.0,-0.011734,22.396,311.34,298.38,304.58
132.20571,7.3852,-0.10882,29.238,300.0,-0.011784,22.402,310.57,297.88,303.86
133.80571,7.3991,-0.10661,30.932,300.0,-0.011591,22.447,308.82,296.85,302.45
135.40571,7.3862,-0.10597,29.793,300.0,-0.011483,22.41,306.39,294.95,300.22
136.8353,7.4058,-0.10514,31.2,300.0,-0.011421,22.46,305.61,294.08,299.39
138.4353,7.4142,-0.10512,31.031,300.0,-0.01143,22.484,304.49,293.17,298.33
140.0353,7.423,-0.10532,32.953,300.0,-0.011414,22.515,306.02,294.16,299.71
141.6353,7.4024,-0.10575,30.849,300.0,-0.011497,22.452,306.63,294.87,300.37
143.2353,7.4167,-0.10481,30.484,300.0,-0.011359,22.499,306.66,294.99,300.41
144.8353,7.4131,-0.10612,29.722,300.0,-0.011558,22.485,306.81,295.16,300.62
145.2866,7.3843,-0.0029739,0.0,6.6714e-06,-0.0011149,22.382,306.42,295.03,300.31
145.2874,7.5358,0.00099599,0.0,9.6426e-17,0.0010094,22.784,306.42,295.02,300.31
145.2882,7.3987,0.006289,0.0,1.3208e-27,0.0013196,22.421,306.42,295.01,300.32
145.289,7.3959,0.0084081,0.0,1.7899e-38,-0.00036282,22.431,306.42,295.0,300.32
145.2898,7.4817,0.0024424,0.0,0.0,0.00075631,22.721,306.42,294.99,300.33
145.2906,7.3376,-0.0039942,0.0,0.0,0.00079295,22.274,306.42,294.98,300.33
145.29139,7.4959,0.011989,0.0,0.0,0.00024176,22.704,306.42,294.97,300.34
145.29219,7.3751,0.0038164,0.0,0.0,8.7917e-05,22.412,306.42,294.96,300.34
145.29299,7.4082,-0.0073374,0.0,0.0,0.00020932,22.436,306.42,294.95,300.35
145.29379,7.4677,0.0098064,0.0,0.0,0.0010027,22.662,306.42,294.95,300.35
145.29459,7.3422,0.0064651,0.0,0.0,5.2584e-05,22.276,306.42,294.95,300.35
145.29539,7.5057,-0.0039652,0.0,0.0,-0.00027842,22.776,306.42,294.96,300.35
145.29619,7.3629,0.0045778,0.0,0.0,0.0011938,22.353,306.42,294.96,300.34
145.29699,7.4341,0.0073637,0.0,0.0,0.00042225,22.534,306.42,294.97,300.34
145.29779,7.4538,0.001023,0.0,0.0,-0.00046742,22.625,306.42,294.97,300.34
145.29859,7.3533,0.0018629,0.0,0.0,0.0012553,22.282,306.42,294.98,300.34
145.29939,7.5157,0.0026731,0.0,0.0,0.00071541,22.779,306.42,294.98,300.33
145.30019,7.3436,0.0047673,0.0,0.0,-0.00044117,22.324,306.42,294.99,300.33
145.30098,7.4404,0.0011752,0.0,0.0,0.00065775,22.576,306.42,294.99,300.33
145.30178,7.4253,-0.00050976,0.0,0.0,0.00078507,22.571,306.42,295.0,300.33
145.30258,7.3494,0.0094968,0.0,0.0,0.00012646,22.301,306.42,295.0,300.32
145.30338,7.4899,0.0034357,0.0,0.0,0.00012819,22.754,306.42,295.01,300.32
145.30418,7.3246,-0.00433,0.0,0.0,0.00031191,22.269,306.42,295.01,300.32
145.30498,7.465,0.011166,0.0,0.0,0.0010336,22.61,306.43,295.01,300.33
145.30578,7.3949,0.005824,0.0,0.0,6.28e-06,22.502,306.43,295.01,300.33
145.30658,7.3682,-0.0043261,0.0,0.0,-0.00017013,22.312,306.43,295.01,300.33
145.30738,7.4878,0.0069313,0.0,0.0,0.0012028,22.715,306.43,295.01,300.33
145.30818,7.3323,0.0076635,0.0,0.0,0.00047275,22.244,306.44,295.01,300.34
145.30898,7.4777,0.0023624,0.0,0.0,-0.00023195,22.656,306.44,295.01,300.34
145.30978,7.3885,0.00057599,0.0,0.0,0.00096158,22.45,306.44,295.01,300.34
145.31057,7.387,0.0038557,0.0,0.0,0.00064146,22.37,306.44,295.01,300.34
145.31137,7.4681,0.0063466,0.0,0.0,1.7961e-05,22.656,306.45,295.01,300.35
145.31217,7.3115,-0.00018914,0.0,0.0,0.00040577,22.229,306.45,295.01,300.35
145.31297,7.4837,-5.0219e-05,0.0,0.0,0.00057825,22.702,306.45,295.01,300.35
145.31377,7.3667,0.010338,0.0,0.0,0.00042338,22.357,306.45,295.01,300.35
145.31457,7.3932,0.0017756,0.0,0.0,0.00014872,22.428,306.46,295.0,300.36
145.31537,7.4679,-0.0015868,0.0,0.0,0.00035769,22.643,306.46,295.0,300.37
145.31617,7.3256,0.010953,0.0,0.0,0.00094159,22.22,306.47,294.99,300.38
145.31697,7.496,0.0039842,0.0,0.0,-0.00011161,22.705,306.47,294.99,300.38
145.31777,7.3504,-0.0019185,0.0,0.0,7.6513e-05,22.326,306.48,294.98,300.39
145.31857,7.4081,0.0071891,0.0,0.0,0.0012211,22.463,306.48,294.98,300.4
145.31937,7.4399,0.0054349,0.0,0.0,0.00017513,22.573,306.49,294.97,300.41
145.32016,7.3185,0.00099809,0.0,0.0,-0.00026091,22.207,306.49,294.97,300.41
145.32096,7.4901,0.0023154,0.0,0.0,0.00096913,22.689,306.5,294.96,300.42
145.32176,7.3366,0.0040721,0.0,0.0,0.00034318,22.278,306.5,294.96,300.43
145.32256,7.4264,0.0070104,0.0,0.0,9.641e-05,22.5,306.51,294.95,300.44
145.32336,7.4271,0.00050711,0.0,0.0,0.00063782,22.535,306.51,294.95,300.44
145.32416,7.3327,0.0013912,0.0,0.0,0.00047023,22.254,306.51,294.95,300.44
145.32496,7.4681,0.0077995,0.0,0.0,0.0001017,22.688,306.51,294.96,300.43
145.32576,7.3287,0.00096095,0.0,0.0,0.00023863,22.198,306.51,294.96,300.42
145.32656,7.4428,-0.00017606,0.0,0.0,0.00033297,22.58,306.51,294.97,300.41
145.32736,7.4002,0.0089967,0.0,0.0,0.00054912,22.447,306.51,294.97,300.41
145.32816,7.347,0.0023381,0.0,0.0,-0.00012895,22.264,306.51,294.98,300.4
145.32896,7.4783,0.00042007,0.0,0.0,0.00038902,22.666,306.51,294.98,300.39
145.32976,7.3133,0.0057509,0.0,0.0,0.00098099,22.187,306.51,294.99,300.39
145.33055,7.449,0.0038479,0.0,0.0,1.7994e-05,22.606,306.51,294.99,300.38
145.33135,7.3716,0.00095191,0.0,0.0,0.00011101,22.37,306.51,295.0,300.37
145.33215,7.3535,0.0026562,0.0,0.0,0.0010258,22.293,306.51,295.0,300.36
145.33295,7.4565,0.00252,0.0,0.0,6.7035e-05,22.63,306.51,295.01,300.36
145.33375,7.3089,0.005209,0.0,0.0,1.2848e-05,22.139,306.81,295.32,300.33
145.33455,7.4579,0.00091929,0.0,0.0,0.00081633,22.61,307.41,295.96,300.29
145.33535,7.3538,0.0031801,0.0,0.0,0.00035223,22.367,308.01,296.6,300.25
145.33615,7.3722,0.0070892,0.0,0.0,0.00018551,22.355,308.61,297.24,300.21
145.33695,7.4411,-0.00076835,0.0,0.0,0.00021482,22.603,309.21,297.88,300.17
145.33775,7.3102,0.003708,0.0,0.0,0.00058468,22.182,309.81,298.52,300.14
145.33855,7.4679,0.009811,0.0,0.0,0.00065284,22.642,310.41,299.16,300.1
145.33935,7.358,-0.00054235,0.0,0.0,-0.00016372,22.327,311.01,299.8,300.06
145.34014,7.3943,0.002446,0.0,0.0,0.00065617,22.424,311.61,300.44,300.02
145.34094,7.4461,0.0080788,0.0,0.0,0.00087742,22.611,312.21,301.08,299.98
145.34174,7.3352,0.002067,0.0,0.0,-0.00017066,22.272,312.82,301.72,299.94
145.34254,7.601,0.0016337,0.0,0.0,0.0004164,22.977,313.42,302.36,299.9
145.34334,7.8575,0.0047376,0.0,0.0,0.0011386,23.922,314.04,303.03,299.86
145.34414,7.0258,0.0034395,0.0,0.0,-0.00013581,21.294,315.58,305.22,299.86
145.34494,7.9713,0.0075806,0.0,0.0,0.00059858,24.134,317.12,307.41,299.87
145.34574,7.208,0.00034808,0.0,0.0,0.00089583,21.952,318.66,309.59,299.87
145.34654,7.4331,0.0073497,0.0,0.0,0.00041108,22.48,320.2,311.78,299.87
145.34734,7.5088,0.0093117,0.0,0.0,0.00049767,22.84,321.73,313.97,299.87
145.34814,7.2838,-0.0040398,0.0,0.0,0.00010395,22.113,323.27,316.15,299.88
145.34894,7.3973,0.005935,0.0,0.0,0.00079551,22.423,324.81,318.34,299.88
145.34973,7.4007,0.0098822,0.0,0.0,0.00042827,22.45,326.35,320.53,299.88
145.35053,7.3685,-0.0037026,0.0,0.0,-0.00030609,22.348,327.89,322.71,299.88
145.35133,7.4448,0.0034998,0.0,0.0,0.00064737,22.509,329.43,324.9,299.89
145.35213,7.389,0.0058648,0.0,0.0,0.00056809,22.426,330.97,327.09,299.89
145.35293,7.3369,0.00023294,0.0,0.0,-0.00039574,22.254,332.51,329.28,299.89
145.35373,7.6125,0.0015866,0.0,0.0,0.00063912,23.005,333.74,331.05,299.94
145.35453,7.247,7.1271e-05,0.0,0.0,0.00055972,22.048,334.74,332.51,300.01
145.35533,7.4231,0.0025269,0.0,0.0,-0.00046206,22.464,335.73,333.97,300.09
145.35613,7.6584,0.0036889,0.0,0.0,0.00043117,23.272,336.73,335.42,300.17
145.35693,6.9781,-0.0051599,0.0,0.0,0.00032042,21.165,337.73,336.88,300.25
145.35773,7.8398,0.0088472,0.0,0.0,0.0003064,23.775,338.72,338.34,300.33
145.35853,9.9468,0.010233,0.0,0.0,0.00037674,27.896,339.72,339.79,300.41
145.35932,38.278,0.19406,0.0,0.0,0.0215,115.51,340.71,341.25,300.49
145.36012,45.244,0.86521,0.0,0.0,0.095374,138.41,341.71,342.71,300.57
145.36092,48.15,1.5243,0.0,0.0,0.17734,145.9,342.71,344.17,300.65
145.36172,48.308,2.0758,0.0,0.0,0.25246,147.07,343.7,345.62,300.72
145.36252,48.725,2.4609,0.0,0.0,0.30731,147.59,344.7,347.08,300.8
145.36332,50.023,3.013,0.0,0.0,0.38818,152.11,345.59,348.35,300.87
145.36412,49.386,3.5835,0.0,0.0,0.47968,149.7,345.47,347.96,300.88
145.36492,51.024,4.0093,0.0,0.0,0.55899,154.89,345.36,347.57,300.88
145.36572,51.071,4.4391,0.0,0.0,0.63901,154.79,345.25,347.18,300.89
145.36652,51.98,4.812,0.0,0.0,0.71078,157.64,345.14,346.79,300.89
145.36732,51.27,5.2394,0.0,0.0,0.80723,155.49,345.02,346.4,300.9
145.36812,51.716,5.5833,0.0,0.0,0.89164,156.99,344.91,346.01,300.9
145.36891,51.317,5.8744,0.0,0.0,0.96028,155.71,344.8,345.62,300.91
145.36971,51.604,6.1607,0.0,0.0,1.0391,156.47,344.69,345.23,300.91
145.37051,51.147,6.3928,0.0,0.0,1.1114,155.22,344.58,344.84,300.92
145.37131,51.268,6.6441,0.0,0.0,1.1868,155.45,344.46,344.45,300.92
145.37211,51.001,6.8427,0.0,0.0,1.2489,154.77,344.35,344.06,300.93
145.37291,51.1,7.0119,0.0,0.0,1.3137,154.99,344.24,343.67,300.93
145.37371,51.171,7.1958,0.0,0.0,1.3846,155.24,344.0,343.19,300.92
145.37451,50.846,7.4002,0.0,0.0,1.4599,154.89,343.7,342.65,300.89
145.37531,43.48,7.2929,0.0,0.0,1.4195,131.63,343.39,342.11,300.86
145.37611,42.416,7.4035,0.0,0.0,1.4704,129.25,343.08,341.57,300.84
145.37691,43.375,7.3348,0.0,0.0,1.4402,131.94,342.77,341.03,300.81
145.37771,42.816,7.3713,0.0,0.0,1.4467,130.2,342.47,340.49,300.78
145.3785,42.716,7.3775,0.0,0.0,1.4571,129.44,342.16,339.95,300.76
145.3793,41.297,7.3452,0.0,0.0,1.4489,125.17,341.85,339.41,300.73
145.3801,41.352,7.4114,0.0,0.0,1.4639,125.55,341.55,338.88,300.7
145.3809,41.18,7.3814,0.0,0.0,1.4541,124.89,341.24,338.34,300.67
145.3817,40.83,7.3715,0.0,0.0,1.4594,123.99,340.93,337.8,300.65
145.3825,40.726,7.4116,0.0,0.0,1.4692,123.53,340.62,337.26,300.62
145.3833,40.316,7.3924,0.0,0.0,1.4554,122.36,340.33,336.76,300.6
145.3841,39.818,7.3834,0.0,0.0,1.4606,120.76,340.08,336.42,300.59
145.3849,39.602,7.4019,0.0,0.0,1.4699,120.21,339.84,336.09,300.59
145.3857,39.227,7.405,0.0,0.0,1.4626,118.97,339.6,335.76,300.58
145.3865,38.839,7.4028,0.0,0.0,1.4627,117.86,339.35,335.43,300.58
145.3873,38.533,7.404,0.0,0.0,1.4713,116.96,339.11,335.1,300.57
145.3881,38.144,7.4012,0.0,0.0,1.4675,115.75,338.87,334.76,300.57
145.38889,37.847,7.41,0.0,0.0,1.463,114.86,338.62,334.43,300.56
145.38969,37.523,7.3926,0.0,0.0,1.4645,113.84,338.38,334.1,300.56
145.39049,37.189,7.3904,0.0,0.0,1.467,112.83,338.13,333.77,300.55
145.39129,36.923,7.4163,0.0,0.0,1.466,112.03,337.89,333.44,300.55
145.39209,36.665,7.4086,0.0,0.0,1.4664,111.26,337.65,333.1,300.54
145.39289,36.439,7.3917,0.0,0.0,1.4665,110.55,337.4,332.77,300.54
145.39369,36.264,7.4167,0.0,0.0,1.4702,110.01,337.23,332.55,300.53
145.39449,36.006,7.4078,0.0,0.0,1.4639,109.25,337.09,332.37,300.52
145.39529,35.625,7.3922,0.0,0.0,1.4637,108.09,336.95,332.19,300.52
145.39609,35.13,7.4094,0.0,0.0,1.4721,106.62,336.81,332.01,300.51
145.39689,34.25,7.4131,0.0,0.0,1.4666,103.93,336.67,331.83,300.5
145.39769,33.184,7.4031,0.0,0.0,1.4633,100.72,336.52,331.66,300.49
145.39848,31.834,7.4026,0.0,0.0,1.471,96.695,336.38,331.48,300.49
145.39928,30.226,7.3967,0.0,0.0,1.4645,91.867,336.24,331.3,300.48
145.40008,28.271,7.3928,0.0,0.0,1.457,85.97,336.1,331.12,300.47
145.40088,25.621,7.3837,0.0,0.0,1.4607,77.985,335.96,330.94,300.46
145.40168,20.988,7.3819,0.0,0.0,1.461,64.442,335.82,330.76,300.46
145.40248,6.2997,7.3782,0.0,0.0,1.452,20.904,335.68,330.58,300.45
145.40328,0.27773,7.2956,0.0,0.0,1.4212,0.84072,335.55,330.4,300.45
145.40408,7.6833,7.3225,0.0,0.0,1.436,22.227,335.45,330.19,300.47
145.40488,10.8,7.3985,0.0,0.0,1.4622,33.01,335.36,329.98,300.48
145.40568,4.9276,7.3577,0.0,0.0,1.4445,15.493,335.26,329.78,300.5
145.40648,4.0837,7.3396,0.0,0.0,1.4417,12.151,335.16,329.57,300.52
145.40728,9.3059,7.3827,0.0,0.0,1.4597,27.823,335.07,329.36,300.53
145.40807,7.5629,7.3796,0.0,0.0,1.4536,23.4,334.97,329.15,300.55
145.40887,4.2574,7.3432,0.0,0.0,1.4396,12.93,334.88,328.94,300.57
145.40967,7.2261,7.3544,0.0,0.0,1.45,21.548,334.78,328.74,300.59
145.41047,8.2912,7.3609,0.0,0.0,1.4488,25.349,334.69,328.53,300.6
145.41127,5.5642,7.3282,0.0,0.0,1.4316,17.089,334.59,328.32,300.62
145.41207,6.023,7.3282,0.0,0.0,1.4384,18.06,334.5,328.11,300.64
145.41287,7.8071,7.3436,0.0,0.0,1.4441,23.592,334.4,327.9,300.66
145.41367,6.6165,7.3495,0.0,0.0,1.4397,20.315,334.29,327.71,300.68
145.41447,5.8088,7.3385,0.0,0.0,1.4399,17.561,334.18,327.53,300.71
145.41527,7.2595,7.3406,0.0,0.0,1.4439,21.9,334.07,327.34,300.73
145.41607,6.9261,7.3585,0.0,0.0,1.446,21.174,333.96,327.16,300.76
145.41687,6.0679,7.3421,0.0,0.0,1.4388,18.427,333.84,326.97,300.79
145.41766,6.9286,7.3423,0.0,0.0,1.4435,20.934,333.73,326.78,300.82
145.41846,6.7998,7.3572,0.0,0.0,1.4486,20.695,333.62,326.6,300.84
145.41926,6.5616,7.3502,0.0,0.0,1.4419,19.882,333.51,326.41,300.87
145.42006,6.5983,7.3463,0.0,0.0,1.4425,19.999,333.39,326.23,300.9
145.42086,6.6987,7.3439,0.0,0.0,1.4456,20.302,333.28,326.04,300.92
145.42166,6.6478,7.3484,0.0,0.0,1.4425,20.212,333.17,325.86,300.95
145.42246,6.4956,7.3445,0.0,0.0,1.4395,19.673,333.06,325.67,300.98
145.42326,6.8578,7.3416,0.0,0.0,1.4441,20.814,332.96,325.5,301.01
145.42406,6.4261,7.3458,0.0,0.0,1.4435,19.502,332.88,325.34,301.04
145.42486,6.6864,7.3528,0.0,0.0,1.4421,20.219,332.8,325.19,301.08
145.42566,6.6117,7.3428,0.0,0.0,1.4426,20.087,332.72,325.04,301.11
145.42646,6.5817,7.3406,0.0,0.0,1.4428,19.937,332.64,324.89,301.15
145.42725,6.7009,7.3508,0.0,0.0,1.4416,20.367,332.56,324.74,301.18
145.42805,6.518,7.339,0.0,0.0,1.438,19.781,332.49,324.59,301.21
145.42885,6.7069,7.3378,0.0,0.0,1.4417,20.348,332.41,324.43,301.25
145.42965,6.5396,7.3493,0.0,0.0,1.4445,19.879,332.33,324.28,301.28
145.43045,6.5878,7.3444,0.0,0.0,1.4393,19.968,332.25,324.13,301.32
145.43125,6.6507,7.3411,0.0,0.0,1.4415,20.191,332.17,323.98,301.35
145.43205,6.4895,7.3418,0.0,0.0,1.4445,19.673,332.09,323.83,301.39
145.43285,6.6662,7.3452,0.0,0.0,1.4403,20.226,332.02,323.68,301.42
145.43365,6.5223,7.3444,0.0,0.0,1.4406,19.789,331.94,323.52,301.46
145.43445,6.6137,7.3408,0.0,0.0,1.4444,20.071,331.85,323.36,301.49
145.43525,6.6005,7.3467,0.0,0.0,1.4425,20.046,331.77,323.21,301.53
145.43605,6.5405,7.3515,0.0,0.0,1.4419,19.839,331.69,323.05,301.56
145.43685,6.5871,7.3378,0.0,0.0,1.4417,20.0,331.61,322.89,301.59
145.43764,6.5504,7.3427,0.0,0.0,1.4428,19.874,331.53,322.74,301.63
145.43844,6.611,7.3529,0.0,0.0,1.4421,20.044,331.45,322.58,301.66
145.43924,6.5744,7.339,0.0,0.0,1.4392,19.939,331.37,322.42,301.7
145.44004,6.5882,7.339,0.0,0.0,1.4429,20.001,331.29,322.27,301.73
145.44084,6.598,7.3499,0.0,0.0,1.4435,20.022,331.21,322.11,301.77
145.44164,6.5483,7.3441,0.0,0.0,1.4393,19.859,331.13,321.95,301.8
145.44244,6.6255,7.3386,0.0,0.0,1.4415,20.097,331.05,321.8,301.84
145.44324,6.5575,7.345,0.0,0.0,1.445,19.889,330.97,321.66,301.88
145.44404,6.5745,7.3467,0.0,0.0,1.4394,19.917,330.88,321.53,301.93
145.44484,6.5648,7.3421,0.0,0.0,1.4406,19.925,330.8,321.41,301.99
145.44564,6.5314,7.3374,0.0,0.0,1.4439,19.827,330.72,321.29,302.04
145.44644,6.6098,7.3488,0.0,0.0,1.4422,20.047,330.63,321.17,302.09
145.44723,6.5338,7.3476,0.0,0.0,1.4404,19.827,330.55,321.04,302.15
145.44803,6.5719,7.3354,0.0,0.0,1.442,19.941,330.47,320.92,302.2
145.44883,6.5578,7.3447,0.0,0.0,1.4428,19.87,330.38,320.8,302.26
145.44963,6.5631,7.3523,0.0,0.0,1.441,19.865,330.3,320.68,302.31
145.45043,6.5837,7.3368,0.0,0.0,1.4395,19.959,330.22,320.56,302.37
145.45123,6.5798,7.3409,0.0,0.0,1.4438,19.97,330.13,320.43,302.42
145.45203,6.5583,7.3519,0.0,0.0,1.4435,19.873,330.05,320.31,302.47
145.45283,6.6388,7.3422,0.0,0.0,1.4389,20.126,329.97,320.19,302.53
145.45363,6.4926,7.3401,0.0,0.0,1.4434,19.707,329.87,320.07,302.56
145.45443,6.6905,7.348,0.0,0.0,1.4454,20.274,329.76,319.94,302.59
145.45523,6.5483,7.3482,0.0,0.0,1.4384,19.901,329.66,319.82,302.63
145.45603,6.6105,7.3429,0.0,0.0,1.4418,20.029,329.56,319.7,302.66
145.45682,6.6537,7.3391,0.0,0.0,1.4452,20.182,329.46,319.58,302.69
145.45762,6.5476,7.3519,0.0,0.0,1.4421,19.872,329.35,319.45,302.72
145.45842,6.6565,7.3498,0.0,0.0,1.4417,20.164,329.25,319.33,302.75
145.45922,6.5823,7.3346,0.0,0.0,1.4421,19.986,329.15,319.21,302.79
145.46002,6.603,7.3522,0.0,0.0,1.4447,19.982,329.05,319.09,302.82
145.46082,6.6391,7.3559,0.0,0.0,1.4421,20.159,328.94,318.96,302.85
145.46162,6.5684,7.3347,0.0,0.0,1.4398,19.962,328.84,318.84,302.88
145.46242,6.7006,7.3471,0.0,0.0,1.4471,20.344,328.74,318.72,302.91
145.46322,6.5791,7.357,0.0,0.0,1.4442,19.973,328.62,318.59,302.94
145.46402,6.6774,7.3435,0.0,0.0,1.4389,20.256,328.5,318.46,302.96
145.46482,6.618,7.3437,0.0,0.0,1.4454,20.078,328.37,318.33,302.97
145.46562,6.6321,7.3487,0.0,0.0,1.4455,20.169,328.24,318.19,302.99
145.46641,6.6663,7.3505,0.0,0.0,1.4391,20.217,328.11,318.06,303.01
145.46721,6.6649,7.3449,0.0,0.0,1.4436,20.215,327.99,317.93,303.03
145.46801,6.6082,7.343,0.0,0.0,1.4469,20.041,327.86,317.8,303.04
145.46881,6.719,7.3578,0.0,0.0,1.4428,20.418,327.73,317.66,303.06
145.46961,6.6139,7.3491,0.0,0.0,1.4424,20.054,327.61,317.53,303.08
145.47041,6.7206,7.3367,0.0,0.0,1.4446,20.438,327.48,317.4,303.09
145.47121,6.5991,7.3563,0.0,0.0,1.4461,20.0,327.35,317.27,303.11
145.47201,6.7274,7.3561,0.0,0.0,1.4415,20.404,327.22,317.13,303.13
145.47281,6.6448,7.3348,0.0,0.0,1.4407,20.155,327.1,317.0,303.15
145.47361,6.6652,7.3511,0.0,0.0,1.4487,20.201,326.98,316.88,303.19
145.47441,6.7274,7.3586,0.0,0.0,1.4444,20.417,326.86,316.77,303.24
145.47521,6.6263,7.3464,0.0,0.0,1.4401,20.146,326.75,316.65,303.28
145.476,6.7089,7.3458,0.0,0.0,1.4479,20.355,326.63,316.53,303.32
145.4768,6.7427,7.3523,0.0,0.0,1.4468,20.5,326.51,316.41,303.37
145.4776,6.6173,7.3524,0.0,0.0,1.4387,20.031,326.39,316.29,303.41
145.4784,6.8759,7.3472,0.0,0.0,1.446,20.843,326.28,316.18,303.46
145.4792,6.6259,7.3456,0.0,0.0,1.4493,20.101,326.16,316.06,303.5
145.48,6.8735,7.3625,0.0,0.0,1.4433,20.807,326.04,315.94,303.55
145.4808,6.6806,7.3495,0.0,0.0,1.4415,20.256,325.92,315.82,303.59
145.4816,6.766,7.3347,0.0,0.0,1.445,20.513,325.81,315.71,303.63
145.4824,6.8119,7.3615,0.0,0.0,1.4466,20.7,325.69,315.59,303.68
145.4832,6.7608,7.3579,0.0,0.0,1.4423,20.503,325.59,315.47,303.71
145.484,6.8743,7.3333,0.0,0.0,1.441,20.82,325.5,315.36,303.74
145.4848,6.7711,7.3531,0.0,0.0,1.4491,20.55,325.42,315.24,303.77
145.48559,6.8664,7.3588,0.0,0.0,1.444,20.826,325.33,315.13,303.79
145.48639,6.8674,7.3446,0.0,0.0,1.4389,20.871,325.25,315.01,303.82
145.48719,6.7267,7.3442,0.0,0.0,1.4473,20.403,325.16,314.89,303.85
145.48799,7.0383,7.354,0.0,0.0,1.447,21.351,325.08,314.78,303.88
145.48879,6.7307,7.3523,0.0,0.0,1.4396,20.441,324.99,314.66,303.9
145.48959,6.8878,7.343,0.0,0.0,1.445,20.836,324.9,314.55,303.93
145.49039,6.9146,7.3481,0.0,0.0,1.4485,20.989,324.82,314.43,303.96
145.49119,6.764,7.3577,0.0,0.0,1.4421,20.48,324.73,314.32,303.98
145.49199,7.0193,7.3471,0.0,0.0,1.4425,21.284,324.65,314.2,304.01
145.49279,6.7925,7.3382,0.0,0.0,1.4456,20.627,324.56,314.09,304.04
145.49359,6.8917,7.3582,0.0,0.0,1.4457,20.893,324.49,313.97,304.07
145.49439,6.9137,7.3551,0.0,0.0,1.4423,21.024,324.42,313.85,304.1
145.49519,6.8203,7.3396,0.0,0.0,1.4423,20.673,324.34,313.73,304.13
145.49598,7.0139,7.3555,0.0,0.0,1.4488,21.298,324.27,313.61,304.17
145.49678,6.752,7.3547,0.0,0.0,1.4427,20.489,324.2,313.49,304.2
145.49758,6.9628,7.344,0.0,0.0,1.4398,21.084,324.12,313.37,304.23
145.49838,6.9003,7.3463,0.0,0.0,1.4474,20.97,324.05,313.25,304.26
145.49918,6.8203,7.3531,0.0,0.0,1.4455,20.68,323.98,313.13,304.29
145.49998,6.9477,7.3509,0.0,0.0,1.4403,21.096,323.9,313.0,304.33
145.50078,6.7902,7.3426,0.0,0.0,1.4447,20.599,323.83,312.88,304.36
145.50158,6.9318,7.3482,0.0,0.0,1.4468,20.972,323.76,312.76,304.39
145.50238,6.9076,7.3563,0.0,0.0,1.4422,20.958,323.68,312.64,304.42
145.50318,6.7877,7.3426,0.0,0.0,1.4415,20.59,323.6,312.53,304.46
145.50398,6.9591,7.3437,0.0,0.0,1.4459,21.139,323.5,312.42,304.49
145.50478,6.734,7.3566,0.0,0.0,1.4447,20.445,323.41,312.31,304.53
145.50557,6.9416,7.3486,0.0,0.0,1.4405,21.023,323.32,312.2,304.57
145.50637,6.8313,7.3409,0.0,0.0,1.443,20.743,323.23,312.09,304.6
145.50717,6.7223,7.3526,0.0,0.0,1.4469,20.364,323.13,311.98,304.64
145.50797,7.0116,7.3521,0.0,0.0,1.4421,21.26,323.04,311.87,304.68
145.50877,6.7005,7.3439,0.0,0.0,1.4407,20.318,322.95,311.76,304.71
145.50957,6.9359,7.3479,0.0,0.0,1.4475,20.999,322.85,311.65,304.75
145.51037,6.8326,7.3521,0.0,0.0,1.4445,20.755,322.76,311.54,304.79
145.51117,6.7892,7.3482,0.0,0.0,1.4407,20.564,322.67,311.43,304.82
145.51197,6.9698,7.3451,0.0,0.0,1.4458,21.151,322.57,311.32,304.86
145.51277,6.6886,7.3487,0.0,0.0,1.4453,20.285,322.48,311.21,304.9
145.51357,6.9583,7.3555,0.0,0.0,1.4423,21.085,322.39,311.11,304.92
145.51437,6.8191,7.3442,0.0,0.0,1.4427,20.706,322.29,311.01,304.94
145.51516,6.8053,7.3433,0.0,0.0,1.4448,20.647,322.2,310.91,304.96
145.51596,6.9484,7.357,0.0,0.0,1.4447,21.093,322.1,310.81,304.98
145.51676,6.7331,7.3483,0.0,0.0,1.4416,20.427,322.0,310.72,305.01
145.51756,6.942,7.341,0.0,0.0,1.4437,21.042,321.91,310.62,305.03
145.51836,6.7607,7.3518,0.0,0.0,1.4458,20.499,321.81,310.52,305.05
145.51916,6.8516,7.3515,0.0,0.0,1.442,20.732,321.72,310.42,305.07
145.51996,6.9247,7.3457,0.0,0.0,1.4427,21.023,321.62,310.32,305.09
145.52076,6.7016,7.3468,0.0,0.0,1.4466,20.343,321.53,310.23,305.12
145.52156,6.9638,7.3518,0.0,0.0,1.4436,21.112,321.43,310.13,305.14
145.52236,6.7344,7.3496,0.0,0.0,1.4417,20.453,321.34,310.03,305.16
145.52316,6.9006,7.3434,0.0,0.0,1.4452,20.912,321.24,309.93,305.18
145.52396,6.8873,7.3488,0.0,0.0,1.4445,20.939,321.15,309.82,305.2
145.52475,6.7569,7.3555,0.0,0.0,1.4428,20.463,321.05,309.71,305.22
145.52555,6.9713,7.3452,0.0,0.0,1.4445,21.164,320.96,309.61,305.24
145.52635,6.7154,7.3439,0.0,0.0,1.4438,20.413,320.86,309.5,305.26
145.52715,6.9261,7.3569,0.0,0.0,1.444,20.991,320.76,309.4,305.28
145.52795,6.8589,7.3478,0.0,0.0,1.4425,20.862,320.67,309.29,305.3
145.52875,6.7796,7.3441,0.0,0.0,1.4445,20.54,320.57,309.19,305.32
145.52955,6.9822,7.3556,0.0,0.0,1.4464,21.191,320.48,309.08,305.34
145.53035,6.7292,7.3485,0.0,0.0,1.4409,20.436,320.38,308.98,305.36
145.53115,6.9577,7.3449,0.0,0.0,1.4427,21.05,320.29,308.87,305.38
145.53195,6.8354,7.3519,0.0,0.0,1.4474,20.763,320.19,308.77,305.4
145.53275,6.814,7.35,0.0,0.0,1.4419,20.625,320.1,308.66,305.42
145.53355,6.9741,7.3497,0.0,0.0,1.4433,21.209,320.02,308.58,305.45
145.53434,6.7499,7.3448,0.0,0.0,1.4463,20.463,319.94,308.49,305.48
145.53514,6.9884,7.3501,0.0,0.0,1.4436,21.164,319.86,308.4,305.51
145.53594,6.8334,7.353,0.0,0.0,1.4426,20.761,319.78,308.31,305.54
145.53674,6.851,7.3423,0.0,0.0,1.4441,20.774,319.7,308.22,305.57
145.53754,6.9895,7.3486,0.0,0.0,1.4448,21.238,319.62,308.13,305.6
145.53834,6.7789,7.3558,0.0,0.0,1.443,20.531,319.53,308.05,305.63
145.53914,7.017,7.3457,0.0,0.0,1.4424,21.289,319.45,307.96,305.65
145.53994,6.8136,7.3478,0.0,0.0,1.4464,20.692,319.37,307.87,305.68
145.54074,6.9045,7.3531,0.0,0.0,1.4442,20.905,319.29,307.78,305.71
145.54154,6.9739,7.3471,0.0,0.0,1.4411,21.167,319.21,307.69,305.74
145.54234,6.7794,7.3468,0.0,0.0,1.445,20.569,319.13,307.6,305.77
145.54314,7.0401,7.3521,0.0,0.0,1.4473,21.401,319.06,307.52,305.81
145.54394,6.7999,7.352,0.0,0.0,1.4416,20.67,319.0,307.44,305.84
145.54473,6.9214,7.3458,0.0,0.0,1.4432,20.971,318.94,307.36,305.87
145.54553,6.9693,7.3464,0.0,0.0,1.4474,21.179,318.87,307.28,305.91
145.54633,6.8024,7.354,0.0,0.0,1.4437,20.607,318.81,307.2,305.94
145.54713,7.0415,7.351,0.0,0.0,1.4425,21.361,318.74,307.12,305.98
145.54793,6.8084,7.3385,0.0,0.0,1.4441,20.668,318.68,307.04,306.01
145.54873,6.9907,7.3552,0.0,0.0,1.4458,21.182,318.62,306.95,306.05
145.54953,6.9431,7.3571,0.0,0.0,1.4431,21.083,318.55,306.87,306.08
145.55033,6.8393,7.3412,0.0,0.0,1.4423,20.719,318.49,306.79,306.11
145.55113,7.0745,7.3516,0.0,0.0,1.4478,21.47,318.43,306.71,306.15
145.55193,6.8025,7.356,0.0,0.0,1.4444,20.678,318.36,306.63,306.18
145.55273,7.0073,7.348,0.0,0.0,1.4403,21.257,318.3,306.55,306.21
145.55353,6.9412,7.3476,0.0,0.0,1.447,21.074,318.23,306.46,306.22
145.55432,6.8986,7.3543,0.0,0.0,1.4478,20.928,318.17,306.36,306.23
145.55512,7.0639,7.3536,0.0,0.0,1.4418,21.437,318.11,306.27,306.24
145.55592,6.8133,7.3456,0.0,0.0,1.4439,20.696,318.04,306.18,306.25
145.55672,7.0641,7.3489,0.0,0.0,1.4485,21.398,317.98,306.09,306.26
145.55752,6.9148,7.3586,0.0,0.0,1.4442,21.032,317.91,306.0,306.27
145.55832,6.9002,7.3509,0.0,0.0,1.4426,20.903,317.85,305.91,306.28
145.55912,7.0557,7.3418,0.0,0.0,1.4459,21.426,317.79,305.82,306.29
145.55992,6.8293,7.3568,0.0,0.0,1.4461,20.685,317.72,305.73,306.3
145.56072,7.0789,7.359,0.0,0.0,1.4439,21.438,317.66,305.64,306.31
145.56152,6.8938,7.3407,0.0,0.0,1.4427,20.957,317.6,305.55,306.32
145.56232,6.947,7.351,0.0,0.0,1.4479,21.047,317.53,305.46,306.33
145.56312,7.0224,7.3606,0.0,0.0,1.4452,21.344,317.45,305.37,306.35
145.56391,6.8381,7.3451,0.0,0.0,1.4398,20.722,317.37,305.29,306.37
145.56471,7.0763,7.3474,0.0,0.0,1.4481,21.434,317.29,305.21,306.4
145.56551,6.8672,7.3578,0.0,0.0,1.4488,20.857,317.21,305.12,306.42
145.56631,6.9662,7.355,0.0,0.0,1.4411,21.104,317.13,305.04,306.45
145.56711,7.0233,7.345,0.0,0.0,1.4454,21.347,317.05,304.96,306.47
145.56791,6.8634,7.3459,0.0,0.0,1.4477,20.781,316.97,304.87,306.5
145.56871,7.0784,7.3658,0.0,0.0,1.4449,21.458,316.89,304.79,306.52
145.56951,6.8375,7.3479,0.0,0.0,1.4429,20.783,316.81,304.7,306.55
145.57031,7.0068,7.3371,0.0,0.0,1.4452,21.227,316.72,304.62,306.57
145.57111,6.9972,7.3629,0.0,0.0,1.4473,21.247,316.64,304.54,306.6
145.57191,6.8559,7.3587,0.0,0.0,1.4426,20.757,316.56,304.45,306.62
145.57271,7.0801,7.3341,0.0,0.0,1.4419,21.499,316.48,304.37,306.65
145.5735,6.8248,7.3542,0.0,0.0,1.4494,20.761,316.38,304.29,306.68
145.5743,7.0443,7.3625,0.0,0.0,1.4449,21.342,316.29,304.2,306.71
145.5751,6.9593,7.3429,0.0,0.0,1.4385,21.151,316.2,304.12,306.73
145.5759,6.8683,7.3471,0.0,0.0,1.4483,20.797,316.1,304.04,306.76
145.5767,7.079,7.3579,0.0,0.0,1.4487,21.456,316.01,303.95,306.79
145.5775,6.8289,7.3526,0.0,0.0,1.4385,20.702,315.92,303.87,306.82
145.5783,7.0638,7.3449,0.0,0.0,1.446,21.412,315.82,303.79,306.85
145.5791,6.9015,7.3475,0.0,0.0,1.4483,20.981,315.73,303.7,306.88
145.5799,6.9011,7.3614,0.0,0.0,1.4426,20.905,315.64,303.62,306.91
145.5807,7.0499,7.3499,0.0,0.0,1.4435,21.461,315.54,303.53,306.94
145.5815,6.8092,7.3384,0.0,0.0,1.4459,20.633,315.45,303.45,306.97
145.5823,7.0827,7.3627,0.0,0.0,1.4463,21.457,315.36,303.37,307.0
145.58309,6.8893,7.3552,0.0,0.0,1.442,20.912,315.28,303.29,307.02
145.58389,6.9261,7.3375,0.0,0.0,1.4422,21.0,315.2,303.21,307.04
145.58469,7.0236,7.3564,0.0,0.0,1.45,21.343,315.12,303.14,307.05
145.58549,6.808,7.358,0.0,0.0,1.4436,20.654,315.04,303.06,307.07
145.58629,7.0711,7.3459,0.0,0.0,1.4404,21.452,314.96,302.99,307.09
145.58709,6.8495,7.3479,0.0,0.0,1.4487,20.828,314.89,302.91,307.1
145.58789,6.9499,7.3523,0.0,0.0,1.4458,21.047,314.81,302.83,307.12
145.58869,7.0042,7.3545,0.0,0.0,1.4406,21.269,314.73,302.76,307.14
145.58949,6.8123,7.347,0.0,0.0,1.4465,20.629,314.65,302.68,307.16
145.59029,7.0652,7.3456,0.0,0.0,1.4463,21.439,314.57,302.6,307.17
145.59109,6.8398,7.3589,0.0,0.0,1.4425,20.762,314.49,302.53,307.19
145.59189,6.9712,7.3477,0.0,0.0,1.4435,21.134,314.41,302.45,307.21
145.59268,6.953,7.3401,0.0,0.0,1.446,21.124,314.35,302.38,307.23
145.59348,6.8386,7.3595,0.0,0.0,1.4456,20.749,314.29,302.32,307.24
145.59428,7.0663,7.3543,0.0,0.0,1.4425,21.398,314.23,302.26,307.26
145.59508,6.8143,7.34,0.0,0.0,1.4433,20.663,314.17,302.2,307.28
145.59588,7.0216,7.3559,0.0,0.0,1.4481,21.256,314.11,302.15,307.3
145.59668,6.9361,7.3576,0.0,0.0,1.4434,21.082,314.05,302.09,307.32
145.59748,6.8555,7.3458,0.0,0.0,1.4415,20.743,313.99,302.03,307.34
145.59828,7.0813,7.3491,0.0,0.0,1.4484,21.479,313.93,301.97,307.36
145.59908,6.7942,7.3536,0.0,0.0,1.4456,20.626,313.87,301.91,307.38
145.59988,7.0303,7.3523,0.0,0.0,1.441,21.28,313.82,301.85,307.4
145.60068,6.9183,7.3451,0.0,0.0,1.4463,21.04,313.76,301.79,307.42
145.60148,6.9244,7.3501,0.0,0.0,1.4468,20.957,313.7,301.73,307.44
145.60228,7.0468,7.3619,0.0,0.0,1.4448,21.381,313.64,301.67,307.46
145.60307,6.8116,7.3438,0.0,0.0,1.4425,20.655,313.58,301.61,307.47
145.60387,7.0582,7.3426,0.0,0.0,1.4454,21.422,313.53,301.54,307.47
145.60467,6.9172,7.3655,0.0,0.0,1.4477,21.018,313.47,301.47,307.48
145.60547,6.9144,7.3525,0.0,0.0,1.4432,20.958,313.41,301.41,307.48
145.60627,7.043,7.3402,0.0,0.0,1.4437,21.426,313.36,301.34,307.49
145.60707,6.8269,7.3576,0.0,0.0,1.4481,20.709,313.3,301.27,307.49
145.60787,7.0811,7.358,0.0,0.0,1.444,21.466,313.24,301.21,307.5
145.60867,6.893,7.3455,0.0,0.0,1.4424,20.912,313.19,301.14,307.5
145.60947,6.9745,7.3496,0.0,0.0,1.4474,21.163,313.13,301.07,307.51
145.61027,7.0276,7.357,0.0,0.0,1.4457,21.354,313.07,301.01,307.51
145.61107,6.8489,7.3525,0.0,0.0,1.4429,20.761,313.02,300.94,307.51
145.61187,7.102,7.3459,0.0,0.0,1.4468,21.536,312.96,300.87,307.52
145.61266,6.8676,7.3517,0.0,0.0,1.4467,20.847,312.9,300.81,307.53
145.61346,7.0344,7.3593,0.0,0.0,1.4441,21.286,312.84,300.75,307.55
145.61426,7.0257,7.3476,0.0,0.0,1.4451,21.35,312.78,300.69,307.57
145.61506,6.8717,7.3487,0.0,0.0,1.4463,20.84,312.72,300.63,307.58
145.61586,7.1189,7.3609,0.0,0.0,1.4459,21.588,312.66,300.58,307.6
145.61666,6.8726,7.3503,0.0,0.0,1.4432,20.867,312.6,300.52,307.62
145.61746,7.0487,7.347,0.0,0.0,1.4457,21.35,312.53,300.46,307.63
145.61826,7.0166,7.3582,0.0,0.0,1.4475,21.286,312.47,300.4,307.65
145.61906,6.9271,7.353,0.0,0.0,1.4428,20.998,312.41,300.34,307.67
145.61986,7.1039,7.3503,0.0,0.0,1.4451,21.569,312.35,300.28,307.69
145.62066,6.8698,7.3528,0.0,0.0,1.4486,20.851,312.29,300.22,307.7
145.62146,7.0887,7.356,0.0,0.0,1.4447,21.447,312.23,300.16,307.72
145.62225,6.9893,7.3532,0.0,0.0,1.444,21.237,312.17,300.1,307.74
145.62305,6.9392,7.3482,0.0,0.0,1.4478,21.003,312.1,300.05,307.76
145.62385,7.1108,7.3576,0.0,0.0,1.447,21.591,312.04,300.0,307.79
145.62465,6.8861,7.358,0.0,0.0,1.4445,20.865,311.97,299.95,307.82
145.62545,7.1084,7.346,0.0,0.0,1.4454,21.536,311.91,299.91,307.85
145.62625,6.9663,7.3519,0.0,0.0,1.4466,21.149,311.85,299.86,307.87
145.62705,6.9721,7.3599,0.0,0.0,1.4452,21.138,311.78,299.81,307.9
145.62785,7.1086,7.3511,0.0,0.0,1.4445,21.577,311.72,299.76,307.93
145.62865,6.883,7.3493,0.0,0.0,1.4465,20.88,311.66,299.71,307.95
145.62945,7.1258,7.3591,0.0,0.0,1.4471,21.618,311.59,299.66,307.98
145.63025,6.9446,7.3524,0.0,0.0,1.4429,21.098,311.53,299.61,308.01
145.63105,7.0229,7.3515,0.0,0.0,1.4467,21.238,311.46,299.56,308.03
145.63184,7.0909,7.3564,0.0,0.0,1.4495,21.539,311.4,299.51,308.06
145.63264,6.9078,7.3542,0.0,0.0,1.4434,20.946,311.34,299.45,308.08
145.63344,7.1559,7.3522,0.0,0.0,1.4446,21.683,311.27,299.39,308.09
145.63424,6.9237,7.3516,0.0,0.0,1.449,21.011,311.2,299.33,308.1
145.63504,7.0548,7.3579,0.0,0.0,1.4456,21.375,311.14,299.27,308.12
145.63584,7.0863,7.3572,0.0,0.0,1.4447,21.533,311.07,299.21,308.13
145.63664,6.9198,7.3479,0.0,0.0,1.4469,20.975,311.0,299.15,308.14
145.63744,7.1635,7.3577,0.0,0.0,1.4476,21.681,310.94,299.09,308.15
145.63824,6.9226,7.3611,0.0,0.0,1.4448,21.042,310.87,299.02,308.17
145.63904,7.084,7.3483,0.0,0.0,1.4441,21.483,310.81,298.96,308.18
145.63984,7.0485,7.3544,0.0,0.0,1.4488,21.444,310.74,298.9,308.19
145.64064,6.9384,7.3592,0.0,0.0,1.4462,21.011,310.67,298.84,308.2
145.64143,7.1696,7.354,0.0,0.0,1.4437,21.744,310.61,298.78,308.21
145.64223,6.9156,7.3518,0.0,0.0,1.4477,20.983,310.54,298.72,308.23
145.64303,7.118,7.3568,0.0,0.0,1.4491,21.579,310.49,298.65,308.23
145.64383,7.0217,7.3559,0.0,0.0,1.4433,21.324,310.43,298.59,308.23
145.64463,6.947,7.352,0.0,0.0,1.4458,21.087,310.37,298.53,308.23
145.64543,7.152,7.3514,0.0,0.0,1.4496,21.714,310.32,298.47,308.23
145.64623,6.9048,7.3586,0.0,0.0,1.4446,20.964,310.26,298.41,308.23
145.64703,7.1461,7.3573,0.0,0.0,1.4452,21.623,310.2,298.35,308.23
145.64783,6.9921,7.3468,0.0,0.0,1.4476,21.252,310.15,298.28,308.23
145.64863,7.0065,7.356,0.0,0.0,1.4463,21.212,310.09,298.22,308.23
145.64943,7.1365,7.363,0.0,0.0,1.4452,21.682,310.03,298.16,308.23
145.65023,6.9079,7.3461,0.0,0.0,1.4446,20.968,309.98,298.1,308.23
145.65103,7.1578,7.3556,0.0,0.0,1.449,21.7,309.92,298.04,308.23
145.65182,6.9588,7.361,0.0,0.0,1.4456,21.139,309.86,297.98,308.23
145.65262,7.0347,7.3504,0.0,0.0,1.4428,21.315,309.82,297.92,308.23
145.65342,7.1155,7.3506,0.0,0.0,1.4482,21.588,309.78,297.86,308.23
145.65422,6.9127,7.3575,0.0,0.0,1.4487,20.963,309.73,297.8,308.23
145.65502,7.1798,7.3577,0.0,0.0,1.4429,21.767,309.69,297.75,308.23
145.65582,6.9513,7.3488,0.0,0.0,1.4464,21.089,309.65,297.69,308.24
145.65662,7.0585,7.352,0.0,0.0,1.4496,21.34,309.61,297.63,308.24
145.65742,7.0937,7.3635,0.0,0.0,1.4452,21.534,309.57,297.58,308.24
145.65822,6.9267,7.3503,0.0,0.0,1.4435,21.017,309.53,297.52,308.24
145.65902,7.1714,7.345,0.0,0.0,1.4477,21.758,309.48,297.46,308.25
145.65982,6.9239,7.3633,0.0,0.0,1.448,21.051,309.44,297.41,308.25
145.66062,7.0905,7.3608,0.0,0.0,1.4442,21.493,309.4,297.35,308.25
145.66141,7.0804,7.3408,0.0,0.0,1.4437,21.509,309.36,297.29,308.25
145.66221,6.9324,7.3554,0.0,0.0,1.4493,21.005,309.31,297.24,308.26
145.66301,7.174,7.3647,0.0,0.0,1.4462,21.788,309.26,297.19,308.27
145.66381,6.9222,7.346,0.0,0.0,1.4416,21.003,309.21,297.14,308.28
145.66461,7.1001,7.3488,0.0,0.0,1.4484,21.499,309.15,297.09,308.3
145.66541,7.0303,7.3589,0.0,0.0,1.4491,21.354,309.1,297.04,308.31
145.66621,6.9579,7.3554,0.0,0.0,1.4412,21.063,309.04,296.99,308.32
145.66701,7.1476,7.347,0.0,0.0,1.4465,21.715,308.99,296.94,308.33
145.66781,6.9085,7.3473,0.0,0.0,1.4487,20.941,308.94,296.89,308.34
145.66861,7.1376,7.3644,0.0,0.0,1.4442,21.593,308.88,296.85,308.36
145.66941,7.0301,7.352,0.0,0.0,1.4445,21.32,308.83,296.8,308.37
145.67021,6.9844,7.3417,0.0,0.0,1.4473,21.165,308.77,296.75,308.38
145.671,7.1459,7.3641,0.0,0.0,1.4472,21.66,308.72,296.7,308.39
145.6718,6.8984,7.3589,0.0,0.0,1.4432,20.978,308.67,296.65,308.41
145.6726,7.1588,7.3402,0.0,0.0,1.4444,21.674,308.61,296.6,308.42
145.6734,6.9724,7.3584,0.0,0.0,1.4506,21.163,308.56,296.55,308.43
145.6742,7.0226,7.3619,0.0,0.0,1.4439,21.255,308.51,296.5,308.45
145.675,7.1227,7.3469,0.0,0.0,1.4417,21.652,308.46,296.45,308.46
145.6758,6.8967,7.3496,0.0,0.0,1.4497,20.921,308.41,296.4,308.48
145.6766,7.166,7.3604,0.0,0.0,1.448,21.713,308.36,296.35,308.49
145.6774,6.953,7.3557,0.0,0.0,1.4404,21.083,308.31,296.3,308.51
145.6782,7.0411,7.3482,0.0,0.0,1.4474,21.317,308.25,296.25,308.52
145.679,7.0957,7.351,0.0,0.0,1.4497,21.533,308.2,296.21,308.54
145.6798,6.9214,7.3638,0.0,0.0,1.4433,20.989,308.15,296.16,308.55
145.68059,7.161,7.3515,0.0,0.0,1.4447,21.724,308.1,296.11,308.57
145.68139,6.9536,7.344,0.0,0.0,1.4484,21.084,308.05,296.06,308.58
145.68219,7.0813,7.3638,0.0,0.0,1.4469,21.467,307.99,296.01,308.6
145.68299,7.0854,7.3594,0.0,0.0,1.4441,21.521,307.93,295.95,308.61
145.68379,6.9395,7.3416,0.0,0.0,1.4447,21.039,307.87,295.89,308.63
145.68459,7.1681,7.3585,0.0,0.0,1.45,21.754,307.81,295.84,308.64
145.68539,6.9223,7.3612,0.0,0.0,1.4446,21.038,307.75,295.78,308.66
145.68619,7.1208,7.3476,0.0,0.0,1.4422,21.565,307.69,295.72,308.67
145.68699,7.0663,7.355,0.0,0.0,1.4514,21.448,307.63,295.67,308.69
145.68779,6.9551,7.3569,0.0,0.0,1.4468,21.093,307.56,295.61,308.7
145.68859,7.1688,7.355,0.0,0.0,1.4412,21.742,307.5,295.55,308.71
145.68939,6.9193,7.3515,0.0,0.0,1.4491,21.02,307.44,295.5,308.73
145.69018,7.1375,7.3533,0.0,0.0,1.449,21.63,307.38,295.44,308.74
145.69098,7.0229,7.3623,0.0,0.0,1.444,21.346,307.32,295.38,308.76
145.69178,7.0284,7.3498,0.0,0.0,1.4451,21.3,307.26,295.33,308.77
145.69258,7.1699,7.35,0.0,0.0,1.4489,21.773,307.2,295.28,308.77
145.69338,6.936,7.3638,0.0,0.0,1.4465,20.989,307.14,295.23,308.77
145.69418,7.1757,7.3556,0.0,0.0,1.4436,21.746,307.08,295.18,308.76
145.69498,7.0358,7.3468,0.0,0.0,1.4462,21.356,307.02,295.13,308.76
145.69578,7.0552,7.3611,0.0,0.0,1.4504,21.38,306.96,295.08,308.75
145.69658,7.1489,7.3581,0.0,0.0,1.4442,21.728,306.9,295.03,308.75
145.69738,6.9412,7.3493,0.0,0.0,1.4434,21.065,306.84,294.98,308.74
145.69818,7.2008,7.3566,0.0,0.0,1.4513,21.828,306.79,294.93,308.74
145.69898,7.0059,7.3557,0.0,0.0,1.4456,21.282,306.73,294.88,308.73
145.69977,7.0917,7.3528,0.0,0.0,1.4423,21.476,306.67,294.83,308.73
145.70057,7.1436,7.353,0.0,0.0,1.4501,21.72,306.61,294.78,308.72
145.70137,6.976,7.3535,0.0,0.0,1.4476,21.139,306.55,294.73,308.72
145.70217,7.2244,7.361,0.0,0.0,1.4438,21.89,306.5,294.69,308.72
145.70297,6.9863,7.3507,0.0,0.0,1.4464,21.231,306.47,294.64,308.72
145.70377,7.1301,7.3486,0.0,0.0,1.4473,21.584,306.43,294.6,308.73
145.70457,7.1323,7.365,0.0,0.0,1.4472,21.655,306.4,294.56,308.74
145.70537,6.9871,7.355,0.0,0.0,1.4445,21.198,306.36,294.52,308.75
145.70617,7.2222,7.3493,0.0,0.0,1.4467,21.918,306.33,294.48,308.75
145.70697,6.9844,7.3596,0.0,0.0,1.4488,21.226,306.29,294.44,308.76
145.70777,7.1665,7.358,0.0,0.0,1.4442,21.689,306.26,294.39,308.77
145.70857,7.1065,7.3503,0.0,0.0,1.4452,21.624,306.23,294.35,308.78
145.70937,7.0138,7.3551,0.0,0.0,1.4495,21.24,306.19,294.31,308.78
145.71016,7.2365,7.3592,0.0,0.0,1.4466,21.952,306.16,294.27,308.79
145.71096,6.9714,7.3551,0.0,0.0,1.4439,21.19,306.12,294.23,308.8
145.71176,7.1752,7.3497,0.0,0.0,1.4483,21.765,306.09,294.18,308.81
145.71256,7.0947,7.355,0.0,0.0,1.4477,21.577,306.05,294.14,308.83
145.71336,7.0442,7.3631,0.0,0.0,1.446,21.35,306.01,294.1,308.85
145.71416,7.2258,7.3494,0.0,0.0,1.4465,21.938,305.96,294.05,308.87
145.71496,6.9784,7.3519,0.0,0.0,1.4471,21.207,305.92,294.01,308.89
145.71576,7.225,7.3661,0.0,0.0,1.4473,21.888,305.88,293.96,308.91
145.71656,7.0769,7.3541,0.0,0.0,1.445,21.524,305.84,293.92,308.94
145.71736,7.0875,7.3496,0.0,0.0,1.4466,21.478,305.8,293.87,308.96
145.71816,7.2049,7.3616,0.0,0.0,1.4485,21.888,305.76,293.83,308.98
145.71896,6.9756,7.3569,0.0,0.0,1.4447,21.18,305.71,293.79,309.0
145.71975,7.2443,7.3505,0.0,0.0,1.446,21.942,305.67,293.74,309.03
145.72055,7.0435,7.3576,0.0,0.0,1.4497,21.386,305.63,293.7,309.05
145.72135,7.1183,7.3579,0.0,0.0,1.4452,21.543,305.59,293.65,309.07
145.72215,7.1862,7.355,0.0,0.0,1.4455,21.835,305.55,293.61,309.08
145.72295,7.0012,7.3515,0.0,0.0,1.4485,21.225,305.5,293.56,309.07
145.72375,7.2474,7.3586,0.0,0.0,1.4464,21.961,305.46,293.51,309.07
145.72455,7.0005,7.36,0.0,0.0,1.446,21.263,305.41,293.46,309.06
145.72535,7.1301,7.3508,0.0,0.0,1.4475,21.58,305.37,293.41,309.06
145.72615,7.1638,7.3564,0.0,0.0,1.4482,21.757,305.32,293.36,309.05
145.72695,6.9999,7.3623,0.0,0.0,1.4456,21.212,305.28,293.31,309.05
145.72775,7.2456,7.3521,0.0,0.0,1.4453,21.966,305.24,293.26,309.05
145.72855,6.9979,7.3546,0.0,0.0,1.4489,21.233,305.19,293.21,309.04
145.72934,7.1603,7.3637,0.0,0.0,1.4482,21.7,305.15,293.16,309.04
145.73014,7.1318,7.355,0.0,0.0,1.4446,21.674,305.1,293.11,309.03
145.73094,7.0109,7.3545,0.0,0.0,1.4483,21.262,305.06,293.06,309.03
145.73174,7.2423,7.3587,0.0,0.0,1.45,21.97,305.02,293.01,309.02
145.73254,6.9782,7.355,0.0,0.0,1.4435,21.186,304.98,292.97,309.02
145.73334,7.1833,7.3545,0.0,0.0,1.4466,21.77,304.94,292.92,309.03
145.73414,7.0907,7.3534,0.0,0.0,1.45,21.529,304.9,292.87,309.03
145.73494,7.0478,7.3593,0.0,0.0,1.4454,21.356,304.86,292.83,309.03
145.73574,7.2321,7.359,0.0,0.0,1.446,21.93,304.82,292.78,309.03
145.73654,6.9851,7.3488,0.0,0.0,1.4476,21.181,304.78,292.73,309.04
145.73734,7.209,7.3581,0.0,0.0,1.4471,21.851,304.74,292.69,309.04
145.73814,7.0677,7.3645,0.0,0.0,1.4461,21.462,304.7,292.64,309.04
145.73893,7.0694,7.3477,0.0,0.0,1.4451,21.429,304.66,292.59,309.04
145.73973,7.2188,7.3565,0.0,0.0,1.4489,21.915,304.62,292.55,309.05
145.74053,6.9819,7.3652,0.0,0.0,1.4478,21.162,304.58,292.5,309.05
145.74133,7.236,7.3528,0.0,0.0,1.4435,21.935,304.54,292.45,309.05
145.74213,7.0349,7.3512,0.0,0.0,1.448,21.411,304.51,292.41,309.06
145.74293,7.1031,7.3598,0.0,0.0,1.4491,21.517,304.47,292.38,309.07
145.74373,7.1933,7.3604,0.0,0.0,1.4449,21.842,304.43,292.35,309.08
145.74453,6.9856,7.3524,0.0,0.0,1.4469,21.145,304.39,292.32,309.09
145.74533,7.2442,7.3531,0.0,0.0,1.4494,21.94,304.35,292.29,309.11
145.74613,7.0439,7.3619,0.0,0.0,1.4452,21.344,304.31,292.25,309.12
145.74693,7.1414,7.3574,0.0,0.0,1.4462,21.619,304.27,292.22,309.13
145.74773,7.1702,7.3476,0.0,0.0,1.4479,21.735,304.23,292.19,309.14
145.74852,7.0023,7.3591,0.0,0.0,1.4462,21.225,304.19,292.16,309.16
145.74932,7.2586,7.3643,0.0,0.0,1.4453,22.005,304.15,292.13,309.17
145.75012,7.0247,7.3478,0.0,0.0,1.4456,21.296,304.11,292.09,309.18
145.75092,7.1604,7.3574,0.0,0.0,1.4499,21.69,304.07,292.06,309.19
145.75172,7.1555,7.3657,0.0,0.0,1.4469,21.726,304.03,292.03,309.2
145.75252,7.0219,7.3487,0.0,0.0,1.443,21.295,304.0,291.99,309.19
145.75332,7.2651,7.3533,0.0,0.0,1.4497,22.044,303.97,291.95,309.18
145.75412,7.0017,7.3598,0.0,0.0,1.4489,21.275,303.94,291.91,309.17
145.75492,7.1976,7.3556,0.0,0.0,1.4424,21.796,303.91,291.87,309.16
145.75572,7.1294,7.3538,0.0,0.0,1.4486,21.659,303.87,291.83,309.15
145.75652,7.0617,7.3523,0.0,0.0,1.4496,21.387,303.84,291.79,309.14
145.75732,7.2535,7.3617,0.0,0.0,1.4441,21.993,303.81,291.75,309.13
145.75812,7.0058,7.3548,0.0,0.0,1.4459,21.274,303.78,291.71,309.13
145.75891,7.2421,7.3481,0.0,0.0,1.4495,21.928,303.75,291.67,309.12
145.75971,7.1091,7.3631,0.0,0.0,1.4468,21.568,303.71,291.63,309.11
145.76051,7.0822,7.361,0.0,0.0,1.4443,21.426,303.68,291.6,309.1
145.76131,7.2449,7.3462,0.0,0.0,1.4462,21.989,303.65,291.56,309.09
145.76211,7.0176,7.3619,0.0,0.0,1.4506,21.291,303.61,291.52,309.08
145.76291,7.2646,7.3641,0.0,0.0,1.4452,21.97,303.57,291.48,309.08
145.76371,7.0801,7.3482,0.0,0.0,1.4425,21.521,303.54,291.44,309.08
145.76451,7.1088,7.3561,0.0,0.0,1.4516,21.568,303.5,291.41,309.07
145.76531,7.2211,7.3626,0.0,0.0,1.449,21.948,303.46,291.37,309.07
145.76611,7.014,7.3549,0.0,0.0,1.4411,21.274,303.42,291.33,309.07
145.76691,7.2812,7.3519,0.0,0.0,1.4489,22.047,303.38,291.3,309.07
145.76771,7.0646,7.356,0.0,0.0,1.4512,21.405,303.34,291.26,309.06
145.7685,7.1534,7.3662,0.0,0.0,1.4438,21.69,303.3,291.22,309.06
145.7693,7.215,7.3539,0.0,0.0,1.445,21.895,303.26,291.19,309.06
145.7701,7.0311,7.3467,0.0,0.0,1.4493,21.309,303.22,291.15,309.06
145.7709,7.276,7.3707,0.0,0.0,1.4489,22.081,303.18,291.11,309.05
145.7717,7.0597,7.3619,0.0,0.0,1.4439,21.408,303.14,291.08,309.05
145.7725,7.1923,7.3414,0.0,0.0,1.4456,21.788,303.1,291.05,309.07
145.97319,7.1077,7.3598,0.0,0.0,1.4481,21.57,288.02,274.26,238.7
147.4365,7.1059,7.3761,0.0,0.0,1.4549,21.559,111.43,92.738,148.72
149.0365,7.104,7.4118,0.0,0.0,1.4698,21.551,44.888,38.952,37.872
150.6365,7.0942,7.4315,0.0,0.0,1.478,21.521,29.174,27.245,23.571
152.2365,7.1333,7.4432,0.0,0.0,1.4831,21.636,23.629,23.262,20.456
153.8365,7.1591,7.4519,0.0,0.0,1.4865,21.711,21.491,21.583,19.51
155.4365,7.1725,7.4588,0.0,0.0,1.4895,21.752,20.468,20.766,19.285
157.0365,7.1648,7.4624,0.0,0.0,1.491,21.73,23.267,24.379,21.589
158.6365,7.1168,7.4647,0.0,0.0,1.492,21.587,26.056,26.852,24.43
160.2365,7.1231,7.4733,0.0,0.0,1.4959,21.61,27.953,28.605,26.681
161.8365,6.9399,7.4772,0.0,0.0,1.4972,21.049,29.153,29.924,28.289
162.6365,5.3077,7.452,0.0,0.0,1.4869,16.103,29.661,34.046,28.917