File: examples/dan-msc-case-studies/CS4/data/01 raw data/hyde_test_038.csv
Time(sec),Force(kN),Jaw(mm),PowAngle(deg),PTemp,Strain,Stress(MPa),TC1(C),TC2(C),TC3(C)
0.0,5.0062,0.0040816,0.0,0.0033407,0.00035588,15.159,19.989,21.058,20.524
0.6,4.8481,0.0035729,0.0,1.6211,0.00042334,14.712,20.124,21.104,20.635
1.2,4.7643,0.0037368,0.0,3.4211,0.00036423,14.45,20.111,21.058,20.615
1.8,4.7117,0.0035679,0.0,5.2211,0.00038513,14.297,20.153,21.102,20.625
2.4,4.6572,0.0032057,0.0,7.0211,0.00042388,14.126,20.184,21.153,20.592
3.0,4.6332,0.0031605,0.0,8.8211,0.00034659,14.058,20.134,21.085,20.588
3.6,4.5956,0.0034684,0.0,10.621,0.00038345,13.939,20.132,21.112,20.619
4.2,4.5882,0.0034002,0.0,12.421,0.00033848,13.923,20.156,21.028,20.596
4.8,4.5573,0.0031604,0.0,14.221,0.00038297,13.824,20.134,21.05,20.6
5.4,4.5457,0.0031016,0.0,16.021,0.00035733,13.793,20.212,21.173,20.621
6.0,4.5274,0.0031597,0.0,17.821,0.00036741,13.732,20.178,21.113,20.616
6.6,4.5328,0.0033697,0.0,19.621,0.00032183,13.752,20.172,21.027,20.591
7.2,4.5084,0.0039484,13.497,21.421,0.000426,13.675,20.17,21.103,20.592
7.8,4.5445,0.0046862,25.995,23.221,0.00058227,13.79,20.737,22.403,21.592
8.3662,4.5539,0.003857,25.789,24.925,0.00045217,13.818,22.998,25.32,24.575
8.9662,4.5567,0.0034565,20.983,26.72,0.00042924,13.819,25.895,27.484,27.326
9.5662,4.5528,0.0031539,21.039,28.52,0.0003539,13.814,27.896,28.704,28.673
10.1662,4.5473,0.0027069,24.023,30.32,0.00026505,13.79,29.394,29.946,29.91
10.7662,4.5554,0.0020871,24.821,32.12,0.00021431,13.824,31.316,38.533,31.783
11.3662,4.5533,0.0012276,24.681,33.92,0.00020347,13.81,33.329,38.575,33.784
11.9662,4.564,0.00085487,24.096,35.72,8.6714e-05,13.849,35.307,38.575,35.464
12.5662,4.5651,0.00033637,24.801,37.52,7.0637e-05,13.846,37.107,38.575,37.13
13.1662,4.5736,-0.00057745,26.084,39.32,-9.412e-05,13.878,38.785,39.019,38.87
13.6679,4.5659,-0.00093996,25.64,40.825,-0.00013881,13.848,40.505,40.601,40.652
14.2679,4.5769,-0.0018454,24.818,42.625,-0.00017148,13.888,42.444,42.256,42.414
14.8679,4.5842,-0.0023208,25.957,44.425,-0.0002246,13.901,44.166,43.83,43.954
15.4679,4.5949,-0.0030728,25.893,46.225,-0.00030555,13.942,46.012,45.629,45.835
16.0679,4.5961,-0.0037547,26.098,48.025,-0.00044991,13.938,47.779,47.1,47.45
16.6679,4.6074,-0.0045145,26.355,49.825,-0.00049031,13.981,49.587,48.823,49.148
17.2679,4.6101,-0.0051014,26.705,51.625,-0.0004897,13.984,51.424,50.722,51.035
17.8679,4.6215,-0.0058136,26.012,53.425,-0.00063543,14.021,53.317,52.465,52.82
18.4679,4.6176,-0.0065644,26.9,55.225,-0.00071641,14.006,55.041,53.975,54.403
19.0679,4.6405,-0.0069738,26.892,57.025,-0.00079143,14.08,56.924,55.76,56.228
19.6679,4.6323,-0.0077199,26.192,58.825,-0.00080536,14.052,58.799,57.439,58.016
20.2679,4.6472,-0.0082972,27.201,60.625,-0.00091447,14.1,60.495,58.951,59.572
20.8679,4.6343,-0.008656,27.399,62.425,-0.00093491,14.057,62.271,60.69,61.306
21.4679,4.6591,-0.0087781,26.884,64.225,-0.0010208,14.134,64.175,62.488,63.175
22.0679,4.6484,-0.0095118,27.461,66.025,-0.0010433,14.103,65.881,64.183,64.824
22.6679,4.6686,-0.0098083,27.656,67.825,-0.0010184,14.163,67.695,65.861,66.597
23.2679,4.6639,-0.010552,28.242,69.625,-0.0011555,14.148,69.444,67.643,68.34
23.8679,4.6817,-0.010712,27.581,71.425,-0.0011933,14.201,71.387,69.474,70.254
24.4679,4.6631,-0.011202,27.737,73.225,-0.0012521,14.148,73.138,70.993,71.842
25.0679,4.6904,-0.012095,28.298,75.025,-0.0012595,14.23,74.876,72.615,73.523
25.6679,4.6848,-0.012528,28.121,76.825,-0.0013783,14.214,76.767,74.419,75.334
26.2679,4.6952,-0.013247,28.136,78.625,-0.0014184,14.241,78.572,76.181,77.131
26.8679,4.6978,-0.013825,28.621,80.425,-0.0015561,14.253,80.341,77.806,78.807
27.4679,4.7176,-0.014687,28.707,82.225,-0.0015956,14.309,82.157,79.555,80.649
28.0679,4.7118,-0.015514,28.62,84.025,-0.0016437,14.298,83.996,81.358,82.514
28.6679,4.7206,-0.016008,28.464,85.825,-0.0017356,14.317,85.783,82.948,84.17
29.2679,4.7205,-0.016726,29.025,87.625,-0.0018609,14.325,87.506,84.664,85.806
29.8679,4.7279,-0.017469,28.967,89.425,-0.0019174,14.34,89.357,86.41,87.719
30.4679,4.7274,-0.018581,28.793,91.225,-0.001966,14.346,91.243,88.177,89.455
31.0679,4.7394,-0.019274,29.06,93.025,-0.0021216,14.376,92.962,89.892,91.188
31.6679,4.74,-0.01972,28.947,94.825,-0.0021543,14.384,94.798,91.492,92.855
32.2679,4.7492,-0.021147,29.273,96.625,-0.0023518,14.404,96.582,93.298,94.696
32.86791,4.7485,-0.022878,28.461,98.425,-0.0024558,14.408,98.6,95.146,96.689
33.46791,4.7511,-0.024143,29.794,100.22,-0.0026387,14.409,100.13,96.607,98.094
34.06791,4.7608,-0.02369,29.123,102.02,-0.0025619,14.447,102.05,98.456,100.08
34.66791,4.7682,-0.02333,29.253,103.82,-0.0026045,14.463,103.84,100.08,101.76
35.26791,4.7788,-0.024352,29.345,105.62,-0.0026603,14.501,105.58,101.76,103.32
35.86791,4.7674,-0.025139,28.598,107.42,-0.0026895,14.462,107.62,103.66,105.37
36.46791,4.7739,-0.026168,29.439,109.22,-0.0028457,14.484,109.2,105.12,106.82
37.06791,4.7771,-0.026731,29.931,111.02,-0.0029474,14.49,110.91,106.79,108.53
37.66791,4.7959,-0.027494,29.48,112.82,-0.003021,14.554,112.86,108.72,110.57
38.26791,4.785,-0.028626,29.236,114.62,-0.0030618,14.515,114.7,110.18,112.18
38.86791,4.8048,-0.029106,30.606,116.42,-0.0031953,14.577,116.21,111.49,113.56
39.46791,4.7861,-0.030254,29.939,118.22,-0.003297,14.519,118.18,113.67,115.8
40.06791,4.8021,-0.031479,29.492,120.02,-0.0034794,14.568,120.13,115.26,117.57
40.66791,4.806,-0.033524,29.816,121.82,-0.0036244,14.578,121.83,116.89,119.12
41.1013,4.8014,-0.034271,28.988,123.13,-0.0037484,14.564,123.28,118.19,120.55
41.7013,4.8222,-0.033897,30.87,124.92,-0.0037479,14.629,124.71,119.82,122.05
42.3013,4.8121,-0.034117,28.778,126.72,-0.003686,14.598,126.98,121.88,124.32
42.9013,4.83,-0.034967,30.655,128.53,-0.0038127,14.651,128.36,123.18,125.57
43.5013,4.8187,-0.036135,29.821,130.33,-0.0039303,14.619,130.4,125.24,127.66
44.1013,4.8321,-0.036743,29.616,132.13,-0.0040654,14.658,132.2,126.81,129.33
44.7013,4.8224,-0.038091,30.766,133.92,-0.0041627,14.632,133.76,128.42,130.87
45.3013,4.8343,-0.039086,29.763,135.72,-0.0042181,14.663,135.85,130.46,133.02
45.9013,4.8302,-0.039968,30.519,137.52,-0.0043475,14.654,137.46,131.94,134.35
46.5013,4.841,-0.040875,30.872,139.32,-0.0044982,14.683,139.23,133.85,136.33
47.1013,4.8339,-0.041673,30.134,141.12,-0.00457,14.668,141.18,135.66,138.13
47.7013,4.8381,-0.043467,31.205,142.92,-0.0046728,14.675,142.81,137.27,139.74
48.3013,4.8394,-0.044573,29.798,144.72,-0.0048719,14.683,144.97,139.41,141.92
48.9013,4.8553,-0.046609,30.785,146.52,-0.0050917,14.726,146.45,140.71,143.09
49.5013,4.8505,-0.046568,31.199,148.32,-0.0051431,14.719,148.24,142.79,145.14
50.1013,4.861,-0.046175,30.121,150.13,-0.0050175,14.742,150.25,144.51,147.12
50.7013,4.8608,-0.047217,32.005,151.92,-0.0051548,14.752,151.62,145.74,148.21
51.3013,4.866,-0.048135,31.424,153.72,-0.0052359,14.758,153.69,147.96,150.49
51.9013,4.8643,-0.049063,30.395,155.52,-0.0054068,14.76,155.67,149.79,152.44
52.5013,4.8653,-0.050492,31.116,157.32,-0.0055072,14.756,157.34,151.4,153.91
53.1013,4.8708,-0.051711,31.8,159.12,-0.0055964,14.781,158.94,153.08,155.55
53.7013,4.8638,-0.052432,30.916,160.93,-0.0057138,14.752,161.07,155.1,157.72
54.3013,4.8758,-0.053445,30.821,162.72,-0.0058677,14.793,162.86,156.61,159.23
54.9013,4.8708,-0.054713,31.603,164.52,-0.0059921,14.773,164.43,158.34,160.75
55.5013,4.8809,-0.057054,31.821,166.33,-0.0061505,14.809,166.27,160.28,162.76
56.1013,4.8721,-0.058829,30.769,168.13,-0.0064446,14.78,168.24,162.0,164.49
56.7013,4.8869,-0.058155,31.576,169.93,-0.0063575,14.825,169.85,163.42,165.95
57.3013,4.8825,-0.058351,31.808,171.73,-0.0064112,14.81,171.66,165.58,167.91
57.9013,4.8792,-0.059052,30.519,173.53,-0.0064009,14.804,173.74,167.25,169.9
58.5013,4.8776,-0.060167,31.93,175.32,-0.006562,14.796,175.18,168.68,171.15
59.1013,4.894,-0.061264,31.381,177.13,-0.006662,14.849,177.12,170.7,173.27
59.7013,4.8725,-0.061887,30.872,178.93,-0.0067992,14.78,179.06,172.28,174.97
60.30131,4.8817,-0.063399,31.442,180.73,-0.0069074,14.81,180.74,173.97,176.71
60.90131,4.875,-0.064102,31.517,182.53,-0.0069478,14.791,182.57,175.6,178.44
61.50131,4.8886,-0.065017,31.719,184.33,-0.0070852,14.828,184.31,177.28,180.02
62.10131,4.8743,-0.066106,31.082,186.13,-0.0072444,14.788,186.27,179.34,182.2
62.70131,4.8883,-0.06721,31.735,187.93,-0.0073504,14.827,187.97,180.78,183.61
63.30131,4.8789,-0.069294,31.877,189.73,-0.0074925,14.8,189.73,182.45,185.28
63.90131,4.8946,-0.071161,31.672,191.53,-0.0077704,14.845,191.62,184.52,187.5
64.50131,4.8842,-0.072421,31.973,193.33,-0.007901,14.819,193.35,185.81,188.88
65.10131,4.8985,-0.072052,32.51,195.13,-0.0079138,14.858,195.0,187.64,190.61
65.70131,4.8854,-0.072086,32.08,196.93,-0.0078436,14.824,196.9,189.43,192.51
66.30131,4.8902,-0.072734,31.881,198.73,-0.0079343,14.833,198.7,191.06,194.15
66.90131,4.8849,-0.074238,32.387,200.53,-0.0080764,14.821,200.46,192.8,195.86
67.50131,4.8921,-0.07506,32.846,202.33,-0.0082361,14.838,202.17,194.34,197.51
68.10131,4.8838,-0.076436,30.97,204.13,-0.0083341,14.82,204.4,196.46,199.72
68.70131,4.8906,-0.077176,32.528,205.93,-0.0083728,14.832,205.83,197.64,200.85
69.30131,4.8904,-0.078705,32.974,207.73,-0.0085675,14.839,207.6,199.58,202.81
69.90131,4.8894,-0.079642,32.836,209.53,-0.0087279,14.829,209.42,201.26,204.43
70.50131,4.8913,-0.08052,32.508,211.33,-0.0087889,14.842,211.31,202.9,206.2
71.10131,4.8847,-0.082435,32.982,213.13,-0.008914,14.813,213.0,204.66,207.92
71.70131,4.8956,-0.084186,32.969,214.93,-0.0091806,14.854,214.79,206.22,209.58
72.30131,4.8901,-0.086839,32.357,216.73,-0.0094709,14.832,216.86,208.31,211.75
72.90131,4.8976,-0.085151,32.444,218.53,-0.0093299,14.86,218.57,209.65,213.12
73.50131,4.8926,-0.085756,33.402,220.34,-0.0094038,14.841,220.2,211.37,214.79
73.929,4.8869,-0.086293,32.85,221.61,-0.0094153,14.823,221.63,212.79,216.34
74.529,4.9037,-0.087512,33.31,223.41,-0.0095732,14.879,223.3,214.28,217.85
75.129,4.8792,-0.08867,32.425,225.21,-0.0096126,14.801,225.26,216.03,219.78
75.729,4.8984,-0.089789,32.668,227.01,-0.0098002,14.86,227.06,217.9,221.48
76.329,4.8768,-0.091048,32.412,228.81,-0.0098988,14.792,228.95,219.8,223.47
76.929,4.8999,-0.092074,33.198,230.61,-0.010081,14.864,230.52,221.21,224.88
77.529,4.8866,-0.093993,32.297,232.41,-0.010216,14.821,232.55,223.18,226.94
78.129,4.8956,-0.096865,33.025,234.21,-0.010527,14.851,234.17,224.62,228.29
78.729,4.8866,-0.097803,32.866,236.01,-0.010653,14.825,236.04,226.57,230.31
79.329,4.8975,-0.096052,32.754,237.81,-0.010519,14.856,237.9,228.13,232.11
79.929,4.895,-0.097137,32.982,239.61,-0.010586,14.853,239.62,229.84,233.72
80.529,4.9002,-0.098362,32.851,241.41,-0.010667,14.863,241.48,231.71,235.69
81.129,4.8903,-0.099561,33.065,243.21,-0.010839,14.838,243.2,233.36,237.35
81.729,4.8997,-0.1008,32.917,245.01,-0.011015,14.861,245.0,235.06,239.01
82.329,4.8936,-0.10194,33.104,246.81,-0.011117,14.85,246.81,236.81,240.88
82.929,4.8966,-0.10302,32.861,248.61,-0.011152,14.849,248.67,238.58,242.66
83.529,4.8912,-0.10403,33.062,250.41,-0.01134,14.844,250.41,240.16,244.21
84.129,4.8989,-0.10613,33.5,252.21,-0.011559,14.856,252.14,241.91,245.99
84.729,4.9008,-0.10904,32.851,254.01,-0.011894,14.873,254.08,243.78,247.89
85.329,4.9033,-0.10933,32.849,255.81,-0.011882,14.873,255.8,245.33,249.51
85.929,4.9037,-0.10836,33.479,257.61,-0.011819,14.88,257.56,247.21,251.27
86.529,4.9003,-0.1086,32.682,259.41,-0.0118,14.862,259.57,248.8,253.15
87.129,4.898,-0.11017,33.795,261.21,-0.012052,14.863,261.11,250.57,254.61
87.729,4.8941,-0.11155,33.059,263.01,-0.012132,14.844,263.04,252.37,256.8
88.329,4.9016,-0.11281,33.271,264.81,-0.012247,14.873,264.83,253.97,258.42
88.929,4.8938,-0.11381,33.512,266.61,-0.012375,14.844,266.6,255.72,260.18
89.529,4.8995,-0.11474,33.445,268.41,-0.01254,14.865,268.4,257.5,261.83
90.129,4.8915,-0.11602,33.669,270.21,-0.012652,14.837,270.19,259.25,263.73
90.729,4.9001,-0.11738,33.269,272.01,-0.01272,14.869,272.03,261.04,265.53
91.329,4.8923,-0.11876,33.763,273.81,-0.012925,14.839,273.75,262.62,267.11
91.929,4.9075,-0.121,33.61,275.61,-0.013185,14.886,275.61,264.48,269.05
92.52901,4.8973,-0.12379,33.57,277.41,-0.013492,14.856,277.47,266.18,270.93
93.12901,4.9105,-0.12344,33.772,279.21,-0.013401,14.896,279.17,267.82,272.45
93.72901,4.8994,-0.12224,33.715,281.01,-0.013337,14.864,281.0,269.77,274.34
94.32901,4.9102,-0.12294,34.039,282.81,-0.013372,14.9,282.73,271.52,276.2
94.92901,4.9011,-0.12411,33.772,284.61,-0.013547,14.868,284.63,273.28,277.95
95.52901,4.908,-0.12558,33.95,286.41,-0.013647,14.89,286.35,274.98,279.64
96.12901,4.8925,-0.12678,33.342,288.21,-0.013783,14.847,288.41,277.04,281.74
96.72901,4.909,-0.12759,33.921,290.01,-0.013858,14.889,289.97,278.42,283.12
97.32901,4.8942,-0.12903,33.941,291.81,-0.014091,14.851,291.83,280.47,285.18
97.92901,4.9026,-0.13019,33.28,293.61,-0.014151,14.872,293.78,282.44,287.18
98.52901,4.8933,-0.13106,33.872,295.41,-0.014229,14.845,295.37,284.06,288.75
99.12901,4.9023,-0.13265,34.565,297.21,-0.014416,14.867,297.07,286.0,290.66
99.72901,4.8814,-0.13304,32.85,299.01,-0.014518,14.811,299.24,288.04,292.61
100.32901,4.9033,-0.13526,34.558,300.81,-0.014732,14.867,300.61,289.59,294.05
100.92901,4.9004,-0.13699,33.552,302.61,-0.014843,14.865,302.71,291.68,296.39
101.52901,4.9087,-0.13891,33.674,304.41,-0.015084,14.886,304.44,293.21,297.83
102.12901,4.9063,-0.14115,33.774,306.21,-0.015365,14.886,306.2,295.04,299.53
102.72901,4.9053,-0.14204,33.484,308.01,-0.01548,14.876,308.11,296.58,301.42
103.32901,4.9069,-0.1424,33.876,309.81,-0.015442,14.886,309.76,298.09,302.65
103.92901,4.9092,-0.14193,33.866,311.61,-0.015487,14.889,311.54,299.79,304.37
104.52901,4.9082,-0.14237,33.906,313.41,-0.015513,14.891,313.42,301.51,306.06
105.12901,4.9082,-0.14194,33.755,315.21,-0.015488,14.886,315.21,302.86,307.35
105.72901,4.9083,-0.14256,33.999,317.01,-0.015475,14.893,316.97,304.39,308.9
106.1589,4.9096,-0.14259,33.895,318.3,-0.015551,14.896,318.33,305.56,310.08
106.7589,4.9032,-0.14326,33.854,320.1,-0.015607,14.873,320.08,306.86,311.36
107.3589,4.9117,-0.14437,34.229,321.9,-0.015643,14.905,321.84,308.62,313.04
107.9589,4.9037,-0.14485,34.144,323.7,-0.015775,14.874,323.69,310.29,314.76
108.5589,4.9116,-0.14578,34.369,325.5,-0.015862,14.902,325.47,311.99,316.5
109.1589,4.8977,-0.14676,34.512,327.3,-0.015998,14.855,327.27,313.8,318.37
109.7589,4.9123,-0.14795,34.257,329.1,-0.016041,14.905,329.11,315.44,320.07
110.3589,4.8991,-0.14877,34.249,330.9,-0.016192,14.862,330.88,317.35,321.96
110.9589,4.9091,-0.1497,34.334,332.7,-0.016259,14.891,332.7,319.23,323.7
111.5589,4.9,-0.15029,34.292,334.5,-0.016401,14.864,334.52,321.31,325.6
112.1589,4.9178,-0.15151,34.53,336.3,-0.016454,14.917,336.27,323.3,327.39
112.7589,4.9026,-0.15237,34.369,338.1,-0.016566,14.874,338.11,325.22,329.12
113.3589,4.9177,-0.15354,34.636,339.9,-0.01668,14.919,339.88,327.12,331.03
113.9589,4.899,-0.1547,35.02,341.7,-0.01689,14.86,341.55,329.0,332.76
114.5589,4.9168,-0.15661,34.533,343.5,-0.017048,14.914,343.53,331.07,334.74
115.1589,4.9024,-0.15852,34.77,345.3,-0.017225,14.872,345.32,333.04,336.59
115.7589,4.9085,-0.16096,34.658,347.1,-0.017493,14.888,347.08,334.97,338.51
116.3589,4.902,-0.16201,34.798,348.9,-0.017652,14.875,348.87,336.82,340.35
116.9589,4.9061,-0.16204,34.729,350.7,-0.017594,14.881,350.68,338.67,342.11
117.5589,4.9029,-0.16116,34.742,352.5,-0.017447,14.875,352.48,340.57,344.0
118.1589,4.9079,-0.16048,34.786,354.3,-0.017427,14.882,354.27,342.42,345.77
118.7589,4.8969,-0.16091,35.285,356.1,-0.017523,14.859,356.04,344.24,347.64
119.3589,4.9019,-0.16105,34.971,357.9,-0.017519,14.866,357.89,346.42,349.5
119.9589,4.8953,-0.16155,35.37,359.7,-0.017498,14.854,359.67,348.33,351.43
120.5589,4.905,-0.16201,35.324,361.5,-0.017608,14.874,361.43,350.17,353.19
121.1589,4.8977,-0.16248,35.269,363.3,-0.017694,14.862,363.31,352.24,355.22
121.7589,4.9018,-0.16315,35.44,365.1,-0.017745,14.866,365.07,354.08,357.04
122.3589,4.9011,-0.16367,35.428,366.9,-0.017722,14.874,366.89,356.05,358.96
122.9589,4.9024,-0.16395,35.196,368.7,-0.017823,14.866,368.71,358.09,360.72
123.5589,4.9048,-0.16425,35.503,370.5,-0.017869,14.883,370.42,360.06,362.55
124.1589,4.9016,-0.16437,35.498,372.3,-0.017882,14.866,372.3,362.14,364.67
124.7589,4.9075,-0.16476,35.497,374.1,-0.017845,14.891,374.09,364.07,366.56
125.35891,4.9031,-0.16474,35.497,375.9,-0.017918,14.87,375.87,366.02,368.44
125.95891,4.9137,-0.16472,36.033,377.7,-0.01791,14.908,377.64,367.93,370.3
126.55891,4.9031,-0.16506,35.67,379.5,-0.017978,14.872,379.47,370.0,372.23
127.15891,4.9267,-0.1663,35.752,381.3,-0.018031,14.943,381.28,371.98,373.99
127.75891,4.9224,-0.1687,36.022,383.1,-0.018381,14.93,383.03,373.92,375.78
128.35891,4.9355,-0.17086,35.687,384.9,-0.018558,14.972,384.89,375.9,377.81
128.95891,4.9308,-0.17028,36.159,386.7,-0.018518,14.955,386.64,377.85,379.66
129.55891,4.9589,-0.16793,35.982,388.5,-0.018171,15.039,388.47,379.86,381.69
130.15891,4.9521,-0.16698,35.93,390.3,-0.018152,15.017,390.29,381.85,383.56
130.75891,4.9867,-0.16618,36.284,392.1,-0.018031,15.126,392.08,383.83,385.54
131.35891,4.9817,-0.16542,36.301,393.9,-0.018014,15.113,393.79,385.93,387.36
131.95891,5.0088,-0.16539,36.181,395.7,-0.017935,15.193,395.74,388.1,389.4
132.55891,5.0096,-0.16451,35.995,397.5,-0.017885,15.2,397.56,389.96,391.34
133.15891,5.0449,-0.16403,36.382,399.3,-0.017795,15.302,399.23,392.09,393.22
133.75891,5.0449,-0.1622,34.308,400.0,-0.017666,15.306,400.48,393.65,394.89
134.35891,5.0688,-0.16096,34.651,400.0,-0.017467,15.373,400.24,393.77,394.75
134.95891,5.0835,-0.15974,34.759,400.0,-0.017367,15.423,400.22,394.16,394.94
135.55891,5.1034,-0.15826,34.612,400.0,-0.017165,15.477,400.18,394.63,395.16
136.15891,5.1202,-0.15663,34.291,400.0,-0.017072,15.537,400.25,394.82,395.44
136.75891,5.1455,-0.15537,34.288,400.0,-0.016863,15.607,400.2,395.09,395.57
137.35891,5.1553,-0.15382,34.183,400.0,-0.016714,15.643,400.18,395.26,395.69
137.95891,5.1779,-0.15239,34.109,400.0,-0.016544,15.706,400.17,395.51,395.74
138.55891,5.1961,-0.15129,34.117,400.0,-0.016513,15.765,400.11,395.71,395.83
139.0859,5.2184,-0.15164,34.23,400.0,-0.016488,15.833,400.09,395.85,395.91
139.6859,5.2212,-0.15331,33.79,400.0,-0.01674,15.836,400.1,395.98,395.99
140.2859,5.2479,-0.15219,34.162,400.0,-0.016485,15.923,400.05,396.07,396.04
140.8859,5.2546,-0.14804,34.011,400.0,-0.016086,15.937,400.07,396.21,396.13
141.4859,5.2818,-0.14625,33.994,400.0,-0.015873,16.022,400.09,396.42,396.18
142.0859,5.286,-0.14437,33.825,400.0,-0.015751,16.032,400.1,396.49,396.28
142.6859,5.3137,-0.14316,33.809,400.0,-0.015547,16.12,400.06,396.63,396.32
143.2859,5.3164,-0.14198,33.877,400.0,-0.015445,16.129,400.11,396.79,396.5
143.8859,5.3487,-0.1404,34.266,400.0,-0.015251,16.224,400.14,396.8,396.62
144.4859,5.351,-0.13905,33.762,400.0,-0.015173,16.232,400.4,397.12,397.11
145.0859,5.3854,-0.13792,34.449,400.0,-0.01497,16.336,400.41,397.25,397.06
145.6859,5.3915,-0.13581,33.773,400.0,-0.014787,16.357,400.65,397.59,397.48
146.2859,5.417,-0.1345,33.951,400.0,-0.014607,16.429,400.62,397.69,397.53
146.8554,5.4324,-0.13324,33.778,400.0,-0.014556,16.483,400.61,397.81,397.71
147.4554,5.4389,-0.13469,33.85,400.0,-0.014691,16.494,400.64,397.9,397.69
148.0554,5.4657,-0.13604,33.813,400.0,-0.014757,16.582,400.61,397.9,397.8
148.6554,5.4731,-0.13212,34.377,400.0,-0.014327,16.6,400.54,397.99,397.91
149.2554,5.4924,-0.12917,33.797,400.0,-0.014107,16.66,400.64,398.16,398.03
149.8554,5.4922,-0.12747,33.974,400.0,-0.013878,16.658,400.59,398.25,397.96
150.4554,5.5262,-0.12547,33.994,400.0,-0.01363,16.764,400.6,398.23,398.1
151.0554,5.5275,-0.12386,33.934,400.0,-0.013462,16.77,400.64,398.37,398.22
151.6554,5.559,-0.12238,33.684,400.0,-0.013374,16.863,400.87,398.78,398.46
152.2554,5.5655,-0.12099,34.171,400.0,-0.013175,16.885,400.74,398.65,398.39
152.8554,5.5903,-0.11946,33.829,400.0,-0.012969,16.957,400.8,398.86,398.59
153.4554,5.5932,-0.11756,33.946,400.0,-0.01278,16.968,400.76,398.92,398.63
154.0554,5.6227,-0.11573,33.577,400.0,-0.012657,17.054,400.91,399.09,398.81
154.6554,5.6246,-0.11428,34.436,400.0,-0.012432,17.063,400.79,399.12,398.75
155.2554,5.6539,-0.11257,33.778,400.0,-0.012223,17.149,401.02,399.28,398.94
155.8554,5.6605,-0.11098,34.202,400.0,-0.012072,17.176,401.11,399.54,399.09
156.4554,5.6937,-0.11013,33.783,400.0,-0.012075,17.27,401.44,400.04,399.53
157.0554,5.6942,-0.11079,33.778,400.0,-0.0121,17.275,401.49,400.05,399.6
157.6554,5.7179,-0.11142,33.89,400.0,-0.012121,17.342,401.42,399.99,399.47
158.2554,5.7191,-0.1102,33.924,400.0,-0.011976,17.353,401.41,399.99,399.51
158.8554,5.7315,-0.10728,33.702,400.0,-0.01171,17.383,401.39,400.13,399.56
159.4554,5.7303,-0.10456,33.651,400.0,-0.011365,17.387,401.34,400.13,399.43
160.0554,5.7339,-0.10186,33.733,400.0,-0.011064,17.388,401.39,400.14,399.49
160.6554,5.732,-0.1002,33.749,400.0,-0.010896,17.39,401.31,400.12,399.42
161.2554,5.7345,-0.098571,34.052,400.0,-0.010781,17.391,401.13,399.97,399.33
161.8554,5.7419,-0.096668,33.444,400.0,-0.010534,17.422,401.29,400.1,399.45
162.4554,5.7421,-0.094537,33.254,400.0,-0.010278,17.417,401.2,400.12,399.47
163.0554,5.7567,-0.093373,33.58,400.0,-0.010162,17.466,401.08,399.93,399.33
163.6554,5.7478,-0.09179,33.432,400.0,-0.010065,17.434,401.16,400.08,399.36
164.2554,5.7572,-0.09033,33.354,400.0,-0.009842,17.468,401.13,400.04,399.4
164.8554,5.7489,-0.088849,33.138,400.0,-0.00967,17.436,401.15,399.96,399.37
165.4554,5.767,-0.087163,33.271,400.0,-0.0094836,17.497,401.12,400.01,399.37
166.05541,5.7542,-0.086088,33.046,400.0,-0.0094401,17.452,401.52,400.58,399.84
166.65541,5.7656,-0.084574,32.891,400.0,-0.0092102,17.494,401.62,400.65,399.86
167.25541,5.7508,-0.083216,32.986,400.0,-0.00906,17.443,401.61,400.76,399.88
167.85541,5.7675,-0.081468,33.036,400.0,-0.0088614,17.496,401.56,400.72,399.88
168.45541,5.7555,-0.079482,32.674,400.0,-0.0087185,17.461,401.56,400.54,400.02
169.05541,5.7678,-0.078217,33.486,400.0,-0.008513,17.498,401.3,400.37,399.67
169.65541,5.7541,-0.076768,33.222,400.0,-0.0083647,17.454,401.41,400.41,399.64
170.25541,5.7711,-0.07519,32.924,400.0,-0.0081787,17.506,401.39,400.48,399.75
170.85541,5.7624,-0.073631,33.424,400.0,-0.0080863,17.483,401.25,400.35,399.61
171.3264,5.7688,-0.072689,32.83,400.0,-0.0079515,17.499,401.26,400.38,399.78
171.9264,5.7641,-0.073447,33.51,400.0,-0.0080993,17.487,401.15,400.19,399.41
172.5264,5.7696,-0.075001,33.204,400.0,-0.0082227,17.499,401.12,400.16,399.43
173.1264,5.7676,-0.073828,32.87,400.0,-0.007987,17.501,401.12,400.15,399.46
173.7264,5.7722,-0.070245,33.163,400.0,-0.0076355,17.505,401.08,399.93,399.23
174.3264,5.7682,-0.067876,32.973,400.0,-0.0074522,17.5,401.16,400.12,399.38
174.9264,5.7643,-0.066529,33.09,400.0,-0.0072459,17.485,401.14,400.11,399.21
175.5264,5.7687,-0.064618,33.742,400.0,-0.0070185,17.504,400.96,399.97,399.18
176.1264,5.7674,-0.063341,33.151,400.0,-0.0068969,17.493,401.09,400.11,399.32
176.7264,5.7746,-0.061573,32.863,400.0,-0.0067738,17.523,401.13,400.17,399.38
177.3264,5.7788,-0.060712,33.013,400.0,-0.0066196,17.527,401.14,400.16,399.29
177.7471,5.7622,-0.059749,33.45,400.0,-0.0065529,17.48,401.04,400.04,399.27
178.3471,5.7827,-0.0014852,32.919,400.0,-9.3396e-05,17.542,401.19,400.25,399.44
178.6204,5.721,0.007834,0.0,13.778,0.00043919,17.335,401.12,400.27,399.46
178.6234,5.8213,0.0083168,0.0,0.0011231,0.00033399,17.674,401.17,400.24,399.46
178.6264,5.7537,0.0069549,0.0,9.1538e-08,0.00061415,17.376,401.21,400.21,399.46
178.6294,5.7819,0.0049723,0.0,7.4607e-12,0.0008598,17.568,401.26,400.18,399.46
178.6324,5.7507,0.004385,0.0,6.0807e-16,0.00095129,17.396,401.24,400.15,399.45
178.6354,5.7791,0.0051776,0.0,4.9558e-20,0.00075267,17.565,401.21,400.11,399.44
178.6384,5.7736,0.006566,0.0,4.0388e-24,0.00052912,17.488,401.19,400.08,399.43
178.6414,5.7576,0.0069223,0.0,3.2914999999999997e-28,0.00073278,17.486,401.17,400.06,399.43
178.6444,5.7939,0.0068493,0.0,2.6824e-32,0.001075,17.549,401.16,400.06,399.43
178.6474,5.7254,0.0071554,0.0,2.1859e-36,0.00058519,17.413,401.15,400.06,399.43
178.6504,5.8076,0.0085879,0.0,1.7724999999999999e-40,0.00040016,17.607,401.14,400.05,399.43
178.6534,5.7025,0.0071591,0.0,1.5414e-44,0.00039391,17.309,401.12,400.02,399.46
178.6564,5.8234,0.0046291,0.0,0.0,0.00064841,17.643,401.1,399.98,399.49
178.6594,5.6996,0.0036336,0.0,0.0,0.00090937,17.31,401.09,399.94,399.52
178.6624,5.8279,0.0047645,0.0,0.0,0.00089597,17.675,401.09,399.97,399.51
178.6654,5.6912,0.0062599,0.0,0.0,0.0005977,17.273,401.1,400.01,399.5
178.6684,5.8228,0.0073898,0.0,0.0,0.00064881,17.654,401.11,400.04,399.49
178.6714,5.7051,0.0070875,0.0,0.0,0.0010326,17.287,401.2,400.18,399.45
178.6744,5.8129,0.0067159,0.0,0.0,0.0008949,17.649,401.35,400.4,399.39
178.6774,5.7206,0.0077463,0.0,0.0,0.00045476,17.343,401.51,400.62,399.33
178.6804,5.7856,0.0080128,0.0,0.0,0.00034896,17.561,401.78,400.99,399.27
178.6834,5.7123,0.0062176,0.0,0.0,0.00061512,17.304,402.47,401.86,399.21
178.6864,10.091,0.010488,0.0,0.0,0.0014377,29.972,403.16,402.74,399.16
178.68939,26.226,0.15958,0.0,0.0,0.017748,79.405,403.84,403.61,399.1
178.69239,29.249,0.42447,0.0,0.0,0.047297,88.527,404.9,404.9,399.07
178.69539,30.52,0.69168,0.0,0.0,0.077837,92.532,406.0,406.24,399.05
178.69839,31.072,0.97044,0.0,0.0,0.11133,94.277,407.11,407.58,399.02
178.70139,31.347,1.2336,0.0,0.0,0.14386,95.104,408.02,408.65,399.0
178.70439,31.326,1.4888,0.0,0.0,0.17569,95.022,408.8,409.51,398.98
178.70739,31.238,1.7237,0.0,0.0,0.20577,94.778,409.58,410.38,398.96
178.71039,31.1,1.9484,0.0,0.0,0.23624,94.318,410.29,411.15,398.95
178.71339,31.105,2.1632,0.0,0.0,0.26653,94.364,410.77,411.59,398.97
178.71639,31.093,2.3741,0.0,0.0,0.29713,94.319,411.26,412.03,398.99
178.71939,31.141,2.5901,0.0,0.0,0.32803,94.465,411.75,412.48,399.01
178.72239,31.199,2.802,0.0,0.0,0.35902,94.61,412.2,412.75,399.02
178.72539,31.242,3.009,0.0,0.0,0.39118,94.781,412.64,413.0,399.04
178.72839,31.31,3.2082,0.0,0.0,0.42355,94.948,413.08,413.25,399.06
178.73139,31.384,3.4035,0.0,0.0,0.45493,95.208,413.45,413.4,399.08
178.73439,31.426,3.5944,0.0,0.0,0.48607,95.303,413.75,413.46,399.11
178.73739,31.481,3.7749,0.0,0.0,0.51723,95.501,414.06,413.53,399.14
178.74039,31.593,3.9497,0.0,0.0,0.54946,95.821,414.35,413.61,399.16
178.74339,31.696,4.1219,0.0,0.0,0.58209,96.132,414.61,413.75,399.16
178.74639,31.889,4.2976,0.0,0.0,0.61507,96.723,414.86,413.9,399.16
178.74939,31.881,4.4731,0.0,0.0,0.6481,96.729,415.11,414.04,399.16
178.75239,31.955,4.6364,0.0,0.0,0.68056,96.923,415.23,414.21,399.17
178.75539,32.037,4.797,0.0,0.0,0.71492,97.165,415.34,414.38,399.19
178.75839,32.135,4.9501,0.0,0.0,0.74757,97.472,415.45,414.55,399.21
178.76139,32.144,5.1012,0.0,0.0,0.77937,97.486,415.44,414.65,399.23
178.76439,32.267,5.2469,0.0,0.0,0.81129,97.869,415.33,414.68,399.26
178.76739,32.329,5.3869,0.0,0.0,0.84497,98.072,415.22,414.72,399.29
178.77039,32.492,5.524,0.0,0.0,0.87954,98.565,415.07,414.72,399.31
178.77339,32.513,5.6581,0.0,0.0,0.9134,98.627,414.76,414.59,399.32
178.77639,32.632,5.7945,0.0,0.0,0.947,98.992,414.45,414.46,399.33
178.77939,32.674,5.9211,0.0,0.0,0.97929,99.102,414.15,414.34,399.34
178.78239,32.761,6.0416,0.0,0.0,1.0128,99.393,413.7,413.96,399.39
178.78539,32.864,6.1599,0.0,0.0,1.0471,99.672,413.24,413.56,399.44
178.78839,32.934,6.2732,0.0,0.0,1.0787,99.892,412.78,413.15,399.5
178.79139,33.062,6.3874,0.0,0.0,1.1105,100.27,412.29,412.59,399.54
178.79439,33.28,6.4965,0.0,0.0,1.144,100.95,411.76,411.91,399.59
178.79739,33.459,6.6048,0.0,0.0,1.1804,101.47,411.24,411.24,399.63
178.80039,33.583,6.7095,0.0,0.0,1.2161,101.87,410.71,410.52,399.66
178.80339,33.768,6.811,0.0,0.0,1.2496,102.42,410.18,409.64,399.61
178.80639,33.908,6.9135,0.0,0.0,1.2831,102.84,409.65,408.76,399.57
178.80939,34.157,7.0076,0.0,0.0,1.3165,103.57,409.12,407.89,399.52
178.81239,34.339,7.1007,0.0,0.0,1.3533,104.17,408.63,406.87,399.53
178.81539,34.609,7.1901,0.0,0.0,1.3871,104.96,408.15,405.85,399.54
178.81839,34.797,7.2795,0.0,0.0,1.4193,105.54,407.68,404.82,399.54
178.82139,35.024,7.3677,0.0,0.0,1.4537,106.23,407.24,403.54,399.57
178.82439,35.125,7.4452,0.0,0.0,1.4885,106.54,406.84,402.08,399.61
178.82738,35.425,7.5201,0.0,0.0,1.5239,107.44,406.45,400.62,399.64
178.83038,35.642,7.5973,0.0,0.0,1.5585,108.18,406.05,399.11,399.67
178.83338,31.975,7.6078,0.0,0.0,1.5611,97.109,405.68,397.45,399.68
178.83638,30.078,7.6174,0.0,0.0,1.5648,91.332,405.3,395.78,399.69
178.83938,29.005,7.6187,0.0,0.0,1.5673,88.053,404.92,394.12,399.7
178.84238,28.292,7.6237,0.0,0.0,1.5704,85.856,404.5,392.76,399.74
178.84538,27.942,7.6279,0.0,0.0,1.57,84.782,404.07,391.44,399.78
178.84838,27.691,7.636,0.0,0.0,1.5711,83.999,403.65,390.12,399.83
178.85138,27.584,7.6411,0.0,0.0,1.5746,83.669,403.19,388.93,399.86
178.85438,27.375,7.6418,0.0,0.0,1.5784,83.047,402.7,387.84,399.86
178.85738,26.785,7.6445,0.0,0.0,1.5814,81.339,402.21,386.76,399.87
178.86038,24.826,7.6432,0.0,0.0,1.5787,75.475,401.77,385.85,399.89
178.86338,21.164,7.64,0.0,0.0,1.5748,64.464,401.48,385.56,399.91
178.86638,14.979,7.634,0.0,0.0,1.5729,46.116,401.19,385.28,399.94
178.86938,4.7512,7.6113,0.0,0.0,1.5643,13.773,400.9,384.99,399.97
178.87238,5.6059,7.6214,0.0,0.0,1.5688,16.677,400.84,385.29,399.97
178.87538,5.6663,7.6165,0.0,0.0,1.5627,17.14,400.8,385.67,399.97
178.87838,5.2681,7.623,0.0,0.0,1.5649,16.022,400.77,386.05,399.97
178.88138,5.2098,7.617,0.0,0.0,1.5655,15.852,400.71,386.39,399.98
178.88438,5.2729,7.6152,0.0,0.0,1.5677,15.947,400.64,386.69,400.0
178.88738,5.0778,7.6176,0.0,0.0,1.5679,15.428,400.57,386.99,400.02
178.89038,5.3086,7.6201,0.0,0.0,1.5664,16.088,400.49,387.25,400.05
178.89338,5.0949,7.6212,0.0,0.0,1.5661,15.446,400.38,387.41,400.12
178.89638,5.2766,7.6202,0.0,0.0,1.5683,16.001,400.27,387.56,400.19
178.89938,5.1223,7.6191,0.0,0.0,1.5684,15.504,400.16,387.71,400.26
178.90238,5.2244,7.6205,0.0,0.0,1.566,15.868,400.02,387.76,400.3
178.90538,5.1211,7.6208,0.0,0.0,1.5635,15.504,399.88,387.8,400.32
178.90838,5.2258,7.6189,0.0,0.0,1.5645,15.883,399.73,387.83,400.35
178.91138,5.1538,7.6153,0.0,0.0,1.5667,15.617,399.57,387.86,400.36
178.91438,5.1818,7.6157,0.0,0.0,1.5678,15.714,399.4,387.86,400.36
178.91738,5.1614,7.6188,0.0,0.0,1.5671,15.626,399.23,387.87,400.36
178.92038,5.1503,7.6205,0.0,0.0,1.5659,15.661,399.07,387.87,400.37
178.92338,5.2213,7.6202,0.0,0.0,1.5671,15.818,398.96,387.84,400.38
178.92638,5.1204,7.617,0.0,0.0,1.5677,15.552,398.86,387.8,400.4
178.92938,5.2554,7.6171,0.0,0.0,1.5661,15.909,398.75,387.76,400.42
178.93238,5.1459,7.6212,0.0,0.0,1.5648,15.65,398.61,387.66,400.45
178.93538,5.2862,7.6216,0.0,0.0,1.5651,15.981,398.46,387.54,400.47
178.93838,5.1314,7.6208,0.0,0.0,1.5679,15.576,398.32,387.42,400.5
178.94138,5.281,7.6175,0.0,0.0,1.5688,15.994,398.14,387.27,400.53
178.94438,5.1258,7.6187,0.0,0.0,1.5684,15.55,397.94,387.09,400.57
178.94738,5.2497,7.6199,0.0,0.0,1.5657,15.94,397.75,386.9,400.6
178.95038,5.162,7.6215,0.0,0.0,1.5667,15.628,397.56,386.72,400.64
178.95338,5.2331,7.6205,0.0,0.0,1.5691,15.899,397.39,386.51,400.69
178.95638,5.2053,7.6194,0.0,0.0,1.5684,15.758,397.23,386.3,400.73
178.95938,5.3142,7.6222,0.0,0.0,1.5662,16.131,397.07,386.09,400.78
178.96238,5.2841,7.622,0.0,0.0,1.5646,15.996,396.89,385.9,400.82
178.96537,5.3562,7.6202,0.0,0.0,1.5661,16.248,396.71,385.71,400.85
178.96837,5.3432,7.6169,0.0,0.0,1.5683,16.174,396.53,385.52,400.89
178.97137,5.4528,7.617,0.0,0.0,1.568,16.572,396.33,385.31,400.91
178.97437,5.4132,7.621,0.0,0.0,1.5672,16.369,396.12,385.08,400.93
178.97737,5.4887,7.6248,0.0,0.0,1.5675,16.708,395.91,384.86,400.95
178.98037,5.4538,7.6204,0.0,0.0,1.5679,16.491,395.71,384.62,400.97
178.98337,5.4481,7.6207,0.0,0.0,1.5694,16.581,395.51,384.36,400.97
178.98637,5.4735,7.6198,0.0,0.0,1.5664,16.54,395.31,384.1,400.98
178.98937,5.3892,7.6219,0.0,0.0,1.5648,16.404,395.11,383.84,400.99
178.99237,5.5062,7.6217,0.0,0.0,1.5651,16.644,394.94,383.61,401.02
178.99537,5.3567,7.6196,0.0,0.0,1.5679,16.306,394.78,383.38,401.04
178.99837,5.5278,7.6193,0.0,0.0,1.5697,16.741,394.62,383.15,401.07
179.00137,5.3374,7.6204,0.0,0.0,1.5686,16.229,394.46,382.94,401.09
179.00437,5.5628,7.6228,0.0,0.0,1.5672,16.844,394.31,382.73,401.1
179.00737,5.3319,7.6223,0.0,0.0,1.5675,16.178,394.15,382.52,401.11
179.01037,5.5756,7.6214,0.0,0.0,1.5698,16.89,393.99,382.31,401.11
179.01337,5.3451,7.6213,0.0,0.0,1.5689,16.204,393.79,382.09,401.07
179.01637,5.5797,7.6245,0.0,0.0,1.5671,16.94,393.59,381.88,401.03
179.01937,5.3756,7.6246,0.0,0.0,1.5658,16.277,393.39,381.66,401.0
179.02237,5.5579,7.6239,0.0,0.0,1.5683,16.912,393.19,381.41,401.01
179.02537,5.3968,7.6186,0.0,0.0,1.569,16.319,392.99,381.16,401.03
179.02837,5.5268,7.6209,0.0,0.0,1.5694,16.813,392.8,380.9,401.05
179.03137,5.4417,7.6235,0.0,0.0,1.5681,16.445,392.6,380.65,401.08
179.03437,5.4635,7.6252,0.0,0.0,1.5681,16.646,392.41,380.41,401.12
179.03737,5.4736,7.6238,0.0,0.0,1.5699,16.529,392.22,380.16,401.17
179.04037,5.4288,7.6223,0.0,0.0,1.5699,16.564,392.04,379.92,401.2
179.04337,5.5126,7.6238,0.0,0.0,1.5676,16.655,391.86,379.66,401.2
179.04637,5.3809,7.6247,0.0,0.0,1.5659,16.404,391.69,379.41,401.2
179.04937,5.5453,7.6225,0.0,0.0,1.5664,16.769,391.52,379.16,401.2
179.05237,5.359,7.6209,0.0,0.0,1.5687,16.333,391.36,378.93,401.2
179.05537,5.5837,7.6213,0.0,0.0,1.5705,16.901,391.19,378.72,401.19
179.05837,5.373,7.6237,0.0,0.0,1.5696,16.302,391.03,378.5,401.18
179.06137,5.594,7.6269,0.0,0.0,1.5687,16.963,390.86,378.28,401.17
179.06437,5.3726,7.6262,0.0,0.0,1.5692,16.296,390.69,378.06,401.16
179.06737,5.595,7.6269,0.0,0.0,1.572,16.982,390.52,377.85,401.15
179.07037,5.3792,7.624,0.0,0.0,1.5695,16.286,390.34,377.62,401.15
179.07337,5.5906,7.628,0.0,0.0,1.568,16.992,390.16,377.39,401.19
179.07637,5.4266,7.6263,0.0,0.0,1.5667,16.425,389.98,377.15,401.22
179.07937,5.5698,7.6236,0.0,0.0,1.5691,16.945,389.8,376.92,401.26
179.08237,5.4639,7.6206,0.0,0.0,1.5704,16.515,389.63,376.72,401.3
179.08537,5.5359,7.6237,0.0,0.0,1.5704,16.859,389.46,376.53,401.35
179.08837,5.4826,7.6256,0.0,0.0,1.5686,16.579,389.28,376.34,401.4
179.09137,5.4981,7.6265,0.0,0.0,1.5691,16.776,389.13,376.14,401.4
179.09437,5.5306,7.6255,0.0,0.0,1.5708,16.725,388.98,375.95,401.37
179.09737,5.4506,7.6254,0.0,0.0,1.5711,16.624,388.84,375.75,401.35
179.10037,5.564,7.6269,0.0,0.0,1.5687,16.815,388.69,375.54,401.32
179.10336,5.422,7.6275,0.0,0.0,1.5669,16.506,388.54,375.34,401.29
179.10636,5.5884,7.6266,0.0,0.0,1.5687,16.911,388.38,375.13,401.26
179.10936,5.3886,7.6234,0.0,0.0,1.5706,16.397,388.23,374.92,401.24
179.11236,5.6206,7.6238,0.0,0.0,1.571,17.017,388.06,374.7,401.24
179.11536,5.3801,7.6233,0.0,0.0,1.569,16.367,387.89,374.48,401.25
179.11836,5.6258,7.6259,0.0,0.0,1.5685,17.067,387.72,374.27,401.26
179.12136,5.4059,7.6239,0.0,0.0,1.569,16.4,387.54,374.05,401.25
179.12436,5.6306,7.6252,0.0,0.0,1.5713,17.085,387.36,373.83,401.24
179.12736,5.4276,7.626,0.0,0.0,1.5695,16.438,387.18,373.61,401.22
179.13036,5.6221,7.6283,0.0,0.0,1.5677,17.092,387.0,373.4,401.2
179.13336,5.4551,7.626,0.0,0.0,1.5668,16.519,386.83,373.18,401.17
179.13636,5.6001,7.6256,0.0,0.0,1.5703,17.047,386.65,372.96,401.14
179.13936,5.4867,7.6223,0.0,0.0,1.5709,16.606,386.48,372.74,401.12
179.14236,5.5386,7.6259,0.0,0.0,1.5712,16.877,386.33,372.54,401.11
179.14536,5.5319,7.6285,0.0,0.0,1.5699,16.737,386.17,372.34,401.11
179.14836,5.5228,7.6286,0.0,0.0,1.5704,16.834,386.02,372.14,401.11
179.15136,5.5682,7.6258,0.0,0.0,1.5713,16.843,385.88,371.95,401.11
179.15436,5.481,7.6251,0.0,0.0,1.5706,16.691,385.74,371.77,401.1
179.15736,5.6142,7.6268,0.0,0.0,1.5682,16.997,385.6,371.59,401.09
179.16036,5.4396,7.6289,0.0,0.0,1.5675,16.546,385.47,371.4,401.08
179.16336,5.6521,7.6294,0.0,0.0,1.5706,17.092,385.34,371.17,401.07
179.16636,5.4295,7.6268,0.0,0.0,1.5727,16.488,385.22,370.95,401.06
179.16936,5.6639,7.6256,0.0,0.0,1.572,17.15,385.09,370.72,401.05
179.17236,5.4295,7.6265,0.0,0.0,1.57,16.473,384.96,370.52,401.05
179.17536,5.6661,7.63,0.0,0.0,1.5699,17.199,384.82,370.33,401.04
179.17836,5.4452,7.6287,0.0,0.0,1.5717,16.483,384.68,370.14,401.03
179.18136,5.67,7.6294,0.0,0.0,1.5728,17.216,384.54,369.97,401.01
179.18436,5.4832,7.6285,0.0,0.0,1.57,16.598,384.38,369.8,401.0
179.18736,5.6484,7.6312,0.0,0.0,1.5689,17.174,384.23,369.64,400.98
179.19036,5.5091,7.6303,0.0,0.0,1.5699,16.674,384.08,369.47,400.96
179.19336,5.6202,7.6275,0.0,0.0,1.5718,17.126,383.92,369.29,400.93
179.19636,5.5495,7.6258,0.0,0.0,1.5726,16.771,383.77,369.11,400.9
179.19936,5.5732,7.6278,0.0,0.0,1.5714,16.984,383.61,368.93,400.88
179.20236,5.5949,7.6291,0.0,0.0,1.5696,16.929,383.49,368.77,400.88
179.20536,5.5471,7.628,0.0,0.0,1.5703,16.903,383.38,368.62,400.89
179.20836,5.6277,7.6269,0.0,0.0,1.5721,16.995,383.26,368.46,400.9
179.21136,5.5052,7.6267,0.0,0.0,1.5711,16.75,383.15,368.31,400.92
179.21436,5.6498,7.6297,0.0,0.0,1.569,17.097,383.04,368.16,400.95
179.21736,5.4777,7.6306,0.0,0.0,1.5688,16.654,382.93,368.0,400.97
179.22036,5.6915,7.6289,0.0,0.0,1.5712,17.213,382.82,367.85,400.99
179.22336,5.4669,7.626,0.0,0.0,1.5727,16.615,382.7,367.7,400.95
179.22636,5.6985,7.627,0.0,0.0,1.5724,17.257,382.58,367.56,400.91
179.22936,5.4818,7.6274,0.0,0.0,1.5696,16.621,382.46,367.41,400.88
179.23236,5.7035,7.629,0.0,0.0,1.5699,17.31,382.33,367.25,400.86
179.23536,5.5044,7.6263,0.0,0.0,1.5709,16.648,382.2,367.09,400.84
179.23836,5.7054,7.629,0.0,0.0,1.5729,17.325,382.06,366.93,400.82
179.24135,5.5167,7.629,0.0,0.0,1.57,16.68,381.92,366.77,400.82
179.24435,5.6694,7.6312,0.0,0.0,1.5692,17.255,381.79,366.61,400.83
179.24735,5.559,7.6272,0.0,0.0,1.5686,16.821,381.65,366.46,400.84
179.25035,5.6224,7.628,0.0,0.0,1.5723,17.114,381.52,366.31,400.84
179.6509,5.4848,7.6335,0.0,0.0,1.5732,16.638,355.62,342.02,310.43
180.2509,5.4427,7.6392,0.0,0.0,1.5758,16.509,316.58,310.3,250.02
180.8509,5.4316,7.6462,0.0,0.0,1.579,16.477,279.16,276.27,221.6
181.4509,5.4297,7.6553,0.0,0.0,1.5832,16.472,235.38,234.54,195.12
182.0509,5.4314,7.6667,0.0,0.0,1.5883,16.481,90.454,129.76,166.08
182.6509,5.4198,7.6805,0.0,0.0,1.5949,16.436,71.145,96.384,92.625
183.2509,5.4155,7.6953,0.0,0.0,1.602,16.433,68.804,83.265,70.202
183.8509,5.3929,7.7067,0.0,0.0,1.6073,16.356,64.358,71.039,58.189
184.4509,5.3865,7.7147,0.0,0.0,1.6108,16.345,61.98,66.808,53.208
185.0509,5.3907,7.7178,0.0,0.0,1.6126,16.35,58.535,62.893,49.823
185.6509,5.4205,7.7222,0.0,0.0,1.6148,16.447,55.311,60.375,47.308
186.2509,5.4213,7.7267,0.0,0.0,1.6169,16.442,53.843,58.466,45.825
186.8509,5.4516,7.7305,0.0,0.0,1.6183,16.539,52.403,56.634,44.707
187.4509,5.4444,7.7334,0.0,0.0,1.6201,16.516,51.028,54.768,43.549
187.8788,5.4528,7.7357,0.0,0.0,1.6209,16.543,50.31,53.816,43.121
188.4788,5.4793,7.7381,0.0,0.0,1.6225,16.62,48.598,52.0,42.058
189.0788,5.4675,7.7407,0.0,0.0,1.6234,16.591,47.412,50.416,41.217
189.6788,5.5994,7.7425,0.0,0.0,1.6243,16.982,49.698,51.313,43.399
190.2788,5.5264,7.7436,0.0,0.0,1.6247,16.767,52.337,52.742,46.227
190.8788,5.5231,7.7441,0.0,0.0,1.6254,16.752,54.232,54.083,48.287
191.4788,5.5879,7.7457,0.0,0.0,1.6258,16.956,55.666,55.192,50.222
192.0788,5.4843,7.7477,0.0,0.0,1.6267,16.635,56.788,56.145,51.777
192.6788,5.5852,7.7519,0.0,0.0,1.6287,16.942,57.675,56.897,53.047
193.2788,5.5019,7.758,0.0,0.0,1.6322,16.69,58.326,57.538,54.074
193.8788,5.5092,7.759,0.0,0.0,1.6322,16.713,58.816,58.052,55.14
194.4788,5.4386,7.7553,0.0,0.0,1.6304,16.498,59.131,58.403,55.957
195.0788,5.3736,7.7534,0.0,0.0,1.6294,16.301,59.39,58.607,56.706
195.6788,5.361,7.7535,0.0,0.0,1.63,16.262,59.536,58.838,57.179
196.0788,5.3485,7.754,0.0,0.0,1.6299,16.227,59.547,58.931,57.344