File: examples/dan-msc-case-studies/CS4/data/01 raw data/hyde_test_001.csv
Time(sec),Force(kN),Jaw(mm),PowAngle(deg),PTemp,Strain,Stress(MPa),TC1(C),TC2(C),TC3(C),TC4(C)
0.0,2.921,-10.215,0.0,0.0051822,-0.78408,3.4546,25.183,25.122,24.913,24.787
0.8,2.8436,-0.0030239,0.0,2.2204,-0.00035605,3.3733,25.238,25.12,25.077,24.816
1.6,2.8455,-0.0028914,0.0,4.6204,-0.00029294,3.3762,25.253,25.108,25.099,24.778
2.4,2.8078,-0.0027694,0.0,7.0204,-0.00028918,3.3319,25.237,25.094,25.023,24.816
3.1773,2.7983,-0.0027925,0.0,9.3608,-0.00029978,3.3207,25.227,25.118,25.061,24.81
3.9773,2.7838,-0.0028501,0.0,11.752,-0.00032612,3.3045,25.197,25.118,25.084,24.863
4.7773,2.782,-0.0026244,0.0,14.152,-0.00030267,3.3027,25.274,25.101,25.062,24.862
5.5773,2.7609,-0.0028783,0.0,16.552,-0.00030921,3.2776,25.216,25.076,25.047,24.812
6.3773,2.7624,-0.0026606,0.0,18.952,-0.00028954,3.2799,25.211,25.099,25.061,24.831
7.1773,2.7413,-0.0027109,0.0,21.352,-0.00031622,3.2547,25.219,25.138,25.096,24.83
7.9773,2.7305,-0.0026355,0.0,23.752,-0.00027381,3.2406,25.216,25.098,25.067,24.844
8.7773,2.728,-0.0025898,9.4405,26.152,-0.00027103,3.2366,25.236,25.097,25.019,24.811
9.5773,2.737,-0.00083944,29.86,28.552,-0.00011265,3.2476,25.384,25.333,25.109,24.862
10.3773,2.7418,-0.00086764,37.626,30.952,-6.9653e-05,3.2523,26.84,27.25,25.247,25.289
11.0158,2.7642,-0.001419,39.901,32.868,-0.00013977,3.2798,28.994,30.708,25.553,26.35
11.8158,2.7696,-0.0022575,39.07,35.268,-0.00027684,3.2866,32.752,38.451,26.329,28.541
12.6158,2.7685,-0.0032932,37.135,37.668,-0.00034372,3.286,36.347,38.63,27.307,31.315
13.4158,2.7694,-0.0034605,36.297,40.068,-0.00037159,3.2876,39.341,41.052,28.499,33.902
14.2158,2.7696,-0.0039768,35.726,42.468,-0.0004614,3.289,42.043,43.12,29.838,36.36
15.0158,2.7724,-0.0048205,36.463,44.868,-0.00052551,3.2913,44.367,45.134,30.909,38.649
15.8158,2.7715,-0.0054587,37.324,47.268,-0.0005883,3.2895,46.69,47.503,31.953,40.937
16.6158,2.7679,-0.0061904,38.14,49.668,-0.00070511,3.2849,49.018,50.159,33.253,43.247
17.4158,2.7874,-0.0072491,38.528,52.068,-0.0007947,3.3073,51.464,53.124,34.884,45.784
18.2158,2.7916,-0.0090135,38.757,54.468,-0.00099204,3.3122,53.945,56.081,36.751,48.491
19.0158,2.7935,-0.0091917,39.368,56.868,-0.0010519,3.3141,56.33,59.033,38.793,51.258
19.8158,2.8064,-0.0088171,39.731,59.268,-0.00099231,3.3288,58.758,61.985,41.029,54.095
20.6158,2.8069,-0.0092931,39.938,61.668,-0.0010274,3.3297,61.211,65.006,43.278,57.153
21.4158,2.8188,-0.01013,40.459,64.068,-0.0011255,3.3444,63.605,68.108,45.729,60.271
22.2158,2.8092,-0.011533,40.801,66.468,-0.0012752,3.3345,66.024,71.239,48.221,63.356
23.0158,2.8248,-0.01262,41.183,68.868,-0.0013951,3.3534,68.45,74.376,50.462,66.626
23.8158,2.8184,-0.013426,41.218,71.268,-0.0014837,3.3458,70.927,77.623,52.545,69.966
24.6158,2.8229,-0.014616,41.598,73.668,-0.001624,3.3519,73.356,80.742,54.751,73.39
25.4158,2.8169,-0.015927,41.697,76.068,-0.0017605,3.3438,75.823,84.096,57.138,76.839
26.2158,2.8219,-0.016923,41.954,78.468,-0.0018672,3.3492,78.2,87.159,59.554,80.254
27.0158,2.8356,-0.0187,41.803,80.868,-0.0020848,3.3646,80.711,90.312,62.055,83.663
27.8158,2.8402,-0.021244,41.927,83.268,-0.0023298,3.3705,83.064,93.31,64.896,86.998
28.6158,2.8434,-0.02145,42.383,85.668,-0.0023846,3.3727,85.439,96.111,67.641,90.287
29.4158,2.8431,-0.021034,42.391,88.068,-0.0023484,3.3725,87.883,99.134,70.537,93.677
30.2158,2.8461,-0.022534,42.4,90.468,-0.0024749,3.3765,90.339,102.14,73.648,97.087
31.0158,2.846,-0.024267,42.29,92.868,-0.0026754,3.376,92.838,104.96,76.803,100.5
31.8158,2.8497,-0.025747,41.832,95.268,-0.0028736,3.3815,95.357,107.6,80.022,103.84
32.6158,2.8492,-0.027547,41.92,97.668,-0.0030235,3.3819,97.742,110.03,83.251,107.04
33.4158,2.8559,-0.029138,42.088,100.07,-0.0032207,3.3905,100.12,112.66,86.458,110.18
34.2158,2.8431,-0.030438,41.797,102.47,-0.0033951,3.376,102.61,115.21,89.653,113.28
35.0158,2.8395,-0.032567,41.797,104.87,-0.0035799,3.3713,105.0,117.46,92.798,116.27
35.8158,2.8423,-0.034524,41.713,107.27,-0.0037912,3.374,107.38,119.84,95.924,119.15
36.4166,2.8298,-0.036803,41.74,109.07,-0.004056,3.3588,109.14,121.62,98.29,121.3
37.2166,2.84,-0.036735,41.483,111.47,-0.0040689,3.3712,111.59,123.8,101.34,124.05
38.0166,2.8392,-0.036684,41.42,113.87,-0.0040868,3.3686,114.0,126.09,104.44,126.73
38.8166,2.8398,-0.038377,41.69,116.27,-0.0042228,3.3695,116.3,128.34,107.45,129.46
39.6166,2.8513,-0.039951,41.721,118.67,-0.0044036,3.3815,118.67,130.64,110.37,132.04
40.4166,2.8544,-0.041521,41.723,121.07,-0.0046152,3.3857,121.07,132.96,113.37,134.72
41.2166,2.853,-0.04345,41.803,123.47,-0.0047911,3.3844,123.47,135.32,116.29,137.36
42.0166,2.8495,-0.044859,41.771,125.87,-0.0049502,3.3816,125.87,137.74,119.19,140.06
42.8166,2.8469,-0.046333,41.803,128.27,-0.0051551,3.3791,128.19,140.11,122.09,142.64
43.6166,2.8536,-0.048441,41.811,130.67,-0.0053383,3.387,130.67,142.43,124.98,145.35
44.4166,2.8439,-0.049819,41.841,133.07,-0.005508,3.3771,133.07,144.79,127.77,147.92
45.2166,2.841,-0.051788,41.698,135.47,-0.0057477,3.3736,135.55,147.16,130.65,150.49
46.0166,2.8388,-0.05346,41.752,137.87,-0.0058984,3.3692,137.89,149.45,133.38,153.02
46.8166,2.8439,-0.055914,41.739,140.27,-0.0061587,3.3755,140.35,151.83,136.16,155.53
47.6166,2.8446,-0.057939,41.276,142.67,-0.0064319,3.3756,142.8,154.06,138.93,157.94
48.4166,2.8462,-0.058815,41.595,145.07,-0.006505,3.376,145.13,156.15,141.55,160.3
49.2166,2.8501,-0.05946,41.62,147.47,-0.0065887,3.3806,147.52,158.53,144.22,162.55
50.0166,2.8562,-0.059865,41.694,149.87,-0.0066637,3.3887,149.81,160.7,146.9,164.94
50.8166,2.8481,-0.061528,42.133,152.27,-0.0067865,3.379,152.12,162.95,149.4,167.33
51.6166,2.8525,-0.062972,42.278,154.67,-0.0069523,3.3849,154.56,165.47,152.06,169.82
52.4166,2.8613,-0.064379,42.124,157.07,-0.0071473,3.3956,157.01,167.76,154.58,172.35
53.2166,2.861,-0.066184,42.414,159.47,-0.0072916,3.3957,159.32,170.16,157.28,174.87
54.0166,2.8591,-0.067931,42.287,161.87,-0.0074935,3.3946,161.82,172.54,159.9,177.35
54.8166,2.8466,-0.069881,41.93,164.27,-0.0077417,3.3796,164.34,174.92,162.5,179.93
55.6166,2.8381,-0.071741,42.058,166.67,-0.0079121,3.3701,166.72,177.19,165.08,182.44
56.4166,2.8358,-0.073521,41.842,169.07,-0.0081199,3.3656,169.12,179.61,167.68,184.91
57.2166,2.8354,-0.074884,41.934,171.47,-0.0083041,3.365,171.56,181.77,170.19,187.28
58.0166,2.8301,-0.076975,41.883,173.87,-0.0084944,3.3575,173.95,184.11,172.81,189.63
58.8166,2.8379,-0.078432,42.193,176.27,-0.0086602,3.3672,176.28,186.38,175.28,191.93
59.6166,2.8451,-0.080185,42.335,178.67,-0.0088822,3.3754,178.61,188.63,177.73,194.24
60.4166,2.8511,-0.082286,42.408,181.07,-0.0090748,3.3823,180.97,190.91,180.32,196.61
61.2166,2.8522,-0.083967,42.095,183.47,-0.0092746,3.3821,183.55,193.29,182.86,199.09
62.0166,2.8538,-0.085745,42.099,185.87,-0.0095021,3.3859,185.91,195.55,185.55,201.53
62.8166,2.8501,-0.08854,42.313,188.27,-0.0097398,3.3817,188.2,197.8,188.12,203.91
63.6166,2.8545,-0.091376,42.609,190.67,-0.010083,3.3884,190.53,200.27,190.79,206.27
64.4166,2.8633,-0.092187,42.401,193.07,-0.010229,3.3983,193.05,202.61,193.44,208.76
65.2166,2.8527,-0.09277,42.268,195.47,-0.010252,3.3864,195.51,205.06,196.05,211.33
66.0166,2.8551,-0.093162,42.419,197.87,-0.010283,3.389,197.87,207.24,198.7,213.83
66.8166,2.848,-0.094772,42.181,200.27,-0.010483,3.3812,200.36,209.61,201.32,216.33
67.6166,2.8373,-0.096959,41.849,202.67,-0.010689,3.368,202.83,211.8,203.9,218.71
68.3456,2.8476,-0.098273,41.694,204.87,-0.010865,3.3808,205.02,213.69,206.23,220.76
69.1456,2.846,-0.10065,42.093,207.26,-0.011122,3.3791,207.31,215.77,208.77,222.89
69.9456,2.8451,-0.10225,42.377,209.66,-0.01128,3.3773,209.59,217.99,211.26,225.13
70.7456,2.8432,-0.10409,42.405,212.06,-0.011503,3.374,211.98,220.26,213.75,227.49
71.5456,2.8361,-0.10626,42.225,214.46,-0.011737,3.3658,214.48,222.62,216.19,229.89
72.3456,2.844,-0.10819,42.598,216.86,-0.011939,3.3735,216.73,224.85,218.76,232.33
73.1456,2.8451,-0.10998,42.506,219.26,-0.012159,3.3757,219.21,227.23,221.23,234.86
73.9456,2.8513,-0.11284,42.407,221.66,-0.012465,3.3821,221.64,229.69,223.8,237.4
74.7456,2.8589,-0.1145,42.331,224.06,-0.012639,3.3919,224.13,232.11,226.37,240.0
75.5456,2.8596,-0.11765,41.681,226.46,-0.01298,3.3925,226.76,234.35,228.96,242.48
76.2005,2.8487,-0.11923,41.802,228.42,-0.013164,3.3821,228.6,236.06,231.11,244.4
77.0005,2.8475,-0.11923,41.609,230.82,-0.013182,3.3807,231.07,238.16,233.78,246.57
77.8005,2.8511,-0.11908,41.739,233.22,-0.013176,3.3856,233.39,240.22,236.38,248.69
78.6005,2.8499,-0.12094,41.926,235.62,-0.013332,3.3826,235.62,242.36,238.95,250.85
79.4005,2.8375,-0.12333,42.325,238.02,-0.01361,3.3669,237.97,244.6,241.47,253.07
80.2005,2.8563,-0.12548,41.935,240.42,-0.013855,3.3885,240.42,246.93,243.99,255.48
81.0005,2.858,-0.12747,42.241,242.82,-0.014051,3.3903,242.82,249.2,246.45,257.89
81.8005,2.8637,-0.12931,42.003,245.22,-0.014254,3.3971,245.28,251.43,249.01,260.22
82.6005,2.8586,-0.13154,41.803,247.62,-0.01453,3.3916,247.73,253.48,251.46,262.5
83.4005,2.8637,-0.13349,41.784,250.02,-0.014718,3.3976,250.1,255.48,253.84,264.6
84.2005,2.8674,-0.13535,42.385,252.42,-0.014922,3.4028,252.27,257.64,256.27,266.72
85.0005,2.8532,-0.13762,42.94,254.82,-0.01519,3.3872,254.53,259.94,258.66,269.0
85.8005,2.8443,-0.13982,42.544,257.22,-0.015409,3.3766,257.12,262.42,261.24,271.63
86.6005,2.8509,-0.14197,42.493,259.62,-0.015642,3.3846,259.6,264.79,263.81,274.28
87.4005,2.8456,-0.14372,42.248,262.02,-0.01586,3.3781,262.16,267.15,266.43,276.89
88.2005,2.8423,-0.14576,41.559,264.42,-0.016049,3.3731,264.79,269.54,269.11,279.28
89.0005,2.851,-0.14701,41.106,266.82,-0.016189,3.3832,267.23,271.45,271.52,281.39
89.8005,2.8487,-0.14967,41.216,269.22,-0.016492,3.3808,269.43,273.25,273.81,283.26
90.6005,2.8588,-0.15304,42.136,271.62,-0.016829,3.3915,271.47,275.01,276.05,285.1
91.4005,2.862,-0.15594,43.286,274.02,-0.017186,3.3955,273.48,277.26,278.25,287.16
92.2005,2.8571,-0.15676,43.401,276.42,-0.017311,3.3892,275.99,279.93,280.7,289.88
93.0005,2.8613,-0.15733,43.007,278.82,-0.017335,3.394,278.69,282.63,283.46,292.76
93.8005,2.8616,-0.15822,42.407,281.22,-0.017427,3.3951,281.34,285.19,286.15,295.67
94.6005,2.8566,-0.15979,42.157,283.62,-0.017625,3.3903,283.81,287.59,288.69,298.23
95.4005,2.8598,-0.1618,42.237,286.02,-0.017794,3.395,286.14,289.74,291.08,300.52
96.2005,2.8545,-0.16424,42.374,288.42,-0.018068,3.3889,288.45,291.85,293.73,302.66
97.0005,2.855,-0.16632,42.424,290.82,-0.018327,3.3899,290.83,294.09,295.7,304.92
97.8005,2.8589,-0.16855,42.202,293.22,-0.018528,3.3936,293.26,296.38,297.24,307.15
98.6005,2.8566,-0.17131,43.094,295.62,-0.018845,3.3914,295.42,298.68,300.16,309.35
99.4005,2.8554,-0.17372,43.352,298.02,-0.019135,3.3891,297.7,301.12,303.69,311.89
100.2005,2.8531,-0.17605,42.152,299.99,-0.019347,3.3846,300.25,303.66,307.95,314.72
100.9755,2.8151,-0.17462,34.212,300.0,-0.019234,3.3399,302.63,305.53,311.07,316.99
101.7755,2.7801,-0.17137,25.636,300.0,-0.018867,3.298,303.56,304.82,312.49,316.34
102.5755,2.7691,-0.16964,26.404,300.0,-0.018692,3.2847,302.4,301.9,311.15,312.57
103.3755,2.7686,-0.17067,33.47,300.0,-0.018792,3.2845,300.36,298.91,308.94,308.27
104.1755,2.7971,-0.17343,38.841,300.0,-0.019074,3.3184,298.82,297.63,307.43,305.74
104.9755,2.8224,-0.17814,41.112,300.0,-0.019608,3.3489,298.43,298.08,307.29,305.6
105.7755,2.8633,-0.17897,40.704,300.0,-0.019717,3.3984,298.97,299.34,308.19,307.05
106.5755,2.872,-0.17795,39.27,300.0,-0.019612,3.4098,299.78,300.42,309.43,308.94
107.3755,2.8622,-0.17793,37.16,300.0,-0.019597,3.3983,300.43,301.0,310.38,310.17
108.1755,2.8559,-0.17837,35.817,300.0,-0.019624,3.3906,300.71,300.91,310.71,310.34
108.9334,2.8433,-0.17885,35.469,300.0,-0.01967,3.3757,300.57,300.44,310.54,309.85
109.7334,2.8391,-0.17979,36.297,300.0,-0.019771,3.3701,300.24,299.85,310.11,308.97
110.5334,2.8524,-0.18099,36.941,300.0,-0.019939,3.3868,299.96,299.55,309.74,308.37
111.3334,2.8463,-0.18268,37.787,300.0,-0.020087,3.3787,299.79,299.56,309.61,308.2
112.1334,2.8601,-0.18385,37.656,300.0,-0.020218,3.395,299.87,299.76,309.68,308.39
112.9334,2.8545,-0.1848,37.09,300.0,-0.020356,3.3871,300.04,299.83,309.81,308.6
113.7334,2.8486,-0.18554,36.673,300.0,-0.020398,3.3793,300.11,299.85,309.91,308.69
114.5334,2.8582,-0.18621,36.708,300.0,-0.020474,3.3904,300.11,299.8,309.86,308.63
115.3334,2.8597,-0.18756,37.023,300.0,-0.020663,3.3918,300.0,299.77,309.76,308.49
116.1334,2.8553,-0.18899,36.685,300.0,-0.020753,3.3869,300.03,299.77,309.7,308.37
116.9334,2.8684,-0.19083,36.497,300.0,-0.02097,3.4028,300.04,299.81,309.65,308.3
117.7334,2.8658,-0.19111,36.666,300.0,-0.021066,3.4007,300.02,299.81,309.59,308.24
118.5334,2.8572,-0.19036,36.46,300.0,-0.020929,3.3919,300.08,299.83,309.49,308.19
119.3334,2.8574,-0.19036,36.427,300.0,-0.020929,3.3917,300.03,299.85,309.46,308.14
120.1334,2.8622,-0.19126,36.31,300.0,-0.021058,3.3985,300.07,299.76,309.38,308.1
120.9334,2.8652,-0.19244,36.491,300.0,-0.021144,3.4022,300.03,299.79,309.31,307.94
121.7334,2.8497,-0.19349,36.493,300.0,-0.021264,3.3826,300.01,299.78,309.17,307.82
122.5334,2.8611,-0.19447,36.341,300.0,-0.021402,3.3961,300.01,299.73,308.99,307.62
123.3334,2.8478,-0.1956,36.383,300.0,-0.021492,3.3797,300.03,299.69,308.94,307.59
124.1334,2.842,-0.19658,36.344,300.0,-0.021605,3.3718,300.02,299.75,308.87,307.55
124.9334,2.8522,-0.19755,36.394,300.0,-0.02173,3.3837,300.02,299.72,308.74,307.39
125.7334,2.8674,-0.19849,36.442,300.0,-0.021804,3.4013,300.02,299.75,308.64,307.26
126.5334,2.8549,-0.19978,36.279,300.0,-0.021954,3.3861,300.07,299.8,308.55,307.28
127.3334,2.8631,-0.2018,35.977,300.0,-0.022188,3.3967,300.1,299.8,308.45,307.21
128.1334,2.8767,-0.20262,35.611,300.0,-0.022267,3.4134,300.16,299.71,308.43,307.1
128.9334,2.8657,-0.20094,35.498,300.0,-0.022089,3.4022,300.12,299.68,308.27,306.98
129.7334,2.873,-0.20142,35.49,300.0,-0.022153,3.4112,300.13,299.65,308.1,306.76
130.5334,2.8641,-0.20266,35.468,300.0,-0.022264,3.4007,300.1,299.52,307.93,306.59
131.3334,2.8633,-0.20345,35.264,300.0,-0.022359,3.3992,300.1,299.46,307.78,306.45
132.1334,2.8569,-0.20449,34.935,300.0,-0.022482,3.3917,300.13,299.4,307.53,306.27
132.9334,2.8671,-0.20547,35.045,300.0,-0.022571,3.4032,300.11,299.25,307.38,306.04
133.6114,2.8567,-0.20612,34.974,300.0,-0.022637,3.3896,300.12,299.23,307.2,305.89
134.4114,2.869,-0.20671,34.969,300.0,-0.022738,3.4055,300.06,299.1,306.99,305.65
135.2114,2.8645,-0.2077,34.75,300.0,-0.022808,3.401,300.08,298.97,306.77,305.46
136.0114,2.8654,-0.20859,34.676,300.0,-0.022909,3.4021,300.08,298.82,306.5,305.24
136.8114,2.8636,-0.20948,34.991,300.0,-0.023045,3.3998,300.0,298.75,306.25,305.02
137.6114,2.8545,-0.21076,34.652,300.0,-0.023131,3.3887,300.04,298.77,306.13,304.91
138.4114,2.8502,-0.21154,34.964,300.0,-0.023236,3.3826,299.98,298.63,305.91,304.7
139.2114,2.8494,-0.21259,34.768,300.0,-0.023363,3.3818,300.04,298.59,305.72,304.51
140.0114,2.8566,-0.21378,34.654,300.0,-0.023461,3.3889,300.04,298.5,305.5,304.34
140.8114,2.8672,-0.21525,34.698,300.0,-0.023644,3.401,300.06,298.4,305.33,304.18
141.6114,2.865,-0.21577,34.655,300.0,-0.023724,3.3989,300.06,298.29,305.13,304.08
142.4114,2.8528,-0.21532,34.651,300.0,-0.023671,3.3849,300.06,298.19,304.93,303.82
143.2114,2.8766,-0.21508,34.637,300.0,-0.023653,3.413,300.01,298.11,304.77,303.66
144.0114,2.8733,-0.21557,34.651,300.0,-0.023685,3.4096,300.04,298.03,304.58,303.5
144.8114,2.8741,-0.21645,34.641,300.0,-0.023775,3.4105,300.03,297.94,304.36,303.3
145.28053,2.8651,0.011819,0.58875,52.335,0.0015788,3.4076,299.95,297.68,304.19,303.15
145.28185,2.8812,0.012174,0.0,0.00016607,0.0013891,3.4202,299.97,297.68,304.21,303.14
145.28317,2.7734,0.01055,0.0,4.9553e-10,0.00055355,3.2924,300.0,297.69,304.23,303.14
145.28449,2.8959,0.014835,0.0,1.4218e-15,0.0019842,3.4472,300.02,297.69,304.25,303.13
145.28581,2.8792,0.0183,0.0,3.9694999999999996e-21,0.00067785,3.4179,300.05,297.7,304.27,303.13
145.28713,2.8075,0.013501,0.0,1.0863e-26,0.001835,3.3333,300.07,297.7,304.29,303.13
145.28845,2.8684,0.018594,0.0,4.8900000000000005e-32,0.0017267,3.4191,300.1,297.7,304.31,303.12
145.28977,2.881,0.013903,0.0,3.1341e-37,0.00098353,3.4175,300.12,297.71,304.33,303.12
145.29109,2.8199,0.011829,0.0,1.2219e-42,0.0025195,3.3458,300.13,297.72,304.34,303.12
145.29241,2.8765,0.0088753,0.0,0.0,0.0012059,3.4261,300.12,297.73,304.33,303.12
145.29373,2.8881,0.010774,0.0,0.0,0.0016803,3.4225,300.1,297.75,304.31,303.12
145.29505,2.8393,0.009759,0.0,0.0,0.001786,3.3592,300.08,297.76,304.3,303.12
145.29637,2.8823,0.010073,0.0,0.0,0.0012618,3.4271,300.07,297.78,304.29,303.12
145.29769,2.8919,0.01406,0.0,0.0,0.0011844,3.419,300.05,297.8,304.28,303.12
145.29901,2.8274,0.016373,0.0,0.0,0.0017206,3.3506,300.03,297.81,304.27,303.12
145.30033,2.879,0.0121,0.0,0.0,5.9263e-05,3.4223,300.02,297.83,304.25,303.12
145.30165,2.8949,0.014493,0.0,0.0,0.0022,3.424,300.01,297.83,304.26,303.12
145.30297,2.8232,0.013306,0.0,0.0,2.7644e-05,3.3477,300.01,297.83,304.26,303.12
145.30429,2.8752,0.013528,0.0,0.0,0.0015482,3.4271,300.01,297.83,304.27,303.12
145.30561,2.8892,0.011127,0.0,0.0,0.0013017,3.4184,300.01,297.83,304.28,303.12
145.30693,2.821,0.012991,0.0,0.0,0.0010848,3.342,300.01,297.83,304.29,303.12
145.30825,2.8856,0.0088916,0.0,0.0,0.0020141,3.4335,300.01,297.83,304.3,303.12
145.30957,2.8908,0.0076241,0.0,0.0,0.0018507,3.4173,300.01,297.83,304.3,303.12
145.31089,2.814,0.0088764,0.0,0.0,0.00089432,3.3416,300.01,297.83,304.31,303.12
145.31221,2.8666,0.014812,0.0,0.0,0.0019655,3.4206,300.02,297.83,304.31,303.12
145.31353,2.8863,0.012725,0.0,0.0,0.0011782,3.4134,300.02,297.83,304.31,303.12
145.31485,2.8245,0.014561,0.0,0.0,0.0011107,3.3567,300.03,297.83,304.31,303.12
145.31617,2.8767,0.014956,0.0,0.0,0.0021192,3.4274,300.03,297.83,304.31,303.12
145.31749,2.8936,0.014774,0.0,0.0,0.00046008,3.4299,300.03,297.83,304.31,303.12
145.31881,2.8275,0.012713,0.0,0.0,0.0021081,3.3534,300.04,297.83,304.31,303.12
145.32013,2.8799,0.013556,0.0,0.0,0.00045819,3.4336,300.04,297.83,304.31,303.12
145.32145,2.8944,0.01215,0.0,0.0,0.0013127,3.4335,300.04,297.83,304.3,303.12
145.32277,2.8141,0.0066777,0.0,0.0,0.00135,3.3384,300.04,297.83,304.28,303.13
145.32409,2.874,0.0090227,0.0,0.0,0.0011114,3.4149,300.04,297.83,304.26,303.14
145.32541,2.8865,0.011741,0.0,0.0,0.0012575,3.4168,300.04,297.83,304.24,303.14
145.32673,2.8299,0.01176,0.0,0.0,0.0019851,3.347,300.04,297.83,304.22,303.15
145.32805,2.8739,0.012687,0.0,0.0,0.00083742,3.4179,300.04,297.83,304.2,303.16
145.32937,2.8782,0.013806,0.0,0.0,0.0016751,3.4137,300.04,297.83,304.18,303.17
145.33069,2.8173,0.015282,0.0,0.0,0.0015725,3.3395,300.04,297.83,304.16,303.18
145.33201,2.8713,0.011143,0.0,0.0,0.00061544,3.4271,300.03,297.83,304.16,303.19
145.33333,2.9093,0.016,0.0,0.0,0.0025932,3.4419,300.02,297.83,304.16,303.2
145.33465,2.782,0.013844,0.0,0.0,0.00074704,3.3072,300.01,297.83,304.16,303.21
145.33597,2.9075,0.011671,0.0,0.0,0.0020053,3.4503,300.0,297.83,304.16,303.23
145.33729,3.2388,0.0099543,0.0,0.0,0.0012607,3.8006,299.98,297.83,304.16,303.24
145.33861,2.6018,0.0069362,0.0,0.0,0.00086847,3.0977,299.97,297.83,304.16,303.25
145.33993,2.9719,0.012111,0.0,0.0,0.0015017,3.5667,299.96,297.83,304.16,303.26
145.34125,2.9651,0.0081801,0.0,0.0,0.0010284,3.4991,300.64,298.52,304.16,303.25
145.34257,2.7286,0.008999,0.0,0.0,6.8464e-05,3.2153,302.27,300.17,304.15,303.2
145.34389,2.6319,0.01072,0.0,0.0,0.0015231,3.1334,303.91,301.82,304.15,303.15
145.34521,2.8336,0.0093987,0.0,0.0,0.00020373,3.3885,305.55,303.46,304.14,303.1
145.34653,2.8178,0.007803,0.0,0.0,0.00089431,3.3423,307.19,305.11,304.14,303.05
145.34785,2.7275,0.012592,0.0,0.0,0.0012377,3.2769,308.83,306.76,304.14,303.01
145.34917,3.0019,0.012804,0.0,0.0,0.00077913,3.5675,310.47,308.41,304.13,302.96
145.35049,2.67,0.0088386,0.0,0.0,0.0019825,3.1179,312.11,310.06,304.13,302.91
145.35181,31.752,0.12871,0.0,0.0,0.012631,32.762,315.01,312.78,304.13,302.9
145.35313,93.828,0.46246,0.0,0.0,0.050057,110.99,318.16,315.71,304.13,302.89
145.35445,114.04,0.72496,0.0,0.0,0.082214,134.67,321.3,318.64,304.13,302.89
145.35577,119.58,1.3294,0.0,0.0,0.15408,141.08,324.45,321.57,304.13,302.88
145.35709,124.3,1.8783,0.0,0.0,0.22628,147.43,327.59,324.5,304.13,302.88
145.35841,128.34,2.4251,0.0,0.0,0.30419,152.09,330.74,327.43,304.13,302.88
145.35973,130.66,2.9886,0.0,0.0,0.38773,154.93,333.88,330.36,304.13,302.87
145.36105,132.83,3.556,0.0,0.0,0.48218,157.52,336.81,333.08,304.14,302.88
145.36237,134.37,4.0994,0.0,0.0,0.57708,159.37,339.15,335.23,304.2,302.9
145.36369,135.63,4.6029,0.0,0.0,0.67724,160.95,341.49,337.39,304.26,302.92
145.36501,136.35,5.0723,0.0,0.0,0.77713,161.82,343.83,339.54,304.33,302.95
145.36633,136.59,5.4949,0.0,0.0,0.87507,162.01,346.17,341.69,304.39,302.97
145.36765,137.06,5.8896,0.0,0.0,0.97858,162.66,348.51,343.84,304.45,303.0
145.36897,137.99,6.2487,0.0,0.0,1.0784,163.73,350.85,345.99,304.51,303.02
145.37029,138.96,6.5765,0.0,0.0,1.1743,164.83,353.18,348.14,304.57,303.05
145.37161,140.29,6.8831,0.0,0.0,1.2786,166.39,353.79,348.99,304.59,303.04
145.37293,141.67,7.1797,0.0,0.0,1.3833,168.01,353.61,349.25,304.6,303.01
145.37425,143.33,7.4668,0.0,0.0,1.4943,169.97,353.42,349.51,304.61,302.99
145.37557,145.14,7.7438,0.0,0.0,1.6263,172.14,353.24,349.77,304.62,302.96
145.37689,139.68,7.9785,0.0,0.0,1.7341,166.92,353.06,350.03,304.62,302.94
145.37821,129.52,8.0168,0.0,0.0,1.7668,154.24,352.88,350.29,304.63,302.92
145.37953,126.6,8.0388,0.0,0.0,1.7732,150.36,352.7,350.56,304.64,302.89
145.38085,123.31,8.0429,0.0,0.0,1.7767,146.54,352.35,350.66,304.64,302.87
145.38217,120.18,8.048,0.0,0.0,1.7855,142.75,350.7,349.53,304.55,302.85
145.38349,117.98,8.0474,0.0,0.0,1.7809,140.08,349.04,348.41,304.46,302.84
145.38481,116.19,8.0463,0.0,0.0,1.7851,137.99,347.38,347.28,304.37,302.82
145.38613,114.58,8.0506,0.0,0.0,1.791,136.03,345.72,346.15,304.28,302.8
145.38745,113.2,8.0708,0.0,0.0,1.7907,134.39,344.06,345.03,304.19,302.79
145.38877,111.89,8.0731,0.0,0.0,1.7959,132.83,342.4,343.9,304.1,302.77
145.39009,110.84,8.0688,0.0,0.0,1.7964,131.58,340.74,342.77,304.02,302.75
145.39141,109.93,8.0716,0.0,0.0,1.7885,130.53,339.45,341.75,303.96,302.76
145.39273,108.99,8.0744,0.0,0.0,1.7995,129.38,338.48,340.81,303.94,302.77
145.39405,108.17,8.0712,0.0,0.0,1.7899,128.41,337.51,339.87,303.92,302.79
145.39537,107.45,8.0751,0.0,0.0,1.7977,127.54,336.54,338.93,303.9,302.8
145.39669,106.7,8.0823,0.0,0.0,1.8,126.66,335.57,337.99,303.88,302.82
145.39801,106.03,8.0746,0.0,0.0,1.7938,125.86,334.59,337.05,303.86,302.84
145.39933,105.46,8.0724,0.0,0.0,1.7997,125.17,333.62,336.11,303.84,302.85
145.40065,104.88,8.0788,0.0,0.0,1.8016,124.49,332.65,335.17,303.82,302.87
145.40197,104.32,8.0846,0.0,0.0,1.7967,123.82,332.06,334.41,303.88,302.9
145.40329,103.82,8.0799,0.0,0.0,1.8048,123.23,331.48,333.65,303.93,302.93
145.40461,103.31,8.0835,0.0,0.0,1.7993,122.62,330.9,332.89,303.99,302.95
145.40593,102.84,8.0872,0.0,0.0,1.8016,122.06,330.32,332.13,304.05,302.98
145.40725,102.42,8.0823,0.0,0.0,1.8054,121.56,329.74,331.37,304.1,303.01
145.40857,101.94,8.0847,0.0,0.0,1.7962,120.98,329.16,330.61,304.16,303.04
145.40989,101.45,8.0883,0.0,0.0,1.8082,120.43,328.58,329.85,304.22,303.07
145.41121,101.09,8.0884,0.0,0.0,1.8024,119.98,328.06,329.18,304.25,303.08
145.41253,100.69,8.0787,0.0,0.0,1.8008,119.5,327.62,328.65,304.27,303.08
145.41385,100.3,8.0813,0.0,0.0,1.8037,119.05,327.19,328.12,304.28,303.08
145.41517,99.91,8.0869,0.0,0.0,1.7998,118.6,326.75,327.59,304.29,303.08
145.41649,99.091,8.0834,0.0,0.0,1.7991,117.64,326.32,327.05,304.3,303.08
145.41781,97.636,8.082,0.0,0.0,1.8048,115.96,325.89,326.52,304.32,303.08
145.41913,95.409,8.0884,0.0,0.0,1.7956,113.35,325.45,325.99,304.33,303.08
145.42045,92.314,8.0784,0.0,0.0,1.8022,109.73,325.02,325.46,304.34,303.08
145.42177,73.682,8.0414,0.0,0.0,1.7804,90.314,324.77,325.21,304.35,303.09
145.42309,24.676,7.9379,0.0,0.0,1.7221,30.857,324.56,325.02,304.36,303.1
145.42441,-2.0029,7.828,0.0,0.0,1.6769,-2.1332,324.35,324.83,304.38,303.11
145.42573,0.56267,7.7285,0.0,0.0,1.6179,0.79404,324.14,324.64,304.39,303.12
145.42705,0.60641,7.8113,0.0,0.0,1.6637,0.3547,323.93,324.45,304.4,303.12
145.42837,4.457,7.8987,0.0,0.0,1.7087,5.943,323.72,324.26,304.41,303.13
145.42969,0.9555,7.839,0.0,0.0,1.672,1.0024,323.51,324.07,304.42,303.14
145.43101,2.666,7.871,0.0,0.0,1.6937,3.4739,323.36,323.94,304.43,303.15
145.43233,3.0725,7.8776,0.0,0.0,1.6874,3.3904,323.43,323.97,304.41,303.17
145.43365,2.1091,7.8696,0.0,0.0,1.6817,2.5738,323.49,324.0,304.39,303.18
145.43497,2.1557,7.8792,0.0,0.0,1.6986,2.4628,323.56,324.03,304.37,303.2
145.43629,2.5307,7.8781,0.0,0.0,1.687,3.068,323.62,324.07,304.35,303.21
145.43761,2.1996,7.8845,0.0,0.0,1.696,2.5296,323.69,324.1,304.33,303.23
145.43893,2.1907,7.8818,0.0,0.0,1.6957,2.635,323.75,324.13,304.31,303.25
145.44025,2.5337,7.8836,0.0,0.0,1.6935,2.9572,323.82,324.16,304.29,303.26
145.44157,2.0587,7.8809,0.0,0.0,1.6985,2.4822,323.9,324.21,304.26,303.25
145.44289,2.5164,7.8783,0.0,0.0,1.6954,3.007,324.0,324.27,304.24,303.22
145.44421,2.3049,7.8705,0.0,0.0,1.6956,2.7202,324.09,324.32,304.22,303.19
145.44553,2.3843,7.8754,0.0,0.0,1.6978,2.8468,324.19,324.38,304.19,303.16
145.44685,2.4019,7.8777,0.0,0.0,1.6903,2.8218,324.29,324.44,304.17,303.14
145.44817,2.3489,7.8735,0.0,0.0,1.6904,2.755,324.38,324.49,304.14,303.11
145.44949,2.2028,7.8779,0.0,0.0,1.6952,2.6167,324.48,324.55,304.12,303.08
145.45081,2.4265,7.8804,0.0,0.0,1.6857,2.9246,324.57,324.6,304.1,303.05
145.45213,2.4484,7.8778,0.0,0.0,1.6964,2.8906,324.64,324.67,304.13,303.05
145.45345,2.2239,7.875,0.0,0.0,1.6879,2.6167,324.71,324.73,304.16,303.04
145.45477,2.3826,7.8781,0.0,0.0,1.6906,2.8333,324.78,324.8,304.2,303.03
145.45609,2.4839,7.8774,0.0,0.0,1.6948,2.935,324.85,324.86,304.23,303.02
145.45741,2.2811,7.8704,0.0,0.0,1.6901,2.7172,324.92,324.93,304.26,303.01
145.45873,2.3926,7.8732,0.0,0.0,1.6943,2.8615,324.98,324.99,304.29,303.0
145.46005,2.5035,7.8747,0.0,0.0,1.6944,2.9392,325.05,325.06,304.33,303.0
145.46137,2.2902,7.874,0.0,0.0,1.6904,2.7049,325.13,325.1,304.34,303.0
145.46269,2.4105,7.8755,0.0,0.0,1.6971,2.892,325.21,325.12,304.34,303.02
145.46401,2.4601,7.8793,0.0,0.0,1.6926,2.9075,325.29,325.14,304.33,303.03
145.46533,2.3149,7.8766,0.0,0.0,1.6891,2.7462,325.37,325.16,304.33,303.05
145.46665,2.4407,7.8746,0.0,0.0,1.6973,2.9052,325.45,325.18,304.32,303.07
145.46797,2.3879,7.8775,0.0,0.0,1.6838,2.8019,325.53,325.2,304.32,303.08
145.46929,2.3148,7.8798,0.0,0.0,1.695,2.7681,325.61,325.22,304.32,303.1
145.47061,2.5236,7.8734,0.0,0.0,1.6905,3.004,325.69,325.24,304.31,303.11
145.47193,2.4403,7.872,0.0,0.0,1.6897,2.8572,325.71,325.23,304.31,303.12
145.47325,2.3309,7.8743,0.0,0.0,1.6938,2.7878,325.72,325.22,304.32,303.12
145.47457,2.4826,7.8726,0.0,0.0,1.6898,2.9775,325.73,325.22,304.32,303.13
145.47589,2.4731,7.8696,0.0,0.0,1.6884,2.9131,325.74,325.21,304.33,303.13
145.47721,2.2887,7.8771,0.0,0.0,1.6968,2.7053,325.76,325.2,304.33,303.14
145.47853,2.478,7.877,0.0,0.0,1.6863,2.9528,325.77,325.19,304.34,303.14
145.47985,2.4962,7.8725,0.0,0.0,1.6944,2.9275,325.78,325.18,304.34,303.14
145.48117,2.3636,7.8752,0.0,0.0,1.6935,2.7966,325.78,325.18,304.34,303.15
145.48249,2.4544,7.8768,0.0,0.0,1.6878,2.914,325.77,325.19,304.35,303.15
145.48381,2.4306,7.875,0.0,0.0,1.6975,2.8764,325.75,325.2,304.35,303.15
145.48513,2.4322,7.8724,0.0,0.0,1.6871,2.8984,325.73,325.21,304.36,303.15
145.48645,2.547,7.8761,0.0,0.0,1.6934,3.0224,325.72,325.21,304.36,303.15
145.48777,2.4383,7.8691,0.0,0.0,1.6914,2.8693,325.7,325.22,304.36,303.15
145.48909,2.3436,7.866,0.0,0.0,1.6878,2.8111,325.69,325.23,304.37,303.15
145.49041,2.5458,7.87,0.0,0.0,1.6901,3.0539,325.67,325.24,304.37,303.15
145.49173,2.5514,7.8756,0.0,0.0,1.6898,2.9919,325.66,325.22,304.36,303.14
145.49305,2.4517,7.8721,0.0,0.0,1.6846,2.9063,325.64,325.2,304.34,303.12
145.49437,2.5642,7.8743,0.0,0.0,1.6955,3.0561,325.63,325.17,304.33,303.11
145.49569,2.5431,7.8752,0.0,0.0,1.6872,2.9905,325.62,325.15,304.31,303.1
145.49701,2.4254,7.8736,0.0,0.0,1.6917,2.8958,325.61,325.12,304.3,303.09
145.49833,2.6253,7.8727,0.0,0.0,1.6951,3.1171,325.6,325.1,304.28,303.08
145.49965,2.5257,7.8759,0.0,0.0,1.6873,2.9803,325.58,325.08,304.26,303.06
145.50097,2.4409,7.8747,0.0,0.0,1.6968,2.9171,325.58,325.05,304.25,303.05
145.50229,2.6537,7.8666,0.0,0.0,1.6917,3.1634,325.59,325.02,304.25,303.04
145.50361,2.6108,7.8676,0.0,0.0,1.6913,3.0308,325.6,324.99,304.25,303.04
145.50493,2.3693,7.8718,0.0,0.0,1.6927,2.8123,325.61,324.97,304.25,303.03
145.50625,2.6247,7.8735,0.0,0.0,1.6905,3.1476,325.63,324.94,304.25,303.02
145.50757,2.5986,7.869,0.0,0.0,1.6862,3.0441,325.64,324.91,304.25,303.01
145.50889,2.2184,7.8771,0.0,0.0,1.6938,2.6838,325.65,324.88,304.25,303.0
145.51021,2.7235,7.8758,0.0,0.0,1.6838,3.281,325.66,324.85,304.25,303.0
145.51153,2.6723,7.872,0.0,0.0,1.6943,3.1096,325.67,324.81,304.26,303.0
145.51285,2.2597,7.8744,0.0,0.0,1.6881,2.7201,325.67,324.76,304.26,303.01
145.51417,2.7811,7.8822,0.0,0.0,1.6912,3.3392,325.67,324.72,304.27,303.01
145.51549,2.5916,7.8672,0.0,0.0,1.6946,2.9691,325.67,324.67,304.28,303.02
145.51681,2.2474,7.8714,0.0,0.0,1.6901,2.6754,325.67,324.62,304.29,303.03
145.51813,2.6447,7.872,0.0,0.0,1.6927,3.1647,325.67,324.57,304.3,303.04
145.51945,2.5881,7.8678,0.0,0.0,1.6929,3.0302,325.67,324.52,304.3,303.05
145.52077,2.275,7.8692,0.0,0.0,1.6895,2.7177,325.66,324.47,304.31,303.06
145.52209,2.6918,7.8762,0.0,0.0,1.6936,3.2256,325.62,324.42,304.32,303.08
145.52341,2.5818,7.8763,0.0,0.0,1.6911,3.0247,325.58,324.37,304.32,303.1
145.52473,2.2828,7.8736,0.0,0.0,1.6862,2.7467,325.53,324.32,304.32,303.13
145.52605,2.6553,7.873,0.0,0.0,1.6956,3.173,325.49,324.27,304.33,303.15
145.52737,2.5702,7.8752,0.0,0.0,1.6824,2.9836,325.44,324.21,304.33,303.18
145.52869,2.3576,7.8765,0.0,0.0,1.6934,2.8067,325.4,324.16,304.34,303.2
145.53001,2.6089,7.8738,0.0,0.0,1.691,3.136,325.35,324.11,304.34,303.23
145.53133,2.5525,7.8756,0.0,0.0,1.6887,3.0043,325.31,324.06,304.35,303.23
145.53265,2.3823,7.8708,0.0,0.0,1.6958,2.8577,325.28,324.02,304.35,303.23
145.53397,2.6599,7.8692,0.0,0.0,1.6929,3.1743,325.24,323.98,304.36,303.22
145.53529,2.5557,7.8671,0.0,0.0,1.6877,3.0001,325.2,323.94,304.37,303.21
145.53661,2.3381,7.877,0.0,0.0,1.697,2.7948,325.17,323.9,304.38,303.2
145.53793,2.6725,7.8736,0.0,0.0,1.6893,3.1908,325.13,323.86,304.39,303.19
145.53925,2.5778,7.8732,0.0,0.0,1.6915,3.0181,325.1,323.82,304.39,303.19
145.54057,2.3888,7.8751,0.0,0.0,1.6938,2.8378,325.06,323.78,304.4,303.18
145.54189,2.6869,7.8767,0.0,0.0,1.6871,3.2173,325.03,323.71,304.41,303.17
145.54321,2.5987,7.8689,0.0,0.0,1.6943,3.0482,325.0,323.64,304.43,303.16
145.54453,2.3893,7.877,0.0,0.0,1.6851,2.8528,324.96,323.57,304.44,303.15
145.54585,2.7159,7.8769,0.0,0.0,1.6904,3.2628,324.93,323.49,304.45,303.15
145.54717,2.6215,7.8664,0.0,0.0,1.6911,3.0798,324.9,323.42,304.46,303.14
145.54849,2.3999,7.8687,0.0,0.0,1.6884,2.8506,324.87,323.35,304.47,303.13
145.54981,2.7072,7.8721,0.0,0.0,1.6904,3.235,324.83,323.28,304.49,303.12
145.55113,2.6035,7.8713,0.0,0.0,1.6933,3.049,324.8,323.2,304.49,303.12
145.55245,2.4255,7.8718,0.0,0.0,1.6867,2.8868,324.76,323.13,304.47,303.13
145.55377,2.7087,7.876,0.0,0.0,1.6952,3.2344,324.72,323.06,304.45,303.13
145.55509,2.6049,7.8727,0.0,0.0,1.6886,3.0649,324.68,322.99,304.43,303.14
145.55641,2.3964,7.871,0.0,0.0,1.6895,2.8708,324.64,322.91,304.41,303.15
145.55773,2.7289,7.8761,0.0,0.0,1.6968,3.2555,324.6,322.84,304.39,303.16
145.55905,2.6316,7.8723,0.0,0.0,1.6847,3.0809,324.56,322.77,304.37,303.17
145.56037,2.4022,7.8721,0.0,0.0,1.6953,2.8617,324.52,322.7,304.35,303.17
145.56169,2.7049,7.8677,0.0,0.0,1.6892,3.226,324.49,322.63,304.33,303.18
145.56301,2.6411,7.8678,0.0,0.0,1.6866,3.0829,324.47,322.57,304.32,303.19
145.56433,2.4199,7.8686,0.0,0.0,1.6915,2.8814,324.44,322.5,304.31,303.2
145.56565,2.729,7.8674,0.0,0.0,1.6884,3.2647,324.42,322.44,304.3,303.21
145.56697,2.6195,7.8698,0.0,0.0,1.6849,3.0789,324.39,322.37,304.28,303.22
145.56829,2.3883,7.8755,0.0,0.0,1.6942,2.8647,324.37,322.31,304.27,303.22
145.56961,2.6949,7.8713,0.0,0.0,1.684,3.233,324.35,322.24,304.26,303.23
145.57093,2.6303,7.8681,0.0,0.0,1.6911,3.0942,324.32,322.18,304.25,303.24
145.57225,2.4073,7.8748,0.0,0.0,1.6904,2.8663,324.27,322.11,304.27,303.23
145.57357,2.7012,7.8721,0.0,0.0,1.6873,3.2307,324.22,322.03,304.29,303.22
145.57489,2.6355,7.8681,0.0,0.0,1.695,3.0881,324.17,321.96,304.3,303.21
145.57621,2.3806,7.8727,0.0,0.0,1.6892,2.8304,324.12,321.89,304.32,303.2
145.57753,2.6988,7.868,0.0,0.0,1.6913,3.2263,324.08,321.82,304.33,303.2
145.57885,2.5932,7.8621,0.0,0.0,1.6921,3.0444,324.03,321.74,304.35,303.19
145.58017,2.3405,7.8652,0.0,0.0,1.6864,2.8147,323.98,321.67,304.37,303.18
145.58149,2.6909,7.874,0.0,0.0,1.6894,3.2183,323.92,321.59,304.37,303.18
145.58281,2.5955,7.8689,0.0,0.0,1.6898,3.0408,323.84,321.5,304.37,303.18
145.58413,2.3769,7.871,0.0,0.0,1.6837,2.8223,323.77,321.4,304.37,303.18
145.58545,2.6771,7.8731,0.0,0.0,1.6933,3.1981,323.7,321.31,304.37,303.18
145.58677,2.5634,7.873,0.0,0.0,1.6846,3.0031,323.63,321.22,304.37,303.18
145.58809,2.3925,7.869,0.0,0.0,1.6895,2.8596,323.55,321.13,304.37,303.18
145.58941,2.6837,7.8752,0.0,0.0,1.6923,3.1968,323.48,321.03,304.37,303.18
145.59073,2.61,7.8704,0.0,0.0,1.6851,3.0696,323.41,320.94,304.37,303.18
145.59205,2.3631,7.8679,0.0,0.0,1.6979,2.8177,323.35,320.84,304.37,303.18
145.59337,2.6786,7.8653,0.0,0.0,1.6914,3.193,323.3,320.73,304.37,303.19
145.59469,2.6026,7.8698,0.0,0.0,1.6887,3.0565,323.24,320.63,304.37,303.2
145.59601,2.383,7.8665,0.0,0.0,1.6923,2.8354,323.18,320.52,304.37,303.21
145.59733,2.6835,7.8719,0.0,0.0,1.6891,3.2044,323.13,320.42,304.37,303.22
145.59865,2.5895,7.8707,0.0,0.0,1.6862,3.039,323.07,320.31,304.37,303.23
145.59997,2.3641,7.8756,0.0,0.0,1.6942,2.818,323.02,320.21,304.37,303.23
145.60129,2.6925,7.8684,0.0,0.0,1.6821,3.2215,322.96,320.11,304.37,303.24
145.60261,2.6103,7.8724,0.0,0.0,1.6924,3.0582,322.9,320.02,304.38,303.25
145.60393,2.3588,7.8756,0.0,0.0,1.6858,2.8106,322.85,319.93,304.38,303.26
145.60525,2.6762,7.8713,0.0,0.0,1.688,3.2133,322.79,319.84,304.39,303.27
145.60657,2.6008,7.8645,0.0,0.0,1.6901,3.0608,322.73,319.76,304.39,303.27
145.60789,2.3869,7.8716,0.0,0.0,1.6887,2.8464,322.68,319.67,304.39,303.28
145.60921,2.6671,7.8687,0.0,0.0,1.6919,3.1907,322.62,319.58,304.4,303.29
145.61053,2.6152,7.8658,0.0,0.0,1.6938,3.0682,322.56,319.49,304.4,303.3
145.61185,2.392,7.8728,0.0,0.0,1.6875,2.8554,322.51,319.4,304.41,303.31
145.61317,2.7249,7.8782,0.0,0.0,1.6945,3.2581,322.46,319.32,304.41,303.31
145.61449,2.6242,7.8695,0.0,0.0,1.6901,3.0829,322.41,319.24,304.41,303.32
145.61581,2.4179,7.8741,0.0,0.0,1.688,2.877,322.36,319.15,304.42,303.33
145.61713,2.7077,7.8754,0.0,0.0,1.6954,3.2351,322.3,319.07,304.42,303.34
145.61845,2.6221,7.8746,0.0,0.0,1.6864,3.0791,322.25,318.98,304.43,303.35
145.61977,2.411,7.8698,0.0,0.0,1.6914,2.8668,322.2,318.9,304.43,303.36
145.62109,2.7121,7.8755,0.0,0.0,1.69,3.2394,322.14,318.82,304.44,303.36
145.62241,2.6138,7.8666,0.0,0.0,1.6853,3.0601,322.08,318.75,304.45,303.35
145.62373,2.3743,7.8677,0.0,0.0,1.6928,2.8314,322.02,318.68,304.46,303.34
145.62505,2.728,7.8671,0.0,0.0,1.6888,3.2592,321.96,318.61,304.47,303.33
145.62637,2.6427,7.8749,0.0,0.0,1.6867,3.0956,321.9,318.54,304.49,303.33
145.62769,2.4288,7.8748,0.0,0.0,1.6966,2.8918,321.84,318.47,304.5,303.32
145.62901,2.6963,7.872,0.0,0.0,1.6876,3.2228,321.78,318.4,304.51,303.31
145.63033,2.6408,7.8742,0.0,0.0,1.6911,3.0963,321.72,318.34,304.52,303.3
145.63165,2.4297,7.8745,0.0,0.0,1.6937,2.8904,321.65,318.27,304.53,303.31
145.63297,2.7214,7.8727,0.0,0.0,1.6867,3.2392,321.57,318.2,304.53,303.33
145.63429,2.6536,7.874,0.0,0.0,1.6957,3.1082,321.5,318.13,304.53,303.34
145.63561,2.4265,7.8764,0.0,0.0,1.6897,2.887,321.42,318.06,304.53,303.36
145.63693,2.7215,7.8677,0.0,0.0,1.6904,3.2637,321.34,317.99,304.53,303.38
145.63825,2.6676,7.8649,0.0,0.0,1.6914,3.1353,321.27,317.92,304.53,303.39
145.63957,2.4092,7.8699,0.0,0.0,1.6864,2.8686,321.19,317.86,304.53,303.41
145.64089,2.7169,7.8725,0.0,0.0,1.6897,3.2472,321.12,317.79,304.52,303.42
145.64221,2.6372,7.8656,0.0,0.0,1.6895,3.0992,321.06,317.71,304.52,303.43
145.64353,2.4276,7.8769,0.0,0.0,1.6855,2.8873,321.0,317.63,304.52,303.44
145.64485,2.717,7.8735,0.0,0.0,1.6944,3.2639,320.94,317.56,304.51,303.45
145.64617,2.6373,7.8697,0.0,0.0,1.6878,3.0791,320.88,317.48,304.51,303.46
145.64749,2.4007,7.8718,0.0,0.0,1.6884,2.8507,320.81,317.4,304.5,303.46
145.64881,2.7295,7.8778,0.0,0.0,1.6956,3.2742,320.75,317.33,304.5,303.47
145.65013,2.6378,7.8693,0.0,0.0,1.6863,3.1064,320.69,317.25,304.5,303.48
145.65145,2.4152,7.8681,0.0,0.0,1.6958,2.8719,320.64,317.17,304.5,303.48
145.65277,2.732,7.8686,0.0,0.0,1.691,3.2539,320.59,317.1,304.51,303.48
145.65409,2.65,7.868,0.0,0.0,1.6882,3.0963,320.53,317.02,304.52,303.48
145.65541,2.4082,7.8663,0.0,0.0,1.692,2.8694,320.48,316.94,304.52,303.48
145.65673,2.7128,7.8728,0.0,0.0,1.688,3.2428,320.43,316.87,304.53,303.48
145.65805,2.6328,7.8717,0.0,0.0,1.6828,3.0932,320.38,316.79,304.54,303.48
145.65937,2.3983,7.8735,0.0,0.0,1.6953,2.8671,320.32,316.71,304.55,303.48
145.66069,2.7149,7.8688,0.0,0.0,1.6822,3.2443,320.27,316.64,304.56,303.48
145.66201,2.6536,7.8736,0.0,0.0,1.6917,3.1117,320.19,316.55,304.56,303.49
145.66333,2.4121,7.873,0.0,0.0,1.6891,2.8671,320.11,316.47,304.57,303.5
145.66465,2.6956,7.8722,0.0,0.0,1.6882,3.2186,320.03,316.38,304.58,303.51
145.66597,2.6124,7.8713,0.0,0.0,1.6933,3.0539,319.95,316.3,304.59,303.52
145.66729,2.3987,7.8695,0.0,0.0,1.69,2.8543,319.87,316.21,304.6,303.52
145.66861,2.7245,7.865,0.0,0.0,1.6939,3.2577,319.79,316.13,304.6,303.53
145.66993,2.6326,7.865,0.0,0.0,1.6927,3.0974,319.71,316.04,304.61,303.54
145.67125,2.3962,7.8745,0.0,0.0,1.6883,2.8575,319.63,315.96,304.62,303.54
145.67257,2.7166,7.8731,0.0,0.0,1.6912,3.2503,319.55,315.87,304.61,303.53
145.67389,2.6362,7.8693,0.0,0.0,1.6902,3.0845,319.48,315.78,304.61,303.53
145.67521,2.4411,7.8731,0.0,0.0,1.6836,2.9079,319.4,315.69,304.6,303.52
145.67653,2.6921,7.8746,0.0,0.0,1.6953,3.2088,319.32,315.6,304.6,303.51
145.67785,2.648,7.8681,0.0,0.0,1.6834,3.0883,319.25,315.51,304.6,303.5
145.67917,2.3828,7.8742,0.0,0.0,1.6903,2.838,319.17,315.42,304.59,303.49
145.68049,2.7259,7.8747,0.0,0.0,1.6906,3.2655,319.09,315.33,304.59,303.49
145.68181,2.6421,7.8677,0.0,0.0,1.6868,3.0916,319.03,315.25,304.59,303.49
145.68313,2.418,7.8642,0.0,0.0,1.6911,2.8815,318.96,315.16,304.59,303.5
145.68445,2.6964,7.872,0.0,0.0,1.6927,3.228,318.9,315.08,304.6,303.51
145.68577,2.645,7.8677,0.0,0.0,1.6879,3.1009,318.83,314.99,304.6,303.51
145.68709,2.4081,7.8706,0.0,0.0,1.6949,2.8779,318.77,314.91,304.61,303.52
145.68841,2.7204,7.8744,0.0,0.0,1.6896,3.2484,318.7,314.82,304.61,303.53
145.68973,2.6551,7.8733,0.0,0.0,1.6884,3.1129,318.64,314.74,304.61,303.54
145.69105,2.416,7.8713,0.0,0.0,1.6957,2.8743,318.57,314.65,304.62,303.55
145.69237,2.7235,7.8748,0.0,0.0,1.683,3.2667,318.5,314.57,304.63,303.57
145.69369,2.6632,7.8749,0.0,0.0,1.6938,3.1173,318.43,314.48,304.64,303.58
145.69501,2.4397,7.8723,0.0,0.0,1.6891,2.9131,318.35,314.39,304.64,303.6
145.69633,2.7198,7.8697,0.0,0.0,1.6892,3.248,318.28,314.3,304.65,303.61
145.69765,2.6706,7.8678,0.0,0.0,1.69,3.1201,318.21,314.21,304.66,303.63
145.69897,2.4492,7.8712,0.0,0.0,1.6887,2.9193,318.14,314.12,304.67,303.65
145.70029,2.7362,7.8679,0.0,0.0,1.6891,3.2642,318.06,314.03,304.68,303.66
145.70161,2.6706,7.8724,0.0,0.0,1.6941,3.1275,317.99,313.94,304.68,303.67
145.70293,2.4185,7.876,0.0,0.0,1.6854,2.8975,317.93,313.86,304.67,303.68
145.70425,2.7359,7.8734,0.0,0.0,1.6954,3.2842,317.86,313.77,304.67,303.69
145.70557,2.6546,7.8712,0.0,0.0,1.691,3.1249,317.79,313.68,304.66,303.7
145.70689,2.4476,7.8743,0.0,0.0,1.6871,2.9208,317.72,313.59,304.66,303.71
145.70821,2.7233,7.8764,0.0,0.0,1.6975,3.266,317.65,313.5,304.66,303.71
145.70953,2.6851,7.8693,0.0,0.0,1.6844,3.1433,317.58,313.41,304.65,303.72
145.71085,2.4494,7.8751,0.0,0.0,1.6943,2.9224,317.51,313.32,304.65,303.73
145.71217,2.7495,7.8707,0.0,0.0,1.6914,3.2853,317.44,313.24,304.66,303.75
145.71349,2.6652,7.8648,0.0,0.0,1.6871,3.1252,317.37,313.15,304.67,303.76
145.71481,2.4233,7.8663,0.0,0.0,1.69,2.887,317.3,313.07,304.69,303.78
145.71613,2.7387,7.8764,0.0,0.0,1.6891,3.2884,317.22,312.98,304.7,303.8
145.71745,2.6941,7.8715,0.0,0.0,1.6845,3.1627,317.15,312.9,304.71,303.81
145.71877,2.4483,7.8716,0.0,0.0,1.6948,2.9164,317.08,312.81,304.72,303.83
145.72009,2.7333,7.8755,0.0,0.0,1.6858,3.2679,317.01,312.73,304.73,303.84
145.72141,2.6697,7.8725,0.0,0.0,1.692,3.1139,316.93,312.64,304.75,303.86
145.72273,2.4385,7.8711,0.0,0.0,1.6923,2.8988,316.87,312.56,304.76,303.87
145.72405,2.7459,7.8759,0.0,0.0,1.6879,3.2847,316.8,312.48,304.77,303.88
145.72537,2.6839,7.8734,0.0,0.0,1.6959,3.1449,316.73,312.39,304.78,303.9
145.72669,2.4301,7.8684,0.0,0.0,1.6913,2.8964,316.66,312.31,304.79,303.91
145.72801,2.7516,7.8669,0.0,0.0,1.6927,3.3032,316.59,312.22,304.81,303.92
145.72933,2.6671,7.8679,0.0,0.0,1.692,3.127,316.52,312.14,304.82,303.93
145.73065,2.4232,7.873,0.0,0.0,1.6898,2.8935,316.45,312.05,304.83,303.94
145.73197,2.7137,7.8699,0.0,0.0,1.6884,3.2464,316.39,311.99,304.83,303.94
145.73329,2.6553,7.8741,0.0,0.0,1.6912,3.1178,316.32,311.92,304.83,303.94
145.73461,2.416,7.874,0.0,0.0,1.6821,2.8784,316.26,311.86,304.83,303.94
145.73593,2.7316,7.8749,0.0,0.0,1.6963,3.2642,316.2,311.79,304.83,303.94
145.73725,2.6604,7.8697,0.0,0.0,1.684,3.1312,316.13,311.73,304.83,303.94
145.73857,2.44,7.879,0.0,0.0,1.6907,2.9124,316.07,311.66,304.83,303.94
145.73989,2.7195,7.8707,0.0,0.0,1.6941,3.2824,316.0,311.6,304.83,303.94
145.74121,2.6735,7.87,0.0,0.0,1.6885,3.141,315.94,311.53,304.84,303.95
145.74253,2.4478,7.8682,0.0,0.0,1.6921,2.9233,315.87,311.45,304.85,303.97
145.74385,2.7307,7.8722,0.0,0.0,1.6945,3.2587,315.81,311.38,304.86,303.98
145.74517,2.6616,7.8639,0.0,0.0,1.6883,3.1123,315.74,311.3,304.87,304.0
145.74649,2.4359,7.8727,0.0,0.0,1.6945,2.9042,315.68,311.22,304.88,304.02
145.74781,2.7389,7.8778,0.0,0.0,1.6905,3.2806,315.61,311.15,304.9,304.03
145.74913,2.7036,7.8704,0.0,0.0,1.6851,3.1583,315.55,311.07,304.91,304.05
145.75045,2.418,7.8717,0.0,0.0,1.6948,2.8898,315.49,310.99,304.92,304.06
145.75177,2.7302,7.8761,0.0,0.0,1.6829,3.2879,315.42,310.91,304.92,304.07
145.75309,2.6704,7.8713,0.0,0.0,1.6915,3.1412,315.35,310.83,304.92,304.08
145.75441,2.439,7.8719,0.0,0.0,1.6893,2.9026,315.28,310.75,304.92,304.09
145.75573,2.7369,7.875,0.0,0.0,1.6884,3.2725,315.21,310.67,304.92,304.1
145.75705,2.6855,7.8702,0.0,0.0,1.6941,3.1504,315.14,310.59,304.92,304.11
145.75837,2.4299,7.865,0.0,0.0,1.6893,2.8854,315.07,310.51,304.92,304.11
145.75969,2.7427,7.8696,0.0,0.0,1.6899,3.2791,315.01,310.43,304.92,304.12
145.76101,2.6948,7.8716,0.0,0.0,1.6939,3.15,314.94,310.35,304.92,304.13
145.76233,2.4423,7.8752,0.0,0.0,1.6888,2.9136,314.86,310.28,304.92,304.12
145.76365,2.7443,7.871,0.0,0.0,1.6929,3.2802,314.79,310.2,304.91,304.12
145.76497,2.6868,7.8749,0.0,0.0,1.6933,3.1566,314.72,310.13,304.91,304.11
145.76629,2.4606,7.8735,0.0,0.0,1.6858,2.9312,314.65,310.06,304.91,304.11
145.76761,2.7352,7.8739,0.0,0.0,1.6971,3.2606,314.57,309.99,304.9,304.11
145.76893,2.6821,7.8732,0.0,0.0,1.683,3.1272,314.5,309.91,304.9,304.1
145.77025,2.431,7.8783,0.0,0.0,1.6918,2.8756,314.43,309.84,304.89,304.1
145.77157,2.7587,7.8697,0.0,0.0,1.6922,3.2937,314.36,309.77,304.9,304.1
145.77289,2.6904,7.8657,0.0,0.0,1.6865,3.1433,314.3,309.69,304.91,304.11
145.77421,2.4555,7.872,0.0,0.0,1.6918,2.9263,314.24,309.61,304.91,304.12
145.77553,2.7454,7.8715,0.0,0.0,1.691,3.2871,314.18,309.53,304.92,304.13
145.77685,2.6758,7.8696,0.0,0.0,1.6856,3.1469,314.12,309.46,304.93,304.13
145.77817,2.4779,7.8759,0.0,0.0,1.6956,2.9546,314.06,309.38,304.94,304.14
145.77949,2.7522,7.8782,0.0,0.0,1.6894,3.2927,314.0,309.3,304.95,304.15
145.78081,2.6983,7.8718,0.0,0.0,1.6912,3.1527,313.94,309.23,304.95,304.16
146.38105,2.5454,7.8743,0.0,0.0,1.6916,3.0206,290.01,284.6,306.21,298.15
147.18105,2.4934,7.8765,0.0,0.0,1.6928,2.9567,271.83,268.45,304.73,291.49
147.98105,2.4481,7.8782,0.0,0.0,1.6934,2.9044,262.28,259.16,300.25,284.1
148.78105,2.4014,7.8796,0.0,0.0,1.6943,2.8482,255.11,252.03,294.09,276.39
149.58105,2.3565,7.8803,0.0,0.0,1.6947,2.7966,249.08,245.79,287.25,268.51
150.2312,2.3362,7.881,0.0,0.0,1.6948,2.7748,244.71,241.08,281.43,262.23
151.0312,2.3335,7.881,0.0,0.0,1.6951,2.7699,239.58,235.9,274.35,255.17
151.8312,2.3515,7.8811,0.0,0.0,1.6951,2.7914,234.64,230.88,267.13,248.4
152.6312,2.3472,7.8814,0.0,0.0,1.6951,2.7861,229.91,226.0,259.97,241.93
153.4312,2.3508,7.8808,0.0,0.0,1.6949,2.7903,225.38,221.37,253.06,235.49
154.2312,2.3454,7.881,0.0,0.0,1.695,2.7827,220.9,216.97,246.55,229.54
155.0312,2.349,7.881,0.0,0.0,1.6949,2.7868,216.57,212.58,240.35,223.81
155.8312,2.3547,7.8808,0.0,0.0,1.6949,2.7943,212.44,208.38,234.32,218.25
156.6312,2.3714,7.8808,0.0,0.0,1.6948,2.8136,208.28,204.32,228.44,213.04
157.4312,2.3584,7.8809,0.0,0.0,1.6949,2.7976,204.35,200.48,222.97,207.93
158.2312,2.3794,7.8813,0.0,0.0,1.6951,2.8233,200.4,196.56,217.63,203.15
159.0312,2.3647,7.8811,0.0,0.0,1.695,2.8073,196.67,192.91,212.59,198.25
159.8312,2.3685,7.8816,0.0,0.0,1.6953,2.8118,193.08,189.36,207.81,193.8
160.6312,2.3789,7.8818,0.0,0.0,1.6954,2.8243,189.45,185.84,203.02,189.39
161.4312,2.3688,7.8819,0.0,0.0,1.6953,2.8128,186.14,182.44,198.45,185.13
162.2312,2.3664,7.8825,0.0,0.0,1.6958,2.8088,182.74,179.16,194.21,181.24
163.0312,2.3617,7.8827,0.0,0.0,1.6958,2.8031,179.45,176.01,190.0,177.19
163.8312,2.3472,7.8831,0.0,0.0,1.6959,2.7858,176.29,172.89,185.92,173.53
164.6312,2.3599,7.8836,0.0,0.0,1.6964,2.7999,173.27,169.98,182.01,170.06
165.4312,2.3563,7.884,0.0,0.0,1.6965,2.7949,170.27,167.04,178.29,166.45
166.2312,2.3491,7.8849,0.0,0.0,1.6968,2.7859,167.34,164.12,174.59,162.95
167.0312,2.3567,7.8857,0.0,0.0,1.6974,2.7962,164.59,161.41,171.16,159.86
167.8312,2.3534,7.8862,0.0,0.0,1.6977,2.7918,161.78,158.69,167.77,156.62
168.6312,2.3478,7.887,0.0,0.0,1.6978,2.7865,159.15,155.94,164.46,153.5
169.4312,2.355,7.8879,0.0,0.0,1.6985,2.7961,156.51,153.53,161.37,150.59
170.2312,2.3577,7.8883,0.0,0.0,1.6987,2.7987,154.04,150.84,158.23,147.79
171.0312,2.3483,7.8892,0.0,0.0,1.699,2.788,151.51,148.5,155.23,144.97
171.8312,2.351,7.8903,0.0,0.0,1.6997,2.791,149.19,146.24,152.47,142.22
172.6312,2.3578,7.8913,0.0,0.0,1.7002,2.7982,146.75,143.9,149.66,139.63
173.4312,2.3501,7.8919,0.0,0.0,1.7004,2.7895,144.51,141.71,147.02,137.08
174.2312,2.3366,7.8926,0.0,0.0,1.7008,2.7731,142.33,139.5,144.36,134.6
175.0312,2.3408,7.8933,0.0,0.0,1.7011,2.7769,139.99,137.24,141.73,132.1
175.8312,2.3628,7.894,0.0,0.0,1.7015,2.8039,137.94,135.19,139.24,129.84
176.6312,2.3496,7.8948,0.0,0.0,1.7019,2.7872,135.81,133.17,136.84,127.59
177.4312,2.3534,7.8956,0.0,0.0,1.7023,2.7922,133.77,131.11,134.47,125.35
178.2312,2.3572,7.897,0.0,0.0,1.703,2.7972,131.87,129.21,132.26,123.31
179.0312,2.3597,7.8973,0.0,0.0,1.7034,2.8007,129.83,127.28,129.99,121.23
179.6921,2.3423,7.8979,0.0,0.0,1.7035,2.78,128.24,125.67,128.18,119.55
180.4921,2.3638,7.8991,0.0,0.0,1.704,2.8053,126.45,123.98,126.05,117.73
181.2921,2.3559,7.8996,0.0,0.0,1.7045,2.7956,124.67,122.16,124.09,115.73
182.0921,2.3444,7.9009,0.0,0.0,1.7051,2.7819,122.79,120.42,122.03,114.02
182.8921,2.3484,7.9016,0.0,0.0,1.7052,2.7865,121.09,118.82,120.18,112.12
183.6921,2.3582,7.9029,0.0,0.0,1.706,2.797,119.38,117.08,118.25,110.33
184.4921,2.3632,7.9038,0.0,0.0,1.7065,2.8047,117.72,115.47,116.47,108.71
185.2921,2.3696,7.9045,0.0,0.0,1.7067,2.8125,116.17,113.85,114.7,107.07
186.0921,2.3656,7.9053,0.0,0.0,1.7072,2.8077,114.6,112.31,112.92,105.44
186.8921,2.3623,7.9063,0.0,0.0,1.7077,2.8037,112.98,110.78,111.23,103.85
187.6921,2.3593,7.907,0.0,0.0,1.7081,2.8007,111.46,109.39,109.58,102.46
188.4921,2.3632,7.908,0.0,0.0,1.7086,2.8059,110.01,108.05,107.92,100.92
189.2921,2.3531,7.9087,0.0,0.0,1.7089,2.7934,108.51,106.59,106.35,99.493
190.0921,2.3581,7.9097,0.0,0.0,1.7095,2.799,107.13,105.23,104.88,98.048
190.8921,2.2798,7.9134,0.0,0.0,1.7113,2.7061,105.84,103.99,103.4,97.152
191.6921,2.2903,7.9153,0.0,0.0,1.7121,2.7177,106.39,104.36,102.43,99.659
192.4921,2.2754,7.9162,0.0,0.0,1.7128,2.7011,106.51,104.44,102.02,100.31
192.6921,2.2755,7.917,0.0,0.0,1.7133,2.7011,106.51,104.45,101.95,100.41