File: examples/dan-msc-case-studies/CS4/data/01 raw data/hyde_test_022.csv
Time(sec),Force(kN),Jaw(mm),PowAngle(deg),PTemp,Strain,Stress(MPa),TC1(C),TC2(C),TC3(C)
0.0,1.8717,0.0028756,0.0,0.003069,0.00031188,5.6986,21.913,22.566,21.414
1.6,1.8688,0.0032138,0.0,4.621,0.00039991,5.6749,22.015,22.574,21.53
3.2,1.8456,0.0036363,0.0,9.421,0.0003851,5.5961,22.176,22.684,21.676
4.8,1.8229,0.0033246,0.0,14.221,0.00039865,5.5256,22.178,22.71,21.691
6.3907,1.8174,0.0034858,0.0,18.993,0.00041603,5.5086,22.23,22.726,21.702
7.9907,1.8115,0.0045659,16.526,23.793,0.00052724,5.4979,22.345,22.805,21.752
9.5907,1.8151,0.0035794,23.359,28.593,0.00039508,5.51,27.203,26.595,25.344
11.1907,1.8342,0.0010923,24.48,33.393,9.4313e-05,5.5653,32.513,38.011,30.61
12.7907,1.8547,8.8371e-05,25.682,38.193,-3.3356e-05,5.6236,37.553,38.016,35.643
14.3465,1.8447,-0.0022864,26.022,42.861,-0.00024604,5.5992,42.461,41.417,40.625
15.9465,1.8585,-0.0038601,26.146,47.661,-0.00046333,5.6429,47.474,46.023,45.586
17.5465,1.8673,-0.0058531,27.604,52.461,-0.00069853,5.6672,52.095,50.413,50.239
19.1465,1.8825,-0.0079777,27.321,57.261,-0.00082746,5.7085,57.077,55.059,55.135
20.7465,1.8771,-0.011084,27.614,62.061,-0.0012561,5.6919,61.91,59.48,59.942
22.3465,1.8734,-0.011727,28.629,66.861,-0.001376,5.681,66.68,63.902,64.736
23.9465,1.8786,-0.014642,29.083,71.661,-0.0015207,5.7019,71.476,68.585,69.493
25.5465,1.885,-0.016441,29.566,76.461,-0.0017744,5.7219,76.319,72.954,74.329
27.1465,1.8886,-0.019011,30.127,81.261,-0.0021148,5.7297,81.107,77.69,79.257
28.7465,1.8944,-0.021347,30.083,86.061,-0.0022728,5.7469,86.011,82.208,84.143
30.3465,1.8845,-0.02349,30.468,90.861,-0.0025166,5.714,90.819,86.829,89.105
31.9465,1.8816,-0.026102,30.664,95.661,-0.002846,5.7086,95.626,91.438,93.992
33.54651,1.8848,-0.02972,30.984,100.46,-0.0033103,5.72,100.37,95.911,98.846
35.14651,1.8906,-0.030853,31.118,105.26,-0.003453,5.7387,105.23,100.58,103.83
36.74651,1.8913,-0.034105,31.389,110.06,-0.0036501,5.737,110.03,105.15,108.72
38.2324,1.8972,-0.037605,31.918,114.52,-0.0040462,5.7504,114.37,109.16,113.18
39.8324,1.8867,-0.038576,31.372,119.32,-0.0042294,5.7214,119.32,114.14,118.35
41.4324,1.8784,-0.041309,31.873,124.12,-0.0045854,5.6989,124.08,118.79,123.25
43.0324,1.8796,-0.044679,31.748,128.92,-0.0047992,5.7055,128.92,123.54,128.25
44.6324,1.894,-0.046902,32.246,133.72,-0.0050821,5.7501,133.63,128.16,133.09
46.2324,1.8919,-0.049562,31.924,138.52,-0.0054104,5.7398,138.48,133.12,138.22
47.8324,1.8855,-0.052565,32.629,143.32,-0.0057816,5.7184,143.28,137.83,143.17
49.4324,1.8846,-0.056865,32.717,148.12,-0.0062958,5.716,148.06,142.72,148.19
51.0324,1.8823,-0.058184,32.435,152.92,-0.0062536,5.7109,152.93,147.51,153.2
52.6324,1.8835,-0.060919,32.661,157.72,-0.0065969,5.7158,157.73,152.44,158.11
54.2324,1.8903,-0.064335,32.729,162.52,-0.0070161,5.7349,162.52,157.43,163.15
55.8324,1.8977,-0.066608,32.859,167.32,-0.0073078,5.756,167.35,162.47,168.34
57.4324,1.8851,-0.069301,32.594,172.12,-0.0076268,5.7165,172.12,167.53,173.2
59.03241,1.8785,-0.072599,32.841,176.92,-0.0078369,5.695,176.86,172.4,178.19
60.63241,1.8959,-0.075624,32.78,181.72,-0.008207,5.7513,181.73,177.39,183.33
62.23241,2.1511,-0.0788,32.815,186.52,-0.0086259,6.5293,186.46,182.44,188.43
63.83241,2.283,-0.079074,32.694,191.32,-0.0086357,6.9271,191.34,187.69,193.75
65.43241,2.3738,-0.081129,32.981,196.12,-0.0089002,7.1985,196.07,192.9,198.85
67.03241,2.4577,-0.084474,33.507,200.92,-0.0091263,7.4517,200.82,198.09,204.17
68.63241,2.4775,-0.087191,33.232,205.72,-0.0094706,7.5144,205.71,203.19,209.42
70.23241,2.4858,-0.09007,33.439,210.52,-0.00983,7.5422,210.53,208.23,214.46
71.7574,2.4944,-0.092627,33.772,215.09,-0.010102,7.5638,215.0,213.11,219.36
73.3574,2.498,-0.095641,33.823,219.89,-0.010447,7.5813,219.81,218.18,224.43
74.9468,2.5194,-0.1009,34.137,224.66,-0.011055,7.6454,224.57,223.31,229.58
76.5468,2.5176,-0.1016,34.161,229.46,-0.010972,7.6394,229.44,228.3,234.68
78.1468,2.5158,-0.10417,33.983,234.26,-0.011292,7.6295,234.32,233.39,239.66
79.7468,2.5133,-0.10763,34.2,239.06,-0.011721,7.6238,239.1,238.41,244.76
81.3468,2.5266,-0.11194,33.837,243.86,-0.012245,7.6668,243.95,243.44,249.8
82.9468,2.5365,-0.11299,34.384,248.66,-0.012368,7.6979,248.67,248.49,254.79
84.5468,2.5402,-0.11626,34.049,253.46,-0.012577,7.7085,253.54,253.61,259.94
86.1468,2.564,-0.12208,34.318,258.26,-0.013275,7.777,258.25,258.32,264.88
87.7468,2.5482,-0.12219,34.159,263.06,-0.013245,7.726,263.07,263.5,270.04
89.3468,2.5413,-0.12499,34.094,267.86,-0.013581,7.7078,267.92,268.4,275.0
90.9468,2.5523,-0.12954,33.912,272.66,-0.014095,7.7408,272.72,273.18,280.07
92.5468,2.5711,-0.13046,34.583,277.46,-0.014235,7.8039,277.37,278.15,285.05
94.14681,2.5819,-0.13342,34.469,282.26,-0.014577,7.8346,282.25,283.12,290.24
95.74681,2.5787,-0.13688,34.638,287.06,-0.014807,7.8205,287.04,287.98,295.09
97.34681,2.5841,-0.14188,35.069,291.86,-0.015391,7.8353,291.73,292.76,300.06
98.94681,2.5931,-0.14238,34.668,296.66,-0.015418,7.8666,296.59,297.6,305.07
100.54681,2.5771,-0.14361,32.172,300.0,-0.01558,7.8238,300.6,301.99,309.14
102.14681,2.5767,-0.14437,33.187,300.0,-0.0157,7.8187,300.18,302.46,308.59
103.5927,2.575,-0.14598,32.805,300.0,-0.015872,7.8036,300.17,302.6,308.46
105.1927,2.5802,-0.14566,32.896,300.0,-0.015873,7.8282,300.09,302.62,308.23
106.7927,2.581,-0.14578,32.72,300.0,-0.015913,7.8336,300.08,302.57,308.21
108.3927,2.5761,-0.14668,32.822,300.0,-0.015897,7.8174,300.01,302.38,308.01
109.9927,2.5578,-0.1473,32.556,300.0,-0.016051,7.7588,300.05,302.46,307.94
111.5927,2.5661,-0.15034,32.449,300.0,-0.016239,7.7818,299.19,301.78,306.69
113.1927,2.574,-0.14768,32.513,300.0,-0.01601,7.8081,299.2,301.51,306.76
114.7927,2.5671,-0.14829,32.104,300.0,-0.016078,7.7875,299.24,301.5,306.77
116.3927,2.5735,-0.14885,32.255,300.0,-0.016159,7.8092,299.22,301.52,306.58
117.9927,2.5697,-0.14923,32.451,300.0,-0.016208,7.7974,299.21,301.4,306.55
119.5927,2.5495,-0.14978,32.795,300.0,-0.0163,7.737,299.14,301.4,306.41
121.1927,2.5516,-0.15154,32.488,300.0,-0.016501,7.7334,299.17,301.29,306.33
122.79271,2.5575,-0.1532,32.129,300.0,-0.016669,7.7592,299.2,301.22,306.42
124.39271,2.574,-0.15082,32.291,300.0,-0.016471,7.8111,299.19,301.16,306.26
125.99271,2.5847,-0.15094,31.981,300.0,-0.016345,7.8452,299.23,301.29,306.27
127.59271,2.5627,-0.15122,32.177,300.0,-0.01647,7.7771,299.24,301.28,306.23
129.19271,2.5659,-0.15177,32.808,300.0,-0.016398,7.7813,299.11,301.24,306.04
130.79271,2.5742,-0.15186,32.72,300.0,-0.016476,7.8076,299.12,301.27,306.12
132.39271,2.566,-0.15287,32.7,300.0,-0.016555,7.7811,299.17,301.31,306.14
133.99271,2.548,-0.15247,31.909,300.0,-0.016509,7.7305,299.31,301.28,306.22
135.59271,2.5616,-0.15294,31.919,300.0,-0.016594,7.7711,299.21,301.24,306.01
137.0262,2.5612,-0.15326,31.902,300.0,-0.016634,7.7691,299.22,301.26,306.03
138.6262,2.5721,-0.15336,32.029,300.0,-0.016642,7.8059,299.24,301.25,305.98
140.2262,2.5653,-0.15389,32.176,300.0,-0.016718,7.7848,299.2,301.29,306.01
141.8262,2.5643,-0.15388,31.993,300.0,-0.016749,7.7792,299.18,301.2,305.85
143.4262,2.5675,-0.15396,32.391,300.0,-0.016746,7.7873,299.19,301.27,305.94
145.0262,2.5712,-0.035311,31.932,300.0,-0.0038966,7.7972,299.26,301.28,305.91
145.2867,2.5759,-0.0045201,32.523,3.0119e-07,0.00080433,7.8374,299.15,301.36,305.84
145.2875,2.518,0.0094981,29.898,4.1765e-18,-0.00026745,7.6174,299.15,301.35,305.84
145.2883,2.6297,0.0025552,27.273,5.717e-29,6.3451e-05,8.025,299.15,301.34,305.83
145.2891,2.4997,-0.0090918,24.648,7.973799999999999e-40,0.00019736,7.5714,299.15,301.33,305.83
145.2899,2.5992,0.007732,22.022,0.0,0.00049958,7.8907,299.15,301.32,305.83
145.2907,2.5772,0.0021309,19.397,0.0,-0.00047792,7.84,299.15,301.31,305.83
145.29149,2.5098,-0.011213,16.772,0.0,-0.0010221,7.5884,299.15,301.3,305.83
145.29229,2.6393,0.0024356,14.147,0.0,0.00094149,7.9891,299.15,301.3,305.82
145.29309,2.5202,0.0055364,11.521,0.0,0.00031524,7.6521,299.15,301.29,305.82
145.29389,2.6238,0.00051926,8.8962,0.0,-0.00070207,7.9221,299.15,301.28,305.82
145.29469,2.5636,9.6385e-05,6.271,0.0,0.00090557,7.8172,299.15,301.27,305.82
145.29549,2.5386,-0.0013936,3.6457,0.0,0.00059025,7.6766,299.15,301.26,305.81
145.29629,2.6254,0.0070235,1.0205,0.0,-0.00043002,7.9613,299.15,301.25,305.81
145.29709,2.4988,0.0003957,0.0,0.0,0.0002591,7.5553,299.15,301.24,305.81
145.29789,2.6247,-0.0052534,0.0,0.0,0.00028525,7.9526,299.15,301.24,305.8
145.29869,2.5403,0.0074099,0.0,0.0,0.00015486,7.7424,299.15,301.24,305.79
145.29949,2.5547,0.0041582,0.0,0.0,-0.00020611,7.7207,299.15,301.24,305.78
145.30029,2.549,-0.0059417,0.0,0.0,-7.6858e-05,7.7379,299.15,301.24,305.78
145.30108,2.5285,0.0032044,0.0,0.0,0.00061825,7.6903,299.15,301.24,305.77
145.30188,2.6475,0.0030772,0.0,0.0,-0.00023455,8.0377,299.15,301.24,305.76
145.30268,2.5305,0.00031268,0.0,0.0,-0.00023981,7.7039,299.15,301.24,305.75
145.30348,2.5681,0.0006004,0.0,0.0,0.0010179,7.7844,299.15,301.24,305.75
145.30428,2.6108,0.0022835,0.0,0.0,0.00032684,7.9088,299.15,301.24,305.74
145.30508,2.5072,0.0048752,0.0,0.0,-0.00045219,7.5772,299.15,301.24,305.73
145.30588,2.6306,-0.0012237,0.0,0.0,0.00038489,8.0061,299.15,301.24,305.72
145.30668,2.5248,-0.0035404,0.0,0.0,0.00048141,7.645,299.15,301.24,305.72
145.30748,2.581,0.006647,0.0,0.0,-8.1754e-06,7.8417,299.16,301.23,305.72
145.30828,2.5869,0.00021277,0.0,0.0,-0.00011649,7.8647,299.16,301.22,305.72
145.30908,2.5111,-0.0062651,0.0,0.0,-3.8252e-05,7.6089,299.16,301.21,305.72
145.30988,2.6517,0.0075198,0.0,0.0,0.00065271,7.9848,299.16,301.2,305.72
145.31067,2.502,0.0026189,0.0,0.0,-0.0003103,7.5994,299.17,301.19,305.72
145.31147,2.6033,-0.0042344,0.0,0.0,-0.00044264,7.8728,299.17,301.18,305.72
145.31227,2.5721,0.0020777,0.0,0.0,0.00096239,7.8409,299.17,301.17,305.72
145.31307,2.5175,0.0030401,0.0,0.0,0.0001577,7.6348,299.17,301.16,305.72
145.31387,2.6357,-0.0010303,0.0,0.0,-0.00047553,8.0194,299.18,301.15,305.72
145.31467,2.491,-0.0014106,0.0,0.0,0.00056091,7.572,299.18,301.14,305.72
145.31547,2.6051,0.00013423,0.0,0.0,0.00029311,7.8914,299.18,301.13,305.72
145.31627,2.5591,0.0058002,0.0,0.0,-0.00016173,7.776,299.18,301.12,305.72
145.31707,2.5309,-0.0031981,0.0,0.0,-9.1986e-07,7.6879,299.19,301.12,305.72
145.31787,2.635,-0.0032013,0.0,0.0,0.0002383,7.9978,299.19,301.13,305.73
145.31867,2.491,0.0089112,0.0,0.0,0.00039379,7.5635,299.19,301.14,305.73
145.31947,2.6195,0.00076698,0.0,0.0,-0.00027679,7.911,299.19,301.15,305.74
145.32026,2.5321,-0.0053288,0.0,0.0,-0.00017413,7.7281,299.2,301.15,305.74
145.32106,2.547,0.0054113,0.0,0.0,0.00074245,7.7268,299.2,301.16,305.75
145.32186,2.6184,0.0011714,0.0,0.0,-0.00019802,7.9622,299.2,301.17,305.75
145.32266,2.4929,-0.00079576,0.0,0.0,-0.00024037,7.57,299.2,301.18,305.75
145.32346,2.6217,0.0010102,0.0,0.0,0.00083715,7.9633,299.21,301.18,305.76
145.32426,2.5217,0.00039138,0.0,0.0,8.9157e-05,7.6747,299.21,301.19,305.76
145.32506,2.5577,0.0022335,0.0,0.0,-0.00037415,7.7364,299.21,301.2,305.77
145.32586,2.6076,-0.0013183,0.0,0.0,0.00040674,7.9192,299.21,301.2,305.77
145.32666,2.4868,-0.00033292,0.0,0.0,0.00026926,7.5809,299.22,301.21,305.78
145.32746,2.634,0.0076856,0.0,0.0,4.5486e-05,7.968,299.22,301.22,305.78
145.32826,2.5128,-0.00097378,0.0,0.0,-8.2603e-05,7.6181,299.22,301.22,305.78
145.32906,2.5777,-0.001715,0.0,0.0,0.00029876,7.811,299.22,301.23,305.79
145.32985,2.5984,0.006445,0.0,0.0,0.00046247,7.8941,299.22,301.23,305.79
145.33065,2.5058,2.1103e-05,0.0,0.0,-0.00031074,7.5702,299.22,301.24,305.79
145.33145,2.6342,-0.00046065,0.0,0.0,0.00016357,7.971,299.22,301.24,305.79
145.33225,2.4905,0.0023211,0.0,0.0,0.00073646,7.5784,299.22,301.25,305.8
145.33305,2.5833,0.0024393,0.0,0.0,-8.4267e-05,7.8206,299.22,301.25,305.8
145.33385,2.5716,0.0021285,0.0,0.0,-4.1187e-06,7.7975,299.22,301.26,305.8
145.33465,2.5059,-0.0020597,0.0,0.0,0.00060942,7.6052,299.22,301.26,305.8
145.33545,2.6302,0.0018661,0.0,0.0,8.3604e-05,7.9355,299.22,301.27,305.81
145.33625,2.4904,0.0056086,0.0,0.0,2.4861e-05,7.5584,299.22,301.27,305.81
145.33705,2.596,-0.0028192,0.0,0.0,0.00010016,7.8406,299.21,301.27,305.81
145.33785,2.5564,0.00057789,0.0,0.0,0.00019821,7.779,299.21,301.27,305.81
145.33865,2.5244,0.0080346,0.0,0.0,0.00026256,7.6477,299.2,301.27,305.8
145.33945,2.6453,-0.0017833,0.0,0.0,-0.00042352,8.0451,299.2,301.27,305.8
145.34024,2.4506,-0.00019869,0.0,0.0,0.00040388,7.4491,299.19,301.27,305.8
145.34104,2.6481,0.0049346,0.0,0.0,0.00056872,8.018,299.19,301.27,305.8
145.34184,2.544,0.0005919,0.0,0.0,-0.00050245,7.767,299.18,301.27,305.79
145.34264,2.9131,0.00043848,0.0,0.0,0.00024513,8.7276,299.18,301.27,305.79
145.34344,2.8315,0.0020299,0.0,0.0,0.00095318,8.7246,299.17,301.27,305.79
145.34424,2.304,-0.00011883,0.0,0.0,-0.0004485,6.9353,299.17,301.27,305.79
145.34504,3.0066,0.0064974,0.0,0.0,0.00042049,9.1585,299.16,301.27,305.78
145.34584,2.3341,-0.0055232,0.0,0.0,0.00014945,7.1237,299.16,301.27,305.78
145.34664,2.6617,0.0043505,0.0,0.0,0.00031142,8.0386,299.25,301.35,305.78
145.34744,2.452,0.0047355,0.0,0.0,-0.00019454,7.4403,301.22,302.98,305.77
145.34824,2.6145,-0.0061245,0.0,0.0,-0.00027003,7.9339,303.19,304.62,305.76
145.34904,2.4199,0.0014659,0.0,0.0,0.00066519,7.2841,305.16,306.25,305.76
145.34983,2.7547,0.0059407,0.0,0.0,0.00026917,8.3468,307.13,307.89,305.75
145.35063,2.347,-0.0048785,0.0,0.0,-0.00089808,7.1425,309.1,309.52,305.74
145.35143,2.6961,-0.0014046,0.0,0.0,0.00010615,8.0909,311.07,311.15,305.73
145.35223,2.439,0.00021145,0.0,0.0,0.00041797,7.4873,313.04,312.79,305.73
145.35303,2.4107,-0.00091159,0.0,0.0,-0.00073115,7.2201,315.01,314.42,305.72
145.35383,2.8074,-0.0017165,0.0,0.0,-1.4492e-05,8.5395,316.98,316.06,305.71
145.35463,2.1694,-0.0083495,0.0,0.0,6.349e-06,6.5873,318.95,317.69,305.71
145.35543,2.8395,0.0054953,0.0,0.0,8.1775e-07,8.4716,320.92,319.32,305.7
145.35623,2.5849,0.00075103,0.0,0.0,-0.00032531,7.9553,322.89,320.96,305.69
145.35703,2.1478,-0.01078,0.0,0.0,-0.00058521,6.455,325.24,322.92,305.68
145.35783,3.1403,0.005326,0.0,0.0,0.00059143,9.5227,327.93,325.16,305.66
145.35863,2.0457,0.0035658,0.0,0.0,-0.00022789,6.3368,330.63,327.41,305.64
145.35942,12.041,0.0031592,0.0,0.0,-0.00012535,29.937,333.32,329.65,305.63
145.36022,41.759,0.27336,0.0,0.0,0.029979,125.08,336.01,331.9,305.61
145.36102,43.389,1.0099,0.0,0.0,0.11276,132.45,338.7,334.14,305.59
145.36182,48.282,1.6761,0.0,0.0,0.19724,146.35,341.39,336.39,305.58
145.36262,47.361,2.2196,0.0,0.0,0.27286,144.47,344.09,338.63,305.56
145.36342,49.291,2.6316,0.0,0.0,0.33288,149.06,346.78,340.88,305.54
145.36422,49.878,3.2914,0.0,0.0,0.43136,151.66,349.47,343.12,305.52
145.36502,49.313,3.8393,0.0,0.0,0.52645,149.19,352.16,345.37,305.51
145.36582,51.815,4.1913,0.0,0.0,0.59433,157.32,354.85,347.61,305.49
145.36662,52.583,4.7752,0.0,0.0,0.70288,159.28,357.49,349.81,305.47
145.36742,53.59,5.4949,0.0,0.0,0.86301,162.69,357.56,349.79,305.48
145.36822,52.078,6.121,0.0,0.0,1.0312,157.83,357.62,349.76,305.48
145.36901,53.422,6.4721,0.0,0.0,1.1355,162.11,357.69,349.74,305.49
145.36981,53.339,6.8024,0.0,0.0,1.2374,161.74,357.76,349.71,305.49
145.37061,53.349,7.0808,0.0,0.0,1.3379,161.82,357.83,349.69,305.5
145.37141,51.764,7.199,0.0,0.0,1.3894,157.21,357.9,349.67,305.5
145.37221,53.132,7.3165,0.0,0.0,1.4345,160.98,357.96,349.64,305.51
145.37301,53.935,7.5038,0.0,0.0,1.5026,163.6,358.03,349.62,305.51
145.37381,49.66,7.6708,0.0,0.0,1.5889,151.9,358.1,349.59,305.52
145.37461,46.118,7.5534,0.0,0.0,1.54,139.22,358.17,349.57,305.52
145.37541,44.572,7.669,0.0,0.0,1.5811,134.89,358.24,349.54,305.53
145.37621,44.696,7.6235,0.0,0.0,1.5604,135.88,358.3,349.52,305.53
145.37701,44.14,7.6265,0.0,0.0,1.5733,134.1,357.8,349.02,305.55
145.37781,44.955,7.6646,0.0,0.0,1.5841,136.6,356.73,348.05,305.58
145.3786,44.339,7.6447,0.0,0.0,1.568,134.25,355.67,347.09,305.61
145.3794,43.381,7.6412,0.0,0.0,1.5744,131.83,354.6,346.13,305.65
145.3802,43.747,7.6511,0.0,0.0,1.5835,132.7,353.54,345.16,305.68
145.381,43.0,7.6642,0.0,0.0,1.5827,130.43,352.47,344.2,305.71
145.3818,43.144,7.6733,0.0,0.0,1.5808,131.0,351.41,343.24,305.74
145.3826,42.735,7.658,0.0,0.0,1.5862,129.59,350.35,342.27,305.77
145.3834,42.292,7.6695,0.0,0.0,1.5924,128.3,349.28,341.31,305.8
145.3842,42.032,7.6866,0.0,0.0,1.5863,127.55,348.22,340.35,305.84
145.385,41.711,7.6559,0.0,0.0,1.5796,126.55,347.15,339.38,305.87
145.3858,41.278,7.6559,0.0,0.0,1.5884,125.3,346.09,338.42,305.9
145.3866,41.166,7.6863,0.0,0.0,1.5914,124.9,345.02,337.45,305.93
145.3874,40.749,7.6809,0.0,0.0,1.585,123.66,344.25,336.83,305.94
145.3882,40.446,7.6651,0.0,0.0,1.5882,122.71,343.48,336.21,305.94
145.38899,40.215,7.686,0.0,0.0,1.5977,122.0,342.71,335.59,305.95
145.38979,39.894,7.6802,0.0,0.0,1.5869,121.01,341.94,334.96,305.95
145.39059,39.674,7.6713,0.0,0.0,1.5833,120.4,341.17,334.34,305.96
145.39139,39.361,7.6674,0.0,0.0,1.5908,119.43,340.4,333.72,305.96
145.39219,39.253,7.6783,0.0,0.0,1.592,119.08,339.63,333.09,305.97
145.39299,39.111,7.6878,0.0,0.0,1.5877,118.68,338.86,332.47,305.97
145.39379,38.948,7.6744,0.0,0.0,1.5908,118.14,338.09,331.85,305.98
145.39459,38.831,7.6708,0.0,0.0,1.5932,117.81,337.32,331.23,305.98
145.39539,38.458,7.6943,0.0,0.0,1.5923,116.72,336.55,330.6,305.99
145.39619,37.837,7.6735,0.0,0.0,1.5849,114.85,335.78,329.98,305.99
145.39699,36.883,7.6632,0.0,0.0,1.5888,112.01,335.24,329.5,305.98
145.39779,35.719,7.6842,0.0,0.0,1.5941,108.49,334.95,329.17,305.95
145.39858,34.329,7.6821,0.0,0.0,1.587,104.36,334.66,328.85,305.93
145.39938,32.525,7.6672,0.0,0.0,1.5848,98.913,334.36,328.52,305.9
145.40018,30.272,7.6685,0.0,0.0,1.5909,92.13,334.07,328.2,305.87
145.40098,27.114,7.6665,0.0,0.0,1.5844,82.634,333.78,327.87,305.85
145.40178,17.661,7.6614,0.0,0.0,1.5776,55.26,333.49,327.54,305.82
145.40258,-0.33858,7.5821,0.0,0.0,1.5521,0.046247,333.2,327.22,305.79
145.40338,0.39052,7.4926,0.0,0.0,1.5111,0.96962,332.91,326.89,305.77
145.40418,-0.051906,7.4871,0.0,0.0,1.499,0.11872,332.61,326.56,305.74
145.40498,-0.40075,7.5287,0.0,0.0,1.5231,-1.429,332.32,326.24,305.71
145.40578,0.18561,7.5559,0.0,0.0,1.5385,0.72974,332.03,325.91,305.68
145.40658,8.2308,7.6858,0.0,0.0,1.5908,24.015,331.74,325.58,305.66
145.40738,5.2031,7.6447,0.0,0.0,1.5711,16.197,331.86,325.57,305.69
145.40817,-0.0049173,7.6095,0.0,0.0,1.5622,0.051639,331.99,325.56,305.73
145.40897,1.1968,7.6355,0.0,0.0,1.5727,3.4535,332.13,325.55,305.77
145.40977,3.6242,7.6465,0.0,0.0,1.5723,11.164,332.26,325.54,305.8
145.41057,1.8095,7.6253,0.0,0.0,1.5648,5.5273,332.4,325.53,305.84
145.41137,1.9822,7.63,0.0,0.0,1.5724,5.9029,332.53,325.52,305.88
145.41217,3.479,7.6327,0.0,0.0,1.5698,10.636,332.66,325.51,305.91
145.41297,1.2349,7.623,0.0,0.0,1.5599,3.9643,332.8,325.5,305.95
145.41377,2.2045,7.616,0.0,0.0,1.5642,6.432,332.93,325.49,305.99
145.41457,2.5775,7.6236,0.0,0.0,1.5691,8.029,333.07,325.48,306.02
145.41537,1.9448,7.627,0.0,0.0,1.5632,5.8236,333.2,325.47,306.06
145.41617,2.4081,7.6147,0.0,0.0,1.5594,7.3454,333.33,325.46,306.1
145.41697,2.0301,7.6084,0.0,0.0,1.5617,6.1461,333.46,325.47,306.13
145.41776,2.492,7.6139,0.0,0.0,1.5608,7.5466,333.59,325.51,306.17
145.41856,1.9875,7.6172,0.0,0.0,1.559,6.0208,333.72,325.55,306.2
145.41936,2.3413,7.6105,0.0,0.0,1.5597,7.089,333.84,325.59,306.23
145.42016,2.2917,7.6159,0.0,0.0,1.5656,6.9656,333.97,325.63,306.27
145.42096,2.0906,7.6185,0.0,0.0,1.5613,6.3414,334.1,325.67,306.3
145.42176,2.2133,7.6198,0.0,0.0,1.5607,6.6643,334.22,325.7,306.34
145.42256,2.2467,7.6085,0.0,0.0,1.5623,6.8766,334.35,325.74,306.37
145.42336,2.1169,7.6162,0.0,0.0,1.5629,6.3871,334.48,325.78,306.4
145.42416,2.3332,7.6244,0.0,0.0,1.5617,7.0548,334.6,325.82,306.44
145.42496,2.074,7.6153,0.0,0.0,1.5625,6.3462,334.73,325.86,306.47
145.42576,2.2011,7.6115,0.0,0.0,1.5626,6.6457,334.86,325.9,306.51
145.42656,2.1392,7.6265,0.0,0.0,1.5637,6.5397,334.98,325.94,306.54
145.42735,2.1534,7.615,0.0,0.0,1.5593,6.5021,335.04,325.95,306.54
145.42815,2.1719,7.6107,0.0,0.0,1.5618,6.6153,335.09,325.96,306.54
145.42895,2.1646,7.6193,0.0,0.0,1.565,6.568,335.13,325.97,306.54
145.42975,2.2352,7.6218,0.0,0.0,1.5614,6.7771,335.18,325.98,306.53
145.43055,2.1478,7.6155,0.0,0.0,1.5609,6.5216,335.23,325.99,306.53
145.43135,2.1666,7.6147,0.0,0.0,1.5655,6.5574,335.28,326.0,306.53
145.43215,2.1934,7.6173,0.0,0.0,1.561,6.6809,335.33,326.01,306.53
145.43295,2.1189,7.6208,0.0,0.0,1.561,6.4289,335.38,326.02,306.52
145.43375,2.2366,7.6122,0.0,0.0,1.5636,6.7859,335.43,326.03,306.52
145.43455,2.0964,7.6177,0.0,0.0,1.5633,6.3579,335.47,326.04,306.52
145.43535,2.217,7.6252,0.0,0.0,1.5618,6.6908,335.52,326.05,306.52
145.43615,2.1477,7.6121,0.0,0.0,1.5604,6.5208,335.57,326.06,306.51
145.43694,2.1158,7.6124,0.0,0.0,1.5632,6.4306,335.61,326.06,306.52
145.43774,2.1898,7.6214,0.0,0.0,1.5628,6.6332,335.64,326.05,306.53
145.43854,2.1048,7.6134,0.0,0.0,1.5575,6.3618,335.66,326.04,306.54
145.43934,2.1702,7.6143,0.0,0.0,1.5628,6.56,335.69,326.04,306.55
145.44014,2.1649,7.6183,0.0,0.0,1.5657,6.6002,335.72,326.03,306.57
145.44094,2.1109,7.6137,0.0,0.0,1.5575,6.3886,335.75,326.02,306.58
145.44174,2.2149,7.6149,0.0,0.0,1.5597,6.712,335.77,326.02,306.59
145.44254,2.0891,7.6108,0.0,0.0,1.5643,6.291,335.8,326.01,306.6
145.44334,2.1928,7.615,0.0,0.0,1.5599,6.632,335.83,326.0,306.62
145.44414,2.1241,7.6162,0.0,0.0,1.5578,6.4847,335.85,325.99,306.63
145.44494,2.1436,7.6096,0.0,0.0,1.5613,6.5138,335.88,325.99,306.64
145.44574,2.1735,7.6149,0.0,0.0,1.563,6.6193,335.91,325.98,306.65
145.44654,2.059,7.621,0.0,0.0,1.5613,6.2359,335.93,325.97,306.66
145.44733,2.24,7.6109,0.0,0.0,1.5586,6.8005,335.97,325.93,306.68
145.44813,2.0833,7.6122,0.0,0.0,1.5638,6.3377,336.01,325.9,306.69
145.44893,2.153,7.6178,0.0,0.0,1.5636,6.5321,336.05,325.86,306.71
145.44973,2.2155,7.6176,0.0,0.0,1.5583,6.7649,336.09,325.82,306.72
145.45053,2.0769,7.6125,0.0,0.0,1.5612,6.2873,336.13,325.78,306.74
145.45133,2.2419,7.6109,0.0,0.0,1.5639,6.7519,336.16,325.74,306.75
145.45213,2.1549,7.6214,0.0,0.0,1.5605,6.5685,336.2,325.7,306.77
145.45293,2.1381,7.6146,0.0,0.0,1.5596,6.4636,336.24,325.66,306.78
145.45373,2.1888,7.6045,0.0,0.0,1.562,6.6465,336.28,325.62,306.8
145.45453,2.0773,7.618,0.0,0.0,1.5621,6.2985,336.32,325.58,306.81
145.45533,2.239,7.6246,0.0,0.0,1.5607,6.7956,336.36,325.55,306.83
145.45613,2.1201,7.6074,0.0,0.0,1.5594,6.424,336.4,325.51,306.84
145.45692,2.2074,7.6145,0.0,0.0,1.5644,6.6975,336.42,325.46,306.86
145.45772,2.1661,7.6237,0.0,0.0,1.563,6.569,336.43,325.4,306.89
145.45852,2.179,7.6128,0.0,0.0,1.5572,6.592,336.44,325.34,306.93
145.45932,2.1971,7.6115,0.0,0.0,1.5642,6.6906,336.45,325.28,306.96
145.46012,2.1846,7.6189,0.0,0.0,1.5666,6.6182,336.45,325.23,306.99
145.46092,2.2062,7.6245,0.0,0.0,1.5595,6.6702,336.46,325.17,307.02
145.46172,2.2217,7.6137,0.0,0.0,1.5615,6.7683,336.47,325.11,307.05
145.46252,2.1332,7.6093,0.0,0.0,1.565,6.4585,336.47,325.05,307.08
145.46332,2.3014,7.627,0.0,0.0,1.563,6.9838,336.48,324.99,307.12
145.46412,2.0963,7.6205,0.0,0.0,1.5595,6.3753,336.49,324.93,307.15
145.46492,2.2852,7.6069,0.0,0.0,1.5617,6.9491,336.5,324.87,307.18
145.46572,2.161,7.622,0.0,0.0,1.5669,6.5965,336.5,324.82,307.21
145.46651,2.2507,7.626,0.0,0.0,1.5606,6.7998,336.51,324.76,307.24
145.46731,2.2415,7.6107,0.0,0.0,1.5579,6.8031,336.52,324.72,307.28
145.46811,2.2084,7.613,0.0,0.0,1.565,6.6917,336.53,324.69,307.31
145.46891,2.2769,7.6222,0.0,0.0,1.5643,6.8995,336.54,324.65,307.34
145.46971,2.2106,7.6191,0.0,0.0,1.5569,6.7524,336.55,324.62,307.37
145.47051,2.2636,7.6143,0.0,0.0,1.5647,6.859,336.56,324.58,307.4
145.47131,2.2759,7.6135,0.0,0.0,1.5665,6.9181,336.57,324.55,307.43
145.47211,2.2091,7.6253,0.0,0.0,1.5596,6.6991,336.58,324.52,307.47
145.47291,2.2986,7.6195,0.0,0.0,1.561,7.003,336.59,324.48,307.5
145.47371,2.2086,7.6057,0.0,0.0,1.5637,6.7077,336.6,324.45,307.53
145.47451,2.2613,7.625,0.0,0.0,1.5643,6.8334,336.61,324.41,307.56
145.47531,2.3097,7.6279,0.0,0.0,1.5611,7.0152,336.62,324.38,307.59
145.4761,2.1741,7.607,0.0,0.0,1.5598,6.5799,336.63,324.35,307.62
145.4769,2.3889,7.6197,0.0,0.0,1.5683,7.2063,336.63,324.31,307.66
145.4777,2.1955,7.6278,0.0,0.0,1.564,6.667,336.63,324.28,307.69
145.4785,2.3311,7.6159,0.0,0.0,1.5563,7.0956,336.63,324.26,307.73
145.4793,2.2788,7.6113,0.0,0.0,1.5662,6.9677,336.62,324.23,307.76
145.4801,2.2673,7.6181,0.0,0.0,1.566,6.8556,336.62,324.2,307.79
145.4809,2.3514,7.6298,0.0,0.0,1.559,7.1509,336.62,324.17,307.83
145.4817,2.2516,7.6132,0.0,0.0,1.5617,6.8812,336.62,324.14,307.86
145.4825,2.3244,7.6056,0.0,0.0,1.5645,7.0827,336.62,324.11,307.9
145.4833,2.3341,7.6299,0.0,0.0,1.5632,7.1129,336.61,324.08,307.93
145.4841,2.3019,7.6198,0.0,0.0,1.5586,6.9767,336.61,324.05,307.97
145.4849,2.3668,7.6033,0.0,0.0,1.5606,7.2297,336.61,324.02,308.0
145.48569,2.3083,7.6214,0.0,0.0,1.5671,7.013,336.61,323.99,308.03
145.48649,2.4135,7.6253,0.0,0.0,1.5607,7.342,336.6,323.96,308.07
145.48729,2.2846,7.6092,0.0,0.0,1.5565,6.9198,336.59,323.92,308.1
145.48809,2.3906,7.6127,0.0,0.0,1.566,7.1873,336.57,323.87,308.13
145.48889,2.3898,7.6211,0.0,0.0,1.5645,7.3158,336.55,323.82,308.16
145.48969,2.2616,7.6193,0.0,0.0,1.557,6.8588,336.53,323.77,308.19
145.49049,2.485,7.6115,0.0,0.0,1.5632,7.5345,336.51,323.72,308.22
145.49129,2.2868,7.6117,0.0,0.0,1.5655,6.9293,336.49,323.67,308.24
145.49209,2.3925,7.6255,0.0,0.0,1.5602,7.2593,336.47,323.62,308.27
145.49289,2.4329,7.6172,0.0,0.0,1.5601,7.4182,336.45,323.58,308.3
145.49369,2.2738,7.6041,0.0,0.0,1.5621,6.8639,336.43,323.53,308.33
145.49449,2.516,7.6254,0.0,0.0,1.5653,7.6256,336.41,323.48,308.36
145.49529,2.2862,7.6227,0.0,0.0,1.5599,7.0063,336.39,323.43,308.39
145.49608,2.4278,7.6079,0.0,0.0,1.5592,7.3196,336.37,323.38,308.42
145.49688,2.4149,7.6183,0.0,0.0,1.5669,7.3819,336.35,323.32,308.45
145.49768,2.2693,7.6225,0.0,0.0,1.5629,6.8459,336.31,323.24,308.47
145.49848,2.5471,7.6162,0.0,0.0,1.5579,7.7331,336.27,323.17,308.5
145.49928,2.3125,7.6095,0.0,0.0,1.564,7.0393,336.23,323.09,308.52
145.50008,2.3604,7.6154,0.0,0.0,1.5644,7.1307,336.19,323.01,308.55
145.50088,2.4814,7.6247,0.0,0.0,1.5596,7.5451,336.15,322.93,308.57
145.50168,2.1873,7.6088,0.0,0.0,1.5595,6.6043,336.11,322.85,308.59
145.50248,2.5654,7.6084,0.0,0.0,1.5627,7.7856,336.07,322.78,308.62
145.50328,2.2107,7.6249,0.0,0.0,1.5623,6.7393,336.04,322.7,308.64
145.50408,2.4043,7.6135,0.0,0.0,1.5574,7.2337,336.0,322.62,308.67
145.50488,2.4232,7.6042,0.0,0.0,1.5594,7.3835,335.96,322.54,308.69
145.50567,2.2205,7.6184,0.0,0.0,1.5648,6.7236,335.92,322.46,308.72
145.50647,2.5184,7.6191,0.0,0.0,1.5599,7.5995,335.88,322.39,308.74
145.50727,2.1821,7.6095,0.0,0.0,1.5572,6.6685,335.84,322.31,308.77
145.50807,2.418,7.6082,0.0,0.0,1.5634,7.2901,335.8,322.24,308.79
145.50887,2.3726,7.6185,0.0,0.0,1.5627,7.2626,335.76,322.17,308.81
145.50967,2.2136,7.6156,0.0,0.0,1.5573,6.6682,335.71,322.09,308.84
145.51047,2.5586,7.6108,0.0,0.0,1.5625,7.7732,335.67,322.02,308.86
145.51127,2.1352,7.6101,0.0,0.0,1.5624,6.5028,335.63,321.95,308.89
145.51207,2.465,7.6231,0.0,0.0,1.5601,7.4347,335.59,321.87,308.91
145.51287,2.3206,7.6137,0.0,0.0,1.5599,7.0919,335.55,321.8,308.94
145.51367,2.2202,7.6042,0.0,0.0,1.5603,6.6829,335.51,321.73,308.96
145.51447,2.5125,7.6209,0.0,0.0,1.5626,7.6533,335.47,321.66,308.99
145.51526,2.1369,7.6176,0.0,0.0,1.559,6.4804,335.43,321.58,309.01
145.51606,2.475,7.6093,0.0,0.0,1.56,7.4704,335.38,321.51,309.03
145.51686,2.2895,7.6123,0.0,0.0,1.5631,7.0101,335.34,321.43,309.06
145.51766,2.274,7.6144,0.0,0.0,1.5592,6.8623,335.3,321.36,309.09
145.51846,2.4931,7.6155,0.0,0.0,1.5592,7.5819,335.25,321.28,309.12
145.51926,2.1276,7.6069,0.0,0.0,1.562,6.4662,335.21,321.2,309.15
145.52006,2.4898,7.6112,0.0,0.0,1.5599,7.5159,335.17,321.12,309.18
145.52086,2.2378,7.6215,0.0,0.0,1.5603,6.8402,335.12,321.05,309.21
145.52166,2.3109,7.608,0.0,0.0,1.5606,6.9472,335.08,320.97,309.24
145.52246,2.4355,7.609,0.0,0.0,1.561,7.443,335.04,320.89,309.27
145.52326,2.1481,7.6194,0.0,0.0,1.5595,6.5194,334.99,320.81,309.3
145.52406,2.5305,7.6115,0.0,0.0,1.5583,7.6744,334.95,320.73,309.32
145.52485,2.2,7.6081,0.0,0.0,1.5611,6.7114,334.9,320.66,309.35
145.52565,2.3626,7.6177,0.0,0.0,1.5629,7.1342,334.86,320.58,309.38
145.52645,2.4041,7.6155,0.0,0.0,1.5588,7.3483,334.82,320.5,309.41
145.52725,2.1764,7.6088,0.0,0.0,1.5585,6.5669,334.76,320.44,309.44
145.52805,2.5253,7.6122,0.0,0.0,1.564,7.6358,334.71,320.37,309.47
145.52885,2.1774,7.6147,0.0,0.0,1.5593,6.6504,334.65,320.31,309.49
145.52965,2.4014,7.6125,0.0,0.0,1.5572,7.261,334.6,320.25,309.52
145.53045,2.3917,7.6091,0.0,0.0,1.5631,7.2935,334.54,320.19,309.55
145.53125,2.2026,7.6134,0.0,0.0,1.5611,6.6734,334.48,320.13,309.57
145.53205,2.5272,7.6211,0.0,0.0,1.5598,7.6649,334.43,320.07,309.6
145.53285,2.1644,7.6076,0.0,0.0,1.5591,6.6027,334.37,320.01,309.63
145.53365,2.4471,7.6078,0.0,0.0,1.5611,7.3999,334.31,319.95,309.66
145.53444,2.3617,7.6223,0.0,0.0,1.5622,7.2069,334.26,319.89,309.68
145.53524,2.2191,7.6126,0.0,0.0,1.558,6.7164,334.2,319.83,309.71
145.53604,2.5373,7.6091,0.0,0.0,1.5609,7.7282,334.15,319.77,309.74
145.53684,2.1465,7.6142,0.0,0.0,1.5632,6.5475,334.09,319.71,309.76
145.53764,2.4766,7.6158,0.0,0.0,1.5582,7.5041,334.04,319.67,309.77
145.53844,2.326,7.6112,0.0,0.0,1.559,7.1184,334.0,319.62,309.79
145.53924,2.2958,7.6077,0.0,0.0,1.5621,6.8915,333.95,319.58,309.8
145.54004,2.5083,7.6187,0.0,0.0,1.5609,7.6751,333.9,319.53,309.82
145.54084,2.1834,7.6144,0.0,0.0,1.5581,6.601,333.85,319.49,309.83
145.54164,2.5219,7.6053,0.0,0.0,1.5602,7.6053,333.8,319.45,309.85
145.54244,2.2936,7.6147,0.0,0.0,1.5623,6.9887,333.75,319.4,309.86
145.54324,2.3489,7.62,0.0,0.0,1.5596,7.1025,333.7,319.36,309.88
145.54403,2.5057,7.6085,0.0,0.0,1.5581,7.6162,333.65,319.31,309.89
145.54483,2.1941,7.6081,0.0,0.0,1.5616,6.6399,333.61,319.27,309.91
145.54563,2.5342,7.618,0.0,0.0,1.562,7.679,333.56,319.23,309.92
145.54643,2.2747,7.6158,0.0,0.0,1.5581,6.9378,333.51,319.18,309.93
145.54723,2.3824,7.6073,0.0,0.0,1.5603,7.195,333.45,319.12,309.96
145.54803,2.4693,7.6132,0.0,0.0,1.5643,7.566,333.39,319.05,309.98
145.54883,2.212,7.6168,0.0,0.0,1.5581,6.6914,333.34,318.98,310.0
145.54963,2.5798,7.6139,0.0,0.0,1.5597,7.8006,333.28,318.91,310.02
145.55043,2.2478,7.6048,0.0,0.0,1.5619,6.8599,333.22,318.85,310.04
145.55123,2.4535,7.6197,0.0,0.0,1.5611,7.3916,333.16,318.78,310.07
145.55203,2.445,7.621,0.0,0.0,1.5599,7.4675,333.1,318.71,310.09
145.55283,2.2511,7.6025,0.0,0.0,1.5586,6.8141,333.04,318.64,310.11
145.55363,2.5929,7.6153,0.0,0.0,1.5641,7.8807,332.98,318.57,310.13
145.55442,2.2424,7.6215,0.0,0.0,1.5611,6.8187,332.93,318.5,310.15
145.55522,2.4878,7.608,0.0,0.0,1.5561,7.4969,332.87,318.43,310.18
145.55602,2.4314,7.612,0.0,0.0,1.5638,7.4508,332.81,318.37,310.2
145.55682,2.299,7.6164,0.0,0.0,1.564,6.9639,332.75,318.3,310.22
145.55762,2.6036,7.6185,0.0,0.0,1.558,7.9163,332.69,318.23,310.24
145.55842,2.2306,7.6088,0.0,0.0,1.5606,6.7673,332.62,318.17,310.26
145.55922,2.5218,7.6062,0.0,0.0,1.5627,7.6507,332.56,318.1,310.28
145.56002,2.371,7.6234,0.0,0.0,1.5611,7.2433,332.5,318.03,310.3
145.56082,2.3234,7.6149,0.0,0.0,1.5582,6.9995,332.43,317.97,310.32
145.56162,2.5677,7.6013,0.0,0.0,1.5603,7.8394,332.37,317.9,310.34
145.56242,2.2212,7.6184,0.0,0.0,1.563,6.7437,332.31,317.84,310.36
145.56322,2.5506,7.6223,0.0,0.0,1.5597,7.7413,332.24,317.77,310.38
145.56401,2.3296,7.6027,0.0,0.0,1.5563,7.1116,332.18,317.7,310.39
145.56481,2.3572,7.6107,0.0,0.0,1.5639,7.1362,332.12,317.64,310.41
145.56561,2.557,7.6232,0.0,0.0,1.5639,7.8036,332.05,317.57,310.43
145.56641,2.2182,7.6125,0.0,0.0,1.5548,6.7139,331.99,317.51,310.45
145.56721,2.5742,7.608,0.0,0.0,1.5625,7.7713,331.93,317.44,310.47
145.56801,2.296,7.6103,0.0,0.0,1.5638,7.0155,331.86,317.38,310.5
145.56881,2.3929,7.6224,0.0,0.0,1.5577,7.2083,331.8,317.32,310.52
145.56961,2.53,7.6121,0.0,0.0,1.5599,7.6853,331.74,317.26,310.54
145.57041,2.2227,7.6019,0.0,0.0,1.5623,6.7068,331.67,317.2,310.56
145.57121,2.5949,7.6233,0.0,0.0,1.5615,7.8995,331.61,317.14,310.58
145.57201,2.2525,7.6219,0.0,0.0,1.5586,6.9174,331.55,317.08,310.61
145.57281,2.4568,7.5971,0.0,0.0,1.5571,7.3862,331.48,317.02,310.63
145.5736,2.4685,7.6182,0.0,0.0,1.5667,7.5709,331.42,316.96,310.65
145.5744,2.2352,7.6216,0.0,0.0,1.5592,6.752,331.36,316.89,310.67
145.5752,2.601,7.6059,0.0,0.0,1.5535,7.9073,331.29,316.83,310.69
145.576,2.2322,7.6096,0.0,0.0,1.5648,6.8386,331.23,316.77,310.72
145.5768,2.47,7.6159,0.0,0.0,1.5636,7.4596,331.17,316.71,310.74
145.5776,2.4285,7.6178,0.0,0.0,1.5544,7.3999,331.11,316.63,310.77
145.5784,2.2653,7.6045,0.0,0.0,1.5594,6.8112,331.05,316.55,310.79
145.5792,2.5773,7.6081,0.0,0.0,1.5648,7.8874,330.98,316.47,310.82
145.58,2.221,7.6241,0.0,0.0,1.5589,6.6966,330.92,316.39,310.85
145.5808,2.5011,7.6138,0.0,0.0,1.5563,7.5413,330.86,316.32,310.87
145.5816,2.3815,7.6005,0.0,0.0,1.5607,7.2258,330.8,316.24,310.9
145.5824,2.283,7.6212,0.0,0.0,1.5647,6.8559,330.74,316.16,310.93
145.58319,2.5686,7.6217,0.0,0.0,1.5582,7.8147,330.68,316.08,310.95
145.58399,2.1796,7.6014,0.0,0.0,1.5557,6.663,330.62,316.0,310.98
145.58479,2.5351,7.6125,0.0,0.0,1.5649,7.6725,330.56,315.93,311.01
145.58559,2.308,7.6204,0.0,0.0,1.5629,7.0869,330.5,315.85,311.04
145.58639,2.3168,7.6122,0.0,0.0,1.5544,7.0127,330.44,315.77,311.06
145.58719,2.5244,7.609,0.0,0.0,1.5634,7.6862,330.37,315.69,311.09
145.58799,2.1726,7.608,0.0,0.0,1.5624,6.6263,330.3,315.62,311.11
145.58879,2.5451,7.6226,0.0,0.0,1.5575,7.6395,330.23,315.54,311.14
145.58959,2.2863,7.6119,0.0,0.0,1.5597,6.9899,330.16,315.46,311.16
145.59039,2.357,7.6015,0.0,0.0,1.5613,7.1035,330.09,315.39,311.19
145.59119,2.4978,7.6228,0.0,0.0,1.5618,7.5831,330.01,315.31,311.21
145.59199,2.1912,7.6161,0.0,0.0,1.5574,6.6076,329.94,315.24,311.23
145.59278,2.55,7.6028,0.0,0.0,1.5589,7.7429,329.87,315.16,311.26
145.59358,2.2334,7.6148,0.0,0.0,1.5649,6.8439,329.8,315.09,311.28
145.59438,2.3747,7.6185,0.0,0.0,1.5592,7.1682,329.73,315.01,311.31
145.59518,2.4431,7.6096,0.0,0.0,1.5562,7.441,329.66,314.93,311.33
145.59598,2.1826,7.6069,0.0,0.0,1.563,6.5876,329.59,314.86,311.36
145.59678,2.5462,7.6148,0.0,0.0,1.5627,7.7035,329.52,314.78,311.38
145.59758,2.2092,7.6168,0.0,0.0,1.5561,6.7456,329.45,314.72,311.41
145.59838,2.4225,7.6065,0.0,0.0,1.5596,7.3283,329.37,314.65,311.43
145.59918,2.3949,7.6081,0.0,0.0,1.5627,7.3163,329.3,314.58,311.45
145.59998,2.2135,7.6209,0.0,0.0,1.5598,6.6787,329.23,314.51,311.48
145.60078,2.5487,7.6147,0.0,0.0,1.5587,7.7329,329.15,314.44,311.5
145.60158,2.1947,7.6037,0.0,0.0,1.5604,6.6882,329.08,314.37,311.53
145.60238,2.4638,7.6189,0.0,0.0,1.5636,7.4226,329.01,314.31,311.55
145.60317,2.3721,7.6188,0.0,0.0,1.5594,7.2422,328.94,314.24,311.58
145.60397,2.2466,7.6054,0.0,0.0,1.5572,6.7666,328.86,314.17,311.6
145.60477,2.5403,7.612,0.0,0.0,1.5644,7.7318,328.79,314.1,311.63
145.60557,2.1981,7.6173,0.0,0.0,1.561,6.6908,328.72,314.03,311.65
145.60637,2.5218,7.6146,0.0,0.0,1.5569,7.5695,328.64,313.96,311.67
145.60717,2.3209,7.6081,0.0,0.0,1.5624,7.0853,328.58,313.88,311.7
145.60797,2.2974,7.6114,0.0,0.0,1.5615,6.9565,328.51,313.79,311.72
145.60877,2.5339,7.6224,0.0,0.0,1.5596,7.6875,328.45,313.7,311.75
145.60957,2.1975,7.6097,0.0,0.0,1.5588,6.6696,328.39,313.61,311.77
145.61037,2.5533,7.6055,0.0,0.0,1.5608,7.7082,328.32,313.52,311.8
145.61117,2.3006,7.6223,0.0,0.0,1.5619,7.0038,328.26,313.43,311.82
145.61197,2.3588,7.6128,0.0,0.0,1.5577,7.0927,328.2,313.34,311.85
145.61276,2.5125,7.6099,0.0,0.0,1.5608,7.6559,328.13,313.25,311.87
145.61356,2.2191,7.6162,0.0,0.0,1.5639,6.7163,328.07,313.16,311.89
145.61436,2.5625,7.6162,0.0,0.0,1.5591,7.7574,328.01,313.07,311.92
145.61516,2.2875,7.6126,0.0,0.0,1.559,7.0045,327.94,312.98,311.94
145.61596,2.4039,7.6102,0.0,0.0,1.5636,7.2305,327.88,312.88,311.97
145.61676,2.4911,7.6154,0.0,0.0,1.5615,7.582,327.82,312.79,311.99
145.61756,2.2396,7.6175,0.0,0.0,1.5584,6.7698,327.75,312.71,312.0
145.61836,2.583,7.6091,0.0,0.0,1.5615,7.7945,327.68,312.62,312.01
145.61916,2.2522,7.6118,0.0,0.0,1.5619,6.8601,327.61,312.53,312.03
145.61996,2.4466,7.6211,0.0,0.0,1.5598,7.3976,327.54,312.44,312.04
145.62076,2.4585,7.6135,0.0,0.0,1.5599,7.4993,327.48,312.35,312.05
145.62156,2.2584,7.607,0.0,0.0,1.5607,6.8076,327.41,312.27,312.06
145.62235,2.5774,7.6205,0.0,0.0,1.5632,7.8252,327.34,312.18,312.07
145.62315,2.231,7.6155,0.0,0.0,1.5589,6.8308,327.27,312.09,312.09
145.62395,2.5007,7.61,0.0,0.0,1.5595,7.5353,327.2,312.0,312.1
145.62475,2.418,7.6169,0.0,0.0,1.5655,7.3963,327.13,311.92,312.11
145.62555,2.2978,7.6131,0.0,0.0,1.5589,6.9452,327.07,311.83,312.12
145.62635,2.5815,7.6149,0.0,0.0,1.5593,7.8424,327.0,311.74,312.14
145.62715,2.2231,7.6102,0.0,0.0,1.5632,6.7585,326.93,311.67,312.15
145.62795,2.5325,7.6161,0.0,0.0,1.5618,7.6147,326.85,311.6,312.16
145.62875,2.3893,7.6186,0.0,0.0,1.5595,7.291,326.78,311.53,312.18
145.62955,2.3328,7.6074,0.0,0.0,1.5596,7.0323,326.71,311.47,312.19
145.63035,2.5833,7.6152,0.0,0.0,1.5634,7.8501,326.63,311.4,312.21
145.63115,2.2305,7.6217,0.0,0.0,1.5618,6.7881,326.56,311.34,312.22
145.63194,2.5562,7.6117,0.0,0.0,1.5586,7.7416,326.49,311.27,312.24
145.63274,2.3546,7.6122,0.0,0.0,1.5628,7.185,326.41,311.2,312.25
145.63354,2.3774,7.6194,0.0,0.0,1.5641,7.1735,326.34,311.14,312.27
145.63434,2.5629,7.6156,0.0,0.0,1.5588,7.7953,326.27,311.07,312.28
145.63514,2.2412,7.6093,0.0,0.0,1.5597,6.8105,326.2,311.01,312.3
145.63594,2.5871,7.6144,0.0,0.0,1.5653,7.8203,326.12,310.94,312.31
145.63674,2.3147,7.6197,0.0,0.0,1.5611,7.055,326.05,310.87,312.33
145.63754,2.4245,7.6145,0.0,0.0,1.5585,7.3047,325.98,310.81,312.34
145.63834,2.5415,7.6111,0.0,0.0,1.5636,7.7531,325.91,310.74,312.36
145.63914,2.2433,7.6192,0.0,0.0,1.5632,6.8183,325.84,310.67,312.37
145.63994,2.5973,7.6202,0.0,0.0,1.5593,7.838,325.77,310.6,312.38
145.64074,2.2736,7.6095,0.0,0.0,1.56,6.9149,325.7,310.53,312.4
145.64153,2.4625,7.6145,0.0,0.0,1.5641,7.4156,325.63,310.46,312.41
145.64233,2.5026,7.6237,0.0,0.0,1.5635,7.6218,325.56,310.39,312.43
145.64313,2.2681,7.6114,0.0,0.0,1.5569,6.8816,325.48,310.33,312.44
145.64393,2.6012,7.6122,0.0,0.0,1.563,7.8941,325.41,310.26,312.46
145.64473,2.2605,7.6163,0.0,0.0,1.5649,6.8753,325.34,310.19,312.47
145.64553,2.5014,7.617,0.0,0.0,1.5575,7.5597,325.27,310.12,312.49
145.64633,2.4576,7.6154,0.0,0.0,1.5614,7.5191,325.2,310.05,312.5
145.64713,2.3015,7.6088,0.0,0.0,1.5639,6.9624,325.13,309.99,312.52
145.64793,2.5932,7.6218,0.0,0.0,1.5616,7.8869,325.07,309.92,312.54
145.64873,2.2506,7.6184,0.0,0.0,1.5592,6.8561,325.0,309.86,312.55
145.64953,2.5343,7.6053,0.0,0.0,1.5598,7.6521,324.93,309.8,312.57
145.65033,2.4125,7.6192,0.0,0.0,1.5645,7.3874,324.86,309.73,312.59
145.65112,2.3419,7.6213,0.0,0.0,1.5598,7.0547,324.79,309.67,312.6
145.65192,2.5903,7.6094,0.0,0.0,1.5577,7.9072,324.72,309.61,312.62
145.65272,2.2374,7.6126,0.0,0.0,1.564,6.7663,324.66,309.54,312.64
145.65352,2.5583,7.6199,0.0,0.0,1.5639,7.719,324.59,309.48,312.65
145.65432,2.3622,7.6157,0.0,0.0,1.5575,7.2167,324.52,309.42,312.67
145.65512,2.358,7.6076,0.0,0.0,1.5608,7.106,324.45,309.35,312.69
145.65592,2.5677,7.6111,0.0,0.0,1.5643,7.8059,324.38,309.29,312.71
145.65672,2.2322,7.6232,0.0,0.0,1.5597,6.8036,324.31,309.23,312.72
145.65752,2.5823,7.6155,0.0,0.0,1.5599,7.8056,324.24,309.18,312.73
145.65832,2.3342,7.6022,0.0,0.0,1.5615,7.0923,324.17,309.12,312.74
145.65912,2.401,7.6189,0.0,0.0,1.5613,7.2062,324.1,309.07,312.74
145.65992,2.5391,7.6258,0.0,0.0,1.5607,7.7168,324.03,309.02,312.75
145.66072,2.2318,7.6008,0.0,0.0,1.5572,6.7459,323.96,308.97,312.76
145.66151,2.6007,7.614,0.0,0.0,1.5646,7.8475,323.89,308.92,312.77
145.66231,2.2831,7.6253,0.0,0.0,1.5621,6.9653,323.82,308.87,312.77
145.66311,2.4191,7.6105,0.0,0.0,1.5547,7.3578,323.75,308.82,312.78
145.66391,2.4878,7.6099,0.0,0.0,1.5636,7.5796,323.68,308.77,312.79
145.66471,2.2466,7.6117,0.0,0.0,1.5632,6.8024,323.61,308.71,312.8
145.66551,2.5812,7.6219,0.0,0.0,1.5566,7.8381,323.54,308.66,312.8
145.66631,2.266,7.6103,0.0,0.0,1.5603,6.8919,323.47,308.61,312.81
145.66711,2.4535,7.6026,0.0,0.0,1.5628,7.3939,323.4,308.55,312.82
145.66791,2.4568,7.6258,0.0,0.0,1.5618,7.4854,323.34,308.49,312.84
145.66871,2.2716,7.6185,0.0,0.0,1.5574,6.8608,323.27,308.42,312.85
145.66951,2.5755,7.6006,0.0,0.0,1.56,7.847,323.21,308.36,312.87
145.67031,2.2429,7.6182,0.0,0.0,1.565,6.8348,323.15,308.3,312.88
145.6711,2.5126,7.6223,0.0,0.0,1.5589,7.6047,323.08,308.23,312.9
145.6719,2.4003,7.6068,0.0,0.0,1.5559,7.3477,323.02,308.17,312.91
145.6727,2.3072,7.6098,0.0,0.0,1.5654,6.9364,322.96,308.11,312.92
145.6735,2.5682,7.6214,0.0,0.0,1.5643,7.8117,322.89,308.04,312.94
145.6743,2.2147,7.615,0.0,0.0,1.5542,6.6915,322.83,307.98,312.95
145.6751,2.5299,7.608,0.0,0.0,1.562,7.6254,322.77,307.92,312.97
145.6759,2.3448,7.6087,0.0,0.0,1.5655,7.2321,322.7,307.85,312.98
145.6767,2.3199,7.6239,0.0,0.0,1.5586,7.0071,322.64,307.79,313.0
145.6775,2.5567,7.615,0.0,0.0,1.5595,7.7936,322.58,307.72,313.02
145.6783,2.2153,7.6,0.0,0.0,1.562,6.7403,322.51,307.65,313.04
145.6791,2.5315,7.6235,0.0,0.0,1.5637,7.6671,322.45,307.58,313.06
145.6799,2.323,7.6227,0.0,0.0,1.5583,7.0799,322.39,307.52,313.08
145.68069,2.3574,7.6013,0.0,0.0,1.5571,7.1238,322.32,307.45,313.1
145.68149,2.5103,7.6162,0.0,0.0,1.5667,7.629,322.26,307.38,313.12
145.68229,2.221,7.6213,0.0,0.0,1.5619,6.7329,322.2,307.31,313.14
145.68309,2.563,7.6124,0.0,0.0,1.5557,7.7407,322.13,307.24,313.15
145.68389,2.2895,7.6109,0.0,0.0,1.565,6.9603,322.07,307.17,313.17
145.68469,2.4022,7.6142,0.0,0.0,1.564,7.2527,322.01,307.1,313.19
145.68549,2.4883,7.6237,0.0,0.0,1.5574,7.5937,321.94,307.04,313.21
145.68629,2.2385,7.6081,0.0,0.0,1.5593,6.7675,321.88,306.97,313.23
145.68709,2.5787,7.6066,0.0,0.0,1.5635,7.8245,321.81,306.9,313.24
145.68789,2.2575,7.6271,0.0,0.0,1.5627,6.9004,321.75,306.83,313.25
145.68869,2.4527,7.6161,0.0,0.0,1.5577,7.4058,321.68,306.77,313.25
145.68949,2.4525,7.6017,0.0,0.0,1.5593,7.5234,321.61,306.7,313.26
145.69028,2.2695,7.6207,0.0,0.0,1.5662,6.882,321.54,306.64,313.26
145.69108,2.5696,7.6225,0.0,0.0,1.5602,7.8276,321.47,306.57,313.27
145.69188,2.2657,7.6084,0.0,0.0,1.5572,6.8747,321.41,306.5,313.27
145.69268,2.4964,7.6127,0.0,0.0,1.5657,7.5468,321.34,306.44,313.28
145.69348,2.4346,7.6208,0.0,0.0,1.5636,7.3925,321.27,306.37,313.28
145.69428,2.3146,7.6162,0.0,0.0,1.5568,6.9684,321.2,306.31,313.29
145.69508,2.5793,7.6091,0.0,0.0,1.5618,7.8205,321.13,306.24,313.29
145.69588,2.2527,7.6109,0.0,0.0,1.5637,6.8383,321.06,306.17,313.3
145.69668,2.5513,7.6258,0.0,0.0,1.5613,7.735,321.0,306.11,313.3
145.69748,2.3867,7.6148,0.0,0.0,1.56,7.278,320.93,306.05,313.32
145.69828,2.3469,7.6049,0.0,0.0,1.561,7.099,320.86,305.98,313.33
145.69908,2.5713,7.6237,0.0,0.0,1.5646,7.8432,320.79,305.92,313.35
145.69987,2.2253,7.6173,0.0,0.0,1.5587,6.7915,320.72,305.86,313.36
145.70067,2.574,7.6066,0.0,0.0,1.5587,7.7602,320.66,305.79,313.38
145.70147,2.3489,7.616,0.0,0.0,1.5653,7.2084,320.59,305.73,313.39
145.70227,2.3975,7.6195,0.0,0.0,1.561,7.222,320.52,305.66,313.41
145.70307,2.5583,7.6165,0.0,0.0,1.5588,7.7728,320.45,305.6,313.42
145.70387,2.249,7.609,0.0,0.0,1.5634,6.8244,320.38,305.54,313.44
145.70467,2.6105,7.6148,0.0,0.0,1.5627,7.873,320.31,305.47,313.45
145.70547,2.3391,7.6216,0.0,0.0,1.5594,7.1349,320.25,305.41,313.46
145.70627,2.4404,7.6117,0.0,0.0,1.5614,7.3633,320.18,305.35,313.48
145.70707,2.5374,7.6116,0.0,0.0,1.5635,7.7108,320.11,305.28,313.49
145.70787,2.2617,7.6221,0.0,0.0,1.5609,6.8527,320.04,305.22,313.51
145.70867,2.6117,7.6164,0.0,0.0,1.5593,7.9307,319.97,305.16,313.52
145.70947,2.3106,7.6074,0.0,0.0,1.5608,7.0276,319.91,305.09,313.54
145.71026,2.4858,7.618,0.0,0.0,1.5636,7.4887,319.84,305.03,313.55
145.71106,2.5076,7.6211,0.0,0.0,1.561,7.6386,319.77,304.97,313.57
145.71186,2.2921,7.6093,0.0,0.0,1.5583,6.9481,319.7,304.9,313.58
145.71266,2.6156,7.6136,0.0,0.0,1.5652,7.9207,319.63,304.84,313.6
145.71346,2.2887,7.6185,0.0,0.0,1.5619,6.9696,319.56,304.77,313.61
145.71426,2.5335,7.6168,0.0,0.0,1.5581,7.6207,319.5,304.71,313.63
145.71506,2.4684,7.6108,0.0,0.0,1.5632,7.5457,319.43,304.65,313.64
145.71586,2.3242,7.6146,0.0,0.0,1.5624,7.0354,319.36,304.58,313.66
145.71666,2.6211,7.6231,0.0,0.0,1.5607,7.9633,319.29,304.52,313.67
145.71746,2.2799,7.6129,0.0,0.0,1.5604,6.9411,319.23,304.46,313.67
145.71826,2.5669,7.6098,0.0,0.0,1.5617,7.7433,319.17,304.4,313.67
145.71906,2.4425,7.6246,0.0,0.0,1.5643,7.4422,319.11,304.34,313.67
145.71985,2.3636,7.6143,0.0,0.0,1.5584,7.1403,319.05,304.29,313.67
145.72065,2.5955,7.6095,0.0,0.0,1.5605,7.9036,318.99,304.23,313.67
145.72145,2.2696,7.6188,0.0,0.0,1.5655,6.8708,318.92,304.17,313.67
145.72225,2.5829,7.6202,0.0,0.0,1.5607,7.8163,318.86,304.11,313.67
145.72305,2.3877,7.6119,0.0,0.0,1.5591,7.2856,318.8,304.05,313.67
145.72385,2.3823,7.6109,0.0,0.0,1.5638,7.2135,318.74,303.99,313.67
145.72465,2.5899,7.6203,0.0,0.0,1.5632,7.8821,318.68,303.93,313.67
145.72545,2.2593,7.6172,0.0,0.0,1.5592,6.8776,318.62,303.88,313.67
145.72625,2.6026,7.609,0.0,0.0,1.5616,7.8737,318.56,303.82,313.67
145.72705,2.3444,7.6166,0.0,0.0,1.5637,7.1382,318.49,303.76,313.67
145.72785,2.4231,7.6216,0.0,0.0,1.5605,7.3258,318.42,303.7,313.68
145.72865,2.542,7.6132,0.0,0.0,1.5598,7.7403,318.36,303.64,313.69
145.72944,2.2684,7.6119,0.0,0.0,1.5629,6.8791,318.29,303.58,313.69
145.73024,2.6034,7.6207,0.0,0.0,1.5633,7.8872,318.22,303.52,313.7
145.73104,2.3132,7.6171,0.0,0.0,1.5589,7.0643,318.15,303.46,313.71
145.73184,2.4578,7.6153,0.0,0.0,1.5626,7.4231,318.08,303.4,313.72
145.73264,2.5115,7.6151,0.0,0.0,1.5651,7.6584,318.01,303.35,313.72
145.73344,2.2847,7.6177,0.0,0.0,1.5594,6.9197,317.95,303.29,313.73
145.73424,2.5945,7.6175,0.0,0.0,1.5608,7.8831,317.88,303.23,313.74
145.73504,2.282,7.6087,0.0,0.0,1.5632,6.965,317.81,303.17,313.75
145.73584,2.5021,7.6174,0.0,0.0,1.5616,7.5328,317.74,303.11,313.75
145.73664,2.4628,7.6237,0.0,0.0,1.5615,7.5199,317.67,303.05,313.76
145.73744,2.3044,7.6084,0.0,0.0,1.5599,6.9646,317.6,302.98,313.78
145.73824,2.6018,7.6151,0.0,0.0,1.5641,7.9042,317.52,302.92,313.79
145.73903,2.2615,7.6233,0.0,0.0,1.5623,6.8706,317.45,302.85,313.81
145.73983,2.5358,7.6126,0.0,0.0,1.5583,7.621,317.38,302.79,313.82
145.74063,2.4204,7.6135,0.0,0.0,1.5637,7.4052,317.3,302.72,313.83
145.74143,2.3185,7.6167,0.0,0.0,1.564,7.0065,317.23,302.65,313.85
145.74223,2.5867,7.6182,0.0,0.0,1.5583,7.8506,317.16,302.59,313.86
145.74303,2.2506,7.6137,0.0,0.0,1.5616,6.8578,317.08,302.52,313.88
145.74383,2.5435,7.6106,0.0,0.0,1.5646,7.71,317.01,302.45,313.89
145.74463,2.3916,7.6214,0.0,0.0,1.5608,7.2816,316.94,302.39,313.91
145.74543,2.3629,7.6161,0.0,0.0,1.5593,7.1335,316.86,302.32,313.92
145.74623,2.5546,7.6072,0.0,0.0,1.5623,7.819,316.79,302.26,313.94
145.74703,2.2563,7.6175,0.0,0.0,1.5631,6.865,316.72,302.2,313.95
145.74783,2.5713,7.6234,0.0,0.0,1.56,7.7939,316.66,302.15,313.96
145.74862,2.3365,7.6093,0.0,0.0,1.5591,7.1658,316.6,302.09,313.97
145.74942,2.3987,7.6115,0.0,0.0,1.564,7.2183,316.54,302.04,313.98
145.75022,2.5585,7.621,0.0,0.0,1.5635,7.7814,316.48,301.99,313.99
145.75102,2.2673,7.6136,0.0,0.0,1.5565,6.8875,316.42,301.94,314.0
145.75182,2.5891,7.611,0.0,0.0,1.5628,7.8279,316.36,301.89,314.01
145.75262,2.3172,7.612,0.0,0.0,1.5642,7.0835,316.3,301.84,314.02
145.75342,2.437,7.6227,0.0,0.0,1.5587,7.3621,316.24,301.79,314.03
145.75422,2.5161,7.6157,0.0,0.0,1.561,7.6704,316.17,301.73,314.04
145.75502,2.2879,7.6022,0.0,0.0,1.5615,6.9303,316.11,301.68,314.05
145.75582,2.6122,7.6242,0.0,0.0,1.5628,7.9369,316.05,301.63,314.06
145.75662,2.2962,7.6229,0.0,0.0,1.5596,7.0237,315.99,301.58,314.07
145.75742,2.4801,7.6012,0.0,0.0,1.5585,7.4822,315.94,301.53,314.07
145.75821,2.4641,7.6176,0.0,0.0,1.5658,7.551,315.88,301.48,314.07
145.75901,2.3136,7.6231,0.0,0.0,1.5608,6.99,315.83,301.43,314.07
145.75981,2.606,7.6111,0.0,0.0,1.5568,7.9015,315.78,301.38,314.08
145.76061,2.2813,7.6099,0.0,0.0,1.5645,6.9155,315.72,301.33,314.08
145.76141,2.5281,7.6183,0.0,0.0,1.5644,7.6377,315.67,301.28,314.08
145.76221,2.4431,7.6214,0.0,0.0,1.5577,7.446,315.62,301.24,314.08
145.76301,2.3453,7.6095,0.0,0.0,1.5618,7.0635,315.56,301.19,314.09
145.76381,2.6114,7.6089,0.0,0.0,1.5653,7.9125,315.51,301.14,314.09
145.76461,2.2715,7.627,0.0,0.0,1.5612,6.9261,315.45,301.09,314.09
145.76541,2.5478,7.6172,0.0,0.0,1.5583,7.7236,315.4,301.04,314.09
145.76621,2.4225,7.6017,0.0,0.0,1.5616,7.3491,315.35,300.99,314.1
145.76701,2.3716,7.6234,0.0,0.0,1.5654,7.1612,315.29,300.94,314.1
145.76781,2.5814,7.6262,0.0,0.0,1.5606,7.8654,315.23,300.88,314.1
145.7686,2.2769,7.6033,0.0,0.0,1.5566,6.9116,315.17,300.82,314.11
145.7694,2.5975,7.6147,0.0,0.0,1.5667,7.7999,315.11,300.77,314.11
145.7702,2.374,7.6261,0.0,0.0,1.5651,7.2527,315.04,300.71,314.12
145.771,2.4099,7.6147,0.0,0.0,1.555,7.2791,314.98,300.66,314.12
145.7718,2.57,7.6109,0.0,0.0,1.5652,7.8559,314.92,300.6,314.13
145.7726,2.275,7.6142,0.0,0.0,1.5665,6.8682,314.86,300.54,314.13
145.7734,2.6139,7.6283,0.0,0.0,1.5587,7.9249,314.8,300.49,314.14
147.0334,2.3206,7.6233,0.0,0.0,1.5654,7.0345,213.67,222.83,182.01
148.6334,2.2501,7.6536,0.0,0.0,1.5788,6.8239,59.821,82.248,48.022
150.2334,2.1531,7.6705,0.0,0.0,1.5871,6.5334,35.913,41.492,24.863
151.8334,2.1642,7.6783,0.0,0.0,1.5906,6.5671,28.295,37.341,21.082
153.4334,2.174,7.6844,0.0,0.0,1.5935,6.5947,24.8,27.443,19.999
155.0334,2.1817,7.69,0.0,0.0,1.5961,6.6159,22.939,25.1,19.571
156.6334,2.2479,7.6936,0.0,0.0,1.5977,6.8172,24.907,26.227,21.03
158.2334,2.2072,7.6956,0.0,0.0,1.5987,6.6946,27.3,27.944,23.425
159.8334,2.1561,7.7021,0.0,0.0,1.6015,6.5392,28.874,29.282,25.413
161.4334,2.2469,7.705,0.0,0.0,1.6029,6.8171,29.898,30.287,27.047
162.6334,2.2397,7.7055,0.0,0.0,1.6034,6.7969,30.437,30.984,27.941