File: examples/dan-msc-case-studies/CS4/data/01 raw data/hyde_test_026.csv
Time(sec),Force(kN),Jaw(mm),PowAngle(deg),PTemp,Strain,Stress(MPa),TC1(C),TC2(C),TC3(C)
0.0,1.7623,-0.0035857,0.0,0.0041529,-0.00033066,5.325,22.12,8000,8000
2.0,1.6272,-0.0009642,0.0,5.0588,-9.4115e-05,4.9358,22.11,8000,8000
4.0,1.5894,-0.0004448,0.0,11.057,-4.7383e-05,4.8194,22.235,8000,8000
6.0,1.5646,-0.00041957,0.0,17.057,-4.8765e-05,4.7469,22.032,8000,8000
8.0,1.5564,0.00055129,11.484,23.057,7.4937e-05,4.7213,22.125,8000,8000
9.2828,1.5604,0.00026186,19.947,26.907,2.8346e-05,4.7324,25.633,8000,8000
11.2828,1.5661,-0.0019541,21.129,32.905,-0.00020409,4.7508,32.229,8000,8000
13.2828,1.5639,-0.0046296,22.323,38.905,-0.00049646,4.7446,38.483,8000,8000
14.4837,1.5675,-0.0062644,22.833,42.508,-0.00069789,4.7557,42.191,8000,8000
16.4837,1.5688,-0.010115,23.567,48.508,-0.0011084,4.7585,48.299,8000,8000
18.4837,1.5742,-0.012047,24.979,54.508,-0.0013163,4.7761,54.237,8000,8000
20.4837,1.5811,-0.015014,25.462,60.508,-0.0016331,4.7958,60.347,8000,8000
22.4837,1.5881,-0.018034,26.202,66.508,-0.0019597,4.8175,66.328,8000,8000
24.4837,1.6116,-0.022573,25.81,72.508,-0.0024687,4.8876,72.551,8000,8000
26.4837,1.6067,-0.024295,26.934,78.508,-0.0026503,4.8743,78.395,8000,8000
28.4837,1.6105,-0.02739,27.629,84.508,-0.002984,4.8847,84.357,8000,8000
30.4837,1.6186,-0.03037,28.101,90.508,-0.0033043,4.9104,90.392,8000,8000
32.4837,1.6203,-0.035255,28.484,96.508,-0.0038485,4.914,96.421,8000,8000
34.4837,1.6224,-0.036987,28.756,102.51,-0.0040429,4.9215,102.43,8000,8000
36.4837,1.6328,-0.040558,27.773,108.51,-0.0044346,4.9531,108.65,8000,8000
38.4837,1.6431,-0.045625,28.459,114.51,-0.0049865,4.9835,114.5,8000,8000
40.4837,1.6386,-0.047217,27.682,120.51,-0.0051415,4.972,120.65,8000,8000
41.9026,1.653,-0.049743,28.731,124.77,-0.0054214,5.0152,124.7,8000,8000
43.9026,1.6608,-0.053136,28.946,130.76,-0.005791,5.0376,130.7,8000,8000
45.2722,1.6632,-0.057434,29.188,134.87,-0.0062574,5.044,134.85,8000,8000
47.2722,1.6639,-0.059648,29.252,140.87,-0.0064975,5.0487,140.88,8000,8000
49.2722,1.6597,-0.062939,29.361,146.87,-0.0068511,5.0353,146.92,8000,8000
51.2722,1.6722,-0.068315,29.885,152.87,-0.007437,5.072,152.81,8000,8000
53.2722,1.6744,-0.070116,30.435,158.87,-0.0076428,5.0809,158.77,8000,8000
55.2722,1.6838,-0.074028,31.402,164.87,-0.0080772,5.1078,164.63,8000,8000
57.2722,1.6711,-0.07835,30.559,170.87,-0.0085268,5.0703,170.89,8000,8000
59.2722,1.6794,-0.081328,31.118,176.87,-0.008845,5.0936,176.78,8000,8000
61.2722,1.6799,-0.085846,31.364,182.87,-0.0093485,5.0966,182.8,8000,8000
63.2722,1.6738,-0.088984,31.212,188.87,-0.0096816,5.0777,188.92,8000,8000
65.2722,1.6843,-0.092661,31.491,194.87,-0.010076,5.1094,194.91,8000,8000
67.2722,1.6832,-0.095425,31.794,200.87,-0.010375,5.1072,200.76,8000,8000
69.2722,1.6891,-0.10008,31.041,206.87,-0.010895,5.1231,207.01,8000,8000
71.2722,1.683,-0.10684,31.684,212.87,-0.011622,5.1054,212.9,8000,8000
73.2722,1.6891,-0.10901,31.897,218.87,-0.01185,5.1202,218.89,8000,8000
74.5311,1.6857,-0.11119,32.274,222.65,-0.012076,5.114,222.61,8000,8000
76.0758,1.6856,-0.1135,32.03,227.28,-0.012326,5.1134,227.27,8000,8000
78.0758,1.6835,-0.11732,31.571,233.28,-0.012742,5.1068,233.39,8000,8000
80.0758,1.6886,-0.1214,32.957,239.28,-0.013196,5.1224,239.07,8000,8000
82.0758,1.6889,-0.1247,31.921,245.28,-0.013542,5.1242,245.32,8000,8000
84.0758,1.693,-0.12859,32.574,251.28,-0.013969,5.1362,251.21,8000,8000
86.0758,1.6847,-0.13254,32.331,257.28,-0.014399,5.1101,257.33,8000,8000
88.0758,1.6915,-0.13646,32.755,263.28,-0.014834,5.1324,263.29,8000,8000
90.0758,1.6961,-0.14055,32.717,269.28,-0.015275,5.1449,269.33,8000,8000
92.0758,1.7006,-0.14509,33.085,275.28,-0.015757,5.1584,275.23,8000,8000
94.0758,1.7,-0.14952,33.144,281.28,-0.01624,5.1562,281.27,8000,8000
96.0758,1.7013,-0.15336,33.821,287.28,-0.016668,5.1595,287.11,8000,8000
98.0758,1.6956,-0.15615,33.689,293.28,-0.016957,5.1427,293.17,8000,8000
100.0758,1.7035,-0.15867,33.804,299.26,-0.017218,5.1677,299.12,8000,8000
102.0758,0.6745,-0.16262,31.766,300.0,-0.017648,2.0456,300.03,8000,8000
104.0758,0.66854,-0.16294,31.043,300.0,-0.01768,2.0275,300.05,8000,8000
106.0758,0.6556,-0.16348,30.039,300.0,-0.01774,1.99,300.22,8000,8000
107.1697,0.66621,-0.16385,30.926,300.0,-0.017769,2.0208,299.94,8000,8000
109.1697,0.66335,-0.16422,30.433,300.0,-0.017802,2.013,300.04,8000,8000
111.1697,0.67033,-0.16477,30.26,300.0,-0.017867,2.0354,300.04,8000,8000
113.1697,0.66637,-0.16545,30.175,300.0,-0.017937,2.0215,300.07,8000,8000
115.1697,0.67259,-0.16605,30.454,300.0,-0.018005,2.0405,299.99,8000,8000
117.1697,0.6742,-0.16728,30.56,300.0,-0.018139,2.0443,299.94,8000,8000
119.1697,0.67454,-0.16838,30.262,300.0,-0.018253,2.045,299.97,8000,8000
121.1697,0.68262,-0.17013,29.724,300.0,-0.018432,2.0706,300.12,8000,8000
123.1697,0.67387,-0.17027,29.36,300.0,-0.018451,2.0443,300.12,8000,8000
125.1697,0.6711,-0.17084,30.056,300.0,-0.018527,2.038,299.98,8000,8000
127.1697,0.67957,-0.17105,30.362,300.0,-0.018548,2.0621,299.91,8000,8000
129.1697,0.67617,-0.17079,29.215,300.0,-0.018538,2.0526,300.17,8000,8000
131.1697,0.67536,-0.17137,29.078,300.0,-0.018595,2.0497,300.18,8000,8000
133.1697,0.67965,-0.17175,29.086,300.0,-0.018622,2.0632,300.12,8000,8000
135.1697,0.69808,-0.17155,29.876,300.0,-0.018575,2.1179,299.94,8000,8000
137.1697,0.68168,-0.17127,30.117,300.0,-0.018555,2.0663,299.92,8000,8000
138.6956,0.6794,-0.17109,30.193,300.0,-0.018559,2.0617,299.9,8000,8000
140.6956,0.68266,-0.171,30.114,300.0,-0.018542,2.0693,299.91,8000,8000
142.6956,0.69636,-0.17139,30.23,300.0,-0.018571,2.1124,299.89,8000,8000
144.6956,0.68806,-0.17203,29.727,300.0,-0.018627,2.0869,300.05,8000,8000
145.2861,0.83249,0.013022,2.6823,236.25,0.0016498,2.5172,300.04,8000,8000
145.2881,0.85611,0.013282,0.0,0.44961,0.001365,2.5594,300.05,8000,8000
145.2901,0.86625,0.014891,0.0,0.0008423,0.0014348,2.5764,300.07,8000,8000
145.2921,0.77831,0.013951,0.0,1.5862e-06,0.001071,2.2978,300.09,8000,8000
145.2941,0.88367,0.01329,0.0,2.9715e-09,0.0019647,2.6731,300.11,8000,8000
145.2961,0.8804,0.014159,0.0,5.5956e-12,0.0018744,2.6573,300.13,8000,8000
145.2981,0.88858,0.011904,0.0,1.0536e-14,0.0014208,2.6672,300.12,8000,8000
145.3001,0.88083,0.015485,0.0,1.9739e-17,0.0015487,2.6542,300.1,8000,8000
145.3021,0.89872,0.015027,0.0,3.7168e-20,0.00096924,2.6977,300.07,8000,8000
145.3041,0.89309,0.011548,0.0,6.963099999999999e-23,0.0016811,2.7212,300.05,8000,8000
145.3061,0.89769,0.013479,0.0,1.3111e-25,0.001701,2.6953,300.03,8000,8000
145.3081,0.89893,0.011827,0.0,2.4685999999999997e-28,0.0015599,2.7445,300.0,8000,8000
145.3101,0.90568,0.014818,0.0,4.6248e-31,0.0015278,2.744,299.98,8000,8000
145.3121,0.89576,0.014681,0.0,8.7076e-34,0.0010327,2.7267,299.95,8000,8000
145.3141,0.8953,0.012089,0.0,1.6394e-36,0.0016085,2.7375,299.93,8000,8000
145.3161,0.89327,0.013268,0.0,3.0714e-39,0.0015386,2.7207,299.9,8000,8000
145.3181,0.89282,0.010999,0.0,5.7818e-42,0.0016945,2.7165,299.88,8000,8000
145.3201,0.89581,0.014616,0.0,9.8091e-45,0.001545,2.7339,299.85,8000,8000
145.3221,0.89435,0.016173,0.0,0.0,0.0011192,2.7481,299.83,8000,8000
145.3241,0.88705,0.012721,0.0,0.0,0.0014492,2.6986,299.8,8000,8000
145.3261,0.88563,0.01332,0.0,0.0,0.0014616,2.71,299.78,8000,8000
145.3281,0.89202,0.012862,0.0,0.0,0.0019893,2.7411,299.77,8000,8000
145.3301,0.88303,0.014526,0.0,0.0,0.0017607,2.7376,299.78,8000,8000
145.3321,0.87092,0.013713,0.0,0.0,0.0010838,2.669,299.78,8000,8000
145.3341,0.87557,0.015455,0.0,0.0,0.0016206,2.7014,299.79,8000,8000
145.3361,0.86395,0.014751,0.0,0.0,0.0013642,2.6618,299.8,8000,8000
145.3381,0.86915,0.010755,0.0,0.0,0.0016953,2.6675,299.82,8000,8000
145.3401,0.85971,0.013987,0.0,0.0,0.0017875,2.6346,299.86,8000,8000
145.3421,0.86608,0.014211,0.0,0.0,0.0012338,2.6478,299.89,8000,8000
145.3441,0.86219,0.015065,0.0,0.0,0.0015054,2.647,299.93,8000,8000
145.3461,0.85598,0.015349,0.0,0.0,0.0012454,2.637,299.97,8000,8000
145.3481,0.80013,0.010883,0.0,0.0,0.0016947,2.4558,300.02,8000,8000
145.3501,5.4365,0.015152,0.0,0.0,0.0021935,16.319,300.1,8000,8000
145.3521,23.76,0.081266,0.0,0.0,0.0086901,69.91,300.17,8000,8000
145.35409,38.797,0.16383,0.0,0.0,0.017576,117.0,300.24,8000,8000
145.35609,45.046,0.31485,0.0,0.0,0.033752,136.23,300.32,8000,8000
145.35809,46.932,0.47966,0.0,0.0,0.053791,142.18,300.45,8000,8000
145.36009,47.767,0.66752,0.0,0.0,0.075214,144.94,300.64,8000,8000
145.36209,48.53,0.83861,0.0,0.0,0.095281,147.12,300.82,8000,8000
145.36409,48.82,1.0142,0.0,0.0,0.11605,148.04,301.01,8000,8000
145.36609,49.199,1.1937,0.0,0.0,0.13762,149.18,301.19,8000,8000
145.36809,49.524,1.386,0.0,0.0,0.16289,150.21,301.43,8000,8000
145.37009,49.79,1.5796,0.0,0.0,0.18753,151.0,301.73,8000,8000
145.37209,50.104,1.7777,0.0,0.0,0.21346,151.93,302.02,8000,8000
145.37409,50.329,1.9718,0.0,0.0,0.23909,152.64,302.32,8000,8000
145.37609,50.493,2.1542,0.0,0.0,0.26341,153.13,302.61,8000,8000
145.37809,50.652,2.314,0.0,0.0,0.28721,153.62,302.93,8000,8000
145.38009,50.773,2.4664,0.0,0.0,0.30911,153.98,303.26,8000,8000
145.38209,50.908,2.6061,0.0,0.0,0.32986,154.43,303.59,8000,8000
145.38409,51.033,2.7451,0.0,0.0,0.34989,154.77,303.92,8000,8000
145.38609,51.2,2.875,0.0,0.0,0.36878,155.3,304.25,8000,8000
145.38809,51.411,3.0003,0.0,0.0,0.38912,155.93,304.54,8000,8000
145.39009,51.633,3.1323,0.0,0.0,0.40982,156.62,304.78,8000,8000
145.39209,51.839,3.2614,0.0,0.0,0.43141,157.22,305.03,8000,8000
145.39409,52.073,3.3954,0.0,0.0,0.45261,157.93,305.27,8000,8000
145.39609,52.296,3.529,0.0,0.0,0.47396,158.62,305.51,8000,8000
145.39809,52.484,3.6646,0.0,0.0,0.49757,159.18,305.71,8000,8000
145.40009,52.657,3.7938,0.0,0.0,0.51977,159.73,305.87,8000,8000
145.40209,52.832,3.9164,0.0,0.0,0.54319,160.26,306.03,8000,8000
145.40409,52.965,4.0508,0.0,0.0,0.56703,160.67,306.19,8000,8000
145.40609,53.07,4.1731,0.0,0.0,0.58823,160.99,306.35,8000,8000
145.40809,53.14,4.2916,0.0,0.0,0.61102,161.21,306.5,8000,8000
145.41009,53.207,4.4094,0.0,0.0,0.6332,161.4,306.65,8000,8000
145.41209,53.25,4.5193,0.0,0.0,0.65689,161.53,306.79,8000,8000
145.41409,53.322,4.6322,0.0,0.0,0.67925,161.75,306.94,8000,8000
145.41609,53.369,4.7401,0.0,0.0,0.70019,161.89,307.09,8000,8000
145.41809,53.431,4.8501,0.0,0.0,0.72276,162.07,307.22,8000,8000
145.42009,53.485,4.955,0.0,0.0,0.74468,162.24,307.34,8000,8000
145.42209,53.547,5.058,0.0,0.0,0.76955,162.44,307.47,8000,8000
145.42409,53.591,5.1636,0.0,0.0,0.79258,162.58,307.59,8000,8000
145.42609,53.626,5.2642,0.0,0.0,0.81475,162.66,307.71,8000,8000
145.42809,53.669,5.3648,0.0,0.0,0.83717,162.8,307.81,8000,8000
145.43009,53.724,5.4658,0.0,0.0,0.86025,162.98,307.9,8000,8000
145.43209,53.779,5.5554,0.0,0.0,0.88452,163.15,307.98,8000,8000
145.43409,53.876,5.6532,0.0,0.0,0.9089,163.42,308.07,8000,8000
145.43609,53.962,5.7426,0.0,0.0,0.93107,163.69,308.16,8000,8000
145.43809,54.017,5.8376,0.0,0.0,0.95448,163.84,308.22,8000,8000
145.44009,54.112,5.9286,0.0,0.0,0.97682,164.15,308.27,8000,8000
145.44209,54.21,6.0119,0.0,0.0,1.0016,164.43,308.32,8000,8000
145.44409,54.325,6.0957,0.0,0.0,1.0251,164.77,308.37,8000,8000
145.44609,54.45,6.1788,0.0,0.0,1.049,165.15,308.42,8000,8000
145.44809,54.588,6.2643,0.0,0.0,1.0719,165.57,308.46,8000,8000
145.45009,54.776,6.3463,0.0,0.0,1.0942,166.14,308.49,8000,8000
145.45209,54.974,6.422,0.0,0.0,1.1188,166.74,308.52,8000,8000
145.45409,55.168,6.4995,0.0,0.0,1.1428,167.34,308.55,8000,8000
145.45609,55.387,6.5743,0.0,0.0,1.1683,167.99,308.58,8000,8000
145.45809,55.524,6.6536,0.0,0.0,1.1919,168.42,308.62,8000,8000
145.46009,55.688,6.7299,0.0,0.0,1.2144,168.9,308.67,8000,8000
145.46209,55.915,6.8022,0.0,0.0,1.2399,169.59,308.72,8000,8000
145.46409,56.184,6.8722,0.0,0.0,1.2639,170.42,308.77,8000,8000
145.46609,56.418,6.938,0.0,0.0,1.2902,171.12,308.81,8000,8000
145.46809,56.654,7.0107,0.0,0.0,1.3146,171.82,308.86,8000,8000
145.47009,56.885,7.0768,0.0,0.0,1.3361,172.52,308.91,8000,8000
145.47209,57.152,7.1431,0.0,0.0,1.361,173.34,308.96,8000,8000
145.47409,57.416,7.2076,0.0,0.0,1.3856,174.14,309.01,8000,8000
145.47609,57.727,7.262,0.0,0.0,1.411,175.06,309.06,8000,8000
145.47809,58.062,7.328,0.0,0.0,1.4368,176.08,309.08,8000,8000
145.48009,58.44,7.3887,0.0,0.0,1.4586,177.19,309.08,8000,8000
145.48209,58.835,7.448,0.0,0.0,1.4827,178.42,309.08,8000,8000
145.48409,59.244,7.5062,0.0,0.0,1.5066,179.64,309.08,8000,8000
145.48609,59.71,7.5582,0.0,0.0,1.5342,181.08,309.08,8000,8000
145.48809,60.199,7.618,0.0,0.0,1.5605,182.54,309.08,8000,8000
145.49009,60.686,7.6732,0.0,0.0,1.5839,184.02,309.07,8000,8000
145.49208,61.182,7.7288,0.0,0.0,1.6079,185.53,309.07,8000,8000
145.49408,61.74,7.7814,0.0,0.0,1.6315,187.22,309.06,8000,8000
145.49608,62.302,7.8275,0.0,0.0,1.6593,188.93,309.05,8000,8000
145.49808,62.972,7.8787,0.0,0.0,1.685,190.94,309.06,8000,8000
145.50008,63.644,7.9258,0.0,0.0,1.7085,192.98,309.09,8000,8000
145.50208,62.669,7.9663,0.0,0.0,1.7281,190.49,309.11,8000,8000
145.50408,60.914,7.9637,0.0,0.0,1.7233,184.83,309.14,8000,8000
145.50608,59.737,7.9687,0.0,0.0,1.7313,181.31,309.16,8000,8000
145.50808,58.75,7.9704,0.0,0.0,1.7329,178.26,309.18,8000,8000
145.51008,58.11,7.9697,0.0,0.0,1.7335,176.27,309.19,8000,8000
145.51208,57.672,7.9778,0.0,0.0,1.7345,174.97,309.2,8000,8000
145.51408,57.361,7.9807,0.0,0.0,1.7326,174.01,309.22,8000,8000
145.51608,57.194,7.9801,0.0,0.0,1.736,173.49,309.23,8000,8000
145.51808,57.081,7.9844,0.0,281.61,1.739,173.14,309.24,8000,8000
145.52008,57.013,7.9838,0.0,299.97,1.7412,172.92,309.25,8000,8000
145.52208,56.901,7.9908,0.0,300.0,1.7433,172.62,309.27,8000,8000
145.52408,56.412,7.9909,0.0,300.0,1.7385,171.17,309.28,8000,8000
145.52608,55.217,7.9891,0.0,300.0,1.7401,167.64,309.29,8000,8000
145.52808,52.936,7.9906,0.0,300.0,1.7409,160.79,309.31,8000,8000
145.53008,49.515,7.9811,0.0,300.0,1.7407,150.58,309.33,8000,8000
145.53208,35.784,7.9809,0.0,300.0,1.7396,111.45,309.36,8000,8000
145.53408,10.526,7.9045,0.0,300.0,1.6956,33.407,309.38,8000,8000
145.53608,-0.14594,7.8053,0.0,300.0,1.647,-0.40717,309.41,8000,8000
145.53808,0.19261,7.8529,0.0,300.0,1.6678,0.077959,309.41,8000,8000
145.54008,0.17945,7.8588,0.0,300.0,1.6777,0.65181,309.39,8000,8000
145.54208,1.2364,7.8605,0.0,300.0,1.6768,4.0364,309.37,8000,8000
145.54408,1.2923,7.8658,0.0,300.0,1.6759,3.7761,309.35,8000,8000
145.54608,0.79006,7.8665,0.0,300.0,1.676,2.3193,309.33,8000,8000
145.54808,0.76643,7.8663,0.0,300.0,1.6748,2.4031,309.31,8000,8000
145.55008,1.0043,7.856,0.0,300.0,1.6755,3.0968,309.28,8000,8000
145.55208,0.9646,7.8563,0.0,300.0,1.6749,2.9085,309.25,8000,8000
145.55408,0.90266,7.8587,0.0,300.0,1.6738,2.7616,309.22,8000,8000
145.55608,0.87118,7.8614,0.0,300.0,1.6733,2.6802,309.19,8000,8000
145.55808,0.88736,7.8596,0.0,300.0,1.6707,2.7231,309.17,8000,8000
145.56008,0.88982,7.8572,0.0,300.0,1.6751,2.7097,309.15,8000,8000
145.56208,0.86523,7.8583,0.0,300.0,1.6761,2.6542,309.14,8000,8000
145.56408,0.84724,7.8561,0.0,300.0,1.674,2.5708,309.13,8000,8000
145.56608,0.87029,7.8619,0.0,300.0,1.6741,2.6444,309.12,8000,8000
145.56808,0.86576,7.8591,0.0,300.0,1.6696,2.6546,309.09,8000,8000
145.57008,0.84709,7.8537,0.0,300.0,1.6724,2.6027,309.05,8000,8000
145.57208,0.83226,7.8564,0.0,300.0,1.6743,2.5502,309.0,8000,8000
145.57408,0.81191,7.8547,0.0,300.0,1.6742,2.4849,308.96,8000,8000
145.57608,0.82666,7.8614,0.0,300.0,1.6746,2.5213,308.92,8000,8000
145.57808,0.82468,7.8612,0.0,300.0,1.671,2.5176,308.88,8000,8000
145.58008,0.86598,7.8569,0.0,300.0,1.6731,2.6303,308.85,8000,8000
145.58208,0.85424,7.859,0.0,300.0,1.6745,2.5925,308.82,8000,8000
145.58408,0.85392,7.8544,0.0,300.0,1.6749,2.6173,308.79,8000,8000
145.58608,0.81604,7.8563,0.0,300.0,1.673,2.4934,308.76,8000,8000
145.58808,0.838,7.8597,0.0,300.0,1.6708,2.5647,308.75,8000,8000
145.59008,0.84641,7.8577,0.0,300.0,1.6724,2.5736,308.75,8000,8000
145.59208,0.87081,7.8603,0.0,300.0,1.6735,2.6333,308.76,8000,8000
145.59408,0.87043,7.8556,0.0,300.0,1.6757,2.6252,308.77,8000,8000
145.59608,0.88182,7.8593,0.0,300.0,1.6759,2.6429,308.77,8000,8000
145.59808,0.89898,7.8609,0.0,300.0,1.6725,2.711,308.76,8000,8000
145.60008,0.90327,7.8585,0.0,300.0,1.6722,2.7385,308.73,8000,8000
145.60208,0.89097,7.8583,0.0,300.0,1.6717,2.684,308.7,8000,8000
145.60408,0.86677,7.8566,0.0,300.0,1.676,2.6001,308.67,8000,8000
145.60608,0.90122,7.8601,0.0,300.0,1.6762,2.6857,308.64,8000,8000
145.60808,0.91371,7.8561,0.0,300.0,1.6711,2.7652,308.61,8000,8000
145.61008,0.91022,7.8602,0.0,300.0,1.673,2.7493,308.59,8000,8000
145.61208,0.88771,7.8615,0.0,300.0,1.6722,2.6632,308.58,8000,8000
145.61408,0.91013,7.8549,0.0,300.0,1.6748,2.7142,308.56,8000,8000
145.61608,0.93038,7.8569,0.0,300.0,1.6751,2.7766,308.54,8000,8000
145.61808,0.92361,7.8574,0.0,300.0,1.6731,2.7812,308.53,8000,8000
145.62008,0.93864,7.8592,0.0,300.0,1.6722,2.8111,308.54,8000,8000
145.62208,1.0013,7.8607,0.0,300.0,1.6712,2.9897,308.55,8000,8000
145.62408,1.0182,7.8572,0.0,300.0,1.6754,3.0881,308.55,8000,8000
145.62608,0.98589,7.8595,0.0,300.0,1.6766,3.0042,308.56,8000,8000
145.62808,0.99893,7.8591,0.0,300.0,1.6746,3.0237,308.54,8000,8000
145.63007,0.97484,7.8585,0.0,300.0,1.6723,2.9361,308.51,8000,8000
145.63207,1.0071,7.862,0.0,300.0,1.6714,3.0365,308.47,8000,8000
145.63407,1.0714,7.86,0.0,300.0,1.6758,3.2284,308.43,8000,8000
145.63607,1.1052,7.8582,0.0,300.0,1.6751,3.3574,308.4,8000,8000
145.63807,1.1436,7.8573,0.0,300.0,1.6753,3.4613,308.34,8000,8000
145.64007,1.1723,7.8627,0.0,300.0,1.6751,3.5338,308.27,8000,8000
145.64207,1.2089,7.8626,0.0,300.0,1.6719,3.6825,308.19,8000,8000
145.64407,1.2119,7.8592,0.0,300.0,1.674,3.6676,308.12,8000,8000
145.64607,1.215,7.8595,0.0,300.0,1.6748,3.6987,308.05,8000,8000
145.64807,1.223,7.8576,0.0,300.0,1.676,3.6994,308.0,8000,8000
145.65007,1.2276,7.8587,0.0,300.0,1.6741,3.718,307.97,8000,8000
145.65207,1.2071,7.8592,0.0,300.0,1.6708,3.6727,307.95,8000,8000
145.65407,1.1948,7.8602,0.0,300.0,1.6736,3.6561,307.92,8000,8000
145.65607,1.1911,7.8599,0.0,300.0,1.6734,3.6633,307.9,8000,8000
145.65807,1.1872,7.8542,0.0,300.0,1.6749,3.6542,307.9,8000,8000
145.66007,1.1894,7.8593,0.0,300.0,1.6754,3.6444,307.91,8000,8000
145.66207,1.1778,7.8593,0.0,300.0,1.6715,3.6315,307.92,8000,8000
145.66407,1.157,7.8576,0.0,300.0,1.6716,3.5619,307.93,8000,8000
145.66607,1.1541,7.86,0.0,300.0,1.6723,3.5572,307.94,8000,8000
145.66807,1.1306,7.854,0.0,300.0,1.6747,3.4995,307.94,8000,8000
145.67007,1.1285,7.8555,0.0,300.0,1.6744,3.5021,307.91,8000,8000
145.67207,1.114,7.8588,0.0,300.0,1.6729,3.4439,307.89,8000,8000
145.67407,1.1115,7.8577,0.0,300.0,1.6713,3.4284,307.86,8000,8000
145.67607,1.0825,7.8584,0.0,300.0,1.6707,3.3564,307.84,8000,8000
145.67807,1.076,7.8544,0.0,300.0,1.6748,3.3332,307.81,8000,8000
145.68007,1.0648,7.86,0.0,300.0,1.6768,3.3032,307.79,8000,8000
145.68207,1.0583,7.8584,0.0,300.0,1.6736,3.257,307.77,8000,8000
145.68407,1.0514,7.8585,0.0,300.0,1.6721,3.2491,307.74,8000,8000
145.68607,1.0377,7.859,0.0,300.0,1.6714,3.2221,307.72,8000,8000
145.68807,1.0292,7.8582,0.0,300.0,1.6758,3.1823,307.69,8000,8000
145.69007,1.0214,7.8557,0.0,300.0,1.6742,3.1511,307.67,8000,8000
145.69207,1.0143,7.8545,0.0,300.0,1.6726,3.1147,307.64,8000,8000
145.69407,1.0105,7.8595,0.0,300.0,1.6729,3.0965,307.62,8000,8000
145.69607,1.0167,7.8581,0.0,300.0,1.6698,3.0992,307.59,8000,8000
145.69807,1.0049,7.8546,0.0,300.0,1.6732,3.0554,307.56,8000,8000
145.70007,1.0021,7.8566,0.0,300.0,1.675,3.0445,307.53,8000,8000
145.70207,1.0154,7.855,0.0,300.0,1.674,3.0849,307.49,8000,8000
145.70407,1.0125,7.8573,0.0,300.0,1.6722,3.0546,307.45,8000,8000
145.70607,1.0185,7.8582,0.0,300.0,1.6703,3.073,307.42,8000,8000
145.70807,1.0208,7.8553,0.0,300.0,1.6723,3.0636,307.39,8000,8000
145.71007,1.0397,7.856,0.0,300.0,1.6732,3.1047,307.36,8000,8000
145.71207,1.0368,7.8526,0.0,300.0,1.6736,3.0999,307.34,8000,8000
145.71407,1.0545,7.8566,0.0,300.0,1.6727,3.1586,307.31,8000,8000
145.71607,1.0683,7.8584,0.0,300.0,1.6705,3.1835,307.29,8000,8000
145.71807,1.0777,7.8581,0.0,300.0,1.6726,3.2099,307.27,8000,8000
145.72007,1.0992,7.8586,0.0,300.0,1.6733,3.2778,307.26,8000,8000
145.72207,1.1064,7.8542,0.0,300.0,1.6751,3.2927,307.25,8000,8000
145.72407,1.1308,7.8568,0.0,300.0,1.6746,3.3541,307.23,8000,8000
145.72607,1.1528,7.8596,0.0,300.0,1.6717,3.4244,307.22,8000,8000
145.72807,1.1787,7.8597,0.0,300.0,1.6726,3.5026,307.2,8000,8000
145.73007,1.1854,7.8598,0.0,300.0,1.6724,3.5315,307.18,8000,8000
145.73207,1.1976,7.8551,0.0,300.0,1.6754,3.5679,307.15,8000,8000
145.73407,1.2113,7.8572,0.0,300.0,1.6749,3.6011,307.13,8000,8000
145.73607,1.2282,7.8588,0.0,300.0,1.6727,3.685,307.11,8000,8000
145.73807,1.2442,7.86,0.0,300.0,1.6726,3.719,307.07,8000,8000
145.74007,1.2623,7.8599,0.0,300.0,1.6715,3.795,307.04,8000,8000
145.74207,1.2762,7.8549,0.0,300.0,1.6747,3.7919,307.0,8000,8000
145.74407,1.2742,7.8589,0.0,300.0,1.6765,3.8218,306.96,8000,8000
145.74607,1.2933,7.8576,0.0,300.0,1.673,3.8946,306.93,8000,8000
145.74807,1.3032,7.8582,0.0,300.0,1.6719,3.9295,306.89,8000,8000
145.75007,1.3101,7.8603,0.0,300.0,1.6712,3.9375,306.86,8000,8000
145.75207,1.2986,7.8567,0.0,300.0,1.6752,3.9214,306.83,8000,8000
145.75407,1.3169,7.8594,0.0,300.0,1.6766,3.9956,306.8,8000,8000
145.75607,1.3089,7.8563,0.0,300.0,1.6733,3.981,306.77,8000,8000
145.75807,1.2987,7.8598,0.0,300.0,1.6729,3.9648,306.75,8000,8000
145.76007,1.3061,7.8627,0.0,300.0,1.6718,3.9956,306.74,8000,8000
145.76207,1.3091,7.8576,0.0,300.0,1.6747,4.0198,306.73,8000,8000
145.76407,1.2944,7.8601,0.0,300.0,1.6764,3.9608,306.71,8000,8000
145.76607,1.2765,7.8579,0.0,300.0,1.6753,3.8953,306.7,8000,8000
145.76806,1.2803,7.8624,0.0,300.0,1.6747,3.9259,306.69,8000,8000
145.77006,1.2606,7.8643,0.0,300.0,1.673,3.9078,306.67,8000,8000
145.77206,1.2408,7.8595,0.0,300.0,1.6744,3.8372,306.65,8000,8000
145.77406,1.2335,7.8605,0.0,300.0,1.6758,3.8078,306.63,8000,8000
145.77606,1.2178,7.8592,0.0,300.0,1.6767,3.7631,306.61,8000,8000
145.77806,1.2064,7.8627,0.0,300.0,1.6757,3.7412,306.59,8000,8000
145.78006,1.1859,7.8612,0.0,300.0,1.6718,3.6646,306.58,8000,8000
145.78206,1.188,7.8611,0.0,300.0,1.6746,3.6786,306.56,8000,8000
145.78406,1.1673,7.8608,0.0,300.0,1.6743,3.6076,306.54,8000,8000
145.78606,1.1586,7.8589,0.0,300.0,1.6775,3.5672,306.52,8000,8000
145.78806,1.1466,7.8616,0.0,300.0,1.6766,3.5512,306.51,8000,8000
145.79006,1.1338,7.8603,0.0,300.0,1.6721,3.4997,306.49,8000,8000
145.79206,1.122,7.8621,0.0,300.0,1.6744,3.4694,306.48,8000,8000
145.79406,1.1165,7.8621,0.0,300.0,1.674,3.4492,306.47,8000,8000
145.79606,1.1063,7.858,0.0,300.0,1.677,3.39,306.46,8000,8000
145.79806,1.1098,7.8601,0.0,300.0,1.6768,3.4094,306.45,8000,8000
145.80006,1.1073,7.8616,0.0,300.0,1.6737,3.3878,306.43,8000,8000
145.80206,1.0914,7.8614,0.0,300.0,1.6733,3.3397,306.42,8000,8000
145.80406,1.0981,7.8613,0.0,300.0,1.673,3.3421,306.41,8000,8000
145.80606,1.1006,7.8603,0.0,300.0,1.6775,3.348,306.4,8000,8000
145.80806,1.1011,7.8604,0.0,300.0,1.6769,3.3511,306.38,8000,8000
145.81006,1.1069,7.8591,0.0,300.0,1.674,3.3408,306.35,8000,8000
145.81206,1.0983,7.8654,0.0,300.0,1.6756,3.3346,306.33,8000,8000
145.81406,1.114,7.8621,0.0,300.0,1.6721,3.3693,306.3,8000,8000
145.81606,1.1146,7.8587,0.0,300.0,1.6761,3.3723,306.28,8000,8000
145.81806,1.1203,7.8604,0.0,300.0,1.677,3.3666,306.25,8000,8000
145.82006,1.1282,7.8602,0.0,300.0,1.6752,3.3853,306.22,8000,8000
145.82206,1.1502,7.8619,0.0,300.0,1.6737,3.4669,306.19,8000,8000
145.82406,1.1505,7.8653,0.0,300.0,1.6734,3.4485,306.16,8000,8000
145.82606,1.1692,7.8584,0.0,300.0,1.6749,3.4722,306.13,8000,8000
145.82806,1.1856,7.8586,0.0,300.0,1.6756,3.51,306.1,8000,8000
145.83006,1.1974,7.8584,0.0,300.0,1.6751,3.5592,306.08,8000,8000
145.83206,1.2194,7.8624,0.0,300.0,1.6745,3.6215,306.05,8000,8000
145.83406,1.231,7.8618,0.0,300.0,1.6716,3.6674,306.03,8000,8000
145.83606,1.243,7.8571,0.0,300.0,1.6732,3.6975,306.0,8000,8000
145.83806,1.2677,7.858,0.0,300.0,1.6748,3.7714,305.99,8000,8000
145.84006,1.2811,7.8596,0.0,300.0,1.6771,3.7939,305.97,8000,8000
145.84206,1.3061,7.8619,0.0,300.0,1.6751,3.9038,305.96,8000,8000
145.84406,1.3151,7.862,0.0,300.0,1.6724,3.905,305.95,8000,8000
145.84606,1.3348,7.8637,0.0,300.0,1.6757,3.972,305.94,8000,8000
145.84806,1.3446,7.8623,0.0,300.0,1.675,4.0203,305.93,8000,8000
145.85006,1.3541,7.8588,0.0,300.0,1.677,4.0458,305.91,8000,8000
145.85206,1.3509,7.8619,0.0,300.0,1.6768,4.0456,305.9,8000,8000
145.85406,1.3767,7.8639,0.0,300.0,1.6732,4.1277,305.89,8000,8000
145.85606,1.374,7.8628,0.0,300.0,1.6744,4.1493,305.88,8000,8000
145.85806,1.3855,7.8638,0.0,300.0,1.675,4.1632,305.85,8000,8000
145.86006,1.3881,7.86,0.0,300.0,1.6777,4.1978,305.81,8000,8000
145.86206,1.3899,7.8635,0.0,300.0,1.678,4.2113,305.78,8000,8000
145.86406,1.383,7.8629,0.0,300.0,1.6743,4.1958,305.74,8000,8000
145.86606,1.3865,7.863,0.0,300.0,1.6745,4.2131,305.7,8000,8000
145.86806,1.3944,7.8638,0.0,300.0,1.6737,4.2572,305.67,8000,8000
145.87006,1.3846,7.8611,0.0,300.0,1.6776,4.2301,305.63,8000,8000
145.87206,1.3753,7.8626,0.0,300.0,1.6777,4.195,305.59,8000,8000
145.87406,1.3603,7.8631,0.0,300.0,1.6759,4.1746,305.56,8000,8000
145.87606,1.3588,7.8647,0.0,300.0,1.6753,4.1598,305.52,8000,8000
145.87806,1.3603,7.8645,0.0,300.0,1.6735,4.1858,305.5,8000,8000
145.88006,1.3326,7.8606,0.0,300.0,1.6771,4.105,305.49,8000,8000
145.88206,1.3214,7.8637,0.0,300.0,1.6784,4.0617,305.47,8000,8000
145.88406,1.3026,7.8636,0.0,300.0,1.6767,4.0105,305.46,8000,8000
145.88606,1.2925,7.8655,0.0,300.0,1.6755,3.9913,305.45,8000,8000
145.88806,1.2747,7.8656,0.0,300.0,1.673,3.9486,305.43,8000,8000
145.89006,1.2752,7.8619,0.0,300.0,1.677,3.9602,305.4,8000,8000
145.89206,1.2447,7.8645,0.0,300.0,1.6787,3.8643,305.37,8000,8000
145.89406,1.2343,7.8629,0.0,300.0,1.6776,3.8351,305.33,8000,8000
145.89606,1.2181,7.8663,0.0,300.0,1.6772,3.7655,305.3,8000,8000
145.89806,1.2087,7.8673,0.0,300.0,1.6744,3.7396,305.26,8000,8000
145.90006,1.2044,7.8626,0.0,300.0,1.6762,3.7233,305.21,8000,8000
145.90206,1.1944,7.8658,0.0,300.0,1.6785,3.6803,305.17,8000,8000
145.90406,1.182,7.8619,0.0,300.0,1.678,3.6526,305.12,8000,8000
145.90605,1.1668,7.8643,0.0,300.0,1.6763,3.5799,305.07,8000,8000
145.90805,1.1748,7.8662,0.0,300.0,1.6741,3.6166,305.04,8000,8000
145.91005,1.1735,7.8649,0.0,300.0,1.6765,3.5949,305.03,8000,8000
145.91205,1.1557,7.8634,0.0,300.0,1.676,3.5341,305.01,8000,8000
145.91405,1.1616,7.8596,0.0,300.0,1.6775,3.5401,305.0,8000,8000
145.91605,1.1708,7.8656,0.0,300.0,1.6787,3.563,304.99,8000,8000
145.9176,1.4426,7.8606,0.0,299.63,1.6771,4.3809,304.98,8000,8000
147.9176,1.2351,7.8728,0.0,50.468,1.6808,3.7467,245.05,8000,8000
149.6195,1.1636,7.8783,0.0,50.002,1.6836,3.5311,211.95,8000,8000
151.6195,1.1886,7.8861,0.0,50.0,1.6876,3.6054,182.13,8000,8000
153.6195,1.1998,7.8928,0.0,50.0,1.6909,3.6392,158.57,8000,8000
155.6195,1.2093,7.8983,0.0,50.0,1.6937,3.6684,139.75,8000,8000
157.0818,1.2148,7.9022,0.0,50.0,1.6958,3.685,128.38,8000,8000
159.0818,1.2217,7.9072,0.0,50.0,1.6983,3.7055,115.38,8000,8000
161.0818,1.2303,7.9115,0.0,50.0,1.7005,3.7329,104.28,8000,8000
163.0818,1.2332,7.9157,0.0,50.0,1.7027,3.7406,95.106,8000,8000
165.0818,1.2395,7.9192,0.0,50.0,1.7046,3.7601,87.209,8000,8000
167.0818,1.2404,7.9229,0.0,50.0,1.7064,3.7638,80.555,8000,8000
169.0818,1.2459,7.926,0.0,50.0,1.7081,3.7794,74.648,8000,8000
171.0818,1.2446,7.9288,0.0,50.0,1.7094,3.7758,69.621,8000,8000
173.0818,1.2477,7.9316,0.0,50.0,1.7108,3.7839,64.978,8000,8000
175.0818,1.2501,7.934,0.0,50.0,1.7122,3.7925,60.937,8000,8000
177.0818,1.2512,7.9364,0.0,50.0,1.7134,3.7957,57.448,8000,8000
179.0818,1.2542,7.9383,0.0,50.0,1.7144,3.8053,54.282,8000,8000
181.0818,1.255,7.9405,0.0,50.0,1.7156,3.8078,51.347,8000,8000
182.2445,1.2549,7.9425,1.447,50.0,1.7165,3.8067,49.817,8000,8000
184.2445,1.2691,7.9432,24.619,50.0,1.717,3.8496,48.112,8000,8000
186.2445,1.264,7.9399,10.43,17.842,1.7153,3.8341,49.3,8000,8000
187.7734,1.2426,7.941,0.083598,0.14673,1.7158,3.7706,52.973,8000,8000
189.7734,1.2938,7.9417,0.0001566,0.00027488,1.7162,3.9241,54.435,8000,8000
191.7734,1.3196,7.9452,2.9339e-07,5.1496e-07,1.718,4.003,54.941,8000,8000
192.7734,1.3452,7.9454,1.2699e-08,2.2289e-08,1.7181,4.0805,54.926,8000,8000