File: examples/dan-msc-case-studies/CS4/data/01 raw data/hyde_test_018.csv
Time(sec),Force(kN),Jaw(mm),PowAngle(deg),PTemp,Strain,Stress(MPa),TC1(C),TC2(C),TC3(C),TC4(C)
0.0,2.4945,-10.197,0.0,0.003225,-0.78084,2.9656,24.739,24.357,24.922,24.629
0.6,2.4472,-0.0010657,0.0,1.6208,-9.3134e-05,2.9051,24.67,24.441,24.94,24.501
1.2,2.4331,0.00015512,0.0,3.4208,3.121e-05,2.8888,24.746,24.491,24.983,24.545
1.8,2.4147,0.00026482,0.0,5.2208,5.1727e-05,2.8666,24.733,24.4,24.923,24.514
2.4,2.4358,0.0012598,0.0,7.0208,0.00013188,2.8903,24.757,24.459,24.961,24.496
3.0,2.4874,0.0025207,0.0,8.8208,0.00025945,2.9524,24.721,24.432,24.948,24.518
3.6,2.5314,0.0033351,0.0,10.621,0.00037661,3.005,24.733,24.427,24.955,24.483
4.2,2.5525,0.0038415,0.0,12.421,0.00044378,3.0287,24.719,24.473,24.954,24.53
4.8,2.5737,0.0045909,0.0,14.221,0.00049806,3.0546,24.76,24.362,24.97,24.508
5.3246,2.586,0.0048423,0.0,15.804,0.00052382,3.069,24.681,24.435,24.969,24.543
5.9246,2.598,0.0051937,0.0,17.595,0.00057232,3.0829,24.716,24.403,24.965,24.503
6.5246,2.5974,0.0053341,0.0,19.395,0.00060076,3.0825,24.689,24.448,24.975,24.543
7.1246,2.5915,0.0053947,0.0,21.195,0.00060669,3.0747,24.71,24.447,24.929,24.473
7.7246,2.5803,0.0054138,0.0,22.995,0.00058635,3.0617,24.729,24.476,25.017,24.548
8.3246,2.5521,0.0048366,0.0,24.795,0.00052869,3.0285,24.73,24.455,24.975,24.533
8.9246,2.4998,0.0045444,19.997,26.595,0.00050839,2.9659,24.734,24.466,24.962,24.502
9.5246,2.3939,0.0039298,29.595,28.395,0.00045988,2.8401,25.428,24.904,25.014,24.599
10.1246,2.2893,0.002909,33.412,30.195,0.00030894,2.7176,26.988,25.924,25.065,24.965
10.6264,2.1988,0.0019193,35.371,31.7,0.00020547,2.6101,28.616,27.34,25.242,25.8
11.2264,2.1218,0.0010836,36.259,33.5,0.00012462,2.5185,30.814,29.373,25.582,27.203
11.8264,2.0964,-0.00073869,36.774,35.3,-7.3397e-05,2.4885,33.036,38.318,26.083,28.885
12.4264,2.0666,-0.00088271,36.935,37.1,-7.8171e-05,2.4518,35.274,38.389,26.762,30.841
13.0264,2.0598,-0.001632,36.881,38.9,-0.0001904,2.4448,37.446,38.389,27.69,32.895
13.6264,2.0484,-0.0020942,37.077,40.7,-0.00024602,2.4313,39.533,39.327,28.774,34.977
14.2264,2.0396,-0.0027107,36.995,42.5,-0.00028263,2.4212,41.602,41.709,30.0,37.107
14.8264,2.0349,-0.0042596,37.079,44.3,-0.00044449,2.4156,43.592,44.048,31.409,39.334
15.4264,2.0332,-0.0044341,37.061,46.1,-0.00049678,2.4131,45.546,46.294,32.895,41.451
16.0264,2.0252,-0.0049136,36.744,47.9,-0.0005428,2.4037,47.513,48.567,34.516,43.626
16.6264,2.024,-0.0053682,37.09,49.7,-0.00058528,2.4026,49.316,50.727,36.184,45.734
17.2264,2.0213,-0.0059057,37.089,51.5,-0.00062454,2.4001,51.176,52.789,37.987,47.879
17.8264,2.0159,-0.0075595,37.024,53.3,-0.00083038,2.3936,53.056,54.872,39.739,49.992
18.4264,2.0186,-0.0078169,37.298,55.1,-0.00086695,2.3963,54.824,56.975,41.658,52.103
19.0264,2.0171,-0.0084428,37.121,56.9,-0.00091171,2.3943,56.722,58.931,43.601,54.164
19.6264,2.0086,-0.0090938,37.59,58.7,-0.00097862,2.3848,58.492,61.029,45.595,56.207
20.2264,2.0142,-0.0094142,37.385,60.5,-0.0010339,2.3903,60.406,63.039,47.57,58.296
20.8264,2.0147,-0.011609,37.588,62.3,-0.0012946,2.3921,62.178,65.016,49.559,60.346
21.4264,2.0098,-0.011744,37.743,64.1,-0.0012778,2.3852,63.993,66.971,51.557,62.337
22.0264,2.0091,-0.01239,37.734,65.9,-0.0013602,2.3842,65.793,68.924,53.551,64.399
22.6264,1.9648,-0.013528,37.837,67.7,-0.0014941,2.3312,67.574,70.919,55.545,66.366
23.2264,1.8413,-0.014667,38.355,69.5,-0.0016394,2.185,69.304,72.882,57.586,68.392
23.8264,1.7185,-0.016557,38.392,71.3,-0.0018255,2.0392,71.121,74.925,59.608,70.427
24.4264,1.6112,-0.019139,38.527,73.1,-0.0020923,1.9125,72.902,76.917,61.6,72.432
25.0264,1.5194,-0.020476,38.562,74.9,-0.0022573,1.8044,74.788,78.877,63.766,74.524
25.6264,1.4493,-0.021812,38.628,76.7,-0.0024286,1.7203,76.537,80.901,65.745,76.575
26.2264,1.41,-0.022958,38.841,78.5,-0.0025416,1.6733,78.35,82.963,67.844,78.566
26.8264,1.3805,-0.023747,38.967,80.3,-0.0026139,1.6385,80.162,84.926,69.827,80.622
27.4264,1.3461,-0.024767,39.238,82.1,-0.0027319,1.5975,81.884,87.003,71.832,82.641
28.0264,1.3169,-0.027162,39.356,83.9,-0.0030052,1.5632,83.701,89.084,73.953,84.706
28.6264,1.2537,-0.027814,39.454,85.7,-0.0030645,1.488,85.491,91.052,75.916,86.722
29.2264,1.1926,-0.029068,39.738,87.5,-0.003208,1.416,87.249,93.195,78.015,88.785
29.8264,1.1438,-0.030421,39.916,89.3,-0.0033487,1.3574,89.08,95.301,80.086,90.834
30.4264,1.1037,-0.031297,39.777,91.1,-0.0034579,1.311,90.965,97.488,82.195,92.855
31.0264,1.0668,-0.031968,39.871,92.9,-0.0035253,1.266,92.781,99.607,84.275,94.971
31.6264,1.0447,-0.033842,39.925,94.7,-0.0037445,1.24,94.599,101.77,86.299,97.011
32.2264,1.0166,-0.035021,39.962,96.5,-0.0038317,1.2062,96.371,103.8,88.424,99.048
32.8264,0.9959,-0.036153,40.057,98.3,-0.0039999,1.1823,98.173,105.83,90.492,101.04
33.4264,0.97886,-0.037252,40.086,100.1,-0.00413,1.1615,100.01,107.73,92.576,103.04
34.0264,0.97165,-0.038024,40.19,101.9,-0.0041914,1.1536,101.83,109.72,94.588,105.03
34.6264,0.96291,-0.038572,40.128,103.7,-0.0042229,1.1428,103.66,111.86,96.645,107.02
35.2264,0.96056,-0.038599,40.275,105.5,-0.0042697,1.1395,105.44,113.87,98.687,109.03
35.8264,0.90203,-0.041174,40.337,107.3,-0.0045582,1.0708,107.24,115.92,100.76,110.95
36.4264,0.82785,-0.042475,40.144,109.1,-0.0046758,0.98274,109.08,117.8,102.74,112.91
37.0264,0.78584,-0.044409,40.442,110.9,-0.0048882,0.93203,110.85,119.84,104.76,114.92
37.6264,0.75581,-0.046432,40.334,112.7,-0.0051274,0.89717,112.66,121.85,106.79,116.84
38.1602,0.74573,-0.047601,40.489,114.3,-0.0052644,0.88493,114.27,123.57,108.57,118.55
38.7602,0.74152,-0.048447,40.569,116.1,-0.0053456,0.88088,116.02,125.48,110.54,120.43
39.3602,0.73973,-0.05119,40.62,117.9,-0.0056418,0.87837,117.78,127.47,112.51,122.41
39.9602,0.7356,-0.051781,40.727,119.7,-0.0056927,0.87361,119.56,129.45,114.51,124.29
40.5602,0.7354,-0.052877,40.997,121.5,-0.0058464,0.87243,121.3,131.45,116.47,126.27
41.1602,0.73765,-0.054012,41.141,123.3,-0.0059726,0.87544,123.16,133.3,118.43,128.19
41.7602,0.73645,-0.05494,41.102,125.1,-0.0060477,0.87538,124.94,135.3,120.33,130.08
42.3602,0.74043,-0.056066,41.196,126.9,-0.006169,0.87849,126.77,137.28,122.33,132.06
42.9602,0.73412,-0.057977,41.296,128.7,-0.006391,0.8719,128.55,139.27,124.28,134.0
43.4753,0.73546,-0.058985,41.326,130.25,-0.0065054,0.87188,130.13,141.0,126.0,135.68
44.0753,0.73641,-0.060122,41.623,132.05,-0.0066475,0.87393,131.87,143.0,127.95,137.61
44.6753,0.73314,-0.061362,41.706,133.85,-0.0067561,0.87019,133.68,144.96,129.91,139.56
45.2753,0.73654,-0.061997,41.79,135.65,-0.0068353,0.87379,135.49,147.05,131.85,141.52
45.8753,0.73375,-0.065161,41.691,137.45,-0.0071786,0.87012,137.35,149.04,133.86,143.52
46.4753,0.73507,-0.065136,41.427,139.25,-0.0072011,0.87261,139.24,151.06,135.82,145.47
47.0753,0.73563,-0.066377,41.697,141.05,-0.0073158,0.87328,140.99,153.13,137.77,147.31
47.6753,0.73332,-0.067437,41.766,142.85,-0.0074272,0.86992,142.75,155.1,139.73,149.21
48.2753,0.73883,-0.06815,41.896,144.65,-0.0074843,0.87673,144.51,157.1,141.7,151.1
48.8753,0.73612,-0.070399,42.019,146.45,-0.0077741,0.87437,146.33,159.26,143.62,153.03
49.4753,0.73389,-0.071095,42.132,148.25,-0.0078569,0.87058,148.08,161.21,145.62,154.91
50.0753,0.7379,-0.072384,42.437,150.05,-0.0079727,0.87565,149.84,163.21,147.53,156.81
50.6753,0.73503,-0.073568,42.394,151.85,-0.0080917,0.87163,151.7,165.51,149.43,158.68
51.2753,0.73786,-0.074218,42.396,153.65,-0.0081838,0.87534,153.49,167.55,151.34,160.57
51.8753,0.73794,-0.075984,41.572,155.45,-0.0083894,0.87598,155.24,169.57,153.32,162.63
52.4753,0.73416,-0.076391,39.669,157.25,-0.0084161,0.87144,156.72,171.01,155.26,164.48
53.0753,0.72624,-0.076976,37.121,159.05,-0.0084533,0.86202,157.67,171.65,157.12,165.98
53.6753,0.72584,-0.076911,34.26,160.85,-0.0084815,0.86064,158.2,171.6,158.78,166.89
54.2753,0.71504,-0.076737,32.056,162.65,-0.0084692,0.84812,158.13,170.76,160.26,167.29
54.8753,0.7234,-0.077102,35.234,164.45,-0.0084894,0.85771,158.17,170.05,161.46,167.16
55.4753,0.73818,-0.078251,36.456,166.25,-0.0086008,0.87533,158.55,170.07,162.49,167.02
56.0753,0.73684,-0.07899,37.559,168.05,-0.0087049,0.87486,159.12,170.32,163.32,167.02
56.6753,0.73832,-0.079847,38.586,169.85,-0.0088141,0.87624,160.04,171.14,164.04,167.36
57.2753,0.73928,-0.080794,40.408,171.65,-0.0088826,0.87689,161.14,172.17,164.66,167.85
57.8753,0.74438,-0.081434,41.765,173.45,-0.0089532,0.88355,162.62,173.95,165.39,168.72
58.4753,0.74306,-0.084894,42.9,175.25,-0.009345,0.88151,164.24,176.1,166.24,169.99
59.0753,0.739,-0.085438,43.522,177.05,-0.0094322,0.87676,166.08,178.53,167.11,171.63
59.6753,0.73842,-0.086769,43.7,178.85,-0.0095443,0.8758,168.09,181.26,168.27,173.62
60.2753,0.7366,-0.088025,43.539,180.65,-0.0096856,0.87397,170.12,183.81,169.59,175.77
60.8753,0.74158,-0.088647,43.442,182.45,-0.0097493,0.88003,172.16,186.4,170.98,178.01
61.4753,0.73791,-0.09087,43.064,184.25,-0.01003,0.87555,174.2,188.84,172.59,180.33
62.0753,0.7375,-0.091656,42.911,186.05,-0.010095,0.87481,176.2,191.1,174.37,182.66
62.6753,0.73797,-0.09323,42.641,187.85,-0.010249,0.87506,178.16,193.24,176.23,184.88
63.2753,0.73551,-0.094501,42.172,189.65,-0.010384,0.87339,180.07,195.2,178.15,187.06
63.8753,0.73839,-0.094922,42.305,191.45,-0.010453,0.87639,181.84,197.16,180.04,189.05
64.4753,0.73911,-0.096539,41.882,193.25,-0.010645,0.87657,183.77,198.99,182.0,191.04
65.0753,0.73506,-0.097517,41.878,195.05,-0.010727,0.87184,185.49,200.71,183.92,192.91
65.6753,0.73556,-0.099417,42.112,196.85,-0.01092,0.87201,187.24,202.48,185.88,194.77
66.2753,0.73975,-0.10038,42.182,198.65,-0.011067,0.87701,188.97,204.38,187.83,196.6
66.8753,0.74019,-0.10098,42.396,200.45,-0.011121,0.87842,190.72,206.19,189.8,198.39
67.4753,0.74191,-0.10266,42.397,202.25,-0.011301,0.87948,192.46,207.96,191.72,200.22
68.0753,0.73327,-0.10384,42.551,204.05,-0.011414,0.87019,194.28,209.83,193.58,202.11
68.6753,0.73903,-0.10547,42.478,205.85,-0.011607,0.87703,196.07,211.67,195.52,203.95
69.2753,0.74062,-0.10645,42.61,207.65,-0.011717,0.87986,197.86,213.53,197.37,205.77
69.8753,0.7358,-0.10742,43.071,209.45,-0.011803,0.87315,199.58,215.33,199.25,207.63
70.4753,0.73331,-0.10949,42.963,211.27,-0.012036,0.86979,201.45,217.3,201.15,209.5
70.8963,0.74311,-0.11064,42.725,212.51,-0.01214,0.88184,202.78,218.7,202.47,210.85
71.4963,0.73856,-0.11119,42.82,214.31,-0.012224,0.87595,204.56,220.51,204.35,212.74
72.0963,0.73666,-0.11254,42.934,216.11,-0.012388,0.87404,206.28,222.36,206.35,214.68
72.6963,0.73983,-0.11358,42.889,217.91,-0.012471,0.878,208.2,224.24,208.2,216.54
73.2963,0.7421,-0.11413,42.728,219.71,-0.012551,0.88053,210.01,226.05,210.12,218.49
73.8963,0.73822,-0.11645,42.68,221.51,-0.012778,0.87587,211.88,227.86,212.03,220.39
74.4963,0.74282,-0.11761,42.685,223.31,-0.012943,0.88247,213.6,229.66,213.87,222.26
75.0963,0.74285,-0.11906,42.828,225.11,-0.013077,0.88215,215.39,231.53,215.79,223.97
75.6963,0.7426,-0.11994,42.867,226.91,-0.013171,0.8812,217.21,233.35,217.63,225.8
76.2963,0.74564,-0.12097,42.907,228.71,-0.01329,0.88475,218.99,235.13,219.47,227.63
76.8963,0.74253,-0.12273,43.121,230.51,-0.013483,0.8816,220.75,237.08,221.38,229.55
77.4963,0.73982,-0.12448,42.828,232.31,-0.013681,0.87848,222.63,238.81,223.29,231.45
78.0963,0.73993,-0.12583,42.985,234.11,-0.013821,0.87893,224.4,240.71,225.16,233.34
78.6963,0.74139,-0.1264,42.976,235.91,-0.013864,0.88118,226.25,242.67,227.08,235.24
79.2963,0.74426,-0.12848,42.664,237.71,-0.01414,0.88387,228.1,244.61,228.95,237.15
79.8963,0.73788,-0.12956,42.512,239.51,-0.014254,0.87603,229.94,246.38,230.88,239.01
80.4963,0.74071,-0.1311,42.948,241.31,-0.014397,0.87887,231.65,248.15,232.81,240.82
81.0963,0.74515,-0.13209,42.922,243.11,-0.0145,0.88381,233.46,249.96,234.64,242.65
81.6963,0.74515,-0.1325,42.561,244.91,-0.014563,0.88507,235.3,251.85,236.58,244.52
82.2963,0.74654,-0.13583,42.961,246.71,-0.014919,0.88661,236.98,253.51,238.42,246.33
82.8963,0.74435,-0.13649,43.036,248.51,-0.014976,0.88322,238.73,255.31,240.29,248.14
83.4963,0.74477,-0.1378,43.217,250.31,-0.015117,0.8841,240.52,257.11,242.09,249.9
84.0963,0.74508,-0.13835,43.394,252.11,-0.015198,0.88514,242.25,258.81,244.01,251.78
84.6963,0.74795,-0.14023,43.451,253.91,-0.015427,0.88694,244.05,260.64,245.8,253.61
85.2963,0.74157,-0.14113,43.395,255.71,-0.015498,0.8799,245.93,262.54,247.68,255.48
85.8963,0.74044,-0.14318,43.525,257.51,-0.015714,0.87903,247.66,264.42,249.52,257.42
86.4963,0.74611,-0.14457,43.52,259.31,-0.015868,0.88614,249.52,266.39,251.4,259.31
87.0963,0.74614,-0.14473,43.529,261.11,-0.015896,0.88531,251.29,268.23,253.29,261.2
87.6963,0.74808,-0.14867,43.694,262.91,-0.016313,0.88839,253.09,270.22,255.23,263.08
88.2963,0.74072,-0.14904,43.647,264.71,-0.016359,0.879,254.95,272.16,257.09,264.95
88.8963,0.74435,-0.15035,43.785,266.51,-0.016487,0.88388,256.75,273.98,259.01,266.94
89.4963,0.7428,-0.15098,43.715,268.31,-0.016578,0.88185,258.58,275.9,260.94,268.89
90.0963,0.74504,-0.15135,43.642,270.11,-0.016622,0.88523,260.41,277.78,262.84,270.75
90.6963,0.74313,-0.15427,43.969,271.91,-0.016908,0.88188,262.15,279.69,264.72,272.64
91.2963,0.74315,-0.15552,43.893,273.71,-0.017043,0.8827,263.97,281.61,266.63,274.5
91.8963,0.74436,-0.15686,44.077,275.51,-0.017217,0.88456,265.75,283.59,268.59,276.47
92.4963,0.747,-0.15771,44.049,277.31,-0.017315,0.8867,267.51,285.58,270.5,278.39
93.0963,0.74349,-0.15867,44.114,279.11,-0.017412,0.88348,269.32,287.6,272.44,280.41
93.6963,0.74961,-0.16153,43.989,280.91,-0.017686,0.88994,271.22,289.49,274.38,282.33
94.2963,0.74406,-0.16263,43.995,282.71,-0.017847,0.88305,273.01,291.36,276.36,284.31
94.8963,0.74408,-0.16408,43.904,284.51,-0.018009,0.88239,274.85,293.4,278.24,286.23
95.4963,0.7486,-0.16508,44.027,286.31,-0.018093,0.88883,276.62,295.3,280.14,288.08
96.0963,0.74896,-0.16541,44.077,288.11,-0.018133,0.8886,278.37,297.23,282.02,289.99
96.6963,0.75043,-0.1696,44.127,289.91,-0.018604,0.88995,280.14,299.13,283.98,291.83
97.2963,0.74446,-0.17015,44.376,291.71,-0.018679,0.88344,281.89,301.0,285.89,293.71
97.8963,0.74451,-0.17149,44.543,293.51,-0.018808,0.88428,283.69,303.08,287.86,295.7
98.4963,0.74796,-0.17277,44.54,295.31,-0.018935,0.88782,285.54,305.1,289.77,297.73
99.0963,0.74571,-0.17371,44.321,297.11,-0.019027,0.88616,287.41,307.25,291.74,299.8
99.6963,0.75073,-0.17504,44.158,298.91,-0.019216,0.89194,289.28,309.32,293.69,301.72
100.2963,0.7498,-0.17727,44.078,300.71,-0.019412,0.88964,291.08,311.4,295.62,303.67
100.8963,0.74458,-0.1788,44.357,302.51,-0.019589,0.88436,292.83,313.32,297.54,305.62
101.4963,0.74375,-0.1805,44.275,304.31,-0.019758,0.88271,294.6,315.21,299.44,307.42
102.0963,0.74884,-0.18176,44.212,306.11,-0.019927,0.88885,296.41,317.16,301.36,309.37
102.6963,0.75023,-0.18232,44.345,307.91,-0.019986,0.89139,298.21,319.2,303.5,311.33
103.1281,0.74803,-0.18303,44.196,309.21,-0.020075,0.88844,299.56,320.63,305.06,312.65
103.7281,0.74736,-0.18741,44.371,311.01,-0.020505,0.88797,301.32,322.68,307.3,314.67
104.3281,0.74359,-0.1881,44.272,312.81,-0.020611,0.88142,303.16,324.61,309.5,316.64
104.9281,0.74341,-0.18918,44.107,314.61,-0.020718,0.88297,305.02,326.53,311.76,318.58
105.5281,0.74864,-0.19038,44.271,316.41,-0.020868,0.88988,306.79,328.37,314.3,320.42
106.1281,0.74728,-0.19127,43.853,318.21,-0.020945,0.8879,308.69,330.35,317.08,322.26
106.7281,0.75036,-0.19194,44.076,320.01,-0.021028,0.89122,310.44,332.09,319.27,324.05
107.3281,0.75372,-0.1962,44.095,321.81,-0.021468,0.8942,312.19,334.05,321.48,325.83
107.9281,0.74073,-0.19597,44.151,323.61,-0.02148,0.88071,313.94,335.83,323.63,327.59
108.5281,0.74654,-0.19779,44.087,325.41,-0.021668,0.88646,315.72,337.62,325.63,329.51
109.1281,0.74628,-0.19939,44.2,327.21,-0.021824,0.88631,317.51,339.59,327.84,331.29
109.7281,0.7501,-0.20065,44.482,329.01,-0.021939,0.89123,319.24,341.47,329.75,333.17
110.3281,0.75117,-0.20118,44.487,330.81,-0.022029,0.89152,321.04,343.4,331.71,335.09
110.9281,0.75166,-0.20582,44.526,332.61,-0.022545,0.89325,322.88,345.5,333.63,336.97
111.5281,0.74545,-0.20527,44.437,334.41,-0.022479,0.88435,324.71,347.49,335.6,338.89
112.1281,0.74346,-0.20782,44.583,336.21,-0.022739,0.88355,326.46,349.47,337.59,340.9
112.7281,0.7485,-0.20926,44.604,338.01,-0.022903,0.88923,328.27,351.38,339.63,342.79
113.3281,0.75215,-0.21052,45.93,339.81,-0.02306,0.89355,330.05,353.44,341.54,344.72
113.9281,0.7554,-0.21246,48.332,341.61,-0.023237,0.89738,332.0,356.07,343.51,346.82
114.5281,0.75754,-0.2177,48.617,343.41,-0.023842,0.90015,334.17,359.67,345.84,349.63
115.1281,0.75016,-0.22019,48.353,345.21,-0.024052,0.89018,336.49,363.42,348.73,353.12
115.7281,0.74762,-0.22331,48.722,347.01,-0.02443,0.88872,339.09,366.89,352.13,356.73
116.3281,0.74982,-0.22614,49.588,348.81,-0.024722,0.88989,341.64,370.86,355.55,360.38
116.9281,0.75109,-0.22925,49.998,350.61,-0.02505,0.89166,344.42,375.1,359.14,364.25
117.5281,0.75083,-0.23181,50.033,352.41,-0.025326,0.89178,347.38,379.44,363.09,368.43
118.1281,0.75357,-0.23343,49.52,354.21,-0.025535,0.89459,350.51,383.87,367.35,372.81
118.7281,0.75209,-0.23814,47.681,356.01,-0.026052,0.89305,353.68,387.93,371.54,376.94
119.3281,0.75,-0.23947,47.414,357.81,-0.02613,0.89155,356.82,391.76,375.55,380.86
119.9281,0.7347,-0.24105,44.498,359.61,-0.026309,0.87265,359.85,395.11,379.38,384.28
120.5281,0.73423,-0.24127,43.065,361.41,-0.026375,0.87226,362.69,397.17,382.62,386.97
121.1281,0.71864,-0.24061,39.688,363.21,-0.026317,0.85259,365.2,398.35,385.16,388.85
121.7281,0.7096,-0.23934,37.147,365.01,-0.026142,0.84206,367.2,398.12,386.71,389.64
122.3281,0.7052,-0.23811,35.692,366.81,-0.026013,0.83729,368.75,396.91,387.36,389.43
122.9281,0.70402,-0.23727,36.441,368.61,-0.025927,0.83621,369.76,395.35,387.3,388.52
123.5281,0.72432,-0.23882,38.933,370.41,-0.026136,0.86092,370.41,394.02,386.88,387.4
124.1281,0.74042,-0.24085,42.226,372.21,-0.026297,0.87904,370.89,393.66,386.41,386.62
124.7281,0.74787,-0.24121,45.272,374.01,-0.026378,0.88726,371.46,394.96,386.34,386.63
125.3281,0.75596,-0.24647,48.278,375.81,-0.02691,0.89734,372.25,397.66,386.93,387.71
125.9281,0.75788,-0.25028,50.22,377.61,-0.027356,0.9005,373.52,401.98,388.4,389.93
126.5281,0.75778,-0.25526,51.663,379.41,-0.027882,0.90087,375.14,407.6,390.67,393.27
127.1281,0.75432,-0.26011,52.596,381.21,-0.028395,0.89487,377.1,413.82,394.17,397.95
127.7281,0.75497,-0.26462,52.852,383.01,-0.028853,0.89714,379.45,420.23,399.03,403.44
128.3281,0.75678,-0.26831,52.1,384.81,-0.02928,0.8985,382.26,426.69,404.48,409.59
128.9281,0.75438,-0.27035,50.577,386.61,-0.029508,0.89584,385.39,432.89,409.98,415.62
129.5281,0.75291,-0.27107,47.623,388.41,-0.029567,0.89425,388.81,438.1,415.23,421.03
130.1281,0.72263,-0.27113,43.217,390.21,-0.029584,0.85756,392.35,441.67,419.72,425.36
130.7281,0.70181,-0.2705,37.284,392.01,-0.029533,0.83357,395.55,442.61,422.95,427.94
131.3281,0.68774,-0.2672,29.917,393.81,-0.029177,0.81622,398.23,440.67,424.47,428.45
131.9281,0.6743,-0.26279,22.311,395.61,-0.028687,0.80097,400.19,435.87,424.2,426.92
132.5281,0.66543,-0.26011,19.971,397.41,-0.028393,0.78983,401.13,429.42,422.47,423.71
133.1281,0.66118,-0.25877,24.858,399.21,-0.028241,0.78513,401.24,423.13,419.62,419.6
133.7281,0.66849,-0.25854,29.69,400.0,-0.028241,0.79446,400.64,418.29,416.47,415.46
134.3281,0.66979,-0.25886,32.312,400.0,-0.028261,0.79566,399.72,414.72,413.61,412.11
134.9281,0.69154,-0.25964,36.105,400.0,-0.028339,0.82119,398.58,412.24,410.99,409.3
135.5281,0.70616,-0.26122,40.126,400.0,-0.028503,0.83857,397.46,411.54,408.97,407.39
135.9651,0.71451,-0.26289,42.749,400.0,-0.028682,0.8485,396.81,412.4,407.95,406.61
136.5651,0.72348,-0.26579,45.136,400.0,-0.028999,0.85963,396.3,414.76,407.46,406.62
137.1651,0.74256,-0.2688,46.445,400.0,-0.029343,0.88168,396.27,418.14,407.9,407.92
137.7651,0.74951,-0.2716,47.012,400.0,-0.029647,0.88999,396.61,422.13,409.21,410.07
138.3651,0.75547,-0.27397,46.404,400.0,-0.029883,0.89652,397.43,426.29,411.24,412.95
138.9651,0.75748,-0.27551,44.881,400.0,-0.030036,0.89929,398.45,429.97,413.64,415.95
139.5651,0.75525,-0.27599,42.198,400.0,-0.030112,0.89616,399.65,432.78,416.0,418.67
140.1651,0.7398,-0.27571,38.775,400.0,-0.03009,0.87888,400.77,433.71,417.85,420.6
140.7651,0.72083,-0.27435,33.993,400.0,-0.029922,0.85532,401.74,432.74,418.99,421.49
141.3651,0.70895,-0.27237,28.814,400.0,-0.029703,0.84115,402.31,429.71,419.18,420.98
141.9651,0.70088,-0.27041,24.942,400.0,-0.029504,0.83216,402.33,425.01,418.24,419.23
142.5651,0.69677,-0.26862,23.368,400.0,-0.02932,0.82774,401.79,419.68,416.38,416.44
143.1651,0.6933,-0.26815,27.112,400.0,-0.02926,0.82373,400.66,414.85,413.95,413.12
143.7651,0.70585,-0.26803,32.245,400.0,-0.029249,0.83715,399.34,411.31,411.32,409.84
144.3651,0.72568,-0.26956,37.418,400.0,-0.029433,0.86068,397.9,410.04,408.89,407.12
144.9651,0.74159,-0.27293,41.612,400.0,-0.029818,0.88009,396.77,411.2,407.19,405.49
145.5651,0.75473,-0.27711,44.719,400.0,-0.030246,0.8951,396.06,414.38,406.35,405.36
146.1651,0.76727,-0.27996,46.506,400.0,-0.0305,0.90988,395.88,418.94,406.69,406.56
146.7651,0.77047,-0.28043,47.114,400.0,-0.030551,0.91467,396.24,424.47,408.05,408.98
147.3651,0.76619,-0.28322,47.007,400.0,-0.030917,0.90907,396.94,430.01,410.23,412.23
147.9651,0.76182,-0.28706,45.563,400.0,-0.031312,0.90482,398.07,435.08,412.89,415.85
148.5651,0.76105,-0.28775,43.045,400.0,-0.031363,0.90335,399.34,438.62,415.61,419.11
149.1651,0.74682,-0.28785,39.321,400.0,-0.031373,0.88631,400.64,440.37,418.02,421.67
149.7651,0.72426,-0.2864,34.334,400.0,-0.031234,0.85876,401.79,439.62,419.66,423.15
150.3651,0.71222,-0.28373,27.684,400.0,-0.030956,0.84546,402.6,436.16,420.44,423.22
150.9651,0.70234,-0.28126,20.881,400.0,-0.030664,0.83411,402.86,430.46,419.93,421.71
151.5651,0.69747,-0.2796,18.219,400.0,-0.030491,0.82818,402.42,424.1,418.36,418.92
152.1651,0.69274,-0.2784,20.812,400.0,-0.030354,0.8227,401.42,418.02,415.98,415.42
152.7651,0.69567,-0.27779,26.72,400.0,-0.030322,0.82495,400.03,413.24,413.13,411.73
153.3651,0.7067,-0.27826,33.405,400.0,-0.030372,0.83888,398.52,410.59,410.29,408.39
153.9651,0.73217,-0.28147,38.84,400.0,-0.030715,0.86921,397.08,410.84,407.88,405.9
154.5651,0.76961,-0.28426,43.104,400.0,-0.030968,0.91328,395.98,413.85,406.31,404.69
155.1651,0.83362,-0.2832,45.796,400.0,-0.03089,0.98845,395.5,418.81,405.78,405.05
155.7651,0.90043,-0.28679,47.475,400.0,-0.031311,1.0687,395.48,425.1,406.47,406.8
156.3651,0.94777,-0.28943,47.969,400.0,-0.031544,1.1255,395.97,431.83,408.17,409.77
156.9651,0.97215,-0.29177,47.814,400.0,-0.031798,1.1543,396.75,438.36,410.57,413.39
157.5651,0.98125,-0.2935,46.415,400.0,-0.031997,1.1653,397.91,443.8,413.48,417.25
158.1651,0.98684,-0.29407,44.036,400.0,-0.032066,1.171,399.2,447.53,416.43,420.84
158.7651,0.98336,-0.29379,40.302,400.0,-0.032015,1.1679,400.6,449.1,419.11,423.77
159.3651,0.95949,-0.29263,35.306,400.0,-0.031891,1.1387,401.79,448.13,421.22,425.62
159.9651,0.93762,-0.29066,28.981,400.0,-0.031677,1.1133,402.67,444.2,422.32,426.09
160.5651,0.89001,-0.28898,20.866,400.0,-0.03153,1.0565,403.15,437.98,422.31,424.97
161.1651,0.84282,-0.28812,17.054,400.0,-0.031418,1.0012,402.83,430.7,421.04,422.43
161.7651,0.78293,-0.28765,16.049,400.0,-0.031357,0.92876,402.04,424.08,418.92,419.07
162.3651,0.74665,-0.28746,21.573,400.0,-0.031331,0.88641,400.83,418.31,416.21,415.33
162.9651,0.72636,-0.28801,28.047,400.0,-0.031402,0.86174,399.39,414.35,413.29,411.62
163.5651,0.7385,-0.28861,34.473,400.0,-0.031478,0.87714,397.97,412.81,410.55,408.45
164.1651,0.75362,-0.29032,39.692,400.0,-0.031642,0.89526,396.67,414.11,408.27,406.26
164.7651,0.75937,-0.29297,43.29,400.0,-0.031929,0.90093,395.85,417.8,406.84,405.35
165.3651,0.76751,-0.29604,45.978,400.0,-0.032263,0.91093,395.43,423.15,406.35,405.81
165.9651,0.77241,-0.29898,47.262,400.0,-0.032603,0.91693,395.59,429.8,407.01,407.63
166.5651,0.77805,-0.30188,47.628,400.0,-0.032891,0.9235,396.14,436.79,408.55,410.45
167.1651,0.77544,-0.30466,47.112,400.0,-0.033182,0.92059,397.01,443.27,410.82,413.77
167.7651,0.77124,-0.30686,45.66,400.0,-0.033413,0.91552,398.17,448.77,413.4,417.31
168.3072,0.76632,-0.30799,43.649,400.0,-0.033535,0.91069,399.19,451.94,415.92,420.44
168.9072,0.75954,-0.30805,40.256,400.0,-0.033564,0.90113,400.49,453.47,418.49,423.28
169.5072,0.73557,-0.30709,35.37,400.0,-0.033461,0.8731,401.71,452.39,420.61,425.3
170.1072,0.72207,-0.30501,28.001,400.0,-0.03323,0.85641,402.73,448.1,421.97,426.01
170.7072,0.71183,-0.30253,19.429,400.0,-0.032947,0.8458,403.31,441.09,422.22,425.31
171.3072,0.70543,-0.30048,8.8741,400.0,-0.032747,0.83812,403.31,433.13,421.41,423.16
171.9072,0.70019,-0.29901,4.5452,400.0,-0.032594,0.8314,402.66,425.83,419.59,419.97
172.5072,0.70185,-0.29798,10.643,400.0,-0.032461,0.83304,401.55,419.46,417.19,416.37
173.1072,0.69404,-0.29747,20.771,400.0,-0.032409,0.8246,400.05,414.23,414.32,412.64
173.7072,0.69811,-0.29772,29.305,400.0,-0.032437,0.83017,398.43,411.0,411.35,409.04
174.3072,0.72659,-0.29887,36.411,400.0,-0.032585,0.86301,396.93,411.43,408.58,406.11
174.9072,0.74398,-0.30106,41.503,400.0,-0.032817,0.88354,395.73,415.44,406.58,404.35
175.4467,0.75785,-0.30342,44.629,400.0,-0.033068,0.9,395.13,421.22,405.55,404.06
176.0467,0.77178,-0.30661,46.974,400.0,-0.033404,0.91695,394.95,429.17,405.49,405.22
176.6467,0.78094,-0.30982,48.1,400.0,-0.033744,0.92647,395.25,438.12,406.55,407.69
177.2467,0.78385,-0.31319,48.344,400.0,-0.034093,0.93082,395.96,446.85,408.5,411.16
177.8467,0.78473,-0.31598,47.737,400.0,-0.034412,0.93183,396.91,454.63,411.18,415.1
178.4467,0.78405,-0.094788,46.293,400.0,-0.01034,0.93009,398.11,460.64,414.31,419.35
178.6144,0.79726,0.044758,0.0,43.769,0.0047417,0.93996,398.41,462.15,415.54,421.21
178.6174,0.77385,0.040755,0.0,0.0035493,0.0041419,0.92035,398.28,462.12,415.58,421.33
178.6204,0.78554,0.039664,0.0,2.8779e-07,0.0042807,0.93398,398.31,462.12,415.59,421.26
178.6234,0.77219,0.038305,0.0,2.3336e-11,0.0045134,0.92437,398.39,462.12,415.6,421.16
178.6264,0.7791,0.038249,0.0,1.8922e-15,0.0046371,0.92802,398.46,462.12,415.61,421.05
178.6294,0.77298,0.039543,0.0,1.5343e-19,0.0044691,0.91646,398.51,462.15,415.63,420.99
178.6324,0.77906,0.040426,0.0,1.2441e-23,0.0043471,0.92459,398.55,462.21,415.66,420.99
178.6354,0.76847,0.040506,0.0,1.0088e-27,0.0045174,0.90837,398.59,462.27,415.68,420.99
178.6384,0.77434,0.040676,0.0,8.1801e-32,0.0043523,0.92015,398.62,462.33,415.71,420.99
178.6414,0.75661,0.040484,0.0,6.6329e-36,0.0040562,0.89887,398.64,462.36,415.71,420.99
178.6444,0.77376,0.039524,0.0,5.3784e-40,0.0041814,0.92025,398.65,462.38,415.71,420.99
178.6474,0.75577,0.03786,0.0,4.344e-44,0.0044066,0.89847,398.67,462.41,415.71,420.99
178.6504,0.76882,0.038113,0.0,0.0,0.0046507,0.91844,398.69,462.41,415.72,421.02
178.6534,0.75362,0.040012,0.0,0.0,0.0044951,0.89374,398.71,462.4,415.74,421.06
178.6564,0.76179,0.04025,0.0,0.0,0.0043744,0.90492,398.73,462.39,415.76,421.1
178.6594,0.74928,0.040214,0.0,0.0,0.0045845,0.8896,398.73,462.38,415.78,421.13
178.6624,0.75929,0.040937,0.0,0.0,0.0043932,0.90214,398.71,462.37,415.81,421.17
178.6654,0.751,0.04032,0.0,0.0,0.0040754,0.89101,398.69,462.36,415.83,421.2
178.6684,0.75704,0.039635,0.0,0.0,0.004238,0.89042,398.68,462.38,415.87,421.24
178.6714,0.74051,0.037496,0.0,0.0,0.0043858,0.88424,398.72,462.5,415.93,421.26
178.6744,0.76308,0.037765,0.0,0.0,0.0046303,0.902,398.75,462.63,415.99,421.27
178.6774,2.875,0.069004,0.0,0.0,0.0077538,3.2672,398.79,462.75,416.06,421.29
178.6804,19.504,0.239,0.0,0.0,0.026266,22.779,399.23,463.57,416.15,421.29
178.6834,41.219,0.34811,0.0,0.0,0.039416,48.415,399.76,464.52,416.25,421.29
178.6864,57.533,0.40783,0.0,0.0,0.045825,68.027,400.28,465.47,416.35,421.29
178.6894,64.108,0.51642,0.0,0.0,0.0579,75.956,401.37,466.75,416.42,421.29
178.6924,68.753,0.6973,0.0,0.0,0.079069,81.474,403.02,468.37,416.47,421.27
178.6954,72.666,0.99788,0.0,0.0,0.11561,86.174,404.67,469.98,416.51,421.25
178.6984,74.074,1.3498,0.0,0.0,0.15991,87.878,406.28,471.47,416.55,421.24
178.7014,74.685,1.686,0.0,0.0,0.20323,88.622,407.66,472.34,416.54,421.24
178.7044,74.495,1.9909,0.0,0.0,0.2442,88.412,409.04,473.21,416.53,421.25
178.7074,73.946,2.2486,0.0,0.0,0.28068,87.763,410.43,474.08,416.52,421.26
178.7104,73.105,2.4638,0.0,0.0,0.31151,86.775,410.87,474.35,416.56,421.28
178.7134,72.68,2.6512,0.0,0.0,0.33864,86.248,411.12,474.51,416.6,421.3
178.7164,72.607,2.8288,0.0,0.0,0.36582,86.16,411.37,474.66,416.65,421.32
178.7194,73.009,3.0058,0.0,0.0,0.39384,86.63,411.54,474.77,416.66,421.33
178.7224,73.513,3.1928,0.0,0.0,0.42398,87.223,411.63,474.84,416.65,421.34
178.7254,74.047,3.3922,0.0,0.0,0.45601,87.867,411.72,474.91,416.65,421.35
178.7284,74.355,3.5919,0.0,0.0,0.48923,88.226,411.79,474.97,416.64,421.36
178.7314,74.6,3.7849,0.0,0.0,0.52322,88.521,411.72,474.92,416.63,421.38
178.7344,74.622,3.972,0.0,0.0,0.55664,88.551,411.64,474.88,416.62,421.39
178.7374,74.69,4.1492,0.0,0.0,0.58826,88.634,411.57,474.83,416.61,421.41
178.7404,74.682,4.3178,0.0,0.0,0.62036,88.623,411.3,474.71,416.66,421.46
178.7434,74.784,4.4797,0.0,0.0,0.65303,88.74,411.0,474.56,416.72,421.51
178.7464,74.813,4.6339,0.0,0.0,0.68452,88.768,410.69,474.42,416.79,421.57
178.7494,75.015,4.7874,0.0,0.0,0.71565,89.015,410.26,474.28,416.81,421.61
178.7524,75.171,4.9389,0.0,0.0,0.747,89.198,409.7,474.13,416.8,421.65
178.7554,75.425,5.0854,0.0,0.0,0.77982,89.505,409.14,473.99,416.8,421.68
178.7584,75.598,5.2267,0.0,0.0,0.81136,89.698,408.54,473.84,416.79,421.72
178.7614,75.845,5.371,0.0,0.0,0.84356,90.003,407.74,473.65,416.79,421.76
178.7644,76.028,5.509,0.0,0.0,0.87653,90.209,406.95,473.46,416.79,421.79
178.7674,76.254,5.6411,0.0,0.0,0.90995,90.487,406.15,473.27,416.79,421.83
178.7704,76.404,5.7705,0.0,0.0,0.94358,90.65,405.24,472.96,416.83,421.85
178.7734,76.641,5.8992,0.0,0.0,0.97637,90.942,404.3,472.63,416.87,421.87
178.7764,76.825,6.0218,0.0,0.0,1.0081,91.16,403.36,472.3,416.92,421.89
178.7794,77.075,6.1411,0.0,0.0,1.0419,91.46,402.33,471.92,416.94,421.9
178.7824,77.326,6.2552,0.0,0.0,1.0745,91.751,401.22,471.5,416.94,421.92
178.7854,77.562,6.3667,0.0,0.0,1.1053,92.037,400.11,471.08,416.94,421.94
178.7884,77.845,6.4765,0.0,0.0,1.1382,92.364,398.98,470.64,416.93,421.96
178.7914,78.156,6.5787,0.0,0.0,1.1714,92.74,397.76,470.11,416.91,422.02
178.7944,78.54,6.6795,0.0,0.0,1.2047,93.186,396.54,469.58,416.88,422.07
178.7974,78.93,6.7828,0.0,0.0,1.2375,93.662,395.32,469.05,416.85,422.13
178.8004,79.381,6.8841,0.0,0.0,1.2705,94.181,394.12,468.37,416.87,422.15
178.8034,79.776,6.9787,0.0,0.0,1.3044,94.66,392.91,467.65,416.9,422.17
178.8064,80.24,7.0712,0.0,0.0,1.3377,95.209,391.71,466.93,416.92,422.19
178.8094,80.636,7.1613,0.0,0.0,1.369,95.685,390.56,466.11,416.95,422.2
178.8124,81.167,7.2455,0.0,0.0,1.4004,96.303,389.47,465.17,416.98,422.2
178.8154,81.64,7.3277,0.0,0.0,1.4351,96.864,388.37,464.24,417.01,422.2
178.8184,82.284,7.4095,0.0,0.0,1.4697,97.623,387.28,463.26,417.04,422.2
178.8214,82.866,7.4902,0.0,0.0,1.5022,98.324,386.2,462.01,417.08,422.2
178.8244,83.626,7.5682,0.0,0.0,1.5331,99.211,385.13,460.76,417.13,422.2
178.8274,84.238,7.6431,0.0,0.0,1.5675,99.949,384.05,459.51,417.17,422.2
178.8304,83.468,7.712,0.0,0.0,1.5997,99.174,382.83,458.07,417.2,422.23
178.8334,79.727,7.7786,0.0,0.0,1.6278,94.714,381.59,456.59,417.23,422.26
178.8364,75.483,7.8128,0.0,0.0,1.6435,89.66,380.35,455.11,417.26,422.3
178.8394,72.686,7.8266,0.0,0.0,1.6527,86.31,379.11,453.65,417.25,422.34
178.8424,70.831,7.8358,0.0,0.0,1.6599,84.087,377.85,452.22,417.2,422.4
178.8454,69.43,7.8435,0.0,0.0,1.6623,82.42,376.6,450.8,417.16,422.45
178.8484,68.359,7.8511,0.0,0.0,1.6636,81.142,375.38,449.41,417.12,422.5
178.8514,67.398,7.8577,0.0,0.0,1.6679,79.998,374.3,448.2,417.12,422.5
178.8544,66.602,7.8636,0.0,0.0,1.6723,79.052,373.22,447.0,417.12,422.5
178.8574,65.792,7.8673,0.0,0.0,1.671,78.1,372.14,445.79,417.12,422.5
178.8604,65.04,7.8713,0.0,0.0,1.672,77.196,371.14,444.78,417.14,422.51
178.8634,64.176,7.8711,0.0,0.0,1.6745,76.183,370.15,443.8,417.17,422.53
178.8664,63.281,7.8722,0.0,0.0,1.6774,75.113,369.16,442.82,417.2,422.55
178.8694,61.831,7.874,0.0,0.0,1.6774,73.445,368.32,442.06,417.19,422.55
178.8724,57.815,7.8742,0.0,0.0,1.6751,68.747,367.63,441.53,417.14,422.53
178.8754,51.752,7.8696,0.0,0.0,1.6737,61.573,366.94,441.0,417.1,422.51
178.8784,18.948,7.797,0.0,0.0,1.6408,23.442,366.34,440.56,417.05,422.5
178.8814,-0.059303,7.7171,0.0,0.0,1.601,-0.030029,366.14,440.56,417.02,422.5
178.8844,-0.25193,7.7564,0.0,0.0,1.6161,-0.29504,365.94,440.56,416.98,422.5
178.8874,0.06255,7.7713,0.0,0.0,1.6269,0.096764,365.74,440.56,416.94,422.5
178.8904,0.69918,7.7795,0.0,0.0,1.6325,0.92144,365.78,440.8,416.98,422.53
178.8934,0.64303,7.7808,0.0,0.0,1.6333,0.78103,365.87,441.09,417.02,422.56
178.8964,0.54444,7.7805,0.0,0.0,1.6301,0.67147,365.96,441.37,417.07,422.6
178.8994,0.54931,7.7807,0.0,0.0,1.6307,0.66522,366.08,441.68,417.09,422.63
178.9024,0.5453,7.7783,0.0,0.0,1.6313,0.65185,366.22,442.0,417.1,422.67
178.9054,0.48309,7.7797,0.0,0.0,1.6297,0.57663,366.37,442.33,417.11,422.71
178.9084,0.51564,7.7789,0.0,0.0,1.628,0.62038,366.51,442.63,417.11,422.74
178.9114,0.48581,7.7791,0.0,0.0,1.6295,0.58083,366.62,442.84,417.07,422.78
178.9144,0.51458,7.7773,0.0,0.0,1.632,0.61538,366.73,443.05,417.02,422.81
178.9174,0.52231,7.7759,0.0,0.0,1.6306,0.61218,366.84,443.25,416.98,422.85
178.9204,0.47268,7.7795,0.0,0.0,1.6296,0.56648,366.91,443.47,416.98,422.89
178.9234,0.52998,7.7824,0.0,0.0,1.6313,0.62527,366.97,443.68,416.98,422.92
178.9264,0.51888,7.7807,0.0,0.0,1.6322,0.61701,367.03,443.9,416.99,422.96
178.9294,0.50917,7.7801,0.0,0.0,1.6304,0.60758,367.06,444.11,416.99,422.99
178.9324,0.49516,7.7819,0.0,0.0,1.6292,0.60357,367.05,444.3,416.97,423.0
178.9354,0.52478,7.7808,0.0,0.0,1.6301,0.62325,367.04,444.5,416.95,423.02
178.9384,0.49295,7.7773,0.0,0.0,1.6315,0.58925,367.03,444.69,416.93,423.03
178.9414,0.52561,7.7779,0.0,0.0,1.6316,0.61944,366.98,444.86,416.9,423.02
178.9444,0.50507,7.7809,0.0,0.0,1.6303,0.61023,366.94,445.04,416.86,423.0
178.9474,0.53253,7.7828,0.0,0.0,1.6315,0.62512,366.89,445.21,416.82,422.98
178.9504,0.50522,7.7816,0.0,0.0,1.6326,0.60846,366.91,445.38,416.81,423.01
178.9534,0.52243,7.7833,0.0,0.0,1.6317,0.61404,366.93,445.56,416.8,423.04
178.9564,0.48732,7.7842,0.0,0.0,1.6299,0.57443,366.96,445.74,416.79,423.08
178.9594,0.51887,7.7835,0.0,0.0,1.6316,0.62665,366.97,445.93,416.8,423.11
178.9624,0.51001,7.7797,0.0,0.0,1.6325,0.60223,366.97,446.12,416.83,423.12
178.9654,0.53725,7.7785,0.0,0.0,1.6321,0.63719,366.97,446.3,416.86,423.14
178.9684,0.56781,7.7814,0.0,0.0,1.631,0.68601,366.97,446.49,416.88,423.15
178.9714,0.59734,7.7831,0.0,0.0,1.6315,0.7125,366.91,446.69,416.91,423.14
178.9744,0.56816,7.7823,0.0,0.0,1.6332,0.68393,366.86,446.89,416.94,423.12
178.9774,0.67684,7.7834,0.0,0.0,1.6323,0.79602,366.8,447.09,416.96,423.1
178.9804,0.62651,7.7836,0.0,0.0,1.6298,0.74339,366.82,447.25,416.99,423.11
178.9834,0.73143,7.7817,0.0,0.0,1.6304,0.86142,366.86,447.4,417.02,423.13
178.9864,0.63582,7.7792,0.0,0.0,1.6317,0.74394,366.9,447.55,417.05,423.15
178.9894,0.73341,7.7795,0.0,0.0,1.6328,0.86685,366.9,447.69,417.07,423.18
178.9924,0.60177,7.7793,0.0,0.0,1.6301,0.71489,366.86,447.82,417.1,423.21
178.9954,0.71439,7.7811,0.0,0.0,1.6304,0.86111,366.82,447.94,417.13,423.25
178.9984,0.59536,7.7788,0.0,0.0,1.6311,0.70723,366.78,448.07,417.15,423.28
179.0014,0.70258,7.781,0.0,0.0,1.6316,0.83879,366.71,448.17,417.15,423.32
179.0044,0.60609,7.7804,0.0,0.0,1.6285,0.71249,366.64,448.28,417.15,423.36
179.0074,0.68692,7.7787,0.0,0.0,1.6285,0.82004,366.56,448.39,417.15,423.39
179.0104,0.6145,7.7756,0.0,0.0,1.6303,0.72075,366.54,448.47,417.16,423.41
179.0134,0.68574,7.7742,0.0,0.0,1.6303,0.82926,366.52,448.54,417.18,423.43
179.0164,0.64423,7.7765,0.0,0.0,1.629,0.74562,366.5,448.61,417.2,423.45
179.0194,0.68239,7.7797,0.0,0.0,1.63,0.82774,366.45,448.7,417.2,423.46
179.0224,0.65117,7.7789,0.0,0.0,1.6316,0.75856,366.37,448.8,417.2,423.46
179.0254,0.67919,7.7788,0.0,0.0,1.6306,0.81638,366.29,448.89,417.19,423.46
179.0284,0.66136,7.7802,0.0,0.0,1.6283,0.77383,366.2,449.0,417.18,423.46
179.0314,0.64133,7.7789,0.0,0.0,1.6285,0.78367,366.11,449.1,417.16,423.46
179.0344,0.66898,7.7751,0.0,0.0,1.6298,0.78725,366.02,449.21,417.14,423.46
179.0374,0.64306,7.7747,0.0,0.0,1.6307,0.7732,365.93,449.32,417.12,423.46
179.0404,0.6885,7.7766,0.0,0.0,1.6296,0.81222,365.83,449.4,417.1,423.47
179.0434,0.62708,7.7765,0.0,0.0,1.6281,0.75527,365.73,449.47,417.07,423.49
179.0464,0.68142,7.7777,0.0,0.0,1.6309,0.79365,365.63,449.54,417.04,423.51
179.0494,0.62791,7.7765,0.0,0.0,1.6297,0.76598,365.55,449.63,417.05,423.52
179.0524,0.69699,7.7792,0.0,0.0,1.6279,0.81525,365.47,449.74,417.08,423.52
179.0554,0.60374,7.7766,0.0,0.0,1.6272,0.72751,365.4,449.85,417.12,423.52
179.0584,0.69476,7.7745,0.0,0.0,1.6291,0.82394,365.34,449.95,417.16,423.52
179.0614,0.61419,7.7727,0.0,0.0,1.6299,0.73084,365.32,450.05,417.23,423.54
179.0644,0.7077,7.7774,0.0,0.0,1.6298,0.83569,365.3,450.15,417.3,423.56
179.0674,0.60726,7.7769,0.0,0.0,1.6281,0.72545,365.28,450.25,417.38,423.57
179.0704,0.72455,7.7789,0.0,0.0,1.6313,0.86154,365.22,450.32,417.41,423.62
179.0734,0.60554,7.7768,0.0,0.0,1.6299,0.72959,365.15,450.4,417.44,423.68
179.0764,0.72936,7.7798,0.0,0.0,1.6286,0.86438,365.07,450.47,417.47,423.73
179.0794,0.59963,7.7788,0.0,0.0,1.628,0.71448,365.0,450.53,417.47,423.77
179.0824,0.72786,7.7768,0.0,0.0,1.6302,0.85836,364.93,450.57,417.45,423.78
179.0854,0.61248,7.7746,0.0,0.0,1.6308,0.73055,364.85,450.62,417.43,423.8
179.0884,0.73083,7.7775,0.0,0.0,1.6303,0.8745,364.78,450.66,417.41,423.82
179.0914,0.60536,7.7788,0.0,0.0,1.6287,0.70858,364.73,450.73,417.39,423.82
179.0944,0.73607,7.7785,0.0,0.0,1.6305,0.87505,364.68,450.79,417.36,423.82
179.0974,0.61035,7.7775,0.0,0.0,1.6307,0.72817,364.62,450.85,417.33,423.82
179.1004,0.71819,7.7798,0.0,0.0,1.6286,0.8592,364.54,450.93,417.35,423.83
179.1034,0.62365,7.7776,0.0,0.0,1.6273,0.73531,364.45,451.01,417.38,423.85
179.1064,0.71099,7.7771,0.0,0.0,1.6299,0.85356,364.35,451.09,417.41,423.87
179.1094,0.62373,7.7752,0.0,0.0,1.6308,0.72781,364.26,451.17,417.44,423.89
179.1124,0.68896,7.7765,0.0,0.0,1.63,0.83757,364.17,451.24,417.49,423.91
179.1154,0.63008,7.7798,0.0,0.0,1.6295,0.73548,364.08,451.31,417.53,423.92
179.1184,0.68266,7.78,0.0,0.0,1.6313,0.83,363.99,451.38,417.57,423.94
179.1214,0.65454,7.7777,0.0,0.0,1.6308,0.76856,363.9,451.41,417.6,423.92
179.1244,0.6731,7.7794,0.0,0.0,1.6286,0.81352,363.81,451.45,417.63,423.9
179.1274,0.65873,7.7797,0.0,0.0,1.6281,0.76851,363.72,451.49,417.65,423.88
179.1304,0.66153,7.7768,0.0,0.0,1.6297,0.80202,363.63,451.49,417.67,423.89
179.1334,0.67388,7.7754,0.0,0.0,1.6311,0.78546,363.54,451.49,417.68,423.91
179.1364,0.65693,7.7767,0.0,0.0,1.6303,0.79759,363.45,451.49,417.68,423.93
179.1394,0.69282,7.7794,0.0,0.0,1.6291,0.80311,363.36,451.52,417.7,423.96
179.1424,0.64868,7.7788,0.0,0.0,1.631,0.78176,363.29,451.59,417.73,423.99
179.1454,0.70107,7.778,0.0,0.0,1.6307,0.81843,363.22,451.65,417.76,424.03
179.1484,0.63859,7.7773,0.0,0.0,1.6277,0.7583,363.15,451.71,417.78,424.06
179.1514,0.70696,7.7801,0.0,0.0,1.6286,0.83515,363.07,451.75,417.78,424.08
179.1544,0.62596,7.7767,0.0,0.0,1.6296,0.74924,363.0,451.8,417.78,424.1
179.1574,0.72559,7.7767,0.0,0.0,1.6315,0.84629,362.93,451.84,417.78,424.12
179.1604,0.62478,7.7769,0.0,0.0,1.6305,0.75068,362.84,451.88,417.79,424.12
179.1634,0.73317,7.7798,0.0,0.0,1.6297,0.86372,362.75,451.92,417.8,424.12
179.1664,0.61937,7.7773,0.0,0.0,1.6294,0.74571,362.66,451.95,417.81,424.12
179.1694,0.73197,7.7785,0.0,0.0,1.6313,0.86395,362.57,451.97,417.82,424.13
179.1724,0.60849,7.7791,0.0,0.0,1.6287,0.72758,362.48,451.97,417.85,424.15
179.1754,0.73944,7.7818,0.0,0.0,1.6287,0.86988,362.38,451.97,417.88,424.16
179.1784,0.60913,7.7769,0.0,0.0,1.6293,0.72513,362.3,451.98,417.9,424.18
179.1814,0.74265,7.7767,0.0,0.0,1.6319,0.87244,362.22,452.01,417.91,424.22
179.1844,0.62007,7.7751,0.0,0.0,1.6301,0.73848,362.15,452.05,417.92,424.26
179.1874,0.73675,7.7796,0.0,0.0,1.6297,0.87686,362.08,452.09,417.93,424.29
179.1904,0.61012,7.778,0.0,0.0,1.6298,0.72626,362.0,452.14,417.93,424.3
179.1934,0.73508,7.7794,0.0,0.0,1.6315,0.87707,361.92,452.21,417.93,424.3
179.1964,0.61526,7.7793,0.0,0.0,1.6287,0.73286,361.83,452.27,417.93,424.3
179.1994,0.72267,7.7798,0.0,0.0,1.6281,0.863,361.76,452.31,417.93,424.29
179.2024,0.6319,7.7763,0.0,0.0,1.6285,0.74706,361.68,452.31,417.92,424.27
179.2054,0.72222,7.7758,0.0,0.0,1.6311,0.87017,361.61,452.32,417.91,424.25
179.2084,0.63599,7.7764,0.0,0.0,1.6308,0.74922,361.54,452.34,417.9,424.24
179.2114,0.713,7.7804,0.0,0.0,1.6302,0.86059,361.46,452.37,417.91,424.26
179.2144,0.64517,7.7801,0.0,0.0,1.6306,0.75413,361.37,452.41,417.92,424.28
179.2174,0.70643,7.7804,0.0,0.0,1.6324,0.84682,361.29,452.44,417.93,424.3
179.2204,0.67033,7.7797,0.0,0.0,1.6293,0.78243,361.19,452.45,417.94,424.34
179.2234,0.68813,7.7807,0.0,0.0,1.6291,0.82797,361.08,452.45,417.95,424.38
179.2264,0.67268,7.7796,0.0,0.0,1.6299,0.77677,360.97,452.45,417.96,424.43
179.2294,0.6838,7.7761,0.0,0.0,1.6313,0.82564,360.89,452.46,417.97,424.43
179.2324,0.67817,7.7773,0.0,0.0,1.6311,0.79425,360.83,452.46,417.99,424.39
179.2354,0.66415,7.7799,0.0,0.0,1.63,0.80529,360.78,452.47,418.0,424.36
179.2384,0.69397,7.7812,0.0,0.0,1.6306,0.81797,360.72,452.48,418.02,424.33
179.2414,0.65694,7.7798,0.0,0.0,1.6317,0.79605,360.64,452.48,418.05,424.34
179.2444,0.70877,7.7814,0.0,0.0,1.6308,0.83177,360.56,452.48,418.08,424.35
179.2474,0.65496,7.7803,0.0,0.0,1.6284,0.79084,360.47,452.48,418.11,424.36
179.2504,0.7229,7.7799,0.0,0.0,1.6299,0.84491,360.41,452.47,418.13,424.39
179.2534,0.63853,7.7765,0.0,0.0,1.6319,0.7722,360.36,452.46,418.14,424.42
179.2564,0.72523,7.7784,0.0,0.0,1.6322,0.8555,360.31,452.46,418.16,424.46
179.2594,0.6215,7.7788,0.0,0.0,1.6298,0.75456,360.26,452.45,418.18,424.48
179.6597,0.65329,7.7797,0.0,0.0,1.6306,0.77615,350.31,447.5,419.11,418.37
180.2597,0.63161,7.7787,0.0,0.0,1.6302,0.7505,321.72,415.67,415.53,339.25
180.8597,0.60613,7.7784,0.0,0.0,1.63,0.7195,298.47,387.38,411.24,323.62
181.4597,0.58929,7.7779,0.0,0.0,1.6297,0.69984,276.07,361.51,401.28,319.44
182.0597,0.5321,7.7782,0.0,0.0,1.6298,0.63215,247.73,337.99,383.09,315.85
182.6597,0.482,7.7759,0.0,0.0,1.6288,0.57217,209.05,313.65,369.8,299.29
183.2433,0.47795,7.7704,0.0,0.0,1.6262,0.56826,127.28,289.52,352.14,278.71
183.8433,0.48754,7.7707,0.0,0.0,1.6264,0.5783,100.26,250.99,335.95,260.23
184.4433,0.49306,7.7699,0.0,0.0,1.6259,0.58521,86.176,161.23,319.78,234.78
185.0433,0.49838,7.7699,0.0,0.0,1.6259,0.59233,73.897,126.31,280.16,196.81
185.6433,0.49392,7.7697,0.0,0.0,1.6259,0.58607,65.008,109.47,219.56,127.44
186.2433,0.49376,7.7687,0.0,0.0,1.6255,0.58487,59.002,100.55,169.16,99.784
186.8433,0.49521,7.7676,0.0,0.0,1.6249,0.58739,53.633,92.484,132.31,79.742
187.4433,0.49508,7.7663,0.0,0.0,1.6242,0.58782,49.406,82.596,105.23,65.617
188.0433,0.48592,7.7651,0.0,0.0,1.6238,0.57713,45.919,79.29,86.03,55.645
188.6433,0.47539,7.7644,0.0,0.0,1.6235,0.56387,42.332,72.096,71.846,47.992
189.2433,0.46933,7.7639,0.0,0.0,1.6232,0.55673,40.097,66.136,61.359,43.88
189.8433,0.46556,7.7635,0.0,0.0,1.6229,0.55307,38.096,61.76,53.684,39.961
190.4433,0.46295,7.7632,0.0,0.0,1.6228,0.54989,36.238,57.195,48.05,37.128
191.0433,0.46057,7.763,0.0,0.0,1.6228,0.5467,34.741,54.215,43.584,35.047
191.6433,0.45873,7.7629,0.0,0.0,1.6228,0.54422,33.669,50.678,40.341,33.357
192.2433,0.45685,7.7624,0.0,0.0,1.6224,0.54255,33.269,48.932,37.689,32.365
192.8433,0.45617,7.7622,0.0,0.0,1.6223,0.54162,32.247,46.536,35.961,31.59
193.4433,0.45612,7.7617,0.0,0.0,1.6222,0.54031,31.956,45.545,34.771,31.026
194.0433,0.45543,7.7612,0.0,0.0,1.622,0.54059,32.035,44.981,34.036,31.141
194.6433,0.43745,6.9887,0.0,0.0,1.309,0.5193,33.0,42.567,33.856,32.325
195.2433,0.44134,6.7154,0.0,0.0,1.2153,0.52361,33.544,41.971,34.211,33.637
195.8433,0.43834,6.6988,0.0,0.0,1.21,0.52085,33.96,42.292,34.918,34.757
196.2433,0.43949,6.6709,0.0,0.0,1.2009,0.52211,34.361,42.493,35.501,35.423