File: examples/dan-msc-case-studies/CS4/data/01 raw data/hyde_test_036.csv
Time(sec),Force(kN),Jaw(mm),PowAngle(deg),PTemp,Strain,Stress(MPa),Stroke(mm),TC1(C),TC2(C),TC3(C),wedge(mm)
0.0,1.4462,-10.316,0.0,0.0054608,-0.77723,4.4058,22.866,23.847,23.861,24.189,-7.6585
2.0,1.4257,0.0052687,0.0,5.8205,0.0005616,4.323,22.866,23.859,23.925,24.202,-7.7718
4.0,1.3971,0.0050936,0.0,11.82,0.000572,4.2397,22.867,23.911,24.042,24.21,-7.7707
6.0,1.401,0.0054088,0.0,17.82,0.0005749,4.2529,22.866,23.858,23.961,24.226,-7.7698
8.0,1.3862,0.0052159,0.0,23.82,0.00058106,4.2053,22.866,23.858,23.922,24.19,-7.7696
10.0,1.4327,0.004119,31.359,29.82,0.00043054,4.3486,22.866,27.402,37.371,30.324,-7.7694
12.0,1.4394,0.0024645,27.407,35.82,0.00029595,4.3676,22.866,34.942,37.268,36.642,-7.7685
14.0,1.4418,-0.00092981,27.155,41.82,-0.00012519,4.3768,22.866,41.639,45.028,44.173,-7.7678
15.8336,1.4463,-0.0027659,30.047,47.322,-0.00026549,4.3891,22.867,46.853,50.018,49.177,-7.7673
17.8336,1.4408,-0.0053494,29.567,53.321,-0.00057803,4.3707,22.866,53.176,56.526,55.695,-7.7663
19.8336,1.4475,-0.0078829,30.167,59.321,-0.00082381,4.3925,22.866,59.186,62.92,62.169,-7.7657
21.8336,1.4534,-0.010408,30.679,65.321,-0.0011387,4.4077,22.866,65.225,69.053,68.357,-7.7651
23.8336,1.4489,-0.014408,31.004,71.321,-0.0015535,4.3959,22.867,71.234,75.608,74.981,-7.7645
25.8336,1.4566,-0.017168,31.871,77.321,-0.0018901,4.4187,22.866,77.2,81.921,81.373,-7.7636
27.8336,1.4508,-0.0198,31.607,83.321,-0.002154,4.3999,22.866,83.26,88.288,87.709,-7.7634
29.8336,1.451,-0.022926,31.178,89.321,-0.0025293,4.4047,22.866,89.455,94.895,94.45,-7.7631
31.8336,1.4575,-0.026395,32.225,95.321,-0.0028702,4.4232,22.866,95.254,101.16,100.65,-7.7632
33.8336,1.4449,-0.029191,31.882,101.32,-0.0031922,4.3837,22.865,101.31,107.27,106.93,-7.7628
35.8336,1.4542,-0.033577,31.884,107.32,-0.0036594,4.4127,22.866,107.42,113.87,113.57,-7.7622
37.8336,1.4563,-0.036922,32.712,113.32,-0.0039997,4.4164,22.866,113.29,120.22,120.0,-7.7615
39.7182,1.4477,-0.039391,32.822,118.98,-0.0043265,4.3935,22.865,118.95,125.96,125.76,-7.7607
41.6599,1.4511,-0.042555,32.357,124.8,-0.0046171,4.4016,22.866,124.86,132.08,131.8,-7.76
43.6599,1.4497,-0.045991,31.983,130.8,-0.0050417,4.3987,22.865,130.94,138.93,138.76,-7.7595
45.6599,1.4603,-0.049771,33.762,136.8,-0.0054371,4.4316,22.866,136.62,144.73,144.68,-7.7589
47.6599,1.4573,-0.053507,32.952,142.8,-0.0058297,4.4206,22.866,142.69,150.52,150.28,-7.7583
49.6599,1.4555,-0.057581,32.123,148.8,-0.0063031,4.4175,22.865,148.96,157.24,157.07,-7.7577
51.6599,1.4561,-0.060574,32.543,154.8,-0.0066116,4.4162,22.865,154.93,163.56,163.59,-7.7571
53.6599,1.4505,-0.064346,33.698,160.8,-0.0070156,4.4008,22.865,160.68,169.33,169.36,-7.7566
55.6599,1.4653,-0.067635,33.804,166.8,-0.0074042,4.4483,22.866,166.63,175.29,175.38,-7.7569
57.6599,1.4462,-0.07231,33.413,172.8,-0.0078814,4.3848,22.866,172.75,181.5,181.56,-7.7565
59.6599,1.4511,-0.07611,33.389,178.8,-0.008285,4.4074,22.866,178.85,188.21,188.34,-7.7562
61.6599,1.4563,-0.079692,33.779,184.8,-0.00872,4.4188,22.866,184.81,194.52,194.63,-7.7549
63.5713,1.4606,-0.086621,34.637,190.53,-0.0094654,4.4305,22.866,190.44,200.63,200.77,-7.7543
65.5713,1.4489,-0.088689,34.083,196.53,-0.0096624,4.3938,22.866,196.52,207.17,207.25,-7.7537
67.5713,1.452,-0.092749,34.237,202.53,-0.010073,4.4081,22.866,202.55,213.61,213.66,-7.7532
69.5713,1.4603,-0.096611,34.594,208.53,-0.010548,4.4303,22.866,208.48,220.24,220.21,-7.7531
71.5506,1.4566,-0.10295,33.877,214.47,-0.011218,4.4194,22.865,214.58,226.99,226.95,-7.7528
73.5506,1.4532,-0.10602,34.432,220.47,-0.011518,4.409,22.865,220.47,233.36,233.36,-7.7524
75.5506,1.4537,-0.1097,34.651,226.47,-0.011963,4.4089,22.865,226.38,239.5,239.44,-7.7524
77.5506,1.4578,-0.11348,34.406,232.47,-0.012371,4.4258,22.865,232.51,246.08,245.86,-7.7519
79.5506,1.4584,-0.1208,33.832,238.47,-0.013142,4.4253,22.865,238.61,252.92,252.65,-7.7509
81.5506,1.4468,-0.12317,33.898,244.47,-0.01338,4.3913,22.866,244.61,259.74,259.33,-7.7492
83.5506,1.4653,-0.12711,34.841,250.47,-0.013842,4.4446,22.865,250.41,266.23,265.71,-7.7491
85.5203,1.4614,-0.13361,34.84,256.39,-0.014497,4.4348,22.865,256.24,272.4,271.5,-7.7494
87.5203,1.4558,-0.13605,34.627,262.38,-0.014779,4.4172,22.865,262.32,279.11,277.99,-7.7488
89.5203,1.4611,-0.14012,33.936,268.38,-0.015273,4.432,22.865,268.57,286.83,285.33,-7.7481
91.5203,1.4508,-0.14536,35.25,274.38,-0.015819,4.4051,22.865,274.28,293.6,291.83,-7.7469
93.3433,1.4529,-0.1484,34.839,279.85,-0.016143,4.4092,22.866,279.83,299.31,297.23,-7.7462
95.3433,1.4564,-0.15432,33.736,285.85,-0.016781,4.4209,22.866,286.11,305.67,303.52,-7.7456
97.3433,1.4494,-0.15761,33.938,291.85,-0.01712,4.3966,22.865,292.14,312.81,310.55,-7.7457
99.3433,1.4542,-0.16213,34.746,297.85,-0.017586,4.4143,22.865,297.99,319.83,317.39,-7.7454
101.3433,1.4708,-0.16577,36.256,303.85,-0.018013,4.4635,22.865,303.52,325.64,322.24,-7.7454
103.3433,1.4571,-0.16926,36.15,309.85,-0.018408,4.4173,22.864,309.36,329.2,325.26,-7.7448
105.3433,1.4506,-0.17173,34.959,315.85,-0.018674,4.4051,22.865,315.67,334.21,330.08,-7.7446
107.3433,1.4502,-0.17512,33.361,321.85,-0.019,4.3992,22.864,322.07,340.26,336.14,-7.7444
109.1679,1.4403,-0.18195,31.826,327.32,-0.019721,4.3713,22.865,328.07,346.88,342.95,-7.7441
111.1679,1.4368,-0.18458,32.011,333.32,-0.020004,4.359,22.865,334.09,353.45,349.59,-7.7437
113.1679,1.9216,-0.18519,34.258,339.32,-0.020089,5.8331,22.865,339.67,360.63,356.31,-7.7425
115.1679,2.6341,-0.18204,34.757,345.32,-0.019784,7.9912,22.865,345.55,366.02,361.18,-7.7411
117.1679,2.9194,-0.18495,34.648,351.32,-0.020071,8.8535,22.866,351.51,368.94,364.12,-7.7404
119.1679,2.9657,-0.18509,34.77,357.32,-0.020114,8.9984,22.864,357.43,372.17,367.95,-7.7403
121.1679,2.9946,-0.18766,34.651,363.32,-0.020388,9.0819,22.864,363.44,375.85,372.21,-7.7406
123.1679,3.2131,-0.18858,33.899,369.32,-0.020478,9.7493,22.864,369.53,379.9,376.9,-7.7399
125.1679,3.3338,-0.18961,34.51,375.32,-0.020572,10.117,22.865,375.39,384.06,381.46,-7.739
127.1679,3.3748,-0.19655,34.347,381.32,-0.021294,10.234,22.865,381.42,388.87,386.57,-7.7377
129.1679,3.3821,-0.19533,34.729,387.32,-0.021173,10.263,22.865,387.29,393.62,391.89,-7.7371
131.1679,3.4018,-0.19764,35.056,393.32,-0.02142,10.32,22.865,393.29,399.07,397.83,-7.737
133.0119,3.4038,-0.19975,35.319,398.86,-0.021656,10.332,22.865,398.82,404.88,403.98,-7.7368
134.8506,3.3971,-0.19848,33.772,400.0,-0.021507,10.304,22.865,400.14,405.35,405.09,-7.7368
136.8506,3.3981,-0.19796,32.949,400.0,-0.021453,10.312,22.865,400.2,405.91,406.05,-7.7372
138.8506,3.4104,-0.19742,32.825,400.0,-0.021406,10.347,22.865,400.14,406.08,406.35,-7.7375
140.8506,3.3862,-0.19723,32.312,400.0,-0.021395,10.273,22.865,400.13,405.76,406.21,-7.7373
142.8506,3.1796,-0.19943,32.035,400.0,-0.021653,9.6476,22.865,400.11,404.94,405.59,-7.7376
144.8506,3.1728,-0.20194,32.086,400.0,-0.021933,9.6241,22.865,400.05,404.07,404.91,-7.7378
146.8506,3.1535,-0.20319,32.992,400.0,-0.022045,9.5673,22.864,398.35,400.72,401.82,-7.7374
148.8506,3.1407,-0.20086,32.201,400.0,-0.02178,9.528,22.866,398.63,400.25,401.69,-7.7365
150.8506,3.1261,-0.19976,31.096,400.0,-0.021701,9.4818,22.865,399.73,400.38,401.87,-7.7365
152.8506,3.1325,-0.19937,31.055,400.0,-0.021644,9.5068,22.865,399.66,399.39,401.12,-7.7372
154.8506,3.1168,-0.19929,31.162,400.0,-0.021634,9.4549,22.864,399.61,398.67,400.42,-7.737
156.6782,3.1168,-0.19872,31.436,400.0,-0.021584,9.4558,22.865,399.58,398.22,400.0,-7.7372
158.6782,3.1111,-0.19856,31.415,400.0,-0.02155,9.4362,22.864,399.63,397.77,399.7,-7.7365
160.6782,3.0957,-0.19794,31.348,400.0,-0.021469,9.3918,22.865,399.6,397.49,399.5,-7.7361
162.6782,3.1121,-0.20291,31.288,400.0,-0.021977,9.4414,22.866,399.59,397.35,399.3,-7.7362
164.5717,3.1038,-0.19967,31.644,400.0,-0.021679,9.413,22.865,399.5,397.12,399.07,-7.7366
166.5717,3.0883,-0.19899,31.619,400.0,-0.021611,9.3688,22.864,399.58,397.21,399.04,-7.7369
168.5717,3.1,-0.1986,31.402,400.0,-0.02155,9.4082,22.865,399.59,397.09,398.95,-7.7372
170.5717,3.0918,-0.19764,31.528,400.0,-0.021405,9.3773,22.865,399.6,397.12,399.0,-7.737
172.5717,3.0875,-0.20259,31.832,400.0,-0.02196,9.3715,22.865,399.55,397.07,398.89,-7.7372
174.5717,3.0921,-0.19922,31.882,400.0,-0.021612,9.3767,22.865,399.56,397.13,398.91,-7.7374
176.5717,3.0746,-0.19906,31.972,400.0,-0.021593,9.3272,22.864,399.54,397.24,398.92,-7.7366
178.4658,3.0596,-0.05083,31.544,400.0,-0.0054964,9.2846,22.865,399.61,397.29,399.01,-7.7354
178.6186,3.1715,0.015666,31.569,400.0,0.0018658,9.6256,22.858,399.58,397.19,398.91,-7.7358
178.6196,3.0691,0.0021708,31.67,400.0,0.0012454,9.3236,22.874,399.58,397.18,398.9,-7.735
178.6206,3.007,0.015706,31.771,400.0,0.00048883,9.116,22.864,399.58,397.18,398.89,-7.7364
178.6216,3.1222,0.0090519,31.872,400.0,0.002189,9.4698,22.862,399.58,397.17,398.89,-7.7351
178.6226,3.0228,0.010754,31.882,400.0,0.001124,9.2056,22.871,399.58,397.16,398.89,-7.7365
178.6236,3.1152,0.022857,31.882,400.0,0.0019734,9.4494,22.864,399.58,397.15,398.9,-7.7358
178.6246,3.0164,0.00087737,31.882,400.0,0.00073422,9.1874,22.866,399.59,397.14,398.9,-7.7372
178.6256,3.1098,0.019068,31.882,400.0,0.0012076,9.4516,22.871,399.59,397.14,398.91,-7.7344
178.6266,3.0198,0.013606,31.882,400.0,0.0023801,9.1309,22.86,399.59,397.13,398.92,-7.7344
178.6276,3.1023,0.010287,31.882,400.0,8.5486e-05,9.4108,22.861,399.6,397.12,398.92,-7.7351
178.6286,2.8706,0.012422,31.882,400.0,0.0018175,8.6699,22.872,399.6,397.11,398.93,-7.7335
178.6296,3.1428,0.0085896,31.882,400.0,0.0016279,9.5337,22.86,399.6,397.1,398.93,-7.7366
178.6306,3.0503,0.022685,31.882,400.0,0.0011827,9.2929,22.864,399.61,397.09,398.94,-7.735
178.6316,3.1032,0.0039929,31.882,400.0,0.0017987,9.4289,22.864,399.61,397.08,398.95,-7.7359
178.6326,3.0144,0.016864,31.882,400.0,0.0011431,9.1465,22.864,399.61,397.09,398.95,-7.735
178.6336,3.1095,0.019725,31.882,400.0,0.0022591,9.4336,22.861,399.61,397.11,398.95,-7.7356
178.6346,3.0211,0.0023472,31.882,400.0,0.00025112,9.1621,22.869,399.61,397.12,398.96,-7.7374
178.6356,3.0971,0.018394,31.882,400.0,0.001841,9.4312,22.864,399.61,397.14,398.96,-7.7356
178.6366,3.0318,0.0092316,31.882,400.0,0.0021287,9.1234,22.858,399.61,397.15,398.96,-7.7364
178.6376,3.1092,0.014454,31.882,400.0,0.0003359,9.4363,22.861,399.61,397.17,398.96,-7.7351
178.6386,3.1592,0.0043815,31.882,400.0,0.0017055,9.621,22.87,399.61,397.18,398.97,-7.7349
178.6396,3.0778,0.0031666,31.882,400.0,0.00037805,9.388,22.865,399.61,397.2,398.97,-7.7364
178.6406,3.0254,0.021782,31.882,400.0,0.0016232,9.1385,22.864,399.61,397.21,398.97,-7.735
178.6416,3.1291,0.0012316,31.882,400.0,0.0010331,9.4774,22.866,399.61,397.23,398.98,-7.7365
178.6426,3.0358,0.018396,31.882,400.0,0.0012071,9.2391,22.873,399.6,397.24,398.98,-7.7352
178.6436,3.1104,0.015341,31.882,400.0,0.0026804,9.4567,22.861,399.6,397.25,398.98,-7.7338
178.6446,3.0466,0.0081771,31.882,400.0,5.5107e-05,9.2054,22.861,399.59,397.26,398.99,-7.7366
178.6456,3.1029,0.014739,31.882,400.0,0.0020745,9.4158,22.867,399.59,397.27,398.99,-7.7351
178.6466,3.0411,0.009472,31.882,400.0,0.0017863,9.2233,22.861,399.58,397.28,398.99,-7.7352
178.6476,3.0896,0.0204,31.882,400.0,0.00096924,9.3747,22.865,399.57,397.28,398.99,-7.735
178.6486,2.9104,0.0067147,31.882,400.0,0.0018423,8.78,22.858,399.57,397.29,399.0,-7.7352
178.6496,3.1358,0.01307,31.882,400.0,0.00075885,9.4907,22.867,399.56,397.3,399.0,-7.7365
178.6506,3.0825,0.021745,31.882,400.0,0.0022128,9.3565,22.864,399.56,397.31,399.0,-7.7357
178.6516,3.0766,0.0080278,31.882,400.0,0.001016,9.3364,22.871,399.55,397.32,399.01,-7.735
178.6526,3.0533,0.017987,31.882,400.0,0.0014674,9.2209,22.867,399.55,397.33,399.01,-7.7365
178.6536,3.089,0.013515,31.882,400.0,0.0022883,9.3544,22.863,399.55,397.33,399.01,-7.735
178.6546,3.0532,0.015421,31.882,400.0,0.00059121,9.2258,22.861,399.56,397.34,399.02,-7.7352
178.6556,3.07,0.0077643,31.882,400.0,0.001791,9.352,22.861,399.56,397.34,399.02,-7.735
178.6566,3.055,0.010943,31.882,400.0,0.0012261,9.2642,22.867,399.56,397.35,399.02,-7.7357
178.6576,3.0641,0.021589,31.882,400.0,0.0014413,9.334,22.867,399.57,397.36,399.02,-7.7366
178.6586,3.1978,-0.0030826,31.882,400.0,0.00086766,9.7004,22.876,399.57,397.36,399.03,-7.7358
178.6596,3.0565,0.011343,31.882,400.0,0.00044622,9.3132,22.875,399.57,397.37,399.03,-7.735
178.6606,3.0477,0.014292,31.882,400.0,0.0023005,9.2542,22.867,399.58,397.37,399.03,-7.7353
178.6616,3.0848,0.0092678,31.882,400.0,0.00048759,9.398,22.868,399.58,397.38,399.04,-7.735
178.6626,3.0933,0.015177,31.882,400.0,0.0018496,9.3308,22.863,399.58,397.38,399.03,-7.7358
178.6636,3.0877,0.010325,31.882,400.0,0.0019355,9.3159,22.859,399.58,397.37,399.03,-7.7351
178.6646,3.0697,0.019556,31.882,400.0,0.00074512,9.3418,22.872,399.59,397.36,399.03,-7.7335
178.6656,3.0643,0.0031791,31.882,400.0,0.0017487,9.3519,22.873,399.59,397.36,399.03,-7.7366
178.6666,3.0891,0.016092,31.882,400.0,0.0010309,9.383,22.867,399.59,397.35,399.02,-7.735
178.6676,3.056,0.020723,31.882,400.0,0.0018772,9.2857,22.865,399.6,397.35,399.02,-7.7366
178.6686,2.9564,0.0021113,31.882,400.0,0.00074226,8.921,22.867,399.6,397.34,399.02,-7.7349
178.6696,3.0893,0.015424,31.882,400.0,0.00093344,9.3773,22.865,399.6,397.33,399.01,-7.7366
178.6706,3.1294,0.014402,31.882,400.0,0.0025216,9.4772,22.869,399.61,397.33,399.01,-7.7351
178.6716,3.0642,0.015528,31.882,400.0,0.00064177,9.3388,22.84,399.61,397.32,399.01,-7.7365
178.6726,3.1075,0.0093508,29.013,400.0,0.0020167,9.4007,22.803,400.31,398.47,399.0,-7.7351
178.6736,3.0554,0.011241,25.824,400.0,0.001564,9.2823,22.724,401.08,399.75,399.0,-7.7358
178.6746,3.4722,0.022813,22.636,400.0,0.0013562,10.407,22.564,401.86,401.03,399.0,-7.7349
178.6756,3.0035,0.0021459,19.448,400.0,0.0012834,9.2392,22.109,402.64,402.31,399.0,-7.735
178.6766,3.2323,0.018906,16.26,400.0,0.0010841,9.711,21.414,403.41,403.58,398.99,-7.7351
178.6776,2.9853,0.017138,13.071,400.0,0.0023738,9.1215,20.462,404.19,404.86,398.99,-7.7358
178.6786,3.4009,0.0071316,9.8832,400.0,0.0002322,10.349,19.378,404.97,406.14,398.99,-7.7352
178.6796,2.8602,0.0059195,6.6949,400.0,0.00091728,8.6871,18.188,405.74,407.42,398.98,-7.7373
178.6806,3.1652,0.0082358,3.5067,400.0,0.0018639,9.5313,16.994,406.52,408.7,398.98,-7.7365
178.6816,2.9045,0.017474,0.31848,400.0,0.00070036,8.8956,15.779,407.3,409.98,398.98,-7.7366
178.6826,3.1423,0.0045395,0.0,400.0,0.0017738,9.539,14.63,409.08,411.89,398.99,-7.7365
178.6836,2.9685,0.0097891,0.0,400.0,0.00086047,9.0082,13.554,410.97,413.88,399.01,-7.7365
178.6846,3.0883,0.02059,0.0,395.32,0.0018011,9.3646,12.522,412.86,415.87,399.02,-7.7366
178.6856,3.0421,-0.0021835,0.0,370.32,0.00041491,9.2282,11.569,414.76,417.86,399.04,-7.735
178.6866,3.1428,0.01982,0.0,345.32,0.0012618,9.5291,10.682,416.65,419.85,399.05,-7.7344
178.6876,2.9678,0.010587,0.0,320.32,0.0020688,9.0206,9.808,418.54,421.84,399.07,-7.7366
178.6886,3.0086,0.011323,0.0,295.32,8.7798e-05,9.0417,8.9891,420.43,423.83,399.08,-7.7366
178.6896,23.87,0.13064,0.0,270.32,0.013694,67.488,8.2316,422.33,425.82,399.1,-7.7352
178.6906,37.373,0.57566,0.0,245.32,0.062081,112.76,7.7058,424.22,427.81,399.11,-7.7034
178.6916,36.091,1.5464,0.0,220.32,0.18078,109.28,6.9274,426.11,429.8,399.13,-7.7118
178.6926,35.633,2.0988,0.0,195.32,0.25749,108.72,6.2262,427.15,430.41,399.12,-7.7
178.6936,37.764,2.745,0.0,170.32,0.34751,114.22,5.6287,428.1,430.87,399.1,-7.7074
178.6946,35.812,3.452,0.0,145.32,0.46179,108.78,4.9681,429.05,431.33,399.09,-7.7062
178.6956,37.955,3.8745,0.0,120.32,0.53391,115.06,4.391,429.99,431.79,399.08,-7.7064
178.6966,37.068,4.4815,0.0,95.316,0.6474,112.3,3.8681,430.94,432.25,399.07,-7.7078
178.6976,37.848,4.9737,0.0,70.316,0.7527,114.94,3.3491,431.88,432.71,399.06,-7.7033
178.6986,38.091,5.3627,0.0,45.316,0.83504,115.32,2.9165,432.83,433.17,399.04,-7.704
178.6996,37.906,5.7668,0.0,20.316,0.9406,114.94,2.526,433.77,433.63,399.03,-7.7033
178.7006,38.133,6.0947,0.0,0.00059176,1.0247,115.63,2.1635,434.72,434.09,399.02,-7.7033
178.7016,37.441,6.3988,0.0,1.3655e-17,1.1124,113.57,1.86,435.67,434.55,399.01,-7.7055
178.7026,37.837,6.6376,0.0,3.1510000000000003e-31,1.1925,114.92,1.5992,435.47,433.83,399.01,-7.7033
178.7036,38.041,6.8872,0.0,7.0065e-45,1.2692,115.38,1.3599,435.15,432.99,399.01,-7.7047
178.7046,38.267,7.1065,0.0,0.0,1.3579,116.1,1.1431,434.83,432.15,399.01,-7.7048
178.7056,38.903,7.3142,0.0,0.0,1.4284,117.94,0.93422,434.51,431.31,399.01,-7.7048
178.7066,39.085,7.5284,0.0,0.0,1.5257,118.57,0.72297,434.19,430.47,399.01,-7.7048
178.7076,38.969,7.7174,0.0,0.0,1.6139,119.23,0.51826,433.87,429.63,399.01,-7.7054
178.7086,31.604,7.7926,0.0,0.0,1.6402,95.563,0.42591,433.55,428.79,399.01,-7.7131
178.7096,31.002,7.7221,0.0,0.0,1.6215,93.705,0.36099,433.23,427.95,399.01,-7.7104
178.7106,30.325,7.7723,0.0,0.0,1.6326,91.704,0.31204,432.9,427.11,399.01,-7.7164
178.7116,29.792,7.771,0.0,0.0,1.6405,90.293,0.25612,432.58,426.27,399.01,-7.7171
178.7126,29.292,7.7643,0.0,0.0,1.6358,88.812,0.20714,432.37,425.28,399.0,-7.7172
178.7136,28.845,7.807,0.0,0.0,1.6543,87.43,0.15685,432.16,424.28,398.98,-7.7173
178.7146,28.662,7.803,0.0,0.0,1.6606,86.877,0.11518,431.95,423.28,398.97,-7.7186
178.7156,28.166,7.8076,0.0,0.0,1.6471,85.432,0.07786,431.74,422.28,398.96,-7.7197
178.7166,27.543,7.7958,0.0,0.0,1.6573,83.632,0.045422,431.54,421.27,398.95,-7.7182
178.7176,27.027,7.8045,0.0,0.0,1.6532,82.045,0.040128,431.33,420.27,398.94,-7.7204
178.7186,26.387,7.8186,0.0,0.0,1.6566,80.067,0.042926,431.12,419.27,398.92,-7.7196
178.7196,25.69,7.7911,0.0,0.0,1.6556,77.987,0.04715,430.92,418.26,398.91,-7.7212
178.7206,25.271,7.8205,0.0,0.0,1.6547,76.705,0.051577,430.71,417.26,398.9,-7.7234
178.7216,25.024,7.8091,0.0,0.0,1.6621,75.929,0.051601,430.5,416.26,398.89,-7.7228
178.7226,24.766,7.8089,0.0,0.0,1.6522,75.123,0.05152,430.29,415.53,398.9,-7.7227
178.7236,24.393,7.8216,0.0,0.0,1.6645,73.988,0.041207,430.07,414.84,398.92,-7.7256
178.7246,24.144,7.8065,0.0,0.0,1.6608,73.23,0.045131,429.86,414.15,398.93,-7.7243
178.7256,23.865,7.8204,0.0,0.0,1.6529,72.393,0.04762,429.64,413.46,398.95,-7.7244
178.7266,23.709,7.8011,0.0,0.0,1.6616,71.912,0.04975,429.42,412.77,398.96,-7.7251
178.7276,23.513,7.819,0.0,0.0,1.657,71.324,0.053325,429.21,412.08,398.98,-7.7265
178.7286,23.392,7.8294,0.0,0.0,1.6673,70.979,0.046756,428.99,411.39,398.99,-7.7251
178.7296,23.14,7.8097,0.0,0.0,1.6596,70.176,0.046971,428.78,410.69,399.01,-7.7258
178.7306,23.067,7.829,0.0,0.0,1.6615,70.006,0.046955,428.56,410.0,399.02,-7.7243
178.7316,22.85,7.8132,0.0,0.0,1.6655,69.331,0.053319,428.34,409.31,399.04,-7.7273
178.7326,22.76,7.8271,0.0,0.0,1.6575,69.041,0.041012,428.07,408.69,399.06,-7.7267
178.7336,22.565,7.8193,0.0,0.0,1.6673,68.473,0.047085,427.79,408.07,399.09,-7.7287
178.7346,22.51,7.8175,0.0,0.0,1.6612,68.267,0.045382,427.51,407.45,399.12,-7.7273
178.7356,22.335,7.8275,0.0,0.0,1.6594,67.756,0.045325,427.23,406.83,399.15,-7.7287
178.7366,22.268,7.8018,0.0,0.0,1.6611,67.6,0.046783,426.95,406.22,399.18,-7.7295
178.7376,22.092,7.8315,0.0,0.0,1.6606,67.053,0.04676,426.68,405.6,399.21,-7.7275
178.7386,22.036,7.826,0.0,0.0,1.6704,66.824,0.044961,426.4,404.98,399.24,-7.7302
178.7396,21.88,7.8135,0.0,0.0,1.6566,66.372,0.040868,426.12,404.37,399.28,-7.7267
178.7406,21.786,7.8273,0.0,0.0,1.6653,66.094,0.044704,425.84,403.75,399.31,-7.7303
178.7416,21.676,7.813,0.0,0.0,1.6649,65.75,0.046728,425.56,403.13,399.34,-7.7273
178.7426,21.603,7.8322,0.0,0.0,1.6593,65.555,0.040855,425.33,402.66,399.36,-7.7288
178.7436,21.494,7.8136,0.0,0.0,1.6683,65.201,0.044678,425.11,402.21,399.38,-7.7296
178.7446,21.406,7.823,0.0,0.0,1.6591,64.918,0.047004,424.89,401.76,399.41,-7.7303
178.7456,21.306,7.8297,0.0,0.0,1.6658,64.68,0.044873,424.66,401.31,399.43,-7.7288
178.7466,21.226,7.8076,0.0,0.0,1.6598,64.425,0.044721,424.44,400.86,399.46,-7.7303
178.7476,21.123,7.8359,0.0,0.0,1.6647,64.122,0.048969,424.22,400.41,399.48,-7.7288
178.7486,21.034,7.8181,0.0,0.0,1.6688,63.809,0.045416,424.0,399.96,399.5,-7.7288
178.7496,20.953,7.8219,0.0,0.0,1.6554,63.575,0.04923,423.77,399.5,399.53,-7.7303
178.7506,20.858,7.8221,0.0,0.0,1.668,63.295,0.047157,423.55,399.05,399.55,-7.7288
178.7516,20.784,7.8157,0.0,0.0,1.6626,63.074,0.047444,423.33,398.6,399.58,-7.729
178.7526,20.656,7.8364,0.0,0.0,1.6626,62.699,0.051404,423.13,398.43,399.62,-7.7287
178.7536,20.531,7.809,0.0,0.0,1.6658,62.229,0.050022,422.92,398.29,399.66,-7.7301
178.7546,20.13,7.8291,0.0,0.0,1.6593,61.13,0.058787,422.72,398.15,399.7,-7.7303
178.7556,19.487,7.8233,0.0,0.0,1.6676,59.17,0.07739,422.52,398.02,399.74,-7.729
178.7566,18.414,7.8092,0.0,0.0,1.6556,55.949,0.11671,422.32,397.88,399.79,-7.7319
178.7576,17.127,7.8217,0.0,0.0,1.6618,52.079,0.16955,422.12,397.74,399.83,-7.7312
178.7586,15.659,7.8008,0.0,0.0,1.6594,47.677,0.22655,421.92,397.6,399.87,-7.7335
178.7596,14.03,7.8091,0.0,0.0,1.6478,42.635,0.29626,421.72,397.46,399.91,-7.7357
178.7606,12.309,7.7899,0.0,0.0,1.6555,37.459,0.37464,421.52,397.32,399.95,-7.7352
178.7616,9.9135,7.788,0.0,0.0,1.6442,30.216,0.45593,421.31,397.18,400.0,-7.7373
178.7626,1.3023,7.7395,0.0,0.0,1.6221,4.5774,0.58802,421.14,397.28,400.04,-7.7413
178.7636,0.59224,7.6707,0.0,0.0,1.5946,1.587,0.96222,420.97,397.4,400.07,-7.7504
178.7646,3.8664,7.7597,0.0,0.0,1.6263,11.374,1.2805,420.8,397.52,400.11,-7.7459
178.7656,3.6014,7.7265,0.0,0.0,1.6236,10.924,1.6649,420.63,397.64,400.15,-7.7443
178.7666,1.7596,7.7467,0.0,0.0,1.6208,5.6399,2.0098,420.46,397.76,400.19,-7.7473
178.7676,2.783,7.7322,0.0,0.0,1.6222,8.2692,2.4098,420.28,397.88,400.23,-7.7459
178.7686,2.4235,7.7317,0.0,0.0,1.6229,7.3316,2.7837,420.11,398.0,400.27,-7.7444
178.7696,3.0904,7.7547,0.0,0.0,1.6219,9.3998,3.1541,419.94,398.12,400.31,-7.7461
178.7706,2.3554,7.7316,0.0,0.0,1.628,7.1897,3.4771,419.77,398.24,400.35,-7.7452
178.7716,3.0225,7.7504,0.0,0.0,1.622,9.0912,3.7797,419.6,398.36,400.39,-7.746
178.7726,2.4172,7.7618,0.0,0.0,1.6364,7.4261,4.0352,419.47,398.52,400.41,-7.7464
178.7736,2.8979,7.7383,0.0,0.0,1.6225,8.7787,4.2538,419.35,398.68,400.43,-7.7443
178.7746,2.4581,7.7632,0.0,0.0,1.632,7.4565,4.4518,419.23,398.85,400.44,-7.7442
178.7756,2.9063,7.745,0.0,0.0,1.6318,8.8041,4.6315,419.11,399.01,400.46,-7.7441
178.7766,2.3707,7.7572,0.0,0.0,1.6227,7.1921,4.822,418.99,399.17,400.48,-7.7428
178.7776,2.9032,7.7402,0.0,0.0,1.631,8.8891,4.9987,418.87,399.33,400.5,-7.742
178.7786,2.4615,7.7503,0.0,0.0,1.6273,7.3847,5.1805,418.75,399.5,400.52,-7.7443
178.7796,2.8633,7.7622,0.0,0.0,1.63,8.7505,5.3565,418.63,399.66,400.53,-7.7412
178.7806,2.531,7.7316,0.0,0.0,1.6248,7.6644,5.5401,418.51,399.82,400.55,-7.7428
178.7816,2.8074,7.7588,0.0,0.0,1.6254,8.563,5.7164,418.39,399.98,400.57,-7.7412
178.7826,2.5513,7.7441,0.0,0.0,1.6306,7.7084,5.9039,418.25,400.06,400.6,-7.7414
178.7836,2.7846,7.7466,0.0,0.0,1.621,8.4375,6.0677,418.1,400.13,400.64,-7.7398
178.7846,2.607,7.7507,0.0,0.0,1.6303,7.9032,6.2441,417.95,400.19,400.67,-7.7405
178.7856,2.7181,7.7404,0.0,0.0,1.6275,8.2729,6.4098,417.81,400.26,400.7,-7.7426
178.7866,2.6527,7.7595,0.0,0.0,1.6244,7.9902,6.5867,417.66,400.32,400.73,-7.7384
178.7876,2.6848,7.7361,0.0,0.0,1.6299,8.1832,6.7476,417.51,400.39,400.77,-7.7397
178.7886,2.6734,7.7523,0.0,0.0,1.624,8.0626,6.9281,417.36,400.46,400.8,-7.739
178.7896,2.6706,7.759,0.0,0.0,1.6334,8.1062,7.0913,417.22,400.52,400.83,-7.7397
178.7906,2.6741,7.735,0.0,0.0,1.6225,8.0878,7.2632,417.07,400.59,400.87,-7.7397
178.7916,2.7242,7.7604,0.0,0.0,1.6294,8.2727,7.4388,416.92,400.66,400.9,-7.7381
178.7926,2.6882,7.7444,0.0,0.0,1.6324,8.1425,7.6187,416.79,400.67,400.95,-7.7397
178.7936,2.6436,7.7514,0.0,0.0,1.6214,8.0603,7.7863,416.67,400.69,400.99,-7.7389
178.7946,2.7353,7.7459,0.0,0.0,1.6319,8.2908,7.9585,416.54,400.7,401.04,-7.7395
178.7956,2.6767,7.7491,0.0,0.0,1.6272,8.1242,8.1317,416.42,400.71,401.09,-7.7368
178.7966,2.7212,7.762,0.0,0.0,1.629,8.2344,8.2933,416.29,400.72,401.14,-7.7366
178.7976,2.6744,7.7332,0.0,0.0,1.6261,8.0551,8.4632,416.16,400.73,401.19,-7.7382
178.7986,2.7179,7.7618,0.0,0.0,1.6267,8.2782,8.6324,416.04,400.75,401.24,-7.736
178.7996,2.7165,7.7486,0.0,0.0,1.633,8.2682,8.8108,415.91,400.76,401.28,-7.7379
178.8006,2.6706,7.7471,0.0,0.0,1.6222,8.1444,8.9718,415.79,400.77,401.33,-7.7366
178.8016,2.7562,7.7565,0.0,0.0,1.632,8.3422,9.1377,415.66,400.78,401.38,-7.7374
178.8026,2.6278,7.7406,0.0,0.0,1.6286,7.97,9.3135,415.55,400.8,401.42,-7.7365
178.8036,2.8125,7.7609,0.0,0.0,1.6243,8.54,9.4835,415.45,400.82,401.45,-7.7381
178.8046,2.6736,7.7398,0.0,0.0,1.6313,8.0807,9.6531,415.35,400.84,401.49,-7.7359
178.8056,2.7461,7.7524,0.0,0.0,1.6244,8.3734,9.8249,415.25,400.85,401.53,-7.7366
178.8066,2.7032,7.7594,0.0,0.0,1.6322,8.214,9.9904,415.15,400.87,401.56,-7.7366
178.8076,2.791,7.737,0.0,0.0,1.625,8.4657,10.162,415.04,400.89,401.6,-7.7352
178.8086,2.6908,7.7578,0.0,0.0,1.6271,8.1909,10.34,414.94,400.91,401.63,-7.7357
178.8096,2.7913,7.7481,0.0,0.0,1.6334,8.4552,10.508,414.84,400.93,401.67,-7.7352
178.8106,2.7007,7.7505,0.0,0.0,1.6202,8.1652,10.685,414.74,400.94,401.71,-7.735
178.8116,2.7744,7.7479,0.0,0.0,1.6323,8.4632,10.854,414.64,400.96,401.74,-7.7357
178.8126,2.7598,7.7419,0.0,0.0,1.6259,8.3088,11.018,414.54,400.94,401.78,-7.735
178.8136,2.7371,7.7584,0.0,0.0,1.6258,8.2933,11.193,414.44,400.92,401.81,-7.7351
178.8146,2.7632,7.7357,0.0,0.0,1.6279,8.3757,11.362,414.35,400.89,401.85,-7.735
178.8156,2.7255,7.7557,0.0,0.0,1.624,8.309,11.534,414.25,400.87,401.89,-7.735
178.8166,2.7365,7.7476,0.0,0.0,1.6314,8.314,11.706,414.15,400.85,401.92,-7.7344
178.8176,2.7108,7.7429,0.0,0.0,1.6218,8.2294,11.878,414.06,400.82,401.96,-7.7336
178.8186,2.7494,7.7508,0.0,0.0,1.6288,8.3369,12.045,413.96,400.8,402.0,-7.7351
178.8196,2.6979,7.7431,0.0,0.0,1.6302,8.2091,12.213,413.87,400.77,402.03,-7.735
178.8206,2.7758,7.7578,0.0,0.0,1.6227,8.388,12.383,413.77,400.75,402.07,-7.7336
178.8216,2.6968,7.7382,0.0,0.0,1.6305,8.1906,12.551,413.67,400.73,402.1,-7.7335
178.8226,2.78,7.7489,0.0,0.0,1.6242,8.5142,12.727,413.57,400.66,402.13,-7.7335
178.8236,2.7185,7.756,0.0,0.0,1.6293,8.291,12.892,413.48,400.59,402.16,-7.735
178.8246,2.7646,7.7325,0.0,0.0,1.6233,8.4119,13.055,413.38,400.51,402.19,-7.7336
178.8256,2.7512,7.7553,0.0,0.0,1.6251,8.3501,13.201,413.28,400.44,402.21,-7.7336
178.8266,2.7851,7.7427,0.0,0.0,1.6309,8.4608,13.34,413.18,400.37,402.24,-7.7359
178.8276,2.8048,7.747,0.0,0.0,1.6196,8.5379,13.463,413.08,400.3,402.27,-7.735
178.8286,2.7856,7.7451,0.0,0.0,1.6296,8.5017,13.56,412.98,400.22,402.29,-7.738
178.8296,2.7906,7.7421,0.0,0.0,1.6261,8.4656,13.65,412.88,400.15,402.32,-7.7366
178.8306,2.8513,7.7568,0.0,0.0,1.6249,8.6457,13.716,412.78,400.08,402.35,-7.7382
178.8316,2.779,7.7306,0.0,0.0,1.6266,8.4682,13.751,412.68,400.01,402.38,-7.7397
178.8326,2.8992,7.7548,0.0,0.0,1.623,8.7917,13.771,412.59,399.91,402.41,-7.7413
178.8336,2.7242,7.7519,0.0,0.0,1.6319,8.2836,13.762,412.49,399.82,402.45,-7.7437
178.8346,3.0014,7.7363,0.0,0.0,1.62,9.1048,13.73,412.39,399.72,402.48,-7.7444
178.8356,2.702,7.7556,0.0,0.0,1.6289,8.1808,13.67,412.3,399.62,402.52,-7.7483
178.8366,3.022,7.738,0.0,0.0,1.6291,9.187,13.586,412.2,399.53,402.56,-7.752
178.8376,2.6825,7.7525,0.0,0.0,1.6208,8.1348,13.479,412.1,399.43,402.59,-7.7544
178.8386,3.0289,7.7396,0.0,0.0,1.6309,9.205,13.352,412.01,399.34,402.63,-7.7597
178.8396,2.655,7.7432,0.0,0.0,1.6229,8.0215,13.215,411.91,399.24,402.66,-7.7621
178.8406,3.0231,7.7563,0.0,0.0,1.6283,9.2123,13.066,411.82,399.14,402.7,-7.7661
178.8416,2.6266,7.732,0.0,0.0,1.6236,7.947,12.942,411.72,399.05,402.74,-7.7721
178.8426,3.0096,7.7573,0.0,0.0,1.6253,9.1562,12.824,411.63,398.95,402.76,-7.7762
178.8436,2.6212,7.7419,0.0,0.0,1.6304,7.9628,12.737,411.55,398.85,402.79,-7.7831
178.8446,2.9834,7.7434,0.0,0.0,1.6189,9.0944,12.677,411.46,398.76,402.82,-7.7877
178.8456,2.6621,7.7464,0.0,0.0,1.6295,8.0907,12.662,411.38,398.66,402.85,-7.7968
178.8466,3.0754,7.74,0.0,0.0,1.6261,9.3283,12.676,411.3,398.57,402.87,-7.8017
178.8476,2.5582,7.7556,0.0,0.0,1.6224,7.7033,12.699,411.21,398.47,402.9,-7.8093
178.8486,3.0834,7.7336,0.0,0.0,1.6279,9.3614,12.747,411.13,398.37,402.93,-7.8156
178.8496,2.5537,7.748,0.0,0.0,1.6207,7.7599,12.823,411.04,398.28,402.95,-7.824
178.8506,3.1458,7.7517,0.0,0.0,1.6314,9.5901,12.904,410.96,398.18,402.98,-7.8294
178.8516,2.5823,7.7307,0.0,0.0,1.6192,7.7597,12.999,410.88,398.08,403.01,-7.8386
178.8526,3.0124,7.7538,0.0,0.0,1.6275,9.2105,13.077,410.8,398.02,403.03,-7.8443
178.8536,2.67,7.7349,0.0,0.0,1.6277,8.022,13.145,410.73,397.95,403.05,-7.8513
178.8546,2.9192,7.7511,0.0,0.0,1.6201,8.9463,13.199,410.66,397.89,403.07,-7.8575
178.8556,2.7479,7.7355,0.0,0.0,1.6283,8.3219,13.241,410.58,397.83,403.09,-7.8661
178.8566,2.9293,7.7405,0.0,0.0,1.6235,8.9332,13.253,410.51,397.76,403.11,-7.8714
178.8576,2.7068,7.7545,0.0,0.0,1.6262,8.1628,13.253,410.44,397.7,403.13,-7.8806
178.8586,2.9813,7.7292,0.0,0.0,1.6239,9.051,13.242,410.37,397.64,403.16,-7.8877
178.8596,2.6547,7.754,0.0,0.0,1.6225,8.0475,13.207,410.3,397.57,403.18,-7.8938
178.8606,2.9505,7.7457,0.0,0.0,1.632,9.0149,13.167,410.22,397.51,403.2,-7.9017
178.8616,2.7123,7.7383,0.0,0.0,1.6172,8.1629,13.119,410.15,397.45,403.22,-7.9093
178.8626,2.904,7.7522,0.0,0.0,1.6313,8.8744,13.074,410.07,397.38,403.24,-7.9148
178.8636,2.749,7.7361,0.0,0.0,1.6267,8.3314,13.021,409.98,397.3,403.27,-7.9226
178.8646,2.876,7.7572,0.0,0.0,1.6234,8.7738,12.988,409.89,397.23,403.29,-7.9287
178.8656,2.7895,7.7331,0.0,0.0,1.6287,8.4503,12.951,409.8,397.16,403.32,-7.9365
178.8666,2.8736,7.7507,0.0,0.0,1.6233,8.7302,12.93,409.72,397.09,403.34,-7.9419
178.8676,2.8067,7.7513,0.0,0.0,1.6296,8.4343,12.923,409.63,397.02,403.36,-7.9503
178.8686,2.9093,7.7334,0.0,0.0,1.6217,8.8742,12.926,409.54,396.94,403.39,-7.9558
178.8696,2.8002,7.7526,0.0,0.0,1.6252,8.4447,12.93,409.45,396.87,403.41,-7.9614
178.8706,2.8763,7.7428,0.0,0.0,1.6312,8.7948,12.944,409.37,396.8,403.44,-7.9705
178.8716,2.8336,7.7467,0.0,0.0,1.6185,8.5222,12.969,409.28,396.73,403.46,-7.9762
178.8726,2.8364,7.7429,0.0,0.0,1.6314,8.6765,12.985,409.18,396.64,403.47,-7.9831
178.8736,2.8962,7.7413,0.0,0.0,1.6233,8.7612,13.009,409.08,396.55,403.47,-7.9907
178.8746,2.8011,7.7585,0.0,0.0,1.6264,8.53,13.036,408.98,396.46,403.48,-7.9968
178.8756,2.9014,7.7287,0.0,0.0,1.6244,8.7482,13.051,408.88,396.38,403.49,-8.0039
178.8766,2.7943,7.7563,0.0,0.0,1.6238,8.5299,13.074,408.78,396.29,403.49,-8.0087
178.8776,2.9302,7.7463,0.0,0.0,1.6315,8.8558,13.084,408.69,396.2,403.5,-8.014
178.8786,2.7872,7.7396,0.0,0.0,1.6196,8.4869,13.097,408.59,396.11,403.5,-8.0226
178.8796,2.9564,7.7494,0.0,0.0,1.6286,8.9308,13.102,408.49,396.03,403.51,-8.0287
178.8806,2.7486,7.7407,0.0,0.0,1.6292,8.4178,13.107,408.39,395.94,403.52,-8.0366
178.8816,2.952,7.7537,0.0,0.0,1.6203,8.9562,13.106,408.29,395.85,403.52,-8.0428
178.8826,2.7848,7.7368,0.0,0.0,1.6303,8.4298,13.102,408.22,395.76,403.54,-8.0504
178.8836,2.9852,7.7471,0.0,0.0,1.6223,9.043,13.095,408.15,395.67,403.56,-8.0582
178.8846,2.7529,7.7548,0.0,0.0,1.63,8.3813,13.088,408.08,395.58,403.57,-8.0656
178.8856,3.0117,7.7293,0.0,0.0,1.6215,9.1071,13.074,408.01,395.49,403.59,-8.0719
178.8866,2.7319,7.7584,0.0,0.0,1.6268,8.304,13.068,407.94,395.4,403.61,-8.079
178.8876,3.0174,7.7392,0.0,0.0,1.6303,9.0894,13.054,407.87,395.31,403.63,-8.0844
178.8886,2.719,7.7468,0.0,0.0,1.619,8.2784,13.046,407.8,395.22,403.65,-8.0914
178.8896,3.0318,7.7439,0.0,0.0,1.6299,9.151,13.033,407.73,395.13,403.66,-8.0992
178.8906,2.7256,7.742,0.0,0.0,1.6259,8.2942,13.03,407.66,395.04,403.68,-8.1046
178.8916,3.0266,7.7561,0.0,0.0,1.6246,9.1693,13.026,407.59,394.95,403.7,-8.111
178.8926,2.7315,7.7328,0.0,0.0,1.6272,8.312,13.025,407.52,394.85,403.74,-8.1188
178.8936,3.0448,7.754,0.0,0.0,1.6226,9.1717,13.023,407.45,394.76,403.77,-8.1234
178.8946,2.7117,7.7489,0.0,0.0,1.6311,8.2505,13.023,407.38,394.67,403.81,-8.1312
178.8956,3.0539,7.7399,0.0,0.0,1.6205,9.2696,13.028,407.32,394.57,403.84,-8.1401
178.8966,2.6911,7.7559,0.0,0.0,1.6302,8.1912,13.028,407.25,394.48,403.88,-8.1464
178.8976,3.0614,7.7394,0.0,0.0,1.6287,9.3,13.032,407.18,394.39,403.92,-8.1513
178.8986,2.6981,7.754,0.0,0.0,1.6213,8.2294,13.032,407.11,394.29,403.95,-8.1603
178.8996,3.0743,7.7382,0.0,0.0,1.6308,9.3182,13.037,407.04,394.2,403.99,-8.1638
178.9006,2.6906,7.7445,0.0,0.0,1.6227,8.1883,13.037,406.97,394.11,404.02,-8.1729
178.9016,3.0669,7.7558,0.0,0.0,1.629,9.2843,13.037,406.9,394.01,404.06,-8.1791
178.9026,2.6979,7.7311,0.0,0.0,1.6234,8.2197,13.037,406.83,393.92,404.09,-8.1869
178.9036,3.0743,7.7544,0.0,0.0,1.6243,9.3029,13.042,406.75,393.83,404.11,-8.1937
178.9046,2.7037,7.7413,0.0,0.0,1.6306,8.2196,13.042,406.68,393.74,404.13,-8.2001
178.9056,3.0554,7.7454,0.0,0.0,1.6188,9.2692,13.048,406.6,393.65,404.16,-8.2069
178.9066,2.6891,7.7445,0.0,0.0,1.6296,8.1398,13.051,406.52,393.56,404.18,-8.2134
178.9076,3.0545,7.7382,0.0,0.0,1.6247,9.2466,13.048,406.45,393.47,404.21,-8.2209
178.9086,2.6955,7.7579,0.0,0.0,1.6242,8.1783,13.051,406.37,393.38,404.23,-8.2272
178.9096,3.0429,7.7313,0.0,0.0,1.6267,9.2644,13.051,406.3,393.29,404.25,-8.2341
178.9106,2.7074,7.7488,0.0,0.0,1.6213,8.1779,13.049,406.22,393.2,404.28,-8.2411
178.9116,3.0358,7.7524,0.0,0.0,1.6318,9.2281,13.051,406.15,393.11,404.3,-8.2487
178.9126,2.6954,7.7321,0.0,0.0,1.6191,8.1708,13.051,406.09,393.01,404.32,-8.2549
178.9136,3.0224,7.7517,0.0,0.0,1.627,9.1899,13.048,406.04,392.92,404.34,-8.2641
178.9146,2.7016,7.7395,0.0,0.0,1.6293,8.1885,13.051,405.99,392.82,404.36,-8.269
178.9156,3.0089,7.7509,0.0,0.0,1.6196,9.1379,13.05,405.94,392.72,404.38,-8.2766
178.9166,2.7019,7.7378,0.0,0.0,1.6292,8.1885,13.051,405.89,392.63,404.39,-8.2823
178.9176,2.9895,7.7432,0.0,0.0,1.6235,9.0971,13.045,405.84,392.53,404.41,-8.2891
178.9186,2.7343,7.7545,0.0,0.0,1.6262,8.2681,13.05,405.79,392.43,404.43,-8.2961
178.9196,2.9765,7.7313,0.0,0.0,1.6238,9.0742,13.047,405.74,392.34,404.45,-8.3024
178.9206,2.7458,7.7519,0.0,0.0,1.6227,8.2523,13.049,405.69,392.24,404.47,-8.3085
178.9216,2.9754,7.7434,0.0,0.0,1.631,9.0405,13.042,405.63,392.14,404.48,-8.3148
178.9226,2.747,7.7404,0.0,0.0,1.6177,8.2862,13.047,405.58,392.04,404.51,-8.3223
178.9236,2.9505,7.7493,0.0,0.0,1.6309,8.9948,13.05,405.52,391.93,404.53,-8.3273
178.9246,2.7608,7.7363,0.0,0.0,1.625,8.3499,13.044,405.46,391.82,404.56,-8.3349
178.9256,2.9297,7.7572,0.0,0.0,1.6233,8.9175,13.05,405.41,391.71,404.58,-8.3419
178.9266,2.7814,7.7283,0.0,0.0,1.6259,8.4067,13.048,405.35,391.6,404.6,-8.349
178.9276,2.9293,7.7566,0.0,0.0,1.625,8.9356,13.043,405.29,391.49,404.63,-8.355
178.9286,2.7738,7.7492,0.0,0.0,1.6296,8.3656,13.047,405.23,391.38,404.65,-8.3629
178.9296,2.8951,7.7323,0.0,0.0,1.62,8.8174,13.047,405.18,391.28,404.68,-8.3697
178.9306,2.8201,7.7553,0.0,0.0,1.6279,8.4861,13.046,405.12,391.17,404.7,-8.3767
178.9316,2.8967,7.7405,0.0,0.0,1.6306,8.8512,13.046,405.06,391.06,404.72,-8.3821
178.9326,2.8223,7.7488,0.0,0.0,1.6191,8.5297,13.05,404.98,390.96,404.74,-8.389
178.9336,2.8615,7.743,0.0,0.0,1.6312,8.71,13.046,404.9,390.86,404.75,-8.3967
178.9346,2.856,7.7421,0.0,0.0,1.6239,8.6505,13.044,404.81,390.77,404.77,-8.403
178.9356,2.8492,7.7575,0.0,0.0,1.627,8.6919,13.046,404.73,390.67,404.78,-8.4093
178.9366,2.8686,7.73,0.0,0.0,1.6242,8.6529,13.046,404.64,390.57,404.8,-8.4169
178.9376,2.8484,7.7583,0.0,0.0,1.6237,8.6917,13.042,404.56,390.48,404.81,-8.4247
178.9386,2.9008,7.7455,0.0,0.0,1.6309,8.7145,13.047,404.48,390.38,404.83,-8.4301
178.9396,2.8156,7.7423,0.0,0.0,1.6196,8.6073,13.043,404.39,390.29,404.85,-8.4387
178.9406,2.9215,7.7489,0.0,0.0,1.6292,8.8014,13.044,404.31,390.19,404.86,-8.4435
178.9416,2.8008,7.7406,0.0,0.0,1.6282,8.5276,13.05,404.22,390.09,404.88,-8.4503
178.9426,2.9487,7.7555,0.0,0.0,1.622,8.8739,13.046,404.15,390.01,404.88,-8.4574
178.9436,2.7953,7.7362,0.0,0.0,1.6305,8.5299,13.046,404.08,389.92,404.88,-8.4644
178.9446,2.9637,7.7506,0.0,0.0,1.6227,8.9428,13.051,404.0,389.84,404.89,-8.4713
178.9456,2.781,7.7549,0.0,0.0,1.6308,8.4891,13.046,403.93,389.75,404.89,-8.4762
178.9466,2.9836,7.7328,0.0,0.0,1.6218,9.007,13.04,403.86,389.67,404.89,-8.4867
178.9476,2.7665,7.7564,0.0,0.0,1.627,8.4141,13.044,403.79,389.58,404.89,-8.4914
178.9486,2.9853,7.7427,0.0,0.0,1.6312,9.0385,13.05,403.72,389.5,404.9,-8.5007
178.9496,2.7667,7.7506,0.0,0.0,1.6208,8.4379,13.046,403.64,389.42,404.9,-8.5053
178.9506,3.0236,7.7412,0.0,0.0,1.6297,9.1072,13.046,403.57,389.33,404.9,-8.5131
178.9516,2.7517,7.7446,0.0,0.0,1.6259,8.3607,13.05,403.5,389.25,404.91,-8.5208
178.9526,3.0258,7.7608,0.0,0.0,1.6269,9.1666,13.056,403.44,389.16,404.91,-8.5249
178.9536,2.7575,7.7312,0.0,0.0,1.6263,8.3581,13.051,403.38,389.07,404.92,-8.5333
178.9546,3.0397,7.7554,0.0,0.0,1.6228,9.1898,13.051,403.33,388.98,404.92,-8.5402
178.9556,2.731,7.7499,0.0,0.0,1.6327,8.2965,13.045,403.27,388.89,404.93,-8.5472
178.9566,3.0591,7.7412,0.0,0.0,1.6208,9.2511,13.044,403.21,388.79,404.94,-8.5541
178.9576,2.7321,7.7532,0.0,0.0,1.6299,8.3122,13.047,403.15,388.7,404.94,-8.561
178.9586,3.061,7.7401,0.0,0.0,1.6294,9.2926,13.044,403.1,388.61,404.95,-8.5674
178.9596,2.7315,7.7555,0.0,0.0,1.6219,8.3252,13.04,403.04,388.52,404.95,-8.5744
178.9606,3.0541,7.7383,0.0,0.0,1.6308,9.2567,13.046,402.98,388.43,404.96,-8.5812
178.9616,2.7056,7.7502,0.0,0.0,1.6236,8.2686,13.052,402.93,388.34,404.97,-8.5875
178.9626,3.0621,7.7554,0.0,0.0,1.6297,9.3154,13.048,402.87,388.27,404.98,-8.5944
178.9636,2.7112,7.7339,0.0,0.0,1.6235,8.2478,13.048,402.82,388.19,404.98,-8.5993
178.9646,3.0739,7.7582,0.0,0.0,1.6258,9.3024,13.051,402.77,388.11,404.99,-8.6069
178.9656,2.7178,7.7438,0.0,0.0,1.6325,8.2837,13.047,402.72,388.04,405.0,-8.6131
178.9666,3.0748,7.7501,0.0,0.0,1.6213,9.328,13.042,402.67,387.96,405.01,-8.6213
178.9676,2.7105,7.7462,0.0,0.0,1.631,8.2267,13.048,402.62,387.89,405.02,-8.6263
178.9686,3.0748,7.745,0.0,0.0,1.6276,9.3236,13.044,402.57,387.81,405.03,-8.6331
178.9696,2.7236,7.7606,0.0,0.0,1.6262,8.2738,13.048,402.52,387.74,405.04,-8.641
178.9706,3.0629,7.7343,0.0,0.0,1.6278,9.3032,13.048,402.46,387.66,405.05,-8.647
178.9716,2.7175,7.7549,0.0,0.0,1.6237,8.2784,13.044,402.41,387.59,405.06,-8.6535
178.9726,3.0629,7.7543,0.0,0.0,1.6336,9.308,13.047,402.37,387.5,405.07,-8.6612
178.9736,2.7292,7.7364,0.0,0.0,1.6204,8.2628,13.043,402.32,387.42,405.08,-8.6674
178.9746,3.0489,7.7567,0.0,0.0,1.6306,9.2694,13.042,402.28,387.33,405.09,-8.675
178.9756,2.7415,7.7411,0.0,0.0,1.6304,8.2758,13.044,402.23,387.25,405.1,-8.6814
178.9766,3.0438,7.7562,0.0,0.0,1.6217,9.272,13.044,402.19,387.17,405.12,-8.6876
178.9776,2.7365,7.7404,0.0,0.0,1.6312,8.3143,13.05,402.14,387.08,405.13,-8.6953
178.9786,3.0378,7.7484,0.0,0.0,1.6247,9.2743,13.046,402.1,387.0,405.14,-8.7028
178.9796,2.7552,7.7558,0.0,0.0,1.6287,8.3346,13.044,402.05,386.91,405.15,-8.7092
178.9806,3.0306,7.7343,0.0,0.0,1.625,9.2338,13.046,402.01,386.83,405.16,-8.7139
178.9816,2.7734,7.7581,0.0,0.0,1.6252,8.3552,13.042,401.96,386.74,405.18,-8.723
178.9826,3.0041,7.7458,0.0,0.0,1.6326,9.1612,13.049,401.91,386.65,405.19,-8.7309
178.9836,2.7805,7.7456,0.0,0.0,1.6196,8.3735,13.046,401.85,386.56,405.21,-8.7362
178.9846,3.0035,7.751,0.0,0.0,1.6313,9.1542,13.043,401.79,386.47,405.23,-8.7448
178.9856,2.7952,7.7422,0.0,0.0,1.6269,8.4528,13.04,401.73,386.38,405.25,-8.7511
178.9866,2.9718,7.7611,0.0,0.0,1.6257,9.095,13.051,401.68,386.29,405.27,-8.7573
178.9876,2.7956,7.733,0.0,0.0,1.6283,8.4504,13.052,401.62,386.2,405.28,-8.7649
178.9886,2.9762,7.7549,0.0,0.0,1.6235,9.0589,13.048,401.56,386.11,405.3,-8.772
178.9896,2.8225,7.7532,0.0,0.0,1.6321,8.5299,13.048,401.51,386.02,405.32,-8.7781
178.9906,2.963,7.7368,0.0,0.0,1.6219,9.0155,13.044,401.45,385.93,405.34,-8.7844
178.9916,2.8399,7.7546,0.0,0.0,1.6274,8.5323,13.04,401.39,385.84,405.36,-8.7914
178.9926,2.9435,7.7435,0.0,0.0,1.6315,8.9818,13.051,401.33,385.76,405.37,-8.799
178.9936,2.8419,7.7501,0.0,0.0,1.619,8.5783,13.044,401.28,385.67,405.39,-8.8052
178.9946,2.9366,7.7425,0.0,0.0,1.6321,8.954,13.044,401.22,385.59,405.4,-8.8115
178.9956,2.8755,7.7434,0.0,0.0,1.6236,8.6867,13.051,401.16,385.51,405.42,-8.8192
178.9966,2.9032,7.7597,0.0,0.0,1.6277,8.8563,13.051,401.1,385.43,405.43,-8.8254
178.9976,2.8825,7.7302,0.0,0.0,1.6248,8.6989,13.05,401.05,385.35,405.45,-8.8333
178.9986,2.8951,7.7572,0.0,0.0,1.6246,8.7996,13.049,400.99,385.27,405.46,-8.8402
178.9996,2.9214,7.7473,0.0,0.0,1.6328,8.7788,13.036,400.93,385.19,405.48,-8.8463
179.0006,2.8503,7.7444,0.0,0.0,1.6201,8.733,13.048,400.88,385.1,405.49,-8.8527
179.0016,2.9236,7.7478,0.0,0.0,1.6301,8.8331,13.048,400.82,385.02,405.51,-8.8603
179.0026,2.8429,7.7456,0.0,0.0,1.6294,8.6764,13.048,400.77,384.93,405.51,-8.8659
179.0036,2.9377,7.7549,0.0,0.0,1.6225,8.8947,13.05,400.72,384.83,405.51,-8.8734
179.0046,2.8412,7.7361,0.0,0.0,1.6299,8.6331,13.05,400.67,384.74,405.52,-8.8797
179.0056,2.9507,7.7536,0.0,0.0,1.624,8.92,13.044,400.63,384.64,405.52,-8.8858
179.0066,2.833,7.7545,0.0,0.0,1.6318,8.5942,13.046,400.58,384.54,405.52,-8.8929
179.0076,2.977,7.7341,0.0,0.0,1.6217,8.984,13.051,400.53,384.45,405.53,-8.9006
179.0086,2.8074,7.759,0.0,0.0,1.6288,8.5482,13.046,400.48,384.35,405.53,-8.906
179.0096,2.9718,7.7436,0.0,0.0,1.6319,8.9975,13.045,400.43,384.25,405.53,-8.9117
179.0106,2.7883,7.7505,0.0,0.0,1.6203,8.5275,13.051,400.38,384.16,405.54,-8.9186
179.0116,3.011,7.7444,0.0,0.0,1.6316,9.1023,13.041,400.34,384.06,405.54,-8.9269
179.0126,2.7753,7.7439,0.0,0.0,1.6255,8.4841,13.05,400.29,383.96,405.54,-8.9333
179.0136,3.0179,7.7595,0.0,0.0,1.6274,9.1074,13.046,400.25,383.87,405.54,-8.9386
179.0146,2.7674,7.7356,0.0,0.0,1.6272,8.4431,13.048,400.2,383.77,405.54,-8.947
179.0156,3.0314,7.7557,0.0,0.0,1.624,9.1435,13.048,400.16,383.67,405.54,-8.9532
179.0166,2.7597,7.7509,0.0,0.0,1.6335,8.4222,13.042,400.11,383.58,405.54,-8.9617
179.0176,3.0648,7.7423,0.0,0.0,1.6194,9.2356,13.044,400.07,383.48,405.54,-8.9672
179.0186,2.7522,7.7566,0.0,0.0,1.6325,8.3606,13.046,400.02,383.38,405.54,-8.9749
179.0196,3.0534,7.7405,0.0,0.0,1.6278,9.2514,13.051,399.97,383.29,405.54,-8.9827
179.0206,2.7318,7.7587,0.0,0.0,1.624,8.3145,13.048,399.93,383.19,405.54,-8.9881
179.0216,3.0613,7.7398,0.0,0.0,1.6312,9.2949,13.046,399.88,383.09,405.54,-8.9966
179.0226,2.7448,7.7517,0.0,0.0,1.6245,8.3326,13.05,399.84,383.04,405.55,-9.0014
179.0236,3.0735,7.7586,0.0,0.0,1.6319,9.2927,13.046,399.79,382.98,405.56,-9.0077
179.0246,2.731,7.7368,0.0,0.0,1.6243,8.2938,13.046,399.75,382.93,405.57,-9.0153
179.0256,3.0765,7.7576,0.0,0.0,1.6264,9.3797,13.044,399.7,382.87,405.59,-9.0215
179.0266,2.7454,7.746,0.0,0.0,1.6334,8.3683,13.046,399.66,382.82,405.6,-9.0299
179.0276,3.0865,7.7499,0.0,0.0,1.6208,9.3183,13.04,399.61,382.76,405.61,-9.0355
179.0286,2.7295,7.748,0.0,0.0,1.6325,8.2679,13.046,399.57,382.71,405.62,-9.0432
179.0296,3.0756,7.7431,0.0,0.0,1.6252,9.3488,13.046,399.52,382.66,405.63,-9.0508
179.0306,2.7368,7.7624,0.0,0.0,1.6281,8.3042,13.042,399.48,382.6,405.65,-9.0585
179.0316,3.0829,7.7366,0.0,0.0,1.6287,9.3672,13.05,399.43,382.55,405.66,-9.0633
179.0326,2.7427,7.7548,0.0,0.0,1.6235,8.2992,13.046,399.38,382.48,405.66,-9.0711
179.0336,3.0889,7.7544,0.0,0.0,1.634,9.3693,13.05,399.33,382.4,405.66,-9.0772
179.0346,2.7427,7.7444,0.0,0.0,1.6224,8.3063,13.048,399.28,382.33,405.66,-9.0849
179.0356,3.0891,7.7523,0.0,0.0,1.6291,9.3876,13.042,399.23,382.26,405.66,-9.0897
179.0366,2.7442,7.7431,0.0,0.0,1.6303,8.3604,13.044,399.18,382.19,405.66,-9.0959
179.0376,3.0762,7.7608,0.0,0.0,1.6238,9.3492,13.042,399.13,382.11,405.66,-9.1052
179.0386,2.7696,7.7353,0.0,0.0,1.6295,8.3968,13.046,399.08,382.04,405.66,-9.1084
179.0396,3.0651,7.7526,0.0,0.0,1.6257,9.3697,13.048,399.02,381.97,405.66,-9.1176
179.0406,2.7764,7.7591,0.0,0.0,1.6309,8.3968,13.051,398.97,381.9,405.66,-9.1238
179.0416,3.0639,7.7348,0.0,0.0,1.6248,9.3361,13.051,398.92,381.82,405.66,-9.13
179.0426,2.7894,7.7598,0.0,0.0,1.627,8.4557,13.051,398.87,381.73,405.65,-9.1378
179.0436,3.0568,7.7466,0.0,0.0,1.6332,9.2973,13.05,398.81,381.63,405.64,-9.144
179.0446,2.7953,7.7492,0.0,0.0,1.6206,8.4374,13.046,398.76,381.54,405.63,-9.1517
179.0456,3.0628,7.7507,0.0,0.0,1.6328,9.2998,13.046,398.71,381.44,405.62,-9.1565
179.0466,2.7967,7.7414,0.0,0.0,1.6265,8.4761,13.048,398.65,381.34,405.62,-9.1626
179.0476,3.0247,7.7667,0.0,0.0,1.6292,9.2386,13.048,398.6,381.25,405.61,-9.1703
179.0486,2.8283,7.7328,0.0,0.0,1.6274,8.5351,13.046,398.54,381.15,405.6,-9.176
179.0496,3.0112,7.7585,0.0,0.0,1.6245,9.1797,13.05,398.49,381.05,405.59,-9.1849
179.0506,2.8226,7.7543,0.0,0.0,1.6341,8.5302,13.044,398.43,380.96,405.58,-9.1897
179.0516,3.0094,7.738,0.0,0.0,1.6211,9.1431,13.048,398.38,380.86,405.57,-9.1975
179.0526,2.8421,7.7574,0.0,0.0,1.6307,8.5941,13.046,398.33,380.78,405.57,-9.2051
179.0536,2.9891,7.7449,0.0,0.0,1.6316,9.0663,13.045,398.28,380.71,405.57,-9.2111
179.0546,2.8616,7.7541,0.0,0.0,1.6214,8.6172,13.047,398.24,380.63,405.57,-9.219
179.0556,2.9692,7.7434,0.0,0.0,1.6326,9.0204,13.049,398.19,380.56,405.57,-9.2245
179.0566,2.8569,7.7479,0.0,0.0,1.6251,8.6401,13.042,398.14,380.48,405.57,-9.2315
179.0576,2.9574,7.761,0.0,0.0,1.6301,9.0205,13.052,398.09,380.4,405.57,-9.2392
179.0586,2.8962,7.733,0.0,0.0,1.625,8.7557,13.05,398.04,380.33,405.57,-9.2426
179.0596,2.937,7.7588,0.0,0.0,1.6256,8.9564,13.05,397.99,380.25,405.57,-9.2518
179.0606,2.91,7.7481,0.0,0.0,1.6335,8.8101,13.05,397.95,380.18,405.57,-9.258
179.0616,2.9292,7.7488,0.0,0.0,1.6215,8.9178,13.042,397.9,380.1,405.57,-9.267
179.0626,2.9361,7.7503,0.0,0.0,1.6316,8.8739,13.043,397.86,380.03,405.57,-9.2734
179.0636,2.8897,7.7439,0.0,0.0,1.6284,8.8201,13.048,397.82,379.96,405.58,-9.2797
179.0646,2.9373,7.7618,0.0,0.0,1.6258,8.8921,13.046,397.78,379.89,405.59,-9.2867
179.0656,2.8901,7.7376,0.0,0.0,1.6301,8.8333,13.051,397.74,379.82,405.59,-9.2936
179.0666,2.9504,7.7527,0.0,0.0,1.6228,8.9176,13.05,397.7,379.75,405.6,-9.3014
179.0676,2.8573,7.7607,0.0,0.0,1.6349,8.7714,13.042,397.66,379.68,405.6,-9.3074
179.0686,2.9693,7.7353,0.0,0.0,1.6211,8.9381,13.048,397.62,379.61,405.61,-9.3152
179.0696,2.8425,7.7593,0.0,0.0,1.63,8.6715,13.046,397.58,379.55,405.62,-9.3214
179.0706,2.9839,7.742,0.0,0.0,1.6311,9.0046,13.042,397.55,379.48,405.62,-9.329
179.0716,2.834,7.7573,0.0,0.0,1.6231,8.6328,13.04,397.51,379.41,405.63,-9.3339
179.0726,2.9977,7.7386,0.0,0.0,1.6299,9.0482,13.05,397.47,379.33,405.63,-9.3428
179.0736,2.8091,7.7481,0.0,0.0,1.6258,8.5867,13.044,397.43,379.26,405.64,-9.3494
179.0746,3.0053,7.7615,0.0,0.0,1.6296,9.0894,13.046,397.39,379.19,405.65,-9.3542
179.0756,2.807,7.7324,0.0,0.0,1.6255,8.5302,13.05,397.35,379.12,405.65,-9.3625
179.0766,3.026,7.7572,0.0,0.0,1.6247,9.1846,13.054,397.31,379.04,405.66,-9.3687
179.0776,2.7929,7.7512,0.0,0.0,1.6353,8.4841,13.05,397.27,378.97,405.66,-9.3771
179.0786,3.0333,7.7436,0.0,0.0,1.6196,9.2078,13.049,397.23,378.9,405.67,-9.3811
179.0796,2.8067,7.7531,0.0,0.0,1.632,8.5408,13.044,397.19,378.83,405.68,-9.3883
179.0806,3.0528,7.7441,0.0,0.0,1.6289,9.2283,13.038,397.15,378.75,405.68,-9.3956
179.0816,2.7917,7.7602,0.0,0.0,1.6244,8.4633,13.042,397.11,378.68,405.69,-9.4021
179.0826,3.0608,7.7375,0.0,0.0,1.6299,9.2925,13.042,397.07,378.62,405.69,-9.4084
179.0836,2.7858,7.7552,0.0,0.0,1.6245,8.4655,13.048,397.02,378.55,405.69,-9.4147
179.0846,3.0741,7.7557,0.0,0.0,1.6312,9.2997,13.048,396.97,378.49,405.69,-9.4221
179.0856,2.7784,7.7357,0.0,0.0,1.6229,8.4402,13.051,396.92,378.43,405.69,-9.4298
179.0866,3.0944,7.7596,0.0,0.0,1.6288,9.3795,13.046,396.87,378.36,405.69,-9.4361
179.0876,2.7721,7.7421,0.0,0.0,1.6316,8.4326,13.049,396.83,378.3,405.69,-9.4416
179.0886,3.0882,7.7519,0.0,0.0,1.6205,9.3595,13.047,396.78,378.24,405.69,-9.45
179.0896,2.7653,7.7466,0.0,0.0,1.6323,8.4097,13.044,396.73,378.17,405.69,-9.4563
179.0906,3.0951,7.7452,0.0,0.0,1.6254,9.3847,13.045,396.68,378.11,405.69,-9.4632
179.0916,2.7652,7.7611,0.0,0.0,1.6279,8.4117,13.046,396.63,378.05,405.69,-9.4694
179.0926,3.1032,7.7341,0.0,0.0,1.6271,9.4212,13.05,396.59,377.99,405.7,-9.4756
179.0936,2.7649,7.7586,0.0,0.0,1.625,8.4046,13.048,396.55,377.93,405.71,-9.4833
179.0946,3.1091,7.7501,0.0,0.0,1.6333,9.4286,13.046,396.51,377.87,405.72,-9.4881
179.0956,2.7708,7.7434,0.0,0.0,1.6213,8.4201,13.048,396.48,377.81,405.72,-9.4959
179.0966,3.1025,7.7557,0.0,0.0,1.6317,9.4285,13.048,396.44,377.76,405.73,-9.5021
179.0976,2.7827,7.7445,0.0,0.0,1.6307,8.4246,13.044,396.4,377.7,405.74,-9.5112
179.0986,3.1161,7.76,0.0,0.0,1.6232,9.4335,13.048,396.36,377.64,405.75,-9.5175
179.0996,2.7723,7.7406,0.0,0.0,1.6318,8.4561,13.042,396.32,377.59,405.76,-9.5244
179.1006,3.0965,7.7562,0.0,0.0,1.626,9.4108,13.044,396.28,377.53,405.77,-9.5314
179.1016,2.7835,7.7578,0.0,0.0,1.6311,8.4201,13.044,396.24,377.47,405.78,-9.5384
179.1026,3.1036,7.7376,0.0,0.0,1.6246,9.4362,13.05,396.19,377.41,405.78,-9.5446
179.1036,2.7897,7.7594,0.0,0.0,1.6279,8.445,13.05,396.14,377.36,405.78,-9.553
179.1046,3.0783,7.7466,0.0,0.0,1.6327,9.3796,13.048,396.1,377.3,405.78,-9.5577
179.1056,2.7967,7.7508,0.0,0.0,1.6213,8.4787,13.046,396.05,377.24,405.78,-9.5655
179.1066,3.0909,7.7509,0.0,0.0,1.6333,9.4135,13.042,396.0,377.18,405.78,-9.5731
179.1076,2.8147,7.7434,0.0,0.0,1.6263,8.481,13.047,395.95,377.13,405.78,-9.5797
179.1086,3.0637,7.7653,0.0,0.0,1.6288,9.3158,13.046,395.9,377.07,405.78,-9.585
179.1096,2.8159,7.7358,0.0,0.0,1.6283,8.5195,13.046,395.85,377.01,405.78,-9.5942
179.1106,3.0506,7.7587,0.0,0.0,1.6251,9.2976,13.05,395.81,376.95,405.78,-9.5997
179.1116,2.8295,7.7546,0.0,0.0,1.6349,8.5608,13.053,395.76,376.9,405.78,-9.606
179.1126,3.0381,7.7422,0.0,0.0,1.6219,9.2773,13.048,395.71,376.82,405.77,-9.6136
179.1136,2.8442,7.7562,0.0,0.0,1.6314,8.6353,13.046,395.67,376.75,405.75,-9.6191
179.1146,3.0321,7.7456,0.0,0.0,1.632,9.2702,13.046,395.62,376.68,405.74,-9.6269
179.1156,2.8555,7.7564,0.0,0.0,1.6228,8.6195,13.044,395.58,376.61,405.72,-9.6322
179.1166,3.0167,7.7436,0.0,0.0,1.6328,9.1641,13.04,395.53,376.53,405.71,-9.6414
179.1176,2.8641,7.7505,0.0,0.0,1.625,8.6809,13.05,395.49,376.46,405.69,-9.6476
179.1186,3.0102,7.7619,0.0,0.0,1.6313,9.1593,13.042,395.44,376.39,405.68,-9.6552
180.1191,2.791,7.7567,0.0,0.0,1.6312,8.4634,13.046,358.39,323.15,279.59,-9.7727
182.1191,2.6932,7.777,0.0,0.0,1.641,8.1752,13.047,257.7,153.89,157.05,-9.7726
184.1191,2.6724,7.8218,0.0,0.0,1.6631,8.1054,13.047,73.49,65.25,40.143,-9.7727
185.9921,2.563,7.8455,0.0,0.0,1.6751,7.7732,13.047,47.535,46.082,31.691,-9.7732
187.9921,2.5679,7.8615,0.0,0.0,1.683,7.7917,13.047,38.062,37.535,28.422,-9.7725
189.9921,2.4926,7.876,0.0,0.0,1.6905,7.5599,13.098,36.689,39.291,31.095,-9.7402
190.9921,2.4858,7.8794,0.0,0.0,1.6921,7.5419,13.072,39.706,42.127,35.501,-9.6689