File: examples/dan-msc-case-studies/CS4/data/01 raw data/hyde_test_027.csv
Time(sec),Force(kN),Jaw(mm),PowAngle(deg),PTemp,Strain,Stress(MPa),TC1(C),TC2(C),TC3(C)
0.0,1.5326,-0.0023562,0.0,0.00020626,-0.00019704,4.624,21.466,8000,8000
2.0,1.4007,-0.0019893,0.0,5.0588,-0.00022712,4.2486,21.345,8000,8000
4.0,1.3511,-0.0020589,0.0,11.057,-0.00023519,4.0972,21.156,8000,8000
6.0,1.3284,-0.0020363,0.0,17.057,-0.00023185,4.0296,21.066,8000,8000
8.0,1.322,-0.001659,15.281,23.057,-0.00018329,4.0088,21.822,8000,8000
9.3066,1.313,-0.0035495,18.004,26.978,-0.00038457,3.9826,26.044,8000,8000
11.3066,1.3253,-0.004694,20.533,32.977,-0.00050967,4.0205,32.382,8000,8000
13.3066,1.3241,-0.0065887,21.922,38.977,-0.00071538,4.017,38.531,8000,8000
14.4024,1.319,-0.0080821,22.259,42.264,-0.00088484,4.001,41.967,8000,8000
16.4024,1.3292,-0.010804,23.096,48.264,-0.0011807,4.0324,48.076,8000,8000
18.4024,1.3341,-0.013999,24.144,54.264,-0.0015345,4.0476,54.04,8000,8000
20.4024,1.3328,-0.016943,23.707,60.264,-0.0018545,4.0433,60.198,8000,8000
22.4024,1.3383,-0.020297,24.009,66.264,-0.0022188,4.0599,66.255,8000,8000
24.4024,1.3539,-0.023712,25.26,72.264,-0.0025958,4.1083,72.147,8000,8000
26.4024,1.3523,-0.026663,25.57,78.264,-0.002916,4.1027,78.17,8000,8000
28.4024,1.359,-0.030043,25.691,84.264,-0.0032785,4.1226,84.215,8000,8000
30.4024,1.3619,-0.033604,25.86,90.264,-0.0036722,4.1322,90.257,8000,8000
32.4024,1.3662,-0.037194,26.302,96.264,-0.0040637,4.1447,96.22,8000,8000
34.4024,1.3709,-0.041132,25.768,102.26,-0.0044798,4.1568,102.34,8000,8000
36.4024,1.3942,-0.046144,26.281,108.26,-0.0050227,4.225,108.34,8000,8000
38.4024,1.4034,-0.05193,27.98,114.26,-0.0056543,4.2599,114.08,8000,8000
40.4024,1.3972,-0.054237,27.719,120.26,-0.0059436,4.2375,120.19,8000,8000
41.9194,1.407,-0.053899,27.861,124.82,-0.0058944,4.2675,124.68,8000,8000
43.9194,1.404,-0.057653,28.656,130.82,-0.0062897,4.2618,130.66,8000,8000
45.186,1.3975,-0.059657,27.761,134.61,-0.006498,4.2384,134.67,8000,8000
47.186,1.4065,-0.064378,28.569,140.61,-0.0070116,4.2684,140.58,8000,8000
49.186,1.4058,-0.068257,28.198,146.61,-0.0074289,4.2638,146.64,8000,8000
51.186,1.4086,-0.072138,28.614,152.61,-0.0078544,4.2733,152.62,8000,8000
53.186,1.4117,-0.076843,29.284,158.61,-0.0083557,4.2788,158.48,8000,8000
55.186,1.42,-0.081425,27.747,164.61,-0.0088809,4.307,164.84,8000,8000
57.186,1.4267,-0.083123,28.46,170.61,-0.009042,4.3269,170.82,8000,8000
59.186,1.4297,-0.087506,29.197,176.61,-0.0095202,4.3367,176.68,8000,8000
61.186,1.414,-0.090226,27.223,182.61,-0.0098172,4.2895,183.07,8000,8000
63.186,1.4493,-0.09803,29.831,188.61,-0.010642,4.3952,188.6,8000,8000
65.186,1.4524,-0.099286,29.991,194.61,-0.010812,4.4069,194.62,8000,8000
67.186,1.4493,-0.10241,29.809,200.61,-0.01114,4.3971,200.68,8000,8000
69.186,1.4238,-0.10523,29.145,206.61,-0.011449,4.32,206.67,8000,8000
71.186,1.4366,-0.10887,30.045,212.61,-0.011838,4.3582,212.56,8000,8000
73.186,1.4572,-0.11524,29.709,218.61,-0.012552,4.421,218.69,8000,8000
74.5458,1.4371,-0.1135,29.481,222.7,-0.012332,4.3603,222.74,8000,8000
75.8845,1.4516,-0.11639,30.798,226.71,-0.012658,4.4048,226.54,8000,8000
77.8845,1.4488,-0.12067,30.259,232.71,-0.013118,4.3941,232.73,8000,8000
79.8845,1.466,-0.12788,30.549,238.71,-0.013876,4.447,238.69,8000,8000
81.8845,1.461,-0.12838,30.842,244.71,-0.013945,4.4321,244.7,8000,8000
83.8845,1.4597,-0.13254,31.104,250.71,-0.01439,4.428,250.66,8000,8000
85.8845,1.4578,-0.1374,31.477,256.71,-0.014913,4.4227,256.65,8000,8000
87.8845,1.4734,-0.14518,31.475,262.71,-0.015738,4.4686,262.7,8000,8000
89.8845,1.4714,-0.14586,31.928,268.71,-0.015832,4.4663,268.63,8000,8000
91.8845,1.465,-0.15055,31.857,274.71,-0.016328,4.4445,274.73,8000,8000
93.8845,1.4658,-0.15471,31.825,280.71,-0.016782,4.4475,280.77,8000,8000
95.8845,1.4628,-0.15943,31.974,286.71,-0.01728,4.435,286.71,8000,8000
97.8845,1.4771,-0.16654,32.142,292.71,-0.01808,4.4807,292.73,8000,8000
99.8845,1.477,-0.16614,32.682,298.71,-0.018021,4.4803,298.64,8000,8000
101.8845,0.61602,-0.17042,30.929,300.0,-0.018483,1.8694,300.2,8000,8000
103.8845,0.60756,-0.17103,30.489,300.0,-0.018552,1.8423,300.15,8000,8000
105.8845,0.60929,-0.17223,29.777,300.0,-0.018673,1.8463,300.11,8000,8000
107.0845,0.61902,-0.17464,29.834,300.0,-0.018942,1.8784,300.08,8000,8000
109.0845,0.6174,-0.17162,29.884,300.0,-0.018618,1.8729,300.04,8000,8000
111.0845,0.62166,-0.17248,29.956,300.0,-0.018707,1.8861,300.03,8000,8000
113.0845,0.61685,-0.17319,29.592,300.0,-0.018783,1.8719,300.08,8000,8000
115.0845,0.62195,-0.17454,29.754,300.0,-0.018916,1.8848,300.0,8000,8000
116.8778,0.62753,-0.17749,29.982,300.0,-0.019252,1.9036,299.95,8000,8000
118.8778,0.62923,-0.17475,29.315,300.0,-0.01894,1.9093,300.08,8000,8000
120.8778,0.62039,-0.17519,29.489,300.0,-0.018984,1.8833,300.01,8000,8000
122.8778,0.62317,-0.17546,29.393,300.0,-0.019019,1.8909,299.99,8000,8000
124.8778,0.62156,-0.17606,29.594,300.0,-0.019079,1.8865,299.99,8000,8000
126.8778,0.63135,-0.17892,29.51,300.0,-0.019413,1.9142,300.01,8000,8000
128.8778,0.63453,-0.17604,29.449,300.0,-0.019089,1.9259,300.02,8000,8000
130.8778,0.63277,-0.17664,29.493,300.0,-0.019153,1.919,300.0,8000,8000
132.8778,0.62603,-0.17712,29.422,300.0,-0.019201,1.8995,300.01,8000,8000
134.8778,0.62932,-0.18023,29.425,300.0,-0.019543,1.9099,300.01,8000,8000
136.8778,0.63828,-0.17718,29.148,300.0,-0.019201,1.9354,300.03,8000,8000
138.7148,0.6352,-0.17795,29.383,300.0,-0.01928,1.9268,300.0,8000,8000
140.7148,0.63204,-0.17815,28.993,300.0,-0.019306,1.9165,300.05,8000,8000
142.7148,0.64063,-0.18123,28.813,300.0,-0.019635,1.9437,300.07,8000,8000
144.7148,0.64277,-0.17842,29.516,300.0,-0.019332,1.9504,299.97,8000,8000
145.2861,0.83534,-0.00045895,0.0,236.25,0.00013229,2.5382,299.96,8000,8000
145.2881,0.79782,0.0017638,0.0,0.44961,-0.00027696,2.4073,299.94,8000,8000
145.2901,0.7998,0.0025908,0.0,0.0008423,0.00024918,2.4097,299.92,8000,8000
145.2921,0.80006,0.0027365,0.0,1.5862e-06,2.3194e-07,2.4071,299.9,8000,8000
145.2941,0.80342,-0.0010886,0.0,2.9715e-09,0.00042434,2.41,299.9,8000,8000
145.2961,0.79014,0.0014522,0.0,5.5956e-12,0.00039178,2.334,299.93,8000,8000
145.2981,0.82512,0.001792,0.0,1.0536e-14,-0.0001598,2.4923,299.96,8000,8000
145.3001,0.8201,0.002831,0.0,1.9739e-17,0.00017813,2.4757,299.99,8000,8000
145.3021,0.82294,0.0026943,0.0,3.7168e-20,-5.7842e-05,2.4742,300.02,8000,8000
145.3041,0.82522,-1.2643e-05,0.0,6.963099999999999e-23,0.00061424,2.4783,300.04,8000,8000
145.3061,0.83625,0.0021373,0.0,1.3111e-25,0.000599,2.5268,300.04,8000,8000
145.3081,0.83663,-0.00066672,0.0,2.4685999999999997e-28,-0.00013157,2.5025,300.03,8000,8000
145.3101,0.84436,0.0021737,0.0,4.6248e-31,0.00010194,2.5298,300.02,8000,8000
145.3121,0.85176,0.0023458,0.0,8.7076e-34,-0.00028595,2.559,300.02,8000,8000
145.3141,0.85564,-0.0011222,0.0,1.6394e-36,0.00041115,2.567,300.02,8000,8000
145.3161,0.86021,0.0021323,0.0,3.0714e-39,0.00056522,2.5719,300.04,8000,8000
145.3181,0.86281,0.0001587,0.0,5.7818e-42,7.6621e-05,2.5884,300.06,8000,8000
145.3201,0.87103,0.0018203,0.0,9.8091e-45,2.3733e-05,2.6275,300.08,8000,8000
145.3221,0.87432,0.00321,0.0,0.0,-0.00034358,2.6129,300.09,8000,8000
145.3241,0.87434,-0.00097487,0.0,0.0,0.00023073,2.6509,300.1,8000,8000
145.3261,0.88474,0.0026805,0.0,0.0,0.00050815,2.6813,300.08,8000,8000
145.3281,0.88615,-0.00038072,0.0,0.0,0.00026133,2.6884,300.06,8000,8000
145.3301,0.88353,0.0025399,0.0,0.0,0.00014691,2.6739,300.04,8000,8000
145.3321,0.89105,0.0020176,0.0,0.0,-0.00035173,2.7167,300.03,8000,8000
145.3341,0.89008,8.4176e-05,0.0,0.0,0.00016074,2.7104,300.06,8000,8000
145.3361,0.88983,0.0028142,0.0,0.0,0.00037028,2.7048,300.19,8000,8000
145.3381,0.88319,0.0010924,0.0,0.0,0.00057987,2.6738,300.33,8000,8000
145.3401,0.88303,0.0012081,0.0,0.0,0.00014282,2.6919,300.46,8000,8000
145.3421,0.88222,0.00056999,0.0,0.0,-0.00040245,2.6672,300.6,8000,8000
145.3441,0.88428,0.0020465,0.0,0.0,0.00017216,2.6905,300.98,8000,8000
145.3461,0.8862,0.0025618,0.0,0.0,0.0001408,2.7193,301.84,8000,8000
145.3481,0.86206,-0.0029741,0.0,0.0,0.00018698,2.6341,302.7,8000,8000
145.3501,0.85113,0.0016578,0.0,0.0,0.00047842,2.6256,303.56,8000,8000
145.3521,9.6976,0.030299,0.0,0.0,0.0026914,28.3,304.42,8000,8000
145.35409,24.036,0.11586,0.0,0.0,0.012245,72.349,305.51,8000,8000
145.35609,37.652,0.18942,0.0,0.0,0.019933,113.09,307.04,8000,8000
145.35809,45.156,0.29231,0.0,0.0,0.032326,136.6,308.58,8000,8000
145.36009,47.746,0.43298,0.0,0.0,0.048041,144.76,310.11,8000,8000
145.36209,49.12,0.58901,0.0,0.0,0.065598,148.88,311.64,8000,8000
145.36409,49.758,0.74769,0.0,0.0,0.084185,150.83,313.07,8000,8000
145.36609,50.275,0.91414,0.0,0.0,0.1037,152.46,314.31,8000,8000
145.36809,50.635,1.0921,0.0,0.0,0.12645,153.56,315.55,8000,8000
145.37009,51.031,1.2949,0.0,0.0,0.15123,154.76,316.78,8000,8000
145.37209,51.444,1.4986,0.0,0.0,0.17669,155.98,318.02,8000,8000
145.37409,51.716,1.7148,0.0,0.0,0.20455,156.84,319.04,8000,8000
145.37609,51.939,1.9151,0.0,0.0,0.23076,157.51,319.7,8000,8000
145.37809,52.136,2.0927,0.0,0.0,0.2564,158.09,320.35,8000,8000
145.38009,52.269,2.2583,0.0,0.0,0.27943,158.5,321.01,8000,8000
145.38209,52.385,2.4058,0.0,0.0,0.3004,158.88,321.66,8000,8000
145.38409,52.494,2.5405,0.0,0.0,0.31947,159.2,322.26,8000,8000
145.38609,52.618,2.6672,0.0,0.0,0.33739,159.58,322.78,8000,8000
145.38809,52.794,2.7874,0.0,0.0,0.3568,160.11,323.29,8000,8000
145.39009,53.012,2.9082,0.0,0.0,0.37509,160.79,323.8,8000,8000
145.39209,53.248,3.032,0.0,0.0,0.39466,161.46,324.31,8000,8000
145.39409,53.5,3.1646,0.0,0.0,0.41485,162.26,324.78,8000,8000
145.39609,53.752,3.2978,0.0,0.0,0.43544,163.02,325.15,8000,8000
145.39809,53.996,3.4327,0.0,0.0,0.4586,163.78,325.53,8000,8000
145.40009,54.175,3.5672,0.0,0.0,0.48077,164.31,325.91,8000,8000
145.40209,54.338,3.695,0.0,0.0,0.50413,164.78,326.29,8000,8000
145.40409,54.477,3.8264,0.0,0.0,0.52642,165.24,325.91,8000,8000
145.40609,54.557,3.9512,0.0,0.0,0.54746,165.49,324.38,8000,8000
145.40809,54.643,4.0709,0.0,0.0,0.5696,165.73,322.85,8000,8000
145.41009,54.741,4.1878,0.0,0.0,0.59113,166.04,321.32,8000,8000
145.41209,54.817,4.2981,0.0,0.0,0.61371,166.26,319.79,8000,8000
145.41409,54.886,4.414,0.0,0.0,0.6357,166.49,317.88,8000,8000
145.41609,54.92,4.5214,0.0,0.0,0.65553,166.59,315.4,8000,8000
145.41809,54.96,4.6276,0.0,0.0,0.67694,166.71,312.92,8000,8000
145.42009,55.026,4.734,0.0,0.0,0.69818,166.9,310.44,8000,8000
145.42209,55.069,4.8335,0.0,0.0,0.72109,167.03,307.96,8000,8000
145.42409,55.123,4.9372,0.0,0.0,0.74292,167.19,306.88,8000,8000
145.42609,55.18,5.0369,0.0,0.0,0.76358,167.38,307.78,8000,8000
145.42809,55.209,5.1418,0.0,0.0,0.78628,167.45,308.69,8000,8000
145.43009,55.232,5.2403,0.0,0.0,0.8076,167.53,309.59,8000,8000
145.43209,55.296,5.3284,0.0,0.0,0.83048,167.72,310.49,8000,8000
145.43409,55.374,5.425,0.0,0.0,0.85317,167.96,311.75,8000,8000
145.43609,55.432,5.5183,0.0,0.0,0.87524,168.13,313.52,8000,8000
145.43809,55.515,5.6155,0.0,0.0,0.89782,168.39,315.29,8000,8000
145.44009,55.6,5.704,0.0,0.0,0.91871,168.66,317.05,8000,8000
145.44209,55.656,5.7851,0.0,0.0,0.94183,168.82,318.82,8000,8000
145.44409,55.743,5.8722,0.0,0.0,0.96477,169.09,320.09,8000,8000
145.44609,55.821,5.9584,0.0,0.0,0.9881,169.32,320.73,8000,8000
145.44809,55.97,6.0439,0.0,0.0,1.01,169.78,321.38,8000,8000
145.45009,56.134,6.1242,0.0,0.0,1.0304,170.28,322.02,8000,8000
145.45209,56.29,6.2023,0.0,0.0,1.0542,170.75,322.66,8000,8000
145.45409,56.388,6.278,0.0,0.0,1.0765,171.04,323.07,8000,8000
145.45609,56.525,6.3523,0.0,0.0,1.0999,171.45,323.2,8000,8000
145.45809,56.669,6.4312,0.0,0.0,1.1224,171.88,323.33,8000,8000
145.46009,56.883,6.5049,0.0,0.0,1.1425,172.51,323.46,8000,8000
145.46209,57.114,6.5781,0.0,0.0,1.1667,173.23,323.58,8000,8000
145.46409,57.353,6.6479,0.0,0.0,1.1888,173.95,323.03,8000,8000
145.46609,57.567,6.713,0.0,0.0,1.213,174.61,321.66,8000,8000
145.46809,57.784,6.7872,0.0,0.0,1.237,175.27,320.29,8000,8000
145.47009,58.035,6.8544,0.0,0.0,1.2571,176.02,318.92,8000,8000
145.47209,58.253,6.9209,0.0,0.0,1.2802,176.68,317.55,8000,8000
145.47409,58.513,6.9866,0.0,0.0,1.3031,177.46,316.82,8000,8000
145.47609,58.805,7.0448,0.0,0.0,1.3281,178.34,316.83,8000,8000
145.47809,59.126,7.109,0.0,0.0,1.3514,179.33,316.85,8000,8000
145.48009,59.419,7.1728,0.0,0.0,1.3733,180.2,316.86,8000,8000
145.48209,59.703,7.2355,0.0,0.0,1.3967,181.07,316.87,8000,8000
145.48409,60.051,7.2919,0.0,0.0,1.4177,182.13,316.68,8000,8000
145.48609,60.409,7.345,0.0,0.0,1.4435,183.21,316.27,8000,8000
145.48809,60.786,7.4031,0.0,0.0,1.4673,184.34,315.86,8000,8000
145.49009,61.192,7.4546,0.0,0.0,1.4876,185.56,315.45,8000,8000
145.49208,61.68,7.509,0.0,0.0,1.5093,187.04,315.04,8000,8000
145.49408,62.182,7.5633,0.0,0.0,1.5306,188.57,313.99,8000,8000
145.49608,62.649,7.6119,0.0,0.0,1.5567,189.97,312.25,8000,8000
145.49808,63.184,7.662,0.0,0.0,1.5808,191.59,310.51,8000,8000
145.50008,63.752,7.7123,0.0,0.0,1.604,193.31,308.77,8000,8000
145.50208,61.543,7.7319,0.0,0.0,1.6112,186.85,307.03,8000,8000
145.50408,59.784,7.7344,0.0,0.0,1.6097,181.5,305.83,8000,8000
145.50608,58.719,7.7371,0.0,0.0,1.6144,178.2,305.18,8000,8000
145.50808,57.849,7.7406,0.0,0.0,1.6168,175.53,304.53,8000,8000
145.51008,57.259,7.7394,0.0,0.0,1.6183,173.74,303.87,8000,8000
145.51208,56.909,7.7469,0.0,0.0,1.6194,172.63,303.22,8000,8000
145.51408,56.632,7.7498,0.0,0.0,1.6172,171.81,302.57,8000,8000
145.51608,56.459,7.7526,0.0,0.0,1.6209,171.25,301.91,8000,8000
145.51808,56.356,7.7572,0.0,0.0,1.6229,170.95,301.25,8000,8000
145.52008,56.296,7.7531,0.0,0.0,1.6254,170.77,300.59,8000,8000
145.52208,56.223,7.7598,0.0,0.0,1.6268,170.55,299.94,8000,8000
145.52408,56.144,7.7637,0.0,0.0,1.6252,170.3,299.36,8000,8000
145.52608,56.034,7.7667,0.0,0.0,1.6269,169.97,298.87,8000,8000
145.52808,55.883,7.7689,0.0,0.0,1.6271,169.52,298.38,8000,8000
145.53008,55.706,7.7646,0.0,0.0,1.6307,169.0,297.89,8000,8000
145.53208,55.52,7.7709,0.0,0.0,1.6327,168.41,297.39,8000,8000
145.53408,55.324,7.7743,0.0,0.0,1.6311,167.8,297.13,8000,8000
145.53608,55.119,7.7745,0.0,0.0,1.6307,167.19,297.08,8000,8000
145.53808,54.915,7.7768,0.0,0.0,1.6304,166.58,297.03,8000,8000
145.54008,54.703,7.7726,0.0,0.0,1.6344,165.95,296.99,8000,8000
145.54208,54.485,7.7759,0.0,0.0,1.6352,165.27,296.94,8000,8000
145.54408,54.275,7.777,0.0,0.0,1.6342,164.64,296.82,8000,8000
145.54608,54.069,7.7814,0.0,0.0,1.6337,164.03,296.66,8000,8000
145.54808,53.871,7.7795,0.0,0.0,1.6307,163.42,296.49,8000,8000
145.55008,53.688,7.7776,0.0,0.0,1.6352,162.86,296.33,8000,8000
145.55208,53.504,7.7787,0.0,0.0,1.636,162.29,296.16,8000,8000
145.55408,53.329,7.7766,3.9312,0.0,1.6347,161.76,295.9,8000,8000
145.55608,53.144,7.781,11.207,0.0,1.6348,161.22,295.56,8000,8000
145.55808,52.977,7.7821,18.483,0.0,1.6325,160.7,295.22,8000,8000
145.56008,52.821,7.7807,25.759,0.0,1.636,160.24,294.89,8000,8000
145.56208,52.661,7.7824,33.035,0.0,1.6373,159.75,294.55,8000,8000
145.56408,52.512,7.7773,36.31,0.0,1.6361,159.29,295.16,8000,8000
145.56608,52.38,7.7832,36.31,0.0,1.6366,158.88,296.56,8000,8000
145.56808,52.242,7.7847,36.31,280.58,1.6338,158.49,297.95,8000,8000
145.57008,52.115,7.782,36.31,299.96,1.6349,158.1,299.35,8000,8000
145.57208,51.984,7.781,36.31,300.0,1.6351,157.72,300.74,8000,8000
145.57408,51.623,7.7806,37.616,300.0,1.639,156.63,300.03,8000,8000
145.57608,50.288,7.7856,39.949,300.0,1.6391,152.72,297.65,8000,8000
145.57808,47.84,7.7776,42.283,300.0,1.6315,145.37,295.28,8000,8000
145.58008,44.477,7.7729,44.617,300.0,1.6303,135.29,292.91,8000,8000
145.58208,39.209,7.769,46.95,300.0,1.6279,119.81,290.53,8000,8000
145.58408,11.999,7.7126,47.955,300.0,1.6074,38.696,291.22,8000,8000
145.58608,-0.39906,7.6035,47.955,300.0,1.5567,-1.3761,294.23,8000,8000
145.58808,-0.26033,7.6208,47.955,300.0,1.5589,-1.002,297.24,8000,8000
145.59008,2.7843,7.6849,47.955,300.0,1.5885,8.9244,300.24,8000,8000
145.59208,0.99018,7.6664,47.955,300.0,1.5784,2.5034,303.25,8000,8000
145.59408,0.094931,7.6725,42.392,300.0,1.587,0.32118,304.18,8000,8000
145.59608,0.87898,7.6714,32.782,300.0,1.5864,2.9247,303.59,8000,8000
145.59808,1.186,7.6826,23.173,300.0,1.589,3.5674,303.01,8000,8000
145.60008,0.82498,7.666,13.563,300.0,1.5798,2.38,302.43,8000,8000
145.60208,0.63939,7.6671,3.9536,300.0,1.5782,1.9451,301.84,8000,8000
145.60408,0.82304,7.6648,0.0,300.0,1.5829,2.5318,297.84,8000,8000
145.60608,0.85046,7.6436,0.0,300.0,1.5732,2.5979,291.45,8000,8000
145.60808,0.87093,7.6698,0.0,300.0,1.5846,2.6062,285.06,8000,8000
145.61008,0.8137,7.6664,0.0,300.0,1.5801,2.4667,278.67,8000,8000
145.61208,0.81402,7.6675,0.0,300.0,1.5783,2.4911,272.28,8000,8000
145.61408,0.80333,7.6649,7.7373,300.0,1.5815,2.4863,270.35,8000,8000
145.61608,0.90344,7.6478,20.673,300.0,1.5742,2.7438,271.4,8000,8000
145.61808,0.82803,7.67,33.61,300.0,1.5856,2.5185,272.46,8000,8000
145.62008,0.8317,7.6639,46.546,300.0,1.5803,2.4834,273.52,8000,8000
145.62208,0.85069,7.6638,59.482,300.0,1.5767,2.5655,274.57,8000,8000
145.62408,0.84535,7.661,64.556,300.0,1.5786,2.5502,280.41,8000,8000
145.62608,0.83948,7.6657,64.556,300.0,1.581,2.5425,289.33,8000,8000
145.62808,0.85698,7.6651,64.556,300.0,1.5836,2.5774,298.26,8000,8000
145.63007,0.89734,7.6669,64.556,300.0,1.5826,2.6928,307.18,8000,8000
145.63207,0.9107,7.6658,64.556,300.0,1.579,2.7462,316.11,8000,8000
145.63407,0.87471,7.6677,56.569,300.0,1.5808,2.6443,319.35,8000,8000
145.63607,0.89054,7.6657,43.632,300.0,1.5795,2.6848,319.08,8000,8000
145.63807,0.89245,7.6609,30.696,300.0,1.5817,2.6607,318.81,8000,8000
145.64007,0.89731,7.6651,17.76,300.0,1.5825,2.7092,318.54,8000,8000
145.64207,0.89602,7.666,4.8241,300.0,1.5799,2.6967,318.27,8000,8000
145.64407,0.99152,7.6623,0.0,300.0,1.5785,3.0329,313.23,8000,8000
145.64607,0.89485,7.6349,0.0,300.0,1.5646,2.6666,305.36,8000,8000
145.64807,0.9591,7.6679,0.0,300.0,1.5848,2.8749,297.5,8000,8000
145.65007,0.97277,7.6504,0.0,300.0,1.5761,2.9508,289.63,8000,8000
145.65207,0.98242,7.6571,0.0,300.0,1.5769,2.9451,281.76,8000,8000
145.65407,1.0177,7.6601,6.9698,300.0,1.576,2.9732,279.69,8000,8000
145.65607,0.98067,7.6323,17.916,300.0,1.5622,2.9886,280.92,8000,8000
145.65807,0.94798,7.6735,28.862,300.0,1.5876,2.8794,282.15,8000,8000
145.66007,0.94679,7.6536,39.808,300.0,1.5773,2.854,283.38,8000,8000
145.66207,0.96464,7.6517,50.754,300.0,1.5758,2.9376,284.61,8000,8000
145.66407,0.96881,7.6583,54.624,300.0,1.5769,2.9412,289.11,8000,8000
145.66607,0.98063,7.6605,54.624,300.0,1.575,2.9618,295.39,8000,8000
145.66807,0.9941,7.66,54.624,300.0,1.5795,3.0212,301.67,8000,8000
145.67007,0.98674,7.6616,54.624,300.0,1.5807,3.0222,307.95,8000,8000
145.67207,0.95951,7.6607,54.624,300.0,1.5804,2.9306,314.23,8000,8000
145.67407,0.93647,7.6636,47.444,300.0,1.5796,2.8471,315.8,8000,8000
145.67607,0.98252,7.6654,36.498,300.0,1.5775,2.9895,314.89,8000,8000
145.67807,1.0063,7.6636,25.552,300.0,1.5801,3.0446,313.98,8000,8000
145.68007,0.97041,7.6621,14.606,300.0,1.5797,2.9657,313.07,8000,8000
145.68207,0.9824,7.6598,3.6604,300.0,1.5813,2.9933,312.16,8000,8000
145.68407,1.2627,7.6579,0.0,300.0,1.5786,3.9005,307.73,8000,8000
145.68607,1.0179,7.6371,0.0,300.0,1.5648,3.105,301.54,8000,8000
145.68807,1.1272,7.6746,0.0,300.0,1.5841,3.4317,295.34,8000,8000
145.69007,1.14,7.6618,0.0,300.0,1.5786,3.4922,289.15,8000,8000
145.69207,1.1352,7.6603,0.0,300.0,1.5817,3.4883,282.95,8000,8000
145.69407,0.9191,7.6627,7.3035,300.0,1.5812,2.8123,281.59,8000,8000
145.69607,1.1686,7.6417,18.12,300.0,1.5681,3.663,282.55,8000,8000
145.69807,1.0793,7.6741,28.936,300.0,1.5842,3.3767,283.51,8000,8000
145.70007,1.0699,7.6594,39.752,300.0,1.5762,3.3132,284.46,8000,8000
145.70207,1.0499,7.655,50.568,300.0,1.5793,3.2729,285.42,8000,8000
145.70407,1.0323,7.66,53.976,300.0,1.5809,3.1984,290.23,8000,8000
145.70607,1.0121,7.6604,53.976,300.0,1.5782,3.1249,296.82,8000,8000
145.70807,1.0041,7.6642,53.976,300.0,1.5785,3.1207,303.4,8000,8000
145.71007,1.0035,7.6623,53.976,300.0,1.5766,3.1008,309.99,8000,8000
145.71207,0.99807,7.6583,53.976,300.0,1.5803,3.0821,316.57,8000,8000
145.71407,0.98342,7.6627,46.463,300.0,1.5821,3.0156,317.98,8000,8000
145.71607,0.98631,7.6624,35.647,300.0,1.5806,3.0213,317.1,8000,8000
145.71807,0.97981,7.6646,24.831,300.0,1.5792,2.9931,316.23,8000,8000
145.72007,0.98477,7.6634,14.015,300.0,1.5764,2.9911,315.36,8000,8000
145.72207,0.98637,7.6617,3.1992,300.0,1.5807,3.0183,314.49,8000,8000
145.72407,1.2121,7.6555,0.0,300.0,1.578,3.747,309.73,8000,8000
145.72607,0.91738,7.6315,0.0,300.0,1.5669,2.7833,303.35,8000,8000
145.72807,1.017,7.6685,0.0,300.0,1.5814,3.0707,296.96,8000,8000
145.73007,1.0297,7.6604,0.0,300.0,1.5752,3.1013,290.57,8000,8000
145.73207,1.0079,7.6604,0.0,300.0,1.5789,3.0427,284.19,8000,8000
145.73407,0.81774,7.6569,7.2701,300.0,1.5781,2.3845,283.14,8000,8000
145.73607,1.0763,7.6358,17.454,300.0,1.57,3.2594,284.25,8000,8000
145.73807,1.0482,7.6712,27.638,300.0,1.5846,3.1536,285.35,8000,8000
145.74007,1.0442,7.6566,37.822,300.0,1.574,3.1152,286.45,8000,8000
145.74207,1.0426,7.6581,48.006,300.0,1.577,3.0906,287.55,8000,8000
145.74407,1.0643,7.6596,50.823,300.0,1.5775,3.1721,292.42,8000,8000
145.74607,1.0938,7.6561,50.823,300.0,1.5795,3.2532,298.74,8000,8000
145.74807,1.1116,7.6627,50.823,300.0,1.5808,3.2894,305.06,8000,8000
145.75007,1.1162,7.6627,50.823,300.0,1.5777,3.3087,311.38,8000,8000
145.75207,1.1528,7.6628,50.823,300.0,1.5781,3.4265,317.7,8000,8000
145.75407,1.1567,7.6629,43.357,300.0,1.5779,3.4118,318.5,8000,8000
145.75607,1.1714,7.6588,33.173,300.0,1.5809,3.4865,317.29,8000,8000
145.75807,1.1943,7.6629,22.989,300.0,1.5819,3.5403,316.08,8000,8000
145.76007,1.2108,7.6622,12.804,300.0,1.5784,3.5975,314.87,8000,8000
145.76207,1.2162,7.6647,2.6201,300.0,1.5789,3.6207,313.65,8000,8000
145.76407,1.4649,7.659,0.0,300.0,1.5753,4.3889,308.67,8000,8000
145.76607,1.172,7.6358,0.0,300.0,1.5695,3.491,302.37,8000,8000
145.76806,1.2752,7.6693,0.0,300.0,1.5849,3.8187,296.08,8000,8000
145.77006,1.2933,7.6606,0.0,300.0,1.5791,3.883,289.78,8000,8000
145.77206,1.284,7.6632,0.0,300.0,1.5782,3.8637,283.49,8000,8000
145.77406,1.0546,7.6643,7.6045,300.0,1.5775,3.1746,282.85,8000,8000
145.77606,1.3361,7.643,17.712,300.0,1.572,4.0525,284.07,8000,8000
145.77806,1.2871,7.6727,27.819,300.0,1.5864,3.8888,285.3,8000,8000
145.78006,1.2929,7.6587,37.926,300.0,1.5791,3.8974,286.52,8000,8000
145.78206,1.2728,7.6642,48.033,300.0,1.5792,3.8542,287.74,8000,8000
145.78406,1.269,7.6632,50.438,300.0,1.5761,3.8688,293.15,8000,8000
145.78606,1.2754,7.6614,50.438,300.0,1.5795,3.8921,299.87,8000,8000
145.78806,1.2712,7.6649,50.438,300.0,1.5817,3.8775,306.58,8000,8000
145.79006,1.2591,7.6639,50.438,300.0,1.5824,3.8777,313.3,8000,8000
145.79206,1.2521,7.6661,50.438,300.0,1.5809,3.8682,320.01,8000,8000
145.79406,1.2457,7.6677,42.639,300.0,1.5789,3.8261,320.58,8000,8000
145.79606,1.2281,7.6675,32.531,300.0,1.581,3.7981,319.33,8000,8000
145.79806,1.2184,7.6669,22.424,300.0,1.5812,3.7622,318.08,8000,8000
145.80006,1.2078,7.6624,12.317,300.0,1.5822,3.74,316.83,8000,8000
145.80206,1.1842,7.6669,2.2099,300.0,1.5826,3.6756,315.58,8000,8000
145.80406,1.3971,7.6617,0.0,300.0,1.5769,4.3294,310.11,8000,8000
145.80606,1.0777,7.642,0.0,300.0,1.5686,3.3417,303.46,8000,8000
145.80806,1.1636,7.672,0.0,300.0,1.5829,3.5941,296.81,8000,8000
145.81006,1.1582,7.6596,0.0,300.0,1.5812,3.5913,290.15,8000,8000
145.81206,1.1371,7.6659,0.0,300.0,1.583,3.5057,283.5,8000,8000
145.81406,0.88266,7.663,7.8666,300.0,1.579,2.7282,283.13,8000,8000
145.81606,1.1496,7.6469,17.813,300.0,1.5709,3.5696,284.41,8000,8000
145.81806,1.0775,7.6759,27.759,300.0,1.583,3.3365,285.7,8000,8000
145.82006,1.0757,7.6575,37.706,300.0,1.5797,3.3036,286.99,8000,8000
145.82206,1.0492,7.6624,47.652,300.0,1.5814,3.2094,288.27,8000,8000
145.82406,1.062,7.6644,49.636,300.0,1.5804,3.2654,294.06,8000,8000
145.82606,1.0598,7.6646,49.636,300.0,1.579,3.2551,300.97,8000,8000
145.82806,1.0524,7.6686,49.636,300.0,1.5796,3.1974,307.87,8000,8000
145.83006,1.053,7.6648,49.636,300.0,1.5823,3.2069,314.78,8000,8000
145.83206,1.0591,7.6637,49.636,300.0,1.5818,3.2048,321.69,8000,8000
145.83406,1.0594,7.6634,41.578,300.0,1.5812,3.2232,322.05,8000,8000
145.83606,1.0557,7.6681,31.631,300.0,1.581,3.1891,320.87,8000,8000
145.83806,1.0669,7.6673,21.685,300.0,1.5783,3.2137,319.7,8000,8000
145.84006,1.0666,7.6625,11.738,300.0,1.5802,3.2153,318.53,8000,8000
145.84206,1.0848,7.6661,1.7917,300.0,1.5828,3.2665,317.35,8000,8000
145.84406,1.3349,7.658,0.0,300.0,1.5798,4.0283,311.52,8000,8000
145.84606,1.0298,7.6419,0.0,300.0,1.5695,3.0738,304.67,8000,8000
145.84806,1.1455,7.6731,0.0,300.0,1.582,3.4108,297.82,8000,8000
145.85006,1.1651,7.6638,0.0,300.0,1.5795,3.4743,290.96,8000,8000
145.85206,1.1663,7.6662,0.0,300.0,1.5809,3.4742,284.11,8000,8000
145.85406,0.93743,7.661,8.0426,300.0,1.582,2.7442,283.99,8000,8000
145.85606,1.2455,7.647,17.738,300.0,1.5733,3.7142,285.26,8000,8000
145.85806,1.2016,7.6741,27.434,300.0,1.5823,3.5635,286.53,8000,8000
145.86006,1.2306,7.6641,37.129,300.0,1.5794,3.6297,287.8,8000,8000
145.86206,1.2258,7.6639,46.825,300.0,1.5789,3.6461,289.06,8000,8000
145.86406,1.2507,7.6609,48.384,300.0,1.582,3.7309,294.98,8000,8000
145.86606,1.2898,7.6651,48.384,300.0,1.5825,3.8467,301.79,8000,8000
145.86806,1.2934,7.6656,48.384,300.0,1.5795,3.8401,308.6,8000,8000
145.87006,1.3084,7.6675,48.384,300.0,1.5799,3.8965,315.41,8000,8000
145.87206,1.3196,7.6687,48.384,300.0,1.5801,3.9279,322.22,8000,8000
145.87406,1.3322,7.6634,40.155,300.0,1.5831,4.0003,322.26,8000,8000
145.87606,1.3327,7.6653,30.46,300.0,1.5828,3.9964,321.09,8000,8000
145.87806,1.3512,7.6684,20.764,300.0,1.5817,4.069,319.92,8000,8000
145.88006,1.3662,7.6682,11.069,300.0,1.5804,4.1111,318.75,8000,8000
145.88206,1.3637,7.6683,1.3732,300.0,1.5791,4.0993,317.59,8000,8000
145.88406,1.5971,7.6592,0.0,300.0,1.5805,4.8011,311.59,8000,8000
145.88606,1.2827,7.6433,0.0,300.0,1.5726,3.8565,304.8,8000,8000
145.88806,1.3859,7.6707,0.0,300.0,1.5845,4.2181,298.01,8000,8000
145.89006,1.3908,7.6686,0.0,300.0,1.5809,4.2174,291.22,8000,8000
145.89206,1.3705,7.6723,0.0,300.0,1.5808,4.1742,284.42,8000,8000
145.89406,1.1317,7.6663,8.4159,300.0,1.5824,3.4637,284.52,8000,8000
145.89606,1.411,7.6498,18.111,300.0,1.5748,4.3417,285.66,8000,8000
145.89806,1.331,7.672,27.807,300.0,1.5861,4.0799,286.81,8000,8000
145.90006,1.3203,7.6646,37.502,300.0,1.5797,4.0566,287.95,8000,8000
145.90206,1.3035,7.669,47.198,300.0,1.5792,4.0163,289.1,8000,8000
145.90406,1.2987,7.6667,48.384,300.0,1.5812,4.0177,295.3,8000,8000
145.90605,1.2938,7.667,48.384,300.0,1.5817,4.0038,302.21,8000,8000
145.90805,1.2648,7.6658,48.384,300.0,1.584,3.9048,309.11,8000,8000
145.91005,1.2494,7.6697,48.384,300.0,1.5834,3.8708,316.02,8000,8000
145.91205,1.2423,7.6711,48.384,300.0,1.5804,3.8389,322.93,8000,8000
145.91405,1.2245,7.6682,39.781,300.0,1.5813,3.7903,322.75,8000,8000
145.91605,1.2149,7.6707,30.085,300.0,1.5825,3.7734,321.67,8000,8000
145.91805,1.1977,7.667,20.39,300.0,1.5844,3.7061,320.6,8000,8000
145.92005,1.1841,7.6678,10.694,300.0,1.5835,3.6668,319.52,8000,8000
145.92205,1.1731,7.6702,0.99868,300.0,1.5815,3.6427,318.45,8000,8000
145.92405,1.3876,7.6626,0.0,300.0,1.5784,4.3074,312.16,8000,8000
145.92605,1.0735,7.6472,0.0,300.0,1.5708,3.298,305.27,8000,8000
145.92805,1.1675,7.6703,0.0,300.0,1.5861,3.5921,298.38,8000,8000
145.93005,1.1672,7.6662,0.0,300.0,1.5832,3.5795,291.49,8000,8000
145.93205,1.1447,7.6692,0.0,300.0,1.5822,3.4904,284.6,8000,8000
145.93405,0.92924,7.6686,8.7124,300.0,1.5803,2.803,284.97,8000,8000
145.93605,1.1895,7.654,18.322,300.0,1.5726,3.6468,286.09,8000,8000
145.93805,1.1285,7.6716,27.931,300.0,1.5871,3.4428,287.21,8000,8000
145.94005,1.12,7.6659,37.541,300.0,1.5829,3.4131,288.33,8000,8000
145.94205,1.1111,7.6649,47.15,300.0,1.5816,3.371,289.45,8000,8000
145.94405,1.1197,7.6687,47.955,300.0,1.5813,3.397,296.05,8000,8000
145.94605,1.1355,7.669,47.955,300.0,1.5786,3.4325,303.15,8000,8000
145.94805,1.1413,7.6645,47.955,300.0,1.5816,3.425,310.25,8000,8000
145.95005,1.1469,7.668,47.955,300.0,1.5836,3.4544,317.35,8000,8000
145.95205,1.1607,7.6655,47.955,300.0,1.5827,3.4974,324.45,8000,8000
145.95405,1.1644,7.6691,39.058,300.0,1.5819,3.4744,323.92,8000,8000
145.95605,1.1812,7.6701,29.449,300.0,1.5793,3.5367,322.77,8000,8000
145.95805,1.1931,7.6686,19.839,300.0,1.5825,3.542,321.62,8000,8000
145.96005,1.2099,7.6685,10.229,300.0,1.5829,3.5924,320.47,8000,8000
145.96205,1.2299,7.6649,0.61979,300.0,1.5833,3.6563,319.32,8000,8000
145.96405,1.462,7.6622,0.0,300.0,1.58,4.3967,312.66,8000,8000
145.96605,1.1773,7.65,0.0,300.0,1.5709,3.4841,305.62,8000,8000
145.9676,1.1503,7.6744,0.0,300.0,1.5869,3.5768,300.17,8000,8000
147.9676,1.254,7.6298,47.763,283.18,1.5645,3.8039,274.79,8000,8000
149.6409,1.2315,7.6039,53.644,266.41,1.5529,3.7367,260.79,8000,8000
151.6409,1.163,7.6232,36.035,246.41,1.5615,3.5266,248.58,8000,8000
153.6409,1.1617,7.63,19.369,226.41,1.5648,3.5236,235.79,8000,8000
155.6409,1.1573,7.6641,0.12141,206.41,1.5803,3.509,217.81,8000,8000
156.7977,1.1611,7.6722,0.0032862,194.84,1.584,3.522,207.77,8000,8000
158.7977,1.172,7.683,6.1563e-06,174.84,1.5889,3.5558,188.29,8000,8000
160.7977,1.1795,7.6913,1.1533e-08,154.84,1.5927,3.5774,169.36,8000,8000
162.7977,1.1878,7.6983,2.1606e-11,134.84,1.5961,3.6037,155.52,8000,8000
164.7977,1.192,7.7043,4.0477e-14,114.84,1.5989,3.6158,141.93,8000,8000
166.7977,1.1968,7.7095,7.5831e-17,94.844,1.6013,3.63,130.32,8000,8000
168.7977,1.2006,7.7143,1.3818e-19,74.844,1.6036,3.6421,120.5,8000,8000
170.7977,1.2015,7.7187,2.5886999999999996e-22,54.844,1.6057,3.6435,111.83,8000,8000
172.7977,1.2068,7.7229,4.8497e-25,50.01,1.6077,3.6607,103.8,8000,8000
174.7977,1.2077,7.7264,9.0855e-28,50.0,1.6093,3.6629,96.668,8000,8000
176.7977,1.2131,7.7301,1.7021e-30,50.0,1.6111,3.6792,90.04,8000,8000
178.7977,1.2101,7.7336,3.1205e-33,50.0,1.6127,3.6707,84.204,8000,8000
180.7977,1.215,7.7366,5.8459e-36,50.0,1.6142,3.6862,78.833,8000,8000
182.1593,1.2152,7.7388,8.129e-38,50.0,1.6152,3.6867,75.592,8000,8000
184.1593,1.2185,7.7417,1.5230999999999998e-40,50.0,1.6166,3.6945,71.159,8000,8000
186.1593,1.2128,7.7444,1.285e-42,27.279,1.6179,3.678,67.65,8000,8000
187.5831,1.2075,7.7455,1.285e-42,0.31204,1.6184,3.663,71.091,8000,8000
189.5831,1.2233,7.7472,1.285e-42,0.00058458,1.6192,3.7107,70.849,8000,8000
191.5831,1.2625,7.7509,1.285e-42,1.0951e-06,1.621,3.8299,69.591,8000,8000
192.5831,1.2985,7.7513,1.285e-42,4.7401e-08,1.6211,3.9395,69.031,8000,8000