File: examples/dan-msc-case-studies/CS4/data/01 raw data/hyde_test_007.csv
Time(sec),Force(kN),Jaw(mm),PowAngle(deg),PTemp,Strain,Stress(MPa),TC1(C),TC2(C),TC3(C),TC4(C)
0.0,3.1621,-0.88447,0.0,0.0010421,-0.076987,3.7503,25.586,25.394,25.649,24.647
1.8,3.08,-0.0038851,0.0,5.2207,-0.00042377,3.6561,25.654,25.332,25.572,24.633
3.4473,3.0391,-0.0038126,0.0,10.163,-0.00042293,3.6062,25.626,25.279,25.532,24.603
5.2473,3.0041,-0.003913,0.0,15.563,-0.00042622,3.5653,25.595,25.258,25.537,24.61
7.0473,2.993,-0.0037444,0.0,20.963,-0.00039024,3.5512,25.657,25.365,25.542,24.622
8.8473,2.9729,-0.0036077,6.1423,26.363,-0.0003698,3.5292,25.637,25.331,25.496,24.658
10.6473,2.999,-0.0037744,35.057,31.763,-0.00039048,3.5588,28.54,38.406,26.0,25.817
12.4473,2.9877,-0.0044739,30.64,37.163,-0.00048928,3.5469,36.331,38.793,28.036,31.028
14.2473,2.9944,-0.0059697,33.049,42.563,-0.00066271,3.5541,41.771,44.112,31.18,35.853
16.0473,3.0003,-0.0066726,32.664,47.963,-0.00072426,3.5612,47.633,49.149,35.256,41.306
17.8473,3.0024,-0.0076756,32.849,53.363,-0.0008333,3.5638,53.149,54.329,39.49,46.458
19.6473,3.0116,-0.0085936,33.214,58.763,-0.00093724,3.5745,58.592,59.531,44.16,51.634
21.4473,3.0018,-0.011185,33.52,64.163,-0.001244,3.5628,64.043,64.471,48.956,56.833
23.2473,3.0075,-0.011651,34.544,69.563,-0.0012951,3.5688,69.334,69.746,53.726,62.042
25.0473,3.0119,-0.012957,34.013,74.963,-0.0014533,3.5733,74.944,74.648,58.618,67.345
26.8473,3.0237,-0.014001,35.346,80.363,-0.0015547,3.5873,80.156,79.805,63.523,72.561
28.6473,3.0283,-0.017569,35.299,85.763,-0.0019637,3.5934,85.663,84.811,68.569,78.055
30.4473,3.0312,-0.018941,35.768,91.163,-0.0020943,3.5962,91.029,90.218,73.598,83.41
32.2473,3.0366,-0.020787,36.099,96.563,-0.0022986,3.6038,96.452,95.308,78.871,88.827
34.0473,3.0499,-0.022727,36.178,101.96,-0.0024898,3.6201,101.84,100.57,84.116,94.222
35.7677,3.059,-0.024356,36.31,107.12,-0.002676,3.6312,107.08,105.56,89.265,99.444
37.4093,3.0649,-0.026239,36.765,112.05,-0.0028805,3.6379,111.99,110.28,94.165,104.48
39.2093,3.085,-0.030669,37.083,117.45,-0.0033616,3.6612,117.38,115.54,99.619,109.89
41.0093,3.089,-0.032818,37.159,122.85,-0.0036192,3.6661,122.76,120.78,105.05,115.32
42.8093,3.0939,-0.035491,37.758,128.25,-0.0039147,3.6721,128.14,125.94,110.41,120.68
44.6093,3.1033,-0.038226,37.835,133.65,-0.0042133,3.6823,133.56,131.23,115.76,126.1
46.4093,3.1095,-0.040732,37.936,139.05,-0.0044993,3.6895,138.97,136.47,121.16,131.49
48.2093,3.1173,-0.043344,38.115,144.45,-0.0047943,3.6981,144.4,141.72,126.48,136.87
50.0093,3.1274,-0.046028,38.531,149.85,-0.0051078,3.7107,149.75,146.89,131.89,142.21
51.8093,3.1277,-0.049472,38.546,155.25,-0.0055037,3.7112,155.2,152.23,137.13,147.54
53.6093,3.1265,-0.055487,38.578,160.65,-0.0061425,3.7107,160.64,157.44,142.43,152.88
55.4093,3.1345,-0.055894,39.154,166.05,-0.006173,3.7198,165.9,162.42,147.97,158.1
57.2093,3.1464,-0.059583,41.077,171.45,-0.0065904,3.7338,171.49,168.25,153.22,163.37
59.0093,3.1407,-0.063978,41.37,176.85,-0.0070625,3.7272,178.84,175.68,158.89,170.01
60.8093,3.1364,-0.066953,39.245,182.25,-0.0073855,3.7224,185.66,181.06,164.82,176.65
62.6093,3.1486,-0.070835,40.174,187.65,-0.0077992,3.7392,190.63,185.65,170.58,181.78
64.4093,3.1485,-0.075714,39.853,193.05,-0.00832,3.7374,196.14,190.79,176.19,187.0
66.2093,3.5135,-0.076656,39.962,198.45,-0.0084384,4.1702,201.47,196.01,181.5,192.21
67.8111,3.6815,-0.076887,39.924,203.25,-0.0085198,4.3686,206.27,200.38,186.07,196.6
69.6111,3.7387,-0.07846,39.924,208.65,-0.0087007,4.437,211.71,205.51,191.24,201.51
71.4111,3.7665,-0.080688,40.021,214.05,-0.008941,4.4689,217.08,210.58,196.43,206.44
73.2111,3.7777,-0.084632,40.389,219.45,-0.0093625,4.4828,222.4,215.71,201.6,211.57
75.0111,3.7841,-0.089708,42.506,224.85,-0.0099045,4.4897,227.92,221.41,206.94,216.83
76.8111,3.7949,-0.094172,41.245,230.25,-0.010372,4.503,235.03,228.35,212.73,223.5
78.6111,3.8039,-0.096374,41.12,235.65,-0.010598,4.5129,240.43,232.87,218.61,229.17
80.4111,3.8184,-0.09798,41.2,241.05,-0.010771,4.5305,245.84,238.27,224.25,234.45
82.2111,3.8417,-0.10096,41.293,246.45,-0.011135,4.5591,251.27,243.53,229.84,239.89
84.0111,3.8584,-0.10497,41.802,251.85,-0.011606,4.5778,256.57,248.88,235.38,245.29
85.8111,3.8752,-0.10876,41.803,257.25,-0.012035,4.5994,261.95,254.45,240.7,250.77
87.6111,3.8848,-0.11233,41.992,262.65,-0.012414,4.6105,267.4,260.02,246.04,256.34
89.4111,3.8988,-0.11592,42.167,268.05,-0.012803,4.6278,272.81,265.46,251.48,261.92
91.2111,3.9239,-0.12,41.993,273.45,-0.013212,4.6582,278.3,270.92,257.13,267.46
93.0111,3.95,-0.1253,42.374,278.85,-0.013754,4.6886,283.61,276.08,262.83,272.91
94.8111,3.9685,-0.131,41.88,284.25,-0.014363,4.71,289.13,281.2,268.5,278.28
96.6111,3.9918,-0.13661,42.154,289.65,-0.014993,4.7368,294.49,286.48,273.7,283.59
98.4111,4.0076,-0.14142,42.396,295.05,-0.015561,4.7557,299.83,291.58,279.32,288.93
100.2111,4.0188,-0.14458,42.504,300.46,-0.015924,4.7686,305.18,296.84,289.05,294.24
101.8416,4.038,-0.1463,42.014,305.35,-0.016135,4.7918,310.26,301.23,293.92,298.98
103.6416,4.0469,-0.14947,42.088,310.75,-0.01644,4.8025,315.62,305.63,298.89,303.84
105.4416,4.0532,-0.15411,42.425,316.15,-0.016929,4.8085,320.93,310.29,305.02,308.52
107.2416,4.064,-0.15946,42.396,321.55,-0.017512,4.8222,326.29,315.16,312.01,313.46
109.0416,4.0712,-0.16511,43.3,326.95,-0.018141,4.8292,331.45,319.98,316.63,318.47
110.8416,4.081,-0.17114,43.987,332.35,-0.018788,4.8419,336.84,326.44,322.67,324.28
112.6416,4.0825,-0.17644,43.302,337.75,-0.019366,4.8437,342.55,332.31,328.75,330.31
114.4416,4.0887,-0.18192,43.396,343.15,-0.019975,4.8527,347.95,337.27,334.95,335.79
116.2416,4.0886,-0.1873,43.166,348.55,-0.020575,4.8514,353.44,342.2,340.69,341.02
118.0416,4.0826,-0.18963,37.854,350.0,-0.020832,4.8457,356.27,344.0,345.23,345.13
119.8416,4.0972,-0.19289,38.562,350.0,-0.021177,4.8632,355.46,343.55,346.74,345.45
121.6416,4.0985,-0.19582,37.799,350.0,-0.021485,4.8653,355.27,343.47,347.25,345.55
123.4416,4.1035,-0.19859,36.705,350.0,-0.021775,4.8698,355.13,343.58,347.28,345.33
125.2416,4.1138,-0.19899,36.505,350.0,-0.021809,4.8828,354.32,342.98,346.85,344.84
127.0416,4.1257,-0.20521,40.209,350.0,-0.022522,4.8971,353.82,342.7,346.27,344.23
128.8416,4.12,-0.20802,39.71,350.0,-0.022796,4.89,362.06,351.67,349.14,348.05
130.6416,4.1194,-0.21063,38.439,350.0,-0.023083,4.8887,361.45,349.7,351.62,350.53
132.4416,4.1174,-0.21328,36.414,350.0,-0.023398,4.8852,361.44,350.07,352.43,350.84
134.0173,4.1185,-0.21555,36.185,350.0,-0.023648,4.8857,360.51,349.4,352.32,350.37
135.8173,4.116,-0.21657,36.862,350.0,-0.023777,4.8819,359.34,348.57,351.58,349.33
137.6173,4.1515,-0.22089,36.142,350.0,-0.024218,4.9254,359.5,348.84,351.2,349.16
139.4173,4.1589,-0.21934,31.787,350.0,-0.024022,4.9353,358.9,348.14,350.82,348.75
141.2173,4.1869,-0.22254,36.313,350.0,-0.024372,4.9686,357.69,347.48,349.7,347.5
143.0173,4.1908,-0.22402,34.794,350.0,-0.024549,4.9739,356.66,346.39,348.93,346.74
144.8173,4.2068,-0.22563,35.641,350.0,-0.02471,4.9931,354.88,344.87,347.63,345.28
146.6173,4.2209,-0.22854,35.239,350.0,-0.025029,5.0107,354.55,344.81,346.66,344.47
148.4173,4.2272,-0.22662,34.563,350.0,-0.024852,5.0177,353.8,344.21,345.77,343.66
150.2173,4.2444,-0.22987,34.939,350.0,-0.025193,5.0382,353.78,344.46,345.22,343.23
152.0173,4.3974,-0.23157,34.746,350.0,-0.025373,5.2199,353.8,344.55,344.92,343.06
153.8173,4.7872,-0.23152,34.884,350.0,-0.025354,5.6816,353.78,344.6,344.87,343.04
155.6173,5.2606,-0.22965,34.651,350.0,-0.025146,6.2432,353.84,344.82,344.85,343.0
157.4173,5.4076,-0.22839,34.922,350.0,-0.025012,6.417,353.79,344.99,344.83,343.05
159.2173,5.4556,-0.23146,34.667,350.0,-0.025368,6.4725,353.87,345.19,344.83,343.12
161.0173,5.4797,-0.22994,34.836,350.0,-0.025205,6.5015,353.82,345.36,344.86,343.15
161.9472,5.4262,0.0048542,22.176,0.0034305,0.00039723,6.4348,353.91,345.44,344.81,343.2
161.9481,5.4526,0.011064,19.058,1.829e-15,0.00063283,6.4699,353.91,345.45,344.81,343.2
161.949,5.4881,0.016318,15.939,9.7508e-28,0.0010756,6.5202,353.91,345.47,344.81,343.2
161.9499,5.4911,0.01672,12.821,5.1984999999999995e-40,0.00095848,6.4949,353.91,345.48,344.81,343.2
161.9508,5.5138,0.019671,9.7019,0.0,0.001221,6.5442,353.91,345.49,344.81,343.2
161.9517,5.4595,0.019045,6.5833,0.0,0.0013303,6.478,353.91,345.51,344.81,343.2
161.9526,5.5208,0.021487,3.4648,0.0,0.0016215,6.5524,353.91,345.52,344.81,343.2
161.9535,5.4461,0.021123,0.34619,0.0,0.0019979,6.4559,353.91,345.53,344.81,343.2
161.9544,5.5165,0.019997,0.0,0.0,0.0022237,6.5673,353.92,345.52,344.85,343.19
161.9553,5.4212,0.01729,0.0,0.0,0.0023077,6.448,353.92,345.51,344.89,343.19
161.9562,5.4046,0.017553,0.0,0.0,0.0026303,6.4161,353.92,345.5,344.94,343.18
161.9571,5.4865,0.015968,0.0,0.0,0.0024444,6.5051,353.92,345.48,344.99,343.18
161.958,5.5408,0.013996,0.0,0.0,0.0019366,6.5744,353.93,345.47,345.03,343.17
161.9589,5.4808,0.019327,0.0,0.0,0.0024773,6.5062,353.93,345.46,345.08,343.16
161.9598,5.4593,0.015315,0.0,0.0,0.0019643,6.4709,353.93,345.44,345.13,343.16
161.9607,5.502,0.016279,0.0,0.0,0.001517,6.5424,353.94,345.43,345.17,343.15
161.9616,5.4473,0.017631,0.0,0.0,0.0014884,6.478,353.94,345.41,345.22,343.15
161.9625,5.5146,0.018427,0.0,0.0,0.0016025,6.5513,353.94,345.4,345.27,343.14
161.9634,5.438,0.017036,0.0,0.0,0.0015726,6.4398,353.94,345.39,345.31,343.14
161.9643,5.5021,0.016691,0.0,0.0,0.0018,6.5503,353.94,345.38,345.3,343.14
161.9652,5.4339,0.012776,0.0,0.0,0.0018553,6.456,353.94,345.36,345.27,343.14
161.9661,5.5129,0.012207,0.0,0.0,0.0018847,6.5342,353.94,345.35,345.23,343.14
161.967,5.4542,0.008073,0.0,0.0,0.0017616,6.4792,353.94,345.34,345.2,343.14
161.9679,5.4861,0.0067841,0.0,0.0,0.0016591,6.5021,353.94,345.33,345.17,343.14
161.9688,5.4742,0.0046396,0.0,0.0,0.0014508,6.5032,353.94,345.32,345.13,343.14
161.9697,5.4655,0.00434,0.0,0.0,0.0011031,6.477,353.94,345.31,345.1,343.14
161.9706,5.4948,0.0053702,0.0,0.0,0.00085949,6.5273,353.94,345.3,345.07,343.14
161.9715,5.4462,0.0060296,0.0,0.0,0.00089023,6.462,353.94,345.29,345.04,343.14
161.9724,5.5068,0.0092748,0.0,0.0,0.00074999,6.5293,353.94,345.28,345.0,343.14
161.9733,5.433,0.011727,0.0,0.0,0.0005594,6.454,353.94,345.27,344.97,343.14
161.9742,5.52,0.01532,0.0,0.0,0.00085254,6.5433,353.94,345.27,344.96,343.14
161.9751,5.4328,0.016689,0.0,0.0,0.00091822,6.4479,353.94,345.28,344.95,343.14
161.976,5.4998,0.018973,0.0,0.0,0.0012546,6.5252,353.93,345.29,344.94,343.14
161.9769,5.4404,0.019833,0.0,0.0,0.0013851,6.464,353.92,345.3,344.94,343.14
161.9778,5.4737,0.021774,0.0,0.0,0.0019028,6.5001,353.92,345.31,344.93,343.14
161.9787,5.4609,0.019734,0.0,0.0,0.0019867,6.4829,353.91,345.32,344.93,343.14
161.9796,5.4534,0.018662,0.0,0.0,0.0022882,6.4799,353.91,345.34,344.92,343.14
161.9805,5.4936,0.017393,0.0,0.0,0.0024784,6.5132,353.9,345.35,344.92,343.14
161.9814,5.4398,0.013702,0.0,0.0,0.0022808,6.4549,353.9,345.36,344.91,343.14
161.9823,5.5017,0.013571,0.0,0.0,0.0021961,6.5423,353.89,345.37,344.91,343.14
161.9832,5.4386,0.013315,0.0,0.0,0.0019699,6.445,353.89,345.38,344.9,343.14
161.9841,5.5129,0.013071,0.0,0.0,0.0016954,6.5291,353.88,345.39,344.9,343.13
161.985,5.4398,0.013495,0.0,0.0,0.0015256,6.4559,353.88,345.4,344.89,343.13
161.9859,5.4996,0.017611,0.0,0.0,0.0015178,6.5181,353.88,345.41,344.89,343.12
161.9868,5.4529,0.016814,0.0,0.0,0.0013833,6.465,353.88,345.42,344.89,343.12
161.9877,5.4922,0.016891,0.0,0.0,0.001421,6.5082,353.88,345.43,344.89,343.11
161.9886,5.4727,0.017313,0.0,0.0,0.0017041,6.482,353.88,345.45,344.88,343.11
161.9895,5.4655,0.014691,0.0,0.0,0.0018553,6.478,353.88,345.46,344.88,343.1
161.9904,5.4761,0.012053,0.0,0.0,0.0017888,6.5192,353.88,345.47,344.88,343.09
161.9913,5.4387,0.011656,0.0,0.0,0.0019898,6.4478,353.88,345.48,344.87,343.09
161.9922,5.5011,0.0053411,0.0,0.0,0.0016397,6.5264,353.88,345.49,344.87,343.08
161.9931,5.4321,0.0052246,0.0,0.0,0.0014309,6.4408,353.88,345.5,344.87,343.08
161.994,5.5077,0.0065919,0.0,0.0,0.0013498,6.5414,353.89,345.51,344.87,343.07
161.9949,5.4336,0.0040901,0.0,0.0,0.00091567,6.4549,353.89,345.52,344.87,343.07
161.9958,5.4993,0.0052148,0.0,0.0,0.00079346,6.5181,353.89,345.53,344.87,343.07
161.9967,5.4474,0.0092484,0.0,0.0,0.00073963,6.472,353.89,345.53,344.87,343.07
161.9976,5.4798,0.011067,0.0,0.0,0.00056982,6.5011,353.9,345.54,344.87,343.07
161.9985,5.4738,0.013139,0.0,0.0,0.00071186,6.49,353.9,345.55,344.87,343.07
161.9994,5.4715,0.016614,0.0,0.0,0.00075715,6.478,353.9,345.56,344.87,343.07
162.0003,5.527,0.019592,0.0,0.0,0.0011147,6.5594,353.9,345.57,344.87,343.07
162.0012,5.4102,0.019879,0.0,0.0,0.0014615,6.4067,353.91,345.58,344.87,343.07
162.0021,5.5619,0.020111,0.0,0.0,0.0016863,6.6066,353.91,345.58,344.87,343.07
162.003,5.6839,0.020412,0.0,0.0,0.0019875,6.7165,353.91,345.59,344.87,343.07
162.0039,5.7096,0.021795,0.0,0.0,0.0027081,6.8045,353.92,345.59,344.87,343.08
162.0048,5.2706,0.014176,0.0,0.0,0.0018882,6.218,353.93,345.57,344.88,343.09
162.0057,5.8463,0.021161,0.0,0.0,0.0027869,6.9689,353.93,345.55,344.89,343.1
162.0066,5.1124,0.0097321,0.0,0.0,0.0016812,6.0542,353.94,345.52,344.9,343.11
162.0075,5.7923,0.018656,0.0,0.0,0.0024751,6.8728,353.95,345.5,344.9,343.12
162.0084,5.1451,0.0083574,0.0,0.0,0.0011129,6.1296,353.96,345.48,344.91,343.13
162.0093,5.6051,0.012839,0.0,0.0,0.001545,6.6624,353.97,345.46,344.92,343.14
162.0102,5.2523,0.011561,0.0,0.0,0.001001,6.244,353.97,345.44,344.93,343.16
162.0111,5.5045,0.012968,0.0,0.0,0.0010385,6.5133,353.98,345.41,344.94,343.17
162.012,5.3042,0.013159,0.0,0.0,0.0010968,6.3364,353.99,345.39,344.94,343.18
162.0129,5.4158,0.013898,0.0,0.0,0.0011427,6.4116,354.0,345.37,344.95,343.19
162.0138,5.5168,0.016146,0.0,0.0,0.0018199,6.5602,354.41,345.75,344.96,343.19
162.0147,5.3255,0.011836,0.0,0.0,0.0016068,6.2922,356.25,347.53,344.96,343.16
162.0156,5.5682,0.015442,0.0,0.0,0.002344,6.6045,358.09,349.31,344.96,343.12
162.0165,5.3635,0.0082306,0.0,0.0,0.0018462,6.3616,359.93,351.09,344.96,343.09
162.0174,5.5565,0.012329,0.0,0.0,0.0024123,6.6066,361.77,352.87,344.96,343.06
162.0183,5.352,0.0083628,0.0,0.0,0.0017699,6.3593,363.61,354.65,344.96,343.03
162.0192,5.5541,0.0088929,0.0,0.0,0.0015728,6.5865,365.45,356.42,344.96,342.99
162.0201,5.4124,0.01076,0.0,0.0,0.0014718,6.4198,367.29,358.2,344.96,342.96
162.021,48.989,0.12258,0.0,0.0,0.012499,56.595,369.13,359.98,344.96,342.93
162.0219,97.326,0.47343,0.0,0.0,0.051288,115.11,370.97,361.76,344.96,342.89
162.0228,103.19,0.96964,0.0,0.0,0.11045,122.66,372.81,363.54,344.96,342.86
162.0237,110.31,1.4628,0.0,0.0,0.172,131.22,374.72,365.41,344.96,342.83
162.0246,107.96,1.9384,0.0,0.0,0.23555,127.92,377.17,367.97,344.95,342.84
162.0255,113.09,2.3614,0.0,0.0,0.2944,134.24,379.62,370.53,344.94,342.85
162.0264,112.91,2.948,0.0,0.0,0.38265,133.91,382.08,373.09,344.92,342.87
162.0273,115.66,3.3496,0.0,0.0,0.44731,137.26,384.53,375.65,344.91,342.88
162.0282,115.81,3.8718,0.0,0.0,0.5389,137.4,386.99,378.21,344.9,342.89
162.0291,117.8,4.2812,0.0,0.0,0.61454,139.85,389.44,380.77,344.89,342.9
162.03,118.15,4.7341,0.0,0.0,0.70578,140.14,391.9,383.33,344.88,342.91
162.0309,118.83,5.1469,0.0,0.0,0.79589,140.99,394.35,385.89,344.87,342.92
162.0318,119.46,5.5512,0.0,0.0,0.89017,141.7,396.81,388.46,344.86,342.93
162.0327,119.76,5.9252,0.0,0.0,0.98457,142.1,399.26,391.02,344.85,342.94
162.0336,120.04,6.2496,0.0,0.0,1.0736,142.45,401.71,393.58,344.84,342.95
162.0345,119.71,6.5857,0.0,0.0,1.1739,142.05,401.94,393.41,344.84,342.99
162.0354,120.63,6.8614,0.0,0.0,1.2621,143.12,402.17,393.23,344.84,343.03
162.0363,120.86,7.1332,0.0,0.0,1.3594,143.41,402.4,393.06,344.84,343.07
162.0372,122.3,7.353,0.0,0.0,1.4448,145.07,402.62,392.89,344.84,343.11
162.0381,123.49,7.5709,0.0,0.0,1.5387,146.49,402.85,392.72,344.84,343.14
162.039,125.71,7.764,0.0,0.0,1.6287,149.16,403.08,392.55,344.84,343.18
162.0399,112.21,7.8557,0.0,0.0,1.6769,133.12,403.31,392.38,344.84,343.22
162.0408,106.43,7.8526,0.0,0.0,1.6789,126.33,403.54,392.21,344.84,343.26
162.0417,104.38,7.8855,0.0,0.0,1.6951,124.07,403.76,392.04,344.84,343.3
162.0426,101.7,7.8669,0.0,0.0,1.6865,120.74,403.99,391.87,344.84,343.34
162.0435,99.785,7.9032,0.0,0.0,1.7045,118.57,404.22,391.69,344.84,343.37
162.0444,98.142,7.8883,0.0,0.0,1.6942,116.57,403.59,390.64,344.83,343.36
162.0453,95.968,7.9028,0.0,0.0,1.6998,113.95,402.85,389.47,344.82,343.35
162.0462,94.417,7.9153,0.0,0.0,1.7016,112.12,402.11,388.3,344.81,343.33
162.0471,92.863,7.9209,0.0,0.0,1.7022,110.22,401.38,387.13,344.81,343.31
162.048,91.735,7.9295,0.0,0.0,1.7048,108.94,400.64,385.95,344.8,343.3
162.0489,90.869,7.9287,0.0,0.0,1.7042,107.84,399.9,384.78,344.79,343.28
162.0498,89.704,7.9488,0.0,0.0,1.715,106.49,399.17,383.61,344.78,343.27
162.0507,88.905,7.9397,0.0,0.0,1.7116,105.56,398.43,382.44,344.77,343.25
162.0516,88.012,7.9431,0.0,0.0,1.7166,104.47,397.69,381.27,344.76,343.23
162.0525,87.066,7.9466,0.0,0.0,1.7202,103.35,396.95,380.1,344.76,343.22
162.0534,86.613,7.936,0.0,0.0,1.7183,102.83,396.22,378.93,344.75,343.2
162.0543,85.895,7.9426,0.0,0.0,1.7239,101.93,395.6,378.21,344.75,343.22
162.0552,85.17,7.9356,0.0,0.0,1.7201,101.11,395.03,377.61,344.75,343.24
162.0561,84.619,7.9418,0.0,0.0,1.7235,100.45,394.45,377.01,344.75,343.26
162.057,83.98,7.9388,0.0,0.0,1.7195,99.674,393.88,376.41,344.76,343.29
162.0579,83.481,7.9428,0.0,0.0,1.7197,99.093,393.3,375.81,344.76,343.31
162.0588,82.959,7.9475,0.0,0.0,1.7192,98.466,392.73,375.22,344.76,343.34
162.0597,82.545,7.9498,0.0,0.0,1.717,97.966,392.15,374.62,344.76,343.36
162.0606,82.03,7.9603,0.0,0.0,1.7214,97.359,391.58,374.02,344.77,343.39
162.0615,81.637,7.955,0.0,0.0,1.7191,96.889,391.0,373.42,344.77,343.41
162.0624,81.229,7.9592,0.0,0.0,1.7226,96.404,390.43,372.82,344.77,343.44
162.0633,80.823,7.9571,0.0,0.0,1.725,95.916,389.85,372.22,344.78,343.46
162.0642,80.45,7.9549,0.0,0.0,1.7267,95.475,389.43,371.74,344.79,343.46
162.0651,80.064,7.9511,0.0,0.0,1.7275,95.023,389.09,371.32,344.8,343.45
162.066,79.745,7.9466,0.0,0.0,1.7278,94.634,388.74,370.91,344.81,343.44
162.0669,79.34,7.9437,0.0,0.0,1.7263,94.175,388.4,370.49,344.83,343.43
162.0678,79.095,7.9405,0.0,0.0,1.7238,93.869,388.05,370.07,344.84,343.42
162.0687,78.716,7.9446,0.0,0.0,1.7235,93.418,387.71,369.65,344.85,343.41
162.0696,78.445,7.9461,0.0,0.0,1.7214,93.101,387.36,369.23,344.87,343.4
162.0705,78.14,7.9484,0.0,0.0,1.7198,92.737,387.02,368.81,344.88,343.39
162.0714,77.902,7.9543,0.0,0.0,1.7193,92.458,386.67,368.39,344.9,343.38
162.0723,77.572,7.9575,0.0,0.0,1.7193,92.063,386.33,367.97,344.91,343.36
162.0732,77.314,7.9648,0.0,0.0,1.7213,91.762,385.98,367.55,344.92,343.35
162.0741,77.043,7.9664,0.0,0.0,1.7231,91.438,385.7,367.27,344.92,343.34
162.075,76.765,7.9681,0.0,0.0,1.7248,91.115,385.47,367.1,344.9,343.33
162.0759,76.521,7.9688,0.0,0.0,1.7274,90.815,385.25,366.93,344.89,343.31
162.0768,76.208,7.9666,0.0,0.0,1.7298,90.423,385.02,366.76,344.87,343.3
162.0777,75.987,7.9629,0.0,0.0,1.7318,90.188,384.79,366.59,344.85,343.29
162.0786,75.674,7.9609,0.0,0.0,1.7316,89.809,384.56,366.41,344.84,343.27
162.0795,75.445,7.9597,0.0,0.0,1.7328,89.545,384.33,366.24,344.82,343.26
162.0804,74.932,7.9572,0.0,0.0,1.7311,88.948,384.11,366.07,344.8,343.25
162.0813,74.317,7.9554,0.0,0.0,1.7295,88.227,383.88,365.9,344.79,343.23
162.0822,73.297,7.9564,0.0,0.0,1.7278,87.026,383.65,365.73,344.77,343.22
162.0831,72.252,7.957,0.0,0.0,1.7248,85.776,383.42,365.56,344.76,343.2
162.084,70.033,7.9569,0.0,0.0,1.7216,83.113,383.25,365.41,344.74,343.2
162.0849,67.263,7.9566,0.0,0.0,1.7205,79.761,383.14,365.29,344.73,343.2
162.0858,63.481,7.9534,0.0,0.0,1.7178,75.509,383.03,365.17,344.73,343.2
162.0867,44.329,7.9142,0.0,0.0,1.701,53.846,382.92,365.06,344.72,343.2
162.0876,10.812,7.8302,0.0,0.0,1.6616,13.76,382.81,364.94,344.71,343.2
162.0885,-0.70055,7.7452,0.0,0.0,1.6247,-0.95421,382.7,364.82,344.7,343.2
162.0894,0.87163,7.7551,0.0,0.0,1.6287,0.72447,382.6,364.7,344.69,343.2
162.0903,10.201,7.8254,0.0,0.0,1.666,12.306,382.49,364.59,344.69,343.2
162.0912,2.6234,7.7727,0.0,0.0,1.6423,3.3441,382.38,364.47,344.68,343.2
162.0921,2.9346,7.7817,0.0,0.0,1.6443,3.2831,382.27,364.35,344.67,343.2
162.093,7.231,7.797,0.0,0.0,1.6515,8.6019,382.16,364.24,344.66,343.2
162.0939,4.849,7.7877,0.0,0.0,1.6448,5.891,382.11,364.14,344.66,343.19
162.0948,3.2236,7.792,0.0,0.0,1.6434,3.7462,382.16,364.07,344.67,343.17
162.0957,6.2786,7.7927,0.0,0.0,1.6407,7.3818,382.22,364.0,344.69,343.15
162.0966,4.7334,7.8107,0.0,0.0,1.6476,5.717,382.27,363.94,344.7,343.12
162.0975,3.9024,7.7975,0.0,0.0,1.6393,4.59,382.32,363.87,344.71,343.1
162.0984,5.4657,7.8168,0.0,0.0,1.6486,6.4505,382.38,363.81,344.73,343.08
162.0993,5.0568,7.8184,0.0,0.0,1.6497,6.0853,382.43,363.74,344.74,343.06
162.1002,4.4626,7.8143,0.0,0.0,1.6497,5.2541,382.49,363.68,344.76,343.04
162.1011,5.1028,7.8157,0.0,0.0,1.6526,6.0268,382.54,363.61,344.77,343.01
162.102,4.7833,7.809,0.0,0.0,1.6529,5.7155,382.6,363.55,344.78,342.99
162.1029,4.6966,7.812,0.0,0.0,1.657,5.5507,382.65,363.48,344.8,342.97
162.1038,5.0727,7.807,0.0,0.0,1.6564,6.0157,382.7,363.42,344.81,342.96
162.1047,4.7417,7.8029,0.0,0.0,1.6535,5.6239,382.73,363.35,344.84,342.97
162.1056,4.7163,7.8028,0.0,0.0,1.6531,5.6092,382.75,363.28,344.86,342.98
162.1065,4.8391,7.803,0.0,0.0,1.6518,5.7104,382.78,363.22,344.89,342.99
162.1074,4.8738,7.8036,0.0,0.0,1.6493,5.8027,382.81,363.15,344.91,343.0
162.1083,4.7183,7.8023,0.0,0.0,1.6463,5.5807,382.83,363.09,344.94,343.01
162.1092,5.0776,7.8102,0.0,0.0,1.6482,6.0488,382.86,363.02,344.96,343.02
162.1101,4.6722,7.8083,0.0,0.0,1.6457,5.5347,382.89,362.96,344.98,343.03
162.111,4.9109,7.8047,0.0,0.0,1.645,5.8268,382.92,362.89,345.01,343.04
162.1119,4.8621,7.8079,0.0,0.0,1.6493,5.7555,382.94,362.83,345.03,343.05
162.1128,4.7421,7.8041,0.0,0.0,1.6501,5.6221,382.97,362.76,345.06,343.07
162.1137,4.8987,7.8002,0.0,0.0,1.6505,5.819,383.0,362.7,345.08,343.08
162.1146,4.8178,7.7986,0.0,0.0,1.6518,5.7286,383.01,362.66,345.09,343.08
162.1155,4.8943,7.7946,0.0,0.0,1.6512,5.7795,383.02,362.63,345.1,343.08
162.1164,4.7334,7.7909,0.0,0.0,1.6498,5.609,383.03,362.59,345.11,343.08
162.1173,4.8796,7.7916,0.0,0.0,1.6495,5.8098,383.04,362.56,345.11,343.09
162.1182,4.7291,7.7917,0.0,0.0,1.6471,5.619,383.05,362.52,345.12,343.09
162.1191,4.9115,7.7962,0.0,0.0,1.6464,5.8237,383.06,362.49,345.13,343.09
162.12,4.7423,7.8,0.0,0.0,1.6454,5.6341,383.07,362.45,345.14,343.09
162.1209,5.0056,7.8055,0.0,0.0,1.6458,5.9434,383.08,362.42,345.15,343.1
162.1218,4.7236,7.8079,0.0,0.0,1.6451,5.622,383.09,362.38,345.16,343.1
162.1227,4.9099,7.8107,0.0,0.0,1.6458,5.8248,383.1,362.34,345.16,343.1
162.1236,4.8373,7.8176,0.0,0.0,1.6489,5.7476,383.11,362.31,345.17,343.11
162.1245,4.855,7.814,0.0,0.0,1.6483,5.7455,383.14,362.26,345.16,343.1
162.1254,4.9805,7.8147,0.0,0.0,1.6509,5.9151,383.17,362.21,345.16,343.09
162.1263,4.7767,7.8126,0.0,0.0,1.6537,5.6752,383.2,362.15,345.15,343.09
162.1272,4.9933,7.8079,0.0,0.0,1.6544,5.9332,383.23,362.1,345.14,343.08
162.1281,4.7675,7.8029,0.0,0.0,1.6537,5.6503,383.26,362.05,345.13,343.08
162.129,5.067,7.8023,0.0,0.0,1.6538,6.0146,383.29,362.0,345.12,343.07
162.1299,4.7353,7.7983,0.0,0.0,1.6519,5.627,383.32,361.95,345.11,343.07
162.1308,5.0112,7.7993,0.0,0.0,1.6507,5.9341,383.35,361.89,345.11,343.06
162.1317,4.8311,7.801,0.0,0.0,1.6493,5.7415,383.38,361.84,345.1,343.06
162.1326,4.9583,7.8035,0.0,0.0,1.6485,5.8832,383.41,361.79,345.09,343.05
162.1335,4.8845,7.8095,0.0,0.0,1.6479,5.802,383.44,361.74,345.08,343.05
162.1344,4.8568,7.81,0.0,0.0,1.6476,5.7688,383.44,361.7,345.08,343.06
162.1353,4.9803,7.8153,0.0,0.0,1.6495,5.9243,383.44,361.67,345.08,343.07
162.1362,4.8674,7.8129,0.0,0.0,1.6506,5.7536,383.43,361.63,345.07,343.08
162.1371,4.9607,7.8105,0.0,0.0,1.6517,5.8962,383.43,361.6,345.07,343.1
162.138,4.8492,7.8072,0.0,0.0,1.6545,5.7517,383.42,361.56,345.07,343.11
162.1389,5.0018,7.803,0.0,0.0,1.6535,5.9525,383.41,361.52,345.06,343.13
162.1398,4.8556,7.7975,0.0,0.0,1.652,5.7526,383.41,361.49,345.06,343.14
162.1407,5.0925,7.7954,0.0,0.0,1.6518,6.0367,383.4,361.45,345.06,343.15
162.1416,4.7842,7.7932,0.0,0.0,1.6507,5.6854,383.4,361.42,345.06,343.17
162.1425,5.0774,7.7896,0.0,0.0,1.6469,6.0015,383.39,361.38,345.05,343.18
162.1434,4.8532,7.7943,0.0,0.0,1.6469,5.7797,383.39,361.35,345.05,343.19
162.1443,5.004,7.7958,0.0,0.0,1.6447,5.9343,383.38,361.29,345.05,343.21
162.1452,4.9453,7.7995,0.0,0.0,1.6438,5.865,383.36,361.24,345.05,343.23
162.1461,4.9313,7.8049,0.0,0.0,1.6441,5.8561,383.35,361.18,345.04,343.24
162.147,5.0067,7.8085,0.0,0.0,1.6448,5.9414,383.34,361.12,345.04,343.26
162.1479,4.8778,7.8122,0.0,0.0,1.6466,5.7948,383.32,361.07,345.04,343.27
162.1488,5.0122,7.8161,0.0,0.0,1.649,5.9414,383.31,361.01,345.03,343.29
162.1497,4.8833,7.8124,0.0,0.0,1.6499,5.7948,383.29,360.95,345.03,343.31
162.1506,4.9997,7.8125,0.0,0.0,1.6532,5.9333,383.28,360.89,345.03,343.32
162.1515,4.9579,7.8098,0.0,0.0,1.654,5.88,383.27,360.84,345.03,343.34
162.1524,5.0256,7.8066,0.0,0.0,1.6547,5.9625,383.25,360.78,345.02,343.36
162.1533,4.9721,7.8016,0.0,0.0,1.6537,5.9072,383.24,360.72,345.02,343.37
162.1542,5.0257,7.8001,0.0,0.0,1.6536,5.9606,383.17,360.65,345.02,343.37
162.1551,4.9723,7.8019,0.0,0.0,1.6524,5.9023,383.08,360.58,345.02,343.36
162.156,5.0444,7.7997,0.0,0.0,1.6493,5.9705,382.99,360.5,345.03,343.35
162.1569,4.9999,7.8044,0.0,0.0,1.6492,5.9335,382.9,360.42,345.03,343.34
162.1578,5.0125,7.809,0.0,0.0,1.6485,5.9475,382.8,360.35,345.03,343.33
162.1587,5.1153,7.8084,0.0,0.0,1.6463,6.079,382.71,360.27,345.04,343.32
162.1596,5.0135,7.8109,0.0,0.0,1.6481,5.9556,382.62,360.19,345.04,343.31
162.1605,5.1152,7.8113,0.0,0.0,1.6496,6.077,382.53,360.12,345.04,343.29
162.1614,5.1232,7.8096,0.0,0.0,1.651,6.0992,382.44,360.04,345.04,343.28
162.1623,5.1262,7.8088,0.0,0.0,1.6531,6.0781,382.34,359.96,345.05,343.27
162.1632,5.0864,7.802,0.0,0.0,1.652,6.0279,382.25,359.89,345.05,343.26
162.1641,5.0796,7.7988,0.0,0.0,1.6523,6.019,382.08,359.8,345.05,343.26
162.165,5.1161,7.7962,0.0,0.0,1.6524,6.0872,381.85,359.71,345.04,343.26
162.1659,5.0809,7.7918,0.0,0.0,1.6509,6.041,381.62,359.61,345.03,343.26
162.1668,5.1439,7.7904,0.0,0.0,1.6475,6.1264,381.39,359.51,345.02,343.26
162.1677,5.0128,7.7922,0.0,0.0,1.6464,5.9505,381.16,359.42,345.01,343.26
162.1686,5.2291,7.7953,0.0,0.0,1.6454,6.2035,380.93,359.32,345.0,343.26
162.1695,4.913,7.7967,0.0,0.0,1.643,5.8321,380.69,359.23,345.0,343.26
162.1704,5.2371,7.8036,0.0,0.0,1.6438,6.2197,380.46,359.13,344.99,343.26
162.1713,4.9677,7.8079,0.0,0.0,1.645,5.9035,380.23,359.04,344.98,343.26
162.1722,5.2118,7.81,0.0,0.0,1.6456,6.1662,380.0,358.94,344.97,343.26
162.1731,5.0285,7.8139,0.0,0.0,1.6484,5.9748,379.77,358.85,344.96,343.26
162.174,5.1099,7.815,0.0,0.0,1.65,6.0439,379.58,358.76,344.96,343.26
162.1749,5.1184,7.815,0.0,0.0,1.6527,6.0892,379.44,358.69,344.97,343.27
162.1758,4.9356,7.8104,0.0,0.0,1.6532,5.8481,379.3,358.61,344.97,343.27
162.1767,5.2064,7.8087,0.0,0.0,1.6551,6.1995,379.15,358.54,344.98,343.28
162.1776,4.9003,7.8038,0.0,0.0,1.6543,5.7898,379.01,358.47,344.98,343.28
162.1785,5.3214,7.8038,0.0,0.0,1.6549,6.3313,378.87,358.39,344.99,343.29
162.1794,4.8476,7.7962,0.0,0.0,1.6515,5.7467,378.73,358.32,344.99,343.29
162.1803,5.3253,7.7999,0.0,0.0,1.6503,6.3333,378.59,358.25,345.0,343.3
162.1812,4.7627,7.8016,0.0,0.0,1.649,5.6493,378.45,358.17,345.01,343.3
162.1821,5.3244,7.8055,0.0,0.0,1.6488,6.3211,378.31,358.1,345.01,343.31
162.183,4.9196,7.8086,0.0,0.0,1.6471,5.8532,378.16,358.02,345.02,343.31
162.1839,5.1172,7.809,0.0,0.0,1.646,6.041,378.06,357.95,345.02,343.32
162.1848,5.0903,7.8132,0.0,0.0,1.6488,6.059,378.01,357.89,345.03,343.31
162.1857,5.0512,7.8106,0.0,0.0,1.6497,5.9845,377.97,357.83,345.05,343.31
162.1866,5.1167,7.81,0.0,0.0,1.6524,6.0812,377.93,357.77,345.06,343.3
162.1875,5.08,7.804,0.0,0.0,1.6524,6.0309,377.89,357.7,345.07,343.29
162.1884,5.2021,7.8032,0.0,0.0,1.654,6.1795,377.85,357.64,345.08,343.29
162.1893,4.9184,7.7954,0.0,0.0,1.6519,5.8411,377.81,357.58,345.09,343.28
162.1902,5.0942,7.7948,0.0,0.0,1.652,6.046,377.77,357.52,345.1,343.28
162.1911,4.9611,7.7924,0.0,0.0,1.6499,5.8942,377.73,357.45,345.11,343.27
162.192,5.1714,7.7925,0.0,0.0,1.6477,6.1121,377.69,357.39,345.12,343.27
162.1929,4.9888,7.7957,0.0,0.0,1.647,5.9334,377.65,357.33,345.13,343.26
162.1938,5.1147,7.797,0.0,0.0,1.6443,6.0739,377.61,357.26,345.14,343.26
162.1947,5.1209,7.8047,0.0,0.0,1.6454,6.0701,377.6,357.17,345.12,343.26
162.1956,4.9975,7.8072,0.0,0.0,1.6448,5.9247,377.58,357.08,345.11,343.27
162.1965,5.2451,7.8113,0.0,0.0,1.6456,6.2379,377.56,357.0,345.1,343.27
162.1974,4.8488,7.8168,0.0,0.0,1.6487,5.7455,377.55,356.91,345.08,343.28
162.1983,5.284,7.8172,0.0,0.0,1.6508,6.2709,377.53,356.82,345.07,343.29
162.1992,4.8711,7.8126,0.0,0.0,1.6506,5.7778,377.51,356.74,345.06,343.29
162.2001,5.3305,7.8149,0.0,0.0,1.6547,6.3231,377.5,356.65,345.04,343.3
162.201,4.9528,7.8087,0.0,0.0,1.6547,5.8783,377.48,356.56,345.03,343.3
162.2019,5.1994,7.8052,0.0,0.0,1.6545,6.1585,377.47,356.47,345.02,343.31
162.2028,5.057,7.8067,0.0,0.0,1.655,6.0208,377.45,356.39,345.0,343.31
162.2037,5.1574,7.8007,0.0,0.0,1.6533,6.1053,377.43,356.3,344.99,343.32
162.2046,5.1051,7.8038,0.0,0.0,1.6522,6.0851,377.42,356.25,345.0,343.3
162.2055,5.0924,7.8011,0.0,0.0,1.6497,6.0379,377.4,356.2,345.0,343.28
162.2064,5.2114,7.8065,0.0,0.0,1.6496,6.1937,377.38,356.16,345.01,343.27
162.2073,4.9837,7.8073,0.0,0.0,1.6477,5.9055,377.37,356.11,345.01,343.25
162.2082,5.3108,7.8116,0.0,0.0,1.6484,6.3019,377.35,356.06,345.02,343.23
162.2091,4.9662,7.8109,0.0,0.0,1.6483,5.9013,377.33,356.01,345.02,343.22
162.21,5.2885,7.8121,0.0,0.0,1.65,6.2597,377.32,355.96,345.03,343.2
162.2109,4.9725,7.8121,0.0,0.0,1.6525,5.8933,377.3,355.91,345.03,343.18
162.2118,5.2686,7.8068,0.0,0.0,1.653,6.2417,377.29,355.86,345.04,343.17
162.2127,5.0758,7.8038,0.0,0.0,1.654,6.0339,377.27,355.81,345.04,343.15
162.2136,5.1459,7.7984,0.0,0.0,1.6532,6.0943,377.25,355.76,345.05,343.14
162.2145,5.1777,7.7972,0.0,0.0,1.6533,6.1625,377.19,355.69,345.08,343.13
162.2154,5.092,7.79,0.0,0.0,1.6489,6.031,377.12,355.63,345.1,343.12
162.2163,5.2185,7.7944,0.0,0.0,1.6498,6.2077,377.06,355.56,345.13,343.12
162.2172,5.0392,7.7923,0.0,0.0,1.647,5.9806,376.99,355.49,345.16,343.11
162.2181,5.2785,7.7982,0.0,0.0,1.6461,6.279,376.93,355.42,345.19,343.11
162.219,5.0266,7.8017,0.0,0.0,1.6443,5.9577,376.86,355.35,345.21,343.1
162.2199,5.2964,7.8066,0.0,0.0,1.6448,6.2839,376.8,355.29,345.24,343.1
162.2208,5.0426,7.8099,0.0,0.0,1.645,5.9948,376.73,355.22,345.27,343.09
162.2217,5.2475,7.8137,0.0,0.0,1.6473,6.2156,376.67,355.15,345.3,343.09
162.2226,5.0914,7.8164,0.0,0.0,1.6502,6.0671,376.6,355.08,345.32,343.08
162.2235,5.2012,7.8147,0.0,0.0,1.6514,6.1727,376.53,355.01,345.35,343.08
162.2244,5.1978,7.8131,0.0,0.0,1.653,6.1795,376.56,354.94,345.36,343.08
162.2253,5.1328,7.8106,0.0,0.0,1.654,6.0773,376.6,354.86,345.36,343.09
162.2262,5.2469,7.8082,0.0,0.0,1.6556,6.2561,376.64,354.78,345.36,343.09
162.2271,5.0722,7.8047,0.0,0.0,1.6555,6.0089,376.68,354.71,345.36,343.1
162.228,5.3057,7.8038,0.0,0.0,1.6546,6.3102,376.71,354.63,345.37,343.1
162.2289,5.0405,7.8011,0.0,0.0,1.652,5.9827,376.75,354.56,345.37,343.11
162.2298,5.3093,7.8043,0.0,0.0,1.6511,6.2839,376.79,354.48,345.37,343.11
162.2307,5.0881,7.8036,0.0,0.0,1.649,6.0359,376.83,354.4,345.38,343.12
162.2316,5.2483,7.8068,0.0,0.0,1.648,6.2176,376.87,354.33,345.38,343.12
162.2325,5.1267,7.8133,0.0,0.0,1.6495,6.1285,376.9,354.25,345.38,343.13
162.2334,5.2202,7.8116,0.0,0.0,1.6481,6.1887,376.94,354.17,345.38,343.13
162.2343,5.2059,7.8111,0.0,0.0,1.6489,6.2008,376.91,354.11,345.38,343.14
162.2352,5.1315,7.812,0.0,0.0,1.6521,6.073,376.86,354.04,345.38,343.15
162.2361,5.272,7.8103,0.0,0.0,1.6535,6.2659,376.81,353.97,345.38,343.15
162.237,5.0731,7.8011,0.0,0.0,1.6513,6.0179,376.76,353.91,345.37,343.16
162.2379,5.2979,7.8035,0.0,0.0,1.6551,6.2879,376.7,353.84,345.37,343.16
162.2388,5.0413,7.797,0.0,0.0,1.6528,5.9899,376.65,353.78,345.37,343.17
162.2397,5.3023,7.7917,0.0,0.0,1.6501,6.283,376.6,353.71,345.37,343.17
162.2406,5.0422,7.7938,0.0,0.0,1.6503,5.9929,376.55,353.65,345.36,343.18
162.2415,5.2793,7.7932,0.0,0.0,1.6476,6.2276,376.5,353.58,345.36,343.18
162.2424,5.1044,7.7944,0.0,0.0,1.6444,6.0771,376.45,353.52,345.36,343.19
162.2433,5.18,7.7996,0.0,0.0,1.644,6.1353,376.39,353.45,345.35,343.19
162.2442,5.1911,7.8054,0.0,0.0,1.6453,6.1705,376.27,353.37,345.36,343.21
162.2451,5.1049,7.8049,0.0,0.0,1.6439,6.0389,376.1,353.28,345.38,343.23
162.246,5.27,7.813,0.0,0.0,1.6472,6.2498,375.94,353.2,345.39,343.25
162.2469,5.0393,7.8146,0.0,0.0,1.6482,5.9786,375.78,353.11,345.4,343.28
162.2478,5.2842,7.8138,0.0,0.0,1.6507,6.2719,375.61,353.02,345.42,343.3
162.2487,5.0266,7.8136,0.0,0.0,1.6526,5.9647,375.45,352.93,345.43,343.32
162.2496,5.282,7.8126,0.0,0.0,1.6539,6.2608,375.29,352.85,345.45,343.34
162.2505,5.0486,7.8081,0.0,0.0,1.6552,6.006,375.12,352.76,345.46,343.36
162.2514,5.2474,7.8075,0.0,0.0,1.6556,6.2156,374.96,352.67,345.47,343.39
162.2523,5.0898,7.8024,0.0,0.0,1.6543,6.0521,374.8,352.59,345.49,343.41
162.2532,5.1734,7.7996,0.0,0.0,1.6515,6.1344,374.63,352.5,345.5,343.43
162.2541,5.179,7.8031,0.0,0.0,1.6522,6.1695,374.51,352.42,345.51,343.44
162.255,5.086,7.8024,0.0,0.0,1.649,6.0319,374.43,352.35,345.51,343.45
162.2559,5.2438,7.8055,0.0,0.0,1.6481,6.2256,374.34,352.27,345.51,343.45
162.2568,5.0267,7.8087,0.0,0.0,1.6479,5.9767,374.25,352.2,345.52,343.46
162.2577,5.2762,7.8131,0.0,0.0,1.6489,6.261,374.17,352.12,345.52,343.46
162.2586,5.0316,7.8117,0.0,0.0,1.6486,5.9585,374.08,352.05,345.52,343.47
162.2595,5.2764,7.8137,0.0,0.0,1.6509,6.265,373.99,351.98,345.52,343.48
162.2604,5.0477,7.81,0.0,0.0,1.6521,5.9938,373.9,351.9,345.53,343.48
162.2613,5.2394,7.8056,0.0,0.0,1.6535,6.1978,373.82,351.83,345.53,343.49
162.2622,5.0905,7.801,0.0,0.0,1.6533,6.0581,373.73,351.76,345.53,343.49
162.2631,5.1655,7.7977,0.0,0.0,1.6533,6.1182,373.64,351.68,345.53,343.5
162.264,5.1655,7.7955,0.0,0.0,1.6516,6.1535,373.56,351.62,345.53,343.5
162.2649,5.1046,7.7923,0.0,0.0,1.6498,6.0399,373.48,351.57,345.52,343.48
162.2658,5.2461,7.7957,0.0,0.0,1.6496,6.248,373.41,351.53,345.52,343.47
162.2667,5.0527,7.7919,0.0,0.0,1.6453,5.9947,373.33,351.48,345.51,343.46
162.2676,5.2838,7.7994,0.0,0.0,1.646,6.2648,373.26,351.44,345.5,343.45
162.2685,5.0332,7.8039,0.0,0.0,1.6447,5.9709,373.18,351.39,345.49,343.44
162.2694,5.2947,7.8072,0.0,0.0,1.6448,6.2669,373.1,351.34,345.48,343.43
162.2703,5.0423,7.81,0.0,0.0,1.6455,6.0009,373.03,351.3,345.48,343.42
162.2712,5.2412,7.8167,0.0,0.0,1.6483,6.2156,372.95,351.25,345.47,343.41
162.2721,5.1088,7.8156,0.0,0.0,1.6497,6.0611,372.88,351.2,345.46,343.4
162.273,5.1681,7.814,0.0,0.0,1.6509,6.1414,372.8,351.16,345.45,343.39
162.2739,5.2036,7.8169,0.0,0.0,1.6547,6.1725,372.73,351.11,345.45,343.38
162.2748,5.1193,7.8087,0.0,0.0,1.6547,6.0641,372.68,351.05,345.45,343.38
162.2757,5.2449,7.8096,0.0,0.0,1.6557,6.2267,372.62,350.99,345.46,343.38
162.2766,5.066,7.8046,0.0,0.0,1.6549,6.0037,372.57,350.93,345.46,343.38
162.2775,5.3122,7.8029,0.0,0.0,1.654,6.3223,372.51,350.88,345.47,343.38
162.2784,5.0473,7.8032,0.0,0.0,1.6525,6.003,372.46,350.82,345.47,343.38
162.2793,5.3026,7.8027,0.0,0.0,1.6507,6.284,372.4,350.76,345.48,343.38
162.2802,5.0697,7.8044,0.0,0.0,1.6493,6.0311,372.35,350.71,345.49,343.38
162.2811,5.2673,7.8103,0.0,0.0,1.6484,6.2346,372.29,350.65,345.49,343.38
162.282,5.1439,7.8124,0.0,0.0,1.6488,6.1145,372.24,350.59,345.5,343.38
162.2829,5.2217,7.8132,0.0,0.0,1.6491,6.2047,372.19,350.53,345.5,343.38
162.2838,5.2057,7.8151,0.0,0.0,1.6513,6.1947,372.14,350.47,345.51,343.38
162.2847,5.1321,7.8105,0.0,0.0,1.6514,6.0741,372.1,350.41,345.52,343.4
162.2856,5.3058,7.8082,0.0,0.0,1.6531,6.3052,372.06,350.34,345.53,343.42
162.2865,5.1061,7.8046,0.0,0.0,1.6543,6.0501,372.02,350.28,345.54,343.43
162.2874,5.3371,7.8021,0.0,0.0,1.6546,6.3262,371.98,350.21,345.55,343.45
162.2883,5.0741,7.7927,0.0,0.0,1.6516,6.021,371.94,350.15,345.56,343.46
162.2892,5.3364,7.7962,0.0,0.0,1.6522,6.3302,371.91,350.08,345.57,343.48
162.2901,5.1031,7.7937,0.0,0.0,1.6494,6.0722,371.87,350.02,345.58,343.5
162.291,5.283,7.7915,0.0,0.0,1.6466,6.266,371.83,349.95,345.6,343.51
162.2919,5.1828,7.7997,0.0,0.0,1.6468,6.1414,371.79,349.88,345.61,343.53
162.2928,5.2341,7.8041,0.0,0.0,1.6455,6.1987,371.75,349.82,345.62,343.55
162.2937,5.239,7.8061,0.0,0.0,1.6455,6.2278,371.71,349.75,345.63,343.56
162.2946,5.1729,7.8093,0.0,0.0,1.6453,6.1284,371.64,349.67,345.61,343.56
162.2955,5.3183,7.8184,0.0,0.0,1.6497,6.3131,371.57,349.6,345.6,343.56
162.2964,5.0944,7.8155,0.0,0.0,1.6495,6.0491,371.5,349.52,345.58,343.56
162.2973,5.3392,7.8197,0.0,0.0,1.6524,6.3513,371.43,349.45,345.57,343.56
162.2982,5.0949,7.8163,0.0,0.0,1.6548,6.0541,371.36,349.37,345.56,343.56
162.2991,5.337,7.8136,0.0,0.0,1.6555,6.3241,371.29,349.29,345.54,343.56
162.3,5.1227,7.8103,0.0,0.0,1.6559,6.0885,371.22,349.22,345.53,343.56
162.3009,5.3289,7.807,0.0,0.0,1.6563,6.3192,371.15,349.14,345.52,343.56
162.3018,5.1711,7.8046,0.0,0.0,1.6551,6.1484,371.08,349.06,345.5,343.56
162.3027,5.2399,7.8041,0.0,0.0,1.6531,6.2005,371.01,348.99,345.49,343.56
162.3036,5.246,7.8045,0.0,0.0,1.6522,6.2429,370.93,348.91,345.48,343.56
162.3045,5.173,7.8045,0.0,0.0,1.65,6.1284,370.84,348.84,345.48,343.57
162.3054,5.3324,7.8114,0.0,0.0,1.6506,6.3312,370.75,348.78,345.49,343.58
162.3063,5.1216,7.8117,0.0,0.0,1.6485,6.0832,370.67,348.71,345.5,343.59
162.3072,5.3541,7.814,0.0,0.0,1.6495,6.3814,370.58,348.65,345.51,343.6
162.3081,5.0949,7.8134,0.0,0.0,1.6498,6.054,370.49,348.58,345.52,343.62
162.309,5.3627,7.8134,0.0,0.0,1.6522,6.3482,370.4,348.52,345.52,343.63
162.3099,5.1363,7.8117,0.0,0.0,1.6535,6.1115,370.31,348.45,345.53,343.64
162.3108,5.3143,7.8078,0.0,0.0,1.6539,6.282,370.22,348.38,345.54,343.65
162.3117,5.1713,7.8026,0.0,0.0,1.6541,6.1494,370.13,348.32,345.55,343.66
162.3126,5.2413,7.7978,0.0,0.0,1.6531,6.2167,370.04,348.25,345.56,343.67
162.3135,5.2665,7.7956,0.0,0.0,1.6524,6.2742,369.95,348.19,345.57,343.68
162.3144,5.1764,7.7925,0.0,0.0,1.6507,6.1595,369.85,348.13,345.58,343.68
162.3153,5.3376,7.7947,0.0,0.0,1.648,6.3231,369.75,348.08,345.6,343.68
162.3162,5.108,7.7946,0.0,0.0,1.6454,6.0661,369.65,348.02,345.62,343.68
162.3171,5.3641,7.8021,0.0,0.0,1.6458,6.3654,369.56,347.97,345.64,343.68
162.318,5.1068,7.8044,0.0,0.0,1.6439,6.0541,369.46,347.91,345.66,343.68
162.3189,5.3508,7.808,0.0,0.0,1.6454,6.3464,369.36,347.86,345.68,343.68
162.3198,5.1152,7.8145,0.0,0.0,1.6472,6.0671,369.26,347.8,345.7,343.68
162.3207,5.3102,7.8161,0.0,0.0,1.6488,6.3041,369.16,347.75,345.72,343.68
162.3216,5.1971,7.8165,0.0,0.0,1.6504,6.1725,369.07,347.69,345.74,343.68
162.3225,5.2539,7.8172,0.0,0.0,1.6531,6.2157,368.97,347.64,345.76,343.68
162.3234,5.2592,7.8137,0.0,0.0,1.6551,6.2529,368.87,347.58,345.78,343.68
162.3243,5.1741,7.8101,0.0,0.0,1.6551,6.1356,368.78,347.53,345.78,343.68
162.3252,5.3207,7.8077,0.0,0.0,1.6561,6.3303,368.7,347.47,345.77,343.68
162.3261,5.1281,7.8017,0.0,0.0,1.6542,6.0823,368.61,347.41,345.77,343.68
162.327,5.3717,7.8042,0.0,0.0,1.6535,6.3664,368.53,347.36,345.77,343.68
162.3279,5.1204,7.8009,0.0,0.0,1.6511,6.0683,368.45,347.3,345.77,343.68
162.3288,5.358,7.8053,0.0,0.0,1.65,6.3623,368.36,347.24,345.76,343.68
162.3297,5.1156,7.8064,0.0,0.0,1.6492,6.0732,368.28,347.18,345.76,343.68
162.3306,5.2889,7.8103,0.0,0.0,1.6486,6.2711,368.19,347.13,345.76,343.68
162.3315,5.1913,7.8147,0.0,0.0,1.6497,6.1706,368.11,347.07,345.76,343.68
162.3324,5.2334,7.8138,0.0,0.0,1.649,6.1926,368.02,347.01,345.75,343.68
162.3333,5.2598,7.8139,0.0,0.0,1.6519,6.2599,367.94,346.95,345.75,343.68
162.3342,5.1799,7.8115,0.0,0.0,1.6527,6.1355,367.88,346.9,345.75,343.7
162.3351,5.3115,7.8094,0.0,0.0,1.655,6.299,367.82,346.86,345.76,343.72
162.336,5.1203,7.801,0.0,0.0,1.6533,6.0681,367.77,346.81,345.77,343.74
162.3369,5.3339,7.8,0.0,0.0,1.654,6.3495,367.71,346.76,345.78,343.76
162.3378,5.0936,7.7978,0.0,0.0,1.653,6.0371,367.66,346.72,345.79,343.78
162.3387,5.3451,7.7941,0.0,0.0,1.6512,6.3515,367.6,346.67,345.8,343.81
162.3396,5.1228,7.7926,0.0,0.0,1.6478,6.0841,367.55,346.62,345.8,343.83
162.3405,5.29,7.798,0.0,0.0,1.6478,6.28,367.49,346.58,345.81,343.85
162.3414,5.1912,7.8003,0.0,0.0,1.6466,6.1726,367.44,346.53,345.82,343.87
162.3423,5.242,7.8017,0.0,0.0,1.6442,6.2157,367.39,346.48,345.83,343.89
162.3432,5.2462,7.809,0.0,0.0,1.6466,6.25,367.33,346.44,345.84,343.92
162.3441,5.1733,7.8108,0.0,0.0,1.6463,6.1284,367.28,346.39,345.85,343.92
162.345,5.3322,7.8152,0.0,0.0,1.6479,6.3353,367.23,346.34,345.87,343.92
162.3459,5.1272,7.8173,0.0,0.0,1.6508,6.0831,367.17,346.28,345.89,343.91
162.3468,5.3582,7.8178,0.0,0.0,1.6528,6.3532,367.12,346.23,345.91,343.91
162.3477,5.1154,7.8132,0.0,0.0,1.6537,6.0781,367.07,346.18,345.93,343.9
162.3486,5.3507,7.8138,0.0,0.0,1.6562,6.3463,367.02,346.13,345.95,343.9
162.3495,5.1362,7.8083,0.0,0.0,1.6561,6.0912,366.97,346.08,345.97,343.89
162.3504,5.3151,7.8047,0.0,0.0,1.6555,6.2951,366.92,346.02,345.98,343.88
162.3513,5.1975,7.8039,0.0,0.0,1.6551,6.1796,366.86,345.97,346.0,343.88
162.3522,5.2349,7.8025,0.0,0.0,1.6524,6.2077,366.81,345.92,346.02,343.87
162.3531,5.278,7.8063,0.0,0.0,1.6515,6.2689,366.76,345.87,346.04,343.87
162.354,5.1808,7.8036,0.0,0.0,1.6486,6.1445,366.71,345.81,346.05,343.86
162.3549,5.3256,7.8135,0.0,0.0,1.6502,6.3223,366.65,345.73,346.05,343.86
162.3558,5.1342,7.8117,0.0,0.0,1.6485,6.093,366.59,345.66,346.05,343.86
162.3567,5.3658,7.8145,0.0,0.0,1.6488,6.3744,366.54,345.59,346.05,343.86
162.3576,5.1213,7.8151,0.0,0.0,1.651,6.0782,366.48,345.51,346.05,343.86
162.3585,5.3767,7.8115,0.0,0.0,1.6528,6.3704,366.42,345.44,346.05,343.86
162.3594,5.1634,7.8078,0.0,0.0,1.6541,6.1376,366.36,345.36,346.05,343.86
162.3603,5.328,7.8067,0.0,0.0,1.655,6.305,366.31,345.29,346.05,343.86
162.3612,5.2056,7.8015,0.0,0.0,1.6543,6.1939,366.25,345.22,346.05,343.86
162.3621,5.2617,7.7962,0.0,0.0,1.6522,6.2389,366.19,345.14,346.05,343.86
162.363,5.2849,7.7964,0.0,0.0,1.6526,6.276,366.13,345.07,346.05,343.86
162.3639,5.2121,7.7921,0.0,0.0,1.6486,6.1563,366.08,344.99,346.05,343.87
162.3648,5.359,7.7946,0.0,0.0,1.648,6.3624,366.02,344.92,346.05,343.87
162.3657,5.1609,7.7975,0.0,0.0,1.6458,6.1224,365.96,344.84,346.05,343.88
162.3666,5.3923,7.8035,0.0,0.0,1.6455,6.3985,365.91,344.76,346.04,343.88
162.3675,5.1347,7.8074,0.0,0.0,1.6456,6.0944,365.85,344.69,346.04,343.89
162.3684,5.3917,7.8131,0.0,0.0,1.6472,6.3956,365.79,344.61,346.04,343.89
162.3693,5.1774,7.8162,0.0,0.0,1.6489,6.1596,365.73,344.53,346.04,343.9
162.3702,5.3308,7.817,0.0,0.0,1.6501,6.3354,365.68,344.46,346.03,343.91
162.3711,5.2447,7.8185,0.0,0.0,1.6525,6.2279,365.62,344.38,346.03,343.91
162.372,5.2946,7.8138,0.0,0.0,1.653,6.2659,365.56,344.3,346.03,343.92
162.3729,5.3215,7.8146,0.0,0.0,1.6562,6.3393,365.51,344.23,346.02,343.92
162.3738,5.2203,7.8083,0.0,0.0,1.6558,6.1794,365.45,344.16,346.02,343.93
162.3747,5.3611,7.8084,0.0,0.0,1.6566,6.3776,365.41,344.1,346.03,343.93
162.3756,5.1877,7.8038,0.0,0.0,1.6547,6.1465,365.37,344.05,346.03,343.93
162.3765,5.4116,7.8065,0.0,0.0,1.6546,6.4146,365.33,343.99,346.03,343.93
162.3774,5.163,7.8023,0.0,0.0,1.6518,6.1345,365.29,343.94,346.03,343.93
162.3783,5.4101,7.8069,0.0,0.0,1.6507,6.4036,365.25,343.88,346.04,343.93
162.3792,5.1855,7.8093,0.0,0.0,1.6496,6.1777,365.21,343.83,346.04,343.93
162.3801,5.3691,7.8109,0.0,0.0,1.6482,6.3614,365.17,343.77,346.04,343.93
162.381,5.2456,7.8148,0.0,0.0,1.6501,6.2359,365.12,343.72,346.04,343.93
162.3819,5.3156,7.8155,0.0,0.0,1.6497,6.3041,365.08,343.66,346.05,343.93
162.3828,5.3198,7.8171,0.0,0.0,1.6537,6.3215,365.04,343.61,346.05,343.93
162.3837,5.2399,7.8118,0.0,0.0,1.6542,6.2008,365.0,343.56,346.05,343.93
162.3846,5.3802,7.8066,0.0,0.0,1.6546,6.3927,364.96,343.51,346.05,343.93
162.3855,5.1948,7.8019,0.0,0.0,1.6538,6.1556,364.93,343.47,346.05,343.94
162.3864,5.4193,7.8002,0.0,0.0,1.6545,6.4317,364.89,343.42,346.04,343.94
162.3873,5.1693,7.7978,0.0,0.0,1.6528,6.1372,364.85,343.38,346.04,343.95
162.3882,5.405,7.7923,0.0,0.0,1.6495,6.4125,364.81,343.34,346.04,343.95
162.3891,5.1962,7.7962,0.0,0.0,1.649,6.1706,364.77,343.29,346.04,343.96
162.39,5.3745,7.7979,0.0,0.0,1.6475,6.3444,364.73,343.25,346.03,343.96
162.3909,5.259,7.7999,0.0,0.0,1.6451,6.2511,364.7,343.21,346.03,343.97
162.3918,5.3069,7.8054,0.0,0.0,1.6457,6.2679,364.66,343.16,346.03,343.98
162.3927,5.3265,7.8118,0.0,0.0,1.6469,6.3252,364.62,343.12,346.03,343.98
162.3936,5.2599,7.8116,0.0,0.0,1.6467,6.2168,364.58,343.07,346.02,343.99
162.3945,5.3801,7.8192,0.0,0.0,1.6504,6.3935,364.53,343.03,346.03,343.99
162.3954,5.1947,7.8175,0.0,0.0,1.6515,6.1616,364.47,342.99,346.03,344.0
162.3963,5.4056,7.818,0.0,0.0,1.6537,6.4147,364.42,342.94,346.04,344.0
162.3972,5.1629,7.8144,0.0,0.0,1.6558,6.1345,364.36,342.9,346.04,344.01
162.3981,5.3927,7.8124,0.0,0.0,1.6559,6.4116,364.31,342.86,346.05,344.01
162.399,5.1967,7.806,0.0,0.0,1.655,6.1795,364.25,342.81,346.06,344.02
162.3999,5.3683,7.8084,0.0,0.0,1.6567,6.3462,364.2,342.77,346.06,344.02
162.4008,5.2461,7.8038,0.0,0.0,1.6546,6.2448,364.15,342.72,346.07,344.03
162.4017,5.2945,7.8008,0.0,0.0,1.6511,6.264,364.09,342.68,346.07,344.04
162.4026,5.3127,7.8086,0.0,0.0,1.6523,6.3153,364.04,342.64,346.08,344.04
162.4035,5.2213,7.8057,0.0,0.0,1.6489,6.1928,363.98,342.59,346.08,344.05
162.4044,5.3873,7.8126,0.0,0.0,1.6497,6.4007,363.92,342.55,346.09,344.06
162.4053,5.1883,7.8134,0.0,0.0,1.6498,6.1556,363.85,342.51,346.1,344.08
162.4062,5.4059,7.817,0.0,0.0,1.6509,6.4216,363.78,342.46,346.11,344.09
162.4071,5.1687,7.8144,0.0,0.0,1.6509,6.1345,363.71,342.42,346.12,344.11
162.408,5.4031,7.8132,0.0,0.0,1.6538,6.3956,363.64,342.37,346.12,344.13
162.4089,5.1914,7.81,0.0,0.0,1.6543,6.1768,363.57,342.33,346.13,344.14
162.4098,5.3509,7.8032,0.0,0.0,1.654,6.3524,363.51,342.29,346.14,344.16
162.4107,5.2469,7.8016,0.0,0.0,1.6551,6.244,363.44,342.24,346.15,344.18
162.4116,5.3004,7.797,0.0,0.0,1.6522,6.2649,363.37,342.2,346.16,344.19
162.4125,5.3321,7.7955,0.0,0.0,1.6513,6.3304,363.3,342.16,346.16,344.21
162.4134,5.2462,7.7942,0.0,0.0,1.6491,6.2017,363.23,342.11,346.17,344.23
162.4143,5.3852,7.798,0.0,0.0,1.6485,6.3865,363.16,342.07,346.18,344.23
162.4152,5.1755,7.7983,0.0,0.0,1.6465,6.1493,363.08,342.02,346.18,344.24
162.4161,5.4073,7.805,0.0,0.0,1.6464,6.4378,363.01,341.98,346.19,344.24
162.417,5.1762,7.8067,0.0,0.0,1.6455,6.1516,362.93,341.94,346.19,344.25
162.4179,5.4117,7.8123,0.0,0.0,1.6467,6.4186,362.85,341.89,346.2,344.26
162.4188,5.2043,7.8183,0.0,0.0,1.6492,6.1787,362.78,341.85,346.21,344.26
162.4197,5.3556,7.8179,0.0,0.0,1.6506,6.3443,362.7,341.81,346.21,344.27
162.4206,5.2642,7.817,0.0,0.0,1.6524,6.2458,362.62,341.76,346.22,344.27
162.4215,5.3094,7.8172,0.0,0.0,1.6559,6.3032,362.55,341.72,346.22,344.28
162.4224,5.3281,7.8148,0.0,0.0,1.6574,6.3403,362.47,341.67,346.23,344.28
162.4233,5.2543,7.8059,0.0,0.0,1.6548,6.2168,362.39,341.63,346.23,344.29
162.4242,5.3996,7.8098,0.0,0.0,1.6571,6.4106,362.33,341.59,346.23,344.29
162.4251,5.2078,7.8059,0.0,0.0,1.6549,6.1706,362.26,341.55,346.22,344.3
162.426,5.42,7.8033,0.0,0.0,1.6528,6.4387,362.2,341.51,346.21,344.3
162.4269,5.1896,7.8056,0.0,0.0,1.6512,6.1648,362.14,341.47,346.2,344.31
162.4278,5.4172,7.8088,0.0,0.0,1.6508,6.4126,362.08,341.42,346.2,344.32
162.4287,5.2064,7.8113,0.0,0.0,1.6495,6.208,362.01,341.38,346.19,344.32
162.4296,5.37,7.8131,0.0,0.0,1.6491,6.3615,361.95,341.34,346.18,344.33
162.4305,5.2866,7.8178,0.0,0.0,1.651,6.2902,361.89,341.3,346.17,344.33
162.4314,5.3279,7.8149,0.0,0.0,1.6504,6.3051,361.83,341.26,346.16,344.34
162.4323,5.365,7.8143,0.0,0.0,1.6532,6.3573,361.76,341.22,346.16,344.34
162.4332,5.2546,7.8119,0.0,0.0,1.6542,6.2268,361.7,341.18,346.15,344.35
162.4341,5.4079,7.8082,0.0,0.0,1.6555,6.4337,361.64,341.14,346.15,344.35
162.435,5.2199,7.7997,0.0,0.0,1.6535,6.1756,361.57,341.09,346.15,344.36
162.4359,5.433,7.8008,0.0,0.0,1.6544,6.4477,361.51,341.05,346.15,344.37
162.4368,5.2025,7.7962,0.0,0.0,1.6518,6.1747,361.44,341.01,346.15,344.37
162.4377,5.432,7.7929,0.0,0.0,1.6496,6.4499,361.37,340.96,346.16,344.38
162.4386,5.2314,7.7968,0.0,0.0,1.6484,6.2189,361.31,340.92,346.16,344.38
162.4395,5.3954,7.7991,0.0,0.0,1.6469,6.3845,361.24,340.87,346.16,344.39
162.4404,5.3011,7.8044,0.0,0.0,1.6469,6.3214,361.18,340.83,346.16,344.39
162.4413,5.3217,7.8066,0.0,0.0,1.6453,6.3051,361.11,340.79,346.17,344.4
162.4422,5.3541,7.814,0.0,0.0,1.6476,6.3715,361.05,340.74,346.17,344.4
162.4431,5.275,7.8136,0.0,0.0,1.6467,6.2551,360.98,340.7,346.17,344.41
162.444,5.4137,7.8201,0.0,0.0,1.6513,6.4337,360.91,340.65,346.18,344.41
162.4449,5.2291,7.8205,0.0,0.0,1.6526,6.2099,360.84,340.61,346.19,344.42
162.4458,5.4597,7.8174,0.0,0.0,1.6538,6.478,360.77,340.56,346.2,344.42
163.64602,5.2911,7.8127,0.0,0.0,1.6538,6.2801,324.13,308.18,343.16,330.23
165.44602,5.2619,7.8189,0.0,0.0,1.6568,6.2464,297.14,287.91,331.16,312.64
167.1445,5.243,7.8247,0.0,0.0,1.6595,6.2206,280.88,272.83,313.4,294.86
168.9445,5.2597,7.8293,0.0,0.0,1.6616,6.2393,266.89,259.54,295.25,277.76
170.7445,5.2578,7.8341,0.0,0.0,1.664,6.2383,254.67,247.45,280.55,262.67
172.5445,5.214,7.8378,0.0,0.0,1.6659,6.1864,243.56,236.34,265.88,248.53
174.3445,4.7864,7.8397,0.0,0.0,1.6669,5.6809,234.48,226.2,251.82,236.16
176.1445,4.2011,7.8395,0.0,0.0,1.6668,4.9857,226.11,216.78,239.28,224.69
177.9445,3.6656,7.8389,0.0,0.0,1.6664,4.3502,218.03,208.17,227.87,214.17
179.7445,3.4281,7.8389,0.0,0.0,1.6665,4.0693,209.17,199.95,217.15,204.32
181.5445,3.1925,7.8394,0.0,0.0,1.6667,3.7893,200.58,192.27,207.41,195.21
183.3445,3.0205,7.8399,0.0,0.0,1.6668,3.5849,193.15,185.08,198.17,186.68
185.1445,2.9376,7.8416,0.0,0.0,1.6676,3.4867,186.03,178.33,190.8,178.68
186.9445,2.9011,7.8435,0.0,0.0,1.6686,3.4431,179.46,172.19,183.1,171.44
188.7445,2.8879,7.8455,0.0,0.0,1.6697,3.4268,173.61,166.18,175.94,164.72
190.5445,2.8412,7.8472,0.0,0.0,1.6706,3.3715,167.88,160.52,169.02,158.12
192.3445,2.7418,7.8491,0.0,0.0,1.6714,3.2529,162.44,155.09,162.68,152.35
194.1445,2.4726,7.8503,0.0,0.0,1.672,2.9341,157.65,150.03,156.62,146.68
195.8901,2.2272,7.8509,0.0,0.0,1.6722,2.6437,152.46,145.37,151.07,141.53
197.6901,2.0783,7.8525,0.0,0.0,1.6731,2.467,147.96,140.85,145.71,136.58
199.4709,1.981,7.8538,0.0,0.0,1.6737,2.3519,143.17,136.57,140.76,131.91
201.2709,1.8957,7.8555,0.0,0.0,1.6746,2.2497,139.09,132.39,135.86,127.34
203.0709,1.7058,7.8569,0.0,0.0,1.6753,2.0242,135.08,128.46,131.35,123.18
204.8709,1.5745,7.8581,0.0,0.0,1.6758,1.8689,130.91,124.71,127.06,119.14
206.6709,1.5157,7.8599,0.0,0.0,1.6768,1.7992,127.1,121.13,122.95,115.35
208.4709,1.3415,7.87,0.0,0.0,1.6817,1.5922,125.63,122.47,119.95,117.2
209.2709,1.3351,7.8713,0.0,0.0,1.6824,1.585,125.68,123.1,119.84,118.0