File: examples/dan-msc-case-studies/CS4/data/01 raw data/hyde_test_024.csv
Time(sec),Force(kN),Jaw(mm),PowAngle(deg),PTemp,Strain,Stress(MPa),TC1(C),TC2(C),TC3(C)
0.0,6.7005,0.0019577,0.0,0.0038352,0.00022667,20.331,21.604,22.883,21.849
2.0,6.4814,0.0026516,0.0,5.0588,0.00027515,19.66,21.75,22.942,21.91
4.0,6.3928,0.0025025,0.0,11.057,0.00026559,19.394,21.766,22.906,21.91
6.0,6.3438,0.0023534,0.0,17.057,0.00025371,19.243,21.77,22.922,21.905
8.0,6.319,0.0033157,13.625,23.057,0.00036577,19.169,21.93,22.998,21.966
9.3158,6.3083,0.0031285,21.118,27.005,0.00033441,19.136,25.719,25.466,24.566
11.3158,6.2975,0.0017794,23.035,33.004,0.0001841,19.104,32.211,34.178,30.318
13.3158,6.2894,-8.721e-05,23.26,39.004,-2.0096e-05,19.079,38.682,38.644,36.31
14.5165,6.2902,-0.0015001,23.752,42.607,-0.00014493,19.081,42.318,39.907,39.73
16.5165,6.2887,-0.0037287,24.223,48.607,-0.00039483,19.077,48.471,45.383,45.558
18.5165,6.29,-0.0062867,24.975,54.607,-0.00068915,19.081,54.468,50.805,51.286
20.5165,6.2865,-0.0098445,25.344,60.607,-0.0010753,19.071,60.548,56.199,56.989
22.5165,6.2932,-0.010805,25.887,66.606,-0.0011773,19.09,66.528,61.609,62.746
24.5165,6.2902,-0.013138,26.19,72.606,-0.0014425,19.082,72.553,67.219,68.606
26.5165,6.2824,-0.015624,26.785,78.606,-0.0017179,19.057,78.513,72.682,74.338
28.5165,6.2824,-0.018645,26.923,84.606,-0.0020495,19.059,84.573,78.284,80.175
30.5165,6.2775,-0.021335,26.786,90.606,-0.0023395,19.042,90.622,83.981,86.155
32.5165,6.2766,-0.024111,26.748,96.606,-0.0026398,19.04,96.676,89.587,91.967
34.5165,6.2948,-0.027017,27.228,102.61,-0.0029514,19.094,102.63,95.024,97.857
36.5165,6.2981,-0.029763,27.805,108.61,-0.0032505,19.105,108.54,100.64,103.66
38.5165,6.3025,-0.032766,27.941,114.61,-0.0035711,19.117,114.56,106.2,109.53
40.5165,6.3043,-0.036078,28.431,120.61,-0.0039323,19.125,120.56,111.81,115.39
41.9395,6.294,-0.039479,28.664,124.88,-0.0043221,19.091,124.81,115.99,119.55
43.9395,6.2995,-0.043425,29.011,130.88,-0.0047299,19.109,130.82,121.79,125.48
45.3052,6.294,-0.044279,28.998,134.97,-0.004823,19.092,134.95,125.72,129.54
47.3052,6.3138,-0.04691,29.452,140.97,-0.005121,19.152,140.95,131.53,135.44
49.3052,6.3197,-0.049889,29.745,146.97,-0.0054405,19.17,146.92,137.25,141.28
51.3052,6.3169,-0.052927,30.017,152.97,-0.0057655,19.162,152.92,142.88,147.25
53.3052,6.3207,-0.056007,30.338,158.97,-0.0060942,19.172,158.89,148.66,153.12
55.3052,6.3257,-0.059396,30.809,164.97,-0.0064589,19.19,164.85,154.35,158.94
57.3052,6.342,-0.062762,30.626,170.97,-0.0068249,19.239,170.94,160.22,164.84
59.3052,6.33,-0.066618,30.845,176.97,-0.007249,19.203,176.96,165.99,170.75
61.3052,6.3387,-0.071314,30.825,182.97,-0.0077742,19.227,182.95,171.71,176.65
63.3052,6.3436,-0.076594,31.376,188.97,-0.0083297,19.244,188.89,177.38,182.46
65.3052,6.3637,-0.078162,31.227,194.97,-0.0084954,19.301,194.96,183.26,188.45
67.3052,6.3745,-0.080598,31.151,200.97,-0.0087699,19.337,201.0,189.09,194.45
69.3052,6.3794,-0.084387,31.325,206.97,-0.0091831,19.353,206.99,194.81,200.31
71.3052,6.3929,-0.087929,31.462,212.97,-0.0095667,19.393,213.01,200.44,206.13
73.3052,6.4031,-0.091353,31.69,218.97,-0.0099369,19.424,219.0,206.24,212.04
74.564,6.4037,-0.094151,31.88,222.75,-0.010241,19.425,222.75,209.81,215.74
76.1057,6.411,-0.099852,31.8,227.37,-0.010847,19.448,227.41,214.26,220.35
78.1057,6.3973,-0.10109,32.366,233.37,-0.010991,19.406,233.35,220.01,226.18
80.1057,6.4142,-0.10477,32.442,239.37,-0.011387,19.459,239.39,225.8,232.11
82.1057,6.428,-0.1082,32.715,245.37,-0.011756,19.5,245.35,231.56,237.99
84.1057,6.4379,-0.11198,32.887,251.37,-0.012171,19.531,251.35,237.34,243.92
86.1057,6.4407,-0.11939,33.012,257.37,-0.012968,19.537,257.32,243.0,249.8
88.1057,6.4354,-0.12033,32.987,263.37,-0.013063,19.522,263.39,248.84,255.69
90.1057,6.4426,-0.12386,33.296,269.37,-0.013459,19.543,269.33,254.61,261.52
92.1057,6.4507,-0.12737,33.067,275.37,-0.01383,19.57,275.45,260.5,267.5
94.1057,6.4478,-0.13083,33.376,281.37,-0.014205,19.558,281.38,266.4,273.47
96.1057,6.5637,-0.13664,33.357,287.37,-0.014861,19.91,287.41,272.34,279.38
98.1057,7.5689,-0.13488,33.361,293.37,-0.014636,22.957,293.4,278.36,285.34
100.1057,8.2035,-0.13349,33.622,299.32,-0.014496,24.885,299.34,284.77,291.4
102.1057,8.3714,-0.13258,31.922,300.0,-0.014399,25.393,300.21,287.18,293.3
104.1057,8.3935,-0.13212,31.488,300.0,-0.014353,25.461,300.13,288.08,293.73
106.0967,8.4035,-0.13551,31.564,300.0,-0.014698,25.49,300.03,288.53,293.82
107.1212,8.3968,-0.13348,31.204,300.0,-0.014487,25.473,300.07,288.76,293.94
109.1212,8.4057,-0.13314,30.905,300.0,-0.014456,25.497,300.05,289.08,294.05
111.1212,8.4071,-0.133,31.053,300.0,-0.014441,25.503,300.0,289.33,294.1
113.1212,8.4162,-0.13623,31.311,300.0,-0.014771,25.53,299.96,289.6,294.19
115.1212,8.4083,-0.13363,30.484,300.0,-0.01451,25.507,300.14,289.88,294.38
117.1212,8.4147,-0.13364,30.87,300.0,-0.014515,25.525,300.01,289.92,294.34
119.1212,8.4177,-0.13395,30.442,300.0,-0.014556,25.534,300.04,290.15,294.5
121.1212,8.4169,-0.13521,30.775,300.0,-0.014674,25.53,299.97,290.19,294.38
123.1212,8.4073,-0.13382,30.343,300.0,-0.014527,25.503,300.05,290.39,294.58
125.1212,8.4093,-0.13371,30.092,300.0,-0.014516,25.509,300.04,290.49,294.56
127.1212,8.4094,-0.1336,29.934,300.0,-0.014512,25.51,300.1,290.62,294.68
129.1212,8.4146,-0.1353,29.96,300.0,-0.014676,25.523,300.04,290.66,294.65
131.1212,8.4063,-0.1341,30.184,300.0,-0.014556,25.501,299.96,290.72,294.56
133.1212,8.4049,-0.13353,29.95,300.0,-0.01449,25.495,300.02,290.87,294.7
135.1212,8.3977,-0.13692,30.098,300.0,-0.014844,25.474,299.98,290.91,294.68
137.1212,8.4001,-0.13417,29.976,300.0,-0.01456,25.482,300.02,291.02,294.74
138.7207,8.4009,-0.13404,30.001,300.0,-0.014556,25.482,300.02,291.08,294.76
140.7207,8.4034,-0.13597,30.152,300.0,-0.014773,25.49,299.96,291.09,294.73
142.7207,8.3928,-0.13434,30.012,300.0,-0.014578,25.458,299.99,291.24,294.84
144.7207,8.3965,-0.1339,29.799,300.0,-0.014531,25.471,300.03,291.3,294.86
145.2861,8.3662,-0.0014428,29.795,236.25,-5.4582e-05,25.397,300.13,291.38,294.95
145.2881,8.3169,-0.00459,25.039,0.44961,-0.0003447,25.205,300.13,291.39,294.94
145.2901,8.2875,-0.0051692,19.092,0.0008423,-0.00074489,25.13,300.13,291.39,294.93
145.2921,8.3358,0.00067764,13.145,1.5862e-06,-0.0006338,25.267,300.12,291.39,294.91
145.2941,8.339,-0.0018471,7.1986,2.9715e-09,0.0001753,25.269,300.11,291.39,294.9
145.2961,8.3447,-0.0012864,1.252,5.5956e-12,1.4466e-05,25.288,300.11,291.39,294.89
145.2981,8.348,-0.0021718,0.0,1.0536e-14,-3.576e-05,25.297,300.11,291.37,294.93
145.3001,8.3934,-0.0022884,0.0,1.9739e-17,-0.00029469,25.449,300.11,291.34,295.0
145.3021,8.3654,0.00056798,0.0,3.7168e-20,-0.00052385,25.35,300.11,291.32,295.06
145.3041,8.371,-0.0024109,0.0,6.963099999999999e-23,-7.4249e-05,25.343,300.11,291.29,295.12
145.3061,8.3768,-0.00019741,0.0,1.3111e-25,2.7411e-05,25.361,300.11,291.27,295.18
145.3081,8.3888,-0.0036517,0.0,2.4685999999999997e-28,-7.5838e-05,25.42,300.09,291.27,295.16
145.3101,8.3847,-0.0011252,0.0,4.6248e-31,-0.00014356,25.378,300.07,291.28,295.13
145.3121,8.3946,0.00028623,0.0,8.7076e-34,-0.00056702,25.44,300.06,291.3,295.09
145.3141,8.4019,-0.0012513,0.0,1.6394e-36,2.6596e-05,25.444,300.04,291.31,295.05
145.3161,8.4148,-0.00064031,0.0,3.0714e-39,-0.00017324,25.462,300.02,291.32,295.02
145.3181,8.4102,-0.0051491,0.0,5.7818e-42,-1.3805e-08,25.476,300.01,291.32,294.99
145.3201,8.4254,-0.00079526,0.0,9.8091e-45,1.667e-05,25.514,300.0,291.32,294.97
145.3221,8.4397,0.0002029,0.0,0.0,-0.00048405,25.547,300.0,291.32,294.94
145.3241,8.4345,-0.00046447,0.0,0.0,-2.1333e-05,25.547,299.99,291.32,294.92
145.3261,8.4395,-0.0010216,0.0,0.0,-0.00022101,25.587,299.98,291.32,294.89
145.3281,8.4549,-0.0034425,0.0,0.0,0.00021212,25.616,300.0,291.33,294.9
145.3301,8.4476,-0.00089799,0.0,0.0,0.00021189,25.611,300.03,291.35,294.91
145.3321,8.4497,-0.0019576,0.0,0.0,-0.00063484,25.607,300.05,291.36,294.92
145.3341,8.4565,-0.00099606,0.0,0.0,-0.00013042,25.643,300.08,291.37,294.93
145.3361,8.459,-0.00099214,0.0,0.0,-0.00036317,25.651,300.1,291.38,294.94
145.3381,8.461,-0.0028536,0.0,0.0,0.00023563,25.631,300.11,291.4,294.94
145.3401,8.4587,-0.00076072,0.0,0.0,0.0002326,25.666,300.12,291.43,294.94
145.3421,8.4574,-0.0019082,0.0,0.0,-0.00052639,25.662,300.12,291.45,294.93
145.3441,8.4458,-0.0012363,0.0,0.0,-0.00024355,25.645,300.13,291.48,294.92
145.3461,8.4377,-0.00076232,0.0,0.0,-0.00042564,25.606,300.14,291.5,294.92
145.3481,8.4023,-0.0050155,0.0,0.0,1.3001e-05,25.531,300.28,291.45,294.89
145.3501,8.3921,-0.0020118,0.0,0.0,0.00010077,25.475,300.47,291.36,294.86
145.3521,10.947,0.017259,0.0,0.0,0.0014727,32.669,300.66,291.27,294.83
145.35409,24.407,0.078298,0.0,0.0,0.0074031,72.811,300.85,291.19,294.8
145.35609,32.919,0.18621,0.0,0.0,0.019382,99.296,301.04,291.1,294.77
145.35809,38.252,0.34016,0.0,0.0,0.037989,115.78,301.49,291.81,294.76
145.36009,41.969,0.48571,0.0,0.0,0.054191,127.03,302.05,292.81,294.76
145.36209,44.025,0.6412,0.0,0.0,0.071821,133.35,302.61,293.82,294.76
145.36409,45.169,0.81632,0.0,0.0,0.092335,136.9,303.16,294.82,294.76
145.36609,45.809,0.97912,0.0,0.0,0.11148,138.9,303.72,295.83,294.76
145.36809,46.318,1.1307,0.0,0.0,0.13124,140.46,304.51,297.45,294.77
145.37009,46.757,1.2931,0.0,0.0,0.15104,141.79,305.4,299.31,294.77
145.37209,47.07,1.4561,0.0,0.0,0.17152,142.73,306.29,301.17,294.78
145.37409,47.324,1.6211,0.0,0.0,0.19244,143.54,307.17,303.03,294.79
145.37609,47.536,1.776,0.0,0.0,0.21238,144.14,308.06,304.89,294.79
145.37809,47.751,1.9323,0.0,0.0,0.23471,144.8,308.95,306.29,294.78
145.38009,47.975,2.1043,0.0,0.0,0.25791,145.5,309.85,307.5,294.76
145.38209,48.16,2.2692,0.0,0.0,0.28071,146.06,310.75,308.71,294.74
145.38409,48.334,2.4331,0.0,0.0,0.3037,146.57,311.64,309.92,294.73
145.38609,48.535,2.5936,0.0,0.0,0.3265,147.22,312.54,311.13,294.71
145.38809,48.673,2.7405,0.0,0.0,0.34979,147.62,313.25,311.91,294.69
145.39009,48.809,2.886,0.0,0.0,0.37176,148.03,313.89,312.49,294.68
145.39209,48.94,3.0238,0.0,0.0,0.39306,148.41,314.52,313.08,294.67
145.39409,49.045,3.1575,0.0,0.0,0.41365,148.75,315.16,313.66,294.66
145.39609,49.204,3.2855,0.0,0.0,0.4334,149.23,315.79,314.25,294.64
145.39809,49.311,3.4032,0.0,0.0,0.45414,149.53,316.34,314.63,294.65
145.40009,49.476,3.5248,0.0,0.0,0.47452,150.06,316.84,314.93,294.66
145.40209,49.648,3.6407,0.0,0.0,0.49435,150.55,317.34,315.22,294.67
145.40409,49.831,3.7656,0.0,0.0,0.51515,151.13,317.84,315.51,294.69
145.40609,50.016,3.8879,0.0,0.0,0.53575,151.69,318.34,315.81,294.7
145.40809,50.185,4.0049,0.0,0.0,0.55802,152.2,318.77,316.15,294.69
145.41009,50.311,4.1257,0.0,0.0,0.58055,152.6,319.16,316.51,294.68
145.41209,50.423,4.239,0.0,0.0,0.60212,152.93,319.56,316.88,294.67
145.41409,50.54,4.3549,0.0,0.0,0.62356,153.29,319.96,317.25,294.66
145.41609,50.655,4.4657,0.0,0.0,0.64396,153.64,320.35,317.61,294.64
145.41809,50.755,4.5767,0.0,0.0,0.66698,153.93,320.61,317.99,294.65
145.42009,50.833,4.6808,0.0,0.0,0.68808,154.2,320.81,318.38,294.66
145.42209,50.898,4.782,0.0,0.0,0.71033,154.38,321.0,318.76,294.67
145.42409,50.965,4.8881,0.0,0.0,0.73194,154.62,321.2,319.14,294.69
145.42609,51.019,4.9871,0.0,0.0,0.75157,154.75,321.39,319.53,294.7
145.42809,51.113,5.0835,0.0,0.0,0.77363,155.05,321.48,319.82,294.72
145.43009,51.152,5.1824,0.0,0.0,0.79556,155.16,321.51,320.05,294.75
145.43209,51.212,5.2746,0.0,0.0,0.81859,155.37,321.54,320.29,294.78
145.43409,51.279,5.3721,0.0,0.0,0.84034,155.54,321.57,320.53,294.81
145.43609,51.361,5.467,0.0,0.0,0.86119,155.8,321.6,320.77,294.84
145.43809,51.401,5.5587,0.0,0.0,0.88398,155.92,321.6,320.95,294.86
145.44009,51.46,5.6496,0.0,0.0,0.9059,156.11,321.58,321.11,294.87
145.44209,51.495,5.7376,0.0,0.0,0.93082,156.22,321.56,321.27,294.87
145.44409,51.514,5.8251,0.0,0.0,0.95239,156.29,321.55,321.43,294.88
145.44609,51.519,5.9111,0.0,0.0,0.97342,156.28,321.53,321.59,294.88
145.44809,51.534,5.9942,0.0,0.0,0.99572,156.31,321.49,321.71,294.91
145.45009,51.589,6.0744,0.0,0.0,1.017,156.49,321.45,321.81,294.94
145.45209,51.657,6.1498,0.0,0.0,1.0413,156.68,321.41,321.92,294.97
145.45409,51.705,6.232,0.0,0.0,1.0643,156.83,321.37,322.02,295.0
145.45609,51.742,6.3086,0.0,0.0,1.0845,156.96,321.32,322.12,295.03
145.45809,51.795,6.3841,0.0,0.0,1.1067,157.11,321.28,322.12,295.07
145.46009,51.889,6.4597,0.0,0.0,1.1288,157.39,321.24,322.06,295.11
145.46209,51.997,6.5299,0.0,0.0,1.1539,157.7,321.2,322.0,295.15
145.46409,52.037,6.6047,0.0,0.0,1.1771,157.86,321.15,321.94,295.2
145.46609,52.102,6.675,0.0,0.0,1.1984,158.03,321.11,321.88,295.24
145.46809,52.163,6.7461,0.0,0.0,1.2208,158.25,321.06,321.76,295.27
145.47009,52.251,6.8101,0.0,0.0,1.2411,158.51,321.02,321.59,295.3
145.47209,52.323,6.8742,0.0,0.0,1.2668,158.72,320.97,321.43,295.33
145.47409,52.434,6.9398,0.0,0.0,1.2898,159.04,320.92,321.26,295.37
145.47609,52.549,7.0043,0.0,0.0,1.3119,159.39,320.87,321.1,295.4
145.47809,52.638,7.0684,0.0,0.0,1.3334,159.67,320.81,320.89,295.43
145.48009,52.761,7.1304,0.0,0.0,1.355,160.04,320.75,320.65,295.47
145.48209,52.879,7.1894,0.0,0.0,1.3819,160.4,320.69,320.42,295.5
145.48409,52.979,7.2545,0.0,0.0,1.4074,160.7,320.63,320.18,295.54
145.48609,53.052,7.3096,0.0,0.0,1.4283,160.92,320.57,319.94,295.58
145.48809,53.099,7.3722,0.0,0.0,1.4521,161.05,320.5,319.67,295.6
145.49009,53.163,7.428,0.0,0.0,1.4726,161.25,320.43,319.37,295.62
145.49208,53.276,7.4768,0.0,0.0,1.4978,161.6,320.36,319.07,295.64
145.49408,53.413,7.531,0.0,0.0,1.5218,162.01,320.28,318.77,295.66
145.49608,53.542,7.5828,0.0,0.0,1.5445,162.39,320.21,318.47,295.68
145.49808,53.66,7.6379,0.0,0.0,1.5668,162.75,320.15,318.12,295.7
145.50008,51.602,7.6593,0.0,0.0,1.5743,156.64,320.09,317.72,295.72
145.50208,50.223,7.6571,0.0,0.0,1.5774,152.48,320.04,317.32,295.75
145.50408,49.222,7.661,0.0,0.0,1.5798,149.39,319.98,316.93,295.77
145.50608,48.357,7.6595,0.0,0.0,1.5804,146.76,319.93,316.53,295.8
145.50808,47.784,7.6664,0.0,0.0,1.5811,144.99,319.86,316.1,295.82
145.51008,47.382,7.6713,0.0,0.0,1.5799,143.76,319.78,315.64,295.85
145.51208,47.12,7.6696,0.0,0.0,1.5826,142.96,319.7,315.18,295.87
145.51408,46.937,7.6716,0.0,0.0,1.5842,142.39,319.62,314.72,295.89
145.51608,46.825,7.6733,0.0,0.0,1.5874,142.05,319.54,314.27,295.92
145.51808,46.746,7.6791,0.0,0.0,1.5874,141.8,319.42,313.82,295.93
145.52008,46.686,7.6808,0.0,0.0,1.5851,141.63,319.26,313.38,295.94
145.52208,46.635,7.6845,0.0,0.0,1.5893,141.47,319.1,312.94,295.95
145.52408,46.536,7.6896,0.0,0.0,1.5917,141.17,318.94,312.5,295.95
145.52608,46.396,7.6839,0.0,0.0,1.5925,140.76,318.79,312.06,295.96
145.52808,46.239,7.6907,0.0,0.0,1.5937,140.27,318.62,311.65,295.99
145.53008,46.042,7.6936,0.0,0.0,1.5913,139.67,318.46,311.26,296.04
145.53208,45.836,7.6946,0.0,0.0,1.5932,139.04,318.29,310.87,296.09
145.53408,45.635,7.6968,0.0,0.0,1.5941,138.44,318.13,310.48,296.14
145.53608,45.418,7.6922,0.0,0.0,1.5964,137.78,317.96,310.09,296.18
145.53808,45.191,7.6966,0.0,0.0,1.5973,137.09,317.81,309.72,296.23
145.54008,44.972,7.7003,0.0,0.0,1.5951,136.43,317.65,309.37,296.28
145.54208,44.757,7.7002,0.0,0.0,1.5958,135.78,317.5,309.02,296.33
145.54408,44.543,7.7012,0.0,0.0,1.5958,135.12,317.35,308.68,296.38
145.54608,44.326,7.699,0.0,0.0,1.5994,134.43,317.2,308.33,296.43
145.54808,44.126,7.7028,0.0,0.0,1.6002,133.84,317.05,307.97,296.46
145.55008,43.927,7.7031,0.0,0.0,1.5967,133.24,316.91,307.61,296.47
145.55208,43.73,7.703,0.0,0.0,1.5968,132.67,316.77,307.25,296.48
145.55408,43.534,7.7029,0.0,0.0,1.596,132.07,316.63,306.89,296.5
145.55608,43.345,7.7012,0.0,0.0,1.6004,131.51,316.49,306.53,296.51
145.55808,43.153,7.7042,0.0,0.0,1.6006,130.9,316.34,306.2,296.53
145.56008,42.972,7.7025,0.0,0.0,1.5974,130.36,316.19,305.88,296.57
145.56208,42.8,7.7052,0.0,0.0,1.5978,129.85,316.04,305.56,296.61
145.56408,42.646,7.7074,0.0,0.0,1.5974,129.36,315.88,305.24,296.64
145.56608,42.488,7.7016,0.0,0.0,1.5998,128.88,315.73,304.93,296.68
145.56808,42.347,7.7026,0.0,280.58,1.6004,128.46,315.56,304.6,296.72
145.57008,42.218,7.7059,0.0,299.96,1.5999,128.06,315.38,304.27,296.77
145.57208,42.064,7.7065,0.0,300.0,1.5988,127.59,315.2,303.94,296.82
145.57408,41.712,7.705,0.0,300.0,1.596,126.56,315.01,303.61,296.87
145.57608,40.504,7.701,0.0,300.0,1.5995,123.02,314.83,303.28,296.92
145.57808,38.438,7.6988,0.0,300.0,1.5984,116.85,314.64,303.04,296.96
145.58008,35.542,7.6929,0.0,300.0,1.5943,108.11,314.46,302.88,296.98
145.58208,31.829,7.6889,0.0,300.0,1.5907,96.918,314.27,302.72,297.0
145.58408,21.668,7.6874,0.0,300.0,1.5877,67.947,314.08,302.56,297.03
145.58608,4.8924,7.5997,0.0,300.0,1.5518,13.969,313.89,302.4,297.05
145.58808,6.9253,7.6352,0.0,300.0,1.5696,22.049,313.71,302.32,297.08
145.59008,9.4532,7.6338,0.0,300.0,1.5677,28.99,313.55,302.32,297.11
145.59208,8.4221,7.6244,0.0,300.0,1.5607,25.202,313.4,302.32,297.14
145.59408,7.4798,7.6209,0.0,300.0,1.5567,22.627,313.24,302.32,297.17
145.59608,7.8464,7.6174,0.0,300.0,1.5597,24.017,313.08,302.32,297.2
145.59808,8.2111,7.6164,0.0,300.0,1.56,25.033,312.94,302.31,297.24
145.60008,8.1769,7.6185,0.0,300.0,1.5612,24.87,312.83,302.31,297.29
145.60208,8.0066,7.6237,0.0,300.0,1.5611,24.331,312.72,302.3,297.34
145.60408,7.9615,7.621,0.0,300.0,1.5575,24.181,312.61,302.3,297.39
145.60608,8.0122,7.6183,0.0,300.0,1.5594,24.322,312.5,302.29,297.44
145.60808,8.0111,7.6187,0.0,300.0,1.5602,24.326,312.41,302.26,297.48
145.61008,7.9481,7.6161,0.0,300.0,1.5608,24.108,312.32,302.21,297.52
145.61208,7.9826,7.62,0.0,300.0,1.5602,24.217,312.23,302.17,297.56
145.61408,7.9855,7.6226,0.0,300.0,1.5582,24.206,312.15,302.12,297.59
145.61608,7.9776,7.6192,0.0,300.0,1.5593,24.199,312.06,302.07,297.63
145.61808,7.9632,7.6195,0.0,300.0,1.5604,24.177,311.98,302.01,297.66
145.62008,7.9777,7.6169,0.0,300.0,1.5614,24.194,311.89,301.94,297.69
145.62208,7.9728,7.6211,0.0,300.0,1.5614,24.209,311.81,301.87,297.71
145.62408,7.9865,7.6221,0.0,300.0,1.5586,24.242,311.72,301.81,297.73
145.62608,7.9903,7.6195,0.0,300.0,1.559,24.233,311.64,301.74,297.76
145.62808,8.0275,7.619,0.0,300.0,1.5589,24.311,311.54,301.69,297.79
145.63007,8.0465,7.6181,0.0,300.0,1.5623,24.369,311.44,301.67,297.84
145.63207,8.0257,7.6203,0.0,300.0,1.5615,24.315,311.34,301.64,297.89
145.63407,8.0493,7.6198,0.0,300.0,1.5579,24.397,311.23,301.62,297.94
145.63607,8.0867,7.6221,0.0,300.0,1.5602,24.49,311.13,301.59,297.99
145.63807,8.0907,7.6223,0.0,300.0,1.5599,24.516,311.03,301.54,298.04
145.64007,8.0826,7.6159,0.0,300.0,1.5612,24.493,310.93,301.46,298.09
145.64207,8.0798,7.621,0.0,300.0,1.5623,24.484,310.83,301.37,298.14
145.64407,8.0885,7.6234,0.0,300.0,1.56,24.507,310.73,301.29,298.19
145.64607,8.1246,7.6223,0.0,300.0,1.5596,24.591,310.64,301.2,298.24
145.64807,8.1608,7.6224,0.0,300.0,1.5592,24.722,310.56,301.11,298.27
145.65007,8.1532,7.6188,0.0,300.0,1.5622,24.714,310.5,301.0,298.3
145.65207,8.159,7.6192,0.0,300.0,1.5618,24.713,310.45,300.9,298.32
145.65407,8.1505,7.6219,0.0,300.0,1.56,24.706,310.39,300.79,298.35
145.65607,8.1582,7.6224,0.0,300.0,1.5597,24.739,310.34,300.69,298.37
145.65807,8.184,7.6228,0.0,300.0,1.559,24.788,310.28,300.58,298.39
145.66007,8.1729,7.6166,0.0,300.0,1.561,24.779,310.21,300.46,298.41
145.66207,8.1728,7.6217,0.0,300.0,1.5631,24.77,310.14,300.35,298.43
145.66407,8.1874,7.6218,0.0,300.0,1.5606,24.805,310.08,300.23,298.45
145.66607,8.2311,7.6224,0.0,300.0,1.5597,24.974,310.01,300.11,298.47
145.66807,8.2684,7.6225,0.0,300.0,1.5586,25.085,309.93,299.99,298.49
145.67007,8.2347,7.6187,0.0,300.0,1.562,25.0,309.84,299.85,298.5
145.67207,8.2257,7.6217,0.0,300.0,1.5627,24.977,309.75,299.71,298.52
145.67407,8.2712,7.6216,0.0,300.0,1.5613,25.112,309.66,299.56,298.54
145.67607,8.3212,7.6239,0.0,300.0,1.5603,25.236,309.57,299.42,298.56
145.67807,8.351,7.626,0.0,300.0,1.5598,25.324,309.47,299.31,298.58
145.68007,8.3714,7.6211,0.0,300.0,1.5628,25.43,309.38,299.24,298.6
145.68207,8.3802,7.623,0.0,300.0,1.5633,25.406,309.29,299.18,298.61
145.68407,8.4195,7.6201,0.0,300.0,1.5611,25.553,309.2,299.11,298.63
145.68607,8.4987,7.6251,0.0,300.0,1.5619,25.834,309.11,299.04,298.65
145.68807,8.5157,7.6277,0.0,300.0,1.5603,25.852,309.02,298.99,298.68
145.69007,8.5202,7.6229,0.0,300.0,1.5625,25.896,308.93,298.95,298.71
145.69207,8.5524,7.6234,0.0,300.0,1.5633,26.014,308.85,298.91,298.75
145.69407,8.5696,7.6228,0.0,300.0,1.563,26.041,308.76,298.88,298.79
145.69607,8.5563,7.6244,0.0,300.0,1.5613,26.0,308.68,298.84,298.82
145.69807,8.5191,7.6258,0.0,300.0,1.5593,25.877,308.6,298.77,298.86
145.70007,8.5013,7.6236,0.0,300.0,1.5621,25.866,308.52,298.65,298.9
145.70207,8.538,7.6248,0.0,300.0,1.5633,25.959,308.45,298.53,298.93
145.70407,8.4996,7.6214,0.0,300.0,1.563,25.85,308.38,298.4,298.97
145.70607,8.485,7.6246,0.0,300.0,1.5617,25.812,308.3,298.28,299.01
145.70807,8.4843,7.6263,0.0,300.0,1.5599,25.822,308.23,298.16,299.04
145.71007,8.4741,7.6245,0.0,300.0,1.5624,25.793,308.15,298.05,299.06
145.71207,8.4789,7.6235,0.0,300.0,1.5624,25.788,308.07,297.94,299.09
145.71407,8.4621,7.6236,0.0,300.0,1.5644,25.711,307.99,297.83,299.11
145.71607,8.4564,7.6262,0.0,300.0,1.5632,25.7,307.91,297.72,299.14
145.71807,8.4414,7.6248,0.0,300.0,1.5597,25.666,307.84,297.61,299.17
145.72007,8.4473,7.6249,0.0,300.0,1.5618,25.676,307.78,297.52,299.2
145.72207,8.4449,7.627,0.0,300.0,1.5632,25.652,307.73,297.42,299.24
145.72407,8.4453,7.6219,0.0,300.0,1.564,25.638,307.67,297.32,299.28
145.72607,8.4499,7.6237,0.0,300.0,1.5627,25.633,307.62,297.22,299.31
145.72807,8.4409,7.6264,0.0,300.0,1.5606,25.619,307.56,297.12,299.35
145.73007,8.4434,7.6266,0.0,300.0,1.5622,25.636,307.49,296.99,299.37
145.73207,8.4482,7.6264,0.0,300.0,1.5616,25.646,307.43,296.87,299.4
145.73407,8.4669,7.6221,0.0,300.0,1.5641,25.682,307.36,296.75,299.42
145.73607,8.4626,7.6249,0.0,300.0,1.5641,25.657,307.29,296.63,299.45
145.73807,8.4643,7.6264,0.0,300.0,1.5613,25.682,307.22,296.51,299.46
145.74007,8.4687,7.6265,0.0,300.0,1.5618,25.666,307.12,296.41,299.47
145.74207,8.4767,7.6259,0.0,300.0,1.5615,25.701,307.03,296.32,299.48
145.74407,8.4922,7.6225,0.0,300.0,1.5641,25.722,306.94,296.22,299.48
145.74607,8.5015,7.6257,0.0,300.0,1.5646,25.735,306.85,296.12,299.49
145.74807,8.5149,7.6273,0.0,300.0,1.5621,25.784,306.76,296.02,299.5
145.75007,8.5386,7.6251,0.0,300.0,1.5609,25.857,306.68,295.92,299.51
145.75207,8.552,7.6266,0.0,300.0,1.5612,25.901,306.59,295.81,299.52
145.75407,8.5645,7.6221,0.0,300.0,1.5642,25.912,306.5,295.71,299.53
145.75607,8.5801,7.6244,0.0,300.0,1.5639,25.968,306.42,295.6,299.55
145.75807,8.6154,7.6283,0.0,300.0,1.563,26.07,306.34,295.5,299.56
145.76007,8.6197,7.6262,0.0,300.0,1.5611,26.091,306.26,295.4,299.56
145.76207,8.6365,7.6281,0.0,300.0,1.5614,26.152,306.18,295.3,299.57
145.76407,8.6434,7.6247,0.0,300.0,1.5649,26.158,306.1,295.21,299.57
145.76607,8.6587,7.6269,0.0,300.0,1.5652,26.218,306.02,295.11,299.58
145.76806,8.6837,7.6275,0.0,300.0,1.5635,26.282,305.94,295.01,299.59
145.77006,8.6986,7.6296,0.0,300.0,1.5626,26.331,305.87,294.91,299.62
145.77206,8.7047,7.6291,0.0,300.0,1.5613,26.363,305.79,294.81,299.65
145.77406,8.7128,7.6275,0.0,300.0,1.5659,26.388,305.72,294.72,299.69
145.77606,8.7258,7.6277,0.0,300.0,1.5653,26.417,305.65,294.62,299.72
145.77806,8.7332,7.6253,0.0,300.0,1.5634,26.471,305.58,294.52,299.75
145.78006,8.7498,7.6302,0.0,300.0,1.5634,26.516,305.52,294.44,299.79
145.78206,8.7503,7.6321,0.0,300.0,1.5624,26.502,305.47,294.35,299.82
145.78406,8.7522,7.6262,0.0,300.0,1.5644,26.559,305.41,294.27,299.86
145.78606,8.7506,7.6276,0.0,300.0,1.5655,26.542,305.36,294.18,299.9
145.78806,8.7659,7.6281,0.0,300.0,1.5648,26.581,305.3,294.1,299.93
145.79006,8.7612,7.6307,0.0,300.0,1.5637,26.589,305.21,294.02,299.95
145.79206,8.7485,7.6311,0.0,300.0,1.5619,26.559,305.13,293.94,299.96
145.79406,8.7594,7.628,0.0,300.0,1.5646,26.608,305.04,293.86,299.98
145.79606,8.7492,7.6287,0.0,300.0,1.5656,26.572,304.95,293.78,300.0
145.79806,8.7436,7.6267,0.0,300.0,1.5649,26.555,304.87,293.69,300.02
145.80006,8.7225,7.6289,0.0,300.0,1.5636,26.49,304.78,293.57,300.03
145.80206,8.7208,7.6316,0.0,300.0,1.5622,26.498,304.68,293.45,300.04
145.80406,8.7039,7.6266,0.0,300.0,1.5638,26.47,304.59,293.34,300.05
145.80606,8.7002,7.6295,0.0,300.0,1.5656,26.453,304.5,293.22,300.07
145.80806,8.6806,7.6278,0.0,300.0,1.566,26.388,304.42,293.11,300.08
145.81006,8.6722,7.6312,0.0,300.0,1.5647,26.367,304.37,293.02,300.1
145.81206,8.6549,7.6315,0.0,300.0,1.5622,26.333,304.32,292.93,300.12
145.81406,8.642,7.6287,0.0,300.0,1.5638,26.287,304.27,292.84,300.14
145.81606,8.6388,7.6304,0.0,300.0,1.5651,26.286,304.23,292.74,300.15
145.81806,8.6083,7.6271,0.0,300.0,1.5662,26.18,304.17,292.66,300.17
145.82006,8.5895,7.6298,0.0,300.0,1.5649,26.135,304.1,292.58,300.16
145.82206,8.5929,7.6314,0.0,300.0,1.5627,26.113,304.04,292.5,300.15
145.82406,8.5739,7.6317,0.0,300.0,1.5648,26.077,303.97,292.42,300.15
145.82606,8.5686,7.6301,0.0,300.0,1.564,26.036,303.9,292.34,300.14
145.82806,8.5632,7.6268,0.0,300.0,1.5665,26.025,303.84,292.25,300.14
145.83006,8.5668,7.6293,0.0,300.0,1.5653,26.062,303.77,292.15,300.13
145.83206,8.5511,7.6296,0.0,300.0,1.5621,25.963,303.7,292.06,300.12
145.83406,8.5536,7.6291,0.0,300.0,1.563,25.969,303.63,291.96,300.12
145.83606,8.5514,7.6307,0.0,300.0,1.5639,25.951,303.57,291.86,300.11
145.83806,8.5436,7.6239,0.0,300.0,1.5649,25.935,303.5,291.76,300.11
145.84006,8.5363,7.629,0.0,300.0,1.5659,25.894,303.42,291.67,300.14
145.84206,8.5404,7.6293,0.0,300.0,1.5629,25.887,303.35,291.58,300.17
145.84406,8.5583,7.6287,0.0,300.0,1.5628,25.95,303.28,291.49,300.21
145.84606,8.5507,7.63,0.0,300.0,1.5627,25.918,303.2,291.4,300.24
145.84806,8.5625,7.6271,0.0,300.0,1.5663,25.95,303.13,291.31,300.26
145.85006,8.5652,7.6283,0.0,300.0,1.5657,25.948,303.06,291.23,300.28
145.85206,8.5816,7.6299,0.0,300.0,1.5637,25.986,303.0,291.16,300.3
145.85406,8.5814,7.631,0.0,300.0,1.5637,25.997,302.93,291.09,300.32
145.85606,8.5978,7.6309,0.0,300.0,1.5627,26.031,302.86,291.01,300.34
145.85806,8.6016,7.6273,0.0,300.0,1.5663,26.049,302.8,290.94,300.35
145.86006,8.6181,7.6298,0.0,300.0,1.5664,26.078,302.74,290.85,300.35
145.86206,8.63,7.6304,0.0,300.0,1.5645,26.136,302.69,290.77,300.35
145.86406,8.651,7.6312,0.0,300.0,1.5634,26.178,302.63,290.68,300.35
145.86606,8.6575,7.6326,0.0,300.0,1.5634,26.204,302.58,290.59,300.35
145.86806,8.6793,7.6271,0.0,300.0,1.5657,26.248,302.52,290.51,300.35
145.87006,8.694,7.6281,0.0,300.0,1.5659,26.291,302.46,290.45,300.36
145.87206,8.702,7.6303,0.0,300.0,1.5652,26.333,302.4,290.39,300.37
145.87406,8.7059,7.6312,0.0,300.0,1.564,26.371,302.34,290.33,300.37
145.87606,8.7269,7.632,0.0,300.0,1.5623,26.401,302.27,290.27,300.38
145.87806,8.7331,7.6265,0.0,300.0,1.5651,26.423,302.22,290.21,300.39
145.88006,8.7423,7.6298,0.0,300.0,1.5662,26.458,302.17,290.16,300.4
145.88206,8.7416,7.6287,0.0,300.0,1.5651,26.476,302.13,290.11,300.42
145.88406,8.7581,7.6315,0.0,300.0,1.5642,26.547,302.09,290.06,300.44
145.88606,8.7551,7.6342,0.0,300.0,1.5631,26.531,302.05,290.01,300.46
145.88806,8.7686,7.63,0.0,300.0,1.566,26.558,302.0,289.96,300.47
145.89006,8.7727,7.6303,0.0,300.0,1.5666,26.598,301.97,289.87,300.47
145.89206,8.7779,7.629,0.0,300.0,1.5655,26.618,301.93,289.77,300.46
145.89406,8.7674,7.6314,0.0,300.0,1.5645,26.608,301.89,289.68,300.46
145.89606,8.7679,7.6343,0.0,300.0,1.5633,26.597,301.86,289.59,300.45
145.89806,8.7755,7.6303,0.0,300.0,1.5655,26.632,301.81,289.5,300.45
145.90006,8.7462,7.6313,0.0,300.0,1.5663,26.529,301.72,289.44,300.46
145.90206,8.7513,7.6309,0.0,300.0,1.567,26.569,301.63,289.38,300.47
145.90406,8.7485,7.6325,0.0,300.0,1.5652,26.589,301.53,289.32,300.48
145.90605,8.7325,7.6324,0.0,300.0,1.5624,26.51,301.44,289.26,300.49
145.90805,8.7181,7.6317,0.0,300.0,1.5656,26.521,301.35,289.2,300.51
145.91005,8.7264,7.6336,0.0,300.0,1.5669,26.524,301.28,289.13,300.52
145.91205,8.6985,7.6294,0.0,300.0,1.5669,26.418,301.21,289.06,300.53
145.91405,8.6784,7.6324,0.0,300.0,1.5655,26.406,301.13,288.99,300.54
145.91605,8.6986,7.6334,0.0,300.0,1.5635,26.453,301.06,288.93,300.56
145.91805,8.6681,7.6325,0.0,300.0,1.5657,26.341,300.99,288.86,300.57
145.92005,8.6485,7.6328,0.0,300.0,1.5657,26.305,300.95,288.78,300.57
145.92205,8.6368,7.629,0.0,300.0,1.5675,26.272,300.9,288.7,300.58
145.92405,8.622,7.6315,0.0,300.0,1.5666,26.217,300.86,288.62,300.59
145.92605,8.6002,7.6308,0.0,300.0,1.5626,26.136,300.82,288.54,300.59
145.92805,8.594,7.632,0.0,300.0,1.5648,26.13,300.77,288.46,300.6
145.93005,8.5903,7.6326,0.0,300.0,1.5647,26.122,300.72,288.41,300.63
145.93205,8.5719,7.6259,0.0,300.0,1.566,26.07,300.66,288.35,300.65
145.93405,8.5729,7.631,0.0,300.0,1.5667,26.045,300.61,288.3,300.67
145.93605,8.556,7.6315,0.0,300.0,1.5632,26.004,300.55,288.24,300.7
145.93805,8.5521,7.6319,0.0,300.0,1.5648,25.987,300.5,288.19,300.72
145.94005,8.537,7.6331,0.0,300.0,1.5644,25.917,300.47,288.16,300.73
145.94205,8.5428,7.6282,0.0,300.0,1.5669,25.942,300.44,288.13,300.75
145.94405,8.5336,7.6316,0.0,300.0,1.5674,25.895,300.41,288.1,300.76
145.94605,8.5256,7.6314,0.0,300.0,1.5637,25.888,300.38,288.07,300.77
145.94805,8.5353,7.6333,0.0,300.0,1.5645,25.892,300.35,288.04,300.78
145.95005,8.531,7.6326,0.0,300.0,1.5635,25.882,300.3,288.03,300.77
145.95205,8.5301,7.628,0.0,300.0,1.5667,25.874,300.26,288.03,300.77
145.95405,8.5418,7.6297,0.0,300.0,1.5664,25.879,300.22,288.02,300.76
145.95605,8.5565,7.6319,0.0,300.0,1.5653,25.907,300.18,288.01,300.76
145.95805,8.5393,7.6327,0.0,300.0,1.5646,25.887,300.13,288.0,300.75
145.96005,8.5473,7.6326,0.0,300.0,1.5633,25.89,300.07,287.93,300.74
145.96205,8.57,7.6288,0.0,300.0,1.5664,25.944,300.01,287.86,300.74
145.96405,8.5768,7.6312,0.0,300.0,1.5673,25.962,299.95,287.8,300.73
145.96605,8.5864,7.6307,0.0,300.0,1.5649,25.99,299.89,287.73,300.73
145.9676,8.6944,7.633,0.0,300.0,1.5659,26.455,299.84,287.68,300.72
147.9676,7.435,7.6386,0.0010288,2.2889,1.5686,22.555,261.07,256.16,255.27
149.6492,7.1642,7.6461,5.2383e-06,3.3204,1.5719,21.731,230.67,230.15,224.35
151.6492,6.9898,7.6547,9.8138e-09,5.317,1.5759,21.203,201.99,203.78,195.13
153.6492,6.8865,7.6627,1.8383e-11,7.317,1.5796,20.888,179.27,182.05,172.18
155.6492,6.7961,7.6693,3.4443e-14,9.317,1.5827,20.617,160.96,164.17,153.81
157.2138,6.7286,7.6745,2.5264e-16,10.882,1.5851,20.41,148.86,152.02,141.67
159.2138,6.6505,7.6803,4.733200000000001e-19,12.882,1.5878,20.175,135.33,138.6,128.3
161.2138,6.5752,7.6861,8.8662e-22,14.882,1.5904,19.944,123.74,126.97,116.92
163.2138,6.5051,7.6911,1.6612e-24,16.882,1.5927,19.733,113.67,116.93,107.13
165.2138,6.4048,7.6956,3.1119e-27,18.882,1.5949,19.428,104.83,108.03,98.75
167.2138,6.3134,7.6996,5.8299e-30,20.882,1.5968,19.152,97.233,100.24,91.44
169.2138,6.2103,7.7032,1.0901999999999999e-32,22.882,1.5984,18.837,90.39,93.397,85.097
171.2138,6.0886,7.7063,2.0421000000000002e-35,24.882,1.5999,18.471,84.308,87.179,79.316
173.2138,5.957,7.7097,3.826e-38,26.882,1.6015,18.07,78.637,81.446,73.976
175.2138,5.8341,7.7126,7.1618e-41,28.882,1.6028,17.699,73.951,76.703,69.686
177.2138,5.7163,7.7152,1.285e-42,30.882,1.604,17.338,69.575,72.209,65.644
179.2138,5.6012,7.7175,1.285e-42,32.882,1.6051,16.991,65.548,68.027,61.782
181.1696,5.4888,7.7196,1.285e-42,34.846,1.6061,16.651,62.102,64.642,58.671
183.1696,5.3855,7.7215,1.285e-42,36.837,1.607,16.336,58.87,61.21,55.591
185.1696,5.2768,7.7235,1.285e-42,38.837,1.608,16.008,56.005,58.351,53.086
187.1696,5.1816,7.7253,1.285e-42,40.837,1.6088,15.718,53.268,55.542,50.555
189.0021,5.096,7.7268,1.285e-42,42.67,1.6095,15.458,50.922,53.207,48.433
191.0021,4.9974,7.7283,1.285e-42,44.67,1.6102,15.16,48.806,50.998,46.594
193.0021,4.9094,7.7295,1.2435,46.67,1.6108,14.893,46.664,48.781,44.601
195.0021,4.8346,7.7297,24.209,48.67,1.6109,14.667,46.906,51.468,43.227
197.0021,4.7668,7.73,25.877,49.986,1.611,14.458,49.063,57.184,43.942
199.0021,4.6833,7.7297,24.622,50.0,1.6108,14.208,49.752,58.422,45.049
201.0021,4.6091,7.7319,23.12,50.0,1.6118,13.981,50.035,58.302,45.929
203.0021,4.5287,7.7292,22.272,50.0,1.6107,13.738,50.122,58.089,46.344
205.0021,4.4619,7.7325,21.864,50.0,1.6122,13.535,50.108,57.882,46.464
207.0021,4.3746,7.7279,21.955,50.0,1.6101,13.272,50.015,57.901,46.539
209.0021,4.3091,7.7325,21.731,50.0,1.6123,13.071,50.027,57.923,46.564
211.0021,4.2426,7.7274,21.912,50.0,1.6098,12.871,50.007,58.093,46.603
213.0021,4.173,7.7326,21.898,50.0,1.6123,12.657,49.988,58.119,46.656
214.7931,4.1186,7.7285,21.986,50.0,1.6102,12.494,49.968,58.201,46.667
216.7931,4.057,7.7326,22.208,50.0,1.6122,12.307,49.991,58.377,46.738
218.7906,3.9851,7.7294,21.967,50.0,1.6106,12.09,49.994,58.544,46.824
220.7906,3.9341,7.7327,21.893,50.0,1.6123,11.934,50.033,58.731,46.866
222.7906,3.8645,7.7315,21.66,50.0,1.6117,11.724,50.033,58.63,46.967
224.7906,3.8057,7.7322,21.718,50.0,1.6121,11.544,50.035,58.726,47.025
226.7906,3.7477,7.7326,21.341,50.0,1.6122,11.371,50.041,58.74,47.068
228.7906,3.7366,7.7321,21.165,50.0,1.612,11.333,50.026,58.627,47.107
230.7906,3.741,7.7327,21.528,50.0,1.6123,11.35,49.986,58.759,47.053
232.7906,3.7408,7.732,21.742,50.0,1.6119,11.347,49.99,58.761,47.09
234.7906,3.7485,7.7332,22.087,50.0,1.6125,11.372,49.931,58.689,47.04
236.7906,3.7466,7.7291,22.534,50.0,1.6107,11.364,49.939,58.829,47.041
238.7906,3.756,7.7335,22.446,50.0,1.6128,11.396,49.975,58.915,47.045
240.7906,3.7649,7.734,22.407,50.0,1.6129,11.419,49.974,58.892,47.058
242.7906,3.748,7.7315,22.432,50.0,1.6119,11.371,49.998,58.957,47.095
244.7906,3.7312,7.7337,22.255,50.0,1.6128,11.317,50.016,58.969,47.093
246.4173,3.7165,7.7341,22.353,50.0,1.6129,11.273,49.98,58.988,47.111
248.4173,3.7002,7.7303,22.389,50.0,1.611,11.225,50.025,59.122,47.116
249.5791,3.7009,7.73,22.316,50.0,1.6112,11.228,49.991,58.979,47.107
251.5791,3.6972,7.7342,22.058,50.0,1.613,11.214,50.019,58.915,47.145
253.5791,3.6862,7.7344,22.267,50.0,1.6132,11.183,50.003,59.027,47.132
255.5791,3.6649,7.7344,22.181,50.0,1.6131,11.118,49.997,58.964,47.135
257.5791,4.2118,7.7345,0.14382,0.36993,1.6131,12.777,49.611,54.378,49.894
259.5791,4.2868,7.736,0.00026943,0.00069302,1.6138,13.004,49.416,52.739,50.13
261.5791,4.2738,7.7419,4.9117e-07,1.2983e-06,1.6168,12.965,48.765,51.368,49.532
262.5791,4.3281,7.742,2.1258e-08,5.6194e-08,1.6168,13.13,48.447,50.751,49.264