File: examples/dan-msc-case-studies/CS4/data/01 raw data/hyde_test_004.csv
Time(sec),Force(kN),Jaw(mm),PowAngle(deg),PTemp,Strain,Stress(MPa),TC1(C),TC2(C),TC3(C),TC4(C)
0.0,3.4237,-9.8648,0.0,0.0,-0.76568,4.0661,24.048,24.577,24.208,24.524
0.6,3.3725,-0.0012905,0.0,1.6207,-0.00012015,4.0029,24.05,24.647,24.216,24.537
1.2,3.3254,0.000185,0.0,3.4207,1.0686e-05,3.9454,24.046,24.654,24.242,24.546
1.8,3.2716,-0.0001141,0.0,5.2207,-2.5399e-05,3.8812,24.061,24.675,24.213,24.52
2.4,3.2287,-0.00037175,0.0,7.0207,-3.2297e-05,3.8315,24.071,24.678,24.24,24.546
3.0,3.2112,-0.00042026,0.0,8.8207,-6.4149e-06,3.8123,24.045,24.616,24.228,24.546
3.6,3.1939,-0.00045303,0.0,10.621,-1.2147e-05,3.792,24.059,24.627,24.263,24.525
4.2,3.1732,-0.00052476,0.0,12.421,-5.1215e-05,3.7653,24.058,24.655,24.255,24.52
4.8,3.1474,-0.00057341,0.0,14.221,-6.1706e-05,3.7343,24.016,24.63,24.232,24.537
5.2768,3.1508,-0.00047081,0.0,15.651,-7.0395e-05,3.7387,24.059,24.642,24.207,24.551
5.8768,3.1307,-0.00067335,0.0,17.451,-7.8572e-05,3.7137,24.033,24.607,24.202,24.516
6.4768,3.1203,-0.00062179,0.0,19.251,-6.1935e-05,3.702,24.049,24.654,24.21,24.523
7.0768,3.1171,-0.00066179,0.0,21.051,-4.9228e-05,3.6997,24.057,24.62,24.217,24.534
7.6768,3.1084,-0.0006968,0.0,22.851,-4.4256e-05,3.6899,24.007,24.601,24.193,24.502
8.2768,3.1099,-0.00057444,5.2994,24.651,-4.1407e-05,3.6902,24.006,24.573,24.196,24.559
8.8768,3.1,-0.00039578,24.119,26.451,-3.1557e-05,3.6778,24.093,24.682,24.217,24.464
9.4768,3.1098,-0.00055764,33.304,28.251,-6.6067e-05,3.69,24.699,25.28,24.258,24.651
10.0768,3.1297,-0.00070582,36.812,30.051,-0.00011576,3.7155,26.332,26.833,24.391,25.094
10.5804,3.12,-0.0011421,37.412,31.562,-0.00012552,3.702,28.31,28.609,24.589,25.945
11.1804,3.1273,-0.0010262,37.118,33.362,-0.00010892,3.7121,30.85,37.609,25.043,27.357
11.7804,3.1338,-0.0022691,37.466,35.162,-0.00028716,3.7199,33.123,37.706,25.672,29.006
12.3804,3.1328,-0.0028569,37.302,36.962,-0.00033754,3.7172,35.374,37.706,26.465,30.737
12.9804,3.1279,-0.0034751,37.498,38.762,-0.00039401,3.7109,37.451,37.305,27.4,32.461
13.5804,3.1261,-0.003882,37.374,40.562,-0.00043559,3.7094,39.589,39.009,28.504,34.308
14.1804,3.1288,-0.0038641,37.099,42.362,-0.00039906,3.7138,41.666,40.87,29.711,36.187
14.7804,3.1383,-0.0043048,36.968,44.162,-0.00043354,3.7239,43.681,42.633,30.921,38.027
15.3804,3.1317,-0.0053007,36.928,45.962,-0.00057651,3.7157,45.563,44.229,32.246,39.894
15.9804,3.1292,-0.0059231,37.284,47.762,-0.0006477,3.713,47.39,45.877,33.64,41.746
16.5804,3.1327,-0.0062653,37.238,49.562,-0.00069264,3.7178,49.269,47.512,35.066,43.594
17.1804,3.1317,-0.0067778,37.675,51.362,-0.00077762,3.7166,51.042,49.228,36.496,45.496
17.7804,3.1316,-0.0069552,37.647,53.162,-0.00079674,3.7169,52.92,50.935,38.025,47.371
18.3804,3.1307,-0.0074607,37.977,54.962,-0.00084034,3.715,54.662,52.651,39.569,49.233
18.9804,3.1341,-0.0070396,38.635,56.762,-0.00079246,3.7184,56.34,54.408,41.119,51.14
19.5804,3.1217,-0.0093205,38.587,58.562,-0.0010262,3.7055,58.215,56.178,42.774,53.163
20.1804,3.1246,-0.010106,38.706,60.362,-0.0010818,3.7094,60.073,57.95,44.407,55.109
20.7804,3.1349,-0.010626,39.198,62.162,-0.001159,3.7207,61.851,59.68,46.07,57.157
21.3804,3.1345,-0.011083,39.287,63.962,-0.0012195,3.719,63.671,61.419,47.787,59.263
21.9804,3.1379,-0.011023,39.279,65.762,-0.0012229,3.7225,65.501,63.265,49.588,61.266
22.5804,3.1356,-0.011887,39.535,67.562,-0.0013468,3.7218,67.246,65.037,51.327,63.471
23.1804,3.1422,-0.01245,39.587,69.362,-0.0014322,3.7302,69.128,66.835,53.127,65.519
23.7804,3.1454,-0.013846,39.902,71.162,-0.0015557,3.7323,70.921,68.671,54.905,67.724
24.3804,3.1423,-0.014686,40.047,72.962,-0.0016373,3.7286,72.7,70.453,56.692,69.842
24.9804,3.1406,-0.015495,40.338,74.762,-0.0017095,3.7265,74.441,72.251,58.631,71.974
25.5804,3.1402,-0.015986,40.366,76.562,-0.0017354,3.728,76.334,74.139,60.459,74.195
26.1804,3.1472,-0.016205,40.518,78.362,-0.0017834,3.7372,78.157,75.947,62.517,76.378
26.7804,3.1525,-0.01647,40.53,80.162,-0.001805,3.741,79.982,77.718,64.401,78.525
27.3804,3.1492,-0.018654,40.567,81.962,-0.0020786,3.7365,81.793,79.569,66.274,80.65
27.9804,3.1429,-0.01944,40.638,83.762,-0.0021929,3.7288,83.581,81.295,68.24,82.757
28.5804,3.1503,-0.020308,41.091,85.562,-0.0022857,3.7401,85.363,83.181,70.155,84.952
29.1804,3.1609,-0.021004,40.745,87.362,-0.0023367,3.7514,87.256,85.012,72.133,87.061
29.7804,3.1643,-0.021302,40.937,89.162,-0.0023658,3.7548,89.051,86.852,74.029,89.169
30.3804,3.1634,-0.022313,40.904,90.962,-0.0024579,3.7532,90.892,88.737,76.074,91.264
30.9804,3.1583,-0.021461,41.168,92.762,-0.0023555,3.748,92.664,90.577,78.036,93.448
31.5804,3.1582,-0.024671,41.189,94.562,-0.002729,3.7497,94.459,92.31,80.012,95.547
32.1804,3.1718,-0.025485,41.218,96.362,-0.0028269,3.7642,96.282,94.142,81.956,97.608
32.7804,3.1705,-0.026317,41.396,98.162,-0.0029335,3.7617,98.003,96.006,83.898,99.643
33.3804,3.1763,-0.026711,41.199,99.962,-0.0030019,3.7695,99.888,97.891,85.802,101.76
33.9804,3.1725,-0.027053,41.407,101.76,-0.0030205,3.7644,101.66,99.749,87.732,103.8
34.5804,3.1842,-0.027175,41.348,103.56,-0.0030142,3.7794,103.5,101.6,89.661,105.84
35.1804,3.1863,-0.03007,41.586,105.36,-0.0033458,3.7808,105.29,103.42,91.551,107.86
35.7804,3.1855,-0.031171,41.586,107.16,-0.0034263,3.7797,107.07,105.23,93.48,109.85
36.3804,3.182,-0.032082,41.761,108.96,-0.0035403,3.7759,108.85,107.05,95.327,111.85
36.9804,3.1921,-0.032591,41.802,110.76,-0.0036075,3.7887,110.62,108.83,97.203,113.85
37.5143,3.2027,-0.032756,41.844,112.37,-0.003634,3.7999,112.24,110.4,98.825,115.6
38.1143,3.1911,-0.034223,41.984,114.16,-0.0037756,3.7866,114.03,112.24,100.68,117.55
38.7143,3.1863,-0.035092,41.958,115.96,-0.0038831,3.7816,115.87,114.1,102.52,119.53
39.3143,3.2003,-0.036923,42.355,117.76,-0.0040774,3.7992,117.58,115.91,104.26,121.47
39.9143,3.2146,-0.03776,42.314,119.56,-0.0041842,3.8145,119.48,117.76,106.15,123.47
40.5143,3.2155,-0.038593,42.299,121.36,-0.0042953,3.8151,121.3,119.61,107.97,125.44
41.1143,3.2129,-0.038835,42.387,123.16,-0.0043518,3.8124,123.05,121.38,109.83,127.36
41.7143,3.2199,-0.04008,42.38,124.96,-0.0044676,3.8217,124.86,123.18,111.64,129.38
42.3143,3.2365,-0.038793,42.476,126.76,-0.0043237,3.842,126.68,125.02,113.48,131.31
42.9143,3.2682,-0.041966,42.47,128.56,-0.0046579,3.8779,128.5,126.79,115.29,133.21
43.4274,3.3018,-0.041964,42.525,130.1,-0.0046699,3.9188,130.05,128.32,116.76,134.89
44.0274,3.361,-0.04225,42.405,131.9,-0.0046958,3.9892,131.84,130.09,118.59,136.82
44.6274,3.4428,-0.042005,42.547,133.7,-0.0046441,4.0855,133.66,131.89,120.37,138.72
45.2274,3.5243,-0.04145,42.403,135.5,-0.0045648,4.1813,135.53,133.69,122.14,140.56
45.8274,3.5935,-0.040693,42.397,137.3,-0.0044754,4.2646,137.36,135.49,123.92,142.46
46.4274,3.6537,-0.042847,41.986,139.1,-0.0047435,4.3374,139.25,137.4,125.69,144.35
47.0274,3.7076,-0.04334,42.338,140.9,-0.0048275,4.4006,140.98,139.2,127.42,146.05
47.6274,3.7341,-0.043904,42.249,142.7,-0.0049068,4.4311,142.77,140.85,129.19,147.89
48.2274,3.752,-0.044339,42.367,144.5,-0.0049271,4.4504,144.54,142.57,130.93,149.6
48.8274,3.7621,-0.044211,42.389,146.3,-0.0049154,4.4647,146.31,144.43,132.65,151.37
49.4274,3.782,-0.044741,42.397,148.1,-0.0049413,4.4895,148.13,146.18,134.36,153.24
50.0274,3.7916,-0.047316,42.489,149.9,-0.0052166,4.5,149.88,147.97,136.03,155.02
50.6274,3.8018,-0.048422,42.566,151.7,-0.0053571,4.5107,151.67,149.79,137.76,156.81
51.2274,3.8053,-0.04937,42.741,153.5,-0.005466,4.5149,153.4,151.53,139.41,158.59
51.8274,3.8092,-0.04986,42.803,155.3,-0.0055301,4.5209,155.22,153.31,141.08,160.45
52.4274,3.8228,-0.049728,42.774,157.1,-0.0055497,4.5378,157.06,155.04,142.81,162.28
53.0274,3.8327,-0.050288,43.112,158.9,-0.0055658,4.5473,158.81,156.81,144.5,164.18
53.6274,3.8259,-0.053487,43.0,160.7,-0.0059368,4.5395,160.62,158.76,146.22,166.08
54.2274,3.8277,-0.054604,42.976,162.5,-0.0060546,4.5411,162.51,160.53,147.93,168.04
54.8274,3.8288,-0.055719,42.994,164.3,-0.0061466,4.544,164.28,162.27,149.64,169.88
55.4274,3.8431,-0.056082,43.112,166.1,-0.0062048,4.5616,166.0,163.99,151.34,171.76
56.0274,3.8536,-0.056029,43.255,167.9,-0.0062119,4.5722,167.85,165.88,153.1,173.65
56.6274,3.8451,-0.056267,43.285,169.7,-0.0062266,4.5614,169.65,167.61,154.84,175.47
57.2274,3.8411,-0.059687,43.208,171.5,-0.0066578,4.5583,171.49,169.35,156.56,177.36
57.8274,3.8452,-0.060999,43.354,173.3,-0.0067754,4.5648,173.22,171.08,158.31,179.27
58.4274,3.8602,-0.062047,43.439,175.1,-0.0068922,4.582,175.03,172.8,160.05,181.18
59.0274,3.8644,-0.062681,43.354,176.9,-0.0069314,4.5848,176.84,174.51,161.82,182.95
59.6274,3.8611,-0.062794,43.527,178.7,-0.00693,4.5812,178.57,176.13,163.5,184.81
60.2274,3.8603,-0.062846,43.544,180.5,-0.006927,4.5808,180.45,178.03,165.3,186.71
60.8274,3.8627,-0.066476,43.451,182.3,-0.0073666,4.5851,182.32,179.79,167.07,188.64
61.4274,3.879,-0.067685,43.483,184.1,-0.0075258,4.6033,184.09,181.56,168.77,190.54
62.0274,3.8756,-0.068904,43.547,185.9,-0.0076735,4.5984,185.87,183.26,170.5,192.3
62.6274,3.8759,-0.06961,43.528,187.7,-0.0077187,4.5996,187.66,185.16,172.33,194.23
63.2274,3.8704,-0.06971,43.733,189.5,-0.0077384,4.5942,189.43,186.89,174.14,196.12
63.8274,3.8877,-0.070352,43.535,191.3,-0.007746,4.6153,191.31,188.7,175.85,198.02
64.4274,3.8908,-0.073826,43.729,193.1,-0.008151,4.6175,193.06,190.51,177.68,199.85
65.0274,3.8936,-0.075025,43.571,194.9,-0.0082986,4.6183,194.92,192.32,179.38,201.78
65.6274,3.8917,-0.076177,43.85,196.7,-0.0084429,4.6172,196.65,194.07,181.1,203.64
66.2274,3.8969,-0.076656,43.841,198.5,-0.008518,4.6254,198.48,195.92,182.88,205.5
66.8274,3.9101,-0.076663,43.961,200.3,-0.0085183,4.6414,200.26,197.74,184.63,207.45
67.4274,3.915,-0.076964,43.79,202.1,-0.0085092,4.6459,202.14,199.57,186.45,209.39
68.0274,3.9122,-0.081143,43.575,203.9,-0.0089917,4.6414,203.98,201.44,188.2,211.31
68.6274,3.9123,-0.082545,43.547,205.7,-0.0091091,4.6422,205.84,203.2,190.06,213.29
69.2274,3.9211,-0.083618,43.501,207.5,-0.0092313,4.6549,207.62,205.05,191.84,215.22
69.8274,3.9373,-0.08366,43.596,209.3,-0.0092443,4.6733,209.33,206.72,193.65,217.07
70.3431,3.9276,-0.084484,43.82,210.85,-0.0093687,4.6606,210.78,208.23,195.19,218.67
70.9431,3.9389,-0.082824,43.868,212.65,-0.0091889,4.6751,212.6,210.1,196.96,220.56
71.5431,3.9467,-0.088335,43.973,214.45,-0.0097486,4.6851,214.42,211.87,198.82,222.53
72.1431,3.9539,-0.089514,43.919,216.25,-0.0098984,4.6918,216.23,213.67,200.65,224.5
72.7431,3.9565,-0.090174,43.981,218.05,-0.009983,4.6935,217.99,215.52,202.47,226.37
73.3431,3.9578,-0.089824,44.09,219.85,-0.0099539,4.6985,219.78,217.36,204.29,228.28
73.9431,3.9679,-0.090496,44.334,221.65,-0.010033,4.7102,221.48,219.16,206.18,230.22
74.5431,3.9776,-0.094184,44.104,223.45,-0.010437,4.7203,223.41,221.07,208.01,232.17
75.1431,3.9817,-0.095718,44.234,225.25,-0.010606,4.7243,225.17,222.95,209.82,234.13
75.7431,3.9815,-0.096812,44.139,227.05,-0.010687,4.7248,226.99,224.7,211.73,236.02
76.1632,3.9801,-0.096759,44.16,228.31,-0.010725,4.7224,228.23,225.97,213.04,237.4
76.7632,3.9918,-0.097448,44.239,230.11,-0.010828,4.7376,230.08,227.94,214.89,239.27
77.3632,4.0025,-0.096004,44.142,231.91,-0.010649,4.7509,231.94,229.93,216.75,241.18
77.9632,3.9988,-0.10182,44.089,233.71,-0.011265,4.7451,233.71,231.79,218.62,243.17
78.5632,4.0065,-0.10336,44.25,235.51,-0.011404,4.7526,235.48,233.64,220.47,245.07
79.1632,4.0039,-0.10424,44.139,237.31,-0.011504,4.7519,237.33,235.53,222.38,246.97
79.7632,4.0136,-0.10398,44.079,239.11,-0.011501,4.7647,239.21,237.43,224.2,249.05
80.3632,4.022,-0.10293,43.995,240.91,-0.011372,4.7732,240.99,239.14,226.1,250.96
80.9632,4.0228,-0.10874,44.077,242.71,-0.012066,4.7738,242.68,240.95,227.96,252.8
81.5632,4.0186,-0.1104,44.098,244.51,-0.012223,4.7672,244.51,242.79,229.82,254.7
82.1632,4.0294,-0.11155,44.451,246.31,-0.012349,4.7825,246.18,244.72,231.71,256.6
82.7632,4.032,-0.11104,44.348,248.11,-0.012266,4.7864,248.06,246.63,233.6,258.54
83.3632,4.0418,-0.11142,44.135,249.91,-0.012246,4.7974,249.94,248.56,235.46,260.55
83.9632,4.0426,-0.11669,44.312,251.71,-0.012892,4.7968,251.72,250.4,237.35,262.43
84.5632,4.0365,-0.11825,44.097,253.51,-0.013073,4.7889,253.57,252.21,239.25,264.35
85.1632,4.0422,-0.1192,44.228,255.31,-0.013202,4.7978,255.33,254.03,241.12,266.3
85.7632,4.0554,-0.11864,44.267,257.11,-0.013135,4.8142,257.12,255.97,242.98,268.23
86.3632,4.0595,-0.11847,44.294,258.91,-0.013072,4.8183,258.93,257.73,244.91,270.11
86.9632,4.0549,-0.12447,44.416,260.71,-0.013761,4.8103,260.7,259.69,246.73,272.07
87.5632,4.0463,-0.12621,44.307,262.51,-0.013916,4.8015,262.52,261.57,248.62,274.08
88.1632,4.0598,-0.12688,44.169,264.31,-0.013994,4.8187,264.36,263.45,250.57,276.07
88.7632,4.072,-0.12679,44.088,266.11,-0.014017,4.8334,266.22,265.3,252.51,277.98
89.3632,4.0758,-0.12524,44.15,267.91,-0.013882,4.8359,267.99,267.13,254.38,279.9
89.9632,4.0692,-0.13201,44.276,269.71,-0.014621,4.8276,269.71,269.06,256.32,281.79
90.5632,4.0665,-0.13362,44.283,271.51,-0.014764,4.8258,271.5,271.0,258.34,283.72
91.1632,4.0751,-0.13361,44.685,273.31,-0.014761,4.8377,273.19,272.9,260.39,285.67
91.7632,4.0869,-0.13564,44.603,275.11,-0.014955,4.8501,275.05,274.79,262.35,287.64
92.3632,4.0829,-0.13791,44.257,276.91,-0.015221,4.8441,276.96,276.77,264.47,289.66
92.9632,4.0771,-0.14007,44.311,278.71,-0.01546,4.8372,278.76,278.69,266.49,291.59
93.5632,4.0784,-0.14114,44.08,280.51,-0.015587,4.841,280.63,280.21,268.51,293.45
94.1632,4.0899,-0.1404,44.562,282.31,-0.015552,4.8561,282.25,282.03,270.59,295.33
94.7632,4.0951,-0.13918,44.571,284.11,-0.015384,4.8603,284.07,284.01,272.66,297.28
95.3632,4.0895,-0.14658,44.596,285.91,-0.016188,4.8528,285.84,285.95,274.76,299.21
95.9632,4.0923,-0.14832,44.572,287.71,-0.016353,4.8553,287.66,287.93,276.85,301.21
96.5632,4.0867,-0.14822,44.604,289.51,-0.016326,4.8508,289.49,289.85,279.01,303.17
97.1632,4.1029,-0.15006,44.482,291.31,-0.016544,4.8702,291.36,291.91,281.34,305.13
97.7632,4.1013,-0.15279,44.473,293.11,-0.016872,4.8671,293.11,293.83,283.94,307.03
98.3632,4.0984,-0.1549,44.604,294.91,-0.017136,4.8629,294.89,295.76,286.77,308.91
98.9632,4.0996,-0.15607,44.726,296.71,-0.01724,4.8648,296.63,297.74,293.09,310.82
99.5632,4.1033,-0.15546,44.966,298.51,-0.017173,4.8704,298.4,299.7,300.52,312.72
100.1632,4.1139,-0.1543,44.014,299.99,-0.017021,4.8831,300.26,301.77,305.94,314.67
100.7632,4.0983,-0.16082,39.459,300.0,-0.017709,4.8631,301.88,303.37,309.79,316.59
101.3632,4.0686,-0.16069,36.383,300.0,-0.01772,4.8268,302.45,303.98,312.2,317.43
101.9632,4.0446,-0.15954,35.597,300.0,-0.017604,4.7999,302.11,303.86,312.94,317.07
102.5632,4.05,-0.15917,35.741,300.0,-0.01759,4.808,301.66,303.6,313.12,316.09
103.0713,4.0651,-0.16021,36.01,300.0,-0.017673,4.8223,301.26,303.47,313.18,315.09
103.6713,4.0618,-0.16137,36.321,300.0,-0.017781,4.8201,300.94,303.27,313.18,314.03
104.2713,4.0705,-0.16166,36.682,300.0,-0.017822,4.8326,300.66,303.13,313.08,313.1
104.8713,4.0866,-0.16055,36.887,300.0,-0.01772,4.8505,300.49,302.96,312.9,312.32
105.4713,4.0865,-0.15922,36.662,300.0,-0.017584,4.8489,300.42,302.88,312.77,311.65
106.0713,4.0789,-0.16361,36.958,300.0,-0.01806,4.8397,300.24,302.73,312.57,311.14
106.6713,4.0843,-0.16441,36.959,300.0,-0.018143,4.8483,300.19,302.69,312.14,310.69
107.2713,4.0917,-0.16436,37.073,300.0,-0.018096,4.8575,300.14,302.57,311.43,310.34
107.8713,4.1008,-0.16449,37.089,300.0,-0.018127,4.8665,300.12,302.51,311.16,310.02
108.4713,4.0987,-0.16584,36.921,300.0,-0.018311,4.8623,300.12,302.53,311.09,309.75
108.9973,4.1017,-0.16697,37.078,300.0,-0.018391,4.8691,300.05,302.43,311.55,309.49
109.5973,4.1023,-0.16749,36.797,300.0,-0.018468,4.8685,300.09,302.46,311.37,309.33
110.1973,4.1081,-0.16664,36.637,300.0,-0.018401,4.8747,300.09,302.48,311.16,309.14
110.7973,4.0898,-0.16583,36.629,300.0,-0.018302,4.8527,300.09,302.37,310.91,308.9
111.3973,4.1013,-0.16979,36.845,300.0,-0.018725,4.867,300.01,302.37,310.87,308.74
111.9973,4.1072,-0.17049,36.972,300.0,-0.018809,4.8758,300.03,302.35,310.75,308.53
112.5973,4.1184,-0.17053,36.46,300.0,-0.018771,4.8874,300.06,302.34,310.55,308.36
113.1973,4.1098,-0.17052,36.673,300.0,-0.018788,4.8759,300.02,302.27,310.37,308.2
113.7973,4.1053,-0.17169,36.434,300.0,-0.018948,4.8702,300.06,302.24,310.17,308.05
114.3973,4.0964,-0.17308,36.715,300.0,-0.019104,4.8637,300.01,302.23,309.96,307.88
114.9973,4.1106,-0.17348,36.31,300.0,-0.019161,4.8792,300.09,302.23,309.85,307.74
115.5973,4.1204,-0.17275,36.271,300.0,-0.019049,4.8892,300.08,302.15,309.64,307.63
116.1973,4.1108,-0.17207,35.971,300.0,-0.018961,4.8777,300.06,302.18,309.48,307.44
116.7973,4.1048,-0.17569,36.114,300.0,-0.019344,4.8713,299.98,302.09,309.24,307.26
117.3973,4.1118,-0.1762,35.948,300.0,-0.019416,4.8807,300.0,302.03,309.01,307.07
117.9973,4.1205,-0.17628,35.612,300.0,-0.019424,4.8921,299.96,301.92,308.82,306.82
118.5973,4.1183,-0.17567,35.413,300.0,-0.0194,4.8862,299.8,301.78,308.63,306.61
119.1973,4.1077,-0.17588,34.734,300.0,-0.019454,4.8736,299.63,301.6,308.29,306.28
119.7973,4.106,-0.17813,35.39,300.0,-0.019646,4.8732,299.41,301.32,308.04,305.97
120.3973,4.1155,-0.17885,35.814,300.0,-0.019716,4.886,299.24,301.25,307.61,305.67
120.9973,4.1234,-0.17874,35.632,300.0,-0.019669,4.8937,299.28,301.15,307.41,305.44
121.5973,4.1183,-0.17917,35.546,300.0,-0.019736,4.8855,299.35,301.16,307.28,305.31
122.1973,4.1055,-0.18056,35.499,300.0,-0.019901,4.8708,299.32,301.13,307.06,305.16
122.7973,4.111,-0.1814,35.354,300.0,-0.020029,4.8793,299.34,301.08,306.9,305.02
123.3973,4.1235,-0.18193,35.503,300.0,-0.020073,4.8945,299.32,301.07,306.71,304.9
123.9973,4.1235,-0.18157,34.811,300.0,-0.020019,4.8931,299.25,301.01,306.56,304.79
124.5973,4.1185,-0.18177,34.887,300.0,-0.020006,4.8859,299.13,300.82,306.37,304.58
125.1973,4.1094,-0.18362,35.097,300.0,-0.02021,4.876,298.97,300.68,306.16,304.38
125.7973,4.1083,-0.18428,34.561,300.0,-0.020303,4.8769,298.88,300.56,305.87,304.2
126.3973,4.1176,-0.18454,34.634,300.0,-0.020352,4.8886,298.73,300.33,305.62,303.94
126.9973,4.1249,-0.18375,34.817,300.0,-0.020283,4.8942,298.58,300.2,305.36,303.64
127.5973,4.1259,-0.18347,34.712,300.0,-0.02021,4.8947,298.52,300.09,305.14,303.43
128.1973,4.1175,-0.18631,34.704,300.0,-0.020544,4.8868,298.53,300.06,304.95,303.26
128.7973,4.1124,-0.18704,35.97,300.0,-0.020586,4.8818,298.54,300.04,304.78,303.16
129.3973,4.135,-0.18799,37.187,300.0,-0.020699,4.9079,298.83,300.31,304.7,303.14
129.9973,4.1343,-0.18717,36.395,300.0,-0.020624,4.9057,299.38,300.79,304.94,303.52
130.5973,4.111,-0.18682,35.425,300.0,-0.02059,4.8787,299.7,301.02,305.16,303.86
131.1973,4.1206,-0.18976,34.976,300.0,-0.020939,4.8902,299.73,301.02,305.28,304.09
131.7973,4.1271,-0.1904,35.113,300.0,-0.02098,4.8991,299.73,301.02,305.28,304.08
132.3973,4.132,-0.19084,34.811,300.0,-0.021016,4.904,299.75,300.94,305.19,303.99
132.9973,4.1271,-0.19007,34.863,300.0,-0.020908,4.8963,299.7,300.88,305.17,303.95
133.5973,4.1213,-0.19012,34.911,300.0,-0.020919,4.8901,299.67,300.86,305.04,303.82
134.1973,4.118,-0.19229,34.869,300.0,-0.02119,4.8878,299.67,300.85,304.95,303.74
134.7973,4.1323,-0.19276,34.867,300.0,-0.021271,4.9052,299.63,300.83,304.87,303.65
135.3073,4.1231,-0.19343,34.712,300.0,-0.021261,4.8932,299.69,300.76,304.74,303.55
135.9073,4.1232,-0.19329,34.698,300.0,-0.021276,4.8942,299.63,300.77,304.71,303.46
136.5073,4.1343,-0.19312,34.652,300.0,-0.021284,4.9068,299.71,300.79,304.6,303.37
137.1073,4.1349,-0.19249,34.716,300.0,-0.021274,4.9064,299.69,300.76,304.54,303.37
137.7073,4.1229,-0.19546,34.626,300.0,-0.021545,4.8913,299.71,300.81,304.49,303.31
138.3073,4.1245,-0.19603,34.467,300.0,-0.021603,4.8944,299.66,300.76,304.38,303.22
138.9073,4.132,-0.19618,34.49,300.0,-0.021592,4.9054,299.64,300.73,304.31,303.15
139.5073,4.135,-0.19548,34.265,300.0,-0.021501,4.9079,299.72,300.7,304.25,303.13
140.1073,4.1386,-0.1944,34.09,300.0,-0.021421,4.9106,299.68,300.68,304.14,303.01
140.7073,4.1254,-0.19804,34.528,300.0,-0.021832,4.8954,299.63,300.57,304.07,302.97
141.3073,4.121,-0.19857,34.019,300.0,-0.021899,4.8913,299.66,300.57,303.96,302.86
141.75,4.1258,-0.19886,34.198,300.0,-0.02189,4.8959,299.62,300.57,303.88,302.81
142.35,4.1357,-0.19808,34.404,300.0,-0.021808,4.9096,299.63,300.55,303.83,302.75
142.95,4.1326,-0.19851,33.884,300.0,-0.021886,4.905,299.67,300.46,303.75,302.65
143.55,4.1359,-0.20009,33.823,300.0,-0.022055,4.9072,299.65,300.44,303.62,302.66
144.15,4.1256,-0.20088,34.094,300.0,-0.022136,4.8948,299.59,300.4,303.58,302.53
144.75,4.1303,-0.2013,33.979,300.0,-0.022141,4.9018,299.63,300.42,303.5,302.5
145.2801,4.1344,0.029302,20.432,237.05,0.0031836,4.9067,299.66,300.49,303.4,302.37
145.2831,4.1379,0.027651,10.078,0.061501,0.0034148,4.9054,299.67,300.5,303.38,302.4
145.2861,4.1457,0.028542,0.0,4.9869e-06,0.0034298,4.9189,299.68,300.51,303.36,302.44
145.2891,4.1469,0.031709,0.0,4.0437e-10,0.0036778,4.9127,299.68,300.51,303.38,302.48
145.2921,4.1398,0.030489,0.0,3.2788e-14,0.0033125,4.9204,299.68,300.51,303.4,302.51
145.2951,4.1371,0.029337,0.0,2.6587e-18,0.0030198,4.9049,299.68,300.51,303.42,302.55
145.2981,4.1376,0.030044,0.0,2.1557999999999997e-22,0.0030506,4.9143,299.66,300.5,303.4,302.53
145.3011,4.1408,0.028551,0.0,1.7481e-26,0.0030507,4.91,299.65,300.49,303.38,302.47
145.3041,4.1206,0.028404,0.0,1.4174000000000002e-30,0.0031541,4.9007,299.63,300.48,303.35,302.42
145.3071,4.1383,0.027643,0.0,1.1494000000000001e-34,0.003139,4.9076,299.62,300.47,303.33,302.38
145.3101,4.1151,0.028002,0.0,9.3196e-39,0.0033942,4.8937,299.65,300.44,303.32,302.39
145.3131,4.1336,0.028587,0.0,7.553e-43,0.003477,4.9026,299.68,300.41,303.31,302.4
145.3161,4.0999,0.02946,0.0,0.0,0.0033527,4.879,299.71,300.38,303.3,302.41
145.3191,4.1453,0.029784,0.0,0.0,0.003333,4.9114,299.72,300.36,303.32,302.45
145.3221,4.096,0.030258,0.0,0.0,0.0031719,4.8712,299.73,300.33,303.34,302.48
145.3251,4.1414,0.0296,0.0,0.0,0.0029649,4.9071,299.73,300.3,303.35,302.52
145.3281,4.0828,0.02882,0.0,0.0,0.0031966,4.8545,299.72,300.29,303.36,302.51
145.3311,4.1426,0.02827,0.0,0.0,0.0032699,4.9157,299.69,300.29,303.36,302.49
145.3341,4.092,0.027162,0.0,0.0,0.0031726,4.8579,299.67,300.29,303.36,302.46
145.3371,4.1553,0.027606,0.0,0.0,0.0033772,4.9183,299.64,300.29,303.37,302.43
145.3401,4.1013,0.028314,0.0,0.0,0.0033725,4.8736,299.62,300.29,303.38,302.39
145.3431,4.1357,0.028876,0.0,0.0,0.0032592,4.9135,299.6,300.29,303.4,302.36
145.3461,11.875,0.04802,0.0,0.0,0.0051331,13.717,299.59,300.29,303.42,302.32
145.3491,35.619,0.19035,0.0,0.0,0.021324,41.618,299.84,300.46,303.42,302.32
145.3521,56.597,0.26089,0.0,0.0,0.029154,66.716,300.12,300.63,303.42,302.32
145.3551,70.101,0.30448,0.0,0.0,0.034162,82.911,300.4,300.8,303.42,302.32
145.3581,84.031,0.37922,0.0,0.0,0.042702,99.31,301.23,301.76,303.41,302.32
145.3611,98.961,0.58576,0.0,0.0,0.066772,117.14,302.42,303.23,303.38,302.32
145.3641,110.02,0.84931,0.0,0.0,0.0983,130.38,303.62,304.7,303.35,302.32
145.3671,114.96,1.162,0.0,0.0,0.13681,136.35,305.01,306.31,303.34,302.31
145.3701,118.27,1.4681,0.0,0.0,0.17581,140.28,306.96,308.29,303.38,302.29
145.3731,120.27,1.7601,0.0,0.0,0.21448,142.69,308.91,310.28,303.41,302.28
145.3761,121.68,2.0228,0.0,0.0,0.25022,144.36,310.86,312.26,303.45,302.26
145.3791,122.63,2.2625,0.0,0.0,0.28394,145.51,312.39,313.47,303.46,302.21
145.3821,123.32,2.4764,0.0,0.0,0.31517,146.33,313.88,314.61,303.47,302.15
145.3851,123.89,2.6773,0.0,0.0,0.34553,147.01,315.37,315.74,303.48,302.1
145.3881,124.48,2.8649,0.0,0.0,0.37458,147.7,316.53,316.8,303.45,302.08
145.3911,125.05,3.0503,0.0,0.0,0.40392,148.38,317.45,317.8,303.4,302.1
145.3941,125.67,3.2347,0.0,0.0,0.43355,149.11,318.36,318.81,303.34,302.12
145.3971,126.25,3.4194,0.0,0.0,0.46381,149.8,319.24,319.8,303.3,302.14
145.4001,126.85,3.6012,0.0,0.0,0.49482,150.52,320.0,320.76,303.28,302.18
145.4031,127.33,3.7799,0.0,0.0,0.52594,151.1,320.75,321.72,303.26,302.21
145.4061,127.8,3.9542,0.0,0.0,0.55704,151.64,321.51,322.67,303.24,302.25
145.4091,128.12,4.1251,0.0,0.0,0.58883,152.03,322.33,323.39,303.28,302.22
145.4121,128.46,4.2881,0.0,0.0,0.62027,152.42,323.16,324.06,303.32,302.19
145.4151,128.67,4.4474,0.0,0.0,0.65187,152.69,323.99,324.73,303.37,302.15
145.4181,128.92,4.6003,0.0,0.0,0.68299,152.98,324.88,325.4,303.4,302.12
145.4211,129.07,4.7515,0.0,0.0,0.71421,153.17,325.84,326.05,303.42,302.1
145.4241,129.25,4.8995,0.0,0.0,0.7453,153.36,326.8,326.71,303.44,302.09
145.4271,129.31,5.0432,0.0,0.0,0.77686,153.46,327.74,327.39,303.45,302.07
145.4301,129.47,5.1821,0.0,0.0,0.80787,153.63,328.62,328.21,303.43,302.09
145.4331,129.52,5.3198,0.0,0.0,0.83913,153.7,329.51,329.03,303.41,302.11
145.4361,129.67,5.4518,0.0,0.0,0.87071,153.87,330.39,329.85,303.39,302.13
145.4391,129.73,5.5811,0.0,0.0,0.903,153.95,331.16,330.66,303.38,302.13
145.4421,129.82,5.7083,0.0,0.0,0.9355,154.05,331.91,331.46,303.37,302.13
145.4451,129.81,5.8315,0.0,0.0,0.96801,154.04,332.65,332.26,303.37,302.13
145.4481,129.9,5.9515,0.0,0.0,0.99961,154.15,333.29,332.94,303.37,302.15
145.4511,129.95,6.0679,0.0,0.0,1.0311,154.21,333.8,333.48,303.37,302.2
145.4541,130.11,6.1808,0.0,0.0,1.0631,154.4,334.31,334.03,303.38,302.25
145.4571,130.24,6.2897,0.0,0.0,1.0944,154.55,334.79,334.55,303.4,302.29
145.4601,130.4,6.3958,0.0,0.0,1.1257,154.75,335.14,334.93,303.43,302.31
145.4631,130.55,6.4984,0.0,0.0,1.1572,154.92,335.48,335.3,303.47,302.33
145.4661,130.79,6.5972,0.0,0.0,1.1893,155.2,335.83,335.67,303.51,302.34
145.4691,131.02,6.6933,0.0,0.0,1.2209,155.46,336.06,336.02,303.49,302.34
145.4721,131.36,6.7883,0.0,0.0,1.2534,155.88,336.26,336.35,303.47,302.33
145.4751,131.63,6.8836,0.0,0.0,1.286,156.19,336.46,336.69,303.44,302.32
145.4781,131.94,6.9749,0.0,0.0,1.3173,156.56,336.6,336.91,303.41,302.32
145.4811,132.14,7.0622,0.0,0.0,1.3494,156.79,336.65,336.98,303.4,302.33
145.4841,132.34,7.1474,0.0,0.0,1.381,157.04,336.71,337.05,303.38,302.34
145.4871,132.52,7.2309,0.0,0.0,1.4123,157.25,336.75,337.09,303.36,302.35
145.4901,132.71,7.3095,0.0,0.0,1.4432,157.47,336.7,336.78,303.38,302.35
145.4931,132.96,7.3833,0.0,0.0,1.4743,157.78,336.64,336.47,303.4,302.35
145.4961,133.31,7.458,0.0,0.0,1.5069,158.19,336.59,336.16,303.42,302.35
145.4991,133.69,7.5301,0.0,0.0,1.5389,158.64,336.16,335.41,303.4,302.36
145.5021,134.05,7.6015,0.0,0.0,1.5697,159.07,335.62,334.51,303.37,302.38
145.5051,130.8,7.6631,0.0,0.0,1.5971,155.4,335.07,333.61,303.35,302.4
145.5081,125.36,7.6839,0.0,0.0,1.6075,148.87,334.37,332.58,303.32,302.41
145.5111,121.99,7.6946,0.0,0.0,1.6119,144.83,333.42,331.35,303.29,302.41
145.5141,119.59,7.7029,0.0,0.0,1.6145,141.96,332.47,330.12,303.26,302.41
145.5171,117.65,7.7085,0.0,0.0,1.6172,139.66,331.53,328.91,303.24,302.41
145.5201,116.09,7.7122,0.0,0.0,1.6199,137.8,330.64,327.94,303.26,302.4
145.5231,114.65,7.7152,0.0,0.0,1.6228,136.09,329.75,326.98,303.28,302.39
145.5261,113.36,7.7193,0.0,0.0,1.6252,134.56,328.85,326.01,303.29,302.38
145.5291,112.07,7.7233,0.0,0.0,1.6264,133.02,327.98,325.18,303.33,302.38
145.5321,110.83,7.7271,0.0,0.0,1.6272,131.55,327.12,324.41,303.38,302.38
145.5351,109.43,7.7286,0.0,0.0,1.6287,129.9,326.25,323.63,303.42,302.38
145.5381,106.46,7.7283,0.0,0.0,1.6279,126.44,325.51,323.02,303.46,302.39
145.5411,100.55,7.7233,0.0,0.0,1.6244,119.53,324.98,322.7,303.48,302.43
145.5441,57.466,7.6459,0.0,0.0,1.5891,69.349,324.45,322.38,303.5,302.46
145.5471,9.3899,7.5285,0.0,0.0,1.538,11.956,323.93,322.07,303.51,302.5
145.5501,4.1755,7.5084,0.0,0.0,1.5293,5.0818,323.9,322.15,303.51,302.52
145.5531,3.7868,7.5046,0.0,0.0,1.5283,4.4604,323.87,322.23,303.51,302.54
145.5561,3.1574,7.5131,0.0,0.0,1.5315,3.7679,323.85,322.32,303.51,302.56
145.5591,3.5573,7.5144,0.0,0.0,1.5305,4.2237,323.91,322.36,303.51,302.54
145.5621,3.3573,7.5148,0.0,0.0,1.5314,4.0077,324.02,322.39,303.5,302.52
145.5651,3.551,7.5135,0.0,0.0,1.5306,4.2036,324.13,322.42,303.49,302.49
145.5681,3.4435,7.5116,0.0,0.0,1.5284,4.0974,324.22,322.44,303.48,302.47
145.5711,3.5738,7.5101,0.0,0.0,1.5276,4.2303,324.28,322.46,303.46,302.46
145.5741,3.3762,7.5117,0.0,0.0,1.529,4.0145,324.33,322.48,303.44,302.45
145.5771,3.5335,7.5104,0.0,0.0,1.5298,4.1937,324.38,322.5,303.42,302.44
145.5801,3.4092,7.5098,0.0,0.0,1.5302,4.0626,324.46,322.51,303.43,302.45
145.5831,3.5096,7.5102,0.0,0.0,1.5297,4.1545,324.53,322.53,303.44,302.46
145.5861,3.402,7.5119,0.0,0.0,1.5296,4.0392,324.6,322.55,303.45,302.47
145.5891,3.5197,7.5131,0.0,0.0,1.5303,4.1871,324.66,322.54,303.47,302.46
145.5921,3.4503,7.5133,0.0,0.0,1.5301,4.0861,324.72,322.51,303.5,302.44
145.5951,3.5128,7.5132,0.0,0.0,1.5293,4.1821,324.77,322.49,303.53,302.42
145.5981,3.4724,7.5122,0.0,0.0,1.5288,4.1167,324.82,322.46,303.55,302.41
145.6011,3.4956,7.5121,0.0,0.0,1.5295,4.1447,324.86,322.43,303.55,302.41
145.6041,3.4306,7.5113,0.0,0.0,1.5302,4.0651,324.9,322.4,303.55,302.41
145.6071,3.5371,7.5108,0.0,0.0,1.531,4.1942,324.93,322.38,303.55,302.41
145.6101,3.4684,7.5114,0.0,0.0,1.5303,4.0989,324.93,322.33,303.54,302.43
145.6131,3.5039,7.513,0.0,0.0,1.5302,4.166,324.93,322.29,303.53,302.46
145.6161,3.4708,7.5139,0.0,0.0,1.5311,4.1221,324.93,322.24,303.52,302.49
145.6191,3.509,7.5146,0.0,0.0,1.5311,4.1732,324.9,322.18,303.52,302.5
145.6221,3.4819,7.5143,0.0,0.0,1.5298,4.1271,324.83,322.11,303.53,302.49
145.6251,3.5104,7.5141,0.0,0.0,1.5295,4.1724,324.77,322.03,303.54,302.48
145.6281,3.5098,7.5111,0.0,0.0,1.5293,4.1624,324.71,321.97,303.55,302.47
145.6311,3.5084,7.5115,0.0,0.0,1.5303,4.1701,324.68,321.93,303.58,302.49
145.6341,3.6191,7.5122,0.0,0.0,1.5315,4.2896,324.64,321.9,303.61,302.51
145.6371,3.6382,7.5131,0.0,0.0,1.5315,4.3128,324.6,321.86,303.63,302.53
145.6401,3.7661,7.5139,0.0,0.0,1.5305,4.4499,324.57,321.77,303.64,302.57
145.6431,3.6932,7.5138,0.0,0.0,1.5308,4.3896,324.55,321.67,303.64,302.62
145.6461,3.8444,7.5144,0.0,0.0,1.531,4.5349,324.52,321.57,303.64,302.66
145.6491,3.7515,7.5149,0.0,0.0,1.53,4.4594,324.48,321.45,303.63,302.68
145.6521,3.8627,7.5142,0.0,0.0,1.5292,4.5491,324.42,321.32,303.62,302.66
145.6551,3.7156,7.513,0.0,0.0,1.5298,4.428,324.37,321.2,303.61,302.64
145.6581,3.8672,7.5108,0.0,0.0,1.5296,4.5563,324.3,321.07,303.6,302.62
145.6611,3.6865,7.511,0.0,0.0,1.531,4.4046,324.19,320.96,303.6,302.6
145.6641,3.8672,7.5114,0.0,0.0,1.5303,4.5644,324.08,320.85,303.59,302.58
145.6671,3.665,7.5136,0.0,0.0,1.5306,4.3638,323.98,320.74,303.58,302.57
145.6701,3.8782,7.5137,0.0,0.0,1.5305,4.585,323.9,320.62,303.58,302.58
145.6731,3.6557,7.5141,0.0,0.0,1.5308,4.3512,323.82,320.49,303.59,302.6
145.6761,3.9008,7.5142,0.0,0.0,1.5296,4.62,323.75,320.37,303.6,302.61
145.6791,3.6624,7.5134,0.0,0.0,1.5291,4.3583,323.67,320.26,303.62,302.63
145.6821,3.9095,7.5122,0.0,0.0,1.5295,4.6312,323.59,320.18,303.63,302.65
145.6851,3.6614,7.5105,0.0,0.0,1.5304,4.352,323.51,320.1,303.65,302.67
145.6881,3.9106,7.5119,0.0,0.0,1.5313,4.6427,323.42,320.01,303.67,302.69
145.6911,3.6627,7.5123,0.0,0.0,1.5308,4.3518,323.31,319.87,303.67,302.71
145.6941,3.9049,7.5145,0.0,0.0,1.5306,4.6327,323.21,319.73,303.67,302.73
145.6971,3.6621,7.5138,0.0,0.0,1.5308,4.3422,323.1,319.6,303.67,302.74
145.7001,3.9001,7.5151,0.0,0.0,1.5313,4.643,323.02,319.44,303.7,302.78
145.7031,3.6784,7.5137,0.0,0.0,1.5296,4.3597,322.96,319.29,303.73,302.81
145.7061,3.8914,7.5146,0.0,0.0,1.5294,4.6299,322.9,319.13,303.77,302.85
145.7091,3.6818,7.5123,0.0,0.0,1.5293,4.3582,322.82,318.99,303.79,302.88
145.7121,3.8786,7.513,0.0,0.0,1.5311,4.6118,322.73,318.86,303.79,302.9
145.7151,3.6973,7.5118,0.0,0.0,1.5312,4.3678,322.64,318.74,303.79,302.91
145.7181,3.8553,7.5147,0.0,0.0,1.5321,4.5936,322.54,318.61,303.79,302.93
145.7211,3.7185,7.5134,0.0,0.0,1.5304,4.3953,322.44,318.47,303.79,302.93
145.7241,3.8468,7.516,0.0,0.0,1.5316,4.5923,322.33,318.33,303.79,302.93
145.7271,3.743,7.5145,0.0,0.0,1.5311,4.4205,322.22,318.2,303.79,302.93
145.7301,3.8234,7.5166,0.0,0.0,1.5309,4.5672,322.11,318.09,303.8,302.93
145.7331,3.7536,7.5144,0.0,0.0,1.5294,4.4263,322.0,318.0,303.81,302.93
145.7361,3.8161,7.5145,0.0,0.0,1.5305,4.553,321.89,317.91,303.82,302.93
145.7391,3.7806,7.5117,0.0,0.0,1.5304,4.4679,321.78,317.8,303.82,302.94
145.7421,3.7993,7.5134,0.0,0.0,1.5323,4.5349,321.66,317.65,303.82,302.96
145.7451,3.8182,7.5137,0.0,0.0,1.5315,4.5031,321.54,317.5,303.82,302.98
145.7481,3.7841,7.5148,0.0,0.0,1.5312,4.5103,321.42,317.35,303.82,302.99
145.7511,3.835,7.5142,0.0,0.0,1.5309,4.5266,321.29,317.17,303.83,303.01
145.7541,3.7723,7.5158,0.0,0.0,1.5316,4.5047,321.16,316.99,303.84,303.03
145.7571,3.8578,7.5154,0.0,0.0,1.5304,4.5543,321.04,316.81,303.85,303.05
145.7601,3.7562,7.5154,0.0,0.0,1.5302,4.4771,320.92,316.65,303.86,303.05
145.7631,3.8916,7.5136,0.0,0.0,1.5299,4.5978,320.8,316.5,303.87,303.05
145.7661,3.738,7.5133,0.0,0.0,1.531,4.46,320.68,316.36,303.88,303.05
145.7691,3.912,7.5124,0.0,0.0,1.5316,4.6171,320.55,316.22,303.87,303.05
145.7721,3.736,7.5143,0.0,0.0,1.5323,4.4521,320.4,316.1,303.84,303.03
145.7751,3.9116,7.5149,0.0,0.0,1.5311,4.6222,320.26,315.98,303.82,303.01
145.7781,3.7055,7.5164,0.0,0.0,1.5319,4.4097,320.11,315.87,303.79,302.99
145.7811,3.9393,7.5162,0.0,0.0,1.5317,4.6624,319.99,315.75,303.79,302.98
145.7841,3.6996,7.5163,0.0,0.0,1.5307,4.4107,319.86,315.63,303.79,302.97
145.7871,3.9395,7.5161,0.0,0.0,1.5301,4.6622,319.73,315.51,303.79,302.96
145.7901,3.7059,7.515,0.0,0.0,1.5307,4.401,319.63,315.37,303.81,302.99
145.7931,3.9441,7.5143,0.0,0.0,1.5312,4.6829,319.54,315.23,303.84,303.02
145.7961,3.7044,7.5132,0.0,0.0,1.532,4.3926,319.45,315.08,303.86,303.06
145.7991,3.948,7.5141,0.0,0.0,1.5319,4.6901,319.34,314.95,303.89,303.09
145.8021,3.7124,7.5149,0.0,0.0,1.5313,4.4073,319.19,314.85,303.91,303.12
145.8051,3.9454,7.5166,0.0,0.0,1.5315,4.693,319.04,314.75,303.93,303.15
145.8081,3.7271,7.5149,0.0,0.0,1.5314,4.417,318.9,314.65,303.94,303.18
145.8111,3.9384,7.5163,0.0,0.0,1.5308,4.6791,318.79,314.55,303.98,303.2
145.8141,3.7419,7.5157,0.0,0.0,1.53,4.4347,318.68,314.45,304.02,303.21
145.8171,3.9388,7.5158,0.0,0.0,1.531,4.6813,318.57,314.35,304.05,303.23
145.8201,3.7527,7.513,0.0,0.0,1.5308,4.4411,318.47,314.22,304.07,303.24
145.8231,3.9229,7.5144,0.0,0.0,1.5322,4.6642,318.38,314.07,304.08,303.25
145.8261,3.771,7.5138,0.0,0.0,1.532,4.4556,318.29,313.92,304.09,303.26
145.8291,3.8975,7.5162,0.0,0.0,1.5317,4.6521,318.18,313.77,304.09,303.27
145.8321,3.7883,7.5154,0.0,0.0,1.5312,4.4838,318.05,313.61,304.09,303.27
145.8351,3.9046,7.5172,0.0,0.0,1.5322,4.6538,317.91,313.44,304.08,303.27
145.8381,3.8085,7.5157,0.0,0.0,1.5308,4.4935,317.77,313.28,304.07,303.27
145.8411,3.8879,7.5161,0.0,0.0,1.5304,4.6339,317.64,313.13,304.02,303.3
145.8441,3.8282,7.5135,0.0,0.0,1.5299,4.5116,317.52,312.98,303.98,303.32
145.8471,3.8699,7.5145,0.0,0.0,1.5314,4.6145,317.39,312.84,303.93,303.35
145.8501,3.8566,7.5129,0.0,0.0,1.5318,4.5543,317.27,312.7,303.91,303.39
145.8531,3.8592,7.5151,0.0,0.0,1.5323,4.6097,317.15,312.58,303.91,303.45
145.8561,3.8753,7.5147,0.0,0.0,1.531,4.5761,317.03,312.45,303.91,303.5
145.8591,3.8226,7.5171,0.0,0.0,1.5318,4.5673,316.91,312.32,303.92,303.55
145.8621,3.9043,7.5157,0.0,0.0,1.5315,4.6038,316.78,312.2,303.96,303.57
145.8651,3.8079,7.5167,0.0,0.0,1.5311,4.5418,316.65,312.08,304.0,303.59
145.8681,3.9314,7.5156,0.0,0.0,1.5302,4.635,316.52,311.97,304.03,303.61
145.8711,3.7985,7.5152,0.0,0.0,1.5309,4.5238,316.4,311.82,304.03,303.59
145.8741,3.9457,7.5141,0.0,0.0,1.5313,4.6572,316.27,311.68,304.02,303.57
145.8771,3.7875,7.514,0.0,0.0,1.5324,4.5199,316.14,311.53,304.01,303.55
145.8801,3.9713,7.5148,0.0,0.0,1.5321,4.6873,316.01,311.39,304.02,303.55
145.8831,3.7807,7.5157,0.0,0.0,1.5317,4.5025,315.88,311.25,304.03,303.55
145.8861,3.9866,7.5161,0.0,0.0,1.5317,4.7153,315.76,311.11,304.05,303.55
145.8891,3.7762,7.5161,0.0,0.0,1.5316,4.4941,315.63,310.98,304.08,303.55
145.8921,3.9805,7.5169,0.0,0.0,1.531,4.7114,315.52,310.87,304.12,303.55
145.8951,3.7713,7.5164,0.0,0.0,1.5304,4.4821,315.41,310.76,304.17,303.55
145.8981,3.9879,7.5165,0.0,0.0,1.531,4.7281,315.3,310.65,304.21,303.55
145.9011,3.7725,7.5144,0.0,0.0,1.5313,4.4823,315.19,310.51,304.21,303.58
145.9041,4.004,7.5152,0.0,0.0,1.5325,4.7443,315.08,310.37,304.2,303.61
145.9071,3.7848,7.5155,0.0,0.0,1.5329,4.4897,314.97,310.22,304.19,303.65
145.9101,3.989,7.5156,0.0,0.0,1.5315,4.7368,314.86,310.11,304.18,303.69
145.9131,3.7809,7.5162,0.0,0.0,1.5316,4.4792,314.75,310.03,304.17,303.72
145.9161,3.9887,7.5169,0.0,0.0,1.5323,4.7421,314.64,309.94,304.17,303.76
145.9191,3.7829,7.5159,0.0,0.0,1.5311,4.4835,314.54,309.86,304.16,303.79
145.9221,3.9796,7.5171,0.0,0.0,1.5307,4.7345,314.43,309.75,304.18,303.77
145.9251,3.7994,7.5154,0.0,0.0,1.5305,4.4995,314.32,309.64,304.2,303.75
146.1265,3.855,7.5171,0.0,0.0,1.5322,4.5748,309.1,303.95,304.2,302.85
146.7265,3.7413,7.5186,0.0,0.0,1.5329,4.4405,291.71,288.33,303.1,295.57
147.3265,3.7022,7.5203,0.0,0.0,1.5336,4.3926,281.15,279.18,302.21,289.73
147.9265,3.6661,7.5225,0.0,0.0,1.5345,4.3506,273.8,272.28,298.51,283.93
148.5265,3.6552,7.5243,0.0,0.0,1.5353,4.3375,267.55,266.34,294.38,277.7
149.1265,3.637,7.5258,0.0,0.0,1.536,4.3143,262.33,261.87,289.25,271.54
149.7265,3.5818,7.5275,0.0,0.0,1.5367,4.2502,257.19,257.02,283.72,265.49
150.2448,3.5611,7.529,0.0,0.0,1.5374,4.2256,252.9,253.09,278.97,260.53
150.8448,3.5536,7.5308,0.0,0.0,1.5381,4.2158,248.42,248.81,273.6,254.84
151.4448,3.5631,7.5324,0.0,0.0,1.5388,4.2289,244.19,244.7,268.2,249.67
152.0448,3.5577,7.5338,0.0,0.0,1.5394,4.2233,240.12,240.52,262.86,244.61
152.6448,3.5883,7.5351,0.0,0.0,1.5402,4.2595,235.97,236.51,257.52,239.72
153.2448,3.5858,7.5365,0.0,0.0,1.5407,4.2549,232.09,232.81,252.37,235.07
153.8448,3.5821,7.5379,0.0,0.0,1.5413,4.2496,228.49,228.93,247.47,230.47
154.4448,3.5829,7.5395,0.0,0.0,1.5419,4.2521,224.73,225.27,242.61,225.97
155.0448,3.5854,7.5406,0.0,0.0,1.5423,4.257,221.05,221.46,238.08,221.3
155.6448,3.6003,7.5418,0.0,0.0,1.5429,4.2731,217.6,217.83,233.52,216.76
156.2448,3.5937,7.5426,0.0,0.0,1.5434,4.2632,214.06,214.0,229.05,212.89
156.8448,3.5866,7.5436,0.0,0.0,1.5439,4.2554,210.68,210.49,224.2,208.81
157.4448,3.5911,7.5447,0.0,0.0,1.5443,4.2622,207.41,207.15,219.66,205.03
158.0448,3.5892,7.5456,0.0,0.0,1.5447,4.2607,204.15,203.93,215.56,201.45
158.6448,3.5995,7.5466,0.0,0.0,1.5449,4.272,200.95,200.47,211.02,197.53
159.2448,3.6036,7.5473,0.0,0.0,1.5453,4.2752,197.9,197.58,206.99,194.62
159.8448,3.6066,7.5481,0.0,0.0,1.5458,4.2806,194.92,194.46,203.19,191.15
160.4448,3.5941,7.5487,0.0,0.0,1.5462,4.2669,192.19,191.7,199.53,188.15
161.0448,3.6037,7.5497,0.0,0.0,1.5465,4.2775,189.39,188.86,195.88,184.91
161.6448,3.6159,7.5507,0.0,0.0,1.5469,4.2908,186.76,186.03,192.6,181.94
162.2448,3.5962,7.5513,0.0,0.0,1.547,4.2661,184.11,183.42,189.52,178.98
162.8448,3.5894,7.552,0.0,0.0,1.5473,4.2604,181.61,180.87,186.46,176.19
163.4448,3.5917,7.5527,0.0,0.0,1.5478,4.2637,179.09,178.37,183.5,173.56
164.0448,3.6114,7.5535,0.0,0.0,1.5482,4.2864,176.62,175.78,180.46,170.76
164.6448,3.6111,7.5541,0.0,0.0,1.5484,4.2851,174.37,173.49,177.43,168.21
165.2448,3.5971,7.5549,0.0,0.0,1.5487,4.2675,172.11,171.07,174.67,165.77
165.8448,3.598,7.5557,0.0,0.0,1.549,4.2702,169.63,168.86,171.92,163.14
166.4448,3.6093,7.5564,0.0,0.0,1.5493,4.2842,167.58,166.59,169.34,160.72
167.0448,3.6061,7.5572,0.0,0.0,1.5497,4.2794,165.49,164.47,166.97,158.42
167.6448,3.6153,7.5578,0.0,0.0,1.5501,4.2887,163.23,162.31,164.4,156.06
168.2448,3.606,7.5587,0.0,0.0,1.5504,4.2785,161.15,160.34,162.02,153.81
168.8448,3.6062,7.5596,0.0,0.0,1.5509,4.2794,159.23,158.36,159.63,151.66
169.4448,3.6088,7.5605,0.0,0.0,1.5511,4.2832,157.27,156.33,157.36,149.46
170.0448,3.6352,7.5613,0.0,0.0,1.5515,4.3132,155.3,154.4,155.16,147.39
170.6448,3.6046,7.5617,0.0,0.0,1.5517,4.2752,153.42,152.52,152.97,145.42
171.2448,3.608,7.5625,0.0,0.0,1.5523,4.2811,151.55,150.66,150.98,143.49
171.8448,3.6107,7.5633,0.0,0.0,1.5525,4.2854,149.77,148.74,148.82,141.59
172.4448,3.6103,7.5642,0.0,0.0,1.5528,4.284,148.06,147.04,146.88,139.66
173.0448,3.6095,7.5649,0.0,0.0,1.5531,4.2819,146.31,145.36,144.92,137.89
173.6448,3.6027,7.5658,0.0,0.0,1.5535,4.2745,144.5,143.6,142.97,136.06
174.2448,3.6019,7.5665,0.0,0.0,1.5539,4.2745,142.82,141.97,141.11,134.33
174.8448,3.6078,7.5673,0.0,0.0,1.5544,4.2815,141.29,140.44,139.42,132.63
175.4448,3.6097,7.568,0.0,0.0,1.5546,4.284,139.62,138.78,137.51,130.92
176.0448,3.5189,7.5707,0.0,0.0,1.5558,4.1729,138.08,137.3,135.81,130.0
176.6448,3.4972,7.5689,0.0,0.0,1.5548,4.1508,138.39,137.51,135.52,133.1
177.2448,3.7237,7.5668,0.0,0.0,1.5539,4.4187,138.44,137.36,135.33,133.76
177.8448,3.501,7.568,0.0,0.0,1.5546,4.155,138.38,137.27,135.35,134.07