File: examples/dan-msc-case-studies/CS4/data/01 raw data/hyde_test_025.csv
Time(sec),Force(kN),Jaw(mm),PowAngle(deg),PTemp,Strain,Stress(MPa),TC1(C),TC2(C),TC3(C)
0.0,1.4805,-0.0047306,0.0,0.0038352,-0.00055652,4.4982,21.309,8000,8000
2.0,1.4469,-0.0038649,0.0,5.0588,-0.00041501,4.3889,21.377,8000,8000
4.0,1.4033,-0.0038365,0.0,11.057,-0.00042648,4.2583,21.404,8000,8000
6.0,1.3805,-0.0036983,0.0,17.057,-0.00039964,4.1864,21.347,8000,8000
8.0,1.3628,-0.0031718,15.119,23.057,-0.00034862,4.1338,21.761,8000,8000
9.3239,1.3522,-0.0032454,22.633,27.03,-0.00036262,4.1018,25.62,8000,8000
11.3239,1.3553,-0.0052389,24.947,33.029,-0.00056409,4.1122,32.155,8000,8000
13.3239,1.3583,-0.007625,25.969,39.029,-0.00082502,4.1207,38.521,8000,8000
14.4216,1.3737,-0.0095639,25.899,42.322,-0.0010346,4.1665,41.992,8000,8000
16.4216,1.3683,-0.011363,26.735,48.322,-0.0012301,4.1522,48.112,8000,8000
18.4216,1.3671,-0.013888,27.598,54.322,-0.0015226,4.1469,54.105,8000,8000
20.4216,1.3848,-0.016693,28.226,60.322,-0.0018178,4.2009,60.169,8000,8000
22.4216,1.385,-0.020851,28.55,66.322,-0.0022759,4.2016,66.203,8000,8000
24.4216,1.402,-0.022754,29.065,72.322,-0.0024761,4.2526,72.251,8000,8000
26.4216,1.3968,-0.025895,29.925,78.322,-0.0028364,4.2385,78.161,8000,8000
28.4216,1.4056,-0.029672,30.162,84.322,-0.0032248,4.2618,84.194,8000,8000
30.4216,1.4123,-0.032646,30.491,90.322,-0.0035588,4.2852,90.26,8000,8000
32.4216,1.4155,-0.036222,30.548,96.322,-0.0039619,4.2941,96.29,8000,8000
34.4216,1.4206,-0.041198,30.993,102.32,-0.0044933,4.3096,102.25,8000,8000
36.4216,1.4304,-0.043156,31.266,108.32,-0.0047072,4.3384,108.26,8000,8000
38.4216,1.4222,-0.046805,31.184,114.32,-0.0050949,4.3157,114.34,8000,8000
40.4216,1.4378,-0.050557,31.338,120.32,-0.0055273,4.3594,120.33,8000,8000
41.9475,1.4392,-0.052685,32.061,124.9,-0.00575,4.3651,124.79,8000,8000
43.9475,1.4397,-0.056472,32.235,130.9,-0.0061494,4.3677,130.83,8000,8000
45.1122,1.4457,-0.059964,32.102,134.39,-0.0065453,4.3857,134.38,8000,8000
47.1122,1.4479,-0.062021,32.475,140.39,-0.0067575,4.3917,140.38,8000,8000
49.1122,1.4473,-0.065948,32.556,146.39,-0.0071821,4.3909,146.43,8000,8000
51.1122,1.4554,-0.070687,32.795,152.39,-0.0077055,4.4146,152.39,8000,8000
53.1122,1.458,-0.073331,33.4,158.39,-0.0079981,4.4226,158.3,8000,8000
55.1122,1.4608,-0.077286,33.251,164.39,-0.0084081,4.4318,164.38,8000,8000
57.1122,1.4698,-0.081157,33.465,170.39,-0.0088314,4.4597,170.38,8000,8000
59.1122,1.4706,-0.084919,33.677,176.39,-0.0092595,4.4609,176.35,8000,8000
61.1122,1.4746,-0.090412,33.53,182.39,-0.0098249,4.4728,182.44,8000,8000
63.1122,1.4772,-0.092696,33.898,188.39,-0.010082,4.482,188.35,8000,8000
65.1122,1.4798,-0.096708,33.862,194.39,-0.010527,4.4884,194.4,8000,8000
67.1122,1.4844,-0.10262,33.894,200.39,-0.011161,4.5038,200.45,8000,8000
69.1122,1.4897,-0.10422,33.824,206.39,-0.011334,4.5191,206.42,8000,8000
71.1122,1.4845,-0.1085,33.816,212.39,-0.0118,4.5045,212.45,8000,8000
73.1122,1.4877,-0.11246,34.08,218.39,-0.012224,4.5118,218.42,8000,8000
74.4754,1.4928,-0.11729,34.112,222.48,-0.012734,4.5287,222.51,8000,8000
75.8167,1.4984,-0.11852,34.196,226.51,-0.012887,4.5446,226.5,8000,8000
77.8167,1.4906,-0.12137,34.198,232.51,-0.013197,4.5228,232.54,8000,8000
79.8167,1.4944,-0.12564,34.413,238.51,-0.013647,4.5328,238.55,8000,8000
81.8167,1.49,-0.12969,34.658,244.51,-0.014084,4.5204,244.52,8000,8000
83.8167,1.4957,-0.13556,34.74,250.51,-0.014718,4.5363,250.53,8000,8000
85.8167,1.5077,-0.13801,34.875,256.51,-0.014988,4.5756,256.5,8000,8000
87.8167,1.5008,-0.14216,35.064,262.51,-0.01543,4.5539,262.48,8000,8000
89.8167,1.4951,-0.14644,35.024,268.51,-0.015901,4.5362,268.49,8000,8000
91.8167,1.504,-0.15295,35.001,274.51,-0.016599,4.5621,274.53,8000,8000
93.8167,1.503,-0.15465,34.859,280.51,-0.016773,4.5606,280.57,8000,8000
95.8167,1.4982,-0.15899,35.173,286.51,-0.017252,4.5447,286.52,8000,8000
97.8167,1.5122,-0.16563,35.255,292.51,-0.017957,4.587,292.5,8000,8000
99.8167,1.5059,-0.16735,35.534,298.51,-0.018151,4.5676,298.43,8000,8000
101.8167,0.61743,-0.17385,33.371,300.0,-0.01885,1.8731,300.32,8000,8000
103.8167,0.61866,-0.1749,33.267,300.0,-0.018967,1.8776,300.13,8000,8000
105.8167,0.61694,-0.17521,32.975,300.0,-0.018997,1.8716,300.11,8000,8000
107.1067,0.61953,-0.17644,32.923,300.0,-0.019115,1.8778,300.08,8000,8000
109.1067,0.6217,-0.17629,32.704,300.0,-0.019115,1.8862,300.11,8000,8000
111.1067,0.61468,-0.17748,32.32,300.0,-0.019225,1.8639,300.1,8000,8000
113.1067,0.62013,-0.17765,32.312,300.0,-0.01925,1.8818,300.05,8000,8000
115.1067,0.6218,-0.17821,32.132,300.0,-0.019322,1.8847,300.05,8000,8000
116.696,0.63035,-0.18003,31.821,300.0,-0.019512,1.9115,300.09,8000,8000
118.696,0.627,-0.17872,32.144,300.0,-0.019367,1.9027,299.99,8000,8000
120.696,0.62403,-0.17949,32.153,300.0,-0.019452,1.8929,299.99,8000,8000
122.696,0.62759,-0.17974,32.179,300.0,-0.019479,1.9042,299.99,8000,8000
124.696,0.62442,-0.18017,32.004,300.0,-0.019532,1.8951,300.04,8000,8000
126.696,0.63478,-0.18229,31.985,300.0,-0.019739,1.9249,300.03,8000,8000
128.696,0.63402,-0.18071,31.751,300.0,-0.019575,1.9239,300.03,8000,8000
130.696,0.63747,-0.18123,31.621,300.0,-0.019651,1.9335,300.04,8000,8000
132.696,0.63517,-0.18184,31.647,300.0,-0.019688,1.9276,300.03,8000,8000
134.696,0.63966,-0.18315,31.514,300.0,-0.019841,1.9404,300.04,8000,8000
136.696,0.63736,-0.18168,31.511,300.0,-0.019694,1.9347,300.02,8000,8000
138.696,0.63759,-0.18221,31.588,300.0,-0.019733,1.9332,299.98,8000,8000
139.7391,0.64227,-0.18243,31.568,300.0,-0.019763,1.9496,300.01,8000,8000
141.7391,0.64498,-0.18248,31.582,300.0,-0.01978,1.9565,300.01,8000,8000
143.7391,0.64446,-0.18262,31.831,300.0,-0.019787,1.9552,299.96,8000,8000
145.136,0.63595,-0.089275,31.677,300.0,-0.0096749,1.9301,300.01,8000,8000
145.2871,0.80574,0.0010589,21.681,10.334,-8.2183e-06,2.4624,299.92,8000,8000
145.2891,0.79981,0.0014514,15.305,0.01946,-9.2048e-05,2.4396,299.94,8000,8000
145.2911,0.80634,-0.0016489,8.9293,3.6646e-05,0.00038004,2.4475,299.96,8000,8000
145.2931,0.79836,0.0011637,2.5533,6.8653e-08,0.00034883,2.4585,299.98,8000,8000
145.2951,0.81521,0.00027384,0.0,1.2928e-10,-0.00020196,2.4684,299.98,8000,8000
145.2971,0.80136,0.0019669,0.0,2.4219e-13,8.4486e-05,2.4532,299.98,8000,8000
145.2991,0.77184,0.0017928,0.0,4.5605e-16,-0.00016646,2.3777,299.98,8000,8000
145.3011,0.79259,-0.0017487,0.0,8.587300000000001e-19,0.00035792,2.4185,299.98,8000,8000
145.3031,0.78639,0.0022774,0.0,1.6087999999999999e-21,0.00048,2.4037,299.98,8000,8000
145.3051,0.78438,-0.00049168,0.0,3.0291e-24,-0.00018784,2.3991,299.99,8000,8000
145.3071,0.78292,0.00053725,0.0,5.6748e-27,-1.9564e-05,2.3871,300.0,8000,8000
145.3091,0.78011,0.0029308,0.0,1.0685e-29,-0.00015207,2.3822,300.02,8000,8000
145.3111,0.78513,-0.0024756,0.0,2.0118e-32,0.00018287,2.3951,300.03,8000,8000
145.3131,0.77796,0.0010273,0.0,3.7689000000000004e-35,0.00041741,2.3684,300.04,8000,8000
145.3151,0.77108,-0.00057989,0.0,7.096e-38,5.3428e-05,2.3459,300.04,8000,8000
145.3171,0.77275,0.0016739,0.0,1.3294e-40,3.0352e-06,2.355,300.04,8000,8000
145.3191,0.77359,0.0018805,0.0,2.5082999999999998e-43,-0.00039973,2.3516,300.04,8000,8000
145.3211,0.77132,-0.0023553,0.0,0.0,0.00021779,2.3503,300.04,8000,8000
145.3231,0.77815,0.00060508,0.0,0.0,0.00029566,2.361,300.04,8000,8000
145.3251,0.77664,-0.0010151,0.0,0.0,6.3508e-05,2.3564,300.03,8000,8000
145.3271,0.77442,0.0019053,0.0,0.0,6.3727e-06,2.3378,300.02,8000,8000
145.3291,0.78128,0.0012203,0.0,0.0,-0.00054366,2.3628,300.0,8000,8000
145.3311,0.78301,-0.0015484,0.0,0.0,0.00012044,2.3671,299.98,8000,8000
145.3331,0.7907,0.00075155,0.0,0.0,0.00027391,2.3928,299.96,8000,8000
145.3351,0.78878,-0.0015219,0.0,0.0,6.9219e-05,2.3749,299.95,8000,8000
145.3371,0.79817,0.00098951,0.0,0.0,2.9501e-05,2.419,299.93,8000,8000
145.3391,0.80238,0.0019921,0.0,0.0,-0.00039218,2.4,299.92,8000,8000
145.3411,0.8092,0.00041904,0.0,0.0,0.00015902,2.435,299.91,8000,8000
145.3431,0.82614,0.0013724,0.0,0.0,0.0001851,2.4918,299.9,8000,8000
145.3451,0.82338,-0.0022203,0.0,0.0,0.00020207,2.4855,299.91,8000,8000
145.3471,0.82854,0.0029485,0.0,0.0,0.00028921,2.4885,299.93,8000,8000
145.3491,0.8375,0.0020998,0.0,0.0,-0.00029228,2.5073,299.96,8000,8000
145.3511,3.494,0.022354,0.0,0.0,0.0021154,9.6198,299.98,8000,8000
145.3531,15.099,0.045156,0.0,0.0,0.0037955,43.228,300.0,8000,8000
145.35509,28.168,0.1374,0.0,0.0,0.01512,84.692,300.18,8000,8000
145.35709,36.468,0.26508,0.0,0.0,0.029207,110.12,300.45,8000,8000
145.35909,41.033,0.41582,0.0,0.0,0.045709,124.04,300.72,8000,8000
145.36109,44.493,0.5652,0.0,0.0,0.062989,134.67,300.99,8000,8000
145.36309,46.212,0.72051,0.0,0.0,0.080859,140.06,301.26,8000,8000
145.36509,47.229,0.87262,0.0,0.0,0.099957,143.24,301.68,8000,8000
145.36709,47.967,1.0441,0.0,0.0,0.12015,145.47,302.22,8000,8000
145.36909,48.595,1.2183,0.0,0.0,0.14092,147.37,302.75,8000,8000
145.37109,49.047,1.3998,0.0,0.0,0.16394,148.74,303.28,8000,8000
145.37309,49.423,1.5908,0.0,0.0,0.188,149.91,303.82,8000,8000
145.37509,49.644,1.7733,0.0,0.0,0.21338,150.57,304.38,8000,8000
145.37709,49.926,1.9669,0.0,0.0,0.23903,151.45,304.97,8000,8000
145.37909,50.128,2.1444,0.0,0.0,0.26286,152.04,305.56,8000,8000
145.38109,50.255,2.3165,0.0,0.0,0.28687,152.43,306.15,8000,8000
145.38309,50.395,2.4751,0.0,0.0,0.30926,152.87,306.73,8000,8000
145.38509,50.506,2.6164,0.0,0.0,0.33143,153.2,307.28,8000,8000
145.38709,50.582,2.7489,0.0,0.0,0.35108,153.45,307.8,8000,8000
145.38909,50.707,2.8745,0.0,0.0,0.36977,153.83,308.32,8000,8000
145.39109,50.852,2.9992,0.0,0.0,0.38854,154.25,308.84,8000,8000
145.39309,51.054,3.1223,0.0,0.0,0.4072,154.85,309.36,8000,8000
145.39509,51.263,3.2419,0.0,0.0,0.42792,155.5,309.84,8000,8000
145.39709,51.502,3.3713,0.0,0.0,0.44892,156.21,310.3,8000,8000
145.39909,51.716,3.501,0.0,0.0,0.47042,156.82,310.76,8000,8000
145.40109,51.93,3.6334,0.0,0.0,0.49221,157.53,311.22,8000,8000
145.40309,52.129,3.7644,0.0,0.0,0.51396,158.12,311.68,8000,8000
145.40509,52.314,3.8905,0.0,0.0,0.53774,158.68,312.1,8000,8000
145.40709,52.446,4.0149,0.0,0.0,0.56015,159.09,312.5,8000,8000
145.40909,52.546,4.1314,0.0,0.0,0.58209,159.4,312.9,8000,8000
145.41109,52.642,4.2504,0.0,0.0,0.60328,159.66,313.29,8000,8000
145.41309,52.766,4.3636,0.0,0.0,0.62381,160.03,313.69,8000,8000
145.41509,52.859,4.4707,0.0,0.0,0.64621,160.33,314.03,8000,8000
145.41709,52.96,4.5789,0.0,0.0,0.66765,160.63,314.34,8000,8000
145.41909,53.07,4.6819,0.0,0.0,0.68968,160.97,314.65,8000,8000
145.42109,53.155,4.79,0.0,0.0,0.71116,161.23,314.95,8000,8000
145.42309,53.231,4.8953,0.0,0.0,0.73177,161.46,315.26,8000,8000
145.42509,53.309,4.9952,0.0,0.0,0.75436,161.68,315.5,8000,8000
145.42709,53.371,5.0951,0.0,0.0,0.77606,161.87,315.69,8000,8000
145.42909,53.44,5.1912,0.0,0.0,0.79949,162.1,315.89,8000,8000
145.43109,53.479,5.2922,0.0,0.0,0.82171,162.21,316.08,8000,8000
145.43309,53.518,5.3873,0.0,0.0,0.84261,162.32,316.28,8000,8000
145.43509,53.564,5.4829,0.0,0.0,0.86547,162.46,316.43,8000,8000
145.43709,53.591,5.5762,0.0,0.0,0.88795,162.54,316.55,8000,8000
145.43909,53.617,5.6624,0.0,0.0,0.91169,162.63,316.68,8000,8000
145.44109,53.654,5.754,0.0,0.0,0.9344,162.73,316.8,8000,8000
145.44309,53.676,5.8378,0.0,0.0,0.95418,162.8,316.92,8000,8000
145.44509,53.724,5.9247,0.0,0.0,0.97709,162.95,317.0,8000,8000
145.44709,53.756,6.0111,0.0,0.0,0.99976,163.05,317.06,8000,8000
145.44909,53.784,6.0903,0.0,0.0,1.0245,163.14,317.11,8000,8000
145.45109,53.834,6.1707,0.0,0.0,1.0465,163.29,317.17,8000,8000
145.45309,53.877,6.2508,0.0,0.0,1.068,163.42,317.22,8000,8000
145.45509,53.897,6.3298,0.0,0.0,1.09,163.48,317.26,8000,8000
145.45709,53.957,6.4075,0.0,0.0,1.1127,163.65,317.29,8000,8000
145.45909,54.045,6.4784,0.0,0.0,1.1374,163.93,317.31,8000,8000
145.46109,54.114,6.5539,0.0,0.0,1.1608,164.12,317.33,8000,8000
145.46309,54.198,6.626,0.0,0.0,1.1831,164.4,317.36,8000,8000
145.46509,54.269,6.7008,0.0,0.0,1.2058,164.63,317.37,8000,8000
145.46709,54.343,6.7694,0.0,0.0,1.2272,164.83,317.37,8000,8000
145.46909,54.46,6.838,0.0,0.0,1.2539,165.19,317.37,8000,8000
145.47109,54.516,6.9072,0.0,0.0,1.278,165.37,317.37,8000,8000
145.47309,54.597,6.9707,0.0,0.0,1.3001,165.6,317.37,8000,8000
145.47509,54.732,7.0353,0.0,0.0,1.3219,166.01,317.35,8000,8000
145.47709,54.893,7.1016,0.0,0.0,1.3442,166.52,317.33,8000,8000
145.47909,55.032,7.159,0.0,0.0,1.3688,166.92,317.31,8000,8000
145.48109,55.132,7.2198,0.0,0.0,1.3929,167.25,317.28,8000,8000
145.48309,55.262,7.28,0.0,0.0,1.4174,167.63,317.26,8000,8000
145.48509,55.399,7.3451,0.0,0.0,1.4415,168.03,317.25,8000,8000
145.48709,55.534,7.4006,0.0,0.0,1.4613,168.45,317.27,8000,8000
145.48909,55.683,7.4526,0.0,0.0,1.4859,168.9,317.28,8000,8000
145.49109,55.894,7.5084,0.0,0.0,1.5102,169.51,317.29,8000,8000
145.49308,56.128,7.5591,0.0,0.0,1.5351,170.23,317.3,8000,8000
145.49508,56.339,7.6141,0.0,0.0,1.5576,170.89,317.3,8000,8000
145.49708,56.521,7.6694,0.0,0.0,1.5793,171.45,317.28,8000,8000
145.49908,56.654,7.7217,0.0,0.0,1.6055,171.88,317.26,8000,8000
145.50108,54.591,7.7422,0.0,0.0,1.6154,165.65,317.24,8000,8000
145.50308,53.152,7.7445,0.0,0.0,1.6213,161.38,317.22,8000,8000
145.50508,51.992,7.7472,0.0,0.0,1.6207,157.77,317.19,8000,8000
145.50708,51.127,7.7523,0.0,0.0,1.6195,155.16,317.14,8000,8000
145.50908,50.527,7.756,0.0,0.0,1.6215,153.33,317.09,8000,8000
145.51108,50.101,7.7578,0.0,0.0,1.6222,152.0,317.04,8000,8000
145.51308,49.83,7.7557,0.0,0.0,1.6267,151.19,316.99,8000,8000
145.51508,49.618,7.7635,0.0,0.0,1.6291,150.53,316.95,8000,8000
145.51708,49.485,7.7671,0.0,0.0,1.6274,150.13,316.91,8000,8000
145.51908,49.403,7.7689,0.0,299.2,1.6276,149.9,316.88,8000,8000
145.52108,49.305,7.7744,0.0,300.0,1.6297,149.59,316.84,8000,8000
145.52308,49.039,7.7729,0.0,300.0,1.6344,148.8,316.8,8000,8000
145.52508,48.3,7.7746,0.0,300.0,1.6346,146.65,316.76,8000,8000
145.52708,46.74,7.7731,0.0,300.0,1.6319,141.99,316.71,8000,8000
145.52908,44.241,7.7729,0.0,300.0,1.6299,134.48,316.66,8000,8000
145.53108,40.58,7.7698,0.0,300.0,1.6269,123.52,316.61,8000,8000
145.53308,22.93,7.7445,0.0,300.0,1.6216,72.585,316.56,8000,8000
145.53508,3.3893,7.6587,0.0,300.0,1.5813,11.587,316.5,8000,8000
145.53708,-0.19011,7.5747,0.0,300.0,1.5401,-0.5999,316.42,8000,8000
145.53908,1.3248,7.652,0.0,300.0,1.5725,2.8948,316.34,8000,8000
145.54108,-0.060438,7.6467,0.0,300.0,1.569,-0.30747,316.26,8000,8000
145.54308,0.9216,7.6601,0.0,300.0,1.5804,3.1209,316.18,8000,8000
145.54508,1.4402,7.6727,0.0,300.0,1.5856,4.1558,316.1,8000,8000
145.54708,0.57418,7.6643,0.0,300.0,1.5819,1.6627,316.02,8000,8000
145.54908,0.52314,7.6624,0.0,300.0,1.5792,1.6539,315.94,8000,8000
145.55108,0.92207,7.6604,0.0,300.0,1.5757,2.8235,315.86,8000,8000
145.55308,0.89066,7.6555,0.0,300.0,1.5764,2.666,315.78,8000,8000
145.55508,0.71894,7.6581,0.0,300.0,1.5784,2.1605,315.7,8000,8000
145.55708,0.72228,7.6524,0.0,300.0,1.5772,2.2062,315.63,8000,8000
145.55908,0.80601,7.655,0.0,300.0,1.5762,2.4269,315.56,8000,8000
145.56108,0.78585,7.6601,0.0,300.0,1.5757,2.3534,315.48,8000,8000
145.56308,0.75864,7.6599,0.0,300.0,1.5782,2.2804,315.41,8000,8000
145.56508,0.79361,7.6607,0.0,300.0,1.5787,2.3921,315.33,8000,8000
145.56708,0.80569,7.6524,0.0,300.0,1.578,2.4212,315.25,8000,8000
145.56908,0.82207,7.6569,0.0,300.0,1.5782,2.4622,315.18,8000,8000
145.57108,0.81757,7.6592,0.0,300.0,1.575,2.4715,315.1,8000,8000
145.57308,0.82646,7.6565,0.0,300.0,1.5755,2.4818,315.02,8000,8000
145.57508,0.79317,7.658,0.0,300.0,1.5761,2.3491,314.93,8000,8000
145.57708,0.82857,7.6555,0.0,300.0,1.5792,2.4635,314.85,8000,8000
145.57908,0.85389,7.6589,0.0,300.0,1.5796,2.5436,314.76,8000,8000
145.58108,0.86495,7.657,0.0,300.0,1.5755,2.6018,314.68,8000,8000
145.58308,0.86389,7.6569,0.0,300.0,1.5753,2.5975,314.59,8000,8000
145.58508,0.8809,7.657,0.0,300.0,1.575,2.6395,314.52,8000,8000
145.58708,0.87917,7.6536,0.0,300.0,1.5784,2.6638,314.45,8000,8000
145.58908,0.88473,7.6555,0.0,300.0,1.5785,2.6511,314.38,8000,8000
145.59108,0.88734,7.6573,0.0,300.0,1.5764,2.6782,314.31,8000,8000
145.59308,0.93576,7.6578,0.0,300.0,1.5756,2.8306,314.25,8000,8000
145.59508,0.92433,7.6591,0.0,300.0,1.5755,2.7981,314.2,8000,8000
145.59708,0.91236,7.6539,0.0,300.0,1.5782,2.7715,314.17,8000,8000
145.59908,0.88784,7.6564,0.0,300.0,1.5789,2.6933,314.14,8000,8000
145.60108,0.86866,7.6551,0.0,300.0,1.5764,2.6271,314.11,8000,8000
145.60308,0.87697,7.6573,0.0,300.0,1.5756,2.6431,314.08,8000,8000
145.60508,0.89782,7.6576,0.0,300.0,1.5742,2.747,314.04,8000,8000
145.60708,0.88847,7.655,0.0,300.0,1.5776,2.7011,314.0,8000,8000
145.60908,0.87173,7.6576,0.0,300.0,1.579,2.6545,313.96,8000,8000
145.61108,0.87532,7.6564,0.0,300.0,1.5776,2.6806,313.91,8000,8000
145.61308,0.90941,7.6609,0.0,300.0,1.5776,2.7561,313.87,8000,8000
145.61508,0.89063,7.6585,0.0,300.0,1.5742,2.6933,313.82,8000,8000
145.61708,0.90807,7.6561,0.0,300.0,1.5778,2.7371,313.77,8000,8000
145.61908,0.88975,7.6552,0.0,300.0,1.5778,2.6977,313.73,8000,8000
145.62108,0.88677,7.6552,0.0,300.0,1.5784,2.7114,313.68,8000,8000
145.62308,0.89361,7.6615,0.0,300.0,1.5788,2.7565,313.63,8000,8000
145.62508,0.93655,7.6603,0.0,300.0,1.5747,2.8373,313.58,8000,8000
145.62708,0.94638,7.6565,0.0,300.0,1.577,2.8649,313.53,8000,8000
145.62908,0.94566,7.6579,0.0,300.0,1.5778,2.8718,313.48,8000,8000
145.63107,1.0038,7.6565,0.0,300.0,1.5795,3.0753,313.43,8000,8000
145.63307,0.98657,7.6592,0.0,300.0,1.5782,2.9952,313.38,8000,8000
145.63507,0.96414,7.6598,0.0,300.0,1.5753,2.9461,313.34,8000,8000
145.63707,0.98358,7.657,0.0,300.0,1.5764,3.0282,313.3,8000,8000
145.63907,0.99621,7.6596,0.0,300.0,1.5775,3.0721,313.27,8000,8000
145.64107,0.9807,7.6552,0.0,300.0,1.5793,3.0281,313.23,8000,8000
145.64307,0.96019,7.6587,0.0,300.0,1.5792,2.959,313.19,8000,8000
145.64507,0.9612,7.66,0.0,300.0,1.576,2.9576,313.17,8000,8000
145.64707,0.9585,7.659,0.0,300.0,1.5769,2.9755,313.14,8000,8000
145.64907,0.94763,7.6562,0.0,300.0,1.575,2.9047,313.12,8000,8000
145.65107,0.94033,7.6521,0.0,300.0,1.5779,2.8973,313.09,8000,8000
145.65307,0.93968,7.6544,0.0,300.0,1.5778,2.8933,313.07,8000,8000
145.65507,0.91985,7.654,0.0,300.0,1.5742,2.8131,313.03,8000,8000
145.65707,0.89627,7.6574,0.0,300.0,1.5758,2.7327,312.99,8000,8000
145.65907,0.92605,7.6566,0.0,300.0,1.5747,2.8348,312.95,8000,8000
145.66107,0.94087,7.6526,0.0,300.0,1.578,2.8613,312.9,8000,8000
145.66307,0.93137,7.6527,0.0,300.0,1.577,2.8111,312.86,8000,8000
145.66507,0.93313,7.6534,0.0,300.0,1.5752,2.8369,312.82,8000,8000
145.66707,0.94228,7.6577,0.0,300.0,1.5758,2.8333,312.78,8000,8000
145.66907,0.94645,7.6545,0.0,300.0,1.5731,2.8473,312.75,8000,8000
145.67107,0.97191,7.6506,0.0,300.0,1.5765,2.9102,312.71,8000,8000
145.67307,0.98258,7.6543,0.0,300.0,1.578,2.9466,312.67,8000,8000
145.67507,0.99187,7.6511,0.0,300.0,1.575,2.9484,312.65,8000,8000
145.67707,1.0048,7.6528,0.0,300.0,1.5737,3.0076,312.62,8000,8000
145.67907,1.0218,7.6545,0.0,300.0,1.5723,3.0516,312.6,8000,8000
145.68107,1.0414,7.6532,0.0,300.0,1.5768,3.0829,312.57,8000,8000
145.68307,1.0516,7.6516,0.0,300.0,1.5763,3.122,312.55,8000,8000
145.68507,1.0711,7.6495,0.0,300.0,1.5749,3.1737,312.52,8000,8000
145.68707,1.0865,7.6551,0.0,300.0,1.5752,3.2196,312.48,8000,8000
145.68907,1.1112,7.6565,0.0,300.0,1.573,3.2835,312.44,8000,8000
145.69107,1.1143,7.6505,0.0,300.0,1.5746,3.287,312.41,8000,8000
145.69307,1.1305,7.6537,0.0,300.0,1.5765,3.3583,312.37,8000,8000
145.69507,1.1446,7.6502,0.0,300.0,1.5758,3.4089,312.34,8000,8000
145.69707,1.1562,7.6556,0.0,300.0,1.5757,3.4263,312.31,8000,8000
145.69907,1.168,7.6563,0.0,300.0,1.5731,3.4955,312.27,8000,8000
145.70107,1.1813,7.6536,0.0,300.0,1.5753,3.5124,312.24,8000,8000
145.70307,1.1984,7.6551,0.0,300.0,1.5761,3.5629,312.21,8000,8000
145.70507,1.209,7.6524,0.0,300.0,1.5773,3.6093,312.18,8000,8000
145.70707,1.2134,7.6554,0.0,300.0,1.5767,3.6457,312.13,8000,8000
145.70907,1.2169,7.6556,0.0,300.0,1.5733,3.6578,312.09,8000,8000
145.71107,1.2227,7.6552,0.0,300.0,1.5755,3.7,312.05,8000,8000
145.71307,1.2312,7.6565,0.0,300.0,1.5757,3.7453,312.0,8000,8000
145.71507,1.2232,7.6529,0.0,300.0,1.5781,3.7023,311.97,8000,8000
145.71707,1.2037,7.6559,0.0,300.0,1.5777,3.6384,311.93,8000,8000
145.71907,1.2293,7.6542,0.0,300.0,1.5734,3.7276,311.89,8000,8000
145.72107,1.2234,7.6562,0.0,300.0,1.5754,3.7284,311.86,8000,8000
145.72307,1.2056,7.6585,0.0,300.0,1.576,3.6919,311.82,8000,8000
145.72507,1.2175,7.6533,0.0,300.0,1.5779,3.7233,311.79,8000,8000
145.72707,1.2037,7.6556,0.0,300.0,1.578,3.6904,311.75,8000,8000
145.72907,1.1997,7.655,0.0,300.0,1.5749,3.6991,311.72,8000,8000
145.73107,1.1772,7.6565,0.0,300.0,1.5752,3.6212,311.69,8000,8000
145.73307,1.178,7.6583,0.0,300.0,1.5753,3.6416,311.66,8000,8000
145.73507,1.1561,7.6535,0.0,300.0,1.5785,3.5876,311.64,8000,8000
145.73707,1.1385,7.6566,0.0,300.0,1.5788,3.5205,311.61,8000,8000
145.73907,1.1368,7.6553,0.0,300.0,1.576,3.5614,311.59,8000,8000
145.74107,1.1248,7.6586,0.0,300.0,1.5759,3.5057,311.56,8000,8000
145.74307,1.1113,7.6585,0.0,300.0,1.5748,3.4373,311.54,8000,8000
145.74507,1.1011,7.6556,0.0,300.0,1.5788,3.4065,311.52,8000,8000
145.74707,1.0903,7.6566,0.0,300.0,1.5787,3.3728,311.52,8000,8000
145.74907,1.0708,7.6557,0.0,300.0,1.577,3.3192,311.51,8000,8000
145.75107,1.0663,7.661,0.0,300.0,1.5778,3.3039,311.51,8000,8000
145.75307,1.0547,7.6602,0.0,300.0,1.5749,3.2557,311.5,8000,8000
145.75507,1.05,7.6543,0.0,300.0,1.5774,3.2365,311.47,8000,8000
145.75707,1.0377,7.6579,0.0,300.0,1.579,3.1596,311.43,8000,8000
145.75907,1.0352,7.6553,0.0,300.0,1.5778,3.1848,311.39,8000,8000
145.76107,1.0301,7.6577,0.0,300.0,1.5765,3.1762,311.34,8000,8000
145.76307,1.0261,7.6586,0.0,300.0,1.5742,3.1508,311.3,8000,8000
145.76507,1.0265,7.6558,0.0,300.0,1.5773,3.1208,311.24,8000,8000
145.76707,1.0138,7.6565,0.0,300.0,1.5782,3.0992,311.18,8000,8000
145.76906,1.0198,7.6531,0.0,300.0,1.5778,3.1074,311.11,8000,8000
145.77106,1.0336,7.6559,0.0,300.0,1.5765,3.1241,311.04,8000,8000
145.77306,1.0361,7.6588,0.0,300.0,1.5746,3.131,310.98,8000,8000
145.77506,1.0296,7.657,0.0,300.0,1.5767,3.1004,310.92,8000,8000
145.77706,1.0326,7.6529,0.0,300.0,1.5748,3.0654,310.88,8000,8000
145.77906,1.0612,7.6551,0.0,300.0,1.579,3.1791,310.84,8000,8000
145.78106,1.0644,7.6581,0.0,300.0,1.5782,3.1863,310.79,8000,8000
145.78306,1.0856,7.6557,0.0,300.0,1.5738,3.2281,310.75,8000,8000
145.78506,1.0988,7.6567,0.0,300.0,1.5761,3.2981,310.72,8000,8000
145.78706,1.1111,7.6592,0.0,300.0,1.5768,3.314,310.68,8000,8000
145.78906,1.131,7.6535,0.0,300.0,1.5785,3.3711,310.65,8000,8000
145.79106,1.1455,7.6552,0.0,300.0,1.5779,3.4061,310.62,8000,8000
145.79306,1.168,7.6587,0.0,300.0,1.5763,3.4793,310.59,8000,8000
145.79506,1.1712,7.6586,0.0,300.0,1.5766,3.4817,310.55,8000,8000
145.79706,1.2096,7.6578,0.0,300.0,1.5755,3.5886,310.5,8000,8000
145.79906,1.2099,7.6538,0.0,300.0,1.5787,3.5972,310.45,8000,8000
145.80106,1.2304,7.6585,0.0,300.0,1.5795,3.6643,310.4,8000,8000
145.80306,1.2457,7.6558,0.0,300.0,1.5754,3.7309,310.36,8000,8000
145.80506,1.2725,7.6599,0.0,300.0,1.5769,3.7831,310.32,8000,8000
145.80706,1.2847,7.6587,0.0,300.0,1.5751,3.8345,310.3,8000,8000
145.80906,1.2865,7.6544,0.0,300.0,1.578,3.8526,310.27,8000,8000
145.81106,1.3126,7.6566,0.0,300.0,1.5787,3.9297,310.25,8000,8000
145.81306,1.3051,7.6583,0.0,300.0,1.5778,3.9026,310.22,8000,8000
145.81506,1.3161,7.6593,0.0,300.0,1.5762,3.946,310.2,8000,8000
145.81706,1.3188,7.6585,0.0,300.0,1.5745,3.9933,310.18,8000,8000
145.81906,1.3254,7.6552,0.0,300.0,1.5783,3.9928,310.17,8000,8000
145.82106,1.3228,7.6585,0.0,300.0,1.5796,3.9929,310.15,8000,8000
145.82306,1.3266,7.6578,0.0,300.0,1.5784,4.0186,310.13,8000,8000
145.82506,1.3253,7.6588,0.0,300.0,1.5765,4.0331,310.11,8000,8000
145.82706,1.3202,7.6619,0.0,300.0,1.5761,4.0263,310.08,8000,8000
145.82906,1.3264,7.6601,0.0,300.0,1.5792,4.0267,310.06,8000,8000
145.83106,1.3123,7.6578,0.0,300.0,1.5786,4.0116,310.03,8000,8000
145.83306,1.3057,7.6581,0.0,300.0,1.5792,4.0002,310.01,8000,8000
145.83506,1.2874,7.6619,0.0,300.0,1.5786,3.9473,309.97,8000,8000
145.83706,1.2895,7.6623,0.0,300.0,1.5759,3.9612,309.92,8000,8000
145.83906,1.2772,7.6584,0.0,300.0,1.5777,3.9312,309.87,8000,8000
145.84106,1.2564,7.661,0.0,300.0,1.5794,3.8601,309.82,8000,8000
145.84306,1.2402,7.6563,0.0,300.0,1.5789,3.8313,309.78,8000,8000
145.84506,1.2291,7.6592,0.0,300.0,1.5782,3.8002,309.72,8000,8000
145.84706,1.2179,7.6633,0.0,300.0,1.5769,3.7644,309.67,8000,8000
145.84906,1.2046,7.6616,0.0,300.0,1.5787,3.7248,309.61,8000,8000
145.85106,1.1967,7.6601,0.0,300.0,1.578,3.721,309.56,8000,8000
145.85306,1.1746,7.6566,0.0,300.0,1.58,3.6422,309.5,8000,8000
145.85506,1.1594,7.6594,0.0,300.0,1.5793,3.5892,309.45,8000,8000
145.85706,1.1585,7.6614,0.0,300.0,1.5766,3.5803,309.41,8000,8000
145.85906,1.1416,7.6604,0.0,300.0,1.5778,3.5223,309.37,8000,8000
145.86106,1.133,7.6609,0.0,300.0,1.5777,3.5089,309.33,8000,8000
145.86306,1.1202,7.6563,0.0,300.0,1.5792,3.4211,309.28,8000,8000
145.86506,1.123,7.6595,0.0,300.0,1.58,3.4419,309.25,8000,8000
145.86706,1.1085,7.6583,0.0,300.0,1.5761,3.4046,309.22,8000,8000
145.86906,1.1151,7.6604,0.0,300.0,1.5771,3.4015,309.19,8000,8000
145.87106,1.1169,7.6624,0.0,300.0,1.5776,3.416,309.16,8000,8000
145.87306,1.1097,7.6568,0.0,300.0,1.5796,3.3744,309.13,8000,8000
145.87506,1.095,7.6594,0.0,300.0,1.58,3.3416,309.1,8000,8000
145.87706,1.1083,7.6597,0.0,300.0,1.5779,3.3674,309.08,8000,8000
145.87906,1.1204,7.6595,0.0,300.0,1.5769,3.3832,309.06,8000,8000
145.88106,1.1152,7.661,0.0,300.0,1.5763,3.3708,309.05,8000,8000
145.88306,1.116,7.659,0.0,300.0,1.5803,3.3599,309.03,8000,8000
145.88506,1.128,7.6614,0.0,300.0,1.5806,3.3941,309.0,8000,8000
145.88706,1.1477,7.6589,0.0,300.0,1.5781,3.4277,308.97,8000,8000
145.88906,1.1542,7.6608,0.0,300.0,1.5772,3.4616,308.94,8000,8000
145.89106,1.1659,7.6607,0.0,300.0,1.575,3.4923,308.91,8000,8000
145.89306,1.1754,7.6573,0.0,300.0,1.5788,3.517,308.88,8000,8000
145.89506,1.1915,7.6601,0.0,300.0,1.5802,3.5609,308.85,8000,8000
145.89706,1.2125,7.6577,0.0,300.0,1.5781,3.6057,308.82,8000,8000
145.89906,1.2186,7.6607,0.0,300.0,1.5777,3.6224,308.79,8000,8000
145.90106,1.2399,7.6617,0.0,300.0,1.5757,3.6817,308.76,8000,8000
145.90306,1.2463,7.6575,0.0,300.0,1.5782,3.7192,308.73,8000,8000
145.90506,1.2864,7.6586,0.0,300.0,1.5789,3.8303,308.68,8000,8000
145.90705,1.2909,7.658,0.0,300.0,1.58,3.8433,308.63,8000,8000
145.90905,1.3069,7.6631,0.0,300.0,1.5792,3.8827,308.57,8000,8000
145.91105,1.3201,7.6635,0.0,300.0,1.5762,3.9195,308.52,8000,8000
145.91305,1.3347,7.6582,0.0,300.0,1.5773,3.9718,308.46,8000,8000
145.91505,1.3308,7.6608,0.0,300.0,1.5789,4.0125,308.41,8000,8000
145.91705,1.3589,7.6581,0.0,300.0,1.5801,4.041,308.36,8000,8000
146.9176,1.2716,7.6653,0.0,14.703,1.5809,3.8535,282.69,8000,8000
148.6624,1.1684,7.6715,0.0,6.1384,1.5836,3.5423,238.35,8000,8000
150.6624,1.155,7.6799,0.0,11.076,1.5875,3.5041,201.61,8000,8000
152.6624,1.1711,7.6878,0.0,16.075,1.5911,3.5525,175.13,8000,8000
154.6624,1.1857,7.6949,0.0,21.075,1.5945,3.5971,155.11,8000,8000
156.6624,1.1895,7.701,0.0,26.075,1.5974,3.6087,139.06,8000,8000
157.7158,1.1922,7.7037,0.0,28.709,1.5987,3.6166,131.76,8000,8000
159.7158,1.1974,7.7089,0.0,33.709,1.601,3.6319,119.93,8000,8000
161.7158,1.2033,7.7136,0.0,38.709,1.6033,3.6507,109.59,8000,8000
163.7158,1.2049,7.7181,0.0,43.709,1.6054,3.6551,100.77,8000,8000
165.7158,1.2115,7.7218,0.0,48.709,1.6071,3.6745,93.174,8000,8000
167.7158,1.2116,7.7255,0.0,53.709,1.6088,3.6749,86.462,8000,8000
169.7158,1.216,7.7287,0.0,58.709,1.6103,3.6884,80.51,8000,8000
171.7158,1.2169,7.7318,0.0,63.709,1.6119,3.6919,75.234,8000,8000
173.7158,1.2211,7.7348,0.0,68.709,1.6133,3.7043,70.491,8000,8000
175.7158,1.2365,7.7363,27.501,73.709,1.614,3.7498,71.609,8000,8000
177.7158,1.2586,7.7332,31.342,78.709,1.6126,3.817,77.108,8000,8000
179.7158,1.355,7.7013,40.599,83.709,1.5974,4.1163,81.137,8000,8000
181.1846,1.3156,7.7147,28.567,87.402,1.6038,3.9906,88.78,8000,8000
183.1846,1.2435,7.7329,8.1934,92.381,1.6124,3.7722,94.229,8000,8000
185.1846,1.3352,7.7108,41.288,97.381,1.602,4.0514,93.781,8000,8000
187.1846,1.305,7.7121,14.761,99.985,1.6026,3.9591,103.22,8000,8000
188.4033,1.263,7.7254,0.33031,99.999,1.6088,3.8307,107.83,8000,8000
190.4033,1.2493,7.733,0.12841,100.0,1.6124,3.7911,101.12,8000,8000
192.4033,1.3161,7.7213,36.332,100.0,1.6069,3.9923,96.383,8000,8000
194.4033,1.3053,7.7202,21.509,100.0,1.6065,3.9592,101.0,8000,8000
196.4033,1.26,7.7331,16.17,100.0,1.6124,3.8225,100.31,8000,8000
198.4033,1.3171,7.7236,33.359,100.0,1.608,3.9954,98.338,8000,8000
200.4033,1.285,7.728,19.095,100.0,1.6101,3.8973,101.27,8000,8000
202.4033,1.2833,7.7298,26.644,100.0,1.6108,3.8932,99.606,8000,8000
204.4033,1.2871,7.73,26.174,100.0,1.611,3.9058,99.941,8000,8000
206.4033,1.279,7.7303,26.377,100.0,1.6112,3.8797,99.895,8000,8000
208.4033,1.2741,7.7307,26.15,100.0,1.6113,3.8668,99.965,8000,8000
210.4033,1.2837,7.7248,27.057,100.0,1.6085,3.8925,99.87,8000,8000
212.4033,1.2797,7.7319,26.273,100.0,1.6119,3.8831,100.03,8000,8000
213.8019,1.2836,7.7316,26.833,100.0,1.6117,3.8954,99.947,8000,8000
215.8019,1.2843,7.7315,26.92,100.0,1.6117,3.8947,99.972,8000,8000
217.8019,1.2872,7.7312,26.844,100.0,1.6116,3.9052,99.956,8000,8000
219.086,1.296,7.7257,27.091,100.0,1.6091,3.9323,99.933,8000,8000
221.086,1.2923,7.7322,26.465,100.0,1.612,3.9201,100.01,8000,8000
223.086,1.3038,7.7329,26.607,100.0,1.6123,3.9545,100.01,8000,8000
225.086,1.2929,7.7329,26.825,100.0,1.6124,3.9219,99.95,8000,8000
227.086,1.2644,7.7329,0.68868,2.5412,1.6124,3.834,103.36,8000,8000
229.086,1.2507,7.7337,0.0012527,0.0047607,1.6127,3.795,100.36,8000,8000
231.086,1.2625,7.7397,2.3467e-06,8.9187e-06,1.6156,3.8294,95.597,8000,8000
232.086,1.3182,7.7398,1.0157e-07,3.8603e-07,1.6157,3.9986,93.264,8000,8000