File: examples/dan-msc-case-studies/CS4/data/01 raw data/hyde_test_031.csv
Time(sec),Force(kN),Jaw(mm),PowAngle(deg),PTemp,Strain,Stress(MPa),TC1(C),TC2(C),TC3(C)
0.0,3.0406,-0.00011689,0.0,0.0020267,4.4683e-05,9.2396,22.254,22.692,22.316
0.4,3.0384,0.00019558,0.0,1.0214,-1.7457e-05,9.2162,22.245,22.719,22.345
0.8,3.0214,0.00041393,0.0,2.221,1.8697e-05,9.1627,22.302,22.702,22.341
1.2,3.0137,0.0003781,0.0,3.421,4.8985e-05,9.1442,22.266,22.683,22.341
1.6,3.0001,0.00033497,0.0,4.621,8.8907e-05,9.0977,22.256,22.697,22.328
2.0,2.9734,0.00055088,0.0,5.821,5.7244e-05,9.0204,22.277,22.654,22.317
2.4,2.9648,0.00042611,0.0,7.021,6.9312e-05,8.9974,22.24,22.704,22.356
2.8,2.951,0.00052745,0.0,8.221,3.0297e-05,8.9509,22.255,22.705,22.332
3.2,2.9347,0.0005588,0.0,9.421,2.4952e-05,8.9008,22.254,22.71,22.396
3.6,2.9304,0.00056395,0.0,10.621,6.3526e-05,8.8934,22.284,22.73,22.372
4.0,2.9263,0.00044035,0.0,11.821,9.8096e-05,8.8734,22.259,22.686,22.35
4.4,2.911,0.00053781,0.0,13.021,5.4646e-05,8.8299,22.281,22.664,22.339
4.8,2.9148,0.00056043,0.0,14.221,7.9264e-05,8.843,22.283,22.689,22.346
5.2,2.91,0.00055792,0.0,15.421,4.1318e-05,8.828,22.244,22.692,22.378
5.6,2.895,0.00074344,0.0,16.621,4.1835e-05,8.7825,22.28,22.698,22.316
6.0,2.9093,0.00067432,0.0,17.821,7.8803e-05,8.8263,22.225,22.699,22.386
6.4,2.9039,0.00061173,0.0,19.021,0.00011706,8.8053,22.261,22.696,22.367
6.8,2.9017,0.00045869,0.0,20.221,5.1858e-05,8.8053,22.264,22.724,22.402
7.2,2.9053,0.00076146,0.0,21.421,9.0749e-05,8.8125,22.263,22.681,22.356
7.6,2.8994,0.00072366,1.0924,22.621,6.5666e-05,8.7933,22.261,22.721,22.341
8.0,2.8905,0.0012558,16.717,23.821,9.2604e-05,8.772,22.294,22.795,22.422
8.3361,2.8939,0.0013093,24.284,24.837,0.00014226,8.7818,22.506,23.518,22.751
8.7361,2.9114,0.0012566,27.42,26.029,0.00013893,8.8314,23.565,25.716,24.379
9.1361,2.9074,0.0012417,25.222,27.229,8.963e-05,8.8167,25.536,28.205,26.609
9.5361,2.9021,0.00079141,21.842,28.429,6.7357e-05,8.8065,27.486,29.493,28.34
9.9361,2.9004,0.00044267,21.077,29.629,8.4062e-05,8.7981,28.903,30.017,29.312
10.3361,2.8868,0.00025056,22.899,30.829,4.9802e-05,8.755,29.908,33.581,30.018
10.7361,2.9046,-5.1576e-05,25.792,32.029,2.7891e-06,8.8154,30.871,38.444,30.894
11.1361,2.9147,-0.00054942,26.047,33.229,-4.4103e-05,8.8392,32.208,38.575,32.374
11.5361,2.9022,-0.00089363,24.836,34.429,-0.00014188,8.8013,33.725,38.575,33.899
11.9361,2.9038,-0.0010826,24.114,35.629,-0.00013328,8.8118,35.131,38.575,35.171
12.3361,2.9059,-0.0015998,24.51,36.829,-0.00013661,8.8142,36.357,38.575,36.196
12.7361,2.9068,-0.001768,25.223,38.029,-0.00016257,8.8174,37.481,38.456,37.245
13.1361,2.9148,-0.002842,26.188,39.229,-0.00031372,8.8417,38.625,39.689,38.45
13.5347,2.9168,-0.0034803,25.654,40.425,-0.00035391,8.8466,40.026,41.174,39.878
13.9347,2.9102,-0.0034274,24.75,41.625,-0.00042619,8.83,41.394,42.241,41.181
14.3347,2.9199,-0.0033453,25.108,42.825,-0.00039406,8.8595,42.575,43.16,42.179
14.7347,2.922,-0.0038611,26.402,44.025,-0.00039135,8.8625,43.579,44.271,43.22
15.1347,2.9104,-0.0042862,26.032,45.225,-0.0004244,8.8305,44.898,45.696,44.475
15.5347,2.9177,-0.0046869,26.216,46.425,-0.00051832,8.8519,46.148,46.911,45.765
15.9347,2.9188,-0.0049528,25.911,47.625,-0.00052324,8.8512,47.497,48.053,46.997
16.3347,2.9141,-0.005559,25.744,48.825,-0.00063704,8.8431,48.692,49.19,48.158
16.7347,2.9283,-0.005738,26.18,50.025,-0.00065429,8.8814,49.826,50.291,49.236
17.1347,2.9232,-0.0063359,26.871,51.225,-0.00068113,8.8661,50.959,51.418,50.332
17.5347,2.9259,-0.0066339,27.064,52.425,-0.0006815,8.8803,52.189,52.65,51.538
17.9347,2.9353,-0.0068955,26.493,53.625,-0.00076121,8.9026,53.526,53.942,52.843
18.3347,2.9275,-0.007755,26.399,54.825,-0.00082046,8.8754,54.717,54.979,53.89
18.7347,2.941,-0.008706,27.367,56.025,-0.00098184,8.9243,55.821,56.033,54.978
19.1347,2.9407,-0.0091203,27.256,57.225,-0.0010342,8.9181,57.067,57.335,56.226
19.5347,2.9303,-0.0090651,27.079,58.425,-0.00097815,8.8901,58.355,58.635,57.457
19.9347,2.9378,-0.0092714,26.496,59.625,-0.00095604,8.9142,59.604,59.671,58.647
20.3347,2.9418,-0.0094277,27.207,60.825,-0.0010358,8.9216,60.715,60.648,59.668
20.7347,2.9351,-0.010133,27.465,62.025,-0.0010756,8.9069,61.874,61.933,60.901
21.1347,2.9458,-0.01032,27.466,63.225,-0.0011563,8.9372,63.135,63.139,62.067
21.5347,2.9431,-0.010729,27.428,64.425,-0.0012023,8.9258,64.34,64.175,63.273
21.9347,2.9381,-0.011544,27.597,65.625,-0.0012422,8.9144,65.488,65.333,64.452
22.3347,2.9461,-0.012023,27.695,66.825,-0.0012613,8.9374,66.675,66.586,65.583
22.7347,2.9417,-0.012341,27.769,68.025,-0.0013503,8.9212,67.911,67.923,66.867
23.1347,2.9447,-0.012818,28.661,69.225,-0.0013738,8.937,69.0,68.983,67.997
23.5347,2.9502,-0.013217,27.686,70.425,-0.0014769,8.9454,70.428,70.532,69.466
23.9347,2.9392,-0.013969,27.223,71.625,-0.0015571,8.9115,71.707,71.408,70.581
24.3347,2.9501,-0.015146,28.173,72.825,-0.0016311,8.9521,72.713,72.344,71.487
24.7347,2.9536,-0.015974,28.463,74.025,-0.0017023,8.9594,73.867,73.739,72.694
25.1347,2.9445,-0.015825,28.266,75.225,-0.0017436,8.9307,75.176,75.109,73.989
25.5347,2.9462,-0.015771,27.755,76.425,-0.0016976,8.9412,76.394,76.284,75.228
25.9347,2.959,-0.015804,28.617,77.625,-0.0017544,8.9752,77.512,77.271,76.253
26.3347,2.9483,-0.016615,28.663,78.825,-0.0018544,8.9449,78.697,78.519,77.483
26.7347,2.96,-0.017437,28.663,80.025,-0.0018963,8.9804,79.945,79.751,78.72
27.1347,2.9586,-0.017852,28.333,81.225,-0.0018994,8.9738,81.189,80.924,79.864
27.5347,2.9498,-0.018345,28.899,82.425,-0.0020076,8.9486,82.356,82.028,81.042
27.9347,2.9634,-0.018749,28.668,83.625,-0.002028,8.9892,83.542,83.189,82.192
28.3347,2.96,-0.019237,28.903,84.825,-0.0021223,8.9771,84.702,84.336,83.309
28.7347,2.9589,-0.019763,29.163,86.025,-0.0021992,8.9781,85.906,85.583,84.528
29.1347,2.9688,-0.020258,29.029,87.225,-0.0022089,9.008,87.145,86.748,85.752
29.5347,2.9598,-0.021067,29.665,88.425,-0.0022555,8.9765,88.257,87.915,86.918
29.9347,2.9665,-0.021546,28.778,89.625,-0.0023518,9.0015,89.614,89.265,88.171
30.3347,2.973,-0.022169,28.914,90.825,-0.0024032,9.0166,90.814,90.243,89.27
30.7347,2.9702,-0.023356,29.132,92.025,-0.0025533,9.009,91.951,91.381,90.342
31.1347,2.9788,-0.024088,29.388,93.225,-0.0026643,9.0403,93.158,92.588,91.55
31.5347,2.9832,-0.0245,29.383,94.425,-0.0026882,9.048,94.392,93.844,92.742
31.9347,2.9758,-0.024208,29.356,95.625,-0.0026004,9.0285,95.62,94.905,93.909
32.3347,2.9796,-0.024479,29.114,96.825,-0.0026686,9.0416,96.84,96.007,95.071
32.7347,2.9827,-0.024975,29.975,98.025,-0.0027162,9.0459,97.94,97.086,96.127
33.13471,2.9753,-0.025548,29.821,99.225,-0.0027879,9.0258,99.145,98.4,97.41
33.53471,2.9812,-0.025926,29.789,100.43,-0.0028649,9.0466,100.4,99.58,98.65
33.93471,2.9806,-0.026655,29.828,101.63,-0.0029185,9.0385,101.53,100.67,99.749
34.33471,2.973,-0.027343,29.795,102.83,-0.0029387,9.0191,102.79,101.9,100.94
34.73471,2.9865,-0.028192,29.896,104.03,-0.0030641,9.0612,103.97,103.01,102.1
35.13471,2.9775,-0.028538,30.009,105.23,-0.0031082,9.0275,105.15,104.08,103.24
35.53471,2.9783,-0.029147,29.999,106.43,-0.0031819,9.0361,106.35,105.18,104.32
35.93471,2.9875,-0.029309,30.539,107.63,-0.0032313,9.065,107.5,106.32,105.46
36.33471,2.9835,-0.030076,30.163,108.83,-0.0032915,9.0492,108.74,107.6,106.7
36.73471,2.983,-0.031253,30.201,110.03,-0.0033634,9.0522,110.0,108.75,107.88
37.13471,2.9976,-0.032412,30.266,111.23,-0.003524,9.0919,111.17,109.84,109.09
37.53471,2.9867,-0.03335,30.181,112.43,-0.0036224,9.0598,112.36,110.94,110.17
37.93471,2.9856,-0.033183,30.394,113.63,-0.0036378,9.0592,113.58,112.12,111.36
38.33471,2.9972,-0.032892,30.451,114.83,-0.0036364,9.0905,114.77,113.32,112.57
38.73471,2.9826,-0.033146,30.428,116.03,-0.0036296,9.0491,116.01,114.53,113.76
39.13471,2.9899,-0.03394,30.492,117.23,-0.0036544,9.0732,117.18,115.68,114.93
39.53471,2.9954,-0.034494,30.822,118.43,-0.0037509,9.0853,118.35,116.82,116.03
39.93471,2.9799,-0.035208,30.967,119.63,-0.0038284,9.0417,119.53,117.96,117.2
40.33471,2.9946,-0.035681,30.827,120.83,-0.0038952,9.0877,120.76,119.24,118.51
40.73471,2.9856,-0.036025,30.835,122.03,-0.0039586,9.0541,121.96,120.34,119.61
40.9689,2.9988,-0.036819,30.88,122.73,-0.0039591,9.0953,122.66,121.14,120.28
41.3689,2.9888,-0.037182,30.845,123.93,-0.0040581,9.0654,123.89,122.32,121.54
41.7689,2.9871,-0.038024,30.874,125.13,-0.004126,9.0638,125.1,123.45,122.74
42.1689,2.9993,-0.038307,30.893,126.33,-0.0041891,9.0971,126.29,124.62,123.89
42.5689,2.988,-0.039346,30.881,127.53,-0.0043189,9.0641,127.47,125.79,125.1
42.9689,3.0029,-0.040611,31.377,128.73,-0.0044291,9.1085,128.63,127.17,126.33
43.3689,3.0075,-0.042164,30.961,129.93,-0.0045526,9.122,129.93,128.32,127.62
43.7689,2.9974,-0.041851,31.038,131.13,-0.0045729,9.0927,131.08,129.53,128.77
44.1689,3.0077,-0.041344,31.197,132.33,-0.0044954,9.1266,132.28,130.66,129.97
44.5689,3.0028,-0.041758,31.27,133.53,-0.0045731,9.1063,133.49,131.94,131.17
44.9689,2.9965,-0.04235,30.975,134.73,-0.0046472,9.0897,134.71,133.15,132.45
45.3689,3.0073,-0.042992,31.599,135.93,-0.0046964,9.1215,135.83,134.28,133.59
45.7689,3.004,-0.043768,31.557,137.13,-0.0047213,9.1098,137.05,135.41,134.78
46.1689,2.9961,-0.044351,31.334,138.33,-0.004829,9.0915,138.31,136.69,135.99
46.5689,3.0075,-0.045073,31.543,139.53,-0.0049006,9.1229,139.49,137.79,137.15
46.9689,3.0006,-0.04546,31.207,140.73,-0.0049684,9.0989,140.75,139.01,138.34
47.3689,3.0034,-0.046049,31.255,141.93,-0.0050568,9.1123,141.95,140.23,139.54
47.7689,3.0096,-0.046769,31.768,143.13,-0.0050984,9.1276,143.09,141.25,140.66
48.1689,2.9958,-0.048063,31.755,144.33,-0.005185,9.0862,144.3,142.49,141.8
48.5689,3.0103,-0.048928,31.543,145.53,-0.0053216,9.1339,145.51,143.57,143.05
48.9689,3.012,-0.050504,31.713,146.73,-0.0054894,9.1353,146.69,144.78,144.2
49.3689,2.9984,-0.050843,31.456,147.93,-0.0055675,9.0959,147.91,145.97,145.41
49.7689,3.0123,-0.05016,31.874,149.13,-0.0055065,9.1405,149.11,147.22,146.65
50.1689,3.0051,-0.05054,31.732,150.33,-0.0055142,9.1155,150.32,148.45,147.98
50.5689,3.0007,-0.051259,31.602,151.53,-0.0055426,9.1052,151.53,149.63,149.1
50.9689,3.0094,-0.051887,31.563,152.73,-0.0056513,9.1311,152.8,150.86,150.29
51.3689,3.005,-0.052547,31.393,153.93,-0.0057152,9.1142,153.97,151.94,151.52
51.7689,3.0005,-0.053315,31.882,155.13,-0.0058202,9.1056,155.11,153.22,152.64
52.1689,3.0104,-0.053969,31.835,156.33,-0.0059188,9.1318,156.26,154.32,153.81
52.5689,3.0045,-0.054846,32.119,157.53,-0.0059843,9.1105,157.45,155.53,154.96
52.9689,2.9975,-0.055537,31.924,158.73,-0.006005,9.094,158.69,156.78,156.16
53.3689,3.0111,-0.05592,32.127,159.93,-0.0060937,9.1367,159.86,158.01,157.38
53.7689,3.0007,-0.05679,32.294,161.13,-0.0061794,9.1006,161.08,159.3,158.64
54.1689,3.0035,-0.057786,32.261,162.33,-0.0063012,9.1128,162.26,160.42,159.83
54.5689,3.0144,-0.059168,32.424,163.53,-0.006474,9.1432,163.46,161.58,160.92
54.9689,3.0052,-0.060656,32.386,164.73,-0.0066203,9.1169,164.65,162.71,162.13
55.3689,3.0128,-0.060211,32.83,165.93,-0.0065219,9.1425,165.79,163.93,163.25
55.7689,3.0156,-0.059715,32.571,167.13,-0.0065047,9.1465,167.05,165.18,164.5
56.1689,3.0012,-0.060364,32.406,168.33,-0.006562,9.1072,168.33,166.42,165.72
56.5689,3.0089,-0.061001,32.364,169.53,-0.0066518,9.1293,169.49,167.64,166.95
56.9689,3.0096,-0.061805,32.807,170.73,-0.0067748,9.1287,170.66,168.73,168.08
57.3689,2.9981,-0.062763,32.74,171.93,-0.0068442,9.0942,171.89,170.0,169.32
57.7689,3.011,-0.063513,32.57,173.13,-0.0068758,9.1372,173.14,171.1,170.54
58.1689,3.003,-0.064103,32.571,174.33,-0.0069851,9.1079,174.35,172.27,171.66
58.5689,2.9967,-0.06479,32.84,175.53,-0.0070491,9.0931,175.5,173.38,172.86
58.9689,3.0096,-0.06525,32.468,176.73,-0.0071198,9.1314,176.77,174.58,174.08
59.3689,3.0101,-0.066825,32.845,177.93,-0.0073201,9.1274,177.91,175.66,175.24
59.7689,3.0073,-0.069073,32.795,179.13,-0.0075185,9.1277,179.08,176.81,176.4
60.16891,3.0142,-0.068429,33.055,180.33,-0.0074256,9.1425,180.22,178.02,177.6
60.56891,3.0087,-0.067733,32.892,181.53,-0.0073843,9.1257,181.44,179.23,178.83
60.96891,3.0039,-0.068282,32.937,182.73,-0.0074274,9.1148,182.73,180.43,180.03
61.36891,3.0124,-0.069062,32.666,183.93,-0.0075437,9.1355,184.0,181.6,181.25
61.76891,2.9985,-0.06983,32.839,185.13,-0.0076425,9.0986,185.1,182.62,182.33
62.16891,3.0038,-0.070667,32.992,186.33,-0.0076935,9.1147,186.25,183.84,183.47
62.56891,3.0063,-0.071297,33.199,187.53,-0.007716,9.1174,187.44,184.98,184.74
62.96891,2.9954,-0.071974,32.864,188.73,-0.0078493,9.0879,188.73,186.17,185.94
63.36891,3.0051,-0.072675,33.213,189.93,-0.0078913,9.1209,189.86,187.3,187.11
63.76891,3.0091,-0.074258,32.893,191.13,-0.0081107,9.1248,191.14,188.64,188.38
64.16891,3.0032,-0.076446,32.857,192.33,-0.008361,9.1127,192.38,189.78,189.58
64.56891,3.0125,-0.075465,32.849,193.53,-0.0082149,9.1381,193.57,190.97,190.82
64.96891,3.0098,-0.075166,33.014,194.73,-0.0081431,9.1304,194.75,192.1,191.99
65.36891,3.0029,-0.075889,32.924,195.93,-0.0082603,9.11,195.97,193.29,193.14
65.76891,3.0085,-0.076764,32.849,197.13,-0.0083355,9.1307,197.17,194.39,194.36
66.16891,3.0043,-0.077344,32.899,198.33,-0.0084494,9.1129,198.33,195.57,195.46
66.56891,3.0009,-0.078395,33.042,199.53,-0.0085747,9.1067,199.53,196.8,196.72
66.96891,3.0055,-0.079107,32.849,200.73,-0.008605,9.1184,200.78,197.96,197.94
67.36891,3.0026,-0.079861,33.051,201.93,-0.008644,9.1063,201.94,199.08,199.09
67.76891,3.0048,-0.080787,32.595,203.13,-0.0087919,9.1167,203.23,200.2,200.3
68.16891,3.0132,-0.082436,32.849,204.33,-0.0089375,9.1399,204.36,201.28,201.44
68.56891,3.0057,-0.084031,32.893,205.53,-0.0091881,9.1177,205.53,202.48,202.56
68.96891,3.0084,-0.082932,32.971,206.73,-0.0090709,9.1262,206.78,203.63,203.7
69.36891,3.0122,-0.08268,32.706,207.93,-0.008996,9.1345,207.98,204.83,204.93
69.76891,3.0026,-0.08349,33.06,209.13,-0.0090401,9.1073,209.12,205.88,206.08
70.16891,3.0077,-0.084226,32.968,210.33,-0.0091635,9.1249,210.33,207.1,207.22
70.56891,3.0048,-0.084873,32.905,211.53,-0.0092184,9.1139,211.57,208.23,208.43
70.96891,3.0006,-0.085663,33.198,212.73,-0.009364,9.105,212.68,209.33,209.57
71.36891,3.0092,-0.086394,33.176,213.93,-0.0094366,9.1311,213.9,210.49,210.83
71.76891,2.9997,-0.087284,33.446,215.13,-0.0094944,9.0969,215.08,211.64,211.95
72.16891,2.999,-0.087925,33.281,216.33,-0.0095186,9.1003,216.29,212.78,213.17
72.56891,3.0058,-0.089068,33.123,217.53,-0.0096938,9.1191,217.53,213.97,214.36
72.96891,3.0014,-0.090442,33.044,218.73,-0.0098065,9.0994,218.73,215.11,215.56
73.36891,3.0088,-0.092437,33.106,219.93,-0.010101,9.1311,219.95,216.24,216.67
73.6897,3.0093,-0.091855,33.442,220.89,-0.010021,9.1328,220.81,217.15,217.6
74.0897,3.0144,-0.09087,33.433,222.09,-0.0098786,9.1409,222.04,218.35,218.86
74.4897,2.9948,-0.091552,33.268,223.29,-0.009976,9.0845,223.32,219.57,220.02
74.7233,3.0054,-0.092074,33.339,223.99,-0.010021,9.1152,224.01,220.19,220.77
75.1233,3.0,-0.092532,33.193,225.19,-0.010044,9.1029,225.19,221.31,221.91
75.5233,3.0114,-0.093404,33.592,226.39,-0.010191,9.1365,226.36,222.56,223.13
75.9233,2.9948,-0.094278,33.752,227.59,-0.010288,9.0805,227.53,223.65,224.28
76.3233,2.9968,-0.094948,33.561,228.79,-0.010329,9.0947,228.77,224.79,225.48
76.7233,3.0034,-0.096084,33.798,229.99,-0.010405,9.1107,229.95,225.99,226.66
77.1233,2.9988,-0.09657,33.711,231.19,-0.010508,9.096,231.18,227.12,227.88
77.5233,2.9957,-0.097449,33.752,232.39,-0.010585,9.0923,232.36,228.28,229.0
77.9233,3.0086,-0.098703,33.942,233.59,-0.01074,9.1224,233.52,229.41,230.09
78.3233,3.001,-0.10076,33.699,234.79,-0.010989,9.1035,234.77,230.62,231.46
78.7233,3.0078,-0.10091,33.776,235.99,-0.010984,9.1271,235.93,231.74,232.58
79.1233,3.0088,-0.099778,33.781,237.19,-0.010825,9.1252,237.18,232.92,233.74
79.5233,3.0031,-0.10005,33.676,238.39,-0.01089,9.1129,238.4,234.11,234.98
79.9233,3.0087,-0.10101,33.772,239.59,-0.010963,9.1293,239.55,235.14,236.06
80.3233,3.0021,-0.10151,34.053,240.79,-0.01107,9.1039,240.75,236.32,237.27
80.7233,3.0007,-0.10245,34.152,241.99,-0.011172,9.1042,241.91,237.53,238.41
81.1233,3.0052,-0.10352,33.859,243.19,-0.011238,9.1192,243.17,238.75,239.63
81.5233,2.9988,-0.10422,33.821,244.39,-0.011287,9.0945,244.42,239.9,240.85
81.9233,2.9975,-0.10486,34.17,245.59,-0.011404,9.0949,245.58,241.05,242.13
82.3233,2.9994,-0.10552,34.136,246.79,-0.011449,9.1,246.77,242.23,243.26
82.7233,2.9966,-0.10669,33.773,247.99,-0.011633,9.0861,248.03,243.44,244.5
83.1233,3.006,-0.10865,33.885,249.19,-0.011828,9.1232,249.21,244.64,245.64
83.5233,3.0122,-0.11032,33.833,250.39,-0.011981,9.1366,250.39,245.8,246.78
83.9233,3.0075,-0.10906,34.16,251.59,-0.011832,9.1195,251.6,247.0,248.0
84.3233,3.0069,-0.10861,33.801,252.79,-0.011818,9.1252,252.81,248.2,249.31
84.7233,3.01,-0.10906,34.159,253.99,-0.011831,9.1296,253.96,249.22,250.39
85.1233,3.0017,-0.1098,33.854,255.19,-0.011975,9.1067,255.21,250.47,251.62
85.5233,3.0061,-0.11096,33.892,256.39,-0.012086,9.1233,256.43,251.66,252.79
85.9233,3.004,-0.11191,33.852,257.59,-0.012141,9.1105,257.63,252.8,254.02
86.3233,2.9991,-0.11261,34.199,258.79,-0.012205,9.0993,258.77,253.87,255.19
86.7233,3.0071,-0.11337,34.445,259.99,-0.012329,9.1252,259.94,255.04,256.39
87.1233,3.0048,-0.11383,34.137,261.19,-0.01236,9.1119,261.18,256.21,257.56
87.5233,2.9964,-0.11485,34.411,262.39,-0.012517,9.0928,262.34,257.42,258.72
87.9233,3.0027,-0.11607,34.254,263.59,-0.012635,9.1077,263.6,258.61,259.94
88.3233,3.0073,-0.11804,34.463,264.79,-0.012787,9.1194,264.74,259.66,261.13
88.7233,3.0074,-0.12014,34.532,265.99,-0.013029,9.1256,265.93,260.81,262.29
89.1233,3.0085,-0.11879,34.346,267.19,-0.01293,9.1253,267.22,262.06,263.48
89.5233,3.0079,-0.118,34.46,268.39,-0.012815,9.1247,268.39,263.23,264.71
89.9233,3.0017,-0.11861,34.561,269.59,-0.012923,9.1098,269.55,264.37,265.88
90.3233,3.0096,-0.11925,34.537,270.79,-0.012976,9.129,270.73,265.44,266.98
90.7233,2.9988,-0.12053,34.424,271.99,-0.01306,9.0958,271.93,266.66,268.17
91.1233,2.9981,-0.12117,34.65,273.19,-0.013145,9.0997,273.11,267.75,269.34
91.5233,3.0057,-0.12218,34.732,274.39,-0.013269,9.1177,274.31,268.89,270.58
91.9233,2.9938,-0.12275,34.653,275.59,-0.013339,9.0822,275.55,270.1,271.72
92.3233,3.0006,-0.1233,34.69,276.79,-0.013446,9.1065,276.73,271.25,272.85
92.7233,3.0042,-0.12438,34.767,277.99,-0.013531,9.1096,277.98,272.35,274.12
93.1233,2.9986,-0.12583,34.805,279.19,-0.013626,9.096,279.14,273.55,275.31
93.5233,3.0117,-0.12743,34.658,280.39,-0.013815,9.1399,280.41,274.74,276.6
93.92331,3.0089,-0.13008,34.786,281.59,-0.014122,9.1259,281.64,275.89,277.71
94.32331,3.0053,-0.12858,34.834,282.79,-0.013986,9.1154,282.77,277.05,278.9
94.72331,3.0133,-0.12738,34.924,283.99,-0.013891,9.142,283.97,278.23,280.13
95.12331,2.9996,-0.12813,34.643,285.19,-0.013933,9.0971,285.19,279.35,281.33
95.52331,2.9947,-0.12916,34.848,286.39,-0.013976,9.0874,286.4,280.5,282.43
95.92331,3.0103,-0.13009,34.947,287.59,-0.014123,9.1314,287.56,281.75,283.58
96.32331,2.9998,-0.13086,35.222,288.79,-0.014204,9.0981,288.69,282.88,284.79
96.72331,2.9991,-0.13151,34.727,289.99,-0.014291,9.0994,290.03,284.14,286.04
97.12331,3.0053,-0.13219,34.946,291.19,-0.014394,9.1159,291.16,285.2,287.18
97.52331,2.9932,-0.13318,34.715,292.39,-0.014481,9.0779,292.43,286.35,288.41
97.92331,3.0026,-0.13394,35.163,293.59,-0.014496,9.1109,293.57,287.53,289.58
98.32331,3.0004,-0.135,34.928,294.79,-0.01464,9.0999,294.83,288.67,290.82
98.72331,2.9988,-0.13627,35.054,295.99,-0.014778,9.0931,296.0,289.86,292.05
99.12331,3.0135,-0.1388,34.78,297.19,-0.015072,9.1433,297.25,291.02,293.23
99.52331,3.0093,-0.13934,34.733,298.39,-0.015184,9.125,298.47,292.21,294.38
99.92331,3.005,-0.13785,34.68,299.59,-0.014989,9.1158,299.66,293.31,295.62
100.32331,3.0076,-0.13734,32.988,300.0,-0.014873,9.126,300.47,293.9,296.57
100.72331,3.0003,-0.13723,32.861,300.0,-0.014891,9.0995,300.45,293.68,296.54
101.12331,2.9914,-0.13745,32.851,300.0,-0.014907,9.0778,300.34,293.37,296.33
101.52331,3.0055,-0.13785,32.936,300.0,-0.014978,9.119,300.29,293.38,296.11
101.92331,2.995,-0.13819,33.036,300.0,-0.015055,9.0834,300.24,293.4,296.1
102.32331,2.9939,-0.13865,33.065,300.0,-0.015067,9.0814,300.18,293.37,296.07
102.72331,3.0027,-0.13899,33.051,300.0,-0.015048,9.1075,300.18,293.39,296.0
103.12331,2.994,-0.13906,32.997,300.0,-0.015096,9.08,300.18,293.41,296.06
103.52331,2.9954,-0.13932,33.288,300.0,-0.015113,9.0885,300.11,293.36,296.05
103.92331,2.9991,-0.13931,32.974,300.0,-0.015143,9.0974,300.16,293.41,296.07
104.32331,3.0014,-0.14039,32.948,300.0,-0.015272,9.1016,300.11,293.41,295.99
104.72331,3.0094,-0.14177,33.024,300.0,-0.015376,9.1309,300.07,293.39,295.96
105.12331,3.0036,-0.1432,32.913,300.0,-0.015508,9.1104,300.14,293.44,295.98
105.52331,3.0001,-0.14118,32.849,300.0,-0.015349,9.0994,300.14,293.39,296.02
105.92331,3.0105,-0.13992,32.942,300.0,-0.015191,9.1327,300.09,293.41,295.95
106.319,3.0079,-0.13999,32.859,300.0,-0.015203,9.1222,300.12,293.5,296.03
106.719,2.9931,-0.14012,32.722,300.0,-0.015185,9.0781,300.12,293.53,295.99
107.119,3.0014,-0.1404,32.896,300.0,-0.015264,9.106,300.07,293.38,295.98
107.519,2.9934,-0.14043,33.69,300.0,-0.015285,9.0754,300.04,293.44,295.97
107.919,2.9955,-0.14179,34.313,300.0,-0.015399,9.0877,300.96,294.61,296.53
108.319,3.0013,-0.14196,32.656,300.0,-0.015359,9.1058,301.48,295.08,297.51
108.719,2.9874,-0.14199,32.261,300.0,-0.01542,9.0604,301.49,294.95,297.45
109.119,2.979,-0.1422,32.819,300.0,-0.015417,9.0413,301.39,294.79,297.32
109.519,2.9992,-0.14226,32.84,300.0,-0.01546,9.0981,301.39,294.72,297.24
109.919,2.9823,-0.14298,32.622,300.0,-0.015554,9.0432,301.37,294.8,297.18
110.319,2.9925,-0.14446,32.594,300.0,-0.015662,9.081,301.38,294.75,297.21
110.719,2.9979,-0.1456,32.712,300.0,-0.015762,9.0931,301.36,294.74,297.17
111.119,2.9938,-0.14401,32.953,300.0,-0.01565,9.081,301.47,294.82,297.19
111.519,3.0004,-0.14283,32.879,300.0,-0.015499,9.1051,301.76,295.17,297.43
111.919,2.9977,-0.14269,32.125,300.0,-0.015501,9.0894,301.85,295.18,297.67
112.319,2.9926,-0.14312,32.603,300.0,-0.015569,9.0786,301.79,295.09,297.54
112.719,2.9991,-0.14343,32.411,300.0,-0.015579,9.0992,301.77,295.03,297.46
113.119,3.0054,-0.14363,32.594,300.0,-0.015537,9.114,301.76,295.04,297.46
113.519,2.9953,-0.14386,32.123,300.0,-0.015615,9.0867,301.8,295.06,297.51
113.919,3.0036,-0.14401,32.364,300.0,-0.015614,9.1136,301.75,295.06,297.46
114.319,3.0004,-0.14406,32.293,300.0,-0.01566,9.0997,301.75,295.13,297.46
114.719,2.993,-0.14428,32.213,300.0,-0.015703,9.08,301.77,295.11,297.5
115.119,2.9955,-0.14458,32.174,300.0,-0.015694,9.0877,301.77,295.08,297.51
115.519,2.9919,-0.14552,32.041,300.0,-0.015739,9.072,301.74,295.06,297.39
115.9093,3.001,-0.14695,32.783,300.0,-0.015925,9.1072,301.72,295.12,297.42
116.3093,3.0079,-0.14765,32.364,300.0,-0.016031,9.1238,302.02,295.43,297.63
116.7093,2.9973,-0.14542,32.541,300.0,-0.015801,9.0907,301.98,295.37,297.75
117.1093,3.0075,-0.14445,32.278,300.0,-0.015721,9.1272,302.13,295.52,297.8
117.5093,3.001,-0.14459,32.368,300.0,-0.015717,9.0994,302.11,295.49,297.78
117.9093,2.9882,-0.14488,32.131,300.0,-0.01568,9.0647,302.14,295.49,297.82
118.3093,3.0042,-0.14498,32.5,300.0,-0.015723,9.1155,302.09,295.51,297.79
118.7093,2.9996,-0.14551,32.936,300.0,-0.015788,9.0969,302.31,295.82,297.88
119.1093,2.9934,-0.14567,32.422,300.0,-0.015808,9.0819,302.56,295.94,298.15
119.5093,2.9919,-0.14582,32.495,300.0,-0.015869,9.0784,302.51,295.93,298.15
119.9093,2.9912,-0.14596,32.44,300.0,-0.015863,9.0714,302.48,295.87,298.06
120.3093,2.9871,-0.14631,32.611,300.0,-0.015852,9.0633,302.49,295.89,298.08
120.7093,3.001,-0.14672,32.815,300.0,-0.015888,9.1022,302.55,295.9,298.07
121.1093,2.9994,-0.14751,32.457,300.0,-0.015992,9.0966,302.83,296.19,298.34
121.5093,2.9953,-0.14926,32.398,300.0,-0.016172,9.0891,302.85,296.25,298.47
121.9093,3.0013,-0.14779,32.157,300.0,-0.016106,9.1018,302.86,296.21,298.42
122.3093,2.9923,-0.14641,32.618,300.0,-0.015924,9.0765,302.77,296.13,298.4
122.7093,3.0085,-0.14753,37.041,300.0,-0.015986,9.1284,303.39,296.84,298.66
123.1093,3.0153,-0.14873,34.147,300.0,-0.016097,9.1442,306.2,299.97,301.38
123.5093,2.9884,-0.14832,31.514,300.0,-0.016102,9.0656,306.81,300.13,302.78
123.9093,2.9914,-0.14857,32.323,300.0,-0.016106,9.0798,306.62,299.82,302.6
124.3093,2.9947,-0.14838,32.243,300.0,-0.016145,9.0832,306.56,299.65,302.36
124.7093,2.9741,-0.1485,31.992,300.0,-0.016146,9.023,306.6,299.6,302.22
125.1093,2.9898,-0.14892,32.169,300.0,-0.016138,9.0709,306.53,299.62,302.1
125.5093,2.9908,-0.14903,32.213,300.0,-0.016133,9.0705,306.51,299.6,302.03
125.9093,2.9767,-0.14943,31.89,300.0,-0.016222,9.0317,306.53,299.59,302.08
126.3093,2.9983,-0.15004,32.053,300.0,-0.016268,9.0938,306.47,299.61,302.01
126.7093,2.9875,-0.15138,31.837,300.0,-0.016455,9.0592,306.35,299.44,301.97
127.1093,2.9851,-0.15193,31.88,300.0,-0.016536,9.0577,306.18,299.25,301.78
127.5093,2.9947,-0.14994,32.318,300.0,-0.016281,9.0863,306.1,299.29,301.65
127.9093,2.9885,-0.1489,32.215,300.0,-0.016113,9.0653,306.11,299.27,301.66
128.3093,2.9847,-0.14901,31.903,300.0,-0.016179,9.0554,306.23,299.35,301.75
128.7093,2.9896,-0.14898,31.621,300.0,-0.016146,9.0662,306.17,299.3,301.74
129.1093,2.9736,-0.14928,31.749,300.0,-0.016228,9.0206,306.06,299.15,301.63
129.5093,2.973,-0.14957,31.536,300.0,-0.016265,9.022,306.05,299.08,301.54
129.9093,2.9811,-0.14947,31.36,300.0,-0.016221,9.0419,305.95,298.99,301.51
130.3093,2.9666,-0.14965,31.62,300.0,-0.016197,8.9975,305.71,298.79,301.33
130.7093,2.9657,-0.14949,31.346,300.0,-0.016227,9.0016,305.45,298.58,301.09
131.1093,2.9676,-0.14961,31.837,300.0,-0.016217,9.0027,305.22,298.34,300.75
131.5093,2.9612,-0.1495,31.882,300.0,-0.016236,8.9825,305.2,298.41,300.75
131.9093,2.9684,-0.14961,31.694,300.0,-0.016281,9.0077,305.25,298.47,300.82
132.3093,2.9649,-0.15008,31.459,300.0,-0.016291,8.9892,305.24,298.41,300.81
132.7093,2.9628,-0.15072,31.553,300.0,-0.016305,8.9874,305.23,298.46,300.75
133.1093,2.9776,-0.15172,31.87,300.0,-0.016438,9.0352,305.19,298.41,300.67
133.5093,2.9762,-0.15277,31.723,300.0,-0.016552,9.0268,305.26,298.44,300.76
133.9093,2.9775,-0.1522,31.879,300.0,-0.016534,9.0359,305.17,298.44,300.72
134.3093,2.9847,-0.15033,31.931,300.0,-0.016364,9.0525,305.21,298.5,300.7
134.70931,2.9749,-0.14977,31.456,300.0,-0.016274,9.0223,305.24,298.48,300.82
135.10931,2.9807,-0.14969,31.529,300.0,-0.016202,9.0474,305.24,298.55,300.74
135.50931,2.9905,-0.1497,31.667,300.0,-0.016217,9.0713,305.2,298.46,300.73
135.90931,2.9828,-0.14972,32.053,300.0,-0.016249,9.049,305.11,298.47,300.67
136.30931,2.9836,-0.15002,31.595,300.0,-0.016273,9.0536,305.22,298.5,300.78
136.70931,2.9919,-0.14998,31.662,300.0,-0.016318,9.0766,305.22,298.45,300.77
137.10931,2.9799,-0.14997,31.757,300.0,-0.016297,9.0372,305.18,298.43,300.73
137.50931,2.981,-0.15046,31.881,300.0,-0.0163,9.0462,305.14,298.39,300.74
137.90931,2.9853,-0.15046,31.788,300.0,-0.016287,9.0526,305.17,298.38,300.74
138.30931,2.98,-0.15037,32.0,300.0,-0.016321,9.0422,305.18,298.44,300.77
138.70931,2.9803,-0.1505,31.56,300.0,-0.016301,9.0421,305.24,298.5,300.77
138.9603,2.9771,-0.15071,31.814,300.0,-0.016374,9.0327,305.22,298.43,300.74
139.3603,2.984,-0.15067,31.883,300.0,-0.016303,9.0536,305.2,298.48,300.78
139.7603,2.9735,-0.15081,31.864,300.0,-0.01633,9.0168,305.21,298.43,300.79
140.1603,2.9691,-0.15123,31.855,300.0,-0.016406,9.0078,305.21,298.41,300.81
140.5603,2.9767,-0.15192,31.753,300.0,-0.016465,9.0296,305.2,298.49,300.75
140.9603,2.9701,-0.15305,31.446,300.0,-0.016627,9.0061,305.26,298.42,300.77
141.3603,2.9657,-0.15393,31.882,300.0,-0.016722,9.0007,305.21,298.5,300.8
141.7603,2.9767,-0.15319,31.837,300.0,-0.016614,9.0272,305.21,298.47,300.79
142.1603,2.9639,-0.15171,31.679,300.0,-0.016439,8.9872,305.24,298.45,300.74
142.5603,2.9636,-0.1506,31.555,300.0,-0.016357,8.9931,305.26,298.46,300.78
142.9603,2.9758,-0.15038,31.645,300.0,-0.016293,9.0277,305.19,298.43,300.74
143.3603,2.9674,-0.15051,31.857,300.0,-0.01636,9.0001,305.16,298.43,300.72
143.7603,2.9655,-0.15088,31.797,300.0,-0.016404,8.9987,305.17,298.49,300.78
144.1603,2.9791,-0.1508,31.496,300.0,-0.01636,9.0355,305.24,298.42,300.75
144.5603,2.9627,-0.15114,31.819,300.0,-0.016354,8.9889,305.19,298.44,300.7
144.9603,2.9647,-0.08186,31.737,300.0,-0.0089152,8.9965,305.19,298.47,300.79
145.2861,2.9232,0.0096412,0.0,236.25,0.0010989,8.8631,305.36,298.69,300.9
145.2881,2.9119,0.010703,0.0,0.44961,0.0012522,8.8222,305.35,298.64,300.85
145.2901,2.9096,0.012058,0.0,0.0008423,0.0013086,8.8139,305.34,298.59,300.8
145.2921,2.9161,0.0068887,0.0,1.5862e-06,0.0011496,8.847,305.33,298.54,300.75
145.2941,2.9171,0.009818,0.0,2.9715e-09,0.001061,8.8313,305.32,298.52,300.72
145.2961,2.9211,0.010557,0.0,5.5956e-12,0.00067101,8.8437,305.32,298.53,300.72
145.2981,2.924,0.0096042,0.0,1.0536e-14,0.0010716,8.843,305.32,298.55,300.72
145.3001,2.9279,0.010885,0.0,1.9739e-17,0.00096295,8.8469,305.32,298.57,300.72
145.3021,2.9359,0.0066606,0.0,3.7168e-20,0.0013476,8.8732,305.32,298.59,300.72
145.3041,2.935,0.0098887,0.0,6.963099999999999e-23,0.0013233,8.8788,305.32,298.6,300.72
145.3061,2.9362,0.010228,0.0,1.3111e-25,0.00074279,8.868,305.32,298.6,300.74
145.3081,2.9416,0.0092586,0.0,2.4685999999999997e-28,0.00094767,8.9086,305.32,298.6,300.75
145.3101,2.9505,0.010258,0.0,4.6248e-31,0.0008004,8.9258,305.32,298.6,300.76
145.3121,2.9399,0.0073528,0.0,8.7076e-34,0.0013918,8.8994,305.32,298.6,300.77
145.3141,2.9559,0.011022,0.0,1.6394e-36,0.0013915,8.9351,305.31,298.59,300.79
145.3161,2.9635,0.0085841,0.0,3.0714e-39,0.00067665,8.9645,305.29,298.58,300.8
145.3181,2.9665,0.0088784,0.0,5.7818e-42,0.00077043,8.9983,305.26,298.56,300.81
145.3201,2.9661,0.011524,0.0,9.8091e-45,0.00077877,8.9761,305.24,298.54,300.82
145.3221,2.9743,0.0072007,0.0,0.0,0.0013466,9.0025,305.21,298.52,300.84
145.3241,2.9723,0.0088871,0.0,0.0,0.0011878,9.0002,305.19,298.5,300.83
145.3261,2.9786,0.0095256,0.0,0.0,0.0009926,8.972,305.17,298.49,300.79
145.3281,2.9859,0.010389,0.0,0.0,0.00093069,9.0347,305.15,298.48,300.75
145.3301,2.9882,0.010864,0.0,0.0,0.000679,9.0648,305.14,298.47,300.72
145.3321,2.9885,0.0075079,0.0,0.0,0.0013048,9.0437,305.12,298.46,300.68
145.3341,2.9938,0.010622,0.0,0.0,0.0013621,9.0721,305.85,299.24,300.63
145.3361,2.9927,0.0074965,0.0,0.0,0.00097143,9.0903,307.68,301.19,300.55
145.3381,2.9864,0.010926,0.0,0.0,0.0010246,9.072,309.52,303.13,300.48
145.3401,3.0024,0.011875,0.0,0.0,0.00064802,9.0968,311.35,305.08,300.41
145.3421,3.0259,0.0082168,0.0,0.0,0.0013141,9.1727,313.18,307.02,300.33
145.3441,3.0216,0.010568,0.0,0.0,0.0013819,9.1944,315.78,309.37,300.29
145.3461,2.9811,0.009448,0.0,0.0,0.0012005,9.0861,319.46,312.29,300.29
145.3481,2.9537,0.010724,0.0,0.0,0.0010429,8.9817,323.14,315.2,300.29
145.3501,12.625,0.068194,0.0,0.0,0.0067173,33.802,326.82,318.12,300.29
145.3521,35.478,0.3047,0.0,0.0,0.033088,106.68,330.5,321.04,300.29
145.35409,43.275,0.68895,0.0,0.0,0.076757,130.99,334.0,323.33,300.31
145.35609,46.043,1.0783,0.0,0.0,0.12376,139.37,337.25,324.77,300.35
145.35809,46.903,1.4909,0.0,0.0,0.17499,142.21,340.5,326.22,300.39
145.36009,47.331,1.9024,0.0,0.0,0.22823,143.51,343.76,327.67,300.44
145.36209,47.677,2.3227,0.0,0.0,0.28704,144.65,347.01,329.12,300.48
145.36409,48.222,2.7471,0.0,0.0,0.34892,146.24,349.55,330.62,300.52
145.36609,48.771,3.1697,0.0,0.0,0.4153,147.86,351.18,332.18,300.56
145.36809,49.416,3.6083,0.0,0.0,0.48673,149.83,352.81,333.75,300.6
145.37009,50.043,4.0483,0.0,0.0,0.56325,151.74,354.44,335.32,300.63
145.37209,50.621,4.4865,0.0,0.0,0.64718,153.51,356.07,336.89,300.67
145.37409,50.999,4.9226,0.0,0.0,0.73635,154.68,356.8,337.97,300.7
145.37609,51.367,5.348,0.0,0.0,0.83336,155.8,356.4,338.45,300.72
145.37809,51.469,5.7708,0.0,0.0,0.93624,156.09,355.99,338.93,300.73
145.38009,51.661,6.1708,0.0,0.0,1.0418,156.67,355.59,339.41,300.75
145.38209,51.849,6.5567,0.0,0.0,1.1572,157.23,355.19,339.9,300.77
145.38409,52.111,6.9029,0.0,0.0,1.2714,158.05,354.35,339.54,300.8
145.38609,52.287,7.1927,0.0,0.0,1.3815,158.61,352.97,338.2,300.85
145.38809,52.254,7.4383,0.0,0.0,1.4803,158.51,351.6,336.85,300.9
145.39009,51.971,7.6259,0.0,0.0,1.5599,157.63,350.23,335.5,300.95
145.39209,51.644,7.7708,0.0,0.0,1.6272,156.65,348.85,334.15,301.0
145.39409,48.018,7.8373,0.0,0.0,1.6614,146.24,347.54,332.82,301.06
145.39609,45.868,7.8478,0.0,0.0,1.6711,139.26,346.31,331.51,301.12
145.39809,44.111,7.8556,0.0,0.0,1.674,133.93,345.07,330.2,301.18
145.40009,43.47,7.8596,0.0,0.0,1.6741,131.91,343.83,328.89,301.24
145.40209,43.097,7.8661,0.0,0.0,1.6766,130.71,342.6,327.57,301.3
145.40409,42.849,7.8776,0.0,0.0,1.6794,130.0,341.61,326.57,301.34
145.40609,42.676,7.874,0.0,0.0,1.6835,129.47,340.88,325.89,301.36
145.40809,42.236,7.8813,0.0,0.0,1.6877,128.17,340.16,325.22,301.38
145.41009,41.407,7.883,0.0,0.0,1.6874,125.7,339.43,324.55,301.4
145.41209,40.063,7.8871,0.0,0.0,1.6868,121.66,338.71,323.88,301.42
145.41409,37.855,7.8863,0.0,0.0,1.6834,115.02,338.2,323.5,301.45
145.41609,34.843,7.8739,0.0,0.0,1.683,106.02,337.93,323.44,301.5
145.41809,29.755,7.8744,0.0,0.0,1.6836,91.148,337.65,323.38,301.55
145.42009,8.1261,7.8206,0.0,0.0,1.6578,26.367,337.38,323.32,301.6
145.42209,0.8863,7.7861,0.0,0.0,1.6372,2.3216,337.11,323.26,301.65
145.42409,2.0032,7.81,0.0,0.0,1.647,6.2127,336.88,323.23,301.71
145.42609,2.502,7.8087,0.0,0.0,1.649,7.5163,336.69,323.23,301.79
145.42809,2.5148,7.8004,0.0,0.0,1.6456,7.5718,336.51,323.23,301.87
145.43009,2.5115,7.793,0.0,0.0,1.6442,7.5789,336.33,323.23,301.95
145.43209,2.5409,7.8004,0.0,0.0,1.6449,7.6761,336.15,323.23,302.03
145.43409,2.47,7.7995,0.0,0.0,1.6412,7.4482,335.92,323.16,302.11
145.43609,2.4508,7.7999,0.0,0.0,1.6444,7.384,335.65,323.03,302.2
145.43809,2.4697,7.8039,0.0,0.0,1.646,7.4657,335.38,322.89,302.29
145.44009,2.5091,7.7956,0.0,0.0,1.6457,7.5445,335.12,322.76,302.37
145.44209,2.4808,7.7995,0.0,0.0,1.6458,7.4849,334.85,322.62,302.46
145.44409,2.4922,7.8005,0.0,0.0,1.6427,7.5524,334.62,322.47,302.55
145.44609,2.4825,7.7997,0.0,0.0,1.6434,7.5091,334.42,322.3,302.65
145.44809,2.4533,7.8015,0.0,0.0,1.6441,7.4294,334.23,322.13,302.75
145.45009,2.4458,7.7986,0.0,0.0,1.6473,7.3809,334.03,321.96,302.85
145.45209,2.4565,7.7992,0.0,0.0,1.6462,7.4494,333.84,321.79,302.95
145.45409,2.4851,7.8012,0.0,0.0,1.644,7.5266,333.64,321.6,303.03
145.45609,2.4944,7.8027,0.0,0.0,1.6448,7.545,333.45,321.39,303.1
145.45809,2.5133,7.8007,0.0,0.0,1.6428,7.6137,333.26,321.18,303.18
145.46009,2.5091,7.7988,0.0,0.0,1.6471,7.5991,333.08,320.97,303.25
145.46209,2.4843,7.8014,0.0,0.0,1.6476,7.539,332.89,320.76,303.33
145.46409,2.4964,7.7999,0.0,0.0,1.6442,7.592,332.63,320.56,303.39
145.46609,2.4725,7.8022,0.0,0.0,1.6443,7.5488,332.31,320.35,303.46
145.46809,2.4797,7.8038,0.0,0.0,1.6435,7.5357,331.99,320.14,303.52
145.47009,2.4627,7.7993,0.0,0.0,1.6473,7.4864,331.68,319.93,303.58
145.47209,2.4868,7.8035,0.0,0.0,1.6487,7.6001,331.36,319.73,303.64
145.47409,2.4976,7.8014,0.0,0.0,1.6458,7.6225,331.08,319.51,303.71
145.47609,2.5106,7.8039,0.0,0.0,1.6452,7.632,330.84,319.3,303.8
145.47809,2.5357,7.8071,0.0,0.0,1.6445,7.7007,330.59,319.09,303.89
145.48009,2.5419,7.8018,0.0,0.0,1.6474,7.7557,330.35,318.87,303.97
145.48209,2.4759,7.803,0.0,0.0,1.6481,7.542,330.1,318.66,304.06
145.48409,2.4864,7.8015,0.0,0.0,1.6469,7.609,329.91,318.43,304.15
145.48609,2.473,7.8053,0.0,0.0,1.6466,7.5164,329.76,318.2,304.25
145.48809,2.4649,7.8079,0.0,0.0,1.6449,7.5017,329.6,317.97,304.35
145.49009,2.4855,7.8016,0.0,0.0,1.6462,7.5784,329.45,317.73,304.45
145.49208,2.4558,7.8042,0.0,0.0,1.6483,7.5067,329.3,317.5,304.54
145.49408,2.4277,7.8027,0.0,0.0,1.6484,7.3984,329.08,317.28,304.63
145.49608,2.4546,7.8045,0.0,0.0,1.6466,7.4892,328.81,317.05,304.71
145.49808,2.4485,7.806,0.0,0.0,1.6443,7.4584,328.54,316.83,304.79
145.50008,2.4503,7.803,0.0,0.0,1.646,7.4574,328.27,316.61,304.87
145.50208,2.4509,7.8027,0.0,0.0,1.646,7.4477,328.01,316.39,304.95
145.50408,2.4411,7.7997,0.0,0.0,1.6479,7.4104,327.72,316.16,305.01
145.50608,2.4518,7.8056,0.0,0.0,1.6485,7.4687,327.43,315.91,305.06
145.50808,2.465,7.8059,0.0,0.0,1.6448,7.4857,327.14,315.67,305.11
145.51008,2.4665,7.8048,0.0,0.0,1.6463,7.4947,326.84,315.42,305.16
145.51208,2.4996,7.8036,0.0,0.0,1.6454,7.5683,326.55,315.18,305.21
145.51408,2.5153,7.8,0.0,0.0,1.648,7.623,326.3,314.94,305.25
145.51608,2.5295,7.8062,0.0,0.0,1.6493,7.6664,326.08,314.72,305.3
145.51808,2.56,7.8053,0.0,0.0,1.6453,7.7727,325.86,314.49,305.34
145.52008,2.5409,7.8039,0.0,0.0,1.645,7.6789,325.64,314.26,305.38
145.52208,2.5678,7.8057,0.0,0.0,1.6456,7.7426,325.42,314.04,305.43
145.52408,2.5608,7.8022,0.0,0.0,1.6489,7.7261,325.19,313.82,305.49
145.52608,2.5275,7.8052,0.0,0.0,1.6496,7.6444,324.94,313.6,305.56
145.52808,2.5308,7.8053,0.0,0.0,1.646,7.6538,324.7,313.39,305.63
145.53008,2.5197,7.8041,0.0,0.0,1.6449,7.5588,324.45,313.17,305.71
145.53208,2.5148,7.8058,0.0,0.0,1.645,7.571,324.21,312.96,305.78
145.53408,2.538,7.7997,0.0,0.0,1.6476,7.6167,323.94,312.74,305.85
145.53608,2.5478,7.8062,0.0,0.0,1.65,7.666,323.64,312.51,305.92
145.53808,2.5753,7.8042,0.0,0.0,1.6465,7.7347,323.35,312.28,305.98
145.54008,2.5896,7.804,0.0,0.0,1.645,7.7556,323.06,312.06,306.05
145.54208,2.6076,7.8072,0.0,0.0,1.6449,7.8112,322.76,311.83,306.12
145.54408,2.6402,7.8031,0.0,0.0,1.6484,7.9088,322.5,311.62,306.18
145.54608,2.6673,7.804,0.0,0.0,1.6488,8.0036,322.26,311.42,306.24
145.54808,2.6944,7.8029,0.0,0.0,1.6472,8.0861,322.01,311.21,306.31
145.55008,2.7044,7.8065,0.0,0.0,1.6461,8.1022,321.77,311.01,306.37
145.55208,2.7165,7.8073,0.0,0.0,1.645,8.149,321.52,310.81,306.43
145.55408,2.7372,7.8046,0.0,0.0,1.6483,8.2243,321.3,310.6,306.51
145.55608,2.7696,7.8046,0.0,0.0,1.6486,8.3179,321.08,310.38,306.6
145.55808,2.7871,7.8023,0.0,0.0,1.6477,8.3814,320.87,310.15,306.69
145.56008,2.8035,7.8056,0.0,0.0,1.6468,8.4539,320.66,309.93,306.78
145.56208,2.8144,7.808,0.0,0.0,1.6448,8.4813,320.44,309.71,306.88
145.56408,2.8046,7.8046,0.0,0.0,1.6468,8.4439,320.24,309.48,306.95
145.56608,2.8199,7.8051,0.0,0.0,1.6481,8.5155,320.03,309.24,307.01
145.56808,2.8183,7.8046,0.0,0.0,1.6497,8.5356,319.83,309.0,307.07
145.57008,2.8293,7.8054,0.0,0.0,1.6475,8.5475,319.63,308.76,307.13
145.57208,2.8254,7.8062,0.0,0.0,1.6447,8.572,319.43,308.53,307.19
145.57408,2.8225,7.8078,0.0,0.0,1.6475,8.5405,319.24,308.31,307.25
145.57608,2.8245,7.8075,0.0,0.0,1.648,8.5806,319.07,308.11,307.3
145.57808,2.8062,7.8036,0.0,0.0,1.6498,8.5397,318.89,307.91,307.35
145.58008,2.7948,7.8046,0.0,0.0,1.6481,8.5285,318.71,307.7,307.39
145.58208,2.7861,7.8084,0.0,0.0,1.6464,8.4917,318.53,307.5,307.44
145.58408,2.7652,7.8075,0.0,0.0,1.6472,8.4391,318.31,307.32,307.49
145.58608,2.7432,7.807,0.0,0.0,1.6464,8.393,318.08,307.14,307.53
145.58808,2.7411,7.8028,0.0,0.0,1.6495,8.3807,317.84,306.96,307.57
145.59008,2.7142,7.8077,0.0,0.0,1.6505,8.318,317.6,306.78,307.62
145.59208,2.6948,7.8047,0.0,0.0,1.6455,8.2529,317.36,306.6,307.66
145.59408,2.684,7.8052,0.0,0.0,1.646,8.2239,317.11,306.42,307.69
145.59608,2.6546,7.8098,0.0,0.0,1.6469,8.1642,316.86,306.24,307.72
145.59808,2.639,7.8027,0.0,0.0,1.6488,8.0928,316.61,306.05,307.74
145.60008,2.6164,7.8033,0.0,0.0,1.6485,8.0666,316.36,305.87,307.76
145.60208,2.6097,7.8086,0.0,0.0,1.6484,8.0113,316.11,305.69,307.79
145.60408,2.5847,7.8084,0.0,0.0,1.647,7.9477,315.9,305.51,307.83
145.60608,2.5658,7.8065,0.0,0.0,1.6448,7.8732,315.71,305.34,307.87
145.60808,2.5511,7.8042,0.0,0.0,1.6491,7.8201,315.52,305.17,307.91
145.61008,2.5309,7.8076,0.0,0.0,1.6507,7.7952,315.33,305.0,307.95
145.61208,2.5186,7.8065,0.0,0.0,1.6483,7.7341,315.14,304.83,308.0
145.61408,2.5192,7.8071,0.0,0.0,1.6467,7.7358,314.94,304.65,308.04
145.61608,2.5216,7.8109,0.0,0.0,1.6464,7.7108,314.75,304.48,308.09
145.61808,2.5037,7.8057,0.0,0.0,1.6497,7.6623,314.55,304.31,308.14
145.62008,2.5112,7.8061,0.0,0.0,1.6501,7.6647,314.35,304.14,308.19
145.62208,2.4957,7.8061,0.0,0.0,1.649,7.6119,314.16,303.97,308.24
145.62408,2.4884,7.8069,0.0,0.0,1.6471,7.5669,313.95,303.79,308.28
145.62608,2.4948,7.8096,0.0,0.0,1.646,7.5636,313.75,303.62,308.32
145.62808,2.4945,7.8057,0.0,0.0,1.6482,7.5612,313.54,303.45,308.35
145.63007,2.5083,7.8079,0.0,0.0,1.65,7.5983,313.33,303.28,308.39
145.63207,2.5089,7.8054,0.0,0.0,1.6498,7.5803,313.12,303.11,308.43
145.63407,2.513,7.8081,0.0,0.0,1.6485,7.5846,312.94,302.95,308.47
145.63607,2.5353,7.8108,0.0,0.0,1.6469,7.6486,312.78,302.8,308.5
145.63807,2.5495,7.8074,0.0,0.0,1.6482,7.6584,312.61,302.66,308.54
145.64007,2.5595,7.808,0.0,0.0,1.6486,7.6866,312.45,302.51,308.58
145.64207,2.573,7.8047,0.0,0.0,1.6499,7.7288,312.28,302.36,308.61
145.64407,2.5843,7.8063,0.0,0.0,1.6487,7.7743,312.12,302.2,308.65
145.64607,2.6018,7.8089,0.0,0.0,1.6465,7.809,311.97,302.02,308.69
145.64807,2.6207,7.8095,0.0,0.0,1.6486,7.8475,311.82,301.85,308.72
145.65007,2.6362,7.8069,0.0,0.0,1.6468,7.9014,311.66,301.68,308.76
145.65207,2.658,7.8042,0.0,0.0,1.6502,7.9605,311.51,301.51,308.8
145.65407,2.6724,7.8093,0.0,0.0,1.6511,8.0174,311.32,301.34,308.83
145.65607,2.6984,7.809,0.0,0.0,1.6473,8.0903,311.12,301.18,308.87
145.65807,2.7112,7.8077,0.0,0.0,1.647,8.113,310.92,301.02,308.91
145.66007,2.7263,7.811,0.0,0.0,1.648,8.1805,310.72,300.86,308.94
145.66207,2.7558,7.8064,0.0,0.0,1.6508,8.2609,310.51,300.7,308.98
145.66407,2.7586,7.8083,0.0,0.0,1.6508,8.2925,310.33,300.56,309.01
145.66607,2.7703,7.8082,0.0,0.0,1.6478,8.3434,310.16,300.44,309.03
145.66807,2.7907,7.8122,0.0,0.0,1.6488,8.4048,309.99,300.31,309.06
145.67007,2.7927,7.8119,0.0,0.0,1.6479,8.4087,309.82,300.18,309.08
145.67207,2.8088,7.8062,0.0,0.0,1.6506,8.4534,309.65,300.05,309.11
145.67407,2.8265,7.809,0.0,0.0,1.6512,8.5239,309.5,299.89,309.11
145.67607,2.8267,7.8097,0.0,0.0,1.6497,8.5416,309.37,299.73,309.11
145.67807,2.8336,7.8125,0.0,0.0,1.6491,8.5857,309.23,299.56,309.11
145.68007,2.836,7.8132,0.0,0.0,1.6476,8.5941,309.1,299.39,309.11
145.68207,2.8414,7.8071,0.0,0.0,1.6503,8.6085,308.96,299.23,309.11
145.68407,2.835,7.8094,0.0,0.0,1.6514,8.5942,308.81,299.07,309.12
145.68607,2.8283,7.8106,0.0,0.0,1.6506,8.606,308.66,298.93,309.13
145.68807,2.8352,7.8124,0.0,0.0,1.6492,8.6226,308.51,298.78,309.15
145.69007,2.8233,7.8115,0.0,0.0,1.6467,8.5962,308.36,298.63,309.16
145.69207,2.8206,7.8103,0.0,0.0,1.6514,8.601,308.2,298.48,309.17
145.69407,2.8108,7.8114,0.0,0.0,1.652,8.5989,308.04,298.36,309.2
145.69607,2.798,7.8074,0.0,0.0,1.6499,8.5462,307.88,298.24,309.24
145.69807,2.7802,7.8106,0.0,0.0,1.6497,8.5131,307.73,298.13,309.27
145.70007,2.76,7.8123,0.0,0.0,1.6475,8.469,307.57,298.01,309.31
145.70207,2.7458,7.8098,0.0,0.0,1.6497,8.4097,307.41,297.89,309.35
145.70407,2.7339,7.8103,0.0,0.0,1.6506,8.381,307.27,297.78,309.39
145.70607,2.7153,7.8064,0.0,0.0,1.6506,8.3127,307.13,297.66,309.43
145.70807,2.6856,7.8113,0.0,0.0,1.6506,8.2556,307.0,297.54,309.48
145.71007,2.6785,7.8128,0.0,0.0,1.6483,8.2427,306.86,297.42,309.52
145.71207,2.6457,7.8113,0.0,0.0,1.6497,8.1167,306.73,297.31,309.56
145.71407,2.6317,7.8097,0.0,0.0,1.6492,8.0775,306.59,297.18,309.6
145.71607,2.6137,7.8079,0.0,0.0,1.652,8.0262,306.46,297.04,309.64
145.71807,2.5944,7.8114,0.0,0.0,1.6518,7.9968,306.32,296.91,309.67
145.72007,2.5794,7.8115,0.0,0.0,1.648,7.9007,306.19,296.77,309.71
145.72207,2.5562,7.8104,0.0,0.0,1.6485,7.8382,306.05,296.63,309.75
145.72407,2.5545,7.8109,0.0,0.0,1.6486,7.8196,305.87,296.49,309.76
145.72607,2.5346,7.8074,0.0,0.0,1.6516,7.7446,305.68,296.34,309.78
145.72807,2.5389,7.8116,0.0,0.0,1.6526,7.7325,305.49,296.19,309.79
145.73007,2.5285,7.8126,0.0,0.0,1.6493,7.7082,305.3,296.05,309.8
145.73207,2.5185,7.8108,0.0,0.0,1.6484,7.6637,305.11,295.9,309.81
145.73407,2.5239,7.8111,0.0,0.0,1.6481,7.6659,304.97,295.76,309.81
145.73607,2.5299,7.8075,0.0,0.0,1.6514,7.6926,304.83,295.63,309.8
145.73807,2.5285,7.8112,0.0,0.0,1.6525,7.659,304.7,295.49,309.8
145.74007,2.5267,7.8109,0.0,0.0,1.6494,7.6402,304.56,295.36,309.79
145.74207,2.5459,7.8099,0.0,0.0,1.6478,7.6892,304.43,295.22,309.79
145.74407,2.5396,7.8137,0.0,0.0,1.6481,7.6794,304.3,295.09,309.79
145.74607,2.5574,7.8078,0.0,0.0,1.651,7.7164,304.18,294.96,309.8
145.74807,2.5691,7.8105,0.0,0.0,1.6522,7.7363,304.06,294.83,309.8
145.75007,2.584,7.8094,0.0,0.0,1.6496,7.7874,303.94,294.7,309.81
145.75207,2.6059,7.8134,0.0,0.0,1.6496,7.8278,303.81,294.57,309.81
145.75407,2.6191,7.8129,0.0,0.0,1.6475,7.8542,303.68,294.46,309.8
145.75607,2.6432,7.8099,0.0,0.0,1.6511,7.9392,303.54,294.36,309.78
145.75807,2.656,7.8105,0.0,0.0,1.6518,7.98,303.41,294.25,309.76
145.76007,2.6783,7.8102,0.0,0.0,1.651,8.0428,303.27,294.15,309.75
145.76207,2.7132,7.8123,0.0,0.0,1.6497,8.1405,303.14,294.05,309.73
145.76407,2.7213,7.8131,0.0,0.0,1.648,8.1508,303.03,293.95,309.73
145.76607,2.7345,7.8103,0.0,0.0,1.6503,8.1917,302.92,293.85,309.75
145.76806,2.7602,7.8121,0.0,0.0,1.6523,8.2824,302.82,293.75,309.76
145.77006,2.7684,7.8095,0.0,0.0,1.6513,8.3142,302.72,293.65,309.77
145.77206,2.7899,7.8146,0.0,0.0,1.6512,8.4002,302.61,293.55,309.78
145.77406,2.8182,7.8154,0.0,0.0,1.6491,8.4879,302.49,293.45,309.81
145.77606,2.8274,7.8113,0.0,0.0,1.6505,8.5087,302.36,293.34,309.83
145.77806,2.8339,7.8126,0.0,0.0,1.6512,8.5359,302.23,293.24,309.85
145.78006,2.8512,7.8107,0.0,0.0,1.6533,8.5847,302.1,293.13,309.88
145.78206,2.8465,7.8136,0.0,0.0,1.6518,8.5922,301.97,293.03,309.9
145.78406,2.8637,7.8121,0.0,0.0,1.6483,8.6505,301.85,292.93,309.91
145.78606,2.8737,7.8141,0.0,0.0,1.6505,8.6688,301.73,292.83,309.91
145.78806,2.8778,7.8146,0.0,0.0,1.6506,8.7078,301.62,292.73,309.91
145.79006,2.8756,7.8097,0.0,0.0,1.6524,8.7076,301.5,292.63,309.91
145.79206,2.8812,7.8126,0.0,0.0,1.6526,8.7498,301.38,292.54,309.91
145.79406,2.8788,7.8129,0.0,0.0,1.6491,8.739,301.26,292.43,309.9
145.79606,2.8719,7.8134,0.0,0.0,1.6498,8.7382,301.14,292.33,309.9
145.79806,2.8593,7.8135,0.0,0.0,1.6494,8.7044,301.01,292.22,309.89
145.80006,2.8619,7.81,0.0,0.0,1.6523,8.7437,300.89,292.12,309.88
145.80113,2.5777,7.8151,0.0,0.0,1.6485,7.7509,300.83,292.06,309.88
146.20113,2.6498,7.8151,0.0,0.0,1.6521,8.0388,285.8,270.14,284.39
146.60113,2.593,7.8187,0.0,0.0,1.6539,7.8662,264.21,232.84,190.15
147.00113,2.5504,7.8236,0.0,0.0,1.6563,7.7373,243.37,165.32,161.5
147.40113,2.52,7.8302,0.0,0.0,1.6595,7.6461,221.93,114.98,143.05
147.80113,2.5047,7.8379,0.0,0.0,1.6634,7.5982,195.2,85.658,122.86
148.20113,2.4945,7.8445,0.0,0.0,1.6666,7.5684,159.2,69.348,75.68
148.60113,2.4772,7.857,0.0,0.0,1.6727,7.5195,108.77,56.947,46.688
148.8843,2.4895,7.8646,0.0,0.0,1.6765,7.5526,80.332,48.761,37.197
149.2843,2.4699,7.8725,0.0,0.0,1.6807,7.4888,62.751,41.809,30.124
149.6843,2.4546,7.8782,0.0,0.0,1.6838,7.4496,52.222,38.948,26.233
150.0843,2.4475,7.8805,0.0,0.0,1.6848,7.423,45.498,38.947,23.975
150.4843,2.4176,7.8832,0.0,0.0,1.6861,7.3311,41.044,34.771,23.318
150.8843,2.4057,7.8891,0.0,0.0,1.6891,7.3021,37.845,29.27,22.273
151.2843,2.4049,7.8927,0.0,0.0,1.6907,7.2948,35.175,27.841,21.778
151.6843,2.3817,7.8951,0.0,0.0,1.692,7.2242,33.086,26.695,21.33
152.0843,2.378,7.8972,0.0,0.0,1.6934,7.2171,31.428,26.351,21.301
152.4843,2.3728,7.8989,0.0,0.0,1.6942,7.1948,30.011,25.48,20.961
152.8843,2.3557,7.897,0.0,0.0,1.693,7.1467,28.795,24.828,20.755
153.2843,2.366,7.8984,0.0,0.0,1.6939,7.1818,27.741,24.27,20.503
153.6843,2.3689,7.9005,0.0,0.0,1.6948,7.1809,26.929,23.864,20.388
154.0843,2.3552,7.9016,0.0,0.0,1.6952,7.1418,25.942,23.254,20.089
154.4843,2.369,7.9023,0.0,0.0,1.6958,7.1896,25.507,22.917,20.076
154.8843,2.3661,7.902,0.0,0.0,1.6959,7.1761,25.206,22.619,20.058
155.2843,2.3555,7.9031,0.0,0.0,1.6962,7.1479,24.954,22.361,20.208
155.6843,2.3674,7.9036,0.0,0.0,1.6965,7.1813,25.025,22.422,20.454
156.0843,2.5044,7.9045,0.0,0.0,1.697,7.5956,25.638,23.481,21.336
156.4843,2.4353,7.9049,0.0,0.0,1.6969,7.3912,26.331,24.637,22.283
156.8843,2.4179,7.905,0.0,0.0,1.6971,7.334,26.962,25.55,23.073
157.2843,2.3819,7.9049,0.0,0.0,1.6974,7.2248,27.558,26.265,23.919
157.6843,2.3674,7.9052,0.0,0.0,1.6974,7.1837,28.107,26.903,24.63
158.0843,2.3791,7.9052,0.0,0.0,1.6973,7.2168,28.637,27.488,25.319
158.4843,2.3098,7.906,0.0,0.0,1.6979,7.0075,29.054,28.045,25.929
158.8843,2.3298,7.9073,0.0,0.0,1.6982,7.0677,29.461,28.544,26.539
159.2843,2.3855,7.9077,0.0,0.0,1.6984,7.2346,29.887,29.002,27.162
159.6843,2.324,7.9107,0.0,0.0,1.7003,7.0472,30.186,29.408,27.706
160.0843,2.3229,7.9132,0.0,0.0,1.7017,7.0476,30.523,29.815,28.174
160.4843,2.3242,7.9137,0.0,0.0,1.7016,7.0518,30.75,30.173,28.63
160.8843,2.2937,7.9139,0.0,0.0,1.7019,6.9572,30.905,30.316,28.881
161.2843,2.3947,7.9126,0.0,0.0,1.701,7.266,31.156,30.651,29.344
161.6843,2.3809,7.9126,0.0,0.0,1.7009,7.2234,31.366,30.881,29.767
162.0843,2.3768,7.9124,0.0,0.0,1.7009,7.2084,31.477,31.129,29.938
162.4843,2.3724,7.9124,0.0,0.0,1.7013,7.1979,31.615,31.73,30.208
162.6843,2.37,7.9129,0.0,0.0,1.7011,7.1896,31.683,31.865,30.305