File: examples/dan-msc-case-studies/CS4/data/01 raw data/hyde_test_019.csv
Time(sec),Force(kN),Jaw(mm),PowAngle(deg),PTemp,Strain,Stress(MPa),TC1(C),TC2(C),TC3(C),TC4(C)
0.0,0.862,-6.9619,0.0,0.005641,-0.53778,1.022,24.358,24.922,24.641,24.617
1.0,0.85232,-0.00072606,0.0,2.8208,-8.9991e-05,1.0108,24.379,24.884,24.646,24.648
2.0,0.83971,-0.0007237,0.0,5.8208,-8.2879e-05,0.99633,24.323,24.862,24.58,24.596
3.0,0.82075,-0.0011473,0.0,8.8208,-9.4156e-05,0.97382,24.364,24.904,24.61,24.638
3.8195,0.81298,-0.0011259,0.0,11.279,-0.00013183,0.96578,24.388,24.927,24.643,24.661
4.8195,0.80579,-0.0010854,0.0,14.279,-0.00016188,0.95618,24.368,24.969,24.654,24.652
5.8195,0.80335,-0.0012256,0.0,17.279,-0.00012133,0.9531,24.345,24.91,24.681,24.571
6.8195,0.81052,-0.0010684,0.0,20.279,-0.00011829,0.96214,24.355,24.895,24.657,24.639
7.8195,0.79806,-0.0015438,0.0,23.279,-0.00012719,0.94759,24.384,24.93,24.635,24.655
8.8195,0.79641,-0.00056397,19.712,26.279,-8.6602e-05,0.94411,24.424,24.922,24.662,24.651
9.8195,0.81551,-0.00059249,28.806,29.279,-8.1231e-05,0.96789,26.815,25.754,24.683,24.871
10.8195,0.8215,-0.0010274,29.754,32.279,-9.8346e-05,0.97493,30.504,27.445,24.948,25.792
11.8195,0.8517,-0.0012609,31.026,35.279,-0.00013031,1.0109,33.802,29.323,25.476,27.463
12.8195,1.1735,0.0029602,31.88,38.279,0.00035919,1.3939,37.152,37.706,26.245,29.514
13.8195,1.3903,0.0058354,32.527,41.279,0.00062268,1.65,40.416,37.706,26.434,31.858
14.8195,1.647,0.0086719,32.652,44.279,0.00094801,1.9557,43.637,37.474,27.121,34.495
15.8195,1.8123,0.0083512,33.135,47.279,0.00094249,2.1515,46.736,39.565,28.121,37.198
16.8195,1.899,0.0097553,33.519,50.279,0.0011259,2.2544,49.842,42.328,29.392,40.067
17.8195,2.0212,0.010974,33.76,53.279,0.001246,2.3987,52.943,45.147,30.868,42.947
18.8195,2.0915,0.011451,34.067,56.279,0.0012485,2.482,55.949,47.988,32.613,45.949
19.8195,2.1341,0.011296,34.202,59.279,0.0012541,2.5324,59.088,51.017,34.465,48.937
20.8195,2.2152,0.011368,34.575,62.279,0.0012785,2.6285,62.04,53.956,36.519,52.01
21.8195,2.3149,0.011488,34.647,65.279,0.0013,2.7472,65.099,57.036,38.672,55.097
22.8195,2.463,0.0096118,34.828,68.279,0.0010857,2.9233,68.109,60.019,40.989,58.188
23.8195,2.6254,0.01225,34.656,71.279,0.0013408,3.1167,71.2,63.077,43.477,61.293
24.8195,2.7975,0.013817,34.811,74.279,0.0015331,3.3203,74.236,66.077,45.997,64.507
25.8195,2.9681,0.014877,35.166,77.279,0.0016687,3.5228,77.212,69.051,48.683,67.635
26.8195,3.1245,0.016581,34.724,80.279,0.0018873,3.7083,80.307,72.15,51.398,70.829
27.8195,3.2205,0.017719,35.069,83.279,0.0019994,3.8214,83.27,75.139,54.192,73.967
28.8195,3.2724,0.015914,35.153,86.279,0.0017275,3.8828,86.236,78.098,57.083,77.121
29.8195,3.3589,0.016331,35.38,89.279,0.0017951,3.9848,89.265,81.097,60.004,80.351
30.8195,3.4316,0.01704,35.496,92.279,0.0019162,4.0713,92.192,84.153,63.07,83.416
31.8195,3.4973,0.017253,35.423,95.279,0.0019412,4.15,95.233,87.278,66.163,86.585
32.8195,3.5514,0.017824,35.518,98.279,0.002013,4.2148,98.234,90.341,69.31,89.667
33.8195,3.5825,0.01584,35.927,101.28,0.0017197,4.2526,101.22,93.387,72.389,92.781
34.8195,3.5996,0.015531,36.243,104.28,0.0017073,4.2734,104.18,96.366,75.547,95.87
35.7398,3.6196,0.015455,35.996,107.06,0.0017401,4.2964,106.98,99.21,78.478,98.657
36.7398,3.623,0.014965,36.251,110.04,0.0016501,4.3005,109.92,102.13,81.578,101.66
37.7398,3.628,0.014571,36.279,113.04,0.0016465,4.3063,113.01,105.16,84.757,104.73
38.7398,3.63,0.010071,36.382,116.04,0.0011334,4.3079,115.94,108.16,87.88,107.64
39.7398,3.6289,0.010819,36.337,119.04,0.0012511,4.3068,118.98,111.07,91.02,110.74
40.7398,3.6382,0.0097989,36.536,122.04,0.0010955,4.3168,121.99,114.1,94.108,113.76
41.7398,3.6452,0.010038,36.496,125.04,0.0010925,4.326,125.0,117.1,97.23,116.77
42.7398,3.6525,0.0056207,36.777,128.04,0.00064646,4.3336,128.01,120.04,100.36,119.84
43.7059,3.6472,0.0058824,37.057,130.94,0.00064397,4.3284,130.85,122.9,103.36,122.72
44.7059,3.6543,0.0048517,37.09,133.94,0.00058199,4.3359,133.9,125.85,106.5,125.74
45.7059,3.676,0.004173,37.15,136.94,0.00044355,4.3612,136.87,128.84,109.54,128.81
46.7059,3.6687,0.0014919,37.204,139.94,0.00013313,4.3532,139.85,131.75,112.66,131.85
47.7059,3.6847,0.00075981,37.313,142.94,6.6733e-05,4.3722,142.87,134.66,115.77,134.85
48.7059,3.733,0.00030836,37.545,145.94,6.3833e-05,4.4314,145.9,137.59,118.85,137.87
49.7059,3.8335,-0.0039164,37.445,148.94,-0.00042539,4.5506,148.97,140.53,121.97,140.89
50.7059,3.9191,-0.0022236,37.843,151.94,-0.00019543,4.6518,151.87,143.42,125.08,143.86
51.7059,3.9977,-0.0022463,37.793,154.94,-0.00026219,4.7441,154.9,146.33,128.11,146.7
52.7059,4.0448,-0.0016625,37.773,157.94,-0.00022977,4.8002,157.95,149.29,131.19,149.66
53.7059,4.0616,-0.004918,37.804,160.94,-0.00055144,4.8193,160.92,152.1,134.19,152.49
54.7059,4.078,-0.0054153,38.05,163.94,-0.00058313,4.8385,163.85,154.93,137.18,155.24
55.7059,4.0803,-0.0061755,37.856,166.94,-0.00067907,4.8418,166.94,157.8,140.18,158.07
56.7059,4.0814,-0.011938,37.838,169.94,-0.0012929,4.8436,169.99,160.67,143.14,160.93
57.7059,4.0531,-0.011292,38.188,172.94,-0.0012642,4.8111,172.93,163.36,146.15,163.78
58.7059,3.8929,-0.014222,38.536,175.94,-0.001618,4.6207,175.88,166.29,149.05,166.62
59.7059,3.7265,-0.01624,38.357,178.94,-0.0018202,4.4238,178.95,169.05,152.03,169.55
60.7059,3.6081,-0.021404,38.528,181.94,-0.0023611,4.2819,181.92,171.78,154.9,172.48
61.7059,3.547,-0.023633,38.708,184.94,-0.0026261,4.2092,184.88,174.47,157.86,175.33
62.7059,3.5313,-0.024767,38.548,187.94,-0.0027146,4.1891,187.94,177.23,160.87,178.25
63.7059,3.5102,-0.031308,38.865,190.94,-0.0035006,4.1645,190.81,179.95,163.81,181.22
64.7059,3.5122,-0.030312,38.559,193.94,-0.0034083,4.1671,193.94,182.6,166.78,184.18
65.7059,3.519,-0.032108,38.766,196.94,-0.0035969,4.1753,196.98,185.25,169.81,187.08
66.7059,3.5348,-0.033449,38.789,199.94,-0.0037258,4.1952,199.93,187.92,172.72,189.96
67.7059,3.5317,-0.037538,39.149,202.94,-0.004188,4.1924,202.9,190.5,175.59,192.83
68.5864,3.5308,-0.03919,39.491,205.58,-0.0043624,4.1894,205.39,192.69,178.19,195.29
69.5864,3.5414,-0.040386,39.369,208.58,-0.0044653,4.2023,208.51,195.35,181.11,198.12
70.5864,3.5429,-0.046255,39.803,211.58,-0.0051361,4.2037,211.47,198.08,184.0,200.99
71.5864,3.5403,-0.046115,39.471,214.58,-0.0051429,4.202,214.54,200.9,186.94,204.04
72.5864,3.5432,-0.047984,39.571,217.58,-0.0053697,4.2055,217.57,203.73,189.89,206.93
73.5864,3.5486,-0.048679,39.367,220.58,-0.005411,4.2119,220.64,206.5,192.87,209.98
74.5864,3.545,-0.053291,39.267,223.58,-0.0058956,4.2075,223.7,209.32,195.87,213.0
75.5864,3.5446,-0.055096,39.483,226.58,-0.006121,4.2077,226.61,211.96,198.83,215.97
76.4418,3.5498,-0.056336,39.513,229.15,-0.0062437,4.2123,229.17,214.4,201.53,218.49
77.4418,3.5575,-0.060573,39.659,232.15,-0.0067546,4.221,232.16,217.21,204.66,221.42
78.4418,3.5547,-0.062057,39.879,235.15,-0.006899,4.2183,235.11,220.07,207.79,224.38
79.4418,3.5567,-0.063923,39.831,238.15,-0.0070719,4.2218,238.16,222.96,211.03,227.29
80.4418,3.5556,-0.064617,40.003,241.15,-0.0071984,4.2196,241.06,225.75,214.13,230.25
81.4418,3.5497,-0.069739,40.368,244.15,-0.0077827,4.2131,244.01,228.54,217.34,233.14
82.4418,3.5459,-0.070839,40.442,247.15,-0.0078895,4.2099,247.0,231.49,220.56,236.09
83.4418,3.5487,-0.071636,40.456,250.15,-0.0079414,4.2118,250.07,234.35,223.86,239.06
84.4418,3.5511,-0.076886,40.293,253.15,-0.0085228,4.2141,253.11,237.17,227.21,242.09
85.4418,3.5474,-0.078697,40.572,256.15,-0.0087189,4.21,256.1,239.98,230.54,245.01
86.4418,3.5569,-0.079911,40.567,259.15,-0.0088479,4.2207,259.03,242.88,233.8,248.03
87.4418,3.5558,-0.086711,40.573,262.15,-0.0096638,4.2188,262.12,245.75,237.13,251.0
88.4418,3.5568,-0.086523,40.726,265.15,-0.0096329,4.2205,265.1,248.7,240.21,254.02
89.4418,3.5595,-0.088657,41.095,268.15,-0.009859,4.2247,268.05,251.53,242.36,256.98
90.4418,3.5617,-0.089481,40.958,271.15,-0.0099364,4.227,271.11,254.35,244.96,259.95
91.4418,3.5573,-0.094305,40.656,274.15,-0.010481,4.2229,274.18,257.27,247.76,262.95
92.4418,3.5513,-0.096498,40.698,277.15,-0.010677,4.216,277.19,259.96,250.6,265.87
93.4418,3.5515,-0.098111,40.916,280.15,-0.010871,4.2155,280.14,262.76,253.57,268.79
94.4418,3.5559,-0.1055,40.682,283.15,-0.011741,4.2196,283.22,265.58,256.53,271.81
95.4418,3.5503,-0.10494,40.816,286.15,-0.011675,4.2119,286.16,268.42,259.52,274.77
96.4418,3.5576,-0.10694,40.678,289.15,-0.011862,4.2203,289.22,271.06,262.87,277.64
97.4418,3.5625,-0.108,41.049,292.15,-0.011984,4.2263,292.1,273.85,266.23,280.54
98.4418,3.5586,-0.11301,40.793,295.15,-0.01254,4.2225,295.2,276.66,270.08,283.54
99.4418,3.5611,-0.11582,40.624,298.15,-0.012807,4.2271,298.21,279.39,272.41,286.49
100.4418,3.5619,-0.11685,41.081,301.15,-0.012937,4.2281,301.17,282.12,275.4,289.32
101.4156,3.5612,-0.12472,41.055,304.07,-0.013834,4.2274,304.01,284.66,278.57,292.03
102.4156,3.5519,-0.12428,41.259,307.07,-0.013785,4.216,306.98,287.38,281.84,294.89
103.4156,3.5547,-0.12662,41.329,310.07,-0.013998,4.2195,309.99,290.13,285.99,297.85
104.4156,3.554,-0.12707,41.053,313.07,-0.014068,4.218,313.13,292.73,288.57,300.75
105.4156,3.557,-0.13266,41.207,316.07,-0.014701,4.22,316.02,295.35,292.04,303.55
106.4156,3.5585,-0.13495,41.525,319.07,-0.014986,4.2211,318.98,297.85,295.6,306.33
107.4156,3.5664,-0.13704,41.241,322.07,-0.015188,4.2313,322.11,300.33,300.48,309.27
108.4156,3.5686,-0.13902,41.515,325.07,-0.015412,4.2342,325.11,302.6,306.55,312.09
109.3806,3.5674,-0.14372,41.488,327.96,-0.015903,4.2318,327.98,304.53,310.88,314.85
110.3806,3.5667,-0.14674,41.659,330.96,-0.016217,4.2329,330.93,307.09,315.55,317.7
111.3806,3.5688,-0.14824,41.585,333.96,-0.01642,4.2364,333.95,310.08,319.64,320.51
112.3806,3.5714,-0.15179,41.737,336.96,-0.016883,4.2392,336.92,314.59,323.09,323.37
113.3806,3.5606,-0.1555,41.802,339.96,-0.017245,4.227,339.95,318.72,326.24,326.22
114.3806,3.5575,-0.15814,41.754,342.96,-0.017481,4.2224,342.94,322.31,329.23,329.1
115.3806,3.5593,-0.15979,41.746,345.96,-0.017665,4.2244,345.95,325.35,332.25,331.97
116.3806,3.5645,-0.16404,42.002,348.96,-0.018183,4.2304,348.89,328.24,335.28,334.85
117.3806,3.5636,-0.16724,41.831,351.96,-0.018468,4.2276,351.93,330.98,338.16,337.73
118.3806,3.5674,-0.16984,41.837,354.96,-0.018783,4.2332,354.99,333.85,341.09,340.55
119.3806,3.5719,-0.17186,42.016,357.96,-0.019016,4.2383,357.92,336.45,343.98,343.43
120.3806,3.5762,-0.17285,42.285,360.96,-0.019161,4.2443,360.87,338.87,346.94,346.3
121.3806,3.5697,-0.17959,42.15,363.96,-0.019829,4.2364,363.97,341.08,350.01,349.15
122.3806,3.5664,-0.18153,42.185,366.96,-0.020054,4.2332,366.96,343.55,353.04,351.97
123.3806,3.5661,-0.18407,42.396,369.96,-0.020352,4.233,369.88,341.39,355.89,354.81
124.3806,3.5646,-0.18575,42.329,372.96,-0.020493,4.2318,372.93,342.11,358.77,357.56
125.3806,3.5633,-0.1894,42.396,375.96,-0.020942,4.2298,375.98,342.56,361.65,360.41
126.3806,3.5654,-0.19445,42.956,378.96,-0.021461,4.2311,378.71,344.04,364.49,363.21
127.3806,3.5628,-0.19655,42.854,381.96,-0.021744,4.2279,381.83,346.15,367.45,366.04
128.3806,3.5699,-0.19925,42.741,384.96,-0.022039,4.2353,384.94,347.68,370.39,368.93
129.3806,3.5735,-0.20185,42.682,387.96,-0.022282,4.2401,387.94,349.96,373.27,371.81
130.3806,3.5771,-0.20335,42.904,390.96,-0.022428,4.2447,390.91,352.17,376.11,374.52
131.3806,3.584,-0.206,42.355,393.96,-0.022771,4.254,394.08,354.46,378.9,377.21
132.3806,3.5763,-0.21605,42.473,396.96,-0.023819,4.2447,397.02,356.61,381.62,379.89
133.3806,3.5676,-0.21458,42.131,399.91,-0.02366,4.2344,400.07,358.72,384.32,382.48
134.3526,3.5667,-0.21546,38.571,400.0,-0.023762,4.2343,401.08,360.04,386.65,384.62
135.1906,3.5654,-0.21674,38.541,400.0,-0.023958,4.2311,400.88,360.5,387.69,385.41
136.1906,3.5648,-0.21802,37.923,400.0,-0.024085,4.2289,400.7,360.75,388.08,385.64
137.1906,3.5761,-0.21943,37.545,400.0,-0.024203,4.2421,400.64,360.81,388.16,385.53
138.1906,3.5769,-0.22034,37.201,400.0,-0.024297,4.2445,400.46,360.74,387.91,385.28
139.1906,3.5803,-0.22126,37.113,400.0,-0.024413,4.2487,400.31,360.74,387.6,384.92
140.1906,3.5784,-0.22213,36.769,400.0,-0.02447,4.2474,400.33,360.76,387.3,384.55
141.1906,3.5885,-0.22395,36.619,400.0,-0.024702,4.2597,400.31,360.62,386.89,384.14
142.1906,3.794,-0.22669,36.562,400.0,-0.025055,4.5037,400.2,360.55,386.56,383.82
143.1906,3.9423,-0.22929,36.725,400.0,-0.025315,4.6797,400.13,360.42,386.18,383.42
144.1906,4.015,-0.22966,39.889,400.0,-0.025338,4.7651,400.38,360.34,385.8,383.02
145.1906,4.0383,-0.22932,37.775,400.0,-0.025287,4.7913,403.79,361.24,386.07,383.45
146.1906,4.0625,-0.23255,41.398,400.0,-0.025644,4.8198,407.51,362.56,387.28,384.77
147.1906,4.0748,-0.23691,42.33,400.0,-0.026126,4.8332,411.56,364.19,389.24,386.89
148.1906,4.0875,-0.23941,44.547,400.0,-0.026385,4.8494,415.02,365.76,391.76,389.32
149.1906,4.119,-0.24389,45.79,400.0,-0.026849,4.888,423.33,368.9,395.18,392.85
150.1906,4.1297,-0.2451,42.906,400.0,-0.026986,4.9011,427.94,372.02,399.92,397.58
151.1906,4.1556,-0.24956,45.794,400.0,-0.027497,4.9336,432.68,374.75,404.23,401.76
152.1906,4.136,-0.24781,40.203,400.0,-0.027336,4.9095,434.88,377.44,408.99,406.35
153.1906,4.1616,-0.25214,41.794,400.0,-0.02781,4.9399,437.44,379.52,412.25,409.33
154.1906,4.1663,-0.25278,40.758,400.0,-0.027871,4.9449,438.4,381.48,415.52,412.49
155.1906,4.1718,-0.255,40.86,400.0,-0.028071,4.9506,439.99,383.42,418.06,414.9
156.1906,4.1855,-0.25741,41.227,400.0,-0.028342,4.9657,441.98,385.58,420.65,417.39
157.1906,4.1903,-0.25823,39.334,400.0,-0.02844,4.9718,443.3,387.63,423.11,419.8
158.1906,4.2043,-0.26198,42.079,400.0,-0.028835,4.9885,445.23,389.73,425.1,421.77
159.1906,4.2095,-0.26301,40.664,400.0,-0.028927,4.996,447.18,392.22,427.62,424.27
160.1906,4.1273,-0.25734,26.705,400.0,-0.02832,4.8989,442.54,392.98,428.92,425.53
161.1906,4.0961,-0.25575,29.575,400.0,-0.028177,4.8628,436.07,391.48,426.78,423.1
162.1906,4.1175,-0.25732,34.977,400.0,-0.02837,4.888,432.81,390.56,423.47,420.14
163.1906,4.0594,-0.25311,0.054736,400.0,-0.027919,4.8178,428.35,389.54,421.14,418.02
164.1906,4.0686,-0.25172,23.058,400.0,-0.027764,4.8289,421.57,386.44,416.41,413.35
165.1906,4.085,-0.25367,35.266,400.0,-0.027935,4.8475,418.17,384.82,412.49,409.52
166.1906,4.1068,-0.25518,34.685,400.0,-0.028052,4.8726,418.69,385.04,410.55,407.71
166.9954,4.1013,-0.25477,34.468,400.0,-0.028067,4.8663,417.47,384.84,409.61,406.89
167.9954,4.1243,-0.25612,34.373,400.0,-0.028186,4.894,417.52,384.71,408.65,406.01
168.9954,4.1006,-0.25559,32.65,400.0,-0.028113,4.8665,416.11,384.12,408.16,405.58
169.9954,4.121,-0.2561,33.329,400.0,-0.028187,4.8919,414.33,383.34,406.99,404.36
170.9954,4.0968,-0.25458,31.465,400.0,-0.028059,4.8634,411.34,382.2,405.63,403.09
171.9954,4.1133,-0.25528,33.71,400.0,-0.028139,4.8827,409.56,381.18,403.77,401.19
172.9954,4.1217,-0.2562,33.817,400.0,-0.028265,4.8917,409.68,381.1,402.59,400.04
173.9954,4.1367,-0.25713,34.643,400.0,-0.028365,4.9087,409.67,381.14,401.98,399.56
174.9954,4.1448,-0.25882,34.519,400.0,-0.028538,4.9177,409.72,381.3,401.8,399.42
175.9954,4.1513,-0.2618,34.677,400.0,-0.02886,4.9252,409.8,381.5,401.81,399.38
176.9954,4.1602,-0.26493,34.662,400.0,-0.029208,4.9358,409.87,381.7,401.86,399.48
177.9954,4.1643,-0.26741,34.848,400.0,-0.029454,4.9416,409.88,382.04,401.94,399.58
178.61373,4.1617,-0.0026846,0.0,69.759,-8.6593e-05,4.934,410.18,382.24,402.0,399.88
178.61538,4.0985,0.00017662,0.0,9.2435e-06,-0.00053666,4.8912,410.32,382.23,402.0,399.95
178.61703,4.2359,-0.00096128,0.0,1.1235e-12,0.00033134,5.0331,410.46,382.22,401.99,400.02
178.61868,4.1922,0.0040873,0.0,1.2974000000000002e-19,0.00093773,4.974,410.6,382.21,401.99,400.09
178.62033,4.1981,0.0060872,0.0,1.4481999999999998e-26,0.00032347,4.9817,410.6,382.21,401.98,400.09
178.62198,4.167,0.0049058,0.0,3.6345e-33,-0.00042566,4.9394,410.5,382.21,401.96,400.03
178.62363,4.15,-0.0031513,0.0,8.4931e-40,0.00010251,4.9263,410.4,382.21,401.95,399.97
178.62528,4.15,0.0015738,0.0,0.0,0.00081103,4.9349,410.3,382.21,401.93,399.91
178.62693,4.1727,-0.00015784,0.0,0.0,-0.00047683,4.9614,410.2,382.21,401.92,399.85
178.62858,4.2026,-0.003433,0.0,0.0,-0.00012412,4.9886,410.1,382.21,401.9,399.79
178.63023,4.2013,0.0028648,0.0,0.0,-0.00042844,4.9783,410.04,382.21,401.91,399.75
178.63188,4.1814,0.0035007,0.0,0.0,0.0011557,4.9374,410.02,382.21,401.93,399.73
178.63353,4.1459,-0.00088789,0.0,0.0,0.00046071,4.912,410.0,382.21,401.95,399.71
178.63518,4.1424,0.0022497,0.0,0.0,-0.00073893,4.9182,409.98,382.21,401.97,399.69
178.63683,4.167,-0.0032752,0.0,0.0,-5.8142e-05,4.9504,409.96,382.21,401.99,399.67
178.63848,4.1964,-0.0022037,0.0,0.0,-0.00027799,4.9854,409.94,382.21,402.01,399.65
178.64013,4.1985,0.001967,0.0,0.0,0.00087128,4.9829,409.93,382.21,402.02,399.63
178.64178,4.1664,-0.0028142,0.0,0.0,-3.0289e-05,4.9411,409.93,382.21,402.03,399.62
178.64343,4.1306,0.0023172,0.0,0.0,-0.00089249,4.9056,409.93,382.21,402.04,399.61
178.64508,4.1425,0.0030353,0.0,0.0,0.00027177,4.9179,409.93,382.21,402.05,399.61
178.64673,4.1674,-0.0034566,0.0,0.0,0.0001292,4.9593,409.93,382.21,402.06,399.6
178.64838,4.1963,8.9842e-05,0.0,0.0,0.00029678,4.9853,409.93,382.21,402.07,399.59
178.65003,4.2026,0.0011406,0.0,0.0,-0.00066266,4.9639,409.94,382.21,402.08,399.58
178.65168,4.166,-0.0040239,0.0,0.0,0.00031718,4.9397,409.95,382.22,402.08,399.57
178.65333,4.1367,0.0033352,0.0,0.0,0.00074873,4.8965,409.97,382.23,402.08,399.56
178.65498,4.1226,0.0039237,0.0,0.0,-0.00015106,4.9126,409.98,382.24,402.08,399.55
178.65663,4.1568,-0.0022597,0.0,0.0,-0.00040112,4.9331,410.0,382.25,402.08,399.54
178.65828,4.1887,0.0029783,0.0,0.0,-0.00072114,4.9777,410.01,382.26,402.08,399.53
178.65993,4.1859,-0.002529,0.0,0.0,0.0010145,4.9736,410.01,382.28,402.08,399.52
178.66158,4.1617,-0.0008422,0.0,0.0,0.000704,4.922,409.98,382.32,402.07,399.51
178.66323,4.1157,0.00024358,0.0,0.0,-0.00062778,4.88,409.95,382.36,402.07,399.5
178.66488,4.1129,-0.0021279,0.0,0.0,-0.00012853,4.8882,409.92,382.4,402.06,399.49
178.66653,4.1513,0.0046206,0.0,0.0,-0.00052403,4.9313,409.9,382.44,402.06,399.48
178.66818,4.1735,0.0035171,0.0,0.0,0.00093339,4.9685,409.87,382.48,402.05,399.47
178.66983,4.1857,-0.001888,0.0,0.0,0.00035652,4.9752,410.16,382.89,402.06,399.45
178.67148,4.1728,0.00036313,0.0,0.0,-0.00058248,4.9466,411.37,384.34,402.1,399.44
178.67313,4.1137,-0.00061792,0.0,0.0,-5.8632e-05,4.8704,412.59,385.8,402.15,399.42
178.67478,4.0758,-0.0049082,0.0,0.0,-0.00012656,4.8386,413.8,387.25,402.19,399.41
178.67643,8.301,0.044568,0.0,0.0,0.0051128,9.5421,415.02,388.7,402.24,399.4
178.67808,37.557,0.16874,0.0,0.0,0.018322,43.707,416.23,390.15,402.28,399.38
178.67973,62.479,0.24481,0.0,0.0,0.026853,73.294,417.59,391.76,402.33,399.37
178.68138,74.186,0.43152,0.0,0.0,0.048494,87.734,419.49,394.0,402.41,399.36
178.68303,79.133,0.62479,0.0,0.0,0.071332,93.702,421.39,396.23,402.49,399.35
178.68468,82.617,0.86768,0.0,0.0,0.10049,97.888,423.3,398.46,402.57,399.34
178.68633,86.025,1.2006,0.0,0.0,0.13943,101.95,425.2,400.69,402.65,399.33
178.68798,87.491,1.5587,0.0,0.0,0.18828,103.78,427.1,402.93,402.73,399.32
178.68963,88.836,1.9326,0.0,0.0,0.23793,105.39,428.92,405.08,402.8,399.31
178.69128,89.443,2.2994,0.0,0.0,0.28902,106.1,430.21,406.76,402.8,399.34
178.69293,89.921,2.6462,0.0,0.0,0.34039,106.67,431.5,408.45,402.8,399.36
178.69458,90.292,2.9813,0.0,0.0,0.39135,107.12,432.8,410.13,402.8,399.39
178.69623,90.712,3.3086,0.0,0.0,0.44735,107.65,434.09,411.81,402.8,399.41
178.69788,91.195,3.6263,0.0,0.0,0.5017,108.21,435.38,413.49,402.8,399.44
178.69953,91.676,3.9495,0.0,0.0,0.55673,108.8,436.67,415.15,402.8,399.46
178.70118,92.125,4.2624,0.0,0.0,0.61508,109.3,437.98,416.48,402.77,399.46
178.70283,92.533,4.5727,0.0,0.0,0.67812,109.77,439.3,417.82,402.75,399.46
178.70448,92.932,4.8834,0.0,0.0,0.74431,110.26,440.61,419.15,402.72,399.46
178.70613,93.357,5.1909,0.0,0.0,0.81006,110.79,441.92,420.48,402.7,399.46
178.70778,93.833,5.4951,0.0,0.0,0.88369,111.32,443.23,421.82,402.67,399.46
178.70943,94.259,5.797,0.0,0.0,0.96007,111.82,444.52,423.14,402.65,399.46
178.71108,94.802,6.0927,0.0,0.0,1.0429,112.46,444.88,423.84,402.6,399.46
178.71273,95.465,6.3864,0.0,0.0,1.1248,113.24,445.24,424.55,402.56,399.46
178.71438,96.163,6.6698,0.0,0.0,1.2097,114.06,445.6,425.25,402.51,399.46
178.71603,97.06,6.9392,0.0,0.0,1.3102,115.14,445.96,425.95,402.47,399.46
178.71768,98.222,7.1992,0.0,0.0,1.4086,116.5,446.33,426.66,402.42,399.46
178.71933,99.465,7.4441,0.0,0.0,1.5099,117.99,446.69,427.36,402.38,399.46
178.72098,100.32,7.6704,0.0,0.0,1.6093,118.99,445.87,427.21,402.36,399.45
178.72263,101.44,7.8815,0.0,0.0,1.7025,120.32,445.0,427.01,402.34,399.44
178.72428,97.449,8.0474,0.0,0.0,1.803,116.16,444.13,426.82,402.32,399.43
178.72593,87.55,8.0556,0.0,0.0,1.8123,103.98,443.26,426.63,402.3,399.42
178.72758,83.255,8.0726,0.0,0.0,1.8165,98.931,442.39,426.43,402.28,399.41
178.72923,80.448,8.087,0.0,0.0,1.8218,95.56,441.52,426.24,402.26,399.4
178.73088,78.088,8.0881,0.0,0.0,1.8264,92.702,440.61,425.46,402.28,399.38
178.73253,76.27,8.1009,0.0,0.0,1.8383,90.574,439.69,424.6,402.3,399.36
178.73418,74.763,8.109,0.0,0.0,1.8382,88.803,438.78,423.75,402.32,399.34
178.73583,73.455,8.1178,0.0,0.0,1.8401,87.218,437.86,422.9,402.34,399.32
178.73748,72.271,8.1215,0.0,0.0,1.8411,85.81,436.95,422.05,402.36,399.3
178.73913,71.171,8.1212,0.0,0.0,1.85,84.511,436.03,421.19,402.38,399.28
178.74078,70.076,8.1237,0.0,0.0,1.8511,83.206,435.28,420.46,402.38,399.3
178.74243,69.03,8.1259,0.0,0.0,1.8421,81.964,434.55,419.74,402.39,399.33
178.74408,67.976,8.1211,0.0,0.0,1.8473,80.727,433.83,419.03,402.39,399.36
178.74573,66.96,8.1309,0.0,0.0,1.8498,79.503,433.11,418.32,402.4,399.39
178.74738,65.974,8.1349,0.0,0.0,1.8573,78.333,432.39,417.6,402.4,399.42
178.74903,65.07,8.1293,0.0,0.0,1.8512,77.247,431.66,416.89,402.41,399.45
178.75068,64.263,8.1316,0.0,0.0,1.8434,76.289,431.02,416.27,402.42,399.49
178.75233,63.61,8.1313,0.0,0.0,1.8513,75.505,430.4,415.67,402.43,399.53
178.75398,63.062,8.1282,0.0,0.0,1.855,74.865,429.78,415.08,402.45,399.57
178.75563,62.537,8.1326,0.0,0.0,1.8562,74.236,429.17,414.48,402.46,399.61
178.75728,62.005,8.1351,0.0,0.0,1.851,73.595,428.55,413.89,402.48,399.65
178.75893,61.374,8.1342,0.0,0.0,1.8493,72.861,427.93,413.29,402.49,399.69
178.76058,60.291,8.1385,0.0,0.0,1.8571,71.614,427.59,412.9,402.5,399.71
178.76223,58.626,8.1313,0.0,0.0,1.8512,69.658,427.37,412.59,402.49,399.72
178.76388,56.52,8.1311,0.0,0.0,1.8486,67.195,427.15,412.29,402.49,399.73
178.76553,53.875,8.1234,0.0,0.0,1.8423,64.125,426.92,411.98,402.48,399.74
178.76718,50.3,8.1147,0.0,0.0,1.8535,59.91,426.7,411.67,402.48,399.75
178.76883,41.889,8.1097,0.0,0.0,1.8443,51.233,426.48,411.36,402.47,399.76
178.77048,7.5781,8.011,0.0,0.0,1.7793,10.116,426.45,411.23,402.47,399.76
178.77213,1.6879,7.9407,0.0,0.0,1.7426,1.5827,426.53,411.19,402.47,399.76
178.77378,3.3009,7.9851,0.0,0.0,1.7675,4.1595,426.61,411.15,402.47,399.76
178.77543,3.6317,7.9973,0.0,0.0,1.7826,4.2195,426.69,411.11,402.47,399.76
178.77708,3.4322,7.9844,0.0,0.0,1.7764,4.1554,426.77,411.07,402.47,399.76
178.77873,4.0697,7.988,0.0,0.0,1.7665,4.8503,426.85,411.03,402.47,399.76
178.78038,3.51,7.9935,0.0,0.0,1.7718,4.1393,426.94,411.03,402.48,399.78
178.78203,3.7209,7.9997,0.0,0.0,1.7765,4.4017,427.02,411.05,402.5,399.81
178.78368,3.4525,8.0041,0.0,0.0,1.7833,4.0853,427.11,411.07,402.52,399.84
178.78533,3.5921,8.0016,0.0,0.0,1.7776,4.278,427.2,411.09,402.54,399.87
178.78698,3.6942,8.0011,0.0,0.0,1.7752,4.3808,427.29,411.11,402.56,399.9
178.78863,3.5906,8.0003,0.0,0.0,1.7796,4.2477,427.38,411.13,402.58,399.93
178.79028,3.5775,7.9925,0.0,0.0,1.7785,4.2342,427.48,411.18,402.58,399.92
178.79193,3.5323,8.0008,0.0,0.0,1.7783,4.1965,427.57,411.27,402.57,399.88
178.79358,3.5198,8.002,0.0,0.0,1.7721,4.1939,427.67,411.35,402.55,399.84
178.79523,3.6013,7.9949,0.0,0.0,1.7766,4.2956,427.77,411.44,402.54,399.8
178.79688,3.6836,8.0013,0.0,0.0,1.7815,4.3842,427.87,411.52,402.52,399.76
178.79853,3.6861,7.9988,0.0,0.0,1.7758,4.3609,427.97,411.6,402.51,399.72
178.80018,3.5832,7.9924,0.0,0.0,1.774,4.2542,428.06,411.66,402.49,399.68
178.80183,3.5609,7.9976,0.0,0.0,1.7706,4.2166,428.14,411.68,402.48,399.64
178.80348,3.6078,7.9993,0.0,0.0,1.7819,4.3075,428.22,411.7,402.47,399.6
178.80513,3.6275,7.9993,0.0,0.0,1.7818,4.3055,428.3,411.72,402.46,399.56
178.80678,3.692,8.001,0.0,0.0,1.774,4.3912,428.38,411.74,402.45,399.52
178.80843,3.6545,7.9986,0.0,0.0,1.7731,4.3334,428.46,411.76,402.44,399.48
178.81008,3.6032,7.996,0.0,0.0,1.7733,4.2618,428.51,411.76,402.43,399.47
178.81173,3.5735,7.9955,0.0,0.0,1.7814,4.2393,428.53,411.74,402.42,399.5
178.81338,3.6105,7.9942,0.0,0.0,1.7781,4.3003,428.55,411.72,402.4,399.53
178.81503,3.6696,7.999,0.0,0.0,1.7739,4.3524,428.57,411.7,402.39,399.56
178.81668,3.6737,8.0006,0.0,0.0,1.7756,4.3536,428.59,411.68,402.37,399.59
178.81833,3.6454,7.9975,0.0,0.0,1.7794,4.3177,428.61,411.66,402.36,399.62
178.81998,3.6112,7.9996,0.0,0.0,1.7774,4.2638,428.63,411.64,402.34,399.64
178.82163,3.5552,7.9995,0.0,0.0,1.7686,4.2208,428.66,411.6,402.32,399.64
178.82328,3.5763,7.9886,0.0,0.0,1.7767,4.2633,428.69,411.57,402.3,399.64
178.82493,3.6421,7.9966,0.0,0.0,1.7805,4.3401,428.72,411.53,402.28,399.64
178.82658,3.7042,7.9971,0.0,0.0,1.7792,4.3987,428.75,411.5,402.26,399.64
178.82823,3.7062,7.9977,0.0,0.0,1.7743,4.3836,428.78,411.46,402.24,399.64
178.82988,3.6606,8.0,0.0,0.0,1.768,4.3402,428.81,411.44,402.22,399.63
178.83153,3.6128,8.0003,0.0,0.0,1.7796,4.2838,428.85,411.43,402.22,399.61
178.83318,3.6122,7.9937,0.0,0.0,1.7796,4.2919,428.89,411.43,402.21,399.59
178.83483,3.6397,7.9945,0.0,0.0,1.7769,4.3354,428.93,411.42,402.2,399.57
178.83648,3.647,7.9913,0.0,0.0,1.7727,4.3284,428.97,411.42,402.19,399.55
178.83813,3.6657,7.9984,0.0,0.0,1.7717,4.3341,429.01,411.41,402.18,399.53
178.83978,3.6181,8.0009,0.0,0.0,1.7809,4.2839,429.05,411.4,402.17,399.52
178.84143,3.591,7.9959,0.0,0.0,1.7775,4.2654,429.06,411.35,402.17,399.53
178.84308,3.617,8.0013,0.0,0.0,1.7753,4.299,429.07,411.31,402.18,399.54
178.84473,3.6892,8.0024,0.0,0.0,1.7744,4.3812,429.08,411.26,402.18,399.55
178.84638,3.6843,7.9911,0.0,0.0,1.7774,4.3771,429.09,411.22,402.19,399.56
178.84803,3.6697,7.9975,0.0,0.0,1.7806,4.3565,429.1,411.17,402.19,399.57
178.84968,3.6522,8.0011,0.0,0.0,1.7747,4.3397,429.1,411.13,402.2,399.58
178.85133,3.6639,7.9971,0.0,0.0,1.7745,4.3632,429.1,411.07,402.23,399.6
178.85298,3.7346,8.0033,0.0,0.0,1.7774,4.4361,429.1,411.01,402.25,399.62
178.85463,3.7604,8.0038,0.0,0.0,1.7836,4.4763,429.1,410.95,402.28,399.64
178.85628,3.7381,7.9959,0.0,0.0,1.7782,4.4321,429.1,410.89,402.3,399.66
178.85793,3.7715,7.9993,0.0,0.0,1.7696,4.4668,429.1,410.83,402.33,399.68
178.85958,3.7781,7.9969,0.0,0.0,1.778,4.4954,429.1,410.77,402.35,399.7
178.86123,3.7753,7.9984,0.0,0.0,1.7794,4.476,429.1,410.72,402.35,399.71
178.86288,3.7802,8.002,0.0,0.0,1.7819,4.4973,429.1,410.66,402.36,399.72
178.86453,3.8601,8.0011,0.0,0.0,1.7768,4.5896,429.1,410.61,402.36,399.73
178.86618,3.9347,8.0023,0.0,0.0,1.7705,4.6752,429.1,410.55,402.37,399.74
178.86783,3.9368,8.0031,0.0,0.0,1.7798,4.6629,429.1,410.5,402.37,399.75
178.86948,3.8058,7.9933,0.0,0.0,1.7797,4.5003,429.1,410.44,402.38,399.76
178.87113,3.726,7.9987,0.0,0.0,1.7777,4.4327,429.1,410.35,402.36,399.78
178.87278,3.7666,8.002,0.0,0.0,1.7748,4.4923,429.1,410.25,402.35,399.8
178.87443,3.8871,7.9999,0.0,0.0,1.7801,4.6489,429.1,410.16,402.33,399.82
178.87608,4.0091,8.0021,0.0,0.0,1.7815,4.7469,429.1,410.06,402.32,399.84
178.87773,3.9121,8.0042,0.0,0.0,1.7747,4.5961,429.1,409.97,402.3,399.86
178.87938,3.7852,7.9945,0.0,0.0,1.7734,4.4648,429.1,409.87,402.29,399.88
178.88103,3.7117,7.9972,0.0,0.0,1.7737,4.3921,429.08,409.81,402.28,399.87
178.88268,3.7464,7.998,0.0,0.0,1.7854,4.4854,429.05,409.75,402.27,399.86
178.88433,3.8916,7.9987,0.0,0.0,1.7813,4.6537,429.03,409.7,402.26,399.85
178.88598,3.9754,8.0028,0.0,0.0,1.772,4.7352,429.0,409.64,402.25,399.84
178.88763,3.9472,7.9963,0.0,0.0,1.7728,4.66,428.98,409.58,402.24,399.83
178.88928,3.8017,8.004,0.0,0.0,1.777,4.4805,428.96,409.52,402.23,399.82
178.89093,3.7013,8.0027,0.0,0.0,1.7837,4.3744,428.93,409.46,402.22,399.79
178.89258,3.7475,7.995,0.0,0.0,1.7798,4.4607,428.92,409.4,402.22,399.76
178.89423,3.8952,7.9998,0.0,0.0,1.7725,4.6439,428.9,409.34,402.21,399.73
178.89588,3.9662,8.0003,0.0,0.0,1.7772,4.7138,428.88,409.28,402.21,399.7
178.89753,3.9326,7.9961,0.0,0.0,1.778,4.6449,428.86,409.22,402.2,399.67
178.89918,3.8072,8.001,0.0,0.0,1.7786,4.4877,428.84,409.16,402.2,399.64
178.90083,3.709,8.0008,0.0,0.0,1.7725,4.3956,428.83,409.1,402.2,399.64
178.90248,3.7602,7.9982,0.0,0.0,1.777,4.4903,428.82,409.04,402.2,399.64
178.90413,3.8891,7.9971,0.0,0.0,1.7799,4.6348,428.82,408.98,402.2,399.64
178.90578,3.9795,7.9974,0.0,0.0,1.778,4.7142,428.81,408.92,402.2,399.64
178.90743,3.9351,7.995,0.0,0.0,1.7741,4.6511,428.81,408.86,402.2,399.64
178.90908,3.8152,8.0,0.0,0.0,1.7712,4.5015,428.8,408.8,402.2,399.64
178.91073,3.7149,7.9989,0.0,0.0,1.7809,4.3891,428.8,408.74,402.2,399.64
178.91238,3.7548,8.0027,0.0,0.0,1.7826,4.4901,428.79,408.68,402.2,399.65
178.91403,3.8918,8.0024,0.0,0.0,1.7744,4.6432,428.79,408.62,402.2,399.65
178.91568,3.9657,7.9954,0.0,0.0,1.7738,4.7137,428.78,408.56,402.2,399.66
178.91733,3.9352,7.9975,0.0,0.0,1.773,4.6442,428.78,408.5,402.2,399.66
178.91898,3.814,7.9992,0.0,0.0,1.7829,4.5003,428.77,408.44,402.2,399.67
178.92063,3.7249,7.9955,0.0,0.0,1.7797,4.4173,428.76,408.35,402.21,399.65
178.92228,3.7537,8.0047,0.0,0.0,1.7739,4.4776,428.74,408.26,402.22,399.63
178.92393,3.893,8.0078,0.0,0.0,1.7767,4.6513,428.72,408.16,402.24,399.61
178.92558,3.9694,7.9958,0.0,0.0,1.777,4.7154,428.7,408.06,402.25,399.59
178.92723,3.9358,7.9991,0.0,0.0,1.7809,4.6517,428.68,407.96,402.27,399.58
178.92888,3.8211,7.9973,0.0,0.0,1.774,4.5116,428.66,407.86,402.28,399.56
178.93053,3.7304,7.997,0.0,0.0,1.7765,4.4331,428.63,407.78,402.31,399.55
178.93218,3.7742,8.0025,0.0,0.0,1.7812,4.5108,428.6,407.72,402.34,399.56
178.93383,3.9111,8.0009,0.0,0.0,1.7804,4.6836,428.56,407.65,402.37,399.56
178.93548,3.9842,8.0057,0.0,0.0,1.7764,4.7393,428.53,407.59,402.4,399.57
178.93713,3.9459,8.0028,0.0,0.0,1.7693,4.6492,428.49,407.52,402.43,399.57
178.93878,3.8241,7.9964,0.0,0.0,1.7813,4.5127,428.46,407.46,402.46,399.58
178.94043,3.7376,7.999,0.0,0.0,1.7829,4.423,428.42,407.39,402.47,399.59
178.94208,3.7833,8.0006,0.0,0.0,1.7787,4.5203,428.38,407.31,402.47,399.61
178.94373,3.9178,8.001,0.0,0.0,1.7765,4.6733,428.34,407.24,402.47,399.63
178.94538,3.9971,8.0061,0.0,0.0,1.7716,4.7513,428.3,407.17,402.47,399.65
178.94703,3.9587,8.0057,0.0,0.0,1.7829,4.6778,428.26,407.09,402.47,399.67
178.94868,3.8338,7.9967,0.0,0.0,1.7817,4.5317,428.22,407.02,402.47,399.69
178.95033,3.7489,8.0032,0.0,0.0,1.7778,4.4425,428.18,406.92,402.47,399.71
178.95198,3.7915,8.0,0.0,0.0,1.775,4.5186,428.14,406.8,402.47,399.71
178.95363,3.9271,8.0001,0.0,0.0,1.7776,4.6794,428.1,406.68,402.47,399.72
178.95528,3.9977,8.0041,0.0,0.0,1.7837,4.7493,428.06,406.56,402.47,399.73
178.95693,3.9684,8.0012,0.0,0.0,1.7767,4.6813,428.02,406.44,402.47,399.74
178.95858,3.842,8.0043,0.0,0.0,1.7759,4.5337,427.98,406.32,402.47,399.75
178.96023,3.7557,8.0046,0.0,0.0,1.778,4.4635,427.96,406.22,402.47,399.76
178.96188,3.8022,7.9997,0.0,0.0,1.7822,4.5338,427.94,406.15,402.48,399.77
178.96353,3.924,8.0008,0.0,0.0,1.7805,4.6775,427.93,406.07,402.48,399.78
178.96518,4.0171,8.0042,0.0,0.0,1.7739,4.7735,427.91,406.0,402.49,399.79
178.96683,3.9776,7.9971,0.0,0.0,1.7774,4.6928,427.9,405.93,402.49,399.8
178.96848,3.8506,8.0067,0.0,0.0,1.782,4.5317,427.88,405.85,402.5,399.81
178.97013,3.7624,8.0069,0.0,0.0,1.7833,4.46,427.86,405.78,402.51,399.82
178.97178,3.7838,7.9978,0.0,0.0,1.7763,4.52,427.83,405.72,402.52,399.82
178.97343,3.9298,8.0042,0.0,0.0,1.7722,4.6874,427.8,405.65,402.54,399.82
178.97508,4.0091,8.0017,0.0,0.0,1.7808,4.7671,427.77,405.59,402.55,399.82
178.97673,3.9637,7.9981,0.0,0.0,1.7824,4.6885,427.74,405.52,402.56,399.82
178.97838,3.85,8.0008,0.0,0.0,1.779,4.5433,427.71,405.46,402.58,399.82
178.98003,3.7478,8.0049,0.0,0.0,1.7754,4.452,427.67,405.39,402.59,399.82
178.98168,3.7866,8.0044,0.0,0.0,1.7749,4.5071,427.62,405.31,402.61,399.82
178.98333,3.923,8.0053,0.0,0.0,1.7834,4.6796,427.58,405.23,402.62,399.82
178.98498,4.0162,7.9998,0.0,0.0,1.7781,4.7568,427.53,405.15,402.64,399.82
178.98663,3.9641,7.9971,0.0,0.0,1.7753,4.6752,427.48,405.07,402.65,399.82
178.98828,3.8522,8.0017,0.0,0.0,1.7765,4.5419,427.43,404.99,402.67,399.82
178.98993,3.745,7.9955,0.0,0.0,1.7837,4.446,427.38,404.91,402.68,399.82
178.99158,3.794,8.0096,0.0,0.0,1.7849,4.5408,427.33,404.83,402.67,399.83
178.99323,3.9307,8.0054,0.0,0.0,1.7713,4.7203,427.29,404.74,402.67,399.84
178.99488,3.9984,8.0008,0.0,0.0,1.7772,4.7689,427.24,404.66,402.66,399.85
178.99653,3.965,8.0004,0.0,0.0,1.7769,4.6722,427.2,404.57,402.66,399.86
178.99818,3.8498,8.0003,0.0,0.0,1.7846,4.5428,427.16,404.49,402.65,399.87
178.99983,3.7627,7.997,0.0,0.0,1.7812,4.4542,427.11,404.4,402.64,399.88
179.00148,3.8035,8.003,0.0,0.0,1.771,4.5386,427.08,404.28,402.62,399.89
179.00313,3.9334,8.0057,0.0,0.0,1.7785,4.6953,427.04,404.17,402.6,399.9
179.00478,4.0159,8.0037,0.0,0.0,1.7804,4.7625,427.01,404.05,402.58,399.91
179.00643,3.9872,8.0045,0.0,0.0,1.7832,4.7123,426.97,403.94,402.56,399.92
179.00808,3.8642,7.9984,0.0,0.0,1.7757,4.5622,426.94,403.82,402.54,399.93
179.00973,3.7833,7.9991,0.0,0.0,1.774,4.4842,426.91,403.72,402.53,399.94
179.01138,3.813,8.0029,0.0,0.0,1.7822,4.5478,426.88,403.64,402.53,399.94
179.01303,3.9438,7.9984,0.0,0.0,1.7806,4.7084,426.86,403.56,402.54,399.94
179.01468,4.0426,8.0076,0.0,0.0,1.7793,4.7938,426.83,403.48,402.54,399.94
179.01633,3.9761,8.0062,0.0,0.0,1.7744,4.7016,426.81,403.4,402.55,399.94
179.01798,3.8693,7.998,0.0,0.0,1.7788,4.5587,426.78,403.32,402.55,399.94
179.01963,3.7916,8.0048,0.0,0.0,1.7846,4.4933,426.76,403.24,402.56,399.94
179.02128,3.8231,8.0021,0.0,0.0,1.7765,4.5692,426.71,403.18,402.56,399.93
179.02293,3.9532,7.9975,0.0,0.0,1.7763,4.7109,426.67,403.12,402.57,399.92
179.02458,4.0424,8.005,0.0,0.0,1.7756,4.7909,426.62,403.06,402.57,399.91
179.02623,4.0119,8.0051,0.0,0.0,1.7852,4.7293,426.58,403.0,402.58,399.9
179.02788,3.8889,8.0027,0.0,0.0,1.7827,4.5887,426.53,402.94,402.58,399.89
179.02953,3.7955,8.0047,0.0,0.0,1.774,4.4897,426.49,402.88,402.59,399.88
179.03118,3.83,8.0022,0.0,0.0,1.7767,4.5617,426.44,402.79,402.59,399.88
179.03283,3.9663,8.0013,0.0,0.0,1.7787,4.722,426.39,402.69,402.59,399.88
179.03448,4.0461,8.0044,0.0,0.0,1.7862,4.8071,426.34,402.6,402.59,399.88
179.03613,4.0071,7.9977,0.0,0.0,1.7795,4.7278,426.29,402.51,402.59,399.88
179.03778,3.8933,8.0069,0.0,0.0,1.7753,4.5946,426.24,402.41,402.59,399.88
179.03943,3.7994,8.0058,0.0,0.0,1.7795,4.5139,426.19,402.32,402.59,399.88
179.04108,3.8271,8.0021,0.0,0.0,1.7813,4.5762,426.15,402.24,402.6,399.89
179.04273,3.9717,8.0047,0.0,0.0,1.7804,4.7458,426.11,402.16,402.62,399.9
179.04438,4.0391,8.0044,0.0,0.0,1.7741,4.7854,426.07,402.08,402.63,399.91
179.04603,4.0222,7.998,0.0,0.0,1.7818,4.734,426.03,402.0,402.65,399.92
179.04768,3.8894,7.9999,0.0,0.0,1.7834,4.5616,425.99,401.92,402.66,399.93
179.04933,3.7881,8.0095,0.0,0.0,1.7814,4.4724,425.95,401.84,402.68,399.94
179.05098,3.8413,8.0012,0.0,0.0,1.7748,4.5936,425.9,401.77,402.68,399.95
179.05263,3.962,8.0066,0.0,0.0,1.7732,4.7268,425.85,401.69,402.69,399.96
179.05428,4.0424,8.0041,0.0,0.0,1.7852,4.7953,425.8,401.62,402.69,399.97
179.05593,4.0031,7.9981,0.0,0.0,1.7834,4.722,425.75,401.54,402.7,399.98
179.05758,3.8847,8.0026,0.0,0.0,1.7785,4.5965,425.71,401.47,402.7,399.99
179.05923,3.7887,7.9973,0.0,0.0,1.7747,4.4849,425.66,401.39,402.71,400.0
179.06088,3.8368,8.0063,0.0,0.0,1.7761,4.5751,425.6,401.3,402.69,400.01
179.06253,3.9538,8.0084,0.0,0.0,1.7858,4.7205,425.55,401.22,402.66,400.02
179.06418,4.031,8.001,0.0,0.0,1.7806,4.7927,425.49,401.13,402.64,400.03
179.06583,4.0071,8.0037,0.0,0.0,1.7762,4.7415,425.44,401.04,402.61,400.04
179.06748,3.8955,8.0044,0.0,0.0,1.7781,4.5964,425.38,400.95,402.59,400.05
179.06913,3.7948,7.9932,0.0,0.0,1.7789,4.4949,425.33,400.86,402.56,400.06
179.07078,3.8294,8.0076,0.0,0.0,1.7844,4.5579,425.29,400.79,402.54,400.06
179.07243,3.9573,8.0064,0.0,0.0,1.7759,4.7218,425.25,400.73,402.52,400.06
179.07408,4.0477,8.0042,0.0,0.0,1.7784,4.8034,425.21,400.67,402.5,400.06
179.07573,3.9997,8.0068,0.0,0.0,1.7817,4.7238,425.17,400.61,402.48,400.06
179.07738,3.8997,8.0016,0.0,0.0,1.7807,4.5965,425.13,400.56,402.46,400.06
179.07903,3.8069,8.0006,0.0,0.0,1.7791,4.5175,425.09,400.5,402.44,400.06
179.08068,3.8327,8.002,0.0,0.0,1.7716,4.5653,425.05,400.43,402.46,400.06
179.08233,3.9877,8.003,0.0,0.0,1.7827,4.764,425.01,400.36,402.49,400.06
179.08398,4.0468,8.0052,0.0,0.0,1.7833,4.814,424.97,400.29,402.52,400.06
179.08563,4.0168,8.0086,0.0,0.0,1.7818,4.7484,424.93,400.22,402.55,400.06
179.08728,3.9156,8.0013,0.0,0.0,1.776,4.6275,424.89,400.15,402.58,400.06
179.08893,3.8148,8.0051,0.0,0.0,1.7743,4.529,424.85,400.08,402.61,400.06
179.09058,3.8536,8.0061,0.0,0.0,1.7852,4.597,424.81,399.98,402.63,400.07
179.09223,4.0038,7.9945,0.0,0.0,1.7828,4.7783,424.76,399.87,402.64,400.09
179.09388,4.0742,8.0061,0.0,0.0,1.7798,4.8346,424.72,399.76,402.66,400.11
179.09553,4.0059,8.0068,0.0,0.0,1.7768,4.7359,424.67,399.65,402.67,400.13
179.09718,3.9241,8.0007,0.0,0.0,1.7787,4.6285,424.63,399.55,402.69,400.15
179.09883,3.8223,8.0062,0.0,0.0,1.7838,4.5391,424.58,399.44,402.7,400.17
179.10048,3.8554,8.005,0.0,0.0,1.7748,4.6047,424.54,399.34,402.71,400.19
179.10213,3.9968,7.9989,0.0,0.0,1.7773,4.7746,424.49,399.25,402.7,400.21
179.10378,4.0767,8.0038,0.0,0.0,1.7812,4.8514,424.44,399.16,402.7,400.23
179.10543,4.0571,8.0019,0.0,0.0,1.7872,4.7922,424.39,399.07,402.69,400.25
179.10708,3.9235,8.0026,0.0,0.0,1.7803,4.625,424.34,398.98,402.69,400.27
179.10873,3.833,8.0087,0.0,0.0,1.7722,4.5301,424.29,398.89,402.68,400.29
179.11038,3.862,8.003,0.0,0.0,1.7792,4.6051,424.24,398.82,402.69,400.3
179.11203,3.9897,8.006,0.0,0.0,1.7826,4.769,424.2,398.77,402.71,400.3
179.11368,4.0808,8.0042,0.0,0.0,1.7845,4.8461,424.15,398.71,402.73,400.3
179.11533,4.0351,7.9934,0.0,0.0,1.7777,4.7759,424.11,398.66,402.75,400.3
179.11698,3.9316,8.0058,0.0,0.0,1.7733,4.6364,424.06,398.61,402.77,400.3
179.11863,3.8343,8.006,0.0,0.0,1.781,4.5382,424.02,398.55,402.79,400.3
179.12028,3.8783,8.0042,0.0,0.0,1.7832,4.623,423.97,398.5,402.81,400.3
179.12193,3.9911,8.0077,0.0,0.0,1.7813,4.7628,423.92,398.44,402.82,400.29
179.12358,4.0725,8.0072,0.0,0.0,1.7771,4.8354,423.87,398.39,402.84,400.28
179.12523,4.0441,7.999,0.0,0.0,1.7778,4.7791,423.82,398.33,402.85,400.27
179.12688,3.9151,8.0019,0.0,0.0,1.7835,4.6236,423.77,398.28,402.87,400.26
179.12853,3.8346,8.0018,0.0,0.0,1.7792,4.5556,423.72,398.22,402.88,400.25
179.13018,3.8593,8.006,0.0,0.0,1.7788,4.6099,423.67,398.16,402.9,400.25
179.13183,4.0026,8.0082,0.0,0.0,1.777,4.773,423.62,398.08,402.91,400.26
179.13348,4.0757,8.0046,0.0,0.0,1.7848,4.8374,423.58,398.0,402.93,400.27
179.13513,4.0435,8.0086,0.0,0.0,1.7856,4.7764,423.53,397.92,402.94,400.28
179.13678,3.9251,7.9987,0.0,0.0,1.7716,4.6337,423.48,397.84,402.96,400.29
179.13843,3.8293,7.9977,0.0,0.0,1.7777,4.5507,423.43,397.76,402.97,400.3
179.14008,3.8589,8.0056,0.0,0.0,1.7786,4.6048,423.38,397.68,402.98,400.3
179.14173,4.0035,8.0064,0.0,0.0,1.7861,4.7742,423.34,397.61,402.98,400.3
179.14338,4.0754,8.0049,0.0,0.0,1.7828,4.8404,423.3,397.53,402.98,400.3
179.94353,3.8218,8.0092,0.0,0.0,1.7824,4.5365,394.37,373.17,401.47,384.84
180.94353,3.7564,8.0131,0.0,0.0,1.7846,4.4586,371.0,356.75,393.63,373.5
181.94353,3.7128,8.0166,0.0,0.0,1.7866,4.4074,355.88,345.17,382.32,361.83
182.94353,3.6862,8.0202,0.0,0.0,1.7887,4.3748,343.6,335.03,370.28,349.99
183.9247,3.6952,8.0238,0.0,0.0,1.7905,4.3857,333.03,326.05,358.72,338.79
184.9247,3.6996,8.027,0.0,0.0,1.7923,4.3894,323.1,317.26,347.23,327.38
185.9247,3.7155,8.0297,0.0,0.0,1.794,4.4079,313.9,308.97,336.11,316.99
186.9247,3.7265,8.033,0.0,0.0,1.7958,4.4208,305.35,300.91,325.27,307.03
187.9247,3.7375,8.0354,0.0,0.0,1.797,4.4344,297.26,293.23,315.4,297.55
188.9247,3.7517,8.0373,0.0,0.0,1.7979,4.4525,289.66,285.87,305.55,288.58
189.9247,3.7581,8.0393,0.0,0.0,1.7989,4.4604,282.11,278.63,295.94,279.52
190.9247,3.756,8.0404,0.0,0.0,1.7995,4.4581,275.17,271.82,287.22,271.97
191.9247,3.7586,8.0424,0.0,0.0,1.8007,4.4618,268.4,265.25,278.73,263.91
192.9247,3.7564,8.0444,0.0,0.0,1.802,4.459,261.92,258.98,271.26,256.55
193.9247,3.7584,8.0454,0.0,0.0,1.8026,4.4603,255.58,252.8,263.67,249.47
194.9247,3.7678,8.0462,0.0,0.0,1.8031,4.4716,249.56,246.87,256.28,242.52
195.9247,3.7649,8.0477,0.0,0.0,1.8037,4.4673,243.73,241.05,249.44,235.9
196.9247,3.7777,8.0494,0.0,0.0,1.8047,4.4835,238.13,235.69,242.88,229.79
197.9247,3.775,8.0504,0.0,0.0,1.8054,4.4787,232.64,230.29,236.58,223.57
198.9247,3.7815,8.0526,0.0,0.0,1.8067,4.4875,227.42,225.19,230.7,217.91
199.9247,3.7871,8.054,0.0,0.0,1.8075,4.4947,222.43,220.4,224.88,212.54
200.9247,3.7814,8.056,0.0,0.0,1.8083,4.4883,217.45,215.48,219.14,207.0
201.9247,3.7783,8.0581,0.0,0.0,1.8094,4.4843,212.81,210.81,213.74,202.08
202.9247,3.7803,8.0596,0.0,0.0,1.8102,4.4861,208.21,206.36,208.52,197.09
203.9247,3.7829,8.0613,0.0,0.0,1.8112,4.4897,203.71,201.85,203.37,192.4
204.9247,3.7903,8.0634,0.0,0.0,1.8125,4.4979,199.42,197.69,198.56,187.84
205.9247,3.7944,8.0651,0.0,0.0,1.8136,4.5024,195.38,193.62,193.95,183.53
206.9247,3.7895,8.0667,0.0,0.0,1.8146,4.4958,191.36,189.66,189.5,179.15
207.9247,3.7977,8.0683,0.0,0.0,1.8153,4.5061,187.55,185.89,185.32,175.23
208.9247,3.8019,8.07,0.0,0.0,1.8162,4.5121,183.83,182.14,181.2,171.32
209.9247,3.804,8.0721,0.0,0.0,1.8174,4.5149,180.06,178.55,177.12,167.52
210.9247,3.8001,8.0737,0.0,0.0,1.8184,4.5108,176.58,175.11,173.52,163.87
211.9247,3.7988,8.0759,0.0,0.0,1.8197,4.509,173.17,171.77,169.81,160.44
212.7843,3.8012,8.0775,0.0,0.0,1.8205,4.5106,170.3,168.95,166.79,157.55
213.7843,3.8025,8.0792,0.0,0.0,1.8217,4.5111,167.1,165.91,163.25,154.22
214.7843,3.8092,8.0812,0.0,0.0,1.8227,4.5211,163.99,162.74,159.91,151.09
215.7843,3.809,8.0828,0.0,0.0,1.8235,4.52,160.98,159.74,156.69,148.11
216.7843,3.8085,8.0852,0.0,0.0,1.8247,4.5195,158.17,156.78,153.56,145.08
217.7843,3.811,8.087,0.0,0.0,1.8256,4.5239,155.28,153.94,150.44,142.17
218.7843,3.8043,8.0887,0.0,0.0,1.8266,4.5154,152.56,151.13,147.69,139.56
219.7843,3.8034,8.0906,0.0,0.0,1.8276,4.5142,149.83,148.5,144.83,136.89
220.7843,3.8067,8.0924,0.0,0.0,1.8288,4.518,147.2,145.86,142.01,134.23
221.7843,3.8066,8.0944,0.0,0.0,1.83,4.5158,144.67,143.44,139.51,131.75
222.7843,3.8104,8.0959,0.0,0.0,1.831,4.5209,142.21,141.11,136.9,129.35
223.7843,3.812,8.0975,0.0,0.0,1.832,4.5237,139.85,138.61,134.38,126.79
224.7843,3.7061,8.1014,0.0,0.0,1.834,4.3975,139.85,137.69,133.35,130.33
225.7843,3.7143,8.0997,0.0,0.0,1.8329,4.4074,140.42,137.64,133.62,131.72
225.9843,3.7085,8.1008,0.0,0.0,1.8339,4.4013,140.46,137.64,133.62,131.86