File: examples/dan-msc-case-studies/CS4/data/01 raw data/hyde_test_016.csv
Time(sec),Force(kN),Jaw(mm),PowAngle(deg),PTemp,Strain,Stress(MPa),TC1(C),TC2(C),TC3(C),TC4(C)
0.0,1.9657,-10.585,0.0,0.0034682,-0.80438,2.3254,24.671,25.079,24.577,24.692
1.8,1.8803,-0.00030087,0.0,5.2208,-2.1722e-05,2.2316,24.711,25.089,24.646,24.71
3.4303,1.8657,-0.00016487,0.0,10.112,-2.7929e-05,2.2148,24.705,25.117,24.627,24.676
5.2303,1.8383,-0.00049472,0.0,15.512,-6.9955e-05,2.1817,24.703,25.148,24.645,24.683
7.0303,1.8236,-0.00053281,0.0,20.912,-7.8814e-05,2.1644,24.738,25.106,24.62,24.676
8.8303,1.8223,-0.00012608,17.488,26.312,-2.6497e-05,2.1624,24.671,25.067,24.63,24.676
10.6303,1.8513,-0.00028848,34.705,31.712,-4.3921e-05,2.1962,28.888,27.833,25.042,25.643
12.4303,1.8597,-0.0019727,34.625,37.112,-0.00023893,2.2078,35.774,38.141,26.995,30.185
14.2303,1.8556,-0.0032129,34.825,42.512,-0.00037381,2.2029,41.817,39.3,29.71,35.547
16.0303,1.8657,-0.0048616,34.792,47.912,-0.00054531,2.2146,47.62,44.638,33.131,41.107
17.8303,1.8732,-0.0064763,35.493,53.312,-0.00072471,2.2243,53.103,49.879,37.007,46.739
19.6303,1.8836,-0.0083261,35.484,58.712,-0.0009366,2.2345,58.576,55.104,41.232,52.174
21.4303,1.7514,-0.011335,36.215,64.112,-0.0012804,2.0777,63.958,60.317,45.751,57.612
23.2303,1.4554,-0.014554,36.462,69.512,-0.0016262,1.7274,69.35,65.603,50.419,63.091
25.0303,1.4725,-0.017394,36.88,74.912,-0.0019465,1.7465,74.793,70.916,55.281,68.625
26.8303,1.4826,-0.019503,37.074,80.312,-0.0021776,1.7586,80.236,76.4,60.32,74.146
28.6303,1.5053,-0.021862,37.49,85.712,-0.0024566,1.7871,85.577,81.774,65.558,79.724
30.4303,1.5053,-0.024282,37.827,91.112,-0.0027145,1.7859,91.015,87.425,70.903,85.3
32.2303,1.5019,-0.026869,37.849,96.512,-0.0029923,1.7835,96.418,93.046,76.305,90.866
34.0303,1.5123,-0.029418,38.53,101.91,-0.0032719,1.7952,101.78,98.732,81.568,96.492
35.7508,1.508,-0.031189,38.616,107.07,-0.0034849,1.7898,106.89,104.3,86.653,101.96
37.3923,1.5124,-0.034253,38.958,112.0,-0.0037966,1.7956,111.84,109.44,91.461,107.23
39.1923,1.5078,-0.03719,38.852,117.4,-0.0041238,1.7888,117.35,115.28,96.698,112.96
40.9923,1.5059,-0.04094,38.888,122.8,-0.0045333,1.7875,122.76,121.0,102.09,118.72
42.7923,1.5136,-0.042588,39.687,128.2,-0.0047204,1.7965,128.07,126.55,107.51,124.47
44.5923,1.5074,-0.046243,39.61,133.6,-0.0051241,1.7881,133.54,132.32,112.88,130.18
46.3923,1.5148,-0.04935,39.924,139.0,-0.0054868,1.7978,138.97,137.99,118.26,135.94
48.1923,1.5117,-0.051716,40.114,144.4,-0.0057422,1.7931,144.32,143.59,123.69,141.6
49.9923,1.5089,-0.05574,40.139,149.8,-0.0061841,1.7905,149.75,149.23,128.99,147.19
51.7923,1.5077,-0.059454,40.399,155.2,-0.00658,1.7898,155.16,154.99,134.34,152.76
53.5923,1.5159,-0.061579,40.609,160.6,-0.0068196,1.7984,160.5,160.87,139.62,158.38
55.3923,1.5005,-0.066206,40.706,166.0,-0.007329,1.7804,165.93,166.6,145.01,164.09
57.1923,1.2918,-0.07078,40.935,171.4,-0.0078478,1.5329,171.33,172.28,150.42,169.72
58.9923,1.1463,-0.075315,41.198,176.8,-0.0083314,1.3605,176.73,178.09,155.78,175.52
60.7923,1.1599,-0.079571,41.21,182.2,-0.0087966,1.3772,182.09,184.17,160.62,181.31
62.5923,1.1737,-0.082817,41.448,187.6,-0.009169,1.3926,187.56,190.5,165.47,187.18
64.3923,1.1706,-0.08672,41.362,193.0,-0.0095903,1.3899,193.0,196.85,170.61,193.11
66.1923,1.1788,-0.090581,41.489,198.4,-0.0099928,1.4004,198.37,202.77,176.01,199.05
67.7981,1.1813,-0.093107,41.359,203.22,-0.010304,1.4019,203.24,208.17,180.21,204.32
69.5981,1.1669,-0.097877,41.542,208.62,-0.010821,1.3852,208.6,214.06,184.79,210.14
71.3981,1.182,-0.1022,41.95,214.02,-0.011316,1.4033,213.89,220.1,189.62,215.95
73.1981,1.1818,-0.10537,41.501,219.42,-0.011652,1.4024,219.44,226.15,194.64,221.85
74.9981,0.97508,-0.11122,41.739,224.82,-0.012281,1.1572,224.86,232.2,199.42,227.78
76.7981,0.82048,-0.11432,41.803,230.22,-0.012654,0.97382,230.23,238.43,204.14,233.56
78.5981,0.77856,-0.11894,41.357,235.62,-0.013137,0.9234,235.71,244.64,209.25,239.4
80.3981,0.75333,-0.12338,41.734,241.02,-0.013629,0.89451,241.01,250.34,214.4,244.86
82.1981,0.75522,-0.12629,41.799,246.42,-0.01396,0.8975,246.38,256.31,219.67,250.38
83.9981,0.7469,-0.13098,42.23,251.82,-0.01446,0.88622,251.67,262.03,224.94,255.89
85.7981,0.74277,-0.13551,42.077,257.22,-0.014957,0.88201,257.17,267.97,230.25,261.54
87.5981,0.75164,-0.13871,42.028,262.62,-0.015319,0.89221,262.62,273.77,235.67,267.16
89.3981,0.74821,-0.14374,42.525,268.02,-0.015855,0.88787,267.89,279.62,241.06,272.71
91.1981,0.74267,-0.14853,42.146,273.42,-0.016378,0.88205,273.46,285.7,246.34,278.43
92.9981,0.75246,-0.15233,42.397,278.82,-0.016802,0.89246,278.8,291.52,251.87,284.02
94.7981,0.74753,-0.15756,42.409,284.22,-0.017355,0.88768,284.2,297.69,257.37,289.8
96.5981,0.7449,-0.16243,42.378,289.62,-0.017899,0.88462,289.65,303.64,262.9,295.66
98.3981,0.74936,-0.16598,42.294,295.02,-0.018293,0.8891,295.06,310.05,268.53,301.46
100.1981,0.753,-0.17235,42.373,300.42,-0.018983,0.89365,300.46,316.87,274.35,307.27
101.8336,0.75485,-0.17463,42.47,305.32,-0.019209,0.89576,305.29,322.65,279.65,312.41
103.6336,0.75285,-0.18051,42.678,310.72,-0.019852,0.89356,310.6,328.82,289.26,318.18
105.4336,0.75001,-0.18558,42.286,316.12,-0.02041,0.89081,316.26,335.01,305.3,323.99
107.2336,0.75419,-0.18975,41.66,321.52,-0.020862,0.89623,321.79,339.71,319.62,329.16
109.0336,0.75284,-0.19411,41.854,326.92,-0.021336,0.89326,326.91,343.94,328.46,333.64
110.8336,0.74958,-0.19897,42.339,332.32,-0.021867,0.89008,332.23,349.13,334.48,338.28
112.6336,0.75133,-0.20356,42.577,337.72,-0.02237,0.89214,337.61,354.39,339.98,343.47
114.4336,0.75032,-0.20887,43.367,343.12,-0.022945,0.89044,342.87,359.94,345.41,348.75
116.2336,0.74836,-0.21391,43.532,348.52,-0.023499,0.88988,348.29,366.02,351.09,354.51
118.0336,0.74711,-0.21929,43.459,353.92,-0.024087,0.88681,353.9,372.28,356.97,360.44
119.8336,0.75434,-0.22409,43.918,359.32,-0.024566,0.89533,359.17,378.5,362.89,366.29
121.6336,0.75757,-0.22973,43.153,364.72,-0.025232,0.8987,364.89,384.71,368.96,372.29
123.4336,0.75746,-0.23164,42.569,370.12,-0.025429,0.89924,370.31,389.69,374.45,377.51
125.2336,0.75663,-0.23733,42.414,375.52,-0.02603,0.8982,375.75,394.87,379.67,382.61
127.0336,0.75683,-0.24294,43.903,380.92,-0.026648,0.8991,380.52,399.81,384.9,387.73
128.8336,0.75611,-0.24983,44.587,386.32,-0.027388,0.89696,385.97,394.4,390.76,394.14
130.6336,0.75379,-0.25552,43.25,391.72,-0.028015,0.89509,392.0,395.91,397.78,401.38
132.4336,0.74863,-0.25937,42.29,397.12,-0.028427,0.88907,397.63,397.64,404.08,407.29
134.0084,0.7301,-0.2615,37.314,400.0,-0.028656,0.86636,401.92,398.95,408.51,411.22
135.8084,0.70597,-0.2561,27.046,400.0,-0.028073,0.83869,402.58,391.37,409.34,409.87
137.6084,0.71678,-0.25549,34.354,400.0,-0.028021,0.85077,399.76,382.03,403.75,402.46
139.4084,0.75741,-0.26004,43.102,400.0,-0.028496,0.89896,397.71,381.59,399.81,399.57
141.2084,0.76461,-0.26712,42.992,400.0,-0.029283,0.90749,399.05,387.7,401.85,403.89
143.0084,0.74382,-0.26975,35.162,400.0,-0.029549,0.88284,401.57,390.53,406.1,408.58
144.8084,0.71737,-0.26686,30.202,400.0,-0.029222,0.85182,401.57,389.32,406.23,406.77
146.6084,0.91422,-0.26564,36.886,400.0,-0.029104,1.0853,399.36,382.98,402.43,401.74
148.4084,1.1527,-0.26875,44.107,400.0,-0.029432,1.3682,397.68,386.6,400.54,400.87
150.2084,1.1881,-0.27427,44.059,400.0,-0.030028,1.4109,399.06,394.16,404.11,406.6
152.0084,1.1817,-0.27506,36.187,400.0,-0.030115,1.4025,401.77,398.9,409.51,412.08
153.8084,1.1689,-0.27183,29.806,400.0,-0.029761,1.3868,401.91,397.05,410.23,410.49
155.6084,1.2261,-0.27555,45.807,400.0,-0.030161,1.4547,396.7,395.02,407.16,406.71
157.4084,1.2614,-0.29234,51.95,400.0,-0.032018,1.497,396.41,413.7,412.26,415.68
159.2084,1.2798,-0.30631,47.407,400.0,-0.033492,1.519,400.5,437.27,427.16,434.13
161.0084,1.3589,-0.318,49.941,400.0,-0.034689,1.6123,400.12,452.12,443.97,450.95
162.8084,1.6375,-0.30559,27.455,400.0,-0.033415,1.9437,406.41,462.96,460.19,464.64
164.6084,1.7917,-0.28928,13.194,400.0,-0.031647,2.1272,403.62,438.91,458.96,456.66
166.211,1.8182,-0.28995,33.228,400.0,-0.031732,2.158,399.53,426.7,449.48,444.87
168.011,1.8659,-0.29738,44.033,400.0,-0.032532,2.2135,397.06,429.74,443.23,440.44
169.811,2.0666,-0.30295,44.436,400.0,-0.033139,2.4529,398.64,437.58,445.08,446.16
171.611,2.0867,-0.3037,38.01,400.0,-0.03322,2.4766,401.03,440.83,449.92,451.13
173.411,2.08,-0.30365,35.498,400.0,-0.033207,2.4684,400.97,438.64,450.8,449.94
175.211,2.1016,-0.30614,38.054,400.0,-0.033476,2.4948,399.87,434.83,448.77,447.02
177.011,1.8884,-0.31264,39.954,400.0,-0.034182,2.2409,399.52,436.84,447.47,446.41
178.6147,1.5573,0.016887,0.0,67.883,0.0025892,1.8544,400.24,438.13,447.88,447.74
178.6156,1.6189,0.02574,0.0,5.9558e-10,0.0025246,1.9213,400.26,438.14,447.89,447.77
178.6165,1.5317,0.032411,0.0,3.1753e-22,0.0038204,1.8138,400.29,438.15,447.89,447.81
178.6174,1.5579,0.03026,0.0,1.6928e-34,0.0037645,1.8478,400.32,438.16,447.89,447.84
178.6183,1.5126,0.025112,0.0,0.0,0.0034392,1.8148,400.34,438.17,447.89,447.87
178.6192,1.556,0.024126,0.0,0.0,0.0032219,1.8317,400.37,438.18,447.9,447.9
178.6201,1.5138,0.022531,0.0,0.0,0.0029842,1.8239,400.39,438.18,447.9,447.92
178.621,1.5439,0.023081,0.0,0.0,0.0028238,1.8238,400.37,438.16,447.89,447.89
178.6219,1.5257,0.022143,0.0,0.0,0.0026647,1.8187,400.36,438.14,447.89,447.86
178.6228,1.5246,0.023779,0.0,0.0,0.0022915,1.8148,400.34,438.11,447.88,447.83
178.6237,1.5503,0.026754,0.0,0.0,0.0024916,1.8277,400.32,438.09,447.88,447.79
178.6246,1.517,0.026109,0.0,0.0,0.002454,1.8006,400.31,438.06,447.87,447.76
178.6255,1.5585,0.02549,0.0,0.0,0.0025298,1.8559,400.29,438.04,447.87,447.73
178.6264,1.5166,0.02522,0.0,0.0,0.0028693,1.7944,400.27,438.01,447.86,447.7
178.6273,1.551,0.021276,0.0,0.0,0.0028788,1.8398,400.26,437.99,447.85,447.66
178.6282,1.5102,0.019951,0.0,0.0,0.0028121,1.7846,400.24,437.97,447.85,447.63
178.6291,1.5385,0.015176,0.0,0.0,0.0026976,1.8379,400.23,437.94,447.84,447.6
178.63,1.5126,0.015158,0.0,0.0,0.0025403,1.8106,400.21,437.92,447.84,447.57
178.6309,1.5425,0.014205,0.0,0.0,0.0021793,1.8157,400.21,437.93,447.86,447.58
178.6318,1.5392,0.013419,0.0,0.0,0.0021434,1.8318,400.21,437.94,447.87,447.59
178.6327,1.5179,0.01458,0.0,0.0,0.0019005,1.8077,400.2,437.95,447.89,447.6
178.6336,1.5324,0.016294,0.0,0.0,0.0016075,1.8266,400.2,437.95,447.91,447.61
178.6345,1.5167,0.018829,0.0,0.0,0.0015234,1.7977,400.2,437.96,447.92,447.63
178.6354,1.5574,0.023067,0.0,0.0,0.0017416,1.8389,400.19,437.97,447.94,447.64
178.6363,1.51,0.023683,0.0,0.0,0.001777,1.7837,400.19,437.98,447.95,447.65
178.6372,1.5455,0.027225,0.0,0.0,0.001974,1.8469,400.19,437.99,447.97,447.66
178.6381,1.5114,0.028949,0.0,0.0,0.0023322,1.8006,400.19,437.99,447.99,447.67
178.639,1.5378,0.029044,0.0,0.0,0.0024722,1.8247,400.18,438.0,448.0,447.68
178.6399,1.5175,0.029401,0.0,0.0,0.0027847,1.7947,400.18,438.01,448.02,447.69
178.6408,1.5255,0.028353,0.0,0.0,0.0032382,1.8209,400.19,438.02,448.02,447.7
178.6417,1.5121,0.026387,0.0,0.0,0.0033029,1.8026,400.2,438.03,448.03,447.71
178.6426,1.5235,0.024969,0.0,0.0,0.0033515,1.8067,400.21,438.04,448.04,447.72
178.6435,1.5575,0.02429,0.0,0.0,0.0033719,1.8418,400.21,438.05,448.04,447.73
178.6444,1.5178,0.022565,0.0,0.0,0.0030393,1.8077,400.22,438.06,448.05,447.74
178.6453,1.545,0.023077,0.0,0.0,0.0029084,1.8347,400.23,438.07,448.05,447.75
178.6462,1.5038,0.021501,0.0,0.0,0.0027284,1.7846,400.24,438.09,448.06,447.77
178.6471,1.5377,0.022682,0.0,0.0,0.0025384,1.8248,400.25,438.1,448.06,447.78
178.648,1.5106,0.026587,0.0,0.0,0.0023583,1.7927,400.25,438.11,448.07,447.79
178.6489,1.5358,0.025287,0.0,0.0,0.0023964,1.8086,400.26,438.12,448.07,447.8
178.6498,1.5114,0.025232,0.0,0.0,0.0022815,1.8006,400.27,438.13,448.08,447.81
178.6507,1.5293,0.025713,0.0,0.0,0.002662,1.7996,400.27,438.13,448.07,447.8
178.6516,1.5242,0.023127,0.0,0.0,0.0026725,1.8017,400.28,438.13,448.07,447.79
178.6525,1.5049,0.019059,0.0,0.0,0.0026599,1.7935,400.28,438.13,448.06,447.78
178.6534,1.5243,0.019338,0.0,0.0,0.0028615,1.8045,400.28,438.13,448.06,447.77
178.6543,1.4983,0.015287,0.0,0.0,0.0027375,1.7907,400.28,438.13,448.05,447.76
178.6552,1.5322,0.014437,0.0,0.0,0.0025289,1.8327,400.29,438.13,448.05,447.75
178.6561,1.5036,0.014242,0.0,0.0,0.0022659,1.7835,400.29,438.13,448.04,447.74
178.657,1.5379,0.01382,0.0,0.0,0.0018502,1.8317,400.29,438.13,448.04,447.72
178.6579,1.4978,0.015078,0.0,0.0,0.001729,1.7766,400.3,438.13,448.03,447.71
178.6588,1.5177,0.017675,0.0,0.0,0.0016849,1.8025,400.3,438.13,448.03,447.7
178.6597,1.4987,0.020352,0.0,0.0,0.0017425,1.7927,400.3,438.13,448.02,447.69
178.6606,1.5238,0.021469,0.0,0.0,0.0015497,1.8077,400.3,438.19,448.01,447.69
178.6615,1.5175,0.026572,0.0,0.0,0.001929,1.8025,400.31,438.26,448.0,447.68
178.6624,1.4991,0.028748,0.0,0.0,0.0021255,1.7995,400.31,438.33,448.0,447.67
178.6633,1.5312,0.030436,0.0,0.0,0.0025034,1.8167,400.31,438.41,447.99,447.67
178.6642,1.5036,0.029224,0.0,0.0,0.0026239,1.7835,400.31,438.48,447.98,447.66
178.6651,1.5331,0.028932,0.0,0.0,0.0030006,1.8337,400.32,438.55,447.97,447.66
178.666,1.4971,0.027126,0.0,0.0,0.0032942,1.7765,400.32,438.62,447.96,447.65
178.6669,1.5319,0.025601,0.0,0.0,0.0032361,1.8317,400.32,438.7,447.96,447.65
178.6678,1.5033,0.02436,0.0,0.0,0.0033624,1.7766,400.33,438.77,447.95,447.64
178.6687,1.5185,0.023398,0.0,0.0,0.0031347,1.8106,400.33,438.84,447.94,447.64
178.6696,1.538,0.022415,0.0,0.0,0.0029075,1.8248,400.33,438.92,447.93,447.63
178.6705,1.5182,0.025157,0.0,0.0,0.0029864,1.8043,401.85,440.1,447.9,447.63
178.6714,1.94,0.024085,0.0,0.0,0.0026348,2.3208,404.11,441.84,447.85,447.63
178.6723,1.4596,0.027682,0.0,0.0,0.0027233,1.7376,406.38,443.59,447.81,447.63
178.6732,1.5126,0.024267,0.0,0.0,0.0020501,1.7985,408.65,445.33,447.76,447.63
178.6741,1.4082,0.027748,0.0,0.0,0.0026786,1.6702,410.92,447.07,447.72,447.63
178.675,1.5571,0.024759,0.0,0.0,0.0025531,1.8438,413.19,448.82,447.67,447.63
178.6759,1.4237,0.024737,0.0,0.0,0.0028763,1.6972,415.46,450.56,447.62,447.63
178.6768,1.3556,0.020958,0.0,0.0,0.0025537,1.6078,417.73,452.3,447.58,447.63
178.6777,1.4216,0.014637,0.0,0.0,0.0023349,1.6802,420.0,454.04,447.53,447.63
178.6786,1.436,0.015817,0.0,0.0,0.0026117,1.7012,422.27,455.79,447.49,447.63
178.6795,1.5641,0.0082427,0.0,0.0,0.0018197,1.8557,424.54,457.53,447.44,447.63
178.6804,1.5512,0.011229,0.0,0.0,0.0019311,1.8435,427.42,459.81,447.42,447.61
178.6813,1.5219,0.0085268,0.0,0.0,0.001368,1.8385,430.78,462.51,447.43,447.59
178.6822,1.4114,0.0083161,0.0,0.0,0.0011358,1.6941,434.13,465.21,447.44,447.56
178.6831,1.5108,0.012379,0.0,0.0,0.0011757,1.7876,437.49,467.92,447.45,447.53
178.684,2.984,0.018357,0.0,0.0,0.0011829,3.2265,440.85,470.62,447.46,447.51
178.6849,59.106,0.35444,0.0,0.0,0.038744,68.132,444.21,473.33,447.47,447.48
178.6858,69.581,0.75732,0.0,0.0,0.084678,82.744,447.56,476.03,447.47,447.45
178.6867,73.634,1.146,0.0,0.0,0.13193,86.847,450.92,478.74,447.48,447.43
178.6876,75.914,1.7371,0.0,0.0,0.20812,90.241,454.28,481.44,447.49,447.4
178.6885,77.235,2.222,0.0,0.0,0.27575,91.44,457.64,484.14,447.5,447.37
178.6894,78.415,2.715,0.0,0.0,0.34785,93.189,460.99,486.85,447.51,447.35
178.6903,79.621,3.233,0.0,0.0,0.43069,94.269,463.11,488.53,447.54,447.33
178.6912,80.241,3.8306,0.0,0.0,0.53229,95.29,463.67,488.95,447.6,447.31
178.6921,81.624,4.3369,0.0,0.0,0.62778,96.789,464.23,489.36,447.67,447.3
178.693,82.214,4.8788,0.0,0.0,0.73787,97.557,464.79,489.77,447.73,447.29
178.6939,82.899,5.3513,0.0,0.0,0.84399,98.341,465.35,490.18,447.8,447.28
178.6948,83.392,5.8342,0.0,0.0,0.96254,98.98,465.91,490.59,447.86,447.27
178.6957,84.2,6.2552,0.0,0.0,1.0782,99.879,466.47,491.0,447.93,447.26
178.6966,84.51,6.668,0.0,0.0,1.2039,100.26,467.03,491.41,447.99,447.25
178.6975,84.822,7.0325,0.0,0.0,1.3267,100.63,467.59,491.82,448.06,447.24
178.6984,85.065,7.3174,0.0,0.0,1.4358,100.93,468.15,492.24,448.12,447.23
178.6993,85.336,7.5868,0.0,0.0,1.5494,101.26,468.71,492.65,448.19,447.22
178.7002,85.503,7.8026,0.0,0.0,1.6518,101.44,468.59,492.47,448.23,447.22
178.7011,86.084,7.9941,0.0,0.0,1.7511,102.16,467.11,491.1,448.23,447.23
178.702,87.068,8.1434,0.0,0.0,1.837,103.27,465.62,489.73,448.23,447.25
178.7029,89.061,8.3045,0.0,0.0,1.9339,105.61,464.14,488.36,448.23,447.26
178.7038,91.502,8.4431,0.0,0.0,2.0262,108.47,462.65,486.99,448.23,447.28
178.7047,94.714,8.579,0.0,0.0,2.1222,112.3,461.17,485.62,448.23,447.3
178.7056,84.446,8.6735,0.0,0.0,2.1923,100.31,459.69,484.26,448.23,447.31
178.7065,79.595,8.692,0.0,0.0,2.2074,94.656,458.2,482.89,448.23,447.33
178.7074,77.279,8.7156,0.0,0.0,2.2185,91.877,456.72,481.52,448.23,447.35
178.7083,75.165,8.7215,0.0,0.0,2.2202,89.275,455.23,480.15,448.23,447.36
178.7092,73.903,8.7537,0.0,0.0,2.2405,87.76,453.75,478.78,448.23,447.38
178.7101,72.538,8.7515,0.0,0.0,2.2357,86.088,452.22,477.45,448.23,447.39
178.711,71.404,8.7724,0.0,0.0,2.2528,84.766,450.51,476.21,448.22,447.4
178.7119,70.022,8.7701,0.0,0.0,2.2517,83.129,448.8,474.98,448.21,447.41
178.7128,68.602,8.784,0.0,0.0,2.2674,81.456,447.1,473.75,448.2,447.42
178.7137,67.446,8.789,0.0,0.0,2.2747,80.097,445.39,472.52,448.19,447.44
178.7146,66.451,8.784,0.0,0.0,2.2768,78.883,443.68,471.29,448.19,447.45
178.7155,65.425,8.7869,0.0,0.0,2.2829,77.674,441.97,470.05,448.18,447.46
178.7164,64.915,8.7794,0.0,0.0,2.279,77.074,440.27,468.82,448.17,447.47
178.7173,64.228,8.7821,0.0,0.0,2.2835,76.237,438.56,467.59,448.16,447.48
178.7182,63.518,8.7779,0.0,0.0,2.2783,75.398,436.85,466.36,448.15,447.49
178.7191,63.028,8.7828,0.0,0.0,2.2795,74.806,435.15,465.13,448.15,447.5
178.72,62.283,8.793,0.0,0.0,2.2848,73.927,433.47,463.94,448.14,447.51
178.7209,61.858,8.7837,0.0,0.0,2.2725,73.428,432.08,463.13,448.12,447.5
178.7218,61.361,8.7952,0.0,0.0,2.2767,72.819,430.68,462.33,448.1,447.5
178.7227,60.95,8.7997,0.0,0.0,2.2793,72.358,429.28,461.52,448.08,447.49
178.7236,60.475,8.803,0.0,0.0,2.2827,71.785,427.89,460.71,448.06,447.49
178.7245,60.102,8.8034,0.0,0.0,2.2857,71.339,426.49,459.9,448.04,447.48
178.7254,59.67,8.8028,0.0,0.0,2.291,70.834,425.09,459.09,448.02,447.48
178.7263,59.356,8.7983,0.0,0.0,2.2922,70.458,423.7,458.29,448.0,447.47
178.7272,59.006,8.7927,0.0,0.0,2.2901,70.054,422.3,457.48,447.99,447.47
178.7281,58.713,8.7968,0.0,0.0,2.2977,69.69,420.9,456.67,447.97,447.46
178.729,58.388,8.7907,0.0,0.0,2.2921,69.306,419.51,455.86,447.95,447.46
178.7299,58.063,8.7836,0.0,0.0,2.2851,68.925,418.11,455.06,447.93,447.45
178.7308,57.846,8.7885,0.0,0.0,2.2856,68.654,416.92,454.46,447.93,447.47
178.7317,57.497,8.7895,0.0,0.0,2.283,68.213,415.73,453.87,447.93,447.48
178.7326,57.289,8.7932,0.0,0.0,2.2814,67.985,414.54,453.28,447.94,447.5
178.7335,56.983,8.7998,0.0,0.0,2.2807,67.616,413.36,452.68,447.94,447.51
178.7344,56.812,8.8054,0.0,0.0,2.2818,67.4,412.17,452.09,447.94,447.53
178.7353,56.511,8.8042,0.0,0.0,2.2791,67.076,410.98,451.5,447.95,447.55
178.7362,56.333,8.8142,0.0,0.0,2.2877,66.85,409.79,450.91,447.95,447.56
178.7371,56.104,8.8183,0.0,0.0,2.2931,66.589,408.6,450.31,447.95,447.58
178.738,55.907,8.8115,0.0,0.0,2.293,66.353,407.41,449.72,447.95,447.6
178.7389,55.737,8.813,0.0,0.0,2.299,66.146,406.23,449.13,447.96,447.61
178.7398,55.52,8.8107,0.0,0.0,2.3024,65.885,405.04,448.53,447.96,447.63
178.7407,55.378,8.8035,0.0,0.0,2.2999,65.72,404.07,448.12,447.97,447.64
178.7416,55.141,8.8037,0.0,0.0,2.3019,65.437,403.13,447.74,447.98,447.66
178.7425,55.02,8.8052,0.0,0.0,2.3024,65.3,402.2,447.35,448.0,447.68
178.7434,54.776,8.7987,0.0,0.0,2.2951,65.003,401.26,446.96,448.01,447.69
178.7443,54.673,8.8011,0.0,0.0,2.2929,64.873,400.32,446.57,448.03,447.71
178.7452,54.465,8.8043,0.0,0.0,2.2924,64.642,399.38,446.18,448.04,447.73
178.7461,54.333,8.811,0.0,0.0,2.2913,64.462,398.44,445.79,448.05,447.74
178.747,54.132,8.8114,0.0,0.0,2.2894,64.242,397.51,445.41,448.07,447.76
178.7479,53.969,8.8144,0.0,0.0,2.2914,64.038,396.57,445.02,448.08,447.77
178.7488,53.709,8.8154,0.0,0.0,2.2933,63.759,395.63,444.63,448.09,447.79
178.7497,53.2,8.8125,0.0,0.0,2.2967,63.151,394.69,444.24,448.11,447.81
178.7506,52.519,8.8087,0.0,0.0,2.2975,62.359,394.16,444.14,448.12,447.81
178.7515,51.571,8.8057,0.0,0.0,2.3005,61.237,393.75,444.12,448.14,447.8
178.7524,50.473,8.7972,0.0,0.0,2.2964,59.923,393.33,444.1,448.15,447.79
178.7533,48.947,8.7906,0.0,0.0,2.2925,58.15,392.92,444.07,448.17,447.79
178.7542,47.236,8.7898,0.0,0.0,2.2906,56.125,392.5,444.05,448.19,447.78
178.7551,44.771,8.7812,0.0,0.0,2.282,53.23,392.09,444.03,448.2,447.78
178.756,42.301,8.7799,0.0,0.0,2.2779,50.284,391.67,444.01,448.22,447.77
178.7569,27.852,8.746,0.0,0.0,2.2454,34.139,391.26,443.99,448.23,447.77
178.7578,-2.5195,8.6635,0.0,0.0,2.1749,-3.0399,390.84,443.97,448.25,447.76
178.7587,1.2312,8.4939,0.0,0.0,2.05,1.3202,390.42,443.95,448.27,447.76
178.7596,-1.3338,8.4777,0.0,0.0,2.0352,-1.4107,390.01,443.92,448.28,447.75
178.7605,0.80901,8.4008,0.0,0.0,1.9832,0.85492,389.88,444.04,448.31,447.74
178.7614,-0.86238,8.3991,0.0,0.0,1.9804,-1.0049,389.89,444.23,448.35,447.72
178.7623,0.27306,8.3852,0.0,0.0,1.9768,0.26479,389.91,444.42,448.39,447.7
178.7632,-0.60462,8.4603,0.0,0.0,2.0277,-0.69373,389.92,444.61,448.43,447.68
178.7641,0.27886,8.4986,0.0,0.0,2.0566,0.37194,389.93,444.8,448.46,447.66
178.765,-0.13912,8.6042,0.0,0.0,2.1373,-0.17419,389.95,444.99,448.5,447.64
178.7659,0.76452,8.7243,0.0,0.0,2.2307,0.6658,389.96,445.17,448.54,447.62
178.7668,5.3527,8.7171,0.0,0.0,2.2314,6.8946,389.98,445.36,448.58,447.6
178.7677,-2.7276,8.713,0.0,0.0,2.2259,-3.1197,389.99,445.55,448.62,447.59
178.7686,0.76636,8.6836,0.0,0.0,2.1955,0.85113,390.0,445.74,448.65,447.57
178.7695,3.0818,8.7432,0.0,0.0,2.2422,3.4739,390.02,445.93,448.69,447.55
178.7704,1.3737,8.7014,0.0,0.0,2.2039,1.5668,390.04,446.1,448.7,447.52
178.7713,0.080993,8.7412,0.0,0.0,2.2323,0.028047,390.07,446.26,448.68,447.49
178.7722,2.0315,8.724,0.0,0.0,2.2155,2.3397,390.11,446.43,448.66,447.46
178.7731,0.97483,8.7336,0.0,0.0,2.2267,1.181,390.14,446.59,448.64,447.42
178.774,0.79282,8.735,0.0,0.0,2.2289,0.90342,390.17,446.75,448.62,447.39
178.7749,1.6157,8.7193,0.0,0.0,2.2221,1.8635,390.2,446.91,448.6,447.36
178.7758,1.0331,8.737,0.0,0.0,2.241,1.3103,390.24,447.07,448.58,447.33
178.7767,0.70508,8.6998,0.0,0.0,2.2137,0.84302,390.27,447.23,448.57,447.3
178.7776,1.4969,8.7232,0.0,0.0,2.2362,1.7753,390.3,447.4,448.55,447.26
178.7785,1.1259,8.7008,0.0,0.0,2.2183,1.3395,390.33,447.56,448.53,447.23
178.7794,0.91588,8.7011,0.0,0.0,2.2193,1.0573,390.37,447.72,448.51,447.2
178.7803,1.3506,8.7148,0.0,0.0,2.2245,1.6196,390.39,447.87,448.46,447.19
178.7812,1.0402,8.6957,0.0,0.0,2.2059,1.2498,390.4,448.0,448.38,447.22
178.7821,1.1036,8.7153,0.0,0.0,2.2152,1.3133,390.41,448.13,448.29,447.24
178.783,1.2185,8.7126,0.0,0.0,2.2073,1.4389,390.42,448.26,448.21,447.26
178.7839,1.0889,8.7233,0.0,0.0,2.215,1.2833,390.43,448.38,448.13,447.29
178.7848,1.0642,8.7279,0.0,0.0,2.2145,1.2651,390.44,448.51,448.04,447.31
178.7857,1.2064,8.7253,0.0,0.0,2.2162,1.4338,390.45,448.64,447.96,447.34
178.7866,1.0728,8.737,0.0,0.0,2.2265,1.2873,390.47,448.77,447.88,447.36
178.7875,1.1219,8.7307,0.0,0.0,2.2253,1.3162,390.48,448.9,447.79,447.39
178.7884,1.2187,8.7312,0.0,0.0,2.2326,1.4378,390.49,449.03,447.71,447.41
178.7893,0.99623,8.7232,0.0,0.0,2.2303,1.1879,390.5,449.16,447.63,447.43
178.7902,1.2752,8.7207,0.0,0.0,2.2316,1.5292,390.51,449.29,447.56,447.46
178.7911,1.0222,8.723,0.0,0.0,2.2334,1.2077,390.53,449.42,447.55,447.48
178.792,1.2489,8.7152,0.0,0.0,2.2272,1.4962,390.55,449.55,447.53,447.5
178.7929,1.1025,8.7185,0.0,0.0,2.2264,1.2992,390.57,449.68,447.52,447.52
178.7938,1.1645,8.7162,0.0,0.0,2.2204,1.3714,390.59,449.81,447.5,447.54
178.7947,1.1437,8.7164,0.0,0.0,2.2186,1.3424,390.61,449.94,447.48,447.57
178.7956,1.1727,8.727,0.0,0.0,2.2201,1.3987,390.63,450.07,447.47,447.59
178.7965,1.1398,8.7237,0.0,0.0,2.217,1.3686,390.64,450.2,447.45,447.61
178.7974,1.1833,8.7291,0.0,0.0,2.2214,1.3998,390.66,450.32,447.44,447.63
178.7983,1.1337,8.728,0.0,0.0,2.2224,1.3546,390.68,450.45,447.42,447.65
178.7992,1.1697,8.7236,0.0,0.0,2.2249,1.3756,390.7,450.58,447.4,447.67
178.8001,1.1606,8.7227,0.0,0.0,2.2267,1.3906,390.72,450.71,447.4,447.68
178.801,1.1117,8.7197,0.0,0.0,2.2281,1.3322,390.72,450.82,447.44,447.66
178.8019,1.2995,8.7175,0.0,0.0,2.2305,1.5283,390.73,450.92,447.49,447.64
178.8028,1.0561,8.7086,0.0,0.0,2.2252,1.254,390.73,451.03,447.53,447.62
178.8037,1.3178,8.7057,0.0,0.0,2.223,1.5403,390.74,451.14,447.57,447.6
178.8046,1.0657,8.7082,0.0,0.0,2.2212,1.2761,390.74,451.25,447.62,447.58
178.8055,1.2865,8.7074,0.0,0.0,2.2166,1.5274,390.75,451.35,447.66,447.56
178.8064,1.1408,8.711,0.0,0.0,2.2131,1.3665,390.76,451.46,447.7,447.53
178.8073,1.23,8.7141,0.0,0.0,2.2122,1.4469,390.76,451.57,447.74,447.51
178.8082,1.2076,8.718,0.0,0.0,2.2114,1.444,390.77,451.68,447.79,447.49
178.8091,1.1763,8.723,0.0,0.0,2.2132,1.3776,390.77,451.79,447.83,447.47
178.81,1.2544,8.7274,0.0,0.0,2.2155,1.487,390.78,451.89,447.87,447.45
178.8109,1.1097,8.7285,0.0,0.0,2.2196,1.3135,390.8,451.97,447.89,447.46
178.8118,1.2487,8.7275,0.0,0.0,2.2224,1.5043,390.83,452.05,447.91,447.47
178.8127,1.177,8.7265,0.0,0.0,2.224,1.3885,390.85,452.13,447.94,447.48
178.8136,1.2137,8.7258,0.0,0.0,2.2292,1.4499,390.88,452.21,447.96,447.49
178.8145,1.211,8.7204,0.0,0.0,2.2295,1.4287,390.9,452.29,447.98,447.51
178.8154,1.1923,8.7177,0.0,0.0,2.23,1.4177,390.93,452.38,448.0,447.52
178.8163,1.2257,8.7137,0.0,0.0,2.2257,1.4529,390.95,452.46,448.02,447.53
178.8172,1.2117,8.7134,0.0,0.0,2.2243,1.4288,390.97,452.54,448.04,447.54
178.8181,1.2219,8.7137,0.0,0.0,2.2222,1.465,391.0,452.62,448.07,447.55
178.819,1.1574,8.7151,0.0,0.0,2.2191,1.3796,391.02,452.7,448.09,447.56
178.8199,1.2685,8.722,0.0,0.0,2.2192,1.5141,391.05,452.78,448.11,447.57
178.8208,1.1406,8.7223,0.0,0.0,2.2167,1.3797,391.07,452.84,448.13,447.58
178.8217,1.2329,8.7245,0.0,0.0,2.2179,1.463,391.09,452.9,448.15,447.59
178.8226,1.1681,8.7276,0.0,0.0,2.2198,1.414,391.11,452.96,448.17,447.6
178.8235,1.2189,8.7241,0.0,0.0,2.2228,1.444,391.13,453.02,448.18,447.61
178.8244,1.2271,8.7233,0.0,0.0,2.2266,1.4589,391.16,453.08,448.2,447.62
178.8253,1.2056,8.7163,0.0,0.0,2.2248,1.4359,391.18,453.14,448.22,447.63
178.8262,1.2617,8.7149,0.0,0.0,2.227,1.5062,391.2,453.19,448.24,447.65
178.8271,1.2065,8.7086,0.0,0.0,2.2254,1.4458,391.22,453.25,448.26,447.66
178.828,1.2674,8.705,0.0,0.0,2.2232,1.5052,391.24,453.31,448.28,447.67
178.8289,1.2307,8.7016,0.0,0.0,2.218,1.4458,391.26,453.37,448.3,447.68
178.8298,1.2206,8.7023,0.0,0.0,2.2139,1.458,391.29,453.43,448.32,447.69
178.8307,1.2873,8.7062,0.0,0.0,2.2127,1.5324,391.29,453.5,448.28,447.71
178.8316,1.2346,8.7083,0.0,0.0,2.2093,1.4812,391.29,453.57,448.24,447.73
178.8325,1.2182,8.715,0.0,0.0,2.2097,1.443,391.3,453.63,448.2,447.75
178.8334,1.309,8.7185,0.0,0.0,2.2104,1.5667,391.3,453.7,448.16,447.77
178.8343,1.1515,8.7233,0.0,0.0,2.212,1.3737,391.3,453.77,448.12,447.8
178.8352,1.3479,8.728,0.0,0.0,2.2161,1.5996,391.31,453.84,448.08,447.82
178.8361,1.1646,8.7287,0.0,0.0,2.2209,1.3706,391.31,453.9,448.04,447.84
178.837,1.3136,8.7272,0.0,0.0,2.2247,1.5565,391.31,453.97,448.0,447.86
178.8379,1.2067,8.7242,0.0,0.0,2.2274,1.4399,391.31,454.04,447.96,447.88
178.8388,1.2599,8.721,0.0,0.0,2.2288,1.4983,391.32,454.1,447.92,447.9
178.8397,1.2546,8.7183,0.0,0.0,2.2292,1.4962,391.32,454.17,447.88,447.92
178.8406,1.2187,8.7147,0.0,0.0,2.2279,1.445,391.31,454.25,447.85,447.94
178.8415,1.2878,8.7128,0.0,0.0,2.2243,1.5364,391.29,454.34,447.82,447.94
178.8424,1.2181,8.7123,0.0,0.0,2.2221,1.4328,391.27,454.42,447.79,447.95
178.8433,1.3217,8.7131,0.0,0.0,2.2186,1.5746,391.26,454.5,447.77,447.96
178.8442,1.2868,8.7169,0.0,0.0,2.2168,1.5273,391.24,454.59,447.74,447.97
178.8451,1.2125,8.7223,0.0,0.0,2.2164,1.445,391.23,454.67,447.71,447.98
178.846,1.321,8.7252,0.0,0.0,2.2177,1.5684,391.21,454.75,447.69,447.98
178.8469,1.2201,8.7237,0.0,0.0,2.2174,1.455,391.19,454.84,447.66,447.99
178.8478,1.3397,8.7257,0.0,0.0,2.221,1.5764,391.18,454.92,447.63,448.0
178.8487,1.1445,8.7229,0.0,0.0,2.2242,1.3475,391.16,455.0,447.61,448.01
178.8496,1.3928,8.7169,0.0,0.0,2.2235,1.6346,391.14,455.09,447.58,448.02
178.8505,1.1893,8.7138,0.0,0.0,2.2255,1.4309,391.13,455.16,447.59,448.01
178.8514,1.3452,8.71,0.0,0.0,2.2257,1.5825,391.12,455.22,447.62,448.0
178.8523,1.196,8.7019,0.0,0.0,2.2209,1.4433,391.1,455.28,447.65,447.99
178.8532,1.3458,8.7023,0.0,0.0,2.2187,1.5944,391.09,455.34,447.68,447.98
178.8541,1.1945,8.7021,0.0,0.0,2.2173,1.4228,391.07,455.4,447.71,447.97
178.855,1.367,8.7011,0.0,0.0,2.2107,1.6176,391.06,455.47,447.74,447.96
178.8559,1.2153,8.7058,0.0,0.0,2.2103,1.454,391.05,455.53,447.77,447.95
178.8568,1.3237,8.7137,0.0,0.0,2.2086,1.5453,391.03,455.59,447.8,447.94
178.8577,1.2988,8.7169,0.0,0.0,2.2093,1.5223,391.02,455.65,447.83,447.93
178.8586,1.2518,8.7235,0.0,0.0,2.212,1.479,391.01,455.71,447.86,447.91
178.8595,1.3078,8.726,0.0,0.0,2.2163,1.5484,390.99,455.78,447.89,447.9
178.8604,1.2442,8.729,0.0,0.0,2.2186,1.461,390.98,455.84,447.91,447.9
178.8613,1.3419,8.7305,0.0,0.0,2.2237,1.5945,390.97,455.9,447.94,447.9
178.8622,1.1773,8.723,0.0,0.0,2.2233,1.3887,390.96,455.97,447.97,447.91
178.8631,1.3691,8.7216,0.0,0.0,2.228,1.6317,390.95,456.03,448.0,447.91
178.864,1.1673,8.7204,0.0,0.0,2.2291,1.4068,390.94,456.1,448.02,447.91
178.8649,1.3477,8.7131,0.0,0.0,2.227,1.5986,390.93,456.16,448.05,447.91
178.8658,1.2069,8.7099,0.0,0.0,2.224,1.4331,390.92,456.23,448.08,447.92
178.8667,1.3309,8.7125,0.0,0.0,2.2226,1.5606,390.91,456.29,448.1,447.92
178.8676,1.3313,8.7105,0.0,0.0,2.2192,1.5996,390.89,456.36,448.13,447.92
178.8685,1.1482,8.7118,0.0,0.0,2.2137,1.3496,390.88,456.42,448.16,447.93
178.8694,1.4725,8.7204,0.0,0.0,2.2177,1.7634,390.87,456.49,448.18,447.93
178.8703,1.0898,8.7198,0.0,0.0,2.2129,1.2934,390.86,456.56,448.19,447.92
178.8712,1.5062,8.7238,0.0,0.0,2.2177,1.8103,390.84,456.64,448.16,447.91
178.8721,1.1035,8.7232,0.0,0.0,2.2173,1.2963,390.81,456.72,448.13,447.89
178.873,1.5094,8.724,0.0,0.0,2.2226,1.7832,390.79,456.8,448.11,447.87
178.8739,1.1263,8.7174,0.0,0.0,2.2229,1.3466,390.77,456.88,448.08,447.86
178.8748,1.4742,8.7157,0.0,0.0,2.2248,1.7354,390.75,456.96,448.05,447.84
178.8757,1.175,8.7091,0.0,0.0,2.2246,1.4059,390.73,457.04,448.03,447.83
178.8766,1.3788,8.7056,0.0,0.0,2.2236,1.6246,390.71,457.12,448.0,447.81
178.8775,1.2698,8.7026,0.0,0.0,2.221,1.5203,390.68,457.21,447.97,447.79
178.8784,1.3717,8.7012,0.0,0.0,2.2156,1.6044,390.66,457.29,447.94,447.78
178.8793,1.3551,8.7022,0.0,0.0,2.2129,1.5987,390.64,457.37,447.92,447.76
178.8802,1.2568,8.7044,0.0,0.0,2.2104,1.474,390.62,457.44,447.89,447.75
178.8811,1.404,8.7081,0.0,0.0,2.208,1.675,390.59,457.5,447.87,447.74
178.882,1.1728,8.7125,0.0,0.0,2.207,1.3988,390.56,457.57,447.86,447.74
178.8829,1.4907,8.7198,0.0,0.0,2.2107,1.7754,390.54,457.63,447.84,447.73
178.8838,1.2009,8.722,0.0,0.0,2.2113,1.4391,390.51,457.69,447.82,447.73
178.8847,1.4418,8.7272,0.0,0.0,2.2159,1.7089,390.48,457.75,447.8,447.72
178.8856,1.2344,8.7243,0.0,0.0,2.2184,1.468,390.45,457.81,447.78,447.72
178.8865,1.3804,8.7235,0.0,0.0,2.2219,1.6339,390.43,457.88,447.76,447.71
178.8874,1.357,8.7212,0.0,0.0,2.2261,1.6157,390.4,457.94,447.74,447.7
178.8883,1.265,8.7173,0.0,0.0,2.2269,1.4953,390.37,458.0,447.72,447.7
178.8892,1.4519,8.711,0.0,0.0,2.2256,1.7384,390.35,458.06,447.7,447.69
178.8901,1.2118,8.7109,0.0,0.0,2.2255,1.4341,390.31,458.12,447.7,447.69
178.891,1.4789,8.7105,0.0,0.0,2.2223,1.7704,390.27,458.16,447.72,447.7
178.8919,1.2454,8.7082,0.0,0.0,2.2177,1.464,390.23,458.2,447.74,447.71
178.8928,1.4628,8.7129,0.0,0.0,2.2174,1.7344,390.19,458.24,447.77,447.72
178.8937,1.2344,8.7115,0.0,0.0,2.2118,1.4732,390.15,458.28,447.79,447.74
178.8946,1.435,8.7198,0.0,0.0,2.2138,1.7062,390.11,458.32,447.82,447.75
178.8955,1.2688,8.7221,0.0,0.0,2.2152,1.5155,390.07,458.36,447.84,447.76
178.8964,1.4079,8.7183,0.0,0.0,2.213,1.6739,390.03,458.4,447.86,447.77
178.8973,1.318,8.7236,0.0,0.0,2.2209,1.5895,389.99,458.44,447.89,447.78
178.8982,1.3111,8.7191,0.0,0.0,2.2211,1.5383,389.95,458.48,447.91,447.79
178.8991,1.4242,8.7124,0.0,0.0,2.2217,1.694,389.91,458.52,447.94,447.8
178.9,1.2387,8.7087,0.0,0.0,2.2231,1.4672,389.87,458.56,447.96,447.81
178.9009,1.4776,8.7061,0.0,0.0,2.2226,1.7613,389.83,458.61,447.97,447.82
178.9018,1.2068,8.7015,0.0,0.0,2.2186,1.446,389.79,458.66,447.97,447.83
178.9027,1.4699,8.7008,0.0,0.0,2.2176,1.7503,389.75,458.7,447.98,447.84
178.9036,1.2216,8.6966,0.0,0.0,2.2124,1.4651,389.72,458.75,447.98,447.85
178.9045,1.4494,8.7001,0.0,0.0,2.2089,1.7241,389.68,458.79,447.99,447.86
178.9054,1.2692,8.7055,0.0,0.0,2.2084,1.5183,389.64,458.84,447.99,447.88
178.9063,1.3811,8.7106,0.0,0.0,2.2068,1.6427,389.6,458.88,448.0,447.89
178.9072,1.3226,8.7115,0.0,0.0,2.2051,1.5736,389.56,458.93,448.0,447.9
178.9081,1.3121,8.7188,0.0,0.0,2.2093,1.5534,389.53,458.98,448.01,447.91
178.909,1.3789,8.7242,0.0,0.0,2.2132,1.6618,389.49,459.02,448.01,447.92
178.9099,1.2381,8.7225,0.0,0.0,2.2159,1.4591,389.45,459.07,448.02,447.93
178.9108,1.4573,8.723,0.0,0.0,2.2186,1.7382,389.42,459.1,448.01,447.92
178.9117,1.179,8.7223,0.0,0.0,2.2236,1.3998,389.39,459.14,447.99,447.92
178.9126,1.4434,8.717,0.0,0.0,2.2245,1.7201,389.36,459.18,447.98,447.91
178.9135,1.176,8.7145,0.0,0.0,2.2264,1.432,389.33,459.22,447.97,447.91
178.9144,1.4206,8.7107,0.0,0.0,2.2241,1.6698,389.3,459.26,447.95,447.9
178.9153,1.2345,8.7076,0.0,0.0,2.2216,1.469,389.27,459.29,447.94,447.9
178.9162,1.367,8.7095,0.0,0.0,2.2207,1.6177,389.24,459.33,447.92,447.89
178.9171,1.2942,8.7079,0.0,0.0,2.2152,1.5273,389.21,459.37,447.91,447.89
178.918,1.2864,8.7095,0.0,0.0,2.213,1.5283,389.18,459.41,447.9,447.88
178.9189,1.364,8.7177,0.0,0.0,2.2128,1.6297,389.15,459.44,447.88,447.88
178.9198,1.2059,8.7182,0.0,0.0,2.2116,1.4419,389.12,459.48,447.87,447.87
178.9207,1.4104,8.7182,0.0,0.0,2.212,1.683,389.09,459.51,447.85,447.88
178.9216,1.1781,8.7195,0.0,0.0,2.2158,1.3987,389.06,459.53,447.82,447.89
178.9225,1.4299,8.7174,0.0,0.0,2.2201,1.7081,389.03,459.55,447.79,447.91
178.9234,1.2001,8.7127,0.0,0.0,2.2193,1.432,389.0,459.57,447.76,447.92
178.9243,1.4136,8.7091,0.0,0.0,2.2217,1.6589,388.97,459.59,447.74,447.94
178.9252,1.215,8.7037,0.0,0.0,2.2206,1.453,388.94,459.61,447.71,447.95
178.9261,1.3528,8.7017,0.0,0.0,2.22,1.5997,388.91,459.63,447.68,447.96
178.927,1.2698,8.6964,0.0,0.0,2.2159,1.5183,388.88,459.66,447.66,447.98
178.9279,1.2971,8.6979,0.0,0.0,2.2111,1.5222,388.85,459.68,447.63,447.99
178.9288,1.3502,8.7004,0.0,0.0,2.2099,1.6146,388.82,459.7,447.6,448.0
178.9297,1.2172,8.7011,0.0,0.0,2.2061,1.4358,388.79,459.72,447.58,448.02
178.9306,1.4097,8.7078,0.0,0.0,2.2067,1.6758,388.75,459.73,447.56,448.02
178.9315,1.1656,8.7109,0.0,0.0,2.2052,1.3898,388.69,459.74,447.54,448.02
178.9324,1.435,8.7159,0.0,0.0,2.2077,1.6941,388.64,459.76,447.52,448.02
178.9333,1.1653,8.7188,0.0,0.0,2.2086,1.3778,388.59,459.77,447.51,448.02
178.9342,1.3939,8.7245,0.0,0.0,2.2159,1.6527,388.54,459.78,447.49,448.02
178.9351,1.2078,8.7222,0.0,0.0,2.2181,1.4431,388.49,459.79,447.48,448.02
178.936,1.3576,8.7182,0.0,0.0,2.2193,1.5884,388.44,459.8,447.46,448.02
178.9369,1.2768,8.7212,0.0,0.0,2.2256,1.5362,388.38,459.81,447.44,448.02
178.9378,1.2913,8.7148,0.0,0.0,2.2239,1.5194,388.33,459.82,447.43,448.02
178.9387,1.3637,8.7084,0.0,0.0,2.2227,1.6349,388.28,459.83,447.41,448.02
178.9396,1.2307,8.7078,0.0,0.0,2.2232,1.4458,388.23,459.84,447.4,448.02
178.9405,1.4109,8.7072,0.0,0.0,2.2195,1.6891,388.18,459.84,447.38,448.01
178.9414,1.203,8.7052,0.0,0.0,2.2154,1.4016,388.14,459.84,447.37,448.0
178.9423,1.4371,8.709,0.0,0.0,2.2138,1.7182,388.09,459.84,447.35,447.98
178.9432,1.1932,8.7134,0.0,0.0,2.2112,1.4179,388.04,459.84,447.34,447.97
178.9441,1.4094,8.7161,0.0,0.0,2.2118,1.6779,388.0,459.84,447.33,447.96
178.945,1.2225,8.7203,0.0,0.0,2.212,1.4761,387.95,459.84,447.31,447.94
178.9459,1.3796,8.7202,0.0,0.0,2.2158,1.6267,387.9,459.84,447.3,447.93
178.9468,1.302,8.7185,0.0,0.0,2.2188,1.5495,387.86,459.84,447.29,447.92
178.9477,1.305,8.7178,0.0,0.0,2.2215,1.5374,387.81,459.84,447.27,447.9
178.9486,1.371,8.7148,0.0,0.0,2.2231,1.6368,387.77,459.84,447.26,447.89
178.9495,1.2513,8.7079,0.0,0.0,2.222,1.4742,387.72,459.84,447.25,447.88
178.9504,1.4497,8.7046,0.0,0.0,2.2221,1.7152,387.67,459.84,447.24,447.87
178.9513,1.2067,8.7009,0.0,0.0,2.2187,1.4432,387.62,459.84,447.23,447.88
178.9522,1.476,8.699,0.0,0.0,2.2143,1.7494,387.57,459.84,447.22,447.88
178.9531,1.2124,8.6992,0.0,0.0,2.2113,1.4311,387.53,459.84,447.21,447.89
178.954,1.4535,8.7017,0.0,0.0,2.2101,1.7062,387.48,459.84,447.2,447.89
178.9549,1.2419,8.7045,0.0,0.0,2.2067,1.4861,387.43,459.84,447.2,447.9
178.9558,1.3942,8.7112,0.0,0.0,2.2065,1.6559,387.38,459.84,447.19,447.9
178.9567,1.3107,8.7153,0.0,0.0,2.208,1.5755,387.33,459.84,447.18,447.91
178.9576,1.3196,8.719,0.0,0.0,2.2101,1.5614,387.28,459.84,447.17,447.92
178.9585,1.379,8.7243,0.0,0.0,2.2136,1.66,387.23,459.84,447.16,447.92
178.9594,1.2655,8.7225,0.0,0.0,2.2164,1.4991,387.18,459.84,447.16,447.93
178.9603,1.457,8.7248,0.0,0.0,2.2222,1.7293,387.13,459.85,447.16,447.93
178.9612,1.2193,8.7217,0.0,0.0,2.2236,1.447,387.07,459.86,447.18,447.93
178.9621,1.4698,8.7156,0.0,0.0,2.2249,1.7433,387.0,459.88,447.2,447.93
178.963,1.233,8.7152,0.0,0.0,2.2267,1.4651,386.94,459.89,447.22,447.93
178.9639,1.4619,8.7109,0.0,0.0,2.2254,1.7322,386.88,459.9,447.25,447.93
178.9648,1.2509,8.7061,0.0,0.0,2.2204,1.5224,386.82,459.92,447.27,447.93
178.9657,1.4135,8.7108,0.0,0.0,2.2213,1.673,386.75,459.93,447.29,447.93
178.9666,1.3233,8.7115,0.0,0.0,2.2174,1.5816,386.69,459.94,447.31,447.93
178.9675,1.333,8.713,0.0,0.0,2.2136,1.5756,386.63,459.96,447.33,447.93
178.9684,1.3984,8.7192,0.0,0.0,2.214,1.6779,386.57,459.97,447.35,447.93
178.9693,1.2718,8.7197,0.0,0.0,2.2122,1.5011,386.5,459.99,447.38,447.93
178.9702,1.4511,8.7207,0.0,0.0,2.2151,1.7302,386.45,460.0,447.4,447.93
178.9711,1.2335,8.7211,0.0,0.0,2.2168,1.4762,386.39,460.03,447.44,447.92
178.972,1.4827,8.7183,0.0,0.0,2.2211,1.7594,386.34,460.06,447.48,447.92
178.9729,1.2332,8.7145,0.0,0.0,2.2221,1.4659,386.29,460.09,447.53,447.91
178.9738,1.463,8.7114,0.0,0.0,2.2235,1.7411,386.24,460.12,447.57,447.91
178.9747,1.2486,8.7052,0.0,0.0,2.2212,1.486,386.19,460.15,447.61,447.9
178.9756,1.4066,8.7039,0.0,0.0,2.2208,1.6597,386.14,460.18,447.65,447.9
178.9765,1.3109,8.6987,0.0,0.0,2.2174,1.5745,386.08,460.21,447.69,447.89
178.9774,1.3505,8.6981,0.0,0.0,2.2133,1.5765,386.03,460.24,447.73,447.88
178.9783,1.3977,8.7021,0.0,0.0,2.2123,1.6751,385.98,460.27,447.77,447.88
178.9792,1.2648,8.7039,0.0,0.0,2.2068,1.4921,385.93,460.3,447.81,447.87
178.9801,1.4384,8.7078,0.0,0.0,2.207,1.7232,385.88,460.33,447.84,447.87
178.981,1.2318,8.7147,0.0,0.0,2.2081,1.455,385.82,460.35,447.84,447.87
178.9819,1.4699,8.7183,0.0,0.0,2.2094,1.7413,385.76,460.37,447.85,447.88
178.9828,1.2211,8.7203,0.0,0.0,2.2099,1.4562,385.7,460.38,447.85,447.88
178.9837,1.4615,8.7261,0.0,0.0,2.2181,1.719,385.64,460.4,447.85,447.88
178.9846,1.2489,8.7228,0.0,0.0,2.2175,1.4922,385.58,460.42,447.85,447.88
178.9855,1.4214,8.7215,0.0,0.0,2.223,1.6881,385.52,460.44,447.86,447.89
178.9864,1.3161,8.7206,0.0,0.0,2.2267,1.5744,385.46,460.46,447.86,447.89
178.9873,1.3521,8.7143,0.0,0.0,2.2256,1.5874,385.4,460.48,447.86,447.89
178.9882,1.39,8.71,0.0,0.0,2.2239,1.6539,385.34,460.5,447.86,447.89
178.9891,1.2655,8.7086,0.0,0.0,2.2244,1.4992,385.28,460.52,447.87,447.9
178.99,1.4516,8.7082,0.0,0.0,2.2218,1.7374,385.22,460.53,447.87,447.9
178.9909,1.2259,8.7065,0.0,0.0,2.2155,1.4601,385.16,460.55,447.83,447.91
178.9918,1.4777,8.7111,0.0,0.0,2.2144,1.7664,385.09,460.56,447.79,447.91
178.9927,1.2199,8.7143,0.0,0.0,2.2129,1.4481,385.03,460.57,447.75,447.92
178.9936,1.4498,8.7189,0.0,0.0,2.2118,1.726,384.97,460.59,447.71,447.92
178.9945,1.2428,8.7197,0.0,0.0,2.2129,1.4983,384.91,460.6,447.68,447.93
178.9954,1.4072,8.7215,0.0,0.0,2.2153,1.6588,384.84,460.61,447.64,447.93
178.9963,1.2894,8.7193,0.0,0.0,2.2182,1.5354,384.78,460.63,447.6,447.94
178.9972,1.3326,8.7148,0.0,0.0,2.2198,1.5766,384.72,460.64,447.56,447.94
178.9981,1.3695,8.7126,0.0,0.0,2.2223,1.6236,384.66,460.66,447.53,447.95
178.999,1.246,8.7043,0.0,0.0,2.2198,1.485,384.59,460.67,447.49,447.95
178.9999,1.4371,8.7017,0.0,0.0,2.2204,1.708,384.53,460.68,447.45,447.96
179.0008,1.2064,8.7031,0.0,0.0,2.22,1.4371,384.47,460.7,447.44,447.97
179.0017,1.4561,8.6975,0.0,0.0,2.2137,1.7202,384.41,460.73,447.42,447.98
179.0026,1.2,8.6975,0.0,0.0,2.2092,1.4268,384.35,460.75,447.41,447.98
179.0035,1.4419,8.7044,0.0,0.0,2.2107,1.709,384.28,460.77,447.4,447.99
179.0044,1.2471,8.708,0.0,0.0,2.2075,1.4833,384.22,460.79,447.38,448.0
179.0053,1.4004,8.7081,0.0,0.0,2.2048,1.6508,384.16,460.81,447.37,448.01
179.0062,1.2956,8.7167,0.0,0.0,2.2079,1.5476,384.1,460.83,447.36,448.02
179.0071,1.3266,8.7188,0.0,0.0,2.209,1.5766,384.03,460.85,447.34,448.02
179.008,1.351,8.7227,0.0,0.0,2.2128,1.6208,383.97,460.88,447.33,448.03
179.0089,1.2692,8.7234,0.0,0.0,2.217,1.4769,383.91,460.9,447.32,448.04
179.0098,1.4248,8.722,0.0,0.0,2.2214,1.7063,383.85,460.92,447.3,448.05
179.0107,1.2039,8.7189,0.0,0.0,2.2236,1.4147,383.78,460.94,447.31,448.06
179.0116,1.4454,8.7158,0.0,0.0,2.226,1.7424,383.72,460.96,447.33,448.07
179.0125,1.1923,8.7099,0.0,0.0,2.2225,1.4177,383.66,460.98,447.35,448.08
179.0134,1.4485,8.7094,0.0,0.0,2.2248,1.7153,383.6,460.99,447.36,448.09
179.0143,1.2146,8.706,0.0,0.0,2.2205,1.4501,383.53,461.01,447.38,448.1
179.0152,1.3942,8.7069,0.0,0.0,2.2177,1.656,383.47,461.03,447.4,448.11
179.0161,1.289,8.7091,0.0,0.0,2.2144,1.5354,383.41,461.05,447.41,448.12
179.017,1.3071,8.7129,0.0,0.0,2.213,1.5595,383.35,461.07,447.43,448.13
179.0179,1.37,8.7183,0.0,0.0,2.2126,1.6298,383.28,461.09,447.44,448.14
179.0188,1.2652,8.719,0.0,0.0,2.2125,1.4911,383.22,461.11,447.46,448.16
179.0197,1.4227,8.7201,0.0,0.0,2.2155,1.6849,383.16,461.13,447.48,448.17
179.0206,1.2176,8.7227,0.0,0.0,2.219,1.429,383.1,461.1,447.51,448.17
179.0215,1.4493,8.7191,0.0,0.0,2.2211,1.7131,383.04,461.06,447.55,448.17
179.0224,1.1863,8.7138,0.0,0.0,2.2216,1.4159,382.99,461.03,447.59,448.17
179.0233,1.4557,8.7079,0.0,0.0,2.2226,1.7242,382.93,460.99,447.63,448.17
179.0242,1.2222,8.7069,0.0,0.0,2.2233,1.4671,382.87,460.95,447.67,448.17
179.0251,1.4001,8.7023,0.0,0.0,2.2193,1.6517,382.82,460.91,447.71,448.17
179.026,1.277,8.6984,0.0,0.0,2.2153,1.5335,382.76,460.88,447.75,448.17
179.0269,1.3251,8.7016,0.0,0.0,2.2131,1.5615,382.7,460.84,447.79,448.17
179.0278,1.365,8.7011,0.0,0.0,2.2103,1.6378,382.64,460.8,447.83,448.17
179.0287,1.2659,8.7039,0.0,0.0,2.2073,1.5053,382.59,460.76,447.88,448.17
179.0296,1.4316,8.7106,0.0,0.0,2.2071,1.7152,382.53,460.72,447.92,448.17
179.0305,1.2385,8.7133,0.0,0.0,2.2081,1.461,382.47,460.7,447.94,448.17
179.0314,1.4829,8.7182,0.0,0.0,2.2092,1.7523,382.41,460.69,447.95,448.18
179.0323,1.208,8.7213,0.0,0.0,2.2126,1.449,382.35,460.68,447.96,448.18
179.0332,1.4549,8.7225,0.0,0.0,2.2159,1.718,382.29,460.67,447.97,448.19
179.0341,1.2344,8.7231,0.0,0.0,2.2191,1.469,382.23,460.66,447.98,448.19
179.035,1.4073,8.7217,0.0,0.0,2.2241,1.6649,382.17,460.65,447.99,448.2
179.0359,1.3034,8.717,0.0,0.0,2.2249,1.5664,382.11,460.64,448.0,448.2
179.0368,1.3456,8.7136,0.0,0.0,2.2251,1.5865,382.05,460.63,448.01,448.21
179.0377,1.3858,8.7116,0.0,0.0,2.2257,1.676,381.99,460.62,448.02,448.22
179.0386,1.2927,8.7083,0.0,0.0,2.2222,1.5322,381.93,460.61,448.03,448.22
179.0395,1.4384,8.7078,0.0,0.0,2.219,1.7242,381.87,460.6,448.04,448.23
179.0404,1.2455,8.7087,0.0,0.0,2.2167,1.47,381.81,460.61,448.03,448.23
179.0413,1.4779,8.7118,0.0,0.0,2.2142,1.7674,381.74,460.65,448.0,448.23
179.0422,1.2261,8.7161,0.0,0.0,2.2116,1.4551,381.67,460.68,447.97,448.24
179.0431,1.4826,8.7211,0.0,0.0,2.2128,1.7572,381.61,460.72,447.94,448.24
179.044,1.2494,8.7174,0.0,0.0,2.2109,1.5072,381.54,460.75,447.91,448.24
179.0449,1.4416,8.7246,0.0,0.0,2.2188,1.7079,381.47,460.79,447.88,448.24
179.0458,1.3111,8.7181,0.0,0.0,2.22,1.5807,381.4,460.82,447.85,448.25
179.0467,1.3664,8.7148,0.0,0.0,2.2198,1.6106,381.33,460.86,447.83,448.25
179.0476,1.3922,8.7134,0.0,0.0,2.223,1.6709,381.27,460.89,447.8,448.25
179.0485,1.2852,8.7046,0.0,0.0,2.2221,1.5214,381.2,460.93,447.77,448.25
179.0494,1.4642,8.7018,0.0,0.0,2.2208,1.7393,381.13,460.96,447.74,448.26
179.0503,1.2479,8.6985,0.0,0.0,2.2161,1.5012,381.06,460.98,447.7,448.26
179.0512,1.4902,8.6996,0.0,0.0,2.214,1.7674,380.99,460.96,447.67,448.26
179.0521,1.2455,8.6984,0.0,0.0,2.2099,1.4651,380.93,460.95,447.63,448.26
179.053,1.4747,8.7021,0.0,0.0,2.208,1.7342,380.86,460.93,447.59,448.26
179.0539,1.249,8.7063,0.0,0.0,2.206,1.5045,380.79,460.92,447.55,448.26
179.0548,1.4338,8.7125,0.0,0.0,2.2071,1.684,380.72,460.91,447.51,448.26
179.0557,1.3043,8.7158,0.0,0.0,2.2071,1.5718,380.65,460.89,447.48,448.26
179.0566,1.3527,8.7226,0.0,0.0,2.2124,1.5945,380.59,460.88,447.44,448.26
179.0575,1.3908,8.7222,0.0,0.0,2.2145,1.6609,380.52,460.87,447.4,448.26
179.0584,1.2904,8.7204,0.0,0.0,2.2157,1.5073,380.45,460.85,447.36,448.26
179.0593,1.4437,8.7259,0.0,0.0,2.2246,1.7143,380.38,460.84,447.33,448.26
179.0602,1.2453,8.7161,0.0,0.0,2.223,1.4771,380.31,460.83,447.29,448.26
179.0611,1.4695,8.7164,0.0,0.0,2.2255,1.7372,380.25,460.81,447.27,448.26
179.062,1.2135,8.7123,0.0,0.0,2.2257,1.448,380.18,460.79,447.25,448.25
179.0629,1.4749,8.7092,0.0,0.0,2.2236,1.7411,380.11,460.77,447.23,448.25
179.0638,1.2553,8.7095,0.0,0.0,2.2211,1.5063,380.04,460.75,447.21,448.25
179.0647,1.4396,8.7098,0.0,0.0,2.219,1.6891,379.97,460.73,447.19,448.24
179.0656,1.2908,8.7092,0.0,0.0,2.2149,1.5566,379.91,460.71,447.16,448.24
179.0665,1.3456,8.7128,0.0,0.0,2.2119,1.5856,379.84,460.69,447.14,448.24
179.0674,1.3703,8.7191,0.0,0.0,2.2131,1.6379,379.77,460.67,447.12,448.24
179.0683,1.2782,8.7188,0.0,0.0,2.2113,1.5072,379.7,460.66,447.1,448.23
179.0692,1.4378,8.7222,0.0,0.0,2.2154,1.7222,379.63,460.64,447.08,448.23
179.0701,1.2374,8.72,0.0,0.0,2.2189,1.454,379.57,460.61,447.07,448.23
179.071,1.4761,8.7176,0.0,0.0,2.2204,1.7433,379.5,460.54,447.1,448.24
179.0719,1.2196,8.7138,0.0,0.0,2.2215,1.44,379.43,460.47,447.13,448.24
179.0728,1.4609,8.708,0.0,0.0,2.222,1.7163,379.36,460.4,447.16,448.25
179.0737,1.2217,8.704,0.0,0.0,2.2221,1.4653,379.29,460.33,447.19,448.25
179.0746,1.4075,8.701,0.0,0.0,2.2198,1.664,379.23,460.26,447.22,448.26
179.0755,1.2824,8.6977,0.0,0.0,2.2142,1.5325,379.16,460.19,447.25,448.26
179.0764,1.3591,8.7008,0.0,0.0,2.2125,1.6016,379.09,460.12,447.27,448.27
179.0773,1.3757,8.7023,0.0,0.0,2.2097,1.6237,379.02,460.05,447.3,448.27
179.0782,1.2837,8.7014,0.0,0.0,2.2043,1.4992,378.95,459.98,447.33,448.28
179.0791,1.4111,8.7127,0.0,0.0,2.2078,1.684,378.89,459.91,447.36,448.28
179.08,1.2314,8.7153,0.0,0.0,2.2069,1.4521,378.82,459.83,447.39,448.29
179.0809,1.4577,8.718,0.0,0.0,2.2078,1.7433,378.76,459.74,447.42,448.3
179.0818,1.2007,8.7219,0.0,0.0,2.2117,1.4399,378.69,459.64,447.44,448.31
179.0827,1.4571,8.7249,0.0,0.0,2.2188,1.734,378.63,459.54,447.47,448.32
179.0836,1.2285,8.7218,0.0,0.0,2.2204,1.4691,378.57,459.45,447.49,448.33
179.0845,1.4199,8.7186,0.0,0.0,2.2219,1.6748,378.51,459.35,447.51,448.34
179.0854,1.29,8.7164,0.0,0.0,2.2255,1.5477,378.44,459.25,447.54,448.35
179.0863,1.3582,8.7129,0.0,0.0,2.2253,1.5856,378.38,459.16,447.56,448.37
179.0872,1.3586,8.71,0.0,0.0,2.2242,1.6378,378.32,459.06,447.59,448.38
179.0881,1.2834,8.7059,0.0,0.0,2.2192,1.5001,378.25,458.96,447.61,448.39
179.089,1.4244,8.7092,0.0,0.0,2.2197,1.6992,378.19,458.86,447.64,448.4
179.0899,1.2317,8.7071,0.0,0.0,2.2148,1.453,378.13,458.77,447.66,448.41
179.0908,1.47,8.7121,0.0,0.0,2.2119,1.7382,378.06,458.63,447.64,448.41
179.0917,1.2199,8.7154,0.0,0.0,2.211,1.4471,377.99,458.5,447.62,448.42
179.0926,1.4744,8.7212,0.0,0.0,2.2134,1.7351,377.93,458.36,447.6,448.42
179.0935,1.2279,8.7183,0.0,0.0,2.2131,1.468,377.86,458.23,447.58,448.43
179.0944,1.4204,8.7205,0.0,0.0,2.2179,1.6749,377.79,458.09,447.57,448.44
179.0953,1.2846,8.719,0.0,0.0,2.2206,1.5496,377.72,457.96,447.55,448.44
179.0962,1.3586,8.7143,0.0,0.0,2.2204,1.5928,377.65,457.83,447.53,448.45
179.0971,1.3771,8.71,0.0,0.0,2.223,1.6398,377.59,457.69,447.51,448.45
179.098,1.285,8.7053,0.0,0.0,2.2224,1.5073,377.52,457.56,447.49,448.46
179.0989,1.4384,8.701,0.0,0.0,2.219,1.7233,377.45,457.42,447.47,448.46
179.0998,1.2517,8.6985,0.0,0.0,2.2167,1.4752,377.38,457.29,447.45,448.47
179.1007,1.4636,8.7006,0.0,0.0,2.217,1.7382,377.32,457.09,447.43,448.47
179.1016,1.2194,8.6987,0.0,0.0,2.2082,1.4479,377.26,456.89,447.4,448.48
179.1025,1.4757,8.704,0.0,0.0,2.208,1.7493,377.2,456.69,447.38,448.48
179.1034,1.2464,8.7084,0.0,0.0,2.2061,1.4682,377.14,456.49,447.36,448.49
179.1043,1.4524,8.7133,0.0,0.0,2.207,1.691,377.08,456.28,447.33,448.49
179.1052,1.2846,8.7202,0.0,0.0,2.2089,1.5556,377.02,456.08,447.31,448.5
179.1061,1.3775,8.7211,0.0,0.0,2.2111,1.6087,376.96,455.88,447.28,448.51
179.107,1.3707,8.7246,0.0,0.0,2.2167,1.6439,376.9,455.68,447.26,448.51
179.1079,1.2994,8.7229,0.0,0.0,2.2181,1.5445,376.84,455.47,447.23,448.52
179.1088,1.4429,8.7223,0.0,0.0,2.2237,1.7011,376.78,455.27,447.21,448.52
179.1097,1.2571,8.7182,0.0,0.0,2.2237,1.47,376.72,455.07,447.19,448.53
179.1106,1.4757,8.716,0.0,0.0,2.2269,1.7391,376.66,455.0,447.18,448.53
179.1115,1.2381,8.7102,0.0,0.0,2.2258,1.457,376.6,454.97,447.17,448.53
179.1124,1.4631,8.7083,0.0,0.0,2.222,1.7352,376.53,454.94,447.17,448.53
179.1133,1.2402,8.7095,0.0,0.0,2.2218,1.469,376.47,454.91,447.16,448.53
179.1142,1.4219,8.7093,0.0,0.0,2.2158,1.6962,376.41,454.88,447.15,448.53
179.1151,1.2826,8.7126,0.0,0.0,2.2151,1.5353,376.35,454.85,447.15,448.53
179.91555,1.2451,8.7114,0.0,0.0,2.2157,1.4804,336.02,415.77,442.7,389.99
181.71555,1.2098,8.7124,0.0,0.0,2.2165,1.436,273.88,300.8,403.23,318.84
183.3527,1.1853,8.7069,0.0,0.0,2.212,1.4065,218.81,206.13,345.25,261.49
185.1527,1.1375,8.7007,0.0,0.0,2.207,1.3502,130.88,113.43,226.26,99.134
186.9527,1.0642,8.7077,0.0,0.0,2.2126,1.2639,86.008,93.671,64.13,46.821
188.7527,1.0066,8.7106,0.0,0.0,2.2149,1.1934,77.255,83.269,47.556,40.508
190.5527,0.97764,8.7172,0.0,0.0,2.2203,1.1604,71.62,74.188,43.599,39.054
192.3527,0.95087,8.7206,0.0,0.0,2.223,1.1279,66.684,67.759,42.128,38.662
194.1527,0.88143,8.7271,0.0,0.0,2.2282,1.0467,62.931,63.802,41.698,38.654
195.9527,0.81979,8.7374,0.0,0.0,2.2366,0.97299,65.956,67.919,44.725,44.552