File: examples/dan-msc-case-studies/CS4/data/01 raw data/hyde_test_006.csv
Time(sec),Force(kN),Jaw(mm),PowAngle(deg),PTemp,Strain,Stress(MPa),TC1(C),TC2(C),TC3(C),TC4(C)
0.0,2.2286,-10.41,0.0,0.0037844,-0.79261,2.6417,24.983,25.391,24.984,24.702
0.8,2.1563,-0.0011369,0.0,2.2207,-9.4758e-05,2.5594,24.953,25.359,25.033,24.53
1.6,2.135,-0.00077686,0.0,4.6207,-9.1286e-05,2.5335,24.95,25.382,25.041,24.528
2.4,2.0966,-0.0010808,0.0,7.0207,-0.00011148,2.4885,24.936,25.372,25.011,24.534
3.2,2.0773,-0.0011313,0.0,9.4263,-0.00010011,2.4658,24.941,25.387,25.035,24.54
3.8013,2.0659,-0.0010576,0.0,11.225,-0.00010231,2.4527,24.925,25.396,25.023,24.572
4.6013,2.0728,-0.001038,0.0,13.625,-0.000131,2.4607,24.887,25.423,24.967,24.531
5.4013,2.077,-0.0008603,0.0,16.025,-8.538e-05,2.4652,24.925,25.389,24.992,24.517
6.2013,2.0637,-0.00090175,0.0,18.425,-0.00011317,2.4493,24.95,25.414,24.987,24.536
7.0013,2.0558,-0.00083844,0.0,20.825,-6.9026e-05,2.4402,24.948,25.475,25.064,24.591
7.8013,2.0377,-0.000999,0.0,23.225,-0.00012811,2.4187,24.94,25.425,25.022,24.583
8.6013,2.0306,-0.0010495,6.4973,25.625,-9.0127e-05,2.4095,24.935,25.416,25.043,24.553
9.4013,2.0301,0.00012194,26.848,28.025,2.2374e-05,2.408,25.433,25.454,25.042,24.552
10.2013,2.0408,-5.3832e-05,31.793,30.425,-8.3184e-06,2.4212,27.636,25.539,25.043,24.871
11.0013,2.0492,-0.00051705,33.728,32.825,-3.7371e-05,2.4315,30.346,25.864,25.218,25.873
11.8013,2.0656,-0.0010022,34.338,35.225,-0.00012043,2.4504,33.262,26.475,25.51,27.4
12.6013,2.069,-0.0017332,34.783,37.625,-0.00017387,2.455,36.076,27.348,26.003,29.371
13.4013,2.0798,-0.0021108,35.438,40.025,-0.00024593,2.4674,38.758,28.48,26.636,31.534
14.2013,2.0794,-0.0030986,35.315,42.425,-0.00030698,2.4678,41.499,29.983,27.451,33.812
15.0013,2.0855,-0.0036027,35.757,44.825,-0.00039736,2.4742,44.059,38.14,28.355,36.283
15.8013,2.0838,-0.004249,35.754,47.225,-0.00043022,2.4712,46.636,38.141,29.484,38.791
16.6013,2.0847,-0.0049921,36.247,49.625,-0.00053152,2.4737,49.07,38.141,30.768,41.367
17.4013,2.0898,-0.0056024,36.335,52.025,-0.00061402,2.4802,51.617,38.498,32.226,43.951
18.2013,2.0895,-0.0061363,36.47,54.425,-0.00065599,2.4797,54.096,40.886,33.779,46.621
19.0013,2.0929,-0.0068027,36.38,56.825,-0.00075989,2.4842,56.596,43.403,35.448,49.321
19.8013,2.0913,-0.0078599,36.749,59.225,-0.00085162,2.4821,59.015,46.005,37.164,52.007
20.6013,2.094,-0.0085969,37.023,61.625,-0.00096608,2.4855,61.434,48.619,38.963,54.605
21.4013,2.0951,-0.0096344,37.042,64.025,-0.0010329,2.4865,63.872,51.255,40.884,57.332
22.2013,2.0996,-0.010377,37.459,66.425,-0.001155,2.4923,66.209,53.965,42.774,59.992
23.0013,2.1008,-0.011603,38.04,68.825,-0.0012502,2.494,68.501,56.69,44.863,62.547
23.8013,2.1039,-0.012747,38.142,71.225,-0.0013857,2.4975,70.98,59.279,46.889,65.237
24.6013,2.1129,-0.013992,38.051,73.625,-0.0015429,2.5075,73.425,62.062,48.997,67.91
25.4013,2.1165,-0.014922,38.201,76.025,-0.001645,2.511,75.869,64.892,51.114,70.589
26.2013,2.13,-0.014926,38.42,78.425,-0.0016769,2.5273,78.328,67.65,53.217,73.272
27.0013,2.1781,-0.013886,38.548,80.825,-0.0015391,2.5847,80.729,70.504,55.351,75.949
27.8013,2.2349,-0.01335,38.551,83.225,-0.0014953,2.6509,83.13,73.261,57.492,78.565
28.6013,2.2838,-0.013396,38.295,85.625,-0.0014601,2.7097,85.611,76.138,59.689,81.188
29.4013,2.3575,-0.013734,38.55,88.025,-0.0015389,2.7968,87.956,78.863,61.898,83.808
30.2013,2.5513,-0.013172,38.208,90.425,-0.0014237,3.0271,90.455,81.526,64.087,86.356
31.0013,2.874,-0.010914,38.119,92.825,-0.001208,3.4097,92.918,84.203,66.305,88.852
31.8013,3.1311,-0.0088681,38.029,95.225,-0.00097391,3.7165,95.335,86.836,68.537,91.257
32.6013,3.2172,-0.0085967,38.212,97.625,-0.00093788,3.8178,97.65,89.514,70.77,93.688
33.4013,3.2631,-0.008967,37.949,100.02,-0.00099356,3.873,100.1,92.074,73.024,96.132
34.2013,3.2876,-0.009497,37.928,102.42,-0.0010423,3.9023,102.48,94.543,75.195,98.502
35.0013,3.2972,-0.010193,38.017,104.82,-0.0011418,3.9126,104.87,97.033,77.441,100.87
35.7194,3.2998,-0.011171,38.133,107.0,-0.001247,3.9149,106.99,99.182,79.376,103.01
36.5194,3.3013,-0.012375,38.526,109.38,-0.0013578,3.917,109.34,101.7,81.576,105.36
37.3194,3.3091,-0.013251,38.362,111.78,-0.0014562,3.927,111.74,104.15,83.766,107.69
38.1194,3.3089,-0.014363,38.522,114.18,-0.0015878,3.9267,114.16,106.61,85.896,110.12
38.9194,3.3122,-0.015723,38.553,116.58,-0.0017286,3.9306,116.52,109.08,88.099,112.47
39.7194,3.3222,-0.016556,38.894,118.98,-0.0018636,3.9428,118.86,111.5,90.286,114.91
40.5194,3.3261,-0.017235,38.755,121.38,-0.0018924,3.9482,121.32,114.07,92.47,117.33
41.3194,3.3253,-0.018517,38.84,123.78,-0.0020546,3.9473,123.73,116.71,94.581,119.77
42.1194,3.3329,-0.020626,38.754,126.18,-0.0022315,3.9563,126.15,119.3,96.589,122.21
42.9194,3.333,-0.022518,39.409,128.58,-0.0024954,3.9561,128.42,121.8,98.588,124.69
43.5844,3.3338,-0.02408,39.152,130.57,-0.0026486,3.9556,130.52,124.24,100.26,126.71
44.3844,3.3345,-0.025229,39.243,132.97,-0.0028097,3.957,132.92,126.48,102.31,129.25
45.1844,3.3388,-0.026266,39.324,135.37,-0.0028918,3.9618,135.26,129.24,104.36,131.72
45.9844,3.3421,-0.026805,39.446,137.77,-0.0029968,3.9651,137.68,132.19,106.56,134.2
46.7844,3.3451,-0.027783,39.767,140.17,-0.0030542,3.9689,140.05,134.82,108.72,136.67
47.5844,3.3457,-0.028338,39.838,142.57,-0.0031514,3.9707,142.49,137.53,110.88,139.19
48.3844,3.3472,-0.029601,39.924,144.97,-0.0032454,3.9727,144.88,140.23,113.06,141.69
49.1844,3.3461,-0.030641,39.924,147.37,-0.0033774,3.9712,147.28,142.93,115.17,144.15
49.9844,3.3484,-0.032048,40.016,149.77,-0.00353,3.9746,149.64,145.49,117.3,146.56
50.7844,3.3501,-0.033446,40.071,152.17,-0.0036778,3.9764,152.13,148.01,119.54,149.09
51.5844,3.346,-0.034852,40.509,154.57,-0.0038534,3.972,154.47,150.84,121.71,151.57
52.3844,3.3481,-0.036632,40.238,156.97,-0.0040248,3.9739,156.96,153.56,123.88,154.06
53.1844,3.352,-0.037908,40.822,159.37,-0.0041964,3.9787,159.22,156.24,126.16,156.58
53.9844,3.3578,-0.039457,40.588,161.77,-0.0043419,3.9861,161.66,158.63,128.51,158.98
54.7844,3.3541,-0.040858,40.761,164.17,-0.0045271,3.9808,164.04,161.83,130.91,161.47
55.5844,3.3529,-0.042488,40.992,166.57,-0.0046732,3.98,166.43,164.43,133.22,164.04
56.3844,3.3615,-0.043824,41.039,168.97,-0.0048533,3.9897,168.85,167.27,135.52,166.52
57.1844,3.3651,-0.045571,40.957,171.37,-0.0050001,3.9937,171.31,169.82,137.82,169.1
57.9844,3.3676,-0.046973,41.087,173.77,-0.005201,3.9961,173.71,172.17,140.19,171.57
58.7844,3.3756,-0.048454,41.159,176.17,-0.0053148,4.0062,176.12,175.18,142.49,174.12
59.5844,3.3787,-0.049828,41.192,178.57,-0.0055081,4.0088,178.49,178.11,144.81,176.51
60.3844,3.379,-0.051501,41.059,180.97,-0.0056598,4.0093,180.96,180.5,147.23,178.96
61.1844,3.3535,-0.053522,41.199,183.37,-0.0059018,3.979,183.3,182.94,149.61,181.41
61.9844,3.2919,-0.055749,41.207,185.77,-0.0061375,3.9062,185.76,185.62,152.01,183.88
62.7844,3.2226,-0.057827,41.466,188.17,-0.0063629,3.8241,188.07,188.9,154.36,186.33
63.5844,3.1728,-0.059405,41.537,190.57,-0.0065525,3.7647,190.52,191.61,156.83,188.78
64.3844,3.1316,-0.061144,41.439,192.97,-0.0067064,3.7157,192.96,194.22,159.13,191.4
65.1844,3.0822,-0.064998,41.601,195.37,-0.0071603,3.6585,195.29,197.05,161.54,193.87
65.9844,3.0436,-0.0664,41.478,197.77,-0.0073312,3.6119,197.77,199.79,164.03,196.44
66.7844,2.9887,-0.066865,41.587,200.17,-0.0073905,3.548,200.15,202.32,166.53,198.95
67.5844,2.9018,-0.0685,41.637,202.57,-0.007548,3.445,202.48,205.06,169.02,201.43
68.362,2.7697,-0.070958,41.898,204.92,-0.0078003,3.288,204.81,207.45,171.44,203.91
69.162,2.6568,-0.073569,41.803,207.31,-0.0081156,3.1543,207.22,209.82,173.99,206.41
69.962,2.5693,-0.076032,41.96,209.71,-0.0083632,3.0506,209.64,212.82,176.55,208.97
70.762,2.4946,-0.078429,42.066,212.11,-0.0086609,2.9612,212.02,216.04,179.07,211.5
71.562,2.4169,-0.080691,42.265,214.51,-0.0088714,2.8689,214.42,218.69,181.55,214.04
72.362,2.3572,-0.082811,42.097,216.91,-0.0091331,2.7987,216.87,221.4,184.18,216.57
73.162,2.3012,-0.085231,42.29,219.31,-0.0093681,2.7308,219.22,224.24,186.7,219.11
73.962,2.2536,-0.086987,42.375,221.71,-0.0095912,2.6745,221.57,226.83,189.26,221.7
74.762,2.2116,-0.089322,42.282,224.11,-0.0097899,2.625,224.01,229.42,191.81,224.22
75.562,2.1823,-0.09062,42.868,226.51,-0.0099984,2.5895,226.33,231.96,194.31,226.65
76.2134,2.1639,-0.091927,42.563,228.46,-0.010097,2.5681,228.36,234.2,196.39,228.8
77.0134,2.1491,-0.096074,42.663,230.86,-0.010589,2.5502,230.8,236.97,198.88,231.39
77.8134,2.1353,-0.095953,42.954,233.26,-0.010569,2.5342,233.18,238.94,201.42,233.96
78.6134,2.1234,-0.096709,42.961,235.66,-0.010653,2.5206,235.59,241.85,203.98,236.4
79.4134,2.1148,-0.099229,42.975,238.06,-0.010896,2.5102,238.01,244.3,206.5,238.98
80.2134,2.1093,-0.10166,42.899,240.46,-0.011203,2.5051,240.46,246.55,209.03,241.49
81.0134,2.1019,-0.10394,42.923,242.86,-0.011411,2.4945,242.86,249.44,211.52,244.03
81.8134,2.1001,-0.10592,42.978,245.26,-0.011666,2.4931,245.21,252.13,213.94,246.56
82.6134,2.0971,-0.10803,43.252,247.66,-0.011848,2.4901,247.58,254.38,216.49,249.02
83.4134,2.1025,-0.10957,43.006,250.06,-0.012078,2.4955,250.06,256.82,219.02,251.54
84.2134,2.1008,-0.1133,43.325,252.46,-0.012413,2.4941,252.37,259.14,221.46,254.07
85.0134,2.1053,-0.11291,43.432,254.86,-0.012445,2.4995,254.79,261.7,223.93,256.53
85.8134,2.1022,-0.11456,43.45,257.26,-0.012567,2.4952,257.22,264.16,226.44,259.09
86.6134,2.104,-0.11704,43.209,259.66,-0.012863,2.4966,259.69,267.34,228.85,261.57
87.4134,2.0943,-0.11969,43.524,262.06,-0.013128,2.4854,261.96,269.98,231.36,264.11
88.2134,1.8514,-0.12385,43.339,264.46,-0.013612,2.1964,264.49,272.81,233.89,266.66
89.0134,1.608,-0.12874,42.932,266.86,-0.014137,1.9086,267.03,275.27,236.36,269.33
89.8134,1.5457,-0.13179,42.996,269.26,-0.01445,1.8339,269.36,278.05,238.79,271.89
90.6134,1.5118,-0.13361,42.942,271.66,-0.014679,1.7941,271.78,279.97,241.28,274.39
91.4134,1.4847,-0.13518,42.977,274.06,-0.014825,1.7622,274.11,282.24,243.73,276.8
92.2134,1.4678,-0.1384,43.018,276.46,-0.015194,1.7418,276.47,284.64,246.2,279.22
93.0134,1.454,-0.14109,43.444,278.86,-0.015477,1.726,278.77,287.56,248.63,281.66
93.8134,1.4451,-0.14366,43.388,281.26,-0.015778,1.7147,281.22,289.97,251.08,284.16
94.6134,1.4315,-0.14606,43.6,283.66,-0.016012,1.6988,283.57,293.44,253.47,286.67
95.4134,1.4312,-0.14785,43.629,286.06,-0.016204,1.699,285.98,296.35,255.96,289.18
96.2134,1.4252,-0.1508,43.636,288.46,-0.016562,1.6915,288.41,298.59,258.37,291.64
97.0134,1.418,-0.15132,43.933,290.86,-0.016609,1.6842,290.76,300.98,260.83,294.2
97.8134,1.4169,-0.1545,44.045,293.26,-0.016941,1.6824,293.15,303.72,263.27,296.73
98.6134,1.4115,-0.1572,44.062,295.66,-0.017262,1.6749,295.58,306.44,265.72,299.34
99.4134,1.407,-0.15981,44.462,298.06,-0.017523,1.6701,297.89,310.16,268.18,301.98
100.2134,1.3967,-0.16221,43.082,299.99,-0.017807,1.6577,300.4,314.4,270.78,304.74
100.9911,1.4014,-0.16342,39.608,300.0,-0.017921,1.6629,301.45,316.95,273.18,307.17
101.7911,1.4004,-0.16286,38.302,300.0,-0.017867,1.663,301.51,317.63,275.7,308.51
102.5911,1.3988,-0.16374,37.15,300.0,-0.017958,1.6598,301.4,317.38,277.96,309.04
103.3911,1.4003,-0.16507,37.091,300.0,-0.018075,1.6629,301.03,316.72,280.19,308.99
104.1911,1.3971,-0.16605,36.936,300.0,-0.018214,1.6581,300.86,316.1,282.11,308.73
104.9911,1.3992,-0.16718,36.719,300.0,-0.018328,1.6597,300.67,315.55,283.88,308.34
105.7911,1.4001,-0.16825,36.881,300.0,-0.01847,1.6612,300.48,315.05,285.35,307.93
106.5911,1.3967,-0.1702,36.74,300.0,-0.018644,1.658,300.36,314.73,286.58,307.58
107.3911,1.4001,-0.1693,36.681,300.0,-0.018591,1.6617,300.27,314.49,287.6,307.2
108.1911,1.3996,-0.17045,36.681,300.0,-0.018676,1.6604,300.22,314.23,288.43,306.82
108.9443,1.3954,-0.17159,36.824,300.0,-0.01883,1.6562,300.15,313.89,289.06,306.52
109.7443,1.326,-0.17343,36.936,300.0,-0.018992,1.5733,300.07,313.73,289.65,306.24
110.5443,1.2299,-0.17528,36.386,300.0,-0.019224,1.4593,300.14,313.55,290.07,306.01
111.3443,1.1491,-0.17764,36.315,300.0,-0.019447,1.3625,300.11,313.37,290.39,305.8
112.1443,1.0895,-0.17964,36.31,300.0,-0.019685,1.2928,300.14,313.18,290.75,305.6
112.9443,1.0499,-0.18026,36.304,300.0,-0.019741,1.2458,300.06,313.08,290.91,305.46
113.7443,1.0218,-0.18118,35.7,300.0,-0.019865,1.213,300.19,312.95,291.12,305.35
114.5443,0.99779,-0.18289,36.041,300.0,-0.020022,1.1848,300.08,312.84,291.28,305.17
115.3443,0.97945,-0.18402,36.155,300.0,-0.020167,1.1626,300.07,312.7,291.34,305.06
116.1443,0.96233,-0.1853,35.598,300.0,-0.020282,1.1422,300.14,312.75,291.4,304.94
116.9443,0.95468,-0.18619,35.693,300.0,-0.020399,1.1346,300.07,312.71,291.47,304.89
117.7443,0.94125,-0.18713,35.983,300.0,-0.020473,1.1175,300.01,312.61,291.49,304.76
118.5443,0.92741,-0.18827,35.995,300.0,-0.020651,1.1017,300.02,312.57,291.48,304.65
119.3443,0.91232,-0.1884,35.475,300.0,-0.020623,1.0831,300.11,312.59,291.45,304.59
120.1443,0.9,-0.18973,35.608,300.0,-0.020797,1.0694,300.04,312.62,291.48,304.47
120.9443,0.88737,-0.19099,35.52,300.0,-0.020898,1.0539,300.09,312.56,291.44,304.32
121.7443,0.87321,-0.19186,33.686,300.0,-0.02102,1.0368,299.78,312.44,291.44,304.26
122.5443,0.86511,-0.1928,32.95,300.0,-0.021095,1.027,299.33,311.77,291.33,303.88
123.3443,0.83895,-0.19219,26.411,300.0,-0.021055,0.99621,297.26,310.22,291.21,303.3
124.1443,0.85524,-0.19322,31.851,300.0,-0.021143,1.0148,295.83,307.81,290.87,301.75
124.9443,0.854,-0.19423,32.123,300.0,-0.021283,1.0126,295.59,306.77,290.41,300.47
125.7443,0.84867,-0.19418,32.778,300.0,-0.021239,1.0068,295.29,306.15,289.94,299.4
126.5443,0.84662,-0.19523,33.675,300.0,-0.021389,1.0038,295.17,305.76,289.31,298.65
127.3443,0.85016,-0.19653,36.945,300.0,-0.021502,1.009,295.28,305.67,288.75,298.09
128.1443,0.84498,-0.19735,35.055,300.0,-0.021628,1.0029,296.29,306.54,288.26,297.92
128.9443,0.84368,-0.19853,36.491,300.0,-0.021718,1.0016,296.58,307.12,287.84,298.08
129.7443,0.83757,-0.19965,35.505,300.0,-0.021868,0.99445,297.29,307.9,287.49,298.32
130.5443,0.83748,-0.20039,34.829,300.0,-0.021906,0.99414,297.49,308.39,287.25,298.61
131.3443,0.83376,-0.20106,34.83,300.0,-0.022047,0.99056,297.52,308.57,287.06,298.82
132.1443,0.83579,-0.20093,34.661,300.0,-0.021971,0.99402,297.58,308.64,286.93,298.92
132.9443,0.83079,-0.20202,34.501,300.0,-0.022129,0.98654,297.57,308.66,286.79,298.97
133.7192,0.82826,-0.20271,34.564,300.0,-0.022214,0.98302,297.56,308.67,286.71,299.01
134.5192,0.8242,-0.20373,34.483,300.0,-0.022277,0.97991,297.57,308.68,286.64,298.96
135.3192,0.81438,-0.20361,28.404,300.0,-0.022316,0.96784,297.06,308.48,286.54,298.99
136.1192,0.81276,-0.20468,32.68,300.0,-0.022391,0.96587,295.84,307.0,286.44,298.54
136.9192,0.82219,-0.20572,33.31,300.0,-0.022531,0.97688,295.66,306.33,286.21,297.95
137.7192,0.8256,-0.20551,34.351,300.0,-0.022491,0.98061,295.84,306.11,286.03,297.52
138.5192,0.81414,-0.20608,34.659,300.0,-0.022573,0.9671,296.21,306.36,285.77,297.25
139.3192,0.82148,-0.20712,34.475,300.0,-0.022656,0.97533,296.72,306.92,285.55,297.29
140.1192,0.81795,-0.20768,34.0,300.0,-0.022747,0.97046,296.8,307.11,285.37,297.42
140.9192,0.81006,-0.20883,34.66,300.0,-0.02286,0.96092,297.05,307.28,285.34,297.48
141.6872,0.79259,-0.20959,33.777,300.0,-0.022949,0.94171,297.28,307.61,285.22,297.58
142.4872,0.80531,-0.21037,33.877,300.0,-0.023012,0.95659,297.84,307.9,285.17,297.77
143.2872,0.80206,-0.21161,33.849,300.0,-0.023161,0.95266,297.86,308.05,285.14,297.98
144.0872,0.81412,-0.21115,33.977,300.0,-0.023088,0.96525,298.07,308.11,285.14,298.14
144.8872,0.81071,-0.2117,33.897,300.0,-0.023176,0.96151,298.11,308.16,285.16,298.23
145.28403,0.80774,0.0063486,24.804,52.336,0.00092053,0.95614,298.08,308.2,285.24,298.33
145.28535,0.81289,0.0077357,20.337,0.00016607,0.0014393,0.97229,298.08,308.21,285.24,298.33
145.28667,0.82232,0.006128,15.87,4.9554e-10,0.0011412,0.97158,298.08,308.21,285.25,298.33
145.28799,0.80346,0.0055939,11.403,1.4218e-15,0.0012547,0.9611,298.08,308.22,285.25,298.33
145.28931,0.80185,0.0052921,6.9366,3.9696e-21,0.0011206,0.95784,298.08,308.22,285.25,298.33
145.29063,0.80626,0.011158,2.4698,1.0863e-26,0.0010001,0.95741,298.08,308.22,285.26,298.33
145.29195,0.79679,0.011602,0.0,4.8903e-32,0.00049027,0.93504,298.09,308.23,285.27,298.32
145.29327,0.82449,0.011127,0.0,3.1342e-37,0.0016233,0.97472,298.12,308.24,285.28,298.31
145.29459,0.82669,0.010556,0.0,1.2219e-42,-0.00011865,0.97552,298.15,308.26,285.29,298.31
145.29591,0.79789,0.010987,0.0,0.0,0.0017016,0.95627,298.18,308.27,285.3,298.3
145.29723,0.81959,0.0083854,0.0,0.0,0.00038475,0.97859,298.21,308.28,285.32,298.29
145.29855,0.74309,0.0088783,0.0,0.0,0.0011987,0.88598,298.23,308.29,285.33,298.28
145.29987,0.81931,0.0070768,0.0,0.0,0.00073477,0.97394,298.26,308.3,285.34,298.27
145.30119,0.81926,0.0068058,0.0,0.0,0.0012802,0.98433,298.29,308.32,285.35,298.26
145.30251,0.82497,0.0025499,0.0,0.0,0.00078352,0.9762,298.28,308.3,285.35,298.25
145.30383,0.78887,0.0070379,0.0,0.0,0.0013418,0.94924,298.26,308.28,285.35,298.23
145.30515,0.81427,0.0089501,0.0,0.0,0.00062429,0.97043,298.25,308.26,285.34,298.22
145.30647,0.82514,0.0087842,0.0,0.0,0.001199,0.97428,298.23,308.24,285.34,298.2
145.30779,0.80118,0.009606,0.0,0.0,0.00086317,0.95866,298.22,308.22,285.33,298.18
145.30911,0.82853,0.012148,0.0,0.0,0.00069184,0.97876,298.2,308.2,285.33,298.17
145.31043,0.81856,0.010637,0.0,0.0,0.0015464,0.96616,298.18,308.18,285.33,298.15
145.31175,0.80326,0.0094344,0.0,0.0,-2.0486e-05,0.93814,298.17,308.16,285.32,298.14
145.31307,0.81716,0.011053,0.0,0.0,0.0016219,0.97901,298.16,308.15,285.32,298.15
145.31439,0.8397,0.0080765,0.0,0.0,0.00072067,0.99389,298.14,308.14,285.31,298.15
145.31571,0.79885,0.0043392,0.0,0.0,0.0012191,0.93757,298.13,308.12,285.31,298.15
145.31703,0.8105,0.0052918,0.0,0.0,0.00080654,0.96742,298.12,308.11,285.31,298.16
145.31835,0.8156,0.0076922,0.0,0.0,0.0010139,0.96244,298.11,308.1,285.3,298.16
145.31967,0.79515,0.0067629,0.0,0.0,0.00036236,0.94064,298.09,308.09,285.3,298.17
145.32099,0.8136,0.00854,0.0,0.0,0.0014627,0.96692,298.08,308.08,285.29,298.17
145.32231,0.82206,0.011116,0.0,0.0,0.00022461,0.9717,298.09,308.08,285.3,298.18
145.32363,0.79696,0.012251,0.0,0.0,0.0014093,0.93516,298.09,308.1,285.31,298.19
145.32495,0.81061,0.008978,0.0,0.0,0.00086418,0.95854,298.1,308.12,285.31,298.19
145.32627,0.81736,0.01272,0.0,0.0,0.00086064,0.96211,298.11,308.13,285.32,298.2
145.32759,0.80453,0.0099912,0.0,0.0,0.001561,0.94401,298.12,308.15,285.33,298.21
145.32891,0.8218,0.0079333,0.0,0.0,0.00067817,0.98191,298.13,308.17,285.34,298.22
145.33023,0.82015,0.0072597,0.0,0.0,0.001658,0.97335,298.13,308.18,285.35,298.23
145.33155,0.79738,0.0065941,0.0,0.0,0.00093202,0.94501,298.16,308.2,285.35,298.23
145.33287,0.8194,0.0058209,0.0,0.0,0.0010584,0.97104,298.27,308.21,285.35,298.23
145.33419,0.8162,0.0047497,0.0,0.0,0.00072471,0.97104,298.37,308.22,285.34,298.22
145.33551,0.79951,0.0083474,0.0,0.0,0.00090716,0.93534,298.48,308.23,285.34,298.22
145.33683,0.81738,0.012025,0.0,0.0,9.6539e-05,0.96813,298.58,308.25,285.34,298.22
145.33815,0.83135,0.0095349,0.0,0.0,0.0015617,0.98813,298.69,308.26,285.33,298.21
145.33947,0.81499,0.0098193,0.0,0.0,-8.3592e-06,0.97043,298.8,308.27,285.33,298.21
145.34079,0.81427,0.010922,0.0,0.0,0.0012701,0.97207,298.9,308.28,285.32,298.2
145.34211,0.78675,0.010277,0.0,0.0,0.00092035,0.94249,299.66,308.96,285.31,298.2
145.34343,0.82921,0.0087139,0.0,0.0,0.00080225,0.98824,300.77,310.01,285.29,298.2
145.34475,0.82637,0.0081561,0.0,0.0,0.0014356,0.96109,301.88,311.06,285.27,298.2
145.34607,1.0002,0.0072848,0.0,0.0,0.0010376,1.1118,303.0,312.12,285.25,298.2
145.34739,8.6854,0.055157,0.0,0.0,0.006554,8.7856,304.11,313.17,285.23,298.2
145.34871,30.335,0.23305,0.0,0.0,0.026689,35.123,305.23,314.22,285.21,298.2
145.35003,52.334,0.27037,0.0,0.0,0.02987,60.79,306.34,315.27,285.19,298.2
145.35135,71.452,0.351,0.0,0.0,0.039335,84.03,307.52,316.38,285.17,298.2
145.35267,84.565,0.42649,0.0,0.0,0.047712,99.768,309.4,318.16,285.16,298.18
145.35399,91.895,0.49613,0.0,0.0,0.054585,108.63,311.28,319.95,285.16,298.17
145.35531,99.888,0.62967,0.0,0.0,0.071764,118.16,313.16,321.73,285.16,298.15
145.35663,107.78,0.79041,0.0,0.0,0.088879,127.48,315.04,323.52,285.15,298.14
145.35795,112.9,0.99449,0.0,0.0,0.11479,133.83,316.92,325.3,285.15,298.12
145.35927,116.32,1.2217,0.0,0.0,0.14191,137.82,318.8,327.08,285.14,298.1
145.36059,119.3,1.4571,0.0,0.0,0.17277,141.46,320.68,328.87,285.14,298.09
145.36191,121.39,1.6977,0.0,0.0,0.20474,143.96,322.47,330.35,285.14,298.07
145.36323,122.73,1.9474,0.0,0.0,0.23801,145.56,324.19,331.57,285.14,298.05
145.36455,124.03,2.1868,0.0,0.0,0.27101,147.11,325.91,332.79,285.14,298.04
145.36587,125.23,2.4203,0.0,0.0,0.30484,148.56,327.62,334.0,285.14,298.02
145.36719,126.16,2.6472,0.0,0.0,0.33749,149.66,329.34,335.22,285.14,298.01
145.36851,127.1,2.8644,0.0,0.0,0.36978,150.79,331.06,336.43,285.14,297.99
145.36983,127.9,3.0678,0.0,0.0,0.40345,151.75,332.77,337.65,285.14,297.97
145.37115,128.62,3.2721,0.0,0.0,0.43292,152.56,334.49,338.87,285.14,297.96
145.37247,129.2,3.4749,0.0,0.0,0.46978,153.31,335.59,339.97,285.15,297.96
145.37379,129.94,3.6663,0.0,0.0,0.50069,154.17,336.67,341.06,285.16,297.97
145.37511,130.5,3.8579,0.0,0.0,0.53574,154.81,337.75,342.16,285.17,297.98
145.37643,131.03,4.0509,0.0,0.0,0.56992,155.47,338.83,343.26,285.19,297.99
145.37775,131.66,4.2373,0.0,0.0,0.60465,156.21,339.91,344.36,285.2,298.0
145.37907,132.1,4.4274,0.0,0.0,0.64216,156.72,340.99,345.45,285.21,298.01
145.38039,132.47,4.6219,0.0,0.0,0.68073,157.2,342.06,346.55,285.22,298.01
145.38171,132.92,4.8149,0.0,0.0,0.71802,157.73,342.86,347.76,285.24,298.02
145.38303,133.22,4.9993,0.0,0.0,0.75956,158.04,343.25,349.15,285.27,298.02
145.38435,133.48,5.1873,0.0,0.0,0.80037,158.39,343.63,350.54,285.3,298.02
145.38567,133.78,5.3764,0.0,0.0,0.84352,158.73,344.01,351.93,285.33,298.02
145.38699,134.02,5.5553,0.0,0.0,0.88847,159.02,344.39,353.32,285.36,298.02
145.38831,134.42,5.7374,0.0,0.0,0.93011,159.5,344.77,354.71,285.38,298.02
145.38963,134.81,5.9195,0.0,0.0,0.98149,159.94,345.15,356.09,285.41,298.02
145.39095,135.2,6.0988,0.0,0.0,1.028,160.42,345.54,357.48,285.44,298.02
145.39227,135.65,6.2699,0.0,0.0,1.0779,160.97,345.52,358.06,285.44,298.03
145.39359,136.16,6.4477,0.0,0.0,1.1313,161.55,345.43,358.48,285.42,298.03
145.39491,136.57,6.6245,0.0,0.0,1.1822,162.01,345.33,358.91,285.41,298.04
145.39623,137.07,6.793,0.0,0.0,1.2369,162.63,345.24,359.33,285.4,298.05
145.39755,137.68,6.9572,0.0,0.0,1.2964,163.35,345.15,359.76,285.39,298.06
145.39887,138.33,7.1223,0.0,0.0,1.3496,164.1,345.06,360.18,285.37,298.07
145.40019,139.1,7.2793,0.0,0.0,1.4147,165.02,344.96,360.61,285.36,298.07
145.40151,139.93,7.4292,0.0,0.0,1.4724,166.0,344.76,360.72,285.35,298.08
145.40283,140.83,7.5766,0.0,0.0,1.534,167.07,344.29,360.03,285.33,298.1
145.40415,135.97,7.7006,0.0,0.0,1.5951,162.24,343.81,359.33,285.31,298.12
145.40547,128.84,7.7092,0.0,0.0,1.5973,153.08,343.33,358.64,285.29,298.13
145.40679,125.72,7.7356,0.0,0.0,1.6169,149.36,342.85,357.95,285.27,298.15
145.40811,123.09,7.7491,0.0,0.0,1.6186,146.24,342.37,357.25,285.25,298.17
145.40943,120.91,7.7543,0.0,0.0,1.6182,143.62,341.89,356.56,285.23,298.18
145.41075,119.13,7.7562,0.0,0.0,1.6211,141.45,341.42,355.87,285.21,298.2
145.41207,117.52,7.7625,0.0,0.0,1.6212,139.55,340.98,355.22,285.2,298.2
145.41339,115.92,7.7704,0.0,0.0,1.621,137.6,340.57,354.6,285.2,298.2
145.41471,114.42,7.7718,0.0,0.0,1.63,135.84,340.16,353.98,285.2,298.2
145.41603,113.11,7.7759,0.0,0.0,1.623,134.3,339.74,353.36,285.2,298.2
145.41735,111.88,7.785,0.0,0.0,1.6329,132.82,339.33,352.74,285.2,298.2
145.41867,110.78,7.7794,0.0,0.0,1.6277,131.53,338.91,352.12,285.2,298.2
145.41999,109.85,7.7759,0.0,0.0,1.6273,130.41,338.5,351.49,285.2,298.2
145.42131,108.99,7.778,0.0,0.0,1.6327,129.38,338.1,350.9,285.2,298.2
145.42263,108.25,7.7797,0.0,0.0,1.6308,128.5,337.79,350.42,285.18,298.19
145.42395,107.62,7.777,0.0,0.0,1.6344,127.75,337.48,349.95,285.16,298.18
145.42527,106.94,7.7826,0.0,0.0,1.6366,126.94,337.16,349.48,285.13,298.18
145.42659,106.33,7.7886,0.0,0.0,1.6325,126.2,336.85,349.0,285.11,298.17
145.42791,105.77,7.7888,0.0,0.0,1.6349,125.55,336.53,348.53,285.09,298.16
145.42923,105.1,7.7864,0.0,0.0,1.6346,124.74,336.22,348.05,285.07,298.15
145.43055,104.22,7.7892,0.0,0.0,1.6298,123.74,335.91,347.58,285.05,298.14
145.43187,102.92,7.7881,0.0,0.0,1.6372,122.2,335.65,347.25,285.05,298.16
145.43319,100.84,7.7852,0.0,0.0,1.6291,119.75,335.42,347.0,285.05,298.19
145.43451,98.24,7.7844,0.0,0.0,1.6335,116.71,335.2,346.76,285.06,298.23
145.43583,94.897,7.7822,0.0,0.0,1.6299,112.9,334.97,346.52,285.06,298.26
145.43715,79.536,7.743,0.0,0.0,1.6143,95.83,334.75,346.28,285.06,298.29
145.43847,54.026,7.6933,0.0,0.0,1.5948,65.039,334.52,346.04,285.07,298.32
145.43979,28.797,7.6434,0.0,0.0,1.5706,35.675,334.29,345.8,285.07,298.36
145.44111,9.013,7.5938,0.0,0.0,1.5455,11.59,334.07,345.57,285.08,298.39
145.44243,-0.40257,7.5077,0.0,0.0,1.5148,-0.61842,333.96,345.57,285.1,298.39
145.44375,-0.33424,7.4553,0.0,0.0,1.4852,-0.32434,333.85,345.57,285.12,298.39
145.44507,0.11581,7.4231,0.0,0.0,1.4732,0.14892,333.73,345.58,285.14,298.39
145.44639,-0.13946,7.436,0.0,0.0,1.4815,-0.21572,333.62,345.58,285.16,298.39
145.44771,-0.36108,7.4897,0.0,0.0,1.4959,-0.37435,333.51,345.59,285.18,298.39
145.44903,0.23976,7.5587,0.0,0.0,1.5314,0.16972,333.4,345.59,285.2,298.39
145.45035,2.1014,7.5908,0.0,0.0,1.5431,2.8434,333.28,345.59,285.22,298.39
145.45167,-0.068582,7.5429,0.0,0.0,1.5258,-0.13042,333.19,345.62,285.23,298.37
145.45299,-0.031466,7.5681,0.0,0.0,1.5356,-0.099982,333.11,345.66,285.24,298.33
145.45431,1.5134,7.5855,0.0,0.0,1.5417,1.9799,333.03,345.7,285.25,298.29
145.45563,0.036449,7.5616,0.0,0.0,1.5321,0.025495,332.96,345.74,285.26,298.25
145.45695,1.2309,7.5815,0.0,0.0,1.5427,1.3822,332.88,345.78,285.27,298.2
145.45827,0.16208,7.5794,0.0,0.0,1.5346,0.22012,332.8,345.82,285.27,298.16
145.45959,0.62385,7.5807,0.0,0.0,1.5421,0.63894,332.73,345.86,285.28,298.12
145.46091,0.50349,7.576,0.0,0.0,1.5368,0.62619,332.65,345.9,285.29,298.08
145.46223,0.47533,7.5813,0.0,0.0,1.5399,0.5431,332.55,345.9,285.29,298.08
145.46355,0.67544,7.5797,0.0,0.0,1.5411,0.84397,332.44,345.91,285.29,298.09
145.46487,0.48416,7.5742,0.0,0.0,1.5348,0.55019,332.33,345.91,285.29,298.09
145.46619,0.57749,7.5779,0.0,0.0,1.5435,0.71407,332.22,345.92,285.29,298.1
145.46751,0.55487,7.5758,0.0,0.0,1.5383,0.64717,332.11,345.92,285.29,298.1
145.46883,0.55414,7.5701,0.0,0.0,1.5376,0.64994,332.0,345.92,285.29,298.1
145.47015,0.46132,7.5718,0.0,0.0,1.5405,0.54237,331.89,345.93,285.29,298.11
145.47147,0.62193,7.5784,0.0,0.0,1.5378,0.74837,331.79,345.94,285.29,298.11
145.47279,0.53108,7.5779,0.0,0.0,1.5358,0.6271,331.72,345.95,285.28,298.12
145.47411,0.50979,7.5773,0.0,0.0,1.5406,0.61044,331.64,345.97,285.27,298.13
145.47543,0.58595,7.5778,0.0,0.0,1.5339,0.69805,331.57,345.99,285.26,298.14
145.47675,0.56322,7.5752,0.0,0.0,1.5393,0.64935,331.49,346.0,285.26,298.15
145.47807,0.50551,7.5752,0.0,0.0,1.5359,0.59947,331.41,346.02,285.25,298.15
145.47939,0.57701,7.5753,0.0,0.0,1.5374,0.69566,331.34,346.03,285.24,298.16
145.48071,0.55668,7.5779,0.0,0.0,1.5407,0.64654,331.26,346.05,285.23,298.17
145.48203,0.50769,7.5732,0.0,0.0,1.5355,0.5951,331.2,346.05,285.23,298.17
145.48335,0.56014,7.5717,0.0,0.0,1.5433,0.63125,331.13,346.05,285.22,298.16
145.48467,0.54249,7.5711,0.0,0.0,1.5394,0.6384,331.07,346.05,285.22,298.16
145.48599,0.49928,7.5747,0.0,0.0,1.5376,0.59906,331.01,346.05,285.21,298.16
145.48731,0.57048,7.574,0.0,0.0,1.5393,0.67871,330.95,346.05,285.21,298.15
145.48863,0.54699,7.5756,0.0,0.0,1.5379,0.6344,330.89,346.05,285.21,298.15
145.48995,0.50822,7.5762,0.0,0.0,1.535,0.59146,330.83,346.05,285.2,298.14
145.49127,0.58255,7.5778,0.0,0.0,1.5407,0.68642,330.77,346.05,285.2,298.14
145.49259,0.60269,7.5743,0.0,0.0,1.5321,0.70333,330.69,346.05,285.2,298.15
145.49391,0.52118,7.5761,0.0,0.0,1.5389,0.60872,330.61,346.04,285.2,298.16
145.49523,0.55124,7.5783,0.0,0.0,1.5358,0.67473,330.54,346.04,285.2,298.17
145.49655,0.58052,7.5741,0.0,0.0,1.5367,0.67995,330.46,346.04,285.2,298.18
145.49787,0.50103,7.5715,0.0,0.0,1.5391,0.59629,330.39,346.03,285.2,298.18
145.49919,0.59001,7.574,0.0,0.0,1.5371,0.7042,330.31,346.03,285.2,298.19
145.50051,0.56626,7.5713,0.0,0.0,1.5388,0.65622,330.23,346.02,285.2,298.2
145.50183,0.52611,7.5726,0.0,0.0,1.5406,0.61754,330.18,346.03,285.2,298.21
145.50315,0.56554,7.5748,0.0,0.0,1.5358,0.67784,330.13,346.04,285.19,298.22
145.50447,0.56085,7.5779,0.0,0.0,1.5393,0.65105,330.09,346.05,285.19,298.22
145.50579,0.50546,7.576,0.0,0.0,1.5392,0.60858,330.04,346.07,285.18,298.23
145.50711,0.57368,7.5766,0.0,0.0,1.5346,0.69782,330.0,346.08,285.18,298.24
145.50843,0.57408,7.5787,0.0,0.0,1.5418,0.67192,329.96,346.09,285.18,298.25
145.50975,0.51205,7.5768,0.0,0.0,1.5347,0.59816,329.91,346.1,285.17,298.26
145.51107,0.54919,7.5757,0.0,0.0,1.5399,0.66112,329.87,346.11,285.17,298.26
145.51239,0.58758,7.5753,0.0,0.0,1.5363,0.68954,329.85,346.09,285.17,298.26
145.51371,0.52346,7.5734,0.0,0.0,1.5363,0.62818,329.83,346.07,285.18,298.26
145.51503,0.57354,7.5681,0.0,0.0,1.5378,0.68688,329.81,346.05,285.18,298.26
145.51635,0.55601,7.5719,0.0,0.0,1.5375,0.64163,329.79,346.03,285.19,298.26
145.51767,0.53324,7.576,0.0,0.0,1.5353,0.62364,329.77,346.01,285.19,298.26
145.51899,0.5609,7.5776,0.0,0.0,1.5414,0.66098,329.75,345.99,285.19,298.26
145.52031,0.56966,7.5747,0.0,0.0,1.5355,0.66916,329.73,345.97,285.2,298.26
145.52163,0.5875,7.5779,0.0,0.0,1.5391,0.6966,329.67,345.94,285.2,298.26
145.52295,0.63215,7.5774,0.0,0.0,1.5397,0.75504,329.59,345.89,285.21,298.25
145.52427,0.62371,7.5736,0.0,0.0,1.5347,0.73748,329.5,345.85,285.21,298.24
145.52559,0.59808,7.579,0.0,0.0,1.5428,0.70801,329.42,345.8,285.21,298.23
145.52691,0.69926,7.5772,0.0,0.0,1.5362,0.81648,329.33,345.76,285.22,298.23
145.52823,0.63119,7.5735,0.0,0.0,1.5401,0.73758,329.25,345.72,285.22,298.22
145.52955,0.62436,7.5701,0.0,0.0,1.5387,0.74811,329.16,345.67,285.23,298.21
145.53087,0.70654,7.5744,0.0,0.0,1.537,0.84815,329.08,345.63,285.23,298.2
145.53219,0.68141,7.5734,0.0,0.0,1.5366,0.79937,329.02,345.58,285.23,298.2
145.53351,0.61842,7.5735,0.0,0.0,1.5387,0.74904,328.95,345.54,285.23,298.2
145.53483,0.76602,7.5782,0.0,0.0,1.5338,0.90781,328.89,345.5,285.23,298.2
145.53615,0.72655,7.5773,0.0,0.0,1.5405,0.82161,328.82,345.45,285.23,298.2
145.53747,0.6088,7.5774,0.0,0.0,1.5359,0.73872,328.76,345.41,285.23,298.2
145.53879,0.77341,7.576,0.0,0.0,1.5386,0.92039,328.69,345.36,285.23,298.2
145.54011,0.70963,7.5789,0.0,0.0,1.5404,0.8272,328.63,345.32,285.23,298.2
145.54143,0.59719,7.5773,0.0,0.0,1.5369,0.72032,328.58,345.28,285.23,298.21
145.54275,0.81523,7.5761,0.0,0.0,1.5431,0.97975,328.55,345.25,285.23,298.23
145.54407,0.70268,7.5738,0.0,0.0,1.5382,0.81137,328.51,345.21,285.23,298.24
145.54539,0.58656,7.5733,0.0,0.0,1.538,0.71673,328.48,345.18,285.23,298.26
145.54671,0.80046,7.5733,0.0,0.0,1.5407,0.96028,328.45,345.15,285.23,298.27
145.54803,0.6859,7.5704,0.0,0.0,1.535,0.78558,328.42,345.12,285.23,298.29
145.54935,0.58679,7.5815,0.0,0.0,1.5372,0.70466,328.38,345.09,285.23,298.31
145.55067,0.80399,7.5761,0.0,0.0,1.5394,0.96056,328.35,345.05,285.23,298.32
145.55199,0.6685,7.5745,0.0,0.0,1.5323,0.76664,328.3,345.01,285.22,298.32
145.55331,0.59747,7.5778,0.0,0.0,1.541,0.72665,328.24,344.97,285.21,298.31
145.55463,0.79674,7.5775,0.0,0.0,1.5353,0.95981,328.19,344.93,285.21,298.3
145.55595,0.69152,7.5736,0.0,0.0,1.537,0.79768,328.13,344.89,285.2,298.29
145.55727,0.60231,7.5746,0.0,0.0,1.5392,0.72405,328.07,344.85,285.19,298.29
145.55859,0.79373,7.5759,0.0,0.0,1.5366,0.95061,328.02,344.81,285.18,298.28
145.55991,0.67433,7.5666,0.0,0.0,1.5404,0.75903,327.96,344.77,285.17,298.27
145.56123,0.59896,7.5678,0.0,0.0,1.5399,0.72192,327.91,344.73,285.17,298.26
145.56255,0.80091,7.5741,0.0,0.0,1.5362,0.94861,327.87,344.68,285.17,298.26
145.56387,0.67307,7.5734,0.0,0.0,1.5391,0.77045,327.83,344.63,285.18,298.26
145.56519,0.60028,7.5724,0.0,0.0,1.5367,0.73099,327.79,344.57,285.18,298.26
145.56651,0.79027,7.5753,0.0,0.0,1.5353,0.95037,327.75,344.52,285.19,298.26
145.56783,0.67567,7.5741,0.0,0.0,1.5392,0.78683,327.71,344.47,285.19,298.26
145.56915,0.60722,7.5744,0.0,0.0,1.5326,0.74541,327.67,344.42,285.19,298.26
145.57047,0.80394,7.5756,0.0,0.0,1.54,0.96033,327.63,344.36,285.2,298.26
145.57179,0.68979,7.575,0.0,0.0,1.533,0.77217,327.59,344.32,285.2,298.28
145.57311,0.5967,7.5725,0.0,0.0,1.5363,0.71854,327.56,344.28,285.2,298.31
145.57443,0.80679,7.5687,0.0,0.0,1.5381,0.96509,327.53,344.24,285.2,298.33
145.57575,0.69304,7.5713,0.0,0.0,1.5359,0.80052,327.5,344.2,285.2,298.36
145.57707,0.60823,7.5713,0.0,0.0,1.5368,0.73662,327.46,344.16,285.2,298.38
145.57839,0.78218,7.5727,0.0,0.0,1.5401,0.94824,327.43,344.12,285.2,298.4
145.57971,0.68337,7.5708,0.0,0.0,1.5339,0.79418,327.4,344.08,285.2,298.43
145.58103,0.59319,7.5777,0.0,0.0,1.54,0.72732,327.36,344.04,285.2,298.45
145.58235,0.79711,7.5746,0.0,0.0,1.5375,0.94974,327.32,343.98,285.2,298.47
145.58367,0.67807,7.5734,0.0,0.0,1.535,0.76439,327.27,343.92,285.2,298.48
145.58499,0.59099,7.5761,0.0,0.0,1.5409,0.71475,327.22,343.86,285.2,298.5
145.58631,0.78892,7.5772,0.0,0.0,1.535,0.93839,327.17,343.79,285.2,298.52
145.58763,0.68854,7.5686,0.0,0.0,1.5384,0.80001,327.12,343.73,285.2,298.53
145.58895,0.61114,7.5764,0.0,0.0,1.5378,0.74408,327.07,343.67,285.2,298.55
145.59027,0.7787,7.5699,0.0,0.0,1.5347,0.9337,327.02,343.61,285.2,298.56
145.59159,0.66755,7.5708,0.0,0.0,1.538,0.77421,326.97,343.55,285.19,298.56
145.59291,0.59881,7.5679,0.0,0.0,1.5358,0.73082,326.92,343.48,285.18,298.53
145.59423,0.80674,7.5797,0.0,0.0,1.5353,0.95398,326.86,343.41,285.17,298.51
145.59555,0.67356,7.5733,0.0,0.0,1.5389,0.77533,326.8,343.34,285.15,298.48
145.59687,0.59976,7.5759,0.0,0.0,1.5352,0.72272,326.75,343.28,285.14,298.46
145.59819,0.786,7.5744,0.0,0.0,1.5384,0.94819,326.69,343.21,285.13,298.43
145.59951,0.6757,7.5761,0.0,0.0,1.5382,0.78907,326.63,343.14,285.12,298.41
145.60083,0.5964,7.5743,0.0,0.0,1.5352,0.72408,326.58,343.07,285.11,298.39
145.60215,0.79728,7.5753,0.0,0.0,1.5421,0.9597,326.53,343.01,285.1,298.4
145.60347,0.66421,7.5739,0.0,0.0,1.5359,0.76302,326.48,342.95,285.1,298.4
145.60479,0.59005,7.5707,0.0,0.0,1.5398,0.71209,326.43,342.89,285.09,298.41
145.60611,0.79863,7.5668,0.0,0.0,1.5389,0.95617,326.38,342.83,285.09,298.42
145.60743,0.68512,7.5694,0.0,0.0,1.5347,0.78144,326.34,342.77,285.09,298.43
145.60875,0.59018,7.5754,0.0,0.0,1.5369,0.71519,326.29,342.71,285.08,298.44
145.61007,0.80002,7.5757,0.0,0.0,1.5391,0.95322,326.24,342.65,285.08,298.44
145.61139,0.67225,7.5736,0.0,0.0,1.5326,0.76659,326.19,342.58,285.08,298.46
145.61271,0.60831,7.5775,0.0,0.0,1.5406,0.74563,326.15,342.5,285.09,298.48
145.61403,0.78528,7.5762,0.0,0.0,1.534,0.94138,326.11,342.43,285.11,298.51
145.61535,0.68738,7.573,0.0,0.0,1.5375,0.80598,326.07,342.35,285.12,298.53
145.61667,0.58806,7.5781,0.0,0.0,1.5393,0.71394,326.03,342.27,285.13,298.56
145.61799,0.80629,7.5781,0.0,0.0,1.5365,0.95886,325.99,342.2,285.14,298.58
145.61931,0.67615,7.5709,0.0,0.0,1.5421,0.76207,325.95,342.12,285.16,298.61
145.62063,0.61948,7.5724,0.0,0.0,1.5389,0.74804,325.91,342.05,285.17,298.63
145.62195,0.78237,7.574,0.0,0.0,1.5384,0.93458,325.88,341.99,285.16,298.62
145.62327,0.68437,7.57,0.0,0.0,1.5391,0.79692,325.85,341.93,285.15,298.61
145.62459,0.61268,7.5729,0.0,0.0,1.5373,0.74471,325.81,341.88,285.14,298.6
145.62591,0.80403,7.578,0.0,0.0,1.5368,0.96876,325.78,341.82,285.14,298.58
145.62723,0.66654,7.5768,0.0,0.0,1.5396,0.77633,325.75,341.76,285.13,298.57
145.62855,0.61174,7.5754,0.0,0.0,1.5332,0.74274,325.72,341.71,285.12,298.56
145.62987,0.80609,7.5766,0.0,0.0,1.5411,0.95405,325.69,341.65,285.11,298.55
145.63119,0.6808,7.5776,0.0,0.0,1.5335,0.7701,325.64,341.6,285.11,298.53
145.63251,0.61152,7.575,0.0,0.0,1.5378,0.74038,325.59,341.56,285.12,298.52
145.63383,0.79932,7.5746,0.0,0.0,1.5386,0.94628,325.53,341.51,285.13,298.5
145.63515,0.68327,7.5725,0.0,0.0,1.5355,0.78516,325.47,341.47,285.13,298.49
145.63647,0.61839,7.5725,0.0,0.0,1.5412,0.75017,325.42,341.42,285.14,298.47
145.63779,0.8074,7.5683,0.0,0.0,1.5393,0.9725,325.36,341.38,285.15,298.45
145.63911,0.68742,7.5718,0.0,0.0,1.5353,0.80034,325.31,341.33,285.16,298.44
145.64043,0.60301,7.5767,0.0,0.0,1.5407,0.7135,325.25,341.29,285.17,298.42
145.64175,0.80939,7.5767,0.0,0.0,1.538,0.95679,325.19,341.22,285.18,298.42
145.64307,0.6866,7.5737,0.0,0.0,1.5354,0.78501,325.12,341.14,285.18,298.42
145.64439,0.61236,7.578,0.0,0.0,1.5409,0.7394,325.06,341.05,285.19,298.43
145.64571,0.79377,7.5777,0.0,0.0,1.5345,0.94282,324.99,340.97,285.2,298.43
145.64703,0.68993,7.5729,0.0,0.0,1.5401,0.79849,324.93,340.89,285.21,298.44
145.64835,0.61336,7.5769,0.0,0.0,1.5348,0.75375,324.86,340.81,285.22,298.44
145.64967,0.81007,7.5751,0.0,0.0,1.5375,0.9563,324.8,340.73,285.22,298.45
145.65099,0.67584,7.5661,0.0,0.0,1.5368,0.77849,324.74,340.66,285.23,298.45
145.65231,0.61236,7.5712,0.0,0.0,1.5368,0.72134,324.7,340.59,285.24,298.48
145.65363,0.79121,7.5747,0.0,0.0,1.5367,0.94167,324.66,340.52,285.24,298.5
145.65495,0.69424,7.5736,0.0,0.0,1.5395,0.78982,324.62,340.45,285.24,298.53
145.65627,0.61972,7.5741,0.0,0.0,1.535,0.75597,324.58,340.38,285.25,298.55
145.65759,0.7829,7.578,0.0,0.0,1.5401,0.94441,324.54,340.31,285.25,298.58
145.65891,0.68324,7.5754,0.0,0.0,1.5371,0.78856,324.5,340.25,285.26,298.6
145.66023,0.60455,7.5755,0.0,0.0,1.5365,0.75866,324.46,340.18,285.26,298.63
145.66155,0.81374,7.5764,0.0,0.0,1.5417,0.98344,324.42,340.12,285.27,298.63
145.66287,0.67201,7.5787,0.0,0.0,1.5357,0.76966,324.39,340.07,285.27,298.63
145.66419,0.61229,7.573,0.0,0.0,1.5406,0.73868,324.36,340.02,285.28,298.63
145.66551,0.79396,7.5735,0.0,0.0,1.5382,0.93966,324.33,339.96,285.29,298.63
145.66683,0.67964,7.5701,0.0,0.0,1.5357,0.78679,324.3,339.91,285.3,298.63
145.66815,0.61051,7.574,0.0,0.0,1.5383,0.73496,324.26,339.86,285.31,298.63
145.66947,0.80326,7.5702,0.0,0.0,1.5366,0.94816,324.23,339.81,285.32,298.63
145.67079,0.6837,7.5755,0.0,0.0,1.5343,0.78592,324.2,339.75,285.32,298.63
145.67211,0.59862,7.5774,0.0,0.0,1.5405,0.74128,324.18,339.69,285.32,298.62
145.67343,0.80664,7.5768,0.0,0.0,1.5345,0.96284,324.15,339.62,285.32,298.61
145.67475,0.6958,7.5724,0.0,0.0,1.5385,0.80202,324.13,339.56,285.32,298.61
145.67607,0.60633,7.5781,0.0,0.0,1.5382,0.73815,324.1,339.5,285.32,298.6
145.67739,0.79046,7.5768,0.0,0.0,1.5362,0.93979,324.08,339.43,285.32,298.59
145.67871,0.69653,7.5716,0.0,0.0,1.5409,0.79219,324.05,339.37,285.32,298.58
145.68003,0.60418,7.575,0.0,0.0,1.5373,0.73106,324.03,339.3,285.32,298.57
145.68135,0.80741,7.5731,0.0,0.0,1.5397,0.9627,324.01,339.24,285.32,298.58
145.68267,0.68133,7.5694,0.0,0.0,1.5395,0.79148,323.98,339.17,285.3,298.58
145.68399,0.61052,7.5703,0.0,0.0,1.536,0.74474,323.96,339.1,285.29,298.59
145.68531,0.79852,7.5791,0.0,0.0,1.5381,0.95121,323.93,339.03,285.28,298.6
145.68663,0.69115,7.5741,0.0,0.0,1.5378,0.80124,323.91,338.96,285.27,298.61
145.68795,0.6224,7.5761,0.0,0.0,1.534,0.75611,323.89,338.9,285.25,298.62
145.68927,0.79859,7.5768,0.0,0.0,1.5407,0.95166,323.86,338.83,285.24,298.62
145.69059,0.69231,7.5775,0.0,0.0,1.5333,0.78677,323.84,338.76,285.23,298.63
145.69191,0.62495,7.5752,0.0,0.0,1.5388,0.7533,323.79,338.68,285.22,298.65
145.69323,0.8045,7.5778,0.0,0.0,1.5391,0.96383,323.74,338.6,285.21,298.67
145.69455,0.68294,7.5763,0.0,0.0,1.5352,0.80123,323.69,338.52,285.19,298.68
145.69587,0.61791,7.5713,0.0,0.0,1.5433,0.74892,323.64,338.44,285.18,298.7
145.69719,0.79985,7.5696,0.0,0.0,1.5388,0.9636,323.59,338.36,285.17,298.71
145.69851,0.6917,7.5728,0.0,0.0,1.5376,0.80398,323.55,338.28,285.16,298.73
145.69983,0.61251,7.5732,0.0,0.0,1.5403,0.7334,323.5,338.2,285.14,298.75
145.70115,0.80182,7.5767,0.0,0.0,1.5379,0.95654,323.45,338.12,285.13,298.76
145.70247,0.69189,7.5747,0.0,0.0,1.5363,0.80239,323.4,338.06,285.12,298.78
145.70379,0.6106,7.5782,0.0,0.0,1.5402,0.7285,323.35,338.0,285.11,298.8
145.70511,0.81141,7.5767,0.0,0.0,1.5338,0.97211,323.3,337.94,285.1,298.81
145.70643,0.68987,7.5733,0.0,0.0,1.5407,0.81215,323.26,337.88,285.08,298.83
145.70775,0.60821,7.5787,0.0,0.0,1.5335,0.74934,323.21,337.82,285.07,298.84
145.70907,0.80939,7.576,0.0,0.0,1.5379,0.9651,323.16,337.76,285.06,298.86
145.71039,0.70292,7.5706,0.0,0.0,1.5376,0.80956,323.11,337.7,285.05,298.88
145.71171,0.61993,7.5738,0.0,0.0,1.5365,0.75873,323.09,337.64,285.05,298.88
145.71303,0.79382,7.5729,0.0,0.0,1.5391,0.95397,323.07,337.57,285.06,298.88
145.71435,0.70592,7.5694,0.0,0.0,1.5388,0.80903,323.05,337.51,285.07,298.88
145.71567,0.61842,7.5728,0.0,0.0,1.5356,0.75076,323.03,337.45,285.08,298.88
145.71699,0.80632,7.5777,0.0,0.0,1.5406,0.95451,323.01,337.38,285.09,298.88
145.71831,0.69572,7.5765,0.0,0.0,1.5367,0.80668,322.99,337.32,285.09,298.88
145.71963,0.61249,7.5749,0.0,0.0,1.5374,0.74679,322.97,337.25,285.1,298.88
145.72095,0.80693,7.5772,0.0,0.0,1.5408,0.96485,322.94,337.19,285.11,298.88
145.72227,0.6933,7.5773,0.0,0.0,1.5345,0.79863,322.91,337.13,285.12,298.88
145.72359,0.62353,7.574,0.0,0.0,1.5412,0.75465,322.88,337.07,285.13,298.88
145.72491,0.79227,7.5753,0.0,0.0,1.5356,0.94329,322.85,337.01,285.13,298.88
145.72623,0.68621,7.5743,0.0,0.0,1.5371,0.79148,322.81,336.95,285.14,298.88
145.72755,0.62142,7.5703,0.0,0.0,1.5386,0.74334,322.78,336.89,285.15,298.88
145.72887,0.82958,7.5711,0.0,0.0,1.5371,0.99178,322.75,336.83,285.16,298.88
145.73019,0.68176,7.5718,0.0,0.0,1.5346,0.8008,322.72,336.77,285.17,298.88
145.73151,0.62314,7.577,0.0,0.0,1.5405,0.75893,322.68,336.71,285.17,298.89
145.73283,0.80438,7.5755,0.0,0.0,1.5347,0.96599,322.64,336.65,285.18,298.91
145.73415,0.69083,7.5754,0.0,0.0,1.5399,0.80963,322.6,336.6,285.18,298.92
145.73547,0.61904,7.5783,0.0,0.0,1.5375,0.74564,322.56,336.54,285.18,298.94
145.73679,0.80679,7.5761,0.0,0.0,1.5372,0.96114,322.52,336.49,285.19,298.96
145.73811,0.68771,7.5749,0.0,0.0,1.5411,0.793,322.48,336.43,285.19,298.97
145.73943,0.61449,7.5785,0.0,0.0,1.5362,0.74449,322.44,336.37,285.2,298.99
145.74075,0.8195,7.5742,0.0,0.0,1.5411,0.98552,322.39,336.31,285.2,299.0
145.74207,0.70326,7.5687,0.0,0.0,1.538,0.81543,322.34,336.25,285.21,299.01
145.74339,0.60971,7.5709,0.0,0.0,1.5373,0.73447,322.29,336.18,285.22,299.02
145.74471,0.79896,7.5762,0.0,0.0,1.5395,0.96021,322.24,336.11,285.23,299.03
145.74603,0.69444,7.5708,0.0,0.0,1.537,0.80615,322.18,336.04,285.23,299.04
145.74735,0.61794,7.5753,0.0,0.0,1.5349,0.74923,322.13,335.97,285.24,299.04
145.74867,0.79676,7.5786,0.0,0.0,1.541,0.9468,322.08,335.9,285.25,299.05
145.74999,0.70147,7.5736,0.0,0.0,1.5316,0.80178,322.03,335.84,285.26,299.06
145.75131,0.61701,7.5744,0.0,0.0,1.54,0.74558,321.97,335.78,285.26,299.06
145.75263,0.80791,7.5782,0.0,0.0,1.5379,0.97026,321.92,335.73,285.25,299.06
145.75395,0.7009,7.577,0.0,0.0,1.5359,0.81586,321.87,335.67,285.25,299.06
145.75527,0.62945,7.5731,0.0,0.0,1.542,0.76903,321.82,335.62,285.25,299.06
145.75659,0.80695,7.5746,0.0,0.0,1.5383,0.96629,321.76,335.57,285.24,299.06
145.75791,0.69583,7.5711,0.0,0.0,1.5384,0.80022,321.71,335.52,285.24,299.06
145.75923,0.62339,7.572,0.0,0.0,1.5398,0.7538,321.66,335.46,285.23,299.06
145.76055,0.82089,7.5719,0.0,0.0,1.5372,0.98318,321.61,335.41,285.23,299.06
145.76187,0.69545,7.5758,0.0,0.0,1.5381,0.78836,321.58,335.36,285.23,299.07
145.76319,0.62664,7.5791,0.0,0.0,1.5393,0.74235,321.55,335.3,285.24,299.08
145.76451,0.8148,7.5762,0.0,0.0,1.5342,0.98636,321.53,335.24,285.24,299.09
145.76583,0.69692,7.5735,0.0,0.0,1.5399,0.81436,321.5,335.19,285.25,299.1
145.76715,0.62967,7.5784,0.0,0.0,1.5331,0.75467,321.47,335.13,285.25,299.1
145.76847,0.81939,7.576,0.0,0.0,1.539,0.97861,321.44,335.07,285.26,299.11
145.76979,0.70671,7.5753,0.0,0.0,1.5379,0.80827,321.41,335.02,285.26,299.12
145.77111,0.62876,7.5753,0.0,0.0,1.536,0.75776,321.39,334.96,285.26,299.13
145.77243,0.81977,7.5757,0.0,0.0,1.5424,0.97514,321.36,334.9,285.25,299.15
145.77375,0.70785,7.5661,0.0,0.0,1.5373,0.82331,321.34,334.84,285.25,299.16
145.77507,0.61751,7.5734,0.0,0.0,1.5374,0.74861,321.31,334.78,285.25,299.18
145.77639,0.81057,7.5766,0.0,0.0,1.5403,0.97195,321.29,334.72,285.24,299.2
145.77771,0.70856,7.5746,0.0,0.0,1.5369,0.82718,321.27,334.66,285.24,299.21
145.77903,0.62678,7.5756,0.0,0.0,1.5389,0.75843,321.24,334.6,285.23,299.23
145.78035,0.80641,7.5782,0.0,0.0,1.5399,0.9566,321.22,334.54,285.23,299.25
145.78167,0.70002,7.576,0.0,0.0,1.5342,0.80803,321.18,334.47,285.23,299.25
145.78299,0.62946,7.5734,0.0,0.0,1.5414,0.75126,321.15,334.4,285.24,299.26
145.78431,0.81779,7.5799,0.0,0.0,1.5341,0.96241,321.12,334.33,285.24,299.27
145.78563,0.69587,7.5738,0.0,0.0,1.5364,0.80213,321.09,334.26,285.25,299.28
145.78695,0.63508,7.5738,0.0,0.0,1.5396,0.76226,321.06,334.19,285.25,299.29
145.78827,0.81063,7.5695,0.0,0.0,1.5355,0.96368,321.02,334.12,285.25,299.29
145.78959,0.69554,7.5733,0.0,0.0,1.5386,0.79365,320.99,334.06,285.26,299.3
145.79091,0.64203,7.5719,0.0,0.0,1.5383,0.7697,320.95,333.98,285.26,299.31
145.79223,0.81017,7.5747,0.0,0.0,1.5358,0.96912,320.91,333.91,285.24,299.31
145.79355,0.6928,7.5756,0.0,0.0,1.5403,0.80582,320.87,333.83,285.23,299.31
145.79487,0.64046,7.5791,0.0,0.0,1.5371,0.76997,320.82,333.75,285.22,299.31
145.79619,0.82284,7.5749,0.0,0.0,1.5381,0.99213,320.78,333.68,285.21,299.31
145.79751,0.71302,7.5757,0.0,0.0,1.5402,0.81786,320.73,333.6,285.19,299.31
145.79883,0.61742,7.5775,0.0,0.0,1.5347,0.74307,320.69,333.53,285.18,299.31
145.80015,0.81861,7.5768,0.0,0.0,1.5421,0.9934,320.64,333.45,285.17,299.31
145.80147,0.71494,7.5723,0.0,0.0,1.5358,0.82697,320.61,333.38,285.17,299.31
145.80279,0.61958,7.574,0.0,0.0,1.5384,0.7505,320.58,333.32,285.16,299.32
145.80411,0.81391,7.5743,0.0,0.0,1.5396,0.97306,320.55,333.25,285.16,299.33
145.80543,0.7001,7.5698,0.0,0.0,1.5359,0.79629,320.51,333.19,285.15,299.34
145.80675,0.62402,7.5734,0.0,0.0,1.5358,0.75648,320.48,333.12,285.15,299.35
145.80807,0.8209,7.5803,0.0,0.0,1.5395,0.98564,320.45,333.06,285.14,299.36
145.80939,0.71842,7.5743,0.0,0.0,1.5328,0.84008,320.42,333.0,285.14,299.36
145.81071,0.6224,7.5758,0.0,0.0,1.5404,0.75764,320.38,332.93,285.15,299.37
145.81203,0.80171,7.5796,0.0,0.0,1.5373,0.96538,320.35,332.87,285.17,299.38
145.81335,0.71546,7.5757,0.0,0.0,1.5369,0.82103,320.32,332.81,285.2,299.39
146.21373,0.68132,7.5756,0.0,0.0,1.5382,0.80853,311.31,318.21,287.04,298.37
147.01373,0.62767,7.5781,0.0,0.0,1.5393,0.74537,268.9,280.16,286.82,266.86
147.81373,0.60027,7.5823,0.0,0.0,1.541,0.71346,226.24,244.22,276.3,247.88
148.61373,0.57569,7.5844,0.0,0.0,1.542,0.68314,189.51,201.56,262.24,227.43
149.41373,0.57334,7.585,0.0,0.0,1.5421,0.68011,129.27,159.43,243.16,204.33
150.1364,0.53232,7.5776,0.0,0.0,1.5389,0.63171,93.501,126.25,218.02,167.31
150.9364,0.50152,7.5604,0.0,0.0,1.5316,0.5954,79.034,98.985,184.82,89.023
151.7364,0.5056,7.5581,0.0,0.0,1.5306,0.59995,69.031,86.111,95.649,62.23
152.5364,0.50485,7.5563,0.0,0.0,1.5298,0.59983,61.318,79.778,78.584,48.152
153.3364,0.5039,7.5556,0.0,0.0,1.5295,0.59746,54.49,71.66,64.151,40.552
154.1364,0.49857,7.5549,0.0,0.0,1.5293,0.59236,48.075,62.902,53.233,35.326
154.9364,0.49368,7.5541,0.0,0.0,1.5288,0.58646,43.481,57.275,45.479,32.748
155.7364,0.48832,7.5535,0.0,0.0,1.5287,0.57975,40.477,51.958,40.352,30.794
156.5364,0.48398,7.5528,0.0,0.0,1.5283,0.57421,37.69,47.869,36.666,29.044
157.3364,0.4816,7.552,0.0,0.0,1.528,0.57046,35.564,44.3,34.098,28.044
158.1364,0.48107,7.5514,0.0,0.0,1.5278,0.57002,34.485,42.401,32.21,27.336
158.9364,0.48018,7.5506,0.0,0.0,1.5275,0.56983,34.033,41.256,31.137,27.464
159.7364,0.47972,7.5502,0.0,0.0,1.5272,0.56885,34.073,40.475,30.732,27.934
160.5364,0.47994,7.5492,0.0,0.0,1.5268,0.56837,33.953,39.731,30.655,28.313
161.3364,0.46533,6.6257,0.0,0.0,1.1867,0.55187,33.423,38.446,30.891,29.639
162.1364,0.4637,6.5113,0.0,0.0,1.1507,0.55039,33.465,38.575,31.623,30.974
162.7364,0.46056,6.4635,0.0,0.0,1.136,0.54589,33.767,38.575,32.405,31.813