File: examples/dan-msc-case-studies/CS4/data/01 raw data/hyde_test_037.csv
Time(sec),Force(kN),Jaw(mm),PowAngle(deg),PTemp,Strain,Stress(MPa),TC1(C),TC2(C),TC3(C)
0.0,4.8772,0.0020123,0.0,0.0041682,0.00012274,14.815,21.248,21.54,21.403
0.6,4.6157,0.00084297,0.0,1.6211,7.558e-05,14.0,21.231,21.582,21.427
1.2,4.433,0.00029203,0.0,3.4211,0.0001275,13.451,21.251,21.565,21.436
1.8,4.2677,0.00019506,0.0,5.2211,-1.9504e-05,12.945,21.226,21.502,21.4
2.4,4.164,-0.00025219,0.0,7.0211,1.3692e-05,12.635,21.176,21.565,21.423
3.0,4.0903,-0.00023913,0.0,8.8211,3.0774e-05,12.408,21.228,21.607,21.433
3.6,4.073,-0.00028726,0.0,10.621,-4.2659e-05,12.358,21.252,21.572,21.423
4.2,4.055,-1.9725e-05,0.0,12.421,-3.786e-05,12.3,21.251,21.538,21.408
4.8,4.0588,-0.0002781,0.0,14.221,-6.2795e-05,12.315,21.267,21.618,21.409
5.4,4.0374,-0.00031959,0.0,16.021,3.2139e-05,12.247,21.226,21.58,21.39
6.0,4.0451,7.8903e-05,0.0,17.821,-4.3935e-05,12.273,21.273,21.564,21.44
6.6,4.0277,-8.5149e-05,0.0,19.621,1.8199e-05,12.22,21.095,21.457,21.284
7.2,4.0386,-0.00017132,0.0,21.421,6.2327e-05,12.254,21.286,21.555,21.381
7.8,4.0386,0.0010851,20.651,23.221,0.00010512,12.25,21.331,21.674,21.637
8.3071,4.0692,0.00050662,28.506,24.755,0.00011472,12.351,21.99,22.597,22.949
8.9071,4.0683,-0.00015809,28.382,26.542,-4.6716e-05,12.339,24.404,25.307,26.427
9.5071,4.0763,-0.00014307,23.34,28.342,1.5218e-05,12.37,27.551,28.172,29.354
10.1071,4.0628,-0.00052642,20.705,30.142,-5.8384e-05,12.325,29.795,29.753,30.6
10.7071,4.0837,-0.00096827,25.02,31.942,-8.7249e-05,12.392,31.067,31.38,31.459
11.3071,4.0841,-0.0013866,27.741,33.742,-0.00021282,12.387,32.615,38.759,33.222
11.9071,4.0866,-0.0024371,27.353,35.542,-0.00027214,12.401,34.739,38.761,35.664
12.5071,4.0801,-0.0031706,25.312,37.342,-0.0002514,12.376,37.064,38.761,37.704
13.1071,4.0858,-0.0032048,25.894,39.142,-0.00039189,12.398,38.841,38.413,39.2
13.5077,4.0924,-0.0038074,26.19,40.344,-0.000425,12.414,39.966,39.343,40.252
14.1077,4.0874,-0.0049799,27.592,42.144,-0.00051455,12.403,41.686,41.063,42.07
14.7077,4.0925,-0.00514,26.834,43.944,-0.00063144,12.412,43.728,42.971,44.085
15.3077,4.087,-0.005957,26.331,45.744,-0.00064709,12.401,45.616,44.648,45.795
15.9077,4.0996,-0.0068242,26.668,47.544,-0.00065865,12.435,47.401,46.233,47.35
16.5077,4.0942,-0.0074254,27.597,49.344,-0.00084236,12.424,49.081,47.876,49.049
17.1077,4.0997,-0.0082319,27.472,51.144,-0.00086562,12.432,51.017,49.762,51.017
17.7077,4.0964,-0.0087135,27.2,52.944,-0.0009566,12.43,52.901,51.572,52.829
18.3077,4.1007,-0.0095186,27.752,54.744,-0.0010276,12.434,54.613,53.282,54.504
18.9077,4.0945,-0.0098727,27.486,56.544,-0.0011394,12.424,56.453,54.996,56.25
19.5077,4.1,-0.010862,27.747,58.344,-0.001197,12.435,58.188,56.69,58.024
20.1077,4.103,-0.011608,27.867,60.144,-0.0011785,12.449,60.048,58.401,59.773
20.7077,4.1059,-0.012349,27.788,61.944,-0.0013903,12.455,61.866,60.122,61.554
21.3077,4.1014,-0.013303,27.976,63.744,-0.0014149,12.446,63.703,61.794,63.386
21.9077,4.1123,-0.013704,27.89,65.544,-0.0014864,12.474,65.519,63.501,65.194
22.5077,4.1087,-0.014764,28.107,67.344,-0.0015986,12.467,67.309,65.185,66.942
23.1077,4.1127,-0.01492,28.545,69.144,-0.0016968,12.474,69.079,66.897,68.711
23.7077,4.1169,-0.015711,28.465,70.944,-0.0017042,12.492,70.909,68.714,70.581
24.3077,4.1121,-0.01661,28.169,72.744,-0.0017328,12.471,72.721,70.364,72.234
24.9077,4.1206,-0.016919,28.678,74.544,-0.001874,12.504,74.447,71.912,73.886
25.5077,4.1217,-0.017779,28.716,76.344,-0.0019193,12.501,76.233,73.644,75.699
26.1077,4.1203,-0.018875,28.875,78.144,-0.0020737,12.505,78.05,75.531,77.581
26.7077,4.1153,-0.019879,28.767,79.944,-0.0021461,12.481,79.902,77.177,79.275
27.3077,4.1261,-0.020602,29.055,81.744,-0.0023184,12.519,81.662,78.822,81.062
27.9077,4.1185,-0.021902,29.571,83.544,-0.0023804,12.493,83.415,80.535,82.874
28.5077,4.1269,-0.023445,28.879,85.344,-0.0024794,12.522,85.405,82.24,84.789
29.1077,4.1181,-0.023903,29.48,87.144,-0.0026236,12.489,87.11,83.92,86.363
29.7077,4.1272,-0.024914,29.352,88.944,-0.0027044,12.522,88.874,85.623,88.162
30.3077,4.1272,-0.025563,29.654,90.744,-0.002805,12.519,90.673,87.435,90.051
30.9077,4.1385,-0.02613,29.159,92.544,-0.0028053,12.557,92.572,89.285,91.838
31.5077,4.1216,-0.026385,29.708,94.344,-0.0029398,12.502,94.297,90.837,93.41
32.1077,4.1264,-0.027106,29.795,96.144,-0.0029297,12.52,96.059,92.504,95.225
32.70771,4.125,-0.027888,29.784,97.944,-0.0029663,12.512,97.925,94.352,97.124
33.30771,4.1368,-0.028329,29.795,99.744,-0.003096,12.552,99.764,96.063,98.955
33.90771,4.1238,-0.028928,29.57,101.54,-0.0031665,12.509,101.54,97.742,100.69
34.50771,4.142,-0.029849,30.246,103.34,-0.0032824,12.568,103.24,99.388,102.35
35.10771,4.1288,-0.030992,30.051,105.14,-0.003331,12.525,105.07,101.22,104.18
35.70771,4.1389,-0.031465,30.198,106.94,-0.0034851,12.556,106.92,102.91,105.99
36.30771,4.1264,-0.032594,29.992,108.74,-0.0035148,12.517,108.73,104.58,107.77
36.90771,4.1425,-0.033439,30.156,110.54,-0.0035871,12.568,110.54,106.31,109.55
37.50771,4.1317,-0.034255,30.41,112.34,-0.00375,12.534,112.26,108.02,111.24
38.10771,4.1467,-0.035285,30.798,114.14,-0.0038868,12.582,114.1,109.72,113.13
38.70771,4.1279,-0.035972,29.904,115.94,-0.0039516,12.521,116.0,111.46,115.01
39.30771,4.1472,-0.037217,30.939,117.74,-0.0039831,12.581,117.6,112.98,116.41
39.90771,4.1372,-0.037698,30.496,119.54,-0.0041592,12.55,119.58,115.0,118.7
40.50771,4.1361,-0.038325,30.056,121.34,-0.0041423,12.546,121.46,116.8,120.26
40.9391,4.1489,-0.039077,30.858,122.65,-0.0043307,12.585,122.54,117.85,121.22
41.5391,4.1351,-0.040332,31.605,124.44,-0.0044094,12.543,124.24,119.6,123.23
42.1391,4.1422,-0.041381,30.167,126.24,-0.0044145,12.566,126.34,121.51,125.36
42.7391,4.1379,-0.041973,30.793,128.04,-0.0046045,12.555,128.05,123.18,126.81
43.3391,4.1497,-0.043105,31.868,129.84,-0.0046755,12.586,129.64,124.79,128.52
43.9391,4.1472,-0.044037,30.921,131.64,-0.004816,12.583,131.7,126.59,130.91
44.5391,4.1536,-0.04492,30.638,133.44,-0.0048752,12.599,133.52,128.42,132.44
45.1391,4.146,-0.045539,31.261,135.24,-0.0050293,12.581,135.16,130.09,134.03
45.7391,4.1574,-0.04678,31.857,137.04,-0.0050783,12.61,136.93,131.9,135.96
46.3391,4.1449,-0.047659,31.178,138.84,-0.0051192,12.575,138.85,133.77,137.83
46.9391,4.1546,-0.048291,31.438,140.64,-0.0052792,12.601,140.59,135.54,139.41
47.5391,4.1476,-0.049473,31.611,142.44,-0.0054004,12.586,142.41,137.23,141.33
48.1391,4.1559,-0.050285,31.608,144.24,-0.0055158,12.606,144.18,139.09,143.14
48.7391,4.1531,-0.051417,31.7,146.04,-0.0055628,12.604,146.01,140.82,144.85
49.3391,4.1632,-0.051796,31.637,147.84,-0.0057041,12.631,147.84,142.55,146.79
49.9391,4.1507,-0.053289,31.518,149.64,-0.0057865,12.594,149.62,144.26,148.52
50.5391,4.1585,-0.054599,31.275,151.44,-0.005905,12.613,151.49,146.0,150.31
51.1391,4.1548,-0.055801,31.626,153.24,-0.0060923,12.606,153.23,147.78,152.07
51.7391,4.154,-0.057031,31.757,155.04,-0.0062395,12.598,155.0,149.54,153.71
52.3391,4.1482,-0.058868,31.88,156.84,-0.0064544,12.587,156.79,151.31,155.57
52.9391,4.1575,-0.060451,31.714,158.64,-0.0065394,12.609,158.66,153.07,157.4
53.5391,4.1544,-0.060998,31.696,160.44,-0.0067023,12.609,160.42,154.8,159.14
54.1391,4.1645,-0.061867,31.997,162.24,-0.0066952,12.632,162.17,156.58,160.86
54.7391,4.1604,-0.062613,31.957,164.04,-0.0067648,12.624,164.03,158.55,162.76
55.3391,4.1594,-0.062887,32.001,165.84,-0.0068341,12.611,165.84,160.27,164.47
55.9391,4.1581,-0.063613,32.423,167.64,-0.0069745,12.617,167.56,161.93,166.15
56.5391,4.1567,-0.064618,32.498,169.44,-0.0070443,12.607,169.38,163.69,167.95
57.1391,4.1587,-0.065383,32.738,171.24,-0.0070408,12.621,171.17,165.59,169.65
57.7391,4.1501,-0.065844,32.295,173.04,-0.0072118,12.586,173.02,167.41,171.5
58.3391,4.1561,-0.067009,32.357,174.84,-0.0072654,12.612,174.82,169.13,173.21
58.9391,4.1484,-0.068237,32.595,176.64,-0.007433,12.582,176.6,170.74,174.97
59.5391,4.1657,-0.069501,32.28,178.44,-0.0075402,12.642,178.47,172.59,176.84
60.13911,4.1599,-0.069938,32.26,180.24,-0.0076842,12.615,180.29,174.44,178.52
60.73911,4.1626,-0.071349,32.823,182.04,-0.0077569,12.631,181.99,176.03,180.2
61.33911,4.1513,-0.072693,32.41,183.84,-0.0078377,12.591,183.89,177.88,182.14
61.93911,4.1627,-0.073006,32.018,185.64,-0.0079659,12.633,185.71,179.68,183.74
62.53911,4.1586,-0.07418,32.935,187.44,-0.0080812,12.615,187.35,181.24,185.43
63.13911,4.1668,-0.075169,32.917,189.24,-0.008216,12.644,189.22,183.16,187.49
63.73911,4.157,-0.076526,31.938,191.04,-0.0082789,12.607,191.18,184.92,189.2
64.33911,4.1661,-0.077149,32.841,192.84,-0.0084537,12.643,192.77,186.39,190.62
64.93911,4.1617,-0.078449,33.112,194.64,-0.0084981,12.623,194.53,188.06,192.53
65.53911,4.1664,-0.07949,32.443,196.44,-0.008598,12.642,196.56,190.02,194.66
66.13911,4.1599,-0.080336,32.671,198.24,-0.0087451,12.619,198.26,191.66,195.95
66.73911,4.1729,-0.081592,33.503,200.04,-0.0089217,12.662,199.88,193.21,197.75
67.33911,4.1557,-0.082717,32.804,201.84,-0.0090219,12.605,201.93,195.1,199.86
67.93911,4.1687,-0.083677,32.832,203.64,-0.0090241,12.648,203.66,196.8,201.3
68.53911,4.1634,-0.084386,33.707,205.44,-0.0092253,12.632,205.31,198.34,202.91
69.13911,4.1737,-0.085743,33.065,207.24,-0.0092987,12.666,207.22,200.22,205.03
69.73911,4.1617,-0.08679,32.834,209.04,-0.0094483,12.626,209.1,201.87,206.67
70.33911,4.1762,-0.088042,33.536,210.84,-0.0095517,12.673,210.74,203.35,208.23
70.93911,4.1601,-0.088765,33.245,212.64,-0.0097155,12.621,212.63,205.31,210.26
71.53911,4.1792,-0.089783,32.981,214.44,-0.0097498,12.678,214.52,207.18,212.07
72.13911,4.168,-0.09097,33.37,216.24,-0.0098322,12.645,216.19,208.56,213.6
72.73911,4.1794,-0.091987,33.557,218.04,-0.010022,12.679,217.98,210.35,215.51
73.33911,4.161,-0.093044,33.192,219.84,-0.010143,12.624,219.96,212.11,217.36
73.7669,4.1675,-0.093538,33.138,221.12,-0.010214,12.647,221.16,213.26,218.47
74.3669,4.1744,-0.094898,33.753,222.92,-0.01029,12.662,222.86,214.94,220.24
74.9669,4.1637,-0.096023,33.486,224.72,-0.010441,12.632,224.76,216.63,222.1
75.5669,4.1783,-0.097229,33.213,226.52,-0.010558,12.673,226.6,218.36,223.89
76.1669,4.1689,-0.098041,33.77,228.32,-0.010735,12.648,228.25,220.03,225.45
76.7669,4.18,-0.099395,33.741,230.12,-0.010795,12.679,230.09,221.83,227.42
77.3669,4.1662,-0.10065,33.264,231.92,-0.010871,12.642,232.01,223.63,229.22
77.9669,4.1825,-0.10145,33.513,233.72,-0.011041,12.685,233.73,225.18,230.81
78.5669,4.1704,-0.10276,33.466,235.52,-0.011211,12.656,235.55,226.92,232.67
79.1669,4.1764,-0.1039,33.379,237.32,-0.011344,12.668,237.39,228.68,234.54
79.7669,4.1764,-0.10537,33.415,239.12,-0.011399,12.673,239.16,230.31,236.05
80.3669,4.1852,-0.10667,34.019,240.92,-0.011665,12.694,240.79,231.94,237.69
80.9669,4.1757,-0.10896,34.367,242.72,-0.011831,12.669,242.55,233.69,239.63
81.5669,4.1815,-0.11074,32.935,244.52,-0.012052,12.682,244.77,235.8,241.73
82.1669,4.1666,-0.11256,33.931,246.32,-0.012233,12.642,246.2,237.23,242.83
82.7669,4.1823,-0.11439,34.673,248.12,-0.0125,12.682,247.94,239.03,245.1
83.3669,4.1726,-0.11462,32.87,249.92,-0.012418,12.661,250.16,240.9,247.16
83.9669,4.1781,-0.11562,34.253,251.72,-0.012477,12.674,251.58,242.22,248.14
84.5669,4.176,-0.11655,34.784,253.52,-0.012659,12.672,253.38,244.02,250.38
85.1669,4.1803,-0.11615,33.114,255.32,-0.012645,12.677,255.57,246.08,252.5
85.7669,4.1749,-0.11724,34.259,257.12,-0.01277,12.667,257.04,247.36,253.45
86.3669,4.1799,-0.11881,34.805,258.92,-0.012837,12.674,258.73,249.15,255.61
86.9669,4.1719,-0.11911,33.66,260.72,-0.012988,12.658,260.89,251.17,257.78
87.5669,4.1703,-0.11992,34.286,262.52,-0.012995,12.645,262.51,252.75,258.97
88.1669,4.1717,-0.12113,35.065,264.32,-0.013146,12.659,264.12,254.43,260.84
88.7669,4.1732,-0.12211,33.993,266.12,-0.013241,12.657,266.2,256.37,263.11
89.3669,4.1737,-0.12292,34.196,267.92,-0.013428,12.665,267.97,257.99,264.41
89.9669,4.169,-0.12442,34.78,269.72,-0.01349,12.644,269.63,259.67,266.25
90.5669,4.1736,-0.12584,34.185,271.52,-0.013612,12.666,271.6,261.51,268.34
91.1669,4.1728,-0.12654,34.568,273.32,-0.013753,12.655,273.33,263.14,269.83
91.7669,4.1756,-0.12762,34.681,275.12,-0.013912,12.671,275.11,264.91,271.71
92.3669,4.1684,-0.12883,34.008,276.92,-0.014016,12.642,277.01,266.69,273.68
92.96691,4.1749,-0.13006,34.642,278.72,-0.014042,12.669,278.68,268.2,275.11
93.56691,4.1739,-0.13099,34.909,280.52,-0.014263,12.66,280.47,270.01,277.17
94.16691,4.1782,-0.13194,34.018,282.32,-0.014318,12.678,282.46,271.72,279.12
94.76691,4.1723,-0.13315,34.55,284.12,-0.01448,12.656,284.11,273.27,280.6
95.36691,4.1809,-0.13469,34.018,285.92,-0.014574,12.686,286.11,275.18,282.93
95.96691,4.1717,-0.13506,33.987,287.72,-0.014724,12.654,287.84,277.11,284.25
96.56691,4.1813,-0.1367,35.389,289.52,-0.014801,12.687,289.34,278.63,285.87
97.16691,4.1712,-0.13789,34.271,291.32,-0.014939,12.653,291.42,280.73,288.27
97.76691,4.1804,-0.13884,34.464,293.12,-0.015072,12.682,293.19,282.69,289.8
98.36691,4.1752,-0.13965,34.66,294.92,-0.015229,12.663,294.88,284.46,291.51
98.96691,4.1806,-0.14072,34.832,296.72,-0.015273,12.683,296.67,286.24,293.39
99.56691,4.1731,-0.14212,34.542,298.52,-0.015356,12.661,298.55,288.22,295.36
100.16691,4.1803,-0.14276,34.724,300.32,-0.015505,12.683,300.35,290.17,297.17
100.76691,4.1756,-0.1438,34.65,302.12,-0.015642,12.666,302.16,291.88,298.89
101.36691,4.191,-0.14457,34.37,303.92,-0.015731,12.714,303.98,293.78,300.64
101.96691,4.1733,-0.14578,34.382,305.72,-0.015751,12.656,305.81,295.52,302.28
102.56691,4.1828,-0.14616,34.122,307.52,-0.015907,12.689,307.65,297.24,303.84
103.16691,4.1703,-0.14647,33.983,309.32,-0.015864,12.65,309.49,298.51,304.62
103.76691,4.1899,-0.14782,34.876,311.12,-0.016063,12.711,311.07,299.75,305.8
104.36691,4.1778,-0.149,34.671,312.92,-0.016139,12.675,312.92,301.32,307.64
104.96691,4.1963,-0.15033,35.183,314.72,-0.016388,12.73,314.61,303.13,309.32
105.56691,4.1733,-0.15235,34.647,316.52,-0.01652,12.658,316.59,304.91,311.22
106.0888,4.1871,-0.15458,34.951,318.1,-0.016763,12.708,318.06,306.65,312.61
106.6888,4.1873,-0.15644,35.239,319.89,-0.016957,12.7,319.83,308.6,314.41
107.2888,4.1818,-0.15829,35.102,321.69,-0.017166,12.691,321.69,310.6,316.2
107.8888,4.186,-0.15924,35.052,323.49,-0.017219,12.696,323.47,312.69,317.9
108.4888,4.187,-0.15838,34.939,325.29,-0.017231,12.703,325.28,314.77,319.7
109.0888,4.19,-0.15872,35.022,327.09,-0.017189,12.705,327.13,316.75,321.43
109.6888,4.1842,-0.15926,35.292,328.89,-0.01724,12.693,328.84,318.78,323.17
110.2888,4.1802,-0.15995,35.007,330.69,-0.017333,12.678,330.73,320.78,325.03
110.8888,4.181,-0.16019,35.276,332.49,-0.017417,12.688,332.5,322.99,326.86
111.4888,4.1799,-0.16123,35.21,334.29,-0.01749,12.676,334.29,324.97,328.61
112.0888,4.1851,-0.16245,35.359,336.09,-0.017572,12.698,336.08,327.01,330.48
112.6888,4.1823,-0.1631,35.199,337.89,-0.017701,12.683,337.91,329.12,332.41
113.2888,4.181,-0.16404,35.234,339.69,-0.017808,12.687,339.72,331.11,334.25
113.8888,4.1776,-0.16502,35.497,341.49,-0.017923,12.671,341.46,333.12,336.12
114.4888,4.1899,-0.16633,35.634,343.29,-0.017956,12.713,343.23,335.06,337.94
115.0888,4.1846,-0.16682,35.593,345.09,-0.018117,12.69,345.08,337.0,339.79
115.6888,4.1907,-0.16763,35.605,346.89,-0.01817,12.715,346.85,338.88,341.63
116.2863,4.1834,-0.16855,35.769,348.68,-0.018305,12.691,348.59,340.91,343.36
116.8863,4.1891,-0.16961,35.506,350.48,-0.01832,12.712,350.5,342.85,345.33
117.4863,4.1794,-0.17019,35.732,352.28,-0.018492,12.679,352.26,344.78,347.2
118.0863,4.1946,-0.17112,36.148,354.08,-0.018522,12.726,353.96,346.64,349.05
118.6863,4.1843,-0.17179,36.003,355.88,-0.018647,12.692,355.83,348.66,351.0
119.2863,4.1971,-0.1727,35.73,357.68,-0.018662,12.735,357.71,350.74,352.98
119.8863,4.1803,-0.17302,35.809,359.48,-0.018805,12.681,359.5,352.57,354.91
120.4863,4.1952,-0.1745,36.179,361.28,-0.018883,12.726,361.22,354.49,356.71
121.0863,4.1894,-0.17603,36.111,363.08,-0.019108,12.707,363.06,356.36,358.53
121.6863,4.1941,-0.17897,35.801,364.88,-0.019405,12.722,364.93,358.4,360.51
122.2863,4.1861,-0.18131,35.872,366.68,-0.019733,12.696,366.72,360.29,362.27
122.8863,4.1968,-0.1828,36.093,368.48,-0.019769,12.731,368.49,362.19,364.16
123.4863,4.1862,-0.18177,35.899,370.28,-0.019636,12.7,370.29,364.01,366.04
124.0863,4.2001,-0.18104,36.105,372.08,-0.019596,12.74,372.1,365.92,368.01
124.6863,4.1751,-0.18131,36.02,373.88,-0.019713,12.664,373.91,367.89,369.91
125.2863,4.189,-0.18126,36.124,375.68,-0.019615,12.708,375.7,369.81,371.76
125.8863,4.1765,-0.18208,36.226,377.48,-0.019669,12.67,377.5,371.83,373.59
126.4863,4.1901,-0.18247,36.272,379.28,-0.019778,12.71,379.28,373.63,375.43
127.0863,4.18,-0.18276,35.826,381.08,-0.019864,12.682,381.13,375.57,377.26
127.6863,4.1914,-0.18337,36.032,382.88,-0.019855,12.714,382.9,377.42,379.07
128.2863,4.1768,-0.184,35.989,384.68,-0.019869,12.672,384.71,379.32,380.99
128.8863,4.1925,-0.18395,36.186,386.48,-0.019935,12.715,386.47,381.1,382.81
129.4863,4.1833,-0.1842,36.447,388.28,-0.020005,12.692,388.19,383.01,384.63
130.0863,4.1986,-0.18432,36.31,390.08,-0.019971,12.737,390.04,385.01,386.53
130.6863,4.1849,-0.1847,36.195,391.88,-0.019937,12.696,391.9,386.96,388.46
131.2863,4.198,-0.18449,36.606,393.68,-0.019997,12.733,393.64,389.02,390.54
131.8863,4.1853,-0.18445,36.424,395.48,-0.020024,12.699,395.49,391.06,392.45
132.4863,4.1967,-0.18528,36.647,397.28,-0.020104,12.729,397.3,392.98,394.25
133.0863,4.1807,-0.18757,36.493,399.08,-0.020275,12.685,399.04,394.85,396.11
133.6863,4.1786,-0.1894,34.755,400.0,-0.020556,12.673,400.41,396.66,397.75
134.2863,4.1531,-0.18964,35.29,400.0,-0.020561,12.601,400.25,396.93,397.82
134.88631,4.1475,-0.18713,35.034,400.0,-0.020271,12.578,400.26,397.25,397.84
135.48631,4.1297,-0.18545,34.975,400.0,-0.020008,12.529,400.21,397.39,397.83
136.08631,4.116,-0.18448,35.222,400.0,-0.019992,12.482,400.16,397.54,397.85
136.68631,4.1049,-0.18349,34.941,400.0,-0.019909,12.456,400.14,397.51,397.88
137.28631,4.1074,-0.18313,34.787,400.0,-0.019868,12.457,400.16,397.51,397.9
137.88631,4.0887,-0.18279,34.736,400.0,-0.019731,12.409,400.18,397.49,398.06
138.48631,4.0859,-0.18202,34.671,400.0,-0.019753,12.39,400.11,397.4,398.07
138.9326,4.0851,-0.1818,34.437,400.0,-0.019623,12.39,400.15,397.33,398.06
139.5326,4.0661,-0.18133,34.419,400.0,-0.019683,12.338,400.15,397.29,398.13
140.1326,4.0825,-0.18086,34.439,400.0,-0.019595,12.381,400.11,397.24,398.07
140.7326,4.062,-0.18018,34.144,400.0,-0.019558,12.325,400.19,397.22,398.16
141.3326,4.0734,-0.17996,34.515,400.0,-0.019427,12.354,400.08,397.23,398.15
141.9326,4.0606,-0.17881,34.171,400.0,-0.019414,12.323,400.08,397.18,398.21
142.5326,4.0675,-0.17836,33.876,400.0,-0.01933,12.337,400.12,397.23,398.31
143.1326,4.0587,-0.17768,34.078,400.0,-0.019287,12.316,400.09,397.24,398.33
143.7326,4.0565,-0.17749,34.283,400.0,-0.019155,12.301,400.05,397.18,398.36
144.3326,4.0558,-0.17778,34.062,400.0,-0.01933,12.308,400.09,397.25,398.43
144.9326,4.0594,-0.18076,33.806,400.0,-0.01963,12.31,400.08,397.13,398.38
145.5326,4.0434,-0.18076,33.786,400.0,-0.019602,12.268,400.1,397.17,398.47
146.1326,4.0404,-0.17821,33.898,400.0,-0.019222,12.251,400.04,397.22,398.51
146.7326,4.0367,-0.17659,33.775,400.0,-0.019157,12.25,400.11,397.21,398.61
147.3326,4.0385,-0.1759,33.801,400.0,-0.019092,12.246,400.04,397.22,398.55
147.9326,4.0405,-0.17575,33.909,400.0,-0.019082,12.259,400.0,397.23,398.6
148.5326,4.0356,-0.17556,33.987,400.0,-0.018931,12.24,400.04,397.39,398.75
149.1326,4.0302,-0.17485,33.759,400.0,-0.018976,12.229,400.04,397.41,398.81
149.7326,4.0358,-0.17409,33.711,400.0,-0.018901,12.241,400.08,397.49,398.86
150.3326,4.0332,-0.17335,33.78,400.0,-0.018825,12.238,400.04,397.49,398.86
150.9326,4.0291,-0.17299,33.773,400.0,-0.018655,12.22,400.04,397.61,398.97
151.5326,4.0374,-0.17364,33.77,400.0,-0.018852,12.252,400.06,397.75,399.03
152.1326,4.0273,-0.17759,33.702,400.0,-0.019303,12.214,400.07,397.74,399.1
152.7326,4.028,-0.17461,33.715,400.0,-0.018918,12.223,400.06,397.86,399.13
153.3326,4.0169,-0.17267,33.509,400.0,-0.018616,12.181,400.05,397.83,399.14
153.9326,4.021,-0.17156,33.772,400.0,-0.018615,12.201,399.95,397.8,399.15
154.5326,4.0129,-0.17134,33.8,400.0,-0.018629,12.171,399.98,397.84,399.09
155.1326,4.0219,-0.17108,33.869,400.0,-0.018574,12.204,399.95,397.89,399.16
155.7326,4.008,-0.17088,33.798,400.0,-0.01844,12.154,399.96,397.91,399.2
156.3326,4.0194,-0.17004,33.796,400.0,-0.018455,12.196,399.97,397.96,399.21
156.9326,4.0111,-0.16886,33.781,400.0,-0.018366,12.166,399.97,397.97,399.22
157.5326,4.0192,-0.16848,33.91,400.0,-0.018268,12.194,400.01,398.06,399.32
158.13261,4.0086,-0.16909,34.1,400.0,-0.018284,12.158,399.96,398.08,399.31
158.73261,4.0186,-0.17212,33.823,400.0,-0.018709,12.192,400.03,398.21,399.3
159.33261,4.0129,-0.17217,33.895,400.0,-0.018699,12.171,400.02,398.11,399.3
159.93261,4.0128,-0.16944,33.959,400.0,-0.018347,12.174,399.97,398.12,399.33
160.53261,3.9931,-0.16855,33.881,400.0,-0.018194,12.112,400.05,398.16,399.33
161.13261,4.0048,-0.16754,33.773,400.0,-0.018162,12.152,400.03,398.17,399.32
161.73261,3.9939,-0.16728,34.302,400.0,-0.018211,12.114,399.94,398.22,399.37
162.33261,4.0151,-0.16677,33.8,400.0,-0.018083,12.181,400.02,398.68,399.76
162.93261,4.003,-0.16691,34.317,400.0,-0.01804,12.145,399.89,398.88,399.97
163.53261,4.0107,-0.16636,33.891,400.0,-0.01802,12.165,400.01,399.24,400.37
164.13261,4.0002,-0.16581,33.877,400.0,-0.018049,12.136,400.03,399.46,400.61
164.73261,4.0119,-0.16546,34.002,400.0,-0.017935,12.169,400.01,399.7,400.76
165.33261,4.003,-0.16506,33.774,400.0,-0.017846,12.143,399.99,399.83,400.91
165.93261,4.0097,-0.16443,33.941,400.0,-0.017804,12.163,400.0,400.03,401.06
166.53261,3.9946,-0.164,33.951,400.0,-0.017862,12.118,400.01,400.21,401.16
167.13261,4.0097,-0.16439,34.021,400.0,-0.017834,12.163,399.97,400.37,401.28
167.73261,3.9981,-0.16599,33.875,400.0,-0.017996,12.131,400.0,400.46,401.44
168.33261,4.0089,-0.16836,33.727,400.0,-0.018253,12.158,400.08,400.62,401.6
168.93261,3.9937,-0.16785,33.831,400.0,-0.018245,12.118,400.04,400.64,401.67
169.53261,4.0093,-0.1655,34.049,400.0,-0.017899,12.161,399.95,400.71,401.7
170.13261,3.9932,-0.16406,33.865,400.0,-0.017767,12.113,399.97,400.78,401.74
170.73261,4.0006,-0.16345,33.973,400.0,-0.017677,12.133,399.92,400.71,401.75
171.33261,3.9891,-0.16228,33.843,400.0,-0.017601,12.1,400.07,400.87,402.0
171.7587,3.984,-0.16215,33.812,400.0,-0.017556,12.088,400.01,400.75,401.97
172.3587,3.9978,-0.16136,34.189,400.0,-0.01757,12.124,399.93,400.69,401.96
172.9587,3.9912,-0.1612,33.942,400.0,-0.017465,12.111,399.98,400.81,402.13
173.5587,3.9944,-0.16092,34.209,400.0,-0.017455,12.114,399.94,400.67,402.16
174.1587,3.9862,-0.16075,33.904,400.0,-0.017379,12.097,400.01,400.63,402.2
174.7587,3.9869,-0.16,33.778,400.0,-0.017421,12.089,400.02,400.57,402.3
175.3587,3.9863,-0.15967,33.915,400.0,-0.017304,12.097,400.01,400.51,402.32
175.9587,3.9934,-0.15902,33.766,400.0,-0.017264,12.111,400.03,400.56,402.42
176.5587,3.9903,-0.15933,33.965,400.0,-0.017211,12.108,400.02,400.41,402.35
177.1587,3.9832,-0.15826,33.693,400.0,-0.0172,12.079,400.08,400.5,402.46
177.7587,3.9851,-0.15781,33.763,400.0,-0.017137,12.095,400.04,400.38,402.45
178.3587,3.9909,-0.052113,33.588,400.0,-0.0056871,12.104,400.03,400.43,402.54
178.6204,4.0554,0.027983,0.0,13.778,0.0028712,12.283,400.06,400.24,402.56
178.6234,3.9261,0.026515,0.0,0.0011231,0.0030659,11.908,400.08,400.22,402.64
178.6264,4.0933,0.024318,0.0,9.1538e-08,0.0028531,12.416,400.1,400.2,402.72
178.6294,3.9304,0.028827,0.0,7.4607e-12,0.0027899,11.899,400.12,400.19,402.81
178.6324,4.0322,0.026024,0.0,6.0807e-16,0.002196,12.251,400.08,400.23,402.77
178.6354,3.9447,0.023903,0.0,4.9558e-20,0.0023465,11.964,400.03,400.29,402.68
178.6384,4.0167,0.023515,0.0,4.0388e-24,0.0027529,12.21,399.97,400.35,402.59
178.6414,3.956,0.022797,0.0,3.2914999999999997e-28,0.0031451,11.967,399.95,400.39,402.52
178.6444,3.9961,0.024936,0.0,2.6824e-32,0.0030255,12.152,399.96,400.39,402.5
178.6474,3.973,0.027302,0.0,2.1859e-36,0.002761,12.016,399.98,400.39,402.49
178.6504,3.9755,0.02699,0.0,1.7724999999999999e-40,0.0028434,12.085,400.0,400.39,402.47
178.6534,3.9886,0.026397,0.0,1.5414e-44,0.0031826,12.097,400.02,400.36,402.49
178.6564,3.9474,0.025663,0.0,0.0,0.0028521,12.012,400.04,400.34,402.51
178.6594,4.0108,0.026831,0.0,0.0,0.002419,12.116,400.06,400.31,402.52
178.6624,3.9332,0.027465,0.0,0.0,0.0023628,11.956,400.05,400.29,402.53
178.6654,4.0044,0.02508,0.0,0.0,0.0027359,12.129,400.03,400.27,402.53
178.6684,3.9044,0.02186,0.0,0.0,0.002894,11.873,400.01,400.25,402.53
178.6714,4.0266,0.023481,0.0,0.0,0.0030636,12.2,400.09,400.4,402.51
178.6744,3.9147,0.024623,0.0,0.0,0.0027428,11.887,400.33,400.83,402.47
178.6774,4.0207,0.025983,0.0,0.0,0.0026622,12.207,400.58,401.27,402.42
178.6804,3.9154,0.025956,0.0,0.0,0.0029395,11.862,400.86,401.73,402.38
178.6834,3.9899,0.025889,0.0,0.0,0.003077,12.137,402.3,403.19,402.29
178.6864,12.453,0.059771,0.0,0.0,0.0066109,37.465,403.75,404.64,402.19
178.68939,27.024,0.26273,0.0,0.0,0.027768,81.598,405.19,406.09,402.1
178.69239,29.577,0.52102,0.0,0.0,0.057168,89.778,406.94,407.75,402.09
178.69539,30.535,0.79666,0.0,0.0,0.090075,92.685,408.82,409.49,402.11
178.69839,30.972,1.0613,0.0,0.0,0.12255,93.901,410.7,411.23,402.13
178.70139,31.035,1.3208,0.0,0.0,0.15467,94.16,412.25,412.61,402.15
178.70439,30.976,1.5798,0.0,0.0,0.18713,93.965,413.25,413.35,402.2
178.70739,30.783,1.8223,0.0,0.0,0.21905,93.398,414.26,414.09,402.24
178.71039,30.665,2.0484,0.0,0.0,0.25025,93.03,415.24,414.81,402.29
178.71339,30.513,2.2661,0.0,0.0,0.28063,92.565,415.66,414.88,402.28
178.71639,30.506,2.4743,0.0,0.0,0.30947,92.526,416.09,414.95,402.27
178.71939,30.504,2.6848,0.0,0.0,0.34003,92.522,416.51,415.02,402.26
178.72239,30.591,2.8883,0.0,0.0,0.37141,92.771,416.7,415.18,402.28
178.72539,30.62,3.0923,0.0,0.0,0.40394,92.876,416.79,415.38,402.3
178.72839,30.745,3.2965,0.0,0.0,0.43704,93.26,416.88,415.58,402.33
178.73139,30.81,3.5002,0.0,0.0,0.47014,93.45,417.01,415.79,402.34
178.73439,30.9,3.698,0.0,0.0,0.50302,93.734,417.2,416.0,402.31
178.73739,30.993,3.8872,0.0,0.0,0.53651,93.986,417.39,416.22,402.28
178.74039,30.997,4.0691,0.0,0.0,0.57035,94.029,417.58,416.43,402.26
178.74339,31.039,4.2419,0.0,0.0,0.60223,94.138,417.83,416.5,402.27
178.74639,31.088,4.412,0.0,0.0,0.63348,94.333,418.08,416.57,402.28
178.74939,31.162,4.5737,0.0,0.0,0.66524,94.529,418.33,416.65,402.29
178.75239,31.253,4.7301,0.0,0.0,0.69837,94.801,418.43,416.86,402.33
178.75539,31.429,4.8894,0.0,0.0,0.7329,95.313,418.46,417.13,402.4
178.75839,31.548,5.0522,0.0,0.0,0.76805,95.717,418.48,417.4,402.46
178.76139,31.709,5.2138,0.0,0.0,0.80283,96.185,418.52,417.67,402.51
178.76439,31.679,5.3716,0.0,0.0,0.83882,96.112,418.56,417.96,402.54
178.76739,31.661,5.5081,0.0,0.0,0.87253,96.035,418.61,418.25,402.56
178.77039,31.657,5.6412,0.0,0.0,0.90567,96.017,418.65,418.53,402.59
178.77339,31.745,5.771,0.0,0.0,0.93746,96.277,418.65,418.36,402.59
178.77639,31.808,5.8991,0.0,0.0,0.96909,96.478,418.65,418.2,402.59
178.77939,31.982,6.023,0.0,0.0,1.0029,97.009,418.65,418.04,402.59
178.78239,32.091,6.1431,0.0,0.0,1.0381,97.347,418.44,417.76,402.61
178.78539,32.298,6.2626,0.0,0.0,1.0734,97.969,418.13,417.42,402.63
178.78839,32.426,6.3802,0.0,0.0,1.1074,98.33,417.82,417.09,402.66
178.79139,32.551,6.4999,0.0,0.0,1.1417,98.753,417.43,416.66,402.68
178.79439,32.738,6.6147,0.0,0.0,1.1781,99.286,416.88,416.07,402.69
178.79739,32.856,6.7223,0.0,0.0,1.2154,99.682,416.33,415.47,402.7
178.80039,32.995,6.8282,0.0,0.0,1.2507,100.08,415.77,414.87,402.71
178.80339,33.108,6.929,0.0,0.0,1.2829,100.44,414.91,413.9,402.76
178.80639,33.248,7.028,0.0,0.0,1.3172,100.84,414.04,412.94,402.8
178.80939,33.413,7.1179,0.0,0.0,1.352,101.34,413.18,411.97,402.85
178.81239,33.677,7.2079,0.0,0.0,1.3891,102.13,412.2,410.98,402.92
178.81539,33.958,7.2996,0.0,0.0,1.4257,102.99,411.17,409.98,403.01
178.81839,34.285,7.3897,0.0,0.0,1.4601,103.97,410.14,408.98,403.1
178.82139,34.449,7.478,0.0,0.0,1.4958,104.5,409.02,407.97,403.17
178.82439,34.719,7.5609,0.0,0.0,1.5329,105.29,407.76,406.94,403.2
178.82738,34.931,7.6408,0.0,0.0,1.5707,105.96,406.5,405.91,403.22
178.83038,35.205,7.7177,0.0,0.0,1.605,106.83,405.23,404.88,403.25
178.83338,31.557,7.727,0.0,0.0,1.6066,95.84,403.9,403.76,403.27
178.83638,29.684,7.733,0.0,0.0,1.6094,90.136,402.58,402.64,403.29
178.83938,28.524,7.7326,0.0,0.0,1.6127,86.582,401.25,401.52,403.31
178.84238,27.875,7.7387,0.0,0.0,1.6184,84.573,400.08,400.45,403.31
178.84538,27.463,7.742,0.0,0.0,1.6189,83.335,398.98,399.41,403.31
178.84838,27.281,7.7483,0.0,0.0,1.619,82.756,397.87,398.38,403.31
178.85138,27.085,7.7543,0.0,0.0,1.6211,82.181,396.86,397.43,403.32
178.85438,26.977,7.7577,0.0,0.0,1.6253,81.865,395.99,396.64,403.34
178.85738,26.311,7.7608,0.0,0.0,1.6275,79.912,395.12,395.85,403.35
178.86038,24.447,7.7622,0.0,0.0,1.6253,74.33,394.27,395.08,403.37
178.86338,20.727,7.758,0.0,0.0,1.6208,63.146,394.16,394.85,403.42
178.86638,14.307,7.751,0.0,0.0,1.6186,44.159,394.06,394.61,403.46
178.86938,2.8145,7.7105,0.0,0.0,1.6025,7.8632,393.95,394.38,403.51
178.87238,3.4616,7.7244,0.0,0.0,1.6119,10.318,394.11,394.44,403.55
178.87538,3.8587,7.7187,0.0,0.0,1.6068,11.577,394.4,394.64,403.6
178.87838,3.6319,7.7205,0.0,0.0,1.6049,11.001,394.69,394.84,403.64
178.88138,3.6223,7.7218,0.0,0.0,1.6059,10.934,394.96,395.03,403.68
178.88438,3.4766,7.7173,0.0,0.0,1.6071,10.586,395.2,395.19,403.71
178.88738,3.5871,7.7182,0.0,0.0,1.6068,10.873,395.43,395.35,403.74
178.89038,3.5076,7.719,0.0,0.0,1.6038,10.667,395.67,395.51,403.76
178.89338,3.5331,7.722,0.0,0.0,1.6039,10.713,395.81,395.59,403.79
178.89638,3.5048,7.718,0.0,0.0,1.6043,10.628,395.96,395.66,403.82
178.89938,3.5433,7.7159,0.0,0.0,1.607,10.737,396.1,395.73,403.84
178.90238,3.4617,7.7164,0.0,0.0,1.6074,10.532,396.13,395.75,403.88
178.90538,3.5869,7.7184,0.0,0.0,1.6058,10.876,396.1,395.74,403.93
178.90838,3.4683,7.7205,0.0,0.0,1.6047,10.522,396.07,395.73,403.97
178.91138,3.594,7.7207,0.0,0.0,1.6069,10.895,396.04,395.7,404.01
178.91438,3.4928,7.7203,0.0,0.0,1.6086,10.532,396.01,395.62,404.02
178.91738,3.5412,7.7212,0.0,0.0,1.6069,10.761,395.97,395.55,404.03
178.92038,3.4833,7.7216,0.0,0.0,1.6042,10.518,395.93,395.48,404.03
178.92338,3.5645,7.7217,0.0,0.0,1.6041,10.865,395.84,395.41,404.06
178.92638,3.5409,7.7198,0.0,0.0,1.6066,10.733,395.75,395.34,404.09
178.92938,3.5195,7.7197,0.0,0.0,1.6092,10.702,395.66,395.26,404.12
178.93238,3.5608,7.7191,0.0,0.0,1.6078,10.753,395.51,395.14,404.16
178.93538,3.5265,7.7198,0.0,0.0,1.6052,10.74,395.33,395.0,404.2
178.93838,3.5623,7.7215,0.0,0.0,1.6056,10.759,395.15,394.85,404.25
178.94138,3.4892,7.7209,0.0,0.0,1.6083,10.635,394.97,394.69,404.28
178.94438,3.5971,7.7216,0.0,0.0,1.609,10.895,394.82,394.51,404.29
178.94738,3.483,7.7244,0.0,0.0,1.607,10.57,394.67,394.33,404.3
178.95038,3.5531,7.7253,0.0,0.0,1.6052,10.782,394.51,394.15,404.31
178.95338,3.4796,7.7225,0.0,0.0,1.6057,10.585,394.32,393.97,404.32
178.95638,3.6318,7.7194,0.0,0.0,1.6076,11.023,394.13,393.79,404.34
178.95938,3.5979,7.7187,0.0,0.0,1.6088,10.911,393.94,393.61,404.36
178.96238,3.6972,7.7223,0.0,0.0,1.6083,11.204,393.73,393.39,404.36
178.96537,3.606,7.7231,0.0,0.0,1.6061,10.956,393.5,393.17,404.36
178.96837,3.7664,7.7232,0.0,0.0,1.6068,11.451,393.27,392.94,404.36
178.97137,3.6709,7.7222,0.0,0.0,1.6095,11.122,393.05,392.72,404.37
178.97437,3.8144,7.7229,0.0,0.0,1.6088,11.647,392.82,392.5,404.39
178.97737,3.6898,7.7226,0.0,0.0,1.6053,11.131,392.6,392.29,404.41
178.98037,3.8176,7.7243,0.0,0.0,1.6048,11.647,392.37,392.07,404.43
178.98337,3.7195,7.7204,0.0,0.0,1.6063,11.221,392.16,391.89,404.48
178.98637,3.7685,7.7191,0.0,0.0,1.6087,11.496,391.95,391.71,404.53
178.98937,3.7339,7.7182,0.0,0.0,1.6084,11.243,391.75,391.53,404.59
178.99237,3.7257,7.7221,0.0,0.0,1.6071,11.365,391.52,391.34,404.61
178.99537,3.7926,7.7242,0.0,0.0,1.6064,11.454,391.28,391.15,404.62
178.99837,3.6711,7.7254,0.0,0.0,1.6092,11.219,391.05,390.96,404.63
179.00137,3.8355,7.7229,0.0,0.0,1.6098,11.576,390.8,390.76,404.64
179.00437,3.6503,7.7246,0.0,0.0,1.6083,11.145,390.54,390.54,404.64
179.00737,3.8766,7.7266,0.0,0.0,1.606,11.712,390.28,390.32,404.64
179.01037,3.6285,7.7229,0.0,0.0,1.605,11.063,390.02,390.11,404.64
179.01337,3.877,7.7202,0.0,0.0,1.607,11.733,389.76,389.97,404.65
179.01637,3.6243,7.7193,0.0,0.0,1.6091,11.002,389.51,389.84,404.67
179.01937,3.8888,7.7216,0.0,0.0,1.609,11.794,389.26,389.7,404.69
179.02237,3.6402,7.7245,0.0,0.0,1.607,11.015,389.05,389.57,404.7
179.02537,3.8642,7.7252,0.0,0.0,1.6074,11.741,388.86,389.43,404.71
179.02837,3.6522,7.7242,0.0,0.0,1.6098,11.035,388.67,389.3,404.72
179.03137,3.8446,7.7243,0.0,0.0,1.61,11.706,388.47,389.13,404.71
179.03437,3.6843,7.7249,0.0,0.0,1.607,11.114,388.25,388.9,404.68
179.03737,3.8073,7.729,0.0,0.0,1.6071,11.607,388.03,388.67,404.64
179.04037,3.734,7.7249,0.0,0.0,1.6069,11.257,387.81,388.45,404.61
179.04337,3.7761,7.7232,0.0,0.0,1.6097,11.541,387.54,388.22,404.61
179.04637,3.783,7.7206,0.0,0.0,1.6096,11.391,387.27,388.0,404.61
179.04937,3.7187,7.7239,0.0,0.0,1.6087,11.373,387.0,387.77,404.61
179.05237,3.8284,7.7254,0.0,0.0,1.6068,11.553,386.76,387.51,404.64
179.05537,3.696,7.7267,0.0,0.0,1.6088,11.283,386.53,387.23,404.68
179.05837,3.8657,7.7264,0.0,0.0,1.6114,11.649,386.31,386.95,404.73
179.06137,3.6631,7.7248,0.0,0.0,1.6093,11.174,386.07,386.68,404.75
179.06437,3.9057,7.7285,0.0,0.0,1.6075,11.812,385.82,386.43,404.73
179.06737,3.6512,7.7269,0.0,0.0,1.6069,11.087,385.56,386.19,404.71
179.07037,3.9074,7.725,0.0,0.0,1.6086,11.844,385.31,385.95,404.7
179.07337,3.6551,7.7216,0.0,0.0,1.61,11.059,385.06,385.8,404.68
179.07637,3.9081,7.7233,0.0,0.0,1.6102,11.848,384.8,385.66,404.66
179.07937,3.6714,7.7253,0.0,0.0,1.6084,11.12,384.55,385.51,404.64
179.08237,3.8974,7.7309,0.0,0.0,1.6095,11.843,384.31,385.34,404.64
179.08537,3.6875,7.7283,0.0,0.0,1.6112,11.139,384.07,385.15,404.65
179.08837,3.8575,7.7283,0.0,0.0,1.6122,11.758,383.84,384.96,404.66
179.09137,3.731,7.7284,0.0,0.0,1.6096,11.269,383.6,384.75,404.67
179.09437,3.8146,7.7298,0.0,0.0,1.6076,11.635,383.36,384.53,404.69
179.09737,3.7904,7.7301,0.0,0.0,1.6086,11.431,383.11,384.3,404.71
179.10037,3.7731,7.7268,0.0,0.0,1.6107,11.524,382.87,384.08,404.73
179.10336,3.8258,7.7228,0.0,0.0,1.6109,11.523,382.67,383.9,404.76
179.10636,3.7232,7.7253,0.0,0.0,1.6101,11.372,382.47,383.73,404.8
179.10936,3.877,7.7297,0.0,0.0,1.6095,11.713,382.27,383.56,404.84
179.11236,3.6907,7.7315,0.0,0.0,1.6106,11.258,382.09,383.38,404.85
179.11536,3.9157,7.729,0.0,0.0,1.6121,11.812,381.9,383.2,404.86
179.11836,3.6764,7.7285,0.0,0.0,1.612,11.183,381.72,383.02,404.87
179.12136,3.931,7.7312,0.0,0.0,1.6098,11.898,381.53,382.82,404.86
179.12436,3.6761,7.732,0.0,0.0,1.6083,11.175,381.31,382.59,404.83
179.12736,3.946,7.7303,0.0,0.0,1.6099,11.982,381.09,382.35,404.79
179.13036,3.6892,7.7257,0.0,0.0,1.6109,11.169,380.88,382.12,404.76
179.13336,3.9279,7.7262,0.0,0.0,1.6121,11.928,380.68,381.97,404.7
179.13636,3.7131,7.7277,0.0,0.0,1.6105,11.238,380.48,381.83,404.65
179.13936,3.9039,7.7289,0.0,0.0,1.6089,11.861,380.28,381.68,404.59
179.14236,3.7456,7.7302,0.0,0.0,1.6108,11.304,380.09,381.54,404.58
179.14536,3.8645,7.7291,0.0,0.0,1.6129,11.788,379.91,381.41,404.59
179.14836,3.7752,7.7273,0.0,0.0,1.61,11.399,379.73,381.27,404.6
179.15136,3.826,7.7295,0.0,0.0,1.6078,11.671,379.54,381.11,404.61
179.15436,3.8385,7.731,0.0,0.0,1.6083,11.559,379.34,380.91,404.61
179.15736,3.7846,7.7319,0.0,0.0,1.6122,11.562,379.14,380.71,404.61
179.16036,3.8754,7.7279,0.0,0.0,1.6129,11.698,378.94,380.52,404.61
179.16336,3.7579,7.7283,0.0,0.0,1.6124,11.468,378.76,380.37,404.57
179.16636,3.9195,7.732,0.0,0.0,1.6114,11.806,378.58,380.22,404.53
179.16936,3.709,7.7314,0.0,0.0,1.6102,11.301,378.4,380.08,404.5
179.17236,3.9455,7.7326,0.0,0.0,1.6136,11.934,378.19,379.95,404.49
179.17536,3.6932,7.7313,0.0,0.0,1.6135,11.236,377.97,379.82,404.49
179.17836,3.9552,7.7326,0.0,0.0,1.6111,11.992,377.76,379.69,404.49
179.18136,3.6991,7.732,0.0,0.0,1.6084,11.209,377.54,379.55,404.49
179.18436,3.9582,7.7323,0.0,0.0,1.6103,12.007,377.32,379.37,404.5
179.18736,3.7164,7.7278,0.0,0.0,1.6112,11.255,377.1,379.18,404.51
179.19036,3.9429,7.7297,0.0,0.0,1.614,11.991,376.89,379.0,404.52
179.19336,3.7362,7.7294,0.0,0.0,1.6123,11.298,376.79,378.82,404.52
179.19636,3.9247,7.7323,0.0,0.0,1.611,11.944,376.69,378.64,404.52
179.19936,3.7858,7.7315,0.0,0.0,1.611,11.419,376.59,378.46,404.52
179.20236,3.8863,7.7313,0.0,0.0,1.6137,11.868,376.44,378.3,404.49
179.20536,3.8291,7.7289,0.0,0.0,1.6121,11.559,376.27,378.14,404.45
179.20836,3.8523,7.7338,0.0,0.0,1.6108,11.732,376.09,377.99,404.42
179.21136,3.8737,7.7352,0.0,0.0,1.6098,11.664,375.91,377.83,404.37
179.21436,3.8017,7.7327,0.0,0.0,1.6112,11.608,375.7,377.67,404.3
179.21736,3.926,7.7289,0.0,0.0,1.6127,11.844,375.49,377.5,404.23
179.22036,3.7584,7.7301,0.0,0.0,1.6141,11.467,375.29,377.34,404.15
179.22336,3.9518,7.73,0.0,0.0,1.6108,11.932,375.19,377.17,404.14
179.22636,3.7332,7.7329,0.0,0.0,1.6107,11.349,375.09,377.0,404.12
179.22936,3.97,7.7332,0.0,0.0,1.6126,12.001,374.99,376.82,404.1
179.23236,3.7253,7.7322,0.0,0.0,1.6142,11.305,374.87,376.68,404.09
179.23536,3.991,7.7328,0.0,0.0,1.6126,12.098,374.74,376.56,404.09
179.23836,3.7331,7.7323,0.0,0.0,1.6096,11.331,374.61,376.43,404.09
179.24135,3.9847,7.7337,0.0,0.0,1.6101,12.113,374.47,376.31,404.08
179.24435,3.7536,7.7319,0.0,0.0,1.6123,11.343,374.3,376.2,404.02
179.24735,3.9577,7.7305,0.0,0.0,1.614,12.039,374.13,376.09,403.97
179.25035,3.792,7.7304,0.0,0.0,1.6135,11.459,373.95,375.98,403.91
179.6509,3.7691,7.7388,0.0,0.0,1.6152,11.436,347.11,343.13,293.53
180.2509,3.7183,7.746,0.0,0.0,1.6186,11.28,318.72,313.62,299.09
180.8509,3.6993,7.7532,0.0,0.0,1.6221,11.221,286.3,274.48,248.73
181.4509,3.6991,7.7619,0.0,0.0,1.6262,11.218,243.25,225.71,214.8
182.0509,3.6929,7.7743,0.0,0.0,1.6324,11.203,133.93,114.46,190.94
182.6509,3.7088,7.7898,0.0,0.0,1.6394,11.252,84.938,80.517,94.465
183.2509,3.6998,7.8117,0.0,0.0,1.6508,11.222,68.543,60.632,51.023
183.8509,3.722,7.8255,0.0,0.0,1.6569,11.292,53.265,47.33,33.719
184.4509,3.7002,7.8343,0.0,0.0,1.6616,11.225,44.016,40.162,28.239
185.0509,3.7123,7.839,0.0,0.0,1.6637,11.263,39.625,39.506,25.706
185.6509,3.6925,7.8449,0.0,0.0,1.6673,11.203,35.938,38.742,24.615
186.2509,3.71,7.8496,0.0,0.0,1.6691,11.256,33.06,30.674,23.805
186.8509,3.7141,7.8535,0.0,0.0,1.671,11.269,30.845,28.779,22.994
187.4509,3.7457,7.8576,0.0,0.0,1.6732,11.363,29.054,27.48,22.399
187.9186,3.7511,7.86,0.0,0.0,1.6746,11.384,27.898,26.755,22.055
188.5186,3.771,7.863,0.0,0.0,1.6755,11.434,26.687,25.659,21.679
189.1186,3.7847,7.8637,0.0,0.0,1.6765,11.485,25.848,24.775,21.523
189.7186,3.7899,7.8647,0.0,0.0,1.6766,11.493,27.393,27.127,22.339
190.3186,3.8093,7.8644,0.0,0.0,1.6769,11.561,29.859,29.058,24.248
190.9186,3.8215,7.8651,0.0,0.0,1.6766,11.591,31.649,30.711,26.245
191.5186,4.063,7.8657,0.0,0.0,1.6775,12.326,33.071,35.817,27.968
192.1186,3.8197,7.8664,0.0,0.0,1.6774,11.585,34.291,39.754,29.437
192.7186,3.848,7.8674,0.0,0.0,1.6785,11.673,35.276,39.754,30.746
193.3186,3.8508,7.8732,0.0,0.0,1.6808,11.683,36.127,39.754,31.778
193.9186,3.8672,7.8751,0.0,0.0,1.6821,11.733,36.77,39.754,32.931
194.5186,3.8279,7.8719,0.0,0.0,1.6801,11.611,37.36,39.754,33.861
195.1186,3.8414,7.8708,0.0,0.0,1.6803,11.653,37.831,39.754,34.753
195.7186,3.854,7.8725,0.0,0.0,1.6805,11.691,38.248,39.754,35.444
196.1186,3.8631,7.8727,0.0,0.0,1.6806,11.718,38.514,39.754,35.852