File: examples/dan-msc-case-studies/CS4/data/01 raw data/hyde_test_020.csv
Time(sec),Force(kN),Jaw(mm),PowAngle(deg),PTemp,Strain,Stress(MPa),TC1(C),TC2(C),TC3(C),TC4(C)
0.0,1.5112,0.28807,0.0,0.0061705,0.032505,1.7959,23.977,24.168,24.211,23.451
0.8,1.4831,0.00049724,0.0,2.2208,6.6923e-05,1.7602,23.93,24.016,24.347,23.511
1.6,1.4724,0.00055649,0.0,4.6208,6.8453e-05,1.7486,24.019,24.039,24.3,23.511
2.4,1.4377,0.00053689,0.0,7.0208,5.5232e-05,1.7072,23.989,24.076,24.365,23.524
3.125,1.4325,0.00063184,0.0,9.2144,5.882e-05,1.7001,23.929,24.058,24.308,23.555
3.925,1.4238,0.00026137,0.0,11.596,4.672e-05,1.6907,23.986,24.018,24.336,23.553
4.725,1.4118,0.00027373,0.0,13.996,3.5833e-05,1.6767,23.96,24.1,24.348,23.473
5.525,1.4078,0.0005526,0.0,16.396,6.5746e-05,1.6716,24.002,24.039,24.401,23.486
6.325,1.4095,0.00053034,0.0,18.796,5.5796e-05,1.6719,23.942,24.053,24.287,23.506
7.125,1.4203,0.00055376,0.0,21.196,8.2134e-05,1.6849,23.974,24.032,24.396,23.567
7.925,1.4223,0.00063073,0.0,23.596,8.3552e-05,1.6877,23.96,24.101,24.338,23.489
8.725,1.4157,0.0011996,21.397,25.996,0.00013982,1.6797,23.974,24.106,24.318,23.473
9.525,1.4414,0.0016033,32.451,28.396,0.00016302,1.7106,25.051,25.081,24.355,23.635
10.325,1.4641,0.00087174,34.416,30.796,0.00011028,1.7372,27.963,27.457,24.467,24.05
10.9665,1.4621,0.00042676,34.65,32.72,3.9556e-05,1.7356,30.473,29.498,24.686,25.005
11.7665,1.465,-0.0010876,34.594,35.12,-0.00010686,1.7384,33.453,38.139,25.128,26.528
12.5665,1.4637,-0.0016142,35.083,37.52,-0.00017617,1.7372,36.194,38.141,25.792,28.45
13.3665,1.462,-0.0020045,35.182,39.92,-0.00022216,1.7343,38.951,38.141,26.529,30.481
14.1665,1.4693,-0.0025136,34.973,42.32,-0.00029086,1.7435,41.644,38.685,27.364,32.464
14.9665,1.4702,-0.0033874,35.45,44.72,-0.00035161,1.7449,44.149,40.719,28.376,34.587
15.7665,1.4688,-0.0039571,35.274,47.12,-0.00043641,1.744,46.716,42.76,29.553,36.826
16.5665,1.4676,-0.0046294,35.518,49.52,-0.00051555,1.7418,49.167,44.736,30.8,38.957
17.3665,1.4721,-0.0062526,36.076,51.92,-0.00070669,1.7474,51.554,46.625,32.055,41.077
18.1665,1.4757,-0.0067461,36.246,54.32,-0.00073063,1.7514,54.0,48.628,33.515,43.258
18.9665,1.4771,-0.0077147,36.106,56.72,-0.00085778,1.7525,56.471,50.703,34.946,45.459
19.7665,1.4776,-0.0084851,36.31,59.12,-0.00094762,1.7543,58.948,52.653,36.485,47.675
20.5665,1.4838,-0.0092917,36.635,61.52,-0.0010392,1.7601,61.297,54.57,38.001,49.836
21.3665,1.4861,-0.010179,36.627,63.92,-0.0011088,1.7643,63.779,56.559,39.691,52.025
22.1665,1.4859,-0.011163,36.511,66.32,-0.0012427,1.7635,66.213,58.497,41.34,54.129
22.9665,1.4791,-0.01208,37.072,68.72,-0.0013457,1.7559,68.588,60.473,43.076,56.392
23.7665,1.4849,-0.012931,36.792,71.12,-0.001444,1.7626,71.056,62.534,44.782,58.595
24.5665,1.4893,-0.013814,36.824,73.52,-0.001523,1.7669,73.425,64.414,46.619,60.789
25.3665,1.4939,-0.015697,37.078,75.92,-0.0017406,1.7722,75.864,66.291,48.407,63.003
26.1665,1.494,-0.016683,37.103,78.32,-0.0018457,1.7726,78.25,68.239,50.241,65.173
26.9665,1.4859,-0.017323,37.191,80.72,-0.0019457,1.7632,80.619,70.13,52.131,67.375
27.7665,1.4882,-0.018456,37.758,83.12,-0.0020301,1.7669,82.971,72.035,53.974,69.592
28.5665,1.4868,-0.019625,37.773,85.52,-0.002178,1.7648,85.376,73.915,55.847,71.718
29.3665,1.4881,-0.020638,37.242,87.92,-0.0022842,1.7672,87.878,75.973,57.676,73.917
30.1665,1.4938,-0.021844,37.819,90.32,-0.0024367,1.7738,90.213,77.796,59.552,76.135
30.9665,1.4887,-0.022909,37.837,92.72,-0.0025374,1.7667,92.676,79.571,61.559,78.323
31.7665,1.4888,-0.024148,37.837,95.12,-0.0026789,1.7656,95.058,81.449,63.552,80.501
32.5665,1.497,-0.025252,38.194,97.52,-0.0027962,1.777,97.399,83.34,65.435,82.757
33.3665,1.4959,-0.02633,38.365,99.92,-0.0029413,1.7753,99.805,85.207,67.379,84.892
34.1665,1.5007,-0.027807,38.3,102.32,-0.0030814,1.782,102.27,87.098,69.227,87.088
34.9665,1.4985,-0.030023,38.501,104.72,-0.00333,1.7792,104.65,88.971,71.099,89.246
35.7615,1.4931,-0.03208,38.327,107.12,-0.003541,1.7728,107.04,90.792,72.952,91.401
36.5615,1.4932,-0.032441,38.551,109.51,-0.0035798,1.772,109.48,92.67,74.919,93.565
37.3615,1.4786,-0.033673,38.603,111.91,-0.0037533,1.7552,111.85,94.527,76.889,95.756
38.1615,1.4886,-0.035051,38.681,114.31,-0.0038967,1.7663,114.24,96.376,78.85,97.979
38.9615,1.4905,-0.036323,38.552,116.71,-0.0040108,1.7689,116.64,98.226,80.833,100.15
39.7615,1.4911,-0.037916,38.735,119.11,-0.0042076,1.7694,119.08,100.09,82.868,102.29
40.5615,1.4943,-0.039085,38.594,121.51,-0.0043495,1.773,121.49,102.0,84.785,104.49
41.3615,1.4958,-0.040546,38.697,123.91,-0.0045079,1.7759,123.9,103.8,86.825,106.66
42.1615,1.4942,-0.041864,38.65,126.31,-0.0046321,1.7742,126.34,105.72,88.814,108.9
42.9615,1.4947,-0.043208,39.24,128.71,-0.0047866,1.7746,128.65,107.54,90.875,111.02
43.7234,1.4963,-0.044451,38.581,130.99,-0.004927,1.777,131.06,109.29,92.809,113.05
44.5234,1.4939,-0.045492,39.225,133.39,-0.0050464,1.7733,133.32,111.07,94.803,115.31
45.3234,1.4902,-0.047729,38.979,135.79,-0.0053092,1.7689,135.8,113.04,96.839,117.41
46.1234,1.4931,-0.050486,39.119,138.19,-0.0055827,1.7718,138.2,114.85,98.804,119.66
46.9234,1.4896,-0.050457,39.157,140.59,-0.0055969,1.7671,140.53,116.7,100.79,121.8
47.7234,1.4934,-0.052259,39.438,142.99,-0.0057932,1.772,142.86,118.48,102.84,123.92
48.5234,1.491,-0.053868,39.428,145.39,-0.005989,1.7701,145.34,120.31,104.85,126.03
49.3234,1.4938,-0.055306,39.744,147.79,-0.0061235,1.7742,147.62,122.11,106.92,128.21
50.1234,1.4954,-0.056668,39.33,150.19,-0.0062805,1.7758,150.21,123.95,108.87,130.37
50.9234,1.4924,-0.058052,39.887,152.59,-0.0064333,1.7714,152.49,125.78,110.93,132.56
51.7234,1.4957,-0.059302,39.677,154.99,-0.0065862,1.7753,154.95,127.59,112.94,134.76
52.5234,1.4997,-0.060654,39.567,157.39,-0.0067185,1.7808,157.4,129.39,114.97,136.89
53.3234,1.5016,-0.063889,39.825,159.79,-0.0070827,1.781,159.74,131.23,117.01,139.07
54.1234,1.5023,-0.064235,39.81,162.19,-0.0071058,1.7829,162.2,133.08,119.06,141.24
54.9234,1.4923,-0.066082,39.485,164.59,-0.0073285,1.772,164.65,134.92,121.07,143.39
55.7234,1.4934,-0.067692,39.903,166.99,-0.007491,1.773,166.98,136.7,123.02,145.56
56.5234,1.4953,-0.06929,39.937,169.39,-0.0076679,1.7751,169.32,138.57,125.0,147.58
57.3234,1.4911,-0.070565,40.257,171.79,-0.0078195,1.7706,171.66,140.45,127.07,149.79
58.1234,1.4967,-0.071722,40.15,174.19,-0.0079556,1.7765,174.11,142.34,129.13,151.93
58.9234,1.4995,-0.073383,40.387,176.59,-0.0081258,1.7794,176.46,144.24,131.09,154.04
59.7234,1.5011,-0.076692,40.425,178.99,-0.0084935,1.7813,178.9,146.15,133.13,156.22
60.5234,1.4954,-0.076799,40.289,181.39,-0.0085187,1.7743,181.34,148.14,135.23,158.39
61.3234,1.4966,-0.07884,40.527,183.79,-0.0087399,1.777,183.71,150.09,137.24,160.53
62.1234,1.4991,-0.080663,40.572,186.19,-0.0089185,1.7801,186.19,152.07,139.29,162.71
62.9234,1.4892,-0.082246,40.462,188.59,-0.0091002,1.7678,188.54,154.08,141.3,164.89
63.7234,1.495,-0.083658,40.862,190.99,-0.0092549,1.7749,190.87,156.05,143.39,167.01
64.5234,1.4959,-0.084817,40.942,193.39,-0.009398,1.7748,193.29,158.32,145.48,169.24
65.3234,1.4959,-0.087106,40.71,195.79,-0.0096517,1.7749,195.76,160.4,147.58,171.44
66.1234,1.5,-0.09075,41.18,198.19,-0.010029,1.7798,198.06,162.49,149.63,173.67
66.9234,1.5052,-0.090853,41.139,200.59,-0.010081,1.7853,200.47,164.75,151.71,175.86
67.7234,1.4976,-0.092916,41.264,202.99,-0.010295,1.7779,202.9,166.91,153.77,178.1
68.4109,1.4926,-0.094582,41.123,205.06,-0.010479,1.7707,205.05,168.85,155.61,180.09
69.2109,1.5006,-0.096238,41.067,207.45,-0.010655,1.7812,207.44,170.99,157.7,182.36
70.0109,1.5009,-0.09777,41.359,209.85,-0.010803,1.7814,209.81,173.01,159.85,184.64
70.8109,1.501,-0.099125,41.247,212.25,-0.010949,1.7824,212.22,175.13,162.0,186.94
71.6109,1.5059,-0.10002,41.306,214.65,-0.011091,1.7888,214.57,177.29,164.23,189.23
72.4109,1.5041,-0.10395,41.409,217.05,-0.011513,1.7858,216.98,179.48,166.44,191.47
73.2109,1.4985,-0.10496,41.246,219.45,-0.011576,1.7792,219.51,181.61,168.69,193.74
74.0109,1.4937,-0.10706,41.778,221.85,-0.011837,1.7728,221.77,183.75,170.89,196.09
74.8109,1.4955,-0.10859,41.442,224.25,-0.012026,1.7747,224.25,185.87,173.26,198.39
75.6109,1.4964,-0.11019,41.905,226.65,-0.012196,1.7753,226.51,187.94,175.48,200.6
76.4109,1.5013,-0.11188,41.802,229.05,-0.012366,1.781,228.99,190.03,177.71,202.9
77.2109,1.5014,-0.11338,42.234,231.45,-0.012534,1.7818,231.28,192.17,179.99,205.1
78.0109,1.5024,-0.11486,41.829,233.85,-0.01271,1.7842,233.8,194.33,182.28,207.37
78.8109,1.5014,-0.11643,41.952,236.25,-0.012871,1.7832,236.21,196.38,184.54,209.68
79.6109,1.4984,-0.11781,42.04,238.65,-0.01301,1.7791,238.62,198.53,186.73,211.99
80.4109,1.4979,-0.11942,41.96,241.05,-0.013192,1.778,241.06,200.66,189.08,214.27
81.2109,1.4985,-0.12123,42.048,243.45,-0.013425,1.7784,243.45,202.73,191.3,216.52
82.0109,1.5026,-0.12394,41.803,245.85,-0.01371,1.7829,245.96,204.91,193.6,218.89
82.8109,1.5061,-0.12684,41.995,248.25,-0.014026,1.7868,248.24,206.95,195.85,221.14
83.6109,1.5075,-0.12884,41.838,250.65,-0.014227,1.7893,250.76,209.04,198.11,223.39
84.4109,1.5079,-0.12934,41.808,253.05,-0.014294,1.79,253.11,211.17,200.37,225.67
85.2109,1.5053,-0.13035,41.92,255.45,-0.014397,1.7868,255.46,213.36,202.68,227.95
86.0109,1.5135,-0.13219,41.912,257.85,-0.014619,1.7966,257.92,215.54,204.96,230.24
86.8109,1.5194,-0.13448,42.37,260.25,-0.014864,1.8026,260.13,217.63,207.2,232.56
87.6109,1.5187,-0.13653,41.991,262.65,-0.015093,1.8021,262.7,219.84,209.45,234.8
88.4109,1.5337,-0.13809,42.067,265.05,-0.015247,1.8194,265.06,222.03,211.7,237.08
89.2109,1.5361,-0.14003,42.197,267.45,-0.015456,1.8212,267.44,224.18,213.98,239.41
90.0109,1.5501,-0.14151,42.221,269.85,-0.015629,1.84,269.85,226.29,216.19,241.71
90.8109,1.5533,-0.14331,42.345,272.25,-0.015845,1.8441,272.23,228.51,218.52,243.99
91.6109,1.5577,-0.1454,42.319,274.65,-0.016042,1.8504,274.62,230.67,220.85,246.19
92.4109,1.5613,-0.1475,42.681,277.05,-0.016285,1.8544,276.91,232.85,223.08,248.55
93.2109,1.562,-0.14919,42.397,279.45,-0.016463,1.8542,279.48,235.07,225.36,250.84
94.0109,1.5679,-0.15103,42.665,281.85,-0.016686,1.8612,281.75,237.21,227.63,253.16
94.8109,1.5735,-0.15286,42.441,284.25,-0.016869,1.8666,284.25,239.45,229.92,255.5
95.6109,1.5854,-0.15468,42.597,286.65,-0.017069,1.88,286.63,241.6,232.25,257.79
96.4109,1.5865,-0.15664,42.617,289.05,-0.017283,1.8834,289.04,243.84,234.5,260.1
97.2109,1.5925,-0.15872,42.937,291.45,-0.017525,1.8907,291.36,246.02,236.77,262.38
98.0109,1.5881,-0.16024,42.616,293.85,-0.017693,1.8852,293.89,248.26,239.03,264.7
98.8109,1.5985,-0.1614,42.536,296.25,-0.017812,1.8987,296.31,250.43,241.34,266.96
99.6109,1.602,-0.16334,42.636,298.65,-0.018006,1.901,298.64,252.64,243.69,269.32
100.4109,1.6042,-0.16662,42.359,301.05,-0.018373,1.903,301.18,254.81,245.98,271.66
101.1404,1.6093,-0.16963,42.7,303.24,-0.018691,1.9101,303.24,256.77,248.08,273.8
101.9404,1.6152,-0.17126,42.627,305.64,-0.018892,1.9173,305.64,258.92,250.38,276.11
102.7404,1.6207,-0.17186,42.401,308.04,-0.01898,1.9228,308.09,261.1,252.69,278.37
103.5404,1.6276,-0.1727,42.367,310.44,-0.019076,1.931,310.58,263.29,255.06,280.68
104.3404,1.6303,-0.17444,42.212,312.84,-0.019227,1.9341,313.0,265.46,257.37,282.97
105.1404,1.635,-0.17606,42.195,315.24,-0.01941,1.9402,315.37,267.47,259.61,285.3
105.9404,1.6379,-0.17811,42.383,317.64,-0.019638,1.9438,317.66,269.69,261.98,287.59
106.7404,1.6334,-0.18031,42.312,320.04,-0.019883,1.9395,320.11,271.78,264.32,289.77
107.5404,1.636,-0.1826,42.397,322.44,-0.020111,1.9426,322.42,273.85,266.62,291.93
108.3404,1.6365,-0.18481,42.714,324.84,-0.02036,1.9418,324.74,275.94,268.93,294.15
109.0002,1.6434,-0.18674,42.404,326.82,-0.020573,1.9508,326.9,277.7,271.71,296.04
109.8002,1.6455,-0.18876,42.539,329.22,-0.020809,1.953,329.2,279.85,274.66,298.28
110.6002,1.6468,-0.19101,42.87,331.62,-0.021058,1.9556,331.53,282.0,278.98,300.5
111.4002,1.6456,-0.19327,42.763,334.02,-0.021277,1.9547,334.0,284.13,278.39,302.81
112.2002,1.6414,-0.19554,42.947,336.42,-0.021525,1.9496,336.34,286.21,280.81,305.08
113.0002,1.64,-0.19745,42.818,338.82,-0.02176,1.9467,338.79,288.39,283.31,307.41
113.8002,1.6482,-0.19981,42.971,341.22,-0.022018,1.9557,341.12,290.53,285.74,309.73
114.6002,1.6556,-0.20183,42.849,343.62,-0.022209,1.9636,343.62,292.71,288.14,312.01
115.4002,1.657,-0.20401,42.75,346.02,-0.022465,1.9656,346.03,294.91,290.68,314.38
116.2002,1.6576,-0.20605,42.867,348.42,-0.022703,1.9682,348.41,297.03,293.21,316.6
117.0002,1.6562,-0.20808,43.046,350.82,-0.022911,1.9669,350.76,299.21,295.62,318.86
117.8002,1.6543,-0.21042,42.979,353.22,-0.023151,1.9643,353.24,301.37,298.16,321.04
118.6002,1.6527,-0.21254,43.422,355.62,-0.023384,1.9616,355.51,303.46,301.05,323.36
119.4002,1.6489,-0.21462,43.074,358.02,-0.023639,1.9567,358.07,305.65,304.6,325.62
120.2002,1.6548,-0.21672,43.111,360.42,-0.023865,1.9638,360.36,308.15,308.24,327.92
121.0002,1.6591,-0.2175,43.002,362.82,-0.023928,1.9683,362.85,310.32,311.03,330.18
121.8002,1.6653,-0.22021,43.204,365.22,-0.024204,1.9753,365.21,312.51,313.95,332.54
122.6002,1.6723,-0.22403,43.098,367.62,-0.024643,1.9845,367.65,314.77,316.52,334.91
123.4002,1.6707,-0.22658,43.168,370.02,-0.024936,1.9834,370.0,316.95,319.63,337.21
124.2002,2.0593,-0.22368,43.071,372.42,-0.024625,2.4441,372.44,318.84,322.24,339.53
125.0002,2.527,-0.21782,43.336,374.82,-0.023982,2.9987,374.8,319.5,326.54,341.85
125.8002,2.8123,-0.21502,43.427,377.22,-0.02369,3.3377,377.21,320.34,329.46,344.3
126.6002,3.0014,-0.21423,43.526,379.62,-0.023579,3.5617,379.54,321.47,332.64,346.61
127.4002,3.1399,-0.21447,43.524,382.02,-0.023588,3.7245,381.94,322.87,335.93,348.78
128.2002,3.2371,-0.21563,43.57,384.42,-0.02372,3.8411,384.36,324.56,339.2,350.94
129.0002,3.347,-0.21638,43.819,386.82,-0.023819,3.9716,386.71,326.5,341.82,353.06
129.8002,3.457,-0.21721,43.672,389.22,-0.023902,4.1047,389.18,328.43,344.39,355.23
130.6002,3.5405,-0.21801,43.774,391.62,-0.023983,4.2035,391.56,330.46,346.76,357.42
131.4002,3.592,-0.21922,43.696,394.02,-0.024113,4.264,394.04,332.48,349.16,359.52
132.2002,3.6546,-0.22044,43.55,396.42,-0.024262,4.338,396.45,334.54,351.49,361.66
133.0002,3.6921,-0.22179,43.627,398.82,-0.024392,4.3805,398.85,336.48,353.88,363.69
133.7702,3.7079,-0.22273,41.463,400.0,-0.024522,4.3987,400.87,338.18,355.88,365.7
134.5702,3.7262,-0.22337,40.607,400.0,-0.024576,4.4203,400.89,338.74,357.96,367.3
135.2072,3.7394,-0.22406,40.237,400.0,-0.024661,4.4396,400.83,339.25,359.29,368.15
136.0072,3.7367,-0.22512,40.018,400.0,-0.02476,4.4364,400.72,340.0,360.7,368.75
136.8072,3.7302,-0.22606,39.491,400.0,-0.02485,4.4288,400.64,340.51,361.85,369.17
137.6072,3.732,-0.22678,39.235,400.0,-0.024934,4.4295,400.57,340.91,362.8,369.42
138.4072,3.7385,-0.22768,38.683,400.0,-0.025053,4.436,400.55,341.34,363.56,369.57
139.2072,3.7484,-0.22865,38.702,400.0,-0.025151,4.447,400.43,341.77,364.22,369.62
140.0072,3.7579,-0.2295,38.651,400.0,-0.025227,4.4592,400.32,342.09,364.7,369.63
140.8072,4.0075,-0.22934,38.548,400.0,-0.025209,4.7556,400.31,342.48,365.02,369.56
141.6072,4.4318,-0.22544,38.542,400.0,-0.024807,5.2606,400.19,342.83,365.33,369.57
142.4072,4.7248,-0.22193,38.706,400.0,-0.024413,5.6089,400.08,343.26,365.63,369.54
143.2072,4.8994,-0.22005,38.948,400.0,-0.02419,5.8167,400.01,344.01,365.8,369.64
144.0072,4.974,-0.21953,38.905,400.0,-0.024139,5.9035,399.99,344.95,366.04,369.76
144.8072,5.015,-0.21951,38.703,400.0,-0.024153,5.9508,400.06,345.77,366.26,369.88
145.6072,5.053,-0.2213,42.876,400.0,-0.024337,5.9941,403.43,348.49,366.67,370.3
146.4072,5.0686,-0.2218,41.456,400.0,-0.024393,6.0137,406.02,350.56,367.49,371.73
147.2072,5.0805,-0.22284,41.188,400.0,-0.024521,6.0292,407.76,352.15,368.42,373.16
148.0072,5.0869,-0.22432,41.55,400.0,-0.024706,6.038,409.2,353.71,369.42,374.69
148.8072,5.0922,-0.22725,43.636,400.0,-0.025026,6.0451,411.38,355.7,370.52,376.14
149.6072,5.091,-0.23048,42.241,400.0,-0.025375,6.0436,414.22,358.06,371.83,378.06
150.4072,5.0904,-0.23303,41.996,400.0,-0.025635,6.0419,416.33,360.0,373.34,380.06
151.2072,5.0956,-0.23403,41.829,400.0,-0.025718,6.0452,417.96,361.87,374.93,382.09
152.0072,5.1054,-0.23385,41.968,400.0,-0.025649,6.0564,420.76,364.41,376.63,384.05
152.8072,5.1107,-0.23215,41.969,400.0,-0.025518,6.0627,421.88,365.89,378.52,386.37
153.6072,5.1252,-0.23378,44.787,400.0,-0.025736,6.0812,423.56,367.91,380.25,388.32
154.4072,5.1393,-0.23724,46.579,400.0,-0.026125,6.1,426.94,371.31,382.41,390.77
155.2072,5.1295,-0.2396,42.845,400.0,-0.026309,6.0894,430.05,374.28,384.75,393.72
156.0072,5.0798,-0.23284,0.13526,400.0,-0.025598,6.0308,425.45,371.63,387.0,396.18
156.8072,5.0998,-0.23137,35.618,400.0,-0.025456,6.0527,414.58,366.4,387.5,394.62
157.6072,5.0902,-0.23034,34.124,400.0,-0.025349,6.0401,411.34,366.34,387.19,392.14
158.4072,5.1114,-0.23091,34.655,400.0,-0.02539,6.0636,410.08,366.88,386.84,390.16
159.2072,5.116,-0.23047,35.64,400.0,-0.025343,6.0698,406.92,365.62,386.32,388.57
160.0072,5.1311,-0.23083,36.244,400.0,-0.025399,6.0888,405.36,365.55,385.59,386.8
160.8072,5.1316,-0.23122,36.205,400.0,-0.025436,6.091,404.55,365.58,384.83,385.46
161.6072,5.1341,-0.23172,35.265,400.0,-0.025467,6.0949,403.98,365.62,384.17,384.49
162.4072,5.1257,-0.23224,36.022,400.0,-0.025539,6.0843,403.03,365.38,383.45,383.73
163.2072,5.1333,-0.23332,36.618,400.0,-0.025677,6.0924,402.98,365.76,382.85,383.02
164.0072,5.1348,-0.23429,36.354,400.0,-0.025762,6.0918,403.06,365.9,382.35,382.66
164.8072,5.1202,-0.23257,25.998,400.0,-0.025558,6.0746,401.95,365.19,381.99,382.5
165.6072,5.1525,-0.23406,36.301,400.0,-0.025727,6.1129,399.09,364.06,381.23,381.49
166.2128,5.1584,-0.2345,35.274,400.0,-0.025792,6.1208,399.4,364.51,380.68,380.75
167.0128,5.1582,-0.23493,35.497,400.0,-0.02584,6.1233,399.33,364.72,380.19,380.34
167.8128,5.1516,-0.23604,35.636,400.0,-0.025932,6.1146,399.4,364.89,379.74,380.01
168.6128,5.1501,-0.23657,35.851,400.0,-0.026,6.1125,399.36,365.01,379.38,379.93
169.4128,5.1525,-0.23715,35.508,400.0,-0.026083,6.1142,399.45,365.18,379.13,379.79
170.2128,5.1581,-0.23779,35.74,400.0,-0.026142,6.1214,399.43,365.23,378.96,379.73
171.0128,5.1679,-0.23843,35.797,400.0,-0.026181,6.1317,399.45,365.37,378.84,379.77
171.8128,5.1757,-0.23888,35.86,400.0,-0.026248,6.1409,399.45,365.55,378.7,379.82
172.6128,5.1829,-0.23932,36.031,400.0,-0.026309,6.1505,399.43,365.71,378.65,379.9
173.4128,5.1788,-0.23984,35.842,400.0,-0.026373,6.1472,399.5,365.86,378.59,379.95
174.2128,5.1843,-0.24024,35.956,400.0,-0.026407,6.1544,399.44,365.98,378.63,380.05
175.0128,5.1838,-0.24253,35.695,400.0,-0.026677,6.1523,399.5,366.26,378.64,380.12
175.8128,5.19,-0.24582,35.663,400.0,-0.027056,6.159,399.49,366.38,378.68,380.24
176.6128,5.1895,-0.24641,35.692,400.0,-0.027048,6.1576,399.48,366.59,378.72,380.33
177.4128,5.1985,-0.24442,35.567,400.0,-0.026836,6.1681,399.53,366.82,378.81,380.42
178.2128,5.1973,-0.24609,35.543,400.0,-0.027054,6.1661,399.5,366.97,378.89,380.54
178.61373,5.2101,0.014577,0.0,69.78,0.00068165,6.1905,399.45,367.14,378.72,380.54
178.61505,5.2283,0.015089,0.0,0.00022142,0.0019739,6.2104,399.46,367.18,378.66,380.54
178.61637,5.1139,0.019488,0.0,6.6071e-10,0.0016292,6.0476,399.47,367.23,378.61,380.53
178.61769,5.2758,0.012558,0.0,1.8957e-15,0.00085963,6.2597,399.49,367.27,378.56,380.52
178.61901,5.2197,0.018812,0.0,5.2927e-21,0.0025653,6.1854,399.49,367.26,378.59,380.52
178.62033,5.1448,0.015088,0.0,1.4484e-26,0.0011692,6.1041,399.49,367.25,378.63,380.53
178.62165,5.2066,0.011901,0.0,6.520000000000001e-32,0.0021721,6.1855,399.49,367.23,378.67,380.54
178.62297,5.2248,0.0072454,0.0,4.1788e-37,0.0012577,6.1878,399.49,367.22,378.71,380.55
178.62429,5.1488,0.010702,0.0,1.6297e-42,0.0016902,6.1126,399.49,367.2,378.75,380.56
178.62561,5.2122,0.011048,0.0,0.0,0.0011612,6.2004,399.49,367.18,378.79,380.56
178.62693,5.2176,0.011819,0.0,0.0,0.0014874,6.1859,399.49,367.17,378.83,380.57
178.62825,5.1554,0.012384,0.0,0.0,0.00062303,6.1174,399.49,367.16,378.86,380.58
178.62957,5.2061,0.015307,0.0,0.0,0.00192,6.183,399.49,367.16,378.88,380.59
178.63089,5.2179,0.015318,0.0,0.0,0.00078405,6.1879,399.5,367.16,378.9,380.6
178.63221,5.1442,0.012614,0.0,0.0,0.0013652,6.1078,399.5,367.16,378.92,380.6
178.63353,5.2051,0.01642,0.0,0.0,0.0014795,6.1861,399.51,367.16,378.94,380.61
178.63485,5.2202,0.012389,0.0,0.0,0.0010193,6.1867,399.51,367.16,378.96,380.62
178.63617,5.1475,0.009663,0.0,0.0,0.0022958,6.1023,399.51,367.16,378.98,380.63
178.63749,5.1977,0.011282,0.0,0.0,0.0016065,6.1759,399.52,367.16,379.0,380.64
178.63881,5.2089,0.0093374,0.0,0.0,0.00142,6.1823,399.52,367.16,379.01,380.66
178.64013,5.1431,0.0098204,0.0,0.0,0.0015184,6.1004,399.52,367.16,379.01,380.68
178.64145,5.1909,0.010544,0.0,0.0,0.0013513,6.1751,399.52,367.16,379.01,380.7
178.64277,5.2103,0.016495,0.0,0.0,0.0008071,6.1656,399.52,367.16,379.01,380.73
178.64409,5.1301,0.014642,0.0,0.0,0.0018565,6.0922,399.52,367.16,379.01,380.75
178.64541,5.2005,0.014319,0.0,0.0,0.00042761,6.1655,399.52,367.16,379.01,380.78
178.64673,5.2108,0.01653,0.0,0.0,0.0018801,6.1693,399.52,367.16,379.01,380.8
178.64805,5.1371,0.013725,0.0,0.0,0.001025,6.1021,399.52,367.15,379.01,380.82
178.64937,5.1915,0.01323,0.0,0.0,0.0013676,6.1714,399.52,367.14,379.0,380.82
178.65069,5.2086,0.01152,0.0,0.0,0.0016971,6.1643,399.53,367.13,379.0,380.81
178.65201,5.1348,0.0097659,0.0,0.0,0.0013753,6.0912,399.53,367.12,378.99,380.81
178.65333,5.1899,0.0079409,0.0,0.0,0.0020346,6.1655,399.54,367.11,378.99,380.8
178.65465,5.2056,0.0091981,0.0,0.0,0.00162,6.1716,399.54,367.09,378.99,380.8
178.65597,5.1246,0.014217,0.0,0.0,0.0014188,6.081,399.54,367.08,378.98,380.8
178.65729,5.1819,0.014699,0.0,0.0,0.0011795,6.1612,399.55,367.07,378.98,380.79
178.65861,5.2088,0.013012,0.0,0.0,0.0017387,6.1668,399.54,367.09,378.98,380.77
178.65993,5.1416,0.016107,0.0,0.0,0.00045749,6.0959,399.54,367.14,378.99,380.73
178.66125,5.1836,0.013283,0.0,0.0,0.0019598,6.163,399.53,367.19,379.0,380.7
178.66257,5.2006,0.012926,0.0,0.0,0.00086822,6.1597,399.52,367.23,379.0,380.66
178.66389,5.1273,0.012446,0.0,0.0,0.0013598,6.0893,399.51,367.28,379.01,380.63
178.66521,5.1897,0.012582,0.0,0.0,0.0017441,6.1692,399.5,367.33,379.02,380.59
178.66653,5.215,0.0075556,0.0,0.0,0.001206,6.1709,399.5,367.38,379.03,380.56
178.66785,5.1484,0.0093673,0.0,0.0,0.0014826,6.1143,399.49,367.43,379.04,380.52
178.66917,5.2041,0.010955,0.0,0.0,0.0016752,6.1813,400.35,368.27,379.04,380.5
178.67049,5.1786,0.012858,0.0,0.0,0.0013722,6.1363,401.25,369.15,379.04,380.48
178.67181,5.1337,0.012157,0.0,0.0,0.0014231,6.0934,402.15,370.03,379.04,380.46
178.67313,5.2085,0.016139,0.0,0.0,0.0016542,6.1889,403.05,370.91,379.04,380.44
178.67445,5.1931,0.014182,0.0,0.0,0.00060044,6.1536,403.94,371.78,379.04,380.42
178.67577,5.2204,0.012979,0.0,0.0,0.0021593,6.1338,404.84,372.66,379.04,380.4
178.67709,15.55,0.060092,0.0,0.0,0.0047678,16.022,405.74,373.54,379.04,380.38
178.67841,39.62,0.15965,0.0,0.0,0.018432,46.063,406.83,374.59,379.03,380.37
178.67973,59.766,0.20975,0.0,0.0,0.023321,69.971,408.23,375.93,379.03,380.36
178.68105,74.339,0.35584,0.0,0.0,0.039877,87.718,409.64,377.26,379.02,380.36
178.68237,80.412,0.50153,0.0,0.0,0.056793,95.171,411.04,378.59,379.01,380.35
178.68369,84.649,0.6629,0.0,0.0,0.075629,100.26,412.44,379.92,379.0,380.35
178.68501,87.342,0.84282,0.0,0.0,0.096784,103.51,413.84,381.25,378.99,380.35
178.68633,90.075,1.0668,0.0,0.0,0.12409,106.72,415.24,382.58,378.99,380.34
178.68765,91.891,1.3244,0.0,0.0,0.15622,109.01,416.64,383.92,378.98,380.34
178.68897,92.971,1.5796,0.0,0.0,0.18827,110.28,417.81,385.11,378.98,380.34
178.69029,93.949,1.847,0.0,0.0,0.22597,111.47,418.91,386.26,378.98,380.35
178.69161,94.432,2.1098,0.0,0.0,0.26073,112.03,420.02,387.41,378.98,380.36
178.69293,95.043,2.3723,0.0,0.0,0.30024,112.77,421.12,388.57,378.98,380.37
178.69425,95.69,2.6272,0.0,0.0,0.33646,113.51,422.23,389.72,378.98,380.38
178.69557,96.229,2.8821,0.0,0.0,0.37574,114.14,423.34,390.88,378.98,380.38
178.69689,96.598,3.134,0.0,0.0,0.41633,114.63,424.44,392.03,378.98,380.39
178.69821,97.089,3.3795,0.0,0.0,0.4561,115.2,425.34,393.22,378.98,380.4
178.69953,97.569,3.6308,0.0,0.0,0.49758,115.75,425.57,394.53,378.99,380.43
178.70085,97.956,3.88,0.0,0.0,0.54256,116.23,425.8,395.83,378.99,380.45
178.70217,98.453,4.126,0.0,0.0,0.58693,116.81,426.03,397.14,379.0,380.47
178.70349,98.773,4.3703,0.0,0.0,0.63481,117.18,426.26,398.44,379.01,380.5
178.70481,99.057,4.6157,0.0,0.0,0.68443,117.55,426.49,399.75,379.02,380.52
178.70613,99.398,4.8531,0.0,0.0,0.7319,117.94,426.72,401.05,379.03,380.55
178.70745,99.671,5.0933,0.0,0.0,0.78803,118.25,426.95,402.36,379.03,380.57
178.70877,99.925,5.3311,0.0,0.0,0.84059,118.58,426.52,403.11,379.01,380.57
178.71009,100.13,5.5611,0.0,0.0,0.89704,118.81,425.75,403.57,378.98,380.57
178.71141,100.44,5.7909,0.0,0.0,0.95694,119.15,424.98,404.04,378.94,380.56
178.71273,100.66,6.027,0.0,0.0,1.016,119.46,424.2,404.5,378.91,380.55
178.71405,101.0,6.2498,0.0,0.0,1.079,119.84,423.43,404.97,378.87,380.54
178.71537,101.19,6.4729,0.0,0.0,1.1497,120.06,422.66,405.43,378.83,380.53
178.71669,101.45,6.6872,0.0,0.0,1.2124,120.38,421.88,405.9,378.8,380.53
178.71801,101.89,6.8949,0.0,0.0,1.2863,120.89,421.11,406.27,378.76,380.52
178.71933,102.27,7.0892,0.0,0.0,1.3566,121.34,420.35,405.61,378.76,380.5
178.72065,102.69,7.281,0.0,0.0,1.4284,121.85,419.59,404.95,378.75,380.48
178.72197,103.09,7.4549,0.0,0.0,1.5045,122.31,418.83,404.29,378.74,380.47
178.72329,103.3,7.6078,0.0,0.0,1.5705,122.57,418.07,403.63,378.73,380.45
178.72461,96.41,7.723,0.0,0.0,1.6294,115.63,417.3,402.97,378.72,380.44
178.72593,89.538,7.7455,0.0,0.0,1.639,106.39,416.54,402.31,378.72,380.42
178.72725,85.968,7.7718,0.0,0.0,1.6486,102.21,415.78,401.65,378.71,380.4
178.72857,83.217,7.7844,0.0,0.0,1.6545,98.9,415.16,400.94,378.71,380.42
178.72989,81.184,7.797,0.0,0.0,1.6601,96.445,414.66,400.17,378.72,380.46
178.73121,79.607,7.7994,0.0,0.0,1.6538,94.564,414.17,399.41,378.73,380.5
178.73253,78.185,7.8018,0.0,0.0,1.6659,92.835,413.68,398.65,378.75,380.54
178.73385,76.942,7.8084,0.0,0.0,1.6616,91.332,413.19,397.88,378.76,380.58
178.73517,75.797,7.8147,0.0,0.0,1.6676,89.972,412.7,397.12,378.77,380.62
178.73649,74.859,7.8145,0.0,0.0,1.6733,88.892,412.2,396.36,378.78,380.66
178.73781,73.93,7.8209,0.0,0.0,1.6722,87.769,411.71,395.59,378.79,380.7
178.73913,73.046,7.8217,0.0,0.0,1.6757,86.736,411.37,395.0,378.81,380.71
178.74045,72.214,7.8208,0.0,0.0,1.6756,85.747,411.03,394.42,378.82,380.73
178.74177,71.334,7.8223,0.0,0.0,1.6745,84.694,410.7,393.84,378.83,380.75
178.74309,70.448,7.8286,0.0,0.0,1.6767,83.635,410.37,393.26,378.84,380.76
178.74441,69.621,7.8327,0.0,0.0,1.6778,82.652,410.03,392.67,378.85,380.78
178.74573,68.719,7.8309,0.0,0.0,1.6736,81.595,409.7,392.09,378.87,380.79
178.74705,67.893,7.8343,0.0,0.0,1.6825,80.609,409.37,391.51,378.88,380.81
178.74837,67.205,7.8365,0.0,0.0,1.673,79.802,409.0,390.97,378.89,380.82
178.74969,66.499,7.8336,0.0,0.0,1.6794,78.938,408.57,390.51,378.89,380.81
178.75101,65.897,7.8321,0.0,0.0,1.6788,78.228,408.14,390.05,378.89,380.8
178.75233,65.451,7.8365,0.0,0.0,1.6783,77.702,407.71,389.59,378.89,380.79
178.75365,64.963,7.8313,0.0,0.0,1.6833,77.123,407.28,389.13,378.89,380.79
178.75497,64.488,7.832,0.0,0.0,1.6834,76.551,406.85,388.66,378.89,380.78
178.75629,64.111,7.8348,0.0,0.0,1.6791,76.095,406.42,388.2,378.89,380.77
178.75761,63.626,7.8423,0.0,0.0,1.6844,75.516,405.99,387.74,378.89,380.76
178.75893,63.113,7.8369,0.0,0.0,1.6795,74.93,405.7,387.47,378.87,380.73
178.76025,62.345,7.8398,0.0,0.0,1.6795,74.071,405.45,387.24,378.85,380.7
178.76157,60.907,7.8396,0.0,0.0,1.6842,72.359,405.2,387.02,378.83,380.67
178.76289,58.882,7.8338,0.0,0.0,1.6743,70.014,404.95,386.8,378.81,380.64
178.76421,56.545,7.8326,0.0,0.0,1.6809,67.208,404.7,386.57,378.79,380.61
178.76553,53.797,7.8289,0.0,0.0,1.673,64.015,404.45,386.35,378.77,380.58
178.76685,50.569,7.8201,0.0,0.0,1.6709,60.175,404.2,386.13,378.75,380.54
178.76817,41.077,7.7975,0.0,0.0,1.6665,49.834,403.99,385.94,378.73,380.52
178.76949,15.445,7.7366,0.0,0.0,1.6337,19.331,403.93,385.91,378.73,380.51
178.77081,2.8046,7.6929,0.0,0.0,1.611,3.7601,403.86,385.87,378.73,380.5
178.77213,5.202,7.6896,0.0,0.0,1.6122,5.8585,403.8,385.84,378.73,380.49
178.77345,4.3103,7.6945,0.0,0.0,1.6105,5.2297,403.74,385.8,378.73,380.48
178.77477,4.4885,7.7071,0.0,0.0,1.6165,5.2652,403.67,385.76,378.73,380.48
178.77609,4.9467,7.7036,0.0,0.0,1.619,5.934,403.61,385.73,378.73,380.47
178.77741,4.4853,7.7009,0.0,0.0,1.6099,5.1722,403.55,385.69,378.73,380.46
178.77873,4.3399,7.715,0.0,0.0,1.6243,5.2263,403.53,385.67,378.73,380.48
178.78005,4.7711,7.7097,0.0,0.0,1.6171,5.6421,403.55,385.65,378.71,380.51
178.78137,4.658,7.7056,0.0,0.0,1.619,5.5115,403.57,385.64,378.7,380.54
178.78269,4.3797,7.7106,0.0,0.0,1.6212,5.1816,403.59,385.62,378.69,380.57
178.78401,4.5772,7.7121,0.0,0.0,1.619,5.4603,403.61,385.6,378.68,380.61
178.78533,4.6439,7.7097,0.0,0.0,1.6187,5.4948,403.63,385.59,378.67,380.64
178.78665,4.4263,7.7151,0.0,0.0,1.6248,5.2979,403.65,385.57,378.65,380.67
178.78797,4.7007,7.7152,0.0,0.0,1.6162,5.5752,403.68,385.55,378.64,380.7
178.78929,4.5481,7.7113,0.0,0.0,1.6227,5.3601,403.74,385.46,378.62,380.69
178.79061,4.533,7.7087,0.0,0.0,1.6197,5.395,403.81,385.37,378.6,380.68
178.79193,4.5767,7.7125,0.0,0.0,1.6165,5.4378,403.88,385.28,378.58,380.68
178.79325,4.6122,7.7063,0.0,0.0,1.6214,5.4551,403.95,385.19,378.56,380.67
178.79457,4.5723,7.7074,0.0,0.0,1.6163,5.4275,404.01,385.1,378.54,380.66
178.79589,4.5992,7.707,0.0,0.0,1.6203,5.4603,404.08,385.0,378.52,380.65
178.79721,4.5741,7.7049,0.0,0.0,1.6189,5.4107,404.15,384.91,378.5,380.64
178.79853,4.5349,7.7055,0.0,0.0,1.6182,5.387,404.19,384.83,378.49,380.64
178.79985,4.6344,7.7061,0.0,0.0,1.617,5.506,404.19,384.77,378.49,380.64
178.80117,4.6413,7.714,0.0,0.0,1.6194,5.4823,404.19,384.71,378.49,380.64
178.80249,4.5448,7.7114,0.0,0.0,1.6144,5.3843,404.2,384.64,378.49,380.64
178.80381,4.5782,7.7123,0.0,0.0,1.6231,5.4508,404.2,384.58,378.49,380.64
178.80513,4.6539,7.7132,0.0,0.0,1.6181,5.512,404.21,384.52,378.49,380.64
178.80645,4.5862,7.7114,0.0,0.0,1.6184,5.4389,404.21,384.45,378.49,380.64
178.80777,4.6214,7.71,0.0,0.0,1.6238,5.4998,404.21,384.39,378.49,380.64
178.80909,4.6344,7.7095,0.0,0.0,1.6168,5.482,404.23,384.32,378.5,380.65
178.81041,4.5319,7.7093,0.0,0.0,1.623,5.3886,404.24,384.26,378.52,380.65
178.81173,4.6429,7.7005,0.0,0.0,1.6204,5.5298,404.25,384.2,378.53,380.66
178.81305,4.6901,7.7059,0.0,0.0,1.6188,5.5351,404.26,384.13,378.54,380.67
178.81437,4.5669,7.7101,0.0,0.0,1.6185,5.4202,404.27,384.07,378.55,380.68
178.81569,4.6134,7.7105,0.0,0.0,1.6199,5.4863,404.28,384.01,378.56,380.69
178.81701,4.6403,7.7097,0.0,0.0,1.6143,5.5026,404.3,383.94,378.58,380.69
178.81833,4.5607,7.7124,0.0,0.0,1.6227,5.423,404.31,383.87,378.58,380.7
178.81965,4.6461,7.7106,0.0,0.0,1.6145,5.5325,404.32,383.77,378.56,380.71
178.82097,4.6739,7.7075,0.0,0.0,1.6193,5.534,404.33,383.68,378.55,380.72
178.82229,4.541,7.712,0.0,0.0,1.6203,5.3839,404.34,383.58,378.53,380.73
178.82361,4.6096,7.7113,0.0,0.0,1.6175,5.48,404.36,383.49,378.51,380.73
178.82493,4.6492,7.7046,0.0,0.0,1.6242,5.5189,404.37,383.39,378.5,380.74
178.82625,4.5505,7.7073,0.0,0.0,1.6219,5.4118,404.38,383.29,378.48,380.75
178.82757,4.6111,7.7074,0.0,0.0,1.6182,5.4884,404.39,383.2,378.47,380.76
178.82889,4.6358,7.7096,0.0,0.0,1.6218,5.509,404.4,383.11,378.47,380.76
178.83021,4.5655,7.7088,0.0,0.0,1.6182,5.4028,404.4,383.03,378.48,380.76
178.83153,4.645,7.7134,0.0,0.0,1.6165,5.5057,404.4,382.95,378.48,380.76
178.83285,4.6323,7.7113,0.0,0.0,1.6222,5.4792,404.4,382.86,378.49,380.76
178.83417,4.5464,7.7091,0.0,0.0,1.6132,5.3832,404.4,382.78,378.5,380.76
178.83549,4.6606,7.713,0.0,0.0,1.621,5.5425,404.4,382.69,378.51,380.76
178.83681,4.6452,7.7122,0.0,0.0,1.6172,5.5005,404.4,382.61,378.52,380.76
178.83813,4.5784,7.7095,0.0,0.0,1.6183,5.4332,404.4,382.52,378.53,380.76
178.83945,4.6219,7.7067,0.0,0.0,1.6212,5.4894,404.4,382.42,378.55,380.76
178.84077,4.6012,7.7097,0.0,0.0,1.6204,5.4578,404.41,382.32,378.57,380.75
178.84209,4.5531,7.7056,0.0,0.0,1.6208,5.4186,404.42,382.21,378.6,380.75
178.84341,4.6422,7.7111,0.0,0.0,1.6245,5.5302,404.43,382.11,378.62,380.74
178.84473,4.6315,7.7124,0.0,0.0,1.6183,5.4941,404.44,382.01,378.65,380.74
178.84605,4.5378,7.7141,0.0,0.0,1.6194,5.4061,404.44,381.9,378.67,380.74
178.84737,4.6522,7.7137,0.0,0.0,1.6236,5.5295,404.45,381.8,378.69,380.73
178.84869,4.6661,7.712,0.0,0.0,1.613,5.5113,404.45,381.69,378.71,380.72
178.85001,4.638,7.7164,0.0,0.0,1.6244,5.5001,404.43,381.58,378.72,380.7
178.85133,4.7173,7.7104,0.0,0.0,1.6171,5.5967,404.41,381.47,378.74,380.69
178.85265,4.7354,7.7126,0.0,0.0,1.6198,5.618,404.4,381.36,378.75,380.67
178.85397,4.7058,7.7108,0.0,0.0,1.6216,5.5993,404.38,381.24,378.76,380.66
178.85529,4.7549,7.7081,0.0,0.0,1.6195,5.6521,404.37,381.13,378.77,380.64
178.85661,4.8012,7.7053,0.0,0.0,1.6188,5.6708,404.35,381.02,378.78,380.62
178.85793,4.7247,7.7143,0.0,0.0,1.6236,5.5941,404.33,380.91,378.79,380.61
178.85925,4.8516,7.7152,0.0,0.0,1.6185,5.7728,404.29,380.79,378.78,380.59
178.86057,4.8829,7.7131,0.0,0.0,1.6225,5.7746,404.24,380.67,378.77,380.57
178.86189,4.7615,7.7144,0.0,0.0,1.6224,5.6631,404.19,380.55,378.76,380.55
178.86321,4.8821,7.7169,0.0,0.0,1.6179,5.807,404.14,380.43,378.75,380.53
178.86453,4.938,7.7124,0.0,0.0,1.6249,5.8419,404.1,380.31,378.73,380.51
178.86585,4.7812,7.7148,0.0,0.0,1.6158,5.6839,404.05,380.19,378.72,380.49
178.86717,4.9203,7.7174,0.0,0.0,1.6226,5.8588,404.0,380.07,378.71,380.47
178.86849,4.8997,7.7095,0.0,0.0,1.6216,5.7707,403.96,379.94,378.7,380.46
178.86981,4.7309,7.7071,0.0,0.0,1.6191,5.6209,403.93,379.8,378.68,380.48
178.87113,4.9298,7.7146,0.0,0.0,1.6216,5.8792,403.91,379.65,378.66,380.5
178.87245,4.9428,7.7121,0.0,0.0,1.6213,5.8243,403.88,379.51,378.64,380.51
178.87377,4.7582,7.7123,0.0,0.0,1.6177,5.6546,403.85,379.37,378.62,380.53
178.87509,4.935,7.7157,0.0,0.0,1.6236,5.8771,403.82,379.22,378.6,380.54
178.87641,4.9097,7.7175,0.0,0.0,1.6207,5.8059,403.79,379.08,378.58,380.56
178.87773,4.7143,7.713,0.0,0.0,1.6199,5.5966,403.77,378.93,378.56,380.58
178.87905,4.9567,7.718,0.0,0.0,1.627,5.9063,403.76,378.78,378.55,380.6
178.88037,4.9058,7.7164,0.0,0.0,1.6182,5.8048,403.76,378.63,378.55,380.62
178.88169,4.7125,7.7121,0.0,0.0,1.6243,5.5851,403.75,378.48,378.54,380.65
178.88301,4.942,7.7103,0.0,0.0,1.6208,5.8747,403.75,378.33,378.54,380.67
178.88433,4.9257,7.7116,0.0,0.0,1.6192,5.8147,403.74,378.18,378.53,380.7
178.88565,4.7242,7.7116,0.0,0.0,1.6207,5.6054,403.74,378.03,378.53,380.72
178.88697,4.9443,7.7119,0.0,0.0,1.6212,5.892,403.74,377.87,378.53,380.74
178.88829,4.9307,7.7163,0.0,0.0,1.6169,5.8283,403.72,377.72,378.53,380.76
178.88961,4.7314,7.7169,0.0,0.0,1.6244,5.6222,403.66,377.58,378.54,380.75
178.89093,4.9527,7.7151,0.0,0.0,1.6187,5.8888,403.61,377.43,378.55,380.74
178.89225,4.9261,7.7137,0.0,0.0,1.6209,5.8191,403.55,377.28,378.56,380.73
178.89357,4.7325,7.716,0.0,0.0,1.623,5.6164,403.49,377.13,378.57,380.73
178.89489,4.9482,7.714,0.0,0.0,1.6186,5.8916,403.44,376.99,378.59,380.72
178.89621,4.911,7.7106,0.0,0.0,1.6247,5.7949,403.38,376.84,378.6,380.71
178.89753,4.7462,7.7121,0.0,0.0,1.6211,5.629,403.33,376.69,378.61,380.7
178.89885,4.9487,7.7101,0.0,0.0,1.6207,5.8919,403.28,376.57,378.62,380.69
178.90017,4.9215,7.707,0.0,0.0,1.6214,5.8257,403.24,376.46,378.63,380.69
178.90149,4.7319,7.712,0.0,0.0,1.618,5.6258,403.19,376.36,378.64,380.68
178.90281,4.9623,7.7186,0.0,0.0,1.6184,5.9032,403.15,376.25,378.64,380.67
178.90413,4.9252,7.7112,0.0,0.0,1.623,5.8186,403.11,376.14,378.65,380.66
178.90545,4.7463,7.7142,0.0,0.0,1.616,5.632,403.06,376.03,378.66,380.65
178.90677,4.9483,7.7177,0.0,0.0,1.6234,5.8963,403.02,375.92,378.67,380.65
178.90809,4.9211,7.7128,0.0,0.0,1.6203,5.8197,402.98,375.82,378.67,380.64
178.90941,4.7396,7.7134,0.0,0.0,1.6187,5.6311,402.95,375.73,378.67,380.65
178.91073,4.9566,7.7167,0.0,0.0,1.626,5.9036,402.92,375.64,378.67,380.66
178.91205,4.9426,7.709,0.0,0.0,1.621,5.8283,402.89,375.54,378.67,380.68
178.91337,4.7175,7.708,0.0,0.0,1.6248,5.6032,402.87,375.45,378.67,380.69
178.91469,4.9523,7.7113,0.0,0.0,1.6231,5.8958,402.84,375.36,378.67,380.7
178.91601,4.936,7.7154,0.0,0.0,1.6205,5.8424,402.81,375.27,378.67,380.71
178.91733,4.7361,7.7116,0.0,0.0,1.6191,5.6245,402.78,375.18,378.67,380.72
178.91865,4.9461,7.717,0.0,0.0,1.6234,5.8786,402.75,375.07,378.68,380.73
178.91997,4.9397,7.7161,0.0,0.0,1.6147,5.8298,402.73,374.96,378.69,380.73
178.92129,4.7375,7.7162,0.0,0.0,1.6251,5.6349,402.7,374.85,378.69,380.73
178.92261,4.942,7.7165,0.0,0.0,1.6199,5.8921,402.67,374.74,378.7,380.73
178.92393,4.9426,7.7184,0.0,0.0,1.6199,5.8262,402.64,374.63,378.71,380.73
178.92525,4.7469,7.7138,0.0,0.0,1.6255,5.6477,402.61,374.51,378.72,380.73
178.92657,4.9552,7.7116,0.0,0.0,1.6212,5.8985,402.59,374.4,378.73,380.73
178.92789,4.9331,7.7116,0.0,0.0,1.6223,5.8257,402.56,374.29,378.73,380.73
178.92921,4.77,7.7139,0.0,0.0,1.6242,5.6636,402.52,374.19,378.74,380.73
178.93053,4.9515,7.7157,0.0,0.0,1.6218,5.889,402.49,374.09,378.75,380.72
178.93185,4.9332,7.7147,0.0,0.0,1.6222,5.8397,402.45,373.99,378.76,380.72
178.93317,4.7539,7.7192,0.0,0.0,1.6234,5.6438,402.42,373.89,378.77,380.71
178.93449,4.9709,7.7168,0.0,0.0,1.6172,5.9056,402.38,373.79,378.77,380.71
178.93581,4.9418,7.7158,0.0,0.0,1.626,5.8408,402.34,373.69,378.78,380.71
178.93713,4.7537,7.7179,0.0,0.0,1.6154,5.6278,402.31,373.59,378.79,380.7
178.93845,4.976,7.7183,0.0,0.0,1.6233,5.9208,402.27,373.49,378.79,380.7
178.93977,4.9482,7.7131,0.0,0.0,1.6223,5.8459,402.21,373.39,378.79,380.7
178.94109,4.7723,7.7133,0.0,0.0,1.6201,5.6568,402.16,373.29,378.79,380.7
178.94241,4.9647,7.7147,0.0,0.0,1.6251,5.9187,402.11,373.19,378.78,380.7
178.94373,4.9618,7.7112,0.0,0.0,1.6241,5.8567,402.06,373.09,378.78,380.7
178.94505,4.7711,7.7149,0.0,0.0,1.6201,5.6562,402.01,372.99,378.77,380.7
178.94637,4.9927,7.7208,0.0,0.0,1.6257,5.9543,401.96,372.89,378.77,380.7
178.94769,4.9779,7.7189,0.0,0.0,1.6226,5.8849,401.9,372.79,378.77,380.7
178.94901,4.7845,7.7161,0.0,0.0,1.6196,5.6793,401.86,372.67,378.75,380.71
178.95033,4.9815,7.7207,0.0,0.0,1.6272,5.9391,401.82,372.55,378.74,380.72
178.95165,4.9755,7.7175,0.0,0.0,1.6182,5.8793,401.78,372.43,378.72,380.73
178.95297,4.802,7.7159,0.0,0.0,1.6245,5.6959,401.74,372.3,378.7,380.75
178.95429,4.9917,7.7188,0.0,0.0,1.6218,5.9376,401.7,372.18,378.69,380.76
178.95561,4.9805,7.7142,0.0,0.0,1.6203,5.8856,401.66,372.06,378.67,380.77
178.95693,4.7809,7.7101,0.0,0.0,1.6228,5.6819,401.62,371.93,378.66,380.78
178.95825,4.9925,7.715,0.0,0.0,1.6228,5.9528,401.58,371.81,378.64,380.79
178.95957,4.9791,7.719,0.0,0.0,1.6196,5.8853,401.53,371.68,378.64,380.81
178.96089,4.7938,7.7171,0.0,0.0,1.6258,5.6868,401.48,371.55,378.63,380.83
178.96221,4.9936,7.7182,0.0,0.0,1.6216,5.9432,401.43,371.42,378.63,380.84
178.96353,4.9791,7.7189,0.0,0.0,1.6216,5.8796,401.38,371.3,378.63,380.86
178.96485,4.7952,7.7198,0.0,0.0,1.6264,5.6886,401.32,371.17,378.62,380.87
178.96617,5.0151,7.7183,0.0,0.0,1.6191,5.9705,401.27,371.04,378.62,380.89
178.96749,4.9918,7.7188,0.0,0.0,1.6265,5.9057,401.22,370.91,378.61,380.91
178.96881,4.7911,7.7186,0.0,0.0,1.6228,5.6945,401.17,370.79,378.62,380.91
178.97013,5.0108,7.7114,0.0,0.0,1.6222,5.9799,401.12,370.68,378.63,380.9
178.97145,4.9958,7.7134,0.0,0.0,1.6231,5.8991,401.07,370.56,378.63,380.9
178.97277,4.8083,7.7156,0.0,0.0,1.6206,5.707,401.01,370.45,378.64,380.9
178.97409,5.003,7.7171,0.0,0.0,1.6202,5.9574,400.96,370.33,378.65,380.89
178.97541,4.982,7.7168,0.0,0.0,1.6255,5.8956,400.91,370.22,378.66,380.89
178.97673,4.8026,7.7192,0.0,0.0,1.6183,5.6996,400.86,370.1,378.67,380.88
178.97805,5.0104,7.7208,0.0,0.0,1.6261,5.9701,400.81,369.99,378.67,380.88
178.97937,4.9912,7.715,0.0,0.0,1.6227,5.9059,400.76,369.88,378.67,380.88
178.98069,4.7726,7.7209,0.0,0.0,1.6203,5.6685,400.72,369.78,378.67,380.88
178.98201,5.003,7.7199,0.0,0.0,1.628,5.96,400.68,369.67,378.67,380.88
178.98333,4.9871,7.7153,0.0,0.0,1.6221,5.8908,400.63,369.57,378.67,380.88
178.98465,4.8177,7.7127,0.0,0.0,1.6239,5.7192,400.59,369.47,378.67,380.88
178.98597,4.9986,7.7174,0.0,0.0,1.6244,5.9471,400.55,369.36,378.67,380.88
178.98729,4.991,7.7128,0.0,0.0,1.6209,5.903,400.5,369.26,378.67,380.88
178.98861,4.8103,7.7139,0.0,0.0,1.6206,5.7103,400.45,369.16,378.68,380.89
178.98993,5.0151,7.7215,0.0,0.0,1.624,5.9791,400.39,369.06,378.68,380.89
178.99125,4.9979,7.7192,0.0,0.0,1.6163,5.9068,400.33,368.97,378.68,380.9
178.99257,4.8006,7.7167,0.0,0.0,1.6255,5.697,400.27,368.87,378.69,380.91
178.99389,5.0072,7.7219,0.0,0.0,1.6213,5.9748,400.21,368.78,378.69,380.92
178.99521,4.9968,7.7195,0.0,0.0,1.6218,5.9041,400.15,368.68,378.7,380.92
178.99653,4.825,7.7157,0.0,0.0,1.627,5.713,400.09,368.59,378.7,380.93
178.99785,5.0115,7.7179,0.0,0.0,1.6225,5.9594,400.03,368.49,378.7,380.94
178.99917,4.9934,7.7141,0.0,0.0,1.6242,5.8974,399.98,368.4,378.7,380.94
179.00049,4.8108,7.7139,0.0,0.0,1.626,5.7131,399.93,368.31,378.7,380.94
179.00181,5.0258,7.715,0.0,0.0,1.6227,5.9981,399.88,368.23,378.69,380.94
179.00313,4.9971,7.7212,0.0,0.0,1.6229,5.9131,399.83,368.14,378.69,380.94
179.00445,4.8029,7.7186,0.0,0.0,1.6238,5.7106,399.77,368.05,378.68,380.94
179.00577,5.0312,7.7197,0.0,0.0,1.6196,6.0008,399.72,367.96,378.68,380.94
179.00709,5.0157,7.7185,0.0,0.0,1.6253,5.9309,399.67,367.87,378.68,380.94
179.00841,4.832,7.7216,0.0,0.0,1.6188,5.7337,399.63,367.79,378.68,380.94
179.00973,5.0285,7.7186,0.0,0.0,1.6237,5.9843,399.6,367.71,378.68,380.94
179.01105,5.0267,7.7201,0.0,0.0,1.6248,5.9533,399.56,367.63,378.68,380.94
179.01237,4.8226,7.719,0.0,0.0,1.6216,5.7219,399.53,367.55,378.69,380.94
179.01369,5.0528,7.713,0.0,0.0,1.628,6.0096,399.5,367.47,378.69,380.94
179.01501,5.0232,7.7126,0.0,0.0,1.6256,5.948,399.47,367.39,378.7,380.94
179.01633,4.8247,7.717,0.0,0.0,1.622,5.7263,399.44,367.31,378.7,380.94
179.01765,5.0114,7.7202,0.0,0.0,1.6261,5.9801,399.4,367.23,378.7,380.94
179.01897,5.0152,7.7181,0.0,0.0,1.623,5.9285,399.37,367.14,378.71,380.95
179.02029,4.841,7.7198,0.0,0.0,1.6198,5.736,399.34,367.06,378.71,380.96
179.02161,5.0315,7.7224,0.0,0.0,1.6274,5.9891,399.31,366.97,378.72,380.96
179.02293,5.0325,7.7187,0.0,0.0,1.6177,5.9354,399.28,366.88,378.72,380.97
179.02425,4.8264,7.7195,0.0,0.0,1.6245,5.7299,399.25,366.79,378.72,380.98
179.02557,5.0692,7.7236,0.0,0.0,1.6228,6.0157,399.21,366.71,378.73,380.99
179.02689,5.0328,7.7163,0.0,0.0,1.6215,5.9422,399.18,366.62,378.73,381.0
179.02821,4.8381,7.7127,0.0,0.0,1.6239,5.7614,399.15,366.53,378.74,381.01
179.02953,5.046,7.7182,0.0,0.0,1.6248,6.0131,399.12,366.45,378.74,381.02
179.03085,5.0295,7.716,0.0,0.0,1.6227,5.9336,399.09,366.37,378.74,381.04
179.03217,4.8522,7.7165,0.0,0.0,1.6263,5.7551,399.05,366.29,378.75,381.05
179.03349,5.0503,7.7222,0.0,0.0,1.623,6.0084,399.02,366.21,378.75,381.07
179.03481,5.0535,7.722,0.0,0.0,1.6223,5.9653,398.99,366.13,378.76,381.09
179.03613,4.8269,7.7174,0.0,0.0,1.627,5.7343,398.96,366.05,378.76,381.1
179.03745,5.0598,7.7226,0.0,0.0,1.6179,6.0402,398.93,365.97,378.76,381.12
179.03877,5.0441,7.7214,0.0,0.0,1.6268,5.9665,398.88,365.88,378.77,381.12
179.04009,4.8571,7.7182,0.0,0.0,1.6217,5.7677,398.82,365.79,378.78,381.11
179.04141,5.0542,7.7172,0.0,0.0,1.6229,6.0223,398.77,365.7,378.79,381.1
179.04273,5.0509,7.7174,0.0,0.0,1.6243,5.9613,398.71,365.61,378.79,381.09
179.04405,4.8535,7.7159,0.0,0.0,1.6223,5.7642,398.66,365.52,378.8,381.09
179.04537,5.0564,7.7153,0.0,0.0,1.6219,6.0167,398.6,365.42,378.81,381.08
179.04669,5.0548,7.7204,0.0,0.0,1.6264,5.9752,398.55,365.33,378.82,381.07
179.04801,4.8567,7.7231,0.0,0.0,1.6207,5.7661,398.49,365.24,378.83,381.06
179.04933,5.0583,7.7203,0.0,0.0,1.6258,6.0448,398.43,365.13,378.83,381.07
179.05065,5.0578,7.7193,0.0,0.0,1.6252,5.9864,398.36,365.02,378.83,381.08
179.05197,4.8694,7.7234,0.0,0.0,1.6211,5.7748,398.3,364.9,378.83,381.09
179.05329,5.0499,7.7201,0.0,0.0,1.6282,6.0097,398.24,364.79,378.83,381.09
179.05461,5.0576,7.7202,0.0,0.0,1.6203,5.9696,398.17,364.68,378.83,381.1
179.05593,4.8657,7.7188,0.0,0.0,1.6246,5.7744,398.11,364.57,378.83,381.11
179.05725,5.0529,7.7173,0.0,0.0,1.6252,6.0176,398.05,364.46,378.83,381.12
179.05857,5.0493,7.7109,0.0,0.0,1.6213,5.9665,397.99,364.35,378.82,381.13
179.05989,4.8636,7.7178,0.0,0.0,1.622,5.7708,397.94,364.26,378.82,381.16
179.06121,5.0591,7.7215,0.0,0.0,1.6253,6.0419,397.89,364.16,378.82,381.18
179.06253,5.0546,7.719,0.0,0.0,1.6196,5.9729,397.85,364.06,378.81,381.21
179.06385,4.8687,7.7197,0.0,0.0,1.6259,5.7831,397.8,363.97,378.81,381.23
179.06517,5.0653,7.7244,0.0,0.0,1.6241,6.0386,397.75,363.87,378.8,381.25
179.06649,5.0596,7.718,0.0,0.0,1.6214,5.9832,397.7,363.78,378.8,381.28
179.06781,4.8645,7.7212,0.0,0.0,1.6284,5.7675,397.66,363.68,378.8,381.3
179.06913,5.0802,7.7235,0.0,0.0,1.6223,6.0461,397.61,363.61,378.78,381.3
179.07045,5.0679,7.7175,0.0,0.0,1.6269,5.9766,397.56,363.53,378.76,381.29
179.07177,4.8669,7.7131,0.0,0.0,1.6246,5.7781,397.51,363.46,378.74,381.28
179.07309,5.0593,7.7184,0.0,0.0,1.623,6.0411,397.47,363.39,378.72,381.27
179.07441,5.0671,7.7202,0.0,0.0,1.6235,5.9897,397.42,363.32,378.7,381.26
179.07573,4.8689,7.7164,0.0,0.0,1.6237,5.7852,397.37,363.25,378.68,381.26
179.07705,5.0744,7.7226,0.0,0.0,1.6201,6.041,397.32,363.17,378.66,381.25
179.07837,5.0744,7.722,0.0,0.0,1.6267,5.9979,397.28,363.11,378.65,381.24
179.07969,4.8757,7.72,0.0,0.0,1.6203,5.772,397.24,363.06,378.65,381.23
179.08101,5.0874,7.7217,0.0,0.0,1.6247,6.0486,397.2,363.0,378.65,381.22
179.08233,5.0839,7.7247,0.0,0.0,1.6268,6.0126,397.16,362.95,378.66,381.22
179.08365,4.8797,7.7203,0.0,0.0,1.6219,5.7982,397.12,362.9,378.66,381.21
179.08497,5.0709,7.7172,0.0,0.0,1.629,6.0412,397.08,362.85,378.67,381.2
179.08629,5.0901,7.7181,0.0,0.0,1.625,6.0262,397.04,362.8,378.67,381.19
179.08761,4.9088,7.7167,0.0,0.0,1.6231,5.827,397.0,362.74,378.67,381.18
179.08893,5.0913,7.7184,0.0,0.0,1.6262,6.0574,396.95,362.69,378.69,381.19
179.09025,5.078,7.7193,0.0,0.0,1.6226,5.9919,396.9,362.63,378.71,381.2
179.09157,4.9011,7.7248,0.0,0.0,1.6202,5.7988,396.86,362.58,378.73,381.21
179.09289,5.1076,7.7232,0.0,0.0,1.6291,6.084,396.81,362.52,378.75,381.21
179.09421,5.0804,7.7196,0.0,0.0,1.6188,6.0022,396.76,362.47,378.77,381.22
179.09553,4.9094,7.7238,0.0,0.0,1.6255,5.8272,396.71,362.41,378.79,381.23
179.09685,5.0856,7.7217,0.0,0.0,1.6238,6.0814,396.67,362.35,378.81,381.24
179.09817,5.0835,7.7196,0.0,0.0,1.6226,6.0074,396.62,362.3,378.83,381.25
179.09949,4.9043,7.7193,0.0,0.0,1.6268,5.8307,396.57,362.24,378.83,381.26
179.10081,5.1033,7.7194,0.0,0.0,1.6257,6.0716,396.52,362.18,378.83,381.28
179.10213,5.0836,7.7137,0.0,0.0,1.6254,5.9953,396.47,362.12,378.84,381.29
179.10345,4.8891,7.7167,0.0,0.0,1.6265,5.7948,396.43,362.06,378.84,381.31
179.10477,5.0997,7.7235,0.0,0.0,1.6236,6.0788,396.38,362.0,378.85,381.33
179.10609,5.1026,7.7216,0.0,0.0,1.6224,6.0394,396.33,361.94,378.85,381.34
179.10741,4.9153,7.7202,0.0,0.0,1.6263,5.8305,396.28,361.88,378.85,381.36
179.10873,5.0925,7.7243,0.0,0.0,1.6185,6.0899,396.24,361.82,378.86,381.36
179.11005,5.1056,7.72,0.0,0.0,1.626,6.0385,396.21,361.77,378.86,381.36
179.11137,4.8955,7.7219,0.0,0.0,1.6229,5.8085,396.17,361.72,378.86,381.36
179.11269,5.1069,7.7209,0.0,0.0,1.6225,6.0724,396.14,361.67,378.86,381.36
179.11401,5.1062,7.7191,0.0,0.0,1.6278,6.0172,396.1,361.61,378.86,381.36
179.11533,4.8935,7.7118,0.0,0.0,1.6227,5.7949,396.06,361.56,378.86,381.36
179.11665,5.1039,7.7184,0.0,0.0,1.6246,6.0843,396.03,361.51,378.86,381.36
179.11797,5.0932,7.7203,0.0,0.0,1.627,6.0171,395.99,361.46,378.86,381.36
179.11929,4.9167,7.7208,0.0,0.0,1.6233,5.8429,395.94,361.38,378.86,381.36
179.12061,5.0992,7.7219,0.0,0.0,1.6253,6.0874,395.88,361.3,378.87,381.36
179.12193,5.092,7.7242,0.0,0.0,1.6261,6.0314,395.82,361.22,378.88,381.36
179.12325,4.9094,7.7208,0.0,0.0,1.6197,5.8321,395.77,361.14,378.89,381.36
179.12457,5.1111,7.7213,0.0,0.0,1.629,6.0808,395.71,361.06,378.9,381.36
179.12589,5.1068,7.7257,0.0,0.0,1.619,6.0253,395.66,360.98,378.9,381.36
179.12721,4.91,7.7215,0.0,0.0,1.6238,5.8098,395.6,360.9,378.91,381.36
179.12853,5.1106,7.7184,0.0,0.0,1.6256,6.0888,395.55,360.81,378.91,381.37
179.12985,5.1203,7.7189,0.0,0.0,1.6232,6.0482,395.5,360.71,378.91,381.39
179.13117,4.9227,7.7181,0.0,0.0,1.6248,5.8407,395.45,360.61,378.91,381.4
179.13249,5.1114,7.7201,0.0,0.0,1.6279,6.0881,395.41,360.51,378.9,381.42
179.13381,5.1143,7.7189,0.0,0.0,1.6212,6.0485,395.36,360.41,378.9,381.44
179.13513,4.9091,7.7242,0.0,0.0,1.6276,5.8343,395.31,360.31,378.89,381.45
179.13645,5.1294,7.7246,0.0,0.0,1.6254,6.1024,395.26,360.21,378.89,381.47
179.13777,5.1129,7.7198,0.0,0.0,1.6214,6.0342,395.22,360.11,378.89,381.48
179.13909,4.9212,7.7252,0.0,0.0,1.6294,5.8269,395.17,360.02,378.88,381.49
179.14041,5.1133,7.7231,0.0,0.0,1.6215,6.0907,395.13,359.94,378.88,381.5
179.14173,5.1219,7.7206,0.0,0.0,1.6273,6.0561,395.09,359.85,378.87,381.51
179.14305,4.9175,7.7188,0.0,0.0,1.6236,5.8495,395.06,359.77,378.87,381.52
179.54353,4.9844,7.724,0.0,0.0,1.626,5.9145,380.97,347.67,378.86,377.02
180.34353,4.9417,7.73,0.0,0.0,1.6288,5.8641,308.39,322.34,367.33,311.11
181.14353,4.93,7.7364,0.0,0.0,1.6318,5.8524,284.84,294.62,355.94,291.57
181.94353,4.9122,7.743,0.0,0.0,1.6351,5.8315,267.55,263.48,337.48,266.28
182.74353,4.8723,7.75,0.0,0.0,1.6383,5.7827,239.52,229.2,314.41,246.91
183.5426,4.8682,7.7538,0.0,0.0,1.6402,5.7771,209.88,191.56,290.02,208.7
184.3426,4.8694,7.7559,0.0,0.0,1.6411,5.778,149.13,152.84,259.81,168.13
185.1426,4.8572,7.7584,0.0,0.0,1.6425,5.7641,117.7,116.66,204.31,79.435
185.9426,4.8343,7.7644,0.0,0.0,1.6453,5.7359,98.412,100.27,158.8,52.518
186.7426,4.8418,7.7699,0.0,0.0,1.6478,5.7461,86.559,88.326,110.94,41.171
187.5426,4.8407,7.7758,0.0,0.0,1.6507,5.7452,76.14,77.238,69.701,35.518
188.3426,4.8411,7.7836,0.0,0.0,1.6546,5.745,67.206,70.134,51.376,32.044
189.1426,4.8373,7.7903,0.0,0.0,1.6578,5.7406,59.83,63.054,42.788,30.202
189.9426,4.8396,7.7966,0.0,0.0,1.6608,5.7431,54.398,58.202,37.972,29.12
190.7426,4.8385,7.8035,0.0,0.0,1.6642,5.7422,49.076,52.929,35.099,27.895
191.5426,4.8443,7.8108,0.0,0.0,1.6679,5.7476,46.798,50.646,33.408,28.144
192.3426,4.8471,7.816,0.0,0.0,1.6704,5.7512,45.746,48.892,32.852,28.913
193.1426,4.8529,7.8215,0.0,0.0,1.6731,5.7594,45.064,47.693,32.917,29.585
193.9426,4.8528,7.8265,0.0,0.0,1.6755,5.7596,44.987,46.97,33.399,30.306
194.7426,4.7467,7.8331,0.0,0.0,1.6788,5.6333,47.899,48.036,34.336,32.601
195.5426,4.8767,7.8332,0.0,0.0,1.6789,5.7868,50.051,49.261,36.227,34.95
196.1426,4.7526,7.8388,0.0,0.0,1.6816,5.6412,51.411,49.974,37.933,36.705