File: examples/dan-msc-case-studies/CS4/data/01 raw data/hyde_test_014.csv
Time(sec),Force(kN),Jaw(mm),PowAngle(deg),PTemp,Strain,Stress(MPa),TC1(C),TC2(C),TC3(C),TC4(C)
0.0,1.8537,-10.295,0.0,0.0046717,-0.78905,2.2053,24.404,24.703,24.248,24.325
0.8,1.8244,0.0034653,0.0,2.2207,0.00040325,2.166,24.389,24.662,24.338,24.365
1.6,1.8043,0.003435,0.0,4.6207,0.00039233,2.1411,24.382,24.635,24.284,24.283
2.4,1.7768,0.0032558,0.0,7.0207,0.00034625,2.1094,24.428,24.635,24.277,24.347
3.139,1.7733,0.0031108,0.0,9.2533,0.00037607,2.1055,24.42,24.666,24.343,24.33
3.939,1.771,0.0032165,0.0,11.638,0.00037464,2.1029,24.418,24.658,24.319,24.365
4.739,1.7636,0.0032068,0.0,14.038,0.00036002,2.0937,24.45,24.654,24.287,24.315
5.539,1.7605,0.0032355,0.0,16.438,0.00037222,2.0896,24.428,24.643,24.283,24.335
6.339,1.7595,0.0032995,0.0,18.838,0.00035618,2.0885,24.443,24.672,24.29,24.336
7.139,1.7593,0.0032935,0.0,21.238,0.00036272,2.0886,24.4,24.685,24.305,24.366
7.939,1.7444,0.0030137,0.0,23.638,0.00033927,2.0702,24.408,24.645,24.312,24.336
8.739,1.7498,0.0033653,17.739,26.038,0.0004014,2.0775,24.406,24.704,24.332,24.326
9.539,1.7559,0.0034473,30.721,28.438,0.00039192,2.0836,25.383,25.604,24.368,24.391
10.339,1.7631,0.0029987,32.755,30.838,0.00034723,2.0922,28.223,27.764,24.491,24.823
11.0772,1.7759,0.0024288,32.849,33.052,0.0002953,2.1079,31.051,29.765,24.743,25.765
11.8772,1.7854,0.0022279,33.704,35.452,0.00026116,2.119,33.773,37.953,25.338,27.096
12.6772,1.7882,0.0015638,33.963,37.852,0.00019257,2.123,36.571,37.954,26.049,28.664
13.4772,1.7945,0.0011071,34.647,40.252,0.00010965,2.1302,39.204,37.954,26.963,30.487
14.2772,1.7879,0.0003727,34.646,42.652,3.1569e-05,2.1216,41.924,38.173,28.086,32.324
15.0772,1.7912,-0.00031508,34.66,45.052,-2.9561e-05,2.1269,44.459,40.305,29.355,34.279
15.8772,1.7984,-0.00090274,35.037,47.452,-9.0992e-05,2.1341,46.954,42.562,30.821,36.356
16.6772,1.7974,-0.0015768,35.476,49.852,-0.00016768,2.1325,49.421,44.697,32.367,38.436
17.4772,1.8029,-0.0023326,35.414,52.252,-0.00024441,2.1397,51.979,47.02,34.049,40.557
18.2772,1.802,-0.0031659,36.131,54.652,-0.00035876,2.1381,54.283,49.245,35.806,42.804
19.0772,1.8028,-0.0037252,35.765,57.052,-0.00043177,2.1396,56.811,51.862,37.621,44.991
19.8772,1.808,-0.0044678,36.571,59.452,-0.00050225,2.1468,59.077,54.111,39.525,47.202
20.6772,1.8086,-0.0054946,36.816,61.852,-0.00059452,2.1467,61.546,56.785,41.484,49.508
21.4772,1.8181,-0.0060634,36.844,64.252,-0.00065639,2.1573,64.025,59.193,43.484,51.819
22.2772,1.8209,-0.0068599,36.634,66.652,-0.00075265,2.16,66.515,61.61,45.569,54.21
23.0772,1.8239,-0.0078868,37.098,69.052,-0.00086565,2.1642,68.892,64.112,47.691,56.562
23.8772,1.8234,-0.008502,37.358,71.452,-0.00095496,2.1629,71.253,66.517,49.846,59.008
24.6772,1.8257,-0.0095703,37.401,73.852,-0.001073,2.1667,73.708,69.044,51.99,61.41
25.4772,1.8247,-0.010488,37.546,76.252,-0.0011589,2.1664,76.092,71.466,54.185,63.842
26.2772,1.8262,-0.011461,37.837,78.652,-0.0012496,2.1675,78.519,73.898,56.458,66.299
27.0772,1.8204,-0.012439,37.833,81.052,-0.00138,2.1609,80.891,76.357,58.738,68.792
27.8772,1.8229,-0.01364,37.91,83.452,-0.0014937,2.1636,83.304,78.662,61.016,71.2
28.6772,1.8216,-0.014685,38.504,85.852,-0.0016442,2.1621,85.644,81.141,63.494,73.673
29.4772,1.8266,-0.015795,38.439,88.252,-0.0017651,2.1681,88.063,83.588,65.9,76.147
30.2772,1.82,-0.017051,38.551,90.652,-0.001887,2.1607,90.519,85.933,68.271,78.633
31.0772,1.8268,-0.018302,39.046,93.052,-0.0020068,2.1691,92.851,88.394,70.633,81.101
31.8772,1.8156,-0.019529,38.551,95.452,-0.0021549,2.156,95.379,90.744,73.018,83.606
32.6772,1.8169,-0.020833,39.236,97.852,-0.0023021,2.1565,97.644,93.184,75.455,86.071
33.4772,1.8202,-0.021846,39.123,100.25,-0.0024272,2.1609,100.16,95.656,77.922,88.533
34.2772,1.8179,-0.023204,39.554,102.65,-0.0025924,2.1571,102.46,98.011,80.354,90.993
35.0772,1.8198,-0.024416,39.621,105.05,-0.0027218,2.1596,104.9,100.46,82.754,93.506
35.7651,1.8179,-0.025483,39.484,107.13,-0.002851,2.1573,107.01,102.5,84.869,95.639
36.5651,1.8194,-0.026939,39.778,109.52,-0.0029775,2.159,109.42,104.91,87.302,98.116
37.3651,1.8184,-0.0282,39.814,111.92,-0.0031125,2.1583,111.8,107.29,89.795,100.57
38.1651,1.8258,-0.029117,39.479,114.32,-0.0032189,2.1667,114.31,109.73,92.219,103.14
38.9651,1.8287,-0.031683,39.444,116.72,-0.0034929,2.1714,116.74,112.18,94.65,105.61
39.7651,1.8251,-0.032814,39.497,119.12,-0.0036594,2.1662,119.09,114.51,97.106,108.11
40.5651,1.8209,-0.033175,39.742,121.52,-0.0037049,2.1623,121.53,116.95,99.548,110.63
41.3651,1.8237,-0.033804,39.676,123.92,-0.0037509,2.1652,123.87,119.37,101.96,113.12
42.1651,1.8199,-0.035288,39.7,126.32,-0.0038881,2.1609,126.31,121.77,104.36,115.66
42.9651,1.8237,-0.036799,40.253,128.72,-0.0040708,2.1639,128.56,124.16,106.82,118.06
43.7143,1.8188,-0.038284,40.032,130.96,-0.0042314,2.1581,130.89,126.54,109.08,120.46
44.5143,1.8247,-0.039702,40.537,133.36,-0.0043721,2.1675,133.2,128.94,111.49,122.91
45.3143,1.8195,-0.041278,40.431,135.76,-0.0045651,2.1598,135.69,131.61,113.94,125.4
46.1143,1.8213,-0.042678,40.444,138.16,-0.0047218,2.163,138.12,134.03,116.35,127.96
46.9143,1.8233,-0.044062,40.623,140.56,-0.0049008,2.1643,140.42,136.45,118.83,130.43
47.7143,1.8193,-0.045611,40.692,142.96,-0.0050649,2.1596,142.89,139.06,121.26,132.97
48.5143,1.8226,-0.047198,40.629,145.36,-0.0052284,2.1636,145.27,141.5,123.74,135.48
49.3143,1.8243,-0.048572,40.927,147.76,-0.0053609,2.1665,147.66,144.08,126.16,137.96
50.1143,1.8183,-0.04996,40.89,150.16,-0.0055389,2.1574,150.09,146.57,128.63,140.49
50.9143,1.8254,-0.05134,40.577,152.56,-0.0056822,2.1659,152.6,149.16,131.09,142.97
51.7143,1.8215,-0.053139,40.743,154.96,-0.0058879,2.1611,154.97,151.53,133.56,145.49
52.5143,1.8256,-0.054209,40.659,157.36,-0.0060338,2.1661,157.41,154.13,136.01,147.89
53.3143,1.8288,-0.055075,41.169,159.76,-0.0061119,2.1695,159.68,156.64,138.51,150.35
54.1143,1.8243,-0.056744,41.077,162.16,-0.0062548,2.1638,162.16,159.33,140.96,152.87
54.9143,1.8287,-0.058907,41.214,164.56,-0.0064963,2.1694,164.45,161.83,143.45,155.42
55.7143,1.8338,-0.0613,41.065,166.96,-0.0067667,2.1762,166.96,164.41,145.97,157.85
56.5143,1.8327,-0.063306,41.199,169.36,-0.0070067,2.1742,169.38,167.04,148.35,160.34
57.3143,1.8318,-0.064845,41.198,171.76,-0.0071997,2.1731,171.8,169.5,150.93,162.82
58.1143,1.8304,-0.066397,41.243,174.16,-0.0073709,2.1732,174.13,171.9,153.39,165.26
58.9143,1.8253,-0.06784,41.232,176.56,-0.0075236,2.1671,176.5,174.21,155.81,167.72
59.7143,1.8352,-0.069252,41.404,178.96,-0.0076554,2.1784,178.89,176.74,158.26,170.15
60.5143,1.831,-0.070462,41.568,181.36,-0.0078057,2.1735,181.29,179.24,160.81,172.62
61.3143,1.8339,-0.071717,41.79,183.76,-0.007942,2.1771,183.74,181.71,163.22,174.95
62.1143,1.8319,-0.073059,41.692,186.16,-0.0081161,2.1744,186.12,184.12,165.69,177.41
62.9143,1.8256,-0.074187,41.588,188.56,-0.0082515,2.168,188.58,186.51,168.06,179.78
63.7143,1.8301,-0.075975,41.78,190.96,-0.0084298,2.1729,190.94,188.89,170.45,182.18
64.5143,1.8288,-0.077355,41.664,193.36,-0.0085513,2.1704,193.31,191.12,172.85,184.59
65.3143,1.8185,-0.079155,41.883,195.76,-0.0087547,2.1582,195.67,193.44,175.21,186.86
66.1143,1.8244,-0.080699,41.819,198.16,-0.0089143,2.166,198.14,195.76,177.58,189.19
66.9143,1.8257,-0.082547,41.805,200.56,-0.0091301,2.1669,200.6,198.08,179.96,191.57
67.7143,1.8251,-0.084169,42.034,202.96,-0.009316,2.1671,202.87,200.32,182.23,193.87
68.3976,1.8299,-0.085849,42.37,205.02,-0.0094967,2.1726,204.86,202.49,184.32,195.85
69.1976,1.8301,-0.087955,42.396,207.41,-0.0097368,2.1723,207.27,205.0,186.69,198.2
69.9976,1.8291,-0.089833,42.371,209.81,-0.0099303,2.1708,209.75,207.53,189.03,200.56
70.7976,1.8252,-0.091784,42.384,212.21,-0.010135,2.1666,212.16,209.81,191.44,203.04
71.5976,1.8262,-0.093883,42.337,214.61,-0.010373,2.1684,214.59,212.38,193.82,205.37
72.3976,1.8245,-0.095542,42.292,217.01,-0.010554,2.1649,217.04,214.84,196.25,207.86
73.1976,1.8195,-0.097404,42.389,219.41,-0.010768,2.1617,219.41,217.28,198.66,210.3
73.9976,1.8257,-0.099067,42.705,221.81,-0.010967,2.1677,221.68,219.72,201.07,212.7
74.7976,1.8229,-0.10109,42.805,224.21,-0.011193,2.1637,224.13,222.25,203.5,215.13
75.5976,1.8229,-0.10274,42.401,226.61,-0.011345,2.1637,226.62,224.54,205.94,217.61
76.3976,1.8217,-0.10461,42.972,229.01,-0.011552,2.1626,228.89,227.02,208.43,220.01
77.1976,1.8244,-0.10649,42.931,231.41,-0.011762,2.1658,231.32,229.55,210.81,222.51
77.9976,1.8225,-0.10834,42.925,233.81,-0.011958,2.1631,233.77,232.02,213.27,225.01
78.7976,1.8239,-0.10979,42.729,236.21,-0.01216,2.1641,236.24,234.49,215.72,227.45
79.5976,1.8261,-0.1109,42.978,238.61,-0.012272,2.1663,238.59,236.85,218.18,229.9
80.3976,1.828,-0.11424,42.887,241.01,-0.012608,2.1688,240.97,239.2,220.58,232.39
81.1976,1.8322,-0.11639,42.969,243.41,-0.012859,2.174,243.33,241.64,223.09,234.75
81.9976,1.8325,-0.11627,42.979,245.81,-0.012845,2.1744,245.77,244.14,225.54,237.22
82.7976,1.8315,-0.11706,43.292,248.21,-0.012928,2.1739,248.1,246.45,228.04,239.66
83.5976,1.8349,-0.11929,43.147,250.61,-0.013155,2.1784,250.53,249.0,230.5,242.13
84.3976,1.8341,-0.12182,43.364,253.01,-0.013465,2.1763,252.94,251.5,232.97,244.64
85.1976,1.8311,-0.12406,43.407,255.41,-0.013718,2.174,255.37,253.85,235.42,247.11
85.9976,1.8312,-0.12612,43.526,257.81,-0.013929,2.1731,257.74,256.24,237.94,249.57
86.7976,1.8274,-0.12819,43.677,260.21,-0.014139,2.1686,260.08,258.74,240.36,252.04
87.5976,1.8289,-0.13021,43.748,262.61,-0.014362,2.1712,262.51,261.18,242.88,254.53
88.3976,1.8287,-0.13077,43.687,265.01,-0.014422,2.1707,264.97,263.72,245.28,256.95
89.1976,1.8338,-0.1354,43.511,267.41,-0.014957,2.1778,267.47,266.05,247.79,259.57
89.9976,1.8336,-0.13439,43.816,269.81,-0.014855,2.1776,269.77,268.55,250.27,262.06
90.7976,1.8242,-0.13696,43.735,272.21,-0.01512,2.1653,272.17,271.06,252.79,264.49
91.5976,1.8297,-0.13976,43.549,274.61,-0.015413,2.172,274.7,273.55,255.34,266.96
92.3976,1.828,-0.14199,43.312,277.01,-0.015643,2.1712,277.12,276.04,257.83,269.54
93.1976,1.8261,-0.14406,43.528,279.41,-0.015897,2.1674,279.44,278.49,260.36,272.07
93.9976,1.8257,-0.14649,43.528,281.81,-0.016148,2.1659,281.85,280.96,262.85,274.59
94.7976,1.8293,-0.14712,43.475,284.21,-0.016225,2.1711,284.25,283.58,265.39,277.12
95.5976,1.8302,-0.15199,43.195,286.61,-0.016771,2.1718,286.75,286.06,267.96,279.66
96.3976,1.83,-0.15126,43.31,289.01,-0.016711,2.1718,289.11,288.38,270.64,282.26
97.1976,1.8326,-0.15273,43.528,291.41,-0.016834,2.1749,291.43,290.8,273.26,284.73
97.9976,1.8306,-0.1555,43.572,293.81,-0.017123,2.1718,293.82,293.25,275.75,287.23
98.7976,1.8316,-0.15809,43.575,296.21,-0.017434,2.1732,296.17,295.69,278.31,289.71
99.5976,1.8321,-0.16035,43.735,298.61,-0.017665,2.1732,298.55,298.1,280.8,292.06
100.3976,1.8333,-0.16262,43.795,301.01,-0.017929,2.1754,300.97,300.5,283.33,294.57
101.1281,1.8266,-0.16461,44.036,303.21,-0.018165,2.1679,303.12,302.7,285.64,296.76
101.9281,1.8315,-0.16695,43.86,305.6,-0.018373,2.1721,305.56,305.02,288.11,299.36
102.7281,1.8327,-0.16755,43.785,308.0,-0.018457,2.1749,307.99,307.4,290.61,301.85
103.5281,1.8318,-0.17237,43.691,310.4,-0.018969,2.1731,310.44,309.76,293.06,304.35
104.3281,1.8345,-0.17391,43.529,312.8,-0.019188,2.1772,312.89,312.15,295.67,306.75
105.1281,1.8378,-0.17329,43.528,315.2,-0.019116,2.1798,315.3,314.51,298.21,309.19
105.9281,1.8387,-0.17541,43.68,317.6,-0.019323,2.1817,317.64,316.77,300.64,311.5
106.7281,1.8368,-0.17817,43.588,320.0,-0.01962,2.1796,320.03,318.89,303.28,313.91
107.5281,1.8389,-0.18088,44.018,322.4,-0.019891,2.1837,322.31,321.33,306.0,316.32
108.3281,1.8395,-0.18343,43.693,324.8,-0.020186,2.1833,324.82,323.88,308.49,318.71
109.0899,1.8347,-0.18588,43.798,327.09,-0.020439,2.1771,327.1,326.06,310.93,320.98
109.8899,1.8333,-0.18798,43.382,329.49,-0.020688,2.1753,329.7,328.36,314.19,323.46
110.6899,1.8328,-0.19022,43.901,331.89,-0.020938,2.176,331.84,330.52,318.1,325.74
111.4899,1.8318,-0.19251,44.711,334.29,-0.021202,2.1744,333.91,333.05,321.16,328.04
112.2899,1.8355,-0.19496,44.587,336.69,-0.021476,2.1783,336.53,335.93,324.2,330.55
113.0899,1.8334,-0.19695,43.504,339.09,-0.021683,2.1772,339.35,338.21,327.35,333.19
113.8899,1.8364,-0.19841,45.267,341.49,-0.021847,2.1794,341.03,340.64,330.24,335.64
114.6899,1.8333,-0.20027,45.077,343.89,-0.022013,2.1767,343.56,343.7,333.12,338.28
115.4899,1.8399,-0.20419,44.564,346.29,-0.022416,2.1841,346.24,346.61,336.16,341.12
116.2899,1.8339,-0.20772,43.293,348.69,-0.022838,2.1771,349.14,348.79,339.02,343.89
117.0899,1.8359,-0.20911,40.701,350.0,-0.023026,2.1798,351.43,350.69,341.83,346.35
117.8899,1.8313,-0.20911,41.309,350.0,-0.023035,2.1752,350.62,350.63,344.07,348.06
118.6899,1.8511,-0.2148,55.233,350.0,-0.023646,2.1966,344.24,357.99,346.37,350.01
119.4899,1.8319,-0.21758,45.442,350.0,-0.023914,2.1744,351.11,365.81,351.6,356.43
120.2899,1.8212,-0.2179,39.791,350.0,-0.023949,2.1621,352.82,366.56,356.59,362.15
121.0899,1.8201,-0.21819,37.903,350.0,-0.023976,2.1608,352.61,365.33,359.75,364.7
121.8899,1.8235,-0.21876,37.105,350.0,-0.024057,2.1639,352.2,364.1,361.55,365.38
122.6899,1.8274,-0.21991,37.064,350.0,-0.024192,2.1693,351.62,363.05,362.56,365.2
123.4899,1.8287,-0.2208,37.18,350.0,-0.024279,2.1701,351.09,362.14,362.98,364.63
124.2899,1.8381,-0.22203,37.568,350.0,-0.024385,2.1815,350.75,361.61,363.24,363.99
125.0899,1.8375,-0.22332,37.358,350.0,-0.02452,2.1803,350.55,361.19,363.31,363.49
125.8899,1.8363,-0.22444,37.687,350.0,-0.024654,2.1787,350.39,360.88,363.26,362.94
126.6899,1.8419,-0.22571,37.534,350.0,-0.024796,2.1869,350.31,360.67,363.15,362.59
127.4899,1.8358,-0.22697,37.612,350.0,-0.024961,2.178,350.19,360.45,362.98,362.22
128.2899,1.8421,-0.22802,37.833,350.0,-0.025065,2.1859,350.14,360.26,362.88,361.86
129.0899,1.8396,-0.22951,37.613,350.0,-0.025209,2.1828,350.08,360.13,362.59,361.55
129.8899,1.8429,-0.23055,37.335,350.0,-0.025312,2.1877,350.13,359.98,362.37,361.25
130.6899,1.836,-0.23168,37.457,350.0,-0.025444,2.1784,350.12,359.78,362.1,361.02
131.4899,1.8325,-0.23277,37.365,350.0,-0.025559,2.1759,350.05,359.71,361.92,360.73
132.2899,1.8319,-0.23393,37.106,350.0,-0.025696,2.1757,350.13,359.65,361.67,360.52
133.0899,1.8365,-0.23482,37.111,350.0,-0.025811,2.1815,350.09,359.59,361.43,360.26
133.7649,1.8349,-0.236,36.939,350.0,-0.025914,2.1766,350.1,359.46,361.29,360.08
134.5649,1.8365,-0.23669,37.24,350.0,-0.026008,2.1787,350.04,359.32,361.09,359.84
135.3649,1.8423,-0.23767,37.072,350.0,-0.02611,2.1858,350.07,359.33,360.81,359.59
136.1649,1.8393,-0.2388,37.018,350.0,-0.026213,2.1819,350.08,359.24,360.55,359.36
136.9649,1.841,-0.23985,37.086,350.0,-0.026314,2.1848,350.07,359.29,360.36,359.11
137.7649,1.8414,-0.24093,36.699,350.0,-0.026452,2.1841,350.12,359.21,360.11,358.92
138.5649,1.8474,-0.24184,36.778,350.0,-0.02655,2.1923,350.08,359.14,359.91,358.73
139.3649,1.8478,-0.24266,36.387,350.0,-0.02665,2.1922,350.1,359.1,359.71,358.56
140.1649,1.8443,-0.24382,36.728,350.0,-0.026783,2.1897,350.05,359.02,359.51,358.34
140.9649,1.8447,-0.2448,36.47,350.0,-0.026885,2.1908,350.05,359.12,359.3,358.21
141.6369,1.8418,-0.24584,36.614,350.0,-0.026983,2.1866,350.05,358.97,359.15,358.04
142.4369,1.8349,-0.24675,36.312,350.0,-0.027077,2.1781,350.05,358.95,359.03,357.93
143.2369,1.8344,-0.24771,36.374,350.0,-0.027192,2.1765,350.07,358.96,358.79,357.68
144.0369,1.8367,-0.24855,36.313,350.0,-0.02727,2.1787,350.05,358.94,358.65,357.55
144.8369,1.842,-0.24935,36.406,350.0,-0.027377,2.1859,350.01,358.98,358.45,357.38
145.6369,1.7609,-0.25085,36.257,350.0,-0.027558,2.0893,350.06,358.98,358.36,357.3
146.4369,1.4767,-0.25459,36.303,350.0,-0.027954,1.7523,350.05,359.01,358.17,357.17
147.2369,1.2682,-0.25767,36.243,350.0,-0.028263,1.5053,350.06,359.04,358.05,357.11
148.0369,1.1617,-0.25977,36.11,350.0,-0.028485,1.3783,350.06,359.25,357.96,357.0
148.8369,1.1001,-0.26153,35.951,350.0,-0.028683,1.3054,350.09,359.3,357.89,356.99
149.6369,1.1112,-0.26244,35.967,350.0,-0.028784,1.3188,350.01,359.23,357.88,357.04
150.4369,1.1214,-0.2634,35.597,350.0,-0.028906,1.3316,350.07,359.33,357.72,356.9
151.2369,1.1276,-0.26437,35.586,350.0,-0.029028,1.339,350.07,359.45,357.64,356.88
152.0369,1.136,-0.26468,35.512,350.0,-0.029056,1.3491,350.04,359.46,357.69,356.83
152.8369,1.1383,-0.26531,35.821,350.0,-0.029104,1.3522,350.0,359.54,357.57,356.79
153.6369,1.137,-0.26572,35.652,350.0,-0.029126,1.3502,350.02,359.73,357.53,356.72
154.4369,1.1357,-0.2671,35.568,350.0,-0.029276,1.3486,350.02,359.83,357.48,356.76
155.2369,1.1414,-0.2688,35.339,350.0,-0.029447,1.3555,350.07,359.8,357.48,356.75
156.0369,1.146,-0.26995,35.139,350.0,-0.029594,1.3598,350.1,359.87,357.44,356.72
156.8369,1.1413,-0.27134,35.301,350.0,-0.029761,1.3555,350.07,359.81,357.4,356.68
157.6369,1.1453,-0.27244,35.263,350.0,-0.029871,1.3599,350.1,359.89,357.32,356.65
158.4369,1.1453,-0.27316,35.042,350.0,-0.029936,1.3602,350.08,359.89,357.27,356.6
159.2369,1.1455,-0.27337,35.264,350.0,-0.029974,1.3595,350.01,359.87,357.22,356.52
160.0369,1.1465,-0.27373,35.381,350.0,-0.030011,1.3615,349.98,359.86,357.16,356.4
160.8369,1.1399,-0.2741,36.471,350.0,-0.030057,1.3534,349.79,360.57,357.13,356.43
161.6369,1.141,-0.27442,35.315,350.0,-0.030112,1.3531,350.13,360.74,357.3,356.67
161.94746,1.1573,0.0012684,13.63,2.5963,0.0013225,1.3663,350.12,360.57,357.35,356.76
161.94878,1.1636,0.00085531,8.9447,8.0881e-06,0.00038274,1.3915,350.12,360.57,357.35,356.75
161.9501,1.1306,0.001258,4.2592,2.3863e-11,0.0006286,1.3432,350.12,360.56,357.34,356.74
161.95142,1.1595,-0.00060159,0.0,6.7944e-17,0.00033221,1.3798,350.13,360.55,357.34,356.73
161.95274,1.1679,0.0015069,0.0,1.8865e-22,0.0002517,1.3733,350.14,360.55,357.36,356.75
161.95406,1.1253,0.0050768,0.0,5.141e-28,-0.00031924,1.3408,350.16,360.54,357.37,356.77
161.95538,1.1425,0.0086411,0.0,3.1802000000000004e-33,0.0010785,1.3353,350.17,360.54,357.39,356.78
161.9567,1.2084,0.0036622,0.0,1.6632e-38,-0.00080062,1.416,350.19,360.53,357.4,356.8
161.95802,1.1351,0.0081576,0.0,6.1657e-44,0.0011122,1.3454,350.21,360.53,357.42,356.81
161.95934,1.1542,0.0052612,0.0,0.0,-4.4656e-05,1.3718,350.22,360.53,357.44,356.83
161.96066,1.1501,0.0022158,0.0,0.0,0.00016231,1.3584,350.24,360.52,357.45,356.85
161.96198,1.1315,0.0012547,0.0,0.0,0.00046594,1.3414,350.24,360.53,357.45,356.85
161.9633,1.1531,0.00032532,0.0,0.0,0.00010234,1.3738,350.22,360.55,357.44,356.85
161.96462,1.1606,-0.0030173,0.0,0.0,0.00094367,1.3631,350.21,360.56,357.42,356.85
161.96594,1.1288,-0.0025081,0.0,0.0,0.00068754,1.3346,350.19,360.58,357.4,356.85
161.96726,1.1576,0.0028623,0.0,0.0,0.00025041,1.3737,350.17,360.59,357.39,356.85
161.96858,1.1523,0.0036964,0.0,0.0,3.2076e-05,1.3612,350.16,360.61,357.37,356.85
161.9699,1.1226,0.0023336,0.0,0.0,0.00036439,1.3309,350.14,360.63,357.36,356.85
161.97122,1.153,0.0040951,0.0,0.0,-0.0007116,1.3665,350.13,360.64,357.34,356.85
161.97254,1.1576,0.0043475,0.0,0.0,0.00097888,1.3673,350.12,360.65,357.34,356.87
161.97386,1.1181,0.0017289,0.0,0.0,-0.00067921,1.3322,350.12,360.65,357.33,356.88
161.97518,1.148,0.0042372,0.0,0.0,0.00058138,1.3593,350.12,360.65,357.33,356.89
161.9765,1.1461,0.0019913,0.0,0.0,-3.8814e-05,1.3518,350.12,360.66,357.32,356.9
161.97782,1.1205,-0.002185,0.0,0.0,-9.3837e-06,1.3211,350.12,360.66,357.32,356.91
161.97914,1.1536,-0.0017581,0.0,0.0,0.00031615,1.3603,350.12,360.67,357.32,356.93
161.98046,1.155,0.0003014,0.0,0.0,0.00051542,1.3716,350.12,360.67,357.31,356.94
161.98178,1.1195,0.00063206,0.0,0.0,0.00013276,1.3426,350.12,360.67,357.31,356.94
161.9831,1.1511,0.0016564,0.0,0.0,0.00059256,1.3716,350.12,360.66,357.32,356.93
161.98442,1.158,0.003507,0.0,0.0,0.0001309,1.3663,350.12,360.65,357.33,356.93
161.98574,1.1257,0.0049586,0.0,0.0,-0.00019211,1.3313,350.12,360.65,357.34,356.92
161.98706,1.1459,0.0033576,0.0,0.0,0.00086298,1.3608,350.12,360.64,357.34,356.91
161.98838,1.1585,0.0055997,0.0,0.0,-0.00077141,1.3652,350.12,360.63,357.35,356.9
161.9897,1.1209,0.0041137,0.0,0.0,0.00095352,1.3155,350.12,360.62,357.36,356.89
161.99102,1.1482,0.0012897,0.0,0.0,-7.8571e-05,1.3712,350.12,360.61,357.37,356.89
161.99234,1.1557,-0.00080391,0.0,0.0,0.00037327,1.3723,350.14,360.61,357.36,356.87
161.99366,1.1215,-0.00016699,0.0,0.0,8.4729e-05,1.3254,350.17,360.6,357.35,356.86
161.99498,1.1464,0.00021919,0.0,0.0,0.00010153,1.3609,350.19,360.6,357.35,356.85
161.9963,1.138,0.00019934,0.0,0.0,-3.2396e-05,1.3525,350.22,360.6,357.34,356.84
161.99762,1.112,0.00097984,0.0,0.0,0.0006443,1.3286,350.24,360.59,357.33,356.83
161.99894,1.1528,0.005765,0.0,0.0,-0.00024726,1.3738,350.26,360.59,357.32,356.81
162.00026,1.146,0.0026605,0.0,0.0,0.00034669,1.3697,350.29,360.58,357.31,356.8
162.00158,1.1161,0.0032125,0.0,0.0,0.00018776,1.3253,350.43,360.61,357.31,356.79
162.0029,1.1691,0.0046239,0.0,0.0,-0.00028229,1.385,351.03,360.74,357.3,356.77
162.00422,1.1517,0.0028378,0.0,0.0,0.0010281,1.3644,351.63,360.86,357.3,356.76
162.00554,1.1197,0.0010774,0.0,0.0,-0.00033095,1.3288,352.23,360.99,357.3,356.74
162.00686,1.1566,0.0024177,0.0,0.0,0.0008818,1.3673,352.83,361.12,357.29,356.73
162.00818,1.144,-0.00091438,0.0,0.0,5.5907e-05,1.3565,353.43,361.25,357.29,356.71
162.0095,3.7964,0.033669,0.0,0.0,0.003887,4.1911,354.04,361.38,357.28,356.69
162.01082,19.026,0.14842,0.0,0.0,0.015839,21.028,354.64,361.5,357.28,356.68
162.01214,37.036,0.2039,0.0,0.0,0.022387,42.803,356.16,362.39,357.27,356.66
162.01346,63.38,0.32305,0.0,0.0,0.034839,74.329,358.22,363.7,357.27,356.65
162.01478,75.545,0.37565,0.0,0.0,0.042495,88.974,360.28,365.02,357.26,356.64
162.0161,83.633,0.51766,0.0,0.0,0.057744,98.949,362.34,366.33,357.25,356.63
162.01742,88.406,0.64375,0.0,0.0,0.072697,104.72,364.39,367.64,357.24,356.62
162.01874,93.056,0.80059,0.0,0.0,0.092181,110.21,366.45,368.96,357.23,356.6
162.02006,96.49,1.0271,0.0,0.0,0.11866,114.34,368.51,370.27,357.23,356.59
162.02138,98.338,1.2692,0.0,0.0,0.15019,116.61,370.58,371.59,357.22,356.58
162.0227,100.08,1.5012,0.0,0.0,0.18023,118.68,372.81,373.04,357.2,356.59
162.02402,101.45,1.7579,0.0,0.0,0.21328,120.31,375.05,374.48,357.18,356.6
162.02534,102.28,2.0193,0.0,0.0,0.24887,121.32,377.28,375.93,357.16,356.61
162.02666,103.09,2.279,0.0,0.0,0.28546,122.31,379.51,377.37,357.14,356.61
162.02798,103.87,2.5312,0.0,0.0,0.32124,123.24,381.75,378.82,357.12,356.62
162.0293,104.46,2.783,0.0,0.0,0.36011,123.9,383.98,380.26,357.1,356.63
162.03062,104.95,3.0255,0.0,0.0,0.39617,124.53,386.22,381.71,357.08,356.64
162.03194,105.56,3.2585,0.0,0.0,0.43612,125.25,388.0,382.96,357.07,356.64
162.03326,105.94,3.4956,0.0,0.0,0.47404,125.67,389.31,384.01,357.07,356.64
162.03458,106.42,3.7262,0.0,0.0,0.51422,126.29,390.62,385.05,357.07,356.63
162.0359,106.98,3.9513,0.0,0.0,0.55615,126.93,391.93,386.1,357.07,356.63
162.03722,107.35,4.1759,0.0,0.0,0.59747,127.36,393.24,387.15,357.07,356.62
162.03854,107.7,4.4038,0.0,0.0,0.64154,127.8,394.55,388.19,357.07,356.62
162.03986,108.22,4.6265,0.0,0.0,0.68676,128.41,395.86,389.24,357.07,356.62
162.04118,108.4,4.8539,0.0,0.0,0.73269,128.6,397.17,390.29,357.07,356.61
162.0425,108.7,5.08,0.0,0.0,0.78122,128.98,398.09,391.61,357.08,356.63
162.04382,109.09,5.3068,0.0,0.0,0.83423,129.45,398.97,392.97,357.09,356.64
162.04514,109.31,5.5194,0.0,0.0,0.8817,129.69,399.85,394.32,357.1,356.66
162.04646,109.69,5.7412,0.0,0.0,0.94193,130.14,400.74,395.67,357.11,356.67
162.04778,110.09,5.9549,0.0,0.0,0.99241,130.62,401.62,397.02,357.12,356.69
162.0491,110.48,6.1653,0.0,0.0,1.0551,131.08,402.5,398.38,357.14,356.71
162.05042,110.88,6.3691,0.0,0.0,1.1151,131.56,403.39,399.73,357.15,356.72
162.05174,111.45,6.5745,0.0,0.0,1.1766,132.22,403.97,400.7,357.16,356.74
162.05306,111.82,6.7667,0.0,0.0,1.2433,132.65,403.95,400.9,357.18,356.78
162.05438,112.4,6.9583,0.0,0.0,1.3107,133.38,403.94,401.1,357.2,356.81
162.0557,113.06,7.1475,0.0,0.0,1.3752,134.12,403.92,401.29,357.22,356.84
162.05702,113.62,7.3344,0.0,0.0,1.4499,134.77,403.9,401.49,357.24,356.87
162.05834,114.36,7.4989,0.0,0.0,1.5182,135.67,403.89,401.69,357.26,356.9
162.05966,115.08,7.6585,0.0,0.0,1.5844,136.52,403.87,401.89,357.28,356.94
162.06098,105.1,7.7638,0.0,0.0,1.6423,124.94,403.86,402.09,357.3,356.97
162.0623,100.18,7.7622,0.0,0.0,1.6344,119.04,403.38,401.55,357.31,356.95
162.06362,96.417,7.7808,0.0,0.0,1.6513,114.54,402.75,400.77,357.31,356.92
162.06494,94.026,7.7899,0.0,0.0,1.6511,111.65,402.12,399.99,357.31,356.89
162.06626,92.282,7.801,0.0,0.0,1.6583,109.61,401.49,399.21,357.31,356.85
162.06758,90.422,7.8016,0.0,0.0,1.6632,107.4,400.87,398.43,357.31,356.82
162.0689,89.056,7.8138,0.0,0.0,1.6659,105.79,400.24,397.65,357.31,356.79
162.07022,87.839,7.8163,0.0,0.0,1.6641,104.31,399.61,396.87,357.31,356.76
162.07154,86.63,7.8157,0.0,0.0,1.6699,102.87,399.0,396.11,357.3,356.73
162.07286,85.504,7.8207,0.0,0.0,1.6664,101.52,398.44,395.43,357.28,356.69
162.07418,84.468,7.8259,0.0,0.0,1.6713,100.29,397.89,394.75,357.26,356.66
162.0755,83.365,7.829,0.0,0.0,1.6751,98.97,397.34,394.07,357.23,356.63
162.07682,82.32,7.8292,0.0,0.0,1.6684,97.75,396.79,393.39,357.21,356.6
162.07814,81.377,7.8353,0.0,0.0,1.6794,96.619,396.23,392.71,357.18,356.57
162.07946,80.427,7.8343,0.0,0.0,1.6732,95.48,395.68,392.03,357.16,356.53
162.08078,79.548,7.8277,0.0,0.0,1.6741,94.458,395.13,391.35,357.14,356.5
162.0821,78.819,7.8304,0.0,0.0,1.6754,93.567,394.62,390.75,357.13,356.5
162.08342,78.1,7.8331,0.0,0.0,1.6733,92.707,394.14,390.21,357.15,356.52
162.08474,77.484,7.8329,0.0,0.0,1.675,91.977,393.66,389.67,357.16,356.54
162.08606,76.967,7.8355,0.0,0.0,1.6788,91.361,393.19,389.13,357.17,356.56
162.08738,76.406,7.8416,0.0,0.0,1.6724,90.692,392.71,388.58,357.18,356.58
162.0887,75.918,7.8394,0.0,0.0,1.6807,90.132,392.23,388.04,357.19,356.6
162.09002,75.459,7.8379,0.0,0.0,1.6767,89.57,391.75,387.5,357.21,356.62
162.09134,74.901,7.8417,0.0,0.0,1.6761,88.904,391.28,386.96,357.22,356.64
162.09266,74.35,7.8426,0.0,0.0,1.6827,88.265,390.95,386.56,357.25,356.67
162.09398,73.425,7.8388,0.0,0.0,1.6754,87.204,390.63,386.16,357.29,356.71
162.0953,71.883,7.8367,0.0,0.0,1.6812,85.409,390.3,385.76,357.33,356.74
162.09662,69.79,7.8352,0.0,0.0,1.6777,82.925,389.97,385.35,357.36,356.77
162.09794,67.271,7.8266,0.0,0.0,1.6729,79.976,389.65,384.95,357.4,356.8
162.09926,64.332,7.8237,0.0,0.0,1.6727,76.46,389.32,384.55,357.43,356.83
162.10058,60.013,7.8246,0.0,0.0,1.6678,71.797,388.99,384.15,357.47,356.87
162.1019,35.861,7.77,0.0,0.0,1.6395,43.912,388.75,383.89,357.5,356.88
162.10322,14.923,7.717,0.0,0.0,1.6238,18.714,388.6,383.79,357.51,356.88
162.10454,-0.51969,7.6418,0.0,0.0,1.5815,-0.58293,388.44,383.69,357.52,356.87
162.10586,-0.10264,7.5782,0.0,0.0,1.5557,-0.089251,388.29,383.6,357.53,356.87
162.10718,-0.11133,7.5818,0.0,0.0,1.558,-0.16332,388.14,383.5,357.54,356.87
162.1085,-0.10369,7.6359,0.0,0.0,1.5779,-0.15452,387.99,383.41,357.56,356.86
162.10982,3.8515,7.6925,0.0,0.0,1.6115,4.7901,387.84,383.31,357.57,356.86
162.11114,-0.28812,7.6503,0.0,0.0,1.5922,-0.42092,387.69,383.22,357.58,356.85
162.11246,1.8305,7.6834,0.0,0.0,1.6078,1.9794,387.62,383.25,357.58,356.83
162.11378,0.39764,7.6696,0.0,0.0,1.5995,0.53735,387.57,383.31,357.57,356.81
162.1151,1.1275,7.6841,0.0,0.0,1.6029,1.2019,387.52,383.37,357.57,356.78
162.11642,0.40079,7.6816,0.0,0.0,1.6015,0.5389,387.47,383.42,357.57,356.76
162.11774,1.2552,7.6908,0.0,0.0,1.6078,1.3982,387.42,383.48,357.56,356.74
162.11906,0.6042,7.6894,0.0,0.0,1.5989,0.75222,387.37,383.53,357.56,356.71
162.12038,0.86438,7.6915,0.0,0.0,1.6096,1.0223,387.31,383.59,357.55,356.69
162.1217,0.87201,7.6853,0.0,0.0,1.6003,1.0731,387.27,383.65,357.55,356.67
162.12302,0.91152,7.688,0.0,0.0,1.602,1.0308,387.24,383.74,357.56,356.68
162.12434,0.66343,7.6806,0.0,0.0,1.6058,0.83132,387.21,383.83,357.57,356.69
162.12566,0.98863,7.6769,0.0,0.0,1.6008,1.1493,387.19,383.92,357.58,356.7
162.12698,0.80894,7.6769,0.0,0.0,1.6028,0.95656,387.16,384.0,357.59,356.71
162.1283,0.85339,7.6804,0.0,0.0,1.6053,1.0025,387.13,384.09,357.59,356.71
162.12962,0.82713,7.6803,0.0,0.0,1.6018,0.97702,387.1,384.18,357.6,356.72
162.13094,0.80415,7.683,0.0,0.0,1.6045,0.94356,387.07,384.27,357.61,356.73
162.13226,0.77762,7.6854,0.0,0.0,1.6039,0.9374,387.02,384.31,357.61,356.74
162.13358,0.91385,7.682,0.0,0.0,1.5984,1.0872,386.96,384.34,357.62,356.75
162.1349,0.84937,7.6798,0.0,0.0,1.6061,1.0026,386.9,384.37,357.62,356.75
162.13622,0.8051,7.684,0.0,0.0,1.596,0.96904,386.84,384.4,357.63,356.76
162.13754,0.89899,7.6821,0.0,0.0,1.6033,1.0635,386.78,384.42,357.63,356.77
162.13886,0.85662,7.6802,0.0,0.0,1.6029,0.99321,386.72,384.45,357.63,356.78
162.14018,0.77624,7.6792,0.0,0.0,1.6002,0.92855,386.66,384.48,357.64,356.79
162.1415,0.891,7.6806,0.0,0.0,1.6051,1.0602,386.61,384.5,357.64,356.79
162.14282,0.85663,7.6765,0.0,0.0,1.6035,1.019,386.57,384.49,357.63,356.79
162.14414,0.80834,7.6785,0.0,0.0,1.6007,0.96403,386.53,384.49,357.62,356.79
162.14546,0.8792,7.6855,0.0,0.0,1.6062,1.0386,386.49,384.48,357.62,356.79
162.14678,0.86538,7.6815,0.0,0.0,1.6005,1.023,386.45,384.47,357.61,356.79
162.1481,0.77549,7.6817,0.0,0.0,1.602,0.92967,386.41,384.46,357.6,356.79
162.14942,0.9069,7.6851,0.0,0.0,1.6061,1.0864,386.37,384.45,357.59,356.79
162.15074,0.87282,7.6833,0.0,0.0,1.5984,1.0193,386.33,384.45,357.58,356.79
162.15206,0.83629,7.6808,0.0,0.0,1.6065,0.98822,386.32,384.44,357.58,356.8
162.15338,0.85294,7.6813,0.0,0.0,1.5989,0.99361,386.32,384.43,357.57,356.81
162.1547,0.8101,7.6791,0.0,0.0,1.6001,0.96074,386.33,384.42,357.57,356.81
162.15602,0.81252,7.6743,0.0,0.0,1.6026,0.9736,386.34,384.41,357.57,356.82
162.15734,0.8712,7.6743,0.0,0.0,1.6003,1.0299,386.35,384.41,357.56,356.83
162.15866,0.85501,7.6808,0.0,0.0,1.6002,1.0122,386.36,384.4,357.56,356.84
162.15998,0.80896,7.682,0.0,0.0,1.6053,0.97101,386.36,384.39,357.55,356.85
162.1613,0.89156,7.6794,0.0,0.0,1.5985,1.0608,386.37,384.38,357.55,356.85
162.16262,0.86338,7.6825,0.0,0.0,1.6044,1.0075,386.36,384.35,357.55,356.85
162.16394,0.77206,7.6828,0.0,0.0,1.6025,0.91535,386.34,384.32,357.55,356.84
162.16526,0.89304,7.6793,0.0,0.0,1.599,1.0956,386.32,384.29,357.55,356.83
162.16658,0.8963,7.6826,0.0,0.0,1.6064,1.0536,386.31,384.25,357.55,356.82
162.1679,0.80994,7.6828,0.0,0.0,1.5998,0.95387,386.29,384.22,357.55,356.81
162.16922,0.86727,7.6773,0.0,0.0,1.6036,1.0391,386.28,384.19,357.55,356.81
162.17054,0.85615,7.6747,0.0,0.0,1.6021,1.0017,386.26,384.16,357.55,356.8
162.17186,0.84214,7.6766,0.0,0.0,1.5992,0.99149,386.24,384.14,357.55,356.79
162.17318,0.84975,7.679,0.0,0.0,1.6015,1.0106,386.21,384.15,357.56,356.79
162.1745,0.85731,7.6772,0.0,0.0,1.6015,1.0159,386.17,384.16,357.57,356.79
162.17582,0.81203,7.6829,0.0,0.0,1.5976,0.96643,386.14,384.17,357.58,356.79
162.17714,0.87749,7.6841,0.0,0.0,1.6055,1.0423,386.11,384.18,357.59,356.79
162.17846,0.83392,7.6804,0.0,0.0,1.5995,0.97391,386.08,384.18,357.59,356.79
162.17978,0.76675,7.6809,0.0,0.0,1.6015,0.92677,386.05,384.19,357.6,356.79
162.1811,0.90215,7.6851,0.0,0.0,1.6052,1.0847,386.02,384.2,357.61,356.79
162.18242,0.87359,7.6809,0.0,0.0,1.5998,1.0273,385.99,384.2,357.62,356.79
162.18374,0.83712,7.6768,0.0,0.0,1.6061,0.98844,385.97,384.2,357.63,356.79
162.18506,0.93187,7.6802,0.0,0.0,1.6033,1.115,385.95,384.2,357.65,356.79
162.18638,0.90587,7.6754,0.0,0.0,1.6013,1.0701,385.93,384.2,357.66,356.79
162.1877,0.889,7.6775,0.0,0.0,1.6038,1.0651,385.91,384.2,357.67,356.79
162.18902,0.96141,7.6808,0.0,0.0,1.6005,1.1429,385.89,384.2,357.68,356.79
162.19034,1.0192,7.6845,0.0,0.0,1.5986,1.2003,385.87,384.2,357.69,356.79
162.19166,0.86236,7.6819,0.0,0.0,1.6053,1.0218,385.86,384.19,357.71,356.79
162.19298,1.0016,7.6822,0.0,0.0,1.5967,1.2138,385.84,384.17,357.73,356.78
162.1943,0.98267,7.6849,0.0,0.0,1.6044,1.1576,385.82,384.15,357.76,356.78
162.19562,0.89463,7.6825,0.0,0.0,1.6017,1.0615,385.81,384.12,357.78,356.77
162.19694,1.0269,7.6823,0.0,0.0,1.6011,1.2302,385.79,384.1,357.8,356.76
162.19826,1.0283,7.6805,0.0,0.0,1.6053,1.2059,385.78,384.07,357.83,356.75
162.19958,0.90136,7.6786,0.0,0.0,1.602,1.0735,385.76,384.05,357.85,356.74
162.2009,1.115,7.6753,0.0,0.0,1.6066,1.3503,385.74,384.03,357.88,356.74
162.20222,0.97109,7.675,0.0,0.0,1.6043,1.1128,385.72,384.0,357.89,356.73
162.20354,0.86819,7.6825,0.0,0.0,1.6015,1.0585,385.69,383.97,357.9,356.73
162.20486,1.1295,7.6849,0.0,0.0,1.6032,1.3693,385.66,383.93,357.91,356.73
162.20618,1.0046,7.6778,0.0,0.0,1.6019,1.1721,385.64,383.9,357.91,356.73
162.2075,0.90025,7.6852,0.0,0.0,1.5978,1.0851,385.61,383.87,357.92,356.73
162.20882,1.1467,7.6811,0.0,0.0,1.6048,1.3642,385.58,383.84,357.93,356.73
162.21014,0.9328,7.679,0.0,0.0,1.5976,1.0883,385.55,383.81,357.94,356.73
162.21146,0.86514,7.6833,0.0,0.0,1.6021,1.0455,385.52,383.78,357.94,356.73
162.21278,1.1545,7.683,0.0,0.0,1.6033,1.3718,385.48,383.75,357.92,356.74
162.2141,0.9737,7.673,0.0,0.0,1.5991,1.1237,385.44,383.72,357.89,356.75
162.21542,0.85529,7.6777,0.0,0.0,1.6036,1.0331,385.4,383.69,357.87,356.76
162.21674,1.1293,7.6791,0.0,0.0,1.6039,1.3528,385.36,383.66,357.85,356.77
162.21806,0.97645,7.6776,0.0,0.0,1.6005,1.1292,385.32,383.64,357.82,356.77
162.21938,0.87722,7.6794,0.0,0.0,1.6052,1.0759,385.28,383.61,357.8,356.78
162.2207,1.1413,7.6829,0.0,0.0,1.602,1.369,385.24,383.58,357.77,356.79
162.22202,0.96462,7.6809,0.0,0.0,1.599,1.1153,385.2,383.55,357.76,356.8
162.22334,0.85209,7.6802,0.0,0.0,1.6061,1.021,385.15,383.51,357.75,356.81
162.22466,1.1397,7.6815,0.0,0.0,1.5949,1.361,385.1,383.48,357.74,356.81
162.22598,0.96766,7.682,0.0,0.0,1.6035,1.1273,385.06,383.44,357.73,356.82
162.2273,0.88067,7.6783,0.0,0.0,1.6006,1.0651,385.01,383.4,357.73,356.83
162.22862,1.1238,7.6771,0.0,0.0,1.5998,1.3476,384.96,383.37,357.72,356.84
162.22994,0.95939,7.6757,0.0,0.0,1.6022,1.0994,384.91,383.33,357.71,356.85
162.23126,0.89699,7.6766,0.0,0.0,1.6008,1.0816,384.87,383.3,357.7,356.85
162.23258,1.1201,7.6756,0.0,0.0,1.5993,1.3402,384.82,383.2,357.69,356.86
162.2339,0.97263,7.6806,0.0,0.0,1.6049,1.1189,384.77,383.11,357.69,356.87
162.23522,0.85667,7.6805,0.0,0.0,1.598,1.0374,384.72,383.01,357.68,356.88
162.23654,1.1403,7.6827,0.0,0.0,1.6046,1.3774,384.67,382.92,357.67,356.89
162.23786,0.95548,7.6753,0.0,0.0,1.6012,1.112,384.63,382.82,357.66,356.89
162.23918,0.89443,7.6854,0.0,0.0,1.5998,1.0829,384.58,382.73,357.65,356.9
162.2405,1.1224,7.678,0.0,0.0,1.6057,1.3454,384.53,382.63,357.65,356.91
162.24182,0.96691,7.6792,0.0,0.0,1.598,1.1224,384.49,382.55,357.64,356.91
162.24314,0.87332,7.6789,0.0,0.0,1.602,1.0628,384.45,382.51,357.64,356.9
162.24446,1.1369,7.6768,0.0,0.0,1.6024,1.3578,384.41,382.47,357.64,356.89
162.24578,0.94599,7.6694,0.0,0.0,1.5981,1.0773,384.37,382.42,357.64,356.87
162.2471,0.85725,7.6787,0.0,0.0,1.6,1.0387,384.33,382.38,357.64,356.86
162.24842,1.1296,7.6814,0.0,0.0,1.6024,1.3325,384.29,382.34,357.64,356.85
162.24974,0.95756,7.6772,0.0,0.0,1.5964,1.1168,384.25,382.29,357.64,356.84
162.25106,0.87828,7.6817,0.0,0.0,1.6048,1.0677,384.21,382.25,357.64,356.83
162.25238,1.113,7.6837,0.0,0.0,1.6007,1.3314,384.18,382.21,357.66,356.82
162.2537,0.9766,7.679,0.0,0.0,1.6002,1.114,384.16,382.18,357.69,356.81
162.25502,0.85995,7.6802,0.0,0.0,1.6061,1.0473,384.13,382.15,357.71,356.8
162.25634,1.1202,7.6837,0.0,0.0,1.5998,1.3309,384.11,382.12,357.73,356.79
162.25766,0.965,7.6774,0.0,0.0,1.6049,1.1092,384.09,382.09,357.76,356.79
162.25898,0.85712,7.6747,0.0,0.0,1.6034,1.0363,384.06,382.05,357.78,356.78
162.2603,1.1152,7.6765,0.0,0.0,1.601,1.345,384.04,382.02,357.81,356.77
162.26162,0.96361,7.6787,0.0,0.0,1.6011,1.1248,384.01,381.98,357.83,356.77
162.26294,0.88927,7.6783,0.0,0.0,1.6018,1.0746,383.99,381.89,357.86,356.79
162.26426,1.1132,7.6812,0.0,0.0,1.5979,1.3397,383.97,381.81,357.9,356.81
162.26558,0.96265,7.6817,0.0,0.0,1.6044,1.111,383.94,381.73,357.93,356.83
162.2669,0.87388,7.6825,0.0,0.0,1.5975,1.056,383.92,381.64,357.96,356.85
162.26822,1.1312,7.6796,0.0,0.0,1.6031,1.3435,383.89,381.56,357.99,356.87
162.26954,0.9469,7.6803,0.0,0.0,1.6014,1.0954,383.87,381.48,358.02,356.89
162.27086,0.8698,7.6842,0.0,0.0,1.601,1.0496,383.85,381.39,358.06,356.91
162.27218,1.1212,7.6776,0.0,0.0,1.6066,1.3471,383.83,381.33,358.08,356.91
162.2735,0.96486,7.6764,0.0,0.0,1.6023,1.1205,383.81,381.28,358.09,356.91
162.27482,0.87698,7.6778,0.0,0.0,1.603,1.068,383.8,381.24,358.11,356.91
162.27614,1.1265,7.6786,0.0,0.0,1.6052,1.3415,383.78,381.19,358.12,356.91
162.27746,0.9622,7.6763,0.0,0.0,1.6,1.0996,383.76,381.14,358.14,356.91
162.27878,0.86026,7.683,0.0,0.0,1.5999,1.025,383.75,381.09,358.16,356.91
162.2801,1.1395,7.6847,0.0,0.0,1.6048,1.355,383.73,381.05,358.17,356.91
162.28142,0.97028,7.6773,0.0,0.0,1.595,1.1241,383.71,381.0,358.19,356.91
162.28274,0.8743,7.684,0.0,0.0,1.6056,1.0732,383.67,380.95,358.18,356.91
162.28406,1.1223,7.6844,0.0,0.0,1.5989,1.3317,383.63,380.9,358.17,356.9
162.28538,0.98924,7.6782,0.0,0.0,1.6006,1.15,383.6,380.85,358.16,356.89
162.2867,0.9008,7.6807,0.0,0.0,1.6044,1.0813,383.56,380.81,358.15,356.88
162.28802,1.1226,7.6798,0.0,0.0,1.6,1.3514,383.52,380.76,358.15,356.87
162.28934,0.98062,7.6741,0.0,0.0,1.6054,1.1195,383.48,380.71,358.14,356.87
162.29066,0.88898,7.6752,0.0,0.0,1.6054,1.07,383.44,380.66,358.13,356.86
162.29198,1.131,7.6823,0.0,0.0,1.6011,1.3455,383.4,380.61,358.13,356.85
162.2933,0.98146,7.6825,0.0,0.0,1.6033,1.1294,383.38,380.57,358.13,356.85
162.29462,0.89108,7.6819,0.0,0.0,1.6035,1.0819,383.36,380.52,358.14,356.85
162.29594,1.1259,7.6826,0.0,0.0,1.5988,1.3539,383.33,380.47,358.14,356.85
162.29726,0.97938,7.6829,0.0,0.0,1.6058,1.1321,383.31,380.42,358.14,356.85
162.29858,0.9017,7.6815,0.0,0.0,1.5978,1.0912,383.28,380.37,358.15,356.85
162.2999,1.1465,7.6835,0.0,0.0,1.6038,1.3688,383.26,380.33,358.15,356.85
162.30122,0.96245,7.6807,0.0,0.0,1.6002,1.0973,383.24,380.28,358.16,356.85
162.30254,0.87856,7.6803,0.0,0.0,1.6012,1.0648,383.21,380.23,358.16,356.86
162.30386,1.136,7.6745,0.0,0.0,1.6029,1.3605,383.19,380.18,358.17,356.87
162.30518,0.98958,7.6776,0.0,0.0,1.6019,1.1334,383.17,380.14,358.18,356.88
162.3065,0.89005,7.6808,0.0,0.0,1.6016,1.0764,383.14,380.09,358.19,356.89
162.30782,1.1358,7.6807,0.0,0.0,1.6056,1.3658,383.12,380.04,358.2,356.89
162.30914,0.97799,7.6812,0.0,0.0,1.6009,1.1372,383.09,379.99,358.2,356.9
162.31046,0.89123,7.6853,0.0,0.0,1.6022,1.0791,383.07,379.94,358.21,356.91
162.31178,1.141,7.6831,0.0,0.0,1.6059,1.3645,383.04,379.9,358.22,356.92
162.3131,0.97507,7.6783,0.0,0.0,1.5959,1.1098,383.01,379.85,358.22,356.94
162.31442,0.8503,7.6862,0.0,0.0,1.6072,1.0379,382.97,379.8,358.23,356.95
162.31574,1.1271,7.6804,0.0,0.0,1.6004,1.349,382.93,379.75,358.23,356.97
162.31706,0.97542,7.6763,0.0,0.0,1.6011,1.1288,382.9,379.7,358.24,356.98
162.31838,0.89221,7.6794,0.0,0.0,1.6032,1.0838,382.86,379.66,358.24,357.0
162.3197,1.1108,7.6791,0.0,0.0,1.6005,1.3319,382.83,379.61,358.24,357.02
162.32102,0.9736,7.676,0.0,0.0,1.5995,1.1343,382.79,379.56,358.25,357.03
162.32234,0.89022,7.6827,0.0,0.0,1.6059,1.0749,382.76,379.52,358.25,357.05
162.32366,1.1243,7.6824,0.0,0.0,1.5975,1.3281,382.73,379.48,358.26,357.06
162.32498,0.97704,7.6819,0.0,0.0,1.6058,1.1117,382.71,379.44,358.27,357.08
162.3263,0.88973,7.6794,0.0,0.0,1.6014,1.0641,382.68,379.4,358.28,357.1
162.32762,1.1195,7.6852,0.0,0.0,1.6006,1.3425,382.65,379.36,358.29,357.11
162.32894,0.96559,7.6805,0.0,0.0,1.6057,1.1281,382.62,379.32,358.29,357.13
162.33026,0.89368,7.6805,0.0,0.0,1.6,1.0893,382.59,379.28,358.3,357.14
162.33158,1.1219,7.6811,0.0,0.0,1.605,1.3322,382.56,379.24,358.31,357.16
162.3329,0.9684,7.676,0.0,0.0,1.602,1.1221,382.52,379.19,358.3,357.16
162.33422,0.88311,7.6762,0.0,0.0,1.6015,1.0787,382.47,379.14,358.3,357.17
162.33554,1.1323,7.6773,0.0,0.0,1.601,1.3642,382.43,379.09,358.3,357.17
162.33686,0.97033,7.681,0.0,0.0,1.6002,1.1002,382.39,379.05,358.29,357.17
162.33818,0.88242,7.6847,0.0,0.0,1.5978,1.0583,382.34,379.0,358.29,357.18
162.3395,1.1306,7.682,0.0,0.0,1.6058,1.3501,382.3,378.95,358.28,357.18
162.34082,0.96741,7.6828,0.0,0.0,1.5986,1.1246,382.26,378.9,358.28,357.19
162.34214,0.88804,7.6844,0.0,0.0,1.6034,1.0827,382.21,378.84,358.27,357.18
162.34346,1.126,7.6808,0.0,0.0,1.6041,1.3416,382.16,378.76,358.27,357.17
162.34478,0.99579,7.6826,0.0,0.0,1.5999,1.1557,382.1,378.69,358.26,357.17
162.3461,0.87713,7.6832,0.0,0.0,1.6065,1.0704,382.05,378.61,358.25,357.16
162.34742,1.1504,7.676,0.0,0.0,1.6041,1.3727,382.0,378.53,358.24,357.15
162.34874,0.98852,7.674,0.0,0.0,1.6021,1.1211,381.95,378.46,358.23,357.14
162.35006,0.89319,7.6819,0.0,0.0,1.6045,1.067,381.9,378.38,358.23,357.13
162.35138,1.1274,7.6821,0.0,0.0,1.602,1.3421,381.85,378.31,358.22,357.13
162.3527,0.9997,7.6787,0.0,0.0,1.5988,1.1608,381.81,378.23,358.2,357.13
162.35402,0.89449,7.6842,0.0,0.0,1.605,1.085,381.77,378.15,358.19,357.13
162.35534,1.13,7.6841,0.0,0.0,1.5969,1.3531,381.73,378.07,358.18,357.14
162.35666,0.97847,7.6796,0.0,0.0,1.6041,1.1361,381.69,377.99,358.17,357.14
162.35798,0.88471,7.6853,0.0,0.0,1.6014,1.0896,381.65,377.91,358.16,357.15
162.3593,1.1345,7.6862,0.0,0.0,1.6006,1.3525,381.61,377.83,358.14,357.15
162.36062,0.99628,7.6772,0.0,0.0,1.6063,1.1403,381.57,377.75,358.13,357.15
162.36194,0.89619,7.6771,0.0,0.0,1.602,1.0771,381.53,377.68,358.11,357.16
162.36326,1.1374,7.6791,0.0,0.0,1.6036,1.3567,381.5,377.64,358.09,357.18
162.36458,0.97943,7.6774,0.0,0.0,1.604,1.1389,381.47,377.59,358.06,357.2
162.3659,0.91901,7.68,0.0,0.0,1.602,1.1178,381.43,377.54,358.03,357.21
162.36722,1.1389,7.6827,0.0,0.0,1.6023,1.3613,381.4,377.49,358.0,357.23
162.36854,0.98506,7.6847,0.0,0.0,1.6037,1.1401,381.37,377.44,357.97,357.24
162.36986,0.88645,7.6802,0.0,0.0,1.5971,1.0933,381.34,377.4,357.95,357.26
162.37118,1.1525,7.6827,0.0,0.0,1.6067,1.3782,381.31,377.35,357.92,357.28
162.3725,1.0031,7.683,0.0,0.0,1.5955,1.144,381.28,377.29,357.92,357.29
162.37382,0.88879,7.6826,0.0,0.0,1.6035,1.0727,381.24,377.24,357.92,357.29
162.37514,1.1346,7.6791,0.0,0.0,1.6027,1.3468,381.21,377.18,357.93,357.3
162.37646,0.98618,7.6799,0.0,0.0,1.6001,1.1412,381.18,377.13,357.93,357.31
162.37778,0.90529,7.6778,0.0,0.0,1.6049,1.1066,381.15,377.07,357.93,357.32
162.3791,1.143,7.6762,0.0,0.0,1.6048,1.3759,381.12,377.01,357.94,357.33
162.38042,0.98417,7.6764,0.0,0.0,1.5993,1.141,381.08,376.96,357.94,357.33
162.38174,0.87395,7.6849,0.0,0.0,1.6061,1.072,381.05,376.9,357.95,357.34
162.38306,1.1259,7.6816,0.0,0.0,1.6015,1.3406,381.02,376.83,357.98,357.34
162.38438,0.99774,7.6816,0.0,0.0,1.6008,1.1394,380.99,376.76,358.01,357.34
162.3857,0.90785,7.6846,0.0,0.0,1.6059,1.0957,380.96,376.69,358.04,357.34
162.38702,1.1267,7.685,0.0,0.0,1.5991,1.3435,380.92,376.63,358.07,357.34
162.38834,0.99369,7.6791,0.0,0.0,1.6044,1.1561,380.89,376.56,358.09,357.34
162.38966,0.90086,7.6833,0.0,0.0,1.5999,1.102,380.86,376.49,358.12,357.34
162.39098,1.1432,7.6809,0.0,0.0,1.6009,1.3624,380.83,376.42,358.15,357.34
162.3923,0.97996,7.6714,0.0,0.0,1.6016,1.1412,380.8,376.37,358.16,357.34
162.39362,0.88848,7.6773,0.0,0.0,1.6015,1.0759,380.76,376.33,358.16,357.34
162.39494,1.1371,7.6831,0.0,0.0,1.601,1.3511,380.73,376.29,358.16,357.34
162.39626,0.98283,7.6791,0.0,0.0,1.605,1.1268,380.7,376.24,358.16,357.34
162.39758,0.90286,7.682,0.0,0.0,1.5999,1.0874,380.67,376.2,358.16,357.34
162.3989,1.1276,7.6842,0.0,0.0,1.6037,1.3501,380.64,376.15,358.16,357.34
162.40022,0.97439,7.6813,0.0,0.0,1.6032,1.1302,380.6,376.11,358.16,357.34
162.40154,0.89637,7.6811,0.0,0.0,1.5987,1.0745,380.57,376.06,358.16,357.34
162.40286,1.1525,7.6847,0.0,0.0,1.6068,1.3666,380.52,376.01,358.17,357.35
162.40418,0.97892,7.6835,0.0,0.0,1.6006,1.1422,380.47,375.95,358.17,357.36
162.4055,0.89262,7.6762,0.0,0.0,1.6027,1.0726,380.43,375.9,358.18,357.36
162.40682,1.1364,7.6801,0.0,0.0,1.6037,1.3462,380.38,375.84,358.19,357.37
162.40814,0.99365,7.6763,0.0,0.0,1.5981,1.141,380.33,375.78,358.2,357.38
162.40946,0.89941,7.6814,0.0,0.0,1.6021,1.0841,380.28,375.73,358.21,357.39
162.41078,1.1411,7.6787,0.0,0.0,1.6032,1.3537,380.23,375.67,358.21,357.4
162.4121,0.99592,7.6842,0.0,0.0,1.5979,1.1624,380.19,375.61,358.22,357.4
162.41342,0.88962,7.6836,0.0,0.0,1.6063,1.0864,380.15,375.55,358.24,357.41
162.41474,1.1438,7.6806,0.0,0.0,1.6009,1.372,380.11,375.48,358.25,357.42
162.41606,0.99388,7.682,0.0,0.0,1.6007,1.1549,380.07,375.42,358.26,357.43
162.41738,0.90618,7.6856,0.0,0.0,1.6066,1.088,380.03,375.36,358.27,357.44
162.4187,1.1324,7.681,0.0,0.0,1.5999,1.3416,379.99,375.29,358.28,357.44
162.42002,1.0032,7.6779,0.0,0.0,1.6065,1.1588,379.95,375.23,358.3,357.45
162.42134,0.91404,7.6807,0.0,0.0,1.6039,1.1096,379.91,375.16,358.31,357.46
162.42266,1.1357,7.6785,0.0,0.0,1.6023,1.352,379.9,375.09,358.3,357.46
162.42398,0.99784,7.6745,0.0,0.0,1.6019,1.1604,379.88,375.02,358.28,357.46
162.4253,0.90518,7.6843,0.0,0.0,1.6019,1.1137,379.87,374.95,358.27,357.46
162.42662,1.1634,7.6843,0.0,0.0,1.5979,1.3682,379.85,374.88,358.26,357.46
162.42794,0.99068,7.6804,0.0,0.0,1.6053,1.1521,379.83,374.81,358.25,357.46
162.42926,0.91247,7.6829,0.0,0.0,1.5978,1.1047,379.82,374.73,358.24,357.46
162.43058,1.1478,7.6855,0.0,0.0,1.6047,1.3667,379.8,374.66,358.22,357.46
162.4319,0.99905,7.6799,0.0,0.0,1.6014,1.1578,379.78,374.6,358.22,357.46
162.43322,0.92129,7.6821,0.0,0.0,1.6005,1.1105,379.75,374.54,358.22,357.47
162.43454,1.1568,7.6843,0.0,0.0,1.6071,1.3811,379.71,374.48,358.22,357.48
162.43586,0.98642,7.6761,0.0,0.0,1.6021,1.1523,379.68,374.42,358.22,357.49
162.43718,0.89088,7.6733,0.0,0.0,1.6047,1.0847,379.65,374.36,358.22,357.5
162.4385,1.1573,7.6786,0.0,0.0,1.6052,1.3799,379.62,374.3,358.22,357.5
162.43982,1.009,7.6811,0.0,0.0,1.6008,1.1744,379.59,374.24,358.22,357.51
162.44114,0.90173,7.6814,0.0,0.0,1.6012,1.0865,379.55,374.18,358.22,357.52
162.44246,1.1406,7.6839,0.0,0.0,1.6045,1.3586,379.52,374.13,358.22,357.53
162.44378,1.0018,7.6817,0.0,0.0,1.5953,1.1526,379.48,374.09,358.23,357.55
162.4451,0.9095,7.6843,0.0,0.0,1.6066,1.1058,379.44,374.05,358.24,357.57
162.44642,1.1457,7.6797,0.0,0.0,1.5986,1.3648,379.4,374.01,358.25,357.58
162.44774,1.001,7.6838,0.0,0.0,1.6008,1.1754,379.36,373.97,358.26,357.6
162.44906,0.88494,7.6806,0.0,0.0,1.6044,1.0873,379.32,373.93,358.26,357.61
162.45038,1.1518,7.6774,0.0,0.0,1.6013,1.3766,379.28,373.89,358.27,357.63
162.4517,1.0032,7.6763,0.0,0.0,1.6026,1.1678,379.24,373.85,358.28,357.64
162.45302,0.92196,7.6812,0.0,0.0,1.6053,1.1159,379.21,373.8,358.28,357.65
162.45434,1.1294,7.6794,0.0,0.0,1.6015,1.3468,379.17,373.75,358.28,357.66
162.45566,1.0029,7.681,0.0,0.0,1.6047,1.1613,379.14,373.7,358.28,357.67
162.45698,0.9134,7.6841,0.0,0.0,1.6028,1.1044,379.11,373.64,358.28,357.68
162.4583,1.1657,7.6842,0.0,0.0,1.5995,1.3887,379.08,373.59,358.28,357.68
162.45962,0.98498,7.6797,0.0,0.0,1.6059,1.1474,379.05,373.54,358.28,357.69
162.46094,0.90227,7.6859,0.0,0.0,1.5961,1.1122,379.02,373.49,358.28,357.7
162.46226,1.1482,7.6843,0.0,0.0,1.6044,1.3604,378.99,373.44,358.28,357.7
162.46358,1.002,7.6785,0.0,0.0,1.6013,1.1628,378.97,373.39,358.29,357.7
162.4649,0.91941,7.6804,0.0,0.0,1.601,1.1128,378.94,373.34,358.29,357.69
162.46622,1.1545,7.6808,0.0,0.0,1.6044,1.3704,378.92,373.3,358.29,357.69
162.46754,1.0011,7.6756,0.0,0.0,1.6013,1.1564,378.89,373.25,358.3,357.68
162.46886,0.91137,7.6787,0.0,0.0,1.6005,1.0865,378.87,373.2,358.3,357.68
162.47018,1.1637,7.6843,0.0,0.0,1.6061,1.3963,378.85,373.15,358.31,357.68
162.4715,1.0189,7.6821,0.0,0.0,1.6001,1.1843,378.82,373.1,358.31,357.67
162.47282,0.90861,7.6822,0.0,0.0,1.6034,1.0963,378.76,373.04,358.31,357.68
162.47414,1.1482,7.683,0.0,0.0,1.6052,1.3769,378.7,372.98,358.31,357.69
162.47546,1.0041,7.684,0.0,0.0,1.5989,1.164,378.65,372.92,358.31,357.7
162.47678,0.91639,7.6809,0.0,0.0,1.6066,1.1062,378.59,372.86,358.31,357.71
163.07693,0.96506,7.6835,0.0,0.0,1.6027,1.1453,362.65,352.97,358.06,352.47
163.87693,0.89955,7.6883,0.0,0.0,1.6058,1.0662,314.86,321.72,343.17,291.7
164.67693,0.868,7.6909,0.0,0.0,1.6069,1.0296,272.37,288.24,321.63,275.88
165.47693,0.87705,7.6958,0.0,0.0,1.6092,1.0403,234.21,255.98,299.69,262.41
166.27693,0.88737,7.6959,0.0,0.0,1.6093,1.0532,195.29,217.28,274.91,236.85
166.9064,0.88734,7.696,0.0,0.0,1.6093,1.0532,132.9,184.01,253.11,212.68
167.7064,0.87793,7.6954,0.0,0.0,1.609,1.0428,103.45,146.67,214.26,187.54
168.5064,0.82119,7.6905,0.0,0.0,1.6067,0.97477,83.987,104.03,111.4,105.65
169.3064,0.80321,7.6905,0.0,0.0,1.6066,0.95381,73.494,93.85,74.832,68.014
170.1064,0.79371,7.6905,0.0,0.0,1.6067,0.94288,66.61,86.095,57.312,49.994
170.9064,0.75721,7.6904,0.0,0.0,1.6067,0.89845,60.517,77.016,46.72,40.924
171.7064,0.73858,7.6905,0.0,0.0,1.6068,0.87607,54.972,68.012,40.12,35.793
172.5064,0.72101,7.6937,0.0,0.0,1.6082,0.85614,49.385,61.229,36.051,33.083
173.3064,0.70556,7.6969,0.0,0.0,1.6098,0.83747,45.367,55.581,33.181,31.08
174.1064,0.69113,7.7011,0.0,0.0,1.6117,0.82058,43.283,51.979,31.543,30.053
174.9064,0.68268,7.7049,0.0,0.0,1.6134,0.80971,41.761,50.067,31.147,30.133
175.7064,0.67406,7.7083,0.0,0.0,1.6149,0.79998,41.54,48.406,31.431,30.631
176.5064,0.66845,7.712,0.0,0.0,1.6167,0.79339,41.406,47.589,32.018,31.274
177.3064,0.66604,7.7158,0.0,0.0,1.6186,0.79019,41.481,47.004,32.619,31.881
178.1064,0.62731,7.717,0.0,0.0,1.6191,0.74395,43.774,47.664,33.753,33.821
178.9064,0.64205,7.7184,0.0,0.0,1.6198,0.76195,45.587,48.879,35.667,35.792
179.3064,0.61233,7.7222,0.0,0.0,1.6216,0.72588,46.418,49.446,36.671,36.721