File: examples/dan-msc-case-studies/CS4/data/01 raw data/hyde_test_017.csv
Time(sec),Force(kN),Jaw(mm),PowAngle(deg),PTemp,Strain,Stress(MPa),TC1(C),TC2(C),TC3(C),TC4(C)
0.0,3.7894,-10.188,0.0,1.9773e-06,-0.78096,4.4969,25.224,25.442,25.965,25.238
1.0,3.7497,0.0031065,0.0,2.8208,0.00033347,4.4511,25.145,25.387,25.912,25.104
2.0,3.7244,0.0031084,0.0,5.8208,0.00036538,4.422,25.131,25.3,25.916,25.116
3.0,3.6993,0.0029639,0.0,8.8208,0.00035193,4.3911,25.156,25.292,25.89,25.137
3.9282,3.6813,0.0024795,0.0,11.605,0.00027847,4.3678,25.118,25.34,25.87,25.074
4.9282,3.6806,0.0026997,0.0,14.605,0.00029179,4.3673,25.185,25.381,25.957,25.118
5.9282,3.6625,0.0026322,0.0,17.605,0.00030462,4.3477,25.152,25.351,25.941,25.072
6.9282,3.658,0.0029314,0.0,20.605,0.00031021,4.3428,25.164,25.308,25.852,25.111
7.9282,3.6694,0.0029015,0.0,23.605,0.00033436,4.3557,25.126,25.308,25.931,25.162
8.9282,3.6715,0.0037307,15.874,26.605,0.00043518,4.3576,25.16,25.31,25.914,25.165
9.9282,3.6746,0.004995,32.548,29.605,0.00054106,4.3603,26.31,26.761,26.673,25.503
10.7712,3.6772,0.003139,33.785,32.134,0.00036428,4.3644,29.475,34.115,28.629,27.109
11.7712,3.6751,0.0033744,33.265,35.134,0.00039152,4.3618,33.441,38.327,31.598,30.265
12.7712,3.6722,0.0027459,33.536,38.134,0.00027579,4.357,36.934,39.662,34.687,33.555
13.7712,3.6657,0.0018822,33.886,41.134,0.00021701,4.3491,40.221,43.81,37.948,36.999
14.7712,3.6667,0.0014549,33.938,44.134,0.00017246,4.3504,43.584,47.836,41.419,40.567
15.7712,3.6765,-0.00035978,34.103,47.134,-4.8039e-05,4.3633,46.675,51.576,44.868,44.065
16.7712,3.6899,0.00018544,34.254,50.134,2.2952e-05,4.3798,49.83,55.327,48.311,47.541
17.7712,3.6957,0.0001013,34.634,53.134,1.7667e-05,4.3874,52.912,59.043,51.791,51.11
18.7712,3.7036,-0.0016928,34.184,56.134,-0.00017672,4.3955,56.034,62.592,55.259,54.581
19.7712,3.7091,-0.0014045,34.318,59.134,-0.00014082,4.4024,59.058,65.981,58.688,58.071
20.7712,3.7178,-0.0038904,34.097,62.134,-0.00046271,4.4109,62.143,69.271,62.17,61.437
21.7712,3.7156,-0.0034295,34.332,65.134,-0.00037165,4.408,65.117,72.567,65.63,64.856
22.7712,3.7303,-0.0036827,34.63,68.134,-0.00038628,4.4253,68.055,75.708,68.945,68.198
23.7712,3.7178,-0.0051343,32.118,71.134,-0.00058305,4.4129,71.003,78.661,72.225,71.519
24.7712,3.7193,-0.0057305,33.741,74.134,-0.00060774,4.4146,73.12,80.273,74.857,74.27
25.7712,3.7335,-0.0073435,31.938,77.134,-0.00077248,4.4323,75.248,82.074,77.301,76.724
26.7712,3.7404,-0.0079301,35.032,80.134,-0.00089152,4.439,77.506,84.077,79.694,78.911
27.7712,3.7631,-0.0088095,35.096,83.134,-0.00097736,4.4659,80.654,87.302,82.759,81.782
28.7712,3.7666,-0.010545,35.242,86.134,-0.0011441,4.4687,83.732,90.338,85.853,84.883
29.7712,3.7708,-0.010399,35.261,89.134,-0.0011648,4.4731,86.803,93.318,88.981,88.032
30.7712,3.7638,-0.013045,35.438,92.134,-0.0014297,4.4659,89.842,96.052,92.138,91.127
31.7712,3.7854,-0.013267,35.195,95.134,-0.0014586,4.4927,92.901,98.817,95.278,94.232
32.7712,3.8268,-0.015574,35.498,98.134,-0.0017507,4.5422,95.884,101.51,98.323,97.268
33.7712,3.861,-0.014752,36.305,101.13,-0.0016098,4.5831,98.768,104.23,101.47,100.29
34.7712,3.8815,-0.014222,35.919,104.13,-0.0015661,4.6075,101.85,107.14,104.51,103.37
35.7652,3.9072,-0.016956,35.988,107.13,-0.0018435,4.6374,104.84,109.7,107.58,106.37
36.7652,3.9298,-0.017365,35.307,110.12,-0.0019187,4.6626,108.07,112.76,110.75,109.47
37.7652,3.9189,-0.01911,33.296,113.12,-0.0021085,4.6496,111.44,116.16,114.26,112.9
38.7652,3.9225,-0.021673,32.036,116.12,-0.0023664,4.6529,114.52,118.75,117.26,116.09
39.7652,3.9415,-0.021179,33.473,119.12,-0.0023725,4.6784,117.02,120.85,119.93,118.66
40.7652,3.9446,-0.022172,32.861,122.12,-0.002441,4.6823,120.1,123.86,123.0,121.61
41.7652,3.9553,-0.025057,32.875,125.12,-0.0027686,4.6945,123.0,126.39,125.82,124.55
42.7652,3.9673,-0.027098,33.702,128.12,-0.0030064,4.7087,125.87,129.06,128.7,127.38
43.7251,3.9833,-0.027729,34.644,131.0,-0.0030495,4.7265,128.5,131.55,131.46,130.06
44.7251,3.9934,-0.029094,35.513,134.0,-0.0032267,4.7374,131.43,134.3,134.17,132.9
45.7251,3.982,-0.030539,37.018,137.0,-0.0033632,4.7249,134.24,137.02,137.09,135.75
46.7251,3.9978,-0.031356,37.6,140.0,-0.003442,4.7448,137.24,139.91,140.08,138.7
47.7251,4.0132,-0.034091,38.273,143.0,-0.0037905,4.7632,140.22,142.8,143.04,141.67
48.7251,4.0175,-0.037585,38.551,146.0,-0.0041296,4.7689,143.39,145.89,146.16,144.76
49.7251,4.0252,-0.03822,38.594,149.0,-0.0041964,4.7778,146.46,148.96,149.16,147.79
50.7251,4.0523,-0.039429,39.314,152.0,-0.0043615,4.8096,149.4,151.94,152.09,150.77
51.7251,4.0545,-0.041141,39.434,155.0,-0.0045155,4.8108,152.47,154.91,155.15,153.81
52.7251,4.0602,-0.043452,39.271,158.0,-0.0047667,4.8166,155.68,158.22,158.18,156.87
53.7251,4.073,-0.045092,39.247,161.0,-0.0050001,4.8321,158.67,161.26,161.22,159.99
54.7251,4.0636,-0.047472,39.253,164.0,-0.0052171,4.8213,161.79,164.28,164.21,163.07
55.7251,4.0778,-0.049543,39.384,167.0,-0.00546,4.8403,164.8,167.29,167.22,166.11
56.7251,4.0921,-0.048575,39.242,170.0,-0.0053879,4.8582,167.81,170.23,170.27,169.04
57.7251,4.0951,-0.050324,39.253,173.0,-0.0055465,4.8617,170.83,173.12,173.07,171.91
58.7251,4.1061,-0.053206,38.905,176.0,-0.0058654,4.8733,173.95,176.21,176.11,174.93
59.7251,4.1059,-0.055285,39.163,179.0,-0.0061255,4.8729,176.84,178.96,178.93,177.81
60.7251,4.1096,-0.057258,38.641,182.0,-0.0063147,4.8759,179.94,181.82,181.89,180.68
61.7251,4.1109,-0.059719,39.242,185.0,-0.0065784,4.8768,182.74,184.58,184.72,183.47
62.7251,4.1162,-0.063481,39.46,188.0,-0.0070177,4.8841,185.71,187.58,187.58,186.25
63.7251,4.1166,-0.061832,39.75,191.0,-0.0068134,4.886,188.67,190.51,190.48,189.23
64.7251,4.1284,-0.064895,39.914,194.0,-0.0071375,4.9007,191.74,193.69,193.55,192.19
65.7251,4.1277,-0.066909,39.606,197.0,-0.0073934,4.9004,194.8,196.75,196.56,195.26
66.7251,4.1467,-0.069564,39.706,200.0,-0.007669,4.9216,197.77,199.59,199.37,198.2
67.7251,4.1456,-0.071236,39.924,203.0,-0.0078645,4.9198,200.72,202.51,202.26,201.07
68.5999,4.1339,-0.072673,39.924,205.62,-0.0079904,4.9073,203.4,205.2,204.77,203.64
69.5999,4.1474,-0.075371,39.979,208.62,-0.0082924,4.9234,206.37,208.13,207.7,206.53
70.5999,4.1523,-0.079737,39.902,211.62,-0.0088119,4.9278,209.44,211.1,210.56,209.41
71.5999,4.1573,-0.078367,39.743,214.62,-0.0086289,4.9333,212.47,213.88,213.44,212.35
72.5999,4.1485,-0.08151,40.023,217.62,-0.0089734,4.9211,215.38,216.69,216.22,215.12
73.5999,4.1558,-0.085875,40.278,220.62,-0.0094549,4.9312,218.34,219.67,219.12,218.04
74.5999,4.1422,-0.084539,40.204,223.62,-0.0093048,4.9149,221.43,222.7,222.11,221.01
75.5999,4.1405,-0.087869,39.999,226.62,-0.0096685,4.9142,224.49,225.8,225.16,224.02
76.5999,4.1597,-0.092229,41.505,229.62,-0.010195,4.9385,227.52,228.72,228.02,226.91
77.5999,4.1619,-0.092811,42.588,232.62,-0.010201,4.9409,232.04,233.66,232.35,230.66
78.5999,4.1614,-0.095294,39.873,235.62,-0.010464,4.939,236.11,237.62,236.23,234.98
79.5999,4.1696,-0.094908,39.74,238.62,-0.010479,4.9476,238.88,239.62,239.11,238.15
80.5999,4.1658,-0.099179,40.299,241.62,-0.010902,4.9431,241.62,241.94,241.8,240.74
81.5999,4.1647,-0.10289,40.479,244.62,-0.011338,4.9404,244.56,244.81,244.65,243.45
82.5999,4.1592,-0.10355,40.571,247.62,-0.011413,4.9363,247.5,247.69,247.5,246.25
83.5999,4.1565,-0.1078,40.572,250.62,-0.011831,4.9334,250.52,250.52,250.38,249.14
84.5999,4.1679,-0.10775,40.58,253.62,-0.011848,4.9472,253.5,253.47,253.38,252.07
85.5999,4.1657,-0.1107,40.583,256.62,-0.012206,4.9454,256.52,256.33,256.31,255.01
86.5999,4.1677,-0.1123,40.577,259.62,-0.012346,4.9469,259.54,259.24,259.28,257.95
87.5999,4.1736,-0.11615,40.69,262.62,-0.012756,4.9519,262.52,262.12,262.22,260.9
88.5999,4.1661,-0.11672,40.705,265.62,-0.012846,4.9419,265.53,265.12,265.15,263.82
89.5999,4.1652,-0.1209,40.723,268.62,-0.013294,4.9422,268.51,267.91,268.13,266.75
90.5999,4.1692,-0.12137,40.774,271.62,-0.013337,4.9474,271.58,270.82,271.04,269.58
91.5999,4.1544,-0.12611,41.096,274.62,-0.013882,4.9312,274.4,273.35,273.87,272.47
92.5999,4.1744,-0.12594,41.081,277.62,-0.013845,4.9551,277.47,276.4,276.91,275.35
93.5999,4.1772,-0.13088,40.988,280.62,-0.014383,4.9586,280.52,279.28,279.88,278.35
94.5999,4.1899,-0.1314,41.186,283.62,-0.014453,4.9729,283.5,282.17,282.87,281.33
95.5999,4.1851,-0.13596,40.75,286.62,-0.014932,4.966,286.57,285.03,285.79,284.22
96.5999,4.1837,-0.13677,41.065,289.62,-0.015023,4.9642,289.55,287.94,288.76,287.11
97.5999,4.1767,-0.14156,41.202,292.62,-0.015561,4.9552,292.51,290.76,291.69,290.04
98.5999,4.1799,-0.14281,41.063,295.62,-0.015698,4.9592,295.52,293.78,294.71,292.98
99.5999,4.1776,-0.147,41.199,298.62,-0.016151,4.9583,298.55,296.82,297.72,295.94
100.5999,4.1727,-0.14874,41.198,301.62,-0.016341,4.9536,301.57,299.8,300.7,299.01
101.5281,4.1931,-0.15485,41.32,304.41,-0.017002,4.9752,304.31,302.58,303.52,301.77
102.3589,4.1941,-0.15347,40.076,306.9,-0.016865,4.9764,307.17,304.9,305.96,304.28
103.3589,4.1898,-0.15584,41.677,309.9,-0.017145,4.9698,309.59,307.33,308.59,306.9
104.3589,4.1853,-0.1598,42.014,312.9,-0.017568,4.9652,312.58,310.96,311.75,309.95
105.3589,4.1849,-0.15942,40.376,315.9,-0.017509,4.9663,316.22,314.39,314.73,313.18
106.3589,4.1791,-0.16442,40.542,318.9,-0.018045,4.9603,319.03,316.43,316.97,315.62
107.3589,4.1857,-0.16488,41.268,321.9,-0.018108,4.9695,321.7,319.05,319.26,318.03
108.3589,4.1857,-0.17039,41.97,324.9,-0.018692,4.9689,324.56,322.66,321.89,320.6
109.3589,4.1942,-0.17129,41.503,327.9,-0.018769,4.9788,327.75,326.18,324.91,323.73
110.3589,4.2008,-0.17685,41.706,330.9,-0.019399,4.9847,330.73,328.79,327.9,326.72
111.3589,4.1962,-0.17753,42.029,333.9,-0.019471,4.9783,333.65,331.42,330.9,329.57
112.3589,4.1944,-0.17853,42.374,336.9,-0.019594,4.9755,336.64,334.42,333.74,332.55
113.3589,4.1906,-0.18358,42.364,339.9,-0.020157,4.9723,339.66,337.64,336.04,335.62
114.3589,4.1946,-0.18509,42.415,342.9,-0.020284,4.978,342.77,340.81,339.37,338.69
115.3589,4.1955,-0.19253,42.459,345.9,-0.021086,4.9802,345.75,343.92,339.29,341.75
116.3589,4.1963,-0.19108,42.48,348.9,-0.02096,4.9816,348.71,347.09,350.4,344.79
117.3589,4.2124,-0.19477,47.455,351.9,-0.021341,4.9998,349.81,351.82,380.72,348.24
118.3589,4.2143,-0.20424,45.276,354.9,-0.022367,5.0006,354.53,359.74,348.61,354.05
119.3589,4.2039,-0.20223,43.675,357.9,-0.02219,4.9877,358.19,364.53,361.83,359.64
120.3589,4.1988,-0.20417,44.004,360.9,-0.022362,4.9816,360.99,367.65,361.8,363.8
121.3589,4.2071,-0.2078,43.944,363.9,-0.022803,4.9918,363.97,371.25,362.31,367.56
122.3589,4.1838,-0.21174,43.465,366.9,-0.023201,4.9664,367.09,374.68,366.27,371.26
123.3589,4.2007,-0.21405,43.14,369.9,-0.023451,4.9864,370.09,377.68,370.19,374.71
124.3589,4.2077,-0.21487,43.459,372.9,-0.023521,4.9953,372.96,380.7,373.91,378.02
125.3589,4.2163,-0.22471,43.146,375.9,-0.024566,5.0046,375.98,383.66,377.57,381.33
126.3589,4.2138,-0.22386,43.034,378.9,-0.024534,4.9999,378.95,386.41,380.94,384.58
127.3589,4.2057,-0.22626,42.833,381.9,-0.024759,4.9907,381.99,389.1,384.55,387.74
128.3589,4.2219,-0.2266,43.149,384.9,-0.024802,5.009,384.82,391.83,388.01,390.8
129.3589,4.2055,-0.23311,43.371,387.9,-0.025509,4.9892,387.79,394.79,391.1,394.03
130.3589,4.2014,-0.23614,42.981,390.9,-0.025817,4.9857,390.88,397.71,394.15,397.26
131.3589,4.2024,-0.23841,43.041,393.9,-0.026052,4.9888,393.84,400.48,397.21,400.44
132.3589,4.2133,-0.23999,43.277,396.9,-0.0263,5.0022,396.75,403.19,400.35,403.41
133.3589,4.2224,-0.24484,43.193,399.88,-0.026759,5.0119,399.75,406.21,403.65,406.55
134.1616,4.2027,-0.24566,39.049,400.0,-0.026852,4.9885,401.29,407.75,406.19,408.85
135.1616,4.2088,-0.24615,37.85,400.0,-0.026899,4.9936,401.18,406.51,408.25,409.72
136.1616,4.2227,-0.24542,37.767,400.0,-0.026853,5.0091,400.84,405.22,409.16,409.27
137.1616,4.2206,-0.25244,37.152,400.0,-0.027589,5.0072,400.68,404.42,409.31,408.54
138.1616,4.2019,-0.25089,37.216,400.0,-0.027414,4.985,400.39,403.63,408.98,407.62
139.1616,4.2048,-0.25207,37.241,400.0,-0.027572,4.9902,400.25,403.28,408.56,406.84
140.1616,4.2182,-0.25267,37.091,400.0,-0.02761,5.0076,400.12,403.1,408.08,406.12
141.1616,4.2105,-0.2524,36.949,400.0,-0.027592,4.9983,400.06,402.86,407.48,405.52
142.1616,4.2275,-0.25842,36.444,400.0,-0.028276,5.0185,399.48,402.4,406.97,404.8
143.1616,4.2252,-0.25742,36.913,400.0,-0.028162,5.014,399.37,402.18,406.36,404.14
144.1616,4.2259,-0.25869,36.378,400.0,-0.028271,5.0133,399.38,402.39,405.82,403.68
145.1616,4.2183,-0.2591,35.522,400.0,-0.028313,5.0044,398.78,401.97,405.3,403.23
146.1616,4.218,-0.25913,35.459,400.0,-0.028333,5.0047,398.32,401.71,404.71,402.53
147.1616,4.2137,-0.25895,35.478,400.0,-0.02829,5.0018,397.54,400.99,404.03,401.74
148.1616,4.2189,-0.2655,36.313,400.0,-0.029019,5.0081,397.3,400.92,403.26,400.99
149.1616,4.2119,-0.26379,36.313,400.0,-0.028857,4.9992,397.35,401.24,402.69,400.65
150.1616,4.2329,-0.26541,35.707,400.0,-0.029002,5.0252,397.29,401.49,402.29,400.56
151.1616,4.23,-0.26638,35.724,400.0,-0.029093,5.0203,397.06,401.45,402.0,400.35
152.1616,4.2265,-0.26723,35.655,400.0,-0.029213,5.0145,396.89,401.54,401.76,400.11
153.1616,4.2271,-0.2679,36.012,400.0,-0.029253,5.0155,396.83,401.67,401.53,399.93
154.1616,4.2249,-0.26847,35.749,400.0,-0.029324,5.0122,396.82,401.94,401.33,399.86
155.1616,4.219,-0.27509,36.212,400.0,-0.030039,5.007,396.86,402.26,401.25,399.84
156.1616,4.2233,-0.27463,37.075,400.0,-0.029973,5.0124,397.09,402.68,401.2,399.94
157.1616,4.2325,-0.27574,37.643,400.0,-0.030088,5.0247,397.86,403.89,401.36,400.41
158.1616,4.2293,-0.27651,36.258,400.0,-0.030208,5.0206,398.76,405.31,401.85,401.35
159.1616,4.2369,-0.27637,34.659,400.0,-0.030165,5.0282,398.58,405.45,402.36,401.88
160.1616,4.2345,-0.27643,35.712,400.0,-0.030179,5.0248,398.23,405.11,402.65,401.87
161.1616,4.2354,-0.28335,35.835,400.0,-0.03094,5.0241,398.12,405.24,402.77,401.76
162.1616,4.2136,-0.282,35.709,400.0,-0.030797,4.9999,398.14,405.34,402.86,401.75
163.1616,4.2258,-0.28241,35.497,400.0,-0.030831,5.0154,398.18,405.6,402.9,401.89
164.1616,4.2294,-0.28334,35.495,400.0,-0.030934,5.0207,398.18,405.79,402.95,401.84
165.1616,4.2303,-0.28375,35.497,400.0,-0.030991,5.0226,398.12,405.96,402.96,401.85
166.1616,4.2457,-0.28386,35.495,400.0,-0.030971,5.0398,398.14,406.15,402.96,401.92
167.0061,4.2368,-0.28939,35.198,400.0,-0.03163,5.0291,398.18,406.26,402.93,401.93
168.0061,4.2394,-0.28846,35.366,400.0,-0.031491,5.0317,398.19,406.41,403.03,402.01
169.0061,4.2517,-0.28942,34.773,400.0,-0.031573,5.0462,398.19,406.57,403.05,402.02
170.0061,4.2469,-0.29043,34.808,400.0,-0.031714,5.0395,398.2,406.76,403.08,402.05
171.0061,4.248,-0.29093,35.058,400.0,-0.031742,5.0394,398.14,406.83,403.09,402.11
172.0061,4.2413,-0.29099,34.975,400.0,-0.03175,5.0326,398.15,406.37,403.12,402.1
173.0061,4.2295,-0.29615,35.118,400.0,-0.03229,5.0185,398.09,405.91,403.16,402.1
174.0061,4.2322,-0.29557,34.893,400.0,-0.032234,5.0235,398.16,405.91,403.17,402.15
175.0061,4.2417,-0.29636,34.876,400.0,-0.032324,5.0353,398.14,405.96,403.14,402.14
176.0061,4.2435,-0.29677,34.903,400.0,-0.032383,5.038,398.09,405.9,403.15,402.18
177.0061,4.2636,-0.29656,34.914,400.0,-0.032348,5.0609,398.09,405.91,403.15,402.15
178.0061,4.2539,-0.30291,34.69,400.0,-0.033006,5.0473,398.15,405.87,403.12,402.13
178.61663,4.2509,0.020969,30.605,69.781,0.0022427,5.0568,398.19,405.86,403.19,402.17
178.61828,4.2873,0.016642,24.899,9.2455e-06,0.0016821,5.0848,398.19,405.84,403.19,402.18
178.61993,4.2774,0.01744,19.193,1.1237e-12,0.0017114,5.0692,398.19,405.82,403.19,402.19
178.62158,4.2186,0.013619,13.487,1.2975000000000002e-19,0.0020743,4.9988,398.19,405.8,403.19,402.2
178.62323,4.2255,0.019885,7.7808,1.4484e-26,0.0024696,5.0109,398.19,405.78,403.19,402.21
178.62488,4.2257,0.023607,2.0748,3.6386000000000004e-33,0.002199,5.0231,398.19,405.76,403.19,402.22
178.62653,4.2532,0.022448,0.0,8.497e-40,0.0016375,5.047,398.18,405.76,403.19,402.21
178.62818,4.2843,0.017975,0.0,0.0,0.0025103,5.0828,398.16,405.78,403.19,402.18
178.62983,4.2756,0.019131,0.0,0.0,0.0027339,5.0701,398.14,405.8,403.19,402.15
178.63148,4.2764,0.018173,0.0,0.0,0.0015835,5.0627,398.12,405.82,403.19,402.12
178.63313,4.2038,0.018525,0.0,0.0,0.0024994,4.9899,398.1,405.84,403.19,402.09
178.63478,4.1936,0.022731,0.0,0.0,0.0017795,4.9862,398.08,405.86,403.19,402.06
178.63643,4.2343,0.021018,0.0,0.0,0.0031598,5.0245,398.09,405.87,403.19,402.05
178.63808,4.269,0.019684,0.0,0.0,0.0026201,5.06,398.11,405.87,403.19,402.06
178.63973,4.2672,0.020732,0.0,0.0,0.0013884,5.065,398.12,405.87,403.19,402.06
178.64138,4.2355,0.016507,0.0,0.0,0.0016974,5.0158,398.14,405.87,403.19,402.06
178.64303,4.2019,0.01737,0.0,0.0,0.0016503,4.9857,398.16,405.87,403.19,402.07
178.64468,4.2006,0.017518,0.0,0.0,0.002848,4.9941,398.18,405.87,403.19,402.07
178.64633,4.2458,0.014788,0.0,0.0,0.0023851,5.0494,398.19,405.87,403.19,402.09
178.64798,4.2919,0.020792,0.0,0.0,0.0015604,5.0885,398.19,405.87,403.18,402.11
178.64963,4.2935,0.02188,0.0,0.0,0.0021111,5.0881,398.19,405.87,403.17,402.13
178.65128,4.2477,0.015618,0.0,0.0,0.0020821,5.0323,398.19,405.87,403.16,402.15
178.65293,4.2254,0.019695,0.0,0.0,0.0023908,5.0166,398.19,405.87,403.15,402.17
178.65458,4.2274,0.018891,0.0,0.0,0.0011461,5.0311,398.19,405.87,403.14,402.19
178.65623,4.2677,0.014578,0.0,0.0,0.0022235,5.0744,398.19,405.87,403.13,402.2
178.65788,4.2916,0.018877,0.0,0.0,0.0020411,5.1033,398.19,405.88,403.12,402.2
178.65953,4.2867,0.016734,0.0,0.0,0.0026712,5.0776,398.19,405.88,403.12,402.21
178.66118,4.2447,0.018904,0.0,0.0,0.0021447,5.0343,398.19,405.89,403.11,402.21
178.66283,4.2077,0.020311,0.0,0.0,0.00068057,4.9773,398.19,405.89,403.11,402.22
178.66448,4.2103,0.017073,0.0,0.0,0.0022617,4.9908,398.19,405.9,403.1,402.22
178.66613,4.2453,0.019495,0.0,0.0,0.0022158,5.033,398.19,405.94,403.1,402.22
178.66778,4.2657,0.018702,0.0,0.0,0.0025651,5.0688,398.19,406.04,403.1,402.19
178.66943,4.2583,0.011507,0.0,0.0,0.0019034,5.0588,398.18,406.14,403.1,402.16
178.67108,4.2325,0.019009,0.0,0.0,0.0011111,5.0071,398.18,406.25,403.1,402.13
178.67273,4.2079,0.018457,0.0,0.0,0.0022501,4.9815,398.17,406.35,403.1,402.1
178.67438,4.1973,0.018076,0.0,0.0,0.0022705,4.9846,398.17,406.46,403.1,402.07
178.67603,4.2202,0.019887,0.0,0.0,0.0022212,5.0246,398.36,406.61,403.1,402.04
178.67768,4.2712,0.019757,0.0,0.0,0.0016299,5.0751,399.09,406.89,403.12,402.01
178.67933,10.045,0.035739,0.0,0.0,0.0039222,11.091,399.82,407.16,403.13,401.98
178.68098,29.499,0.14381,0.0,0.0,0.016613,34.17,400.55,407.44,403.15,401.95
178.68263,46.897,0.19758,0.0,0.0,0.021882,54.872,401.28,407.72,403.16,401.92
178.68428,60.456,0.27342,0.0,0.0,0.030355,71.363,402.01,408.0,403.18,401.89
178.68593,67.174,0.35128,0.0,0.0,0.038049,79.541,402.87,408.43,403.2,401.86
178.68758,70.826,0.45263,0.0,0.0,0.051501,83.906,404.27,409.48,403.21,401.82
178.68923,74.581,0.58405,0.0,0.0,0.066368,88.289,405.67,410.53,403.23,401.78
178.69088,78.585,0.7604,0.0,0.0,0.086287,93.074,407.08,411.58,403.25,401.74
178.69253,80.714,0.95486,0.0,0.0,0.11031,95.682,408.48,412.63,403.27,401.7
178.69418,81.925,1.1717,0.0,0.0,0.13594,97.182,409.88,413.68,403.29,401.66
178.69583,82.722,1.3853,0.0,0.0,0.16499,98.146,411.17,414.72,403.32,401.62
178.69748,83.215,1.5877,0.0,0.0,0.19112,98.744,411.69,415.71,403.36,401.6
178.69913,83.401,1.7907,0.0,0.0,0.21668,98.969,412.2,416.7,403.4,401.58
178.70078,83.328,1.9713,0.0,0.0,0.24114,98.887,412.72,417.69,403.44,401.56
178.70243,83.021,2.1353,0.0,0.0,0.26398,98.523,413.23,418.68,403.48,401.54
178.70408,82.564,2.2888,0.0,0.0,0.28736,97.986,413.75,419.67,403.51,401.52
178.70573,82.169,2.417,0.0,0.0,0.30559,97.538,414.2,420.62,403.55,401.51
178.70738,81.797,2.5456,0.0,0.0,0.32354,97.092,413.54,420.87,403.59,401.55
178.70903,81.431,2.6552,0.0,0.0,0.33949,96.649,412.88,421.13,403.63,401.59
178.71068,81.158,2.7565,0.0,0.0,0.35676,96.321,412.22,421.39,403.67,401.63
178.71233,80.966,2.8606,0.0,0.0,0.37171,96.074,411.56,421.65,403.71,401.67
178.71398,80.92,2.9648,0.0,0.0,0.38503,96.022,410.9,421.9,403.75,401.71
178.71563,81.102,3.0504,0.0,0.0,0.40106,96.233,410.25,422.16,403.79,401.75
178.71728,81.388,3.1614,0.0,0.0,0.41806,96.555,410.84,422.44,403.78,401.77
178.71893,81.734,3.2662,0.0,0.0,0.43735,96.972,411.46,422.71,403.77,401.8
178.72058,82.092,3.3733,0.0,0.0,0.45438,97.387,412.08,422.99,403.76,401.82
178.72223,82.379,3.4905,0.0,0.0,0.47072,97.736,412.7,423.27,403.75,401.84
178.72388,82.631,3.6055,0.0,0.0,0.4922,98.057,413.31,423.55,403.74,401.87
178.72553,82.875,3.7243,0.0,0.0,0.51246,98.342,413.93,423.82,403.73,401.89
178.72718,83.073,3.8399,0.0,0.0,0.53424,98.582,415.03,424.07,403.74,401.88
178.72883,83.205,3.9454,0.0,0.0,0.55332,98.729,416.17,424.31,403.75,401.86
178.73048,83.246,4.06,0.0,0.0,0.57188,98.786,417.32,424.55,403.76,401.84
178.73213,83.223,4.1657,0.0,0.0,0.59308,98.751,418.46,424.8,403.77,401.82
178.73378,83.236,4.2689,0.0,0.0,0.61359,98.777,419.6,425.04,403.78,401.8
178.73543,83.209,4.3769,0.0,0.0,0.63392,98.748,420.75,425.28,403.79,401.78
178.73708,83.188,4.48,0.0,0.0,0.65174,98.723,421.07,425.44,403.8,401.78
178.73873,83.145,4.5654,0.0,0.0,0.67044,98.662,421.22,425.57,403.81,401.79
178.74038,83.091,4.6618,0.0,0.0,0.69071,98.596,421.38,425.71,403.82,401.79
178.74203,83.025,4.7487,0.0,0.0,0.70896,98.514,421.54,425.85,403.83,401.8
178.74368,83.031,4.8384,0.0,0.0,0.72737,98.539,421.7,425.99,403.84,401.8
178.74533,83.092,4.9291,0.0,0.0,0.74359,98.605,421.86,426.13,403.85,401.81
178.74698,83.18,5.0135,0.0,0.0,0.7661,98.704,422.0,426.27,403.85,401.86
178.74863,83.259,5.1082,0.0,0.0,0.78598,98.797,422.13,426.41,403.85,401.93
178.75028,83.321,5.1951,0.0,0.0,0.80487,98.86,422.26,426.56,403.85,402.0
178.75193,83.335,5.2776,0.0,0.0,0.82345,98.9,422.4,426.7,403.85,402.07
178.75358,83.335,5.3673,0.0,0.0,0.842,98.889,422.53,426.84,403.85,402.14
178.75523,83.406,5.4521,0.0,0.0,0.86587,98.969,422.67,426.99,403.85,402.21
178.75688,83.441,5.5309,0.0,0.0,0.88683,99.019,422.76,427.13,403.87,402.23
178.75853,83.434,5.6169,0.0,0.0,0.90506,99.007,422.84,427.27,403.89,402.23
178.76018,83.432,5.702,0.0,0.0,0.92459,99.006,422.92,427.42,403.91,402.23
178.76183,83.488,5.7775,0.0,0.0,0.94436,99.06,423.0,427.56,403.93,402.23
178.76348,83.55,5.8622,0.0,0.0,0.96846,99.149,423.08,427.71,403.95,402.23
178.76513,83.59,5.935,0.0,0.0,0.98613,99.207,423.16,427.85,403.97,402.23
178.76678,83.643,6.0091,0.0,0.0,1.006,99.265,423.17,427.95,403.97,402.19
178.76843,83.666,6.086,0.0,0.0,1.0257,99.284,423.14,428.03,403.96,402.13
178.77008,83.643,6.1517,0.0,0.0,1.0508,99.264,423.11,428.11,403.95,402.07
178.77173,83.619,6.2336,0.0,0.0,1.0713,99.219,423.08,428.19,403.94,402.01
178.77338,83.614,6.3054,0.0,0.0,1.0866,99.223,423.05,428.27,403.93,401.95
178.77503,83.663,6.3691,0.0,0.0,1.1075,99.278,423.02,428.35,403.92,401.89
178.77668,83.708,6.4424,0.0,0.0,1.1274,99.338,422.96,428.39,403.9,401.87
178.77833,83.838,6.5065,0.0,0.0,1.1533,99.479,422.86,428.41,403.88,401.88
178.77998,83.954,6.5693,0.0,0.0,1.1738,99.615,422.77,428.42,403.86,401.89
178.78163,84.078,6.6353,0.0,0.0,1.1893,99.77,422.67,428.44,403.84,401.9
178.78328,84.223,6.7075,0.0,0.0,1.213,99.949,422.58,428.45,403.82,401.91
178.78493,84.377,6.7701,0.0,0.0,1.2334,100.13,422.49,428.47,403.8,401.92
178.78658,84.52,6.8404,0.0,0.0,1.2606,100.29,422.4,428.43,403.79,401.94
178.78823,84.583,6.8985,0.0,0.0,1.2787,100.36,422.33,428.33,403.79,401.97
178.78988,84.627,6.959,0.0,0.0,1.2973,100.42,422.26,428.23,403.79,402.0
178.79153,84.707,7.0222,0.0,0.0,1.3208,100.51,422.2,428.13,403.79,402.03
178.79318,84.847,7.0707,0.0,0.0,1.343,100.67,422.13,428.03,403.79,402.06
178.79483,85.031,7.1393,0.0,0.0,1.3671,100.91,422.06,427.93,403.79,402.09
178.79648,85.192,7.198,0.0,0.0,1.3836,101.11,421.95,427.8,403.8,402.11
178.79813,85.304,7.2535,0.0,0.0,1.4078,101.23,421.78,427.62,403.81,402.11
178.79978,85.425,7.3143,0.0,0.0,1.431,101.36,421.61,427.45,403.82,402.11
178.80143,85.518,7.3699,0.0,0.0,1.4565,101.48,421.44,427.27,403.83,402.11
178.80308,85.656,7.4198,0.0,0.0,1.4766,101.64,421.28,427.09,403.84,402.11
178.80473,85.875,7.4744,0.0,0.0,1.4913,101.9,421.11,426.91,403.85,402.11
178.80638,86.094,7.5261,0.0,0.0,1.5209,102.16,420.89,426.7,403.86,402.11
178.80803,86.316,7.5787,0.0,0.0,1.5436,102.42,420.57,426.44,403.87,402.11
178.80968,86.458,7.63,0.0,0.0,1.5679,102.58,420.26,426.17,403.88,402.11
178.81133,86.681,7.6781,0.0,0.0,1.5866,102.84,419.94,425.9,403.89,402.11
178.81298,86.939,7.7288,0.0,0.0,1.6028,103.16,419.62,425.64,403.9,402.11
178.81463,87.319,7.7768,0.0,0.0,1.631,103.61,419.31,425.37,403.91,402.11
178.81628,87.671,7.8153,0.0,0.0,1.6548,104.03,418.95,425.08,403.91,402.1
178.81793,88.044,7.8631,0.0,0.0,1.6762,104.46,418.46,424.74,403.89,402.1
178.81958,88.414,7.9094,0.0,0.0,1.6933,104.89,417.97,424.4,403.87,402.09
178.82123,88.773,7.9516,0.0,0.0,1.7197,105.33,417.48,424.06,403.85,402.08
178.82288,89.199,7.9988,0.0,0.0,1.745,105.83,416.99,423.72,403.83,402.07
178.82453,89.711,8.0448,0.0,0.0,1.7657,106.44,416.5,423.38,403.81,402.06
178.82618,90.275,8.0832,0.0,0.0,1.7824,107.1,415.99,423.01,403.79,402.05
178.82783,90.848,8.124,0.0,0.0,1.8012,107.77,415.4,422.51,403.77,402.04
178.82948,91.398,8.1607,0.0,0.0,1.8373,108.41,414.8,422.02,403.75,402.04
178.83113,91.97,8.2019,0.0,0.0,1.8604,109.09,414.21,421.52,403.73,402.03
178.83278,92.576,8.2465,0.0,0.0,1.8796,109.84,413.61,421.03,403.71,402.03
178.83443,92.293,8.2804,0.0,0.0,1.8984,109.7,413.02,420.53,403.69,402.02
178.83608,88.112,8.3098,0.0,0.0,1.9079,104.71,412.42,420.03,403.67,402.02
178.83773,84.9,8.3244,0.0,0.0,1.9298,100.83,411.79,419.43,403.67,402.04
178.83938,82.587,8.3247,0.0,0.0,1.934,98.07,411.16,418.84,403.67,402.06
178.84103,80.823,8.333,0.0,0.0,1.9324,95.971,410.53,418.25,403.67,402.08
178.84268,79.421,8.3386,0.0,0.0,1.9339,94.3,409.9,417.65,403.67,402.1
178.84433,78.264,8.3423,0.0,0.0,1.9373,92.917,409.28,417.06,403.67,402.12
178.84598,77.253,8.347,0.0,0.0,1.947,91.704,408.65,416.47,403.67,402.14
178.84763,76.352,8.35,0.0,0.0,1.9446,90.64,408.12,415.92,403.69,402.15
178.84928,75.541,8.362,0.0,0.0,1.9459,89.671,407.6,415.37,403.71,402.17
178.85093,74.842,8.3578,0.0,0.0,1.9432,88.847,407.07,414.82,403.73,402.18
178.85258,74.268,8.3592,0.0,0.0,1.9542,88.155,406.55,414.27,403.75,402.2
178.85423,73.718,8.3631,0.0,0.0,1.9564,87.503,406.02,413.72,403.77,402.21
178.85588,73.183,8.3657,0.0,0.0,1.9497,86.87,405.5,413.17,403.79,402.23
178.85753,72.647,8.364,0.0,0.0,1.9526,86.225,405.06,412.69,403.81,402.22
178.85918,72.114,8.3747,0.0,0.0,1.9558,85.604,404.62,412.22,403.82,402.22
178.86083,71.61,8.3783,0.0,0.0,1.9661,85.026,404.19,411.74,403.84,402.21
178.86248,71.138,8.3744,0.0,0.0,1.9633,84.444,403.75,411.27,403.85,402.21
178.86413,70.634,8.38,0.0,0.0,1.9547,83.843,403.31,410.79,403.87,402.2
178.86578,70.106,8.3771,0.0,0.0,1.9583,83.214,402.88,410.32,403.88,402.2
178.86743,69.538,8.3781,0.0,0.0,1.9615,82.537,402.51,409.94,403.89,402.19
178.86908,68.943,8.3804,0.0,0.0,1.9704,81.828,402.15,409.58,403.9,402.18
178.87073,68.298,8.379,0.0,0.0,1.9658,81.073,401.78,409.22,403.91,402.17
178.87238,67.393,8.3842,0.0,0.0,1.9585,80.021,401.42,408.86,403.92,402.16
178.87403,65.779,8.3883,0.0,0.0,1.9655,78.133,401.06,408.49,403.93,402.15
178.87568,63.549,8.3778,0.0,0.0,1.9631,75.522,400.7,408.13,403.94,402.14
178.87733,60.638,8.3817,0.0,0.0,1.9642,72.116,400.49,408.01,403.96,402.15
178.87898,57.046,8.377,0.0,0.0,1.9529,67.897,400.32,407.93,403.99,402.16
178.88063,46.199,8.3506,0.0,0.0,1.9507,56.471,400.14,407.86,404.01,402.18
178.88228,16.071,8.2899,0.0,0.0,1.9138,20.211,399.97,407.78,404.04,402.19
178.88393,1.2038,8.2249,0.0,0.0,1.874,1.5858,399.8,407.71,404.06,402.21
178.88558,4.8706,8.2561,0.0,0.0,1.8836,5.7717,399.62,407.63,404.09,402.22
178.88723,3.0608,8.2501,0.0,0.0,1.8708,3.662,399.59,407.72,404.08,402.24
178.88888,4.1186,8.2465,0.0,0.0,1.8823,4.8546,399.61,407.87,404.06,402.25
178.89053,3.3687,8.2437,0.0,0.0,1.884,3.9132,399.63,408.01,404.04,402.26
178.89218,3.5205,8.2452,0.0,0.0,1.8848,4.194,399.65,408.15,404.02,402.26
178.89383,3.7893,8.2443,0.0,0.0,1.8823,4.4688,399.67,408.3,404.0,402.27
178.89548,3.5302,8.2514,0.0,0.0,1.8754,4.1765,399.69,408.44,403.98,402.28
178.89713,3.583,8.2514,0.0,0.0,1.8844,4.2259,399.76,408.56,403.95,402.28
178.89878,3.4895,8.2486,0.0,0.0,1.8856,4.1413,399.84,408.65,403.92,402.27
178.90043,3.4406,8.2497,0.0,0.0,1.8826,4.0844,399.92,408.75,403.89,402.26
178.90208,3.5817,8.2503,0.0,0.0,1.8783,4.2616,400.01,408.85,403.86,402.25
178.90373,3.6241,8.2422,0.0,0.0,1.8782,4.3146,400.09,408.95,403.83,402.24
178.90538,3.6459,8.2421,0.0,0.0,1.8832,4.3153,400.18,409.05,403.8,402.23
178.90703,3.5216,8.2441,0.0,0.0,1.8811,4.1522,400.27,409.14,403.8,402.23
178.90868,3.4819,8.2466,0.0,0.0,1.8793,4.1265,400.38,409.22,403.8,402.23
178.91033,3.4699,8.2511,0.0,0.0,1.8777,4.1124,400.48,409.3,403.81,402.23
178.91198,3.5269,8.2517,0.0,0.0,1.8872,4.2051,400.59,409.38,403.81,402.23
178.91363,3.6564,8.2516,0.0,0.0,1.8879,4.3632,400.69,409.46,403.82,402.23
178.91528,3.6787,8.2516,0.0,0.0,1.8804,4.3418,400.79,409.53,403.82,402.23
178.91693,3.5616,8.2416,0.0,0.0,1.8781,4.2048,400.88,409.61,403.82,402.24
178.91858,3.4988,8.2466,0.0,0.0,1.8761,4.1518,400.95,409.69,403.82,402.25
178.92023,3.4952,8.2474,0.0,0.0,1.8872,4.1365,401.02,409.77,403.81,402.27
178.92188,3.535,8.2452,0.0,0.0,1.8851,4.2127,401.09,409.85,403.81,402.28
178.92353,3.5877,8.2512,0.0,0.0,1.8789,4.2726,401.16,409.93,403.8,402.3
178.92518,3.6112,8.2501,0.0,0.0,1.8774,4.2714,401.23,410.01,403.8,402.31
178.92683,3.5745,8.2476,0.0,0.0,1.8797,4.2354,401.28,410.08,403.79,402.31
178.92848,3.5147,8.2468,0.0,0.0,1.8868,4.1624,401.31,410.14,403.79,402.3
178.93013,3.5257,8.2438,0.0,0.0,1.8811,4.1888,401.34,410.2,403.79,402.29
178.93178,3.5164,8.2491,0.0,0.0,1.8803,4.1891,401.37,410.26,403.79,402.28
178.93343,3.59,8.2487,0.0,0.0,1.88,4.2757,401.4,410.32,403.79,402.27
178.93508,3.6196,8.2471,0.0,0.0,1.8865,4.2977,401.43,410.38,403.79,402.26
178.93673,3.5945,8.253,0.0,0.0,1.885,4.2568,401.47,410.42,403.8,402.26
178.93838,3.5518,8.2534,0.0,0.0,1.8729,4.1869,401.53,410.44,403.81,402.26
178.94003,3.5398,8.2454,0.0,0.0,1.8808,4.2095,401.59,410.46,403.82,402.27
178.94168,3.5679,8.2475,0.0,0.0,1.8823,4.2371,401.65,410.48,403.83,402.27
178.94333,3.6078,8.2498,0.0,0.0,1.8913,4.2931,401.71,410.5,403.84,402.28
178.94498,3.6358,8.2436,0.0,0.0,1.883,4.3116,401.77,410.52,403.85,402.28
178.94663,3.5882,8.2499,0.0,0.0,1.8731,4.2366,401.82,410.54,403.86,402.3
178.94828,3.5309,8.2534,0.0,0.0,1.8826,4.2059,401.87,410.55,403.87,402.33
178.94993,3.5132,8.2483,0.0,0.0,1.8814,4.169,401.92,410.57,403.88,402.36
178.95158,3.5504,8.2533,0.0,0.0,1.8892,4.225,401.97,410.58,403.89,402.39
178.95323,3.621,8.2454,0.0,0.0,1.8825,4.3082,402.02,410.6,403.9,402.42
178.95488,3.625,8.2469,0.0,0.0,1.8763,4.3041,402.07,410.61,403.91,402.45
178.95653,3.5945,8.2512,0.0,0.0,1.8847,4.2662,402.12,410.63,403.91,402.46
178.95818,3.5628,8.2442,0.0,0.0,1.8829,4.2213,402.17,410.65,403.92,402.44
178.95983,3.5256,8.2538,0.0,0.0,1.8849,4.1947,402.22,410.67,403.92,402.42
178.96148,3.5892,8.2567,0.0,0.0,1.8794,4.271,402.27,410.69,403.93,402.4
178.96313,3.6277,8.2473,0.0,0.0,1.8811,4.3241,402.32,410.71,403.93,402.38
178.96478,3.6302,8.2516,0.0,0.0,1.8863,4.3104,402.37,410.73,403.94,402.36
178.96643,3.6108,8.2463,0.0,0.0,1.882,4.2762,402.41,410.75,403.95,402.35
178.96808,3.5863,8.2445,0.0,0.0,1.8801,4.2545,402.45,410.75,403.96,402.33
178.96973,3.6181,8.2515,0.0,0.0,1.8757,4.2935,402.49,410.75,403.97,402.32
178.97138,3.6854,8.2506,0.0,0.0,1.8873,4.3653,402.53,410.75,403.97,402.3
178.97303,3.7364,8.2534,0.0,0.0,1.8885,4.4387,402.57,410.75,403.98,402.29
178.97468,3.7487,8.2534,0.0,0.0,1.8836,4.4191,402.61,410.75,403.99,402.27
178.97633,3.7654,8.2478,0.0,0.0,1.8795,4.4721,402.65,410.75,404.0,402.26
178.97798,3.7476,8.2491,0.0,0.0,1.8751,4.4254,402.67,410.76,404.0,402.3
178.97963,3.7062,8.249,0.0,0.0,1.8872,4.3867,402.69,410.77,403.99,402.33
178.98128,3.7324,8.2442,0.0,0.0,1.8869,4.4399,402.71,410.78,403.99,402.37
178.98293,3.8027,8.2525,0.0,0.0,1.883,4.52,402.73,410.79,403.98,402.4
178.98458,3.8925,8.2552,0.0,0.0,1.8807,4.6041,402.75,410.8,403.98,402.43
178.98623,3.8447,8.2492,0.0,0.0,1.8803,4.5374,402.77,410.81,403.97,402.47
178.98788,3.7183,8.2541,0.0,0.0,1.8886,4.3932,402.81,410.81,403.95,402.48
178.98953,3.7086,8.251,0.0,0.0,1.8818,4.4146,402.85,410.82,403.92,402.5
178.99118,3.7512,8.2472,0.0,0.0,1.8799,4.4964,402.89,410.82,403.9,402.51
178.99283,3.8982,8.2534,0.0,0.0,1.8816,4.6633,402.93,410.83,403.87,402.53
178.99448,3.9821,8.2423,0.0,0.0,1.8905,4.7013,402.97,410.83,403.85,402.54
178.99613,3.8466,8.2503,0.0,0.0,1.8874,4.5126,403.01,410.84,403.82,402.56
178.99778,3.7079,8.2552,0.0,0.0,1.8769,4.3712,403.02,410.83,403.82,402.55
178.99943,3.6721,8.2447,0.0,0.0,1.8771,4.3642,403.03,410.82,403.81,402.55
179.00108,3.7654,8.2536,0.0,0.0,1.8812,4.5226,403.04,410.81,403.81,402.54
179.00273,3.9506,8.2521,0.0,0.0,1.8899,4.7065,403.05,410.8,403.8,402.54
179.00438,3.9136,8.2423,0.0,0.0,1.8856,4.6376,403.06,410.79,403.8,402.53
179.00603,3.8469,8.2497,0.0,0.0,1.8777,4.5479,403.07,410.78,403.79,402.53
179.00768,3.6912,8.247,0.0,0.0,1.8789,4.3537,403.08,410.77,403.78,402.55
179.00933,3.6773,8.2509,0.0,0.0,1.8816,4.3821,403.09,410.76,403.76,402.57
179.01098,3.7735,8.2536,0.0,0.0,1.8887,4.497,403.1,410.75,403.74,402.59
179.01263,3.9129,8.25,0.0,0.0,1.8828,4.6528,403.11,410.74,403.72,402.61
179.01428,3.9608,8.2501,0.0,0.0,1.8786,4.6859,403.12,410.73,403.7,402.63
179.01593,3.8488,8.247,0.0,0.0,1.8799,4.533,403.13,410.72,403.68,402.65
179.01758,3.6887,8.2423,0.0,0.0,1.8847,4.366,403.14,410.68,403.67,402.65
179.01923,3.6831,8.2499,0.0,0.0,1.8849,4.3854,403.16,410.64,403.67,402.65
179.02088,3.7877,8.2535,0.0,0.0,1.8786,4.5265,403.17,410.61,403.67,402.65
179.02253,3.9312,8.2493,0.0,0.0,1.8823,4.6752,403.19,410.57,403.67,402.65
179.02418,3.9349,8.2513,0.0,0.0,1.8841,4.6544,403.2,410.53,403.67,402.65
179.02583,3.8462,8.2518,0.0,0.0,1.8857,4.5333,403.22,410.49,403.67,402.65
179.02748,3.7032,8.2464,0.0,0.0,1.8823,4.3529,403.22,410.45,403.69,402.64
179.02913,3.6763,8.2481,0.0,0.0,1.8733,4.3889,403.23,410.42,403.72,402.63
179.03078,3.7946,8.247,0.0,0.0,1.8841,4.5356,403.23,410.39,403.74,402.62
179.03243,3.9137,8.2501,0.0,0.0,1.8861,4.6684,403.24,410.36,403.77,402.61
179.03408,3.9419,8.2517,0.0,0.0,1.8862,4.6679,403.24,410.33,403.79,402.6
179.03573,3.8353,8.2476,0.0,0.0,1.8797,4.5201,403.25,410.3,403.81,402.59
179.03738,3.6935,8.2525,0.0,0.0,1.8756,4.3704,403.26,410.28,403.83,402.59
179.03903,3.6588,8.2508,0.0,0.0,1.8834,4.3524,403.28,410.25,403.84,402.59
179.04068,3.7882,8.2453,0.0,0.0,1.8862,4.527,403.3,410.23,403.85,402.59
179.04233,3.9307,8.2467,0.0,0.0,1.8818,4.6735,403.32,410.2,403.86,402.59
179.04398,3.9335,8.2497,0.0,0.0,1.8788,4.6386,403.34,410.18,403.87,402.59
179.04563,3.8251,8.2466,0.0,0.0,1.8825,4.5038,403.36,410.15,403.88,402.59
179.04728,3.719,8.2509,0.0,0.0,1.8868,4.3737,403.37,410.11,403.88,402.59
179.04893,3.6814,8.2537,0.0,0.0,1.8817,4.3851,403.38,410.05,403.87,402.6
179.05058,3.7879,8.2499,0.0,0.0,1.8776,4.5642,403.38,409.99,403.86,402.61
179.05223,3.942,8.2495,0.0,0.0,1.8752,4.6927,403.39,409.93,403.85,402.62
179.05388,3.9466,8.2465,0.0,0.0,1.8892,4.6712,403.39,409.87,403.84,402.63
179.05553,3.8348,8.2474,0.0,0.0,1.8879,4.5188,403.4,409.81,403.83,402.64
179.05718,3.7184,8.2483,0.0,0.0,1.88,4.3826,403.4,409.78,403.82,402.65
179.05883,3.6828,8.249,0.0,0.0,1.8797,4.3753,403.41,409.76,403.82,402.65
179.06048,3.7818,8.2534,0.0,0.0,1.8758,4.5225,403.41,409.75,403.81,402.65
179.06213,3.9581,8.2586,0.0,0.0,1.8899,4.7035,403.42,409.73,403.81,402.65
179.06378,3.9363,8.2462,0.0,0.0,1.8866,4.6555,403.42,409.72,403.8,402.65
179.06543,3.8404,8.2495,0.0,0.0,1.8807,4.532,403.43,409.7,403.8,402.65
179.06708,3.7282,8.2472,0.0,0.0,1.8784,4.4045,403.44,409.68,403.8,402.65
179.06873,3.6914,8.2478,0.0,0.0,1.8817,4.3985,403.45,409.66,403.81,402.66
179.07038,3.8202,8.2501,0.0,0.0,1.8877,4.5637,403.46,409.63,403.83,402.67
179.07203,3.9475,8.2533,0.0,0.0,1.8841,4.707,403.47,409.61,403.84,402.68
179.07368,3.9787,8.2553,0.0,0.0,1.8811,4.6986,403.48,409.58,403.86,402.69
179.07533,3.8524,8.2537,0.0,0.0,1.8816,4.5476,403.49,409.56,403.87,402.7
179.07698,3.7176,8.2469,0.0,0.0,1.8854,4.4015,403.48,409.52,403.88,402.72
179.07863,3.6974,8.2474,0.0,0.0,1.8855,4.4116,403.47,409.45,403.88,402.75
179.08028,3.8254,8.2531,0.0,0.0,1.8789,4.5812,403.45,409.38,403.87,402.78
179.08193,3.9636,8.2433,0.0,0.0,1.8799,4.7217,403.43,409.31,403.87,402.81
179.08358,3.9737,8.257,0.0,0.0,1.8844,4.7028,403.41,409.24,403.86,402.84
179.08523,3.8696,8.2542,0.0,0.0,1.8897,4.5562,403.39,409.17,403.86,402.87
179.08688,3.7275,8.2488,0.0,0.0,1.8856,4.4039,403.37,409.1,403.85,402.89
179.08853,3.7197,8.2498,0.0,0.0,1.875,4.4175,403.35,409.05,403.85,402.9
179.09018,3.8194,8.249,0.0,0.0,1.8815,4.5582,403.34,409.0,403.85,402.91
179.09183,3.9607,8.2492,0.0,0.0,1.8848,4.7178,403.32,408.94,403.85,402.92
179.09348,3.9923,8.2505,0.0,0.0,1.8888,4.7166,403.31,408.89,403.85,402.93
179.09513,3.8656,8.2458,0.0,0.0,1.8822,4.5561,403.29,408.83,403.85,402.94
179.09678,3.7206,8.2538,0.0,0.0,1.8782,4.4121,403.28,408.78,403.86,402.95
179.09843,3.7094,8.2537,0.0,0.0,1.8838,4.4188,403.29,408.75,403.89,402.96
179.10008,3.8368,8.251,0.0,0.0,1.8855,4.5801,403.29,408.71,403.92,402.97
179.10173,3.9622,8.2509,0.0,0.0,1.8835,4.7127,403.3,408.68,403.95,402.98
179.10338,3.9619,8.2517,0.0,0.0,1.877,4.679,403.3,408.64,403.98,402.99
179.10503,3.8639,8.2444,0.0,0.0,1.8848,4.5446,403.31,408.61,404.01,403.0
179.10668,3.7126,8.2498,0.0,0.0,1.8882,4.3884,403.31,408.57,404.03,403.01
179.10833,3.7022,8.2545,0.0,0.0,1.8871,4.4004,403.28,408.53,404.03,402.99
179.10998,3.8299,8.2528,0.0,0.0,1.8812,4.5825,403.25,408.49,404.03,402.97
179.11163,3.961,8.2527,0.0,0.0,1.8735,4.718,403.22,408.45,404.03,402.95
179.11328,3.9512,8.253,0.0,0.0,1.8876,4.6743,403.19,408.41,404.03,402.93
179.11493,3.8572,8.2474,0.0,0.0,1.8875,4.5443,403.16,408.37,404.03,402.91
179.11658,3.7239,8.2485,0.0,0.0,1.8843,4.4016,403.13,408.33,404.03,402.89
179.11823,3.7134,8.2453,0.0,0.0,1.8813,4.42,403.1,408.28,404.01,402.88
179.11988,3.8255,8.2515,0.0,0.0,1.8758,4.5626,403.08,408.23,403.99,402.87
179.12153,3.9829,8.258,0.0,0.0,1.8891,4.7413,403.05,408.17,403.97,402.86
179.12318,3.9779,8.2473,0.0,0.0,1.8849,4.7009,403.03,408.12,403.95,402.85
179.12483,3.8524,8.2523,0.0,0.0,1.8827,4.5401,403.01,408.06,403.93,402.84
179.12648,3.7263,8.2522,0.0,0.0,1.8793,4.4035,402.98,408.01,403.91,402.83
179.12813,3.7098,8.2456,0.0,0.0,1.882,4.4228,402.97,407.97,403.92,402.83
179.12978,3.8634,8.2502,0.0,0.0,1.8888,4.6105,402.95,407.93,403.92,402.83
179.13143,3.9683,8.2498,0.0,0.0,1.8833,4.7181,402.94,407.89,403.93,402.83
179.13308,3.9659,8.2523,0.0,0.0,1.882,4.6826,402.92,407.85,403.93,402.83
179.13473,3.8683,8.2534,0.0,0.0,1.8792,4.5591,402.91,407.81,403.94,402.83
179.13638,3.733,8.2519,0.0,0.0,1.8881,4.426,402.89,407.77,403.94,402.83
179.13803,3.722,8.2523,0.0,0.0,1.8893,4.4407,402.88,407.71,403.96,402.82
179.13968,3.8604,8.2552,0.0,0.0,1.8811,4.6256,402.87,407.64,403.98,402.81
179.14133,4.0069,8.2451,0.0,0.0,1.8798,4.7768,402.86,407.58,404.0,402.8
179.14298,3.9924,8.25,0.0,0.0,1.879,4.715,402.85,407.51,404.02,402.79
179.14463,3.8651,8.2545,0.0,0.0,1.8916,4.5662,402.84,407.45,404.04,402.78
179.14628,3.7504,8.248,0.0,0.0,1.8865,4.4343,402.83,407.38,404.06,402.77
179.14793,3.7223,8.2556,0.0,0.0,1.8795,4.4263,402.82,407.32,404.06,402.79
179.14958,3.8634,8.2548,0.0,0.0,1.8809,4.6136,402.81,407.26,404.05,402.81
179.15123,3.9917,8.2513,0.0,0.0,1.8836,4.7245,402.8,407.19,404.04,402.83
179.15288,3.9866,8.2486,0.0,0.0,1.8883,4.7207,402.79,407.13,404.03,402.85
179.15453,3.8769,8.2491,0.0,0.0,1.8831,4.5783,402.78,407.06,404.02,402.87
179.15618,3.7482,8.2484,0.0,0.0,1.8801,4.435,402.77,407.0,404.01,402.89
179.15783,3.7522,8.2545,0.0,0.0,1.8851,4.4764,402.73,406.95,403.98,402.91
179.15948,3.8715,8.251,0.0,0.0,1.8875,4.6317,402.68,406.9,403.96,402.94
179.16113,4.0069,8.2553,0.0,0.0,1.8838,4.7755,402.63,406.86,403.93,402.97
179.16278,4.0155,8.2572,0.0,0.0,1.8743,4.7273,402.58,406.81,403.91,403.0
179.16443,3.8897,8.2444,0.0,0.0,1.8832,4.5851,402.53,406.77,403.89,403.03
179.16608,3.7594,8.2513,0.0,0.0,1.8866,4.443,402.48,406.73,403.86,403.06
179.16773,3.7532,8.25,0.0,0.0,1.8891,4.4794,402.46,406.68,403.86,403.08
179.16938,3.8638,8.2508,0.0,0.0,1.8849,4.6195,402.44,406.64,403.87,403.09
179.17103,3.9957,8.2548,0.0,0.0,1.8746,4.7571,402.43,406.59,403.88,403.1
179.17268,3.9816,8.2557,0.0,0.0,1.8845,4.7152,402.41,406.55,403.89,403.11
179.17433,3.8745,8.2544,0.0,0.0,1.8871,4.5732,402.4,406.5,403.9,403.12
179.17598,3.7621,8.2508,0.0,0.0,1.8873,4.4552,402.38,406.46,403.91,403.13
179.17763,3.7489,8.2489,0.0,0.0,1.8831,4.4663,402.37,406.41,403.93,403.13
179.17928,3.8937,8.2518,0.0,0.0,1.8791,4.6488,402.36,406.37,403.95,403.14
179.18093,4.0074,8.2544,0.0,0.0,1.8864,4.7609,402.35,406.32,403.97,403.14
179.18258,4.0125,8.2487,0.0,0.0,1.8852,4.7501,402.34,406.28,403.99,403.15
179.18423,3.8661,8.2558,0.0,0.0,1.8847,4.5593,402.33,406.24,404.01,403.15
179.18588,3.736,8.2588,0.0,0.0,1.8807,4.4237,402.32,406.19,404.03,403.16
179.18753,3.7455,8.248,0.0,0.0,1.8831,4.4617,402.29,406.14,404.04,403.16
179.18918,3.8813,8.2532,0.0,0.0,1.8888,4.6413,402.23,406.08,404.06,403.17
179.19083,3.9982,8.2544,0.0,0.0,1.8862,4.751,402.18,406.02,404.07,403.17
179.19248,3.9788,8.2451,0.0,0.0,1.88,4.7102,402.12,405.96,404.09,403.18
179.19413,3.8883,8.2543,0.0,0.0,1.8784,4.5863,402.07,405.9,404.1,403.18
179.19578,3.7401,8.2486,0.0,0.0,1.8872,4.4158,402.01,405.84,404.12,403.19
179.19743,3.7548,8.2574,0.0,0.0,1.8915,4.4701,401.97,405.78,404.13,403.2
179.19908,3.8879,8.2567,0.0,0.0,1.8833,4.6479,401.94,405.71,404.13,403.21
179.20073,4.0085,8.2478,0.0,0.0,1.8791,4.7581,401.9,405.64,404.14,403.22
179.20238,4.0023,8.2537,0.0,0.0,1.8795,4.7332,401.87,405.57,404.14,403.23
179.20403,3.8806,8.2478,0.0,0.0,1.8874,4.5958,401.83,405.5,404.15,403.24
179.20568,3.7558,8.2462,0.0,0.0,1.8881,4.4461,401.8,405.43,404.15,403.25
179.20733,3.7547,8.2572,0.0,0.0,1.8847,4.4793,401.77,405.37,404.15,403.25
179.20898,3.9119,8.2559,0.0,0.0,1.8808,4.6677,401.75,405.33,404.13,403.26
179.21063,4.0159,8.2546,0.0,0.0,1.8847,4.7714,401.73,405.29,404.12,403.26
179.21228,4.0129,8.2549,0.0,0.0,1.8895,4.7364,401.71,405.25,404.1,403.27
179.21393,3.8994,8.2513,0.0,0.0,1.881,4.5939,401.69,405.21,404.09,403.27
179.21558,3.7669,8.2484,0.0,0.0,1.8809,4.4809,401.67,405.17,404.07,403.28
179.21723,3.7515,8.2519,0.0,0.0,1.8836,4.4732,401.65,405.13,404.06,403.28
179.21888,3.9026,8.2484,0.0,0.0,1.8919,4.6921,401.62,405.07,404.06,403.29
179.22053,4.0505,8.2569,0.0,0.0,1.8895,4.8106,401.6,405.01,404.06,403.3
179.22218,4.0164,8.2568,0.0,0.0,1.8763,4.7495,401.57,404.95,404.06,403.31
179.22383,3.8792,8.2495,0.0,0.0,1.8808,4.5577,401.55,404.89,404.06,403.32
179.22548,3.7732,8.2562,0.0,0.0,1.8844,4.466,401.52,404.83,404.06,403.33
179.22713,3.772,8.2526,0.0,0.0,1.8915,4.4898,401.5,404.77,404.07,403.34
179.22878,3.925,8.2474,0.0,0.0,1.8886,4.6949,401.48,404.69,404.09,403.35
179.23043,4.0546,8.2542,0.0,0.0,1.8778,4.8108,401.46,404.62,404.11,403.35
179.23208,4.0231,8.2525,0.0,0.0,1.8813,4.749,401.44,404.54,404.13,403.36
179.23373,3.9002,8.2538,0.0,0.0,1.8843,4.6077,401.42,404.47,404.15,403.36
179.23538,3.7731,8.2545,0.0,0.0,1.8885,4.4639,401.4,404.39,404.17,403.37
179.23703,3.7844,8.2546,0.0,0.0,1.885,4.5052,401.38,404.33,404.18,403.37
179.23868,3.9232,8.2531,0.0,0.0,1.881,4.6796,401.35,404.29,404.17,403.36
179.24033,4.0356,8.2527,0.0,0.0,1.8859,4.8071,401.32,404.25,404.16,403.35
179.24198,4.0306,8.2453,0.0,0.0,1.8853,4.7642,401.29,404.21,404.15,403.34
179.24363,3.9021,8.2516,0.0,0.0,1.8849,4.6013,401.26,404.17,404.14,403.33
179.24528,3.7828,8.2557,0.0,0.0,1.8797,4.4797,401.23,404.13,404.13,403.32
179.24693,3.795,8.2515,0.0,0.0,1.8845,4.5312,401.2,404.09,404.12,403.31
179.24858,3.928,8.2569,0.0,0.0,1.8892,4.7022,401.15,404.05,404.12,403.32
179.25023,4.0383,8.2553,0.0,0.0,1.8875,4.8036,401.11,404.01,404.11,403.33
179.25188,4.0211,8.2488,0.0,0.0,1.8826,4.7444,401.06,403.97,404.11,403.34
179.25353,3.9006,8.2527,0.0,0.0,1.8757,4.5982,401.02,403.93,404.1,403.35
179.25518,3.7839,8.2499,0.0,0.0,1.887,4.4688,400.98,403.89,404.1,403.36
179.25683,3.7941,8.2555,0.0,0.0,1.8903,4.515,400.93,403.85,404.09,403.37
179.25848,3.9412,8.2561,0.0,0.0,1.8872,4.708,400.9,403.81,404.1,403.37
179.26013,4.0386,8.2553,0.0,0.0,1.8831,4.8034,400.86,403.76,404.11,403.36
179.26178,4.011,8.256,0.0,0.0,1.8779,4.7446,400.83,403.72,404.12,403.36
179.6627,3.8197,8.255,0.0,0.0,1.8856,4.5333,388.94,390.63,706.36,398.52
180.6627,3.7493,8.2587,0.0,0.0,1.8878,4.4494,360.59,365.19,393.7,386.1
181.6627,3.7323,8.2617,0.0,0.0,1.8898,4.4273,345.71,349.42,375.04,374.04
182.6627,3.691,8.2645,0.0,0.0,1.8914,4.3788,335.86,336.84,374.15,361.37
183.6627,3.6885,8.2675,0.0,0.0,1.893,4.3765,326.95,325.81,361.76,348.85
184.4715,3.6986,8.2697,0.0,0.0,1.8945,4.3892,320.36,317.83,352.08,339.52
185.4715,3.6846,8.2719,0.0,0.0,1.8958,4.3735,312.51,308.63,340.61,328.3
186.4715,3.7049,8.274,0.0,0.0,1.8971,4.3977,304.95,300.17,329.84,317.92
187.4715,3.7153,8.2757,0.0,0.0,1.898,4.4113,297.57,292.01,319.68,307.82
188.4715,3.7444,8.2777,0.0,0.0,1.8992,4.4442,290.56,284.51,309.9,298.43
189.4715,3.7383,8.2788,0.0,0.0,1.8998,4.4369,283.77,277.01,300.62,289.41
190.4715,3.7814,8.2806,0.0,0.0,1.901,4.4858,277.46,270.32,291.94,280.91
191.4715,3.76,8.2818,0.0,0.0,1.9018,4.4618,271.02,263.57,283.56,272.81
192.4715,3.7519,8.2835,0.0,0.0,1.9026,4.4517,264.73,257.16,275.72,265.23
193.4715,3.7655,8.2855,0.0,0.0,1.904,4.4696,258.59,251.04,268.27,257.81
194.4715,3.7497,8.2875,0.0,0.0,1.9053,4.451,252.83,245.13,265.96,250.79
195.4715,3.7579,8.2893,0.0,0.0,1.9061,4.4601,247.1,239.41,781.45,244.06
196.4715,3.78,8.2903,0.0,0.0,1.907,4.4865,241.61,233.83,7822.9,237.62
197.4715,3.7768,8.2915,0.0,0.0,1.9076,4.4816,236.17,228.51,423.98,231.36
198.4715,3.7597,8.2936,0.0,0.0,1.9088,4.4611,231.01,223.36,264.26,225.32
199.4715,3.7729,8.295,0.0,0.0,1.9097,4.4761,226.03,218.39,238.9,219.59
200.4715,3.7608,8.2969,0.0,0.0,1.9109,4.463,221.25,213.55,224.36,214.14
201.4715,3.7638,8.2991,0.0,0.0,1.9122,4.4666,216.61,209.0,218.57,208.73
202.4715,3.7687,8.3004,0.0,0.0,1.9129,4.4736,212.05,204.65,212.9,203.79
203.4715,3.7708,8.3018,0.0,0.0,1.9138,4.4768,207.5,200.15,207.66,198.83
204.4715,3.7795,8.3037,0.0,0.0,1.915,4.4855,203.2,195.93,202.9,194.23
205.4715,3.7866,8.3057,0.0,0.0,1.9161,4.4935,199.17,191.94,198.03,189.61
206.4715,3.7702,8.3068,0.0,0.0,1.9169,4.474,195.15,188.09,193.72,185.31
207.4715,3.7718,8.3093,0.0,0.0,1.9185,4.4752,191.25,184.31,189.45,181.05
208.4715,3.7853,8.3108,0.0,0.0,1.9191,4.4912,187.56,180.66,185.68,177.06
209.4715,3.7724,8.3126,0.0,0.0,1.9205,4.4767,183.94,177.1,181.84,173.35
210.4715,3.7743,8.3143,0.0,0.0,1.9216,4.4789,180.32,173.73,176.62,169.4
211.4715,3.7848,8.3161,0.0,0.0,1.9224,4.4929,176.88,170.45,172.95,165.75
212.4186,3.7757,8.3178,0.0,0.0,1.9235,4.4807,173.61,167.43,170.52,162.55
213.4186,3.7897,8.3197,0.0,0.0,1.9248,4.4963,170.4,164.26,167.25,159.11
214.4186,3.7746,8.3217,0.0,0.0,1.9259,4.4796,167.35,161.17,164.9,155.84
215.4186,3.8003,8.3232,0.0,0.0,1.9268,4.5103,164.23,158.12,161.98,152.77
216.4186,3.8023,8.3255,0.0,0.0,1.9282,4.5134,161.35,155.3,159.48,149.71
217.3049,3.789,8.3265,0.0,0.0,1.929,4.496,158.81,152.81,157.1,147.1
218.3049,3.799,8.3283,0.0,0.0,1.93,4.5082,156.11,150.12,154.42,144.42
219.3049,3.7925,8.3298,0.0,0.0,1.9311,4.5014,153.41,147.59,151.58,141.56
220.3049,3.7859,8.332,0.0,0.0,1.9322,4.4938,150.71,144.96,147.63,138.82
221.3049,3.7878,8.3338,0.0,0.0,1.9334,4.4952,148.2,142.5,144.82,136.29
222.3049,3.788,8.3353,0.0,0.0,1.9345,4.4953,145.66,140.13,141.42,133.78
223.3049,3.814,8.3371,0.0,0.0,1.9353,4.5257,143.16,137.64,138.39,131.35
224.3049,3.7295,8.3383,0.0,0.0,1.9363,4.4232,140.8,135.39,135.41,129.01
225.3049,3.6903,8.3413,0.0,0.0,1.9382,4.3796,140.74,136.07,135.95,131.72
226.1049,3.674,8.3416,0.0,0.0,1.9384,4.3598,140.69,136.42,136.5,132.25