File: examples/dan-msc-case-studies/CS4/data/01 raw data/hyde_test_030.csv
Time(sec),Force(kN),Jaw(mm),PowAngle(deg),PTemp,Strain,Stress(MPa),TC1(C),TC2(C),TC3(C)
0.0,2.8963,-0.00062156,0.0,0.0024082,-0.00010955,8.802,22.065,22.503,22.054
0.4,2.8373,5.4024e-05,0.0,1.0214,-6.5228e-05,8.6054,22.19,22.654,22.093
0.8,2.8345,-9.2333e-05,0.0,2.221,-7.7139e-05,8.6002,22.281,22.753,22.24
1.2,2.8394,0.00023449,0.0,3.421,-3.761e-05,8.6134,22.157,22.64,22.146
1.6,2.8156,-0.00019266,0.0,4.621,-7.9598e-05,8.539,22.268,22.707,22.167
2.0,2.7989,-0.00014884,0.0,5.821,-6.9229e-05,8.4931,22.098,22.589,22.045
2.4,2.7902,-0.0003461,0.0,7.021,-6.8254e-05,8.4633,22.102,22.606,22.057
2.8,2.7718,-0.00015224,0.0,8.221,-3.5158e-05,8.4094,22.092,22.583,22.034
3.2,2.769,-0.00020153,0.0,9.421,-2.913e-05,8.4014,22.342,22.768,22.253
3.6,2.772,-0.00017672,0.0,10.621,-5.8552e-06,8.4068,22.32,22.729,22.245
4.0,2.7642,-0.00017149,0.0,11.821,-6.7418e-06,8.3875,22.087,22.555,22.054
4.4,2.7641,6.4431e-06,0.0,13.021,2.3476e-05,8.3851,22.125,22.548,22.042
4.8,2.7558,-5.8606e-05,0.0,14.221,2.9343e-05,8.3571,22.322,22.79,22.243
5.2,2.7443,-0.00033476,0.0,15.421,4.6827e-06,8.3283,22.107,22.567,22.045
5.6,2.7582,-0.0002129,0.0,16.621,1.7266e-05,8.3669,22.043,22.563,22.027
6.0,2.7423,-0.00016103,0.0,17.821,3.5076e-05,8.318,22.093,22.563,22.089
6.4,2.7562,-0.00013908,0.0,19.021,5.0195e-05,8.3616,22.215,22.71,22.127
6.8,2.7516,-8.024e-05,0.0,20.221,6.7746e-05,8.3434,22.27,22.776,22.238
7.2,2.7316,-0.00046662,0.0,21.421,2.9045e-05,8.2868,22.145,22.634,22.125
7.6,2.7338,-0.00034458,1.7174,22.621,6.278e-05,8.2956,22.213,22.754,22.204
8.0,2.7373,0.00026127,18.768,23.821,0.00014246,8.3013,22.064,22.697,22.114
8.3495,2.741,0.00093287,25.704,24.876,0.00010008,8.3155,22.315,23.696,22.558
8.7495,2.7482,0.00042938,29.2,26.07,1.6735e-05,8.3377,23.324,26.672,24.38
9.1495,2.7556,-0.00062097,29.361,27.27,-9.7803e-05,8.3628,24.877,34.817,27.074
9.5495,2.773,-0.0011827,27.904,28.47,-0.00017974,8.4109,26.701,37.456,29.821
9.9495,2.768,-0.0014636,24.229,29.67,-0.00021811,8.3969,28.801,37.458,32.234
10.3495,2.7708,-0.0016299,21.906,30.87,-0.00024076,8.4082,30.484,37.458,33.8
10.7495,2.7701,-0.001974,21.348,32.07,-0.00029208,8.4,31.818,37.458,34.522
11.1495,2.7712,-0.0022609,23.241,33.27,-0.00032774,8.4074,32.827,37.458,35.072
11.5495,2.7831,-0.0028385,24.622,34.47,-0.00038238,8.4443,33.873,37.294,35.853
11.9495,2.7806,-0.0028862,25.845,35.67,-0.00038891,8.4331,34.956,38.204,36.83
12.3495,2.7847,-0.0033993,27.698,36.87,-0.00043773,8.4486,35.892,39.48,37.823
12.7495,2.7977,-0.0037621,27.846,38.07,-0.00047921,8.4864,37.27,41.757,39.641
13.1495,2.7916,-0.0042681,27.041,39.27,-0.00052994,8.4686,38.734,43.455,41.405
13.5462,2.7994,-0.0045601,26.194,40.46,-0.00055962,8.494,40.174,44.704,42.932
13.9462,2.7988,-0.0051842,26.605,41.66,-0.00062164,8.4868,41.356,45.558,44.028
14.3462,2.7914,-0.0053659,24.962,42.86,-0.00064983,8.4677,42.831,46.719,45.347
14.7462,2.801,-0.0057468,25.672,44.06,-0.00068421,8.4981,43.958,47.461,46.298
15.1462,2.7875,-0.0062705,27.024,45.26,-0.00073981,8.4532,44.903,48.174,47.037
15.5462,2.7959,-0.0067106,28.013,46.46,-0.00077451,8.4829,45.974,49.621,48.256
15.9462,2.8021,-0.007197,28.141,47.66,-0.00082461,8.501,47.257,51.266,49.711
16.3462,2.796,-0.0078894,26.286,48.86,-0.00087443,8.4815,48.819,52.833,51.364
16.7462,2.8026,-0.0084032,26.365,50.06,-0.00090813,8.5036,50.061,53.639,52.501
17.1462,2.8066,-0.0096068,27.891,51.26,-0.0010155,8.5127,50.999,54.403,53.307
17.5462,2.8012,-0.009885,27.823,52.46,-0.0010367,8.4991,52.217,55.779,54.436
17.9462,2.8046,-0.0099353,27.501,53.66,-0.0010239,8.5092,53.468,57.122,55.765
18.3462,2.8078,-0.0098241,26.532,54.86,-0.001011,8.5171,54.9,58.481,57.223
18.7462,2.8011,-0.010323,27.46,56.06,-0.0010549,8.4971,55.926,59.284,58.118
19.1462,2.8083,-0.010851,27.109,57.26,-0.001105,8.521,57.265,60.65,59.461
19.5462,2.8076,-0.011438,27.879,58.46,-0.0011654,8.5187,58.322,61.604,60.463
19.9462,2.8023,-0.011837,27.397,59.66,-0.0012101,8.506,59.664,62.879,61.77
20.3462,2.813,-0.012082,27.833,60.86,-0.0012319,8.5341,60.684,63.708,62.733
20.7462,2.7933,-0.013047,27.618,62.06,-0.0013331,8.4734,62.04,65.256,64.079
21.1462,2.8071,-0.013131,27.78,63.26,-0.0013366,8.5193,63.232,66.292,65.305
21.5462,2.8036,-0.013636,27.687,64.46,-0.0013955,8.5031,64.424,67.352,66.437
21.9462,2.8014,-0.014106,28.684,65.66,-0.0014448,8.4984,65.409,68.297,67.284
22.3462,2.8099,-0.015116,28.677,66.86,-0.0015504,8.5247,66.65,69.813,68.665
22.7462,2.8141,-0.015813,27.495,68.06,-0.001613,8.5336,68.103,71.213,70.188
23.1462,2.8033,-0.016609,27.632,69.26,-0.001701,8.5068,69.308,72.095,71.237
23.5462,2.8165,-0.016388,27.523,70.46,-0.0016809,8.543,70.456,73.124,72.266
23.9462,2.8137,-0.016579,28.07,71.66,-0.0016918,8.5334,71.612,74.292,73.443
24.3462,2.8046,-0.016979,28.949,72.86,-0.001734,8.5113,72.658,75.503,74.488
24.7462,2.8151,-0.017234,27.862,74.06,-0.0017747,8.5389,74.102,76.977,76.049
25.1462,2.8011,-0.017841,27.566,75.26,-0.0018424,8.496,75.326,77.688,76.981
25.5462,2.8133,-0.018152,28.664,76.46,-0.0018776,8.5365,76.35,78.728,77.931
25.9462,2.8098,-0.018992,28.16,77.66,-0.001981,8.5234,77.708,80.101,79.336
26.3462,2.8038,-0.019419,28.279,78.86,-0.002032,8.506,78.807,80.897,80.264
26.7462,2.8137,-0.019866,28.049,80.06,-0.0020913,8.5382,80.095,82.131,81.512
27.1462,2.8074,-0.020437,29.077,81.26,-0.0021632,8.5152,81.097,82.92,82.403
27.5462,2.8042,-0.021183,28.388,82.46,-0.0022499,8.5088,82.49,84.498,83.779
27.9462,2.8123,-0.021494,28.183,83.66,-0.0022964,8.5325,83.709,85.564,84.956
28.3462,2.7958,-0.022224,29.538,84.86,-0.0023767,8.48,84.673,86.342,85.817
28.7462,2.8089,-0.02307,29.502,86.06,-0.002462,8.5245,85.869,87.841,87.063
29.1462,2.8104,-0.023749,28.001,87.26,-0.0025519,8.5231,87.382,89.157,88.565
29.5462,2.81,-0.024709,28.649,88.46,-0.0026527,8.5239,88.456,89.955,89.496
29.9462,2.8179,-0.024997,29.463,89.66,-0.0026922,8.55,89.523,91.024,90.448
30.3462,2.8192,-0.024856,30.655,90.86,-0.0026781,8.5505,90.503,92.297,91.548
30.7462,2.8101,-0.02516,29.643,92.06,-0.0027005,8.5271,91.969,93.899,93.203
31.1462,2.8066,-0.025511,28.496,93.26,-0.0027435,8.5181,93.409,95.043,94.631
31.5462,2.8111,-0.025946,28.957,94.46,-0.0027944,8.5272,94.531,95.794,95.58
31.9462,2.8099,-0.026587,30.275,95.66,-0.0028769,8.528,95.422,96.586,96.343
32.3462,2.82,-0.027285,30.017,96.86,-0.0029379,8.5557,96.725,98.295,97.721
32.74621,2.806,-0.028154,30.126,98.06,-0.0030386,8.5112,97.899,99.511,99.045
33.14621,2.8081,-0.02848,29.2,99.26,-0.0030738,8.5229,99.328,100.94,100.55
33.54621,2.815,-0.028916,29.692,100.46,-0.0031246,8.5381,100.49,101.81,101.62
33.94621,2.8041,-0.029676,29.772,101.66,-0.0032069,8.5071,101.62,102.86,102.63
34.34621,2.8102,-0.030442,30.281,102.86,-0.0032779,8.527,102.74,104.03,103.76
34.74621,2.8123,-0.031151,30.362,104.06,-0.0033436,8.5313,103.91,105.42,105.09
35.14621,2.8022,-0.032022,30.364,105.26,-0.0034279,8.5045,105.18,106.89,106.47
35.54621,2.8162,-0.032787,29.549,106.46,-0.0035028,8.5435,106.54,107.99,107.86
35.94621,2.8137,-0.034094,29.303,107.66,-0.0036206,8.5349,107.78,109.01,109.0
36.34621,2.8123,-0.034369,29.235,108.86,-0.0036521,8.5331,108.98,109.92,110.04
36.74621,2.8232,-0.03396,29.898,110.06,-0.003608,8.5631,110.01,110.93,110.99
37.14621,2.8091,-0.034411,31.503,111.26,-0.0036324,8.5228,110.92,111.99,111.94
37.54621,2.8072,-0.03494,30.027,112.46,-0.0036896,8.5199,112.45,113.84,113.63
37.94621,2.8075,-0.035504,30.427,113.66,-0.0037397,8.5142,113.58,114.84,114.93
38.34621,2.8112,-0.036385,30.152,114.86,-0.003832,8.5286,114.9,116.19,116.15
38.74621,2.809,-0.036557,29.864,116.06,-0.0038453,8.5225,116.12,117.09,117.3
39.14621,2.8118,-0.037502,30.004,117.26,-0.0039398,8.5271,117.34,118.3,118.43
39.54621,2.8068,-0.038115,29.813,118.46,-0.0039952,8.5174,118.54,119.34,119.58
39.94621,2.8184,-0.03855,30.065,119.66,-0.0040351,8.5501,119.69,120.41,120.65
40.34621,2.8087,-0.039314,30.311,120.86,-0.0041265,8.5183,120.89,121.63,121.86
40.74621,2.8066,-0.039692,30.118,122.06,-0.0041519,8.5155,122.05,122.82,123.03
41.0864,2.8053,-0.040228,30.079,123.08,-0.0042582,8.5126,123.09,123.76,124.09
41.4864,2.817,-0.040692,30.341,124.28,-0.0043099,8.5465,124.27,124.89,125.27
41.8864,2.8101,-0.041589,31.074,125.48,-0.0043972,8.5226,125.3,125.93,126.24
42.2864,2.8139,-0.042569,30.023,126.68,-0.0044985,8.5376,126.76,127.56,127.79
42.6864,2.8198,-0.043427,29.864,127.88,-0.0045878,8.5546,127.99,128.64,129.08
43.0864,2.8134,-0.044901,30.85,129.08,-0.0047464,8.535,128.96,129.4,129.89
43.4864,2.8138,-0.045395,30.005,130.28,-0.0048222,8.5372,130.37,130.96,131.35
43.8864,2.8137,-0.045001,30.175,131.48,-0.0047818,8.5343,131.55,131.77,132.39
44.2531,2.816,-0.044979,30.685,132.58,-0.0047782,8.5427,132.51,132.6,133.21
44.6531,2.8225,-0.045224,31.006,133.78,-0.0048058,8.5613,133.63,133.8,134.42
45.0531,2.8139,-0.046108,31.67,134.98,-0.004899,8.539,134.73,135.27,135.64
45.4531,2.8204,-0.04641,30.265,136.18,-0.0049335,8.5557,136.31,136.76,137.36
45.8531,2.811,-0.047149,30.127,137.38,-0.0050145,8.5241,137.5,137.36,138.39
46.2531,2.8128,-0.047504,30.661,138.58,-0.0050464,8.5385,138.59,138.2,139.14
46.6531,2.8234,-0.048533,32.045,139.78,-0.005159,8.5667,139.44,139.28,140.03
47.0531,2.8104,-0.04916,31.979,140.98,-0.0052343,8.5263,140.73,140.89,141.58
47.4531,2.8163,-0.049701,29.981,142.18,-0.0052907,8.5466,142.38,142.54,143.37
47.8531,2.8137,-0.050158,29.803,143.38,-0.0053452,8.5366,143.6,143.22,144.46
48.2531,2.8127,-0.050638,30.72,144.58,-0.0053924,8.5321,144.6,143.95,145.27
48.6531,2.8168,-0.051372,31.141,145.78,-0.0054814,8.5485,145.65,144.95,146.17
49.0531,2.8095,-0.052449,31.588,146.98,-0.005602,8.5203,146.85,146.4,147.44
49.4531,2.8123,-0.052723,31.522,148.18,-0.0056272,8.5352,148.08,147.77,148.86
49.8531,2.8167,-0.053468,31.213,149.38,-0.0057044,8.546,149.3,148.94,150.12
50.2531,2.8089,-0.054182,31.607,150.58,-0.0057877,8.5204,150.49,150.19,151.25
50.6531,2.8171,-0.054577,30.461,151.78,-0.005832,8.5501,151.92,151.6,152.75
51.0531,2.8177,-0.054974,30.174,152.98,-0.0058782,8.5476,153.18,152.27,153.73
51.4531,2.8121,-0.055496,31.277,154.18,-0.0059261,8.5323,154.12,152.97,154.46
51.8531,2.8159,-0.056443,31.859,155.38,-0.006028,8.5434,155.15,154.24,155.57
52.2531,2.8094,-0.057152,32.106,156.58,-0.006105,8.5222,156.39,155.74,156.98
52.6531,2.8127,-0.057887,31.871,157.78,-0.0061767,8.5345,157.65,157.27,158.46
53.0531,2.817,-0.05874,31.365,158.98,-0.0062583,8.5451,158.99,158.47,159.78
53.4531,2.8148,-0.059501,31.025,160.18,-0.0063453,8.5341,160.24,159.36,160.87
53.8531,2.808,-0.060274,31.639,161.38,-0.0064242,8.52,161.26,160.26,161.8
54.2531,2.8237,-0.061796,32.72,162.58,-0.0065816,8.5655,162.32,161.49,162.86
54.6531,2.8179,-0.062481,31.419,163.78,-0.0066519,8.5494,163.81,163.2,164.55
55.0531,2.8145,-0.06324,31.032,164.98,-0.0067386,8.5431,165.15,164.27,165.86
55.4531,2.8259,-0.064016,31.234,166.18,-0.0068289,8.5715,166.28,165.04,166.74
55.8531,2.8169,-0.065221,32.651,167.38,-0.0069566,8.5456,167.1,165.86,167.52
56.2531,2.8246,-0.065717,31.89,168.58,-0.0070119,8.5701,168.5,167.72,169.06
56.6531,2.8186,-0.06634,31.851,169.78,-0.0070857,8.5491,169.76,168.77,170.45
57.0531,2.816,-0.066717,31.902,170.98,-0.0071338,8.5459,171.01,169.93,171.65
57.4531,2.823,-0.067114,31.882,172.18,-0.0071706,8.5647,172.2,170.95,172.75
57.8531,2.8166,-0.067215,31.835,173.38,-0.0071941,8.5433,173.41,172.06,173.83
58.2531,2.8224,-0.067657,31.882,174.58,-0.0072254,8.5658,174.54,172.98,174.94
58.6531,2.8314,-0.068097,32.567,175.78,-0.0072774,8.5875,175.66,174.14,176.02
59.0531,2.8198,-0.068808,32.507,176.98,-0.007346,8.552,176.86,175.4,177.33
59.4531,2.8255,-0.069033,31.95,178.18,-0.0073779,8.5749,178.17,176.71,178.66
59.8531,2.8285,-0.069458,32.464,179.38,-0.0074155,8.5781,179.32,177.73,179.8
60.2531,2.8214,-0.070103,32.639,180.58,-0.00748,8.5613,180.48,178.87,180.88
60.6531,2.8296,-0.070836,32.55,181.78,-0.0075607,8.5894,181.72,180.21,182.14
61.0531,2.8294,-0.071347,32.592,182.98,-0.0076157,8.5834,182.94,181.25,183.38
61.4531,2.822,-0.072068,32.875,184.18,-0.0076891,8.5635,184.01,182.34,184.38
61.8531,2.8286,-0.072677,32.334,185.38,-0.0077535,8.5814,185.43,183.74,185.85
62.2531,2.823,-0.073464,32.809,186.58,-0.0078409,8.5627,186.5,184.65,186.91
62.6531,2.815,-0.074481,32.343,187.78,-0.0079338,8.5399,187.82,186.12,188.21
63.0531,2.8209,-0.07459,31.369,188.98,-0.007958,8.5557,189.23,187.19,189.62
63.4531,2.8167,-0.075264,31.877,190.18,-0.0080284,8.5453,190.28,187.89,190.45
63.85311,2.8255,-0.076117,32.71,191.38,-0.0081138,8.5756,191.26,188.83,191.38
64.25311,2.8248,-0.076877,33.096,192.58,-0.0082062,8.567,192.41,190.32,192.64
64.65311,2.818,-0.077724,32.87,193.78,-0.0082849,8.5509,193.71,191.8,194.11
65.05311,2.8265,-0.078213,32.449,194.98,-0.0083294,8.5765,195.05,193.02,195.46
65.45311,2.8185,-0.078758,32.402,196.18,-0.0083949,8.5497,196.21,193.87,196.53
65.85311,2.825,-0.079588,33.506,197.38,-0.008472,8.5725,197.19,194.78,197.38
66.25311,2.8244,-0.080362,33.37,198.58,-0.0085453,8.568,198.43,196.33,198.71
66.65311,2.8182,-0.081189,32.034,199.78,-0.0086442,8.547,199.94,197.69,200.37
67.05311,2.8232,-0.081383,32.755,200.98,-0.0086588,8.5683,201.03,198.32,201.22
67.45311,2.8239,-0.082542,33.186,202.18,-0.0087899,8.5651,202.05,199.37,202.2
67.85311,2.8137,-0.083036,32.501,203.38,-0.0088329,8.5367,203.44,200.81,203.57
68.25311,2.8235,-0.083788,32.808,204.58,-0.0089166,8.5667,204.58,201.81,204.7
68.65311,2.8241,-0.084395,33.392,205.78,-0.0089704,8.5654,205.63,202.83,205.72
69.05311,2.8234,-0.08509,33.193,206.98,-0.0090382,8.57,206.92,204.09,207.01
69.45311,2.8322,-0.086018,33.892,208.18,-0.009135,8.5915,207.97,205.29,208.15
69.85311,2.8202,-0.086539,32.317,209.38,-0.0091883,8.5561,209.54,206.75,209.84
70.25311,2.8257,-0.087034,32.463,210.58,-0.0092385,8.5783,210.7,207.62,210.85
70.65311,2.8307,-0.087705,32.872,211.78,-0.0093076,8.5863,211.82,208.45,211.78
71.05311,2.8224,-0.088408,33.29,212.98,-0.0093813,8.5608,212.93,209.44,212.73
71.45311,2.8243,-0.089232,33.625,214.18,-0.0094587,8.5704,214.03,210.61,213.84
71.85311,2.8338,-0.089959,33.393,215.38,-0.0095387,8.595,215.36,212.01,215.17
72.25311,2.8255,-0.090755,33.43,216.58,-0.0096187,8.5741,216.54,213.02,216.39
72.65311,2.8334,-0.091222,33.383,217.78,-0.0096699,8.5975,217.76,214.06,217.53
73.05311,2.8306,-0.091865,33.352,218.98,-0.0097242,8.5852,218.97,214.99,218.52
73.45311,2.8232,-0.092902,33.768,220.18,-0.0098376,8.5692,220.05,216.07,219.59
73.7194,2.8297,-0.093343,33.615,220.98,-0.0097856,8.5845,220.92,216.95,220.38
74.1194,2.8248,-0.094277,33.928,222.18,-0.0098895,8.5729,222.03,217.8,221.44
74.5194,2.8265,-0.094889,33.187,223.38,-0.0099544,8.576,223.46,219.32,222.92
74.8549,2.8329,-0.095265,33.06,224.39,-0.009981,8.5971,224.52,220.0,223.8
75.2549,2.8211,-0.096287,33.539,225.59,-0.010089,8.5557,225.56,220.75,224.63
75.6549,2.8291,-0.096824,34.645,226.79,-0.010153,8.5868,226.47,221.67,225.46
76.0549,2.8355,-0.097585,34.049,227.99,-0.010224,8.6034,227.85,223.5,227.04
76.4549,2.8277,-0.09822,33.52,229.19,-0.010302,8.5783,229.28,224.7,228.51
76.8549,2.8302,-0.098955,33.368,230.39,-0.010372,8.5906,230.53,225.7,229.65
77.2549,2.832,-0.099569,33.627,231.59,-0.010439,8.5916,231.64,226.58,230.66
77.6549,2.826,-0.10032,34.417,232.79,-0.010515,8.5738,232.61,227.53,231.59
78.0549,2.8328,-0.10135,33.646,233.99,-0.010619,8.5969,234.02,229.21,233.18
78.4549,2.8299,-0.10196,33.693,235.19,-0.010685,8.584,235.25,230.35,234.36
78.8549,2.8223,-0.10241,33.771,236.39,-0.010735,8.5637,236.43,231.31,235.47
79.2549,2.8359,-0.10291,33.83,237.59,-0.010796,8.6058,237.57,232.34,236.49
79.6549,2.8308,-0.10396,34.299,238.79,-0.010912,8.5853,238.66,233.37,237.62
80.0549,2.8291,-0.10473,34.503,239.99,-0.010979,8.5851,239.88,234.7,238.9
80.4549,2.832,-0.1054,34.068,241.19,-0.011059,8.5932,241.16,235.96,240.29
80.8549,2.8251,-0.10605,34.075,242.39,-0.01113,8.5698,242.4,236.97,241.38
81.2549,2.8316,-0.10663,34.395,243.59,-0.011181,8.5932,243.52,237.9,242.4
81.6549,2.8303,-0.1076,34.729,244.79,-0.011288,8.5869,244.68,239.08,243.53
82.0549,2.8252,-0.10834,34.65,245.99,-0.011367,8.5693,245.88,240.39,244.81
82.4549,2.8317,-0.10914,33.965,247.19,-0.011442,8.5931,247.23,241.63,246.11
82.8549,2.8238,-0.10988,34.246,248.39,-0.011524,8.5646,248.41,242.58,247.16
83.2549,2.8253,-0.11036,34.472,249.59,-0.011581,8.5728,249.51,243.64,248.23
83.6549,2.8356,-0.11112,34.623,250.79,-0.011664,8.6057,250.69,244.79,249.39
84.0549,2.8319,-0.11243,35.583,251.99,-0.011803,8.5895,251.66,246.0,250.46
84.4549,2.8259,-0.11291,34.216,253.19,-0.01186,8.5764,253.26,247.6,252.24
84.8549,2.8343,-0.1133,33.911,254.39,-0.011905,8.5984,254.51,248.49,253.3
85.2549,2.8225,-0.11432,34.289,255.59,-0.012018,8.5618,255.59,249.43,254.3
85.6549,2.8264,-0.11495,34.652,256.79,-0.012105,8.5775,256.72,250.59,255.38
86.0549,2.828,-0.11585,34.909,257.99,-0.012204,8.5781,257.89,251.85,256.65
86.4549,2.8199,-0.11673,34.681,259.19,-0.01232,8.5574,259.17,253.21,258.03
86.8549,2.8255,-0.11722,34.584,260.39,-0.012384,8.5731,260.41,254.37,259.23
87.2549,2.8278,-0.11799,34.868,261.59,-0.012482,8.5771,261.58,255.37,260.39
87.6549,2.8181,-0.11893,35.186,262.79,-0.012589,8.5512,262.71,256.7,261.59
88.0549,2.8303,-0.11966,34.653,263.99,-0.01267,8.5846,264.0,257.94,262.93
88.4549,2.824,-0.12024,34.47,265.19,-0.012733,8.5653,265.25,258.93,264.06
88.8549,2.8245,-0.12119,34.951,266.39,-0.01283,8.5748,266.35,259.97,265.04
89.2549,2.8288,-0.12176,34.885,267.59,-0.012888,8.582,267.56,261.25,266.31
89.6549,2.8199,-0.12274,34.948,268.79,-0.012983,8.556,268.78,262.47,267.56
90.0549,2.8303,-0.12342,34.98,269.99,-0.01306,8.5906,269.97,263.62,268.8
90.4549,2.8292,-0.1242,34.999,271.19,-0.013129,8.5789,271.18,264.79,269.97
90.8549,2.8225,-0.12489,34.785,272.39,-0.013218,8.565,272.42,265.93,271.19
91.2549,2.8293,-0.1261,34.787,273.59,-0.013354,8.5845,273.63,266.95,272.34
91.6549,2.8286,-0.12724,35.371,274.79,-0.013487,8.5757,274.74,268.01,273.35
92.0549,2.8313,-0.12892,34.988,275.99,-0.013646,8.5904,275.97,269.27,274.68
92.4549,2.8364,-0.13101,35.065,277.19,-0.013857,8.6015,277.18,270.5,275.86
92.8549,2.8293,-0.13169,34.89,278.39,-0.013939,8.5836,278.42,271.57,277.07
93.2549,2.832,-0.1313,35.493,279.59,-0.013907,8.5941,279.55,272.67,278.23
93.6549,2.8418,-0.13053,35.464,280.79,-0.01381,8.6202,280.79,274.06,279.51
94.0549,2.833,-0.13052,34.737,281.99,-0.0138,8.597,282.08,275.24,280.88
94.45491,2.8334,-0.13098,34.717,283.19,-0.013831,8.5977,283.3,276.18,281.98
94.85491,2.8354,-0.1317,35.362,284.39,-0.013886,8.6009,284.35,277.16,282.97
95.25491,2.8304,-0.13288,35.565,285.59,-0.014002,8.5899,285.5,278.43,284.14
95.65491,2.8358,-0.13387,35.497,286.79,-0.014101,8.6018,286.75,279.74,285.45
96.05491,2.8273,-0.13458,34.771,287.99,-0.014172,8.5758,288.07,281.03,286.83
96.45491,2.829,-0.13566,35.196,289.19,-0.014285,8.5853,289.24,282.05,287.94
96.85491,2.835,-0.13648,35.14,290.39,-0.014365,8.599,290.41,283.03,288.99
97.25491,2.8256,-0.13735,35.237,291.59,-0.01446,8.5715,291.62,284.17,290.13
97.65491,2.8255,-0.13805,35.203,292.79,-0.01453,8.5733,292.82,285.34,291.35
98.05491,2.8292,-0.13873,34.917,293.99,-0.01459,8.5811,294.05,286.5,292.39
98.45491,2.8205,-0.13977,35.149,295.19,-0.014703,8.5566,295.21,287.66,293.56
98.85491,2.8304,-0.14056,35.206,296.39,-0.014763,8.5851,296.4,288.81,294.74
99.25491,2.8296,-0.1417,34.676,297.59,-0.014886,8.5782,297.69,289.79,295.84
99.65491,2.8305,-0.14376,34.774,298.79,-0.015089,8.5885,298.88,290.69,296.85
100.05491,2.8382,-0.14562,34.915,299.92,-0.015307,8.6104,300.03,291.75,297.85
100.45491,2.8204,-0.14391,30.709,300.0,-0.015152,8.5553,301.07,291.92,298.55
100.85491,2.7995,-0.14136,29.763,300.0,-0.0149,8.4945,301.05,290.33,297.43
101.25491,2.8091,-0.14071,33.233,300.0,-0.014795,8.5194,300.17,288.86,295.7
101.65491,2.8158,-0.1417,35.175,300.0,-0.014902,8.5401,299.63,289.18,295.4
102.05491,2.8344,-0.14258,34.265,300.0,-0.014964,8.6008,299.9,290.38,296.33
102.45491,2.8304,-0.14249,32.056,300.0,-0.014944,8.5825,300.5,290.76,297.07
102.85491,2.8098,-0.14213,31.5,300.0,-0.014888,8.5239,300.53,290.06,296.75
103.25491,2.8241,-0.14237,32.681,300.0,-0.014896,8.5674,300.18,289.21,295.91
103.65491,2.832,-0.14305,33.748,300.0,-0.014962,8.5874,299.87,289.24,295.61
104.05491,2.8286,-0.14352,33.525,300.0,-0.015009,8.5824,299.96,289.77,296.0
104.45491,2.8354,-0.14399,32.343,300.0,-0.015045,8.6017,300.23,290.08,296.4
104.85491,2.8212,-0.14373,32.582,300.0,-0.015011,8.5544,300.16,289.64,296.18
105.25491,2.8218,-0.14422,32.247,300.0,-0.015038,8.5648,300.2,289.68,296.07
105.65491,2.8308,-0.14404,32.201,300.0,-0.015016,8.5834,300.2,289.57,296.09
106.05491,2.8266,-0.14511,32.78,300.0,-0.015132,8.5716,300.07,289.36,295.88
106.3506,2.8397,-0.1456,32.738,300.0,-0.015309,8.6161,299.98,289.48,295.89
106.7506,2.8446,-0.14701,32.85,300.0,-0.015465,8.6283,300.02,289.64,295.99
107.1506,2.8308,-0.14623,32.226,300.0,-0.015408,8.5876,300.16,289.71,296.11
107.5506,2.831,-0.14465,31.891,300.0,-0.015244,8.5904,300.17,289.58,295.97
107.9506,2.8398,-0.14399,32.765,300.0,-0.015171,8.6119,300.04,289.36,295.76
108.3506,2.8313,-0.14446,32.792,300.0,-0.015213,8.593,300.03,289.53,295.89
108.7506,2.8515,-0.14699,37.83,300.0,-0.015461,8.6504,300.32,290.95,296.62
109.1506,2.832,-0.14779,33.524,300.0,-0.015543,8.5891,301.88,294.07,299.37
109.5506,2.7932,-0.14587,25.822,300.0,-0.015333,8.4757,303.44,293.72,300.48
109.9506,2.7768,-0.14489,27.564,300.0,-0.015228,8.4221,302.84,290.82,298.09
110.3506,2.7776,-0.1458,33.917,300.0,-0.015322,8.4264,301.32,289.41,295.9
110.7506,2.8134,-0.14765,36.073,300.0,-0.015524,8.5377,300.83,290.86,296.34
111.1506,2.8183,-0.14793,33.209,300.0,-0.015555,8.5466,301.7,292.82,298.25
111.5506,2.796,-0.14716,29.141,300.0,-0.015485,8.4818,302.61,292.74,299.02
111.9506,2.7878,-0.14649,29.637,300.0,-0.015404,8.4601,302.39,291.25,297.96
112.3506,2.7931,-0.14678,32.474,300.0,-0.01542,8.4713,301.66,290.3,296.76
112.7506,2.8086,-0.14845,34.151,300.0,-0.015574,8.5215,301.31,290.81,296.67
113.1506,2.8299,-0.14944,32.822,300.0,-0.015652,8.5828,301.74,291.75,297.63
113.5506,2.8055,-0.15009,30.945,300.0,-0.015707,8.5098,302.2,291.85,298.14
113.9506,2.805,-0.14992,30.423,300.0,-0.0157,8.5101,302.19,291.19,297.68
114.3506,2.815,-0.14897,31.851,300.0,-0.015612,8.5366,301.78,290.55,296.97
114.7506,2.8275,-0.1482,32.783,300.0,-0.015491,8.5766,301.58,290.68,296.93
115.1506,2.8392,-0.14791,32.331,300.0,-0.015448,8.6157,301.74,291.15,297.27
115.5506,2.8357,-0.14775,31.607,300.0,-0.015415,8.5992,301.93,291.23,297.51
115.946,2.8275,-0.14771,31.377,300.0,-0.0154,8.5788,301.97,290.94,297.38
116.346,2.8337,-0.14805,32.095,300.0,-0.015444,8.5957,301.79,290.74,297.12
116.746,2.8361,-0.14823,32.396,300.0,-0.015487,8.6025,301.76,290.71,297.1
117.146,2.8384,-0.14836,31.884,300.0,-0.015517,8.6143,301.8,290.78,297.14
117.546,2.8383,-0.14859,32.105,300.0,-0.015547,8.6087,301.83,290.94,297.19
117.946,2.8342,-0.14939,33.559,300.0,-0.015639,8.5983,301.95,291.31,297.44
118.346,2.8455,-0.14976,33.206,300.0,-0.015704,8.6331,302.51,292.23,298.27
118.746,2.8333,-0.14955,31.15,300.0,-0.015689,8.5921,303.08,292.68,298.94
119.146,2.8179,-0.14905,30.173,300.0,-0.01566,8.5491,303.28,292.06,298.64
119.546,2.8163,-0.14901,31.77,300.0,-0.015669,8.5449,302.84,291.27,297.85
119.946,2.8247,-0.14972,33.772,300.0,-0.01577,8.5679,302.57,291.44,297.58
120.346,2.833,-0.1509,34.246,300.0,-0.015901,8.5933,302.85,292.67,298.54
120.746,2.8409,-0.1516,33.127,300.0,-0.015996,8.615,303.7,293.67,299.74
121.146,2.8282,-0.152,31.181,300.0,-0.016028,8.5783,304.49,294.39,300.55
121.546,2.8158,-0.15184,29.528,300.0,-0.016008,8.547,304.74,293.57,300.32
121.946,2.8151,-0.15259,31.717,300.0,-0.01609,8.5374,304.19,292.6,299.23
122.346,2.8336,-0.15255,34.59,300.0,-0.016093,8.5933,303.83,293.0,299.05
122.746,2.8481,-0.15178,33.295,300.0,-0.016002,8.6438,304.28,294.6,300.36
123.146,2.8332,-0.15107,30.534,300.0,-0.015907,8.593,305.08,295.04,301.28
123.546,2.8105,-0.1504,29.632,300.0,-0.015811,8.5292,305.22,294.25,300.87
123.946,2.8107,-0.15055,31.24,300.0,-0.01579,8.5272,304.75,293.25,299.89
124.346,2.8192,-0.15089,33.178,300.0,-0.015809,8.5508,304.29,293.23,299.45
124.746,2.8263,-0.15161,32.872,300.0,-0.015877,8.5742,304.33,293.99,299.93
125.146,2.8348,-0.15172,31.947,300.0,-0.015891,8.5952,304.68,294.48,300.55
125.546,2.8266,-0.15149,30.54,300.0,-0.015878,8.5735,304.95,294.31,300.73
125.946,2.8245,-0.15148,30.972,300.0,-0.015869,8.5689,304.86,293.82,300.25
126.346,2.8264,-0.15168,31.986,300.0,-0.015897,8.5704,304.61,293.53,299.91
126.746,2.8366,-0.15234,32.629,300.0,-0.015974,8.6079,304.59,294.0,300.07
127.146,2.8428,-0.15226,31.892,300.0,-0.015972,8.6244,304.86,294.47,300.66
127.546,2.8255,-0.15208,30.875,300.0,-0.015975,8.5684,305.05,294.4,300.79
127.946,2.8198,-0.1519,30.862,300.0,-0.015995,8.5556,304.98,293.98,300.45
128.346,2.8322,-0.15193,31.862,300.0,-0.01603,8.5916,304.75,293.71,300.02
128.746,2.8379,-0.15247,32.306,300.0,-0.016093,8.6077,304.64,293.98,300.04
129.146,2.8417,-0.15312,32.127,300.0,-0.016157,8.6213,304.75,294.16,300.35
129.546,2.8349,-0.15262,29.583,300.0,-0.016095,8.5951,304.88,294.08,300.39
129.946,2.8205,-0.15343,30.798,300.0,-0.016174,8.5563,304.58,293.22,299.67
130.346,2.8331,-0.15445,31.915,300.0,-0.0163,8.5955,304.05,292.82,299.07
130.746,2.8444,-0.15478,32.975,300.0,-0.016358,8.6257,303.85,293.19,299.23
131.146,2.8435,-0.15392,32.002,300.0,-0.016276,8.6263,304.09,294.01,299.9
131.546,2.8528,-0.15254,30.57,300.0,-0.016097,8.6559,304.43,293.98,300.16
131.946,2.8285,-0.1518,30.161,300.0,-0.016004,8.5751,304.41,293.54,299.95
132.346,2.8279,-0.15135,30.948,300.0,-0.015935,8.5803,304.06,292.76,299.21
132.746,2.825,-0.15168,32.539,300.0,-0.015973,8.5702,303.63,292.6,298.78
133.146,2.8292,-0.15246,32.744,300.0,-0.016053,8.5812,303.56,293.19,299.1
133.546,2.8199,-0.15226,29.858,300.0,-0.016021,8.5586,303.78,293.3,299.51
133.946,2.81,-0.15181,30.121,300.0,-0.015954,8.52,303.66,292.55,298.98
134.346,2.8122,-0.152,31.853,300.0,-0.015963,8.5313,303.21,292.18,298.37
134.746,2.8197,-0.15247,31.89,300.0,-0.016011,8.5589,303.0,292.36,298.46
135.146,2.8167,-0.15254,31.661,300.0,-0.016034,8.543,303.06,292.57,298.65
135.54601,2.8046,-0.15259,30.663,300.0,-0.016041,8.509,303.12,292.66,298.78
135.94601,2.8012,-0.15227,30.467,300.0,-0.015989,8.4985,303.01,292.14,298.43
136.34601,2.7932,-0.15239,31.175,300.0,-0.015983,8.4713,302.64,291.72,297.9
136.74601,2.8005,-0.15269,32.149,300.0,-0.015996,8.4984,302.36,291.59,297.59
137.14601,2.8122,-0.15312,32.56,300.0,-0.016026,8.527,302.33,292.06,297.91
137.54601,2.8099,-0.153,31.224,300.0,-0.016022,8.5245,302.57,292.45,298.45
137.94601,2.8044,-0.15231,29.801,300.0,-0.015927,8.5072,302.68,292.07,298.31
138.34601,2.7932,-0.15225,30.71,300.0,-0.015897,8.4709,302.36,291.33,297.55
138.701,2.8077,-0.15249,32.519,300.0,-0.016002,8.5167,301.98,291.14,297.11
139.101,2.8234,-0.15294,33.114,300.0,-0.016105,8.5601,301.85,291.76,297.53
139.501,2.8213,-0.1531,31.928,300.0,-0.016122,8.5628,302.23,292.34,298.28
139.901,2.8227,-0.15259,30.39,300.0,-0.016068,8.5643,302.59,292.34,298.5
140.301,2.8012,-0.15248,30.452,300.0,-0.016035,8.4943,302.51,291.7,298.04
140.701,2.8175,-0.15344,31.68,300.0,-0.016117,8.5494,302.2,291.42,297.54
141.101,2.8285,-0.15392,32.434,300.0,-0.016159,8.5773,302.06,291.74,297.69
141.501,2.8341,-0.15461,31.43,300.0,-0.016207,8.5988,302.27,292.08,297.99
141.901,2.9263,-0.15462,31.04,300.0,-0.016223,8.8803,302.43,292.06,298.11
142.301,3.0978,-0.15432,30.913,300.0,-0.016201,9.396,302.39,291.79,297.99
142.701,3.225,-0.15332,31.482,300.0,-0.01611,9.7834,302.27,291.52,297.71
143.101,3.3316,-0.15206,31.935,300.0,-0.015961,10.107,302.23,291.66,297.67
143.501,3.3889,-0.15063,31.88,300.0,-0.015794,10.277,302.25,291.86,297.92
143.901,3.423,-0.14993,31.063,300.0,-0.015688,10.387,302.37,292.06,298.07
144.301,3.45,-0.14889,30.881,300.0,-0.015578,10.465,302.37,291.78,297.94
144.701,3.4586,-0.14909,32.097,300.0,-0.015583,10.491,302.23,291.67,297.71
145.101,3.4702,-0.0034135,32.764,300.0,-0.00023618,10.528,302.25,292.07,297.93
145.2861,3.4979,0.0111,14.522,236.25,0.00094623,10.609,302.34,292.49,298.32
145.2881,3.4734,0.0097638,7.7684,0.44961,0.00072823,10.492,302.33,292.49,298.29
145.2901,3.4834,0.0092142,1.0145,0.0008423,0.0015052,10.61,302.32,292.49,298.27
145.2921,3.478,0.010865,0.0,1.5862e-06,0.0013538,10.548,302.31,292.49,298.27
145.2941,3.4711,0.0092451,0.0,2.9715e-09,0.00067705,10.544,302.31,292.49,298.28
145.2961,3.4654,0.0088332,0.0,5.5956e-12,0.00086195,10.535,302.3,292.49,298.28
145.2981,3.458,0.0098579,0.0,1.0536e-14,0.00069272,10.521,302.29,292.49,298.29
145.3001,3.4445,0.0066758,0.0,1.9739e-17,0.0012356,10.474,302.29,292.49,298.29
145.3021,3.4419,0.0094763,0.0,3.7168e-20,0.0012099,10.441,302.34,292.5,298.32
145.3041,3.445,0.010318,0.0,6.963099999999999e-23,0.00080971,10.487,302.4,292.51,298.34
145.3061,3.4325,0.0092111,0.0,1.3111e-25,0.00084978,10.433,302.46,292.53,298.36
145.3081,3.4253,0.0093326,0.0,2.4685999999999997e-28,0.00064501,10.415,302.52,292.54,298.39
145.3101,3.4196,0.0061356,0.0,4.6248e-31,0.0010979,10.391,302.58,292.55,298.41
145.3121,3.4197,0.0090254,0.0,8.7076e-34,0.0012534,10.379,302.59,292.57,298.4
145.3141,3.4173,0.0085052,0.0,1.6394e-36,0.00061254,10.381,302.58,292.6,298.37
145.3161,3.4108,0.0092118,0.0,3.0714e-39,0.00084533,10.345,302.58,292.62,298.35
145.3181,3.418,0.010992,0.0,5.7818e-42,0.00080799,10.37,302.57,292.65,298.32
145.3201,3.4159,0.0069863,0.0,9.8091e-45,0.001286,10.377,302.56,292.67,298.3
145.3221,3.4197,0.0086097,0.0,0.0,0.0011226,10.371,302.53,292.68,298.28
145.3241,3.4154,0.0086601,0.0,0.0,0.00064771,10.365,302.49,292.68,298.27
145.3261,3.4126,0.010254,0.0,0.0,0.00093774,10.347,302.46,292.68,298.26
145.3281,3.409,0.010932,0.0,0.0,0.00074656,10.343,302.42,292.68,298.25
145.3301,3.418,0.0079611,0.0,0.0,0.0012841,10.358,302.38,292.68,298.23
145.3321,3.4234,0.0098588,0.0,0.0,0.0012053,10.358,302.38,292.67,298.25
145.3341,3.4198,0.0087237,0.0,0.0,0.00064375,10.355,302.38,292.65,298.27
145.3361,3.428,0.010896,0.0,0.0,0.0011289,10.385,302.38,292.64,298.29
145.3381,3.441,0.010941,0.0,0.0,0.00074692,10.408,302.38,292.63,298.3
145.3401,3.4568,0.0066123,0.0,0.0,0.001185,10.451,302.38,292.62,298.32
145.3421,3.4736,0.0097795,0.0,0.0,0.0012621,10.507,302.37,292.65,298.34
145.3441,3.4802,0.010041,0.0,0.0,0.00087261,10.568,302.36,292.69,298.35
145.3461,3.4645,0.0093853,0.0,0.0,0.00091282,10.527,302.34,292.74,298.36
145.3481,3.4401,0.011108,0.0,0.0,0.00076587,10.429,302.33,292.78,298.37
145.3501,5.2159,0.026286,0.0,0.0,0.0026873,14.857,302.32,292.82,298.38
145.3521,31.585,0.20272,0.0,0.0,0.021292,95.19,304.08,294.83,298.35
145.35409,42.019,0.57774,0.0,0.0,0.061396,126.81,306.17,297.2,298.31
145.35609,45.409,0.98711,0.0,0.0,0.10808,137.76,308.25,299.56,298.26
145.35809,46.801,1.4074,0.0,0.0,0.15805,142.05,310.34,301.93,298.22
145.36009,47.349,1.8225,0.0,0.0,0.21131,143.6,312.42,304.29,298.18
145.36209,47.773,2.2525,0.0,0.0,0.26753,144.9,316.09,307.94,298.17
145.36409,48.27,2.6905,0.0,0.0,0.32743,146.37,320.03,311.81,298.17
145.36609,48.838,3.1154,0.0,0.0,0.39003,148.08,323.98,315.68,298.17
145.36809,49.455,3.5498,0.0,0.0,0.45744,150.02,327.93,319.55,298.17
145.37009,50.092,3.9791,0.0,0.0,0.52999,151.92,331.88,323.42,298.17
145.37209,50.718,4.4186,0.0,0.0,0.60763,153.82,334.83,326.19,298.23
145.37409,51.256,4.8574,0.0,0.0,0.69041,155.47,337.61,328.76,298.31
145.37609,51.72,5.2898,0.0,0.0,0.77988,156.86,340.38,331.33,298.38
145.37809,51.977,5.7143,0.0,0.0,0.87511,157.64,343.16,333.91,298.46
145.38009,52.082,6.1233,0.0,0.0,0.97796,158.0,345.93,336.48,298.53
145.38209,52.198,6.5192,0.0,0.0,1.085,158.32,347.91,337.88,298.54
145.38409,52.41,6.8795,0.0,0.0,1.1903,158.96,349.75,339.07,298.54
145.38609,52.541,7.203,0.0,0.0,1.2973,159.4,351.59,340.26,298.54
145.38809,52.621,7.4692,0.0,0.0,1.3932,159.61,353.43,341.46,298.54
145.39009,52.552,7.6814,0.0,0.0,1.4807,159.44,355.27,342.65,298.54
145.39209,52.462,7.8482,0.0,0.0,1.5504,159.14,355.4,341.66,298.56
145.39409,52.375,7.9795,0.0,0.0,1.6058,158.91,355.23,340.28,298.57
145.39609,52.357,8.085,0.0,0.0,1.656,158.81,355.05,338.9,298.59
145.39809,48.074,8.1059,0.0,0.0,1.6671,146.21,354.87,337.52,298.61
145.40009,46.174,8.1047,0.0,0.0,1.6705,140.08,354.7,336.14,298.63
145.40209,45.094,8.1114,0.0,0.0,1.6729,136.85,352.85,333.79,298.65
145.40409,44.585,8.1194,0.0,0.0,1.6732,135.27,350.7,331.27,298.68
145.40609,44.159,8.1262,0.0,0.0,1.677,133.98,348.56,328.75,298.7
145.40809,43.47,8.1302,0.0,0.0,1.6781,131.95,346.41,326.23,298.73
145.41009,42.25,8.125,0.0,0.0,1.6814,128.3,344.26,323.71,298.75
145.41209,40.365,8.1275,0.0,0.0,1.6811,122.63,342.62,322.37,298.72
145.41409,37.494,8.128,0.0,0.0,1.6772,114.05,341.07,321.26,298.69
145.41609,31.053,8.1281,0.0,0.0,1.6774,95.283,339.52,320.14,298.65
145.41809,7.8463,8.0698,0.0,0.0,1.6501,25.301,337.97,319.03,298.61
145.42009,2.1929,8.0361,0.0,0.0,1.6377,5.8804,336.42,317.91,298.58
145.42209,2.5377,8.051,0.0,0.0,1.6445,7.7529,335.86,317.75,298.59
145.42409,3.2357,8.0544,0.0,0.0,1.6424,9.7957,335.49,317.77,298.62
145.42609,3.0,8.0492,0.0,0.0,1.6402,9.0949,335.12,317.79,298.64
145.42809,2.832,8.0463,0.0,0.0,1.6384,8.6434,334.75,317.81,298.67
145.43009,2.9822,8.0471,0.0,0.0,1.6437,9.1106,334.38,317.82,298.69
145.43209,2.9824,8.048,0.0,0.0,1.6427,9.0832,334.34,318.04,298.78
145.43409,2.8901,8.0493,0.0,0.0,1.6397,8.8595,334.37,318.29,298.87
145.43609,2.8647,8.0535,0.0,0.0,1.6421,8.725,334.39,318.54,298.97
145.43809,2.9308,8.0484,0.0,0.0,1.6393,8.8964,334.41,318.79,299.07
145.44009,2.9124,8.0431,0.0,0.0,1.6416,8.8642,334.44,319.04,299.17
145.44209,2.8961,8.0502,0.0,0.0,1.6438,8.7723,334.43,319.15,299.24
145.44409,2.9018,8.0491,0.0,0.0,1.6394,8.7875,334.42,319.24,299.31
145.44609,2.9107,8.0486,0.0,0.0,1.6399,8.8328,334.41,319.33,299.38
145.44809,2.8717,8.05,0.0,0.0,1.6401,8.6961,334.4,319.41,299.44
145.45009,2.9006,8.0453,0.0,0.0,1.6428,8.7703,334.38,319.5,299.51
145.45209,2.9388,8.0509,0.0,0.0,1.6442,8.8711,334.37,319.45,299.54
145.45409,2.9537,8.0513,0.0,0.0,1.6404,8.9493,334.36,319.39,299.57
145.45609,2.9743,8.0493,0.0,0.0,1.6395,8.999,334.35,319.32,299.59
145.45809,2.951,8.0502,0.0,0.0,1.6404,8.925,334.34,319.25,299.62
145.46009,2.9373,8.048,0.0,0.0,1.6439,8.8777,334.32,319.18,299.64
145.46209,2.9545,8.0515,0.0,0.0,1.6442,8.936,334.13,319.08,299.68
145.46409,2.9924,8.0516,0.0,0.0,1.6405,9.0464,333.89,318.96,299.71
145.46609,3.027,8.0522,0.0,0.0,1.6415,9.1395,333.66,318.84,299.75
145.46809,3.0361,8.0529,0.0,0.0,1.6421,9.1606,333.43,318.73,299.79
145.47009,3.0773,8.0482,0.0,0.0,1.6439,9.3148,333.2,318.61,299.82
145.47209,3.0837,8.0524,0.0,0.0,1.6445,9.3276,332.96,318.5,299.89
145.47409,3.0283,8.0533,0.0,0.0,1.6416,9.1798,332.71,318.39,299.97
145.47609,3.0517,8.0544,0.0,0.0,1.6422,9.2356,332.47,318.28,300.04
145.47809,3.1171,8.0547,0.0,0.0,1.6424,9.4129,332.23,318.17,300.11
145.48009,3.1032,8.052,0.0,0.0,1.646,9.3773,331.98,318.06,300.19
145.48209,3.1007,8.0537,0.0,0.0,1.6451,9.3995,331.73,317.92,300.26
145.48409,3.1121,8.0533,0.0,0.0,1.6417,9.4039,331.47,317.78,300.32
145.48609,3.107,8.0552,0.0,0.0,1.643,9.3965,331.22,317.64,300.39
145.48809,3.1201,8.0562,0.0,0.0,1.643,9.4291,330.96,317.5,300.46
145.49009,3.1194,8.0512,0.0,0.0,1.6454,9.4539,330.7,317.36,300.53
145.49208,3.1333,8.053,0.0,0.0,1.645,9.517,330.41,317.15,300.57
145.49408,3.1244,8.0568,0.0,0.0,1.6433,9.4597,330.11,316.93,300.62
145.49608,3.1243,8.0572,0.0,0.0,1.6436,9.4786,329.82,316.71,300.66
145.49808,3.1607,8.0525,0.0,0.0,1.641,9.576,329.52,316.49,300.7
145.50008,3.1232,8.0487,0.0,0.0,1.6445,9.4962,329.22,316.27,300.74
145.50208,3.0808,8.0554,0.0,0.0,1.6465,9.3844,328.95,316.01,300.81
145.50408,3.0775,8.0547,0.0,0.0,1.6423,9.3466,328.69,315.74,300.89
145.50608,3.0966,8.0531,0.0,0.0,1.6421,9.4043,328.43,315.47,300.96
145.50808,3.1002,8.0563,0.0,0.0,1.643,9.4248,328.16,315.2,301.03
145.51008,3.1381,8.0539,0.0,0.0,1.647,9.5366,327.9,314.93,301.11
145.51208,3.138,8.0541,0.0,0.0,1.6454,9.5223,327.53,314.7,301.22
145.51408,3.1259,8.0524,0.0,0.0,1.6413,9.4711,327.14,314.46,301.35
145.51608,3.1761,8.0559,0.0,0.0,1.6434,9.6571,326.75,314.23,301.47
145.51808,3.2101,8.0573,0.0,0.0,1.6434,9.7647,326.36,314.0,301.59
145.52008,3.1897,8.0528,0.0,0.0,1.6461,9.7129,325.97,313.77,301.71
145.52208,3.2039,8.0558,0.0,0.0,1.6463,9.7571,325.58,313.53,301.82
145.52408,3.2021,8.0565,0.0,0.0,1.6429,9.7311,325.19,313.29,301.91
145.52608,3.189,8.0569,0.0,0.0,1.6438,9.7328,324.8,313.05,302.01
145.52808,3.1703,8.0584,0.0,0.0,1.6442,9.7151,324.41,312.81,302.11
145.53008,3.1504,8.0523,0.0,0.0,1.6459,9.638,324.02,312.58,302.21
145.53208,3.1585,8.0532,0.0,0.0,1.6449,9.679,323.72,312.35,302.26
145.53408,3.1459,8.055,0.0,0.0,1.6426,9.6243,323.44,312.13,302.29
145.53608,3.1159,8.0568,0.0,0.0,1.6436,9.5464,323.16,311.91,302.33
145.53808,3.1089,8.0555,0.0,0.0,1.6425,9.5418,322.88,311.69,302.37
145.54008,3.0967,8.0501,0.0,0.0,1.6452,9.482,322.6,311.47,302.4
145.54208,3.0828,8.0564,0.0,0.0,1.6467,9.4417,322.22,311.25,302.45
145.54408,3.0736,8.0575,0.0,0.0,1.6438,9.4084,321.83,311.02,302.5
145.54608,3.0632,8.0551,0.0,0.0,1.6429,9.3575,321.43,310.79,302.55
145.54808,3.0525,8.0567,0.0,0.0,1.6432,9.3051,321.04,310.57,302.6
145.55008,3.0598,8.0528,0.0,0.0,1.6463,9.3216,320.64,310.34,302.65
145.55208,3.0531,8.055,0.0,0.0,1.6463,9.2783,320.29,310.06,302.72
145.55408,3.0601,8.0567,0.0,0.0,1.6433,9.2805,319.96,309.76,302.79
145.55608,3.0554,8.0564,0.0,0.0,1.6434,9.2824,319.62,309.47,302.86
145.55808,3.0785,8.0574,0.0,0.0,1.6437,9.3341,319.29,309.18,302.94
145.56008,3.0792,8.0543,0.0,0.0,1.6471,9.3151,318.95,308.88,303.01
145.56208,3.0866,8.0549,0.0,0.0,1.646,9.3443,318.64,308.61,303.08
145.56408,3.1014,8.0579,0.0,0.0,1.6439,9.3518,318.34,308.33,303.15
145.56608,3.1043,8.0575,0.0,0.0,1.6438,9.3659,318.03,308.06,303.21
145.56808,3.1126,8.0584,0.0,0.0,1.644,9.373,317.72,307.78,303.28
145.57008,3.1182,8.0558,0.0,0.0,1.6474,9.3816,317.42,307.51,303.35
145.57208,3.142,8.0564,0.0,0.0,1.6466,9.4686,317.12,307.22,303.41
145.57408,3.1563,8.0565,0.0,0.0,1.643,9.4876,316.83,306.93,303.46
145.57608,3.1701,8.0573,0.0,0.0,1.6444,9.5332,316.54,306.64,303.52
145.57808,3.1966,8.0594,0.0,0.0,1.6446,9.6044,316.24,306.36,303.57
145.58008,3.2081,8.0539,0.0,0.0,1.6462,9.6434,315.95,306.07,303.63
145.58208,3.2213,8.0572,0.0,0.0,1.647,9.6777,315.61,305.8,303.68
145.58408,3.2438,8.0589,0.0,0.0,1.6444,9.7566,315.26,305.54,303.73
145.58608,3.2613,8.0607,0.0,0.0,1.6453,9.8132,314.91,305.28,303.78
145.58808,3.2807,8.0571,0.0,0.0,1.6432,9.8467,314.56,305.01,303.83
145.59008,3.3045,8.0549,0.0,0.0,1.6472,9.9301,314.21,304.75,303.87
145.59208,3.3185,8.0596,0.0,0.0,1.6486,9.9686,313.82,304.52,303.93
145.59408,3.3349,8.0576,0.0,0.0,1.6437,10.027,313.42,304.3,303.98
145.59608,3.3465,8.0556,0.0,0.0,1.6432,10.081,313.01,304.08,304.04
145.59808,3.3616,8.0588,0.0,0.0,1.6444,10.129,312.61,303.86,304.09
145.60008,3.3763,8.0555,0.0,0.0,1.6476,10.183,312.2,303.64,304.15
145.60208,3.3823,8.0587,0.0,0.0,1.6478,10.226,311.98,303.42,304.19
145.60408,3.4054,8.0593,0.0,0.0,1.6446,10.276,311.78,303.2,304.23
145.60608,3.3904,8.0593,0.0,0.0,1.6449,10.247,311.58,302.98,304.26
145.60808,3.4055,8.0599,0.0,0.0,1.6446,10.304,311.39,302.76,304.3
145.61008,3.4136,8.0574,0.0,0.0,1.6482,10.348,311.19,302.54,304.34
145.61208,3.4152,8.0589,0.0,0.0,1.648,10.376,310.96,302.33,304.36
145.61408,3.4152,8.0601,0.0,0.0,1.6448,10.364,310.72,302.13,304.39
145.61608,3.4168,8.0606,0.0,0.0,1.6453,10.355,310.48,301.93,304.41
145.61808,3.4131,8.0598,0.0,0.0,1.645,10.393,310.25,301.72,304.44
145.62008,3.4132,8.0586,0.0,0.0,1.6487,10.37,310.01,301.52,304.46
145.62208,3.3987,8.0604,0.0,0.0,1.6487,10.38,309.66,301.3,304.51
145.62408,3.3935,8.0614,0.0,0.0,1.6455,10.355,309.29,301.07,304.57
145.62608,3.3891,8.0615,0.0,0.0,1.6464,10.363,308.93,300.84,304.62
145.62808,3.3508,8.0619,0.0,0.0,1.6458,10.237,308.56,300.62,304.68
145.63007,3.3406,8.0595,0.0,0.0,1.6495,10.225,308.19,300.39,304.73
145.63207,3.3343,8.0602,0.0,0.0,1.6483,10.193,307.9,300.15,304.78
145.63407,3.2976,8.0613,0.0,0.0,1.6458,10.096,307.63,299.91,304.83
145.63607,3.2999,8.0623,0.0,0.0,1.6462,10.092,307.35,299.67,304.88
145.63807,3.2674,8.0616,0.0,0.0,1.6456,10.025,307.08,299.43,304.93
145.64007,3.2616,8.0579,0.0,0.0,1.6481,9.9931,306.8,299.19,304.98
145.64207,3.2368,8.0598,0.0,0.0,1.6484,9.9245,306.54,298.97,305.02
145.64407,3.2098,8.0607,0.0,0.0,1.6455,9.8297,306.29,298.76,305.07
145.64607,3.2007,8.0616,0.0,0.0,1.6457,9.8079,306.03,298.54,305.12
145.64807,3.1748,8.0617,0.0,0.0,1.6457,9.7135,305.77,298.33,305.17
145.65007,3.1689,8.0583,0.0,0.0,1.6487,9.7128,305.52,298.11,305.22
145.65207,3.1471,8.0591,0.0,0.0,1.6478,9.6031,305.31,297.92,305.27
145.65407,3.1454,8.0596,0.0,0.0,1.6447,9.594,305.11,297.72,305.33
145.65607,3.1304,8.0623,0.0,0.0,1.6462,9.5505,304.92,297.52,305.38
145.65807,3.1283,8.0606,0.0,0.0,1.6451,9.5337,304.72,297.33,305.44
145.66007,3.1182,8.0593,0.0,0.0,1.6489,9.4913,304.53,297.13,305.49
145.66207,3.1149,8.0606,0.0,0.0,1.6487,9.4699,304.37,296.93,305.54
145.66407,3.1166,8.0612,0.0,0.0,1.6452,9.4454,304.22,296.74,305.59
145.66607,3.1143,8.0616,0.0,0.0,1.6457,9.4456,304.08,296.54,305.64
145.66807,3.1102,8.0617,0.0,0.0,1.6457,9.4363,303.93,296.34,305.69
145.67007,3.1191,8.0573,0.0,0.0,1.6486,9.4429,303.78,296.15,305.74
145.67207,3.1241,8.0607,0.0,0.0,1.6485,9.4563,303.57,295.94,305.8
145.67407,3.1317,8.06,0.0,0.0,1.6446,9.4571,303.34,295.73,305.86
145.67607,3.1492,8.0612,0.0,0.0,1.6459,9.5104,303.12,295.52,305.92
145.67807,3.1741,8.0639,0.0,0.0,1.6467,9.5629,302.89,295.31,305.98
145.68007,3.1869,8.0582,0.0,0.0,1.6484,9.5923,302.66,295.1,306.04
145.68207,3.199,8.0587,0.0,0.0,1.6479,9.6527,302.45,294.9,306.08
145.68407,3.217,8.062,0.0,0.0,1.6457,9.687,302.25,294.69,306.12
145.68607,3.2302,8.0624,0.0,0.0,1.6463,9.7303,302.05,294.48,306.16
145.68807,3.2488,8.0614,0.0,0.0,1.6452,9.7502,301.85,294.27,306.2
145.69007,3.2905,8.0597,0.0,0.0,1.6493,9.8877,301.64,294.06,306.23
145.69207,3.3026,8.0614,0.0,0.0,1.6489,9.9096,301.42,293.86,306.24
145.69407,3.311,8.0612,0.0,0.0,1.6454,9.9721,301.18,293.67,306.24
145.69607,3.3446,8.0626,0.0,0.0,1.6462,10.044,300.95,293.47,306.24
145.69807,3.3779,8.0627,0.0,0.0,1.646,10.145,300.72,293.27,306.24
145.70007,3.3891,8.0582,0.0,0.0,1.6484,10.195,300.48,293.08,306.24
145.70207,3.3987,8.0623,0.0,0.0,1.6491,10.221,300.27,292.89,306.26
145.70407,3.4312,8.0628,0.0,0.0,1.6465,10.355,300.06,292.69,306.28
145.70607,3.4255,8.0649,0.0,0.0,1.6473,10.333,299.85,292.5,306.31
145.70807,3.4482,8.0642,0.0,0.0,1.6463,10.382,299.64,292.31,306.33
145.71007,3.4555,8.0599,0.0,0.0,1.6494,10.421,299.43,292.12,306.36
145.71207,3.4664,8.0632,0.0,0.0,1.6499,10.466,299.22,291.94,306.39
145.71407,3.4756,8.0627,0.0,0.0,1.6462,10.49,298.99,291.77,306.43
145.71607,3.4812,8.0646,0.0,0.0,1.6472,10.534,298.77,291.59,306.46
145.71807,3.4824,8.0657,0.0,0.0,1.6472,10.558,298.55,291.41,306.5
145.72007,3.4819,8.0599,0.0,0.0,1.6494,10.554,298.33,291.23,306.54
145.72207,3.4843,8.0633,0.0,0.0,1.6503,10.563,298.13,291.07,306.56
145.72407,3.4804,8.0633,0.0,0.0,1.6465,10.559,297.93,290.92,306.59
145.72607,3.4687,8.0649,0.0,0.0,1.6476,10.539,297.74,290.77,306.61
145.72807,3.466,8.0648,0.0,0.0,1.6467,10.55,297.54,290.61,306.64
145.73007,3.4588,8.0601,0.0,0.0,1.6495,10.521,297.34,290.46,306.66
145.73207,3.4376,8.0619,0.0,0.0,1.6495,10.474,297.19,290.3,306.68
145.73407,3.4255,8.0643,0.0,0.0,1.6473,10.45,297.05,290.14,306.69
145.73607,3.4213,8.0639,0.0,0.0,1.6468,10.43,296.91,289.98,306.7
145.73807,3.4069,8.0647,0.0,0.0,1.6467,10.408,296.77,289.82,306.71
145.74007,3.3939,8.0602,0.0,0.0,1.6493,10.371,296.63,289.66,306.72
145.74207,3.3639,8.0626,0.0,0.0,1.6497,10.312,296.49,289.5,306.77
145.74407,3.3437,8.0642,0.0,0.0,1.6476,10.234,296.35,289.33,306.82
145.74607,3.3267,8.0646,0.0,0.0,1.6474,10.209,296.21,289.17,306.87
145.74807,3.3087,8.0645,0.0,0.0,1.6465,10.137,296.06,289.0,306.91
145.75007,3.3002,8.0607,0.0,0.0,1.65,10.105,295.92,288.83,306.96
145.75207,3.276,8.0625,0.0,0.0,1.6499,10.04,295.77,288.68,307.01
145.75407,3.2629,8.0632,0.0,0.0,1.6463,10.005,295.61,288.54,307.06
145.75607,3.2385,8.065,0.0,0.0,1.6474,9.9234,295.45,288.39,307.11
145.75807,3.2458,8.0647,0.0,0.0,1.6466,9.9221,295.29,288.24,307.16
145.76007,3.2143,8.0616,0.0,0.0,1.6507,9.8218,295.13,288.09,307.21
145.76207,3.2113,8.0646,0.0,0.0,1.6507,9.8242,294.96,287.95,307.22
145.76407,3.2087,8.063,0.0,0.0,1.6464,9.7893,294.79,287.8,307.22
145.76607,3.2007,8.0648,0.0,0.0,1.6473,9.7623,294.61,287.65,307.22
145.76806,3.1837,8.0651,0.0,0.0,1.647,9.6997,294.44,287.5,307.22
145.77006,3.1789,8.0606,0.0,0.0,1.6499,9.652,294.27,287.35,307.22
145.77206,3.1891,8.0645,0.0,0.0,1.6505,9.7092,294.1,287.21,307.22
145.77406,3.1797,8.0654,0.0,0.0,1.6476,9.6511,293.94,287.06,307.22
145.77606,3.1842,8.0649,0.0,0.0,1.647,9.6633,293.77,286.91,307.22
145.77806,3.1846,8.0649,0.0,0.0,1.6471,9.6586,293.61,286.76,307.22
145.78006,3.1937,8.0599,0.0,0.0,1.6492,9.659,293.44,286.61,307.22
145.78206,3.2113,8.0641,0.0,0.0,1.6504,9.7124,293.28,286.46,307.23
145.78406,3.2198,8.0634,0.0,0.0,1.6471,9.7179,293.13,286.31,307.25
145.78606,3.2192,8.0642,0.0,0.0,1.647,9.7191,292.98,286.15,307.27
145.78806,3.2396,8.065,0.0,0.0,1.647,9.7619,292.82,286.0,307.29
145.79006,3.2621,8.0597,0.0,0.0,1.6496,9.8234,292.67,285.84,307.3
145.79206,3.2728,8.0623,0.0,0.0,1.6494,9.8483,292.54,285.69,307.34
145.79406,3.2862,8.0654,0.0,0.0,1.6479,9.8909,292.42,285.55,307.39
145.79606,3.3046,8.0659,0.0,0.0,1.6477,9.9331,292.3,285.4,307.43
145.79806,3.3377,8.0655,0.0,0.0,1.6471,10.027,292.17,285.25,307.47
145.80006,3.3378,8.0611,0.0,0.0,1.6501,10.038,292.05,285.1,307.51
146.00103,3.3321,8.0655,0.0,0.0,1.6492,10.105,283.7,276.39,305.71
146.40103,3.304,8.0675,0.0,0.0,1.65,10.021,269.14,256.13,261.96
146.80103,3.3018,8.0703,0.0,0.0,1.6513,10.015,247.51,231.43,189.55
147.20103,3.306,8.0735,0.0,0.0,1.6529,10.028,226.69,209.18,170.38
147.60103,3.319,8.0777,0.0,0.0,1.6549,10.067,203.12,185.52,149.93
148.00103,3.3221,8.0828,0.0,0.0,1.6573,10.075,161.22,152.77,134.11
148.40103,3.332,8.0903,0.0,0.0,1.6609,10.108,128.14,120.51,98.252
148.6217,3.3383,8.0948,0.0,0.0,1.6637,10.129,114.48,99.295,74.726
149.0217,3.3428,8.1053,0.0,0.0,1.6687,10.135,93.241,82.259,46.451
149.4217,3.331,8.1161,0.0,0.0,1.6739,10.105,75.958,70.14,34.68
149.8217,3.343,8.1235,0.0,0.0,1.6776,10.143,65.446,61.691,29.056
150.2217,3.3119,8.1296,0.0,0.0,1.6806,10.041,57.716,55.605,26.552
150.6217,3.2712,8.1338,0.0,0.0,1.6826,9.9277,51.969,50.137,24.715
151.0217,3.2621,8.1377,0.0,0.0,1.6843,9.8945,47.141,46.367,24.379
151.4217,3.2501,8.141,0.0,0.0,1.6859,9.8558,43.56,43.57,23.513
151.8217,3.2594,8.1442,0.0,0.0,1.6873,9.8925,40.379,40.946,22.566
152.2217,3.2704,8.1469,0.0,0.0,1.6886,9.917,37.68,38.769,21.9
152.6217,3.2592,8.1497,0.0,0.0,1.6899,9.8852,35.503,38.186,21.436
153.0217,3.2689,8.1516,0.0,0.0,1.6908,9.9179,34.164,38.203,21.197
153.4217,3.2721,8.1537,0.0,0.0,1.6917,9.92,32.289,38.203,20.917
153.8217,3.2627,8.1558,0.0,0.0,1.6926,9.8979,31.476,38.203,20.851
154.2217,3.2774,8.1575,0.0,0.0,1.6933,9.9435,29.63,38.21,20.317
154.6217,3.2733,8.1591,0.0,0.0,1.694,9.9248,29.104,37.217,20.557
155.0217,3.2698,8.1605,0.0,0.0,1.6948,9.924,28.521,31.039,20.625
155.4217,3.2853,8.1617,0.0,0.0,1.6955,9.9662,28.182,30.12,20.734
155.8217,3.2748,8.1627,0.0,0.0,1.696,9.9331,28.295,29.925,21.027
156.2217,3.2683,8.1633,0.0,0.0,1.6964,9.9179,29.785,31.206,22.213
156.6217,3.2811,8.164,0.0,0.0,1.6968,9.952,30.759,38.375,23.183
157.0217,3.2636,8.1642,0.0,0.0,1.6971,9.9007,31.492,38.389,24.02
157.4217,3.2708,8.1646,0.0,0.0,1.6974,9.9262,32.26,38.389,24.9
157.8217,3.4135,8.1652,0.0,0.0,1.6979,10.356,32.906,38.389,25.775
158.2217,3.4295,8.1652,0.0,0.0,1.6979,10.405,33.454,38.389,26.688
158.6217,3.2418,8.1664,0.0,0.0,1.6985,9.8326,33.968,38.389,27.484
159.0217,3.2596,8.1672,0.0,0.0,1.6988,9.887,34.388,38.389,28.277
159.4217,3.4522,8.1688,0.0,0.0,1.6997,10.472,34.795,38.389,28.965
159.8217,3.2453,8.1733,0.0,0.0,1.7019,9.8449,35.109,38.389,29.657
160.2217,3.2476,8.1762,0.0,0.0,1.7032,9.8525,35.419,38.389,30.28
160.6217,3.2485,8.1767,0.0,0.0,1.7033,9.8544,35.619,38.389,30.933
161.0217,3.1904,8.1718,0.0,0.0,1.7007,9.6756,35.859,38.389,31.438
161.4217,3.2172,8.1713,0.0,0.0,1.7002,9.7585,36.069,38.389,31.939
161.8217,3.2202,8.1715,0.0,0.0,1.7003,9.7685,36.276,38.389,32.395
162.2217,3.2215,8.1721,0.0,0.0,1.7005,9.7748,36.429,38.389,32.808
162.6217,3.2221,8.1727,0.0,0.0,1.7008,9.7742,36.513,38.306,33.205