File: examples/dan-msc-case-studies/CS4/data/01 raw data/hyde_test_015.csv
Time(sec),Force(kN),Jaw(mm),PowAngle(deg),PTemp,Strain,Stress(MPa),TC1(C),TC2(C),TC3(C),TC4(C)
0.0,1.8687,-2.023,0.0,0.0022065,-0.15757,2.2228,25.758,25.739,25.576,25.532
2.0,1.8214,-0.0023242,0.0,5.8208,-0.00024335,2.1611,25.767,25.748,25.589,25.52
3.9693,1.796,-0.0024393,0.0,11.729,-0.00028101,2.1325,25.747,25.627,25.514,25.424
5.9693,1.7792,-0.002563,0.0,17.729,-0.00030135,2.1125,25.722,25.696,25.561,25.454
7.9693,1.77,-0.0026025,0.0,23.729,-0.0003102,2.1008,25.744,25.692,25.528,25.433
9.9693,1.7749,-0.0020887,32.345,29.729,-0.00025713,2.1066,26.302,26.031,25.548,25.472
11.8233,1.7994,-0.0041468,38.243,35.291,-0.00047564,2.1356,32.56,37.524,25.844,28.116
13.8233,1.8022,-0.0061764,37.988,41.291,-0.00069864,2.1387,40.088,39.385,27.137,34.023
15.8233,1.7965,-0.0080942,37.711,47.291,-0.00091343,2.1326,46.864,46.665,29.732,40.561
17.8233,1.763,-0.010267,38.051,53.291,-0.0011786,2.0921,53.011,53.518,33.278,47.057
19.8233,1.7885,-0.012284,38.865,59.291,-0.0013894,2.1238,58.989,60.452,37.653,53.377
21.8233,1.8035,-0.014742,39.331,65.291,-0.0016613,2.1403,65.016,67.551,42.59,59.864
23.8233,1.8125,-0.017947,40.181,71.291,-0.0020182,2.1511,71.01,74.971,48.188,66.439
25.8233,1.8248,-0.019761,40.569,77.291,-0.0022199,2.1662,77.098,82.44,53.908,73.378
27.8233,1.8299,-0.02284,40.564,83.291,-0.0025455,2.1716,83.206,89.788,59.871,80.366
29.8233,1.8434,-0.02554,40.884,89.291,-0.0028452,2.1886,89.161,96.867,66.359,87.164
31.8233,1.8446,-0.028922,41.162,95.291,-0.0032068,2.1894,95.159,104.11,72.889,94.061
33.8233,1.8488,-0.032361,41.565,101.29,-0.0035952,2.1937,101.17,111.32,79.707,100.99
35.8056,1.8584,-0.035859,41.778,107.24,-0.0040016,2.2065,107.13,118.63,86.527,107.9
37.6333,1.8604,-0.038463,42.036,112.72,-0.0042795,2.2082,112.59,125.12,92.801,114.15
39.6333,1.8611,-0.042605,42.433,118.72,-0.0047446,2.2086,118.55,132.46,99.794,120.92
41.6333,1.8645,-0.046689,42.803,124.72,-0.0051868,2.2134,124.58,139.86,106.7,127.72
43.6333,1.8664,-0.049302,43.287,130.72,-0.0054993,2.2151,130.52,147.29,113.73,134.68
45.6333,1.6561,-0.05625,43.477,136.72,-0.0062662,1.9658,136.57,155.0,120.69,141.61
47.6333,1.367,-0.064451,44.58,142.72,-0.0071765,1.6221,142.26,163.06,127.7,148.51
49.6333,1.2804,-0.071687,45.447,148.72,-0.0079843,1.5185,148.23,172.37,134.87,155.88
51.6333,1.1999,-0.076312,46.568,154.72,-0.0084912,1.424,154.14,182.74,142.27,163.92
53.6333,1.1386,-0.083595,46.906,160.72,-0.009312,1.3516,160.4,193.67,150.17,172.73
55.6333,0.92274,-0.092799,45.914,166.72,-0.010327,1.0951,166.91,203.86,158.53,181.29
57.6333,0.86893,-0.099373,45.039,172.72,-0.011049,1.0309,173.15,212.01,167.07,188.91
59.6333,0.88557,-0.10416,44.263,178.72,-0.011581,1.0513,179.19,218.57,175.13,195.39
61.6333,0.89586,-0.10618,44.295,184.72,-0.01181,1.0638,184.92,224.2,182.51,201.16
63.6333,0.89626,-0.1116,44.797,190.72,-0.012411,1.0636,190.67,230.17,189.41,206.8
65.6333,0.89389,-0.11664,45.44,196.72,-0.012966,1.0609,196.5,237.27,195.89,212.87
67.5379,0.90286,-0.12189,45.607,202.45,-0.013499,1.0715,202.31,244.89,202.1,219.23
69.3663,0.90643,-0.1272,45.121,207.92,-0.014126,1.0759,208.06,252.05,208.09,225.53
71.3663,1.8852,-0.11255,46.087,213.92,-0.012494,2.2378,213.49,259.27,214.68,231.9
73.3663,2.1022,-0.11477,46.864,219.92,-0.012751,2.4964,219.66,270.99,221.27,238.93
75.3663,2.226,-0.11696,45.059,225.92,-0.012995,2.6428,226.5,280.43,228.06,246.61
77.3663,2.2853,-0.12024,43.735,231.92,-0.013331,2.713,232.56,285.85,234.96,252.72
79.3663,2.3053,-0.12145,43.276,237.92,-0.013469,2.7359,238.33,290.18,241.28,257.8
81.3663,2.3158,-0.12654,44.026,243.92,-0.014043,2.7496,243.92,295.26,247.03,262.78
83.3663,2.3165,-0.13129,44.465,249.92,-0.014567,2.7506,249.81,301.6,252.74,268.39
85.3663,2.326,-0.13685,44.536,255.92,-0.015154,2.7614,255.88,308.25,258.44,274.58
87.3663,2.3394,-0.13976,44.271,261.92,-0.015499,2.777,261.98,313.51,264.2,280.93
89.3663,2.345,-0.14528,44.078,267.92,-0.016095,2.7843,268.03,319.17,270.27,287.11
91.3663,2.3552,-0.15084,44.168,273.92,-0.016715,2.7964,273.96,325.43,277.76,292.97
93.3663,2.3685,-0.15604,44.549,279.92,-0.01729,2.8125,279.87,331.91,285.77,299.01
95.3663,2.3842,-0.16107,44.361,285.92,-0.017843,2.8304,285.92,338.69,294.03,305.23
97.3663,2.3958,-0.16572,44.452,291.92,-0.018347,2.8442,291.9,345.24,303.56,311.42
99.3663,2.4078,-0.1709,44.613,297.92,-0.018911,2.8588,297.89,352.06,313.6,317.61
101.1668,2.4155,-0.1756,45.258,303.32,-0.019414,2.8678,303.1,358.42,320.87,323.39
103.1668,2.4258,-0.18032,44.349,309.32,-0.019929,2.8792,309.56,365.34,329.04,330.15
105.1668,2.436,-0.18544,44.489,315.32,-0.020482,2.8923,315.51,371.54,336.15,336.12
107.1668,2.4401,-0.18956,43.675,321.32,-0.02094,2.8972,321.6,376.45,342.42,341.57
109.1668,2.4527,-0.19449,45.295,327.32,-0.021478,2.9123,326.81,381.95,347.88,346.51
111.1668,2.464,-0.19955,45.798,333.32,-0.022033,2.9254,332.86,389.96,354.14,353.01
113.1668,2.4867,-0.20696,52.368,339.32,-0.022864,2.9523,339.87,401.6,361.39,360.32
115.1668,2.4841,-0.22022,47.394,345.32,-0.024315,2.9488,351.33,420.19,374.64,374.51
117.1668,2.4805,-0.22092,44.101,351.32,-0.024373,2.9441,359.24,426.04,385.73,384.45
119.1668,2.485,-0.22719,44.385,357.32,-0.02509,2.9499,365.19,429.31,392.42,389.94
121.1668,2.4849,-0.23451,47.992,363.32,-0.025871,2.9498,371.82,437.82,398.52,395.8
123.1668,2.4892,-0.24217,47.022,369.32,-0.026712,2.9555,380.01,448.89,407.12,404.66
125.1668,2.4906,-0.24766,44.775,375.32,-0.027307,2.9571,387.38,456.43,416.07,413.3
127.1668,2.5003,-0.25594,49.22,381.32,-0.028224,2.9681,394.38,464.83,423.4,420.36
129.1668,2.4968,-0.2622,44.899,387.32,-0.028901,2.964,403.05,475.74,433.59,430.64
131.1668,2.5022,-0.26608,43.684,393.32,-0.029316,2.9708,408.8,479.96,440.56,436.74
133.0026,2.5005,-0.27123,44.994,398.83,-0.029843,2.9688,413.54,484.89,445.12,440.92
135.0026,2.4143,-0.26937,15.577,400.0,-0.029656,2.8655,416.69,482.45,449.03,444.5
137.0026,2.3617,-0.26535,29.77,400.0,-0.029218,2.8034,410.24,461.26,440.46,435.03
139.0026,2.3782,-0.26691,33.372,400.0,-0.029401,2.8246,405.95,453.48,432.28,427.14
141.0026,2.4134,-0.27206,37.392,400.0,-0.029963,2.8649,402.51,449.12,426.77,421.93
143.0026,2.4314,-0.27303,37.01,400.0,-0.030097,2.8863,401.62,449.4,424.77,420.61
145.0026,2.4527,-0.27601,37.863,400.0,-0.030408,2.9118,400.8,448.7,423.65,419.72
147.0026,2.4337,-0.27746,34.972,400.0,-0.030563,2.8891,399.95,446.56,422.8,418.88
149.0026,2.4704,-0.27978,38.855,400.0,-0.030803,2.9331,398.9,444.96,420.63,416.71
151.0026,2.492,-0.282,37.364,400.0,-0.03104,2.958,399.83,446.23,420.63,417.03
153.0026,2.5008,-0.2869,36.665,400.0,-0.031593,2.9689,400.0,445.33,420.59,417.06
155.0026,2.5025,-0.28742,36.474,400.0,-0.031657,2.9704,399.87,443.77,420.07,416.46
157.0026,3.8039,-0.27503,37.408,400.0,-0.030277,4.516,399.57,442.42,419.19,415.72
159.0026,4.2239,-0.26846,38.108,400.0,-0.029568,5.0141,399.63,443.35,418.91,415.59
161.0026,3.1999,-0.27743,36.409,400.0,-0.030523,3.7982,400.08,441.8,418.84,415.59
163.0026,2.4474,-0.28639,35.655,400.0,-0.031483,2.9055,400.04,438.9,417.93,414.58
165.0026,2.4561,-0.28933,35.997,400.0,-0.031811,2.9164,399.87,436.67,416.58,413.28
166.7723,2.1866,-0.29488,35.52,400.0,-0.032422,2.5956,399.96,435.1,415.61,412.41
168.7723,1.4701,-0.30713,34.673,400.0,-0.033778,1.7456,400.06,432.79,414.55,411.44
170.7723,1.0192,-0.31778,34.077,400.0,-0.034931,1.2112,400.04,430.28,413.5,410.46
172.7723,0.81925,-0.32467,34.579,400.0,-0.035656,0.97325,399.83,428.27,412.4,409.43
174.7723,0.76801,-0.32715,34.656,400.0,-0.035916,0.91328,399.82,427.0,411.52,408.66
176.7723,0.77293,-0.32807,34.722,400.0,-0.036051,0.91859,399.77,426.41,411.03,408.14
178.6156,0.73904,0.0094989,0.69267,58.692,0.0014284,0.90412,399.67,426.01,410.41,407.59
178.6166,0.79873,0.0078678,0.0,2.5778e-11,0.0014168,0.94748,399.66,426.01,410.43,407.59
178.6176,0.74517,0.0077205,0.0,5.9485e-25,0.0014056,0.8852,399.64,426.01,410.45,407.6
178.6186,0.79331,0.013369,0.0,1.3727e-38,0.0007834,0.95471,399.63,426.01,410.47,407.6
178.6196,0.74516,-0.0004311,0.0,0.0,0.00091402,0.88525,399.61,426.01,410.5,407.61
178.6206,0.79975,0.011781,0.0,0.0,0.00088527,0.95366,399.6,426.01,410.52,407.61
178.6216,0.73922,0.014884,0.0,0.0,0.0016057,0.88423,399.58,426.01,410.54,407.62
178.6226,0.79003,0.006957,0.0,0.0,0.00076157,0.92044,399.57,426.01,410.56,407.63
178.6236,0.773,0.0077146,0.0,0.0,0.00080303,0.93044,399.55,426.01,410.58,407.63
178.6246,0.78739,0.014735,0.0,0.0,0.0022279,0.94858,399.54,426.01,410.6,407.64
178.6256,0.75061,0.011087,0.0,0.0,0.00033276,0.87709,399.52,426.01,410.62,407.64
178.6266,0.79344,0.0039479,0.0,0.0,0.0013599,0.95455,399.54,426.01,410.61,407.65
178.6276,0.7328,0.0086465,0.0,0.0,0.0010644,0.8814,399.56,426.01,410.6,407.66
178.6286,0.78577,0.01646,0.0,0.0,0.0010653,0.93428,399.59,426.01,410.58,407.66
178.6296,0.73781,-0.0015349,0.0,0.0,0.00041051,0.8682,399.61,426.01,410.57,407.67
178.6306,0.79173,0.011982,0.0,0.0,0.00096911,0.93242,399.63,426.01,410.55,407.67
178.6316,0.73791,0.012349,0.0,0.0,0.0018987,0.86816,399.66,426.01,410.54,407.68
178.6326,0.79255,0.0054794,0.0,0.0,4.7415e-05,0.94054,399.68,426.01,410.52,407.69
178.6336,0.73836,0.0069405,0.0,0.0,0.0011467,0.87615,399.71,426.01,410.51,407.69
178.6346,0.78696,0.0098538,0.0,0.0,0.0015779,0.94655,399.73,426.01,410.49,407.7
178.6356,0.73208,0.013886,0.0,0.0,0.00056519,0.87522,399.75,426.01,410.48,407.7
178.6366,0.7858,-0.0011429,0.0,0.0,0.00086394,0.93335,399.76,426.01,410.48,407.71
178.6376,0.74475,0.011821,0.0,0.0,0.0008748,0.88322,399.76,426.01,410.48,407.71
178.6386,0.79148,0.014734,0.0,0.0,0.001433,0.93242,399.76,426.0,410.48,407.71
178.6396,0.74452,-0.00063062,0.0,0.0,3.4378e-06,0.88233,399.76,426.0,410.49,407.71
178.6406,0.77883,0.012248,0.0,0.0,0.0011792,0.92536,399.76,426.0,410.49,407.71
178.6416,0.7443,0.009348,0.0,0.0,0.0017185,0.87522,399.76,425.99,410.49,407.71
178.6426,0.77856,0.0080842,0.0,0.0,5.2785e-05,0.91736,399.76,425.99,410.5,407.71
178.6436,0.73755,0.0030949,0.0,0.0,0.001131,0.86815,399.76,425.99,410.5,407.71
178.6446,0.77969,0.007048,0.0,0.0,0.00092101,0.93149,399.76,425.98,410.5,407.71
178.6456,0.73288,0.01632,0.0,0.0,0.00099961,0.88326,399.76,425.98,410.5,407.71
178.6466,0.77357,-0.0013618,0.0,0.0,0.00063918,0.93246,399.75,425.97,410.51,407.7
178.6476,0.74405,0.010941,0.0,0.0,0.00064422,0.87522,399.75,425.96,410.51,407.68
178.6486,0.76676,0.012865,0.0,0.0,0.0016806,0.92439,399.74,425.96,410.51,407.67
178.6496,0.73773,0.0046139,0.0,0.0,-0.00012563,0.87425,399.74,425.95,410.51,407.66
178.6506,0.77201,0.0070467,0.0,0.0,0.0013003,0.90928,399.73,425.94,410.51,407.65
178.6516,0.74497,0.0084136,0.0,0.0,0.0014713,0.89016,399.72,425.93,410.51,407.64
178.6526,0.76065,0.013076,0.0,0.0,0.00034652,0.91829,399.72,425.92,410.51,407.62
178.6536,0.73167,-0.0011081,0.0,0.0,0.00087396,0.86812,399.71,425.91,410.51,407.61
178.6546,0.7712,0.011872,0.0,0.0,0.00088435,0.90132,399.71,425.9,410.51,407.6
178.6556,0.74467,0.013867,0.0,0.0,0.001271,0.88229,399.7,425.89,410.51,407.59
178.6566,0.75973,0.00015424,0.0,0.0,9.0745e-05,0.91461,399.71,425.89,410.5,407.59
178.6576,0.73838,0.012183,0.0,0.0,0.0010922,0.88419,399.72,425.9,410.48,407.59
178.6586,0.76001,0.0093842,0.0,0.0,0.0017298,0.91546,399.73,425.9,410.47,407.59
178.6596,0.74404,0.0072543,0.0,0.0,-9.9624e-05,0.87534,399.75,425.9,410.46,407.59
178.6606,0.77726,0.0031364,0.0,0.0,0.0012633,0.90322,399.76,425.91,410.45,407.59
178.6616,0.73135,0.0072236,0.0,0.0,0.0010827,0.86904,399.77,425.91,410.44,407.59
178.6626,0.74678,0.016261,0.0,0.0,0.00092311,0.90035,399.78,425.91,410.42,407.59
178.6636,0.73166,-0.0027931,0.0,0.0,0.00061917,0.86816,399.79,425.91,410.41,407.59
178.6646,0.76621,0.011815,0.0,0.0,0.00082564,0.9155,399.81,425.92,410.4,407.59
178.6656,0.75078,0.01288,0.0,0.0,0.0017371,0.88229,399.82,425.92,410.39,407.59
178.6666,0.75226,0.0026021,0.0,0.0,-0.00013563,0.89421,399.81,425.94,410.38,407.6
178.6676,0.74556,0.0083629,0.0,0.0,0.0013003,0.89118,399.8,425.96,410.37,407.61
178.6686,0.7658,0.0085104,0.0,0.0,0.0015779,0.91021,399.79,425.99,410.37,407.62
178.6696,0.74623,0.012326,0.0,0.0,0.00034648,0.89324,399.77,426.01,410.36,407.63
178.6706,0.78559,-0.00089543,0.0,0.0,0.0011232,0.9344,399.76,426.04,410.36,407.64
178.6716,0.73842,0.011159,0.0,0.0,0.00087353,0.87111,399.75,426.06,410.35,407.66
178.6726,1.2066,0.01616,0.0,0.0,0.0014434,1.4334,399.74,426.08,410.34,407.67
178.6736,0.66556,-0.00034102,0.0,0.0,0.000179,0.80123,399.73,426.11,410.34,407.68
178.6746,0.78513,0.012084,0.0,0.0,0.0010613,0.93044,399.71,426.13,410.33,407.69
178.6756,0.69645,0.0085773,0.0,0.0,0.0015475,0.81392,399.7,426.16,410.33,407.7
178.6766,0.78094,0.011074,0.0,0.0,0.00032092,0.94147,401.25,427.31,410.37,407.7
178.6776,0.6986,-0.0023567,0.0,0.0,0.00066816,0.83175,403.19,428.75,410.43,407.7
178.6786,0.64348,0.0071458,0.0,0.0,0.00094014,0.76065,405.13,430.19,410.48,407.69
178.6796,0.68297,0.011566,0.0,0.0,0.00033953,0.79892,407.06,431.63,410.54,407.68
178.6806,0.62899,-0.006108,0.0,0.0,-7.2478e-05,0.74259,409.0,433.07,410.6,407.68
178.6816,0.70669,0.008473,0.0,0.0,0.00023132,0.85507,410.94,434.51,410.66,407.67
178.6826,0.63754,0.0075022,0.0,0.0,0.0011192,0.76374,412.88,435.94,410.71,407.67
178.6836,0.76964,-0.0014278,0.0,0.0,-0.0007303,0.8982,414.82,437.38,410.77,407.66
178.6846,0.66331,0.0049228,0.0,0.0,0.00062816,0.78676,416.75,438.82,410.83,407.65
178.6856,0.78522,0.0052257,0.0,0.0,0.0010579,0.93153,418.69,440.26,410.89,407.65
178.6866,30.263,0.2202,0.0,0.0,0.022445,34.16,420.64,442.03,410.95,407.63
178.6876,75.346,0.50672,0.0,0.0,0.057635,89.437,422.6,443.89,411.02,407.6
178.6886,78.869,0.82572,0.0,0.0,0.094525,93.357,424.55,445.74,411.08,407.58
178.6896,86.774,1.4182,0.0,0.0,0.16842,102.94,426.5,447.6,411.15,407.55
178.6906,87.289,1.8779,0.0,0.0,0.23098,103.34,428.45,449.45,411.21,407.53
178.6916,89.377,2.38,0.0,0.0,0.29948,106.13,430.41,451.31,411.28,407.51
178.6926,91.802,2.8939,0.0,0.0,0.37966,108.82,432.36,453.16,411.35,407.48
178.6936,91.572,3.4973,0.0,0.0,0.4754,108.7,434.31,455.01,411.41,407.46
178.6946,93.413,3.9691,0.0,0.0,0.56187,110.85,436.27,456.87,411.48,407.43
178.6956,94.107,4.4993,0.0,0.0,0.66314,111.66,438.22,458.72,411.55,407.41
178.6966,94.59,4.9963,0.0,0.0,0.76508,112.26,438.38,459.32,411.52,407.41
178.6976,94.964,5.4134,0.0,0.0,0.86672,112.65,438.1,459.61,411.48,407.43
178.6986,95.214,5.8602,0.0,0.0,0.9749,112.98,437.81,459.89,411.43,407.44
178.6996,95.933,6.2324,0.0,0.0,1.0828,113.83,437.53,460.18,411.39,407.45
178.7006,95.985,6.5467,0.0,0.0,1.1761,113.9,437.24,460.46,411.34,407.46
178.7016,96.43,6.8607,0.0,0.0,1.2821,114.44,436.96,460.74,411.3,407.47
178.7026,96.333,7.1064,0.0,0.0,1.3755,114.32,436.67,461.03,411.25,407.49
178.7036,96.783,7.3378,0.0,0.0,1.4576,114.83,436.39,461.31,411.21,407.5
178.7046,97.298,7.5301,0.0,0.0,1.5511,115.44,436.1,461.6,411.16,407.51
178.7056,98.227,7.727,0.0,0.0,1.6332,116.51,435.82,461.88,411.12,407.52
178.7066,94.584,7.9098,0.0,0.0,1.7274,112.99,435.36,461.67,411.05,407.55
178.7076,85.759,7.9461,0.0,0.0,1.7521,101.83,434.85,461.33,410.98,407.59
178.7086,82.15,7.9376,0.0,0.0,1.7394,97.519,434.35,460.99,410.91,407.63
178.7096,79.282,7.9706,0.0,0.0,1.7685,94.124,433.85,460.65,410.83,407.66
178.7106,77.29,7.9914,0.0,0.0,1.7665,91.778,433.34,460.32,410.76,407.7
178.7116,75.558,7.9789,0.0,0.0,1.7699,89.661,432.84,459.98,410.69,407.74
178.7126,73.912,7.9956,0.0,0.0,1.7779,87.754,432.33,459.64,410.62,407.77
178.7136,72.354,8.012,0.0,0.0,1.7772,85.906,431.83,459.3,410.54,407.81
178.7146,70.74,7.9882,0.0,0.0,1.7781,83.98,431.33,458.96,410.47,407.84
178.7156,69.09,8.0275,0.0,0.0,1.7868,82.035,430.82,458.63,410.4,407.88
178.7166,68.104,8.0187,0.0,0.0,1.7895,80.881,430.37,458.26,410.38,407.87
178.7176,67.158,8.003,0.0,0.0,1.7775,79.69,429.93,457.89,410.38,407.86
178.7186,66.161,8.0219,0.0,0.0,1.7882,78.536,429.49,457.53,410.38,407.84
178.7196,65.416,8.0127,0.0,0.0,1.7908,77.658,429.05,457.16,410.37,407.83
178.7206,64.73,8.0267,0.0,0.0,1.784,76.831,428.61,456.79,410.37,407.81
178.7216,63.893,8.0213,0.0,0.0,1.7965,75.82,428.16,456.42,410.37,407.8
178.7226,63.246,8.0191,0.0,0.0,1.7856,75.064,427.72,456.05,410.36,407.78
178.7236,62.756,8.0355,0.0,0.0,1.7939,74.476,427.28,455.69,410.36,407.77
178.7246,62.162,8.0176,0.0,0.0,1.7909,73.787,426.84,455.32,410.36,407.75
178.7256,61.673,8.0375,0.0,0.0,1.7917,73.208,426.4,454.95,410.36,407.74
178.7266,61.132,8.0322,0.0,0.0,1.8012,72.563,426.01,454.57,410.38,407.74
178.7276,60.69,8.0296,0.0,0.0,1.7876,72.033,425.64,454.19,410.4,407.74
178.7286,60.225,8.0303,0.0,0.0,1.7981,71.486,425.26,453.8,410.43,407.74
178.7296,59.856,8.0327,0.0,0.0,1.7979,71.035,424.88,453.42,410.46,407.74
178.7306,59.377,8.0468,0.0,0.0,1.796,70.472,424.51,453.04,410.48,407.74
178.7316,59.051,8.0208,0.0,0.0,1.7962,70.084,424.13,452.65,410.51,407.74
178.7326,58.652,8.0407,0.0,0.0,1.7944,69.619,423.76,452.27,410.54,407.74
178.7336,58.326,8.0422,0.0,0.0,1.8032,69.209,423.38,451.89,410.57,407.74
178.7346,57.948,8.0272,0.0,0.0,1.7918,68.782,423.01,451.5,410.59,407.74
178.7356,57.696,8.0449,0.0,0.0,1.8004,68.475,422.63,451.12,410.62,407.74
178.7366,57.337,8.0328,0.0,0.0,1.8013,68.058,422.32,450.8,410.63,407.75
178.7376,57.1,8.0437,0.0,0.0,1.7932,67.769,422.03,450.5,410.64,407.76
178.7386,56.763,8.0322,0.0,0.0,1.8025,67.389,421.73,450.2,410.64,407.78
178.7396,56.563,8.0379,0.0,0.0,1.7967,67.121,421.44,449.91,410.65,407.79
178.7406,56.26,8.0478,0.0,0.0,1.8003,66.772,421.14,449.61,410.65,407.81
178.7416,56.035,8.0253,0.0,0.0,1.795,66.49,420.85,449.31,410.66,407.82
178.7426,55.725,8.0476,0.0,0.0,1.7978,66.145,420.55,449.01,410.67,407.84
178.7436,55.535,8.0406,0.0,0.0,1.805,65.903,420.26,448.71,410.67,407.85
178.7446,55.236,8.0387,0.0,0.0,1.7918,65.552,419.97,448.41,410.68,407.87
178.7456,55.047,8.0393,0.0,0.0,1.8021,65.325,419.67,448.11,410.68,407.88
178.7466,54.763,8.0361,0.0,0.0,1.8012,65.004,419.42,447.91,410.65,407.89
178.7476,54.6,8.0507,0.0,0.0,1.7983,64.801,419.18,447.73,410.62,407.89
178.7486,54.316,8.0293,0.0,0.0,1.8008,64.467,418.94,447.55,410.58,407.89
178.7496,54.166,8.0447,0.0,0.0,1.7975,64.279,418.7,447.37,410.54,407.89
178.7506,53.835,8.046,0.0,0.0,1.805,63.901,418.46,447.19,410.5,407.89
178.7516,53.375,8.0328,0.0,0.0,1.7953,63.347,418.22,447.01,410.46,407.89
178.7526,52.498,8.0457,0.0,0.0,1.8013,62.337,417.98,446.83,410.42,407.89
178.7536,51.362,8.0337,0.0,0.0,1.8018,60.986,417.74,446.65,410.38,407.89
178.7546,49.861,8.0399,0.0,0.0,1.7914,59.22,417.5,446.47,410.34,407.89
178.7556,46.723,8.0221,0.0,0.0,1.7969,55.506,417.26,446.29,410.3,407.89
178.7566,43.159,8.0266,0.0,0.0,1.7917,51.198,417.11,446.2,410.26,407.88
178.7576,35.493,8.0223,0.0,0.0,1.7861,42.722,416.98,446.13,410.21,407.87
178.7586,2.8935,7.9024,0.0,0.0,1.7318,4.5043,416.86,446.06,410.16,407.85
178.7596,-0.22426,7.7669,0.0,0.0,1.6555,-0.2635,416.73,445.99,410.11,407.84
178.7606,-0.97969,7.6602,0.0,0.0,1.6119,-1.0568,416.6,445.92,410.06,407.83
178.7616,0.36548,7.5562,0.0,0.0,1.5562,0.33005,416.48,445.85,410.02,407.82
178.7626,-0.81641,7.5234,0.0,0.0,1.5464,-0.98684,416.35,445.78,409.97,407.8
178.7636,0.10101,7.4511,0.0,0.0,1.5164,0.11253,416.22,445.72,409.92,407.79
178.7646,-0.47746,7.4766,0.0,0.0,1.519,-0.5848,416.1,445.65,409.87,407.78
178.7656,-0.39398,7.4294,0.0,0.0,1.5101,-0.40548,415.97,445.58,409.82,407.77
178.7666,-0.01589,7.4563,0.0,0.0,1.5111,-0.030071,415.92,445.54,409.82,407.75
178.7676,-0.37185,7.4946,0.0,0.0,1.5328,-0.43901,415.88,445.5,409.82,407.72
178.7686,0.070639,7.5284,0.0,0.0,1.5454,0.10016,415.85,445.47,409.83,407.7
178.7696,-0.27218,7.6164,0.0,0.0,1.5839,-0.32454,415.81,445.44,409.84,407.67
178.7706,-0.025757,7.7037,0.0,0.0,1.6317,-0.023063,415.77,445.41,409.84,407.65
178.7716,-0.14587,7.8085,0.0,0.0,1.6704,-0.18192,415.74,445.37,409.85,407.63
178.7726,0.29509,7.9218,0.0,0.0,1.7403,0.30541,415.7,445.34,409.85,407.6
178.7736,5.3168,7.9573,0.0,0.0,1.7554,6.7699,415.67,445.31,409.86,407.58
178.7746,-1.7851,7.9227,0.0,0.0,1.7341,-2.1467,415.63,445.27,409.87,407.55
178.7756,0.55384,7.8589,0.0,0.0,1.7078,0.64393,415.59,445.24,409.87,407.53
178.7766,-0.40665,7.8832,0.0,0.0,1.7099,-0.6158,415.57,445.22,409.88,407.54
178.7776,-0.32107,7.9032,0.0,0.0,1.729,-0.32128,415.55,445.2,409.89,407.57
178.7786,3.624,7.9326,0.0,0.0,1.7379,4.0755,415.54,445.18,409.9,407.59
178.7796,0.29398,7.9527,0.0,0.0,1.7557,0.52832,415.52,445.15,409.91,407.62
178.7806,0.16247,7.8824,0.0,0.0,1.7202,0.23254,415.5,445.13,409.92,407.64
178.7816,-0.59529,7.9206,0.0,0.0,1.7284,-0.67468,415.48,445.11,409.93,407.67
178.7826,0.029053,7.9141,0.0,0.0,1.7377,0.040267,415.46,445.09,409.93,407.69
178.7836,2.1951,7.9464,0.0,0.0,1.7437,2.7175,415.45,445.07,409.94,407.71
178.7846,-0.23108,7.9249,0.0,0.0,1.7385,-0.25145,415.43,445.05,409.95,407.74
178.7856,0.27194,7.9121,0.0,0.0,1.7315,0.29385,415.41,445.03,409.96,407.76
178.7866,0.87405,7.9413,0.0,0.0,1.7427,1.0039,415.35,445.05,409.98,407.77
178.7876,0.73665,7.9198,0.0,0.0,1.7411,0.90223,415.29,445.08,410.01,407.78
178.7886,0.23351,7.9232,0.0,0.0,1.7303,0.27031,415.22,445.12,410.03,407.78
178.7896,0.84174,7.9338,0.0,0.0,1.7469,1.0186,415.16,445.15,410.06,407.79
178.7906,0.52809,7.9244,0.0,0.0,1.7378,0.62616,415.09,445.18,410.08,407.8
178.7916,0.46659,7.942,0.0,0.0,1.7414,0.54767,415.02,445.22,410.1,407.8
178.7926,0.75362,7.921,0.0,0.0,1.7405,0.90225,414.96,445.25,410.13,407.81
178.7936,0.41496,7.9307,0.0,0.0,1.7355,0.50139,414.89,445.28,410.15,407.81
178.7946,0.51946,7.9321,0.0,0.0,1.7464,0.60496,414.82,445.31,410.18,407.82
178.7956,0.65362,7.9272,0.0,0.0,1.7355,0.79868,414.76,445.35,410.2,407.83
178.7966,0.41993,7.9251,0.0,0.0,1.7401,0.50351,414.69,445.33,410.24,407.82
178.7976,0.5952,7.9272,0.0,0.0,1.7434,0.69728,414.62,445.31,410.29,407.8
178.7986,0.56231,7.9388,0.0,0.0,1.7366,0.66012,414.55,445.28,410.34,407.79
178.7996,0.51486,7.9154,0.0,0.0,1.7399,0.60581,414.48,445.25,410.39,407.78
178.8006,0.60197,7.9378,0.0,0.0,1.7397,0.70637,414.41,445.22,410.44,407.77
178.8016,0.57173,7.9364,0.0,0.0,1.7441,0.69956,414.34,445.2,410.48,407.76
178.8026,0.50456,7.918,0.0,0.0,1.7363,0.57255,414.28,445.17,410.53,407.74
178.8036,0.65738,7.9407,0.0,0.0,1.7432,0.78583,414.21,445.14,410.58,407.73
178.8046,0.5134,7.9253,0.0,0.0,1.7445,0.60171,414.14,445.12,410.63,407.72
178.8056,0.61639,7.9339,0.0,0.0,1.735,0.73153,414.07,445.09,410.68,407.71
178.8066,0.53022,7.9277,0.0,0.0,1.744,0.64829,414.06,445.04,410.71,407.71
178.8076,0.58322,7.9291,0.0,0.0,1.7403,0.69236,414.08,444.99,410.73,407.71
178.8086,0.54939,7.9391,0.0,0.0,1.7415,0.66521,414.09,444.94,410.76,407.71
178.8096,0.5482,7.9181,0.0,0.0,1.7391,0.63203,414.1,444.89,410.79,407.71
178.8106,0.56775,7.9346,0.0,0.0,1.7379,0.6702,414.11,444.84,410.82,407.71
178.8116,0.58525,7.9304,0.0,0.0,1.7452,0.71229,414.12,444.79,410.84,407.71
178.8126,0.58157,7.9249,0.0,0.0,1.7341,0.6892,414.14,444.74,410.87,407.71
178.8136,0.54401,7.9296,0.0,0.0,1.7417,0.65607,414.15,444.69,410.9,407.71
178.8146,0.64736,7.9234,0.0,0.0,1.7417,0.75147,414.16,444.64,410.92,407.71
178.8156,0.49116,7.9382,0.0,0.0,1.7366,0.60602,414.17,444.59,410.95,407.71
178.8166,0.68128,7.9169,0.0,0.0,1.7406,0.7917,414.18,444.57,411.0,407.69
178.8176,0.48898,7.9325,0.0,0.0,1.7374,0.5861,414.18,444.55,411.05,407.67
178.8186,0.6624,7.9368,0.0,0.0,1.7427,0.77854,414.18,444.54,411.1,407.66
178.8196,0.54796,7.915,0.0,0.0,1.7347,0.63804,414.19,444.53,411.15,407.64
178.8206,0.58313,7.9366,0.0,0.0,1.7401,0.69232,414.19,444.52,411.2,407.62
178.8216,0.56846,7.9252,0.0,0.0,1.7433,0.67426,414.19,444.51,411.25,407.6
178.8226,0.59024,7.9308,0.0,0.0,1.7337,0.70137,414.19,444.49,411.3,407.58
178.8236,0.56905,7.9261,0.0,0.0,1.7435,0.67527,414.2,444.48,411.36,407.57
178.8246,0.61719,7.9253,0.0,0.0,1.7387,0.73848,414.2,444.47,411.41,407.55
178.8256,0.57004,7.9426,0.0,0.0,1.7415,0.68945,414.2,444.46,411.46,407.53
178.8266,0.62882,7.915,0.0,0.0,1.7378,0.73856,414.17,444.45,411.51,407.55
178.8276,0.58861,7.9375,0.0,0.0,1.7388,0.69139,414.13,444.43,411.56,407.58
178.8286,0.63675,7.9312,0.0,0.0,1.7455,0.75561,414.09,444.42,411.61,407.61
178.8296,0.58266,7.9197,0.0,0.0,1.732,0.69224,414.04,444.41,411.66,407.64
178.8306,0.61703,7.9334,0.0,0.0,1.7433,0.73247,414.0,444.4,411.71,407.67
178.8316,0.64484,7.9226,0.0,0.0,1.7409,0.7868,413.96,444.39,411.77,407.7
178.8326,0.63883,7.9329,0.0,0.0,1.7345,0.76988,413.92,444.37,411.82,407.73
178.8336,0.61665,7.9214,0.0,0.0,1.7429,0.73755,413.88,444.36,411.87,407.76
178.8346,0.65821,7.9287,0.0,0.0,1.7358,0.78785,413.83,444.35,411.92,407.79
178.8356,0.57646,7.936,0.0,0.0,1.7427,0.68945,413.79,444.34,411.97,407.82
178.8366,0.69689,7.9196,0.0,0.0,1.7374,0.81899,413.75,444.32,411.99,407.84
178.8376,0.56318,7.9326,0.0,0.0,1.7374,0.67726,413.71,444.31,412.0,407.85
178.8386,0.64378,7.929,0.0,0.0,1.7452,0.77149,413.67,444.29,412.01,407.86
178.8396,0.54212,7.9295,0.0,0.0,1.7335,0.64003,413.62,444.28,412.01,407.87
178.8406,0.71777,7.9251,0.0,0.0,1.7422,0.85601,413.58,444.26,412.02,407.88
178.8416,0.52078,7.9264,0.0,0.0,1.7403,0.6061,413.54,444.25,412.03,407.9
178.8426,0.70228,7.9378,0.0,0.0,1.7388,0.82572,413.5,444.23,412.04,407.91
178.8436,0.5155,7.9152,0.0,0.0,1.7386,0.61491,413.46,444.22,412.05,407.92
178.8446,0.75488,7.9367,0.0,0.0,1.7377,0.92336,413.41,444.2,412.06,407.93
178.8456,0.46035,7.9309,0.0,0.0,1.7442,0.5457,413.37,444.19,412.07,407.94
178.8466,0.80667,7.9231,0.0,0.0,1.7349,0.95754,413.35,444.17,412.05,407.92
178.8476,0.48761,7.9308,0.0,0.0,1.7409,0.57692,413.34,444.15,412.02,407.89
178.8486,0.73323,7.9226,0.0,0.0,1.7413,0.875,413.33,444.14,411.99,407.86
178.8496,0.5268,7.9351,0.0,0.0,1.7351,0.62101,413.32,444.12,411.97,407.83
178.8506,0.73346,7.9176,0.0,0.0,1.7413,0.88211,413.31,444.1,411.94,407.8
178.8516,0.52775,7.9264,0.0,0.0,1.7347,0.62408,413.29,444.08,411.91,407.77
178.8526,0.71104,7.9375,0.0,0.0,1.7431,0.844,413.28,444.06,411.89,407.74
178.8536,0.53656,7.9119,0.0,0.0,1.7331,0.64422,413.27,444.05,411.86,407.71
178.8546,0.70488,7.934,0.0,0.0,1.7378,0.84104,413.26,444.03,411.83,407.68
178.8556,0.49594,7.9269,0.0,0.0,1.745,0.59603,413.25,444.01,411.81,407.65
178.8566,0.83163,7.927,0.0,0.0,1.7319,0.9864,413.23,443.97,411.78,407.66
178.8576,0.44878,7.9243,0.0,0.0,1.7414,0.54171,413.22,443.93,411.75,407.68
178.8586,0.79716,7.9271,0.0,0.0,1.7399,0.94236,413.21,443.88,411.72,407.7
178.8596,0.46221,7.9363,0.0,0.0,1.7381,0.55872,413.2,443.84,411.7,407.71
178.8606,0.75617,7.916,0.0,0.0,1.7392,0.88299,413.19,443.79,411.67,407.73
178.8616,0.46748,7.936,0.0,0.0,1.7374,0.55266,413.17,443.75,411.64,407.75
178.8626,0.73856,7.9308,0.0,0.0,1.7438,0.88203,413.16,443.7,411.62,407.77
178.8636,0.45465,7.9214,0.0,0.0,1.7333,0.54675,413.15,443.66,411.59,407.79
178.8646,0.7743,7.9359,0.0,0.0,1.7429,0.93939,413.14,443.61,411.56,407.8
178.8656,0.52094,7.9213,0.0,0.0,1.7415,0.61702,413.13,443.57,411.53,407.82
178.8666,0.69277,7.9344,0.0,0.0,1.7352,0.83884,413.08,443.52,411.53,407.83
178.8676,0.58155,7.9191,0.0,0.0,1.7416,0.68742,413.04,443.48,411.52,407.83
178.8686,0.69936,7.9284,0.0,0.0,1.7374,0.83383,412.99,443.44,411.52,407.83
178.8696,0.54849,7.9365,0.0,0.0,1.7416,0.65015,412.94,443.4,411.52,407.83
178.8706,0.77743,7.9144,0.0,0.0,1.7349,0.9031,412.89,443.36,411.51,407.83
178.8716,0.54021,7.9337,0.0,0.0,1.7363,0.62608,412.84,443.31,411.51,407.83
178.8726,0.77332,7.929,0.0,0.0,1.745,0.92353,412.8,443.27,411.51,407.83
178.8736,0.56184,7.9237,0.0,0.0,1.7322,0.66254,412.75,443.23,411.51,407.83
178.8746,0.74057,7.9274,0.0,0.0,1.7433,0.89514,412.7,443.19,411.5,407.83
178.8756,0.56207,7.9241,0.0,0.0,1.7387,0.66335,412.65,443.15,411.5,407.83
178.8766,0.73889,7.9362,0.0,0.0,1.7377,0.88004,412.62,443.12,411.5,407.81
178.8776,0.56791,7.9154,0.0,0.0,1.7399,0.67405,412.58,443.09,411.5,407.79
178.8786,0.77341,7.935,0.0,0.0,1.7366,0.92734,412.55,443.07,411.51,407.77
178.8796,0.56665,7.9322,0.0,0.0,1.7442,0.65527,412.52,443.05,411.51,407.75
178.8806,0.7667,7.9194,0.0,0.0,1.7337,0.91845,412.48,443.02,411.51,407.73
178.8816,0.56868,7.9327,0.0,0.0,1.7406,0.67515,412.45,443.0,411.52,407.7
178.8826,0.75371,7.9272,0.0,0.0,1.7432,0.90327,412.42,442.98,411.52,407.68
178.8836,0.57512,7.932,0.0,0.0,1.7334,0.6812,412.38,442.95,411.52,407.66
178.8846,0.76718,7.9213,0.0,0.0,1.7423,0.9185,412.35,442.93,411.53,407.64
178.8856,0.60749,7.9271,0.0,0.0,1.7375,0.71053,412.32,442.9,411.53,407.62
178.8866,0.74752,7.9363,0.0,0.0,1.7403,0.90428,412.3,442.89,411.54,407.61
178.8876,0.61437,7.9152,0.0,0.0,1.7359,0.71954,412.29,442.87,411.55,407.59
178.8886,0.74103,7.9346,0.0,0.0,1.7373,0.89713,412.28,442.86,411.55,407.58
178.8896,0.60866,7.9258,0.0,0.0,1.743,0.71949,412.27,442.84,411.56,407.57
178.8906,0.75395,7.9274,0.0,0.0,1.7333,0.90335,412.25,442.83,411.57,407.56
178.8916,0.61482,7.9254,0.0,0.0,1.7409,0.72664,412.24,442.81,411.58,407.55
178.8926,0.73559,7.925,0.0,0.0,1.7399,0.89815,412.23,442.8,411.59,407.53
178.8936,0.62285,7.9376,0.0,0.0,1.7382,0.74963,412.22,442.78,411.6,407.52
178.8946,0.72068,7.9146,0.0,0.0,1.7394,0.86612,412.21,442.77,411.61,407.51
178.8956,0.6609,7.9322,0.0,0.0,1.7366,0.76667,412.19,442.75,411.62,407.5
178.8966,0.69451,7.9351,0.0,0.0,1.745,0.84919,412.18,442.73,411.63,407.5
178.8976,0.66716,7.9165,0.0,0.0,1.7328,0.76658,412.17,442.72,411.64,407.5
178.8986,0.70749,7.9342,0.0,0.0,1.7413,0.85012,412.17,442.7,411.64,407.5
178.8996,0.65496,7.9234,0.0,0.0,1.7415,0.76666,412.16,442.68,411.65,407.51
178.9006,0.71999,7.9329,0.0,0.0,1.7343,0.86624,412.15,442.66,411.66,407.51
178.9016,0.66089,7.9198,0.0,0.0,1.7417,0.76573,412.14,442.64,411.67,407.51
178.9026,0.68251,7.9271,0.0,0.0,1.7375,0.842,412.13,442.63,411.68,407.52
178.9036,0.66359,7.9355,0.0,0.0,1.74,0.79679,412.12,442.61,411.69,407.52
178.9046,0.6928,7.9155,0.0,0.0,1.7367,0.82787,412.11,442.59,411.7,407.52
178.9056,0.67495,7.9338,0.0,0.0,1.7367,0.78883,412.1,442.57,411.71,407.52
178.9066,0.67358,7.9275,0.0,0.0,1.7445,0.81793,412.07,442.54,411.69,407.54
178.9076,0.6875,7.9235,0.0,0.0,1.7312,0.7997,412.04,442.5,411.66,407.57
178.9086,0.64653,7.9285,0.0,0.0,1.7428,0.77787,412.0,442.46,411.63,407.59
178.9096,0.68223,7.9237,0.0,0.0,1.7398,0.80495,411.96,442.42,411.61,407.62
178.9106,0.62051,7.9368,0.0,0.0,1.7374,0.76175,411.93,442.38,411.58,407.64
178.9116,0.67603,7.9145,0.0,0.0,1.7389,0.79771,411.89,442.34,411.55,407.67
178.9126,0.63247,7.9346,0.0,0.0,1.7379,0.76353,411.86,442.3,411.53,407.69
178.9136,0.68191,7.9298,0.0,0.0,1.7418,0.80288,411.82,442.26,411.5,407.71
178.9146,0.62464,7.9197,0.0,0.0,1.7348,0.74656,411.78,442.23,411.47,407.74
178.9156,0.68913,7.9334,0.0,0.0,1.7407,0.81718,411.75,442.19,411.44,407.76
178.9166,0.61634,7.9221,0.0,0.0,1.7419,0.72761,411.72,442.15,411.41,407.77
178.9176,0.69056,7.9307,0.0,0.0,1.7335,0.82894,411.7,442.12,411.37,407.77
178.9186,0.58421,7.9204,0.0,0.0,1.7418,0.69752,411.67,442.09,411.34,407.77
178.9196,0.70066,7.9248,0.0,0.0,1.7364,0.81295,411.65,442.06,411.3,407.77
178.9206,0.57999,7.9378,0.0,0.0,1.7409,0.71869,411.62,442.03,411.27,407.77
178.9216,0.68853,7.9117,0.0,0.0,1.7353,0.80765,411.6,442.0,411.23,407.77
178.9226,0.57142,7.9345,0.0,0.0,1.7369,0.68924,411.58,441.97,411.19,407.77
178.9236,0.70124,7.9275,0.0,0.0,1.744,0.81764,411.55,441.94,411.16,407.77
178.9246,0.55041,7.9251,0.0,0.0,1.7321,0.65818,411.53,441.91,411.12,407.77
178.9256,0.71568,7.9261,0.0,0.0,1.7412,0.83181,411.5,441.88,411.08,407.77
178.9266,0.5635,7.9229,0.0,0.0,1.7394,0.67134,411.52,441.86,411.09,407.77
178.9276,0.70324,7.9358,0.0,0.0,1.7356,0.83093,411.54,441.85,411.1,407.78
178.9286,0.54553,7.9155,0.0,0.0,1.7401,0.67651,411.56,441.83,411.11,407.78
178.9296,0.70418,7.9308,0.0,0.0,1.736,0.84497,411.58,441.81,411.12,407.79
178.9306,0.55691,7.9334,0.0,0.0,1.7431,0.66944,411.6,441.79,411.14,407.8
178.9316,0.71592,7.9167,0.0,0.0,1.7339,0.84785,411.62,441.77,411.15,407.8
178.9326,0.54447,7.9332,0.0,0.0,1.7402,0.66233,411.64,441.76,411.16,407.81
178.9336,0.72925,7.923,0.0,0.0,1.743,0.84886,411.66,441.74,411.17,407.81
178.9346,0.53537,7.9307,0.0,0.0,1.7332,0.6303,411.68,441.72,411.18,407.82
178.9356,0.74431,7.9211,0.0,0.0,1.7423,0.87826,411.71,441.7,411.2,407.83
178.9366,0.53036,7.9265,0.0,0.0,1.7379,0.63915,411.69,441.68,411.24,407.84
178.9376,0.74359,7.9367,0.0,0.0,1.7397,0.88012,411.66,441.66,411.28,407.85
178.9386,0.53041,7.9134,0.0,0.0,1.7369,0.64706,411.63,441.63,411.33,407.86
178.9396,0.76235,7.9344,0.0,0.0,1.7369,0.88203,411.6,441.61,411.38,407.87
178.9406,0.53791,7.9289,0.0,0.0,1.7444,0.65937,411.56,441.58,411.43,407.88
178.9416,0.75164,7.9231,0.0,0.0,1.7324,0.90331,411.53,441.56,411.48,407.9
178.9426,0.51656,7.9289,0.0,0.0,1.7414,0.62202,411.5,441.54,411.53,407.91
178.9436,0.75703,7.9252,0.0,0.0,1.7408,0.88909,411.47,441.51,411.57,407.92
178.9446,0.53055,7.9345,0.0,0.0,1.7356,0.65037,411.44,441.49,411.62,407.93
178.9456,0.77611,7.9183,0.0,0.0,1.7408,0.90424,411.41,441.46,411.67,407.94
178.9466,0.54151,7.9323,0.0,0.0,1.7361,0.63107,411.36,441.44,411.69,407.94
178.9476,0.75263,7.9341,0.0,0.0,1.7433,0.89823,411.31,441.42,411.71,407.94
178.9486,0.53061,7.9184,0.0,0.0,1.7349,0.65041,411.25,441.39,411.73,407.93
178.9496,0.78387,7.9369,0.0,0.0,1.7416,0.91617,411.19,441.37,411.75,407.92
178.9506,0.54228,7.9252,0.0,0.0,1.7434,0.6452,411.13,441.34,411.77,407.92
178.9516,0.7986,7.9315,0.0,0.0,1.7341,0.9446,411.08,441.32,411.78,407.91
178.9526,0.54845,7.9233,0.0,0.0,1.7428,0.65307,411.02,441.3,411.8,407.91
178.9536,0.79871,7.926,0.0,0.0,1.7387,0.94646,410.96,441.27,411.82,407.9
178.9546,0.54985,7.938,0.0,0.0,1.7392,0.66115,410.91,441.25,411.84,407.89
178.9556,0.79263,7.9164,0.0,0.0,1.738,0.94134,410.85,441.22,411.86,407.89
178.9566,0.55518,7.9339,0.0,0.0,1.7375,0.66017,410.82,441.2,411.85,407.89
178.9576,0.80574,7.9304,0.0,0.0,1.7451,0.95551,410.8,441.18,411.84,407.9
178.9586,0.56021,7.924,0.0,0.0,1.733,0.64605,410.79,441.15,411.83,407.9
178.9596,0.80581,7.9306,0.0,0.0,1.7429,0.95645,410.77,441.13,411.81,407.91
178.9606,0.56073,7.9251,0.0,0.0,1.7402,0.65311,410.75,441.1,411.8,407.92
178.9616,0.80553,7.9382,0.0,0.0,1.7369,0.94845,410.73,441.08,411.79,407.92
178.9626,0.55386,7.9184,0.0,0.0,1.7411,0.64507,410.71,441.06,411.78,407.93
178.9636,0.78787,7.9319,0.0,0.0,1.7377,0.95645,410.7,441.03,411.77,407.93
178.9646,0.56146,7.9355,0.0,0.0,1.7431,0.66017,410.68,441.01,411.75,407.94
178.9656,0.79983,7.9193,0.0,0.0,1.7359,0.9476,410.66,440.98,411.74,407.95
178.9666,0.56739,7.9352,0.0,0.0,1.74,0.66712,410.66,440.95,411.73,407.95
178.9676,0.80542,7.929,0.0,0.0,1.7453,0.9504,410.66,440.91,411.72,407.95
178.9686,0.56862,7.9279,0.0,0.0,1.7326,0.67431,410.66,440.88,411.71,407.95
178.9696,0.79838,7.9255,0.0,0.0,1.7439,0.93525,410.66,440.84,411.71,407.95
178.9706,0.57364,7.9275,0.0,0.0,1.7392,0.66627,410.66,440.81,411.7,407.95
178.9716,0.79343,7.9388,0.0,0.0,1.7395,0.94147,410.66,440.77,411.69,407.95
178.9726,0.57568,7.9157,0.0,0.0,1.7379,0.68133,410.66,440.73,411.68,407.95
178.9736,0.7882,7.9376,0.0,0.0,1.7391,0.95565,410.66,440.7,411.67,407.95
178.9746,0.56874,7.9311,0.0,0.0,1.7451,0.67519,410.66,440.66,411.66,407.95
178.9756,0.76823,7.9241,0.0,0.0,1.7337,0.93449,410.66,440.63,411.65,407.95
178.9766,0.57604,7.9326,0.0,0.0,1.7429,0.6823,410.64,440.6,411.64,407.94
178.9776,0.76902,7.924,0.0,0.0,1.7413,0.94156,410.61,440.58,411.63,407.94
178.9786,0.57486,7.9367,0.0,0.0,1.7362,0.68217,410.59,440.55,411.62,407.94
178.9796,0.78154,7.9216,0.0,0.0,1.7434,0.94342,410.56,440.53,411.61,407.94
178.9806,0.58706,7.9296,0.0,0.0,1.7365,0.68039,410.54,440.5,411.61,407.93
178.9816,0.7729,7.9385,0.0,0.0,1.7446,0.91329,410.52,440.48,411.6,407.93
178.9826,0.56858,7.9157,0.0,0.0,1.7351,0.67227,410.49,440.46,411.59,407.93
178.9836,0.74768,7.9373,0.0,0.0,1.7401,0.90327,410.47,440.43,411.58,407.92
178.9846,0.59954,7.9268,0.0,0.0,1.7441,0.68831,410.44,440.41,411.57,407.92
178.9856,0.74732,7.9308,0.0,0.0,1.7338,0.89815,410.42,440.38,411.56,407.92
178.9866,0.59284,7.9231,0.0,0.0,1.7421,0.6812,410.38,440.37,411.57,407.93
178.9876,0.74637,7.9293,0.0,0.0,1.7408,0.89536,410.34,440.36,411.59,407.94
178.9886,0.60105,7.9371,0.0,0.0,1.7383,0.70426,410.31,440.35,411.61,407.95
178.9896,0.72751,7.916,0.0,0.0,1.739,0.88021,410.27,440.33,411.63,407.96
178.9906,0.60838,7.9344,0.0,0.0,1.7364,0.71851,410.23,440.32,411.65,407.97
178.9916,0.70722,7.9317,0.0,0.0,1.745,0.84911,410.19,440.31,411.66,407.99
178.9926,0.6322,7.9219,0.0,0.0,1.7326,0.71844,410.15,440.3,411.68,408.0
178.9936,0.71939,7.931,0.0,0.0,1.7421,0.85897,410.11,440.29,411.7,408.01
178.9946,0.61508,7.9232,0.0,0.0,1.7409,0.72643,410.07,440.27,411.72,408.02
178.9956,0.70646,7.9374,0.0,0.0,1.7363,0.84302,410.03,440.26,411.74,408.03
178.9966,0.61452,7.9155,0.0,0.0,1.7405,0.72558,410.01,440.23,411.76,408.04
178.9976,0.6866,7.9318,0.0,0.0,1.7375,0.82597,410.0,440.19,411.78,408.04
178.9986,0.64763,7.9367,0.0,0.0,1.7423,0.75151,409.98,440.16,411.81,408.05
178.9996,0.66038,7.9173,0.0,0.0,1.7363,0.80279,409.97,440.12,411.83,408.05
179.0006,0.64714,7.9334,0.0,0.0,1.7385,0.74961,409.95,440.09,411.86,408.05
179.0016,0.65932,7.9267,0.0,0.0,1.7444,0.79581,409.94,440.05,411.88,408.05
179.0026,0.63402,7.928,0.0,0.0,1.7331,0.73438,409.92,440.01,411.9,408.06
179.0036,0.66594,7.9269,0.0,0.0,1.7442,0.80376,409.91,439.98,411.93,408.06
179.0046,0.64734,7.9241,0.0,0.0,1.7395,0.75236,409.89,439.94,411.95,408.06
179.0056,0.6728,7.9394,0.0,0.0,1.7395,0.80799,409.88,439.91,411.98,408.07
179.0066,0.66712,7.9152,0.0,0.0,1.7388,0.76661,409.88,439.87,411.98,408.06
179.0076,0.63943,7.9375,0.0,0.0,1.7381,0.77681,409.88,439.83,411.98,408.06
179.0086,0.67388,7.9316,0.0,0.0,1.7443,0.78354,409.88,439.8,411.98,408.05
179.0096,0.63731,7.9222,0.0,0.0,1.7337,0.74665,409.88,439.76,411.98,408.04
179.0106,0.65576,7.9325,0.0,0.0,1.7424,0.77461,409.89,439.73,411.98,408.04
179.0116,0.6322,7.9228,0.0,0.0,1.7423,0.76175,409.89,439.69,411.98,408.03
179.0126,0.66891,7.9357,0.0,0.0,1.7349,0.78883,409.89,439.65,411.98,408.03
179.0136,0.61894,7.9207,0.0,0.0,1.7425,0.74669,409.9,439.62,411.98,408.02
179.0146,0.68224,7.9295,0.0,0.0,1.7361,0.81189,409.9,439.58,411.98,408.01
179.0156,0.61177,7.939,0.0,0.0,1.7432,0.73747,409.9,439.55,411.98,408.01
179.0166,0.70162,7.9158,0.0,0.0,1.7353,0.8148,409.88,439.54,411.97,408.0
179.0176,0.604,7.9372,0.0,0.0,1.7395,0.72059,409.86,439.53,411.96,407.99
179.0186,0.69685,7.9268,0.0,0.0,1.7443,0.82898,409.84,439.53,411.96,407.97
179.0196,0.60447,7.9287,0.0,0.0,1.7332,0.72156,409.81,439.53,411.95,407.96
179.0206,0.70337,7.9267,0.0,0.0,1.7433,0.82898,409.79,439.53,411.94,407.95
179.0216,0.59212,7.9263,0.0,0.0,1.74,0.71352,409.76,439.52,411.93,407.94
179.0226,0.70812,7.9377,0.0,0.0,1.7384,0.81682,409.74,439.52,411.92,407.93
179.0236,0.5904,7.9177,0.0,0.0,1.7408,0.6974,409.72,439.52,411.91,407.91
179.0246,0.73139,7.9345,0.0,0.0,1.737,0.87809,409.69,439.51,411.9,407.9
179.0256,0.57762,7.933,0.0,0.0,1.7443,0.69643,409.67,439.51,411.89,407.89
179.0266,0.7503,7.9222,0.0,0.0,1.7341,0.88706,409.63,439.49,411.9,407.89
179.0276,0.58547,7.9329,0.0,0.0,1.7413,0.71162,409.6,439.47,411.91,407.9
179.0286,0.74899,7.925,0.0,0.0,1.7428,0.87115,409.56,439.44,411.92,407.9
179.0296,0.58416,7.9345,0.0,0.0,1.7353,0.69644,409.53,439.42,411.92,407.91
179.0306,0.76276,7.919,0.0,0.0,1.7411,0.88816,409.49,439.39,411.93,407.92
179.0316,0.58338,7.9292,0.0,0.0,1.7378,0.69736,409.45,439.37,411.94,407.92
179.0326,0.77656,7.9364,0.0,0.0,1.7412,0.91122,409.42,439.35,411.95,407.93
179.0336,0.57079,7.9152,0.0,0.0,1.7358,0.68637,409.38,439.32,411.96,407.93
179.0346,0.77685,7.9362,0.0,0.0,1.7387,0.91219,409.34,439.3,411.97,407.94
179.0356,0.56386,7.9276,0.0,0.0,1.7447,0.6793,409.31,439.27,411.98,407.95
179.0366,0.77832,7.9272,0.0,0.0,1.7323,0.92543,409.29,439.24,412.0,407.96
179.0376,0.57708,7.9287,0.0,0.0,1.7429,0.6875,409.28,439.2,412.02,407.97
179.0386,0.78424,7.9258,0.0,0.0,1.7407,0.9292,409.27,439.16,412.04,407.98
179.0396,0.57762,7.9384,0.0,0.0,1.7385,0.69631,409.26,439.12,412.06,407.99
179.0406,0.80924,7.9177,0.0,0.0,1.7407,0.93131,409.24,439.08,412.08,408.0
179.0416,0.5575,7.9353,0.0,0.0,1.7378,0.6774,409.23,439.04,412.1,408.02
179.0426,0.79886,7.9337,0.0,0.0,1.7442,0.95243,409.22,439.0,412.12,408.03
179.0436,0.58217,7.921,0.0,0.0,1.7345,0.68725,409.21,438.97,412.14,408.04
179.0446,0.79322,7.9352,0.0,0.0,1.7425,0.94549,409.2,438.93,412.17,408.05
179.0456,0.58306,7.9244,0.0,0.0,1.7432,0.69343,409.18,438.89,412.19,408.06
179.0466,0.81711,7.9351,0.0,0.0,1.7349,0.94646,409.18,438.87,412.2,408.06
179.0476,0.5692,7.9215,0.0,0.0,1.7432,0.67121,409.18,438.86,412.21,408.06
179.0486,0.82556,7.9284,0.0,0.0,1.7371,0.98272,409.18,438.85,412.22,408.05
179.0496,0.57089,7.9396,0.0,0.0,1.7433,0.69246,409.18,438.83,412.23,408.04
179.0506,0.82366,7.9161,0.0,0.0,1.7363,0.96347,409.18,438.82,412.23,408.04
179.0516,0.56913,7.9369,0.0,0.0,1.7384,0.67723,409.18,438.81,412.24,408.03
179.0526,0.81782,7.9307,0.0,0.0,1.7462,0.95551,409.18,438.8,412.25,408.03
179.0536,0.55767,7.9266,0.0,0.0,1.7328,0.67638,409.18,438.79,412.26,408.02
179.0546,0.81239,7.9309,0.0,0.0,1.7441,0.96068,409.18,438.77,412.27,408.01
179.0556,0.56257,7.9244,0.0,0.0,1.7399,0.66927,409.18,438.76,412.28,408.01
179.0566,0.79896,7.9391,0.0,0.0,1.7386,0.94828,409.15,438.74,412.29,408.01
179.0576,0.55763,7.917,0.0,0.0,1.7406,0.67532,409.12,438.71,412.29,408.02
179.0586,0.81253,7.9374,0.0,0.0,1.7379,0.96355,409.09,438.68,412.3,408.02
179.0596,0.56867,7.933,0.0,0.0,1.7441,0.67431,409.06,438.65,412.3,408.03
179.0606,0.80128,7.9211,0.0,0.0,1.7352,0.96545,409.02,438.62,412.31,408.04
179.0616,0.55474,7.9343,0.0,0.0,1.7418,0.64418,408.99,438.59,412.32,408.04
179.0626,0.79926,7.9252,0.0,0.0,1.7435,0.94663,408.96,438.56,412.32,408.05
179.0636,0.56302,7.9336,0.0,0.0,1.7343,0.67528,408.92,438.53,412.33,408.05
179.0646,0.79302,7.9245,0.0,0.0,1.7445,0.93948,408.89,438.5,412.33,408.06
179.0656,0.55547,7.9248,0.0,0.0,1.7367,0.6672,408.86,438.47,412.34,408.07
179.0666,0.79216,7.9407,0.0,0.0,1.7424,0.93339,408.81,438.43,412.34,408.07
179.0676,0.56007,7.9163,0.0,0.0,1.7372,0.64406,408.77,438.4,412.33,408.07
179.0686,0.79294,7.9353,0.0,0.0,1.7377,0.9424,408.72,438.36,412.32,408.07
179.0696,0.54781,7.9298,0.0,0.0,1.7453,0.64934,408.68,438.32,412.32,408.07
179.0706,0.78031,7.9267,0.0,0.0,1.7329,0.93335,408.63,438.29,412.31,408.07
179.0716,0.56739,7.927,0.0,0.0,1.7421,0.6592,408.59,438.25,412.31,408.07
179.0726,0.77337,7.9267,0.0,0.0,1.7415,0.92547,408.54,438.22,412.3,408.07
179.0736,0.56727,7.939,0.0,0.0,1.7375,0.66525,408.5,438.18,412.29,408.07
179.0746,0.77314,7.9185,0.0,0.0,1.7417,0.9193,408.45,438.14,412.29,408.07
179.0756,0.56645,7.9336,0.0,0.0,1.7364,0.65298,408.41,438.11,412.28,408.07
179.0766,0.77939,7.9345,0.0,0.0,1.745,0.92641,408.39,438.09,412.28,408.07
179.0776,0.56193,7.9211,0.0,0.0,1.7353,0.67232,408.38,438.07,412.28,408.08
179.0786,0.75319,7.9348,0.0,0.0,1.7407,0.8962,408.36,438.05,412.27,408.08
179.0796,0.56946,7.9244,0.0,0.0,1.7431,0.68128,408.35,438.03,412.27,408.09
179.0806,0.76047,7.9345,0.0,0.0,1.7351,0.91227,408.34,438.01,412.27,408.1
179.0816,0.56908,7.9212,0.0,0.0,1.7421,0.67934,408.33,438.0,412.26,408.1
179.0826,0.74668,7.9295,0.0,0.0,1.7388,0.88821,408.32,437.98,412.26,408.11
179.0836,0.58289,7.9383,0.0,0.0,1.7401,0.70337,408.3,437.96,412.26,408.11
179.0846,0.73278,7.9163,0.0,0.0,1.7374,0.86794,408.29,437.94,412.25,408.12
179.0856,0.607,7.9367,0.0,0.0,1.7382,0.70252,408.28,437.92,412.25,408.13
179.0866,0.73373,7.9298,0.0,0.0,1.7456,0.88122,408.27,437.9,412.26,408.14
179.0876,0.60025,7.9253,0.0,0.0,1.7329,0.70244,408.25,437.87,412.26,408.16
179.0886,0.7578,7.9305,0.0,0.0,1.7425,0.89015,408.24,437.84,412.27,408.18
179.0896,0.59478,7.9252,0.0,0.0,1.7407,0.70253,408.22,437.82,412.27,408.2
179.0906,0.72694,7.9397,0.0,0.0,1.738,0.87306,408.21,437.79,412.28,408.21
179.0916,0.62772,7.9168,0.0,0.0,1.7404,0.72939,408.19,437.76,412.29,408.23
179.0926,0.70603,7.937,0.0,0.0,1.7392,0.84112,408.18,437.74,412.29,408.25
179.0936,0.63593,7.932,0.0,0.0,1.743,0.75579,408.16,437.71,412.3,408.27
179.0946,0.708,7.9191,0.0,0.0,1.7352,0.86608,408.15,437.68,412.3,408.29
179.0956,0.64063,7.9361,0.0,0.0,1.7407,0.74348,408.13,437.66,412.31,408.3
179.0966,0.70842,7.9267,0.0,0.0,1.7441,0.86329,408.1,437.62,412.3,408.3
179.0976,0.63544,7.9299,0.0,0.0,1.7332,0.74958,408.07,437.59,412.29,408.3
179.0986,0.70079,7.9271,0.0,0.0,1.7449,0.85008,408.04,437.55,412.28,408.29
179.0996,0.66842,7.9258,0.0,0.0,1.7376,0.78976,408.01,437.51,412.27,408.29
179.1006,0.68168,7.9399,0.0,0.0,1.7414,0.84104,407.98,437.48,412.25,408.28
179.1016,0.67966,7.9149,0.0,0.0,1.7373,0.77461,407.95,437.44,412.24,408.27
179.1026,0.69255,7.9375,0.0,0.0,1.7383,0.82594,407.92,437.41,412.23,408.27
179.1036,0.66247,7.9296,0.0,0.0,1.7448,0.78879,407.89,437.37,412.22,408.26
179.1046,0.69387,7.926,0.0,0.0,1.7329,0.84197,407.86,437.33,412.21,408.26
179.1056,0.68142,7.9299,0.0,0.0,1.7428,0.79776,407.83,437.3,412.19,408.25
179.1066,0.67361,7.9255,0.0,0.0,1.7419,0.81878,407.8,437.27,412.19,408.25
179.1076,0.69668,7.9368,0.0,0.0,1.7371,0.82991,407.77,437.25,412.18,408.26
179.1086,0.67329,7.9201,0.0,0.0,1.7424,0.80893,407.74,437.22,412.17,408.26
179.1096,0.68898,7.9309,0.0,0.0,1.7364,0.80499,407.71,437.2,412.17,408.27
179.1106,0.65424,7.9365,0.0,0.0,1.7449,0.80707,407.68,437.18,412.16,408.28
179.1116,0.71002,7.92,0.0,0.0,1.736,0.84404,407.65,437.15,412.16,408.28
179.1126,0.65405,7.9346,0.0,0.0,1.7404,0.80097,407.62,437.13,412.15,408.29
179.1136,0.71482,7.9257,0.0,0.0,1.7429,0.82995,407.59,437.1,412.14,408.29
179.1146,0.64443,7.9368,0.0,0.0,1.7365,0.76264,407.56,437.08,412.14,408.3
179.1156,0.72887,7.9195,0.0,0.0,1.7408,0.85491,407.53,437.06,412.13,408.31
179.31644,0.65666,7.9292,0.0,0.0,1.7403,0.7771,403.9,433.3,410.11,406.1
181.31644,0.51372,7.9319,0.0,0.0,1.7412,0.60972,356.59,391.14,390.75,378.45
183.2905,0.45311,7.92,0.0,0.0,1.735,0.53818,335.73,369.84,370.47,354.95
185.2905,0.46159,7.9157,0.0,0.0,1.7327,0.54867,319.01,350.21,350.61,333.74
187.2905,0.46976,7.9139,0.0,0.0,1.7317,0.55769,302.49,330.88,338.65,314.32
189.2905,0.47389,7.9127,0.0,0.0,1.7312,0.56246,286.68,313.2,321.38,296.44
191.2905,0.47925,7.9124,0.0,0.0,1.7311,0.56836,272.31,296.69,303.8,280.37
193.2905,0.47859,7.9125,0.0,0.0,1.7312,0.56871,258.97,281.09,287.54,265.15
195.2905,0.47801,7.9126,0.0,0.0,1.7312,0.56739,246.69,267.02,273.42,250.71
197.2905,0.47547,7.9133,0.0,0.0,1.7315,0.56476,234.87,253.94,258.34,237.58
199.2905,0.47343,7.9138,0.0,0.0,1.7316,0.56213,224.0,241.62,244.79,225.42
201.2905,0.47036,7.914,0.0,0.0,1.7317,0.55829,213.76,230.07,232.11,214.22
203.2905,0.46608,7.9146,0.0,0.0,1.732,0.55325,204.1,219.45,220.42,203.65
205.2905,0.46191,7.9154,0.0,0.0,1.7325,0.54777,195.12,209.37,209.84,193.69
207.2905,0.45833,7.9158,0.0,0.0,1.7327,0.5443,186.66,200.06,199.9,184.63
209.2905,0.45566,7.916,0.0,0.0,1.7328,0.54162,178.77,191.08,190.58,176.02
211.2905,0.45346,7.9162,0.0,0.0,1.733,0.53832,171.18,182.91,182.12,168.35
213.1475,0.44795,7.9167,0.0,0.0,1.7331,0.53318,164.55,175.59,174.52,161.28
215.1475,0.44703,7.9168,0.0,0.0,1.7332,0.53199,157.97,168.34,166.94,154.21
217.1475,0.44485,7.9168,0.0,0.0,1.7333,0.52907,151.8,161.37,160.11,147.87
219.1475,0.44413,7.9174,0.0,0.0,1.7337,0.52805,145.88,154.79,153.56,141.67
221.1475,0.44292,7.9178,0.0,0.0,1.7339,0.5268,140.16,148.6,147.23,135.91
223.1475,0.44225,7.9181,0.0,0.0,1.7341,0.52586,134.79,142.89,141.27,130.6
225.1475,0.42784,6.8623,0.0,0.0,1.2854,0.50765,133.5,137.68,136.61,132.39
225.9475,0.42294,6.8494,0.0,0.0,1.2808,0.50125,133.93,136.89,136.05,133.25