File: examples/dan-msc-case-studies/CS4/data/01 raw data/hyde_test_009.csv
Time(sec),Force(kN),Jaw(mm),PowAngle(deg),PTemp,Strain,Stress(MPa),TC1(C),TC2(C),TC3(C)
0.0,2.3807,0.0071075,0.0,0.00573,0.00078078,7.2333,20.511,21.224,20.574
1.6,2.3326,0.0068308,0.0,4.621,0.00075373,7.0751,20.57,21.106,20.608
3.2,2.3029,0.0070036,0.0,9.421,0.00074942,6.9851,20.739,21.372,20.729
4.8,2.2669,0.0066478,0.0,14.221,0.0007375,6.8753,20.767,21.315,20.722
6.3499,2.2666,0.0067602,0.0,18.871,0.00074564,6.874,20.578,21.119,20.529
7.9499,2.2767,0.0078771,25.542,23.671,0.00088549,6.9051,21.255,22.959,21.309
9.5499,2.2934,0.0060066,24.211,28.471,0.00063391,6.9575,27.365,30.056,28.206
11.1499,2.287,0.0052603,23.689,33.271,0.00058006,6.9396,32.767,38.947,33.578
12.7499,2.2919,0.0030982,25.784,38.071,0.00032942,6.9536,37.578,40.365,38.373
14.2027,2.3086,0.00058667,26.654,42.429,8.8548e-05,7.0018,42.013,45.383,42.975
15.8027,2.3096,0.00022866,27.03,47.229,-7.0655e-07,7.0064,46.892,50.259,47.884
17.4027,2.3232,-0.0014329,26.191,52.029,-0.00016294,7.0496,51.887,55.025,52.862
19.0027,2.3292,-0.0043453,27.047,56.829,-0.00048363,7.0658,56.671,59.837,57.621
20.6027,2.3335,-0.0046654,26.899,61.629,-0.00050473,7.0794,61.576,64.686,62.464
22.2027,2.3254,-0.0068385,27.673,66.429,-0.00073228,7.0528,66.277,69.51,67.138
23.8027,2.3258,-0.0095201,27.144,71.229,-0.0010577,7.0545,71.276,74.529,72.278
25.4027,2.334,-0.010043,27.809,76.029,-0.0010742,7.0848,75.946,79.11,76.816
27.0027,2.3365,-0.012103,28.3,80.829,-0.0012863,7.0894,80.774,83.924,81.64
28.6027,2.3397,-0.014618,28.663,85.629,-0.0016208,7.0946,85.554,88.658,86.332
30.2027,2.3373,-0.016064,28.718,90.429,-0.0017412,7.0875,90.34,93.451,91.154
31.8027,2.3273,-0.018449,29.792,95.229,-0.0019766,7.0616,95.022,98.233,95.791
33.40271,2.3309,-0.020084,29.816,100.03,-0.00223,7.0726,99.928,103.27,100.79
35.00271,2.345,-0.022631,29.74,104.83,-0.0024797,7.1134,104.71,107.98,105.61
36.60271,2.3436,-0.024223,29.21,109.63,-0.0026258,7.1089,109.62,112.96,110.6
38.1856,2.3324,-0.026282,28.67,114.38,-0.0028733,7.0756,114.47,117.42,115.46
39.7856,2.3279,-0.029355,29.514,119.18,-0.0032099,7.0627,119.21,122.21,120.14
41.3856,2.3436,-0.03222,30.011,123.98,-0.0035371,7.1129,123.93,126.88,124.7
42.9856,2.3411,-0.033244,30.111,128.78,-0.0036179,7.1039,128.71,131.89,129.68
44.5098,2.3403,-0.03548,30.26,133.35,-0.0038844,7.1026,133.33,136.13,134.28
46.1098,2.3422,-0.038102,31.31,138.15,-0.0041548,7.1034,137.96,141.24,138.9
47.7098,2.3362,-0.040477,31.148,142.95,-0.0044382,7.0857,142.8,145.59,143.6
49.3098,2.3289,-0.043109,31.772,147.75,-0.004691,7.064,147.51,150.51,148.43
50.9098,2.3342,-0.047535,31.493,152.55,-0.0051413,7.082,152.48,155.61,153.36
52.5098,2.338,-0.048654,31.815,157.35,-0.005351,7.0934,157.26,160.36,158.19
54.1098,2.3438,-0.050194,31.587,162.15,-0.0054567,7.1103,162.1,165.26,163.02
55.7098,2.3363,-0.053239,32.264,166.95,-0.0057697,7.0836,166.81,170.19,167.89
57.3098,2.3358,-0.055891,32.291,171.75,-0.0061355,7.0879,171.62,175.2,172.83
58.9098,2.3371,-0.058822,32.581,176.55,-0.0064159,7.0921,176.37,179.95,177.52
60.5098,2.3314,-0.061908,32.32,181.35,-0.0067152,7.0762,181.25,184.43,182.19
62.1098,2.3437,-0.065922,32.374,186.15,-0.0072315,7.1097,186.04,189.01,186.97
63.70981,2.3613,-0.065731,32.22,190.95,-0.0071732,7.1627,190.92,193.89,191.81
65.30981,2.1998,-0.069312,31.68,195.75,-0.0075598,6.6737,195.95,198.9,197.02
66.90981,2.0773,-0.073152,31.856,200.55,-0.0079826,6.3034,200.7,203.49,201.78
68.50981,2.0908,-0.076446,32.966,205.35,-0.0083353,6.3468,205.27,208.38,206.28
70.10981,2.104,-0.079895,33.97,210.15,-0.0086992,6.383,209.86,213.13,210.86
71.6165,2.1193,-0.084368,33.739,214.67,-0.0092298,6.4301,214.55,217.66,215.62
73.2165,2.2489,-0.08308,33.174,219.47,-0.009042,6.8199,219.44,222.61,220.69
74.8038,2.2892,-0.085454,32.936,224.23,-0.0092774,6.9432,224.37,227.6,225.72
76.4038,2.2915,-0.088169,33.302,229.03,-0.0096397,6.9553,229.06,232.55,230.57
78.0038,2.288,-0.091439,33.91,233.83,-0.0099427,6.942,233.73,237.29,235.29
79.6038,2.2925,-0.095769,33.417,238.63,-0.010413,6.9524,238.66,241.92,240.34
81.2038,2.2937,-0.095974,33.699,243.43,-0.010484,6.9549,243.46,247.1,245.25
82.8038,2.2879,-0.099485,33.618,248.23,-0.01083,6.9402,248.31,251.92,250.05
84.4038,2.2878,-0.10266,33.845,253.03,-0.011154,6.9431,253.03,256.68,254.95
86.0038,2.3047,-0.1074,33.536,257.83,-0.011752,6.9917,257.94,261.21,259.92
87.6038,2.3031,-0.1078,33.192,262.63,-0.011742,6.988,262.82,266.57,264.98
89.2038,2.3016,-0.11178,33.563,267.43,-0.012159,6.9798,267.49,271.63,269.92
90.8038,2.2936,-0.11479,33.764,272.23,-0.012512,6.9571,272.26,276.38,274.8
92.4038,2.3021,-0.12117,33.774,277.03,-0.013165,6.9837,277.15,281.28,279.76
94.0038,2.2985,-0.12068,33.996,281.83,-0.013143,6.9757,281.87,286.18,284.67
95.60381,2.3035,-0.12382,34.145,286.63,-0.013475,6.9869,286.59,291.08,289.48
97.20381,2.301,-0.12752,34.628,291.43,-0.013856,6.978,291.33,295.96,294.25
98.80381,2.2883,-0.13058,34.634,296.23,-0.014214,6.939,296.15,300.91,299.16
100.40381,2.3032,-0.13566,34.566,301.03,-0.014721,6.9854,301.05,305.07,303.55
102.00381,2.3073,-0.13598,34.869,305.83,-0.014781,6.9996,305.69,308.58,307.0
103.5428,2.2999,-0.13793,34.8,310.45,-0.015002,6.9772,310.31,311.77,310.27
105.1428,2.2924,-0.14114,34.858,315.25,-0.015327,6.953,315.16,315.86,314.25
106.5984,2.3005,-0.14386,34.569,319.62,-0.015598,6.9743,319.64,319.68,318.31
108.1984,2.2985,-0.1505,34.712,324.42,-0.016373,6.9726,324.4,324.23,322.7
109.7984,2.3006,-0.14915,34.706,329.22,-0.016184,6.9819,329.18,328.87,327.27
111.3984,2.3034,-0.15219,34.651,334.02,-0.016492,6.9912,334.01,333.52,331.96
112.9984,2.2999,-0.15539,34.657,338.82,-0.01691,6.9747,338.9,338.58,336.9
114.5984,2.2984,-0.16029,35.301,343.62,-0.017373,6.967,343.59,343.6,341.79
116.1984,2.3049,-0.16233,35.013,348.42,-0.017607,6.9918,348.46,348.59,346.66
117.7984,2.2992,-0.16226,33.775,350.0,-0.017636,6.9752,350.13,349.18,348.31
119.3984,2.2993,-0.1633,33.752,350.0,-0.017706,6.9769,350.12,349.09,348.41
120.9984,2.2772,-0.16436,33.466,350.0,-0.017804,6.9077,350.09,349.02,348.29
122.5984,2.2909,-0.16637,33.61,350.0,-0.018072,6.947,350.0,349.25,348.34
124.1984,2.2928,-0.16757,33.3,350.0,-0.018198,6.9536,350.03,349.25,348.32
125.79841,2.3015,-0.16565,33.169,350.0,-0.017946,6.9839,350.01,349.16,348.22
127.39841,2.2825,-0.16667,32.909,350.0,-0.018115,6.9272,350.03,349.25,348.21
128.99841,2.2835,-0.16769,32.753,350.0,-0.018175,6.9292,350.08,349.24,348.21
130.59841,2.3041,-0.16963,32.697,350.0,-0.018373,6.9853,350.07,349.32,348.14
132.19841,2.3082,-0.16893,32.625,350.0,-0.018371,7.0016,350.01,349.15,347.92
133.79841,2.2708,-0.1682,31.936,350.0,-0.018238,6.8877,350.13,349.2,347.99
135.39841,2.2921,-0.16908,32.008,350.0,-0.018326,6.9556,350.09,349.29,347.95
136.8101,2.2981,-0.16919,32.22,350.0,-0.018375,6.9724,350.04,349.06,347.89
138.4101,2.2866,-0.16978,32.559,350.0,-0.018422,6.9368,350.0,349.16,347.78
140.0101,2.2673,-0.17036,32.475,350.0,-0.018476,6.8789,349.99,349.06,347.79
141.6101,2.2934,-0.1719,32.822,350.0,-0.018662,6.9517,349.95,348.99,347.63
143.2101,2.3036,-0.17407,32.121,350.0,-0.018888,6.9844,350.09,348.99,347.73
144.8101,2.2924,-0.17262,32.301,350.0,-0.018752,6.9546,350.02,348.93,347.66
146.4101,2.2694,-0.17128,32.169,350.0,-0.0186,6.8849,350.0,348.79,347.57
148.0101,2.3061,-0.17094,32.293,350.0,-0.018568,6.9981,350.02,348.84,347.56
149.6101,2.3045,-0.17143,32.248,350.0,-0.018611,6.9905,350.01,348.83,347.52
151.2101,2.2873,-0.1723,32.82,350.0,-0.018686,6.9388,349.99,348.89,347.46
152.8101,2.2732,-0.17212,32.395,350.0,-0.018713,6.8989,350.05,348.91,347.61
154.4101,2.3022,-0.17257,32.355,350.0,-0.018736,6.9861,350.04,348.86,347.45
156.01011,2.3106,-0.17289,32.506,350.0,-0.018725,7.0116,349.99,348.87,347.42
157.61011,2.291,-0.17467,31.921,350.0,-0.018977,6.9464,350.08,348.9,347.44
159.21011,2.2813,-0.1755,32.092,350.0,-0.019054,6.9168,350.01,348.85,347.39
160.81011,2.3005,-0.17252,32.01,350.0,-0.018681,6.9795,350.09,348.9,347.49
161.953,2.15,-0.0034525,0.0,0.095948,0.00048869,6.5645,350.06,348.81,347.37
161.9538,2.3491,-0.0016191,0.0,1.3369e-12,0.00058696,7.1012,350.09,348.83,347.36
161.9546,2.3908,0.0076541,0.0,1.8987999999999998e-23,-0.00045802,7.2389,350.11,348.84,347.34
161.9554,2.276,0.0036798,0.0,2.5753e-34,0.00067094,6.9014,350.13,348.86,347.33
161.9562,2.3489,-0.0046327,0.0,2.8026e-45,0.0007551,7.1229,350.15,348.88,347.31
161.957,2.2908,0.011122,0.0,0.0,0.0007585,6.9696,350.17,348.9,347.3
161.95779,2.3039,0.0064138,0.0,0.0,-2.2388e-05,7.0195,350.19,348.91,347.28
161.95859,2.332,-0.0062724,0.0,0.0,-0.00036238,7.1064,350.22,348.93,347.27
161.95939,2.2747,0.0066594,0.0,0.0,0.0013451,6.8794,350.24,348.95,347.25
161.96019,2.355,0.0046045,0.0,0.0,0.00044378,7.0924,350.26,348.96,347.24
161.96099,2.2798,0.0014587,0.0,0.0,-0.00084826,6.9538,350.28,348.98,347.22
161.96179,2.3152,0.0022345,0.0,0.0,0.001125,7.0343,350.3,349.0,347.21
161.96259,2.3338,0.0011599,0.0,0.0,0.00075168,7.0978,350.29,348.99,347.21
161.96339,2.276,0.0080923,0.0,0.0,-0.00042148,6.9033,350.28,348.97,347.22
161.96419,2.3606,0.00072246,0.0,0.0,0.00031133,7.1455,350.27,348.96,347.23
161.96499,2.2816,-0.0037533,0.0,0.0,0.00056855,6.9143,350.25,348.94,347.24
161.96579,2.3163,0.0094765,0.0,0.0,0.00030793,7.0168,350.24,348.93,347.24
161.96659,2.3237,0.0041218,0.0,0.0,-0.00010358,7.0544,350.22,348.91,347.25
161.96738,2.2752,-0.0052457,0.0,0.0,-5.2258e-05,6.9253,350.21,348.9,347.26
161.96818,2.3522,0.0067543,0.0,0.0,0.0011472,7.1491,350.19,348.89,347.26
161.96898,2.2694,0.0049121,0.0,0.0,6.8104e-05,6.8841,350.18,348.87,347.27
161.96978,2.319,0.00050957,0.0,0.0,-0.00049376,7.0295,350.16,348.86,347.28
161.97058,2.3113,0.0026368,0.0,0.0,0.001056,7.0052,350.15,348.84,347.29
161.97138,2.2771,0.00040135,0.0,0.0,0.00048716,6.9415,350.13,348.83,347.29
161.97218,2.3319,0.00623,0.0,0.0,-0.00029674,7.0746,350.12,348.82,347.3
161.97298,2.2541,0.00067995,0.0,0.0,0.00039528,6.8353,350.11,348.81,347.3
161.97378,2.324,-0.0033769,0.0,0.0,0.00045539,7.0125,350.1,348.81,347.3
161.97458,2.303,0.0077767,0.0,0.0,3.7468e-05,6.9804,350.09,348.81,347.3
161.97538,2.2839,0.0051274,0.0,0.0,0.00010469,6.9239,350.08,348.81,347.3
161.97618,2.3304,-0.0040114,0.0,0.0,0.00012695,7.076,350.07,348.8,347.3
161.97697,2.2497,0.0059363,0.0,0.0,0.0008496,6.8509,350.06,348.8,347.3
161.97777,2.3229,0.0051575,0.0,0.0,0.00012951,7.0319,350.05,348.8,347.3
161.97857,2.2829,-0.00030262,0.0,0.0,-0.00030428,6.9211,350.04,348.8,347.3
161.97937,2.2757,0.0035097,0.0,0.0,0.0011848,6.8958,350.03,348.8,347.3
161.98017,2.3171,0.0029636,0.0,0.0,0.00037884,7.0548,350.02,348.79,347.3
161.98097,2.2486,0.0039985,0.0,0.0,-0.00029585,6.8092,350.01,348.79,347.3
161.98177,2.33,0.00012356,0.0,0.0,0.00057151,7.0595,350.0,348.79,347.3
161.98257,2.2741,0.00081856,0.0,0.0,0.00052462,6.9015,350.0,348.79,347.3
161.98337,2.2879,0.0088125,0.0,0.0,0.00026175,6.971,349.99,348.79,347.3
161.98417,2.3179,0.0022642,0.0,0.0,4.9472e-05,7.0496,349.99,348.79,347.3
161.98497,2.2535,-0.0014811,0.0,0.0,0.00018688,6.8416,349.98,348.8,347.3
161.98577,2.3293,0.0079653,0.0,0.0,0.0010098,7.0351,349.98,348.8,347.3
161.98657,2.2678,0.0028295,0.0,0.0,-0.00027581,6.8808,349.97,348.8,347.3
161.98736,2.297,0.0010261,0.0,0.0,-3.9769e-05,6.9491,349.97,348.8,347.3
161.98816,2.3022,0.0046379,0.0,0.0,0.0011128,6.9974,349.96,348.81,347.3
161.98896,2.2528,0.0012659,0.0,0.0,8.0569e-06,6.8321,349.96,348.81,347.3
161.98976,2.3411,0.0041485,0.0,0.0,-1.5197e-05,7.0683,349.96,348.81,347.3
161.99056,2.255,0.00072007,0.0,0.0,0.00073368,6.8556,349.95,348.81,347.3
161.99136,2.3109,0.0010749,0.0,0.0,0.00035225,6.984,349.95,348.82,347.3
161.99216,2.286,0.0065535,0.0,0.0,0.00010189,6.9379,349.94,348.82,347.3
161.99296,2.2566,0.00061851,0.0,0.0,9.0774e-05,6.8118,349.95,348.81,347.3
161.99376,2.325,0.00051964,0.0,0.0,0.00045601,7.0776,349.95,348.81,347.3
161.99456,2.2426,0.0077504,0.0,0.0,0.00058237,6.8151,349.95,348.8,347.31
161.99536,2.2996,0.0022524,0.0,0.0,-0.00015827,6.9633,349.95,348.8,347.31
161.99616,2.2861,0.00059438,0.0,0.0,0.00014726,6.9471,349.96,348.79,347.31
161.99695,2.2628,0.0034428,0.0,0.0,0.0008376,6.8703,349.96,348.79,347.31
161.99775,2.3209,0.0029785,0.0,0.0,3.4444e-05,7.0674,349.96,348.78,347.32
161.99855,2.2357,0.0041866,0.0,0.0,0.00013955,6.7727,349.96,348.78,347.32
161.99935,2.3091,-0.00040802,0.0,0.0,0.00075731,6.983,349.96,348.77,347.32
162.00015,2.2667,0.0024952,0.0,0.0,0.00023376,6.8964,349.97,348.77,347.32
162.00095,2.2652,0.0082086,0.0,0.0,0.00040776,6.8603,349.97,348.76,347.33
162.00175,2.3044,-0.0017816,0.0,0.0,0.00019337,7.0198,349.97,348.76,347.33
162.00255,2.2479,0.00043194,0.0,0.0,0.00038003,6.7817,349.98,348.75,347.34
162.00335,2.3083,0.0084523,0.0,0.0,0.00055857,6.972,349.99,348.74,347.35
162.00415,2.261,0.00073701,0.0,0.0,-5.7638e-05,6.8767,349.99,348.72,347.36
162.00495,2.2752,0.001016,0.0,0.0,0.00040274,6.8767,350.0,348.71,347.38
162.00575,2.3048,0.0027931,0.0,0.0,0.00070148,6.989,350.01,348.7,347.39
162.00654,2.2727,0.0034735,0.0,0.0,1.1568e-05,6.8783,350.01,348.69,347.4
162.00734,2.3095,0.0024334,0.0,0.0,0.00033723,6.9861,350.02,348.67,347.41
162.00814,2.2906,-0.00089716,0.0,0.0,0.00067305,6.9392,350.03,348.66,347.42
162.00894,2.254,0.0030705,0.0,0.0,7.1382e-05,6.7929,350.04,348.65,347.44
162.00974,2.744,0.0079815,0.0,0.0,0.00042645,8.327,350.04,348.64,347.45
162.01054,2.177,-0.0020556,0.0,0.0,0.00033316,6.6754,350.05,348.63,347.46
162.01134,2.2788,0.00064564,0.0,0.0,0.00016826,6.8726,350.06,348.61,347.47
162.01214,2.4019,0.013422,0.0,0.0,0.00095973,7.3272,350.25,348.81,347.48
162.01294,2.1251,-0.0029137,0.0,0.0,-0.000509,6.4258,350.89,349.49,347.48
162.01374,2.2707,0.0041799,0.0,0.0,0.00077078,6.8703,351.53,350.17,347.48
162.01454,2.2466,0.003708,0.0,0.0,0.0006224,6.814,352.17,350.85,347.48
162.01534,2.1902,0.0024917,0.0,0.0,-0.00030925,6.6527,352.81,351.53,347.48
162.01613,2.2365,-0.0016892,0.0,0.0,-8.8924e-05,6.7515,353.45,352.21,347.48
162.01693,2.2629,-0.0025526,0.0,0.0,0.00048074,6.8622,354.09,352.89,347.48
162.01773,2.0793,0.0035999,0.0,0.0,-0.0001105,6.2962,354.73,353.57,347.48
162.01853,2.3091,0.0024282,0.0,0.0,-5.724e-05,6.9518,355.37,354.25,347.48
162.01933,2.1813,-0.0066803,0.0,0.0,0.00012882,6.6387,356.01,354.94,347.48
162.02013,2.1982,0.0047853,0.0,0.0,0.0003937,6.6469,356.65,355.62,347.48
162.02093,2.303,0.0053979,0.0,0.0,-0.00018436,7.0184,357.29,356.3,347.48
162.02173,2.1169,-0.0071314,0.0,0.0,-0.00064658,6.4312,357.93,356.98,347.48
162.02253,2.348,0.0038601,0.0,0.0,0.00098119,7.1432,359.5,358.67,347.47
162.02333,2.1036,0.0010156,0.0,0.0,8.4644e-05,6.4098,361.32,360.64,347.45
162.02413,2.2287,-0.00018946,0.0,0.0,-0.00072906,6.7365,363.14,362.6,347.43
162.02493,2.285,0.0026526,0.0,0.0,0.00082515,7.0206,364.96,364.57,347.41
162.02572,26.474,0.14667,0.0,0.0,0.015447,76.743,366.78,366.54,347.39
162.02652,41.13,0.5666,0.0,0.0,0.060115,124.29,368.61,368.5,347.37
162.02732,39.139,1.3398,0.0,0.0,0.1551,118.05,370.43,370.47,347.35
162.02812,43.54,1.8512,0.0,0.0,0.2228,131.56,372.25,372.44,347.33
162.02892,40.661,2.3479,0.0,0.0,0.29028,123.45,374.07,374.41,347.31
162.02972,44.093,2.8395,0.0,0.0,0.36087,133.53,375.9,376.37,347.29
162.03052,42.959,3.387,0.0,0.0,0.45018,130.47,377.72,378.34,347.27
162.03132,43.882,3.9325,0.0,0.0,0.54472,132.92,379.54,380.31,347.25
162.03212,43.77,4.2789,0.0,0.0,0.60728,132.96,381.14,382.0,347.24
162.03292,44.654,4.6923,0.0,0.0,0.68832,135.23,382.17,382.97,347.25
162.03372,44.799,5.0835,0.0,0.0,0.77431,135.99,383.19,383.94,347.27
162.03452,44.914,5.4579,0.0,0.0,0.8611,136.17,384.21,384.91,347.28
162.03532,44.872,5.7637,0.0,0.0,0.93227,136.14,385.24,385.88,347.29
162.03611,44.855,6.0545,0.0,0.0,1.0124,136.11,386.26,386.86,347.3
162.03691,45.358,6.3014,0.0,0.0,1.087,137.72,387.28,387.83,347.31
162.03771,44.7,6.565,0.0,0.0,1.1613,135.52,388.31,388.8,347.33
162.03851,45.357,6.76,0.0,0.0,1.2232,137.58,389.33,389.77,347.34
162.03931,45.067,6.9572,0.0,0.0,1.298,136.65,390.36,390.74,347.35
162.04011,45.603,7.1589,0.0,0.0,1.3731,138.27,391.38,391.71,347.36
162.04091,45.69,7.3411,0.0,0.0,1.4374,138.54,392.4,392.68,347.37
162.04171,44.12,7.5066,0.0,0.0,1.5085,135.45,393.43,393.65,347.39
162.04251,37.751,7.3977,0.0,0.0,1.4725,114.76,393.24,393.31,347.4
162.04331,36.503,7.5156,0.0,0.0,1.52,111.0,392.68,392.55,347.4
162.04411,37.015,7.4606,0.0,0.0,1.4854,112.65,392.11,391.79,347.41
162.04491,36.647,7.4816,0.0,0.0,1.5049,111.61,391.54,391.03,347.42
162.0457,36.95,7.493,0.0,0.0,1.5136,112.18,390.98,390.27,347.42
162.0465,35.738,7.4883,0.0,0.0,1.5012,108.05,390.41,389.51,347.43
162.0473,35.236,7.5165,0.0,0.0,1.5126,107.01,389.84,388.75,347.44
162.0481,35.178,7.4909,0.0,0.0,1.5104,106.72,389.28,387.99,347.45
162.0489,34.684,7.5028,0.0,0.0,1.5144,105.33,388.71,387.23,347.45
162.0497,34.756,7.5249,0.0,0.0,1.5162,105.51,388.14,386.47,347.46
162.0505,34.21,7.4945,0.0,0.0,1.5054,103.81,387.58,385.71,347.47
162.0513,33.7,7.5137,0.0,0.0,1.523,102.28,387.01,384.95,347.48
162.0521,33.438,7.5217,0.0,0.0,1.5217,101.5,386.41,384.19,347.48
162.0529,33.129,7.5212,0.0,0.0,1.5129,100.55,385.73,383.41,347.46
162.0537,32.743,7.5184,0.0,0.0,1.5213,99.404,385.05,382.64,347.45
162.0545,32.512,7.5173,0.0,0.0,1.5245,98.627,384.37,381.86,347.43
162.05529,32.078,7.5238,0.0,0.0,1.516,97.306,383.68,381.09,347.42
162.05609,31.756,7.5241,0.0,0.0,1.5176,96.376,383.0,380.31,347.4
162.05689,31.425,7.5031,0.0,0.0,1.5165,95.39,382.32,379.54,347.39
162.05769,31.08,7.527,0.0,0.0,1.5237,94.324,381.63,378.76,347.38
162.05849,30.841,7.5333,0.0,0.0,1.5196,93.56,380.95,377.99,347.36
162.05929,30.511,7.5143,0.0,0.0,1.5158,92.611,380.27,377.21,347.35
162.06009,30.24,7.52,0.0,0.0,1.5248,91.743,379.59,376.44,347.33
162.06089,29.97,7.5287,0.0,0.0,1.5235,90.954,378.9,375.66,347.32
162.06169,29.467,7.5216,0.0,0.0,1.5138,89.428,378.22,374.89,347.3
162.06249,28.985,7.5164,0.0,0.0,1.5212,87.984,377.76,374.39,347.3
162.06329,28.034,7.5205,0.0,0.0,1.5244,85.141,377.37,374.0,347.31
162.06409,26.909,7.5321,0.0,0.0,1.5191,81.747,376.99,373.6,347.32
162.06488,25.551,7.5228,0.0,0.0,1.5176,77.688,376.6,373.2,347.33
162.06568,23.464,7.5039,0.0,0.0,1.5164,71.412,376.22,372.81,347.33
162.06648,21.268,7.5156,0.0,0.0,1.5177,64.76,375.84,372.41,347.34
162.06728,18.502,7.5083,0.0,0.0,1.5099,56.375,375.45,372.01,347.35
162.06808,12.036,7.4915,0.0,0.0,1.5057,37.608,375.07,371.62,347.35
162.06888,-1.0869,7.4467,0.0,0.0,1.493,-2.6793,374.68,371.22,347.36
162.06968,0.20656,7.3763,0.0,0.0,1.4579,0.49819,374.3,370.83,347.37
162.07048,-0.49174,7.3785,0.0,0.0,1.454,-1.1826,373.92,370.43,347.38
162.07128,-0.27772,7.4214,0.0,0.0,1.4807,-0.99378,373.53,370.03,347.38
162.07208,1.9058,7.4812,0.0,0.0,1.5046,4.767,373.21,369.72,347.39
162.07288,5.1734,7.5187,0.0,0.0,1.5138,16.487,373.13,369.67,347.39
162.07368,1.0216,7.4935,0.0,0.0,1.5071,3.4395,373.05,369.62,347.4
162.07447,0.97138,7.4737,0.0,0.0,1.5027,2.7794,372.97,369.58,347.4
162.07527,2.7964,7.5078,0.0,0.0,1.5131,8.4552,372.89,369.53,347.4
162.07607,1.1822,7.5099,0.0,0.0,1.5111,3.6789,372.8,369.49,347.4
162.07687,1.5491,7.4786,0.0,0.0,1.5022,4.5436,372.72,369.44,347.4
162.07767,2.6473,7.4983,0.0,0.0,1.5131,7.9173,372.64,369.39,347.41
162.07847,2.3372,7.4947,0.0,0.0,1.5065,7.3128,372.56,369.35,347.41
162.07927,0.89541,7.4767,0.0,0.0,1.4971,2.6161,372.47,369.3,347.41
162.08007,2.5563,7.4834,0.0,0.0,1.507,7.6163,372.39,369.26,347.41
162.08087,2.0287,7.4823,0.0,0.0,1.5044,6.2403,372.31,369.21,347.42
162.08167,1.6483,7.4758,0.0,0.0,1.4957,5.0061,372.23,369.16,347.42
162.08247,2.0745,7.4723,0.0,0.0,1.4996,6.2618,372.23,369.2,347.43
162.08327,1.9271,7.4601,0.0,0.0,1.497,5.8864,372.27,369.26,347.43
162.08406,1.8554,7.4803,0.0,0.0,1.4991,5.666,372.31,369.32,347.44
162.08486,1.8817,7.4752,0.0,0.0,1.497,5.669,372.35,369.38,347.45
162.08566,1.9868,7.4669,0.0,0.0,1.4982,6.0473,372.39,369.45,347.45
162.08646,1.7929,7.4781,0.0,0.0,1.503,5.4731,372.42,369.51,347.46
162.08726,1.8044,7.4798,0.0,0.0,1.4993,5.4492,372.46,369.57,347.47
162.08806,2.0005,7.4775,0.0,0.0,1.4991,6.0795,372.5,369.64,347.48
162.08886,1.7155,7.4739,0.0,0.0,1.5035,5.2442,372.54,369.7,347.48
162.08966,1.8781,7.4783,0.0,0.0,1.501,5.6769,372.58,369.76,347.49
162.09046,1.8992,7.487,0.0,0.0,1.501,5.779,372.62,369.82,347.5
162.09126,1.8293,7.4743,0.0,0.0,1.5019,5.531,372.66,369.89,347.51
162.09206,1.8576,7.4736,0.0,0.0,1.5013,5.6425,372.69,369.95,347.52
162.09286,1.8287,7.4874,0.0,0.0,1.5019,5.5502,372.71,370.0,347.54
162.09366,1.8829,7.4735,0.0,0.0,1.4974,5.7014,372.72,370.06,347.56
162.09445,1.8366,7.4699,0.0,0.0,1.4999,5.589,372.73,370.11,347.58
162.09525,1.8765,7.4811,0.0,0.0,1.503,5.6929,372.75,370.17,347.6
162.09605,1.8393,7.4771,0.0,0.0,1.4979,5.5825,372.76,370.23,347.62
162.09685,1.8195,7.4716,0.0,0.0,1.4979,5.5294,372.78,370.28,347.65
162.09765,1.8595,7.4736,0.0,0.0,1.5026,5.6414,372.79,370.34,347.67
162.09845,1.7886,7.4769,0.0,0.0,1.4991,5.4285,372.81,370.39,347.69
162.09925,1.8292,7.4776,0.0,0.0,1.4981,5.557,372.82,370.45,347.71
162.10005,1.8198,7.4698,0.0,0.0,1.5003,5.5412,372.84,370.5,347.73
162.10085,1.7505,7.4774,0.0,0.0,1.5015,5.3159,372.85,370.56,347.76
162.10165,1.8736,7.4847,0.0,0.0,1.5002,5.7149,372.86,370.61,347.78
162.10245,1.805,7.4714,0.0,0.0,1.4978,5.4714,372.86,370.66,347.8
162.10325,1.7904,7.4735,0.0,0.0,1.5018,5.4394,372.85,370.69,347.83
162.10404,1.8586,7.4813,0.0,0.0,1.5017,5.6441,372.84,370.72,347.86
162.10484,1.7582,7.4753,0.0,0.0,1.4971,5.3235,372.82,370.76,347.88
162.10564,1.8612,7.4737,0.0,0.0,1.4999,5.6438,372.81,370.79,347.91
162.10644,1.8532,7.476,0.0,0.0,1.5034,5.6519,372.8,370.82,347.94
162.10724,1.7763,7.4775,0.0,0.0,1.498,5.3673,372.79,370.86,347.96
162.10804,1.8919,7.4737,0.0,0.0,1.4977,5.7476,372.78,370.89,347.99
162.10884,1.7455,7.4687,0.0,0.0,1.5012,5.3047,372.76,370.93,348.02
162.10964,1.8686,7.4768,0.0,0.0,1.4999,5.6373,372.75,370.96,348.04
162.11044,1.8115,7.4828,0.0,0.0,1.4985,5.5532,372.74,370.99,348.07
162.11124,1.765,7.4695,0.0,0.0,1.4985,5.3336,372.73,371.03,348.1
162.11204,1.8923,7.4741,0.0,0.0,1.5016,5.7353,372.72,371.06,348.12
162.11284,1.7145,7.4818,0.0,0.0,1.5004,5.2238,372.7,371.09,348.15
162.11363,1.8956,7.4754,0.0,0.0,1.4975,5.7701,372.69,371.12,348.17
162.11443,1.7526,7.4737,0.0,0.0,1.5017,5.3211,372.68,371.15,348.2
162.11523,1.8488,7.474,0.0,0.0,1.5023,5.6101,372.67,371.18,348.22
162.11603,1.8043,7.4796,0.0,0.0,1.4977,5.4504,372.66,371.21,348.24
162.11683,1.7736,7.4761,0.0,0.0,1.4997,5.3534,372.64,371.23,348.27
162.11763,1.9179,7.4667,0.0,0.0,1.5014,5.7937,372.63,371.26,348.29
162.11843,1.748,7.4788,0.0,0.0,1.4988,5.3338,372.62,371.29,348.32
162.11923,1.9119,7.4828,0.0,0.0,1.4986,5.7644,372.61,371.32,348.34
162.12003,1.7843,7.4674,0.0,0.0,1.4987,5.4711,372.6,371.35,348.37
162.12083,1.8262,7.4746,0.0,0.0,1.5016,5.531,372.58,371.38,348.39
162.12163,1.8906,7.485,0.0,0.0,1.501,5.7741,372.57,371.41,348.41
162.12243,1.7499,7.4716,0.0,0.0,1.4965,5.3274,372.55,371.42,348.43
162.12322,1.9214,7.4728,0.0,0.0,1.5022,5.8332,372.52,371.42,348.44
162.12402,1.7554,7.4779,0.0,0.0,1.5027,5.3427,372.5,371.42,348.45
162.12482,1.9041,7.4811,0.0,0.0,1.4977,5.7697,372.47,371.42,348.46
162.12562,1.843,7.4767,0.0,0.0,1.5015,5.6313,372.44,371.42,348.47
162.12642,1.8163,7.4708,0.0,0.0,1.503,5.5063,372.42,371.42,348.48
162.12722,1.8946,7.4873,0.0,0.0,1.501,5.7502,372.39,371.42,348.49
162.12802,1.8135,7.4839,0.0,0.0,1.4997,5.4931,372.36,371.42,348.5
162.12882,1.9232,7.4672,0.0,0.0,1.5001,5.8366,372.34,371.42,348.51
162.12962,1.8724,7.4791,0.0,0.0,1.5028,5.6724,372.31,371.42,348.52
162.13042,1.8901,7.487,0.0,0.0,1.5002,5.7482,372.28,371.42,348.53
162.13122,1.8711,7.4704,0.0,0.0,1.4968,5.662,372.26,371.42,348.54
162.13202,1.8838,7.4726,0.0,0.0,1.5032,5.7545,372.23,371.42,348.55
162.13281,1.8945,7.4819,0.0,0.0,1.5037,5.7295,372.18,371.4,348.57
162.13361,1.9428,7.4792,0.0,0.0,1.4961,5.9037,372.14,371.38,348.59
162.13441,1.831,7.4729,0.0,0.0,1.501,5.5665,372.1,371.36,348.61
162.13521,1.9732,7.4726,0.0,0.0,1.5041,6.0135,372.05,371.34,348.62
162.13601,1.8101,7.4892,0.0,0.0,1.5001,5.5405,372.01,371.32,348.64
162.13681,1.9577,7.4801,0.0,0.0,1.4987,5.9187,371.97,371.3,348.66
162.13761,1.8834,7.467,0.0,0.0,1.5012,5.7539,371.92,371.28,348.68
162.13841,1.8585,7.486,0.0,0.0,1.5051,5.6454,371.88,371.26,348.7
162.13921,1.971,7.4853,0.0,0.0,1.4986,5.9779,371.84,371.24,348.72
162.14001,1.8304,7.4693,0.0,0.0,1.4969,5.5822,371.79,371.22,348.74
162.14081,1.99,7.4786,0.0,0.0,1.5061,5.9946,371.75,371.2,348.76
162.14161,1.925,7.4839,0.0,0.0,1.5031,5.8764,371.71,371.18,348.78
162.14241,1.8952,7.478,0.0,0.0,1.4952,5.7312,371.66,371.17,348.81
162.1432,2.0036,7.472,0.0,0.0,1.5021,6.0265,371.6,371.16,348.84
162.144,1.8774,7.4746,0.0,0.0,1.505,5.7173,371.54,371.16,348.88
162.1448,1.9836,7.4886,0.0,0.0,1.4991,5.9976,371.49,371.15,348.91
162.1456,1.9638,7.4766,0.0,0.0,1.4989,5.9432,371.43,371.14,348.94
162.1464,1.9092,7.4645,0.0,0.0,1.5017,5.7538,371.38,371.14,348.98
162.1472,2.0061,7.4894,0.0,0.0,1.505,6.0851,371.32,371.13,349.01
162.148,1.9313,7.4885,0.0,0.0,1.4991,5.8591,371.27,371.12,349.05
162.1488,1.9836,7.4638,0.0,0.0,1.4962,6.0171,371.21,371.11,349.08
162.1496,1.9824,7.4778,0.0,0.0,1.5063,6.1001,371.16,371.11,349.11
162.1504,1.9755,7.4879,0.0,0.0,1.5039,5.9728,371.1,371.1,349.15
162.1512,2.0198,7.4777,0.0,0.0,1.4956,6.1064,371.04,371.09,349.18
162.152,1.9395,7.4705,0.0,0.0,1.5026,5.8287,370.99,371.08,349.22
162.15279,2.1336,7.474,0.0,0.0,1.5047,6.4684,370.93,371.06,349.25
162.15359,1.9048,7.4863,0.0,0.0,1.4979,5.7692,370.87,371.03,349.28
162.15439,2.0594,7.4728,0.0,0.0,1.498,6.1802,370.81,371.0,349.31
162.15519,2.0661,7.468,0.0,0.0,1.5034,6.3297,370.76,370.98,349.34
162.15599,1.9088,7.4856,0.0,0.0,1.502,5.7736,370.7,370.95,349.37
162.15679,2.1662,7.4842,0.0,0.0,1.4989,6.5573,370.64,370.92,349.41
162.15759,1.9075,7.4666,0.0,0.0,1.4982,5.8184,370.58,370.9,349.44
162.15839,2.1172,7.4784,0.0,0.0,1.5047,6.3837,370.52,370.87,349.47
162.15919,2.0266,7.4866,0.0,0.0,1.5023,6.2299,370.47,370.84,349.5
162.15999,1.9372,7.4766,0.0,0.0,1.4958,5.8408,370.41,370.82,349.53
162.16079,2.17,7.4743,0.0,0.0,1.5037,6.5808,370.35,370.79,349.56
162.16159,1.8932,7.4772,0.0,0.0,1.5036,5.7615,370.29,370.76,349.6
162.16238,2.191,7.4864,0.0,0.0,1.4983,6.6099,370.23,370.73,349.62
162.16318,1.9615,7.4757,0.0,0.0,1.5005,6.014,370.16,370.69,349.65
162.16398,1.9652,7.4675,0.0,0.0,1.5017,5.924,370.09,370.65,349.67
162.16478,2.2434,7.4868,0.0,0.0,1.502,6.8256,370.03,370.61,349.7
162.16558,1.8247,7.4805,0.0,0.0,1.4983,5.5358,369.96,370.56,349.72
162.16638,2.2148,7.4686,0.0,0.0,1.4994,6.7014,369.89,370.52,349.74
162.16718,1.9723,7.4786,0.0,0.0,1.5038,6.0221,369.82,370.48,349.77
162.16798,1.9582,7.4801,0.0,0.0,1.4986,5.8498,369.75,370.44,349.79
162.16878,2.1941,7.4772,0.0,0.0,1.4983,6.6825,369.69,370.4,349.82
162.16958,1.8519,7.4687,0.0,0.0,1.5015,5.6336,369.62,370.36,349.84
162.17038,2.1808,7.4737,0.0,0.0,1.5007,6.6317,369.55,370.32,349.87
162.17118,1.9477,7.4816,0.0,0.0,1.4974,5.9521,369.48,370.28,349.89
162.17197,1.9618,7.4711,0.0,0.0,1.4994,5.939,369.42,370.24,349.91
162.17277,2.0992,7.4684,0.0,0.0,1.501,6.4158,369.33,370.2,349.93
162.17357,1.8398,7.4827,0.0,0.0,1.4989,5.5574,369.25,370.17,349.95
162.17437,2.1561,7.4756,0.0,0.0,1.4973,6.5232,369.16,370.13,349.97
162.17517,1.9231,7.4653,0.0,0.0,1.4986,5.8931,369.08,370.1,349.99
162.17597,1.9775,7.4788,0.0,0.0,1.5019,5.9159,368.99,370.07,350.01
162.17677,2.1262,7.4809,0.0,0.0,1.4995,6.4795,368.91,370.03,350.03
162.17757,1.795,7.469,0.0,0.0,1.4962,5.4413,368.82,370.0,350.05
162.17837,2.1919,7.4714,0.0,0.0,1.5026,6.6482,368.74,369.97,350.07
162.17917,1.8568,7.4778,0.0,0.0,1.5009,5.6792,368.65,369.93,350.09
162.17997,2.0238,7.4772,0.0,0.0,1.4968,6.0844,368.57,369.9,350.11
162.18077,2.0358,7.4685,0.0,0.0,1.4998,6.2139,368.48,369.86,350.13
162.18156,1.8442,7.4706,0.0,0.0,1.5005,5.6033,368.4,369.83,350.15
162.18236,2.1503,7.4836,0.0,0.0,1.4995,6.5458,368.32,369.79,350.17
162.18316,1.8542,7.4739,0.0,0.0,1.4975,5.6394,368.24,369.75,350.19
162.18396,2.0545,7.4671,0.0,0.0,1.4991,6.152,368.17,369.72,350.2
162.18476,2.0188,7.4809,0.0,0.0,1.5019,6.1645,368.09,369.68,350.22
162.18556,1.8726,7.4762,0.0,0.0,1.4973,5.5969,368.01,369.64,350.24
162.18636,2.1499,7.472,0.0,0.0,1.4983,6.5211,367.93,369.6,350.26
162.18716,1.8312,7.4728,0.0,0.0,1.5021,5.5635,367.86,369.56,350.28
162.18796,2.0696,7.4769,0.0,0.0,1.499,6.228,367.78,369.52,350.3
162.18876,1.9847,7.4771,0.0,0.0,1.498,6.0915,367.7,369.48,350.32
162.18956,1.8879,7.4658,0.0,0.0,1.4993,5.7138,367.62,369.45,350.34
162.19036,2.1521,7.4749,0.0,0.0,1.501,6.5933,367.55,369.41,350.36
162.19115,1.8293,7.484,0.0,0.0,1.4991,5.5616,367.47,369.37,350.38
162.19195,2.1097,7.4695,0.0,0.0,1.4976,6.3879,367.39,369.33,350.4
162.19275,1.9362,7.4707,0.0,0.0,1.5002,5.9352,367.31,369.27,350.42
162.19355,1.9417,7.4827,0.0,0.0,1.5018,5.8431,367.23,369.22,350.43
162.19435,2.1278,7.4734,0.0,0.0,1.497,6.4599,367.15,369.16,350.45
162.19515,1.8229,7.4693,0.0,0.0,1.4984,5.5406,367.07,369.11,350.47
162.19595,2.1377,7.478,0.0,0.0,1.5036,6.4447,366.99,369.05,350.48
162.19675,1.9285,7.4786,0.0,0.0,1.4989,5.8933,366.91,369.0,350.5
162.19755,1.9695,7.4725,0.0,0.0,1.4972,5.9302,366.83,368.94,350.52
162.19835,2.1065,7.4704,0.0,0.0,1.5019,6.4185,366.75,368.88,350.54
162.19915,1.8284,7.4786,0.0,0.0,1.5006,5.5443,366.67,368.83,350.55
162.19995,2.1516,7.4796,0.0,0.0,1.4983,6.5131,366.59,368.77,350.57
162.20075,1.9044,7.4671,0.0,0.0,1.4976,5.8005,366.51,368.72,350.59
162.20154,2.0134,7.4742,0.0,0.0,1.5012,6.0785,366.43,368.66,350.6
162.20234,2.1001,7.4846,0.0,0.0,1.5014,6.4053,366.35,368.59,350.62
162.20314,1.8463,7.4679,0.0,0.0,1.4949,5.5901,366.26,368.52,350.64
162.20394,2.1871,7.4727,0.0,0.0,1.5009,6.5835,366.17,368.44,350.66
162.20474,1.8922,7.479,0.0,0.0,1.5032,5.7311,366.08,368.36,350.68
162.20554,2.0725,7.474,0.0,0.0,1.4967,6.2524,365.99,368.28,350.7
162.20634,2.0655,7.4719,0.0,0.0,1.4983,6.3438,365.9,368.21,350.72
162.20714,1.8847,7.4724,0.0,0.0,1.5028,5.7297,365.81,368.13,350.74
162.20794,2.1755,7.4825,0.0,0.0,1.5009,6.5994,365.72,368.05,350.76
162.20874,1.8773,7.4749,0.0,0.0,1.4963,5.6922,365.63,367.98,350.78
162.20954,2.1123,7.4654,0.0,0.0,1.4983,6.3996,365.54,367.9,350.8
162.21034,2.042,7.4802,0.0,0.0,1.503,6.2527,365.45,367.82,350.82
162.21113,1.9127,7.4811,0.0,0.0,1.4988,5.7705,365.36,367.74,350.83
162.21193,2.18,7.4688,0.0,0.0,1.4959,6.6307,365.28,367.67,350.85
162.21273,1.853,7.4731,0.0,0.0,1.5021,5.6351,365.19,367.6,350.88
162.21353,2.1351,7.4801,0.0,0.0,1.5026,6.4397,365.11,367.53,350.9
162.21433,2.0192,7.475,0.0,0.0,1.496,6.1642,365.03,367.46,350.93
162.21513,1.9596,7.4716,0.0,0.0,1.4992,5.9107,364.95,367.39,350.95
162.21593,2.1615,7.4731,0.0,0.0,1.5033,6.5786,364.86,367.32,350.98
162.21673,1.8833,7.4789,0.0,0.0,1.4974,5.7401,364.78,367.25,351.0
162.21753,2.1855,7.4777,0.0,0.0,1.4979,6.5919,364.7,367.18,351.02
162.21833,1.9754,7.467,0.0,0.0,1.5007,5.9915,364.62,367.11,351.05
162.21913,2.0157,7.4778,0.0,0.0,1.501,6.0665,364.53,367.04,351.07
162.21993,2.1917,7.4845,0.0,0.0,1.4999,6.6327,364.45,366.97,351.1
162.22072,1.883,7.4647,0.0,0.0,1.4955,5.7164,364.37,366.9,351.12
162.22152,2.1977,7.4729,0.0,0.0,1.5025,6.6495,364.29,366.83,351.15
162.22232,1.9643,7.4829,0.0,0.0,1.5022,5.9715,364.2,366.76,351.17
162.22312,2.0675,7.4739,0.0,0.0,1.4952,6.2165,364.12,366.69,351.19
162.22392,2.1603,7.4713,0.0,0.0,1.5008,6.5501,364.03,366.62,351.22
162.22472,1.9153,7.4736,0.0,0.0,1.5026,5.8129,363.95,366.55,351.24
162.22552,2.2167,7.4826,0.0,0.0,1.4978,6.7463,363.86,366.49,351.27
162.22632,1.9412,7.4738,0.0,0.0,1.4983,5.9141,363.78,366.42,351.29
162.22712,2.0934,7.4624,0.0,0.0,1.4999,6.3295,363.7,366.35,351.31
162.22792,2.1261,7.4821,0.0,0.0,1.5014,6.4769,363.61,366.28,351.34
162.22872,1.9129,7.4825,0.0,0.0,1.4973,5.7841,363.53,366.22,351.36
162.22952,2.2315,7.4634,0.0,0.0,1.4968,6.7679,363.44,366.15,351.39
162.23031,1.9109,7.4749,0.0,0.0,1.5035,5.8578,363.36,366.08,351.41
162.23111,2.1297,7.482,0.0,0.0,1.4999,6.3979,363.27,366.01,351.44
162.23191,2.0626,7.4735,0.0,0.0,1.4945,6.2898,363.19,365.94,351.46
162.23271,1.9533,7.468,0.0,0.0,1.5012,5.8846,363.11,365.88,351.47
162.23351,2.2187,7.4754,0.0,0.0,1.5036,6.7518,363.03,365.81,351.49
162.23431,1.9034,7.4825,0.0,0.0,1.496,5.7694,362.95,365.74,351.5
162.23511,2.1596,7.4718,0.0,0.0,1.4985,6.4887,362.87,365.67,351.52
162.23591,2.0251,7.4646,0.0,0.0,1.5018,6.19,362.79,365.61,351.53
162.23671,1.9771,7.4826,0.0,0.0,1.5002,5.9483,362.71,365.54,351.55
162.23751,2.2069,7.483,0.0,0.0,1.4979,6.7116,362.63,365.47,351.56
162.23831,1.8672,7.4609,0.0,0.0,1.4966,5.7174,362.55,365.4,351.58
162.23911,2.1739,7.4761,0.0,0.0,1.5034,6.5793,362.47,365.33,351.59
162.2399,1.9737,7.483,0.0,0.0,1.4996,6.02,362.39,365.27,351.61
162.2407,1.9853,7.4688,0.0,0.0,1.4924,6.0059,362.31,365.2,351.62
162.2415,2.1818,7.47,0.0,0.0,1.5033,6.6443,362.23,365.13,351.63
162.2423,1.8822,7.4749,0.0,0.0,1.5028,5.677,362.15,365.06,351.65
162.2431,2.1983,7.4825,0.0,0.0,1.4953,6.6063,362.08,365.0,351.66
162.2439,1.9475,7.4683,0.0,0.0,1.4986,5.9432,362.01,364.93,351.68
162.2447,2.0345,7.4624,0.0,0.0,1.502,6.1225,361.94,364.86,351.69
162.2455,2.1432,7.488,0.0,0.0,1.5007,6.5279,361.87,364.79,351.71
162.2463,1.9007,7.4783,0.0,0.0,1.4951,5.7271,361.8,364.72,351.72
162.2471,2.2071,7.46,0.0,0.0,1.4979,6.6853,361.73,364.66,351.74
162.2479,1.9149,7.4792,0.0,0.0,1.5044,5.8389,361.66,364.59,351.75
162.2487,2.0399,7.4829,0.0,0.0,1.4986,6.188,361.59,364.52,351.76
162.2495,2.1068,7.4686,0.0,0.0,1.4944,6.4468,361.52,364.45,351.78
162.25029,1.8878,7.4668,0.0,0.0,1.5024,5.7221,361.45,364.38,351.79
162.25109,2.1923,7.4777,0.0,0.0,1.5024,6.6155,361.38,364.32,351.81
162.25189,1.8873,7.4822,0.0,0.0,1.4956,5.7306,361.31,364.25,351.82
162.25269,2.0726,7.4691,0.0,0.0,1.4997,6.2527,361.22,364.17,351.85
162.25349,2.0481,7.4661,0.0,0.0,1.5016,6.2777,361.13,364.09,351.87
162.25429,1.9046,7.4842,0.0,0.0,1.4988,5.7476,361.03,364.02,351.9
162.25509,2.2009,7.4755,0.0,0.0,1.4963,6.6566,360.94,363.94,351.92
162.25589,1.8659,7.4614,0.0,0.0,1.4982,5.6878,360.85,363.86,351.94
162.25669,2.1084,7.4804,0.0,0.0,1.5031,6.3751,360.76,363.78,351.97
162.25749,2.0265,7.4815,0.0,0.0,1.4978,6.1713,360.67,363.71,351.99
162.25829,1.9112,7.466,0.0,0.0,1.4946,5.74,360.57,363.63,352.02
162.25909,2.1637,7.4723,0.0,0.0,1.5038,6.6068,360.48,363.55,352.04
162.25988,1.8384,7.4769,0.0,0.0,1.5006,5.6127,360.39,363.47,352.07
162.26068,2.1222,7.4762,0.0,0.0,1.4946,6.3795,360.3,363.4,352.09
162.26148,1.9573,7.4695,0.0,0.0,1.5,5.9827,360.21,363.32,352.11
162.26228,1.9558,7.4672,0.0,0.0,1.501,5.8999,360.11,363.24,352.14
162.26308,2.1403,7.4844,0.0,0.0,1.4989,6.5084,360.01,363.16,352.16
162.26388,1.8432,7.4745,0.0,0.0,1.4969,5.6103,359.92,363.09,352.18
162.26468,2.1503,7.4628,0.0,0.0,1.4983,6.5194,359.82,363.01,352.2
162.26548,1.9318,7.4815,0.0,0.0,1.5026,5.8859,359.72,362.93,352.22
162.26628,1.9763,7.4777,0.0,0.0,1.4965,5.9626,359.63,362.85,352.25
162.26708,2.133,7.4691,0.0,0.0,1.4971,6.481,359.53,362.78,352.27
162.26788,1.8487,7.4713,0.0,0.0,1.5026,5.6042,359.43,362.7,352.29
162.26868,2.1803,7.4769,0.0,0.0,1.4996,6.6178,359.34,362.62,352.31
162.26947,1.9007,7.4765,0.0,0.0,1.4961,5.8105,359.24,362.54,352.33
162.27027,2.0499,7.468,0.0,0.0,1.5001,6.1283,359.14,362.47,352.35
162.27107,2.0876,7.4728,0.0,0.0,1.5014,6.4122,359.05,362.39,352.38
162.27187,1.8626,7.4799,0.0,0.0,1.4977,5.6347,358.95,362.31,352.4
162.27267,2.1771,7.4731,0.0,0.0,1.4982,6.6323,358.87,362.24,352.41
162.27347,1.8955,7.468,0.0,0.0,1.5,5.7722,358.8,362.18,352.42
162.27427,2.0762,7.4786,0.0,0.0,1.5007,6.2828,358.72,362.11,352.43
162.27507,2.064,7.4775,0.0,0.0,1.497,6.3102,358.65,362.04,352.45
162.27587,1.8945,7.4688,0.0,0.0,1.4981,5.6938,358.57,361.97,352.46
162.27667,2.1924,7.4755,0.0,0.0,1.5031,6.6614,358.5,361.9,352.47
162.27747,1.8884,7.4789,0.0,0.0,1.4994,5.7217,358.42,361.84,352.48
162.27827,2.1143,7.4752,0.0,0.0,1.4968,6.3805,358.35,361.77,352.5
162.27906,2.0319,7.4703,0.0,0.0,1.5018,6.2017,358.27,361.7,352.51
162.27986,1.946,7.4714,0.0,0.0,1.4991,5.8345,358.2,361.63,352.52
162.28066,2.205,7.4824,0.0,0.0,1.4988,6.6727,358.12,361.57,352.53
162.28146,1.8742,7.4696,0.0,0.0,1.4983,5.6935,358.05,361.5,352.54
162.28226,2.1639,7.4707,0.0,0.0,1.5008,6.5675,357.97,361.43,352.55
162.28306,2.0119,7.4862,0.0,0.0,1.5021,6.1652,357.89,361.37,352.56
162.28386,1.9782,7.4732,0.0,0.0,1.4965,5.9061,357.82,361.31,352.57
162.28466,2.1829,7.4686,0.0,0.0,1.499,6.658,357.74,361.24,352.58
162.28546,1.8888,7.4782,0.0,0.0,1.5031,5.7159,357.66,361.18,352.58
162.28626,2.181,7.4804,0.0,0.0,1.4991,6.5875,357.58,361.12,352.59
162.28706,1.9848,7.4756,0.0,0.0,1.4987,6.0412,357.51,361.05,352.6
162.28786,2.0242,7.4686,0.0,0.0,1.5014,6.0736,357.43,360.99,352.6
162.28865,2.1676,7.4788,0.0,0.0,1.5011,6.6009,357.35,360.93,352.61
162.28945,1.8878,7.4805,0.0,0.0,1.4986,5.7439,357.27,360.87,352.62
162.29025,2.2167,7.4699,0.0,0.0,1.4995,6.6798,357.2,360.8,352.63
162.29105,1.9732,7.4729,0.0,0.0,1.5004,6.0258,357.12,360.74,352.63
162.29185,2.0541,7.485,0.0,0.0,1.5009,6.2172,357.04,360.68,352.64
162.29265,2.1462,7.4759,0.0,0.0,1.499,6.5375,356.96,360.61,352.65
162.29345,1.896,7.469,0.0,0.0,1.4994,5.7495,356.88,360.54,352.65
162.29425,2.2169,7.482,0.0,0.0,1.5031,6.6914,356.8,360.47,352.66
162.29505,1.9366,7.4774,0.0,0.0,1.4979,5.8978,356.72,360.4,352.66
162.29585,2.109,7.4727,0.0,0.0,1.4985,6.3548,356.64,360.33,352.67
162.29665,2.1154,7.4764,0.0,0.0,1.5043,6.464,356.56,360.26,352.67
162.29745,1.931,7.4784,0.0,0.0,1.4993,5.8327,356.48,360.18,352.68
162.29824,2.2161,7.4799,0.0,0.0,1.4987,6.7445,356.4,360.11,352.68
162.29904,1.9134,7.4689,0.0,0.0,1.5006,5.8403,356.32,360.04,352.68
162.29984,2.1416,7.4767,0.0,0.0,1.5013,6.4594,356.24,359.97,352.69
162.30064,2.0739,7.485,0.0,0.0,1.5002,6.3327,356.16,359.9,352.69
162.30144,1.9486,7.4707,0.0,0.0,1.4977,5.9017,356.08,359.83,352.7
162.30224,2.2177,7.4746,0.0,0.0,1.5018,6.7455,356.0,359.76,352.71
162.30304,1.9101,7.4838,0.0,0.0,1.5021,5.7971,355.93,359.69,352.73
162.30384,2.1733,7.4772,0.0,0.0,1.4979,6.5372,355.85,359.62,352.74
162.30464,2.0528,7.4725,0.0,0.0,1.5,6.2285,355.78,359.54,352.76
162.30544,1.9875,7.4755,0.0,0.0,1.5031,6.0152,355.7,359.47,352.78
162.30624,2.2149,7.4823,0.0,0.0,1.4993,6.729,355.63,359.4,352.79
162.30704,1.9043,7.476,0.0,0.0,1.4986,5.7961,355.55,359.33,352.81
162.30784,2.1935,7.47,0.0,0.0,1.5012,6.6372,355.48,359.25,352.83
162.30863,1.9982,7.4809,0.0,0.0,1.5015,6.1384,355.4,359.18,352.84
162.30943,2.0317,7.4811,0.0,0.0,1.4983,6.1383,355.33,359.11,352.86
162.31023,2.1975,7.4696,0.0,0.0,1.4984,6.7011,355.25,359.04,352.88
162.31103,1.9017,7.4761,0.0,0.0,1.5032,5.7839,355.18,358.96,352.9
162.31183,2.2148,7.4833,0.0,0.0,1.501,6.6792,355.1,358.89,352.91
162.31263,1.9709,7.4744,0.0,0.0,1.4959,6.0119,355.03,358.83,352.93
162.31343,2.0522,7.4745,0.0,0.0,1.5015,6.2236,354.95,358.77,352.94
162.31423,2.1656,7.478,0.0,0.0,1.5036,6.6019,354.87,358.71,352.95
162.31503,1.9217,7.4772,0.0,0.0,1.4961,5.8125,354.79,358.65,352.96
162.31583,2.217,7.476,0.0,0.0,1.4996,6.7336,354.72,358.59,352.97
162.31663,1.9383,7.4696,0.0,0.0,1.5024,5.9166,354.64,358.53,352.99
162.31743,2.0882,7.48,0.0,0.0,1.4997,6.3051,354.56,358.47,353.0
162.31822,2.1382,7.4819,0.0,0.0,1.498,6.5056,354.48,358.41,353.01
162.31902,1.9325,7.4651,0.0,0.0,1.498,5.8055,354.41,358.34,353.02
162.31982,2.2203,7.4787,0.0,0.0,1.5038,6.7375,354.33,358.28,353.03
162.32062,1.9146,7.483,0.0,0.0,1.4998,5.8325,354.25,358.22,353.05
162.32142,2.1348,7.4708,0.0,0.0,1.4957,6.3909,354.17,358.16,353.06
162.32222,2.0858,7.4746,0.0,0.0,1.5034,6.3744,354.1,358.1,353.07
162.32302,1.9439,7.4768,0.0,0.0,1.5026,5.9063,354.04,358.04,353.07
162.32382,2.2199,7.4785,0.0,0.0,1.4962,6.7486,353.98,357.98,353.08
162.32462,1.9134,7.4714,0.0,0.0,1.4994,5.797,353.92,357.92,353.08
162.32542,2.1515,7.4693,0.0,0.0,1.5031,6.4986,353.86,357.86,353.09
162.32622,2.036,7.4837,0.0,0.0,1.4998,6.2053,353.8,357.8,353.09
162.32702,1.9766,7.4776,0.0,0.0,1.4965,5.9464,353.74,357.74,353.1
162.32781,2.2055,7.4658,0.0,0.0,1.4995,6.7241,353.68,357.68,353.1
162.32861,1.8956,7.48,0.0,0.0,1.5036,5.7515,353.62,357.62,353.11
162.32941,2.1876,7.4843,0.0,0.0,1.4989,6.5936,353.56,357.56,353.11
162.33021,1.9911,7.4702,0.0,0.0,1.4963,6.0901,353.5,357.5,353.12
162.33101,1.9935,7.4706,0.0,0.0,1.5028,5.9877,353.44,357.44,353.12
162.33181,2.1905,7.4812,0.0,0.0,1.5029,6.6494,353.38,357.38,353.13
162.33261,1.8834,7.476,0.0,0.0,1.4946,5.6922,353.31,357.31,353.14
162.33341,2.2001,7.4708,0.0,0.0,1.5003,6.65,353.25,357.25,353.15
162.33421,1.9699,7.4698,0.0,0.0,1.5039,6.0081,353.19,357.18,353.17
162.33501,2.0317,7.4859,0.0,0.0,1.4986,6.114,353.12,357.11,353.18
162.33581,2.1592,7.4789,0.0,0.0,1.498,6.5764,353.06,357.05,353.2
162.33661,1.8965,7.4602,0.0,0.0,1.4997,5.7507,353.0,356.98,353.21
162.3374,2.2084,7.4848,0.0,0.0,1.5043,6.7119,352.94,356.92,353.23
162.3382,1.9314,7.4872,0.0,0.0,1.4994,5.8934,352.87,356.85,353.24
162.339,2.064,7.4629,0.0,0.0,1.4943,6.2245,352.81,356.79,353.26
162.3398,2.1137,7.4743,0.0,0.0,1.5049,6.4083,352.75,356.72,353.27
162.3406,1.8969,7.4815,0.0,0.0,1.5022,5.7853,352.68,356.66,353.28
162.3414,2.2135,7.4801,0.0,0.0,1.4954,6.6777,352.62,356.59,353.3
162.3422,1.9072,7.4706,0.0,0.0,1.5017,5.8289,352.55,356.53,353.31
162.343,2.1161,7.4688,0.0,0.0,1.503,6.3522,352.47,356.46,353.32
162.3438,2.0776,7.4893,0.0,0.0,1.4991,6.3525,352.4,356.4,353.33
162.3446,1.9145,7.4736,0.0,0.0,1.4978,5.7648,352.32,356.34,353.34
162.3454,2.2108,7.4632,0.0,0.0,1.5011,6.7562,352.24,356.28,353.35
162.3462,1.8909,7.4856,0.0,0.0,1.5037,5.7474,352.16,356.21,353.36
162.34699,2.1344,7.4831,0.0,0.0,1.498,6.4564,352.09,356.15,353.37
162.34779,2.0402,7.4656,0.0,0.0,1.4961,6.2672,352.01,356.09,353.38
162.34859,1.9579,7.475,0.0,0.0,1.504,5.8975,351.93,356.02,353.39
162.34939,2.2041,7.4835,0.0,0.0,1.5019,6.7191,351.85,355.96,353.4
162.35019,1.8922,7.4765,0.0,0.0,1.4953,5.7262,351.78,355.9,353.41
162.35099,2.1692,7.4694,0.0,0.0,1.5023,6.5559,351.7,355.83,353.42
162.35179,1.9941,7.4735,0.0,0.0,1.5032,6.1006,351.62,355.77,353.43
162.35259,1.9729,7.4855,0.0,0.0,1.4981,5.9549,351.55,355.71,353.44
162.35339,2.1726,7.4739,0.0,0.0,1.499,6.6106,351.48,355.65,353.44
162.35419,1.8848,7.4642,0.0,0.0,1.5009,5.7342,351.41,355.58,353.45
162.35499,2.1868,7.4867,0.0,0.0,1.5021,6.6093,351.34,355.52,353.46
162.35579,1.9755,7.4848,0.0,0.0,1.4992,6.0292,351.27,355.46,353.46
162.35659,2.0198,7.4632,0.0,0.0,1.497,6.1028,351.2,355.39,353.47
162.35738,2.166,7.4776,0.0,0.0,1.5047,6.6024,351.13,355.33,353.48
162.35818,1.8812,7.4856,0.0,0.0,1.5021,5.7235,351.06,355.27,353.49
162.35898,2.2135,7.4756,0.0,0.0,1.4957,6.6776,350.99,355.2,353.49
162.35978,1.9498,7.4701,0.0,0.0,1.5021,5.9638,350.92,355.14,353.5
162.36058,2.0799,7.4755,0.0,0.0,1.5026,6.2414,350.85,355.08,353.51
162.36138,2.1383,7.4859,0.0,0.0,1.4987,6.533,350.78,355.02,353.52
162.36218,1.9314,7.4702,0.0,0.0,1.4984,5.8299,350.71,354.95,353.52
162.36298,2.2332,7.4709,0.0,0.0,1.5027,6.7645,350.64,354.89,353.53
162.36378,1.932,7.4859,0.0,0.0,1.5016,5.8877,350.57,354.83,353.54
162.36458,2.1181,7.4765,0.0,0.0,1.4967,6.3983,350.5,354.76,353.55
162.36538,2.1118,7.4694,0.0,0.0,1.4996,6.4639,350.44,354.7,353.56
162.36618,1.9448,7.4805,0.0,0.0,1.5049,5.8541,350.37,354.64,353.57
162.36697,2.2408,7.4813,0.0,0.0,1.4998,6.7861,350.3,354.58,353.58
162.36777,1.9215,7.4742,0.0,0.0,1.4967,5.8491,350.23,354.51,353.59
162.36857,2.1495,7.4738,0.0,0.0,1.5038,6.4822,350.16,354.45,353.6
162.36937,2.0945,7.4784,0.0,0.0,1.5025,6.4085,350.1,354.39,353.61
162.37017,1.9727,7.4793,0.0,0.0,1.497,5.952,350.03,354.32,353.62
162.37097,2.2429,7.4729,0.0,0.0,1.5008,6.821,349.96,354.26,353.63
162.37177,1.9226,7.4725,0.0,0.0,1.502,5.8561,349.89,354.2,353.64
162.37257,2.1875,7.4857,0.0,0.0,1.501,6.5789,349.83,354.13,353.65
162.37337,2.047,7.4784,0.0,0.0,1.4984,6.2684,349.76,354.05,353.65
162.37417,2.0035,7.4671,0.0,0.0,1.499,6.071,349.7,353.98,353.66
162.37497,2.221,7.4843,0.0,0.0,1.5049,6.746,349.63,353.91,353.66
162.37577,1.9332,7.4796,0.0,0.0,1.4988,5.8473,349.56,353.84,353.66
162.37656,2.2089,7.4743,0.0,0.0,1.4982,6.6879,349.5,353.76,353.67
162.37736,2.0229,7.4784,0.0,0.0,1.5049,6.1734,349.43,353.69,353.67
162.37816,2.0533,7.4789,0.0,0.0,1.5012,6.1859,349.37,353.62,353.68
162.37896,2.2144,7.4797,0.0,0.0,1.498,6.7244,349.3,353.54,353.68
162.37976,1.9147,7.4704,0.0,0.0,1.5009,5.8153,349.24,353.47,353.69
162.38056,2.2432,7.4766,0.0,0.0,1.5029,6.7784,349.17,353.4,353.69
162.38136,1.9973,7.4867,0.0,0.0,1.5009,6.0897,349.11,353.33,353.7
162.38216,2.087,7.4723,0.0,0.0,1.4975,6.2912,349.04,353.25,353.7
162.38296,2.1747,7.4742,0.0,0.0,1.5015,6.6589,348.99,353.18,353.71
162.38376,1.9441,7.4844,0.0,0.0,1.5033,5.8789,348.94,353.11,353.72
162.38456,2.2481,7.4806,0.0,0.0,1.4989,6.8076,348.88,353.04,353.73
162.38536,1.9618,7.4726,0.0,0.0,1.4995,5.9999,348.83,352.96,353.73
162.38615,2.1523,7.4772,0.0,0.0,1.5039,6.4687,348.78,352.89,353.74
162.38695,2.142,7.4805,0.0,0.0,1.5004,6.5574,348.72,352.82,353.75
162.38775,1.957,7.4783,0.0,0.0,1.4981,5.9208,348.67,352.75,353.76
162.38855,2.2523,7.4753,0.0,0.0,1.503,6.8408,348.62,352.67,353.76
162.38935,1.9489,7.4782,0.0,0.0,1.5018,5.9302,348.56,352.6,353.77
162.39015,2.1572,7.4828,0.0,0.0,1.4989,6.5021,348.51,352.53,353.78
162.39095,2.1204,7.4764,0.0,0.0,1.4999,6.4687,348.46,352.46,353.78
162.39175,1.9617,7.4744,0.0,0.0,1.502,5.9165,348.4,352.38,353.79
162.39255,2.2355,7.4841,0.0,0.0,1.5019,6.7845,348.34,352.32,353.8
162.39335,1.918,7.4766,0.0,0.0,1.498,5.8272,348.28,352.26,353.81
162.39415,2.1737,7.4748,0.0,0.0,1.501,6.5533,348.21,352.21,353.81
162.39495,2.0727,7.4801,0.0,0.0,1.5045,6.3352,348.15,352.15,353.82
162.39574,1.9925,7.4782,0.0,0.0,1.4986,6.0135,348.09,352.09,353.83
162.39654,2.2222,7.4782,0.0,0.0,1.4999,6.7791,348.03,352.03,353.84
162.39734,1.9088,7.4713,0.0,0.0,1.5025,5.7915,347.96,351.97,353.84
162.39814,2.2035,7.4793,0.0,0.0,1.501,6.6473,347.9,351.91,353.85
162.39894,2.0138,7.4838,0.0,0.0,1.5,6.1701,347.84,351.86,353.86
162.39974,2.028,7.4709,0.0,0.0,1.4996,6.1119,347.77,351.8,353.86
162.40054,2.1834,7.4786,0.0,0.0,1.5033,6.6495,347.71,351.74,353.87
162.40134,1.9062,7.4806,0.0,0.0,1.4995,5.7813,347.65,351.68,353.88
162.40214,2.2161,7.4758,0.0,0.0,1.4979,6.6986,347.58,351.62,353.88
162.40294,1.9843,7.477,0.0,0.0,1.5032,6.0627,347.51,351.56,353.89
162.40374,2.0577,7.4781,0.0,0.0,1.5031,6.1967,347.45,351.5,353.89
162.40454,2.1813,7.4785,0.0,0.0,1.4974,6.6779,347.38,351.43,353.89
162.40533,1.919,7.4757,0.0,0.0,1.5006,5.8198,347.31,351.37,353.89
162.40613,2.2269,7.4733,0.0,0.0,1.5036,6.7241,347.24,351.31,353.9
162.40693,1.9519,7.4839,0.0,0.0,1.5009,5.964,347.17,351.24,353.9
162.40773,2.0922,7.4788,0.0,0.0,1.4986,6.3196,347.11,351.18,353.9
162.40853,2.1407,7.471,0.0,0.0,1.5005,6.5561,347.04,351.12,353.9
162.40933,1.9272,7.4793,0.0,0.0,1.5026,5.8558,346.97,351.06,353.91
162.41013,2.2411,7.4863,0.0,0.0,1.5006,6.7714,346.9,350.99,353.91
162.41093,1.9285,7.469,0.0,0.0,1.4963,5.8626,346.83,350.93,353.91
162.41173,2.1243,7.4753,0.0,0.0,1.503,6.395,346.77,350.87,353.91
162.41253,2.1058,7.4841,0.0,0.0,1.5041,6.4046,346.71,350.81,353.92
162.41333,1.9391,7.4744,0.0,0.0,1.4955,5.8913,346.65,350.74,353.94
162.41413,2.2115,7.4752,0.0,0.0,1.5013,6.7581,346.6,350.68,353.95
162.41493,1.9233,7.4746,0.0,0.0,1.5038,5.8509,346.54,350.62,353.96
162.41572,2.1597,7.4844,0.0,0.0,1.4997,6.4805,346.48,350.56,353.97
162.41652,2.0766,7.4793,0.0,0.0,1.4986,6.3324,346.43,350.5,353.98
162.41732,1.9821,7.4669,0.0,0.0,1.5004,6.018,346.37,350.44,354.0
162.41812,2.217,7.4829,0.0,0.0,1.5032,6.7319,346.32,350.38,354.01
162.41892,1.9054,7.4845,0.0,0.0,1.4989,5.8158,346.26,350.32,354.02
162.41972,2.1919,7.4707,0.0,0.0,1.4982,6.5975,346.21,350.26,354.03
162.42052,2.0219,7.4756,0.0,0.0,1.5038,6.1913,346.15,350.2,354.04
162.42132,2.0126,7.4813,0.0,0.0,1.5019,6.0771,346.09,350.14,354.06
162.42212,2.2296,7.4791,0.0,0.0,1.4968,6.7879,346.04,350.08,354.07
162.42292,1.9139,7.4749,0.0,0.0,1.503,5.8351,345.98,350.04,354.08
162.42372,2.2195,7.4737,0.0,0.0,1.5034,6.7093,345.91,350.0,354.09
162.42452,2.0118,7.4873,0.0,0.0,1.4988,6.1198,345.85,349.96,354.1
162.42531,2.0563,7.4779,0.0,0.0,1.4991,6.1755,345.79,349.92,354.11
162.42611,2.185,7.4687,0.0,0.0,1.5028,6.6682,345.73,349.88,354.12
162.42691,1.9252,7.484,0.0,0.0,1.5021,5.8423,345.67,349.84,354.13
162.42771,2.2304,7.4859,0.0,0.0,1.4991,6.7733,345.61,349.79,354.14
162.42851,1.9771,7.4673,0.0,0.0,1.4983,6.0087,345.55,349.75,354.15
162.42931,2.0863,7.4755,0.0,0.0,1.5041,6.3208,345.49,349.71,354.16
162.43011,2.174,7.4875,0.0,0.0,1.5029,6.6205,345.43,349.67,354.17
162.43091,1.9453,7.4761,0.0,0.0,1.4955,5.8928,345.37,349.63,354.17
162.43171,2.2481,7.4746,0.0,0.0,1.5038,6.8167,345.31,349.59,354.18
162.43251,1.9518,7.4766,0.0,0.0,1.5043,5.9505,345.25,349.54,354.18
162.43331,2.1263,7.4862,0.0,0.0,1.4975,6.4051,345.2,349.49,354.17
162.43411,2.1334,7.4777,0.0,0.0,1.5006,6.5028,345.15,349.44,354.17
162.4349,1.9519,7.4637,0.0,0.0,1.5021,5.934,345.1,349.39,354.16
162.4357,2.2485,7.4871,0.0,0.0,1.5021,6.8208,345.05,349.35,354.15
162.4365,1.9391,7.4874,0.0,0.0,1.4992,5.9063,345.0,349.3,354.15
162.4373,2.165,7.4623,0.0,0.0,1.4975,6.5385,344.95,349.25,354.14
162.4381,2.1018,7.4792,0.0,0.0,1.5056,6.3864,344.9,349.2,354.13
162.4389,1.9888,7.488,0.0,0.0,1.5012,6.0029,344.85,349.15,354.12
162.4397,2.2554,7.4754,0.0,0.0,1.4955,6.8448,344.8,349.1,354.12
163.83979,1.9322,7.4853,0.0,0.0,1.5041,5.8642,246.37,252.43,174.63
165.43979,1.8375,7.5187,0.0,0.0,1.5186,5.5769,79.173,90.53,75.77
167.03979,1.7508,7.5429,0.0,0.0,1.529,5.3115,43.33,48.653,29.784
168.4695,1.7476,7.5534,0.0,0.0,1.5337,5.3047,32.593,39.868,24.341
170.0695,1.743,7.5621,0.0,0.0,1.5375,5.2866,27.462,30.068,22.255
171.6695,1.7386,7.5693,0.0,0.0,1.5407,5.2724,24.923,27.342,21.636
173.2695,1.8039,7.5733,0.0,0.0,1.5426,5.4701,26.794,28.568,23.253
174.8695,1.7802,7.5757,0.0,0.0,1.5434,5.4011,29.657,30.735,26.25
176.4695,1.709,7.5834,0.0,0.0,1.5471,5.1852,31.733,39.753,28.847
178.0695,1.8045,7.583,0.0,0.0,1.547,5.4759,33.003,39.754,30.786
179.2695,1.8083,7.5834,0.0,0.0,1.547,5.4879,33.689,39.754,31.884