File: examples/dan-msc-case-studies/CS4/data/01 raw data/hyde_test_040.csv
Time(sec),Force(kN),Jaw(mm),PowAngle(deg),PTemp,Strain,Stress(MPa),TC1(C),TC2(C),TC3(C)
0.0,3.7125,0.005433,0.0,0.0020111,0.00062574,11.26,20.618,21.49,20.68
0.8,3.6759,0.0053653,0.0,2.2211,0.00054872,11.147,20.431,21.146,20.414
1.6,3.6158,0.0053,0.0,4.6211,0.00059778,10.972,20.68,21.367,20.658
2.4,3.5705,0.0050305,0.0,7.0211,0.0005339,10.832,20.725,21.382,20.704
3.2,3.5537,0.0049839,0.0,9.4211,0.00059866,10.778,20.693,21.386,20.715
4.0,3.5492,0.0052915,0.0,11.821,0.00053563,10.768,20.459,21.183,20.465
4.8,3.5208,0.0053416,0.0,14.221,0.00060882,10.68,20.705,21.372,20.693
5.6,3.5147,0.0052653,0.0,16.621,0.00057577,10.661,20.72,21.425,20.745
6.3397,3.4943,0.0054509,0.0,18.841,0.00056408,10.598,20.471,21.183,20.45
7.1397,3.4757,0.0056528,4.0334,21.24,0.00063081,10.545,20.714,21.488,20.762
7.9397,3.4734,0.0072296,25.503,23.64,0.00077754,10.539,21.246,23.213,21.332
8.7397,3.4935,0.0059512,25.322,26.04,0.00070047,10.594,24.33,28.695,25.353
9.5397,3.4902,0.0053914,24.229,28.44,0.00054828,10.592,27.42,37.085,28.913
10.3397,3.4821,0.0043038,25.823,30.84,0.00048907,10.564,29.863,36.839,31.575
11.1397,3.496,0.003652,25.133,33.24,0.00038245,10.604,32.557,37.705,34.336
11.9397,3.4913,0.0027652,24.87,35.64,0.0003573,10.593,35.178,40.476,37.134
12.7397,3.4887,0.0021236,26.08,38.04,0.00019815,10.584,37.577,43.591,39.832
13.4842,3.4915,0.001249,26.182,40.274,0.00011087,10.596,39.841,45.838,42.131
14.2842,3.497,0.00034322,24.744,42.674,1.9619e-05,10.606,42.581,48.396,44.971
15.0842,3.5059,-0.0014309,25.744,45.074,-9.336e-05,10.637,44.849,50.95,47.3
15.8842,3.5092,-0.0026907,26.343,47.474,-0.00028379,10.646,47.229,53.699,49.785
16.6842,3.5057,-0.0027319,26.798,49.874,-0.00034058,10.63,49.584,55.999,52.29
17.4842,3.5122,-0.0034154,25.547,52.274,-0.00039254,10.656,52.231,58.722,55.084
18.2842,3.7674,-0.0034247,26.739,54.674,-0.00029944,11.431,54.481,61.32,57.418
19.0842,4.3259,-0.0013213,26.19,57.074,-0.00013389,13.12,56.994,63.994,60.077
19.8842,4.8003,-0.0002179,27.862,59.474,-7.4119e-05,14.566,59.143,66.595,62.552
20.6842,5.1671,0.00099449,25.683,61.874,0.00010513,15.674,61.931,69.285,65.573
21.4842,5.219,0.00021234,27.732,64.274,8.0896e-05,15.828,63.923,72.073,67.688
22.2842,5.1429,-0.0012812,26.121,66.674,-0.00011972,15.603,66.688,74.82,70.799
23.0842,4.9514,-0.0043775,27.109,69.074,-0.00053958,15.021,68.932,77.568,73.203
23.8842,4.5843,-0.0061874,26.935,71.474,-0.0006772,13.905,71.436,80.27,75.897
24.6842,4.1399,-0.0088061,27.431,73.874,-0.00091089,12.561,73.78,82.763,78.375
25.4842,3.6551,-0.011646,27.426,76.274,-0.001233,11.091,76.171,85.139,80.81
26.2842,3.2173,-0.014209,28.048,78.674,-0.0016147,9.7591,78.524,87.821,83.303
27.0842,2.848,-0.016656,28.153,81.074,-0.0017922,8.6423,80.952,90.23,85.753
27.8842,2.5567,-0.019177,28.741,83.474,-0.0020812,7.754,83.261,92.74,88.159
28.6842,2.3485,-0.021906,28.494,85.874,-0.0023809,7.1216,85.83,95.653,91.043
29.4842,2.2888,-0.024166,29.165,88.274,-0.0026872,6.9457,88.087,97.354,93.204
30.2842,2.3255,-0.02502,28.674,90.674,-0.0026975,7.0529,90.579,100.08,95.598
31.0842,2.3477,-0.025205,28.796,93.074,-0.0027622,7.1221,93.017,102.52,98.106
31.8842,2.3643,-0.0266,29.565,95.474,-0.0028476,7.1761,95.33,104.76,100.4
32.6842,2.3827,-0.027494,29.285,97.874,-0.0030435,7.2262,97.784,107.25,102.93
33.48421,2.3945,-0.028599,29.26,100.27,-0.003113,7.2633,100.21,109.63,105.42
34.28421,2.3999,-0.02988,30.541,102.67,-0.0032701,7.2834,102.49,112.09,107.75
35.08421,2.4075,-0.032148,29.966,105.07,-0.0034614,7.3021,104.99,114.65,110.3
35.88421,2.4189,-0.033694,29.875,107.47,-0.0036912,7.3392,107.37,116.78,112.73
36.68421,2.4073,-0.033749,29.797,109.87,-0.0036905,7.3067,109.76,119.32,115.14
37.48421,2.4067,-0.035246,30.797,112.27,-0.0038857,7.2974,112.14,122.18,117.74
38.28421,2.4154,-0.036526,30.252,114.67,-0.0039218,7.3276,114.62,124.23,120.25
38.9793,2.4142,-0.037328,30.593,116.76,-0.0041416,7.3231,116.68,126.63,122.34
39.7793,2.4248,-0.038677,30.169,119.16,-0.0042006,7.3532,119.13,129.02,124.96
40.5793,2.4291,-0.042172,30.449,121.56,-0.0045977,7.3724,121.5,131.53,127.39
41.3793,2.4183,-0.041846,29.796,123.96,-0.0045435,7.3364,124.09,134.04,130.1
42.1793,2.425,-0.042999,30.918,126.36,-0.0047378,7.3534,126.21,136.38,132.28
42.9793,2.4223,-0.044515,30.866,128.76,-0.0048427,7.3485,128.75,139.17,135.0
43.7793,2.4222,-0.04554,31.684,131.16,-0.0049919,7.3465,130.9,141.31,137.22
44.493,2.4294,-0.048573,30.595,133.3,-0.0052713,7.3733,133.36,143.89,139.87
45.293,2.4163,-0.049633,31.921,135.7,-0.00538,7.3323,135.5,146.59,142.11
46.093,2.4182,-0.049938,31.605,138.1,-0.0055081,7.3347,137.95,148.76,144.79
46.893,2.4231,-0.051324,30.88,140.5,-0.0055803,7.3525,140.63,151.62,147.6
47.693,2.4258,-0.052784,32.883,142.9,-0.0057682,7.357,142.59,153.81,149.49
48.493,2.4269,-0.055504,31.651,145.3,-0.0060094,7.3604,145.3,156.82,152.45
49.293,2.4287,-0.056829,32.252,147.7,-0.0062193,7.3691,147.57,158.78,154.68
50.093,2.4211,-0.057504,31.928,150.1,-0.0062795,7.3448,150.09,161.7,157.33
50.893,2.4287,-0.058846,31.893,152.5,-0.0064543,7.3668,152.51,164.06,159.76
51.693,2.4312,-0.060439,32.413,154.9,-0.0065222,7.3794,154.84,166.71,162.23
52.493,2.4258,-0.061744,31.612,157.3,-0.0067351,7.3615,157.45,169.6,165.11
53.293,2.4352,-0.065261,32.387,159.7,-0.0071826,7.3872,159.64,171.54,167.28
54.093,2.4225,-0.065228,33.37,162.1,-0.007105,7.3519,161.86,174.03,169.55
54.893,2.4184,-0.06628,32.124,164.5,-0.0072018,7.336,164.54,176.38,172.26
55.693,2.4277,-0.068025,32.902,166.9,-0.0073857,7.3661,166.76,178.95,174.54
56.493,2.4258,-0.069294,33.078,169.3,-0.0076092,7.362,169.19,181.52,177.2
57.293,2.4297,-0.070845,33.84,171.7,-0.0077118,7.3698,171.44,184.0,179.45
58.093,2.4332,-0.074228,31.674,174.1,-0.0081128,7.3808,174.41,186.71,182.58
58.893,2.4239,-0.074979,33.526,176.5,-0.0080967,7.3561,176.32,188.75,184.35
59.693,2.4197,-0.075939,33.182,178.9,-0.0082751,7.3396,178.85,191.53,187.22
60.493,2.4321,-0.076968,33.586,181.3,-0.0084294,7.38,181.25,193.9,189.66
61.293,2.4263,-0.078419,33.482,183.7,-0.0085537,7.3641,183.66,196.3,192.1
62.093,2.4284,-0.080218,33.564,186.1,-0.0086981,7.3634,186.06,198.89,194.6
62.893,2.4313,-0.081718,33.796,188.5,-0.0088787,7.3762,188.36,201.28,197.0
63.693,2.4254,-0.084946,33.127,190.9,-0.0093277,7.3583,190.99,203.92,199.65
64.49301,2.4307,-0.086549,33.559,193.3,-0.0094004,7.3735,193.29,206.08,201.99
65.29301,2.4268,-0.086746,33.331,195.7,-0.0094744,7.3638,195.73,208.65,204.45
66.09301,2.4223,-0.088765,33.307,198.1,-0.0095959,7.3507,198.16,211.08,206.94
66.89301,2.4282,-0.090066,33.978,200.5,-0.009806,7.3627,200.38,213.42,209.27
67.69301,2.4299,-0.091135,32.761,202.9,-0.0099834,7.3725,203.12,216.14,212.06
68.49301,2.4252,-0.092752,33.742,205.3,-0.010094,7.3617,205.25,218.52,214.18
69.29301,2.4358,-0.09435,33.737,207.7,-0.010268,7.3877,207.69,220.95,216.7
70.09301,2.4364,-0.098757,33.672,210.1,-0.010717,7.3942,210.11,223.49,219.2
70.89301,2.4198,-0.09846,33.813,212.5,-0.010757,7.3405,212.47,226.0,221.76
71.608,2.4291,-0.099005,33.772,214.65,-0.01081,7.3695,214.65,228.23,223.97
72.408,2.4233,-0.10097,33.766,217.05,-0.010927,7.3543,217.01,230.63,226.42
73.208,2.4262,-0.10273,34.194,219.45,-0.011166,7.3603,219.39,233.13,228.8
74.008,2.4333,-0.10389,33.859,221.85,-0.011378,7.3846,221.9,235.65,231.43
74.808,2.4248,-0.1056,33.799,224.25,-0.011476,7.3572,224.24,237.92,233.74
75.4847,2.428,-0.10958,34.334,226.28,-0.01192,7.3633,226.23,239.94,235.8
76.2847,2.43,-0.10974,34.073,228.68,-0.011942,7.3691,228.68,242.34,238.29
77.0847,2.4221,-0.11065,33.911,231.08,-0.011988,7.3511,231.07,244.79,240.78
77.8847,2.418,-0.112,33.907,233.48,-0.012213,7.333,233.48,247.27,243.14
78.6847,2.4341,-0.11361,34.565,235.88,-0.012383,7.3852,235.85,249.69,245.5
79.4847,2.4284,-0.11457,33.987,238.28,-0.012484,7.3698,238.3,252.03,247.99
80.2847,2.4354,-0.11704,34.63,240.68,-0.012699,7.3848,240.64,254.45,250.44
81.0847,2.4387,-0.1213,34.616,243.08,-0.013154,7.3972,243.02,256.55,252.74
81.8847,2.4211,-0.12017,34.365,245.48,-0.01313,7.348,245.52,259.16,255.26
82.6847,2.4224,-0.12175,34.544,247.88,-0.013223,7.3467,247.89,261.55,257.64
83.4847,2.43,-0.12333,34.508,250.28,-0.013439,7.3724,250.24,263.77,260.1
84.2847,2.4231,-0.12508,34.727,252.68,-0.01353,7.3543,252.65,266.27,262.58
85.0847,2.4333,-0.12623,34.696,255.08,-0.013729,7.382,255.04,268.7,264.91
85.8847,2.4372,-0.1296,34.905,257.48,-0.014181,7.3941,257.41,270.99,267.24
86.6847,2.4264,-0.13154,35.046,259.88,-0.014273,7.3609,259.8,273.44,269.79
87.4847,2.423,-0.13165,34.931,262.28,-0.014308,7.3489,262.22,275.93,272.38
88.2847,2.4323,-0.13286,35.07,264.68,-0.014387,7.3794,264.64,278.21,274.74
89.0847,2.4231,-0.13452,34.804,267.08,-0.01465,7.3515,267.12,280.61,277.09
89.8847,2.427,-0.13603,35.352,269.48,-0.0148,7.3618,269.4,282.72,279.31
90.6847,2.4314,-0.13729,34.9,271.88,-0.014937,7.3783,271.91,285.26,281.9
91.4847,2.4274,-0.13908,35.378,274.28,-0.01508,7.3654,274.16,287.41,284.24
92.2847,2.4302,-0.14408,35.335,276.68,-0.015633,7.3711,276.66,289.77,286.66
93.0847,2.4311,-0.14348,35.388,279.08,-0.015639,7.3736,279.08,292.35,289.13
93.8847,2.4218,-0.14442,35.138,281.48,-0.015687,7.3476,281.45,294.76,291.59
94.68471,2.4248,-0.146,35.065,283.88,-0.015897,7.3543,283.9,297.0,293.93
95.48471,2.4276,-0.14762,35.413,286.28,-0.015973,7.3677,286.24,299.16,296.24
96.28471,2.4216,-0.14904,35.371,288.68,-0.016167,7.3462,288.65,301.5,298.56
97.08471,2.4298,-0.15042,35.496,291.08,-0.016409,7.3675,290.99,303.72,300.82
97.88471,2.4328,-0.15162,34.692,293.48,-0.016448,7.3827,293.59,306.01,303.38
98.68471,2.4305,-0.15561,35.533,295.88,-0.016945,7.3706,295.8,308.02,305.36
99.48471,2.4359,-0.15804,35.202,298.28,-0.017068,7.3874,298.34,310.02,307.87
100.28471,2.421,-0.15755,35.399,300.68,-0.017105,7.3486,300.65,312.94,310.09
101.08471,2.4182,-0.15863,35.53,303.08,-0.017299,7.3334,303.06,315.2,312.38
101.88471,2.4255,-0.16039,35.488,305.48,-0.01739,7.3561,305.44,317.46,314.67
102.68471,2.4271,-0.16175,35.491,307.88,-0.017578,7.3651,307.92,319.9,317.01
103.48471,2.4263,-0.16323,35.396,310.28,-0.017655,7.3585,310.28,322.06,319.33
104.1354,2.4298,-0.16392,35.493,312.23,-0.017853,7.369,312.21,323.95,321.08
104.9354,2.435,-0.16667,34.657,314.63,-0.018101,7.3846,314.77,325.8,323.17
105.7354,2.431,-0.17058,35.497,317.03,-0.018527,7.3773,316.95,327.76,324.94
106.4804,2.4278,-0.16926,35.05,319.26,-0.018348,7.3667,319.35,329.93,327.17
107.2804,2.4226,-0.17067,35.496,321.66,-0.018463,7.3498,321.64,332.02,329.25
108.0804,2.4324,-0.17196,35.652,324.06,-0.018673,7.3764,323.99,334.08,331.41
108.8804,2.4251,-0.17329,35.472,326.46,-0.018856,7.3618,326.51,336.43,333.79
109.6804,2.4294,-0.1744,35.871,328.86,-0.018918,7.3712,328.81,338.62,336.0
110.4804,2.4383,-0.1799,35.503,331.26,-0.019527,7.3936,331.34,341.01,338.48
111.2804,2.4184,-0.17918,35.673,333.66,-0.019373,7.3393,333.62,343.03,340.53
112.0804,2.4174,-0.17983,36.045,336.06,-0.019511,7.3305,336.03,345.34,342.91
112.8804,2.4325,-0.18126,36.208,338.46,-0.01972,7.3767,338.37,347.56,345.14
113.6804,2.4281,-0.18281,36.138,340.86,-0.01981,7.3694,340.85,350.14,347.74
114.4804,2.4331,-0.18372,36.38,343.26,-0.019941,7.381,343.16,352.37,349.93
115.2804,2.4404,-0.18974,36.216,345.66,-0.020532,7.4036,345.64,354.77,352.49
116.0804,2.4274,-0.18851,36.239,348.06,-0.02044,7.3618,348.08,357.39,354.91
116.8804,2.4241,-0.1889,36.472,350.46,-0.020554,7.3512,350.4,359.66,357.24
117.6804,2.4322,-0.1904,36.34,352.86,-0.02062,7.3775,352.83,361.93,359.6
118.4804,2.4275,-0.19166,35.604,355.26,-0.02079,7.3676,355.48,364.64,362.28
119.2804,2.4252,-0.19307,36.471,357.66,-0.020864,7.354,357.65,366.85,364.49
120.0804,2.4363,-0.1987,36.704,360.06,-0.021543,7.3875,360.0,369.04,366.83
120.8804,2.4162,-0.19737,36.634,362.46,-0.021451,7.3336,362.45,371.38,369.18
121.6804,2.4167,-0.19789,36.656,364.86,-0.021425,7.327,364.86,373.73,371.51
122.4804,2.4346,-0.19905,36.843,367.26,-0.021603,7.3868,367.21,375.89,373.77
123.2804,2.43,-0.20081,37.044,369.66,-0.021692,7.373,369.59,378.41,376.18
124.0804,2.436,-0.20219,36.879,372.06,-0.021908,7.3876,372.02,380.82,378.73
124.8804,2.4403,-0.20586,36.672,374.46,-0.022344,7.4039,374.49,383.11,381.06
125.68041,2.4231,-0.20497,36.656,376.86,-0.022195,7.3509,376.85,385.36,383.39
126.48041,2.4251,-0.20601,36.827,379.26,-0.022346,7.3537,379.27,387.73,385.76
127.28041,2.4365,-0.20746,36.837,381.66,-0.022422,7.3924,381.67,390.0,388.02
128.08041,2.4225,-0.20831,36.598,384.06,-0.022533,7.3514,384.11,392.42,390.48
128.88041,2.4288,-0.21337,36.9,386.46,-0.02314,7.3658,386.45,394.72,392.63
129.68041,2.4246,-0.21135,37.083,388.86,-0.022898,7.3562,388.89,396.91,395.03
130.48041,2.4154,-0.21214,35.239,391.26,-0.022993,7.3314,391.17,398.67,397.15
131.28041,2.4323,-0.21343,38.387,393.66,-0.023091,7.3764,392.03,399.75,397.7
132.08041,2.4372,-0.21383,36.831,396.06,-0.023117,7.395,394.91,402.12,400.56
132.88041,2.4268,-0.22001,37.121,398.46,-0.023835,7.3637,397.25,404.6,402.78
133.68041,2.4154,-0.2159,34.627,400.0,-0.023414,7.324,399.46,406.11,404.86
134.48041,2.4242,-0.21586,36.176,400.0,-0.023375,7.3555,398.92,404.49,403.87
135.28041,2.4186,-0.2157,35.25,400.0,-0.023348,7.3363,399.12,404.42,403.9
136.08041,2.4342,-0.21514,35.12,400.0,-0.023245,7.382,399.03,403.99,403.49
136.7688,2.4264,-0.21742,35.27,400.0,-0.023652,7.3636,398.98,403.53,403.31
137.5688,2.4105,-0.21686,35.109,400.0,-0.02345,7.3122,398.95,403.05,403.07
138.2089,2.3971,-0.21603,35.066,400.0,-0.023393,7.273,398.94,402.47,402.75
139.0089,2.3801,-0.21441,29.894,400.0,-0.023247,7.2166,398.64,400.97,402.09
139.8089,2.3533,-0.21141,36.371,400.0,-0.022844,7.1412,391.69,392.19,394.16
140.6089,2.3797,-0.21307,33.039,400.0,-0.023045,7.2211,392.96,395.67,395.7
141.4089,2.3745,-0.21551,34.641,400.0,-0.023338,7.1993,392.46,394.28,394.85
142.2089,2.3731,-0.21345,34.16,400.0,-0.023143,7.1998,392.62,393.86,394.88
143.0089,2.3802,-0.21341,33.928,400.0,-0.023115,7.2237,392.64,393.24,394.65
143.8089,2.4008,-0.21329,33.771,400.0,-0.023103,7.2797,393.02,393.11,394.68
144.6089,2.4096,-0.21479,34.494,400.0,-0.023226,7.3105,393.2,392.51,394.53
145.4089,2.404,-0.21491,32.908,400.0,-0.023262,7.2914,393.99,392.8,395.05
146.2089,2.3936,-0.21385,33.853,400.0,-0.023226,7.259,393.7,391.89,394.38
147.0089,2.3999,-0.21393,33.7,400.0,-0.023147,7.2848,394.13,391.83,394.59
147.8089,2.4067,-0.21414,34.317,400.0,-0.023227,7.3024,395.15,392.75,395.34
148.6089,2.4162,-0.21913,34.949,400.0,-0.023646,7.3258,395.64,392.63,395.55
149.4089,2.4048,-0.21574,34.434,400.0,-0.023339,7.2987,396.86,393.28,396.58
150.2089,2.4044,-0.21605,34.919,400.0,-0.023424,7.2936,397.88,394.34,397.41
151.0089,2.4228,-0.21566,34.847,400.0,-0.023407,7.347,398.7,394.72,398.07
151.8089,2.4206,-0.2201,33.671,400.0,-0.023819,7.3464,399.49,395.33,398.77
152.6089,2.4147,-0.21675,33.891,400.0,-0.023491,7.3248,399.26,395.35,398.5
153.4089,2.4243,-0.21716,34.035,400.0,-0.023434,7.3506,399.3,395.59,398.58
154.2089,2.4297,-0.21694,33.858,400.0,-0.023459,7.3724,400.07,396.82,399.47
155.0089,2.4288,-0.21932,34.409,400.0,-0.023826,7.3641,399.85,396.65,399.38
155.8089,2.4223,-0.21748,33.533,400.0,-0.023558,7.3465,400.06,397.27,399.71
156.6089,2.4127,-0.21737,33.586,400.0,-0.023544,7.323,399.98,397.63,399.8
157.40891,2.409,-0.21703,33.746,400.0,-0.023495,7.305,399.95,398.06,399.96
158.20891,2.4142,-0.222,33.803,400.0,-0.023941,7.3238,399.93,398.61,400.14
159.00891,2.5269,-0.21706,33.79,400.0,-0.023494,7.6673,399.87,398.99,400.29
159.80891,2.7876,-0.21481,33.791,400.0,-0.02333,8.4564,399.93,399.64,400.52
160.60891,2.908,-0.21463,33.784,400.0,-0.023255,8.8177,399.88,400.2,400.53
161.40891,2.8838,-0.21474,33.831,400.0,-0.023267,8.7498,399.91,400.77,400.7
162.20891,2.8817,-0.21398,34.059,400.0,-0.023147,8.7405,399.92,401.38,400.84
163.00891,2.8904,-0.21345,34.062,400.0,-0.023052,8.7668,399.85,401.71,400.95
163.80891,2.7937,-0.21856,34.15,400.0,-0.023647,8.4772,399.83,402.08,401.11
164.60891,2.581,-0.21527,34.296,400.0,-0.023392,7.829,399.81,402.38,401.28
165.40891,2.4117,-0.21601,33.826,400.0,-0.023366,7.3166,399.93,402.76,401.51
166.20891,2.3035,-0.21621,33.85,400.0,-0.023452,6.9897,399.91,403.05,401.62
167.00891,2.2503,-0.21928,33.984,400.0,-0.02367,6.8198,399.91,403.16,401.76
167.80891,2.2665,-0.21779,34.005,400.0,-0.023541,6.8745,399.89,403.26,401.79
168.60891,2.2687,-0.21726,33.824,400.0,-0.023532,6.8846,399.93,403.42,401.93
169.2145,2.2936,-0.21683,34.514,400.0,-0.023492,6.9574,399.86,403.68,401.99
170.0145,2.2864,-0.22039,34.02,400.0,-0.023807,6.938,399.81,403.57,402.03
170.8145,2.2897,-0.21743,34.632,400.0,-0.023561,6.9455,398.93,402.86,401.03
171.6145,2.3045,-0.21709,33.28,400.0,-0.02343,6.9907,399.21,403.33,401.48
172.4145,2.3069,-0.21666,33.772,400.0,-0.02342,7.0014,399.17,403.52,401.52
173.2145,2.3103,-0.22002,33.766,400.0,-0.023818,7.0048,399.12,403.64,401.52
174.0145,2.3063,-0.21742,33.773,400.0,-0.02357,6.9987,399.12,403.84,401.61
174.8145,2.2968,-0.21765,33.647,400.0,-0.023543,6.9724,399.12,404.06,401.66
175.6145,2.2869,-0.21675,33.691,400.0,-0.023486,6.9363,399.12,404.16,401.79
176.4145,2.2915,-0.2211,33.923,400.0,-0.023828,6.954,399.07,404.24,401.8
177.2145,2.2826,-0.21845,34.467,400.0,-0.023624,6.9262,399.0,404.46,401.83
178.0145,2.2866,-0.21761,33.771,400.0,-0.023603,6.9349,399.12,404.57,401.99
178.6194,2.2744,0.025375,6.1232,199.3,0.0020066,6.9135,399.35,404.85,402.22
178.62072,2.3448,0.025827,1.6834,0.0018611,0.00302,7.0923,399.36,404.87,402.23
178.62204,2.2973,0.024214,0.0,7.7769e-09,0.0025035,6.9616,399.36,404.9,402.22
178.62336,2.2506,0.023788,0.0,2.6575e-14,0.0021999,6.8405,399.34,404.93,402.21
178.62468,2.3266,0.026935,0.0,8.2719e-20,0.0032263,7.0826,399.33,404.97,402.2
178.626,2.2432,0.022822,0.0,2.4393000000000003e-25,0.0015626,6.7075,399.31,405.01,402.18
178.62732,2.2994,0.019484,0.0,6.9445e-31,0.0029715,6.9973,399.3,405.04,402.17
178.62864,2.3207,0.027408,0.0,1.9287e-36,0.0017266,7.044,399.28,405.08,402.16
178.62996,2.3025,0.026852,0.0,5.2535e-42,0.0031422,6.9775,399.26,405.11,402.15
178.63128,2.2368,0.020356,0.0,0.0,0.0023957,6.7786,399.25,405.15,402.14
178.6326,2.3235,0.018058,0.0,0.0,0.0023168,7.0626,399.26,405.12,402.14
178.63392,2.2984,0.018979,0.0,0.0,0.0023664,6.9528,399.27,405.09,402.15
178.63524,2.2505,0.022342,0.0,0.0,0.0023611,6.8236,399.28,405.06,402.15
178.63656,2.3241,0.020379,0.0,0.0,0.0019787,7.0545,399.3,405.04,402.15
178.63788,2.3071,0.022093,0.0,0.0,0.00288,6.9541,399.31,405.01,402.16
178.6392,2.2362,0.024825,0.0,0.0,0.0016463,6.7875,399.32,404.98,402.16
178.64052,2.3058,0.026484,0.0,0.0,0.0030455,7.032,399.33,404.95,402.17
178.64184,2.3104,0.024159,0.0,0.0,0.0023062,6.9583,399.34,404.93,402.17
178.64316,2.2343,0.022694,0.0,0.0,0.0022655,6.7981,399.33,404.92,402.16
178.64448,2.3016,0.025951,0.0,0.0,0.0030202,6.9953,399.33,404.91,402.16
178.6458,2.2994,0.022415,0.0,0.0,0.0019602,6.9605,399.32,404.9,402.15
178.64712,2.2214,0.022666,0.0,0.0,0.0036326,6.7637,399.32,404.88,402.15
178.64844,2.283,0.020987,0.0,0.0,0.0022916,6.941,399.32,404.87,402.15
178.64976,2.2925,0.021531,0.0,0.0,0.0029303,6.9458,399.31,404.86,402.14
178.65108,2.2224,0.01665,0.0,0.0,0.0026626,6.7444,399.31,404.85,402.14
178.6524,2.2743,0.018344,0.0,0.0,0.0024582,6.957,399.3,404.85,402.14
178.65372,2.3003,0.023111,0.0,0.0,0.0024489,6.946,399.3,404.86,402.15
178.65504,2.2234,0.025392,0.0,0.0,0.0025983,6.7372,399.3,404.87,402.16
178.65636,2.274,0.021641,0.0,0.0,0.0016263,6.8881,399.29,404.88,402.17
178.65768,2.3027,0.025271,0.0,0.0,0.0031538,6.9807,399.29,404.88,402.18
178.659,2.2274,0.02496,0.0,0.0,0.0012277,6.7589,399.29,404.89,402.18
178.66032,2.2668,0.025094,0.0,0.0,0.0032232,6.8953,399.28,404.9,402.19
178.66164,2.309,0.022317,0.0,0.0,0.0016997,6.9697,399.28,404.91,402.2
178.66296,2.2222,0.024072,0.0,0.0,0.002521,6.7472,399.28,404.9,402.21
178.66428,2.2546,0.024284,0.0,0.0,0.002681,6.8892,399.28,404.9,402.22
178.6656,2.3031,0.020116,0.0,0.0,0.0021558,6.9662,399.28,404.89,402.22
178.66692,2.2248,0.018167,0.0,0.0,0.0026691,6.7563,399.28,404.89,402.23
178.66824,2.2514,0.020557,0.0,0.0,0.0025084,6.8366,399.28,404.89,402.24
178.66956,2.3032,0.020675,0.0,0.0,0.0025745,6.9905,399.28,404.88,402.25
178.67088,2.2297,0.02048,0.0,0.0,0.0029658,6.7578,399.28,404.88,402.25
178.6722,2.2443,0.022358,0.0,0.0,0.0019855,6.8316,399.75,405.35,402.25
178.67352,2.3276,0.025932,0.0,0.0,0.0029275,7.0562,400.57,406.16,402.23
178.67484,2.2376,0.02433,0.0,0.0,0.0024547,6.7554,401.38,406.97,402.21
178.67616,2.2076,0.023352,0.0,0.0,0.0019755,6.7531,402.19,407.78,402.19
178.67747,2.3387,0.026067,0.0,0.0,0.0032825,7.1194,403.0,408.6,402.17
178.67879,2.2428,0.026519,0.0,0.0,0.0018457,6.7667,403.81,409.41,402.15
178.68011,2.2411,0.022007,0.0,0.0,0.0032873,6.8047,404.62,410.22,402.13
178.68143,2.3005,0.022895,0.0,0.0,0.0020708,6.989,405.43,411.03,402.11
178.68275,9.0792,0.068098,0.0,0.0,0.0076942,24.931,406.94,412.48,402.09
178.68407,26.552,0.17559,0.0,0.0,0.019071,79.322,408.46,413.94,402.08
178.68539,30.332,0.42952,0.0,0.0,0.046756,91.157,409.97,415.4,402.06
178.68671,31.76,0.73401,0.0,0.0,0.082483,96.31,411.49,416.86,402.04
178.68803,32.764,1.016,0.0,0.0,0.11432,99.43,413.01,418.33,402.03
178.68935,32.972,1.3291,0.0,0.0,0.1533,100.18,414.53,419.79,402.01
178.69067,33.071,1.6326,0.0,0.0,0.19416,100.28,416.05,421.25,402.0
178.69199,33.026,1.9381,0.0,0.0,0.2326,100.15,417.42,422.61,401.99
178.69331,33.081,2.2403,0.0,0.0,0.27555,100.31,418.54,423.8,401.99
178.69463,33.108,2.5385,0.0,0.0,0.3179,100.43,419.66,424.99,401.99
178.69595,33.142,2.8423,0.0,0.0,0.36337,100.55,420.78,426.19,401.99
178.69727,33.284,3.1422,0.0,0.0,0.41067,100.95,421.9,427.38,401.99
178.69859,33.478,3.4421,0.0,0.0,0.4585,101.48,423.03,428.57,401.99
178.69991,33.614,3.7317,0.0,0.0,0.51026,101.88,424.15,429.76,401.99
178.70123,33.83,4.0247,0.0,0.0,0.56188,102.6,425.27,430.95,401.99
178.70255,34.101,4.311,0.0,0.0,0.61464,103.41,426.06,431.6,402.0
178.70387,34.309,4.5936,0.0,0.0,0.67125,103.99,426.76,432.07,402.02
178.70519,34.521,4.8825,0.0,0.0,0.7287,104.69,427.45,432.55,402.03
178.70651,34.716,5.1625,0.0,0.0,0.79019,105.26,428.15,433.03,402.05
178.70783,34.94,5.4366,0.0,0.0,0.8543,105.97,428.84,433.51,402.06
178.70915,35.138,5.7031,0.0,0.0,0.91643,106.56,429.53,433.98,402.08
178.71047,35.291,5.959,0.0,0.0,0.98893,107.01,430.23,434.46,402.09
178.71179,35.39,6.2079,0.0,0.0,1.0496,107.27,430.82,434.79,402.11
178.71311,35.432,6.4405,0.0,0.0,1.1257,107.49,430.88,434.34,402.13
178.71443,35.504,6.6483,0.0,0.0,1.1884,107.71,430.93,433.88,402.14
178.71575,35.534,6.8438,0.0,0.0,1.2544,107.76,430.99,433.43,402.16
178.71707,35.458,7.0116,0.0,0.0,1.3148,107.64,431.04,432.98,402.17
178.71839,35.349,7.1615,0.0,0.0,1.3701,107.24,431.1,432.52,402.19
178.71971,35.155,7.2869,0.0,0.0,1.423,106.64,431.15,432.07,402.2
178.72103,35.003,7.4088,0.0,0.0,1.4717,106.2,431.21,431.61,402.22
178.72235,34.9,7.512,0.0,0.0,1.5105,105.87,430.88,430.96,402.23
178.72367,34.76,7.597,0.0,0.0,1.5551,105.43,430.25,430.15,402.23
178.72499,34.762,7.6825,0.0,0.0,1.588,105.45,429.62,429.34,402.23
178.72631,34.953,7.763,0.0,0.0,1.6292,105.97,428.99,428.52,402.23
178.72763,34.694,7.8418,0.0,0.0,1.6685,105.64,428.36,427.71,402.23
178.72895,31.092,7.8382,0.0,0.0,1.6628,94.361,427.73,426.9,402.23
178.73027,29.314,7.8479,0.0,0.0,1.6773,89.066,427.1,426.09,402.23
178.73159,28.365,7.8584,0.0,0.0,1.6728,86.097,426.46,425.27,402.23
178.73291,27.736,7.8528,0.0,0.0,1.6796,84.23,425.68,424.52,402.23
178.73423,27.267,7.8489,0.0,0.0,1.675,82.757,424.89,423.78,402.23
178.73555,27.013,7.86,0.0,0.0,1.6784,81.993,424.09,423.03,402.23
178.73687,26.895,7.8647,0.0,0.0,1.6831,81.612,423.3,422.28,402.23
178.73819,26.75,7.8684,0.0,0.0,1.6814,81.181,422.5,421.54,402.23
178.73951,26.529,7.8724,0.0,0.0,1.6834,80.53,421.71,420.79,402.23
178.74083,26.254,7.8844,0.0,0.0,1.6878,79.73,420.92,420.04,402.23
178.74215,25.807,7.8825,0.0,0.0,1.6812,78.339,420.22,419.39,402.24
178.74347,25.165,7.8783,0.0,0.0,1.6923,76.413,419.7,418.91,402.26
178.74479,24.404,7.8799,0.0,0.0,1.6824,74.153,419.18,418.43,402.28
178.74611,23.205,7.883,0.0,0.0,1.6903,70.569,418.67,417.96,402.31
178.74743,21.68,7.8806,0.0,0.0,1.6873,65.997,418.15,417.48,402.33
178.74875,19.924,7.8756,0.0,0.0,1.6836,60.679,417.63,417.0,402.35
178.75007,17.853,7.8732,0.0,0.0,1.6886,54.425,417.11,416.52,402.38
178.75139,15.298,7.8701,0.0,0.0,1.6822,46.782,416.6,416.04,402.4
178.75271,9.7141,7.864,0.0,0.0,1.6882,30.935,416.4,415.81,402.41
178.75403,-0.32929,7.8261,0.0,0.0,1.6686,-0.56715,416.31,415.66,402.42
178.75535,2.6361,7.8541,0.0,0.0,1.6721,7.3228,416.23,415.51,402.43
178.75667,1.5783,7.8682,0.0,0.0,1.6857,4.9995,416.15,415.36,402.44
178.75799,1.8772,7.8721,0.0,0.0,1.6831,5.6934,416.07,415.21,402.45
178.75931,1.6924,7.8724,0.0,0.0,1.684,5.0707,415.98,415.06,402.45
178.76063,1.974,7.8731,0.0,0.0,1.6863,6.0534,415.9,414.91,402.46
178.76195,1.8728,7.8662,0.0,0.0,1.6761,5.663,415.82,414.77,402.47
178.76327,1.6864,7.8574,0.0,0.0,1.6824,5.1156,415.78,414.76,402.47
178.76459,1.8408,7.8616,0.0,0.0,1.67,5.6405,415.73,414.75,402.47
178.76591,1.9204,7.8609,0.0,0.0,1.678,5.7815,415.69,414.74,402.47
178.76723,1.7707,7.8584,0.0,0.0,1.6783,5.3783,415.65,414.73,402.47
178.76855,1.9346,7.855,0.0,0.0,1.6755,5.8886,415.6,414.71,402.47
178.76987,1.9142,7.862,0.0,0.0,1.6815,5.7249,415.56,414.7,402.47
178.77119,1.7809,7.8601,0.0,0.0,1.6773,5.3581,415.52,414.69,402.47
178.77251,1.7441,7.8622,0.0,0.0,1.6796,5.3313,415.41,414.67,402.48
178.77383,1.9339,7.8604,0.0,0.0,1.6815,5.8868,415.26,414.65,402.51
178.77515,1.7956,7.8651,0.0,0.0,1.674,5.432,415.1,414.63,402.54
178.77647,1.8164,7.8623,0.0,0.0,1.683,5.6008,414.94,414.6,402.57
178.77779,1.8559,7.86,0.0,0.0,1.6764,5.618,414.78,414.58,402.59
178.77911,1.7604,7.8644,0.0,0.0,1.6798,5.3323,414.62,414.55,402.62
178.78043,1.8174,7.8637,0.0,0.0,1.6813,5.5666,414.47,414.53,402.65
178.78175,1.8609,7.8649,0.0,0.0,1.6774,5.5983,414.31,414.51,402.68
178.78307,1.7879,7.8643,0.0,0.0,1.6865,5.3919,414.18,414.52,402.68
178.78439,1.7893,7.8651,0.0,0.0,1.679,5.4564,414.05,414.54,402.68
178.78571,1.8864,7.8611,0.0,0.0,1.6822,5.7173,413.92,414.55,402.68
178.78703,1.7762,7.8568,0.0,0.0,1.6835,5.3411,413.78,414.57,402.68
178.78835,1.7871,7.8573,0.0,0.0,1.6777,5.4619,413.65,414.58,402.68
178.78967,1.8844,7.8613,0.0,0.0,1.68,5.7453,413.52,414.6,402.68
178.79099,1.8095,7.8628,0.0,0.0,1.6786,5.47,413.39,414.61,402.68
178.7923,1.7984,7.8619,0.0,0.0,1.6765,5.4942,413.28,414.63,402.68
178.79362,1.8727,7.8656,0.0,0.0,1.6816,5.6753,413.22,414.65,402.69
178.79494,1.8316,7.8658,0.0,0.0,1.6725,5.5535,413.15,414.66,402.71
178.79626,1.8231,7.8645,0.0,0.0,1.6839,5.5011,413.08,414.68,402.72
178.79758,1.8891,7.8631,0.0,0.0,1.6754,5.7434,413.01,414.69,402.73
178.7989,1.86,7.8672,0.0,0.0,1.6794,5.6119,412.95,414.71,402.74
178.80022,1.8183,7.8651,0.0,0.0,1.6802,5.5126,412.88,414.72,402.75
178.80154,1.888,7.86,0.0,0.0,1.6769,5.7354,412.81,414.74,402.77
178.80286,1.8453,7.8586,0.0,0.0,1.6818,5.5799,412.7,414.73,402.8
178.80418,1.8299,7.8623,0.0,0.0,1.6796,5.5902,412.58,414.72,402.84
178.8055,1.9176,7.8589,0.0,0.0,1.6805,5.7871,412.45,414.7,402.89
178.80682,1.8661,7.8602,0.0,0.0,1.6842,5.6539,412.32,414.69,402.93
178.80814,1.8142,7.8642,0.0,0.0,1.6774,5.5406,412.2,414.67,402.97
178.80946,1.9429,7.869,0.0,0.0,1.684,5.8953,412.07,414.66,403.02
178.81078,1.881,7.8652,0.0,0.0,1.6807,5.6772,411.94,414.64,403.06
178.8121,1.8057,7.8618,0.0,0.0,1.6779,5.5047,411.81,414.62,403.1
178.81342,1.9103,7.8679,0.0,0.0,1.6851,5.8052,411.61,414.57,403.12
178.81474,1.9179,7.866,0.0,0.0,1.6751,5.7691,411.42,414.53,403.13
178.81606,1.8296,7.8637,0.0,0.0,1.6849,5.5445,411.22,414.48,403.15
178.81738,1.8805,7.8656,0.0,0.0,1.6761,5.7401,411.02,414.43,403.17
178.8187,1.9142,7.8665,0.0,0.0,1.681,5.8271,410.82,414.38,403.18
178.82002,1.8431,7.8612,0.0,0.0,1.682,5.5981,410.62,414.34,403.2
178.82134,1.8775,7.8554,0.0,0.0,1.6769,5.7244,410.43,414.29,403.21
178.82266,1.9194,7.8605,0.0,0.0,1.6801,5.7928,410.25,414.24,403.22
178.82398,1.8386,7.8639,0.0,0.0,1.6778,5.5912,410.1,414.19,403.22
178.8253,1.8994,7.8645,0.0,0.0,1.6768,5.7714,409.94,414.14,403.22
178.82662,1.9019,7.8637,0.0,0.0,1.6838,5.7492,409.79,414.09,403.22
178.82794,1.8329,7.8668,0.0,0.0,1.675,5.565,409.63,414.03,403.22
178.82926,1.8532,7.8665,0.0,0.0,1.6843,5.6596,409.48,413.98,403.22
178.83058,1.8642,7.8641,0.0,0.0,1.6794,5.6472,409.32,413.93,403.22
178.8319,1.8183,7.8669,0.0,0.0,1.6794,5.5549,409.17,413.88,403.22
178.83322,1.9011,7.8686,0.0,0.0,1.6847,5.8059,409.02,413.84,403.25
178.83454,1.8848,7.8641,0.0,0.0,1.6773,5.7061,408.86,413.8,403.27
178.83586,1.8122,7.8615,0.0,0.0,1.687,5.46,408.71,413.76,403.3
178.83718,1.8836,7.862,0.0,0.0,1.6811,5.7507,408.55,413.72,403.33
178.8385,1.9377,7.8628,0.0,0.0,1.6812,5.8274,408.4,413.68,403.36
178.83982,1.7898,7.8586,0.0,0.0,1.6832,5.4339,408.24,413.64,403.38
178.84114,1.8861,7.8616,0.0,0.0,1.6789,5.7784,408.09,413.6,403.41
178.84246,1.9682,7.866,0.0,0.0,1.681,5.9827,407.95,413.56,403.44
178.84378,1.8874,7.8683,0.0,0.0,1.6815,5.7079,407.83,413.5,403.47
178.8451,1.9252,7.8633,0.0,0.0,1.6755,5.8783,407.72,413.44,403.5
178.84642,1.9625,7.8648,0.0,0.0,1.6844,5.961,407.6,413.38,403.54
178.84774,1.9117,7.866,0.0,0.0,1.6721,5.7338,407.49,413.32,403.57
178.84906,1.8944,7.8662,0.0,0.0,1.6837,5.7512,407.37,413.26,403.6
178.85038,2.0428,7.8631,0.0,0.0,1.6771,6.2044,407.26,413.2,403.63
178.8517,1.9574,7.8669,0.0,0.0,1.6794,5.9053,407.14,413.14,403.66
178.85302,1.956,7.867,0.0,0.0,1.6828,6.0,406.97,413.08,403.68
178.85434,2.1167,7.8597,0.0,0.0,1.6775,6.3953,406.77,413.0,403.7
178.85566,1.9351,7.8575,0.0,0.0,1.6811,5.8391,406.58,412.93,403.71
178.85698,1.9606,7.864,0.0,0.0,1.6823,5.9947,406.38,412.86,403.73
178.8583,2.1242,7.8645,0.0,0.0,1.6794,6.4178,406.18,412.79,403.75
178.85962,1.9131,7.8638,0.0,0.0,1.6851,5.7276,405.98,412.72,403.76
178.86094,1.9564,7.8653,0.0,0.0,1.6777,5.9785,405.79,412.65,403.78
178.86226,2.1514,7.8692,0.0,0.0,1.6836,6.4848,405.59,412.58,403.79
178.86358,1.8723,7.8647,0.0,0.0,1.6809,5.6391,405.36,412.52,403.82
178.8649,1.9638,7.8622,0.0,0.0,1.6773,6.1106,405.13,412.45,403.84
178.86622,2.1776,7.8692,0.0,0.0,1.6867,6.5879,404.9,412.39,403.87
178.86754,1.8962,7.8674,0.0,0.0,1.6769,5.6775,404.67,412.33,403.89
178.86886,1.936,7.8643,0.0,0.0,1.6848,5.9777,404.44,412.26,403.91
178.87018,2.1575,7.8608,0.0,0.0,1.6784,6.4924,404.21,412.2,403.94
178.8715,1.8892,7.8634,0.0,0.0,1.6799,5.6729,403.98,412.14,403.96
178.87282,1.922,7.8621,0.0,0.0,1.6819,5.9191,403.8,412.06,403.98
178.87414,2.1724,7.8609,0.0,0.0,1.6783,6.5603,403.67,411.99,404.0
178.87546,1.8972,7.8617,0.0,0.0,1.6789,5.7055,403.54,411.91,404.01
178.87678,1.9088,7.8681,0.0,0.0,1.6788,5.9247,403.42,411.83,404.03
178.8781,2.1924,7.8685,0.0,0.0,1.6754,6.6521,403.29,411.75,404.04
178.87942,1.9396,7.8618,0.0,0.0,1.6832,5.8242,403.16,411.67,404.06
178.88074,1.898,7.8647,0.0,0.0,1.6746,5.8056,403.04,411.59,404.08
178.88206,2.1521,7.8674,0.0,0.0,1.6829,6.5187,402.91,411.51,404.09
178.88338,1.9685,7.8651,0.0,0.0,1.6803,5.902,402.76,411.43,404.12
178.8847,1.8922,7.8628,0.0,0.0,1.6772,5.807,402.61,411.35,404.15
178.88602,2.1643,7.8697,0.0,0.0,1.6865,6.5642,402.45,411.26,404.17
178.88734,1.9757,7.8637,0.0,0.0,1.6777,5.9088,402.3,411.18,404.2
178.88866,1.8745,7.857,0.0,0.0,1.6859,5.7941,402.14,411.1,404.23
178.88998,2.1766,7.8602,0.0,0.0,1.6834,6.6539,401.99,411.01,404.26
178.8913,1.9993,7.8616,0.0,0.0,1.6783,5.9675,401.83,410.93,404.28
178.89262,1.8904,7.8633,0.0,0.0,1.684,5.7808,401.68,410.85,404.31
178.89394,2.1635,7.8619,0.0,0.0,1.6783,6.5632,401.54,410.79,404.34
178.89526,2.0017,7.8656,0.0,0.0,1.6796,5.9636,401.4,410.72,404.37
178.89658,1.8817,7.8665,0.0,0.0,1.6822,5.7677,401.25,410.66,404.39
178.8979,2.1654,7.8636,0.0,0.0,1.6742,6.6118,401.11,410.6,404.42
178.89922,2.0384,7.8627,0.0,0.0,1.6853,6.0849,400.97,410.53,404.45
178.90054,1.8602,7.8682,0.0,0.0,1.6727,5.7075,400.83,410.47,404.48
178.90186,2.1432,7.8646,0.0,0.0,1.6812,6.5431,400.68,410.41,404.51
178.90318,2.0475,7.865,0.0,0.0,1.6804,6.1107,400.55,410.34,404.52
178.9045,1.8529,7.8584,0.0,0.0,1.6765,5.648,400.42,410.26,404.53
178.90582,2.1344,7.8654,0.0,0.0,1.683,6.5314,400.29,410.19,404.54
178.90714,2.0534,7.859,0.0,0.0,1.6769,6.1605,400.16,410.11,404.54
178.90845,1.8352,7.858,0.0,0.0,1.679,5.5838,400.03,410.04,404.55
178.90977,2.1314,7.864,0.0,0.0,1.6838,6.5374,399.9,409.96,404.56
178.91109,2.0807,7.867,0.0,0.0,1.6753,6.2203,399.77,409.89,404.57
178.91241,1.8314,7.8642,0.0,0.0,1.6855,5.6019,399.64,409.81,404.58
178.91373,2.0822,7.8632,0.0,0.0,1.6778,6.3746,399.49,409.71,404.58
178.91505,2.0836,7.8658,0.0,0.0,1.6813,6.2445,399.35,409.61,404.58
178.91637,1.8387,7.8651,0.0,0.0,1.6824,5.5775,399.21,409.51,404.59
178.91769,2.0761,7.8637,0.0,0.0,1.6771,6.388,399.07,409.41,404.59
178.91901,2.0961,7.8663,0.0,0.0,1.6865,6.2821,398.92,409.32,404.6
178.92033,1.8291,7.8674,0.0,0.0,1.6779,5.528,398.78,409.22,404.6
178.92165,2.0556,7.8623,0.0,0.0,1.6842,6.3709,398.64,409.12,404.6
178.92297,2.1231,7.8577,0.0,0.0,1.682,6.3631,398.5,409.02,404.61
178.92429,1.8374,7.8602,0.0,0.0,1.6789,5.5583,398.36,408.91,404.62
178.92561,2.0341,7.8631,0.0,0.0,1.6816,6.2481,398.23,408.81,404.62
178.92693,2.1066,7.8632,0.0,0.0,1.6794,6.3188,398.1,408.71,404.63
178.92825,1.8433,7.8588,0.0,0.0,1.6759,5.5541,397.96,408.61,404.64
178.92957,2.0245,7.8699,0.0,0.0,1.6828,6.241,397.83,408.5,404.65
178.93089,2.1363,7.8644,0.0,0.0,1.6717,6.4225,397.69,408.4,404.66
178.93221,1.8432,7.8633,0.0,0.0,1.6844,5.5519,397.56,408.3,404.66
178.93353,2.0095,7.8638,0.0,0.0,1.6745,6.2083,397.41,408.21,404.69
178.93485,2.1509,7.8681,0.0,0.0,1.6809,6.4624,397.27,408.13,404.72
178.93617,1.8601,7.8644,0.0,0.0,1.6802,5.5704,397.12,408.06,404.74
178.93749,2.0038,7.8638,0.0,0.0,1.6782,6.1603,396.97,407.98,404.77
178.93881,2.1524,7.8634,0.0,0.0,1.6834,6.4856,396.83,407.9,404.8
178.94013,1.8795,7.8627,0.0,0.0,1.6796,5.6501,396.68,407.82,404.83
178.94145,1.99,7.8581,0.0,0.0,1.6827,6.1591,396.53,407.74,404.85
178.94277,2.1823,7.8596,0.0,0.0,1.6839,6.6054,396.39,407.66,404.88
178.94409,1.8845,7.8632,0.0,0.0,1.6769,5.6527,396.27,407.59,404.9
178.94541,1.9639,7.8678,0.0,0.0,1.6843,6.0849,396.15,407.52,404.91
178.94673,2.1881,7.8649,0.0,0.0,1.6805,6.5741,396.04,407.45,404.93
178.94805,1.9092,7.8648,0.0,0.0,1.6789,5.6918,395.92,407.38,404.94
178.94937,1.9598,7.8682,0.0,0.0,1.6851,6.0384,395.8,407.31,404.96
178.95069,2.1831,7.8664,0.0,0.0,1.676,6.5764,395.68,407.23,404.97
178.95201,1.9185,7.864,0.0,0.0,1.6847,5.7235,395.56,407.16,404.99
178.95333,1.9387,7.8671,0.0,0.0,1.6748,6.0151,395.44,407.08,405.0
178.95465,2.2061,7.8706,0.0,0.0,1.6826,6.672,395.31,406.98,405.02
178.95597,1.9381,7.8625,0.0,0.0,1.6817,5.8156,395.18,406.89,405.03
178.95729,1.9365,7.8612,0.0,0.0,1.6787,5.9774,395.06,406.79,405.04
178.95861,2.2,7.8636,0.0,0.0,1.682,6.6372,394.93,406.7,405.05
178.95993,1.9503,7.8634,0.0,0.0,1.6786,5.8031,394.8,406.6,405.06
178.96125,1.936,7.8638,0.0,0.0,1.6784,5.9476,394.67,406.51,405.08
178.96257,2.1931,7.8665,0.0,0.0,1.685,6.6493,394.55,406.41,405.09
178.96389,1.978,7.8698,0.0,0.0,1.676,5.915,394.4,406.32,405.11
178.96521,1.9106,7.8677,0.0,0.0,1.6857,5.9159,394.25,406.23,405.13
178.96653,2.2056,7.8664,0.0,0.0,1.6804,6.7207,394.11,406.14,405.15
178.96785,1.9952,7.8674,0.0,0.0,1.6798,5.9624,393.96,406.05,405.17
178.96917,1.91,7.8699,0.0,0.0,1.6857,5.8687,393.81,405.96,405.19
178.97049,2.1852,7.8662,0.0,0.0,1.6779,6.6239,393.67,405.87,405.21
178.97181,2.0092,7.8647,0.0,0.0,1.6869,5.998,393.52,405.78,405.23
178.97313,1.8985,7.8643,0.0,0.0,1.6805,5.8024,393.39,405.69,405.24
178.97445,2.1818,7.8638,0.0,0.0,1.6825,6.6303,393.3,405.6,405.24
178.97577,2.0168,7.8608,0.0,0.0,1.6851,6.0283,393.2,405.52,405.25
178.97709,1.8762,7.8593,0.0,0.0,1.6776,5.7747,393.11,405.44,405.25
178.97841,2.1956,7.8695,0.0,0.0,1.6826,6.683,393.01,405.36,405.26
178.97973,2.0462,7.8672,0.0,0.0,1.6812,6.1198,392.92,405.27,405.26
178.98105,1.8812,7.8646,0.0,0.0,1.677,5.7346,392.82,405.19,405.26
178.98237,2.1632,7.8682,0.0,0.0,1.6846,6.5988,392.73,405.11,405.27
178.98369,2.0561,7.8661,0.0,0.0,1.6724,6.1515,392.63,405.02,405.28
178.98501,1.8688,7.8665,0.0,0.0,1.6845,5.7244,392.52,404.93,405.3
178.98633,2.1442,7.8641,0.0,0.0,1.6773,6.561,392.42,404.83,405.32
178.98765,2.0765,7.8714,0.0,0.0,1.6808,6.2336,392.32,404.74,405.34
178.98897,1.8443,7.8642,0.0,0.0,1.6816,5.6455,392.21,404.65,405.36
178.99029,2.1403,7.8629,0.0,0.0,1.6789,6.5153,392.11,404.56,405.38
178.99161,2.0966,7.8608,0.0,0.0,1.683,6.2732,392.01,404.47,405.4
178.99293,1.8591,7.8623,0.0,0.0,1.6808,5.6576,391.9,404.38,405.42
178.99425,2.1188,7.8631,0.0,0.0,1.6811,6.4753,391.77,404.3,405.43
178.99557,2.0932,7.8643,0.0,0.0,1.6852,6.284,391.64,404.21,405.44
178.99689,1.8704,7.8647,0.0,0.0,1.6776,5.7027,391.51,404.13,405.46
178.99821,2.1139,7.8707,0.0,0.0,1.6841,6.5166,391.38,404.05,405.47
178.99953,2.125,7.8645,0.0,0.0,1.6811,6.409,391.25,403.97,405.48
179.00085,1.8475,7.8653,0.0,0.0,1.6789,5.6085,391.11,403.88,405.49
179.00217,2.1042,7.8697,0.0,0.0,1.6867,6.4417,390.98,403.8,405.5
179.00349,2.1367,7.8688,0.0,0.0,1.6771,6.3804,390.87,403.71,405.51
179.00481,1.8784,7.8635,0.0,0.0,1.685,5.6993,390.77,403.63,405.51
179.00613,2.0656,7.866,0.0,0.0,1.6789,6.3709,390.66,403.54,405.51
179.00745,2.1445,7.8667,0.0,0.0,1.6812,6.423,390.56,403.45,405.51
179.00877,1.85,7.8609,0.0,0.0,1.6814,5.6004,390.46,403.37,405.51
179.01009,2.0671,7.8591,0.0,0.0,1.6787,6.3824,390.35,403.28,405.51
179.01141,2.1753,7.8633,0.0,0.0,1.6807,6.5314,390.25,403.19,405.51
179.01273,1.8634,7.8682,0.0,0.0,1.6801,5.6239,390.15,403.1,405.51
179.01405,2.0456,7.8668,0.0,0.0,1.6764,6.2933,390.04,403.01,405.51
179.01537,2.1772,7.8682,0.0,0.0,1.6867,6.5418,389.93,402.91,405.5
179.01669,1.8884,7.8654,0.0,0.0,1.6748,5.6995,389.81,402.81,405.5
179.01801,2.0306,7.8699,0.0,0.0,1.6851,6.2755,389.7,402.71,405.49
179.01933,2.192,7.8648,0.0,0.0,1.6804,6.6121,389.59,402.61,405.49
179.02065,1.8878,7.8681,0.0,0.0,1.6793,5.696,389.48,402.51,405.49
179.02197,2.0243,7.8715,0.0,0.0,1.6862,6.2656,389.37,402.41,405.48
179.02328,2.2134,7.8674,0.0,0.0,1.6794,6.6737,389.25,402.31,405.47
179.0246,1.9166,7.8595,0.0,0.0,1.6864,5.7221,389.12,402.21,405.45
179.02592,2.014,7.8635,0.0,0.0,1.6834,6.1867,388.99,402.12,405.43
179.02724,2.2031,7.8647,0.0,0.0,1.6813,6.6165,388.86,402.02,405.41
179.02856,1.9275,7.8625,0.0,0.0,1.684,5.7892,388.73,401.92,405.39
179.02988,1.9951,7.8644,0.0,0.0,1.6799,6.1904,388.6,401.82,405.37
179.0312,2.2111,7.8697,0.0,0.0,1.6814,6.6898,388.47,401.72,405.35
179.03252,1.9335,7.8698,0.0,0.0,1.6832,5.8082,388.34,401.62,405.33
179.03384,1.9712,7.8642,0.0,0.0,1.6749,6.0618,388.21,401.53,405.33
179.03516,2.2268,7.8685,0.0,0.0,1.6863,6.7312,388.1,401.44,405.34
179.03648,1.9694,7.8686,0.0,0.0,1.6731,5.8635,387.98,401.36,405.34
179.0378,1.9804,7.8698,0.0,0.0,1.6841,6.0623,387.86,401.27,405.34
179.03912,2.2074,7.8657,0.0,0.0,1.68,6.6853,387.74,401.18,405.35
179.04044,1.9748,7.8668,0.0,0.0,1.6796,5.9103,387.62,401.1,405.35
179.04176,1.9621,7.865,0.0,0.0,1.6834,6.0537,387.5,401.01,405.35
179.04308,2.2303,7.8631,0.0,0.0,1.6799,6.7396,387.38,400.92,405.36
179.0444,1.974,7.8591,0.0,0.0,1.6813,5.876,387.29,400.85,405.39
179.04572,1.9392,7.8661,0.0,0.0,1.6843,5.9828,387.19,400.77,405.42
179.04704,2.2172,7.8675,0.0,0.0,1.679,6.7271,387.1,400.7,405.45
179.04836,2.0088,7.8688,0.0,0.0,1.687,5.9601,387.0,400.62,405.47
179.04968,1.9328,7.8647,0.0,0.0,1.6782,5.9384,386.91,400.55,405.5
179.051,2.2046,7.8736,0.0,0.0,1.684,6.7078,386.81,400.47,405.53
179.05232,2.0255,7.8665,0.0,0.0,1.6827,6.0461,386.72,400.4,405.56
179.05364,1.9097,7.8677,0.0,0.0,1.6788,5.8892,386.62,400.32,405.57
179.05496,2.2144,7.8702,0.0,0.0,1.6875,6.7317,386.53,400.25,405.57
179.05628,2.0432,7.8728,0.0,0.0,1.6797,6.1098,386.43,400.18,405.57
179.0576,1.8991,7.8641,0.0,0.0,1.6842,5.8422,386.34,400.11,405.57
179.05892,2.1979,7.8645,0.0,0.0,1.6829,6.6653,386.24,400.04,405.57
179.06024,2.0633,7.8653,0.0,0.0,1.6809,6.1498,386.15,399.97,405.57
179.06156,1.8998,7.8631,0.0,0.0,1.6824,5.8175,386.05,399.9,405.57
179.06288,2.1809,7.8671,0.0,0.0,1.6816,6.6529,385.96,399.83,405.57
179.0642,2.0789,7.8623,0.0,0.0,1.6774,6.2136,385.88,399.75,405.56
179.06552,1.8861,7.874,0.0,0.0,1.6836,5.7724,385.8,399.67,405.55
179.06684,2.1804,7.8675,0.0,0.0,1.6737,6.6857,385.72,399.59,405.53
179.06816,2.1029,7.8694,0.0,0.0,1.6871,6.2778,385.64,399.51,405.52
179.06948,1.8812,7.8661,0.0,0.0,1.6761,5.7455,385.56,399.43,405.51
179.0708,2.1634,7.8717,0.0,0.0,1.684,6.6126,385.48,399.35,405.5
179.07212,2.1071,7.8676,0.0,0.0,1.6821,6.2769,385.4,399.27,405.49
179.07344,1.8879,7.8656,0.0,0.0,1.6784,5.7482,385.33,399.19,405.48
179.07476,2.1435,7.8685,0.0,0.0,1.6858,6.5828,385.26,399.11,405.49
179.07608,2.1315,7.8667,0.0,0.0,1.6804,6.3877,385.2,399.03,405.51
179.0774,1.8705,7.8584,0.0,0.0,1.6861,5.6999,385.14,398.94,405.52
179.07872,2.1592,7.8633,0.0,0.0,1.686,6.6331,385.07,398.86,405.53
179.08004,2.1589,7.8662,0.0,0.0,1.6795,6.4428,385.01,398.78,405.54
179.08136,1.8882,7.8676,0.0,0.0,1.6846,5.7201,384.95,398.69,405.55
179.08268,2.1203,7.8651,0.0,0.0,1.68,6.5286,384.88,398.61,405.57
179.084,2.1656,7.8703,0.0,0.0,1.6811,6.4882,384.8,398.53,405.58
179.08532,1.8945,7.8692,0.0,0.0,1.6845,5.7301,384.71,398.46,405.6
179.08664,2.1083,7.868,0.0,0.0,1.6766,6.4793,384.63,398.38,405.61
179.08796,2.1898,7.8681,0.0,0.0,1.6878,6.5665,384.54,398.31,405.63
179.08928,1.8714,7.8698,0.0,0.0,1.6731,5.6614,384.45,398.23,405.64
179.0906,2.0946,7.872,0.0,0.0,1.6835,6.4528,384.37,398.16,405.66
179.09192,2.2024,7.8657,0.0,0.0,1.6827,6.598,384.28,398.08,405.68
179.09324,1.906,7.8629,0.0,0.0,1.6788,5.7502,384.19,398.0,405.69
179.09456,2.0842,7.8666,0.0,0.0,1.6841,6.4399,384.11,397.91,405.68
179.09588,2.2023,7.8659,0.0,0.0,1.6806,6.6288,384.03,397.82,405.66
179.0972,1.9118,7.8611,0.0,0.0,1.6786,5.7783,383.95,397.73,405.65
179.09852,2.0706,7.8691,0.0,0.0,1.6855,6.3867,383.88,397.64,405.64
179.09984,2.2215,7.8728,0.0,0.0,1.677,6.7108,383.8,397.55,405.63
179.10116,1.8998,7.8698,0.0,0.0,1.6872,5.7373,383.72,397.46,405.62
179.10248,2.0569,7.8675,0.0,0.0,1.6811,6.3262,383.64,397.37,405.61
179.1038,2.2192,7.8718,0.0,0.0,1.682,6.6829,383.55,397.28,405.6
179.10512,1.9516,7.8692,0.0,0.0,1.685,5.8656,383.47,397.2,405.59
179.10644,2.0396,7.8679,0.0,0.0,1.6787,6.2991,383.38,397.11,405.58
179.10776,2.2194,7.8691,0.0,0.0,1.6888,6.693,383.29,397.03,405.57
179.10908,1.9372,7.8686,0.0,0.0,1.6806,5.8384,383.21,396.95,405.56
179.1104,2.016,7.865,0.0,0.0,1.6834,6.2394,383.12,396.86,405.56
179.11172,2.2442,7.8617,0.0,0.0,1.6863,6.7865,383.03,396.78,405.55
179.11304,1.9559,7.8615,0.0,0.0,1.6782,5.8344,382.94,396.7,405.54
179.11436,1.9944,7.8701,0.0,0.0,1.6832,6.1279,382.85,396.63,405.56
179.11568,2.2365,7.8694,0.0,0.0,1.6827,6.7692,382.76,396.57,405.58
179.117,1.9812,7.8654,0.0,0.0,1.6775,5.9379,382.67,396.5,405.6
179.11832,1.9946,7.8705,0.0,0.0,1.6851,6.1819,382.58,396.44,405.62
179.11964,2.2345,7.8713,0.0,0.0,1.6754,6.7882,382.49,396.38,405.64
179.12096,1.9756,7.866,0.0,0.0,1.6847,5.9457,382.4,396.31,405.66
179.12228,1.9549,7.8679,0.0,0.0,1.6779,6.057,382.31,396.25,405.68
179.1236,2.2543,7.8735,0.0,0.0,1.6815,6.8489,382.22,396.19,405.69
179.12492,2.0116,7.8684,0.0,0.0,1.6833,5.9872,382.16,396.12,405.67
179.12624,1.957,7.8665,0.0,0.0,1.6798,6.0135,382.1,396.05,405.66
179.12756,2.2339,7.8649,0.0,0.0,1.6849,6.7969,382.03,395.98,405.65
179.12888,2.0232,7.8663,0.0,0.0,1.6825,6.0528,381.97,395.92,405.64
179.1302,1.9609,7.8627,0.0,0.0,1.6832,6.0417,381.9,395.85,405.63
179.13152,2.2331,7.8659,0.0,0.0,1.6868,6.7991,381.84,395.78,405.61
179.13284,2.0306,7.87,0.0,0.0,1.6797,6.0815,381.78,395.71,405.6
179.13416,1.921,7.8716,0.0,0.0,1.6854,5.8795,381.71,395.64,405.6
179.73443,1.9833,7.8749,0.0,0.0,1.6863,6.0091,336.88,360.44,312.6
180.53443,1.9223,7.8801,0.0,0.0,1.6883,5.8281,279.59,313.84,234.91
181.33443,1.8906,7.8913,0.0,0.0,1.6943,5.7385,202.41,247.43,183.03
182.13443,1.8181,7.9065,0.0,0.0,1.7023,5.5152,85.844,158.79,104.04
182.93443,1.7311,7.9243,0.0,0.0,1.7111,5.2483,74.688,91.368,65.873
183.73444,1.7285,7.9335,0.0,0.0,1.7156,5.2463,67.688,74.417,52.003
184.53444,1.7246,7.9406,0.0,0.0,1.7199,5.2298,62.967,67.134,46.925
185.33444,1.7355,7.9448,0.0,0.0,1.7217,5.2625,59.704,62.384,44.64
186.13444,1.7331,7.9489,0.0,0.0,1.7242,5.2612,57.067,58.388,43.352
186.93444,1.7299,7.9523,0.0,0.0,1.7261,5.2453,54.005,55.123,41.886
187.73444,1.7398,7.9562,0.0,0.0,1.7278,5.2772,51.806,52.618,40.64
188.3712,1.7359,7.9586,0.0,0.0,1.7292,5.2616,50.277,50.826,39.839
189.1712,1.8647,7.962,0.0,0.0,1.7306,5.654,48.069,48.744,38.672
189.9712,1.7975,7.9635,0.0,0.0,1.7318,5.4521,51.555,50.185,42.636
190.7712,1.7515,7.9645,0.0,0.0,1.7323,5.3125,53.648,51.65,45.69
191.5712,1.7595,7.9658,0.0,0.0,1.7329,5.3396,55.118,52.992,47.988
192.3712,1.7198,7.9672,0.0,0.0,1.7341,5.218,56.147,54.121,49.851
193.1712,1.71,7.9712,0.0,0.0,1.7359,5.186,56.98,55.039,51.47
193.9712,1.7038,7.9766,0.0,0.0,1.7384,5.1681,57.408,55.734,52.696
194.7712,1.7276,7.9737,0.0,0.0,1.7372,5.2409,57.73,56.194,53.681
195.5712,1.7166,7.9749,0.0,0.0,1.7378,5.2082,57.771,56.508,54.291
195.9712,1.7129,7.9753,0.0,0.0,1.7378,5.1966,57.819,56.698,54.54