File: examples/dan-msc-case-studies/CS4/data/01 raw data/hyde_test_010.csv
Time(sec),Force(kN),Jaw(mm),PowAngle(deg),PTemp,Strain,Stress(MPa),TC1(C),TC2(C),TC3(C),TC4(C)
0.0,3.073,-10.578,0.0,0.0045301,-0.80283,3.6445,25.157,24.76,24.755,24.262
2.0,2.9149,-0.00015845,0.0,5.8207,-3.7441e-05,3.4593,25.093,24.764,24.717,24.262
3.8381,2.8771,-0.0001319,0.0,11.335,1.331e-05,3.4156,25.068,24.762,24.668,24.25
5.8381,2.8477,5.6673e-05,0.0,17.335,3.9501e-07,3.3797,25.131,24.752,24.694,24.251
7.8381,2.8346,0.00021107,0.0,23.335,1.6424e-06,3.3633,25.116,24.725,24.678,24.27
9.8381,2.85,0.0015837,28.605,29.335,0.00019028,3.3828,26.708,26.019,24.871,24.489
11.8381,2.8507,-0.00017598,31.068,35.335,-1.1533e-05,3.3827,33.793,38.253,27.79,27.312
13.8381,2.8418,-0.00066264,32.166,41.335,-4.8218e-05,3.3728,40.47,37.895,32.619,32.214
15.8381,2.862,-0.00099622,32.544,47.335,-0.00012249,3.3965,46.905,43.154,38.161,37.704
17.8381,2.8558,-0.0023908,32.849,53.335,-0.00029357,3.3887,53.075,48.946,43.844,43.464
19.8381,2.856,-0.0030384,32.974,59.335,-0.00033122,3.39,59.168,54.876,49.574,49.322
21.8381,2.9683,-0.0037888,33.454,65.335,-0.0004053,3.5219,65.171,60.781,55.398,55.227
23.8381,3.5205,0.00084289,34.293,71.335,0.00013104,4.1767,71.146,66.898,61.356,61.113
25.8381,3.5963,0.0022056,34.651,77.335,0.00024345,4.2688,77.158,72.926,67.399,67.183
27.8381,3.6216,0.00051862,34.975,83.335,4.0259e-05,4.2973,83.196,78.97,73.516,73.313
29.8381,3.6273,-0.0017503,35.148,89.335,-0.00020464,4.3053,89.252,85.015,79.565,79.493
31.8381,3.6485,-0.0025303,35.814,95.335,-0.00026652,4.331,95.192,91.064,85.632,85.596
33.8381,3.6489,-0.0047957,36.484,101.34,-0.00051697,4.3291,101.13,97.05,91.649,91.688
35.7613,3.6631,-0.0064001,36.502,107.1,-0.00068426,4.3472,106.99,102.85,97.424,97.506
37.5999,3.6718,-0.0088926,36.419,112.62,-0.0010024,4.3561,112.62,108.36,103.08,103.14
39.5999,3.6681,-0.011015,37.073,118.62,-0.0012406,4.3534,118.52,114.24,109.08,109.3
41.5999,3.6919,-0.013486,37.032,124.62,-0.0014797,4.3812,124.6,120.05,115.1,115.33
43.5999,3.6904,-0.016437,37.238,130.62,-0.0018114,4.3792,130.57,125.97,121.09,121.32
45.5999,3.6989,-0.020008,37.593,136.62,-0.0022151,4.3911,136.56,131.72,127.11,127.39
47.5999,3.7103,-0.022419,37.377,142.62,-0.0024734,4.4023,142.63,137.4,133.08,133.43
49.5999,3.7135,-0.024399,37.967,148.62,-0.0027071,4.4065,148.52,143.08,139.04,139.36
51.5999,3.7269,-0.028141,37.971,154.62,-0.0031438,4.4235,154.56,148.58,144.9,145.32
53.5999,3.7448,-0.031989,38.551,160.62,-0.0035221,4.443,160.52,154.3,150.78,151.1
55.5999,3.7524,-0.034087,38.628,166.62,-0.0037598,4.4543,166.56,160.06,156.67,157.02
57.5999,3.7714,-0.038541,38.824,172.62,-0.0042205,4.4747,172.58,165.71,162.53,162.95
59.5999,3.7702,-0.0426,38.942,178.62,-0.0047192,4.4735,178.59,171.33,168.38,168.88
61.5999,3.7869,-0.0458,38.885,184.62,-0.0050841,4.4949,184.62,176.7,174.28,174.78
63.5999,3.8055,-0.050229,38.897,190.62,-0.0055711,4.5156,190.61,182.17,180.02,180.54
65.5999,3.8059,-0.054455,37.787,196.62,-0.0060073,4.5158,197.0,187.81,185.91,186.48
67.5997,3.8187,-0.058484,36.475,202.63,-0.0064545,4.5324,203.06,193.32,192.03,192.63
69.4269,3.8308,-0.062258,36.779,208.1,-0.00687,4.5451,208.31,197.95,197.4,197.99
71.4269,3.8222,-0.065993,37.599,214.1,-0.0072781,4.5352,213.97,203.05,202.91,203.49
73.4269,3.846,-0.071366,41.709,220.1,-0.0078896,4.5651,220.1,208.56,208.47,209.06
75.4269,3.8522,-0.075287,40.584,226.1,-0.0082884,4.5703,229.95,216.98,216.29,216.89
77.4269,3.8452,-0.0807,41.529,232.1,-0.0089038,4.5633,237.69,224.03,224.03,224.71
79.4269,3.8654,-0.085415,43.24,238.1,-0.0094649,4.5878,245.05,230.81,231.46,232.15
81.4269,3.8566,-0.090923,43.322,244.1,-0.010041,4.5755,252.55,237.71,238.85,239.46
83.4269,3.8599,-0.095648,43.494,250.1,-0.010532,4.5821,259.11,243.92,245.56,246.34
85.4269,3.8651,-0.10086,44.863,256.1,-0.011113,4.5863,265.03,249.35,251.73,252.42
87.4269,3.8676,-0.10492,45.401,262.1,-0.011557,4.5897,271.15,254.93,257.7,258.37
89.4269,3.8709,-0.11417,45.077,268.1,-0.012577,4.5949,277.44,260.68,263.79,264.41
91.4269,3.8798,-0.11503,44.375,274.1,-0.012697,4.6038,283.67,266.44,269.93,270.55
93.4269,3.8666,-0.12246,43.528,280.1,-0.013498,4.5895,289.81,271.9,275.96,276.58
95.4269,3.8786,-0.12665,42.936,286.1,-0.013945,4.6026,295.72,277.38,281.75,282.38
97.4269,3.8739,-0.13311,42.452,292.1,-0.014643,4.5956,301.7,282.94,287.61,288.17
99.4269,3.8692,-0.13889,42.414,298.1,-0.015232,4.5935,307.59,288.49,293.4,293.73
101.2336,3.8834,-0.1445,42.248,303.52,-0.015895,4.6084,313.04,293.65,298.7,298.65
103.2336,3.8758,-0.15326,42.077,309.52,-0.016827,4.5982,318.98,299.27,304.55,304.32
105.2336,3.8819,-0.15866,45.328,315.52,-0.017418,4.6079,328.67,307.33,311.88,312.26
107.2336,3.8888,-0.16704,42.852,321.52,-0.018371,4.6141,336.07,314.7,320.35,320.83
109.2336,3.876,-0.17033,42.63,327.52,-0.018738,4.5999,341.94,320.83,326.88,327.64
111.2336,3.8853,-0.17913,42.821,333.52,-0.019668,4.6116,347.83,326.59,332.84,333.81
113.2336,3.8873,-0.1825,43.13,339.52,-0.020029,4.6115,353.65,332.2,338.6,339.68
115.2336,3.8932,-0.1912,43.326,345.52,-0.020984,4.6209,359.64,337.97,344.44,345.63
117.2336,3.8863,-0.19378,40.633,350.0,-0.021249,4.6117,365.15,343.3,350.35,351.46
119.2336,3.8765,-0.19728,38.763,350.0,-0.021667,4.5994,365.09,344.73,353.19,354.52
121.2336,3.8873,-0.20006,37.98,350.0,-0.021967,4.6149,364.79,345.47,353.79,355.19
123.2336,3.9026,-0.20126,37.837,350.0,-0.022106,4.6305,364.54,346.03,353.87,355.3
125.2336,3.8781,-0.20755,38.871,350.0,-0.022773,4.6024,365.47,347.11,353.94,355.37
127.2336,3.9027,-0.21023,38.789,350.0,-0.023042,4.6316,367.37,349.09,355.27,356.72
129.2336,3.8857,-0.21538,37.917,350.0,-0.023621,4.6104,368.29,350.38,356.68,358.01
131.2336,3.892,-0.21762,36.959,350.0,-0.023834,4.6199,367.54,350.48,356.89,358.32
133.1642,3.9017,-0.22009,36.636,350.0,-0.024134,4.6293,366.76,350.21,356.35,357.83
135.0059,3.8784,-0.22218,34.842,350.0,-0.02434,4.6034,365.73,349.81,355.65,357.06
137.0059,3.9002,-0.22289,34.293,350.0,-0.024438,4.629,362.46,347.39,353.36,354.81
139.0059,3.9109,-0.22294,34.202,350.0,-0.024457,4.64,359.97,345.68,350.94,352.42
141.0059,3.894,-0.22517,33.615,350.0,-0.024672,4.6228,358.37,344.64,349.16,350.59
143.0059,3.9023,-0.2277,34.119,350.0,-0.024934,4.6313,356.6,343.33,347.3,348.72
145.0059,3.9023,-0.22875,34.356,350.0,-0.025059,4.6304,355.43,342.34,345.56,347.02
147.0059,3.9094,-0.2325,34.514,350.0,-0.025426,4.6403,355.06,342.12,344.7,346.11
149.0059,3.9079,-0.23332,33.343,350.0,-0.025552,4.637,354.73,342.02,344.17,345.56
151.0059,3.9071,-0.2337,33.772,350.0,-0.025616,4.636,353.38,340.96,343.11,344.51
153.0059,3.9154,-0.23702,34.77,350.0,-0.026,4.6469,354.98,342.34,343.24,344.66
155.0059,3.9062,-0.23923,34.592,350.0,-0.026206,4.6343,355.13,342.73,343.71,345.12
157.0059,3.9132,-0.24207,34.415,350.0,-0.026522,4.6448,355.13,342.89,343.85,345.22
159.0059,3.9181,-0.2436,34.123,350.0,-0.026668,4.65,355.17,343.04,343.83,345.23
161.0059,3.9181,-0.24418,33.996,350.0,-0.02672,4.6494,355.17,343.2,343.9,345.31
161.9513,3.9286,-0.0065269,0.0,0.00014849,-0.00016812,4.6613,355.28,343.3,344.31,345.11
161.9523,3.8891,0.0048516,0.0,3.4264e-18,0.00023535,4.6232,355.3,343.32,344.39,345.09
161.9533,3.934,0.0035407,0.0,7.9067e-32,0.00075873,4.6524,355.31,343.34,344.46,345.06
161.9543,3.8757,-0.0025346,0.0,1.4013e-45,-0.0007861,4.609,355.33,343.36,344.54,345.04
161.9553,3.9348,-0.00023584,0.0,0.0,0.00044179,4.6674,355.34,343.38,344.58,345.02
161.9563,3.89,-0.00046976,0.0,0.0,0.00037623,4.6242,355.33,343.37,344.51,345.04
161.9573,3.942,0.0073355,0.0,0.0,-0.00024247,4.6754,355.32,343.37,344.45,345.06
161.9583,3.8889,-0.0077498,0.0,0.0,-1.1452e-06,4.6162,355.32,343.37,344.38,345.08
161.9593,3.9413,0.0023922,0.0,0.0,-0.00010611,4.6703,355.31,343.37,344.32,345.1
161.9603,3.8829,0.0083038,0.0,0.0,0.00075175,4.6142,355.31,343.36,344.26,345.12
161.9613,3.9354,-0.0071709,0.0,0.0,-0.00071325,4.6613,355.3,343.36,344.19,345.13
161.9623,3.8754,0.0042074,0.0,0.0,0.00018529,4.6,355.29,343.36,344.13,345.15
161.9633,3.9481,0.0028278,0.0,0.0,0.00080796,4.6783,355.29,343.35,344.06,345.17
161.9643,3.8749,0.00067539,0.0,0.0,-0.00082626,4.6,355.28,343.35,344.0,345.19
161.9653,3.9429,-0.0027668,0.0,0.0,0.0003946,4.6845,355.28,343.35,343.96,345.2
161.9663,3.8691,5.3076e-06,0.0,0.0,0.00025386,4.599,355.27,343.34,343.95,345.21
161.9673,3.9424,0.0083741,0.0,0.0,0.00016793,4.6773,355.27,343.34,343.95,345.22
161.9683,3.8747,-0.0088614,0.0,0.0,-0.00047096,4.5981,355.27,343.34,343.95,345.22
161.9693,3.9427,0.0060417,0.0,0.0,9.4558e-05,4.6845,355.26,343.34,343.94,345.23
161.9703,3.8685,0.0028803,0.0,0.0,0.00090934,4.599,355.26,343.33,343.94,345.23
161.9713,3.9416,-0.0019722,0.0,0.0,-0.00088145,4.6693,355.26,343.33,343.94,345.24
161.9723,3.8616,-0.0016383,0.0,0.0,0.00034583,4.5839,355.26,343.33,343.93,345.25
161.9733,3.9421,0.00026592,0.0,0.0,0.00049654,4.6764,355.25,343.32,343.93,345.25
161.9743,3.8678,0.0059466,0.0,0.0,-0.0002632,4.5839,355.25,343.32,343.93,345.26
161.9753,3.9413,-0.0070034,0.0,0.0,1.8694e-05,4.6694,355.25,343.32,343.93,345.26
161.9763,3.8688,0.0031731,0.0,0.0,1.5186e-05,4.5981,355.24,343.32,343.93,345.26
161.9773,3.9305,0.0061341,0.0,0.0,0.00062869,4.6783,355.24,343.33,343.93,345.26
161.9783,3.8618,-0.0057983,0.0,0.0,-0.00072275,4.5829,355.24,343.33,343.94,345.26
161.9793,3.9305,0.0031319,0.0,0.0,0.00048748,4.6765,355.23,343.33,343.94,345.26
161.9803,3.8609,0.0013714,0.0,0.0,0.00080792,4.5829,355.23,343.33,343.94,345.26
161.9813,3.923,0.001478,0.0,0.0,-0.00076081,4.6623,355.23,343.34,343.94,345.26
161.9823,3.8602,-0.0049152,0.0,0.0,0.00018649,4.5749,355.23,343.34,343.95,345.26
161.9833,3.9352,0.0012884,0.0,0.0,0.00017879,4.6623,355.22,343.34,343.95,345.26
161.9843,3.8621,0.0070201,0.0,0.0,7.2591e-05,4.5943,355.22,343.35,343.95,345.26
161.9853,3.9341,-0.0081504,0.0,0.0,-0.00045107,4.6534,355.22,343.35,343.96,345.26
161.9863,3.8487,0.0031518,0.0,0.0,-8.7064e-05,4.5729,355.22,343.35,343.95,345.26
161.9873,3.9167,0.0042144,0.0,0.0,0.00079757,4.6622,355.22,343.36,343.95,345.26
161.9883,3.8605,0.00010605,0.0,0.0,-0.00085073,4.581,355.23,343.36,343.95,345.26
161.9893,3.923,-0.0023427,0.0,0.0,0.00027075,4.6623,355.23,343.36,343.94,345.26
161.9903,3.8558,0.00098222,0.0,0.0,0.00050734,4.5899,355.23,343.36,343.94,345.26
161.9913,3.9354,0.0074039,0.0,0.0,-0.00010171,4.6704,355.24,343.37,343.94,345.26
161.9923,3.8671,-0.0084911,0.0,0.0,-6.8136e-05,4.5881,355.24,343.37,343.93,345.26
161.9933,3.9219,0.0045575,0.0,0.0,-2.9637e-05,4.6552,355.24,343.37,343.93,345.26
161.9943,3.8536,0.0049056,0.0,0.0,0.0007595,4.5659,355.25,343.38,343.93,345.26
161.9953,3.9234,-0.0050872,0.0,0.0,-0.00061737,4.6684,355.25,343.38,343.92,345.26
161.9963,3.8684,0.0017139,0.0,0.0,0.00034628,4.5942,355.24,343.37,343.92,345.26
161.9973,3.9222,0.0012784,0.0,0.0,0.00076217,4.6543,355.24,343.36,343.92,345.26
161.9983,3.8605,0.0035923,0.0,0.0,-0.0006189,4.5748,355.24,343.36,343.92,345.26
161.9993,3.9178,-0.0061247,0.0,0.0,0.00034712,4.6703,355.23,343.35,343.91,345.26
162.0003,3.8609,0.00047401,0.0,0.0,2.8175e-05,4.573,355.23,343.35,343.91,345.26
162.0013,3.917,0.0078205,0.0,0.0,0.00024262,4.6623,355.23,343.34,343.91,345.26
162.0023,3.8674,-0.0090584,0.0,0.0,-0.0006571,4.5871,355.23,343.33,343.9,345.26
162.0033,3.9097,0.0039723,0.0,0.0,-2.1086e-05,4.6472,355.22,343.33,343.9,345.26
162.0043,3.9016,0.0028689,0.0,0.0,0.00094867,4.6343,355.22,343.32,343.9,345.26
162.0053,3.8875,-0.0012436,0.0,0.0,-0.0007969,4.6071,355.22,343.31,343.89,345.26
162.0063,3.8883,-0.0022924,0.0,0.0,0.00027935,4.615,355.21,343.3,343.89,345.26
162.0073,4.4523,0.00098555,0.0,0.0,0.00049738,5.2979,355.2,343.28,343.88,345.26
162.0083,3.5273,0.0067748,0.0,0.0,-0.00020609,4.2137,355.2,343.27,343.87,345.26
162.0093,4.2502,-0.0070325,0.0,0.0,9.3192e-05,5.0341,355.19,343.25,343.87,345.26
162.0103,3.5985,8.8326e-06,0.0,0.0,-0.0004568,4.2796,355.18,343.24,343.86,345.26
162.0113,4.046,0.010058,0.0,0.0,0.0011879,4.8178,355.18,343.22,343.86,345.26
162.0123,3.6219,-0.012972,0.0,0.0,-0.0016454,4.2876,355.17,343.21,343.85,345.26
162.0133,3.9196,0.00094583,0.0,0.0,0.00028158,4.6723,355.17,343.19,343.84,345.26
162.0143,3.7519,-0.0055692,0.0,0.0,6.4805e-05,4.4543,355.16,343.18,343.84,345.26
162.0153,3.9449,0.0012792,0.0,0.0,-0.00089761,4.6904,355.76,343.71,343.83,345.27
162.0163,3.633,-0.010838,0.0,0.0,-0.00028811,4.3205,357.26,345.07,343.82,345.28
162.0173,4.0723,0.0049318,0.0,0.0,0.00040533,4.839,358.76,346.43,343.81,345.28
162.0183,3.601,0.0019218,0.0,0.0,-0.00013071,4.2515,360.26,347.78,343.79,345.29
162.0193,4.0841,-0.0036405,0.0,0.0,-6.7469e-05,4.838,361.76,349.14,343.78,345.3
162.0203,3.6803,0.0031076,0.0,0.0,-0.00017214,4.376,363.26,350.5,343.77,345.31
162.0213,3.959,0.0074763,0.0,0.0,0.001399,4.7198,364.76,351.86,343.76,345.32
162.0223,3.7127,0.001132,0.0,0.0,-0.00047212,4.414,366.26,353.21,343.74,345.33
162.0233,3.9842,0.0032341,0.0,0.0,0.00096563,4.7357,367.76,354.57,343.73,345.34
162.0243,3.4913,-0.0020592,0.0,0.0,0.00013145,4.1845,369.26,355.93,343.72,345.35
162.0253,66.677,0.23049,0.0,0.0,0.024432,76.02,371.35,357.72,343.73,345.35
162.0263,95.579,0.6865,0.0,0.0,0.077471,113.25,374.25,360.12,343.76,345.33
162.0273,107.47,1.1462,0.0,0.0,0.13202,126.84,377.14,362.51,343.8,345.31
162.0283,107.88,1.7665,0.0,0.0,0.21356,128.23,380.04,364.9,343.84,345.29
162.0293,112.96,2.1798,0.0,0.0,0.2697,133.9,382.94,367.29,343.87,345.27
162.0303,112.91,2.8573,0.0,0.0,0.3697,133.93,385.84,369.69,343.91,345.25
162.0313,115.58,3.3163,0.0,0.0,0.44363,137.2,388.74,372.08,343.95,345.24
162.0323,115.88,3.8972,0.0,0.0,0.54087,137.38,391.64,374.47,343.98,345.22
162.0333,117.59,4.3707,0.0,0.0,0.63261,139.51,394.53,376.87,344.02,345.2
162.0343,118.58,4.8546,0.0,0.0,0.72819,140.69,397.43,379.26,344.06,345.18
162.0353,118.32,5.3207,0.0,0.0,0.83268,140.42,399.43,380.64,344.07,345.18
162.0363,119.09,5.7068,0.0,0.0,0.92791,141.33,400.28,380.73,344.07,345.2
162.0373,118.82,6.1089,0.0,0.0,1.0326,140.93,401.13,380.82,344.06,345.22
162.0383,118.96,6.4499,0.0,0.0,1.1364,141.2,401.98,380.91,344.06,345.24
162.0393,118.31,6.7498,0.0,0.0,1.2244,140.38,402.84,381.0,344.05,345.27
162.0403,118.4,7.0427,0.0,0.0,1.333,140.51,403.69,381.09,344.04,345.29
162.0413,118.91,7.281,0.0,0.0,1.4205,141.04,404.54,381.18,344.04,345.31
162.0423,120.19,7.5263,0.0,0.0,1.5167,142.55,405.39,381.27,344.03,345.33
162.0433,107.05,7.6285,0.0,0.0,1.5726,126.97,406.24,381.37,344.03,345.35
162.0443,102.2,7.6565,0.0,0.0,1.577,121.32,407.1,381.46,344.02,345.37
162.0453,99.722,7.7006,0.0,0.0,1.603,118.47,407.17,380.99,343.99,345.39
162.0463,97.561,7.6657,0.0,0.0,1.5816,115.85,406.33,379.88,343.92,345.39
162.0473,94.718,7.6979,0.0,0.0,1.6018,112.53,405.48,378.77,343.86,345.4
162.0483,92.868,7.7111,0.0,0.0,1.609,110.29,404.64,377.66,343.8,345.41
162.0493,91.134,7.7113,0.0,0.0,1.5985,108.19,403.8,376.55,343.73,345.41
162.0503,89.303,7.7067,0.0,0.0,1.6104,106.01,402.96,375.44,343.67,345.42
162.0513,88.378,7.726,0.0,0.0,1.6091,104.93,402.12,374.33,343.6,345.42
162.0523,87.372,7.7258,0.0,0.0,1.612,103.69,401.28,373.22,343.54,345.43
162.0533,86.139,7.7169,0.0,0.0,1.6102,102.25,400.44,372.11,343.48,345.44
162.0543,85.374,7.733,0.0,0.0,1.6123,101.36,399.59,371.0,343.41,345.44
162.0553,84.55,7.7227,0.0,0.0,1.6165,100.35,398.9,370.22,343.39,345.45
162.0563,83.614,7.7392,0.0,0.0,1.6133,99.231,398.36,369.79,343.4,345.47
162.0573,82.887,7.7259,0.0,0.0,1.6173,98.392,397.82,369.36,343.42,345.49
162.0583,82.33,7.729,0.0,0.0,1.6148,97.726,397.28,368.93,343.43,345.51
162.0593,81.589,7.7486,0.0,0.0,1.6187,96.834,396.74,368.51,343.45,345.53
162.0603,80.899,7.724,0.0,0.0,1.6164,96.02,396.19,368.08,343.46,345.55
162.0613,80.374,7.7468,0.0,0.0,1.6178,95.415,395.65,367.65,343.48,345.56
162.0623,79.895,7.744,0.0,0.0,1.6252,94.822,395.11,367.22,343.49,345.58
162.0633,79.355,7.7375,0.0,0.0,1.6136,94.191,394.57,366.8,343.51,345.6
162.0643,78.893,7.7472,0.0,0.0,1.6237,93.635,394.03,366.37,343.52,345.62
162.0653,78.381,7.7438,0.0,0.0,1.6252,93.052,393.54,366.0,343.55,345.62
162.0663,77.965,7.7534,0.0,0.0,1.6187,92.53,393.1,365.69,343.59,345.62
162.0673,77.559,7.7368,0.0,0.0,1.6239,92.048,392.66,365.37,343.64,345.61
162.0683,77.19,7.7538,0.0,0.0,1.6211,91.599,392.22,365.06,343.68,345.61
162.0693,76.705,7.7571,0.0,0.0,1.6278,91.029,391.78,364.75,343.72,345.6
162.0703,76.385,7.7406,0.0,0.0,1.62,90.64,391.34,364.44,343.77,345.59
162.0713,76.027,7.7524,0.0,0.0,1.6236,90.23,390.89,364.12,343.81,345.59
162.0723,75.709,7.7481,0.0,0.0,1.6278,89.863,390.45,363.81,343.85,345.58
162.0733,75.351,7.7561,0.0,0.0,1.6208,89.441,390.01,363.5,343.89,345.58
162.0743,75.066,7.7448,0.0,0.0,1.6272,89.094,389.57,363.19,343.94,345.57
162.0753,74.759,7.7504,0.0,0.0,1.6239,88.717,389.16,362.89,343.96,345.56
162.0763,74.476,7.7613,0.0,0.0,1.6255,88.395,388.77,362.61,343.97,345.54
162.0773,74.17,7.7402,0.0,0.0,1.6238,88.011,388.38,362.33,343.97,345.53
162.0783,73.905,7.7614,0.0,0.0,1.6242,87.704,388.0,362.05,343.98,345.51
162.0793,73.581,7.752,0.0,0.0,1.6294,87.328,387.61,361.77,343.98,345.5
162.0803,73.328,7.7491,0.0,0.0,1.6193,87.006,387.22,361.49,343.99,345.48
162.0813,72.985,7.7575,0.0,0.0,1.6296,86.62,386.84,361.21,344.0,345.47
162.0823,72.735,7.7506,0.0,0.0,1.6268,86.329,386.45,360.94,344.0,345.45
162.0833,72.336,7.7629,0.0,0.0,1.6236,85.859,386.06,360.66,344.01,345.44
162.0843,71.79,7.7453,0.0,0.0,1.628,85.224,385.68,360.38,344.01,345.42
162.0853,70.876,7.7577,0.0,0.0,1.6233,84.132,385.38,360.15,343.99,345.41
162.0863,69.814,7.7603,0.0,0.0,1.6299,82.893,385.15,359.98,343.95,345.41
162.0873,68.333,7.7435,0.0,0.0,1.6208,81.135,384.93,359.81,343.91,345.41
162.0883,66.642,7.7533,0.0,0.0,1.6242,79.143,384.71,359.64,343.87,345.41
162.0893,64.377,7.7434,0.0,0.0,1.6253,76.481,384.48,359.46,343.82,345.41
162.0903,61.663,7.7475,0.0,0.0,1.6164,73.273,384.26,359.29,343.78,345.41
162.0913,52.995,7.7197,0.0,0.0,1.616,63.453,384.03,359.12,343.74,345.41
162.0923,24.407,7.659,0.0,0.0,1.5817,30.031,383.81,358.94,343.7,345.41
162.0933,-1.3104,7.5932,0.0,0.0,1.5507,-0.97299,383.59,358.77,343.65,345.41
162.0943,-0.33946,7.4893,0.0,0.0,1.5117,-0.55555,383.36,358.6,343.61,345.41
162.0953,-0.7561,7.5721,0.0,0.0,1.5368,-0.8809,383.25,358.59,343.58,345.43
162.0963,8.4897,7.612,0.0,0.0,1.5657,10.246,383.22,358.71,343.57,345.45
162.0973,2.0841,7.628,0.0,0.0,1.5631,2.9242,383.19,358.82,343.56,345.47
162.0983,1.3882,7.5758,0.0,0.0,1.5462,1.5872,383.16,358.94,343.55,345.49
162.0993,4.0898,7.6306,0.0,0.0,1.572,5.0832,383.13,359.06,343.54,345.51
162.1003,4.4691,7.6269,0.0,0.0,1.5612,5.3721,383.1,359.18,343.52,345.53
162.1013,2.3243,7.6086,0.0,0.0,1.5645,2.8024,383.07,359.3,343.51,345.55
162.1023,3.8961,7.6231,0.0,0.0,1.5604,4.6702,383.04,359.42,343.5,345.58
162.1033,3.6081,7.6284,0.0,0.0,1.5686,4.297,383.01,359.53,343.49,345.6
162.1043,3.6054,7.6086,0.0,0.0,1.5587,4.2524,382.98,359.65,343.48,345.62
162.1053,3.2056,7.6363,0.0,0.0,1.571,3.8152,382.97,359.75,343.5,345.64
162.1063,4.0038,7.6132,0.0,0.0,1.5659,4.733,382.97,359.84,343.54,345.65
162.1073,2.7015,7.6189,0.0,0.0,1.5579,3.1643,382.98,359.93,343.59,345.67
162.1083,3.8412,7.615,0.0,0.0,1.5683,4.5798,382.99,360.02,343.63,345.68
162.1093,2.9973,7.619,0.0,0.0,1.5625,3.505,382.99,360.11,343.68,345.7
162.1103,3.3349,7.6293,0.0,0.0,1.5668,3.9783,383.0,360.19,343.72,345.71
162.1113,2.8968,7.6071,0.0,0.0,1.5613,3.4229,383.0,360.28,343.77,345.73
162.1123,3.3614,7.622,0.0,0.0,1.561,3.9862,383.01,360.37,343.82,345.74
162.1133,3.035,7.6187,0.0,0.0,1.5681,3.5975,383.02,360.46,343.86,345.76
162.1143,3.4306,7.6192,0.0,0.0,1.5591,4.0894,383.02,360.55,343.91,345.77
162.1153,3.1552,7.6107,0.0,0.0,1.5635,3.7379,383.02,360.59,343.94,345.74
162.1163,3.3232,7.6091,0.0,0.0,1.5609,3.968,383.02,360.61,343.95,345.68
162.1173,3.2024,7.6263,0.0,0.0,1.5613,3.7912,383.02,360.62,343.97,345.62
162.1183,3.3571,7.6004,0.0,0.0,1.5613,4.0081,383.02,360.64,343.99,345.56
162.1193,3.247,7.6212,0.0,0.0,1.5607,3.8212,383.02,360.65,344.01,345.5
162.1203,3.2335,7.6234,0.0,0.0,1.568,3.8546,383.02,360.67,344.03,345.44
162.1213,3.2286,7.6074,0.0,0.0,1.5573,3.8152,383.02,360.68,344.05,345.38
162.1223,3.3138,7.6258,0.0,0.0,1.5669,3.9428,383.02,360.7,344.06,345.32
162.1233,3.216,7.616,0.0,0.0,1.5661,3.8105,383.02,360.71,344.08,345.26
162.1243,3.2418,7.627,0.0,0.0,1.5607,3.8646,383.02,360.73,344.1,345.19
162.1253,3.3288,7.6111,0.0,0.0,1.5664,3.9256,383.01,360.74,344.09,345.17
162.1263,3.228,7.6225,0.0,0.0,1.5629,3.8504,382.99,360.75,344.05,345.17
162.1273,3.3331,7.6272,0.0,0.0,1.5667,3.958,382.98,360.76,344.02,345.16
162.1283,3.2724,7.6064,0.0,0.0,1.5611,3.8846,382.96,360.78,343.99,345.16
162.1293,3.2459,7.6231,0.0,0.0,1.5621,3.8634,382.94,360.79,343.95,345.16
162.1303,3.4012,7.6179,0.0,0.0,1.5681,4.0375,382.92,360.8,343.92,345.15
162.1313,3.306,7.6141,0.0,0.0,1.5577,3.9338,382.9,360.81,343.89,345.15
162.1323,3.3216,7.6148,0.0,0.0,1.566,3.958,382.89,360.83,343.85,345.15
162.1333,3.3215,7.6129,0.0,0.0,1.5622,3.9217,382.87,360.84,343.82,345.15
162.1343,3.3189,7.6289,0.0,0.0,1.5627,3.9268,382.85,360.85,343.79,345.14
162.1353,3.3032,7.6027,0.0,0.0,1.5627,3.9037,382.82,360.85,343.77,345.16
162.1363,3.2612,7.6227,0.0,0.0,1.5613,3.8876,382.79,360.83,343.75,345.18
162.1373,3.337,7.6222,0.0,0.0,1.5683,3.9368,382.76,360.82,343.74,345.21
162.1383,3.3749,7.6154,0.0,0.0,1.559,4.0123,382.72,360.81,343.73,345.23
162.1393,3.2708,7.6212,0.0,0.0,1.5651,3.8805,382.69,360.8,343.72,345.25
162.1403,3.382,7.6138,0.0,0.0,1.5655,4.0231,382.66,360.79,343.71,345.28
162.1413,3.3028,7.6257,0.0,0.0,1.5608,3.9037,382.62,360.77,343.69,345.3
162.1423,3.388,7.6088,0.0,0.0,1.5655,4.0251,382.59,360.76,343.68,345.33
162.1433,3.3052,7.6207,0.0,0.0,1.5614,3.9189,382.56,360.75,343.67,345.35
162.1443,3.3798,7.6279,0.0,0.0,1.5666,4.0043,382.52,360.74,343.66,345.38
162.1453,3.315,7.6061,0.0,0.0,1.5601,3.9018,382.51,360.7,343.67,345.39
162.1463,3.3517,7.6268,0.0,0.0,1.5638,4.0062,382.5,360.64,343.69,345.39
162.1473,3.3962,7.6142,0.0,0.0,1.5671,4.0031,382.5,360.59,343.72,345.4
162.1483,3.3021,7.6191,0.0,0.0,1.5588,3.9318,382.49,360.53,343.74,345.41
162.1493,3.4717,7.615,0.0,0.0,1.5667,4.1005,382.48,360.48,343.77,345.41
162.1503,3.2938,7.612,0.0,0.0,1.5619,3.9128,382.48,360.42,343.79,345.42
162.1513,3.4134,7.6268,0.0,0.0,1.5629,4.0552,382.47,360.37,343.81,345.42
162.1523,3.2883,7.6049,0.0,0.0,1.5627,3.919,382.47,360.31,343.84,345.43
162.1533,3.4532,7.6219,0.0,0.0,1.5608,4.0884,382.46,360.26,343.86,345.44
162.1543,3.3138,7.6207,0.0,0.0,1.568,3.9359,382.45,360.2,343.89,345.44
162.1553,3.4671,7.6092,0.0,0.0,1.5569,4.1075,382.44,360.15,343.89,345.45
162.1563,3.3399,7.6208,0.0,0.0,1.5661,3.97,382.43,360.11,343.88,345.47
162.1573,3.4593,7.6135,0.0,0.0,1.5645,4.0854,382.42,360.06,343.87,345.48
162.1583,3.374,7.6255,0.0,0.0,1.5604,4.0121,382.41,360.01,343.86,345.49
162.1593,3.4865,7.6102,0.0,0.0,1.5652,4.1297,382.39,359.96,343.85,345.5
162.1603,3.4083,7.6198,0.0,0.0,1.5604,4.0543,382.38,359.91,343.84,345.51
162.1613,3.4939,7.6235,0.0,0.0,1.5656,4.1377,382.37,359.86,343.83,345.53
162.1623,3.4213,7.6068,0.0,0.0,1.5599,4.0614,382.36,359.81,343.83,345.54
162.1633,3.5227,7.6233,0.0,0.0,1.5633,4.1779,382.35,359.77,343.82,345.55
162.1643,3.4069,7.6125,0.0,0.0,1.5658,4.0383,382.33,359.72,343.81,345.56
162.1653,3.6584,7.6204,0.0,0.0,1.5586,4.3477,382.31,359.67,343.8,345.58
162.1663,3.3469,7.6114,0.0,0.0,1.5657,3.9731,382.28,359.62,343.79,345.6
162.1673,3.697,7.6133,0.0,0.0,1.5613,4.3768,382.25,359.57,343.79,345.62
162.1683,3.3474,7.6254,0.0,0.0,1.5626,3.9783,382.22,359.52,343.78,345.63
162.1693,3.7025,7.6015,0.0,0.0,1.5606,4.3768,382.19,359.47,343.78,345.65
162.1703,3.2991,7.6219,0.0,0.0,1.5608,3.9098,382.16,359.43,343.77,345.67
162.1713,3.7386,7.6184,0.0,0.0,1.567,4.4351,382.13,359.38,343.76,345.69
162.1723,3.2857,7.6112,0.0,0.0,1.5566,3.8979,382.1,359.33,343.76,345.71
162.1733,3.6658,7.6193,0.0,0.0,1.5655,4.3557,382.07,359.28,343.75,345.73
162.1743,3.2811,7.6096,0.0,0.0,1.5628,3.9158,382.04,359.23,343.75,345.74
162.1753,3.6785,7.627,0.0,0.0,1.561,4.3707,382.0,359.16,343.76,345.74
162.1763,3.2999,7.6043,0.0,0.0,1.5633,3.9168,381.97,359.08,343.79,345.73
162.1773,3.6709,7.6175,0.0,0.0,1.5601,4.3565,381.93,359.0,343.81,345.72
162.1783,3.3379,7.6228,0.0,0.0,1.5656,3.9461,381.89,358.92,343.83,345.7
162.1793,3.5652,7.6056,0.0,0.0,1.5582,4.2402,381.86,358.85,343.86,345.69
162.1803,3.3799,7.6219,0.0,0.0,1.563,4.0083,381.82,358.77,343.88,345.68
162.1813,3.5907,7.6132,0.0,0.0,1.5655,4.2673,381.78,358.69,343.91,345.67
162.1823,3.3871,7.6195,0.0,0.0,1.5578,4.0192,381.75,358.61,343.93,345.65
162.1833,3.5105,7.6099,0.0,0.0,1.5647,4.1707,381.71,358.53,343.96,345.64
162.1843,3.4604,7.6125,0.0,0.0,1.5609,4.1026,381.68,358.45,343.98,345.63
162.1853,3.5254,7.6249,0.0,0.0,1.5631,4.2021,381.63,358.38,343.98,345.63
162.1863,3.5132,7.6001,0.0,0.0,1.5603,4.1568,381.59,358.31,343.97,345.63
162.1873,3.5198,7.6226,0.0,0.0,1.5611,4.1589,381.54,358.24,343.95,345.63
162.1883,3.3347,7.6147,0.0,0.0,1.566,3.9782,381.5,358.17,343.94,345.63
162.1893,3.5965,7.6111,0.0,0.0,1.5562,4.2705,381.45,358.1,343.93,345.63
162.1903,3.3114,7.6144,0.0,0.0,1.5648,3.921,381.41,358.03,343.92,345.63
162.1913,3.6122,7.6148,0.0,0.0,1.5644,4.2995,381.36,357.96,343.9,345.63
162.1923,3.4124,7.6241,0.0,0.0,1.5602,4.0443,381.32,357.89,343.89,345.63
162.1933,3.5763,7.6043,0.0,0.0,1.5637,4.2422,381.27,357.82,343.88,345.63
162.1943,3.3244,7.6184,0.0,0.0,1.5605,3.942,381.22,357.75,343.87,345.63
162.1953,3.5884,7.6224,0.0,0.0,1.5666,4.2423,381.18,357.7,343.86,345.63
162.1963,3.2771,7.6057,0.0,0.0,1.5583,3.8797,381.13,357.65,343.85,345.63
162.1973,3.5437,7.6215,0.0,0.0,1.5638,4.2071,381.09,357.61,343.84,345.63
162.1983,3.3362,7.6117,0.0,0.0,1.5653,3.9349,381.04,357.56,343.83,345.63
162.1993,3.5488,7.6196,0.0,0.0,1.5581,4.1971,381.0,357.52,343.82,345.63
162.2003,3.3045,7.6093,0.0,0.0,1.5648,3.9199,380.95,357.47,343.81,345.63
162.2013,3.6585,7.6167,0.0,0.0,1.5619,4.3409,380.91,357.42,343.8,345.63
162.2023,3.1828,7.6235,0.0,0.0,1.5628,3.7823,380.86,357.38,343.79,345.63
162.2033,3.6942,7.6065,0.0,0.0,1.5612,4.3888,380.82,357.33,343.78,345.63
162.2043,3.2578,7.6195,0.0,0.0,1.5593,3.8768,380.77,357.29,343.78,345.63
162.2053,3.6758,7.6194,0.0,0.0,1.5684,4.3848,380.72,357.22,343.78,345.63
162.2063,3.3134,7.6124,0.0,0.0,1.5563,3.8977,380.67,357.15,343.8,345.64
162.2073,3.6489,7.6153,0.0,0.0,1.5655,4.3639,380.62,357.08,343.81,345.64
162.2083,3.3618,7.6116,0.0,0.0,1.5628,3.9609,380.57,357.0,343.82,345.65
162.2093,3.5946,7.6272,0.0,0.0,1.5618,4.2824,380.51,356.93,343.83,345.66
162.2103,3.4118,7.6018,0.0,0.0,1.5618,4.0424,380.46,356.86,343.84,345.66
162.2113,3.6,7.6248,0.0,0.0,1.5615,4.2915,380.41,356.78,343.86,345.67
162.2123,3.4906,7.6181,0.0,0.0,1.5658,4.1136,380.36,356.71,343.87,345.67
162.2133,3.5179,7.6068,0.0,0.0,1.5579,4.1861,380.31,356.64,343.88,345.68
162.2143,3.4389,7.6186,0.0,0.0,1.5631,4.0755,380.26,356.57,343.89,345.69
162.2153,3.5447,7.6139,0.0,0.0,1.566,4.2102,380.2,356.47,343.89,345.69
162.2163,3.4459,7.6201,0.0,0.0,1.5577,4.0865,380.14,356.38,343.88,345.7
162.2173,3.5732,7.6086,0.0,0.0,1.5649,4.2523,380.08,356.28,343.88,345.71
162.2183,3.4652,7.6143,0.0,0.0,1.5602,4.0978,380.03,356.18,343.87,345.71
162.2193,3.5188,7.6253,0.0,0.0,1.5644,4.1891,379.97,356.08,343.87,345.72
162.2203,3.5054,7.6011,0.0,0.0,1.559,4.1418,379.91,355.99,343.86,345.72
162.2213,3.5927,7.6265,0.0,0.0,1.5626,4.2736,379.85,355.89,343.85,345.73
162.2223,3.4454,7.6125,0.0,0.0,1.5655,4.0715,379.8,355.79,343.85,345.74
162.2233,3.6085,7.6163,0.0,0.0,1.5581,4.3077,379.74,355.7,343.84,345.74
162.2243,3.4845,7.6132,0.0,0.0,1.5651,4.1077,379.68,355.6,343.84,345.75
162.2253,3.6087,7.6129,0.0,0.0,1.5626,4.3036,379.63,355.52,343.84,345.74
162.2263,3.5378,7.6257,0.0,0.0,1.5613,4.1707,379.59,355.44,343.84,345.74
162.2273,3.5542,7.6043,0.0,0.0,1.5633,4.2411,379.54,355.36,343.84,345.73
162.2283,3.5404,7.6194,0.0,0.0,1.559,4.196,379.5,355.28,343.85,345.73
162.2293,3.5462,7.6213,0.0,0.0,1.5678,4.2212,379.45,355.2,343.85,345.72
162.2303,3.5801,7.6073,0.0,0.0,1.5572,4.2342,379.41,355.12,343.85,345.71
162.2313,3.5483,7.6217,0.0,0.0,1.5648,4.2434,379.36,355.04,343.86,345.71
162.2323,3.5524,7.61,0.0,0.0,1.5643,4.195,379.32,354.96,343.86,345.7
162.2333,3.5122,7.6232,0.0,0.0,1.5589,4.1871,379.27,354.88,343.86,345.7
162.2343,3.5733,7.6051,0.0,0.0,1.5643,4.2202,379.23,354.81,343.86,345.69
162.2353,3.5143,7.6172,0.0,0.0,1.5611,4.2061,379.18,354.73,343.88,345.7
162.2363,3.5733,7.6231,0.0,0.0,1.564,4.2201,379.15,354.66,343.89,345.71
162.2373,3.4726,7.6026,0.0,0.0,1.5593,4.1419,379.11,354.59,343.91,345.72
162.2383,3.6208,7.6222,0.0,0.0,1.5617,4.2843,379.07,354.51,343.92,345.73
162.2393,3.4804,7.615,0.0,0.0,1.5673,4.159,379.03,354.44,343.94,345.75
162.2403,3.6276,7.6137,0.0,0.0,1.5564,4.2844,378.99,354.37,343.95,345.76
162.2413,3.4584,7.6118,0.0,0.0,1.5652,4.1239,378.95,354.29,343.97,345.77
162.2423,3.6286,7.6103,0.0,0.0,1.5602,4.2934,378.91,354.22,343.98,345.78
162.2433,3.4662,7.6273,0.0,0.0,1.5623,4.1469,378.87,354.15,344.0,345.8
162.2443,3.6543,7.6025,0.0,0.0,1.5616,4.3165,378.83,354.08,344.01,345.81
162.2453,3.4314,7.6218,0.0,0.0,1.5604,4.0865,378.78,354.0,344.03,345.81
162.2463,3.6156,7.616,0.0,0.0,1.5655,4.2914,378.72,353.92,344.05,345.82
162.2473,3.4062,7.6087,0.0,0.0,1.5573,4.0766,378.67,353.84,344.07,345.83
162.2483,3.6547,7.6166,0.0,0.0,1.5634,4.3226,378.61,353.76,344.09,345.83
162.2493,3.3847,7.6131,0.0,0.0,1.5657,4.0435,378.56,353.68,344.11,345.84
162.2503,3.6354,7.6208,0.0,0.0,1.5579,4.3005,378.51,353.6,344.12,345.85
162.2513,3.3888,7.6044,0.0,0.0,1.5641,4.0283,378.45,353.52,344.14,345.85
162.2523,3.6489,7.6168,0.0,0.0,1.5596,4.3255,378.4,353.45,344.16,345.86
162.2533,3.3829,7.6234,0.0,0.0,1.565,4.0265,378.34,353.37,344.18,345.86
162.2543,3.6413,7.6015,0.0,0.0,1.558,4.3077,378.29,353.29,344.2,345.87
162.2553,3.3635,7.6223,0.0,0.0,1.5621,4.0112,378.22,353.21,344.18,345.88
162.2563,3.6697,7.6124,0.0,0.0,1.5653,4.3487,378.16,353.14,344.16,345.89
162.2573,3.3548,7.6153,0.0,0.0,1.557,3.9862,378.1,353.06,344.15,345.91
162.2583,3.6698,7.6111,0.0,0.0,1.5649,4.3497,378.03,352.98,344.13,345.92
162.2593,3.3345,7.612,0.0,0.0,1.5616,3.9612,377.97,352.91,344.11,345.93
162.2603,3.6633,7.6236,0.0,0.0,1.5613,4.3425,377.91,352.83,344.09,345.94
162.2613,3.3425,7.6024,0.0,0.0,1.5614,3.9861,377.84,352.76,344.07,345.95
162.2623,3.6829,7.6225,0.0,0.0,1.5606,4.3597,377.78,352.68,344.06,345.97
162.2633,3.3341,7.6162,0.0,0.0,1.5665,3.9592,377.72,352.6,344.04,345.98
162.2643,3.664,7.6092,0.0,0.0,1.5566,4.3466,377.65,352.53,344.02,345.99
162.2653,3.3084,7.6184,0.0,0.0,1.5647,3.9422,377.59,352.46,344.02,346.0
162.2663,3.6765,7.6105,0.0,0.0,1.5634,4.3527,377.53,352.4,344.02,346.02
162.2673,3.3133,7.6239,0.0,0.0,1.5591,3.935,377.47,352.34,344.02,346.03
162.2683,3.6576,7.6043,0.0,0.0,1.5638,4.3466,377.41,352.27,344.02,346.04
162.2693,3.3156,7.6198,0.0,0.0,1.5604,3.957,377.35,352.21,344.02,346.05
162.2703,3.6778,7.6235,0.0,0.0,1.5655,4.3576,377.29,352.14,344.02,346.06
162.2713,3.3203,7.6036,0.0,0.0,1.5582,3.9499,377.23,352.08,344.02,346.08
162.2723,3.6842,7.6218,0.0,0.0,1.5627,4.3638,377.17,352.02,344.02,346.09
162.2733,3.3262,7.6125,0.0,0.0,1.5654,3.9411,377.11,351.95,344.02,346.1
162.2743,3.6908,7.6181,0.0,0.0,1.5576,4.3778,377.05,351.89,344.02,346.11
162.2753,3.3389,7.6105,0.0,0.0,1.5647,3.9491,377.0,351.83,344.04,346.12
162.2763,3.7048,7.614,0.0,0.0,1.5618,4.3968,376.95,351.77,344.06,346.14
162.2773,3.3438,7.6232,0.0,0.0,1.5616,3.9401,376.9,351.72,344.08,346.15
162.2783,3.6916,7.6016,0.0,0.0,1.5608,4.3818,376.85,351.66,344.1,346.16
162.2793,3.3448,7.6211,0.0,0.0,1.5601,3.9552,376.8,351.6,344.12,346.17
162.2803,3.7122,7.6191,0.0,0.0,1.5673,4.4049,376.75,351.54,344.14,346.19
162.2813,3.3327,7.6105,0.0,0.0,1.5566,3.956,376.71,351.48,344.16,346.2
162.2823,3.7005,7.6172,0.0,0.0,1.5651,4.413,376.66,351.43,344.19,346.21
162.2833,3.3578,7.6119,0.0,0.0,1.5639,3.9711,376.61,351.37,344.21,346.22
162.2843,3.7062,7.6241,0.0,0.0,1.5602,4.405,376.56,351.31,344.23,346.23
162.2853,3.3659,7.6056,0.0,0.0,1.5633,3.9941,376.51,351.26,344.23,346.24
162.2863,3.6997,7.6221,0.0,0.0,1.5613,4.3971,376.46,351.21,344.22,346.25
162.2873,3.3642,7.6192,0.0,0.0,1.5648,3.9762,376.41,351.16,344.22,346.25
162.2883,3.7127,7.608,0.0,0.0,1.5595,4.4088,376.35,351.1,344.22,346.26
162.2893,3.3733,7.6214,0.0,0.0,1.5636,4.0093,376.3,351.05,344.21,346.27
162.2903,3.6923,7.6109,0.0,0.0,1.5651,4.3839,376.25,351.0,344.21,346.27
162.2913,3.3912,7.6195,0.0,0.0,1.5579,4.0083,376.2,350.95,344.21,346.28
162.2923,3.6943,7.6115,0.0,0.0,1.566,4.399,376.15,350.9,344.21,346.28
162.2933,3.399,7.6117,0.0,0.0,1.5605,4.0295,376.1,350.85,344.2,346.29
162.2943,3.7061,7.6286,0.0,0.0,1.5647,4.3948,376.05,350.79,344.2,346.3
162.2953,3.4196,7.6014,0.0,0.0,1.56,4.0536,375.98,350.73,344.2,346.3
162.2963,3.6937,7.6241,0.0,0.0,1.5614,4.3939,375.91,350.66,344.19,346.31
162.2973,3.4389,7.6164,0.0,0.0,1.5671,4.0644,375.85,350.59,344.19,346.31
162.2983,3.6938,7.6113,0.0,0.0,1.5571,4.3859,375.78,350.53,344.19,346.32
162.2993,3.4452,7.6165,0.0,0.0,1.5651,4.0766,375.71,350.46,344.18,346.33
162.3003,3.6749,7.6128,0.0,0.0,1.5645,4.386,375.65,350.39,344.18,346.33
162.3013,3.4387,7.6241,0.0,0.0,1.5602,4.0677,375.58,350.33,344.18,346.34
162.3023,3.662,7.6066,0.0,0.0,1.5644,4.3708,375.51,350.26,344.17,346.34
162.3033,3.4659,7.6217,0.0,0.0,1.5602,4.1017,375.45,350.19,344.17,346.35
162.3043,3.6726,7.6239,0.0,0.0,1.5675,4.3567,375.38,350.13,344.17,346.36
162.3053,3.4518,7.604,0.0,0.0,1.5573,4.0786,375.32,350.04,344.16,346.37
162.3063,3.6617,7.6247,0.0,0.0,1.5659,4.3699,375.26,349.96,344.16,346.37
162.3073,3.4909,7.6116,0.0,0.0,1.5649,4.1106,375.2,349.88,344.15,346.38
162.3083,3.6482,7.6211,0.0,0.0,1.5588,4.3478,375.14,349.8,344.14,346.39
162.3093,3.4932,7.61,0.0,0.0,1.5651,4.1318,375.08,349.72,344.14,346.4
162.3103,3.6535,7.6167,0.0,0.0,1.5616,4.345,375.02,349.63,344.13,346.41
162.3113,3.5067,7.6228,0.0,0.0,1.5631,4.1569,374.96,349.55,344.13,346.42
162.3123,3.6334,7.6066,0.0,0.0,1.5619,4.3246,374.9,349.47,344.12,346.43
162.3133,3.5179,7.6218,0.0,0.0,1.56,4.1417,374.83,349.39,344.11,346.44
162.3143,3.6061,7.6185,0.0,0.0,1.5678,4.2873,374.77,349.3,344.11,346.45
162.3153,3.5391,7.6139,0.0,0.0,1.5565,4.1818,374.72,349.23,344.12,346.44
162.3163,3.6331,7.6173,0.0,0.0,1.5652,4.3167,374.66,349.16,344.13,346.44
162.3173,3.5535,7.6124,0.0,0.0,1.5631,4.2111,374.61,349.09,344.14,346.43
162.3183,3.5946,7.6274,0.0,0.0,1.5625,4.2915,374.56,349.02,344.16,346.42
162.3193,3.5584,7.6034,0.0,0.0,1.5625,4.196,374.5,348.95,344.17,346.42
162.3203,3.5992,7.6225,0.0,0.0,1.5605,4.2755,374.45,348.88,344.18,346.41
162.3213,3.5596,7.621,0.0,0.0,1.5665,4.2051,374.39,348.81,344.19,346.41
162.3223,3.5785,7.6077,0.0,0.0,1.5586,4.2463,374.34,348.74,344.21,346.4
162.3233,3.5596,7.6178,0.0,0.0,1.5628,4.204,374.28,348.67,344.22,346.39
162.3243,3.5603,7.6155,0.0,0.0,1.5667,4.2453,374.23,348.6,344.23,346.39
162.3253,3.5733,7.6194,0.0,0.0,1.5577,4.2273,374.16,348.52,344.25,346.38
162.3263,3.5348,7.6101,0.0,0.0,1.5659,4.2222,374.1,348.44,344.26,346.37
162.3273,3.5927,7.6151,0.0,0.0,1.5606,4.2433,374.03,348.36,344.28,346.37
162.3283,3.5338,7.6252,0.0,0.0,1.5644,4.2222,373.96,348.27,344.29,346.36
162.3293,3.6214,7.6027,0.0,0.0,1.5599,4.2895,373.9,348.19,344.31,346.36
162.3303,3.5257,7.623,0.0,0.0,1.5619,4.1981,373.83,348.11,344.32,346.35
162.3313,3.6189,7.6125,0.0,0.0,1.5655,4.2613,373.76,348.03,344.34,346.34
162.3323,3.4923,7.6155,0.0,0.0,1.5578,4.165,373.7,347.95,344.35,346.34
162.3333,3.6204,7.612,0.0,0.0,1.5635,4.2764,373.63,347.86,344.37,346.33
162.3343,3.4741,7.6146,0.0,0.0,1.5638,4.1561,373.56,347.78,344.38,346.33
162.3353,3.6404,7.6258,0.0,0.0,1.5617,4.2995,373.5,347.7,344.38,346.32
162.3363,3.4663,7.6017,0.0,0.0,1.5613,4.1409,373.45,347.61,344.38,346.31
162.3373,3.6479,7.6224,0.0,0.0,1.5603,4.3165,373.39,347.53,344.38,346.31
162.3383,3.464,7.6198,0.0,0.0,1.5673,4.1168,373.33,347.44,344.38,346.3
162.3393,3.6546,7.6066,0.0,0.0,1.557,4.3247,373.27,347.36,344.38,346.3
162.3403,3.445,7.6203,0.0,0.0,1.5645,4.1078,373.22,347.27,344.38,346.29
162.3413,3.6611,7.6121,0.0,0.0,1.5646,4.3255,373.16,347.18,344.38,346.28
162.3423,3.4435,7.6225,0.0,0.0,1.559,4.0918,373.1,347.1,344.38,346.28
162.3433,3.6807,7.6071,0.0,0.0,1.5644,4.3365,373.04,347.01,344.38,346.27
162.3443,3.4248,7.6188,0.0,0.0,1.5618,4.0838,372.99,346.93,344.38,346.27
162.3453,3.6561,7.624,0.0,0.0,1.5653,4.3346,372.95,346.88,344.38,346.28
162.3463,3.4031,7.6033,0.0,0.0,1.5593,4.0505,372.9,346.83,344.39,346.28
162.3473,3.6836,7.6221,0.0,0.0,1.5614,4.3659,372.86,346.78,344.39,346.29
162.3483,3.4044,7.6179,0.0,0.0,1.5677,4.0665,372.82,346.72,344.39,346.3
162.3493,3.6831,7.6145,0.0,0.0,1.5564,4.3667,372.78,346.67,344.4,346.31
162.3503,3.397,7.6133,0.0,0.0,1.5652,4.0415,372.73,346.62,344.4,346.32
162.3513,3.704,7.6144,0.0,0.0,1.5632,4.3918,372.69,346.57,344.4,346.33
162.3523,3.4022,7.626,0.0,0.0,1.562,4.0425,372.65,346.52,344.41,346.34
162.3533,3.7032,7.6041,0.0,0.0,1.5626,4.3847,372.61,346.46,344.41,346.35
162.3543,3.3952,7.6242,0.0,0.0,1.562,4.0334,372.56,346.41,344.41,346.36
162.3553,3.7168,7.6195,0.0,0.0,1.5662,4.4008,372.5,346.34,344.44,346.38
162.3563,3.4019,7.6103,0.0,0.0,1.5583,4.0414,372.45,346.27,344.47,346.39
162.3573,3.7368,7.6204,0.0,0.0,1.5645,4.417,372.39,346.2,344.5,346.41
162.3583,3.3807,7.6137,0.0,0.0,1.5654,4.0084,372.33,346.13,344.52,346.43
162.3593,3.7182,7.6233,0.0,0.0,1.5595,4.409,372.27,346.06,344.55,346.45
162.3603,3.3833,7.6066,0.0,0.0,1.5645,4.0376,372.22,345.99,344.58,346.47
162.3613,3.7328,7.6193,0.0,0.0,1.561,4.4411,372.16,345.92,344.61,346.49
162.3623,3.3819,7.6242,0.0,0.0,1.5657,4.0253,372.1,345.85,344.63,346.5
162.3633,3.752,7.6047,0.0,0.0,1.5597,4.4492,372.04,345.78,344.66,346.52
162.3643,3.3818,7.6224,0.0,0.0,1.5624,4.0144,371.99,345.71,344.69,346.54
162.3653,3.7467,7.6147,0.0,0.0,1.5664,4.4563,371.92,345.63,344.69,346.56
162.3663,3.3871,7.6168,0.0,0.0,1.5577,4.0214,371.86,345.56,344.69,346.58
162.3673,3.7508,7.6134,0.0,0.0,1.5658,4.4351,371.8,345.48,344.69,346.6
162.3683,3.3822,7.612,0.0,0.0,1.5616,4.0275,371.73,345.41,344.7,346.61
162.3693,3.7515,7.6267,0.0,0.0,1.5625,4.4389,371.67,345.33,344.7,346.63
162.3703,3.4066,7.6026,0.0,0.0,1.5616,4.0374,371.6,345.25,344.7,346.65
162.3713,3.7397,7.624,0.0,0.0,1.5612,4.4442,371.54,345.18,344.71,346.67
162.3723,3.3892,7.6176,0.0,0.0,1.5667,4.0416,371.48,345.1,344.71,346.69
162.3733,3.7512,7.6122,0.0,0.0,1.5577,4.446,371.41,345.03,344.71,346.71
162.3743,3.425,7.6185,0.0,0.0,1.5651,4.0364,371.35,344.95,344.71,346.72
162.3753,3.774,7.6121,0.0,0.0,1.5644,4.4914,371.29,344.9,344.69,346.72
162.3763,3.4206,7.6241,0.0,0.0,1.5601,4.0515,371.24,344.86,344.66,346.72
162.3773,3.7594,7.6067,0.0,0.0,1.5649,4.4552,371.18,344.81,344.63,346.72
162.3783,3.426,7.6175,0.0,0.0,1.5597,4.0585,371.12,344.76,344.6,346.72
162.3793,3.7606,7.6259,0.0,0.0,1.5669,4.4694,371.06,344.71,344.58,346.72
162.3803,3.4538,7.6038,0.0,0.0,1.5588,4.0897,371.01,344.66,344.55,346.72
162.3813,3.7597,7.6231,0.0,0.0,1.5627,4.4632,370.95,344.61,344.52,346.72
162.3823,3.44,7.6147,0.0,0.0,1.5662,4.0806,370.89,344.56,344.49,346.72
162.3833,3.7624,7.6182,0.0,0.0,1.5576,4.4855,370.83,344.51,344.47,346.72
162.3843,3.4592,7.6135,0.0,0.0,1.5657,4.0896,370.78,344.46,344.44,346.72
162.3853,3.7545,7.6143,0.0,0.0,1.5626,4.4632,370.72,344.4,344.44,346.74
162.3863,3.4469,7.6239,0.0,0.0,1.5621,4.0947,370.67,344.34,344.44,346.75
162.3873,3.7534,7.6056,0.0,0.0,1.563,4.4553,370.61,344.27,344.44,346.76
162.3883,3.4675,7.6198,0.0,0.0,1.5605,4.1117,370.56,344.21,344.44,346.77
162.3893,3.7425,7.6185,0.0,0.0,1.5677,4.4614,370.5,344.14,344.44,346.78
162.3903,3.466,7.6121,0.0,0.0,1.5573,4.0966,370.45,344.08,344.44,346.8
162.3913,3.733,7.6186,0.0,0.0,1.5654,4.427,370.39,344.02,344.44,346.81
162.3923,3.4789,7.6127,0.0,0.0,1.5641,4.1117,370.34,343.95,344.44,346.82
162.3933,3.7271,7.6257,0.0,0.0,1.5611,4.4281,370.29,343.89,344.44,346.83
162.3943,3.4861,7.6036,0.0,0.0,1.5632,4.1239,370.23,343.82,344.45,346.84
162.3953,3.6902,7.6223,0.0,0.0,1.5622,4.4163,370.18,343.76,344.47,346.86
162.3963,3.4993,7.6214,0.0,0.0,1.5653,4.1358,370.13,343.7,344.49,346.87
162.3973,3.7148,7.6074,0.0,0.0,1.5601,4.4171,370.09,343.63,344.52,346.88
162.3983,3.5067,7.6227,0.0,0.0,1.5636,4.1569,370.04,343.57,344.54,346.89
162.3993,3.6939,7.6148,0.0,0.0,1.5665,4.3931,369.99,343.5,344.57,346.91
162.4003,3.5122,7.6188,0.0,0.0,1.5575,4.149,369.94,343.44,344.59,346.92
162.4013,3.6875,7.6114,0.0,0.0,1.5653,4.3799,369.89,343.38,344.62,346.93
162.4023,3.5203,7.614,0.0,0.0,1.5615,4.1641,369.84,343.31,344.64,346.94
162.4033,3.655,7.6271,0.0,0.0,1.5638,4.3629,369.8,343.25,344.67,346.95
162.4043,3.5249,7.6007,0.0,0.0,1.56,4.1499,369.75,343.19,344.69,346.96
162.4053,3.6358,7.625,0.0,0.0,1.5621,4.3478,369.69,343.13,344.71,346.96
162.4063,3.521,7.6147,0.0,0.0,1.5661,4.1739,369.64,343.08,344.73,346.96
162.4073,3.6547,7.6172,0.0,0.0,1.5586,4.3549,369.58,343.02,344.74,346.96
162.4083,3.5468,7.6155,0.0,0.0,1.5641,4.197,369.53,342.97,344.76,346.96
162.4093,3.6532,7.614,0.0,0.0,1.5641,4.3406,369.47,342.91,344.78,346.96
162.4103,3.5784,7.6263,0.0,0.0,1.5609,4.2202,369.42,342.86,344.8,346.96
162.4113,3.6144,7.6058,0.0,0.0,1.5641,4.3077,369.36,342.8,344.82,346.96
162.4123,3.5801,7.6195,0.0,0.0,1.5592,4.2292,369.31,342.75,344.83,346.96
162.4133,3.6014,7.6247,0.0,0.0,1.5679,4.2997,369.25,342.69,344.85,346.96
162.4143,3.5682,7.6033,0.0,0.0,1.5572,4.2352,369.2,342.64,344.87,346.97
162.4153,3.6076,7.6237,0.0,0.0,1.5646,4.3015,369.14,342.59,344.88,346.97
162.4163,3.6069,7.6117,0.0,0.0,1.5653,4.2603,369.08,342.54,344.88,346.98
162.4173,3.5944,7.6211,0.0,0.0,1.5588,4.2935,369.02,342.49,344.89,346.98
162.4183,3.614,7.6093,0.0,0.0,1.5652,4.2763,368.96,342.44,344.89,346.99
162.4193,3.5816,7.6167,0.0,0.0,1.5612,4.2756,368.9,342.4,344.9,347.0
162.4203,3.6207,7.6236,0.0,0.0,1.5634,4.2835,368.84,342.35,344.91,347.0
162.4213,3.5799,7.6064,0.0,0.0,1.5609,4.2623,368.78,342.3,344.91,347.01
162.4223,3.648,7.6211,0.0,0.0,1.5603,4.3156,368.71,342.25,344.92,347.01
162.4233,3.5533,7.6194,0.0,0.0,1.5682,4.2364,368.65,342.2,344.92,347.02
162.4243,3.6481,7.6132,0.0,0.0,1.5566,4.3166,368.6,342.15,344.93,347.03
162.4253,3.5276,7.6167,0.0,0.0,1.5658,4.2141,368.54,342.1,344.93,347.03
162.4263,3.6548,7.6124,0.0,0.0,1.5628,4.3228,368.49,342.06,344.93,347.03
162.4273,3.5324,7.6281,0.0,0.0,1.5625,4.2052,368.44,342.01,344.93,347.03
162.4283,3.6554,7.6042,0.0,0.0,1.5631,4.3255,368.39,341.96,344.93,347.03
162.4293,3.521,7.6234,0.0,0.0,1.5612,4.2044,368.34,341.91,344.93,347.03
162.4303,3.6958,7.6233,0.0,0.0,1.5675,4.3818,368.29,341.86,344.93,347.03
162.4313,3.5135,7.6093,0.0,0.0,1.5593,4.1952,368.23,341.81,344.93,347.03
162.4323,3.6896,7.6194,0.0,0.0,1.5635,4.3658,368.18,341.76,344.93,347.03
162.4333,3.5121,7.6164,0.0,0.0,1.5677,4.1792,368.13,341.71,344.93,347.03
162.4343,3.7161,7.6203,0.0,0.0,1.5583,4.3978,368.08,341.66,344.93,347.03
162.4353,3.4991,7.6109,0.0,0.0,1.566,4.1749,368.04,341.61,344.92,347.04
162.4363,3.7289,7.6181,0.0,0.0,1.5618,4.4059,367.99,341.56,344.91,347.05
162.4373,3.4864,7.626,0.0,0.0,1.5647,4.1702,367.95,341.51,344.91,347.06
162.4383,3.7235,7.6048,0.0,0.0,1.5602,4.406,367.9,341.46,344.9,347.08
162.4393,3.4776,7.6252,0.0,0.0,1.5626,4.14,367.85,341.41,344.9,347.09
162.4403,3.7369,7.6155,0.0,0.0,1.5665,4.4301,367.81,341.35,344.89,347.1
162.4413,3.4786,7.6178,0.0,0.0,1.5585,4.1452,367.76,341.3,344.88,347.11
162.4423,3.7562,7.6145,0.0,0.0,1.5648,4.4401,367.72,341.25,344.88,347.13
162.4433,3.4708,7.616,0.0,0.0,1.5639,4.13,367.67,341.2,344.87,347.14
162.4443,3.7437,7.6282,0.0,0.0,1.563,4.4321,367.63,341.15,344.87,347.15
162.4453,3.4577,7.6034,0.0,0.0,1.5624,4.121,367.57,341.1,344.88,347.16
162.4463,3.7642,7.6249,0.0,0.0,1.5617,4.4544,367.52,341.04,344.88,347.17
162.4473,3.4646,7.622,0.0,0.0,1.5676,4.1298,367.46,340.99,344.89,347.19
162.4483,3.7574,7.6096,0.0,0.0,1.5579,4.4491,367.41,340.94,344.89,347.2
162.4493,3.4425,7.6241,0.0,0.0,1.5655,4.0879,367.35,340.89,344.9,347.21
162.85002,3.5868,7.6198,0.0,0.0,1.5642,4.2585,352.74,326.62,340.8,347.3
164.85002,3.4702,7.6341,0.0,0.0,1.5706,4.1168,280.84,231.88,228.81,306.92
166.8331,3.4852,7.6385,0.0,0.0,1.5726,4.1371,214.28,146.01,165.69,234.49
168.8331,3.413,7.6399,0.0,0.0,1.5733,4.0509,147.56,88.187,55.229,87.369
170.8331,3.36,7.6579,0.0,0.0,1.5814,3.9876,87.05,66.539,33.346,43.632
172.8331,3.3464,7.6737,0.0,0.0,1.5885,3.9715,70.193,57.991,33.782,37.176
174.8331,3.3556,7.6866,0.0,0.0,1.5943,3.9818,63.446,54.734,35.686,37.705
176.8331,3.3553,7.6951,0.0,0.0,1.5983,3.9823,58.535,52.067,36.77,38.582
178.8331,3.3678,7.702,0.0,0.0,1.6016,3.9969,54.688,49.618,36.966,38.762
180.8331,3.3729,7.7084,0.0,0.0,1.6045,4.0014,51.578,47.675,36.67,38.466
182.8331,3.3721,7.7135,0.0,0.0,1.6068,4.0029,49.063,46.008,36.138,37.921
184.8331,3.3831,7.7185,0.0,0.0,1.6093,4.0145,47.011,44.561,35.672,37.346
186.8331,3.3831,7.7224,0.0,0.0,1.611,4.0141,45.419,43.335,35.207,36.827
188.8331,3.3859,7.7266,0.0,0.0,1.6128,4.0187,43.99,42.269,34.92,36.319
190.8331,3.3992,7.7302,0.0,0.0,1.6144,4.0332,42.971,41.447,34.642,35.935
192.8331,3.3955,7.7334,0.0,0.0,1.616,4.0298,41.979,40.649,34.464,35.676
194.8331,3.3982,7.7362,0.0,0.0,1.6174,4.0335,41.124,40.034,34.084,35.507
196.6808,3.4095,7.7387,0.0,0.0,1.6187,4.0459,40.584,39.506,34.279,35.457
198.6808,3.4012,7.741,0.0,0.0,1.6196,4.036,40.017,39.602,34.341,35.526
200.6808,3.4122,7.7437,0.0,0.0,1.6208,4.0501,39.518,39.878,34.313,35.594
202.6808,3.4138,7.7454,0.0,0.0,1.6216,4.0504,39.245,39.94,34.725,35.807
204.6808,3.4133,7.7468,0.0,0.0,1.6223,4.0495,38.903,39.94,34.613,35.78
206.6808,3.4181,7.7488,0.0,0.0,1.6233,4.0576,38.714,40.002,34.557,35.811
208.6808,3.331,7.7569,0.0,0.0,1.6271,3.9533,39.102,40.002,35.958,36.142
209.2808,3.3163,7.7574,0.0,0.0,1.6273,3.9355,39.256,40.002,36.241,36.323