File: examples/dan-msc-case-studies/CS4/data/01 raw data/hyde_test_034.csv
Time(sec),Force(kN),Jaw(mm),PowAngle(deg),PTemp,Strain,Stress(MPa),TC1(C),TC2(C),TC3(C)
0.0,3.8603,-0.002352,0.0,0.00032067,-0.00021038,11.72,21.871,22.458,22.147
0.8,3.7587,-0.0021188,0.0,2.221,-0.00020977,11.396,22.096,22.585,22.325
1.6,3.6939,-0.0021972,0.0,4.621,-0.00019828,11.204,22.129,22.604,22.374
2.4,3.619,-0.0023477,0.0,7.021,-0.00022406,10.982,22.091,22.593,22.309
3.2,3.5452,-0.002791,0.0,9.421,-0.00030299,10.755,22.045,22.564,22.31
4.0,3.5154,-0.0027354,0.0,11.821,-0.00030057,10.661,22.134,22.633,22.324
4.8,3.4805,-0.0029117,0.0,14.221,-0.00030305,10.56,22.11,22.647,22.303
5.6,3.4548,-0.0026958,0.0,16.621,-0.00026963,10.484,22.134,22.667,22.385
6.3745,3.4422,-0.002766,0.0,18.945,-0.00026289,10.441,22.096,22.646,22.316
7.1745,3.4334,-0.0027068,0.0,21.345,-0.00028523,10.413,21.948,22.474,22.117
7.9745,3.4109,-0.0024478,18.144,23.745,-0.00026363,10.349,22.13,22.73,22.396
8.7745,3.4082,-0.0026162,23.848,26.145,-0.00026893,10.341,24.276,25.021,24.479
9.5745,3.4125,-0.0031041,24.287,28.545,-0.00031028,10.35,27.194,28.02,27.466
10.3745,3.4013,-0.0038535,23.864,30.945,-0.0004261,10.32,29.984,30.789,30.196
11.1745,3.3964,-0.0047749,24.231,33.345,-0.00054404,10.306,32.594,39.504,32.738
11.9745,3.3943,-0.0052946,24.145,35.745,-0.00061565,10.298,35.202,39.506,35.301
12.7745,3.4081,-0.0062245,24.818,38.145,-0.0007022,10.335,37.694,39.21,37.726
13.416,3.4076,-0.0069438,25.246,40.069,-0.00075876,10.333,39.657,40.83,39.735
14.216,3.4134,-0.0079739,25.478,42.469,-0.00086566,10.356,42.128,43.282,42.244
15.016,3.4006,-0.0090816,26.189,44.869,-0.00096717,10.321,44.511,45.727,44.616
15.816,3.3891,-0.0097118,25.065,47.269,-0.0010475,10.282,47.135,48.232,47.161
16.616,3.3996,-0.01075,25.966,49.669,-0.0011885,10.311,49.515,50.629,49.539
17.416,3.4071,-0.011569,26.149,52.069,-0.0012889,10.337,51.909,53.068,51.894
18.216,3.3967,-0.012271,26.086,54.469,-0.0013781,10.306,54.302,55.392,54.29
19.016,3.396,-0.013451,26.2,56.869,-0.0014932,10.3,56.827,57.916,56.67
19.816,3.4082,-0.014456,26.868,59.269,-0.0015918,10.34,59.15,60.192,59.074
20.616,3.4069,-0.015449,26.914,61.669,-0.0016693,10.34,61.541,62.573,61.504
21.416,3.4049,-0.016541,27.219,64.069,-0.0017672,10.328,63.982,64.855,63.908
22.216,3.4153,-0.017457,27.219,66.469,-0.0018696,10.358,66.407,67.206,66.37
23.016,3.4273,-0.018398,27.43,68.869,-0.0019992,10.399,68.812,69.08,68.673
23.816,3.4121,-0.019332,27.388,71.269,-0.0021019,10.354,71.228,71.577,71.163
24.616,3.4204,-0.020528,27.602,73.669,-0.0022275,10.375,73.544,74.022,73.48
25.416,3.4269,-0.021475,27.657,76.069,-0.0023302,10.393,76.025,76.657,76.014
26.216,3.4221,-0.022878,28.437,78.469,-0.0025035,10.385,78.368,79.108,78.42
27.016,3.424,-0.02445,27.917,80.869,-0.0027057,10.385,80.824,81.436,80.796
27.816,3.4337,-0.026107,28.219,83.269,-0.0028877,10.414,83.23,83.925,83.239
28.616,3.4293,-0.027557,28.601,85.669,-0.003036,10.405,85.611,86.467,85.656
29.416,3.4254,-0.028155,28.088,88.069,-0.0030818,10.394,88.08,88.889,88.111
30.216,3.4325,-0.029064,28.487,90.469,-0.0031678,10.407,90.436,91.315,90.469
31.016,3.4465,-0.029786,28.731,92.869,-0.0032236,10.454,92.835,93.722,92.892
31.816,3.449,-0.03094,29.551,95.269,-0.0033265,10.466,95.061,95.978,95.181
32.616,3.4405,-0.031791,28.898,97.669,-0.0034504,10.436,97.599,98.567,97.784
33.41601,3.4514,-0.033211,29.874,100.07,-0.003626,10.467,99.903,100.76,100.07
34.21601,3.4533,-0.034081,28.866,102.47,-0.0037182,10.478,102.49,103.51,102.76
35.01601,3.4425,-0.035549,29.427,104.87,-0.0038584,10.446,104.79,105.79,104.99
35.81601,3.4518,-0.036492,29.67,107.27,-0.0039698,10.468,107.21,108.27,107.47
36.61601,3.466,-0.037758,29.453,109.67,-0.0041227,10.512,109.7,110.67,109.99
37.41601,3.4601,-0.039118,30.081,112.07,-0.004305,10.499,111.95,112.93,112.33
38.21601,3.4598,-0.04044,29.848,114.47,-0.004445,10.494,114.41,115.5,114.81
39.0152,3.4692,-0.041796,30.212,116.87,-0.004542,10.523,116.8,117.84,117.17
39.8152,3.4725,-0.04301,30.09,119.27,-0.0046997,10.537,119.23,120.23,119.6
40.6152,3.4692,-0.044028,29.979,121.67,-0.004816,10.525,121.64,122.64,121.98
41.4152,3.4731,-0.045147,30.406,124.07,-0.0049622,10.533,124.01,125.03,124.39
42.2152,3.4817,-0.046934,30.584,126.47,-0.0051538,10.562,126.38,127.39,126.85
43.0152,3.4793,-0.048194,30.43,128.87,-0.005279,10.559,128.82,129.83,129.21
43.8152,3.4771,-0.049552,30.878,131.27,-0.0054158,10.549,131.13,132.17,131.61
44.4258,3.4879,-0.050507,31.273,133.1,-0.0055219,10.582,132.88,133.96,133.41
45.2258,3.4788,-0.05168,30.61,135.5,-0.005644,10.555,135.45,136.5,136.01
46.0258,3.4809,-0.053155,30.422,137.9,-0.0057799,10.557,137.95,139.02,138.47
46.8258,3.4892,-0.054547,30.25,140.3,-0.0059312,10.585,140.36,141.46,140.92
47.6258,3.4899,-0.056025,30.873,142.7,-0.0061315,10.589,142.7,143.84,143.34
48.4258,3.4894,-0.057105,30.913,145.1,-0.0062629,10.582,145.01,146.08,145.68
49.2258,3.4981,-0.058293,31.026,147.5,-0.0063896,10.609,147.49,148.46,148.18
50.0258,3.4943,-0.059641,30.341,149.9,-0.006527,10.603,150.06,151.17,150.79
50.8258,3.4915,-0.061225,31.088,152.3,-0.0066948,10.59,152.25,153.36,152.96
51.6258,3.4996,-0.062442,31.514,154.7,-0.0068019,10.612,154.67,155.78,155.42
52.4258,3.5017,-0.06401,31.786,157.1,-0.0069504,10.626,157.02,158.08,157.76
53.2258,3.492,-0.065009,31.559,159.5,-0.0070572,10.597,159.49,160.59,160.23
54.0258,3.5014,-0.06672,31.832,161.9,-0.0072742,10.621,161.84,162.99,162.7
54.8258,3.5076,-0.068483,31.948,164.3,-0.0074776,10.638,164.19,165.22,165.0
55.6258,3.4994,-0.070561,32.427,166.7,-0.0076922,10.617,166.54,167.75,167.32
56.4258,3.4901,-0.072196,31.963,169.1,-0.0078739,10.588,169.08,170.19,169.92
57.2258,3.5051,-0.073987,32.554,171.5,-0.0080864,10.629,171.37,172.49,172.26
58.0258,3.509,-0.075517,32.544,173.9,-0.0082639,10.646,173.79,174.95,174.72
58.8258,3.499,-0.07674,32.352,176.3,-0.0084118,10.616,176.26,177.4,177.16
59.6258,3.4919,-0.077957,32.474,178.7,-0.0085422,10.591,178.63,179.72,179.54
60.4258,3.5091,-0.079115,32.269,181.1,-0.0086632,10.644,181.07,182.21,181.98
61.2258,3.5024,-0.080503,32.523,183.5,-0.0087924,10.629,183.46,184.61,184.34
62.0258,3.4946,-0.081252,32.673,185.9,-0.0088469,10.601,185.79,186.99,186.75
62.8258,3.5104,-0.082219,32.848,188.3,-0.0089252,10.645,188.3,189.48,189.32
63.6258,3.5076,-0.083298,32.873,190.7,-0.0090626,10.644,190.66,191.79,191.7
64.42581,3.4996,-0.084787,32.781,193.1,-0.0092331,10.619,193.06,194.33,194.28
65.22581,3.5025,-0.085921,32.732,195.5,-0.0093611,10.623,195.53,196.63,196.58
66.02581,3.5076,-0.087423,33.226,197.9,-0.0095055,10.639,197.76,198.92,198.78
66.82581,3.5059,-0.088826,33.031,200.3,-0.0096581,10.638,200.31,201.56,201.58
67.62581,3.5009,-0.090225,33.451,202.7,-0.0098308,10.62,202.63,203.75,203.78
68.42581,3.5018,-0.091996,33.332,205.1,-0.010045,10.62,205.02,206.22,206.26
69.22581,3.5042,-0.093316,32.968,207.5,-0.010188,10.631,207.54,208.64,208.76
70.02581,3.4959,-0.094773,33.624,209.9,-0.010346,10.61,209.85,210.95,211.07
70.82581,3.4936,-0.096567,33.715,212.3,-0.010529,10.594,212.14,213.21,213.45
71.5359,3.4982,-0.09771,32.994,214.43,-0.010632,10.616,214.46,215.55,215.75
72.3359,3.4928,-0.099509,33.624,216.83,-0.010843,10.594,216.77,217.81,218.16
73.1359,3.496,-0.10089,33.544,219.23,-0.010969,10.602,219.19,220.32,220.55
73.9359,3.5068,-0.1032,33.524,221.63,-0.01121,10.636,221.62,222.56,222.95
74.7359,3.5031,-0.10606,33.581,224.03,-0.011526,10.63,224.01,225.11,225.49
75.4136,3.5014,-0.10795,33.601,226.06,-0.011717,10.621,226.12,227.12,227.58
76.2136,3.5064,-0.10704,33.791,228.46,-0.011645,10.634,228.38,229.35,229.83
77.0136,3.5105,-0.1076,33.588,230.86,-0.011718,10.654,230.85,231.84,232.31
77.8136,3.5005,-0.10917,33.668,233.26,-0.011875,10.621,233.26,234.25,234.75
78.6136,3.502,-0.1111,33.56,235.66,-0.01207,10.621,235.72,236.69,237.26
79.4136,3.5043,-0.1126,33.345,238.06,-0.012247,10.628,238.1,239.06,239.64
80.2136,3.4979,-0.11408,33.064,240.46,-0.012431,10.616,240.58,241.4,242.13
81.0136,3.4931,-0.11559,33.33,242.86,-0.012601,10.594,242.94,243.8,244.51
81.8136,3.5026,-0.11725,33.649,245.26,-0.012792,10.622,245.25,246.12,246.86
82.6136,3.5035,-0.11966,33.499,247.66,-0.013032,10.627,247.74,248.61,249.35
83.4136,3.5019,-0.12337,33.313,250.06,-0.013435,10.624,250.14,250.9,251.71
84.2136,3.506,-0.12214,33.786,252.46,-0.013294,10.634,252.45,253.25,254.16
85.0136,3.5114,-0.12296,33.759,254.86,-0.013343,10.65,254.89,255.71,256.66
85.8136,3.5029,-0.12463,33.664,257.26,-0.013516,10.629,257.23,258.06,259.0
86.6136,3.4974,-0.12628,33.765,259.66,-0.013711,10.609,259.64,260.48,261.46
87.4136,3.5034,-0.12809,33.886,262.06,-0.013924,10.626,262.08,262.88,263.86
88.2136,3.4985,-0.12964,33.744,264.46,-0.014088,10.615,264.47,265.16,266.27
89.0136,3.49,-0.13159,33.702,266.86,-0.014289,10.586,266.9,267.62,268.66
89.8136,3.5046,-0.13456,33.768,269.26,-0.014596,10.627,269.27,269.95,271.11
90.6136,3.5101,-0.13715,33.423,271.66,-0.014928,10.649,271.78,272.34,273.57
91.4136,3.5028,-0.13559,33.814,274.06,-0.014779,10.629,274.08,274.57,275.89
92.2136,3.5009,-0.13678,34.318,276.46,-0.0149,10.617,276.4,276.8,278.2
93.0136,3.5077,-0.1382,33.751,278.86,-0.015041,10.638,278.91,279.26,280.74
93.8136,3.5038,-0.14024,33.931,281.26,-0.015249,10.633,281.25,281.64,283.1
94.61361,3.4975,-0.14207,34.267,283.66,-0.015436,10.61,283.63,284.17,285.61
95.41361,3.4986,-0.14366,34.301,286.06,-0.015583,10.608,286.03,286.42,287.99
96.21361,3.5042,-0.1451,34.272,288.46,-0.015724,10.631,288.45,288.88,290.36
97.01361,3.4938,-0.14642,34.649,290.86,-0.01587,10.601,290.78,291.08,292.69
97.81361,3.4885,-0.14839,34.89,293.26,-0.016104,10.582,293.15,293.26,295.1
98.61361,3.5031,-0.15095,34.651,295.66,-0.016386,10.623,295.61,295.61,297.53
99.41361,3.5107,-0.15472,34.857,298.06,-0.01678,10.656,297.97,297.9,299.87
100.21361,3.504,-0.15426,35.011,300.46,-0.016767,10.628,300.41,300.29,302.36
101.01361,3.509,-0.15365,35.276,302.86,-0.0167,10.64,302.78,302.49,304.69
101.81361,3.5095,-0.15494,35.373,305.26,-0.016847,10.647,305.21,304.79,307.14
102.61361,3.4967,-0.15672,34.821,307.66,-0.017053,10.61,307.68,307.04,309.48
103.41361,3.5008,-0.15838,35.226,310.06,-0.017225,10.616,310.07,309.36,311.73
104.1663,3.4939,-0.15988,35.128,312.32,-0.017366,10.598,312.35,311.53,313.85
104.9663,3.501,-0.16134,35.48,314.72,-0.017502,10.618,314.67,313.92,316.17
105.7063,3.4897,-0.16298,35.657,316.94,-0.017695,10.584,316.86,316.53,318.28
106.5063,3.5037,-0.16477,36.072,319.34,-0.01788,10.626,319.15,319.29,320.52
107.3063,3.5264,-0.16843,36.287,321.74,-0.018239,10.699,321.59,322.57,323.24
108.1063,3.5114,-0.16893,35.663,324.14,-0.018336,10.652,324.12,325.17,325.6
108.9063,3.5088,-0.16782,36.098,326.54,-0.018212,10.641,326.46,327.86,328.07
109.7063,3.5099,-0.16946,36.044,328.94,-0.018407,10.647,328.87,330.46,330.68
110.5063,3.4954,-0.17129,34.883,331.34,-0.018608,10.606,331.61,333.65,333.9
111.3063,3.4986,-0.17312,36.415,333.74,-0.018822,10.609,333.67,336.62,336.81
112.1063,3.5041,-0.17482,36.14,336.14,-0.018993,10.628,336.18,339.77,340.14
112.9063,3.4973,-0.17655,36.18,338.54,-0.01916,10.612,338.56,342.54,342.84
113.7063,3.4959,-0.17871,36.26,340.94,-0.019362,10.603,340.9,345.18,345.63
114.5063,3.5101,-0.18341,36.394,343.34,-0.019834,10.644,343.31,346.57,348.48
115.3063,3.51,-0.18272,36.364,345.74,-0.019812,10.65,345.76,345.45,351.13
116.1063,3.4978,-0.18154,36.315,348.14,-0.019675,10.614,348.17,347.45,353.77
116.9063,3.4935,-0.18246,34.914,349.99,-0.019787,10.596,350.4,349.69,356.28
117.7063,3.4968,-0.18317,34.79,350.0,-0.019858,10.606,350.28,349.96,356.16
118.5063,3.4924,-0.18375,34.583,350.0,-0.019904,10.598,350.27,350.1,356.17
119.3063,3.4858,-0.18398,34.621,350.0,-0.019939,10.574,350.27,350.15,356.05
120.1063,3.4886,-0.18429,34.577,350.0,-0.020003,10.579,350.13,350.07,355.93
120.9063,3.4895,-0.18462,34.555,350.0,-0.020054,10.587,350.15,350.07,355.87
121.7063,3.4832,-0.18476,34.305,350.0,-0.020073,10.568,350.15,350.04,355.91
122.5063,3.4889,-0.18529,34.649,350.0,-0.020109,10.582,349.97,349.99,355.76
123.3063,3.4935,-0.18647,34.575,350.0,-0.02023,10.595,350.06,350.12,355.93
124.1063,3.5018,-0.18859,34.787,350.0,-0.020418,10.625,349.94,350.08,355.9
124.90631,3.49,-0.18938,33.969,350.0,-0.020516,10.585,350.15,350.23,355.98
125.70631,3.5032,-0.18703,34.401,350.0,-0.020268,10.622,350.02,350.19,355.93
126.50631,3.5034,-0.18575,34.15,350.0,-0.020124,10.629,350.06,350.32,356.02
127.30631,3.4943,-0.18586,34.016,350.0,-0.020152,10.604,350.09,350.34,356.04
128.10631,3.4941,-0.18622,34.014,350.0,-0.02019,10.596,350.09,350.31,356.01
128.90631,3.5079,-0.18643,34.253,350.0,-0.020201,10.642,350.01,350.43,356.09
129.70631,3.4905,-0.18663,34.285,350.0,-0.020216,10.591,349.71,350.1,355.66
130.50631,3.49,-0.18695,33.917,350.0,-0.020275,10.583,349.78,350.15,355.8
131.30631,3.4991,-0.18731,33.876,350.0,-0.020339,10.613,349.78,350.18,355.81
132.10631,3.4842,-0.18757,34.157,350.0,-0.020374,10.572,349.72,350.15,355.76
132.90631,3.4914,-0.18762,34.076,350.0,-0.020363,10.591,349.73,350.12,355.75
133.70631,3.4759,-0.18754,34.003,350.0,-0.020347,10.542,349.3,349.82,355.34
134.50631,3.4859,-0.18877,33.984,350.0,-0.020459,10.573,349.32,349.76,355.35
135.30631,3.4791,-0.19106,34.172,350.0,-0.020667,10.553,349.25,349.64,355.27
136.10631,3.4821,-0.19007,33.99,350.0,-0.020592,10.559,349.31,349.57,355.28
136.7974,3.4958,-0.1875,34.032,350.0,-0.020323,10.604,349.3,349.7,355.28
137.5974,3.4808,-0.18757,34.386,350.0,-0.020327,10.562,349.23,349.68,355.24
138.3974,3.4735,-0.18796,34.061,350.0,-0.02039,10.535,349.22,349.68,355.29
139.1974,3.4852,-0.18785,33.834,350.0,-0.020393,10.57,349.13,349.52,355.1
139.9974,3.4723,-0.18831,33.851,350.0,-0.020447,10.537,349.13,349.5,355.09
140.7974,3.4619,-0.18858,33.772,350.0,-0.020467,10.503,349.14,349.55,355.11
141.5974,3.4673,-0.18878,33.779,350.0,-0.020477,10.515,349.18,349.57,355.17
142.3974,3.4751,-0.18957,33.768,350.0,-0.020549,10.541,349.06,349.5,355.1
143.1974,3.4753,-0.19201,33.708,350.0,-0.020772,10.546,349.04,349.46,355.04
143.9974,3.4771,-0.19075,33.338,350.0,-0.020664,10.545,349.02,349.43,355.04
144.7974,3.4862,-0.18851,33.28,350.0,-0.020427,10.575,349.23,349.62,355.2
145.5974,3.4671,-0.18858,33.489,350.0,-0.020454,10.52,349.05,349.57,355.18
146.3974,3.4672,-0.18874,32.914,350.0,-0.020456,10.516,349.05,349.51,355.11
147.0094,3.4745,-0.18883,34.107,350.0,-0.020505,10.543,348.63,349.16,354.61
147.8094,3.461,-0.18894,33.517,350.0,-0.020512,10.502,348.71,349.26,354.77
148.6094,3.4497,-0.18914,33.102,350.0,-0.020522,10.462,348.75,349.39,354.85
149.4094,3.4655,-0.18909,33.934,350.0,-0.020497,10.515,348.7,349.27,354.81
150.2094,3.4568,-0.18957,33.79,350.0,-0.020522,10.489,349.01,349.64,355.19
151.0094,3.4504,-0.19024,33.826,350.0,-0.020585,10.466,349.14,349.72,355.37
151.8094,3.4697,-0.19211,33.538,350.0,-0.020779,10.521,349.42,350.13,355.7
152.6094,3.4744,-0.19203,33.734,350.0,-0.020848,10.543,349.66,350.28,355.85
153.4094,3.4537,-0.1892,33.652,350.0,-0.020509,10.48,349.74,350.29,355.85
154.2094,3.457,-0.18904,33.704,350.0,-0.020481,10.483,349.71,350.35,355.92
155.0094,3.46,-0.18962,33.198,350.0,-0.020547,10.496,349.78,350.28,355.95
155.8094,3.4536,-0.18965,33.014,350.0,-0.020575,10.48,349.78,350.38,355.93
156.6094,3.4448,-0.18986,33.246,350.0,-0.02061,10.448,349.72,350.43,355.93
157.4094,3.4541,-0.18972,33.2,350.0,-0.020605,10.474,349.77,350.45,355.96
158.2094,3.4463,-0.19037,33.511,350.0,-0.02065,10.455,349.71,350.35,355.88
159.0094,3.4518,-0.19229,33.427,350.0,-0.020833,10.472,349.7,350.27,355.85
159.8094,3.4455,-0.19204,33.374,350.0,-0.020837,10.447,349.69,350.35,355.85
160.6094,3.4467,-0.18964,33.082,350.0,-0.020528,10.457,349.76,350.32,355.88
161.4094,3.4389,-0.1898,33.488,350.0,-0.020539,10.436,349.65,350.36,355.86
161.95313,3.4226,0.021009,0.0,12.032,0.002887,10.35,349.73,350.21,356.0
161.95445,3.4009,0.019293,0.0,7.6204e-05,0.0014202,10.345,349.74,350.19,356.02
161.95577,3.4837,0.015441,0.0,2.9702e-10,0.0022748,10.521,349.75,350.18,356.04
161.95709,3.4691,0.013089,0.0,9.8484e-16,0.001452,10.516,349.76,350.16,356.06
161.95841,3.3954,0.017894,0.0,3.0156999999999998e-21,0.0020669,10.296,349.74,350.17,356.05
161.95973,3.4918,0.01537,0.0,8.8007e-27,0.0018147,10.598,349.72,350.18,356.03
161.96105,3.4276,0.015827,0.0,2.4891e-32,0.0018496,10.374,349.7,350.2,356.0
161.96237,3.3914,0.017258,0.0,6.8723e-38,0.0010211,10.284,349.67,350.21,355.98
161.96369,3.491,0.020883,0.0,1.8637e-43,0.0023729,10.579,349.65,350.23,355.95
161.96501,3.4324,0.017855,0.0,0.0,0.0010182,10.392,349.62,350.25,355.93
161.96633,3.391,0.017629,0.0,0.0,0.002097,10.315,349.6,350.26,355.91
161.96765,3.4797,0.019105,0.0,0.0,0.0019154,10.587,349.58,350.28,355.88
161.96897,3.4377,0.017689,0.0,0.0,0.0015117,10.396,349.59,350.28,355.88
161.97029,3.3807,0.017074,0.0,0.0,0.0028321,10.279,349.59,350.28,355.88
161.97161,3.47,0.017126,0.0,0.0,0.0016271,10.552,349.6,350.28,355.87
161.97293,3.4422,0.015382,0.0,0.0,0.0023346,10.405,349.61,350.28,355.87
161.97425,3.3679,0.011962,0.0,0.0,0.0022548,10.251,349.62,350.28,355.86
161.97557,3.4638,0.011583,0.0,0.0,0.0019182,10.542,349.63,350.28,355.86
161.97689,3.4358,0.018235,0.0,0.0,0.0017814,10.399,349.63,350.28,355.86
161.97821,3.3675,0.016977,0.0,0.0,0.0018586,10.226,349.64,350.29,355.85
161.97953,3.4578,0.016169,0.0,0.0,0.00096004,10.541,349.65,350.3,355.84
161.98085,3.4378,0.01906,0.0,0.0,0.0025723,10.396,349.66,350.32,355.83
161.98217,3.365,0.018564,0.0,0.0,0.00072747,10.201,349.67,350.33,355.83
161.98349,3.4465,0.016528,0.0,0.0,0.0021553,10.457,349.67,350.35,355.82
161.98481,3.4441,0.01945,0.0,0.0,0.0016961,10.414,349.68,350.37,355.81
161.98613,3.3585,0.019685,0.0,0.0,0.0015836,10.209,349.69,350.38,355.8
161.98745,3.441,0.012773,0.0,0.0,0.0024832,10.461,349.7,350.4,355.79
161.98877,3.4427,0.013672,0.0,0.0,0.0018122,10.427,349.7,350.4,355.81
161.99009,3.3601,0.014232,0.0,0.0,0.001962,10.197,349.69,350.41,355.82
161.99141,3.4321,0.016212,0.0,0.0,0.0022296,10.437,349.69,350.41,355.83
161.99273,3.4489,0.014835,0.0,0.0,0.0017563,10.419,349.68,350.41,355.84
161.99405,3.3514,0.017166,0.0,0.0,0.0020832,10.17,349.68,350.42,355.85
161.99537,3.4262,0.019076,0.0,0.0,0.0018733,10.414,349.67,350.42,355.87
161.99669,3.455,0.02063,0.0,0.0,0.001275,10.471,349.67,350.43,355.88
161.99801,3.3555,0.016086,0.0,0.0,0.0024326,10.165,349.89,350.37,355.87
161.99933,3.4039,0.021948,0.0,0.0,0.00080442,10.402,350.39,350.24,355.85
162.00065,3.4533,0.018954,0.0,0.0,0.0023095,10.449,350.88,350.1,355.83
162.00197,3.3522,0.016206,0.0,0.0,0.0015783,10.169,351.38,349.97,355.8
162.00329,3.4017,0.015746,0.0,0.0,0.0016858,10.324,351.88,349.84,355.78
162.00461,3.4544,0.015647,0.0,0.0,0.0019933,10.464,352.38,349.71,355.75
162.00593,3.3657,0.013283,0.0,0.0,0.0016563,10.208,352.87,349.57,355.73
162.00725,3.4233,0.013588,0.0,0.0,0.0016856,10.396,353.37,349.44,355.71
162.00856,3.4931,0.017344,0.0,0.0,0.0024777,10.551,354.79,350.73,355.7
162.00988,3.3124,0.018698,0.0,0.0,0.0012258,10.05,356.34,352.22,355.69
162.0112,3.4228,0.017519,0.0,0.0,0.0022687,10.439,357.88,353.7,355.68
162.01252,3.4933,0.019163,0.0,0.0,0.001917,10.538,359.43,355.18,355.67
162.01384,3.3496,0.018646,0.0,0.0,0.0013447,10.143,360.98,356.66,355.66
162.01516,3.3639,0.019681,0.0,0.0,0.0028111,10.233,362.52,358.14,355.66
162.01648,12.853,0.061988,0.0,0.0,0.0057952,35.655,364.07,359.63,355.65
162.0178,30.27,0.19053,0.0,0.0,0.020778,91.222,365.68,361.35,355.65
162.01912,35.435,0.44576,0.0,0.0,0.048373,106.68,367.45,363.6,355.68
162.02044,37.43,0.72863,0.0,0.0,0.081593,113.37,369.21,365.85,355.72
162.02176,38.56,0.99747,0.0,0.0,0.11398,116.98,370.97,368.1,355.75
162.02308,39.147,1.2882,0.0,0.0,0.14875,118.74,372.73,370.35,355.78
162.0244,39.492,1.5665,0.0,0.0,0.18449,119.73,374.49,372.6,355.81
162.02572,39.672,1.8495,0.0,0.0,0.22286,120.28,376.25,374.85,355.84
162.02704,39.748,2.1337,0.0,0.0,0.25948,120.56,378.01,377.11,355.88
162.02836,39.944,2.4205,0.0,0.0,0.30125,121.16,379.26,378.44,355.9
162.02968,40.128,2.7098,0.0,0.0,0.34339,121.68,380.34,379.49,355.91
162.031,40.318,3.004,0.0,0.0,0.38805,122.28,381.43,380.54,355.93
162.03232,40.579,3.2955,0.0,0.0,0.43585,123.07,382.51,381.6,355.94
162.03364,40.895,3.5768,0.0,0.0,0.48149,123.98,383.6,382.65,355.96
162.03496,41.138,3.8597,0.0,0.0,0.53268,124.73,384.69,383.7,355.98
162.03628,41.514,4.1495,0.0,0.0,0.5846,125.88,385.77,384.75,355.99
162.0376,41.879,4.4376,0.0,0.0,0.63869,126.99,386.73,385.68,356.01
162.03892,42.163,4.7315,0.0,0.0,0.69932,127.85,387.15,386.11,356.03
162.04024,42.419,5.0166,0.0,0.0,0.75664,128.63,387.56,386.55,356.05
162.04156,42.669,5.3072,0.0,0.0,0.82112,129.38,387.98,386.99,356.07
162.04288,42.822,5.5836,0.0,0.0,0.89099,129.87,388.4,387.43,356.09
162.0442,42.991,5.8566,0.0,0.0,0.95535,130.37,388.82,387.87,356.11
162.04552,43.148,6.1227,0.0,0.0,1.032,130.85,389.24,388.31,356.13
162.04684,43.162,6.3722,0.0,0.0,1.1004,130.87,389.66,388.75,356.15
162.04816,43.267,6.6049,0.0,0.0,1.1749,131.22,389.45,388.74,356.15
162.04948,43.245,6.8214,0.0,0.0,1.2482,131.2,388.88,388.48,356.14
162.0508,43.136,7.0097,0.0,0.0,1.3122,130.85,388.31,388.21,356.14
162.05212,43.005,7.1694,0.0,0.0,1.3782,130.48,387.74,387.95,356.13
162.05344,42.859,7.3107,0.0,0.0,1.4345,130.05,387.17,387.69,356.12
162.05476,42.503,7.4422,0.0,0.0,1.4823,128.97,386.59,387.42,356.11
162.05608,42.255,7.5482,0.0,0.0,1.5318,128.2,386.02,387.16,356.1
162.0574,42.05,7.6328,0.0,0.0,1.5673,127.6,385.41,386.88,356.1
162.05872,41.838,7.714,0.0,0.0,1.6024,126.91,384.25,386.38,356.09
162.06004,41.798,7.7903,0.0,0.0,1.6444,126.8,383.1,385.89,356.09
162.06136,38.163,7.7948,0.0,0.0,1.6411,116.08,381.95,385.39,356.08
162.06268,36.734,7.8047,0.0,0.0,1.6538,111.53,380.79,384.9,356.08
162.064,35.495,7.8178,0.0,0.0,1.6481,107.8,379.64,384.4,356.08
162.06532,34.752,7.8208,0.0,0.0,1.6567,105.42,378.48,383.91,356.07
162.06664,34.349,7.8175,0.0,0.0,1.6607,104.25,377.33,383.41,356.07
162.06796,34.113,7.8221,0.0,0.0,1.6589,103.51,376.29,382.97,356.08
162.06928,33.951,7.8292,0.0,0.0,1.664,103.0,375.37,382.56,356.1
162.0706,33.843,7.8285,0.0,0.0,1.6666,102.67,374.45,382.16,356.13
162.07192,33.764,7.8351,0.0,0.0,1.6629,102.41,373.52,381.76,356.15
162.07324,33.528,7.8418,0.0,0.0,1.6718,101.71,372.6,381.35,356.17
162.07456,33.187,7.8487,0.0,0.0,1.67,100.7,371.68,380.95,356.2
162.07588,32.764,7.8469,0.0,0.0,1.6719,99.53,370.75,380.55,356.22
162.0772,32.115,7.8487,0.0,0.0,1.6763,97.476,369.83,380.14,356.25
162.07852,31.153,7.8509,0.0,0.0,1.6679,94.665,369.38,379.85,356.31
162.07984,29.936,7.8477,0.0,0.0,1.6774,91.004,368.96,379.57,356.37
162.08116,28.258,7.8414,0.0,0.0,1.6672,85.951,368.53,379.29,356.43
162.08248,26.294,7.8392,0.0,0.0,1.6678,80.071,368.11,379.0,356.49
162.0838,24.045,7.8373,0.0,0.0,1.6701,73.244,367.69,378.72,356.55
162.08512,20.339,7.829,0.0,0.0,1.6635,62.497,367.26,378.43,356.61
162.08644,9.6943,7.825,0.0,0.0,1.661,31.025,366.84,378.15,356.67
162.08776,1.105,7.7841,0.0,0.0,1.6399,3.8216,366.57,377.92,356.71
162.08908,3.6742,7.7939,0.0,0.0,1.6389,10.665,366.53,377.76,356.75
162.0904,2.524,7.8036,0.0,0.0,1.6539,7.9588,366.5,377.6,356.78
162.09172,3.0666,7.8032,0.0,0.0,1.6452,9.3333,366.46,377.44,356.81
162.09304,3.1572,7.8019,0.0,0.0,1.6489,9.5653,366.42,377.28,356.84
162.09436,2.8088,7.7927,0.0,0.0,1.6486,8.343,366.39,377.12,356.88
162.09568,2.9599,7.7953,0.0,0.0,1.6427,9.1154,366.35,376.96,356.91
162.097,3.0209,7.7933,0.0,0.0,1.6493,9.1205,366.32,376.8,356.94
162.09832,2.826,7.7885,0.0,0.0,1.6469,8.5563,366.28,376.63,356.95
162.09964,2.9187,7.7864,0.0,0.0,1.6462,8.9556,366.25,376.46,356.97
162.10096,3.0367,7.7935,0.0,0.0,1.6488,9.1896,366.22,376.29,356.98
162.10228,2.7909,7.7932,0.0,0.0,1.6436,8.4347,366.19,376.13,356.99
162.1036,2.8466,7.7925,0.0,0.0,1.6439,8.713,366.15,375.96,357.0
162.10492,2.9823,7.7992,0.0,0.0,1.648,8.9911,366.12,375.79,357.01
162.10624,2.7852,7.796,0.0,0.0,1.6384,8.4002,366.09,375.62,357.03
162.10756,2.906,7.795,0.0,0.0,1.6498,8.8894,366.03,375.45,357.05
162.10888,2.9832,7.7941,0.0,0.0,1.6411,9.0083,365.91,375.25,357.11
162.1102,2.804,7.7972,0.0,0.0,1.6447,8.4663,365.79,375.05,357.16
162.11152,2.8709,7.7954,0.0,0.0,1.6476,8.7761,365.67,374.86,357.22
162.11284,2.9192,7.7909,0.0,0.0,1.643,8.8501,365.55,374.66,357.28
162.11416,2.7878,7.7922,0.0,0.0,1.6481,8.4302,365.43,374.47,357.33
162.11548,2.8679,7.7931,0.0,0.0,1.6472,8.7183,365.31,374.27,357.39
162.1168,2.9272,7.7899,0.0,0.0,1.6461,8.8658,365.19,374.08,357.44
162.11812,2.8478,7.7933,0.0,0.0,1.6502,8.5982,365.02,373.89,357.5
162.11944,2.8487,7.7976,0.0,0.0,1.6445,8.6698,364.83,373.72,357.56
162.12076,2.8795,7.8009,0.0,0.0,1.6467,8.7485,364.64,373.54,357.61
162.12208,2.831,7.7937,0.0,0.0,1.6488,8.6006,364.44,373.37,357.67
162.12339,2.8696,7.7978,0.0,0.0,1.6402,8.7614,364.25,373.19,357.72
162.12471,2.9722,7.7966,0.0,0.0,1.65,9.0038,364.06,373.01,357.78
162.12603,2.8616,7.7965,0.0,0.0,1.643,8.617,363.87,372.84,357.84
162.12735,2.8068,7.7953,0.0,0.0,1.6462,8.547,363.68,372.66,357.89
162.12867,2.9904,7.7984,0.0,0.0,1.6472,9.0974,363.5,372.49,357.93
162.12999,2.9075,7.7932,0.0,0.0,1.6437,8.769,363.32,372.31,357.98
162.13131,2.8929,7.7905,0.0,0.0,1.6475,8.7774,363.15,372.13,358.02
162.13263,2.9508,7.7944,0.0,0.0,1.6477,8.9279,362.97,371.96,358.07
162.13395,2.8689,7.7986,0.0,0.0,1.644,8.7079,362.8,371.78,358.11
162.13527,2.9125,7.7991,0.0,0.0,1.6523,8.8855,362.62,371.61,358.16
162.13659,2.9226,7.7969,0.0,0.0,1.6441,8.8536,362.44,371.43,358.2
162.13791,2.8456,7.8006,0.0,0.0,1.6482,8.6449,362.26,371.25,358.24
162.13923,2.9335,7.7986,0.0,0.0,1.6495,8.9447,362.07,371.07,358.28
162.14055,2.9798,7.7969,0.0,0.0,1.6423,8.9839,361.88,370.89,358.32
162.14187,2.875,7.8007,0.0,0.0,1.6531,8.7041,361.69,370.71,358.36
162.14319,2.896,7.8021,0.0,0.0,1.6464,8.8336,361.51,370.53,358.4
162.14451,2.9944,7.7955,0.0,0.0,1.6486,9.0737,361.32,370.35,358.44
162.14583,2.8978,7.7944,0.0,0.0,1.6488,8.7491,361.13,370.17,358.48
162.14715,2.8914,7.7965,0.0,0.0,1.6445,8.8344,360.94,369.99,358.52
162.14847,2.9971,7.7971,0.0,0.0,1.6473,9.09,360.73,369.85,358.56
162.14979,2.932,7.7954,0.0,0.0,1.6473,8.8685,360.52,369.7,358.6
162.15111,2.8925,7.8003,0.0,0.0,1.6426,8.802,360.31,369.55,358.64
162.15243,2.9762,7.8019,0.0,0.0,1.6522,9.06,360.11,369.4,358.68
162.15375,2.9447,7.7977,0.0,0.0,1.6428,8.88,359.9,369.25,358.72
162.15507,2.8777,7.7969,0.0,0.0,1.6479,8.7429,359.69,369.11,358.76
162.15639,2.9503,7.8018,0.0,0.0,1.6489,8.9544,359.48,368.96,358.8
162.15771,2.9295,7.7977,0.0,0.0,1.6441,8.8512,359.26,368.82,358.84
162.15903,2.8785,7.7969,0.0,0.0,1.6536,8.7522,359.02,368.68,358.89
162.16035,2.942,7.7971,0.0,0.0,1.6472,8.9289,358.78,368.54,358.93
162.16167,2.9069,7.7971,0.0,0.0,1.6493,8.7795,358.54,368.41,358.98
162.16299,2.8776,7.792,0.0,0.0,1.6506,8.75,358.3,368.27,359.02
162.16431,2.9556,7.7952,0.0,0.0,1.6457,8.9736,358.06,368.14,359.06
162.16563,2.9413,7.8017,0.0,0.0,1.6472,8.8537,357.81,368.0,359.11
162.16695,2.8694,7.8007,0.0,0.0,1.6491,8.7121,357.57,367.86,359.15
162.16827,2.9427,7.7985,0.0,0.0,1.6423,8.9738,357.36,367.74,359.2
162.16959,2.9682,7.7994,0.0,0.0,1.6513,8.9715,357.14,367.61,359.24
162.17091,2.8532,7.8008,0.0,0.0,1.6412,8.633,356.92,367.48,359.29
162.17223,2.9311,7.7976,0.0,0.0,1.6484,8.9238,356.71,367.35,359.33
162.17355,3.0067,7.8007,0.0,0.0,1.6479,9.0936,356.49,367.22,359.37
162.17487,2.902,7.8025,0.0,0.0,1.6453,8.7896,356.27,367.1,359.42
162.17619,2.9845,7.7956,0.0,0.0,1.654,9.0841,356.06,366.97,359.46
162.17751,3.0381,7.792,0.0,0.0,1.6481,9.1834,355.86,366.84,359.5
162.17883,2.948,7.7976,0.0,0.0,1.6481,8.9568,355.69,366.7,359.54
162.18015,3.0232,7.8001,0.0,0.0,1.6521,9.1794,355.52,366.56,359.58
162.18147,3.1231,7.7991,0.0,0.0,1.6472,9.4373,355.35,366.42,359.62
162.18279,2.9865,7.7983,0.0,0.0,1.6489,9.0661,355.18,366.28,359.66
162.18411,3.046,7.8028,0.0,0.0,1.6502,9.2957,355.02,366.14,359.7
162.18543,3.1265,7.7996,0.0,0.0,1.6437,9.4841,354.85,366.0,359.74
162.18675,2.9752,7.7988,0.0,0.0,1.6532,9.0154,354.68,365.85,359.78
162.18807,3.0825,7.8035,0.0,0.0,1.6401,9.4555,354.48,365.71,359.82
162.18939,3.211,7.8052,0.0,0.0,1.6503,9.6936,354.27,365.57,359.85
162.19071,2.9974,7.7986,0.0,0.0,1.6486,9.085,354.06,365.43,359.88
162.19203,3.1094,7.7954,0.0,0.0,1.6451,9.4975,353.85,365.29,359.91
162.19335,3.239,7.7979,0.0,0.0,1.65,9.7464,353.65,365.15,359.95
162.19467,2.9567,7.7958,0.0,0.0,1.6465,8.9195,353.44,365.01,359.98
162.19599,3.1084,7.7961,0.0,0.0,1.6456,9.4934,353.23,364.87,360.01
162.19731,3.2612,7.8006,0.0,0.0,1.6518,9.7782,353.01,364.73,360.04
162.19863,2.8917,7.8028,0.0,0.0,1.6436,8.7739,352.78,364.59,360.08
162.19995,3.0815,7.7984,0.0,0.0,1.6511,9.5319,352.55,364.45,360.11
162.20127,3.2492,7.7975,0.0,0.0,1.6481,9.7946,352.32,364.31,360.14
162.20259,2.9413,7.8021,0.0,0.0,1.6453,8.8837,352.08,364.17,360.17
162.20391,3.0928,7.7998,0.0,0.0,1.6532,9.4983,351.85,364.03,360.2
162.20523,3.2548,7.7983,0.0,0.0,1.6437,9.7603,351.62,363.89,360.24
162.20655,2.9333,7.7992,0.0,0.0,1.6504,8.8593,351.39,363.75,360.27
162.20787,3.09,7.7984,0.0,0.0,1.6491,9.4604,351.16,363.61,360.29
162.20919,3.288,7.7925,0.0,0.0,1.6462,9.8853,350.93,363.46,360.32
162.21051,2.9561,7.793,0.0,0.0,1.6475,8.8874,350.7,363.32,360.34
162.21183,3.069,7.8029,0.0,0.0,1.6467,9.4651,350.47,363.18,360.37
162.21315,3.2893,7.8004,0.0,0.0,1.6435,9.9524,350.24,363.03,360.39
162.21447,2.9745,7.7995,0.0,0.0,1.6517,8.972,350.01,362.89,360.41
162.21579,3.0448,7.8011,0.0,0.0,1.643,9.3154,349.78,362.74,360.44
162.21711,3.2859,7.8019,0.0,0.0,1.6512,9.9079,349.56,362.6,360.46
162.21843,2.9845,7.7973,0.0,0.0,1.6476,8.978,349.38,362.47,360.48
162.21975,3.042,7.8008,0.0,0.0,1.6455,9.3321,349.2,362.34,360.5
162.22107,3.3159,7.8056,0.0,0.0,1.6544,10.042,349.02,362.21,360.52
162.22239,3.0184,7.7978,0.0,0.0,1.6467,9.0854,348.84,362.09,360.54
162.22371,3.0304,7.7941,0.0,0.0,1.6524,9.2979,348.66,361.96,360.56
162.22503,3.3057,7.7986,0.0,0.0,1.6513,10.038,348.48,361.83,360.58
162.22635,3.0405,7.7975,0.0,0.0,1.6465,9.1343,348.29,361.7,360.6
162.22767,3.0214,7.7969,0.0,0.0,1.6497,9.2386,348.13,361.59,360.62
162.22899,3.3041,7.8018,0.0,0.0,1.6479,10.0,347.97,361.49,360.64
162.23031,3.0543,7.8013,0.0,0.0,1.6426,9.1698,347.81,361.39,360.65
162.23163,2.9927,7.8019,0.0,0.0,1.6527,9.177,347.66,361.29,360.67
162.23295,3.3141,7.7967,0.0,0.0,1.6406,10.082,347.5,361.19,360.68
162.23427,3.0751,7.8054,0.0,0.0,1.651,9.2607,347.34,361.09,360.7
162.23559,2.9836,7.8015,0.0,0.0,1.6452,9.1386,347.19,360.99,360.72
162.23691,3.2874,7.8011,0.0,0.0,1.647,10.004,347.03,360.89,360.73
162.23822,3.0916,7.7977,0.0,0.0,1.6504,9.2655,346.86,360.77,360.76
162.23954,2.9769,7.799,0.0,0.0,1.6469,9.0959,346.68,360.66,360.8
162.24086,3.2885,7.7961,0.0,0.0,1.6521,10.029,346.51,360.54,360.83
162.24218,3.0916,7.7942,0.0,0.0,1.6525,9.2513,346.34,360.42,360.86
162.2435,2.9166,7.7978,0.0,0.0,1.6447,8.9141,346.17,360.31,360.89
162.24482,3.2887,7.8057,0.0,0.0,1.6529,10.053,345.99,360.19,360.92
162.24614,3.108,7.7969,0.0,0.0,1.647,9.3339,345.82,360.07,360.96
162.24746,2.9392,7.8007,0.0,0.0,1.6454,8.9629,345.65,359.95,360.99
162.24878,3.2577,7.8026,0.0,0.0,1.6527,9.916,345.47,359.82,361.04
162.2501,3.1267,7.801,0.0,0.0,1.6432,9.3783,345.29,359.7,361.08
162.25142,2.9264,7.7988,0.0,0.0,1.6508,8.9122,345.12,359.57,361.13
162.25274,3.2422,7.8022,0.0,0.0,1.6443,9.9158,344.94,359.44,361.17
162.25406,3.1521,7.8005,0.0,0.0,1.6465,9.4597,344.76,359.31,361.21
162.25538,2.9032,7.791,0.0,0.0,1.6486,8.8527,344.58,359.18,361.26
162.2567,3.2308,7.7975,0.0,0.0,1.6466,9.8741,344.41,359.05,361.3
162.25802,3.1687,7.7992,0.0,0.0,1.6472,9.5109,344.24,358.95,361.32
162.25934,2.9204,7.7991,0.0,0.0,1.6517,8.8731,344.07,358.86,361.34
162.26066,3.1988,7.7991,0.0,0.0,1.6442,9.7661,343.9,358.76,361.35
162.26198,3.1767,7.8036,0.0,0.0,1.6525,9.5033,343.73,358.67,361.37
162.2633,2.9023,7.8003,0.0,0.0,1.6472,8.7912,343.56,358.57,361.39
162.26462,3.2105,7.801,0.0,0.0,1.6483,9.861,343.39,358.47,361.4
162.26594,3.2083,7.7998,0.0,0.0,1.6524,9.6187,343.23,358.38,361.42
162.26726,2.9063,7.8069,0.0,0.0,1.6463,8.8223,343.06,358.28,361.43
162.26858,3.1807,7.7985,0.0,0.0,1.6525,9.7541,342.88,358.18,361.45
162.2699,3.2177,7.7974,0.0,0.0,1.6482,9.6939,342.71,358.08,361.46
162.27122,2.929,7.7972,0.0,0.0,1.6468,8.8473,342.54,357.98,361.47
162.27254,3.176,7.799,0.0,0.0,1.65,9.7257,342.36,357.88,361.48
162.27386,3.2364,7.7974,0.0,0.0,1.6474,9.7279,342.19,357.78,361.49
162.27518,2.9191,7.7998,0.0,0.0,1.6458,8.8481,342.02,357.68,361.51
162.2765,3.1518,7.8062,0.0,0.0,1.651,9.7303,341.85,357.58,361.52
162.27782,3.2748,7.8023,0.0,0.0,1.6426,9.8482,341.69,357.47,361.53
162.27914,2.9378,7.7997,0.0,0.0,1.6516,8.8863,341.53,357.36,361.55
162.28046,3.1432,7.8042,0.0,0.0,1.6479,9.6575,341.38,357.24,361.56
162.28178,3.2767,7.8045,0.0,0.0,1.6483,9.8524,341.23,357.13,361.58
162.2831,2.952,7.8002,0.0,0.0,1.6535,8.8929,341.08,357.02,361.6
162.28442,3.1459,7.8016,0.0,0.0,1.647,9.6379,340.92,356.91,361.61
162.28574,3.2905,7.8021,0.0,0.0,1.6532,9.8929,340.77,356.8,361.63
162.28706,2.9612,7.7947,0.0,0.0,1.6508,8.9608,340.62,356.69,361.64
162.28838,3.111,7.7942,0.0,0.0,1.6497,9.6397,340.5,356.59,361.66
162.2897,3.3084,7.8026,0.0,0.0,1.6521,9.9705,340.38,356.49,361.67
162.29102,2.9943,7.8011,0.0,0.0,1.6472,9.0447,340.26,356.4,361.68
162.29234,3.1107,7.8021,0.0,0.0,1.6472,9.5387,340.14,356.3,361.69
162.29366,3.3093,7.8039,0.0,0.0,1.6513,9.9624,340.02,356.21,361.7
162.29498,3.0121,7.8047,0.0,0.0,1.6419,9.0769,339.9,356.11,361.72
162.2963,3.0822,7.8026,0.0,0.0,1.6526,9.4482,339.78,356.01,361.73
162.29762,3.3259,7.8023,0.0,0.0,1.6463,10.057,339.65,355.92,361.74
162.29894,3.0155,7.8063,0.0,0.0,1.6477,9.0854,339.52,355.83,361.75
162.30026,3.0578,7.8032,0.0,0.0,1.652,9.4168,339.39,355.75,361.75
162.30158,3.3262,7.7987,0.0,0.0,1.6475,10.077,339.25,355.66,361.76
162.3029,3.0466,7.7986,0.0,0.0,1.6507,9.1592,339.12,355.57,361.77
162.30422,3.0656,7.8026,0.0,0.0,1.6528,9.3968,338.99,355.48,361.78
162.30554,3.3267,7.8008,0.0,0.0,1.6495,10.05,338.86,355.39,361.79
162.30686,3.0467,7.8006,0.0,0.0,1.6531,9.1558,338.72,355.3,361.8
162.30818,3.0281,7.8049,0.0,0.0,1.6485,9.2753,338.57,355.21,361.83
162.3095,3.3313,7.8073,0.0,0.0,1.6489,10.12,338.43,355.11,361.86
162.31082,3.0708,7.8005,0.0,0.0,1.6535,9.2079,338.28,355.02,361.89
162.31214,3.009,7.8061,0.0,0.0,1.644,9.2539,338.13,354.92,361.92
162.31346,3.316,7.8041,0.0,0.0,1.653,10.084,337.98,354.82,361.96
162.31478,3.0779,7.806,0.0,0.0,1.6485,9.242,337.83,354.73,361.99
162.3161,3.0106,7.7994,0.0,0.0,1.6488,9.2259,337.68,354.63,362.02
162.31742,3.3098,7.8038,0.0,0.0,1.6516,10.051,337.55,354.55,362.04
162.31874,3.0949,7.7999,0.0,0.0,1.6469,9.2854,337.43,354.47,362.06
162.32006,2.9924,7.795,0.0,0.0,1.6486,9.1551,337.32,354.4,362.08
162.32138,3.3207,7.8025,0.0,0.0,1.6525,10.081,337.2,354.33,362.09
162.3227,3.124,7.805,0.0,0.0,1.6445,9.3949,337.08,354.26,362.11
162.32402,2.9783,7.8036,0.0,0.0,1.6545,9.1217,336.97,354.19,362.12
162.32534,3.2972,7.8024,0.0,0.0,1.6481,10.047,336.85,354.11,362.14
162.32666,3.1431,7.8051,0.0,0.0,1.6491,9.4323,336.73,354.04,362.16
162.32798,2.9646,7.8053,0.0,0.0,1.654,9.0361,336.62,353.95,362.15
162.3293,3.3005,7.8006,0.0,0.0,1.6448,10.054,336.51,353.85,362.15
162.33062,3.1553,7.8067,0.0,0.0,1.656,9.4701,336.4,353.75,362.15
162.33194,2.9534,7.8008,0.0,0.0,1.6475,8.9909,336.28,353.66,362.14
162.33326,3.3057,7.8022,0.0,0.0,1.6518,10.073,336.17,353.56,362.14
162.33458,3.1714,7.7922,0.0,0.0,1.6494,9.5191,336.06,353.47,362.13
162.3359,2.9375,7.8033,0.0,0.0,1.6479,8.9511,335.95,353.37,362.13
162.33722,3.2665,7.8,0.0,0.0,1.647,9.9598,335.82,353.27,362.13
162.33854,3.1968,7.8022,0.0,0.0,1.6514,9.5938,335.68,353.16,362.14
162.33986,2.949,7.8037,0.0,0.0,1.6437,8.9804,335.54,353.04,362.15
162.34118,3.2579,7.8068,0.0,0.0,1.6539,9.9659,335.4,352.93,362.15
162.3425,3.2165,7.8023,0.0,0.0,1.6458,9.6465,335.26,352.82,362.16
162.34382,2.9376,7.8021,0.0,0.0,1.6496,8.9268,335.12,352.71,362.17
162.34514,3.2492,7.8079,0.0,0.0,1.6529,9.9724,334.98,352.59,362.18
162.34646,3.2428,7.8053,0.0,0.0,1.6477,9.7632,334.84,352.48,362.19
162.34778,2.9612,7.7997,0.0,0.0,1.6561,8.9805,334.72,352.4,362.19
162.3491,3.2353,7.8015,0.0,0.0,1.6516,9.9157,334.6,352.32,362.2
162.35042,3.2392,7.8029,0.0,0.0,1.651,9.7303,334.48,352.24,362.21
162.35174,2.9723,7.7979,0.0,0.0,1.6521,8.9978,334.36,352.15,362.22
162.35306,3.2289,7.8033,0.0,0.0,1.6494,9.9162,334.25,352.07,362.23
162.35437,3.2697,7.8074,0.0,0.0,1.649,9.8317,334.13,351.99,362.23
162.35569,2.9466,7.8071,0.0,0.0,1.6524,8.9255,334.01,351.91,362.24
162.35701,3.2013,7.8036,0.0,0.0,1.6441,9.8548,333.9,351.83,362.25
162.35833,3.2907,7.8069,0.0,0.0,1.655,9.9204,333.8,351.75,362.25
162.35965,2.9773,7.8067,0.0,0.0,1.6439,8.9725,333.7,351.67,362.25
162.36097,3.202,7.8055,0.0,0.0,1.651,9.797,333.6,351.58,362.25
162.36229,3.3042,7.8044,0.0,0.0,1.651,9.9297,333.5,351.5,362.25
162.36361,2.9868,7.8051,0.0,0.0,1.6479,9.0442,333.4,351.41,362.25
162.36493,3.1892,7.8016,0.0,0.0,1.6555,9.8203,333.3,351.33,362.25
162.36625,3.3298,7.7957,0.0,0.0,1.6518,10.032,333.2,351.24,362.25
162.36757,2.9898,7.8009,0.0,0.0,1.6486,9.0419,333.09,351.15,362.25
162.36889,3.1368,7.8071,0.0,0.0,1.6548,9.6463,332.97,351.06,362.25
162.37021,3.3308,7.8048,0.0,0.0,1.6492,10.037,332.86,350.97,362.25
162.37153,3.0323,7.8049,0.0,0.0,1.6511,9.1026,332.75,350.88,362.25
162.37285,3.147,7.8069,0.0,0.0,1.6534,9.6472,332.64,350.79,362.25
162.37417,3.3308,7.8066,0.0,0.0,1.6463,10.049,332.52,350.69,362.25
162.37549,3.0158,7.8025,0.0,0.0,1.6552,9.1019,332.41,350.6,362.25
162.37681,3.118,7.8076,0.0,0.0,1.6442,9.638,332.3,350.51,362.25
162.37813,3.3626,7.8091,0.0,0.0,1.6514,10.143,332.19,350.45,362.26
162.37945,3.0395,7.8002,0.0,0.0,1.651,9.1636,332.09,350.38,362.27
162.38077,3.0941,7.7989,0.0,0.0,1.6475,9.4794,331.98,350.32,362.27
162.38209,3.35,7.8034,0.0,0.0,1.6521,10.124,331.88,350.25,362.28
162.38341,3.0629,7.8032,0.0,0.0,1.6507,9.2085,331.77,350.19,362.29
162.38473,3.1007,7.8032,0.0,0.0,1.6472,9.4819,331.67,350.13,362.3
162.38605,3.3557,7.8091,0.0,0.0,1.656,10.151,331.56,350.06,362.31
162.38737,3.0561,7.8068,0.0,0.0,1.6465,9.1818,331.45,350.0,362.3
162.38869,3.0529,7.8054,0.0,0.0,1.6543,9.4447,331.34,349.94,362.28
162.39001,3.3699,7.8059,0.0,0.0,1.6537,10.207,331.23,349.88,362.27
162.39133,3.0715,7.8084,0.0,0.0,1.6477,9.2471,331.12,349.82,362.25
162.39265,3.0501,7.8054,0.0,0.0,1.6556,9.3469,331.0,349.76,362.24
162.39397,3.3457,7.8067,0.0,0.0,1.6497,10.137,330.89,349.7,362.22
162.39529,3.0978,7.8039,0.0,0.0,1.6525,9.3001,330.78,349.64,362.2
162.39661,3.0279,7.8033,0.0,0.0,1.6526,9.2617,330.66,349.58,362.19
162.39793,3.3466,7.8012,0.0,0.0,1.65,10.182,330.55,349.5,362.19
162.39925,3.1001,7.8013,0.0,0.0,1.6501,9.309,330.44,349.42,362.19
162.40057,2.9869,7.8098,0.0,0.0,1.6499,9.1774,330.33,349.34,362.19
162.40189,3.3481,7.8087,0.0,0.0,1.6463,10.169,330.21,349.26,362.19
162.40321,3.1399,7.8061,0.0,0.0,1.6557,9.4414,330.1,349.18,362.19
162.40453,3.0191,7.8066,0.0,0.0,1.6462,9.2346,329.99,349.1,362.19
162.40585,3.3376,7.8098,0.0,0.0,1.6543,10.12,329.87,349.02,362.19
162.40717,3.1589,7.8053,0.0,0.0,1.6519,9.4704,329.77,348.95,362.19
162.40849,3.0154,7.807,0.0,0.0,1.649,9.2109,329.69,348.89,362.2
162.40981,3.3319,7.8102,0.0,0.0,1.657,10.157,329.6,348.83,362.21
162.41113,3.183,7.803,0.0,0.0,1.6517,9.5556,329.52,348.78,362.22
162.41245,2.9896,7.7976,0.0,0.0,1.6546,9.1528,329.44,348.72,362.22
162.41377,3.3235,7.8042,0.0,0.0,1.6549,10.138,329.35,348.66,362.23
162.41509,3.191,7.8061,0.0,0.0,1.6493,9.615,329.27,348.61,362.24
162.41641,3.0005,7.8034,0.0,0.0,1.6516,9.1484,329.18,348.55,362.25
162.41773,3.3094,7.8076,0.0,0.0,1.6518,10.09,329.1,348.48,362.24
162.41905,3.2221,7.8095,0.0,0.0,1.646,9.6911,329.02,348.42,362.23
162.42037,2.9859,7.8065,0.0,0.0,1.6552,9.0965,328.94,348.35,362.23
162.42169,3.3113,7.8053,0.0,0.0,1.6458,10.122,328.86,348.28,362.22
162.42301,3.2396,7.8104,0.0,0.0,1.6525,9.7445,328.78,348.21,362.21
162.42433,2.9818,7.8087,0.0,0.0,1.65,9.0473,328.7,348.14,362.2
162.42565,3.2877,7.8049,0.0,0.0,1.649,10.058,328.62,348.08,362.19
162.42697,3.2583,7.8026,0.0,0.0,1.6533,9.8039,328.53,348.0,362.18
162.42829,3.0105,7.8045,0.0,0.0,1.6507,9.1179,328.44,347.92,362.17
162.42961,3.2864,7.803,0.0,0.0,1.6527,10.096,328.35,347.84,362.16
162.43093,3.282,7.8032,0.0,0.0,1.6555,9.8622,328.25,347.76,362.15
162.43225,2.9912,7.8065,0.0,0.0,1.6481,9.0779,328.16,347.68,362.14
162.43357,3.277,7.8126,0.0,0.0,1.6547,10.069,328.07,347.6,362.12
162.43489,3.3124,7.8062,0.0,0.0,1.6533,9.937,327.98,347.52,362.11
162.43621,2.9927,7.8055,0.0,0.0,1.6468,9.0365,327.88,347.44,362.1
162.43753,3.2534,7.8122,0.0,0.0,1.6579,9.958,327.79,347.37,362.09
162.43885,3.313,7.8082,0.0,0.0,1.6474,9.9594,327.69,347.29,362.08
162.44017,3.0147,7.8071,0.0,0.0,1.6541,9.1233,327.59,347.22,362.07
162.44149,3.2417,7.8082,0.0,0.0,1.6508,9.9433,327.5,347.15,362.07
162.44281,3.3355,7.8065,0.0,0.0,1.6494,10.03,327.4,347.08,362.06
162.44413,2.9962,7.8007,0.0,0.0,1.6528,9.0574,327.3,347.0,362.05
162.44545,3.21,7.8014,0.0,0.0,1.6495,9.8904,327.21,346.93,362.04
162.44677,3.3505,7.8096,0.0,0.0,1.6496,10.089,327.11,346.86,362.04
162.44809,3.0247,7.8083,0.0,0.0,1.6564,9.0881,327.03,346.8,362.06
162.44941,3.1919,7.8058,0.0,0.0,1.6475,9.7805,326.95,346.73,362.07
162.45073,3.3579,7.8094,0.0,0.0,1.6546,10.107,326.87,346.67,362.09
162.45205,3.0418,7.8115,0.0,0.0,1.6536,9.1957,326.79,346.6,362.1
162.45337,3.1876,7.8051,0.0,0.0,1.6492,9.8182,326.71,346.54,362.12
162.45469,3.3584,7.8105,0.0,0.0,1.6584,10.139,326.63,346.48,362.14
162.45601,3.0102,7.8117,0.0,0.0,1.6497,9.0968,326.55,346.41,362.15
162.45733,3.1474,7.8052,0.0,0.0,1.6556,9.6898,326.48,346.34,362.16
162.45865,3.3613,7.8035,0.0,0.0,1.6533,10.153,326.41,346.27,362.16
162.45997,3.0582,7.8023,0.0,0.0,1.6487,9.2018,326.34,346.2,362.16
162.46129,3.1373,7.8072,0.0,0.0,1.6526,9.593,326.27,346.12,362.16
162.46261,3.3664,7.8047,0.0,0.0,1.6514,10.195,326.2,346.05,362.16
162.46393,3.0674,7.8062,0.0,0.0,1.6474,9.2597,326.13,345.98,362.16
162.46525,3.1343,7.8109,0.0,0.0,1.6555,9.6812,326.07,345.91,362.16
162.46657,3.3827,7.8096,0.0,0.0,1.6466,10.274,326.0,345.84,362.16
162.46783,2.9817,7.809,0.0,0.0,1.6551,9.0426,325.92,345.77,362.15
163.26783,3.0597,7.8144,0.0,0.0,1.6556,9.2842,285.75,275.61,233.74
164.06783,3.0033,7.8195,0.0,0.0,1.6581,9.1045,246.96,198.24,188.63
164.86783,2.9838,7.835,0.0,0.0,1.6659,9.0504,187.97,73.665,148.45
165.66783,2.9524,7.8572,0.0,0.0,1.677,8.961,116.25,47.474,56.437
166.46783,2.9241,7.8738,0.0,0.0,1.6853,8.8705,68.153,40.126,31.807
167.1955,2.9163,7.8835,0.0,0.0,1.6903,8.8494,51.646,30.209,26.569
167.9955,2.8823,7.8901,0.0,0.0,1.6937,8.7421,43.048,27.587,24.571
168.7955,2.8677,7.896,0.0,0.0,1.6967,8.6926,37.267,25.776,23.227
169.5955,2.8531,7.9008,0.0,0.0,1.6991,8.6542,33.419,24.603,22.402
170.3955,2.8204,7.9049,0.0,0.0,1.701,8.5596,30.577,23.863,22.006
171.1955,2.825,7.9091,0.0,0.0,1.7032,8.567,29.148,23.508,21.928
171.9955,2.8336,7.9121,0.0,0.0,1.7048,8.5958,27.495,22.779,21.596
172.7955,2.9721,7.9142,0.0,0.0,1.7059,9.0178,27.873,24.101,22.472
173.5955,2.8617,7.9147,0.0,0.0,1.7062,8.6792,29.614,26.687,24.509
174.3955,2.8324,7.9153,0.0,0.0,1.7067,8.589,31.039,28.439,26.376
175.1955,2.7946,7.9169,0.0,0.0,1.7076,8.4762,31.971,29.657,27.823
175.9955,3.0035,7.9181,0.0,0.0,1.7081,9.1115,32.917,30.842,29.147
176.7955,2.7866,7.9229,0.0,0.0,1.7105,8.4523,33.611,31.841,30.337
177.5955,2.7787,7.9224,0.0,0.0,1.7102,8.4283,34.142,37.382,31.359
178.3955,2.7823,7.9204,0.0,0.0,1.7092,8.4414,34.54,40.312,32.196
179.1955,2.7827,7.9211,0.0,0.0,1.7096,8.4398,34.897,40.312,32.919
179.3955,2.7823,7.9212,0.0,0.0,1.7096,8.4431,34.999,40.312,32.998