File: examples/dan-msc-case-studies/CS4/data/01 raw data/hyde_test_013.csv
Time(sec),Force(kN),Jaw(mm),PowAngle(deg),PTemp,Strain,Stress(MPa),TC1(C),TC2(C),TC3(C),TC4(C)
0.0,4.166,-0.046598,0.0,0.0059081,-0.0050873,4.9472,24.857,25.208,24.697,25.019
1.0,4.0568,-0.0027623,0.0,2.8207,-0.00029699,4.8134,24.886,25.223,24.626,24.99
2.0,3.9952,-0.0027753,0.0,5.8207,-0.00030135,4.7406,24.871,25.284,24.608,25.034
3.0,3.9436,-0.0029826,0.0,8.8266,-0.00036397,4.6801,24.918,25.229,24.592,25.017
3.8121,3.9309,-0.0026468,0.0,11.257,-0.00030915,4.6652,24.924,25.233,24.623,24.993
4.8121,3.9162,-0.0028669,0.0,14.257,-0.00032297,4.6481,24.914,25.215,24.669,25.004
5.8121,3.9071,-0.002791,0.0,17.257,-0.00030462,4.6369,24.875,25.231,24.668,25.023
6.8121,3.8994,-0.0029055,0.0,20.257,-0.00033142,4.627,24.888,25.235,24.625,25.043
7.8121,3.885,-0.0029088,0.0,23.257,-0.00033868,4.6092,24.86,25.232,24.672,24.942
8.8121,3.8776,-0.0020124,14.786,26.257,-0.00022999,4.6012,24.895,25.265,24.654,25.015
9.8121,3.9005,-0.0012379,32.991,29.257,-0.00013716,4.6292,25.81,26.525,24.738,25.296
10.8121,3.9169,-0.0019574,34.879,32.257,-0.00022272,4.6494,29.541,37.687,25.267,27.215
11.8121,3.9146,-0.0043168,33.651,35.257,-0.00048184,4.6453,33.705,37.954,26.605,30.503
12.8121,3.9094,-0.0034769,33.706,38.257,-0.00038138,4.6389,37.202,39.414,28.667,33.727
13.8121,3.9051,-0.003966,33.542,41.257,-0.00044228,4.6335,40.568,42.646,31.004,36.951
14.8121,3.9049,-0.0054866,33.766,44.257,-0.00061703,4.6338,43.791,45.731,33.554,40.147
15.8121,3.9044,-0.005477,33.696,47.257,-0.00060311,4.6348,46.977,48.793,36.131,43.27
16.8121,3.91,-0.005245,34.193,50.257,-0.00059026,4.6409,49.947,51.761,38.788,46.319
17.8121,3.9153,-0.0071924,34.646,53.257,-0.00079988,4.6461,52.892,54.779,41.383,49.351
18.8121,3.9167,-0.0074433,34.552,56.257,-0.00082827,4.647,56.074,57.927,44.258,52.542
19.8121,3.9121,-0.0080362,34.651,59.257,-0.00088819,4.6418,59.094,61.009,47.216,55.812
20.8121,3.9092,-0.0096659,34.85,62.257,-0.0010576,4.6392,62.087,63.934,50.152,58.974
21.8121,3.913,-0.010313,35.215,65.257,-0.0011431,4.6451,65.107,66.968,53.096,62.146
22.8121,3.9262,-0.010384,34.976,68.257,-0.0011468,4.6605,68.123,69.953,56.155,65.398
23.8121,3.9218,-0.012998,35.275,71.257,-0.001425,4.6529,71.138,72.941,59.047,68.687
24.8121,3.9257,-0.013497,35.133,74.257,-0.0014782,4.6582,74.208,75.957,62.168,71.953
25.8121,3.9245,-0.014007,35.688,77.257,-0.0015263,4.6569,77.166,78.855,65.17,75.249
26.8121,3.9349,-0.016862,35.498,80.257,-0.0018277,4.6703,80.205,81.837,68.226,78.534
27.8121,3.9365,-0.016799,36.075,83.257,-0.0018302,4.6726,83.137,84.7,71.213,81.832
28.8121,3.9497,-0.017439,36.039,86.257,-0.0019004,4.6866,86.17,87.698,74.187,85.053
29.8121,3.958,-0.021446,35.937,89.257,-0.0023364,4.6967,89.182,90.67,77.208,88.378
30.8121,3.9568,-0.020795,36.136,92.257,-0.0022783,4.6953,92.209,93.637,80.216,91.616
31.8121,3.9612,-0.021288,36.215,95.257,-0.0023193,4.7015,95.195,96.468,83.187,94.841
32.8121,3.9704,-0.025437,36.782,98.257,-0.0027805,4.7128,98.078,99.403,86.099,98.032
33.8121,3.982,-0.024904,37.084,101.26,-0.0027182,4.7272,101.03,102.34,89.137,101.3
34.8121,3.992,-0.025908,37.085,104.26,-0.0028243,4.7369,104.14,105.38,92.142,104.59
35.7254,3.9963,-0.026483,36.924,107.0,-0.0029307,4.7437,106.96,108.06,94.852,107.63
36.7254,4.001,-0.029277,37.04,110.0,-0.0032196,4.7487,109.96,110.92,97.856,110.88
37.7254,4.0079,-0.030195,37.089,113.0,-0.0033195,4.7565,112.94,113.93,100.83,114.1
38.7254,4.0146,-0.030681,37.274,116.0,-0.0033729,4.763,115.94,116.8,103.8,117.26
39.7254,4.0122,-0.034299,37.37,119.0,-0.0037666,4.7606,118.92,119.69,106.81,120.38
40.7254,4.0128,-0.035357,37.441,122.0,-0.0038822,4.7627,121.91,122.65,109.7,123.56
41.7254,4.0212,-0.035613,37.678,125.0,-0.0039001,4.7734,124.89,125.59,112.51,126.76
42.7254,4.026,-0.039355,37.837,128.0,-0.0043021,4.7776,127.9,128.47,115.28,129.91
43.6943,4.0297,-0.040488,37.866,130.9,-0.0044549,4.781,130.85,131.36,117.88,132.98
44.6943,4.0339,-0.041106,38.216,133.9,-0.0045225,4.7851,133.78,134.32,120.63,136.17
45.6943,4.035,-0.045575,38.109,136.9,-0.0050039,4.7882,136.88,137.27,123.29,139.34
46.6943,4.0365,-0.045412,38.415,139.9,-0.0049948,4.7916,139.83,140.18,126.01,142.4
47.6943,4.0522,-0.046426,38.435,142.9,-0.0051023,4.8102,142.84,143.06,128.71,145.49
48.6943,4.0536,-0.050892,38.944,145.9,-0.0056093,4.8095,145.74,145.94,131.36,148.56
49.6943,4.0483,-0.050825,38.793,148.9,-0.0055864,4.8034,148.87,148.89,133.99,151.69
50.6943,4.0499,-0.052664,39.051,151.9,-0.005784,4.8053,151.87,151.94,136.6,154.75
51.6943,4.0534,-0.053058,38.884,154.9,-0.0058247,4.8103,154.85,154.84,139.19,157.78
52.6943,4.0584,-0.057299,39.106,157.9,-0.0062927,4.817,157.84,157.75,141.8,160.76
53.6943,4.0613,-0.058476,39.393,160.9,-0.0064323,4.8202,160.77,160.76,144.44,163.9
54.6943,4.0702,-0.059754,39.324,163.9,-0.0065785,4.8289,163.85,163.67,147.17,167.02
55.6943,4.0651,-0.060824,39.274,166.9,-0.0067094,4.8227,166.93,166.67,149.84,170.15
56.6943,4.0592,-0.065056,39.404,169.9,-0.0071497,4.8163,169.9,169.62,152.46,173.19
57.6943,4.0614,-0.066212,39.47,172.9,-0.0073077,4.821,172.9,172.42,155.17,176.09
58.6943,4.0656,-0.067845,39.797,175.9,-0.0074948,4.8264,175.86,175.31,157.79,179.18
59.6943,4.0689,-0.068471,39.44,178.9,-0.0075686,4.8293,178.91,178.37,160.55,182.26
60.6943,4.075,-0.074976,39.915,181.9,-0.008274,4.8349,181.85,181.19,163.3,185.21
61.6943,4.0621,-0.074208,39.659,184.9,-0.0082098,4.8191,184.88,184.11,166.0,188.31
62.6943,4.0568,-0.076075,39.641,187.9,-0.0084165,4.8152,187.92,186.99,168.79,191.39
63.6943,4.0636,-0.07744,39.882,190.9,-0.0085598,4.8228,190.86,189.91,171.51,194.42
64.6943,4.0733,-0.082886,39.921,193.9,-0.0091809,4.8345,193.89,192.84,174.28,197.52
65.6943,4.0699,-0.083169,39.985,196.9,-0.0091947,4.8297,196.86,195.72,176.95,200.53
66.6943,4.0704,-0.085001,40.22,199.9,-0.0093755,4.829,199.83,199.47,179.63,203.61
67.6943,4.0681,-0.086454,40.248,202.9,-0.0095394,4.827,202.84,202.53,182.24,206.6
68.5733,4.0789,-0.087409,39.926,205.54,-0.0096086,4.8407,205.55,205.11,184.69,209.26
69.5733,4.0719,-0.092281,40.341,208.54,-0.01011,4.8309,208.46,207.75,187.45,212.24
70.5733,4.0618,-0.093732,40.46,211.54,-0.010271,4.82,211.49,210.48,190.2,215.24
71.5733,4.0656,-0.095463,40.43,214.54,-0.010469,4.8251,214.47,213.42,192.95,218.25
72.5733,4.0769,-0.096254,40.289,217.54,-0.01055,4.8395,217.57,216.31,195.74,221.41
73.5733,4.0802,-0.10285,40.555,220.54,-0.011299,4.8428,220.5,219.19,198.64,224.39
74.5733,4.0739,-0.10269,40.57,223.54,-0.011273,4.8345,223.54,222.1,201.58,227.48
75.5733,4.0661,-0.10437,40.533,226.54,-0.011477,4.8252,226.51,224.92,204.5,230.43
76.5332,4.0697,-0.10593,40.569,229.42,-0.011615,4.8313,229.43,227.59,207.28,233.31
77.5332,4.0801,-0.10794,40.671,232.42,-0.011862,4.8431,232.36,230.44,210.11,236.25
78.5332,4.078,-0.11145,40.835,235.42,-0.012242,4.8385,235.38,233.24,212.97,239.22
79.5332,4.0674,-0.11357,40.579,238.42,-0.012478,4.825,238.44,236.14,215.83,242.28
80.5332,4.0678,-0.11538,40.829,241.42,-0.012679,4.827,241.41,238.83,218.71,245.28
81.5332,4.0734,-0.11603,40.94,244.42,-0.012763,4.8355,244.36,241.46,221.51,248.21
82.5332,4.0777,-0.12229,41.003,247.42,-0.013416,4.8407,247.42,244.43,224.35,251.19
83.5332,4.0772,-0.12329,40.723,250.42,-0.013542,4.8397,250.46,247.21,227.21,254.26
84.5332,4.0796,-0.12534,40.995,253.42,-0.013766,4.8399,253.41,249.94,230.09,257.27
85.5332,4.0753,-0.12612,40.705,256.42,-0.013827,4.8358,256.47,252.68,233.08,260.26
86.5332,4.0723,-0.13308,41.194,259.42,-0.014572,4.8326,259.41,255.4,235.99,263.17
87.5332,4.0723,-0.13333,41.198,262.42,-0.014629,4.8331,262.4,258.14,238.9,266.18
88.5332,4.0783,-0.13547,41.239,265.42,-0.014868,4.841,265.38,260.88,241.75,269.15
89.5332,4.0845,-0.13656,41.229,268.42,-0.015003,4.847,268.39,263.55,244.54,272.17
90.5332,4.0874,-0.14419,41.211,271.42,-0.015856,4.8488,271.45,266.25,247.39,275.06
91.5332,4.0715,-0.14409,41.56,274.42,-0.015833,4.8304,274.34,268.92,250.23,278.02
92.5332,4.0721,-0.14613,41.479,277.42,-0.016067,4.8325,277.4,271.72,253.2,281.12
93.5332,4.0764,-0.1479,41.604,280.42,-0.016264,4.839,280.39,274.38,256.16,284.08
94.5332,4.0872,-0.15023,41.76,283.42,-0.016544,4.8517,283.36,277.17,259.04,287.13
95.5332,4.0838,-0.15462,41.551,286.42,-0.016989,4.8453,286.44,279.87,261.95,290.17
96.5332,4.071,-0.1573,41.683,289.42,-0.01728,4.8297,289.4,282.52,264.86,293.04
97.5332,4.0743,-0.1597,41.575,292.42,-0.017533,4.8348,292.44,285.31,267.62,296.04
98.5332,4.0762,-0.1611,41.803,295.42,-0.017678,4.8381,295.4,288.03,270.89,299.03
99.5332,4.0845,-0.16824,41.485,298.42,-0.018474,4.848,298.5,290.67,274.01,301.99
100.5332,4.0843,-0.169,41.644,301.42,-0.01853,4.8469,301.42,293.42,277.05,304.96
101.4102,4.0763,-0.17085,41.689,304.05,-0.018718,4.8385,304.13,295.83,279.69,307.55
102.4102,4.077,-0.17317,41.072,307.05,-0.018977,4.8391,307.28,298.36,283.41,310.38
103.4102,4.0876,-0.174,40.987,310.05,-0.019078,4.8505,310.25,300.56,287.46,312.9
104.4102,4.0829,-0.18012,41.203,313.05,-0.019784,4.8447,313.1,302.89,291.51,315.31
105.4102,4.0744,-0.18136,40.767,316.05,-0.01989,4.8336,316.26,305.14,295.15,317.79
106.4102,4.0721,-0.18386,40.112,319.05,-0.020144,4.832,319.37,307.32,299.0,320.01
107.4102,4.0825,-0.18665,41.461,322.05,-0.020426,4.8456,321.86,309.22,302.01,321.97
108.4102,4.0919,-0.18813,42.879,325.05,-0.020596,4.8564,324.46,312.01,305.75,324.49
109.4102,4.094,-0.19547,41.817,328.05,-0.021435,4.8573,328.0,315.33,310.53,327.9
110.4102,4.0795,-0.19606,41.477,331.05,-0.021493,4.8404,331.13,317.94,314.57,330.89
111.4102,4.076,-0.19864,41.962,334.05,-0.021782,4.8362,333.94,320.46,318.66,333.57
112.4102,4.0736,-0.20101,41.852,337.05,-0.022031,4.8353,337.02,323.31,323.25,336.43
113.4102,4.0903,-0.20215,42.464,340.05,-0.022153,4.8555,339.87,325.91,328.3,339.31
114.4102,4.0858,-0.21146,42.242,343.05,-0.023194,4.8494,343.01,328.92,333.01,342.37
115.4102,4.0867,-0.21116,42.122,346.05,-0.023138,4.8488,346.07,331.58,336.86,345.34
116.4102,4.081,-0.21403,42.599,349.05,-0.023435,4.8417,348.92,334.31,340.3,348.14
117.4102,4.0754,-0.21478,37.265,350.0,-0.023501,4.8365,351.66,337.0,343.43,351.26
118.4102,4.0764,-0.21388,36.212,350.0,-0.023401,4.8396,351.33,336.99,345.37,351.93
119.4102,4.0862,-0.22031,37.085,350.0,-0.024092,4.8501,350.76,336.96,345.81,351.29
120.4102,4.0873,-0.21894,36.444,350.0,-0.023933,4.8499,350.64,337.42,345.81,350.9
121.4102,4.0878,-0.22028,37.174,350.0,-0.024058,4.8498,350.28,337.89,345.82,350.64
122.4102,4.0836,-0.22138,36.414,350.0,-0.024175,4.8459,350.36,338.21,345.73,350.54
123.4102,4.0826,-0.22158,37.017,350.0,-0.024202,4.8458,350.14,338.54,345.72,350.29
124.4102,4.0862,-0.22679,36.721,350.0,-0.024818,4.8499,350.17,338.78,345.69,350.18
125.4102,4.0908,-0.22611,36.499,350.0,-0.024738,4.8555,350.11,339.0,345.62,349.94
126.4102,4.0855,-0.22714,36.412,350.0,-0.02485,4.8477,350.09,339.21,345.52,349.73
127.4102,4.087,-0.22823,36.328,350.0,-0.024953,4.849,350.09,339.52,345.42,349.59
128.4102,4.0844,-0.22923,36.28,350.0,-0.025051,4.8464,350.12,339.74,345.37,349.55
129.4102,4.0863,-0.22951,36.256,350.0,-0.025071,4.8501,350.07,340.03,345.31,349.39
130.4102,4.0938,-0.23262,35.946,350.0,-0.025452,4.86,350.09,340.25,345.27,349.29
131.4102,4.0914,-0.23479,35.823,350.0,-0.025648,4.856,350.12,340.44,345.26,349.33
132.4102,4.0929,-0.2351,35.533,350.0,-0.025732,4.8573,350.11,340.66,345.28,349.25
133.3334,4.0806,-0.2365,35.497,350.0,-0.02581,4.8435,350.07,340.73,345.24,349.06
134.3334,4.0862,-0.23744,35.63,350.0,-0.025919,4.8503,350.08,341.06,345.2,349.01
135.1752,4.0853,-0.23812,35.497,350.0,-0.026014,4.8504,350.06,341.32,345.2,349.0
136.1752,4.1026,-0.23906,37.619,350.0,-0.026126,4.8695,350.14,341.46,345.23,349.02
137.1752,4.1014,-0.23989,36.771,350.0,-0.026238,4.8659,351.01,342.39,345.49,349.42
138.1752,4.0988,-0.2456,37.806,350.0,-0.026902,4.8633,351.95,343.46,346.09,350.16
139.1752,4.0813,-0.2452,36.346,350.0,-0.02682,4.8425,352.9,344.63,346.95,351.22
140.1752,4.0935,-0.24787,39.439,350.0,-0.027101,4.8584,353.76,345.41,347.73,351.94
141.1752,4.0974,-0.24988,40.242,350.0,-0.027307,4.8633,355.91,347.6,348.97,353.66
142.1752,4.0969,-0.25042,35.287,350.0,-0.027354,4.8623,357.65,349.35,350.79,355.72
143.1752,4.0945,-0.25082,35.734,350.0,-0.027395,4.8577,357.66,348.67,351.85,356.15
144.1752,4.0892,-0.25187,35.704,350.0,-0.02748,4.8522,357.56,348.05,352.12,356.06
145.1752,4.0937,-0.25298,37.139,350.0,-0.027604,4.8582,357.67,348.11,352.33,356.35
146.1752,4.1,-0.25941,38.589,350.0,-0.028325,4.8672,358.69,348.01,352.98,357.3
147.1752,4.0987,-0.25975,36.995,350.0,-0.028322,4.865,359.8,349.07,354.26,358.89
148.1752,4.0864,-0.2595,33.604,350.0,-0.028336,4.8489,359.83,349.46,355.37,360.11
149.1752,4.0847,-0.26017,32.908,350.0,-0.028409,4.8463,358.39,348.56,355.84,359.88
150.1752,4.0877,-0.26082,33.559,350.0,-0.028468,4.8501,356.97,347.27,355.33,358.94
151.1752,4.0873,-0.26206,34.975,350.0,-0.028595,4.8512,356.52,347.15,354.62,358.03
152.1752,4.0917,-0.26101,31.414,350.0,-0.028474,4.8579,355.86,346.77,354.13,357.61
153.1752,4.1018,-0.26437,33.938,350.0,-0.028896,4.868,354.9,345.91,353.32,356.55
154.1752,4.1061,-0.26516,34.64,350.0,-0.02896,4.8714,354.85,346.09,352.59,356.03
155.1752,4.0863,-0.26547,33.088,350.0,-0.029008,4.8487,354.33,345.66,352.31,355.74
156.1752,4.0868,-0.26664,34.491,350.0,-0.029137,4.8499,353.99,345.41,351.76,355.08
157.1752,4.0977,-0.26722,33.996,350.0,-0.029188,4.864,354.15,345.71,351.48,354.94
158.1752,4.1051,-0.26716,33.847,350.0,-0.029177,4.8733,354.19,345.83,351.4,354.95
159.1752,4.1043,-0.2718,32.897,350.0,-0.029637,4.8705,354.22,345.97,351.45,355.0
160.1752,4.0843,-0.27019,32.692,350.0,-0.029486,4.846,353.07,344.82,351.1,354.38
161.1752,4.0985,-0.27142,33.766,350.0,-0.029583,4.8643,352.84,344.65,350.48,353.61
161.9502,4.0917,0.042809,0.0,179.54,0.0044996,4.8574,352.86,344.96,350.29,353.44
161.95185,4.0166,0.045781,0.0,0.00019375,0.0055993,4.7907,352.9,344.99,350.35,353.45
161.9535,4.1739,0.0436,0.0,2.3867e-11,0.0040564,4.955,352.94,345.03,350.4,353.47
161.95515,4.1176,0.044328,0.0,2.7796e-18,0.0052634,4.8842,352.98,345.06,350.46,353.48
161.9568,4.0897,0.048133,0.0,3.1210000000000003e-25,0.0046678,4.8431,353.01,345.08,350.47,353.49
161.95845,4.0518,0.048563,0.0,5.7054e-32,0.0060792,4.8023,353.01,345.07,350.42,353.48
161.9601,4.0672,0.04397,0.0,1.6641e-38,0.0056381,4.8405,353.01,345.07,350.37,353.47
161.96175,4.1017,0.046216,0.0,2.8026e-45,0.0039395,4.8689,353.01,345.06,350.32,353.46
161.9634,4.1207,0.043555,0.0,0.0,0.0050233,4.8973,353.01,345.06,350.27,353.45
161.96505,4.1061,0.043822,0.0,0.0,0.0050623,4.8649,353.01,345.05,350.22,353.44
161.9667,4.0759,0.045803,0.0,0.0,0.0056798,4.8365,353.0,345.05,350.19,353.43
161.96835,4.0551,0.043844,0.0,0.0,0.0048367,4.8167,352.98,345.06,350.19,353.45
161.97,4.0691,0.048712,0.0,0.0,0.0042437,4.8303,352.96,345.07,350.2,353.46
161.97165,4.0858,0.047288,0.0,0.0,0.0052919,4.8581,352.94,345.08,350.2,353.48
161.9733,4.1136,0.042709,0.0,0.0,0.0050997,4.8822,352.92,345.09,350.21,353.49
161.97495,4.1006,0.043837,0.0,0.0,0.0049049,4.8557,352.9,345.1,350.21,353.51
161.9766,4.078,0.045154,0.0,0.0,0.0043489,4.8332,352.88,345.11,350.21,353.52
161.97825,4.0459,0.040905,0.0,0.0,0.0055512,4.7971,352.88,345.11,350.21,353.51
161.9799,4.0616,0.046459,0.0,0.0,0.0056468,4.8455,352.87,345.11,350.2,353.5
161.98155,4.0937,0.047998,0.0,0.0,0.0046373,4.872,352.87,345.11,350.2,353.49
161.9832,4.1188,0.043256,0.0,0.0,0.0047864,4.8843,352.86,345.11,350.19,353.48
161.98485,4.0987,0.046697,0.0,0.0,0.0042146,4.8562,352.86,345.11,350.19,353.47
161.9865,4.0735,0.044673,0.0,0.0,0.006045,4.829,352.85,345.11,350.18,353.46
161.98815,4.0485,0.041866,0.0,0.0,0.0055338,4.8156,352.85,345.1,350.16,353.47
161.9898,4.0637,0.046109,0.0,0.0,0.0045022,4.8273,352.85,345.1,350.14,353.48
161.99145,4.0794,0.043932,0.0,0.0,0.0048884,4.8513,352.85,345.09,350.12,353.49
161.9931,4.1231,0.045978,0.0,0.0,0.0043922,4.8907,352.85,345.09,350.1,353.5
161.99475,4.099,0.04846,0.0,0.0,0.0059569,4.8658,352.85,345.08,350.08,353.51
161.9964,4.0704,0.041011,0.0,0.0,0.0049125,4.8169,352.86,345.09,350.07,353.52
161.99805,4.056,0.045292,0.0,0.0,0.0045129,4.8121,352.87,345.13,350.09,353.53
161.9997,4.0598,0.045387,0.0,0.0,0.0049835,4.8244,352.88,345.18,350.11,353.53
162.00135,4.0988,0.038984,0.0,0.0,0.0048759,4.8662,352.89,345.22,350.13,353.54
162.003,4.1156,0.048956,0.0,0.0,0.0055441,4.883,352.9,345.27,350.15,353.54
162.00465,4.1169,0.048421,0.0,0.0,0.0044967,4.8825,352.91,345.31,350.17,353.55
162.0063,4.1034,0.042742,0.0,0.0,0.0050361,4.8683,353.03,345.47,350.19,353.55
162.00795,4.0876,0.046416,0.0,0.0,0.0053988,4.8431,354.33,346.86,350.2,353.51
162.0096,4.0412,0.043256,0.0,0.0,0.0049664,4.7927,355.64,348.25,350.21,353.47
162.01125,4.0557,0.0412,0.0,0.0,0.0048241,4.8152,356.95,349.64,350.22,353.43
162.0129,7.338,0.079028,0.0,0.0,0.0070212,8.2717,358.25,351.03,350.23,353.39
162.01455,35.517,0.231,0.0,0.0,0.026489,41.315,359.56,352.41,350.24,353.35
162.0162,60.731,0.27138,0.0,0.0,0.030472,70.949,360.88,353.82,350.24,353.31
162.01785,78.68,0.39869,0.0,0.0,0.043789,92.937,363.33,356.24,350.14,353.27
162.0195,87.0,0.56142,0.0,0.0,0.063041,102.96,365.77,358.66,350.04,353.24
162.02115,93.647,0.77685,0.0,0.0,0.08763,110.85,368.22,361.07,349.94,353.2
162.0228,99.529,1.0929,0.0,0.0,0.1276,117.94,370.67,363.49,349.84,353.17
162.02445,102.54,1.4545,0.0,0.0,0.17343,121.59,373.11,365.91,349.74,353.13
162.0261,104.88,1.8465,0.0,0.0,0.22312,124.36,375.56,368.33,349.64,353.1
162.02775,106.11,2.2423,0.0,0.0,0.27763,125.86,377.28,370.15,349.59,353.1
162.0294,107.22,2.6105,0.0,0.0,0.33212,127.18,378.96,371.92,349.53,353.1
162.03105,107.97,2.963,0.0,0.0,0.38594,128.11,380.64,373.69,349.48,353.1
162.0327,108.51,3.2706,0.0,0.0,0.43301,128.75,382.31,375.46,349.42,353.1
162.03435,109.1,3.5678,0.0,0.0,0.48434,129.44,383.99,377.24,349.37,353.1
162.036,109.63,3.8565,0.0,0.0,0.53413,130.07,385.67,379.01,349.31,353.1
162.03765,110.18,4.1455,0.0,0.0,0.5884,130.68,387.0,380.25,349.2,353.1
162.0393,110.69,4.4338,0.0,0.0,0.64127,131.33,388.29,381.41,349.09,353.11
162.04095,111.24,4.7177,0.0,0.0,0.6956,132.0,389.58,382.57,348.97,353.12
162.0426,111.74,4.9954,0.0,0.0,0.75843,132.58,390.86,383.73,348.86,353.13
162.04425,112.18,5.2777,0.0,0.0,0.82221,133.1,392.15,384.88,348.74,353.14
162.0459,112.57,5.5541,0.0,0.0,0.88824,133.56,393.44,386.04,348.63,353.15
162.04755,113.02,5.8248,0.0,0.0,0.95567,134.08,394.83,387.09,348.6,353.14
162.0492,113.49,6.1102,0.0,0.0,1.027,134.67,396.26,388.12,348.59,353.12
162.05085,114.17,6.3773,0.0,0.0,1.1082,135.47,397.68,389.14,348.58,353.1
162.0525,114.91,6.6363,0.0,0.0,1.1893,136.34,399.1,390.16,348.57,353.08
162.05415,115.67,6.897,0.0,0.0,1.2728,137.22,400.53,391.19,348.56,353.06
162.0558,116.61,7.1472,0.0,0.0,1.3604,138.32,401.95,392.21,348.55,353.04
162.05745,117.66,7.3854,0.0,0.0,1.4564,139.56,402.34,392.61,348.55,353.07
162.0591,118.95,7.6274,0.0,0.0,1.5619,141.11,402.32,392.76,348.55,353.12
162.06075,120.38,7.8533,0.0,0.0,1.6623,142.8,402.31,392.91,348.56,353.17
162.0624,121.9,8.0576,0.0,0.0,1.7639,144.58,402.29,393.07,348.56,353.22
162.06405,123.71,8.2507,0.0,0.0,1.8698,146.73,402.28,393.22,348.57,353.27
162.0657,113.36,8.3507,0.0,0.0,1.9427,134.91,402.26,393.38,348.57,353.32
162.06735,107.11,8.3689,0.0,0.0,1.9541,127.37,401.48,392.84,348.61,353.36
162.069,103.47,8.3823,0.0,0.0,1.9521,123.01,400.27,391.92,348.67,353.4
162.07065,100.74,8.3821,0.0,0.0,1.9609,119.6,399.07,391.01,348.72,353.44
162.0723,98.301,8.4,0.0,0.0,1.9703,116.74,397.86,390.1,348.78,353.48
162.07395,96.4,8.4054,0.0,0.0,1.979,114.47,396.65,389.18,348.83,353.52
162.0756,94.705,8.4034,0.0,0.0,1.9742,112.45,395.45,388.27,348.89,353.56
162.07725,93.12,8.4141,0.0,0.0,1.9701,110.56,394.37,387.32,349.0,353.55
162.0789,91.667,8.4142,0.0,0.0,1.9784,108.84,393.38,386.35,349.16,353.5
162.08055,90.234,8.4088,0.0,0.0,1.9822,107.13,392.39,385.38,349.32,353.45
162.0822,88.9,8.4168,0.0,0.0,1.9847,105.52,391.4,384.42,349.48,353.4
162.08385,87.66,8.4211,0.0,0.0,1.9801,104.07,390.42,383.45,349.64,353.35
162.0855,86.564,8.4215,0.0,0.0,1.9812,102.77,389.43,382.48,349.8,353.3
162.08715,85.649,8.4271,0.0,0.0,1.9898,101.68,388.55,381.59,349.91,353.28
162.0888,84.863,8.4256,0.0,0.0,1.9857,100.75,387.79,380.79,349.98,353.28
162.09045,84.145,8.4253,0.0,0.0,1.9828,99.878,387.03,379.99,350.04,353.28
162.0921,83.416,8.4256,0.0,0.0,1.9795,99.028,386.27,379.19,350.11,353.28
162.09375,82.697,8.4216,0.0,0.0,1.9957,98.168,385.51,378.39,350.17,353.28
162.0954,81.951,8.4268,0.0,0.0,1.9929,97.292,384.75,377.59,350.24,353.28
162.09705,80.978,8.4321,0.0,0.0,1.9841,96.153,384.19,376.96,350.14,353.29
162.0987,79.365,8.4262,0.0,0.0,1.9829,94.277,383.87,376.58,349.84,353.32
162.10035,77.302,8.4269,0.0,0.0,1.9812,91.838,383.56,376.19,349.53,353.35
162.102,74.8,8.4261,0.0,0.0,1.9934,88.875,383.25,375.8,349.23,353.38
162.10365,71.593,8.4124,0.0,0.0,1.988,85.085,382.94,375.41,348.92,353.41
162.1053,61.488,8.4013,0.0,0.0,1.9669,74.135,382.62,375.02,348.62,353.44
162.10695,22.699,8.3085,0.0,0.0,1.9124,28.036,382.44,374.76,348.28,353.46
162.1086,-0.48809,8.1982,0.0,0.0,1.8501,-0.4271,382.48,374.72,347.87,353.47
162.11025,5.9498,8.2658,0.0,0.0,1.8885,6.8329,382.53,374.68,347.47,353.48
162.1119,2.6676,8.233,0.0,0.0,1.8653,3.3036,382.57,374.64,347.06,353.49
162.11355,3.9171,8.2409,0.0,0.0,1.8691,4.6642,382.62,374.6,346.66,353.5
162.1152,3.0076,8.2455,0.0,0.0,1.8774,3.4521,382.66,374.56,346.25,353.51
162.11685,3.1865,8.2516,0.0,0.0,1.8838,3.7417,382.72,374.55,345.94,353.51
162.1185,2.9438,8.2525,0.0,0.0,1.8806,3.4892,382.83,374.6,345.85,353.49
162.12015,3.3239,8.2552,0.0,0.0,1.874,3.9833,382.94,374.65,345.76,353.47
162.1218,3.5194,8.2515,0.0,0.0,1.8815,4.1696,383.05,374.7,345.67,353.45
162.12345,3.4356,8.2553,0.0,0.0,1.8843,4.0869,383.16,374.75,345.58,353.43
162.1251,3.3652,8.2551,0.0,0.0,1.879,4.0081,383.27,374.8,345.49,353.41
162.12675,3.3725,8.2435,0.0,0.0,1.8747,4.0171,383.38,374.84,345.45,353.4
162.1284,3.4462,8.2497,0.0,0.0,1.8711,4.0947,383.47,374.86,345.62,353.41
162.13005,3.4457,8.2473,0.0,0.0,1.8833,4.1071,383.56,374.88,345.79,353.42
162.1317,3.4968,8.2451,0.0,0.0,1.8808,4.1402,383.66,374.9,345.96,353.43
162.13335,3.4274,8.2501,0.0,0.0,1.8743,4.0445,383.75,374.92,346.13,353.44
162.135,3.3535,8.2493,0.0,0.0,1.8721,3.9664,383.85,374.94,346.3,353.45
162.13665,3.3116,8.2459,0.0,0.0,1.8733,3.9332,383.94,374.95,346.48,353.46
162.1383,3.4103,8.2443,0.0,0.0,1.8811,4.0594,384.01,374.93,346.69,353.48
162.13995,3.4972,8.2423,0.0,0.0,1.8764,4.1585,384.08,374.9,346.9,353.5
162.1416,3.4753,8.2467,0.0,0.0,1.8737,4.1238,384.15,374.88,347.11,353.52
162.14325,3.4457,8.2498,0.0,0.0,1.8765,4.081,384.22,374.85,347.32,353.54
162.1449,3.4282,8.244,0.0,0.0,1.8789,4.0624,384.29,374.83,347.53,353.56
162.14655,3.3916,8.2508,0.0,0.0,1.8773,4.0177,384.36,374.8,347.71,353.58
162.1482,3.4184,8.2504,0.0,0.0,1.8674,4.0669,384.42,374.76,347.52,353.55
162.14985,3.4878,8.2392,0.0,0.0,1.8754,4.1351,384.48,374.72,347.33,353.52
162.1515,3.4728,8.2449,0.0,0.0,1.8793,4.1062,384.55,374.68,347.14,353.49
162.15315,3.4124,8.2462,0.0,0.0,1.8804,4.0277,384.61,374.64,346.95,353.46
162.1548,3.3664,8.2451,0.0,0.0,1.8747,3.9938,384.68,374.6,346.76,353.43
162.15645,3.4003,8.2489,0.0,0.0,1.8668,4.0461,384.74,374.56,346.57,353.4
162.1581,3.4451,8.2496,0.0,0.0,1.878,4.1067,384.77,374.51,346.64,353.4
162.15975,3.4929,8.2463,0.0,0.0,1.881,4.1459,384.8,374.45,346.72,353.4
162.1614,3.484,8.2436,0.0,0.0,1.8768,4.1221,384.83,374.4,346.79,353.4
162.16305,3.4864,8.2415,0.0,0.0,1.8718,4.1212,384.86,374.34,346.87,353.4
162.1647,3.4306,8.246,0.0,0.0,1.8711,4.0598,384.89,374.29,346.94,353.4
162.16635,3.4006,8.248,0.0,0.0,1.8806,4.042,384.92,374.23,347.02,353.4
162.168,3.4464,8.2466,0.0,0.0,1.8789,4.0988,384.92,374.17,347.33,353.42
162.16965,3.5099,8.2494,0.0,0.0,1.8741,4.1591,384.92,374.12,347.66,353.44
162.1713,3.5002,8.2476,0.0,0.0,1.8708,4.1402,384.92,374.06,347.99,353.46
162.17295,3.4337,8.2404,0.0,0.0,1.8765,4.0656,384.92,374.0,348.32,353.48
162.1746,3.4146,8.2437,0.0,0.0,1.8796,4.0496,384.92,373.94,348.65,353.5
162.17625,3.3812,8.2471,0.0,0.0,1.8726,4.011,384.92,373.88,348.98,353.52
162.1779,3.4106,8.2432,0.0,0.0,1.8728,4.0557,384.93,373.8,349.16,353.51
162.17955,3.4889,8.2488,0.0,0.0,1.8743,4.1416,384.94,373.71,349.32,353.5
162.1812,3.5042,8.2521,0.0,0.0,1.8831,4.1516,384.95,373.63,349.47,353.49
162.18285,3.4472,8.2463,0.0,0.0,1.8795,4.065,384.96,373.54,349.63,353.48
162.1845,3.3905,8.2449,0.0,0.0,1.8675,4.0151,384.97,373.46,349.78,353.47
162.18615,3.431,8.243,0.0,0.0,1.8751,4.0761,384.98,373.37,349.94,353.46
162.1878,3.4922,8.2463,0.0,0.0,1.8778,4.144,385.01,373.29,349.94,353.45
162.18945,3.5538,8.2481,0.0,0.0,1.8811,4.2204,385.04,373.21,349.9,353.44
162.1911,3.5801,8.2457,0.0,0.0,1.8752,4.2333,385.07,373.13,349.86,353.43
162.19275,3.5167,8.2532,0.0,0.0,1.8708,4.1705,385.1,373.05,349.82,353.42
162.1944,3.4831,8.2499,0.0,0.0,1.8774,4.1439,385.13,372.97,349.78,353.41
162.19605,3.5833,8.2429,0.0,0.0,1.8782,4.2715,385.16,372.89,349.74,353.4
162.1977,3.5773,8.2478,0.0,0.0,1.8782,4.2707,385.18,372.82,349.67,353.41
162.19935,3.6458,8.2474,0.0,0.0,1.872,4.3208,385.21,372.74,349.58,353.42
162.201,3.6809,8.2455,0.0,0.0,1.8799,4.3373,385.23,372.67,349.5,353.43
162.20265,3.5997,8.2495,0.0,0.0,1.8815,4.2591,385.26,372.59,349.41,353.44
162.2043,3.5734,8.2544,0.0,0.0,1.875,4.2255,385.28,372.52,349.33,353.45
162.20595,3.573,8.2472,0.0,0.0,1.8733,4.2493,385.31,372.44,349.24,353.46
162.2076,3.6362,8.2492,0.0,0.0,1.8728,4.3386,385.31,372.37,349.23,353.47
162.20925,3.7597,8.2465,0.0,0.0,1.8853,4.4716,385.3,372.29,349.26,353.48
162.2109,3.7603,8.2469,0.0,0.0,1.882,4.4396,385.29,372.21,349.29,353.5
162.21255,3.6104,8.2483,0.0,0.0,1.8708,4.2564,385.28,372.13,349.32,353.51
162.2142,3.5215,8.2467,0.0,0.0,1.8735,4.1601,385.27,372.05,349.35,353.53
162.21585,3.5087,8.2502,0.0,0.0,1.8738,4.1828,385.26,371.97,349.38,353.54
162.2175,3.6584,8.2521,0.0,0.0,1.8846,4.3739,385.25,371.9,349.26,353.55
162.21915,3.7729,8.2419,0.0,0.0,1.8781,4.4893,385.23,371.83,349.03,353.55
162.2208,3.7336,8.2464,0.0,0.0,1.871,4.4148,385.22,371.77,348.79,353.55
162.22245,3.6,8.2454,0.0,0.0,1.875,4.2604,385.2,371.7,348.56,353.55
162.2241,3.5061,8.2419,0.0,0.0,1.8763,4.1553,385.19,371.64,348.32,353.55
162.22575,3.5214,8.2514,0.0,0.0,1.8804,4.2136,385.17,371.57,348.09,353.55
162.2274,3.6706,8.2562,0.0,0.0,1.8752,4.3792,385.16,371.52,347.8,353.55
162.22905,3.7679,8.2441,0.0,0.0,1.8731,4.468,385.14,371.47,347.45,353.54
162.2307,3.7502,8.247,0.0,0.0,1.8792,4.4304,385.13,371.42,347.1,353.54
162.23235,3.6079,8.2455,0.0,0.0,1.8772,4.2496,385.11,371.37,346.75,353.53
162.234,3.5146,8.2417,0.0,0.0,1.8735,4.1634,385.1,371.32,346.4,353.53
162.23565,3.5234,8.2501,0.0,0.0,1.8714,4.2036,385.08,371.27,346.05,353.52
162.2373,3.6577,8.2464,0.0,0.0,1.8808,4.3596,385.07,371.2,345.78,353.52
162.23895,3.7847,8.2515,0.0,0.0,1.8826,4.4828,385.06,371.12,345.63,353.52
162.2406,3.7307,8.2495,0.0,0.0,1.8745,4.409,385.05,371.04,345.48,353.52
162.24225,3.6241,8.2418,0.0,0.0,1.8709,4.2713,385.04,370.97,345.33,353.52
162.2439,3.5203,8.2442,0.0,0.0,1.8698,4.1695,385.03,370.89,345.18,353.52
162.24555,3.546,8.2473,0.0,0.0,1.8828,4.2205,385.02,370.81,345.03,353.52
162.2472,3.6588,8.2408,0.0,0.0,1.8794,4.3657,385.01,370.72,344.95,353.52
162.24885,3.7576,8.2526,0.0,0.0,1.8742,4.4725,385.0,370.63,345.02,353.52
162.2505,3.7487,8.2475,0.0,0.0,1.8707,4.4276,384.98,370.54,345.08,353.52
162.25215,3.6064,8.241,0.0,0.0,1.874,4.2658,384.97,370.45,345.15,353.52
162.2538,3.5086,8.2487,0.0,0.0,1.8812,4.1658,384.95,370.36,345.21,353.52
162.25545,3.5432,8.244,0.0,0.0,1.8711,4.2308,384.94,370.27,345.28,353.52
162.2571,3.6565,8.2438,0.0,0.0,1.8747,4.3626,384.91,370.19,345.34,353.52
162.25875,3.7502,8.246,0.0,0.0,1.8781,4.45,384.87,370.1,345.39,353.53
162.2604,3.7444,8.2459,0.0,0.0,1.8811,4.4089,384.83,370.01,345.45,353.54
162.26205,3.6161,8.2473,0.0,0.0,1.8725,4.2456,384.79,369.92,345.5,353.55
162.2637,3.5187,8.251,0.0,0.0,1.866,4.1625,384.76,369.83,345.56,353.56
162.26535,3.5429,8.2431,0.0,0.0,1.8775,4.2157,384.72,369.74,345.61,353.57
162.267,3.6498,8.2469,0.0,0.0,1.8811,4.368,384.68,369.65,345.65,353.58
162.26865,3.7604,8.2464,0.0,0.0,1.8792,4.4694,384.65,369.56,345.58,353.59
162.2703,3.7522,8.2407,0.0,0.0,1.8726,4.4287,384.63,369.48,345.52,353.6
162.27195,3.6035,8.2504,0.0,0.0,1.8683,4.2282,384.6,369.39,345.45,353.61
162.2736,3.5109,8.2505,0.0,0.0,1.8792,4.1472,384.58,369.31,345.38,353.62
162.27525,3.5377,8.2468,0.0,0.0,1.8812,4.2204,384.55,369.23,345.32,353.63
162.2769,3.6604,8.25,0.0,0.0,1.8775,4.3727,384.53,369.14,345.27,353.64
162.27855,3.7553,8.2464,0.0,0.0,1.8721,4.4652,384.52,369.05,345.32,353.64
162.2802,3.7344,8.2432,0.0,0.0,1.8739,4.4105,384.51,368.96,345.38,353.64
162.28185,3.6111,8.2471,0.0,0.0,1.8815,4.2615,384.5,368.87,345.43,353.64
162.2835,3.5214,8.2473,0.0,0.0,1.8756,4.1787,384.49,368.78,345.49,353.64
162.28515,3.5463,8.2523,0.0,0.0,1.8755,4.2212,384.48,368.69,345.54,353.64
162.2868,3.6757,8.2513,0.0,0.0,1.8742,4.3867,384.47,368.6,345.6,353.64
162.28845,3.774,8.2452,0.0,0.0,1.8799,4.4833,384.43,368.5,345.76,353.64
162.2901,3.7437,8.2457,0.0,0.0,1.8798,4.4212,384.38,368.4,345.92,353.64
162.29175,3.6226,8.2461,0.0,0.0,1.8695,4.2768,384.34,368.3,346.09,353.64
162.2934,3.5276,8.241,0.0,0.0,1.8742,4.172,384.29,368.2,346.25,353.64
162.29505,3.53,8.2515,0.0,0.0,1.8778,4.227,384.25,368.1,346.41,353.64
162.2967,3.6834,8.2533,0.0,0.0,1.8833,4.4002,384.2,368.0,346.57,353.64
162.29835,3.7717,8.2458,0.0,0.0,1.8772,4.4953,384.14,367.91,346.74,353.64
162.3,3.7361,8.249,0.0,0.0,1.8684,4.4178,384.08,367.83,346.91,353.64
162.30165,3.6428,8.2483,0.0,0.0,1.8771,4.2971,384.02,367.74,347.08,353.64
162.3033,3.546,8.2398,0.0,0.0,1.8774,4.1973,383.96,367.65,347.25,353.64
162.30495,3.5732,8.2493,0.0,0.0,1.8816,4.2732,383.9,367.56,347.42,353.64
162.3066,3.6965,8.2487,0.0,0.0,1.8747,4.412,383.84,367.47,347.59,353.64
162.30825,3.7848,8.2506,0.0,0.0,1.8732,4.4841,383.8,367.39,347.65,353.65
162.3099,3.7582,8.2506,0.0,0.0,1.8797,4.4416,383.76,367.31,347.71,353.66
162.31155,3.6239,8.2449,0.0,0.0,1.8761,4.2792,383.72,367.23,347.76,353.67
162.3132,3.5347,8.2481,0.0,0.0,1.8754,4.1866,383.68,367.15,347.82,353.68
162.31485,3.5717,8.246,0.0,0.0,1.8713,4.2805,383.64,367.07,347.87,353.69
162.3165,3.6982,8.2427,0.0,0.0,1.884,4.4283,383.6,366.99,347.93,353.7
162.31815,3.7858,8.2517,0.0,0.0,1.8833,4.494,383.56,366.9,347.92,353.72
162.3198,3.7459,8.2507,0.0,0.0,1.871,4.4252,383.51,366.81,347.91,353.74
162.32145,3.6285,8.2426,0.0,0.0,1.8709,4.2634,383.46,366.72,347.89,353.76
162.3231,3.5445,8.2498,0.0,0.0,1.8736,4.1946,383.41,366.63,347.88,353.78
162.32475,3.5787,8.2478,0.0,0.0,1.8831,4.2741,383.36,366.54,347.86,353.8
162.3264,3.6857,8.243,0.0,0.0,1.8817,4.4085,383.31,366.45,347.85,353.82
162.32805,3.7845,8.2465,0.0,0.0,1.8696,4.4968,383.27,366.35,347.8,353.82
162.3297,3.7611,8.2447,0.0,0.0,1.8736,4.4325,383.23,366.25,347.74,353.82
162.33135,3.6306,8.2505,0.0,0.0,1.8773,4.2841,383.2,366.15,347.68,353.82
162.333,3.5308,8.248,0.0,0.0,1.8804,4.1894,383.17,366.06,347.62,353.82
162.33465,3.5689,8.2466,0.0,0.0,1.8762,4.2488,383.13,365.96,347.56,353.82
162.3363,3.7094,8.2502,0.0,0.0,1.8745,4.415,383.1,365.86,347.5,353.82
162.33795,3.7843,8.245,0.0,0.0,1.8764,4.4916,383.05,365.76,347.33,353.83
162.3396,3.7508,8.2386,0.0,0.0,1.8769,4.4309,383.01,365.66,347.1,353.84
162.34125,3.6273,8.2497,0.0,0.0,1.8782,4.2826,382.96,365.56,346.88,353.85
162.3429,3.561,8.2518,0.0,0.0,1.8715,4.2281,382.92,365.46,346.65,353.86
162.34455,3.5759,8.2454,0.0,0.0,1.8772,4.2628,382.88,365.36,346.43,353.87
162.3462,3.7102,8.2519,0.0,0.0,1.8826,4.4172,382.83,365.26,346.2,353.88
162.34785,3.7938,8.2507,0.0,0.0,1.8775,4.5044,382.77,365.16,345.98,353.9
162.3495,3.7674,8.2412,0.0,0.0,1.8731,4.4335,382.71,365.06,345.75,353.92
162.35115,3.6408,8.2478,0.0,0.0,1.8702,4.276,382.64,364.96,345.53,353.94
162.3528,3.5428,8.2464,0.0,0.0,1.8824,4.1925,382.58,364.86,345.3,353.96
162.35445,3.5805,8.2518,0.0,0.0,1.884,4.2746,382.52,364.76,345.08,353.98
162.3561,3.7128,8.2515,0.0,0.0,1.8751,4.4396,382.45,364.66,344.85,354.0
162.35775,3.7921,8.2512,0.0,0.0,1.8748,4.5214,382.4,364.57,344.73,354.01
162.3594,3.7522,8.2444,0.0,0.0,1.8719,4.4337,382.35,364.48,344.69,354.01
162.36105,3.6354,8.2458,0.0,0.0,1.8824,4.3002,382.31,364.4,344.66,354.01
162.3627,3.5421,8.2419,0.0,0.0,1.8793,4.2038,382.26,364.31,344.62,354.01
162.36435,3.5833,8.2513,0.0,0.0,1.8746,4.2761,382.22,364.23,344.59,354.01
162.366,3.7189,8.2518,0.0,0.0,1.8767,4.4406,382.17,364.14,344.55,354.01
162.36765,3.7937,8.2478,0.0,0.0,1.8798,4.5024,382.12,364.06,344.55,354.0
162.3693,3.7607,8.2499,0.0,0.0,1.8786,4.4313,382.06,363.98,344.6,353.99
162.37095,3.6447,8.2519,0.0,0.0,1.8699,4.2753,382.0,363.9,344.64,353.98
162.3726,3.5415,8.2394,0.0,0.0,1.8763,4.1901,381.94,363.82,344.69,353.97
162.37425,3.588,8.2482,0.0,0.0,1.8826,4.2998,381.88,363.74,344.73,353.96
162.3759,3.7271,8.252,0.0,0.0,1.8832,4.4575,381.82,363.66,344.78,353.95
162.37755,3.7952,8.2476,0.0,0.0,1.8744,4.5119,381.76,363.59,344.81,353.96
162.3792,3.7622,8.2545,0.0,0.0,1.8695,4.4405,381.7,363.54,344.82,353.99
162.38085,3.635,8.2486,0.0,0.0,1.8789,4.2754,381.64,363.48,344.83,354.02
162.3825,3.5565,8.2486,0.0,0.0,1.8828,4.2243,381.58,363.43,344.84,354.05
162.38415,3.5855,8.2474,0.0,0.0,1.8792,4.286,381.53,363.37,344.85,354.08
162.3858,3.733,8.2446,0.0,0.0,1.8747,4.4686,381.47,363.32,344.86,354.11
162.38745,3.8131,8.2507,0.0,0.0,1.8721,4.5222,381.41,363.25,344.87,354.14
162.3891,3.7605,8.2527,0.0,0.0,1.8823,4.4433,381.37,363.17,344.88,354.18
162.39075,3.6406,8.2483,0.0,0.0,1.8801,4.3076,381.33,363.09,344.89,354.22
162.3924,3.5598,8.2526,0.0,0.0,1.8762,4.2176,381.29,363.01,344.9,354.26
162.39405,3.6048,8.2536,0.0,0.0,1.8753,4.292,381.25,362.93,344.91,354.3
162.3957,3.7295,8.2426,0.0,0.0,1.8786,4.4486,381.21,362.85,344.92,354.34
162.39735,3.8098,8.2495,0.0,0.0,1.8829,4.5232,381.17,362.77,344.94,354.37
162.399,3.7625,8.2501,0.0,0.0,1.875,4.4422,381.13,362.69,344.98,354.36
162.40065,3.6475,8.2486,0.0,0.0,1.8752,4.2985,381.09,362.6,345.03,354.35
162.4023,3.5727,8.2508,0.0,0.0,1.8759,4.2385,381.05,362.52,345.07,354.34
162.40395,3.6072,8.2549,0.0,0.0,1.8848,4.314,381.01,362.43,345.12,354.33
162.4056,3.7361,8.2499,0.0,0.0,1.8806,4.4547,380.97,362.35,345.16,354.32
162.40725,3.8215,8.2466,0.0,0.0,1.8682,4.5343,380.93,362.27,345.22,354.31
162.4089,3.7751,8.2452,0.0,0.0,1.8776,4.4564,380.89,362.2,345.31,354.3
162.41055,3.6491,8.2485,0.0,0.0,1.8789,4.3005,380.84,362.14,345.41,354.29
162.4122,3.5583,8.252,0.0,0.0,1.8835,4.2315,380.8,362.07,345.5,354.28
162.41385,3.617,8.2492,0.0,0.0,1.8771,4.3087,380.75,362.01,345.6,354.27
162.4155,3.741,8.2515,0.0,0.0,1.8703,4.4659,380.71,361.94,345.69,354.26
162.41715,3.8156,8.2543,0.0,0.0,1.8807,4.545,380.66,361.88,345.79,354.25
162.4188,3.788,8.2414,0.0,0.0,1.88,4.4698,380.6,361.8,345.86,354.26
162.42045,3.6456,8.2495,0.0,0.0,1.8797,4.3084,380.54,361.73,345.94,354.27
162.4221,3.5751,8.2484,0.0,0.0,1.8733,4.2449,380.48,361.65,346.01,354.28
162.42375,3.6178,8.2495,0.0,0.0,1.8797,4.3346,380.42,361.58,346.09,354.29
162.4254,3.7448,8.2549,0.0,0.0,1.8844,4.4673,380.36,361.5,346.16,354.3
162.42705,3.8236,8.2543,0.0,0.0,1.8759,4.5234,380.3,361.43,346.23,354.31
162.4287,3.7822,8.2468,0.0,0.0,1.8733,4.4588,380.24,361.35,346.19,354.33
162.43035,3.6596,8.2493,0.0,0.0,1.8739,4.2952,380.17,361.28,346.15,354.35
162.432,3.5672,8.2462,0.0,0.0,1.8858,4.2245,380.11,361.2,346.11,354.37
162.43365,3.6271,8.2508,0.0,0.0,1.8842,4.3338,380.05,361.13,346.07,354.39
162.4353,3.7502,8.256,0.0,0.0,1.874,4.4821,379.98,361.05,346.03,354.41
162.43695,3.8206,8.2473,0.0,0.0,1.8735,4.5297,379.92,360.98,345.99,354.43
162.4386,3.7814,8.2545,0.0,0.0,1.8769,4.4605,379.86,360.88,345.92,354.45
162.44025,3.648,8.2545,0.0,0.0,1.8856,4.2994,379.8,360.78,345.85,354.47
162.4419,3.5656,8.2423,0.0,0.0,1.8797,4.225,379.74,360.68,345.78,354.49
162.44355,3.6307,8.2521,0.0,0.0,1.8733,4.3335,379.68,360.58,345.71,354.51
162.4452,3.7632,8.2506,0.0,0.0,1.8773,4.4794,379.62,360.48,345.64,354.53
162.44685,3.8206,8.2496,0.0,0.0,1.8799,4.5361,379.56,360.38,345.57,354.55
162.4485,3.767,8.254,0.0,0.0,1.8818,4.4523,379.51,360.28,345.51,354.54
162.45015,3.6492,8.2522,0.0,0.0,1.874,4.3059,379.46,360.17,345.45,354.53
162.4518,3.5716,8.2481,0.0,0.0,1.8758,4.2372,379.41,360.07,345.39,354.52
162.45345,3.6256,8.2505,0.0,0.0,1.8821,4.3225,379.36,359.96,345.33,354.51
162.4551,3.7611,8.2471,0.0,0.0,1.8797,4.4855,379.31,359.86,345.27,354.5
162.45675,3.8261,8.2525,0.0,0.0,1.8791,4.5294,379.26,359.75,345.21,354.49
162.4584,3.7739,8.2506,0.0,0.0,1.8709,4.4555,379.21,359.67,345.13,354.48
162.46005,3.6572,8.2513,0.0,0.0,1.8828,4.3154,379.16,359.59,345.04,354.47
162.4617,3.5608,8.2553,0.0,0.0,1.8851,4.233,379.11,359.51,344.95,354.46
162.46335,3.6372,8.2535,0.0,0.0,1.8775,4.3477,379.06,359.43,344.86,354.45
162.465,3.7763,8.2472,0.0,0.0,1.8762,4.5031,379.01,359.35,344.77,354.44
162.46665,3.8314,8.2503,0.0,0.0,1.8732,4.5472,378.96,359.27,344.68,354.43
162.4683,3.7799,8.2516,0.0,0.0,1.8847,4.4647,378.9,359.19,344.61,354.44
162.46995,3.6647,8.2487,0.0,0.0,1.8828,4.3385,378.84,359.12,344.55,354.45
162.4716,3.5694,8.2533,0.0,0.0,1.8746,4.2429,378.78,359.04,344.49,354.46
162.47325,3.6347,8.2578,0.0,0.0,1.8768,4.3399,378.72,358.97,344.43,354.47
162.4749,3.7751,8.2488,0.0,0.0,1.8771,4.5062,378.66,358.89,344.37,354.48
162.47655,3.8324,8.2511,0.0,0.0,1.8833,4.5423,378.6,358.82,344.31,354.49
162.4782,3.7903,8.2473,0.0,0.0,1.8751,4.46,378.54,358.74,344.29,354.51
162.47985,3.657,8.2499,0.0,0.0,1.8772,4.3107,378.48,358.66,344.28,354.54
163.08023,3.5904,8.2536,0.0,0.0,1.8806,4.2622,356.17,337.0,336.95,347.54
164.08023,3.4992,8.2566,0.0,0.0,1.8819,4.1513,329.95,316.85,311.72,337.66
165.08023,3.4225,8.26,0.0,0.0,1.8838,4.0622,315.23,303.96,295.32,327.35
166.08023,3.3699,8.2633,0.0,0.0,1.8856,4.0003,303.77,293.46,286.77,316.8
166.9898,3.3386,8.266,0.0,0.0,1.8874,3.9614,294.69,284.95,278.4,306.8
167.9898,3.3271,8.2693,0.0,0.0,1.8894,3.9488,285.76,276.48,269.03,296.4
168.9898,3.3303,8.2721,0.0,0.0,1.8912,3.9539,277.73,268.82,261.26,287.31
169.9898,3.3298,8.2744,0.0,0.0,1.8925,3.952,270.24,261.54,254.8,277.97
170.9898,3.3359,8.2767,0.0,0.0,1.8938,3.9583,263.19,254.63,247.57,269.34
171.9898,3.3309,8.2792,0.0,0.0,1.8952,3.9519,256.54,248.18,239.91,261.13
172.9898,3.3244,8.2805,0.0,0.0,1.8958,3.9448,250.23,241.99,233.23,253.49
173.9898,3.3283,8.2826,0.0,0.0,1.8971,3.9506,244.19,236.07,226.42,245.87
174.9898,3.3316,8.2839,0.0,0.0,1.8978,3.9545,238.28,230.28,220.16,238.91
175.9898,3.3323,8.285,0.0,0.0,1.8985,3.955,232.57,224.82,214.16,232.31
176.9898,3.3362,8.2865,0.0,0.0,1.8996,3.9585,227.13,219.42,207.85,225.79
177.9898,3.3265,8.288,0.0,0.0,1.9006,3.9467,221.92,214.21,202.24,219.61
178.9898,3.3245,8.2893,0.0,0.0,1.9015,3.9455,216.85,209.35,197.11,213.76
179.9898,3.3298,8.2908,0.0,0.0,1.9025,3.9526,212.14,204.76,192.3,208.2
180.9898,3.3285,8.2925,0.0,0.0,1.9035,3.9505,207.43,200.11,187.35,202.91
181.9898,3.3282,8.2943,0.0,0.0,1.9044,3.9496,202.82,195.77,182.78,197.73
182.9898,3.3213,8.296,0.0,0.0,1.9053,3.9408,198.49,191.53,178.39,192.92
183.9898,3.3213,8.2981,0.0,0.0,1.9066,3.9409,194.32,187.49,174.19,188.25
184.9898,3.3178,8.2993,0.0,0.0,1.9073,3.9371,190.16,183.54,170.1,183.77
185.9898,3.3178,8.3013,0.0,0.0,1.9088,3.9378,186.17,179.7,166.22,179.31
186.9898,3.3239,8.3032,0.0,0.0,1.9098,3.9456,182.48,176.05,162.52,175.37
187.9898,3.3192,8.3048,0.0,0.0,1.9107,3.938,178.76,172.54,158.77,171.21
188.9898,3.3135,8.3068,0.0,0.0,1.9118,3.9319,175.12,169.11,155.27,167.46
189.9898,3.3112,8.3088,0.0,0.0,1.9129,3.9302,171.71,165.81,152.16,163.7
190.9898,3.3104,8.3104,0.0,0.0,1.9139,3.9292,168.37,162.5,148.67,160.06
191.9898,3.3112,8.3122,0.0,0.0,1.9149,3.9301,165.08,159.47,145.58,156.67
192.9898,3.3132,8.3137,0.0,0.0,1.9159,3.9327,161.94,156.27,142.59,153.34
193.9898,3.3117,8.3154,0.0,0.0,1.9171,3.9293,158.93,153.37,139.6,150.22
194.9898,3.3043,8.3176,0.0,0.0,1.9186,3.92,155.99,150.51,136.7,147.02
195.9516,3.2997,8.3189,0.0,0.0,1.9193,3.9161,153.19,147.86,134.08,144.16
196.9516,3.3062,8.3209,0.0,0.0,1.9203,3.9247,150.49,145.27,131.58,141.42
197.9516,3.3087,8.3232,0.0,0.0,1.9217,3.9271,147.65,142.51,128.99,138.45
198.9516,3.3043,8.3247,0.0,0.0,1.9225,3.9203,145.03,140.22,126.49,135.86
199.8429,3.3028,8.3259,0.0,0.0,1.9236,3.9212,142.8,137.97,124.31,133.48
200.8429,3.3033,8.3277,0.0,0.0,1.9248,3.92,140.32,135.56,121.96,130.85
201.8429,3.3016,8.3295,0.0,0.0,1.9259,3.918,137.86,133.24,119.77,128.44
202.8429,3.3102,8.3313,0.0,0.0,1.9267,3.9278,135.43,130.92,117.49,126.07
203.8429,3.2971,8.3328,0.0,0.0,1.9275,3.9128,133.23,128.69,115.47,123.8
204.8429,3.2997,8.3347,0.0,0.0,1.9287,3.9165,130.9,126.51,113.34,121.38
205.8429,3.2997,8.3361,0.0,0.0,1.9296,3.9167,128.81,124.57,111.32,119.3
206.8429,3.3047,8.3374,0.0,0.0,1.9305,3.9209,126.63,122.54,109.41,117.32
207.8429,3.202,8.3415,0.0,0.0,1.9333,3.8005,125.64,121.52,108.91,117.83
208.8429,3.3697,8.3396,0.0,0.0,1.9323,3.9996,126.22,122.54,112.59,119.29
209.4429,3.208,8.3414,0.0,0.0,1.9332,3.8065,126.35,122.83,114.0,119.64