File: examples/dan-msc-case-studies/CS4/data/01 raw data/hyde_test_028.csv
Time(sec),Force(kN),Jaw(mm),PowAngle(deg),PTemp,Strain,Stress(MPa),TC1(C),TC2(C),TC3(C)
0.0,5.2976,0.0029811,0.0,0.0027825,0.00030981,16.094,19.832,20.631,20.658
0.6,5.2863,0.0022454,0.0,1.621,0.00026792,16.026,19.858,20.61,20.674
1.2,5.602,0.0030508,0.0,3.421,0.00028341,16.989,20.027,20.753,20.782
1.8,5.864,0.003547,0.0,5.221,0.00035105,17.777,19.813,20.577,20.634
2.4,6.1032,0.0038227,0.0,7.021,0.00044638,18.511,19.881,20.538,20.658
3.0,6.2506,0.0044247,0.0,8.821,0.00053291,18.953,19.886,20.565,20.666
3.6,6.4405,0.0046441,0.0,10.621,0.00048988,19.531,19.871,20.575,20.637
4.2,6.5808,0.0049708,0.0,12.421,0.00057432,19.953,19.882,20.646,20.622
4.8,6.7161,0.0054722,0.0,14.221,0.00055675,20.368,19.873,20.611,20.658
5.4,6.7771,0.0051567,0.0,16.021,0.00052162,20.551,19.906,20.575,20.61
6.0,6.8336,0.0051935,0.0,17.821,0.00059069,20.722,19.871,20.586,20.659
6.6,6.8335,0.0052728,0.0,19.621,0.0006395,20.722,19.908,20.597,20.631
7.2,6.8664,0.0063132,16.604,21.421,0.00066875,20.819,19.93,20.635,20.686
7.8,6.8695,0.0064848,26.81,23.221,0.00073121,20.833,20.71,21.862,21.809
8.3234,6.891,0.0054201,26.68,24.801,0.00062355,20.903,22.804,24.51,24.363
8.9234,6.8968,0.0054629,24.511,26.591,0.00058588,20.908,25.418,27.609,27.414
9.5234,6.9099,0.0049394,23.842,28.391,0.00056177,20.958,27.508,31.941,29.602
10.1234,6.9117,0.0044169,24.808,30.191,0.00042304,20.954,29.326,37.83,31.46
10.7234,6.9324,0.0026196,25.233,31.991,0.00026041,21.025,31.274,37.83,33.392
11.3234,6.9338,0.002532,25.585,33.791,0.00033514,21.023,33.209,37.83,35.424
11.9234,6.9533,0.0020661,25.668,35.591,0.00025721,21.088,35.135,38.4,37.428
12.5234,6.9524,0.0014057,25.873,37.391,0.00015663,21.081,36.965,40.42,39.409
13.1234,6.972,0.0010695,26.207,39.191,0.0001326,21.144,38.854,42.437,41.422
13.6279,6.9755,0.00030533,26.526,40.705,5.2886e-05,21.15,40.348,44.108,43.024
14.2279,6.9849,-0.0011468,26.206,42.505,-0.00018265,21.184,42.246,46.07,45.018
14.8279,6.9915,-0.0012526,27.127,44.305,-0.00015766,21.198,44.008,47.907,46.772
15.4279,7.0057,-0.0019361,26.613,46.105,-0.00015883,21.244,45.898,49.971,48.809
16.0279,7.0064,-0.0024762,26.525,47.905,-0.00023287,21.244,47.752,51.937,50.707
16.6279,7.0267,-0.0028989,26.197,49.705,-0.00032522,21.309,49.69,53.873,52.664
17.2279,7.0267,-0.0036131,27.84,51.505,-0.00038195,21.306,51.198,55.601,54.277
17.8279,7.0456,-0.0055454,26.954,53.305,-0.00066006,21.366,53.261,57.774,56.557
18.4279,7.0309,-0.0053377,27.765,55.105,-0.0006022,21.321,54.885,59.54,58.164
19.0279,7.0563,-0.006277,27.534,56.905,-0.00063621,21.396,56.768,61.46,60.109
19.6279,7.0477,-0.0070952,27.645,58.705,-0.0007407,21.375,58.593,63.455,62.117
20.2279,7.0754,-0.0074991,27.024,60.505,-0.0008196,21.452,60.544,65.521,64.207
20.8279,7.0676,-0.0090042,28.515,62.305,-0.00096665,21.435,62.104,67.101,65.804
21.4279,7.0797,-0.0096521,27.993,64.105,-0.001105,21.463,63.956,69.068,67.745
22.0279,7.0745,-0.010099,28.191,65.905,-0.0011184,21.458,65.808,71.005,69.692
22.6279,7.0933,-0.011073,28.001,67.705,-0.0011703,21.503,67.654,73.075,71.746
23.2279,7.0926,-0.011609,28.251,69.505,-0.001226,21.513,69.417,74.965,73.569
23.8279,7.1014,-0.012728,28.662,71.305,-0.0014036,21.531,71.23,76.924,75.488
24.4279,7.108,-0.014066,28.662,73.105,-0.0015074,21.557,73.055,78.719,77.406
25.0279,7.1114,-0.014013,28.657,74.905,-0.0015829,21.56,74.828,80.613,79.26
25.6279,7.1215,-0.014746,29.237,76.705,-0.0016319,21.598,76.542,82.392,81.086
26.2279,7.126,-0.015976,29.308,78.505,-0.0016976,21.605,78.373,84.258,83.005
26.8279,7.1313,-0.016831,29.211,80.305,-0.0018071,21.629,80.205,86.195,84.963
27.4279,7.1339,-0.018594,29.321,82.105,-0.002037,21.629,82.019,88.156,86.882
28.0279,7.142,-0.018467,29.4,83.905,-0.002,21.662,83.825,90.07,88.81
28.6279,7.1411,-0.018908,29.584,85.705,-0.0021189,21.652,85.579,91.893,90.699
29.2279,7.1636,-0.019901,29.293,87.505,-0.0021927,21.723,87.483,93.841,92.686
29.8279,7.1513,-0.021349,29.718,89.305,-0.0022773,21.685,89.189,95.684,94.449
30.4279,7.1658,-0.022748,29.795,91.105,-0.0024541,21.729,91.005,97.52,96.363
31.0279,7.1605,-0.022543,29.809,92.905,-0.0024623,21.715,92.847,99.46,98.35
31.6279,7.1825,-0.023419,29.874,94.705,-0.0025496,21.778,94.645,101.37,100.23
32.2279,7.1749,-0.024001,30.101,96.505,-0.0026775,21.759,96.388,103.25,102.14
32.8279,7.1955,-0.025247,30.3,98.305,-0.0027745,21.821,98.21,105.15,104.06
33.42791,7.1871,-0.027457,30.269,100.1,-0.0029343,21.798,100.05,107.12,106.09
34.02791,7.2121,-0.027122,29.97,101.9,-0.0029307,21.867,101.86,109.03,108.04
34.62791,7.2211,-0.027716,30.576,103.7,-0.0030273,21.903,103.63,110.91,109.89
35.22791,7.2372,-0.028345,29.945,105.5,-0.0030794,21.943,105.61,113.02,111.98
35.82791,7.2406,-0.029316,31.313,107.3,-0.0032541,21.961,107.1,114.6,113.51
36.42791,7.2433,-0.032111,30.639,109.1,-0.0035053,21.961,109.09,116.65,115.66
37.02791,7.2484,-0.031825,31.341,110.9,-0.0034145,21.986,110.74,118.4,117.43
37.62791,7.2455,-0.032117,30.276,112.7,-0.0034872,21.967,112.78,120.54,119.66
38.22791,7.2637,-0.033128,30.455,114.5,-0.0036001,22.032,114.54,122.37,121.4
38.82791,7.2757,-0.034117,31.838,116.3,-0.0037301,22.059,116.11,124.01,123.1
39.42791,7.2858,-0.036391,30.974,118.1,-0.0040343,22.096,118.17,126.24,125.38
40.02791,7.2732,-0.03693,29.889,119.9,-0.0040289,22.049,120.16,128.28,127.39
40.62791,7.2926,-0.037269,31.001,121.7,-0.0040059,22.116,121.64,129.73,128.72
41.1543,7.3153,-0.038115,32.632,123.28,-0.0042072,22.184,122.96,131.21,130.34
41.7543,7.3016,-0.039049,30.777,125.08,-0.0042422,22.145,125.25,133.62,132.87
42.3543,7.3286,-0.039961,31.231,126.88,-0.0043041,22.221,126.9,135.28,134.44
42.9543,7.3269,-0.043426,32.386,128.68,-0.004757,22.224,128.49,137.07,136.31
43.5543,7.3374,-0.042945,31.041,130.48,-0.0046439,22.244,130.59,139.26,138.57
44.1543,7.3334,-0.043178,31.634,132.28,-0.00475,22.244,132.29,140.96,140.16
44.6275,7.3438,-0.043903,31.882,133.7,-0.0047845,22.268,133.6,142.29,141.54
45.2275,7.3616,-0.044926,31.882,135.5,-0.0049636,22.328,135.4,144.11,143.56
45.8275,7.3628,-0.045798,31.814,137.3,-0.0050056,22.325,137.19,145.94,145.41
46.4275,7.3805,-0.050208,32.556,139.1,-0.0054079,22.383,138.97,147.77,147.33
47.0275,7.3522,-0.048733,31.092,140.9,-0.0053119,22.294,141.1,149.99,149.59
47.6275,7.3829,-0.049485,32.006,142.7,-0.0053741,22.387,142.58,151.46,150.96
48.2275,7.3829,-0.050979,32.459,144.5,-0.0055801,22.389,144.38,153.43,153.03
48.8275,7.3953,-0.05145,31.81,146.3,-0.0056446,22.425,146.34,155.31,154.99
49.4275,7.3902,-0.052996,32.227,148.1,-0.0058005,22.413,148.05,157.04,156.61
50.0275,7.4129,-0.056374,32.849,149.9,-0.0060473,22.477,149.68,158.91,158.48
50.6275,7.3982,-0.055342,31.994,151.7,-0.0060496,22.438,151.72,161.01,160.67
51.2275,7.4188,-0.056059,31.988,153.5,-0.00608,22.494,153.56,162.84,162.4
51.8275,7.4093,-0.057488,32.844,155.3,-0.0063108,22.474,155.19,164.55,164.11
52.4275,7.4327,-0.058232,31.957,157.1,-0.0063869,22.534,157.16,166.56,166.17
53.0275,7.4268,-0.061727,31.906,158.9,-0.0067116,22.525,158.97,168.38,167.97
53.6275,7.4386,-0.061855,32.931,160.7,-0.0066771,22.549,160.66,170.12,169.81
54.2275,7.4399,-0.062038,33.185,162.5,-0.0067642,22.566,162.36,171.81,171.6
54.8275,7.4501,-0.063147,32.125,164.3,-0.0068518,22.587,164.39,173.93,173.78
55.4275,7.4594,-0.064009,33.685,166.1,-0.0070222,22.626,165.89,175.29,175.23
56.0275,7.4657,-0.065463,32.662,167.9,-0.0071556,22.635,167.97,177.43,177.45
56.6275,7.4631,-0.068601,31.692,169.7,-0.0074143,22.636,170.01,179.48,179.52
57.2275,7.4651,-0.067617,32.382,171.5,-0.0073405,22.634,171.56,181.02,180.87
57.8275,7.4785,-0.068838,32.895,173.3,-0.0074987,22.683,173.3,182.73,182.73
58.4275,7.4715,-0.069427,32.781,175.1,-0.0075561,22.656,175.15,184.67,184.74
59.0275,7.5028,-0.070719,33.251,176.9,-0.0077546,22.752,176.84,186.34,186.5
59.6275,7.4936,-0.074062,32.807,178.7,-0.0080847,22.723,178.79,188.39,188.59
60.2275,7.5055,-0.073665,32.15,180.5,-0.0079492,22.76,180.68,190.21,190.41
60.8275,7.5008,-0.074429,33.179,182.3,-0.0081124,22.746,182.26,191.79,192.04
61.4275,7.5183,-0.075185,32.861,184.1,-0.0081664,22.8,184.13,193.69,193.99
62.0275,7.5156,-0.076237,33.584,185.9,-0.0083251,22.791,185.83,195.38,195.74
62.6275,7.5389,-0.078281,33.688,187.7,-0.0085785,22.856,187.64,197.23,197.6
63.2275,7.5298,-0.0803,34.294,189.5,-0.0087164,22.835,189.33,199.01,199.46
63.8275,7.5451,-0.080196,34.377,191.3,-0.0086756,22.873,191.14,200.82,201.33
64.42751,7.5358,-0.080805,33.501,193.1,-0.0088087,22.857,193.13,202.76,203.37
65.02751,7.5554,-0.081996,33.78,194.9,-0.0089073,22.909,194.86,204.69,205.11
65.62751,7.5548,-0.082735,33.842,196.7,-0.0090606,22.915,196.62,206.4,206.91
66.22751,7.569,-0.085798,34.256,198.5,-0.0093777,22.947,198.41,208.4,208.88
66.82751,7.5705,-0.087444,33.379,200.3,-0.0094421,22.96,200.49,210.54,211.19
67.42751,7.574,-0.08708,33.893,202.1,-0.0094724,22.962,202.16,212.12,212.66
68.02751,7.5741,-0.087889,33.877,203.9,-0.0095551,22.973,203.89,213.84,214.41
68.62751,7.5784,-0.089272,34.435,205.7,-0.009728,22.975,205.6,215.64,216.33
69.22751,7.5892,-0.089689,33.02,207.5,-0.009811,23.019,207.76,217.77,218.57
69.82751,7.5868,-0.091463,34.316,209.3,-0.0099644,23.008,209.24,219.15,219.79
70.42751,7.6007,-0.096383,34.302,211.1,-0.010417,23.053,211.07,221.19,222.04
71.02751,7.5788,-0.094083,33.344,212.9,-0.010245,22.982,213.08,223.23,224.22
71.62751,7.5974,-0.095175,33.71,214.7,-0.01033,23.041,214.81,224.94,225.86
72.22751,7.5794,-0.095895,33.61,216.5,-0.010469,22.984,216.64,226.59,227.61
72.82751,7.6022,-0.097163,34.226,218.3,-0.010594,23.056,218.22,228.23,229.28
73.42751,7.5927,-0.098462,34.43,220.1,-0.010681,23.026,220.03,230.18,231.34
73.8767,7.5902,-0.10206,34.497,221.45,-0.011111,23.015,221.39,231.66,232.96
74.4767,7.5611,-0.10176,33.243,223.25,-0.011112,22.931,223.53,233.6,234.96
75.0767,7.5539,-0.10233,34.346,225.05,-0.011152,22.905,224.94,234.92,236.13
75.5203,7.5607,-0.1033,35.01,226.38,-0.011291,22.924,226.11,236.23,237.5
76.1203,7.544,-0.10419,33.948,228.18,-0.011322,22.879,228.28,238.45,240.1
76.7203,7.543,-0.10496,34.482,229.98,-0.011347,22.872,229.94,239.99,241.56
77.3203,7.5641,-0.10677,34.869,231.78,-0.011641,22.941,231.68,241.68,243.29
77.9203,7.5505,-0.10976,33.854,233.58,-0.011896,22.896,233.71,243.69,245.36
78.5203,7.5653,-0.1087,35.021,235.38,-0.011855,22.942,235.22,245.27,246.74
79.1203,7.5565,-0.10985,35.419,237.18,-0.011977,22.915,236.96,247.02,248.79
79.7203,7.5725,-0.11119,33.556,238.98,-0.012066,22.962,239.29,249.3,251.26
80.3203,7.5668,-0.112,35.205,240.78,-0.012121,22.947,240.66,250.71,252.5
80.9203,7.5968,-0.11299,34.517,242.58,-0.012298,23.034,242.67,252.7,254.68
81.5203,7.5851,-0.11741,34.705,244.38,-0.012728,23.006,244.41,254.45,256.32
82.1203,7.5914,-0.11627,35.316,246.18,-0.01268,23.017,246.08,256.14,258.16
82.7203,7.5866,-0.11687,34.724,247.98,-0.012718,23.009,248.03,258.09,260.16
83.3203,7.5962,-0.11817,34.797,249.78,-0.012785,23.031,249.81,259.9,262.1
83.9203,7.5952,-0.11891,35.15,251.58,-0.012919,23.039,251.57,261.63,263.77
84.5203,7.5975,-0.11985,35.298,253.38,-0.013012,23.034,253.41,263.49,265.7
85.1203,7.603,-0.12323,34.981,255.18,-0.013435,23.06,255.29,265.5,267.79
85.7203,7.6041,-0.1249,35.433,256.98,-0.013589,23.055,256.94,267.09,269.36
86.3203,7.5994,-0.12443,35.265,258.78,-0.013516,23.049,258.79,269.11,271.24
86.9203,7.5958,-0.12541,35.375,260.58,-0.01356,23.029,260.52,270.85,272.99
87.5203,7.6027,-0.12626,35.337,262.38,-0.013739,23.059,262.4,272.64,275.03
88.1203,7.5994,-0.12739,35.017,264.18,-0.013806,23.044,264.3,274.67,277.1
88.7203,7.6187,-0.12782,35.409,265.98,-0.013928,23.107,265.98,276.37,278.56
89.3203,7.6124,-0.13031,35.886,267.78,-0.014211,23.08,267.65,278.07,280.33
89.9203,7.6176,-0.13467,35.671,269.58,-0.014575,23.102,269.49,279.9,282.29
90.5203,7.5873,-0.13301,34.698,271.38,-0.014396,23.007,271.62,282.09,284.53
91.1203,7.6138,-0.13311,35.392,273.18,-0.014458,23.087,273.18,283.65,285.89
91.7203,7.6011,-0.13443,35.884,274.98,-0.014585,23.05,274.88,285.35,287.72
92.3203,7.619,-0.13544,36.101,276.78,-0.014755,23.103,276.65,287.24,289.71
92.9203,7.5984,-0.13617,34.979,278.58,-0.014792,23.042,278.75,289.35,291.82
93.5203,7.6144,-0.13725,35.496,280.38,-0.014856,23.087,280.43,290.93,293.33
94.1203,7.6148,-0.14026,36.628,282.18,-0.015235,23.092,281.88,292.6,294.97
94.7203,7.62,-0.14313,34.899,283.98,-0.015517,23.106,284.22,294.97,297.55
95.32031,7.6034,-0.14142,35.651,285.78,-0.015364,23.059,285.79,296.49,298.84
95.92031,7.6151,-0.14204,35.822,287.58,-0.015463,23.087,287.51,298.23,300.65
96.52031,7.6098,-0.14322,35.49,289.38,-0.015542,23.081,289.43,300.05,302.65
97.12031,7.6222,-0.14425,36.293,291.18,-0.015592,23.108,291.08,301.65,304.24
97.72031,7.6123,-0.14505,35.798,292.98,-0.015756,23.089,292.97,303.5,306.28
98.32031,7.6214,-0.14564,36.189,294.78,-0.01578,23.107,294.66,305.18,307.95
98.92031,7.6243,-0.14708,35.702,296.58,-0.016036,23.127,296.71,307.32,310.01
99.52031,7.6198,-0.15217,35.757,298.38,-0.016546,23.102,298.43,308.8,311.83
100.12031,7.6221,-0.15092,35.531,299.97,-0.016327,23.116,300.1,310.2,313.58
100.72031,7.5691,-0.14833,31.019,300.0,-0.016052,22.949,301.11,311.28,313.81
101.32031,7.554,-0.14813,33.413,300.0,-0.016084,22.91,300.35,309.88,311.27
101.92031,7.5707,-0.14893,34.748,300.0,-0.016157,22.954,299.92,309.28,311.0
102.52031,7.5896,-0.14907,33.578,300.0,-0.016239,23.017,300.32,309.7,311.69
103.12031,7.5665,-0.14866,33.0,300.0,-0.016143,22.943,300.36,309.54,311.36
103.72031,7.5873,-0.14875,33.709,300.0,-0.016081,23.01,300.14,309.14,310.87
104.32031,7.5783,-0.15025,33.521,300.0,-0.016332,22.978,300.13,309.13,311.08
104.92031,7.5937,-0.15262,32.85,300.0,-0.016524,23.027,300.22,309.17,311.06
105.52031,7.5723,-0.15017,32.869,300.0,-0.016322,22.962,300.13,308.91,310.79
106.1056,7.5876,-0.15005,33.403,300.0,-0.016285,23.002,300.05,308.82,310.7
106.7056,7.5815,-0.14992,32.839,300.0,-0.016303,22.996,300.2,308.91,310.85
107.1338,7.5803,-0.14988,32.267,300.0,-0.016247,22.993,300.24,308.93,310.73
107.7338,7.5934,-0.14973,32.966,300.0,-0.016291,23.022,300.08,308.69,310.55
108.3338,7.5953,-0.14991,32.809,300.0,-0.016299,23.037,300.08,308.7,310.48
108.9338,7.591,-0.15298,32.789,300.0,-0.016584,23.013,300.12,308.54,310.41
109.5338,7.5913,-0.15222,32.48,300.0,-0.016471,23.023,300.08,308.56,310.43
110.1338,7.5698,-0.15117,32.758,300.0,-0.016406,22.95,300.04,308.39,310.21
110.7338,7.5915,-0.15108,32.699,300.0,-0.016383,23.026,300.04,308.28,310.16
111.3338,7.5783,-0.15088,32.617,300.0,-0.016426,22.981,300.06,308.21,310.13
111.9338,7.5944,-0.15062,32.356,300.0,-0.016358,23.031,300.05,308.19,310.04
112.5338,7.5804,-0.15329,32.673,300.0,-0.016595,22.984,300.05,308.12,310.04
113.1338,7.5362,-0.15291,32.3,300.0,-0.016591,22.851,300.07,308.06,309.93
113.7338,7.3157,-0.15262,32.437,300.0,-0.016538,22.183,300.01,307.97,309.87
114.3338,7.1739,-0.15294,32.63,300.0,-0.016628,21.754,299.99,307.94,309.82
114.9338,7.0326,-0.1533,32.185,300.0,-0.016662,21.329,300.08,307.89,309.86
115.5338,6.984,-0.15379,32.367,300.0,-0.016669,21.178,300.02,307.88,309.8
116.1338,6.9362,-0.15731,31.905,300.0,-0.017006,21.038,300.05,307.84,309.73
116.7338,6.9271,-0.15479,32.546,300.0,-0.016795,21.0,299.98,307.71,309.57
117.3338,6.9048,-0.15517,32.45,300.0,-0.016831,20.943,300.01,307.72,309.7
117.9338,6.903,-0.15471,32.293,300.0,-0.016842,20.926,300.02,307.69,309.61
118.5338,6.8864,-0.15476,32.623,300.0,-0.016793,20.888,299.96,307.51,309.4
119.1338,6.8835,-0.15843,32.413,300.0,-0.017125,20.869,300.01,307.57,309.54
119.7338,6.8455,-0.15593,32.158,300.0,-0.016929,20.765,300.02,307.6,309.54
120.3338,6.8281,-0.15585,32.438,300.0,-0.016877,20.7,299.97,307.42,309.35
120.9338,6.8034,-0.15584,32.882,300.0,-0.016965,20.634,299.93,307.35,309.39
121.5338,6.7717,-0.15574,32.384,300.0,-0.01692,20.529,300.01,307.48,309.56
122.1338,6.7379,-0.15714,32.405,300.0,-0.017011,20.436,299.99,307.4,309.33
122.7338,6.6913,-0.15871,32.682,300.0,-0.017179,20.289,299.97,307.33,309.29
123.3338,6.6487,-0.15734,32.573,300.0,-0.017054,20.166,299.97,307.28,309.27
123.9338,6.5787,-0.15728,32.333,300.0,-0.017091,19.948,300.05,307.31,309.38
124.5338,6.461,-0.15776,32.552,300.0,-0.017158,19.595,299.99,307.3,309.32
125.1338,6.3228,-0.15786,32.678,300.0,-0.017108,19.174,299.96,307.18,309.23
125.7338,6.2303,-0.16227,32.237,300.0,-0.017549,18.892,300.05,307.27,309.43
126.3338,6.1078,-0.16025,32.281,300.0,-0.01738,18.521,300.06,307.24,309.24
126.9338,6.02,-0.15986,32.214,300.0,-0.017318,18.252,300.06,307.27,309.31
127.53381,5.9027,-0.16019,31.9,300.0,-0.017433,17.9,300.09,307.25,309.32
128.13381,5.8258,-0.16041,32.025,300.0,-0.017419,17.664,300.03,307.09,309.14
128.73381,5.7299,-0.16242,31.971,300.0,-0.017569,17.377,300.03,306.95,309.12
129.33381,5.6479,-0.16338,32.139,300.0,-0.017714,17.124,300.02,307.0,309.17
129.93381,5.5281,-0.16238,31.904,300.0,-0.017591,16.768,300.04,307.04,309.19
130.53381,5.4476,-0.16263,32.395,300.0,-0.017687,16.516,299.99,306.92,309.06
131.13381,5.3529,-0.16293,32.227,300.0,-0.0177,16.236,300.0,306.86,309.03
131.73381,5.2912,-0.16341,32.203,300.0,-0.017685,16.044,300.0,306.78,308.99
132.33381,5.2225,-0.1668,32.029,300.0,-0.018058,15.843,300.02,306.81,309.03
132.93381,5.1568,-0.16449,32.092,300.0,-0.017823,15.637,299.99,306.78,308.93
133.53381,5.1187,-0.16454,32.282,300.0,-0.01786,15.53,299.95,306.65,308.91
134.13381,5.068,-0.1647,31.888,300.0,-0.017892,15.364,300.03,306.76,309.05
134.73381,5.0284,-0.16501,32.474,300.0,-0.017881,15.252,299.97,306.64,308.85
135.33381,4.9682,-0.16892,32.207,300.0,-0.018261,15.063,299.99,306.57,308.85
135.93381,4.9292,-0.1664,32.325,300.0,-0.018044,14.95,300.0,306.57,308.88
136.53381,4.887,-0.16605,32.129,300.0,-0.017991,14.818,300.04,306.57,308.94
137.13381,4.862,-0.16612,32.233,300.0,-0.018064,14.745,299.97,306.49,308.83
137.73381,4.811,-0.16613,32.224,300.0,-0.018027,14.587,300.04,306.56,308.93
138.33381,4.768,-0.16884,32.592,300.0,-0.018264,14.456,299.95,306.45,308.82
138.9313,4.693,-0.16865,32.425,300.0,-0.018276,14.23,299.97,306.47,308.84
139.5313,4.6362,-0.16778,31.952,300.0,-0.018136,14.058,300.03,306.5,308.88
140.1313,4.5592,-0.16825,32.832,300.0,-0.018255,13.827,299.89,306.39,308.66
140.7313,4.5236,-0.16817,32.38,300.0,-0.018227,13.718,300.03,306.48,308.91
141.3313,4.4566,-0.16801,32.419,300.0,-0.018267,13.517,299.97,306.44,308.71
141.9313,4.424,-0.17239,32.849,300.0,-0.018706,13.415,299.9,306.32,308.74
142.5313,4.3578,-0.16982,31.897,300.0,-0.018339,13.22,300.16,306.47,308.97
143.1313,4.3383,-0.16969,32.698,300.0,-0.018415,13.151,299.98,306.37,308.72
143.7313,4.298,-0.16974,32.064,300.0,-0.018379,13.036,300.08,306.46,308.9
144.3313,4.2686,-0.16965,31.966,300.0,-0.018442,12.938,300.03,306.32,308.71
144.9313,4.2518,-0.17004,32.583,300.0,-0.018453,12.898,299.92,306.29,308.64
145.2861,4.2049,0.0079705,0.0,236.25,0.0011139,12.746,300.01,306.53,309.09
145.2891,4.2339,0.0084194,0.0,0.01946,0.0010261,12.879,300.01,306.53,309.07
145.2921,4.2492,0.0073566,0.0,1.5862e-06,0.00023827,12.855,300.0,306.51,309.01
145.2951,4.2169,0.010183,0.0,1.2928e-10,0.00049984,12.817,299.99,306.5,308.95
145.2981,4.248,0.009331,0.0,1.0536e-14,0.00094142,12.831,299.99,306.47,308.89
145.3011,4.188,0.0062874,0.0,8.587300000000001e-19,0.0010632,12.746,299.99,306.44,308.88
145.3041,4.2626,0.005978,0.0,6.963099999999999e-23,0.0011267,12.884,300.0,306.4,308.86
145.3071,4.1703,0.0082185,0.0,5.6748e-27,0.0009531,12.671,300.01,306.36,308.84
145.3101,4.2777,0.010051,0.0,4.6248e-31,0.00096877,12.948,300.04,306.34,308.85
145.3131,4.1541,0.0084538,0.0,3.7689000000000004e-35,0.0010099,12.611,300.07,306.32,308.85
145.3161,4.279,0.0090255,0.0,3.0714e-39,0.0013237,12.955,300.09,306.31,308.86
145.3191,4.1469,0.0092711,0.0,2.5082999999999998e-43,0.00082119,12.575,300.1,306.3,308.88
145.3221,4.2835,0.010188,0.0,0.0,0.00048749,12.977,300.08,306.3,308.91
145.3251,4.1492,0.0097756,0.0,0.0,0.00062102,12.591,300.06,306.3,308.94
145.3281,4.2801,0.0074352,0.0,0.0,0.00095585,12.994,300.04,306.33,308.96
145.3311,4.1669,0.0061629,0.0,0.0,0.0013267,12.604,300.04,306.47,308.94
145.3341,4.2522,0.0065707,0.0,0.0,0.0010596,12.932,300.04,306.61,308.92
145.3371,4.1765,0.0099671,0.0,0.0,0.00089802,12.647,300.04,306.74,308.9
145.3401,4.2346,0.010399,0.0,0.0,0.0010544,12.886,301.06,308.02,308.84
145.3431,4.2115,0.0094181,0.0,0.0,0.0013438,12.738,302.19,309.42,308.78
145.3461,4.1869,0.0085212,0.0,0.0,0.00097733,12.718,303.32,310.82,308.71
145.3491,4.2195,0.010166,0.0,0.0,0.00058555,12.775,305.2,312.53,308.64
145.3521,21.961,0.052503,0.0,0.0,0.0044798,64.041,307.68,314.49,308.57
145.35509,35.607,0.28134,0.0,0.0,0.030606,107.55,310.17,316.45,308.5
145.35809,41.537,0.54423,0.0,0.0,0.061141,125.69,312.49,318.26,308.44
145.36109,43.497,0.82326,0.0,0.0,0.093941,131.74,314.24,319.55,308.44
145.36409,44.395,1.0862,0.0,0.0,0.12509,134.58,315.99,320.84,308.44
145.36709,44.915,1.3266,0.0,0.0,0.15477,136.23,317.74,322.13,308.44
145.37009,45.227,1.5595,0.0,0.0,0.18502,137.1,318.69,323.25,308.46
145.37309,45.549,1.7962,0.0,0.0,0.21609,138.09,319.53,324.36,308.49
145.37609,45.788,2.0431,0.0,0.0,0.24869,138.82,320.37,325.46,308.52
145.37909,45.997,2.2993,0.0,0.0,0.28383,139.48,321.31,326.4,308.54
145.38209,46.253,2.5514,0.0,0.0,0.32069,140.25,322.33,327.21,308.55
145.38509,46.401,2.7924,0.0,0.0,0.35741,140.71,323.35,328.01,308.55
145.38809,46.578,3.0105,0.0,0.0,0.39148,141.21,324.34,328.77,308.57
145.39109,46.669,3.2161,0.0,0.0,0.42354,141.52,325.19,329.35,308.59
145.39409,46.863,3.4078,0.0,0.0,0.45414,142.08,326.04,329.94,308.62
145.39709,47.021,3.5941,0.0,0.0,0.48568,142.59,326.89,330.52,308.65
145.40009,47.275,3.7791,0.0,0.0,0.51829,143.33,327.43,330.87,308.65
145.40309,47.472,3.9667,0.0,0.0,0.5511,143.95,327.92,331.18,308.65
145.40609,47.69,4.1555,0.0,0.0,0.58466,144.61,328.41,331.49,308.65
145.40909,47.794,4.3366,0.0,0.0,0.61863,144.92,328.8,331.66,308.67
145.41209,47.934,4.5038,0.0,0.0,0.65271,145.36,329.1,331.69,308.71
145.41509,48.0,4.6727,0.0,0.0,0.6877,145.55,329.39,331.73,308.75
145.41809,48.118,4.834,0.0,0.0,0.72103,145.9,329.65,331.77,308.78
145.42109,48.184,4.9993,0.0,0.0,0.75511,146.09,329.79,331.84,308.8
145.42409,48.273,5.1573,0.0,0.0,0.78965,146.37,329.93,331.9,308.82
145.42709,48.256,5.3067,0.0,0.0,0.82521,146.32,330.06,331.96,308.83
145.43009,48.284,5.4503,0.0,0.0,0.85909,146.41,330.06,332.01,308.86
145.43309,48.288,5.5901,0.0,0.0,0.89134,146.42,330.03,332.04,308.89
145.43609,48.337,5.7282,0.0,0.0,0.92485,146.57,330.01,332.08,308.91
145.43909,48.36,5.8624,0.0,0.0,0.96056,146.63,329.93,331.98,308.97
145.44209,48.404,5.992,0.0,0.0,0.99697,146.77,329.82,331.76,309.07
145.44509,48.482,6.1224,0.0,0.0,1.0333,147.02,329.7,331.53,309.16
145.44809,48.539,6.2504,0.0,0.0,1.0683,147.18,329.57,331.29,309.24
145.45109,48.631,6.3741,0.0,0.0,1.1035,147.44,329.38,331.0,309.31
145.45409,48.705,6.4939,0.0,0.0,1.1411,147.69,329.18,330.71,309.37
145.45709,48.835,6.607,0.0,0.0,1.1778,148.08,328.99,330.41,309.44
145.46009,48.9,6.7189,0.0,0.0,1.2129,148.26,328.78,330.15,309.49
145.46309,49.074,6.8263,0.0,0.0,1.2466,148.82,328.56,329.9,309.53
145.46609,49.178,6.9344,0.0,0.0,1.2839,149.12,328.34,329.64,309.58
145.46909,49.356,7.0348,0.0,0.0,1.3228,149.66,328.11,329.33,309.63
145.47209,49.426,7.1344,0.0,0.0,1.3617,149.87,327.86,328.95,309.68
145.47509,49.585,7.2332,0.0,0.0,1.3986,150.35,327.62,328.58,309.74
145.47809,49.672,7.3306,0.0,0.0,1.4348,150.62,327.28,328.19,309.79
145.48109,49.81,7.4233,0.0,0.0,1.4728,151.03,326.39,327.71,309.85
145.48409,49.91,7.51,0.0,0.0,1.5124,151.32,325.49,327.22,309.9
145.48709,50.067,7.5977,0.0,0.0,1.5513,151.81,324.6,326.74,309.96
145.49009,50.153,7.685,0.0,0.0,1.5876,152.08,323.45,326.13,309.99
145.49308,50.274,7.7705,0.0,0.0,1.6261,152.44,322.24,325.48,310.02
145.49608,50.389,7.8468,0.0,0.0,1.6662,152.78,321.02,324.83,310.05
145.49908,50.002,7.9214,0.0,0.0,1.7081,152.03,319.97,324.16,310.08
145.50208,46.837,7.9253,0.0,0.0,1.7106,142.17,319.1,323.46,310.11
145.50508,45.276,7.9306,0.0,0.0,1.7101,137.39,318.23,322.75,310.15
145.50808,44.362,7.9374,0.0,0.0,1.7115,134.58,317.41,322.07,310.19
145.51108,43.892,7.9397,0.0,0.0,1.7155,133.13,316.93,321.52,310.28
145.51408,43.599,7.9424,0.0,0.0,1.7191,132.21,316.45,320.97,310.38
145.51708,43.509,7.9479,0.0,0.0,1.7193,131.96,315.98,320.43,310.47
145.52008,43.431,7.9533,0.0,0.0,1.7179,131.69,315.93,320.13,310.53
145.52308,43.166,7.9575,0.0,0.0,1.7209,130.96,316.0,319.91,310.59
145.52608,41.792,7.9563,0.0,0.0,1.7251,126.87,316.07,319.69,310.64
145.52908,38.507,7.9494,0.0,0.0,1.7239,117.04,316.21,319.59,310.68
145.53208,32.085,7.9452,0.0,0.0,1.7199,98.126,316.43,319.62,310.7
145.53508,3.7229,7.8718,0.0,0.0,1.6795,12.163,316.65,319.66,310.72
145.53808,3.514,7.8812,0.0,0.0,1.6842,10.893,316.86,319.7,310.74
145.54108,3.309,7.8692,0.0,0.0,1.6812,10.229,316.94,319.79,310.79
145.54408,3.5734,7.8636,0.0,0.0,1.6778,10.903,317.02,319.88,310.85
145.54708,3.438,7.8709,0.0,0.0,1.677,10.378,317.1,319.97,310.9
145.55008,3.5939,7.8697,0.0,0.0,1.6753,10.894,317.12,320.02,310.98
145.55308,3.5119,7.8681,0.0,0.0,1.6774,10.684,317.12,320.06,311.06
145.55608,3.6137,7.8644,0.0,0.0,1.6796,10.966,317.12,320.1,311.14
145.55908,3.4952,7.8645,0.0,0.0,1.6793,10.584,317.08,320.12,311.21
145.56208,3.5664,7.8676,0.0,0.0,1.6777,10.838,316.96,320.11,311.27
145.56508,3.4963,7.869,0.0,0.0,1.6777,10.571,316.84,320.1,311.32
145.56808,3.586,7.8681,0.0,0.0,1.6791,10.898,316.72,320.09,311.38
145.57108,3.4919,7.8651,0.0,0.0,1.6792,10.562,316.57,320.06,311.39
145.57408,3.5727,7.8675,0.0,0.0,1.6773,10.889,316.42,320.03,311.41
145.57708,3.5329,7.8696,0.0,0.0,1.6754,10.656,316.28,320.0,311.43
145.58008,3.5037,7.8693,0.0,0.0,1.6768,10.651,316.13,319.96,311.47
145.58308,3.5524,7.8655,0.0,0.0,1.6785,10.75,315.98,319.92,311.52
145.58608,3.5102,7.8639,0.0,0.0,1.6798,10.684,315.84,319.87,311.56
145.58908,3.6312,7.8663,0.0,0.0,1.6787,10.996,315.7,319.79,311.62
145.59208,3.4873,7.8692,0.0,0.0,1.6772,10.582,315.57,319.67,311.7
145.59508,3.6079,7.8709,0.0,0.0,1.6794,10.931,315.44,319.54,311.79
145.59808,3.5074,7.8684,0.0,0.0,1.6808,10.644,315.31,319.41,311.87
145.60108,3.5945,7.8667,0.0,0.0,1.6789,10.908,315.13,319.26,311.92
145.60408,3.5281,7.8693,0.0,0.0,1.6764,10.699,314.94,319.12,311.98
145.60708,3.597,7.8708,0.0,0.0,1.6761,10.9,314.76,318.97,312.03
145.61008,3.5027,7.8689,0.0,0.0,1.6785,10.622,314.57,318.85,312.07
145.61308,3.621,7.8673,0.0,0.0,1.6815,11.018,314.38,318.74,312.1
145.61608,3.5688,7.8673,0.0,0.0,1.6807,10.785,314.19,318.63,312.12
145.61908,3.5595,7.868,0.0,0.0,1.6779,10.808,314.0,318.52,312.16
145.62208,3.5552,7.8708,0.0,0.0,1.6781,10.748,313.83,318.42,312.23
145.62508,3.6413,7.8711,0.0,0.0,1.6813,11.068,313.65,318.32,312.29
145.62808,3.6501,7.8688,0.0,0.0,1.6813,11.044,313.48,318.22,312.36
145.63107,3.7334,7.8708,0.0,0.0,1.6786,11.369,313.31,318.11,312.42
145.63407,3.7604,7.8713,0.0,0.0,1.6767,11.355,313.13,318.0,312.48
145.63707,3.7485,7.8693,0.0,0.0,1.6773,11.396,312.96,317.89,312.55
145.64007,3.8377,7.8669,0.0,0.0,1.6793,11.578,312.75,317.77,312.59
145.64307,3.7266,7.8662,0.0,0.0,1.681,11.343,312.53,317.64,312.61
145.64607,3.8748,7.8681,0.0,0.0,1.679,11.683,312.31,317.51,312.64
145.64907,3.7052,7.8706,0.0,0.0,1.6779,11.275,312.09,317.38,312.66
145.65207,3.8797,7.8707,0.0,0.0,1.6792,11.741,311.86,317.23,312.65
145.65507,3.6529,7.8707,0.0,0.0,1.6821,11.1,311.63,317.09,312.64
145.65807,3.8842,7.8707,0.0,0.0,1.6804,11.768,311.4,316.94,312.63
145.66107,3.6641,7.8714,0.0,0.0,1.6776,11.112,311.22,316.77,312.65
145.66407,3.8855,7.8734,0.0,0.0,1.6779,11.773,311.04,316.59,312.67
145.66707,3.6612,7.867,0.0,0.0,1.6782,11.061,310.85,316.42,312.68
145.67007,3.8908,7.8676,0.0,0.0,1.6817,11.836,310.67,316.26,312.73
145.67307,3.7017,7.8678,0.0,0.0,1.6811,11.188,310.47,316.12,312.8
145.67607,3.8565,7.8718,0.0,0.0,1.6797,11.747,310.28,315.97,312.86
145.67907,3.7278,7.8731,0.0,0.0,1.6796,11.252,310.09,315.82,312.92
145.68207,3.8329,7.8711,0.0,0.0,1.6815,11.679,309.91,315.68,312.98
145.68507,3.7779,7.8705,0.0,0.0,1.6818,11.397,309.73,315.53,313.03
145.68807,3.799,7.8716,0.0,0.0,1.6785,11.614,309.54,315.38,313.09
145.69107,3.8046,7.8714,0.0,0.0,1.6763,11.469,309.36,315.2,313.18
145.69407,3.7471,7.8699,0.0,0.0,1.6776,11.438,309.18,315.02,313.27
145.69707,3.8384,7.8669,0.0,0.0,1.6801,11.583,308.99,314.83,313.36
145.70007,3.6997,7.8679,0.0,0.0,1.6816,11.271,308.81,314.63,313.44
145.70307,3.8808,7.8705,0.0,0.0,1.6801,11.739,308.63,314.41,313.5
145.70607,3.6801,7.8723,0.0,0.0,1.6789,11.192,308.44,314.19,313.56
145.70907,3.8884,7.8734,0.0,0.0,1.6812,11.747,308.25,313.98,313.61
145.71207,3.6623,7.8711,0.0,0.0,1.6823,11.119,308.04,313.8,313.63
145.71507,3.8997,7.8725,0.0,0.0,1.6806,11.826,307.83,313.61,313.65
145.71807,3.6695,7.8733,0.0,0.0,1.6778,11.127,307.62,313.43,313.67
145.72107,3.9071,7.8728,0.0,0.0,1.6781,11.853,307.45,313.29,313.69
145.72407,3.6962,7.8682,0.0,0.0,1.6794,11.19,307.27,313.15,313.7
145.72707,3.8926,7.8683,0.0,0.0,1.6821,11.844,307.1,313.02,313.72
145.73007,3.7226,7.8671,0.0,0.0,1.6801,11.248,306.94,312.88,313.73
145.73307,3.8735,7.8725,0.0,0.0,1.6795,11.787,306.79,312.76,313.73
145.73607,3.7513,7.8736,0.0,0.0,1.68,11.333,306.65,312.63,313.73
145.73907,3.8294,7.873,0.0,0.0,1.683,11.683,306.49,312.49,313.74
145.74207,3.8026,7.8709,0.0,0.0,1.6819,11.46,306.3,312.32,313.77
145.74507,3.7831,7.8749,0.0,0.0,1.6796,11.562,306.1,312.16,313.79
145.74807,3.8348,7.8733,0.0,0.0,1.6774,11.555,305.91,312.0,313.82
145.75107,3.749,7.8719,0.0,0.0,1.679,11.444,305.74,311.83,313.84
145.75407,3.8757,7.8702,0.0,0.0,1.682,11.698,305.58,311.67,313.86
145.75707,3.7097,7.8695,0.0,0.0,1.6823,11.309,305.42,311.5,313.88
145.76007,3.9149,7.8718,0.0,0.0,1.68,11.831,305.27,311.35,313.89
145.76307,3.7028,7.8754,0.0,0.0,1.6804,11.231,305.13,311.22,313.91
145.76607,3.9284,7.8741,0.0,0.0,1.6821,11.895,304.99,311.08,313.93
145.76906,3.6992,7.8727,0.0,0.0,1.683,11.233,304.85,310.94,313.95
145.77206,3.92,7.8748,0.0,0.0,1.681,11.864,304.67,310.78,313.99
145.77506,3.6911,7.8746,0.0,0.0,1.6778,11.18,304.5,310.62,314.03
145.77806,3.9197,7.8751,0.0,0.0,1.6796,11.921,304.32,310.47,314.06
145.78106,3.7229,7.8693,0.0,0.0,1.6802,11.258,304.17,310.32,314.09
145.78406,3.9,7.8706,0.0,0.0,1.6831,11.869,304.01,310.18,314.12
145.78706,3.7602,7.8694,0.0,0.0,1.6805,11.352,303.85,310.03,314.15
145.79006,3.8652,7.8736,0.0,0.0,1.6795,11.804,303.69,309.88,314.17
145.79306,3.7957,7.8732,0.0,0.0,1.68,11.453,303.53,309.74,314.2
145.79606,3.8449,7.8749,0.0,0.0,1.684,11.72,303.36,309.59,314.23
145.79906,3.8305,7.8739,0.0,0.0,1.6825,11.558,303.2,309.45,314.25
145.80206,3.7892,7.8773,0.0,0.0,1.6807,11.569,303.04,309.31,314.26
145.80506,3.8909,7.8761,0.0,0.0,1.6788,11.757,302.89,309.17,314.27
145.80806,3.7591,7.8744,0.0,0.0,1.681,11.466,302.73,309.03,314.28
145.81106,3.9069,7.8704,0.0,0.0,1.6828,11.81,302.6,308.89,314.27
145.81406,3.7267,7.8713,0.0,0.0,1.6826,11.34,302.47,308.74,314.26
145.81706,3.9362,7.874,0.0,0.0,1.6814,11.895,302.34,308.59,314.25
145.82006,3.7162,7.8751,0.0,0.0,1.6801,11.289,302.19,308.46,314.26
145.82306,3.9478,7.8763,0.0,0.0,1.6833,11.952,302.03,308.33,314.28
145.82606,3.7233,7.8745,0.0,0.0,1.6841,11.29,301.86,308.2,314.3
145.82906,3.9614,7.8761,0.0,0.0,1.6814,12.013,301.7,308.07,314.31
145.83206,3.7272,7.8758,0.0,0.0,1.6789,11.287,301.55,307.93,314.31
145.83506,3.9331,7.8755,0.0,0.0,1.6799,11.946,301.41,307.8,314.31
145.83806,3.7585,7.8711,0.0,0.0,1.6814,11.364,301.26,307.66,314.31
145.84106,3.9281,7.8714,0.0,0.0,1.6834,11.941,301.11,307.51,314.31
145.84406,3.7937,7.8734,0.0,0.0,1.6822,11.449,300.96,307.35,314.31
145.84706,3.8865,7.8772,0.0,0.0,1.6817,11.853,300.82,307.2,314.31
145.85006,3.8394,7.8761,0.0,0.0,1.6817,11.596,300.67,307.03,314.32
145.85306,3.8442,7.8753,0.0,0.0,1.6845,11.75,300.52,306.87,314.33
145.85606,3.8727,7.8738,0.0,0.0,1.6823,11.672,300.38,306.7,314.33
145.85906,3.7962,7.8754,0.0,0.0,1.6794,11.584,300.24,306.54,314.34
145.86206,3.9189,7.8757,0.0,0.0,1.6789,11.82,300.15,306.38,314.32
145.86506,3.7732,7.8721,0.0,0.0,1.6806,11.493,300.06,306.21,314.3
145.86806,3.9436,7.8705,0.0,0.0,1.683,11.919,299.96,306.05,314.28
145.87106,3.7441,7.8704,0.0,0.0,1.6821,11.384,299.87,305.94,314.29
145.87406,3.9694,7.8739,0.0,0.0,1.6805,12.006,299.76,305.84,314.3
145.87706,3.7343,7.8752,0.0,0.0,1.681,11.332,299.66,305.74,314.31
145.88006,3.9707,7.8753,0.0,0.0,1.6833,12.054,299.55,305.64,314.33
145.88306,3.7457,7.8739,0.0,0.0,1.6835,11.35,299.42,305.55,314.37
145.88606,3.984,7.8778,0.0,0.0,1.6819,12.072,299.29,305.46,314.4
145.88906,3.7651,7.8781,0.0,0.0,1.6796,11.389,299.16,305.35,314.43
145.89206,3.95,7.8774,0.0,0.0,1.681,12.026,299.01,305.21,314.41
145.89506,3.7851,7.8734,0.0,0.0,1.6831,11.452,298.86,305.06,314.39
145.89806,3.9214,7.875,0.0,0.0,1.685,11.95,298.72,304.91,314.37
145.90106,3.8314,7.8739,0.0,0.0,1.6821,11.554,298.59,304.78,314.37
145.90406,3.8897,7.8771,0.0,0.0,1.6814,11.862,298.47,304.64,314.37
145.90705,3.8619,7.8763,0.0,0.0,1.682,11.659,298.35,304.5,314.37
145.91005,3.8576,7.8772,0.0,0.0,1.6849,11.761,298.23,304.37,314.38
145.91305,3.9092,7.8749,0.0,0.0,1.6825,11.792,298.11,304.25,314.39
145.91605,3.8124,7.8777,0.0,0.0,1.6805,11.615,298.0,304.14,314.4
146.1176,3.8514,7.8761,0.0,0.0,1.6825,11.677,293.11,299.24,313.17
146.7176,3.8086,7.8794,0.0,0.0,1.6841,11.547,278.55,284.05,304.8
147.3176,3.7684,7.8763,0.0,0.0,1.6826,11.425,242.78,263.49,240.91
147.9176,3.7656,7.8827,0.0,0.0,1.6858,11.416,193.43,233.72,208.96
148.5176,3.7532,7.8926,0.0,0.0,1.6909,11.383,83.379,187.23,122.8
149.0745,3.7559,7.9006,0.0,0.0,1.695,11.388,79.016,166.01,108.43
149.6745,3.7303,7.9093,0.0,0.0,1.6991,11.312,63.226,127.44,66.86
150.2745,3.725,7.9189,0.0,0.0,1.7043,11.293,56.29,79.22,50.634
150.8745,3.6756,7.9259,0.0,0.0,1.7083,11.147,55.489,67.56,44.532
151.4745,3.6586,7.9315,0.0,0.0,1.7107,11.094,50.0,60.471,41.834
152.0745,3.6095,7.935,0.0,0.0,1.7129,10.948,47.9,55.845,39.919
152.6745,3.598,7.9382,0.0,0.0,1.7141,10.908,46.583,53.107,38.655
153.2745,3.5884,7.9412,0.0,0.0,1.7158,10.885,45.745,50.686,37.867
153.8745,3.5994,7.944,0.0,0.0,1.7177,10.909,44.774,48.98,37.308
154.4745,3.591,7.9467,0.0,0.0,1.7186,10.893,43.605,47.528,36.645
155.0745,3.6022,7.9496,0.0,0.0,1.7205,10.92,43.245,46.209,36.282
155.6745,3.5968,7.9518,0.0,0.0,1.7212,10.909,42.663,45.083,35.862
156.2745,3.7232,7.9532,0.0,0.0,1.722,11.288,43.902,45.121,37.774
156.8745,3.6477,7.9535,0.0,0.0,1.7227,11.065,45.97,46.096,40.018
157.4453,3.6092,7.9549,0.0,0.0,1.7233,10.945,47.295,46.998,41.934
158.0453,3.6521,7.9557,0.0,0.0,1.7234,11.073,48.479,47.916,43.635
158.6453,3.5577,7.9574,0.0,0.0,1.7244,10.79,49.304,48.703,45.111
159.2453,3.5771,7.9582,0.0,0.0,1.7245,10.844,50.045,49.402,46.235
159.8453,3.5441,7.9629,0.0,0.0,1.7274,10.747,50.534,49.962,47.301
160.4453,3.5455,7.9649,0.0,0.0,1.7286,10.753,50.935,50.54,48.314
161.0453,3.5052,7.9649,0.0,0.0,1.7282,10.63,51.199,50.866,48.929
161.6453,3.5338,7.9625,0.0,0.0,1.7272,10.713,51.4,51.178,49.443
162.2453,3.5364,7.9636,0.0,0.0,1.7273,10.722,51.581,51.314,49.936
162.8453,3.5388,7.9637,0.0,0.0,1.7277,10.73,51.577,51.527,50.366