File: examples/dan-msc-case-studies/CS4/data/01 raw data/hyde_test_032.csv
Time(sec),Force(kN),Jaw(mm),PowAngle(deg),PTemp,Strain,Stress(MPa),TC1(C),TC2(C),TC3(C)
0.0,1.7269,0.00068661,0.0,0.0018352,0.00010575,5.2183,20.712,21.873,21.244
0.6,1.6875,0.00035133,0.0,1.621,2.68e-05,5.1193,20.7,21.863,21.21
1.2,1.6831,0.00052226,0.0,3.421,5.2172e-05,5.1042,20.716,21.858,21.195
1.8,1.6864,0.00018915,0.0,5.221,6.9623e-06,5.1154,20.738,21.817,21.225
2.4,2.0009,0.0024647,0.0,7.021,0.00027855,6.068,20.761,21.865,21.203
3.0,2.4605,0.006618,0.0,8.821,0.00075301,7.4647,20.748,21.859,21.214
3.6,2.8842,0.010263,0.0,10.621,0.0011474,8.7511,20.733,21.873,21.246
4.2,3.2226,0.013003,0.0,12.421,0.0014105,9.772,20.736,21.935,21.206
4.8,3.4165,0.014422,0.0,14.221,0.0015914,10.365,20.726,21.831,21.19
5.4,3.6377,0.016201,0.0,16.021,0.0017709,11.032,20.748,21.882,21.23
6.0,3.7593,0.017086,0.0,17.821,0.0018853,11.403,20.74,21.877,21.236
6.6,3.9276,0.018365,0.0,19.621,0.0020361,11.913,20.763,21.876,21.214
7.2,4.0919,0.019877,0.0,21.421,0.0021927,12.413,20.769,21.854,21.243
7.8,4.3863,0.022677,8.7437,23.221,0.0024841,13.307,20.766,21.841,21.21
8.362,4.6431,0.026209,25.002,24.912,0.0028794,14.088,20.832,22.078,21.516
8.962,4.7743,0.027252,32.005,26.707,0.002969,14.48,21.833,23.41,23.708
9.562,4.8199,0.026894,32.487,28.507,0.0029661,14.62,24.34,26.767,28.227
10.162,4.8826,0.026764,26.757,30.307,0.0029652,14.811,27.855,32.961,32.178
10.762,4.9889,0.027636,21.152,32.107,0.0030206,15.132,30.574,38.04,33.402
11.362,5.0768,0.028451,20.25,33.907,0.0031252,15.403,32.463,38.201,33.847
11.962,5.1157,0.028672,26.395,35.707,0.0031383,15.516,33.36,38.203,34.294
12.562,5.1375,0.02803,30.468,37.507,0.0030811,15.589,34.562,38.203,36.136
13.162,5.1585,0.027479,30.901,39.307,0.0030488,15.647,36.572,38.136,39.17
13.6628,5.2041,0.027079,28.966,40.809,0.0029867,15.789,38.664,40.259,41.672
14.2628,5.2895,0.027305,25.962,42.609,0.0029981,16.046,41.14,42.446,43.638
14.8628,5.3491,0.0276,25.796,44.409,0.0030273,16.225,42.938,43.8,44.6
15.4628,5.3932,0.02755,28.063,46.209,0.0030049,16.363,44.335,44.907,45.563
16.0628,5.4187,0.026942,29.984,48.009,0.0029674,16.437,45.798,46.501,47.407
16.6628,5.4323,0.026359,30.072,49.809,0.0029185,16.482,47.738,48.555,49.953
17.2628,5.4499,0.025817,28.682,51.609,0.0028254,16.531,49.968,50.774,52.241
17.8628,5.4477,0.025349,27.564,53.409,0.0027904,16.526,51.933,52.646,53.79
18.4628,5.463,0.024817,29.338,55.209,0.0027119,16.571,53.419,53.886,54.898
19.0628,5.4532,0.024046,29.023,57.009,0.0026585,16.544,55.315,55.761,56.88
19.6628,5.4624,0.023426,29.13,58.809,0.0025962,16.572,57.101,57.476,58.718
20.2628,5.4687,0.023054,28.903,60.609,0.0025205,16.59,58.98,59.304,60.57
20.8628,5.4713,0.021938,29.114,62.409,0.0024007,16.601,60.79,61.029,62.418
21.4628,5.4758,0.021507,29.127,64.209,0.002374,16.61,62.586,62.835,64.19
22.0628,5.4775,0.020255,29.734,66.009,0.0022394,16.616,64.285,64.464,65.911
22.6628,5.4904,0.019447,29.559,67.809,0.0021363,16.655,66.182,66.232,67.713
23.2628,5.4892,0.018826,29.794,69.609,0.002063,16.653,67.884,68.052,69.484
23.8628,5.508,0.018849,29.876,71.409,0.0020556,16.71,69.673,69.825,71.349
24.4628,5.5012,0.018372,29.79,73.209,0.0020374,16.687,71.631,71.546,73.089
25.0628,5.5138,0.01817,29.764,75.009,0.0019885,16.728,73.442,73.334,74.861
25.6628,5.5101,0.017516,29.907,76.809,0.0019256,16.714,75.162,75.069,76.603
26.2628,5.4896,0.016477,29.858,78.609,0.0018013,16.656,76.998,76.843,78.339
26.8628,5.4928,0.015636,29.846,80.409,0.0017372,16.659,78.794,78.46,80.067
27.4628,5.4917,0.014905,30.119,82.209,0.0016293,16.66,80.556,80.188,81.906
28.0628,5.5265,0.01424,29.794,84.009,0.0015649,16.765,82.433,81.972,83.676
28.6628,5.5166,0.013634,30.304,85.809,0.001496,16.734,84.161,83.676,85.337
29.2628,5.5288,0.012662,30.201,87.609,0.0014068,16.775,85.995,85.44,87.175
29.8628,5.5186,0.011464,30.342,89.409,0.0012556,16.738,87.803,87.293,89.103
30.4628,5.5229,0.0099803,29.869,91.209,0.0010991,16.758,89.674,89.115,90.765
31.0628,5.5274,0.0099779,30.157,93.009,0.001096,16.767,91.42,90.655,92.357
31.6628,5.5304,0.0097578,30.87,94.809,0.0010884,16.78,93.04,92.374,94.139
32.2628,5.539,0.0092628,30.692,96.609,0.001006,16.801,94.941,94.154,96.162
32.8628,5.5373,0.0084532,30.92,98.409,0.00091872,16.8,96.799,96.054,98.119
33.46281,5.5507,0.0075897,30.525,100.21,0.00084647,16.837,98.66,97.892,99.899
34.06281,5.5421,0.0070528,30.076,102.01,0.00078224,16.811,100.53,99.508,101.48
34.66281,5.5577,0.00628,30.866,103.81,0.00069911,16.861,102.1,101.24,103.2
35.26281,5.5583,0.0054892,31.086,105.61,0.00058947,16.859,103.95,103.1,105.17
35.86281,5.5512,0.0044997,30.187,107.41,0.00051848,16.843,105.92,104.95,107.09
36.46281,5.561,0.003283,30.329,109.21,0.00035098,16.866,107.71,106.65,108.67
37.06281,5.5541,0.0015862,30.556,111.01,0.00018186,16.85,109.48,108.31,110.37
37.66281,5.5612,0.0010157,30.539,112.81,0.00011998,16.867,111.22,109.92,112.04
38.26281,5.5516,0.0012831,30.872,114.61,0.00013916,16.844,113.03,111.73,114.04
38.86281,5.5561,0.00067378,30.604,116.41,7.671e-05,16.855,114.89,113.52,115.73
39.46281,5.5511,-0.00010458,31.055,118.21,-6.3156e-06,16.838,116.58,115.17,117.37
40.06281,5.5646,-0.0012059,30.928,120.01,-0.00011719,16.883,118.39,116.95,119.2
40.66281,5.5524,-0.0020443,30.843,121.81,-0.00022723,16.84,120.22,118.69,120.99
41.098,5.5646,-0.0026906,30.85,123.12,-0.00029401,16.877,121.54,119.85,122.24
41.698,5.556,-0.0037764,30.872,124.92,-0.00039303,16.858,123.3,121.56,123.88
42.298,5.5731,-0.0045827,31.357,126.72,-0.00050573,16.907,125.03,123.25,125.65
42.898,5.5595,-0.0054853,31.207,128.52,-0.00060339,16.866,126.89,124.97,127.49
43.498,5.5787,-0.0064485,31.013,130.32,-0.00069191,16.923,128.73,126.68,129.21
44.098,5.5848,-0.0082089,31.66,132.12,-0.00087904,16.938,130.45,128.36,130.92
44.698,5.6039,-0.009922,31.213,133.91,-0.0010699,17.001,132.31,130.07,132.77
45.298,5.618,-0.010371,31.741,135.71,-0.0011392,17.039,134.0,131.89,134.46
45.898,5.6305,-0.010113,31.784,137.51,-0.0011023,17.084,135.85,133.63,136.37
46.498,5.643,-0.010832,31.628,139.31,-0.0011793,17.116,137.7,135.42,138.19
47.098,5.6302,-0.011616,31.779,141.12,-0.0012629,17.083,139.5,137.14,139.88
47.698,5.6328,-0.012545,31.893,142.91,-0.0013587,17.085,141.25,138.85,141.57
48.298,5.6161,-0.01343,32.247,144.72,-0.0014652,17.037,143.02,140.62,143.27
48.898,5.6336,-0.014545,32.448,146.51,-0.0015854,17.091,144.8,142.26,145.19
49.498,5.6131,-0.015714,32.83,148.32,-0.0017084,17.025,146.55,144.04,147.09
50.098,5.6357,-0.016286,32.464,150.11,-0.0017796,17.098,148.46,145.77,148.91
50.698,5.642,-0.01805,32.131,151.92,-0.0019559,17.114,150.33,147.54,150.6
51.298,5.6508,-0.019837,32.414,153.71,-0.0021467,17.143,152.08,149.17,152.29
51.898,5.6569,-0.020934,32.68,155.51,-0.0022949,17.157,153.89,150.86,154.07
52.498,5.6417,-0.020372,32.403,157.32,-0.0022238,17.118,155.74,152.68,155.93
53.098,5.6578,-0.020866,32.146,159.12,-0.0022678,17.16,157.55,154.45,157.63
53.698,5.6549,-0.022076,32.661,160.91,-0.002418,17.155,159.27,156.17,159.38
54.298,5.6626,-0.023432,32.502,162.72,-0.0025383,17.18,161.1,158.06,161.25
54.898,5.6663,-0.024054,32.617,164.51,-0.0026344,17.188,162.89,159.77,162.99
55.498,5.6773,-0.025123,32.83,166.32,-0.0027522,17.225,164.66,161.51,164.7
56.098,5.6724,-0.026443,32.056,168.12,-0.0028661,17.202,166.59,163.19,166.6
56.698,5.686,-0.028897,32.15,169.92,-0.0031581,17.252,168.39,164.96,168.26
57.298,5.6985,-0.028745,32.68,171.71,-0.0031701,17.284,170.04,166.63,169.84
57.898,5.6903,-0.028714,32.774,173.51,-0.0031205,17.265,171.89,168.22,171.73
58.498,5.6972,-0.029837,32.315,175.32,-0.0032529,17.284,173.79,170.04,173.62
59.098,5.6846,-0.030994,32.617,177.12,-0.0033853,17.245,175.55,171.59,175.1
59.698,5.6945,-0.031978,32.844,178.91,-0.0034809,17.278,177.24,173.15,176.82
60.298,5.6852,-0.033139,32.91,180.72,-0.0036144,17.244,179.06,174.91,178.58
60.89801,5.6817,-0.034369,32.849,182.51,-0.0037311,17.241,180.93,176.53,180.34
61.49801,5.7002,-0.036709,32.943,184.32,-0.004002,17.291,182.67,178.32,182.19
62.09801,5.6977,-0.037497,32.86,186.11,-0.0041283,17.286,184.48,180.01,183.99
62.69801,5.7112,-0.036816,32.866,187.92,-0.0040012,17.325,186.31,181.73,185.78
63.29801,5.6954,-0.037847,33.101,189.71,-0.004135,17.278,188.08,183.47,187.62
63.89801,5.7031,-0.039233,33.114,191.51,-0.004268,17.302,189.9,185.14,189.32
64.49801,5.6927,-0.040197,33.064,193.32,-0.0043809,17.269,191.71,186.8,191.12
65.09801,5.7093,-0.041254,33.25,195.12,-0.0045182,17.321,193.53,188.5,192.89
65.69801,5.71,-0.042203,32.962,196.92,-0.004586,17.319,195.34,190.26,194.71
66.29801,5.7177,-0.04416,33.226,198.71,-0.0048153,17.345,197.09,191.92,196.35
66.89801,5.7248,-0.047048,32.996,200.52,-0.005135,17.365,198.9,193.66,198.34
67.49801,5.7298,-0.045732,33.149,202.32,-0.0050092,17.383,200.73,195.44,200.07
68.09801,5.7349,-0.045943,33.4,204.12,-0.0050321,17.398,202.48,197.02,201.68
68.69801,5.7308,-0.047227,33.265,205.92,-0.005143,17.385,204.32,198.69,203.48
69.29801,5.7375,-0.048234,33.252,207.72,-0.0052697,17.406,206.13,200.49,205.38
69.89801,5.7277,-0.049402,33.483,209.51,-0.0053976,17.373,207.92,202.09,207.11
70.49801,5.7375,-0.050236,33.654,211.32,-0.0054888,17.408,209.67,203.74,208.78
71.09801,5.7324,-0.051502,33.76,213.12,-0.0056366,17.389,211.45,205.53,210.75
71.69801,5.7296,-0.053306,33.663,214.92,-0.0057968,17.382,213.32,207.23,212.45
72.29801,5.7437,-0.055763,33.512,216.71,-0.0060733,17.42,215.09,208.85,214.11
72.89801,5.74,-0.056037,33.715,218.52,-0.006116,17.414,216.85,210.48,215.93
73.49801,5.7505,-0.05537,33.514,220.33,-0.0060212,17.444,218.75,212.21,217.9
73.9298,5.755,-0.055744,32.853,221.61,-0.0060962,17.459,220.16,213.47,219.01
74.5298,5.7444,-0.057207,33.771,223.41,-0.006226,17.425,221.78,215.07,220.57
75.1298,5.753,-0.058252,33.38,225.21,-0.0063559,17.451,223.67,216.9,222.65
75.7298,5.7481,-0.059114,33.598,227.01,-0.0064351,17.435,225.42,218.47,224.2
76.3298,5.7465,-0.06037,33.617,228.81,-0.0065955,17.433,227.18,220.15,225.94
76.9298,5.7425,-0.06151,33.933,230.61,-0.0067041,17.419,228.94,221.82,227.72
77.5298,5.7426,-0.0629,33.886,232.41,-0.0068711,17.423,230.78,223.6,229.74
78.1298,5.7537,-0.064685,33.072,234.21,-0.0070593,17.452,232.76,225.36,231.58
78.7298,5.7576,-0.067582,34.426,236.01,-0.0073536,17.465,234.4,226.86,232.82
79.3298,5.779,-0.068739,35.779,237.81,-0.007536,17.53,237.02,229.04,236.5
79.9298,5.7554,-0.067573,31.993,239.61,-0.0073658,17.459,239.85,231.83,239.22
80.5298,5.7667,-0.067589,33.168,241.41,-0.0073716,17.495,241.18,233.08,239.02
81.1298,5.7693,-0.069334,34.946,243.21,-0.0075386,17.499,242.53,234.32,240.65
81.7298,5.7655,-0.070891,34.334,245.01,-0.0077433,17.493,244.57,236.42,243.48
82.3298,5.7628,-0.071912,33.556,246.81,-0.007837,17.479,246.61,238.31,245.22
82.9298,5.7539,-0.072728,33.762,248.61,-0.007956,17.455,248.26,239.75,246.34
83.5298,5.7564,-0.074278,34.576,250.41,-0.0081085,17.462,249.9,241.2,248.12
84.1298,5.7551,-0.075494,34.521,252.21,-0.0082467,17.458,251.76,243.0,250.19
84.7298,5.7591,-0.076519,34.055,254.01,-0.0083668,17.47,253.69,244.8,252.03
85.3298,5.7556,-0.077764,34.048,255.81,-0.0084708,17.456,255.43,246.4,253.59
85.9298,5.773,-0.07995,34.343,257.61,-0.0087257,17.515,257.19,248.02,255.32
86.5298,5.7673,-0.082618,34.588,259.41,-0.008981,17.49,258.93,249.71,257.13
87.1298,5.7726,-0.082705,34.92,261.21,-0.0090458,17.513,260.68,251.35,258.96
87.7298,5.7765,-0.08167,34.479,263.01,-0.0088969,17.52,262.67,253.32,261.11
88.3298,5.7601,-0.082262,34.395,264.81,-0.0089693,17.473,264.45,254.98,262.8
88.9298,5.7803,-0.083394,34.723,266.61,-0.0090703,17.535,266.16,256.6,264.13
89.5298,5.7655,-0.084918,35.091,268.41,-0.0092623,17.491,267.9,258.21,266.17
90.1298,5.7764,-0.086252,34.82,270.21,-0.0093903,17.525,269.82,260.09,268.2
90.7298,5.77,-0.087055,34.431,272.01,-0.0095052,17.501,271.76,261.77,269.83
91.3298,5.7743,-0.088439,34.996,273.81,-0.0096398,17.517,273.34,263.35,271.36
91.9298,5.7706,-0.089667,35.446,275.61,-0.0097904,17.501,275.13,264.95,273.29
92.5298,5.7623,-0.091581,34.687,277.41,-0.00997,17.48,277.14,266.84,275.43
93.12981,5.7776,-0.094212,34.672,279.21,-0.010269,17.525,278.91,268.55,276.92
93.72981,5.7762,-0.094835,35.35,281.01,-0.010358,17.523,280.55,270.13,278.4
94.32981,5.7814,-0.093442,34.974,282.81,-0.010202,17.54,282.44,271.86,280.56
94.92981,5.77,-0.094151,34.666,284.61,-0.010251,17.504,284.33,273.6,282.35
95.52981,5.7764,-0.095535,34.903,286.41,-0.010417,17.524,286.01,275.26,284.14
96.12981,5.7719,-0.096859,35.383,288.21,-0.010549,17.506,287.75,276.91,285.88
96.72981,5.7753,-0.098141,35.494,290.01,-0.010711,17.522,289.58,278.66,288.06
97.32981,5.7697,-0.098802,34.619,291.81,-0.010758,17.498,291.59,280.38,289.72
97.92981,5.761,-0.099835,35.273,293.61,-0.010891,17.481,293.16,281.93,291.04
98.52981,5.7731,-0.10212,35.695,295.41,-0.011116,17.511,294.91,283.78,293.33
99.12981,5.7664,-0.10411,34.662,297.21,-0.011347,17.492,296.96,285.61,295.38
99.72981,5.7826,-0.10612,35.364,299.01,-0.011563,17.542,298.55,287.25,296.53
100.32981,5.7831,-0.10409,36.216,300.81,-0.011357,17.543,300.22,289.03,298.75
100.92981,5.7803,-0.10464,35.497,302.61,-0.011388,17.538,302.22,291.0,301.17
101.52981,5.7683,-0.10521,33.453,304.41,-0.011469,17.496,304.23,292.79,302.71
102.12981,5.7655,-0.10579,34.361,306.21,-0.011507,17.492,305.27,294.15,302.69
102.72981,5.7767,-0.10691,36.169,308.01,-0.011649,17.522,306.19,295.07,303.86
103.32981,5.7722,-0.10894,36.299,309.81,-0.011854,17.511,308.0,297.0,307.06
103.92981,5.7764,-0.11006,35.018,311.61,-0.011992,17.519,310.2,299.29,310.04
104.52981,5.7632,-0.11042,34.65,313.41,-0.012006,17.484,312.09,301.47,311.32
105.12981,5.7793,-0.11246,36.22,315.21,-0.012242,17.529,313.47,303.24,312.95
105.72981,5.7868,-0.11551,35.972,317.01,-0.012554,17.552,315.39,305.86,315.94
106.1648,5.7786,-0.11683,34.894,318.32,-0.012731,17.527,317.04,308.39,317.62
106.7648,5.7855,-0.11409,34.625,320.12,-0.012434,17.554,318.85,311.09,318.41
107.3648,5.7829,-0.11367,35.832,321.92,-0.0124,17.54,320.29,312.88,319.57
107.9648,5.7816,-0.11491,35.869,323.72,-0.0125,17.541,322.12,315.22,321.92
108.5648,5.7745,-0.11548,34.433,325.52,-0.01258,17.515,324.31,317.37,323.57
109.1648,5.7694,-0.11622,35.462,327.32,-0.012659,17.505,325.79,318.63,324.37
109.7648,5.7845,-0.11749,35.923,329.12,-0.012799,17.547,327.49,320.6,326.57
110.3648,5.7556,-0.11814,35.635,330.92,-0.012875,17.459,329.42,322.56,328.6
110.9648,5.7781,-0.11887,35.735,332.72,-0.012933,17.53,331.17,324.56,330.36
111.5648,5.7655,-0.11966,35.514,334.52,-0.013024,17.487,333.09,326.59,332.16
112.1648,5.7747,-0.1215,36.017,336.32,-0.013193,17.518,334.74,328.51,333.9
112.7648,5.788,-0.12483,35.611,338.12,-0.013573,17.555,336.62,330.61,335.91
113.3648,5.7802,-0.12319,36.007,339.92,-0.013428,17.535,338.37,332.41,337.57
113.9648,5.7912,-0.12153,36.154,341.72,-0.013253,17.568,340.18,334.31,339.64
114.5648,5.7726,-0.12234,35.748,343.52,-0.013321,17.512,342.06,336.36,341.58
115.1648,5.7868,-0.12296,35.646,345.32,-0.013385,17.553,343.91,338.35,343.54
115.7648,5.7756,-0.12387,35.906,347.12,-0.013492,17.517,345.6,340.11,345.18
116.3648,5.775,-0.12467,36.144,348.92,-0.013548,17.52,347.36,342.04,347.1
116.9648,5.7654,-0.12443,33.883,350.0,-0.013546,17.487,349.1,344.01,349.02
117.5648,5.7448,-0.12366,33.065,350.0,-0.01344,17.431,349.08,343.61,347.87
118.1648,5.7578,-0.12332,34.124,350.0,-0.013438,17.464,348.72,343.09,347.02
118.7648,5.7605,-0.12408,34.356,350.0,-0.013498,17.475,348.66,343.44,347.37
119.3648,5.7797,-0.12494,33.709,350.0,-0.013583,17.53,348.74,343.7,347.63
119.9648,5.7575,-0.12673,33.685,350.0,-0.013798,17.467,348.68,343.79,347.54
120.5648,5.7733,-0.12478,33.538,350.0,-0.0136,17.514,348.7,343.85,347.54
121.1648,5.7567,-0.12245,33.697,350.0,-0.013348,17.461,348.66,343.97,347.57
121.7648,5.7558,-0.12193,33.755,350.0,-0.013265,17.462,348.57,344.05,347.58
122.3648,5.7437,-0.12175,33.645,350.0,-0.01327,17.42,348.61,344.18,347.64
122.9648,5.7341,-0.12163,33.522,350.0,-0.013258,17.397,348.63,344.28,347.68
123.5648,5.7289,-0.12196,33.73,350.0,-0.013259,17.378,348.55,344.11,347.57
124.1648,5.7102,-0.12199,33.531,350.0,-0.01328,17.324,348.58,344.34,347.78
124.7648,5.7075,-0.12163,33.268,350.0,-0.013228,17.312,348.59,344.31,347.74
125.3648,5.6989,-0.12184,33.376,350.0,-0.013274,17.289,348.54,344.34,347.71
125.96481,5.715,-0.12182,33.695,350.0,-0.013281,17.338,348.9,344.84,348.36
126.56481,5.685,-0.12185,32.849,350.0,-0.01326,17.242,349.07,344.99,348.47
127.16481,5.6848,-0.12156,33.175,350.0,-0.013241,17.247,348.95,344.69,348.14
127.76481,5.6865,-0.12146,33.301,350.0,-0.013213,17.247,348.92,344.72,348.21
128.36481,5.6835,-0.12172,33.748,350.0,-0.013266,17.243,349.03,344.96,348.46
128.96481,5.6817,-0.12216,33.574,350.0,-0.013299,17.232,349.37,345.39,348.99
129.56481,5.6813,-0.1225,32.726,350.0,-0.013301,17.235,350.06,346.13,349.96
130.16481,5.6835,-0.12208,32.422,350.0,-0.013303,17.239,350.13,345.97,349.64
130.76481,5.6725,-0.12242,33.213,350.0,-0.01332,17.206,349.92,345.72,349.26
131.36481,5.6777,-0.12277,32.865,350.0,-0.013345,17.224,349.92,345.76,349.38
131.96481,5.6733,-0.1231,33.114,350.0,-0.013382,17.206,349.91,345.77,349.41
132.56481,5.6776,-0.12361,33.044,350.0,-0.013413,17.225,349.92,345.88,349.56
133.16481,5.6847,-0.1238,33.069,350.0,-0.013475,17.24,349.95,345.77,349.53
133.76481,5.7123,-0.12389,33.02,350.0,-0.013473,17.332,349.92,345.72,349.55
134.36481,5.7839,-0.12361,32.784,350.0,-0.013421,17.544,350.01,345.79,349.62
134.96481,5.8725,-0.12297,32.849,350.0,-0.013388,17.815,349.94,345.56,349.54
135.56481,5.9504,-0.1227,32.869,350.0,-0.013347,18.048,349.91,345.56,349.61
136.16481,6.0243,-0.12239,33.149,350.0,-0.013295,18.274,349.88,345.62,349.65
136.76481,6.1985,-0.1213,33.094,350.0,-0.013186,18.805,349.88,345.6,349.67
137.36481,6.3167,-0.12027,32.826,350.0,-0.013077,19.157,349.92,345.54,349.69
137.96481,6.3974,-0.11964,32.85,350.0,-0.013013,19.409,349.96,345.58,349.78
138.56481,6.4543,-0.11822,32.612,350.0,-0.012855,19.574,349.98,345.57,349.91
139.0947,6.4916,-0.11769,32.818,350.0,-0.012805,19.691,349.94,345.52,349.78
139.6947,6.5185,-0.11663,32.696,350.0,-0.012667,19.779,349.93,345.55,349.81
140.2947,6.596,-0.11501,32.438,350.0,-0.012518,20.004,349.96,345.62,349.91
140.8947,6.6494,-0.11404,32.811,350.0,-0.012418,20.168,349.87,345.58,349.92
141.4947,6.7053,-0.11315,32.635,350.0,-0.012301,20.336,349.96,345.55,349.99
142.0947,6.7205,-0.11203,32.738,350.0,-0.012204,20.385,349.9,345.41,349.83
142.6947,6.7784,-0.11089,32.254,350.0,-0.012069,20.563,349.93,345.47,349.96
143.2947,6.8181,-0.11026,32.637,350.0,-0.012009,20.68,349.89,345.47,350.01
143.8947,6.865,-0.10954,32.684,350.0,-0.011936,20.828,349.87,345.43,349.98
144.4947,6.8946,-0.10874,32.678,350.0,-0.011846,20.913,349.89,345.55,350.08
145.0947,6.9153,-0.10818,32.212,350.0,-0.011778,20.978,349.92,345.63,350.17
145.6947,6.9362,-0.10758,32.829,350.0,-0.011732,21.038,349.83,345.65,350.11
146.2947,6.9462,-0.10676,32.737,350.0,-0.011637,21.073,349.88,345.89,350.21
146.8651,6.9567,-0.10619,32.849,350.0,-0.011546,21.099,349.86,345.94,350.19
147.4651,6.9596,-0.10574,33.046,350.0,-0.011525,21.115,349.86,346.04,350.23
148.0651,6.9714,-0.10498,32.636,350.0,-0.011443,21.144,349.94,346.1,350.36
148.6651,6.9643,-0.10447,32.643,350.0,-0.011367,21.127,349.87,346.19,350.31
149.2651,6.9843,-0.104,33.263,350.0,-0.011332,21.185,349.82,346.33,350.27
149.8651,6.9683,-0.10323,33.042,350.0,-0.01125,21.135,349.87,346.5,350.46
150.4651,6.9813,-0.10302,33.674,350.0,-0.01121,21.178,349.85,346.65,350.43
151.0651,6.9755,-0.10235,33.851,350.0,-0.011148,21.158,350.17,347.2,350.92
151.6651,6.979,-0.10179,32.493,350.0,-0.011097,21.171,350.55,347.6,351.38
152.2651,6.9762,-0.10115,33.046,350.0,-0.011029,21.159,350.39,347.31,350.97
152.8651,6.9751,-0.10102,33.658,350.0,-0.010994,21.16,350.3,347.4,351.04
153.4651,6.9818,-0.10039,33.321,350.0,-0.01096,21.177,350.36,347.71,351.26
154.0651,6.9604,-0.099962,32.883,350.0,-0.01091,21.119,350.44,347.96,351.43
154.6651,6.9798,-0.099352,32.926,350.0,-0.01081,21.172,350.42,347.9,351.3
155.2651,6.9669,-0.099004,33.089,350.0,-0.010801,21.134,350.37,347.96,351.28
155.8651,6.9761,-0.098265,32.867,350.0,-0.010702,21.163,350.4,348.04,351.43
156.4651,6.9634,-0.097986,32.853,350.0,-0.010658,21.121,350.42,348.07,351.46
157.0651,6.9766,-0.097727,32.878,350.0,-0.010645,21.166,350.43,348.24,351.42
157.6651,6.9754,-0.096996,32.819,350.0,-0.010576,21.156,350.44,348.24,351.39
158.2651,6.9706,-0.09681,32.685,350.0,-0.010562,21.148,350.48,348.4,351.5
158.8651,6.9747,-0.096489,32.699,350.0,-0.010496,21.154,350.47,348.45,351.5
159.4651,6.9623,-0.096093,32.554,350.0,-0.010488,21.122,350.49,348.55,351.52
160.0651,6.9788,-0.095413,32.746,350.0,-0.010404,21.167,350.43,348.65,351.4
160.6651,6.9654,-0.095016,31.951,350.0,-0.010336,21.128,350.5,348.81,351.56
161.2651,6.9781,-0.094776,32.833,350.0,-0.010322,21.168,350.39,348.78,351.45
161.8027,6.9886,0.00082104,32.644,350.0,0.00011503,21.199,350.39,349.02,351.53
161.9548,6.9798,0.008767,25.189,0.52455,0.00079849,21.192,350.42,349.01,351.44
161.9578,6.9533,0.0020182,15.625,4.2754e-05,0.00043326,21.041,350.41,349.02,351.46
161.9608,6.9796,0.0068056,6.0613,3.4668e-09,0.00097807,21.183,350.4,349.02,351.48
161.9638,6.9986,0.0076854,0.0,2.8256e-13,0.0010332,21.203,350.41,349.01,351.52
161.9668,6.807,0.0073303,0.0,2.3029e-17,0.00045088,20.66,350.44,348.97,351.59
161.9698,6.9968,0.011299,0.0,1.8769e-21,0.00056678,21.198,350.46,348.92,351.66
161.9728,6.9293,0.0086857,0.0,1.5296e-25,0.0004337,21.069,350.49,348.88,351.73
161.9758,7.0159,0.0077233,0.0,1.2466e-29,0.00076142,21.27,350.47,348.94,351.7
161.9788,6.9231,0.0045266,0.0,1.0159e-33,0.00087503,21.021,350.45,348.99,351.68
161.9818,7.0202,0.004221,0.0,8.2787e-38,0.0010254,21.289,350.43,349.04,351.65
161.9848,6.9249,0.0046972,0.0,6.7459e-42,0.00099811,21.005,350.43,349.06,351.65
161.9878,7.0131,0.0055192,0.0,0.0,0.00062726,21.277,350.44,349.06,351.66
161.9908,6.9158,0.0075793,0.0,0.0,0.00063829,20.957,350.45,349.06,351.67
161.9938,7.0117,0.0086722,0.0,0.0,0.00077334,21.307,350.46,349.05,351.67
161.9968,6.9232,0.0082443,0.0,0.0,0.0011717,20.989,350.46,349.02,351.67
161.9998,6.9873,0.0081445,0.0,0.0,0.0011613,21.208,350.46,349.0,351.67
162.0028,6.9372,0.0074092,0.0,0.0,0.00074272,21.002,350.46,348.98,351.67
162.0058,6.9656,0.0075148,0.0,0.0,0.00036905,21.146,350.45,349.39,351.62
162.0088,6.9484,0.0091536,0.0,0.0,0.00034959,21.055,350.44,349.8,351.58
162.0118,6.9618,0.0076933,0.0,0.0,0.00043898,21.117,350.43,350.21,351.53
162.0148,6.9479,0.0065537,0.0,0.0,0.00075856,21.058,350.47,351.15,351.46
162.0178,6.9158,0.0043123,0.0,0.0,0.00089561,21.029,350.54,352.31,351.38
162.02079,23.981,0.10367,0.0,0.0,0.01179,71.969,350.6,353.48,351.3
162.02379,33.072,0.33386,0.0,0.0,0.036967,100.07,351.13,354.76,351.23
162.02679,36.166,0.58449,0.0,0.0,0.064956,109.7,352.46,356.25,351.17
162.02979,37.361,0.84443,0.0,0.0,0.095637,113.32,353.8,357.74,351.12
162.03279,37.937,1.0974,0.0,0.0,0.12655,115.02,355.15,359.22,351.07
162.03579,38.175,1.3454,0.0,0.0,0.15796,115.77,356.91,360.37,351.08
162.03879,38.328,1.5856,0.0,0.0,0.18887,116.25,358.68,361.51,351.1
162.04179,38.386,1.82,0.0,0.0,0.2192,116.41,360.44,362.66,351.12
162.04479,38.437,2.0418,0.0,0.0,0.24882,116.58,361.52,363.48,351.15
162.04779,38.48,2.2648,0.0,0.0,0.27979,116.7,362.3,364.16,351.19
162.05079,38.551,2.4803,0.0,0.0,0.31113,116.95,363.08,364.85,351.22
162.05379,38.632,2.6939,0.0,0.0,0.3434,117.17,363.83,365.42,351.24
162.05679,38.742,2.9066,0.0,0.0,0.37622,117.52,364.52,365.8,351.23
162.05979,38.87,3.1127,0.0,0.0,0.40841,117.9,365.21,366.18,351.23
162.06279,38.954,3.3181,0.0,0.0,0.44117,118.17,365.91,366.56,351.22
162.06579,39.094,3.5157,0.0,0.0,0.47326,118.58,366.66,366.98,351.25
162.06879,39.192,3.7106,0.0,0.0,0.50661,118.88,367.41,367.4,351.29
162.07179,39.309,3.8968,0.0,0.0,0.53999,119.24,368.17,367.82,351.33
162.07479,39.309,4.07,0.0,0.0,0.57209,119.23,368.75,368.24,351.39
162.07779,39.506,4.2453,0.0,0.0,0.60468,119.81,369.26,368.68,351.46
162.08079,39.583,4.42,0.0,0.0,0.63727,120.07,369.76,369.12,351.53
162.08379,39.723,4.5925,0.0,0.0,0.67084,120.49,370.17,369.46,351.59
162.08679,39.712,4.7562,0.0,0.0,0.70445,120.46,370.38,369.65,351.62
162.08979,39.75,4.9102,0.0,0.0,0.73777,120.59,370.6,369.84,351.65
162.09279,39.753,5.0547,0.0,0.0,0.77041,120.58,370.82,370.03,351.67
162.09579,39.829,5.1963,0.0,0.0,0.8029,120.82,370.91,370.09,351.76
162.09879,39.897,5.3414,0.0,0.0,0.83608,121.01,371.0,370.16,351.84
162.10179,40.018,5.4803,0.0,0.0,0.86808,121.39,371.09,370.22,351.92
162.10479,40.109,5.6221,0.0,0.0,0.90208,121.66,371.06,370.12,352.03
162.10779,40.157,5.7597,0.0,0.0,0.93714,121.8,370.98,369.95,352.14
162.11079,40.207,5.8876,0.0,0.0,0.97177,121.95,370.9,369.77,352.26
162.11379,40.215,6.0139,0.0,0.0,1.0064,121.98,370.73,369.54,352.35
162.11679,40.264,6.132,0.0,0.0,1.0386,122.14,370.42,369.21,352.38
162.11979,40.37,6.2535,0.0,0.0,1.0717,122.45,370.12,368.87,352.4
162.12279,40.481,6.3691,0.0,0.0,1.1048,122.76,369.8,368.54,352.43
162.12579,40.565,6.4832,0.0,0.0,1.1398,123.07,369.42,368.15,352.49
162.12879,40.714,6.5928,0.0,0.0,1.1759,123.5,369.04,367.77,352.56
162.13179,40.833,6.6976,0.0,0.0,1.2118,123.85,368.66,367.39,352.62
162.13479,40.979,6.8029,0.0,0.0,1.2476,124.27,368.32,367.0,352.7
162.13779,41.069,6.9059,0.0,0.0,1.2825,124.57,367.99,366.6,352.8
162.14079,41.21,7.0066,0.0,0.0,1.3167,124.99,367.67,366.2,352.89
162.14379,41.312,7.102,0.0,0.0,1.3511,125.31,367.37,365.84,352.96
162.14679,41.488,7.1924,0.0,0.0,1.3861,125.84,367.11,365.54,353.02
162.14979,41.627,7.2812,0.0,0.0,1.4235,126.26,366.86,365.24,353.07
162.15279,41.808,7.3651,0.0,0.0,1.458,126.82,366.6,364.94,353.13
162.15579,41.906,7.4539,0.0,0.0,1.4933,127.1,366.31,364.71,353.18
162.15878,42.126,7.5366,0.0,0.0,1.5266,127.78,366.02,364.48,353.24
162.16178,42.342,7.6171,0.0,0.0,1.5617,128.43,365.73,364.26,353.29
162.16478,42.222,7.6939,0.0,0.0,1.5985,128.43,365.42,363.94,353.33
162.16778,38.726,7.6962,0.0,0.0,1.6026,117.6,365.09,363.59,353.37
162.17078,37.048,7.7005,0.0,0.0,1.607,112.5,364.76,363.23,353.41
162.17378,36.032,7.7039,0.0,0.0,1.6089,109.38,364.44,362.84,353.46
162.17678,35.505,7.7099,0.0,0.0,1.6097,107.71,364.14,362.37,353.53
162.17978,35.171,7.7161,0.0,0.0,1.6106,106.7,363.84,361.91,353.6
162.18278,35.037,7.7213,0.0,0.0,1.6124,106.29,363.54,361.45,353.67
162.18578,34.907,7.7276,0.0,0.0,1.6168,105.87,363.14,361.01,353.76
162.18878,34.741,7.7317,0.0,0.0,1.6214,105.43,362.74,360.58,353.84
162.19178,33.794,7.732,0.0,0.0,1.6213,102.63,362.34,360.14,353.92
162.19478,31.169,7.7317,0.0,0.0,1.6186,94.797,362.0,359.83,354.0
162.19778,26.789,7.7245,0.0,0.0,1.6128,81.555,361.68,359.57,354.07
162.20078,10.492,7.7032,0.0,0.0,1.6039,33.727,361.36,359.32,354.14
162.20378,7.1808,7.6947,0.0,0.0,1.6003,22.255,361.12,359.16,354.21
162.20678,5.9978,7.6818,0.0,0.0,1.5972,18.555,361.01,359.16,354.26
162.20978,6.0616,7.6785,0.0,0.0,1.5973,18.381,360.9,359.16,354.32
162.21278,6.2833,7.6815,0.0,0.0,1.5982,19.029,360.79,359.16,354.37
162.21578,6.3505,7.6815,0.0,0.0,1.596,19.264,360.68,359.14,354.42
162.21878,6.1887,7.6822,0.0,0.0,1.5941,18.823,360.57,359.12,354.48
162.22178,6.3153,7.6845,0.0,0.0,1.5954,19.154,360.46,359.1,354.53
162.22478,6.1895,7.6834,0.0,0.0,1.5972,18.784,360.38,359.05,354.59
162.22778,6.3144,7.6817,0.0,0.0,1.5975,19.194,360.31,358.97,354.66
162.23078,6.2188,7.6817,0.0,0.0,1.5971,18.848,360.23,358.9,354.72
162.23378,6.2655,7.6851,0.0,0.0,1.5955,19.01,360.14,358.82,354.78
162.23678,6.2224,7.6859,0.0,0.0,1.5941,18.871,360.01,358.73,354.81
162.23978,6.2495,7.6841,0.0,0.0,1.5936,18.972,359.89,358.64,354.85
162.24278,6.236,7.6819,0.0,0.0,1.5948,18.89,359.76,358.55,354.89
162.24578,6.2503,7.682,0.0,0.0,1.5972,18.996,359.59,358.43,354.93
162.24878,6.2486,7.68,0.0,0.0,1.5978,18.932,359.41,358.31,354.98
162.25178,6.2368,7.682,0.0,0.0,1.5979,18.964,359.24,358.19,355.02
162.25478,6.3107,7.6849,0.0,0.0,1.5963,19.139,359.11,358.08,355.08
162.25778,6.251,7.6884,0.0,0.0,1.5966,18.961,359.0,357.97,355.14
162.26078,6.3352,7.6883,0.0,0.0,1.5974,19.194,358.89,357.86,355.21
162.26378,6.2279,7.6866,0.0,0.0,1.5993,18.913,358.77,357.74,355.27
162.26678,6.3374,7.685,0.0,0.0,1.5992,19.207,358.63,357.6,355.32
162.26978,6.2386,7.6855,0.0,0.0,1.5978,18.926,358.48,357.45,355.38
162.27278,6.3782,7.6862,0.0,0.0,1.5959,19.348,358.33,357.3,355.43
162.27578,6.2452,7.6886,0.0,0.0,1.5952,18.924,358.17,357.15,355.47
162.27878,6.3109,7.6865,0.0,0.0,1.5953,19.167,358.01,357.0,355.5
162.28178,6.2826,7.6847,0.0,0.0,1.5966,19.054,357.84,356.84,355.54
162.28478,6.3005,7.6819,0.0,0.0,1.5978,19.14,357.71,356.68,355.57
162.28778,6.3201,7.6831,0.0,0.0,1.5988,19.145,357.58,356.52,355.6
162.29078,6.3435,7.6845,0.0,0.0,1.5981,19.279,357.45,356.35,355.62
162.29378,6.3922,7.6858,0.0,0.0,1.5963,19.338,357.32,356.18,355.66
162.29677,6.4522,7.6884,0.0,0.0,1.5968,19.591,357.17,356.0,355.7
162.29977,6.5537,7.6885,0.0,0.0,1.5983,19.783,357.03,355.82,355.75
162.30277,6.5458,7.6865,0.0,0.0,1.5999,19.894,356.88,355.64,355.79
162.30577,6.6525,7.6867,0.0,0.0,1.6001,20.118,356.71,355.47,355.84
162.30877,6.6029,7.6861,0.0,0.0,1.5976,20.065,356.53,355.31,355.89
162.31177,6.6839,7.6867,0.0,0.0,1.5952,20.2,356.36,355.15,355.93
162.31477,6.5342,7.6864,0.0,0.0,1.5943,19.874,356.23,355.0,355.96
162.31777,6.7002,7.6861,0.0,0.0,1.5958,20.288,356.11,354.85,355.99
162.32077,6.5095,7.685,0.0,0.0,1.5976,19.798,355.99,354.7,356.02
162.32377,6.7133,7.6854,0.0,0.0,1.6001,20.316,355.86,354.55,356.05
162.32677,6.4954,7.6838,0.0,0.0,1.5997,19.737,355.69,354.36,356.07
162.32977,6.7082,7.6877,0.0,0.0,1.5992,20.346,355.53,354.18,356.1
162.33277,6.4888,7.689,0.0,0.0,1.5978,19.682,355.36,354.0,356.13
162.33577,6.7305,7.6895,0.0,0.0,1.5976,20.431,355.19,353.8,356.16
162.33877,6.5248,7.6866,0.0,0.0,1.5977,19.763,355.02,353.6,356.2
162.34177,6.7141,7.6886,0.0,0.0,1.6006,20.402,354.85,353.4,356.24
162.34477,6.5521,7.6869,0.0,0.0,1.5994,19.842,354.7,353.21,356.25
162.34777,6.6845,7.6899,0.0,0.0,1.598,20.327,354.56,353.03,356.26
162.35077,6.5898,7.6904,0.0,0.0,1.5968,19.922,354.43,352.85,356.27
162.35377,6.6554,7.6896,0.0,0.0,1.5961,20.243,354.28,352.69,356.27
162.35677,6.6217,7.6889,0.0,0.0,1.5977,20.038,354.12,352.56,356.25
162.35977,6.6087,7.687,0.0,0.0,1.5996,20.115,353.95,352.43,356.24
162.36277,6.6763,7.686,0.0,0.0,1.6002,20.202,353.79,352.3,356.22
162.36577,6.5866,7.687,0.0,0.0,1.6003,20.039,353.65,352.16,356.22
162.36877,6.7128,7.6895,0.0,0.0,1.5992,20.289,353.52,352.01,356.22
162.37177,6.5593,7.6914,0.0,0.0,1.5986,19.945,353.38,351.87,356.22
162.37477,6.7382,7.69,0.0,0.0,1.5983,20.397,353.24,351.67,356.25
162.37777,6.5628,7.6878,0.0,0.0,1.5992,19.925,353.11,351.45,356.29
162.38077,6.7761,7.6883,0.0,0.0,1.6007,20.537,352.97,351.24,356.34
162.38377,6.5526,7.6874,0.0,0.0,1.5991,19.872,352.84,351.03,356.39
162.38677,6.7706,7.6904,0.0,0.0,1.5978,20.541,352.7,350.85,356.44
162.38977,6.5639,7.6901,0.0,0.0,1.5962,19.899,352.56,350.67,356.5
162.39277,6.7722,7.6928,0.0,0.0,1.5978,20.554,352.43,350.49,356.55
162.39577,6.5993,7.6891,0.0,0.0,1.5988,19.988,352.28,350.38,356.57
162.39877,6.7735,7.6874,0.0,0.0,1.6003,20.607,352.14,350.27,356.59
162.40177,6.6174,7.6857,0.0,0.0,1.6007,20.029,351.99,350.16,356.61
162.40477,6.7438,7.6889,0.0,0.0,1.6011,20.517,351.81,350.02,356.61
162.40777,6.679,7.6899,0.0,0.0,1.5987,20.204,351.62,349.88,356.61
162.41077,6.6993,7.6943,0.0,0.0,1.5996,20.387,351.43,349.73,356.61
162.41377,6.7127,7.6932,0.0,0.0,1.5999,20.277,351.26,349.59,356.6
162.41677,6.6799,7.6919,0.0,0.0,1.6019,20.341,351.14,349.44,356.59
162.41977,6.763,7.6915,0.0,0.0,1.6023,20.45,351.01,349.29,356.57
162.42277,6.639,7.691,0.0,0.0,1.6004,20.195,350.88,349.15,356.55
162.42577,6.7945,7.6927,0.0,0.0,1.5982,20.557,350.76,349.03,356.56
162.42877,6.6233,7.6922,0.0,0.0,1.5975,20.131,350.64,348.91,356.57
162.43177,6.8261,7.6918,0.0,0.0,1.5978,20.677,350.53,348.79,356.58
162.43476,6.6136,7.6892,0.0,0.0,1.5997,20.083,350.38,348.66,356.59
162.43776,6.8329,7.6875,0.0,0.0,1.6002,20.734,350.23,348.51,356.6
162.44076,6.6204,7.6882,0.0,0.0,1.6017,20.085,350.07,348.37,356.61
162.44376,6.8409,7.6907,0.0,0.0,1.6009,20.768,349.92,348.21,356.61
162.44676,6.626,7.6906,0.0,0.0,1.5987,20.081,349.77,348.04,356.62
162.44976,6.8214,7.6925,0.0,0.0,1.5986,20.728,349.63,347.86,356.63
162.45276,6.666,7.6915,0.0,0.0,1.5996,20.183,349.48,347.69,356.64
162.45576,6.8046,7.6912,0.0,0.0,1.6019,20.682,349.32,347.54,356.65
162.45876,6.6963,7.6901,0.0,0.0,1.6011,20.262,349.15,347.4,356.66
162.46176,6.7746,7.691,0.0,0.0,1.5994,20.615,348.99,347.25,356.67
162.46476,6.7428,7.6926,0.0,0.0,1.5977,20.388,348.86,347.11,356.65
162.46776,6.7384,7.6933,0.0,0.0,1.5977,20.51,348.75,346.96,356.63
162.47076,6.7912,7.6908,0.0,0.0,1.5983,20.541,348.65,346.82,356.6
162.47376,6.707,7.6892,0.0,0.0,1.5996,20.41,348.54,346.67,356.57
162.47676,6.8435,7.6906,0.0,0.0,1.6027,20.713,348.45,346.52,356.53
162.47976,6.7091,7.6902,0.0,0.0,1.6022,20.406,348.36,346.38,356.5
162.48276,6.8757,7.692,0.0,0.0,1.6009,20.822,348.27,346.23,356.46
162.48576,6.6855,7.692,0.0,0.0,1.5989,20.314,348.13,346.08,356.48
162.48876,6.8833,7.6937,0.0,0.0,1.5995,20.851,347.99,345.92,356.5
162.49176,6.6701,7.691,0.0,0.0,1.6002,20.25,347.86,345.77,356.51
162.49476,6.8989,7.6919,0.0,0.0,1.602,20.898,347.71,345.64,356.53
162.49776,6.6948,7.691,0.0,0.0,1.6008,20.292,347.55,345.53,356.54
162.50076,6.902,7.6942,0.0,0.0,1.6005,20.968,347.4,345.42,356.54
162.50376,6.716,7.6926,0.0,0.0,1.598,20.346,347.25,345.32,356.54
162.50676,6.8815,7.6949,0.0,0.0,1.5991,20.905,347.13,345.21,356.51
162.50976,6.7441,7.692,0.0,0.0,1.5993,20.427,347.0,345.1,356.49
162.51276,6.8511,7.6913,0.0,0.0,1.6015,20.849,346.87,344.99,356.46
162.51576,6.7976,7.6911,0.0,0.0,1.6032,20.56,346.77,344.83,356.45
162.51876,6.8192,7.6912,0.0,0.0,1.6023,20.735,346.67,344.68,356.44
162.52176,6.8348,7.6925,0.0,0.0,1.6006,20.67,346.57,344.52,356.43
162.52476,6.7901,7.6928,0.0,0.0,1.5994,20.668,346.45,344.4,356.42
162.52776,6.8709,7.694,0.0,0.0,1.6,20.8,346.32,344.29,356.4
162.53076,6.7598,7.6934,0.0,0.0,1.6021,20.564,346.2,344.18,356.38
162.53376,6.9171,7.6917,0.0,0.0,1.6023,20.919,346.07,344.07,356.37
162.53676,6.7495,7.6926,0.0,0.0,1.6014,20.513,345.93,343.95,356.36
162.53976,6.9424,7.697,0.0,0.0,1.6006,21.014,345.79,343.83,356.35
162.54276,6.7379,7.6961,0.0,0.0,1.5988,20.453,345.66,343.71,356.34
162.54576,6.9541,7.6943,0.0,0.0,1.5989,21.085,345.56,343.6,356.34
162.54876,6.7452,7.6919,0.0,0.0,1.6001,20.488,345.47,343.49,356.34
162.55176,6.9598,7.6915,0.0,0.0,1.6023,21.112,345.38,343.38,356.34
162.55476,6.7621,7.6899,0.0,0.0,1.6022,20.508,345.27,343.28,356.31
162.55776,6.9472,7.6926,0.0,0.0,1.6021,21.1,345.15,343.18,356.28
162.56076,6.7816,7.6939,0.0,0.0,1.6002,20.528,345.04,343.08,356.24
162.56376,6.9267,7.696,0.0,0.0,1.6005,21.063,344.91,342.97,356.21
162.56676,6.8144,7.6948,0.0,0.0,1.601,20.635,344.77,342.85,356.21
162.56976,6.8906,7.6939,0.0,0.0,1.6032,20.949,344.64,342.74,356.2
162.57275,6.8529,7.6937,0.0,0.0,1.603,20.721,344.5,342.62,356.19
162.57575,6.8577,7.6951,0.0,0.0,1.602,20.878,344.39,342.48,356.21
162.57875,6.9163,7.6967,0.0,0.0,1.6002,20.923,344.28,342.34,356.22
162.58175,6.837,7.6982,0.0,0.0,1.5999,20.782,344.17,342.21,356.24
162.5843,6.8244,7.6924,0.0,0.0,1.6019,20.731,344.08,342.11,356.23
163.1843,6.8431,7.7027,0.0,0.0,1.6054,20.758,325.61,327.11,180.44
163.7843,6.8961,7.7124,0.0,0.0,1.61,20.92,308.1,313.55,165.0
164.3843,6.9367,7.723,0.0,0.0,1.615,21.042,278.14,301.52,123.79
164.9843,6.9672,7.7343,0.0,0.0,1.6204,21.136,244.79,288.34,51.916
165.5843,6.964,7.744,0.0,0.0,1.625,21.126,207.04,232.33,31.497
166.1843,6.9803,7.7516,0.0,0.0,1.6288,21.177,165.29,133.25,26.094
166.7843,6.9613,7.7574,0.0,0.0,1.6315,21.114,129.58,82.75,24.418
167.2931,6.9494,7.7644,0.0,0.0,1.6349,21.085,96.053,66.094,23.434
167.8931,6.9528,7.7732,0.0,0.0,1.6392,21.09,70.099,53.811,23.022
168.4931,6.8763,7.7802,0.0,0.0,1.6427,20.862,55.278,46.195,22.6
169.0931,6.8688,7.7856,0.0,0.0,1.6452,20.837,47.799,40.93,21.933
169.6931,6.8577,7.7889,0.0,0.0,1.6469,20.8,41.831,38.943,20.906
170.2931,6.8666,7.7918,0.0,0.0,1.6482,20.834,37.628,39.133,20.598
170.8931,6.8638,7.7934,0.0,0.0,1.6492,20.819,34.68,30.82,20.366
171.4931,6.8589,7.7957,0.0,0.0,1.6502,20.809,32.388,28.938,20.058
172.0931,6.8647,7.7986,0.0,0.0,1.6516,20.823,30.523,27.63,19.941
172.6931,7.0822,7.8,0.0,0.0,1.6522,21.487,28.914,26.663,19.746
173.2931,6.8969,7.8006,0.0,0.0,1.6527,20.922,29.866,30.549,22.285
173.8931,6.9906,7.8023,0.0,0.0,1.6534,21.206,31.034,39.127,24.999
174.4931,6.9762,7.8039,0.0,0.0,1.6542,21.167,32.125,39.133,27.461
175.0931,6.7899,7.8053,0.0,0.0,1.6549,20.598,33.154,39.133,29.615
175.6931,6.8558,7.8078,0.0,0.0,1.6563,20.798,34.049,39.133,31.509
176.2931,6.8009,7.8128,0.0,0.0,1.6587,20.632,34.916,39.133,33.171
176.8931,6.783,7.8164,0.0,0.0,1.6603,20.574,35.648,38.844,34.534
177.4931,6.7839,7.8178,0.0,0.0,1.6611,20.577,36.379,39.528,35.721
178.0931,6.6145,7.81,0.0,0.0,1.6573,20.065,36.729,39.936,36.576
178.6931,6.6023,7.8094,0.0,0.0,1.6571,20.027,37.426,40.508,37.6
179.2931,4.4315,7.7934,0.0,0.0,1.649,13.447,37.835,40.918,38.312
179.4931,3.2918,7.7846,0.0,0.0,1.6447,9.9846,37.954,41.037,38.477