File: examples/dan-msc-case-studies/CS4/data/01 raw data/hyde_test_033.csv
Time(sec),Force(kN),Jaw(mm),PowAngle(deg),PTemp,Strain,Stress(MPa),TC1(C),TC2(C),TC3(C)
0.0,3.9432,0.0021473,0.0,0.0025966,0.00022195,11.938,20.86,21.327,20.878
0.6,3.9145,0.0023084,0.0,1.621,0.00025457,11.875,20.678,21.291,20.931
1.2,3.8679,0.0026597,0.0,3.421,0.0003174,11.735,20.763,21.287,20.974
1.8,3.8353,0.0025835,0.0,5.221,0.00026846,11.632,20.731,21.284,21.009
2.4,3.8011,0.0024409,0.0,7.021,0.00023942,11.53,20.713,21.278,20.962
3.0,3.7854,0.0023964,0.0,8.821,0.00024438,11.482,20.72,21.285,20.948
3.6,3.7641,0.0023068,0.0,10.621,0.00028888,11.422,20.737,21.276,20.946
4.2,3.7625,0.0023215,0.0,12.421,0.00028007,11.41,20.728,21.253,20.945
4.8,3.7477,0.002368,0.0,14.221,0.00026254,11.372,20.721,21.273,20.976
5.4,3.7417,0.0026005,0.0,16.021,0.00030528,11.349,20.707,21.307,20.949
6.0,3.7318,0.0025779,0.0,17.821,0.00025917,11.322,20.714,21.241,20.91
6.6,3.74,0.0027824,0.0,19.621,0.00027816,11.342,20.715,21.33,20.945
7.2,3.7243,0.0029217,7.172,21.421,0.00031188,11.301,20.708,21.291,20.914
7.8,3.7338,0.0038857,22.973,23.221,0.00045904,11.326,21.074,21.66,21.377
8.3097,3.7304,0.0033135,24.906,24.762,0.00034696,11.319,22.74,23.257,23.198
8.9097,3.7343,0.0029595,20.885,26.55,0.00029092,11.326,25.512,25.606,25.726
9.5097,3.7212,0.0024607,21.593,28.35,0.00024407,11.289,27.505,26.992,27.161
10.1097,3.737,0.0010357,23.889,30.15,0.00012261,11.333,29.109,28.297,28.561
10.7097,3.7267,0.001088,23.914,31.95,0.00016123,11.308,31.151,30.077,30.615
11.3097,3.7297,0.00079738,22.848,33.75,0.00010049,11.312,33.261,38.723,32.452
11.9097,3.7309,0.00024592,24.068,35.55,3.1124e-05,11.321,34.997,38.761,34.049
12.5097,3.7342,-0.00051853,25.115,37.35,-4.678e-05,11.326,36.807,38.761,35.726
13.1097,3.7372,-0.0006597,23.939,39.15,-0.00010541,11.338,38.903,38.84,37.834
13.5114,3.7329,-0.0012843,24.32,40.355,-0.00010035,11.32,40.029,38.484,38.85
14.1114,3.7353,-0.0020364,24.845,42.155,-0.00021635,11.333,41.779,39.973,40.486
14.7114,3.7296,-0.0030359,23.947,43.955,-0.00031422,11.31,43.837,41.897,42.483
15.3114,3.7367,-0.0031515,25.992,45.755,-0.00032611,11.338,45.393,43.286,43.972
15.9114,3.7343,-0.0033869,24.972,47.555,-0.00040215,11.324,47.391,45.204,45.882
16.5114,3.7402,-0.0039798,25.53,49.355,-0.00046258,11.35,49.176,46.847,47.574
17.1114,3.7395,-0.0044855,26.191,51.155,-0.00048568,11.342,50.911,48.4,49.245
17.7114,3.745,-0.00516,26.28,52.955,-0.00052312,11.363,52.705,50.214,51.064
18.3114,3.7353,-0.0057504,27.022,54.755,-0.00061391,11.33,54.534,51.872,52.75
18.9114,3.7458,-0.0061746,26.373,56.555,-0.0006668,11.364,56.411,53.691,54.52
19.5114,3.735,-0.0072708,26.515,58.355,-0.00079637,11.329,58.198,55.391,56.23
20.1114,3.7528,-0.0086618,26.521,60.155,-0.00098582,11.385,60.071,57.069,58.052
20.7114,3.7324,-0.0084725,26.259,61.955,-0.00095265,11.324,61.943,58.822,59.801
21.3114,3.7441,-0.0088222,26.791,63.755,-0.00096332,11.359,63.66,60.388,61.379
21.9114,3.7317,-0.0097124,26.777,65.555,-0.0010118,11.322,65.51,62.128,63.241
22.5114,3.7473,-0.010082,27.21,67.355,-0.0010863,11.366,67.272,63.826,64.948
23.1114,3.7344,-0.010729,27.464,69.155,-0.0011597,11.332,69.045,65.514,66.701
23.7114,3.7521,-0.011121,27.196,70.955,-0.0011972,11.38,70.918,67.262,68.52
24.3114,3.7513,-0.011724,27.469,72.755,-0.001304,11.383,72.656,68.997,70.222
24.9114,3.7501,-0.012684,27.466,74.555,-0.0014192,11.373,74.497,70.588,71.922
25.5114,3.7504,-0.014532,27.406,76.355,-0.0015932,11.38,76.288,72.371,73.64
26.1114,3.7536,-0.014883,28.026,78.155,-0.001587,11.382,78.049,73.972,75.41
26.7114,3.7547,-0.014509,26.81,79.955,-0.0015675,11.391,80.138,76.03,77.356
27.3114,3.7531,-0.015066,28.636,81.755,-0.0016475,11.383,81.555,77.257,78.584
27.9114,3.7688,-0.015748,27.862,83.555,-0.0016989,11.435,83.503,79.057,80.597
28.5114,3.757,-0.016131,28.501,85.355,-0.0017876,11.395,85.254,80.816,82.246
29.1114,3.7654,-0.016947,28.056,87.155,-0.0018765,11.423,87.121,82.487,84.072
29.7114,3.7641,-0.017634,28.463,88.955,-0.001925,11.421,88.922,84.213,85.808
30.3114,3.7808,-0.018845,28.212,90.755,-0.0020184,11.468,90.732,85.936,87.573
30.9114,3.765,-0.020724,28.587,92.555,-0.0022376,11.421,92.488,87.601,89.325
31.5114,3.776,-0.02013,28.379,94.355,-0.0021897,11.453,94.32,89.461,91.075
32.1114,3.7603,-0.02051,27.914,96.155,-0.002215,11.406,95.787,90.814,92.391
32.7114,3.7783,-0.021069,28.276,97.955,-0.0023388,11.458,97.578,92.519,94.218
33.3114,3.7778,-0.021795,29.432,99.755,-0.0024045,11.463,99.146,94.1,95.835
33.91141,3.7785,-0.022605,28.665,101.56,-0.0024726,11.458,101.16,95.924,97.844
34.51141,3.7853,-0.023503,29.002,103.36,-0.0025197,11.488,102.88,97.685,99.512
35.11141,3.7889,-0.02487,27.541,105.16,-0.0026985,11.489,104.58,99.185,101.06
35.71141,3.7969,-0.026076,29.605,106.96,-0.0028373,11.521,105.93,100.51,102.35
36.31141,3.7916,-0.025672,29.219,108.76,-0.0027882,11.501,107.9,102.51,104.42
36.91141,3.7966,-0.026425,29.426,110.56,-0.002906,11.52,109.7,104.18,106.16
37.51141,3.7952,-0.0271,29.377,112.36,-0.0029994,11.51,111.5,105.91,107.91
38.11141,3.8105,-0.027954,29.777,114.16,-0.0030602,11.562,113.26,107.55,109.6
38.71141,3.803,-0.028698,29.798,115.96,-0.0031011,11.533,115.08,109.34,111.45
39.31141,3.8188,-0.03116,29.48,117.76,-0.0033823,11.584,116.98,111.08,113.31
39.91141,3.8035,-0.031005,29.88,119.56,-0.0033714,11.539,118.66,112.8,114.98
40.51141,3.8173,-0.031217,30.161,121.36,-0.0033825,11.578,120.47,114.61,116.87
40.9428,3.8214,-0.031541,29.063,122.66,-0.0034904,11.593,121.98,116.11,118.33
41.5428,3.8151,-0.032651,30.639,124.45,-0.0035824,11.574,123.45,117.48,119.74
42.1428,3.8244,-0.033085,28.757,126.25,-0.0035837,11.599,125.38,119.47,121.74
42.7428,3.8224,-0.033965,30.72,128.05,-0.0036702,11.598,126.84,120.75,122.94
43.3428,3.8276,-0.036201,29.569,129.85,-0.0039517,11.608,128.43,122.41,124.67
43.9428,3.817,-0.035479,30.15,131.65,-0.0038529,11.581,130.02,123.89,126.11
44.5428,3.8312,-0.036535,31.743,133.45,-0.003991,11.618,131.47,125.29,127.64
45.1428,3.8245,-0.037334,29.505,135.25,-0.0041099,11.604,133.83,127.74,130.19
45.7428,3.8282,-0.037943,30.84,137.05,-0.0041631,11.61,135.32,129.08,131.46
46.3428,3.8398,-0.03906,31.04,138.85,-0.0042547,11.651,137.05,130.76,133.19
46.9428,3.8356,-0.041804,30.699,140.65,-0.0045241,11.634,139.05,132.76,135.23
47.5428,3.8394,-0.0412,30.606,142.45,-0.0044837,11.649,140.89,134.53,136.97
48.1428,3.836,-0.041715,31.069,144.25,-0.0045386,11.634,142.51,136.05,138.51
48.7428,3.8473,-0.042595,31.846,146.05,-0.0046496,11.673,144.26,137.75,140.28
49.3428,3.835,-0.043198,30.9,147.85,-0.004747,11.633,146.28,139.81,142.37
49.9428,3.8535,-0.043966,31.323,149.65,-0.0048181,11.691,148.01,141.43,143.9
50.5428,3.8462,-0.045715,31.353,151.45,-0.0049846,11.667,149.8,143.19,145.75
51.1428,3.857,-0.047403,31.14,153.25,-0.0051177,11.7,151.63,144.98,147.6
51.7428,3.8389,-0.047391,31.658,155.05,-0.0051659,11.648,153.4,146.57,149.25
52.3428,3.8515,-0.047886,31.516,156.85,-0.0052045,11.68,155.26,148.48,151.19
52.9428,3.8457,-0.048505,30.842,158.65,-0.0052868,11.668,157.11,150.28,152.86
53.5428,3.8619,-0.049706,32.845,160.45,-0.0054615,11.712,158.56,151.62,154.3
54.1428,3.8573,-0.050517,31.277,162.25,-0.0055367,11.706,160.75,153.98,156.73
54.7428,3.8552,-0.053607,31.046,164.05,-0.0058451,11.694,162.57,155.59,158.21
55.3428,3.8565,-0.053659,32.394,165.85,-0.0057985,11.702,164.07,157.05,159.69
55.9428,3.8486,-0.053906,31.899,167.65,-0.0058733,11.672,166.04,159.14,161.82
56.5428,3.8569,-0.054475,31.452,169.45,-0.0059227,11.702,167.96,160.93,163.58
57.1428,3.8562,-0.055166,32.31,171.25,-0.0060036,11.696,169.53,162.4,165.06
57.7428,3.8667,-0.055785,31.889,173.05,-0.0061137,11.731,171.43,164.25,166.98
58.3428,3.8618,-0.057258,31.887,174.85,-0.0062779,11.714,173.25,166.04,168.72
58.9428,3.8669,-0.060585,32.214,176.65,-0.0065959,11.731,175.01,167.75,170.46
59.5428,3.8543,-0.059774,31.872,178.45,-0.0064655,11.691,176.88,169.55,172.34
60.1428,3.8655,-0.060208,31.882,180.25,-0.006547,11.727,178.63,171.16,173.98
60.74281,3.8554,-0.061357,32.422,182.05,-0.0066746,11.697,180.39,172.9,175.73
61.34281,3.8686,-0.062113,32.155,183.85,-0.0067475,11.733,182.27,174.66,177.6
61.94281,3.863,-0.062544,32.366,185.65,-0.0068385,11.724,184.01,176.27,179.19
62.54281,3.8711,-0.065659,32.631,187.45,-0.0071966,11.742,185.82,177.96,180.95
63.14281,3.8695,-0.066179,32.058,189.25,-0.0072006,11.741,187.74,179.81,182.83
63.74281,3.8682,-0.065987,32.648,191.05,-0.0071575,11.732,189.41,181.44,184.38
64.34281,3.8662,-0.067304,32.735,192.85,-0.0073019,11.733,191.21,183.24,186.32
64.94281,3.86,-0.067774,31.941,194.65,-0.0073819,11.706,193.11,184.83,188.12
65.54281,3.8681,-0.068653,33.016,196.45,-0.0074585,11.738,194.73,186.48,189.67
66.14281,3.8692,-0.070505,32.172,198.25,-0.0077126,11.733,196.7,188.45,191.71
66.74281,3.8717,-0.072161,32.791,200.05,-0.0078719,11.746,198.44,190.08,193.32
67.34281,3.8593,-0.07218,33.354,201.85,-0.0078792,11.704,200.12,191.71,194.98
67.94281,3.8729,-0.073104,33.03,203.65,-0.0079311,11.752,201.98,193.45,196.74
68.54281,3.8577,-0.074032,33.167,205.45,-0.0080263,11.702,203.75,195.19,198.53
69.14281,3.8739,-0.074774,32.876,207.25,-0.0081482,11.752,205.69,196.99,200.39
69.74281,3.8662,-0.076172,32.87,209.05,-0.0082881,11.729,207.44,198.61,202.02
70.34281,3.8781,-0.079539,33.456,210.85,-0.0086508,11.765,209.2,200.37,203.91
70.94281,3.8572,-0.077787,32.761,212.65,-0.0084986,11.703,211.09,202.16,205.64
71.54281,3.8739,-0.079121,33.777,214.45,-0.0086326,11.75,212.69,203.77,207.42
72.14281,3.8603,-0.080069,32.759,216.25,-0.0087013,11.713,214.81,205.85,209.48
72.74281,3.8686,-0.08063,32.899,218.05,-0.0087418,11.732,216.45,207.29,210.9
73.34281,3.868,-0.081626,32.886,219.85,-0.0088787,11.739,218.35,209.11,212.82
73.872,3.8673,-0.085391,33.784,221.44,-0.0093173,11.735,219.72,210.45,214.12
74.472,3.855,-0.0843,32.955,223.24,-0.0091543,11.689,221.71,212.38,216.27
75.072,3.8665,-0.084863,33.22,225.04,-0.0092051,11.732,223.49,214.0,217.92
75.6139,3.8704,-0.085475,32.86,226.66,-0.0092742,11.742,225.21,215.63,219.52
76.2139,3.8595,-0.086413,33.469,228.46,-0.0093636,11.708,226.86,217.27,221.21
76.8139,3.8734,-0.087163,33.782,230.26,-0.00949,11.752,228.54,218.92,222.95
77.4139,3.8664,-0.091326,33.542,232.06,-0.0099268,11.731,230.48,220.75,224.87
78.0139,3.8676,-0.090086,33.105,233.86,-0.0098048,11.732,232.33,222.42,226.55
78.6139,3.8628,-0.090498,34.389,235.66,-0.0098828,11.719,233.76,223.86,227.82
79.2139,3.8704,-0.091726,33.722,237.46,-0.0099985,11.739,235.85,225.82,230.17
79.8139,3.8665,-0.092351,33.754,239.26,-0.010032,11.73,237.56,227.39,231.64
80.4139,3.8737,-0.093863,34.318,241.06,-0.010178,11.747,239.28,229.1,233.48
81.0139,3.8675,-0.097226,32.349,242.86,-0.010563,11.736,241.56,231.33,235.74
81.6139,3.8651,-0.095944,33.466,244.66,-0.010431,11.723,243.09,232.81,237.15
82.2139,3.8628,-0.097153,34.185,246.46,-0.010563,11.722,244.66,234.4,238.88
82.8139,3.8608,-0.097644,33.114,248.26,-0.010656,11.708,246.76,236.33,240.96
83.4139,3.8694,-0.098373,33.775,250.06,-0.010721,11.742,248.41,237.87,242.35
84.0139,3.8693,-0.10175,33.929,251.86,-0.011084,11.734,250.14,239.5,244.14
84.6139,3.8621,-0.10216,33.857,253.66,-0.011069,11.716,251.99,241.38,246.09
85.2139,3.856,-0.10181,32.668,255.46,-0.011064,11.697,254.1,243.27,247.93
85.8139,3.875,-0.10343,34.648,257.26,-0.011247,11.755,255.46,244.66,249.27
86.4139,3.8643,-0.10387,33.556,259.06,-0.011274,11.72,257.57,246.69,251.41
87.0139,3.8741,-0.10597,33.432,260.86,-0.011556,11.75,259.39,248.34,253.0
87.6139,3.87,-0.10759,35.285,262.66,-0.011732,11.738,260.7,249.66,254.44
88.2139,3.8681,-0.10743,32.968,264.46,-0.011692,11.733,263.17,252.11,257.13
88.8139,3.8618,-0.10852,34.635,266.26,-0.011766,11.717,264.51,253.26,258.1
89.4139,3.8739,-0.10928,34.48,268.06,-0.011846,11.749,266.4,255.19,260.23
90.0139,3.8703,-0.1111,33.773,269.86,-0.012098,11.742,268.39,257.07,262.11
90.6139,3.8671,-0.11263,34.479,271.66,-0.01222,11.722,269.94,258.46,263.43
91.2139,3.8595,-0.11289,34.47,273.46,-0.012285,11.712,271.81,260.29,265.55
91.8139,3.8625,-0.11356,33.77,275.26,-0.012383,11.716,273.78,262.26,267.3
92.4139,3.8696,-0.11431,34.796,277.06,-0.012445,11.744,275.31,263.62,268.77
93.0139,3.8692,-0.11656,34.407,278.86,-0.012669,11.733,277.22,265.58,270.85
93.6139,3.8689,-0.11829,35.17,280.66,-0.012813,11.736,278.86,267.24,272.56
94.2139,3.857,-0.11818,34.364,282.46,-0.012844,11.695,280.89,269.2,274.58
94.81391,3.8738,-0.11893,34.644,284.26,-0.012904,11.754,282.61,271.01,276.33
95.41391,3.8586,-0.11922,34.386,286.06,-0.012952,11.704,284.48,272.72,277.99
96.01391,3.8833,-0.12236,35.907,287.86,-0.013361,11.783,285.93,274.19,279.53
96.61391,3.8547,-0.12284,33.415,289.66,-0.01336,11.691,288.4,276.42,282.04
97.21391,3.8692,-0.12336,35.534,291.46,-0.013397,11.736,289.61,277.65,282.94
97.81391,3.8623,-0.12461,34.724,293.26,-0.0135,11.718,291.78,279.84,285.46
98.41391,3.8757,-0.12466,34.639,295.06,-0.013536,11.755,293.5,281.34,286.91
99.01391,3.8714,-0.12726,34.577,296.86,-0.013841,11.743,295.36,283.22,288.8
99.61391,3.8722,-0.12819,34.842,298.66,-0.013904,11.742,297.02,284.86,290.45
100.21391,3.86,-0.1287,35.534,300.46,-0.014009,11.711,298.68,286.44,292.15
100.81391,3.8728,-0.12883,33.779,302.26,-0.01403,11.743,300.94,288.63,294.39
101.41391,4.1483,-0.12815,36.121,304.06,-0.013923,12.585,302.09,289.67,295.37
102.01391,4.5841,-0.12683,34.586,305.86,-0.013769,13.905,304.34,291.93,297.8
102.61391,4.8157,-0.12633,34.635,307.66,-0.013692,14.609,306.14,293.72,299.5
103.21391,4.885,-0.12526,35.033,309.46,-0.013613,14.816,307.89,295.35,301.1
103.81391,4.9064,-0.12565,35.533,311.26,-0.013638,14.887,309.58,296.97,302.61
104.41391,4.9092,-0.12531,34.318,313.06,-0.013631,14.889,311.71,298.94,304.59
105.01391,4.9249,-0.12734,35.5,314.86,-0.013888,14.94,313.09,300.24,305.84
105.61391,4.9229,-0.12922,35.203,316.66,-0.014032,14.93,315.0,302.06,307.6
106.1021,4.9203,-0.12818,34.246,318.14,-0.013937,14.928,316.76,303.62,309.25
106.7021,4.923,-0.12915,36.139,319.93,-0.014019,14.933,317.99,304.91,310.37
107.3021,4.9362,-0.12922,34.0,321.73,-0.014042,14.975,320.39,307.07,312.63
107.9021,4.9359,-0.12983,35.767,323.53,-0.014148,14.975,321.71,308.64,313.8
108.5021,4.9588,-0.13414,36.067,325.33,-0.014557,15.042,323.83,310.77,316.18
109.1021,4.9437,-0.1334,35.07,327.13,-0.01448,14.999,327.59,314.56,320.25
109.7021,4.9452,-0.13261,34.563,328.93,-0.014374,15.0,329.3,316.49,321.36
110.3021,4.9724,-0.13413,36.331,330.73,-0.014562,15.087,330.63,318.5,323.25
110.9021,4.9677,-0.13379,34.197,332.53,-0.014529,15.067,332.73,320.6,325.04
111.5021,4.9801,-0.13831,37.134,334.33,-0.015002,15.108,333.73,321.92,326.2
112.1021,4.9583,-0.13555,33.805,336.13,-0.014758,15.037,336.48,324.66,328.97
112.7021,4.9784,-0.13694,36.395,337.93,-0.01489,15.104,337.63,325.98,330.25
113.3021,4.9736,-0.13683,35.101,339.73,-0.014852,15.087,339.76,328.12,332.36
113.9021,4.9838,-0.13775,36.917,341.53,-0.014928,15.123,341.01,329.53,333.69
114.5021,4.9694,-0.14177,34.036,343.33,-0.015367,15.072,343.64,332.23,336.39
115.1021,4.9737,-0.13962,37.083,345.13,-0.015153,15.092,344.57,333.12,337.13
115.7021,4.9666,-0.13999,34.89,346.93,-0.015205,15.064,347.06,335.76,339.88
116.3021,4.9836,-0.13973,35.464,348.73,-0.0152,15.12,348.7,337.16,341.27
116.7049,4.9848,-0.1404,36.983,349.9,-0.015205,15.119,349.41,338.12,342.08
117.3049,4.9645,-0.1402,31.202,350.0,-0.015251,15.062,350.95,339.32,343.52
117.9049,4.9784,-0.14258,36.205,350.0,-0.01545,15.097,349.59,338.62,342.38
118.5049,4.9676,-0.14038,32.736,350.0,-0.015237,15.071,350.47,339.75,343.47
119.1049,4.9739,-0.14001,35.323,350.0,-0.015227,15.087,349.66,339.01,342.59
119.7049,4.9784,-0.13943,32.72,350.0,-0.015157,15.104,350.41,340.06,343.57
120.3049,4.9744,-0.13925,34.524,350.0,-0.015127,15.089,349.79,339.54,342.85
120.9049,4.9939,-0.1439,33.266,350.0,-0.015585,15.149,350.18,340.37,343.62
121.5049,4.9566,-0.14,32.703,350.0,-0.015193,15.034,350.22,340.1,343.46
122.1049,4.9962,-0.14042,34.686,350.0,-0.015237,15.156,349.73,340.32,343.34
122.7049,4.9682,-0.13917,31.598,350.0,-0.015093,15.073,350.46,340.81,343.96
123.3049,4.9965,-0.139,35.173,350.0,-0.015119,15.155,349.55,340.24,343.22
123.9049,4.9849,-0.14074,32.311,350.0,-0.015337,15.122,350.28,341.12,344.13
124.5049,4.988,-0.14058,34.04,350.0,-0.015263,15.122,349.76,340.54,343.41
125.1049,4.973,-0.1399,33.293,350.0,-0.01515,15.09,349.99,341.04,343.87
125.7049,4.971,-0.1394,33.374,350.0,-0.015118,15.074,349.94,340.91,343.73
126.3049,4.981,-0.13942,34.335,350.0,-0.015134,15.112,349.73,340.89,343.56
126.9049,4.9765,-0.13941,32.96,350.0,-0.015133,15.091,350.42,341.67,344.36
127.5049,4.9826,-0.14232,34.226,350.0,-0.015458,15.118,350.24,341.46,344.16
128.1049,4.9668,-0.13959,32.898,350.0,-0.015185,15.063,350.64,341.87,344.57
128.7049,4.99,-0.13943,34.254,350.0,-0.015145,15.139,350.26,341.58,344.13
129.3049,4.9935,-0.13977,32.559,350.0,-0.015133,15.145,351.12,342.68,345.21
129.9049,4.9865,-0.13855,33.364,350.0,-0.015016,15.128,350.85,342.03,344.6
130.5049,4.9927,-0.14345,33.956,350.0,-0.015565,15.147,350.69,342.41,344.73
131.1049,4.9817,-0.13951,33.506,350.0,-0.015132,15.112,350.85,342.4,344.74
131.7049,4.9979,-0.14018,35.55,350.0,-0.015243,15.162,350.93,342.81,344.98
132.3049,5.0033,-0.1396,32.048,350.0,-0.015196,15.178,352.64,344.4,346.72
132.9049,4.9833,-0.13885,34.901,350.0,-0.015097,15.117,351.75,343.19,345.54
133.5049,5.0099,-0.14109,33.614,350.0,-0.015318,15.193,352.27,344.24,346.43
134.1049,4.9861,-0.14118,34.228,350.0,-0.015273,15.127,352.02,343.74,346.04
134.7049,4.9911,-0.13965,33.904,350.0,-0.015174,15.137,352.14,344.13,346.28
135.3049,4.9799,-0.13966,33.909,350.0,-0.015144,15.108,352.05,344.01,346.15
135.90491,4.9878,-0.13951,33.94,350.0,-0.015162,15.126,352.11,344.25,346.33
136.50491,4.9863,-0.13873,33.986,350.0,-0.015097,15.129,352.05,344.07,346.18
137.10491,4.9933,-0.13935,34.18,350.0,-0.015176,15.143,352.44,344.71,346.71
137.70491,4.9805,-0.14286,33.168,350.0,-0.01548,15.113,352.79,344.82,346.95
138.30491,4.9821,-0.14068,34.008,350.0,-0.015227,15.111,352.55,344.87,346.86
138.7464,4.9866,-0.13967,33.313,350.0,-0.015167,15.124,352.74,345.07,347.09
139.3464,4.9876,-0.1397,33.908,350.0,-0.015156,15.135,352.57,344.91,346.9
139.9464,4.9857,-0.13913,33.069,350.0,-0.015136,15.121,352.74,345.16,347.11
140.5464,5.0022,-0.13866,33.791,350.0,-0.015086,15.176,352.54,345.08,347.02
141.1464,4.9984,-0.1384,32.173,350.0,-0.015044,15.162,352.98,345.64,347.47
141.7464,5.0096,-0.14174,34.385,350.0,-0.01537,15.197,352.38,345.0,346.81
142.3464,4.9986,-0.14063,32.993,350.0,-0.015228,15.163,352.8,345.69,347.49
142.9464,5.009,-0.13928,33.708,350.0,-0.015122,15.197,352.74,345.58,347.37
143.5464,4.9896,-0.13904,33.129,350.0,-0.01507,15.135,352.92,345.82,347.58
144.1464,5.0073,-0.13888,34.0,350.0,-0.015097,15.186,352.66,345.6,347.36
144.7464,4.9888,-0.13831,31.965,350.0,-0.01506,15.138,353.18,346.2,347.95
145.3464,5.0015,-0.13811,33.805,350.0,-0.015011,15.168,352.67,345.79,347.38
145.9464,4.9864,-0.13831,32.606,350.0,-0.015002,15.131,352.95,346.17,347.8
146.5464,4.9966,-0.14227,33.554,350.0,-0.015417,15.154,352.7,345.85,347.47
147.1464,4.9845,-0.13948,32.904,350.0,-0.015137,15.122,352.89,346.18,347.77
147.7464,4.9843,-0.13852,33.087,350.0,-0.015035,15.115,352.84,346.1,347.63
148.3464,4.9888,-0.13826,33.193,350.0,-0.015011,15.14,352.79,346.13,347.65
148.9464,4.9892,-0.13825,32.854,350.0,-0.015048,15.13,352.83,346.24,347.7
149.5464,5.0033,-0.13786,32.875,350.0,-0.01499,15.181,352.83,346.42,347.79
150.1464,4.9996,-0.1372,33.068,350.0,-0.014891,15.163,352.83,346.39,347.8
150.7464,5.0154,-0.1387,33.057,350.0,-0.01504,15.216,352.84,346.4,347.78
151.3464,5.0039,-0.14079,32.848,350.0,-0.015254,15.177,352.85,346.46,347.84
151.9464,5.0081,-0.13825,32.986,350.0,-0.014996,15.194,352.78,346.5,347.86
152.5464,4.9879,-0.13755,32.828,350.0,-0.01492,15.13,352.82,346.48,347.87
153.1464,5.0045,-0.13722,32.728,350.0,-0.014926,15.183,352.84,346.62,347.92
153.7464,4.9957,-0.13686,32.395,350.0,-0.014885,15.158,352.93,346.62,347.97
154.3464,5.0072,-0.13685,32.688,350.0,-0.014872,15.189,352.82,346.56,347.91
154.9464,4.9902,-0.13746,32.586,350.0,-0.014914,15.139,352.88,346.75,348.05
155.5464,4.9985,-0.14001,32.601,350.0,-0.015152,15.159,352.85,346.7,348.0
156.1464,4.9819,-0.13716,32.7,350.0,-0.014895,15.116,352.82,346.62,347.91
156.7464,4.9877,-0.13706,32.589,350.0,-0.01486,15.128,352.84,346.73,348.05
157.3464,4.9942,-0.13675,32.849,350.0,-0.01486,15.153,352.78,346.73,347.93
157.9464,4.9934,-0.13627,32.565,350.0,-0.014821,15.145,352.85,346.87,348.05
158.54641,4.9908,-0.13607,32.398,350.0,-0.014788,15.145,352.88,346.84,348.08
159.14641,4.994,-0.13958,32.804,350.0,-0.015162,15.145,352.81,346.93,348.06
159.74641,5.0006,-0.13765,32.425,350.0,-0.014898,15.17,352.85,346.95,348.08
160.34641,4.9955,-0.13664,32.78,350.0,-0.014834,15.152,352.79,346.87,348.03
160.94641,4.9967,-0.13634,32.356,350.0,-0.01479,15.161,352.9,347.04,348.13
161.54641,5.0032,-0.1362,32.823,350.0,-0.014796,15.175,352.81,347.0,348.08
161.9528,5.0099,0.006391,0.0,275.69,0.00089365,15.181,352.86,347.09,348.31
161.9558,4.9344,0.0065618,0.0,0.022704,0.00089713,14.992,352.87,347.13,348.44
161.9588,5.1004,0.0037433,0.0,1.8505e-06,4.1071e-05,15.46,352.88,347.17,348.57
161.9618,4.9308,0.0084796,0.0,1.5082e-10,0.00035017,14.96,352.88,347.16,348.52
161.9648,5.0569,0.0053224,0.0,1.2293e-14,0.00044232,15.339,352.87,347.13,348.39
161.9678,4.9314,0.0028352,0.0,1.0018e-18,0.00077718,14.968,352.86,347.1,348.26
161.9708,5.0585,0.0042668,0.0,8.1237e-23,0.00105,15.351,352.86,347.09,348.18
161.9738,4.9373,0.0066985,0.0,6.6206e-27,0.00080832,14.962,352.89,347.11,348.19
161.9768,5.0368,0.0074741,0.0,5.3956e-31,0.00074146,15.309,352.92,347.13,348.2
161.9798,4.9403,0.0064218,0.0,4.3971e-35,0.00095727,14.955,352.94,347.15,348.21
161.9828,5.0237,0.0055973,0.0,3.5832999999999996e-39,0.00083559,15.273,352.97,347.13,348.19
161.9858,4.9569,0.0075174,0.0,2.9147e-43,0.00041801,14.986,353.0,347.11,348.17
161.9888,5.0017,0.0078319,0.0,0.0,0.00022809,15.19,353.03,347.09,348.16
161.9918,4.9762,0.0047616,0.0,0.0,0.00042744,15.076,353.04,347.07,348.13
161.9948,4.9855,0.0024436,0.0,0.0,0.00060661,15.168,353.04,347.06,348.1
161.9978,4.9909,0.0033941,0.0,0.0,0.0009114,15.116,353.04,347.04,348.08
162.0008,4.96,0.0037487,0.0,0.0,0.00054485,15.067,353.14,347.16,348.03
162.0038,5.0149,0.0069809,0.0,0.0,0.00064193,15.179,353.44,347.57,347.96
162.0068,4.9475,0.0051493,0.0,0.0,0.00080042,15.026,353.75,347.98,347.89
162.0098,4.9914,0.0062222,0.0,0.0,0.00087233,15.118,354.06,348.39,347.82
162.0128,4.9507,0.0076997,0.0,0.0,0.00057282,15.044,357.56,352.13,347.78
162.0158,5.0205,0.0078962,0.0,0.0,0.00020826,15.245,361.1,355.92,347.74
162.0188,32.335,0.29675,0.0,0.0,0.031335,96.791,364.64,359.71,347.71
162.02179,39.175,0.90394,0.0,0.0,0.10266,118.62,369.2,363.81,347.71
162.02479,40.324,1.5707,0.0,0.0,0.18585,122.22,374.32,368.08,347.74
162.02779,40.65,2.2255,0.0,0.0,0.27334,123.31,379.43,372.35,347.77
162.03079,41.141,2.8795,0.0,0.0,0.36877,124.75,383.67,375.84,347.79
162.03379,41.647,3.5377,0.0,0.0,0.475,126.32,385.92,377.55,347.8
162.03679,42.413,4.1814,0.0,0.0,0.5894,128.61,388.17,379.26,347.81
162.03979,43.029,4.8268,0.0,0.0,0.71612,130.47,390.42,380.97,347.81
162.04279,43.537,5.4619,0.0,0.0,0.85722,132.06,390.22,381.82,347.85
162.04579,43.804,6.0664,0.0,0.0,1.013,132.89,389.92,382.65,347.89
162.04879,43.999,6.5947,0.0,0.0,1.1718,133.49,389.62,383.47,347.92
162.05179,43.719,7.013,0.0,0.0,1.3146,132.64,388.66,383.5,347.95
162.05479,43.348,7.3139,0.0,0.0,1.4274,131.51,387.29,383.06,347.98
162.05779,42.752,7.523,0.0,0.0,1.5141,129.7,385.93,382.62,348.01
162.06079,42.004,7.6854,0.0,0.0,1.5902,128.14,384.53,381.99,348.04
162.06379,36.865,7.6801,0.0,0.0,1.5897,112.08,383.03,380.92,348.06
162.06679,35.242,7.6987,0.0,0.0,1.5952,106.91,381.53,379.84,348.09
162.06979,34.704,7.7035,0.0,0.0,1.5949,105.32,380.03,378.76,348.12
162.07279,34.389,7.7131,0.0,0.0,1.6015,104.32,378.94,377.75,348.16
162.07579,33.536,7.7165,0.0,0.0,1.6064,101.82,377.87,376.73,348.21
162.07879,31.702,7.717,0.0,0.0,1.608,96.306,376.8,375.72,348.25
162.08179,28.011,7.7155,0.0,0.0,1.6044,85.239,376.11,374.92,348.3
162.08479,22.475,7.7112,0.0,0.0,1.6006,68.766,375.67,374.27,348.36
162.08779,2.4433,7.6541,0.0,0.0,1.577,7.7981,375.22,373.62,348.41
162.09079,3.3316,7.6728,0.0,0.0,1.5865,10.09,374.84,372.97,348.47
162.09379,3.8786,7.6644,0.0,0.0,1.5793,11.7,374.63,372.34,348.55
162.09679,4.3541,7.6704,0.0,0.0,1.5792,13.13,374.42,371.71,348.62
162.09979,4.3783,7.6695,0.0,0.0,1.5808,13.218,374.22,371.07,348.69
162.10279,4.3858,7.6649,0.0,0.0,1.5826,13.376,374.02,370.41,348.78
162.10579,4.344,7.6655,0.0,0.0,1.5838,13.162,373.82,369.74,348.87
162.10879,4.3796,7.6671,0.0,0.0,1.582,13.323,373.62,369.07,348.96
162.11179,4.3547,7.6694,0.0,0.0,1.5809,13.16,373.36,368.54,349.05
162.11479,4.335,7.6693,0.0,0.0,1.5831,13.219,373.06,368.11,349.13
162.11779,4.4178,7.669,0.0,0.0,1.5844,13.379,372.76,367.69,349.21
162.12079,4.3388,7.671,0.0,0.0,1.5824,13.195,372.47,367.27,349.29
162.12379,4.3993,7.6701,0.0,0.0,1.5791,13.318,372.18,366.88,349.34
162.12679,4.3178,7.6706,0.0,0.0,1.5809,13.092,371.89,366.49,349.4
162.12979,4.4346,7.6669,0.0,0.0,1.5835,13.463,371.6,366.1,349.45
162.13279,4.3609,7.6652,0.0,0.0,1.584,13.237,371.28,365.62,349.55
162.13579,4.4599,7.6688,0.0,0.0,1.5826,13.494,370.97,365.12,349.66
162.13879,4.3409,7.6717,0.0,0.0,1.5822,13.17,370.65,364.62,349.77
162.14179,4.4586,7.6727,0.0,0.0,1.5844,13.541,370.3,364.19,349.86
162.14479,4.3858,7.6718,0.0,0.0,1.586,13.308,369.92,363.82,349.92
162.14779,4.4643,7.6722,0.0,0.0,1.5831,13.552,369.54,363.45,349.98
162.15079,4.4234,7.6736,0.0,0.0,1.5808,13.401,369.15,363.07,350.05
162.15379,4.4655,7.6715,0.0,0.0,1.5816,13.565,368.76,362.66,350.1
162.15679,4.393,7.6673,0.0,0.0,1.5836,13.323,368.36,362.25,350.15
162.15978,4.4488,7.668,0.0,0.0,1.5848,13.502,367.96,361.84,350.21
162.16278,4.4059,7.6719,0.0,0.0,1.5843,13.345,367.53,361.39,350.3
162.16578,4.4166,7.6737,0.0,0.0,1.5832,13.44,367.09,360.92,350.39
162.16878,4.4533,7.6727,0.0,0.0,1.5846,13.482,366.66,360.46,350.48
162.17178,4.4054,7.6723,0.0,0.0,1.5856,13.396,366.29,360.07,350.55
162.17478,4.4846,7.6728,0.0,0.0,1.5841,13.598,365.98,359.73,350.6
162.17778,4.495,7.6745,0.0,0.0,1.5815,13.643,365.68,359.4,350.66
162.18078,4.5416,7.6712,0.0,0.0,1.5811,13.771,365.37,359.05,350.71
162.18378,4.5579,7.6697,0.0,0.0,1.5844,13.848,365.07,358.68,350.78
162.18678,4.6392,7.6689,0.0,0.0,1.5854,14.034,364.77,358.31,350.84
162.18978,4.5138,7.6718,0.0,0.0,1.5848,13.688,364.47,357.94,350.91
162.19278,4.6931,7.6742,0.0,0.0,1.5836,14.255,364.09,357.56,351.03
162.19578,4.4888,7.6747,0.0,0.0,1.5853,13.641,363.69,357.19,351.17
162.19878,4.7425,7.6756,0.0,0.0,1.5875,14.398,363.29,356.82,351.3
162.20178,4.4973,7.6745,0.0,0.0,1.5847,13.623,362.93,356.51,351.43
162.20478,4.7168,7.6758,0.0,0.0,1.5821,14.322,362.61,356.26,351.53
162.20778,4.5031,7.6727,0.0,0.0,1.5819,13.599,362.3,356.0,351.64
162.21078,4.7043,7.6703,0.0,0.0,1.5844,14.316,361.97,355.74,351.74
162.21378,4.5532,7.6684,0.0,0.0,1.5852,13.75,361.63,355.46,351.75
162.21678,4.6762,7.6729,0.0,0.0,1.5848,14.253,361.28,355.18,351.77
162.21978,4.591,7.6751,0.0,0.0,1.5837,13.867,360.94,354.9,351.79
162.22278,4.6329,7.6735,0.0,0.0,1.5846,14.121,360.58,354.57,351.83
162.22578,4.6623,7.6728,0.0,0.0,1.5862,14.076,360.22,354.24,351.88
162.22878,4.5978,7.6748,0.0,0.0,1.5849,14.019,359.85,353.9,351.92
162.23178,4.7025,7.6745,0.0,0.0,1.5814,14.21,359.52,353.59,351.98
162.23478,4.5565,7.6751,0.0,0.0,1.5824,13.908,359.21,353.3,352.05
162.23778,4.7194,7.6739,0.0,0.0,1.5859,14.257,358.9,353.01,352.13
162.24078,4.5057,7.6713,0.0,0.0,1.5866,13.712,358.59,352.72,352.2
162.24378,4.7377,7.6742,0.0,0.0,1.5858,14.329,358.25,352.46,352.26
162.24678,4.4939,7.6759,0.0,0.0,1.5844,13.635,357.92,352.19,352.32
162.24978,4.745,7.6749,0.0,0.0,1.5848,14.389,357.58,351.93,352.39
162.25278,4.5001,7.6734,0.0,0.0,1.5866,13.653,357.25,351.64,352.44
162.25578,4.7432,7.6743,0.0,0.0,1.5848,14.402,356.93,351.34,352.5
162.25878,4.5081,7.6755,0.0,0.0,1.582,13.658,356.6,351.04,352.55
162.26178,4.7309,7.6759,0.0,0.0,1.5828,14.377,356.29,350.77,352.61
162.26478,4.5402,7.6711,0.0,0.0,1.5846,13.721,356.0,350.52,352.66
162.26778,4.7051,7.6703,0.0,0.0,1.5859,14.322,355.71,350.27,352.72
162.27078,4.5885,7.6721,0.0,0.0,1.5847,13.849,355.41,350.03,352.77
162.27378,4.6607,7.6792,0.0,0.0,1.5857,14.21,355.09,349.82,352.81
162.27678,4.6453,7.6783,0.0,0.0,1.5864,14.015,354.76,349.6,352.86
162.27978,4.6387,7.6765,0.0,0.0,1.5878,14.14,354.43,349.38,352.91
162.28278,4.6852,7.6757,0.0,0.0,1.5859,14.141,354.12,349.1,352.95
162.28578,4.5981,7.6771,0.0,0.0,1.5832,14.04,353.81,348.81,353.0
162.28878,4.7348,7.6776,0.0,0.0,1.5834,14.313,353.51,348.52,353.04
162.29178,4.5665,7.6753,0.0,0.0,1.5862,13.914,353.22,348.23,353.09
162.29478,4.767,7.6755,0.0,0.0,1.5882,14.423,352.97,347.95,353.13
162.29777,4.5471,7.676,0.0,0.0,1.587,13.827,352.71,347.67,353.18
162.30077,4.7884,7.6792,0.0,0.0,1.5859,14.481,352.45,347.4,353.22
162.30377,4.5422,7.6778,0.0,0.0,1.5861,13.79,352.14,347.19,353.26
162.30677,4.7908,7.6782,0.0,0.0,1.5888,14.506,351.84,346.98,353.29
162.30977,4.5395,7.6761,0.0,0.0,1.5863,13.75,351.53,346.77,353.33
162.31277,4.7915,7.6781,0.0,0.0,1.584,14.538,351.21,346.58,353.37
162.31577,4.5752,7.6775,0.0,0.0,1.5838,13.848,350.88,346.4,353.42
162.31877,4.7583,7.6756,0.0,0.0,1.5864,14.489,350.55,346.22,353.46
162.32177,4.6054,7.6735,0.0,0.0,1.5878,13.914,350.26,346.03,353.5
162.32477,4.7268,7.676,0.0,0.0,1.587,14.383,350.0,345.83,353.52
162.32777,4.6497,7.6783,0.0,0.0,1.5854,14.037,349.75,345.63,353.53
162.33077,4.6983,7.6794,0.0,0.0,1.5866,14.302,349.5,345.43,353.55
162.33377,4.6904,7.6757,0.0,0.0,1.5875,14.154,349.29,345.24,353.55
162.33677,4.6437,7.6764,0.0,0.0,1.5865,14.162,349.08,345.04,353.55
162.33977,4.7371,7.6782,0.0,0.0,1.5834,14.311,348.87,344.85,353.55
162.34277,4.5973,7.6796,0.0,0.0,1.585,14.009,348.65,344.62,353.56
162.34577,4.7632,7.6761,0.0,0.0,1.5865,14.396,348.42,344.38,353.58
162.34877,4.5838,7.675,0.0,0.0,1.5881,13.989,348.19,344.13,353.6
162.35177,4.8034,7.676,0.0,0.0,1.5871,14.526,347.97,343.9,353.63
162.35477,4.5696,7.6796,0.0,0.0,1.5864,13.883,347.75,343.68,353.66
162.35777,4.8224,7.6787,0.0,0.0,1.5864,14.607,347.53,343.46,353.7
162.36077,4.5764,7.6763,0.0,0.0,1.5881,13.887,347.31,343.25,353.74
162.36377,4.8268,7.679,0.0,0.0,1.5879,14.646,347.08,343.1,353.79
162.36677,4.5863,7.6808,0.0,0.0,1.5852,13.871,346.86,342.95,353.85
162.36977,4.8267,7.6805,0.0,0.0,1.5851,14.653,346.63,342.81,353.9
162.37277,4.6232,7.6766,0.0,0.0,1.5865,13.978,346.4,342.64,353.91
162.37577,4.7921,7.6734,0.0,0.0,1.5876,14.592,346.17,342.46,353.9
162.37877,4.6539,7.6753,0.0,0.0,1.5868,14.05,345.95,342.27,353.89
162.38177,4.7628,7.6791,0.0,0.0,1.5861,14.514,345.74,342.09,353.88
162.38477,4.7123,7.679,0.0,0.0,1.5865,14.221,345.58,341.91,353.86
162.38777,4.7148,7.6789,0.0,0.0,1.5889,14.375,345.42,341.73,353.84
162.39077,4.7429,7.6798,0.0,0.0,1.588,14.326,345.25,341.55,353.83
162.39377,4.6716,7.68,0.0,0.0,1.5849,14.256,345.06,341.38,353.86
162.39677,4.7765,7.6806,0.0,0.0,1.585,14.439,344.87,341.22,353.9
162.39977,4.6178,7.6789,0.0,0.0,1.5875,14.073,344.68,341.06,353.93
162.40277,4.8057,7.6757,0.0,0.0,1.5885,14.539,344.46,340.89,353.95
162.40577,4.609,7.6763,0.0,0.0,1.5878,14.035,344.23,340.73,353.96
162.40877,4.8422,7.6798,0.0,0.0,1.5862,14.639,344.01,340.56,353.97
162.41177,4.599,7.68,0.0,0.0,1.5869,13.973,343.78,340.42,353.98
162.41477,4.8417,7.6791,0.0,0.0,1.5892,14.693,343.56,340.31,354.0
162.41777,4.6082,7.6799,0.0,0.0,1.5884,13.964,343.35,340.2,354.02
162.42077,4.8562,7.6825,0.0,0.0,1.5862,14.736,343.13,340.09,354.04
162.42377,4.6302,7.6816,0.0,0.0,1.5853,14.028,342.96,339.95,354.04
162.42677,4.8362,7.678,0.0,0.0,1.5872,14.692,342.78,339.8,354.04
162.42977,4.6774,7.6756,0.0,0.0,1.5885,14.146,342.61,339.66,354.04
162.43277,4.8192,7.6789,0.0,0.0,1.5888,14.677,342.46,339.47,354.05
162.43576,4.718,7.6794,0.0,0.0,1.5865,14.243,342.31,339.27,354.08
162.43876,4.7764,7.6819,0.0,0.0,1.5872,14.57,342.17,339.07,354.11
162.44176,4.7425,7.6808,0.0,0.0,1.5897,14.303,342.0,338.88,354.13
162.44476,4.7377,7.6825,0.0,0.0,1.59,14.439,341.8,338.72,354.13
162.44776,4.7931,7.6825,0.0,0.0,1.5865,14.46,341.6,338.56,354.13
162.45076,4.6851,7.6814,0.0,0.0,1.5853,14.308,341.4,338.39,354.13
162.45376,4.8229,7.6789,0.0,0.0,1.5872,14.573,341.25,338.32,354.09
162.45676,4.6683,7.6759,0.0,0.0,1.5887,14.204,341.09,338.25,354.05
162.45976,4.8519,7.6776,0.0,0.0,1.5881,14.676,340.94,338.18,354.02
162.46276,4.6342,7.6806,0.0,0.0,1.587,14.099,340.79,338.07,354.03
162.46576,4.8699,7.6819,0.0,0.0,1.5873,14.732,340.64,337.94,354.07
162.46783,4.8816,7.6836,0.0,0.0,1.5853,14.792,340.54,337.85,354.09
163.06783,4.6866,7.6851,0.0,0.0,1.5899,14.218,309.17,288.64,268.57
163.66783,4.6558,7.6913,0.0,0.0,1.5929,14.124,256.53,226.46,165.28
164.26783,4.6515,7.6981,0.0,0.0,1.596,14.11,204.96,115.32,141.26
164.86783,4.6554,7.7097,0.0,0.0,1.6015,14.121,104.75,70.507,123.31
165.46783,4.6559,7.7256,0.0,0.0,1.6091,14.12,69.609,51.128,75.32
166.06783,4.658,7.7416,0.0,0.0,1.6164,14.133,53.493,40.744,43.271
166.66783,4.635,7.752,0.0,0.0,1.6214,14.059,43.015,39.32,30.788
167.26783,4.6345,7.7576,0.0,0.0,1.624,14.061,36.278,29.704,26.057
167.74,4.6093,7.7639,0.0,0.0,1.6273,13.985,33.528,28.318,24.778
168.34,4.6065,7.7717,0.0,0.0,1.6308,13.969,30.287,26.398,23.284
168.94,4.5919,7.7765,0.0,0.0,1.6331,13.932,28.16,25.367,22.495
169.54,4.6101,7.7803,0.0,0.0,1.6352,13.981,26.925,24.453,22.135
170.14,4.6126,7.78,0.0,0.0,1.6351,13.996,25.687,23.872,21.641
170.74,4.6152,7.7832,0.0,0.0,1.6366,13.996,24.811,23.285,21.445
171.34,4.6237,7.7843,0.0,0.0,1.637,14.031,24.166,22.846,21.156
171.94,4.6218,7.7866,0.0,0.0,1.6383,14.014,23.509,22.552,20.995
172.54,4.8069,7.7886,0.0,0.0,1.6391,14.584,22.894,22.378,20.758
173.14,4.6914,7.7898,0.0,0.0,1.6395,14.23,25.813,25.313,22.369
173.74,4.6558,7.7904,0.0,0.0,1.6399,14.125,27.367,26.814,23.784
174.34,4.6364,7.7905,0.0,0.0,1.6402,14.065,28.731,28.05,25.245
174.94,4.5973,7.791,0.0,0.0,1.6405,13.944,29.787,29.14,26.526
175.54,4.5959,7.7933,0.0,0.0,1.6414,13.942,30.762,30.143,27.67
176.14,4.5911,7.798,0.0,0.0,1.6438,13.928,31.504,30.904,28.68
176.74,4.59,7.8004,0.0,0.0,1.645,13.923,32.252,31.89,29.604
177.34,4.59,7.8004,0.0,0.0,1.6448,13.924,32.855,39.551,30.454
177.94,4.5336,7.7961,0.0,0.0,1.6426,13.751,33.282,39.754,31.162
178.54,4.5294,7.7962,0.0,0.0,1.6428,13.741,33.773,39.754,31.794
179.14,4.5286,7.7966,0.0,0.0,1.6432,13.739,34.089,39.718,32.366
179.34,4.5291,7.7969,0.0,0.0,1.643,13.738,34.225,39.752,32.533