File: examples/dan-msc-case-studies/CS4/data/01 raw data/hyde_test_002.csv
Time(sec),Force(kN),Jaw(mm),PowAngle(deg),PTemp,Strain,Stress(MPa),TC1(C),TC2(C),TC3(C),TC4(C)
0.0,2.0058,-10.762,0.0,0.0,-0.81392,2.3785,25.657,25.394,25.403,25.565
1.8,1.935,0.0018704,0.0,5.2207,0.00019079,2.2969,25.661,25.361,25.34,25.526
3.577,1.8911,0.0015946,0.0,10.552,0.00019462,2.2449,25.65,25.351,25.33,25.51
5.377,1.879,0.0013401,0.0,15.952,0.0001344,2.2298,25.64,25.331,25.361,25.496
7.177,1.8834,0.0012015,0.0,21.352,0.00015822,2.2355,25.658,25.345,25.369,25.539
8.977,1.8738,0.0018985,11.696,26.752,0.00021755,2.2236,25.673,25.361,25.372,25.497
10.6314,1.9051,0.0016838,28.514,31.715,0.00019793,2.2607,29.677,27.235,25.479,26.06
12.4314,1.9195,0.00084616,29.499,37.115,9.0037e-05,2.2771,35.922,30.08,26.619,28.573
14.2314,1.917,-0.00078971,30.499,42.515,-0.00010217,2.2744,41.803,37.954,28.619,31.83
16.0314,1.9263,-0.0022939,30.33,47.915,-0.0002477,2.2873,47.554,37.954,31.338,35.364
17.8314,1.9333,-0.0036127,30.824,53.315,-0.0004196,2.2939,53.11,39.056,34.711,39.211
19.6314,1.9301,-0.0055108,31.897,58.715,-0.00061097,2.2911,58.42,42.357,38.367,43.108
21.4314,1.9309,-0.0072113,32.194,64.115,-0.00079844,2.2913,63.871,46.009,42.541,47.234
23.2314,1.941,-0.0088094,32.802,69.515,-0.00099624,2.3045,69.312,49.816,47.107,51.499
25.0314,1.9467,-0.010548,33.419,74.915,-0.0011442,2.3099,74.664,53.516,51.419,55.918
26.8314,1.9428,-0.014002,33.65,80.315,-0.0015318,2.3058,80.184,57.391,56.159,60.367
28.6314,1.946,-0.01534,34.082,85.715,-0.0017245,2.3102,85.516,61.184,60.134,64.86
30.4314,1.9429,-0.017843,34.323,91.115,-0.001949,2.3057,91.016,65.185,65.936,69.486
32.2314,1.9545,-0.020014,34.856,96.515,-0.0022009,2.3211,96.353,69.031,71.353,74.012
34.0314,2.0298,-0.020848,35.205,101.91,-0.0023277,2.4094,101.82,73.07,75.721,78.731
35.8087,2.44,-0.020488,35.631,107.25,-0.0022766,2.8959,107.08,77.107,80.523,83.314
37.4344,2.5243,-0.020826,35.539,112.12,-0.0022948,2.996,112.01,80.946,84.802,87.615
39.2344,2.5675,-0.022102,36.119,117.52,-0.0024817,3.048,117.4,85.498,88.951,92.474
41.0344,2.5888,-0.02367,36.442,122.92,-0.0025953,3.0723,122.79,90.364,94.393,97.504
42.8344,2.5949,-0.027117,36.874,128.32,-0.0029749,3.08,128.19,95.174,98.796,102.68
44.6344,2.605,-0.029208,37.01,133.72,-0.0032603,3.0921,133.63,100.19,105.47,107.92
46.4344,2.612,-0.031243,37.348,139.12,-0.0034323,3.099,138.98,105.07,110.75,113.15
48.2344,2.6187,-0.034114,37.808,144.52,-0.003784,3.1086,144.43,110.18,116.4,118.34
50.0344,2.6202,-0.037681,38.314,149.92,-0.0041717,3.1082,149.71,115.36,121.83,123.66
51.8344,2.632,-0.039727,38.427,155.32,-0.0044019,3.1248,155.18,120.58,127.42,129.07
53.6344,2.8341,-0.042351,38.532,160.72,-0.0047153,3.3639,160.67,125.95,132.66,134.53
55.4344,3.518,-0.036134,38.8,166.12,-0.0039668,4.1757,166.02,131.44,138.19,139.91
57.2344,3.8531,-0.03451,39.421,171.52,-0.0038066,4.5728,171.34,137.29,143.17,145.39
59.0344,3.9433,-0.035538,39.624,176.92,-0.0039428,4.6796,176.81,143.23,148.45,150.92
60.8344,3.9797,-0.036702,39.758,182.32,-0.0040544,4.7246,182.26,149.25,153.62,156.66
62.6344,3.9909,-0.040832,39.889,187.72,-0.0045374,4.7361,187.66,155.18,160.3,162.2
64.4344,4.0078,-0.043192,39.698,193.12,-0.0047467,4.7576,193.1,161.01,166.73,167.82
66.2344,4.0248,-0.047577,39.664,198.52,-0.0052408,4.7757,198.56,166.71,172.43,173.35
67.9421,4.0284,-0.04949,39.805,203.65,-0.0054361,4.7808,203.63,171.88,178.2,178.42
69.5694,4.0348,-0.050879,39.931,208.53,-0.0056567,4.7884,208.47,176.77,183.3,183.4
71.3694,4.0433,-0.05593,40.076,213.93,-0.0061572,4.7997,213.9,182.18,188.93,188.87
73.1694,4.0528,-0.058051,40.317,219.33,-0.0064178,4.8085,219.27,187.45,194.63,194.25
74.9694,4.0601,-0.062504,40.204,224.73,-0.0069184,4.8183,224.74,192.78,200.46,199.55
76.7694,4.5742,-0.061034,40.562,230.13,-0.0067391,5.4277,230.06,197.86,206.18,204.75
78.5694,5.2206,-0.057518,40.667,235.53,-0.0063906,6.1958,235.46,203.13,211.68,210.14
80.3694,5.414,-0.057856,40.681,240.93,-0.0063758,6.4246,240.86,208.45,217.06,215.35
82.1694,5.4512,-0.061412,40.571,246.33,-0.0068238,6.4683,246.37,213.76,222.26,220.65
83.9694,5.4926,-0.064177,40.733,251.73,-0.0070842,6.5193,251.72,219.12,227.54,225.84
85.7694,5.5014,-0.068594,40.724,257.13,-0.0075949,6.5259,257.21,224.42,232.96,231.11
87.5694,5.5185,-0.071988,40.995,262.53,-0.0079674,6.5509,262.48,229.61,238.27,236.26
89.3694,5.5447,-0.076998,46.828,267.93,-0.0085198,6.5787,271.33,236.41,244.28,242.12
91.1694,5.577,-0.084751,46.477,273.33,-0.0093801,6.6196,287.86,248.35,255.77,253.67
92.9694,5.5889,-0.088689,42.939,278.73,-0.009796,6.6313,293.16,254.84,265.21,262.83
94.7694,5.6012,-0.093684,43.391,284.13,-0.010334,6.6474,299.9,260.96,272.07,269.36
96.5694,5.6305,-0.10061,43.82,289.53,-0.011107,6.6831,306.05,266.97,279.05,276.09
98.3694,5.6352,-0.10404,42.354,294.93,-0.011483,6.6866,314.28,274.13,286.71,283.59
100.167,5.647,-0.11111,41.574,299.99,-0.012268,6.7038,319.34,279.14,292.79,289.5
101.7954,5.6584,-0.11523,38.93,300.0,-0.012696,6.714,319.68,281.92,296.38,293.03
103.5954,5.6509,-0.11591,38.08,300.0,-0.012777,6.7073,319.42,283.98,298.14,294.8
105.3954,5.6748,-0.11834,37.394,300.0,-0.013085,6.734,319.29,285.73,299.26,296.0
107.1954,5.6609,-0.12087,37.204,300.0,-0.013318,6.7188,319.11,287.21,300.1,296.83
108.9954,5.6761,-0.12474,36.864,300.0,-0.013788,6.7371,319.05,288.52,300.78,297.6
110.7954,5.6819,-0.12673,36.443,300.0,-0.013981,6.7416,319.0,289.64,301.28,298.25
112.5954,5.6858,-0.13027,36.25,300.0,-0.014383,6.7497,318.98,290.71,301.79,298.81
114.3954,5.6843,-0.13324,35.695,300.0,-0.014645,6.7439,318.94,291.69,302.29,299.29
116.1954,5.6885,-0.13502,34.816,300.0,-0.014871,6.7523,318.6,292.43,302.49,299.63
117.9954,5.6828,-0.13635,34.582,300.0,-0.015036,6.7423,314.85,291.23,301.31,298.52
119.7954,5.6871,-0.1378,34.989,300.0,-0.015181,6.7494,314.7,291.53,300.51,297.78
121.5954,5.6806,-0.13955,33.542,300.0,-0.015401,6.7412,313.15,291.18,299.97,297.29
123.3954,5.6846,-0.14147,34.064,300.0,-0.015577,6.7455,312.18,290.97,299.04,296.39
125.1954,5.7046,-0.14227,33.118,300.0,-0.015709,6.7701,310.59,290.36,298.09,295.53
126.9954,5.6959,-0.14484,33.167,300.0,-0.01595,6.7587,309.82,290.19,297.13,294.7
128.7954,5.7092,-0.14673,33.819,300.0,-0.016185,6.7765,309.74,290.19,296.72,294.31
130.5954,5.7134,-0.14866,32.873,300.0,-0.016389,6.7792,309.56,290.39,296.59,294.21
132.3954,5.6985,-0.14943,31.462,300.0,-0.016457,6.7645,309.04,290.38,296.43,294.12
134.0022,5.7229,-0.15279,33.263,300.0,-0.01684,6.7909,307.58,289.84,295.8,293.46
135.8022,5.7002,-0.15232,31.221,300.0,-0.01677,6.7642,306.88,289.58,295.22,293.0
137.6022,5.7195,-0.15318,32.836,300.0,-0.016845,6.7888,306.0,289.13,294.38,292.15
139.4022,5.7221,-0.1551,33.821,300.0,-0.017109,6.7894,306.07,289.19,294.15,291.92
141.2022,5.7183,-0.15716,31.642,300.0,-0.017307,6.7873,306.55,289.7,294.49,292.26
143.0022,5.7257,-0.15733,32.698,300.0,-0.017351,6.794,306.2,289.69,294.29,292.08
144.8022,5.711,-0.16003,31.854,300.0,-0.017617,6.7801,305.47,289.55,294.25,292.07
145.2807,5.6953,0.0040476,0.0,5.5087e-06,-0.00034282,6.7453,304.94,289.29,294.04,291.86
145.2816,5.7712,0.0083392,0.0,2.9369e-18,-8.1363e-05,6.8496,304.89,289.3,294.06,291.88
145.2825,5.6829,0.010902,0.0,1.5658e-30,0.00044844,6.7383,304.85,289.31,294.08,291.9
145.2834,5.7068,0.011112,0.0,8.3517e-43,0.00057856,6.7478,304.8,289.32,294.09,291.91
145.2843,5.7441,0.006082,0.0,0.0,0.0003399,6.8055,304.75,289.32,294.11,291.93
145.2852,5.772,0.0095562,0.0,0.0,0.0012019,6.8558,304.71,289.33,294.13,291.95
145.2861,5.7127,0.0083354,0.0,0.0,0.0013738,6.7936,304.66,289.34,294.14,291.96
145.287,5.7026,0.0038861,0.0,0.0,0.0010872,6.7673,304.61,289.35,294.16,291.98
145.2879,5.7381,0.0038905,0.0,0.0,0.0011084,6.8167,304.57,289.36,294.18,292.0
145.2888,5.6706,0.0020484,0.0,0.0,0.00063364,6.7433,304.58,289.37,294.18,291.99
145.2897,5.7512,0.0019093,0.0,0.0,0.00054884,6.8247,304.62,289.37,294.17,291.97
145.2906,5.6748,0.003829,0.0,0.0,0.00047618,6.7212,304.65,289.38,294.16,291.95
145.2915,5.7575,0.0036875,0.0,0.0,0.0003515,6.8299,304.69,289.39,294.16,291.93
145.2924,5.6765,0.00495,0.0,0.0,0.00025674,6.7322,304.73,289.4,294.15,291.91
145.2933,5.7625,0.0064747,0.0,0.0,0.00039086,6.8175,304.76,289.41,294.15,291.89
145.2942,5.6977,0.0055882,0.0,0.0,0.00011499,6.7684,304.8,289.42,294.14,291.87
145.2951,5.7243,0.0043906,0.0,0.0,0.00017027,6.8004,304.83,289.42,294.14,291.85
145.296,5.7173,0.0034127,0.0,0.0,0.00052895,6.7865,304.87,289.43,294.13,291.83
145.2969,5.7098,0.0014241,0.0,0.0,0.00052895,6.7725,304.9,289.44,294.13,291.81
145.2978,5.7314,-0.00044034,0.0,0.0,0.00070935,6.8096,304.94,289.45,294.12,291.79
145.2987,5.6761,-0.0025216,0.0,0.0,0.00051116,6.7352,304.96,289.45,294.12,291.78
145.2996,5.7442,-0.0045497,0.0,0.0,0.00033246,6.8176,304.96,289.45,294.11,291.78
145.3005,5.67,-0.005335,0.0,0.0,0.0002002,6.7272,304.96,289.45,294.1,291.77
145.3014,5.7626,-0.0062089,0.0,0.0,1.3025e-05,6.8176,304.96,289.45,294.1,291.77
145.3023,5.6642,-0.0050614,0.0,0.0,-0.00017464,6.7363,304.97,289.45,294.09,291.76
145.3032,5.7442,-0.0032722,0.0,0.0,-0.00037085,6.8217,304.97,289.45,294.09,291.75
145.3041,5.6792,-0.0020892,0.0,0.0,-0.00051171,6.7676,304.97,289.45,294.08,291.75
145.305,5.724,0.0011499,0.0,0.0,-0.00068103,6.7925,304.97,289.45,294.08,291.74
145.3059,5.7061,0.0018746,0.0,0.0,-0.00053988,6.7926,304.98,289.45,294.07,291.74
145.3068,5.6983,0.0033177,0.0,0.0,-0.0004181,6.7815,304.98,289.45,294.07,291.73
145.3077,5.7196,0.008277,0.0,0.0,-0.00014626,6.8035,304.98,289.45,294.06,291.73
145.3086,5.6762,0.0091273,0.0,0.0,5.9595e-05,6.7292,304.99,289.45,294.05,291.73
145.3095,5.7393,0.010186,0.0,0.0,0.00036103,6.8186,304.99,289.43,294.04,291.74
145.3104,5.6566,0.0074662,0.0,0.0,0.00041557,6.7131,304.99,289.42,294.03,291.74
145.3113,5.7572,0.0071764,0.0,0.0,0.00087854,6.8247,304.99,289.41,294.02,291.75
145.3122,5.6658,0.0066905,0.0,0.0,0.0011149,6.7462,305.0,289.4,294.01,291.76
145.3131,5.7622,0.0031793,0.0,0.0,0.0010577,6.8218,305.0,289.39,294.0,291.77
145.314,5.6852,0.0023285,0.0,0.0,0.00092533,6.7614,305.0,289.38,293.99,291.78
145.3149,5.7366,0.0023578,0.0,0.0,0.0009357,6.8056,305.0,289.37,293.97,291.79
145.3158,5.7124,0.0020799,0.0,0.0,0.0007003,6.7997,305.01,289.36,293.96,291.79
145.3167,5.7156,0.0017154,0.0,0.0,0.00039871,6.7682,305.01,289.35,293.95,291.8
145.3176,5.7504,0.0022235,0.0,0.0,0.00020973,6.8195,305.01,289.34,293.94,291.81
145.3185,5.6894,0.0041013,0.0,0.0,0.00018072,6.7484,305.01,289.33,293.94,291.81
145.3194,5.7631,0.0049469,0.0,0.0,0.00015302,6.8266,305.01,289.33,293.94,291.81
145.3203,5.6815,0.0041688,0.0,0.0,0.0001046,6.7283,305.01,289.34,293.95,291.81
145.3212,5.7649,0.0051915,0.0,0.0,0.00033294,6.8407,305.01,289.34,293.95,291.81
145.3221,5.6634,0.0039388,0.0,0.0,0.00044323,6.7231,305.0,289.34,293.96,291.8
145.323,5.7319,0.0021039,0.0,0.0,0.00053895,6.8147,305.0,289.34,293.96,291.8
145.3239,5.6792,-0.0006401,0.0,0.0,0.00048261,6.7544,305.0,289.35,293.97,291.8
145.3248,5.7358,-0.003989,0.0,0.0,0.0004052,6.7986,304.99,289.35,293.97,291.8
145.3257,5.7119,-0.0037389,0.0,0.0,0.00056997,6.7865,304.99,289.35,293.98,291.79
145.3266,5.7081,-0.0060475,0.0,0.0,0.00021062,6.7504,304.99,289.35,293.99,291.79
145.3275,5.7252,-0.0061503,0.0,0.0,8.86e-05,6.8035,304.99,289.36,293.99,291.79
145.3284,5.677,-0.0059537,0.0,0.0,-0.0004215,6.7503,304.98,289.36,294.0,291.79
145.3293,5.7511,-0.003771,0.0,0.0,-0.00021993,6.8195,304.98,289.37,293.99,291.79
145.3302,5.662,-0.0027652,0.0,0.0,-0.00058681,6.7051,304.97,289.37,293.99,291.79
145.3311,5.7504,-0.00078076,0.0,0.0,-0.00053081,6.8166,304.97,289.38,293.99,291.79
145.332,5.6638,0.0018671,0.0,0.0,-0.00053986,6.7265,304.96,289.38,293.98,291.79
145.3329,5.7632,0.0039711,0.0,0.0,-0.00040857,6.8307,304.96,289.39,293.98,291.79
145.3338,5.7309,0.0076128,0.0,0.0,-0.00014582,6.7945,304.95,289.39,293.98,291.79
145.3347,5.691,0.0077128,0.0,0.0,-5.6139e-06,6.7625,304.94,289.4,293.98,291.79
145.3356,5.7454,0.0078681,0.0,0.0,0.00021014,6.8206,304.94,289.4,293.97,291.79
145.3365,5.8201,0.0083664,0.0,0.0,0.00058809,6.883,304.93,289.41,293.97,291.79
145.3374,6.0495,0.010181,0.0,0.0,0.0011266,7.2146,304.93,289.42,293.97,291.79
145.3383,5.3614,0.0035252,0.0,0.0,0.00071504,6.3434,305.03,289.53,293.96,291.79
145.3392,6.1259,0.010767,0.0,0.0,0.0017362,7.2805,306.21,290.75,293.94,291.79
145.3401,5.3714,-0.0015959,0.0,0.0,0.00035509,6.3678,307.39,291.96,293.92,291.79
145.341,5.7232,0.0031384,0.0,0.0,0.0010322,6.7843,308.57,293.18,293.9,291.79
145.3419,5.5972,-0.0011024,0.0,0.0,0.00028928,6.6509,309.76,294.4,293.87,291.79
145.3428,5.5858,0.0008796,0.0,0.0,0.00023747,6.6177,310.94,295.61,293.85,291.79
145.3437,5.6094,-0.00060335,0.0,0.0,0.00018718,6.6528,312.12,296.83,293.83,291.79
145.3446,5.682,0.0010524,0.0,0.0,-0.00024878,6.74,313.3,298.05,293.81,291.79
145.3455,5.5229,0.0056049,0.0,0.0,0.00017251,6.5636,314.48,299.26,293.79,291.79
145.3464,5.6262,0.00090128,0.0,0.0,-0.00039271,6.6559,315.67,300.48,293.76,291.79
145.3473,5.5237,0.0072051,0.0,0.0,0.000278,6.5225,316.85,301.7,293.74,291.79
145.3482,5.7793,0.0045729,0.0,0.0,0.00036798,6.8657,318.03,302.91,293.72,291.79
145.3491,5.5428,0.0011351,0.0,0.0,0.00022658,6.5915,320.5,305.24,293.71,291.78
145.35,5.7582,0.0039479,0.0,0.0,0.0010335,6.8409,323.02,307.61,293.7,291.77
145.3509,20.582,0.037476,0.0,0.0,0.0040871,21.58,325.55,309.98,293.69,291.77
145.3518,82.322,0.22726,0.0,0.0,0.026057,96.294,328.08,312.36,293.68,291.76
145.3527,102.71,0.51724,0.0,0.0,0.059124,121.14,330.61,314.73,293.66,291.76
145.3536,113.66,0.70856,0.0,0.0,0.081562,134.64,333.13,317.11,293.65,291.75
145.3545,117.57,1.0388,0.0,0.0,0.12086,139.63,335.66,319.48,293.64,291.75
145.3554,124.5,1.4316,0.0,0.0,0.17026,147.56,338.19,321.85,293.63,291.74
145.3563,125.97,1.8987,0.0,0.0,0.23155,149.42,340.71,324.23,293.62,291.74
145.3572,129.62,2.2636,0.0,0.0,0.28199,153.71,343.24,326.6,293.61,291.73
145.3581,131.18,2.7263,0.0,0.0,0.34927,155.72,345.77,328.98,293.6,291.72
145.359,134.16,3.1438,0.0,0.0,0.41424,159.2,347.37,330.43,293.61,291.72
145.3599,134.86,3.608,0.0,0.0,0.4914,160.08,348.78,331.68,293.64,291.71
145.3608,136.84,4.0134,0.0,0.0,0.56341,162.32,350.19,332.94,293.66,291.7
145.3617,137.77,4.4783,0.0,0.0,0.65195,163.44,351.59,334.19,293.68,291.69
145.3626,138.74,4.9163,0.0,0.0,0.74333,164.6,353.0,335.44,293.7,291.68
145.3635,138.05,5.3077,0.0,0.0,0.83306,163.77,354.41,336.69,293.73,291.68
145.3644,138.11,5.6384,0.0,0.0,0.91376,163.9,355.82,337.95,293.75,291.67
145.3653,137.42,5.9498,0.0,0.0,0.99579,163.11,357.22,339.2,293.77,291.66
145.3662,136.9,6.2386,0.0,0.0,1.0771,162.5,358.63,340.45,293.79,291.65
145.3671,135.98,6.4686,0.0,0.0,1.1466,161.4,360.04,341.71,293.81,291.64
145.368,136.24,6.665,0.0,0.0,1.208,161.65,361.45,342.96,293.84,291.63
145.3689,136.78,6.8562,0.0,0.0,1.2711,162.29,361.58,343.14,293.84,291.62
145.3698,137.5,7.0447,0.0,0.0,1.3364,163.15,361.14,342.83,293.83,291.6
145.3707,138.56,7.2247,0.0,0.0,1.4019,164.37,360.7,342.53,293.82,291.59
145.3716,139.82,7.3961,0.0,0.0,1.4687,165.85,360.26,342.22,293.81,291.57
145.3725,141.8,7.5605,0.0,0.0,1.5382,168.18,359.82,341.92,293.8,291.55
145.3734,129.72,7.6422,0.0,0.0,1.5765,154.03,359.38,341.61,293.8,291.54
145.3743,125.55,7.6532,0.0,0.0,1.5839,149.27,358.93,341.3,293.79,291.52
145.3752,123.89,7.6602,0.0,0.0,1.5883,147.17,358.49,341.0,293.78,291.5
145.3761,120.81,7.6634,0.0,0.0,1.5934,143.56,358.05,340.69,293.77,291.49
145.377,119.43,7.6886,0.0,0.0,1.6066,141.85,357.61,340.39,293.76,291.47
145.3779,117.45,7.6651,0.0,0.0,1.5968,139.46,357.17,340.08,293.75,291.45
145.3788,115.63,7.6767,0.0,0.0,1.6038,137.25,356.55,339.57,293.74,291.45
145.3797,114.24,7.674,0.0,0.0,1.601,135.61,355.77,338.9,293.72,291.46
145.3806,112.83,7.6762,0.0,0.0,1.601,133.92,355.0,338.23,293.71,291.48
145.3815,112.02,7.6839,0.0,0.0,1.6023,132.97,354.22,337.56,293.69,291.49
145.3824,111.08,7.681,0.0,0.0,1.5992,131.82,353.45,336.88,293.67,291.5
145.3833,110.03,7.6993,0.0,0.0,1.6042,130.63,352.68,336.21,293.66,291.51
145.3842,109.32,7.6924,0.0,0.0,1.5991,129.76,351.9,335.54,293.64,291.52
145.3851,108.43,7.7031,0.0,0.0,1.6036,128.67,351.13,334.87,293.63,291.53
145.386,107.56,7.7108,0.0,0.0,1.6052,127.69,350.36,334.19,293.61,291.54
145.3869,107.2,7.7087,0.0,0.0,1.6049,127.22,349.58,333.52,293.59,291.55
145.3878,106.36,7.7174,0.0,0.0,1.6102,126.23,348.81,332.85,293.58,291.56
145.3887,105.81,7.7114,0.0,0.0,1.6099,125.59,348.16,332.28,293.57,291.58
145.3896,105.19,7.7188,0.0,0.0,1.6154,124.86,347.7,331.85,293.57,291.62
145.3905,104.57,7.7135,0.0,0.0,1.6164,124.11,347.23,331.41,293.57,291.65
145.3914,104.1,7.7118,0.0,0.0,1.6173,123.56,346.76,330.98,293.58,291.68
145.3923,103.64,7.7103,0.0,0.0,1.6172,123.01,346.3,330.55,293.58,291.72
145.3932,103.21,7.7064,0.0,0.0,1.6152,122.49,345.83,330.12,293.58,291.75
145.3941,102.68,7.7104,0.0,0.0,1.6181,121.86,345.36,329.68,293.58,291.78
145.395,102.29,7.7094,0.0,0.0,1.6138,121.4,344.9,329.25,293.59,291.82
145.3959,101.81,7.7113,0.0,0.0,1.6135,120.83,344.43,328.82,293.59,291.85
145.3968,101.44,7.7143,0.0,0.0,1.6122,120.39,343.96,328.39,293.59,291.88
145.3977,101.0,7.719,0.0,0.0,1.6118,119.88,343.5,327.95,293.59,291.92
145.3986,100.68,7.7242,0.0,0.0,1.6138,119.48,343.06,327.55,293.6,291.94
145.3995,100.25,7.7243,0.0,0.0,1.6139,118.98,342.68,327.22,293.6,291.96
145.4004,99.968,7.7241,0.0,0.0,1.6157,118.65,342.31,326.89,293.6,291.98
145.4013,99.623,7.7217,0.0,0.0,1.6168,118.25,341.94,326.56,293.6,291.99
145.4022,99.315,7.7203,0.0,0.0,1.6188,117.86,341.56,326.23,293.6,292.01
145.4031,99.005,7.7151,0.0,0.0,1.6193,117.5,341.19,325.9,293.6,292.03
145.404,98.686,7.7118,0.0,0.0,1.6192,117.12,340.81,325.56,293.6,292.04
145.4049,98.428,7.7099,0.0,0.0,1.6192,116.81,340.44,325.23,293.6,292.06
145.4058,98.114,7.7068,0.0,0.0,1.6171,116.42,340.07,324.9,293.6,292.08
145.4067,97.88,7.7057,0.0,0.0,1.615,116.17,339.69,324.57,293.6,292.09
145.4076,97.562,7.705,0.0,0.0,1.6126,115.79,339.32,324.24,293.6,292.11
145.4085,97.357,7.7098,0.0,0.0,1.613,115.54,338.96,323.92,293.6,292.12
145.4094,97.052,7.7128,0.0,0.0,1.6115,115.17,338.72,323.7,293.59,292.13
145.4103,96.828,7.7158,0.0,0.0,1.6104,114.9,338.47,323.48,293.59,292.13
145.4112,96.545,7.723,0.0,0.0,1.6119,114.57,338.23,323.25,293.59,292.13
145.4121,96.283,7.725,0.0,0.0,1.6123,114.28,337.98,323.03,293.59,292.13
145.413,96.071,7.7288,0.0,0.0,1.6147,114.02,337.74,322.8,293.58,292.14
145.4139,95.753,7.7322,0.0,0.0,1.6171,113.64,337.49,322.58,293.58,292.14
145.4148,95.334,7.7297,0.0,0.0,1.6179,113.15,337.25,322.35,293.58,292.14
145.4157,94.571,7.7273,0.0,0.0,1.6194,112.25,337.0,322.13,293.57,292.15
145.4166,93.738,7.7258,0.0,0.0,1.6214,111.27,336.75,321.9,293.57,292.15
145.4175,92.529,7.7224,0.0,0.0,1.6215,109.85,336.51,321.68,293.57,292.15
145.4184,91.209,7.7159,0.0,0.0,1.6202,108.3,336.27,321.46,293.57,292.15
145.4193,89.409,7.7098,0.0,0.0,1.6182,106.16,336.21,321.35,293.55,292.14
145.4202,87.186,7.7071,0.0,0.0,1.6153,103.56,336.15,321.24,293.54,292.13
145.4211,83.004,7.7003,0.0,0.0,1.61,98.781,336.09,321.13,293.52,292.12
145.422,63.444,7.6614,0.0,0.0,1.5913,76.225,336.03,321.02,293.51,292.11
145.4229,35.7,7.6141,0.0,0.0,1.5676,43.45,335.97,320.91,293.5,292.1
145.4238,7.0221,7.5408,0.0,0.0,1.5338,9.411,335.91,320.8,293.48,292.09
145.4247,-1.3962,7.4359,0.0,0.0,1.4881,-1.7067,335.85,320.69,293.47,292.08
145.4256,0.98187,7.4529,0.0,0.0,1.4925,1.2653,335.79,320.58,293.46,292.06
145.4265,11.417,7.573,0.0,0.0,1.547,13.822,335.73,320.47,293.44,292.05
145.4274,6.9235,7.5377,0.0,0.0,1.5332,8.5052,335.67,320.36,293.43,292.04
145.4283,0.3665,7.5149,0.0,0.0,1.526,0.39348,335.61,320.25,293.41,292.03
145.4292,8.007,7.5476,0.0,0.0,1.5415,9.1385,335.6,320.2,293.42,292.02
145.4301,6.2893,7.5484,0.0,0.0,1.5449,7.4898,335.6,320.15,293.44,292.02
145.431,2.3451,7.5313,0.0,0.0,1.5372,2.8499,335.6,320.11,293.45,292.01
145.4319,5.5713,7.5415,0.0,0.0,1.5419,6.4983,335.6,320.06,293.47,292.0
145.4328,5.7989,7.5552,0.0,0.0,1.5468,7.0481,335.6,320.01,293.48,291.99
145.4337,4.0925,7.5207,0.0,0.0,1.5309,4.89,335.6,319.97,293.49,291.98
145.4346,5.2192,7.5443,0.0,0.0,1.5391,6.0751,335.6,319.92,293.51,291.97
145.4355,6.0662,7.5523,0.0,0.0,1.5392,7.2439,335.6,319.87,293.52,291.97
145.4364,4.1822,7.5401,0.0,0.0,1.5318,4.899,335.6,319.83,293.53,291.96
145.4373,4.7574,7.5504,0.0,0.0,1.5354,5.5911,335.6,319.78,293.55,291.95
145.4382,5.3182,7.5516,0.0,0.0,1.5348,6.3445,335.6,319.73,293.56,291.94
145.4391,4.3108,7.5606,0.0,0.0,1.5379,5.1551,335.6,319.7,293.6,291.94
145.44,5.166,7.5636,0.0,0.0,1.5402,6.1249,335.6,319.67,293.65,291.94
145.4409,5.2915,7.563,0.0,0.0,1.5422,6.3221,335.59,319.64,293.7,291.94
145.4418,4.6436,7.5596,0.0,0.0,1.5423,5.4983,335.59,319.61,293.74,291.94
145.4427,5.1037,7.5542,0.0,0.0,1.5428,6.0358,335.59,319.58,293.79,291.94
145.4436,4.9302,7.5588,0.0,0.0,1.5469,5.8359,335.58,319.55,293.84,291.94
145.4445,4.8658,7.5522,0.0,0.0,1.5456,5.7838,335.58,319.52,293.88,291.94
145.4454,4.9373,7.5492,0.0,0.0,1.5444,5.858,335.58,319.49,293.93,291.94
145.4463,4.9485,7.5461,0.0,0.0,1.5432,5.8911,335.58,319.46,293.98,291.94
145.4472,4.7836,7.544,0.0,0.0,1.5408,5.6853,335.57,319.43,294.02,291.94
145.4481,5.2009,7.5501,0.0,0.0,1.5408,6.1733,335.57,319.4,294.07,291.94
145.449,4.7286,7.5504,0.0,0.0,1.5395,5.603,335.56,319.34,294.09,291.94
145.4499,5.1743,7.5553,0.0,0.0,1.54,6.1462,335.54,319.26,294.1,291.93
145.4508,4.7916,7.5592,0.0,0.0,1.5392,5.6974,335.53,319.18,294.1,291.92
145.4517,5.0233,7.5562,0.0,0.0,1.5382,5.9474,335.51,319.1,294.11,291.92
145.4526,4.8471,7.5643,0.0,0.0,1.5429,5.7659,335.49,319.02,294.11,291.91
145.4535,4.993,7.5594,0.0,0.0,1.5423,5.9354,335.48,318.94,294.12,291.91
145.4544,5.0351,7.5571,0.0,0.0,1.5437,5.9835,335.46,318.86,294.12,291.9
145.4553,4.8552,7.5541,0.0,0.0,1.5447,5.7557,335.44,318.78,294.13,291.9
145.4562,5.1346,7.5487,0.0,0.0,1.5445,6.088,335.43,318.7,294.14,291.89
145.4571,4.8182,7.5462,0.0,0.0,1.5445,5.7306,335.41,318.62,294.14,291.89
145.458,5.0953,7.5456,0.0,0.0,1.5443,6.059,335.4,318.54,294.15,291.88
145.4589,4.8519,7.5399,0.0,0.0,1.5407,5.7738,335.37,318.46,294.13,291.87
145.4598,5.0591,7.5396,0.0,0.0,1.5397,5.9997,335.33,318.39,294.1,291.87
145.4607,5.0275,7.5419,0.0,0.0,1.5381,5.9747,335.29,318.31,294.06,291.86
145.4616,4.9978,7.5436,0.0,0.0,1.5373,5.9266,335.24,318.23,294.02,291.86
145.4625,5.0146,7.5518,0.0,0.0,1.5372,5.9615,335.2,318.16,293.99,291.85
145.4634,4.8906,7.5504,0.0,0.0,1.5352,5.8029,335.16,318.08,293.95,291.85
145.4643,5.0735,7.5584,0.0,0.0,1.5369,6.0147,335.12,318.0,293.92,291.84
145.4652,4.9497,7.5606,0.0,0.0,1.538,5.8592,335.08,317.92,293.88,291.84
145.4661,5.0332,7.563,0.0,0.0,1.5401,5.9698,335.04,317.85,293.84,291.83
145.467,4.9254,7.5635,0.0,0.0,1.5416,5.854,335.0,317.77,293.81,291.82
145.4679,5.0799,7.5635,0.0,0.0,1.544,6.0258,334.96,317.69,293.77,291.82
145.4688,4.9591,7.5581,0.0,0.0,1.5441,5.8923,334.92,317.62,293.75,291.82
145.4697,5.0458,7.5578,0.0,0.0,1.5458,5.9885,334.89,317.54,293.75,291.82
145.4706,4.9939,7.5559,0.0,0.0,1.5464,5.9363,334.87,317.46,293.76,291.82
145.4715,5.0221,7.5513,0.0,0.0,1.545,5.9275,334.84,317.39,293.76,291.82
145.4724,5.039,7.5528,0.0,0.0,1.5456,5.9684,334.81,317.31,293.76,291.82
145.4733,5.0056,7.5502,0.0,0.0,1.5436,5.9367,334.78,317.23,293.76,291.82
145.4742,5.05,7.5488,0.0,0.0,1.5409,6.0158,334.76,317.16,293.77,291.82
145.4751,4.9703,7.5521,0.0,0.0,1.5406,5.8873,334.73,317.08,293.77,291.82
145.476,5.1165,7.5559,0.0,0.0,1.5394,6.0862,334.7,317.0,293.77,291.82
145.4769,4.9763,7.5553,0.0,0.0,1.5376,5.8802,334.67,316.92,293.78,291.82
145.4778,5.0684,7.56,0.0,0.0,1.5399,6.0228,334.65,316.85,293.78,291.82
145.4787,4.9396,7.5601,0.0,0.0,1.5403,5.8721,334.62,316.76,293.78,291.82
145.4796,5.0815,7.5577,0.0,0.0,1.5409,6.041,334.6,316.66,293.78,291.82
145.4805,5.0067,7.557,0.0,0.0,1.5433,5.9495,334.58,316.56,293.79,291.83
145.4814,5.0721,7.5531,0.0,0.0,1.5434,6.0027,334.56,316.45,293.79,291.83
145.4823,5.0061,7.5476,0.0,0.0,1.5432,5.9425,334.53,316.35,293.79,291.84
145.4832,5.0243,7.5459,0.0,0.0,1.5435,5.9535,334.51,316.24,293.8,291.84
145.4841,5.0427,7.5431,0.0,0.0,1.5432,6.007,334.49,316.14,293.8,291.85
145.485,5.0444,7.5384,0.0,0.0,1.5402,5.9727,334.47,316.03,293.8,291.86
145.4859,5.0477,7.5411,0.0,0.0,1.54,5.9937,334.45,315.93,293.8,291.86
145.4868,5.0124,7.5413,0.0,0.0,1.5387,5.9484,334.42,315.83,293.81,291.87
145.4877,5.1134,7.5414,0.0,0.0,1.5365,6.0558,334.4,315.72,293.81,291.87
145.4886,5.1013,7.5503,0.0,0.0,1.537,6.061,334.38,315.62,293.81,291.88
145.4895,5.0471,7.552,0.0,0.0,1.5359,5.9948,334.34,315.52,293.81,291.88
145.4904,5.1353,7.5563,0.0,0.0,1.5372,6.0961,334.3,315.42,293.82,291.89
145.4913,5.0807,7.5577,0.0,0.0,1.5372,6.0349,334.26,315.32,293.82,291.89
145.4922,5.121,7.5637,0.0,0.0,1.5396,6.0719,334.23,315.22,293.82,291.9
145.4931,5.1327,7.5634,0.0,0.0,1.5412,6.0732,334.19,315.12,293.83,291.91
145.494,5.123,7.5609,0.0,0.0,1.542,6.0873,334.15,315.02,293.83,291.91
145.4949,5.1009,7.5601,0.0,0.0,1.5441,6.0501,334.11,314.92,293.83,291.92
145.4958,5.2826,7.5585,0.0,0.0,1.5457,6.2608,334.07,314.83,293.83,291.92
145.4967,5.0401,7.5535,0.0,0.0,1.545,5.9877,334.03,314.73,293.84,291.93
145.4976,5.2364,7.5501,0.0,0.0,1.5455,6.2197,334.0,314.63,293.84,291.93
145.4985,5.0545,7.5493,0.0,0.0,1.5452,5.9948,333.96,314.53,293.84,291.94
145.4994,5.236,7.5473,0.0,0.0,1.5429,6.2126,333.9,314.44,293.84,291.93
145.5003,5.1512,7.5483,0.0,0.0,1.5414,6.1353,333.84,314.34,293.84,291.93
145.5012,5.2333,7.5484,0.0,0.0,1.5398,6.1896,333.79,314.25,293.84,291.92
145.5021,5.1499,7.5546,0.0,0.0,1.5399,6.1163,333.73,314.16,293.84,291.92
145.503,5.1101,7.5548,0.0,0.0,1.5379,6.0421,333.67,314.06,293.84,291.91
145.5039,5.1162,7.5592,0.0,0.0,1.5393,6.0852,333.61,313.97,293.84,291.91
145.5048,5.0541,7.5571,0.0,0.0,1.5387,6.009,333.56,313.88,293.84,291.9
145.5057,5.2342,7.5615,0.0,0.0,1.5426,6.2368,333.5,313.78,293.84,291.89
145.5066,5.013,7.5559,0.0,0.0,1.5418,5.9476,333.44,313.69,293.84,291.89
145.5075,5.318,7.5543,0.0,0.0,1.5434,6.316,333.38,313.6,293.84,291.88
145.5084,4.999,7.549,0.0,0.0,1.5432,5.9334,333.33,313.5,293.84,291.88
145.5093,5.4097,7.5436,0.0,0.0,1.5427,6.4074,333.28,313.42,293.84,291.88
145.5102,4.8694,7.5433,0.0,0.0,1.5437,5.7598,333.25,313.35,293.83,291.88
145.5111,5.2902,7.5393,0.0,0.0,1.5411,6.2829,333.21,313.27,293.82,291.88
145.512,4.9961,7.5398,0.0,0.0,1.5402,5.9497,333.17,313.19,293.81,291.88
145.5129,5.2601,7.5382,0.0,0.0,1.5372,6.2297,333.13,313.11,293.8,291.88
145.5138,5.0502,7.5414,0.0,0.0,1.5363,6.0059,333.09,313.04,293.79,291.88
145.5147,5.2197,7.5446,0.0,0.0,1.5356,6.1764,333.05,312.96,293.79,291.88
145.5156,5.1984,7.5506,0.0,0.0,1.5357,6.1796,333.02,312.88,293.78,291.88
145.5165,5.109,7.5501,0.0,0.0,1.5344,6.0329,332.98,312.81,293.77,291.88
145.5174,5.1352,7.5553,0.0,0.0,1.5361,6.0954,332.94,312.73,293.76,291.88
145.5183,5.0968,7.5606,0.0,0.0,1.5384,6.0703,332.9,312.65,293.75,291.88
145.5192,5.2271,7.5624,0.0,0.0,1.54,6.1926,332.86,312.58,293.76,291.88
145.5201,5.0755,7.5586,0.0,0.0,1.5413,6.0331,332.81,312.5,293.76,291.88
145.521,5.2466,7.5586,0.0,0.0,1.5435,6.2086,332.77,312.42,293.77,291.88
145.5219,5.094,7.5569,0.0,0.0,1.5451,6.0359,332.73,312.35,293.78,291.88
145.5228,5.1823,7.5521,0.0,0.0,1.5448,6.1484,332.68,312.27,293.79,291.88
145.5237,5.1495,7.5515,0.0,0.0,1.5455,6.1143,332.64,312.19,293.8,291.88
145.5246,5.167,7.5505,0.0,0.0,1.5447,6.1283,332.6,312.11,293.81,291.88
145.5255,5.2447,7.5473,0.0,0.0,1.5427,6.2419,332.55,312.04,293.81,291.88
145.5264,4.9847,7.5483,0.0,0.0,1.5418,5.9126,332.51,311.96,293.82,291.88
145.5273,5.2444,7.5501,0.0,0.0,1.5406,6.237,332.46,311.88,293.83,291.88
145.5282,5.039,7.5504,0.0,0.0,1.5396,5.9806,332.42,311.81,293.84,291.88
145.5291,5.1753,7.5557,0.0,0.0,1.5395,6.1404,332.37,311.71,293.85,291.87
145.53,5.0694,7.5577,0.0,0.0,1.5388,6.0269,332.3,311.61,293.85,291.87
145.5309,5.2467,7.5601,0.0,0.0,1.54,6.2096,332.24,311.5,293.86,291.86
145.5318,5.1411,7.5597,0.0,0.0,1.5414,6.1425,332.18,311.39,293.86,291.86
145.5327,5.162,7.5567,0.0,0.0,1.5424,6.088,332.11,311.28,293.87,291.85
145.5336,5.274,7.5558,0.0,0.0,1.5437,6.2841,332.05,311.18,293.87,291.85
145.5345,5.043,7.5496,0.0,0.0,1.5434,5.9717,331.99,311.07,293.88,291.84
145.5354,5.2745,7.5509,0.0,0.0,1.5446,6.281,331.93,310.96,293.88,291.84
145.5363,5.0989,7.5431,0.0,0.0,1.543,6.047,331.86,310.86,293.89,291.83
145.5372,5.3248,7.5417,0.0,0.0,1.5424,6.3191,331.8,310.75,293.89,291.82
145.5381,5.0184,7.5382,0.0,0.0,1.5395,5.9477,331.74,310.64,293.9,291.82
145.539,5.3305,7.5401,0.0,0.0,1.5389,6.3162,331.68,310.55,293.91,291.82
145.5399,5.081,7.541,0.0,0.0,1.5376,6.0179,331.62,310.47,293.91,291.82
145.5408,5.2613,7.5455,0.0,0.0,1.5366,6.2337,331.56,310.39,293.92,291.82
145.5417,5.1306,7.5508,0.0,0.0,1.5361,6.0961,331.5,310.31,293.92,291.82
145.5426,5.2963,7.5518,0.0,0.0,1.5354,6.2829,331.45,310.23,293.93,291.82
145.5435,5.2047,7.5583,0.0,0.0,1.5369,6.1917,331.39,310.15,293.93,291.82
145.5444,5.1245,7.5584,0.0,0.0,1.5376,6.062,331.33,310.07,293.94,291.82
145.5453,5.2649,7.5632,0.0,0.0,1.541,6.2561,331.27,309.99,293.94,291.82
145.5462,5.0465,7.5614,0.0,0.0,1.5412,5.981,331.22,309.91,293.95,291.82
145.5471,5.346,7.5621,0.0,0.0,1.5439,6.3583,331.16,309.83,293.96,291.82
145.548,5.0671,7.5581,0.0,0.0,1.5448,6.0149,331.1,309.75,293.96,291.82
145.5489,5.337,7.5543,0.0,0.0,1.5454,6.325,331.05,309.67,293.97,291.82
145.5498,5.1147,7.5528,0.0,0.0,1.5452,6.0702,330.99,309.59,293.98,291.82
145.5507,5.286,7.5507,0.0,0.0,1.545,6.2488,330.94,309.52,293.98,291.83
145.5516,5.2044,7.549,0.0,0.0,1.5439,6.1826,330.89,309.44,293.99,291.83
145.5525,5.1591,7.5492,0.0,0.0,1.5425,6.112,330.84,309.36,294.0,291.84
145.5534,5.2876,7.5502,0.0,0.0,1.5409,6.296,330.79,309.29,294.01,291.84
145.5543,5.1515,7.5496,0.0,0.0,1.5388,6.0882,330.73,309.21,294.02,291.85
145.5552,5.3421,7.558,0.0,0.0,1.5398,6.3695,330.68,309.13,294.03,291.86
145.5561,5.125,7.5553,0.0,0.0,1.5375,6.057,330.63,309.06,294.03,291.86
145.557,5.34,7.5585,0.0,0.0,1.5392,6.3504,330.58,308.98,294.04,291.87
145.5579,5.0881,7.5588,0.0,0.0,1.5402,6.0451,330.53,308.9,294.05,291.87
145.5588,5.3577,7.5574,0.0,0.0,1.5425,6.3614,330.47,308.82,294.06,291.88
145.5597,5.1158,7.5549,0.0,0.0,1.543,6.0832,330.41,308.74,294.06,291.88
145.5606,5.3093,7.5495,0.0,0.0,1.5426,6.298,330.36,308.65,294.06,291.89
145.5615,5.2102,7.5517,0.0,0.0,1.5453,6.1824,330.3,308.57,294.07,291.89
145.5624,5.2196,7.5429,0.0,0.0,1.5427,6.1765,330.24,308.48,294.07,291.9
145.5633,5.2652,7.5401,0.0,0.0,1.5419,6.258,330.18,308.4,294.07,291.91
145.5642,5.1613,7.5407,0.0,0.0,1.541,6.1285,330.13,308.31,294.07,291.91
145.5651,5.3332,7.5403,0.0,0.0,1.5395,6.3453,330.07,308.23,294.08,291.92
145.566,5.1142,7.5388,0.0,0.0,1.5368,6.067,330.01,308.14,294.08,291.92
145.5669,5.3843,7.5441,0.0,0.0,1.5366,6.3763,329.95,308.06,294.08,291.93
145.5678,5.0879,7.5464,0.0,0.0,1.5353,6.0399,329.9,307.97,294.09,291.93
145.5687,5.3635,7.5512,0.0,0.0,1.5355,6.3553,329.84,307.89,294.09,291.94
145.5696,5.1293,7.5553,0.0,0.0,1.536,6.0913,329.77,307.82,294.08,291.94
145.5705,5.29,7.5598,0.0,0.0,1.5377,6.2801,329.71,307.75,294.08,291.94
145.5714,5.1648,7.5623,0.0,0.0,1.5398,6.1475,329.64,307.68,294.07,291.94
145.5723,5.2399,7.5597,0.0,0.0,1.5399,6.2006,329.58,307.61,294.07,291.94
145.5732,5.2785,7.5603,0.0,0.0,1.5422,6.267,329.51,307.54,294.06,291.94
145.5741,5.1587,7.5588,0.0,0.0,1.5447,6.1052,329.45,307.48,294.05,291.94
145.575,5.3007,7.5571,0.0,0.0,1.5458,6.3174,329.38,307.41,294.05,291.94
145.5759,5.0939,7.5484,0.0,0.0,1.5439,6.05,329.31,307.34,294.04,291.94
145.5768,5.3389,7.5506,0.0,0.0,1.5449,6.3485,329.25,307.27,294.04,291.94
145.5777,5.0682,7.5504,0.0,0.0,1.5439,6.03,329.18,307.2,294.03,291.94
145.5786,5.3424,7.547,0.0,0.0,1.5417,6.3231,329.12,307.13,294.03,291.94
145.5795,5.1079,7.5474,0.0,0.0,1.5411,6.0521,329.06,307.06,294.02,291.94
145.5804,5.2818,7.5482,0.0,0.0,1.5392,6.256,329.0,306.98,294.01,291.95
145.5813,5.1573,7.555,0.0,0.0,1.5388,6.1342,328.94,306.91,294.0,291.95
145.5822,5.2284,7.5539,0.0,0.0,1.5375,6.2067,328.88,306.84,293.99,291.96
145.5831,5.2124,7.5584,0.0,0.0,1.5392,6.2099,328.82,306.76,293.99,291.97
145.584,5.141,7.5579,0.0,0.0,1.5393,6.1113,328.76,306.69,293.98,291.97
145.5849,5.2922,7.5556,0.0,0.0,1.5412,6.297,328.69,306.61,293.97,291.98
145.5858,5.0867,7.5517,0.0,0.0,1.5416,6.0332,328.63,306.54,293.96,291.98
145.5867,5.3256,7.5547,0.0,0.0,1.5446,6.3315,328.57,306.47,293.95,291.99
145.5876,5.0809,7.5456,0.0,0.0,1.5432,6.0309,328.51,306.39,293.94,291.99
145.5885,5.3224,7.5428,0.0,0.0,1.5425,6.3,328.45,306.32,293.94,292.0
145.5894,5.0892,7.5416,0.0,0.0,1.5423,6.0552,328.4,306.24,293.94,292.0
145.5903,5.2969,7.5384,0.0,0.0,1.5402,6.2932,328.34,306.15,293.94,292.01
145.5912,5.1582,7.5375,0.0,0.0,1.5391,6.1385,328.29,306.07,293.94,292.02
145.5921,5.2187,7.5375,0.0,0.0,1.5368,6.1624,328.23,305.99,293.94,292.02
145.593,5.2449,7.5421,0.0,0.0,1.5366,6.2348,328.18,305.91,293.95,292.03
145.5939,5.1469,7.5458,0.0,0.0,1.5356,6.1051,328.12,305.82,293.95,292.03
145.5948,5.2928,7.5506,0.0,0.0,1.5359,6.2952,328.07,305.74,293.95,292.04
145.5957,5.1004,7.5517,0.0,0.0,1.535,6.051,328.01,305.66,293.96,292.04
145.5966,5.3374,7.559,0.0,0.0,1.5372,6.3271,327.96,305.58,293.96,292.05
145.5975,5.0826,7.5609,0.0,0.0,1.5398,6.0452,327.91,305.49,293.96,292.05
145.5984,5.3361,7.5619,0.0,0.0,1.5408,6.3214,327.85,305.41,293.96,292.06
145.5993,5.1216,7.5596,0.0,0.0,1.5422,6.0802,327.8,305.34,293.97,292.06
145.6002,5.2964,7.558,0.0,0.0,1.5441,6.288,327.74,305.27,293.98,292.06
145.6011,5.1853,7.5577,0.0,0.0,1.5457,6.1796,327.69,305.19,293.99,292.06
145.602,5.2346,7.5515,0.0,0.0,1.5453,6.2067,327.63,305.12,294.0,292.06
145.6029,5.259,7.5493,0.0,0.0,1.545,6.2519,327.58,305.05,294.0,292.06
145.6038,5.1729,7.5475,0.0,0.0,1.5432,6.1283,327.52,304.98,294.01,292.06
145.6047,5.3058,7.5488,0.0,0.0,1.5433,6.3061,327.47,304.91,294.02,292.06
145.6056,5.1384,7.5466,0.0,0.0,1.5402,6.076,327.41,304.84,294.03,292.06
145.6065,5.3456,7.5506,0.0,0.0,1.5405,6.3513,327.36,304.77,294.04,292.06
145.6074,5.1014,7.553,0.0,0.0,1.5391,6.0621,327.3,304.69,294.04,292.06
145.6083,5.35,7.5562,0.0,0.0,1.5385,6.3394,327.25,304.62,294.05,292.06
145.6092,5.1366,7.5585,0.0,0.0,1.5392,6.0983,327.19,304.55,294.06,292.06
145.6101,5.328,7.5608,0.0,0.0,1.5402,6.3051,327.11,304.49,294.07,292.07
145.611,5.1864,7.5605,0.0,0.0,1.5417,6.1858,327.04,304.42,294.07,292.08
145.6119,5.2608,7.5581,0.0,0.0,1.5424,6.2318,326.97,304.36,294.08,292.08
145.6128,5.2918,7.5546,0.0,0.0,1.5447,6.291,326.9,304.29,294.08,292.09
145.6137,5.2159,7.5492,0.0,0.0,1.5438,6.1978,326.83,304.22,294.09,292.09
145.6146,5.3531,7.5467,0.0,0.0,1.5441,6.3604,326.76,304.16,294.09,292.1
145.6155,5.1475,7.5423,0.0,0.0,1.5425,6.1055,326.69,304.09,294.1,292.1
145.6164,5.3855,7.5401,0.0,0.0,1.5418,6.3906,326.62,304.03,294.1,292.11
145.6173,5.1347,7.539,0.0,0.0,1.5397,6.0951,326.54,303.96,294.11,292.11
145.6182,5.3844,7.5421,0.0,0.0,1.5384,6.3875,326.47,303.89,294.12,292.12
145.6191,5.1642,7.543,0.0,0.0,1.5372,6.1385,326.41,303.83,294.12,292.13
145.62,5.3436,7.5474,0.0,0.0,1.5363,6.3453,326.34,303.75,294.13,292.14
145.6209,5.2262,7.5507,0.0,0.0,1.5363,6.225,326.28,303.68,294.14,292.15
145.6218,5.2808,7.5533,0.0,0.0,1.536,6.2498,326.22,303.61,294.15,292.16
145.6227,5.301,7.56,0.0,0.0,1.5383,6.3125,326.15,303.54,294.15,292.17
145.6236,5.2269,7.5605,0.0,0.0,1.5383,6.1838,326.09,303.47,294.16,292.18
145.6245,5.3665,7.5632,0.0,0.0,1.541,6.3775,326.03,303.4,294.17,292.19
145.6254,5.1741,7.5624,0.0,0.0,1.5427,6.1375,325.96,303.32,294.18,292.2
145.6263,5.4069,7.5607,0.0,0.0,1.5439,6.4279,325.9,303.25,294.19,292.21
145.6272,5.1556,7.5575,0.0,0.0,1.5447,6.1174,325.84,303.18,294.2,292.23
145.6281,5.4057,7.5544,0.0,0.0,1.5459,6.4195,325.78,303.11,294.2,292.24
145.629,5.1703,7.5515,0.0,0.0,1.5455,6.1446,325.71,303.04,294.21,292.25
145.6299,5.3813,7.5483,0.0,0.0,1.5438,6.3604,325.66,302.98,294.22,292.26
145.6308,5.2313,7.5511,0.0,0.0,1.5441,6.2058,325.61,302.92,294.24,292.27
145.6317,5.3078,7.5499,0.0,0.0,1.5424,6.2811,325.55,302.86,294.25,292.28
145.6326,5.3267,7.5494,0.0,0.0,1.5408,6.3384,325.5,302.8,294.26,292.29
145.6335,5.2415,7.5539,0.0,0.0,1.5401,6.2088,325.44,302.74,294.27,292.3
145.6344,5.3672,7.5573,0.0,0.0,1.5397,6.3784,325.39,302.68,294.28,292.31
145.6353,5.201,7.557,0.0,0.0,1.5389,6.1635,325.33,302.62,294.29,292.33
145.6362,5.4207,7.5602,0.0,0.0,1.5404,6.4547,325.28,302.55,294.3,292.34
145.6371,5.1746,7.5591,0.0,0.0,1.5411,6.1354,325.22,302.49,294.31,292.35
145.638,5.4096,7.5573,0.0,0.0,1.5421,6.3966,325.17,302.43,294.32,292.36
145.6389,5.1831,7.5552,0.0,0.0,1.5439,6.1536,325.11,302.37,294.33,292.37
145.6398,5.358,7.5489,0.0,0.0,1.5428,6.3605,325.05,302.3,294.34,292.37
145.6407,5.2456,7.5488,0.0,0.0,1.5444,6.2369,324.99,302.23,294.35,292.36
145.6416,5.3224,7.543,0.0,0.0,1.5427,6.3183,324.93,302.16,294.36,292.36
145.6425,5.3073,7.5394,0.0,0.0,1.5414,6.3162,324.87,302.09,294.37,292.36
145.6434,5.2352,7.5406,0.0,0.0,1.5409,6.2158,324.81,302.01,294.38,292.35
145.6443,5.3854,7.5401,0.0,0.0,1.539,6.3846,324.75,301.94,294.38,292.35
145.6452,5.194,7.5399,0.0,0.0,1.5362,6.1485,324.69,301.87,294.39,292.35
145.6461,5.4132,7.5478,0.0,0.0,1.5373,6.4308,324.63,301.8,294.4,292.35
145.647,5.1627,7.5471,0.0,0.0,1.5353,6.1346,324.57,301.73,294.41,292.34
145.6479,5.4127,7.5532,0.0,0.0,1.5355,6.4348,324.51,301.65,294.42,292.34
145.6488,5.1769,7.5585,0.0,0.0,1.5377,6.1414,324.45,301.58,294.43,292.34
145.6497,5.3965,7.5607,0.0,0.0,1.5389,6.3926,324.4,301.52,294.43,292.33
145.6506,5.2452,7.5601,0.0,0.0,1.5393,6.2359,324.35,301.47,294.44,292.33
145.6515,5.3082,7.563,0.0,0.0,1.5426,6.2801,324.3,301.41,294.45,292.32
145.6524,5.3137,7.5623,0.0,0.0,1.5445,6.3224,324.25,301.35,294.46,292.32
145.6533,5.2417,7.5559,0.0,0.0,1.5438,6.2167,324.2,301.29,294.47,292.31
145.6542,5.3939,7.5557,0.0,0.0,1.5455,6.4026,324.15,301.24,294.47,292.3
145.6551,5.2073,7.5508,0.0,0.0,1.5451,6.1697,324.1,301.18,294.48,292.3
145.656,5.4327,7.5514,0.0,0.0,1.5454,6.4478,324.05,301.12,294.49,292.29
145.6569,5.1759,7.5466,0.0,0.0,1.5423,6.1496,324.01,301.06,294.5,292.29
145.6578,5.4185,7.5477,0.0,0.0,1.5417,6.4267,323.96,301.0,294.51,292.28
145.6587,5.1983,7.5487,0.0,0.0,1.5405,6.1768,323.91,300.95,294.52,292.28
145.6596,5.396,7.5502,0.0,0.0,1.5389,6.3855,323.86,300.9,294.52,292.29
145.6605,5.2464,7.5543,0.0,0.0,1.5389,6.243,323.81,300.85,294.53,292.31
145.6614,5.3296,7.5577,0.0,0.0,1.539,6.3254,323.77,300.8,294.54,292.33
145.6623,5.2926,7.5579,0.0,0.0,1.5398,6.2912,323.72,300.76,294.55,292.35
145.6632,5.2405,7.5558,0.0,0.0,1.5391,6.2017,323.67,300.71,294.56,292.37
145.6641,5.3876,7.5587,0.0,0.0,1.5422,6.4106,323.63,300.66,294.57,292.39
145.665,5.175,7.5534,0.0,0.0,1.5423,6.1456,323.58,300.62,294.57,292.41
145.6659,5.4004,7.551,0.0,0.0,1.5437,6.4218,323.53,300.57,294.58,292.43
145.6668,5.1759,7.5477,0.0,0.0,1.5429,6.1416,323.49,300.52,294.59,292.45
145.6677,5.4206,7.543,0.0,0.0,1.5427,6.4518,323.44,300.47,294.6,292.47
145.6686,5.183,7.5408,0.0,0.0,1.5416,6.1484,323.39,300.43,294.61,292.49
145.6695,5.3908,7.5398,0.0,0.0,1.5404,6.3945,323.34,300.37,294.62,292.5
145.6704,5.2395,7.5394,0.0,0.0,1.5388,6.2349,323.28,300.3,294.62,292.52
145.6713,5.327,7.5402,0.0,0.0,1.5371,6.2961,323.22,300.24,294.63,292.54
145.6722,5.3257,7.5433,0.0,0.0,1.5357,6.3224,323.16,300.17,294.64,292.55
145.6731,5.255,7.5469,0.0,0.0,1.5346,6.2319,323.1,300.1,294.65,292.57
145.674,5.3872,7.5526,0.0,0.0,1.5358,6.4026,323.04,300.04,294.66,292.59
145.6749,5.1823,7.5538,0.0,0.0,1.5355,6.1565,322.98,299.97,294.67,292.6
145.6758,5.4252,7.56,0.0,0.0,1.5384,6.4326,322.92,299.9,294.67,292.62
145.6767,5.1951,7.5622,0.0,0.0,1.5395,6.1646,322.86,299.84,294.68,292.64
145.6776,5.4317,7.5613,0.0,0.0,1.5411,6.4428,322.8,299.77,294.69,292.65
145.6785,5.1961,7.5619,0.0,0.0,1.543,6.1686,322.74,299.71,294.7,292.67
145.6794,5.3845,7.5589,0.0,0.0,1.5448,6.3935,322.68,299.64,294.7,292.67
145.6803,5.265,7.5558,0.0,0.0,1.546,6.244,322.62,299.58,294.71,292.67
145.6812,5.3538,7.5514,0.0,0.0,1.5447,6.3254,322.56,299.51,294.71,292.66
145.6821,5.3331,7.5506,0.0,0.0,1.5447,6.3352,322.5,299.45,294.71,292.66
145.683,5.2684,7.5473,0.0,0.0,1.5429,6.2418,322.44,299.39,294.71,292.65
145.6839,5.3991,7.5509,0.0,0.0,1.5434,6.4026,322.38,299.32,294.72,292.64
145.6848,5.2137,7.5471,0.0,0.0,1.5396,6.1726,322.32,299.26,294.72,292.64
145.6857,5.4336,7.5504,0.0,0.0,1.5398,6.4549,322.25,299.2,294.72,292.63
145.6866,5.19,7.5552,0.0,0.0,1.5394,6.1667,322.19,299.13,294.73,292.63
145.6875,5.4468,7.5563,0.0,0.0,1.5388,6.4741,322.13,299.07,294.73,292.62
145.6884,5.1858,7.5584,0.0,0.0,1.5389,6.1847,322.07,299.01,294.73,292.62
145.6893,5.4111,7.5617,0.0,0.0,1.5412,6.4167,322.02,298.95,294.73,292.62
145.6902,5.272,7.5557,0.0,0.0,1.5412,6.2662,321.96,298.89,294.72,292.62
145.6911,5.3488,7.5562,0.0,0.0,1.5429,6.3364,321.91,298.84,294.72,292.62
145.692,5.3536,7.5541,0.0,0.0,1.5447,6.3645,321.85,298.78,294.71,292.62
145.6929,5.2824,7.5463,0.0,0.0,1.5432,6.266,321.8,298.73,294.71,292.63
145.6938,5.4202,7.5453,0.0,0.0,1.5439,6.4348,321.74,298.67,294.7,292.63
145.6947,5.2487,7.5409,0.0,0.0,1.5419,6.2198,321.69,298.62,294.7,292.63
145.6956,5.4599,7.54,0.0,0.0,1.5413,6.4739,321.63,298.56,294.69,292.63
145.6965,5.2221,7.5387,0.0,0.0,1.5388,6.1907,321.58,298.51,294.69,292.64
145.6974,5.4714,7.5405,0.0,0.0,1.5378,6.4761,321.52,298.45,294.68,292.64
145.6983,5.2428,7.5421,0.0,0.0,1.5366,6.2118,321.47,298.4,294.68,292.64
145.6992,5.419,7.5472,0.0,0.0,1.5359,6.4337,321.41,298.34,294.67,292.65
145.7001,5.287,7.5508,0.0,0.0,1.5364,6.2922,321.35,298.28,294.67,292.66
145.701,5.3769,7.5532,0.0,0.0,1.5358,6.3755,321.29,298.22,294.68,292.67
145.7019,5.3609,7.5598,0.0,0.0,1.538,6.3777,321.22,298.17,294.68,292.68
145.7028,5.308,7.5615,0.0,0.0,1.5391,6.283,321.16,298.11,294.68,292.69
145.7037,5.441,7.5634,0.0,0.0,1.5415,6.4659,321.1,298.05,294.69,292.7
145.7046,5.2814,7.561,0.0,0.0,1.5426,6.2552,321.03,297.99,294.69,292.71
145.7055,5.4739,7.5602,0.0,0.0,1.5448,6.5022,320.97,297.93,294.69,292.73
145.7064,5.2241,7.5542,0.0,0.0,1.5451,6.2068,320.91,297.88,294.69,292.74
145.7073,5.4913,7.5551,0.0,0.0,1.546,6.4967,320.85,297.82,294.7,292.75
145.7082,5.2382,7.5506,0.0,0.0,1.5447,6.2222,320.78,297.76,294.7,292.76
145.7091,5.4525,7.5474,0.0,0.0,1.5431,6.474,320.72,297.7,294.7,292.77
145.71,5.3125,7.5487,0.0,0.0,1.543,6.3103,320.66,297.64,294.71,292.77
145.7109,5.3905,7.5488,0.0,0.0,1.5409,6.3926,320.6,297.59,294.73,292.77
145.7118,5.3682,7.5506,0.0,0.0,1.5402,6.3957,320.54,297.53,294.74,292.78
145.7127,5.3301,7.5529,0.0,0.0,1.5387,6.3283,320.48,297.47,294.75,292.78
145.7136,5.4623,7.557,0.0,0.0,1.5388,6.4981,320.42,297.41,294.76,292.78
145.7145,5.2867,7.5585,0.0,0.0,1.5395,6.2449,320.36,297.35,294.77,292.78
145.7154,5.4943,7.5594,0.0,0.0,1.5402,6.5281,320.3,297.3,294.78,292.79
145.7163,5.2502,7.5585,0.0,0.0,1.5416,6.2379,320.24,297.24,294.79,292.79
145.7172,5.4931,7.5577,0.0,0.0,1.5434,6.5171,320.18,297.18,294.8,292.79
145.7181,5.2602,7.5522,0.0,0.0,1.543,6.2712,320.12,297.12,294.81,292.8
145.719,5.4596,7.5484,0.0,0.0,1.5432,6.4829,320.06,297.07,294.83,292.8
145.7199,5.2994,7.5467,0.0,0.0,1.5438,6.2993,320.01,297.02,294.84,292.8
145.7208,5.3839,7.5417,0.0,0.0,1.5428,6.3906,319.97,296.98,294.86,292.81
145.7217,5.3821,7.5408,0.0,0.0,1.5415,6.4047,319.93,296.93,294.87,292.81
145.7226,5.3296,7.5388,0.0,0.0,1.5391,6.3213,319.88,296.89,294.89,292.82
145.7235,5.4411,7.5415,0.0,0.0,1.539,6.4608,319.84,296.84,294.91,292.83
145.7244,5.2804,7.5414,0.0,0.0,1.5364,6.2448,319.79,296.8,294.92,292.83
145.7253,5.475,7.5468,0.0,0.0,1.5363,6.5121,319.75,296.76,294.94,292.84
145.7262,5.2426,7.5506,0.0,0.0,1.5356,6.2157,319.71,296.71,294.96,292.84
145.7271,5.4998,7.5541,0.0,0.0,1.5367,6.5241,319.66,296.67,294.97,292.85
145.728,5.25,7.556,0.0,0.0,1.5363,6.2249,319.62,296.62,294.99,292.85
145.7289,5.4588,7.5631,0.0,0.0,1.5401,6.4749,319.58,296.58,295.01,292.86
145.7298,5.2867,7.5618,0.0,0.0,1.5406,6.2922,319.52,296.53,295.01,292.86
145.7307,5.4034,7.5609,0.0,0.0,1.542,6.3996,319.47,296.48,295.02,292.87
145.7316,5.3872,7.5601,0.0,0.0,1.5438,6.4047,319.41,296.43,295.02,292.88
145.7325,5.3342,7.5553,0.0,0.0,1.5444,6.299,319.36,296.38,295.03,292.88
145.7334,5.4415,7.5559,0.0,0.0,1.5465,6.4669,319.3,296.33,295.04,292.89
145.7343,5.2704,7.5484,0.0,0.0,1.5439,6.266,319.25,296.28,295.04,292.89
145.7352,5.4942,7.5498,0.0,0.0,1.5444,6.5263,319.19,296.23,295.05,292.9
145.7361,5.2376,7.5481,0.0,0.0,1.5433,6.2281,319.14,296.18,295.05,292.9
145.737,5.4864,7.549,0.0,0.0,1.5416,6.503,319.08,296.13,295.06,292.91
145.7379,5.2478,7.5477,0.0,0.0,1.5395,6.2632,319.03,296.08,295.06,292.91
145.7388,5.452,7.5538,0.0,0.0,1.5398,6.4668,318.97,296.03,295.07,292.92
145.7397,5.3061,7.5563,0.0,0.0,1.5388,6.3073,318.91,295.99,295.06,292.93
145.7406,5.416,7.5584,0.0,0.0,1.5392,6.4087,318.84,295.94,295.06,292.93
145.7415,5.3675,7.5593,0.0,0.0,1.5397,6.3815,318.78,295.9,295.05,292.94
145.7424,5.3295,7.5574,0.0,0.0,1.54,6.3204,318.71,295.86,295.04,292.94
145.7433,5.4408,7.5576,0.0,0.0,1.5431,6.4599,318.65,295.81,295.03,292.95
145.7442,5.2888,7.5538,0.0,0.0,1.544,6.2688,318.58,295.77,295.02,292.95
145.7451,5.5016,7.5496,0.0,0.0,1.5429,6.5352,318.51,295.72,295.01,292.96
145.746,5.2614,7.5442,0.0,0.0,1.5427,6.2289,318.45,295.68,295.01,292.96
145.7469,5.506,7.5446,0.0,0.0,1.5434,6.5261,318.38,295.64,295.0,292.97
145.7478,5.2586,7.5399,0.0,0.0,1.5411,6.257,318.32,295.59,294.99,292.97
145.7487,5.4707,7.5395,0.0,0.0,1.5389,6.4741,318.25,295.55,294.98,292.98
145.7496,5.3203,7.5406,0.0,0.0,1.5383,6.3243,318.19,295.5,294.98,292.99
145.7505,5.4367,7.5415,0.0,0.0,1.5366,6.4337,318.15,295.45,294.99,292.99
145.7514,5.3833,7.5439,0.0,0.0,1.5354,6.4206,318.1,295.4,295.0,293.0
145.7523,5.35,7.5492,0.0,0.0,1.5356,6.3425,318.05,295.35,295.01,293.0
145.7532,5.4621,7.5541,0.0,0.0,1.5363,6.4971,318.0,295.3,295.02,293.01
145.7541,5.3018,7.5567,0.0,0.0,1.5361,6.283,317.95,295.25,295.02,293.01
145.755,5.5205,7.5621,0.0,0.0,1.5387,6.5504,317.9,295.2,295.03,293.02
145.7559,5.2751,7.561,0.0,0.0,1.5404,6.2469,317.85,295.15,295.04,293.02
145.7568,5.5191,7.5615,0.0,0.0,1.5414,6.5412,317.8,295.1,295.05,293.03
145.7577,5.2849,7.5592,0.0,0.0,1.5432,6.2811,317.75,295.05,295.06,293.04
145.7586,5.4986,7.5598,0.0,0.0,1.5455,6.5141,317.7,295.0,295.07,293.04
145.7595,5.332,7.5549,0.0,0.0,1.5453,6.3244,317.65,294.96,295.07,293.05
145.7604,5.4633,7.5507,0.0,0.0,1.5451,6.4649,317.6,294.91,295.08,293.06
145.7613,5.39,7.5515,0.0,0.0,1.5454,6.4279,317.55,294.87,295.09,293.06
145.7622,5.3828,7.5488,0.0,0.0,1.5429,6.3765,317.5,294.82,295.1,293.07
145.7631,5.4694,7.5476,0.0,0.0,1.5415,6.501,317.45,294.78,295.11,293.08
145.764,5.3215,7.55,0.0,0.0,1.5405,6.2982,317.4,294.74,295.12,293.09
145.7649,5.5271,7.5526,0.0,0.0,1.5402,6.5505,317.35,294.69,295.12,293.1
145.7658,5.277,7.5541,0.0,0.0,1.5383,6.262,317.3,294.65,295.13,293.11
145.7667,5.5259,7.5592,0.0,0.0,1.5394,6.5413,317.26,294.6,295.14,293.11
145.7676,5.2981,7.5594,0.0,0.0,1.5401,6.2902,317.21,294.56,295.15,293.12
145.7685,5.5128,7.5588,0.0,0.0,1.5404,6.5331,317.16,294.52,295.16,293.13
145.7694,5.3349,7.5582,0.0,0.0,1.5431,6.3555,317.11,294.47,295.16,293.14
145.7703,5.4709,7.5549,0.0,0.0,1.5428,6.4871,317.05,294.43,295.17,293.15
145.7712,5.4143,7.5505,0.0,0.0,1.5437,6.4378,317.0,294.39,295.18,293.16
145.7721,5.3898,7.5477,0.0,0.0,1.5429,6.3916,316.95,294.35,295.18,293.16
145.773,5.4814,7.5467,0.0,0.0,1.5437,6.5081,316.9,294.31,295.19,293.17
145.7739,5.3302,7.5393,0.0,0.0,1.5413,6.3163,316.84,294.27,295.19,293.18
145.7748,5.5286,7.5392,0.0,0.0,1.5408,6.5764,316.79,294.22,295.2,293.19
145.7757,5.303,7.5402,0.0,0.0,1.5392,6.2872,316.74,294.18,295.2,293.2
145.7766,5.5465,7.5411,0.0,0.0,1.5375,6.5744,316.69,294.14,295.21,293.21
145.7775,5.3122,7.544,0.0,0.0,1.536,6.3194,316.64,294.1,295.21,293.21
145.7784,5.5131,7.5494,0.0,0.0,1.5363,6.5392,316.58,294.06,295.22,293.22
145.7793,5.3471,7.5518,0.0,0.0,1.5355,6.3555,316.53,294.02,295.23,293.23
145.7802,5.4708,7.5569,0.0,0.0,1.5368,6.4739,316.48,293.97,295.23,293.24
145.98095,5.3919,7.5524,0.0,0.0,1.5412,6.3973,309.29,287.94,295.77,292.27
147.78095,5.2667,7.5614,0.0,0.0,1.5451,6.252,253.91,193.96,264.45,196.32
149.58095,5.2701,7.5672,0.0,0.0,1.5475,6.252,206.42,117.21,217.27,159.64
151.2604,5.1532,7.5765,0.0,0.0,1.5518,6.1145,138.59,86.033,87.356,78.525
153.0604,5.1743,7.5871,0.0,0.0,1.5564,6.1409,85.243,67.498,42.715,39.872
154.8604,5.1854,7.596,0.0,0.0,1.5603,6.1529,61.493,54.494,32.695,31.21
156.6604,5.1887,7.6036,0.0,0.0,1.5636,6.1582,50.964,46.441,29.694,29.247
158.4604,5.209,7.6107,0.0,0.0,1.5669,6.1811,47.513,43.571,30.683,30.455
160.2604,5.2146,7.6166,0.0,0.0,1.5694,6.1871,46.083,42.57,31.915,31.606
162.0604,5.1031,7.6286,0.0,0.0,1.575,6.0566,46.893,44.071,35.237,35.484
162.6604,5.074,7.6306,0.0,0.0,1.5758,6.0203,47.328,44.715,36.536,36.743