File: examples/dan-msc-case-studies/CS4/data/01 raw data/hyde_test_023.csv
Time(sec),Force(kN),Jaw(mm),PowAngle(deg),PTemp,Strain,Stress(MPa),TC1(C),TC2(C),TC3(C)
0.0,4.1429,0.0020467,0.0,0.0044498,0.00026462,12.516,20.026,20.299,20.928
2.0,4.3678,0.0075206,0.0,5.0593,0.00082705,13.2,20.175,20.329,21.016
4.0,4.9283,0.017303,0.0,11.057,0.0019028,14.895,20.161,20.33,21.002
6.0,5.5163,0.02432,0.0,17.057,0.0026822,16.673,20.198,20.346,21.035
7.65231,5.5974,0.026904,18.265,22.014,0.0029638,16.918,20.317,20.506,21.252
9.65231,5.6381,0.025989,19.21,28.014,0.0028654,17.039,27.584,27.325,30.113
11.65231,5.6629,0.024496,24.382,34.014,0.0026975,17.116,33.342,36.792,35.479
13.65231,5.678,0.022879,23.719,40.014,0.0025186,17.161,39.761,39.406,41.897
15.65231,5.6949,0.020748,24.563,46.014,0.0022821,17.213,45.878,45.201,47.957
17.65231,5.7103,0.018757,25.416,52.014,0.0020625,17.26,51.832,51.015,53.746
19.65231,5.7252,0.016617,25.78,58.014,0.0018313,17.306,57.922,56.905,59.864
21.65231,5.7363,0.01305,26.188,64.014,0.0014339,17.337,63.915,62.733,65.775
23.65231,5.7441,0.011376,26.699,70.014,0.0012616,17.362,69.94,68.651,71.861
25.65231,5.7517,0.0094471,27.266,76.014,0.0010447,17.383,75.951,74.502,77.806
27.65231,5.7643,0.0070826,27.228,82.014,0.00078677,17.422,82.015,80.27,83.774
29.65231,5.7727,0.0046183,27.381,88.014,0.00051133,17.449,87.972,86.119,89.646
31.65231,5.7794,0.001099,27.697,94.014,0.00011238,17.468,93.955,91.974,95.612
33.44131,5.788,-0.0013501,28.054,99.401,-0.00014377,17.493,99.359,97.25,101.02
35.44131,5.7945,-0.0032672,28.417,105.38,-0.00035135,17.514,105.35,103.18,106.95
37.44131,5.8062,-0.0060206,29.118,111.38,-0.00065228,17.549,111.28,108.91,112.85
39.44121,5.8189,-0.0088083,29.358,117.38,-0.00096775,17.587,117.31,114.81,118.81
41.44121,5.8319,-0.012106,29.526,123.38,-0.0013317,17.627,123.36,120.69,124.88
43.44121,5.85,-0.017426,29.873,129.38,-0.0019125,17.682,129.38,126.65,130.95
45.44121,5.8632,-0.019158,30.441,135.38,-0.0020892,17.72,135.3,132.45,136.87
47.44121,5.8771,-0.021507,30.855,141.38,-0.0023487,17.764,141.3,138.33,142.78
49.44121,5.8945,-0.024727,30.788,147.38,-0.0027124,17.816,147.34,144.1,148.85
51.44121,5.9066,-0.027881,30.803,153.38,-0.0030546,17.852,153.35,149.96,154.78
53.44121,5.9186,-0.031399,30.801,159.38,-0.0034371,17.889,159.43,155.92,160.9
55.44121,5.9266,-0.034866,31.021,165.38,-0.0038136,17.914,165.38,161.65,166.76
57.44121,5.9324,-0.038248,31.019,171.38,-0.0041889,17.931,171.44,167.51,172.74
59.44121,5.9456,-0.041593,31.191,177.38,-0.004554,17.971,177.41,173.08,178.55
61.44121,5.9523,-0.045043,31.126,183.38,-0.0049271,17.992,183.43,178.81,184.46
63.44121,5.9652,-0.049422,31.769,189.38,-0.0054229,18.029,189.32,184.46,190.32
65.44121,5.972,-0.055477,31.877,195.38,-0.0060682,18.051,195.35,190.21,196.27
66.96301,5.9778,-0.057218,31.997,199.95,-0.0062472,18.067,199.92,194.58,200.88
68.96301,5.9756,-0.059809,31.991,205.95,-0.006535,18.06,206.0,200.29,206.84
70.13781,5.9811,-0.061563,32.226,209.47,-0.0067338,18.079,209.48,203.68,210.27
72.13781,5.9882,-0.065129,32.087,215.47,-0.007129,18.099,215.5,209.32,216.19
74.13781,5.9932,-0.068942,32.53,221.47,-0.0075431,18.115,221.43,214.99,222.06
76.13781,5.9991,-0.072632,32.556,227.47,-0.0079481,18.133,227.47,220.81,228.05
78.13781,6.0042,-0.07649,32.442,233.47,-0.008364,18.149,233.52,226.61,234.12
80.13781,6.0064,-0.08022,32.563,239.47,-0.0087753,18.154,239.5,232.25,240.0
82.13781,6.0128,-0.083809,32.475,245.47,-0.0091664,18.173,245.53,238.06,245.97
84.13781,6.0171,-0.089148,32.73,251.47,-0.0097648,18.185,251.48,243.8,251.92
86.13781,6.0159,-0.093938,33.026,257.47,-0.010255,18.183,257.44,249.45,257.73
88.13781,6.0095,-0.095775,33.036,263.47,-0.010462,18.164,263.5,255.24,263.73
90.13781,6.0168,-0.099563,33.408,269.47,-0.010878,18.187,269.44,261.03,269.6
92.13781,6.0198,-0.10312,33.522,275.47,-0.011271,18.194,275.45,266.89,275.56
94.13781,6.0251,-0.10686,33.685,281.47,-0.011668,18.209,281.48,272.93,281.68
96.13781,6.027,-0.11116,33.623,287.47,-0.012162,18.215,287.48,278.67,287.59
98.13781,6.0271,-0.11782,33.909,293.47,-0.01285,18.217,293.43,284.23,293.64
99.59971,6.0204,-0.11825,34.237,297.86,-0.012901,18.195,297.79,288.65,298.02
100.92921,5.981,-0.11747,29.624,299.95,-0.012823,18.077,300.84,291.47,300.52
102.92921,5.9891,-0.11837,30.805,300.0,-0.012928,18.101,300.42,291.16,299.4
104.92921,5.9939,-0.11899,30.361,300.0,-0.012997,18.116,300.39,291.29,299.25
106.92921,5.998,-0.1197,30.854,300.0,-0.013076,18.129,300.15,291.2,298.99
108.92921,6.0068,-0.12017,30.704,300.0,-0.013119,18.156,300.14,291.32,298.98
110.92921,6.0355,-0.12415,30.414,300.0,-0.013565,18.241,300.15,291.42,299.01
112.92921,6.4003,-0.12065,29.707,300.0,-0.013171,19.345,300.24,291.58,299.14
114.92921,6.8299,-0.11902,29.588,300.0,-0.012998,20.641,300.19,291.65,299.13
116.92921,7.3071,-0.11672,29.387,300.0,-0.012749,22.085,300.22,291.81,299.15
118.92921,7.9478,-0.11603,29.815,300.0,-0.012663,24.021,300.17,291.88,299.2
120.92921,8.3689,-0.11187,30.358,300.0,-0.012223,25.293,300.02,291.91,299.0
122.92921,8.8057,-0.10941,30.216,300.0,-0.011954,26.614,300.12,292.12,299.13
124.92921,8.9529,-0.10783,29.659,300.0,-0.011785,27.06,300.23,292.39,299.37
126.92921,8.9671,-0.11059,30.622,300.0,-0.012097,27.101,300.05,292.39,299.26
128.92921,8.972,-0.10854,30.303,300.0,-0.011849,27.116,300.06,292.51,299.22
130.136,8.9657,-0.055853,29.773,300.0,-0.006094,27.097,300.19,292.74,299.49
130.2866,9.0057,0.0074534,0.0,10.293,8.8765e-05,27.251,300.19,292.55,299.17
130.2876,8.9434,0.0054478,0.0,0.019284,0.0010728,27.006,300.2,292.55,299.17
130.2886,8.994,0.0032824,0.0,3.6426e-05,0.00048535,27.228,300.22,292.55,299.16
130.2896,8.9463,0.004013,0.0,6.824e-08,0.00019895,27.016,300.23,292.55,299.15
130.2906,8.9943,0.0043348,0.0,1.2784e-10,0.00078623,27.206,300.22,292.55,299.17
130.2916,8.9521,0.0067287,0.0,2.4146e-13,0.00049497,27.035,300.21,292.55,299.19
130.2926,8.9758,0.0015303,0.0,4.5235e-16,0.00051899,27.163,300.19,292.55,299.21
130.2936,8.9166,0.0059586,0.0,8.4744e-19,0.00051538,26.988,300.18,292.55,299.23
130.2946,9.0073,0.0043307,0.0,1.6003e-21,0.00018672,27.233,300.17,292.55,299.24
130.2956,9.0073,-0.0026731,0.0,2.9984e-24,0.00024913,27.179,300.16,292.55,299.26
130.2966,8.9707,0.0086618,0.0,5.6172e-27,0.00023662,27.138,300.14,292.55,299.28
130.2976,8.9656,0.0068947,0.0,1.0523e-29,0.00084421,27.078,300.13,292.55,299.3
130.2986,8.9542,0.00064826,0.0,1.9874e-32,0.00048807,27.1,300.12,292.55,299.32
130.2996,8.9712,0.0071893,0.0,3.7231000000000003e-35,3.9143e-05,27.087,300.11,292.55,299.34
130.3006,8.9548,0.0049202,0.0,6.9749e-38,0.0010498,27.057,300.11,292.56,299.34
130.3016,8.9786,0.0011245,0.0,1.3171e-40,0.00022122,27.119,300.11,292.56,299.35
130.3026,8.947,0.0049358,0.0,2.4663e-43,0.0001676,27.068,300.12,292.57,299.36
130.3036,8.9974,0.0047678,0.0,0.0,0.00082014,27.156,300.12,292.58,299.36
130.3046,8.9438,0.0046105,0.0,0.0,0.00022796,27.061,300.12,292.58,299.37
130.3056,8.9982,0.0024581,0.0,0.0,0.00059954,27.172,300.12,292.59,299.37
130.3066,8.9356,0.0052048,0.0,0.0,0.00042999,27.068,300.13,292.59,299.38
130.3076,8.9979,0.0056106,0.0,0.0,0.00049906,27.168,300.13,292.6,299.39
130.3086,8.9354,-3.9766e-05,0.0,0.0,0.00064383,27.043,300.13,292.61,299.39
130.3096,9.0078,0.005888,0.0,0.0,-1.7626e-06,27.178,300.14,292.61,299.4
130.3106,8.9191,0.0054978,0.0,0.0,0.00067483,26.978,300.13,292.61,299.39
130.3116,9.0131,-0.00053632,0.0,0.0,0.00047938,27.208,300.13,292.61,299.38
130.3126,8.9174,0.0072306,0.0,0.0,6.4361e-06,26.962,300.12,292.61,299.37
130.3136,9.0078,0.004473,0.0,0.0,0.00093755,27.195,300.11,292.61,299.36
130.3146,8.9164,0.0012218,0.0,0.0,0.00032709,26.98,300.11,292.61,299.35
130.3156,9.0184,0.0061817,0.0,0.0,0.00022945,27.244,300.1,292.61,299.35
130.3166,8.9083,0.0032466,0.0,0.0,0.00078873,26.945,300.09,292.61,299.34
130.3176,9.0232,0.0055384,0.0,0.0,0.00040697,27.255,300.09,292.61,299.33
130.3186,8.9052,0.0020788,0.0,0.0,0.00060271,26.942,300.08,292.61,299.32
130.3196,9.0263,0.0051757,0.0,0.0,0.00055158,27.244,300.08,292.61,299.31
130.3206,8.9071,0.0064616,0.0,0.0,0.00052867,26.93,300.06,292.61,299.3
130.3216,9.0113,0.00038534,0.0,0.0,0.00056603,27.2,300.05,292.61,299.29
130.3226,8.9086,0.0065692,0.0,0.0,8.9777e-05,26.934,300.04,292.61,299.28
130.3236,9.025,0.0061269,0.0,0.0,0.00072767,27.274,300.03,292.61,299.27
130.3246,8.912,5.5941e-05,0.0,0.0,0.00063311,26.935,300.02,292.61,299.26
130.3256,9.019,0.0065224,0.0,0.0,-9.5613e-05,27.266,300.0,292.61,299.25
130.3266,8.9145,0.0048041,0.0,0.0,0.00096472,26.939,299.99,292.61,299.24
130.3276,9.018,0.002689,0.0,0.0,0.0006428,27.297,299.98,292.61,299.24
130.3286,8.9107,0.0052943,0.0,0.0,0.00010279,26.902,299.97,292.61,299.23
130.3296,9.0242,0.0049887,0.0,0.0,0.00086179,27.277,299.95,292.61,299.22
130.3306,8.9207,0.0047269,0.0,0.0,0.0003272,26.949,299.95,292.62,299.2
130.3316,9.0159,0.0020734,0.0,0.0,0.00037042,27.269,299.95,292.63,299.19
130.3326,8.9166,0.0050045,0.0,0.0,0.00059426,26.956,299.94,292.63,299.18
130.3336,9.0111,0.0064523,0.0,0.0,0.0004707,27.254,299.94,292.64,299.17
130.3346,8.9168,-2.2254e-05,0.0,0.0,0.00057209,26.928,299.94,292.64,299.16
130.3356,9.0011,0.0050445,0.0,0.0,2.9588e-06,27.21,299.93,292.65,299.14
130.3366,8.9266,0.0064567,0.0,0.0,0.00079758,26.957,299.93,292.66,299.13
130.3376,9.0077,0.00024781,0.0,0.0,0.00072744,27.248,299.93,292.66,299.12
130.3386,8.9299,0.0051901,0.0,0.0,-0.00015221,26.988,299.93,292.67,299.11
130.3396,8.9954,0.0068195,0.0,0.0,0.0011077,27.194,299.92,292.67,299.09
130.3406,8.9374,0.00068745,0.0,0.0,0.00029242,26.99,300.13,292.9,299.08
130.3416,8.9765,0.0044028,0.0,0.0,-0.00016866,27.165,300.37,293.15,299.06
130.3426,8.9473,0.0062163,0.0,0.0,0.00098299,27.002,300.6,293.4,299.05
130.3436,8.9856,0.0032459,0.0,0.0,0.0002654,27.22,300.84,293.65,299.03
130.3446,8.9331,0.0022291,0.0,0.0,0.00022233,26.966,301.08,293.91,299.02
130.3456,8.9931,0.005801,0.0,0.0,0.00074548,27.205,301.31,294.16,299.0
130.3466,8.9475,0.0055781,0.0,0.0,0.00043763,26.987,301.55,294.41,298.99
130.3476,8.9567,-4.9144e-05,0.0,0.0,0.00045685,27.123,301.79,294.66,298.97
130.3486,8.9641,0.0074528,0.0,0.0,0.00025632,27.028,302.02,294.91,298.96
130.3496,8.9461,0.0052664,0.0,0.0,0.00055131,27.082,302.26,295.17,298.94
130.3506,8.97,0.00024894,0.0,0.0,0.00071432,27.086,302.7,295.54,298.93
130.3516,8.9442,0.0064576,0.0,0.0,-0.00012642,27.079,303.18,295.93,298.92
130.3526,10.138,0.011363,0.0,0.0,0.0014079,30.103,303.65,296.32,298.9
130.3536,13.323,0.018767,0.0,0.0,0.0020724,38.717,304.12,296.71,298.89
130.35459,21.327,0.056816,0.0,0.0,0.0050227,62.384,304.59,297.1,298.88
130.35559,28.363,0.10935,0.0,0.0,0.012202,84.914,305.06,297.49,298.87
130.35659,31.673,0.14843,0.0,0.0,0.015929,95.626,305.53,297.88,298.85
130.35759,34.706,0.22575,0.0,0.0,0.024484,104.52,306.01,298.27,298.84
130.35859,37.283,0.30499,0.0,0.0,0.033814,112.19,306.48,298.66,298.83
130.35959,39.128,0.36506,0.0,0.0,0.040382,117.91,306.95,299.05,298.82
130.36059,40.986,0.4322,0.0,0.0,0.048466,123.48,307.35,299.35,298.82
130.36159,42.495,0.51962,0.0,0.0,0.057719,128.23,307.74,299.63,298.82
130.36259,43.503,0.59177,0.0,0.0,0.066454,131.34,308.12,299.92,298.82
130.36359,44.255,0.67197,0.0,0.0,0.076684,133.59,308.51,300.2,298.82
130.36459,44.96,0.77152,0.0,0.0,0.086764,135.74,308.9,300.49,298.82
130.36559,45.38,0.85719,0.0,0.0,0.098229,137.07,309.29,300.77,298.82
130.36659,45.799,0.93743,0.0,0.0,0.10798,138.39,309.68,301.06,298.82
130.36759,46.132,1.035,0.0,0.0,0.11881,139.35,310.07,301.35,298.82
130.36859,46.353,1.1196,0.0,0.0,0.13049,140.03,310.45,301.63,298.82
130.36959,46.613,1.1994,0.0,0.0,0.13977,140.83,310.84,301.92,298.82
130.37059,46.813,1.2855,0.0,0.0,0.15049,141.46,311.19,302.26,298.82
130.37159,46.97,1.3679,0.0,0.0,0.16133,141.92,311.53,302.6,298.83
130.37259,47.108,1.4515,0.0,0.0,0.17133,142.36,311.87,302.95,298.83
130.37359,47.211,1.5259,0.0,0.0,0.18177,142.65,312.21,303.29,298.84
130.37459,47.338,1.6125,0.0,0.0,0.19206,143.06,312.55,303.64,298.85
130.37559,47.41,1.6883,0.0,0.0,0.20221,143.28,312.88,303.99,298.85
130.37659,47.483,1.7564,0.0,0.0,0.21236,143.49,313.22,304.33,298.86
130.37759,47.549,1.8381,0.0,0.0,0.22148,143.7,313.56,304.68,298.86
130.37859,47.625,1.9093,0.0,0.0,0.2324,143.94,313.9,305.03,298.87
130.37959,47.701,1.9778,0.0,0.0,0.24201,144.13,314.24,305.37,298.88
130.38059,47.79,2.0538,0.0,0.0,0.2509,144.43,314.59,305.7,298.89
130.38159,47.857,2.1231,0.0,0.0,0.26224,144.64,314.94,306.03,298.91
130.38259,47.95,2.1929,0.0,0.0,0.27123,144.92,315.3,306.36,298.92
130.38359,48.058,2.2658,0.0,0.0,0.28122,145.23,315.65,306.7,298.94
130.38459,48.145,2.339,0.0,0.0,0.29241,145.49,316.0,307.03,298.95
130.38559,48.239,2.4174,0.0,0.0,0.30268,145.77,316.35,307.36,298.97
130.38659,48.327,2.4836,0.0,0.0,0.31337,146.04,316.7,307.69,298.98
130.38759,48.428,2.5639,0.0,0.0,0.3242,146.32,317.05,308.02,299.0
130.38859,48.509,2.6354,0.0,0.0,0.33474,146.61,317.41,308.35,299.01
130.38959,48.606,2.7035,0.0,0.0,0.34636,146.91,317.76,308.68,299.03
130.39059,48.701,2.7856,0.0,0.0,0.35656,147.17,318.04,308.91,299.04
130.39159,48.797,2.8567,0.0,0.0,0.3688,147.46,318.32,309.13,299.04
130.39259,48.841,2.9217,0.0,0.0,0.3796,147.61,318.6,309.35,299.05
130.39359,48.948,2.9995,0.0,0.0,0.38966,147.92,318.88,309.57,299.06
130.39459,49.037,3.0661,0.0,0.0,0.40226,148.18,319.16,309.79,299.06
130.39559,49.151,3.1331,0.0,0.0,0.41212,148.52,319.43,310.01,299.07
130.39659,49.201,3.207,0.0,0.0,0.42333,148.69,319.71,310.23,299.07
130.39759,49.303,3.2706,0.0,0.0,0.43479,148.96,319.99,310.45,299.08
130.39859,49.347,3.3388,0.0,0.0,0.44455,149.14,320.27,310.67,299.09
130.39959,49.436,3.4008,0.0,0.0,0.45603,149.4,320.54,310.89,299.09
130.40059,49.477,3.4657,0.0,0.0,0.46614,149.52,320.74,311.06,299.1
130.40159,49.564,3.5281,0.0,0.0,0.47633,149.8,320.93,311.22,299.1
130.40259,49.589,3.5829,0.0,0.0,0.48754,149.86,321.11,311.38,299.1
130.40359,49.7,3.6498,0.0,0.0,0.49646,150.19,321.3,311.53,299.1
130.40459,49.75,3.7082,0.0,0.0,0.50791,150.36,321.48,311.69,299.11
130.40559,49.826,3.7598,0.0,0.0,0.51803,150.58,321.67,311.85,299.11
130.40659,49.874,3.8255,0.0,0.0,0.52705,150.72,321.86,312.01,299.11
130.40759,49.984,3.8783,0.0,0.0,0.53897,151.02,322.04,312.17,299.12
130.40859,50.019,3.9336,0.0,0.0,0.54808,151.17,322.23,312.33,299.12
130.40959,50.121,3.9951,0.0,0.0,0.55819,151.46,322.41,312.49,299.12
130.41059,50.186,4.0462,0.0,0.0,0.56937,151.68,322.52,312.6,299.12
130.41159,50.286,4.1064,0.0,0.0,0.57861,151.98,322.62,312.71,299.12
130.41259,50.329,4.1603,0.0,0.0,0.59007,152.11,322.72,312.82,299.11
130.41359,50.415,4.2157,0.0,0.0,0.60016,152.37,322.81,312.92,299.11
130.41459,50.465,4.274,0.0,0.0,0.61031,152.51,322.91,313.03,299.11
130.41559,50.571,4.3217,0.0,0.0,0.62155,152.8,323.01,313.14,299.11
130.41659,50.612,4.3856,0.0,0.0,0.6313,152.98,323.11,313.24,299.1
130.41759,50.701,4.4417,0.0,0.0,0.6436,153.21,323.2,313.35,299.1
130.41859,50.724,4.4861,0.0,0.0,0.65373,153.31,323.3,313.46,299.1
130.41959,50.826,4.5505,0.0,0.0,0.6636,153.59,323.4,313.56,299.09
130.42059,50.869,4.5998,0.0,0.0,0.67642,153.74,323.43,313.62,299.1
130.42159,50.944,4.6503,0.0,0.0,0.68599,153.96,323.45,313.67,299.1
130.42259,50.97,4.707,0.0,0.0,0.69604,154.03,323.46,313.72,299.11
130.42359,51.034,4.7562,0.0,0.0,0.70863,154.23,323.48,313.77,299.12
130.42459,51.031,4.809,0.0,0.0,0.7178,154.24,323.5,313.82,299.12
130.42559,51.096,4.8556,0.0,0.0,0.72862,154.41,323.52,313.86,299.13
130.42659,51.114,4.9067,0.0,0.0,0.73942,154.46,323.54,313.91,299.14
130.42759,51.159,4.9604,0.0,0.0,0.75008,154.61,323.55,313.96,299.14
130.42859,51.175,4.9992,0.0,0.0,0.7606,154.67,323.57,314.01,299.15
130.42959,51.232,5.0557,0.0,0.0,0.77031,154.85,323.59,314.06,299.15
130.43059,51.225,5.1024,0.0,0.0,0.78211,154.81,323.58,314.09,299.17
130.43159,51.271,5.1405,0.0,0.0,0.79225,154.96,323.56,314.11,299.19
130.43259,51.287,5.1963,0.0,0.0,0.8015,155.02,323.55,314.13,299.22
130.43359,51.336,5.2388,0.0,0.0,0.81426,155.14,323.53,314.15,299.24
130.43459,51.367,5.2814,0.0,0.0,0.82352,155.22,323.52,314.17,299.26
130.43559,51.417,5.332,0.0,0.0,0.83327,155.4,323.5,314.19,299.28
130.43659,51.44,5.3756,0.0,0.0,0.84649,155.47,323.49,314.21,299.3
130.43759,51.474,5.4228,0.0,0.0,0.85546,155.55,323.47,314.24,299.32
130.43859,51.496,5.465,0.0,0.0,0.86642,155.63,323.46,314.26,299.35
130.43959,51.524,5.5131,0.0,0.0,0.87838,155.72,323.44,314.28,299.37
130.44059,51.543,5.5595,0.0,0.0,0.88821,155.76,323.42,314.28,299.37
130.44159,51.545,5.5986,0.0,0.0,0.90042,155.83,323.39,314.27,299.38
130.44259,51.58,5.6476,0.0,0.0,0.90974,155.89,323.36,314.27,299.39
130.44359,51.619,5.6915,0.0,0.0,0.92192,156.03,323.33,314.27,299.39
130.44459,51.653,5.7275,0.0,0.0,0.93334,156.12,323.31,314.27,299.4
130.44559,51.67,5.7796,0.0,0.0,0.94233,156.16,323.28,314.26,299.41
130.44659,51.674,5.8184,0.0,0.0,0.9561,156.17,323.25,314.26,299.41
130.44759,51.677,5.8552,0.0,0.0,0.96543,156.2,323.23,314.26,299.42
130.44859,51.699,5.9,0.0,0.0,0.97458,156.24,323.2,314.25,299.42
130.44959,51.68,5.9409,0.0,0.0,0.98931,156.21,323.17,314.25,299.43
130.45059,51.69,5.9772,0.0,0.0,0.99666,156.22,323.12,314.23,299.44
130.45159,51.681,6.0169,0.0,0.0,1.008,156.21,323.08,314.22,299.44
130.45259,51.71,6.0563,0.0,0.0,1.0198,156.26,323.03,314.2,299.45
130.45359,51.727,6.0972,0.0,0.0,1.0288,156.34,322.98,314.18,299.45
130.45459,51.755,6.129,0.0,0.0,1.0408,156.4,322.93,314.16,299.46
130.45559,51.764,6.1745,0.0,0.0,1.0505,156.45,322.88,314.14,299.47
130.45659,51.805,6.2096,0.0,0.0,1.0615,156.54,322.83,314.12,299.47
130.45759,51.825,6.2404,0.0,0.0,1.0734,156.63,322.78,314.11,299.48
130.45859,51.861,6.2867,0.0,0.0,1.0819,156.72,322.73,314.09,299.49
130.45959,51.867,6.3203,0.0,0.0,1.0956,156.74,322.69,314.07,299.49
130.46059,51.92,6.3529,0.0,0.0,1.1054,156.92,322.65,314.05,299.5
130.46159,51.945,6.3964,0.0,0.0,1.1151,157.0,322.61,314.03,299.5
130.46259,52.011,6.4279,0.0,0.0,1.129,157.19,322.57,314.0,299.51
130.46359,52.05,6.4647,0.0,0.0,1.1377,157.3,322.54,313.98,299.52
130.46459,52.102,6.4995,0.0,0.0,1.1485,157.46,322.5,313.96,299.52
130.46559,52.136,6.535,0.0,0.0,1.1617,157.56,322.46,313.94,299.53
130.46659,52.207,6.5747,0.0,0.0,1.171,157.78,322.43,313.92,299.53
130.46759,52.214,6.6021,0.0,0.0,1.1831,157.82,322.39,313.9,299.54
130.46859,52.278,6.6435,0.0,0.0,1.1934,158.0,322.35,313.88,299.55
130.46959,52.294,6.6799,0.0,0.0,1.2056,158.03,322.32,313.85,299.55
130.47059,52.341,6.7028,0.0,0.0,1.2171,158.21,322.29,313.84,299.56
130.47159,52.363,6.7477,0.0,0.0,1.2257,158.24,322.26,313.83,299.58
130.47259,52.406,6.7758,0.0,0.0,1.2396,158.39,322.23,313.82,299.59
130.47359,52.398,6.804,0.0,0.0,1.2497,158.37,322.21,313.8,299.6
130.47459,52.471,6.8448,0.0,0.0,1.2593,158.58,322.18,313.79,299.61
130.47559,52.491,6.871,0.0,0.0,1.2738,158.63,322.15,313.78,299.63
130.47659,52.574,6.905,0.0,0.0,1.2828,158.87,322.12,313.77,299.64
130.47759,52.61,6.9359,0.0,0.0,1.2932,158.99,322.1,313.76,299.65
130.47859,52.667,6.9663,0.0,0.0,1.307,159.17,322.07,313.74,299.66
130.47959,52.68,7.0,0.0,0.0,1.3152,159.21,322.04,313.73,299.67
130.48059,52.764,7.0255,0.0,0.0,1.3282,159.45,322.0,313.71,299.69
130.48159,52.788,7.0595,0.0,0.0,1.3374,159.52,321.96,313.69,299.71
130.48259,52.843,7.0922,0.0,0.0,1.3497,159.72,321.92,313.67,299.72
130.48359,52.883,7.1128,0.0,0.0,1.3617,159.82,321.87,313.65,299.74
130.48459,52.949,7.1534,0.0,0.0,1.3707,160.01,321.83,313.63,299.75
130.48559,52.98,7.1787,0.0,0.0,1.3846,160.11,321.79,313.6,299.77
130.48659,53.025,7.2036,0.0,0.0,1.3952,160.25,321.75,313.58,299.78
130.48759,53.076,7.2368,0.0,0.0,1.4029,160.4,321.7,313.56,299.8
130.48859,53.162,7.2619,0.0,0.0,1.4192,160.66,321.66,313.54,299.81
130.48959,53.218,7.2906,0.0,0.0,1.4276,160.84,321.62,313.52,299.83
130.49059,53.301,7.3195,0.0,0.0,1.4381,161.08,321.57,313.47,299.85
130.49159,53.343,7.3463,0.0,0.0,1.4524,161.19,321.53,313.42,299.87
130.49258,53.427,7.3752,0.0,0.0,1.4602,161.48,321.48,313.38,299.89
130.49358,53.492,7.398,0.0,0.0,1.4734,161.66,321.44,313.33,299.91
130.49458,53.568,7.4281,0.0,0.0,1.4839,161.89,321.39,313.28,299.93
130.49558,53.64,7.4542,0.0,0.0,1.4934,162.1,321.34,313.23,299.96
130.49658,53.73,7.473,0.0,0.0,1.5069,162.36,321.3,313.18,299.98
130.49758,53.793,7.5099,0.0,0.0,1.5161,162.56,321.25,313.13,300.0
130.49858,53.862,7.5314,0.0,0.0,1.5296,162.77,321.21,313.08,300.02
130.49958,52.674,7.542,0.0,0.0,1.5368,159.6,321.16,313.03,300.04
130.50058,51.473,7.55,0.0,0.0,1.5337,155.73,321.1,312.99,300.05
130.50158,50.682,7.5476,0.0,0.0,1.5401,153.31,321.05,312.95,300.06
130.50258,49.978,7.548,0.0,0.0,1.5376,151.14,320.99,312.91,300.06
130.50358,49.435,7.5541,0.0,0.0,1.5376,149.51,320.93,312.87,300.07
130.50458,48.962,7.5544,0.0,0.0,1.5425,148.12,320.87,312.83,300.07
130.50558,48.515,7.5576,0.0,0.0,1.5389,146.67,320.82,312.79,300.08
130.50658,48.213,7.5568,0.0,0.0,1.5422,145.75,320.76,312.75,300.09
130.50758,47.913,7.5589,0.0,0.0,1.5413,144.85,320.7,312.71,300.09
130.50858,47.706,7.5661,0.0,0.0,1.5431,144.22,320.64,312.67,300.1
130.50958,47.523,7.5555,0.0,0.0,1.5437,143.66,320.58,312.63,300.11
130.51058,47.396,7.5671,0.0,0.0,1.5417,143.26,320.51,312.58,300.11
130.51158,47.242,7.5683,0.0,0.0,1.5463,142.77,320.44,312.51,300.11
130.51258,47.16,7.5608,0.0,0.0,1.5459,142.55,320.37,312.45,300.11
130.51358,47.06,7.5719,0.0,0.0,1.5429,142.24,320.3,312.39,300.11
130.51458,47.021,7.5702,0.0,0.0,1.5495,142.11,320.23,312.33,300.11
130.51558,46.95,7.5684,0.0,0.0,1.5464,141.91,320.16,312.27,300.11
130.51658,46.933,7.5769,0.0,0.0,1.5474,141.87,320.09,312.21,300.11
130.51758,46.87,7.5711,0.0,0.0,1.5502,141.65,320.02,312.15,300.11
130.51858,46.86,7.5772,0.0,0.0,1.548,141.63,319.95,312.09,300.11
130.51958,46.811,7.5776,0.0,0.0,1.551,141.51,319.88,312.02,300.11
130.52058,46.791,7.5762,0.0,0.0,1.5497,141.43,319.82,311.96,300.13
130.52158,46.723,7.5842,0.0,0.0,1.5506,141.23,319.76,311.89,300.15
130.52258,46.605,7.5765,0.0,0.0,1.5531,140.91,319.69,311.82,300.17
130.52358,46.38,7.5845,0.0,0.0,1.55,140.23,319.63,311.74,300.19
130.52458,46.043,7.5853,0.0,0.0,1.5536,139.23,319.56,311.67,300.21
130.52558,45.509,7.5781,0.0,0.0,1.5535,137.6,319.5,311.6,300.23
130.52658,44.799,7.5878,0.0,0.0,1.5501,135.5,319.43,311.53,300.25
130.52758,43.81,7.5816,0.0,0.0,1.5546,132.57,319.37,311.46,300.28
130.52858,42.568,7.5772,0.0,0.0,1.5508,128.86,319.31,311.39,300.3
130.52958,41.125,7.5834,0.0,0.0,1.55,124.53,319.24,311.32,300.32
130.53058,39.484,7.5762,0.0,0.0,1.5526,119.64,319.16,311.27,300.33
130.53158,37.531,7.5773,0.0,0.0,1.548,113.8,319.09,311.22,300.35
130.53258,33.723,7.5757,0.0,0.0,1.5494,102.88,319.01,311.17,300.37
130.53358,23.14,7.5688,0.0,0.0,1.548,72.399,318.93,311.12,300.38
130.53458,10.509,7.5297,0.0,0.0,1.5276,33.197,318.85,311.08,300.4
130.53558,6.3423,7.5102,0.0,0.0,1.5232,19.052,318.77,311.03,300.41
130.53658,9.2875,7.5245,0.0,0.0,1.5234,27.643,318.69,310.98,300.43
130.53758,8.2777,7.5389,0.0,0.0,1.5326,25.464,318.61,310.93,300.44
130.53858,8.0159,7.5195,0.0,0.0,1.5279,23.845,318.53,310.88,300.46
130.53958,8.8299,7.5316,0.0,0.0,1.5257,26.806,318.45,310.83,300.47
130.54058,8.0874,7.5191,0.0,0.0,1.5266,24.513,318.38,310.77,300.49
130.54158,8.592,7.5176,0.0,0.0,1.5247,25.829,318.31,310.71,300.51
130.54258,8.3725,7.5219,0.0,0.0,1.5227,25.423,318.24,310.65,300.53
130.54358,8.384,7.5177,0.0,0.0,1.5267,25.23,318.17,310.59,300.55
130.54458,8.3865,7.5205,0.0,0.0,1.5234,25.398,318.1,310.53,300.56
130.54558,8.3653,7.521,0.0,0.0,1.5249,25.264,318.03,310.47,300.58
130.54658,8.2017,7.5225,0.0,0.0,1.5268,24.792,317.96,310.4,300.6
130.54758,8.4233,7.5266,0.0,0.0,1.5252,25.468,317.89,310.34,300.62
130.54858,8.2267,7.5234,0.0,0.0,1.5288,24.869,317.82,310.28,300.64
130.54958,8.4592,7.5263,0.0,0.0,1.5254,25.56,317.74,310.22,300.66
130.55058,8.2392,7.5274,0.0,0.0,1.5268,24.921,317.68,310.16,300.67
130.55158,8.384,7.5205,0.0,0.0,1.5284,25.331,317.62,310.1,300.69
130.55258,8.2279,7.5269,0.0,0.0,1.523,24.851,317.56,310.04,300.71
130.55358,8.355,7.525,0.0,0.0,1.5283,25.287,317.5,309.98,300.73
130.55458,8.2281,7.5173,0.0,0.0,1.5251,24.835,317.44,309.92,300.75
130.55558,8.3686,7.5275,0.0,0.0,1.5244,25.305,317.38,309.85,300.77
130.55658,8.2445,7.5193,0.0,0.0,1.5275,24.91,317.32,309.79,300.79
130.55758,8.3514,7.5224,0.0,0.0,1.5245,25.23,317.25,309.73,300.8
130.55858,8.2334,7.5217,0.0,0.0,1.5244,24.87,317.19,309.67,300.82
130.55958,8.3729,7.5232,0.0,0.0,1.5275,25.32,317.13,309.61,300.84
130.56058,8.2153,7.5256,0.0,0.0,1.5249,24.833,317.06,309.56,300.86
130.56158,8.3632,7.5204,0.0,0.0,1.5272,25.267,316.99,309.51,300.89
130.56258,8.2556,7.5257,0.0,0.0,1.5256,24.933,316.91,309.46,300.91
130.56358,8.3423,7.5277,0.0,0.0,1.5272,25.256,316.84,309.41,300.94
130.56458,8.2506,7.5188,0.0,0.0,1.5275,24.919,316.77,309.36,300.96
130.56558,8.3513,7.5275,0.0,0.0,1.524,25.276,316.69,309.31,300.99
130.56658,8.3055,7.5259,0.0,0.0,1.5285,25.078,316.62,309.27,301.01
130.56758,8.315,7.5215,0.0,0.0,1.5272,25.161,316.55,309.22,301.04
130.56858,8.3307,7.5285,0.0,0.0,1.5249,25.152,316.47,309.17,301.06
130.56958,8.2895,7.5232,0.0,0.0,1.5289,25.087,316.4,309.12,301.09
130.57058,8.3721,7.5243,0.0,0.0,1.526,25.278,316.33,309.07,301.1
130.57158,8.3231,7.526,0.0,0.0,1.5259,25.152,316.26,309.02,301.11
130.57258,8.3458,7.5234,0.0,0.0,1.5282,25.217,316.2,308.97,301.12
130.57358,8.3174,7.5274,0.0,0.0,1.5259,25.129,316.13,308.92,301.12
130.57458,8.33,7.5231,0.0,0.0,1.5279,25.162,316.06,308.87,301.13
130.57558,8.3233,7.5267,0.0,0.0,1.5262,25.155,316.0,308.82,301.14
130.57658,8.3105,7.5267,0.0,0.0,1.5261,25.101,315.93,308.78,301.15
130.57758,8.3519,7.5222,0.0,0.0,1.5289,25.286,315.86,308.73,301.16
130.57858,8.32,7.5277,0.0,0.0,1.5242,25.125,315.79,308.68,301.17
130.57958,8.354,7.5292,0.0,0.0,1.5293,25.255,315.73,308.63,301.18
130.58058,8.3678,7.5225,0.0,0.0,1.5279,25.287,315.64,308.57,301.18
130.58158,8.338,7.5318,0.0,0.0,1.5261,25.203,315.56,308.51,301.17
130.58258,8.3763,7.525,0.0,0.0,1.53,25.316,315.47,308.45,301.16
130.58358,8.3658,7.5249,0.0,0.0,1.5264,25.295,315.39,308.39,301.16
130.58458,8.3749,7.5277,0.0,0.0,1.5264,25.312,315.3,308.32,301.15
130.58558,8.3722,7.5263,0.0,0.0,1.5297,25.318,315.21,308.26,301.14
130.58658,8.3872,7.5266,0.0,0.0,1.5253,25.316,315.13,308.2,301.14
130.58758,8.3472,7.5251,0.0,0.0,1.528,25.252,315.04,308.14,301.13
130.58858,8.4039,7.527,0.0,0.0,1.5272,25.377,314.96,308.08,301.13
130.58958,8.3504,7.5283,0.0,0.0,1.5265,25.234,314.87,308.02,301.12
130.59058,8.4088,7.5215,0.0,0.0,1.5288,25.403,314.79,307.96,301.12
130.59158,8.3641,7.53,0.0,0.0,1.5255,25.29,314.72,307.9,301.13
130.59258,8.4038,7.527,0.0,0.0,1.528,25.395,314.64,307.84,301.14
130.59358,8.3839,7.5229,0.0,0.0,1.5286,25.341,314.57,307.77,301.14
130.59458,8.3967,7.5313,0.0,0.0,1.5254,25.385,314.49,307.71,301.15
130.59558,8.371,7.5251,0.0,0.0,1.53,25.303,314.41,307.65,301.16
130.59658,8.4241,7.5254,0.0,0.0,1.5272,25.463,314.34,307.59,301.16
130.59758,8.388,7.5297,0.0,0.0,1.527,25.368,314.26,307.53,301.17
130.59858,8.4312,7.5253,0.0,0.0,1.5293,25.513,314.18,307.47,301.17
130.59958,8.3907,7.5303,0.0,0.0,1.5268,25.363,314.11,307.41,301.18
130.60058,8.4521,7.5234,0.0,0.0,1.5273,25.553,314.04,307.36,301.2
130.60158,8.3955,7.5273,0.0,0.0,1.5275,25.347,313.98,307.31,301.22
130.60258,8.4547,7.5301,0.0,0.0,1.5275,25.56,313.92,307.26,301.23
130.60358,8.3907,7.5206,0.0,0.0,1.5282,25.352,313.86,307.21,301.25
130.60458,8.4546,7.5293,0.0,0.0,1.5253,25.569,313.8,307.16,301.27
130.60558,8.3946,7.529,0.0,0.0,1.5289,25.372,313.74,307.11,301.29
130.60658,8.4687,7.5212,0.0,0.0,1.5278,25.585,313.68,307.06,301.31
130.60758,8.4155,7.532,0.0,0.0,1.5255,25.437,313.62,307.01,301.33
130.60858,8.4537,7.5266,0.0,0.0,1.5303,25.546,313.55,306.97,301.34
130.60958,8.3996,7.5257,0.0,0.0,1.5277,25.369,313.49,306.92,301.36
130.61058,8.4708,7.5307,0.0,0.0,1.5268,25.619,313.42,306.87,301.39
130.61158,8.395,7.5288,0.0,0.0,1.5312,25.381,313.35,306.82,301.41
130.61258,8.4899,7.5289,0.0,0.0,1.5267,25.679,313.28,306.77,301.44
130.61358,8.4306,7.5262,0.0,0.0,1.5286,25.439,313.21,306.72,301.46
130.61458,8.4668,7.5285,0.0,0.0,1.5285,25.646,313.14,306.67,301.48
130.61558,8.4506,7.5306,0.0,0.0,1.5272,25.513,313.07,306.62,301.51
130.61658,8.4728,7.523,0.0,0.0,1.5289,25.625,313.0,306.57,301.53
130.61758,8.461,7.5325,0.0,0.0,1.527,25.563,312.93,306.53,301.56
130.61858,8.4644,7.5282,0.0,0.0,1.5283,25.604,312.86,306.48,301.58
130.61958,8.4708,7.5246,0.0,0.0,1.5294,25.583,312.79,306.43,301.61
130.62058,8.4713,7.5334,0.0,0.0,1.5263,25.614,312.73,306.38,301.62
130.62158,8.4699,7.5263,0.0,0.0,1.5299,25.568,312.67,306.34,301.63
130.62258,8.4965,7.5272,0.0,0.0,1.5285,25.687,312.62,306.3,301.65
130.62358,8.5009,7.532,0.0,0.0,1.5272,25.656,312.56,306.26,301.66
130.62458,8.5384,7.5262,0.0,0.0,1.5302,25.813,312.5,306.21,301.67
130.62558,8.5585,7.5293,0.0,0.0,1.5271,25.825,312.44,306.17,301.68
130.62658,8.5674,7.5295,0.0,0.0,1.5291,25.921,312.38,306.13,301.7
130.62758,8.6187,7.5272,0.0,0.0,1.5289,26.027,312.32,306.08,301.71
130.62858,8.6425,7.5318,0.0,0.0,1.5276,26.133,312.27,306.04,301.72
130.62958,8.6703,7.5248,0.0,0.0,1.5292,26.177,312.21,306.0,301.73
130.63057,8.6587,7.5307,0.0,0.0,1.5265,26.178,312.16,305.95,301.75
130.63157,8.7764,7.5315,0.0,0.0,1.5288,26.496,312.11,305.91,301.77
130.63257,8.7101,7.5233,0.0,0.0,1.5298,26.321,312.06,305.86,301.79
130.63357,8.8349,7.5314,0.0,0.0,1.5253,26.663,312.01,305.82,301.8
130.63457,8.7456,7.5305,0.0,0.0,1.5312,26.448,311.96,305.77,301.82
130.63557,8.8675,7.5253,0.0,0.0,1.5278,26.746,311.91,305.72,301.84
130.63657,8.7739,7.5312,0.0,0.0,1.5267,26.545,311.86,305.68,301.86
130.63757,8.9343,7.5285,0.0,0.0,1.5307,26.936,311.82,305.63,301.88
130.63857,8.8585,7.5285,0.0,0.0,1.5269,26.807,311.77,305.59,301.9
130.63957,8.9616,7.5284,0.0,0.0,1.5282,27.015,311.72,305.54,301.92
130.64057,8.8842,7.5291,0.0,0.0,1.5301,26.866,311.67,305.49,301.93
130.64157,8.9842,7.5333,0.0,0.0,1.5281,27.099,311.61,305.44,301.95
130.64257,8.8943,7.5249,0.0,0.0,1.529,26.918,311.56,305.39,301.97
130.64357,8.9912,7.5342,0.0,0.0,1.5283,27.111,311.51,305.33,301.99
130.64457,8.8569,7.5319,0.0,0.0,1.5293,26.836,311.46,305.28,302.01
130.64557,9.0011,7.5233,0.0,0.0,1.5293,27.15,311.41,305.23,302.03
130.64657,8.8313,7.5346,0.0,0.0,1.5272,26.756,311.35,305.18,302.04
130.64757,9.0134,7.5303,0.0,0.0,1.5306,27.202,311.3,305.13,302.06
130.64857,8.8361,7.5263,0.0,0.0,1.5289,26.765,311.25,305.07,302.08
130.64957,9.0125,7.5343,0.0,0.0,1.5272,27.189,311.2,305.02,302.1
130.65057,8.824,7.5283,0.0,0.0,1.5316,26.708,311.13,304.97,302.12
130.65157,9.0025,7.5299,0.0,0.0,1.5279,27.151,311.07,304.92,302.14
130.65257,8.8152,7.531,0.0,0.0,1.5288,26.677,311.0,304.87,302.16
130.65357,8.9955,7.5298,0.0,0.0,1.5308,27.158,310.93,304.83,302.19
130.65457,8.796,7.5313,0.0,0.0,1.5273,26.628,310.86,304.78,302.21
130.65557,9.0006,7.5285,0.0,0.0,1.5307,27.168,310.8,304.73,302.23
130.65657,8.798,7.5301,0.0,0.0,1.5277,26.612,310.73,304.68,302.25
130.65757,9.0168,7.5345,0.0,0.0,1.5294,27.218,310.66,304.63,302.27
130.65857,8.8036,7.5249,0.0,0.0,1.5304,26.635,310.6,304.58,302.29
130.65957,9.0252,7.5338,0.0,0.0,1.5264,27.235,310.53,304.53,302.31
130.66057,8.8172,7.5314,0.0,0.0,1.5311,26.65,310.49,304.51,302.32
130.66157,9.0325,7.5263,0.0,0.0,1.5293,27.299,310.45,304.48,302.33
130.66257,8.8092,7.5322,0.0,0.0,1.5265,26.638,310.41,304.46,302.34
130.66357,9.0424,7.53,0.0,0.0,1.5322,27.323,310.38,304.44,302.34
130.66457,8.8321,7.5279,0.0,0.0,1.5277,26.687,310.34,304.42,302.35
130.66557,9.0521,7.5306,0.0,0.0,1.5286,27.353,310.3,304.39,302.35
130.66657,8.8364,7.5295,0.0,0.0,1.5308,26.708,310.26,304.37,302.36
130.66757,9.0389,7.5325,0.0,0.0,1.5281,27.317,310.23,304.35,302.37
130.66857,8.8365,7.5262,0.0,0.0,1.5298,26.708,310.19,304.33,302.37
130.66957,9.0617,7.5338,0.0,0.0,1.5295,27.405,310.15,304.3,302.38
130.67057,8.8706,7.5308,0.0,0.0,1.5282,26.786,310.12,304.28,302.39
130.67157,9.0522,7.5259,0.0,0.0,1.5302,27.379,310.08,304.26,302.39
130.67257,8.8681,7.5321,0.0,0.0,1.5262,26.777,310.04,304.24,302.4
130.67357,9.0533,7.5334,0.0,0.0,1.5315,27.409,310.01,304.21,302.41
130.67457,8.8726,7.5244,0.0,0.0,1.5288,26.786,309.97,304.19,302.41
130.67557,9.0475,7.5349,0.0,0.0,1.5276,27.386,309.93,304.17,302.42
130.67657,8.8981,7.5288,0.0,0.0,1.5316,26.84,309.89,304.15,302.43
130.67757,9.0318,7.5293,0.0,0.0,1.5285,27.343,309.86,304.12,302.43
130.67857,8.9067,7.5303,0.0,0.0,1.528,26.873,309.82,304.1,302.44
130.67957,9.0351,7.5297,0.0,0.0,1.5311,27.341,309.78,304.07,302.44
130.68057,8.9108,7.5327,0.0,0.0,1.528,26.878,309.74,304.03,302.45
130.68157,9.0266,7.5277,0.0,0.0,1.5297,27.318,309.69,303.99,302.45
130.68257,8.9475,7.5328,0.0,0.0,1.5298,26.991,309.65,303.95,302.45
130.68357,9.017,7.5337,0.0,0.0,1.5294,27.311,309.61,303.92,302.45
130.68457,8.9663,7.5258,0.0,0.0,1.5304,27.03,309.56,303.88,302.46
130.68557,9.0051,7.5348,0.0,0.0,1.5279,27.265,309.52,303.84,302.46
130.68657,8.9753,7.5321,0.0,0.0,1.5306,27.071,309.48,303.81,302.46
130.68757,9.0058,7.528,0.0,0.0,1.5303,27.294,309.44,303.77,302.47
130.68857,8.9877,7.5355,0.0,0.0,1.5272,27.095,309.39,303.73,302.47
130.68957,9.0007,7.5323,0.0,0.0,1.5327,27.272,309.35,303.69,302.48
130.69057,9.0207,7.5296,0.0,0.0,1.5288,27.196,309.3,303.64,302.48
130.69157,8.9963,7.5326,0.0,0.0,1.5283,27.206,309.26,303.59,302.49
130.69257,9.0442,7.531,0.0,0.0,1.5318,27.282,309.21,303.54,302.49
130.69357,8.9692,7.533,0.0,0.0,1.5284,27.165,309.16,303.49,302.5
130.69457,9.0398,7.5294,0.0,0.0,1.5305,27.245,309.12,303.44,302.51
130.69557,8.9632,7.5309,0.0,0.0,1.5294,27.132,309.07,303.39,302.51
130.69657,9.0695,7.5334,0.0,0.0,1.5286,27.358,309.03,303.34,302.52
130.69757,8.9668,7.5275,0.0,0.0,1.5312,27.136,308.98,303.29,302.52
130.69857,9.0816,7.5347,0.0,0.0,1.5276,27.386,308.94,303.24,302.53
130.69957,8.9509,7.5337,0.0,0.0,1.5315,27.085,308.89,303.2,302.55
130.70057,9.098,7.5253,0.0,0.0,1.5296,27.445,308.85,303.16,302.57
130.70157,8.9412,7.5373,0.0,0.0,1.5279,27.079,308.81,303.11,302.59
130.70257,9.1153,7.5319,0.0,0.0,1.5325,27.502,308.76,303.07,302.61
130.70357,8.9507,7.5269,0.0,0.0,1.5277,27.117,308.72,303.03,302.64
130.70457,9.1286,7.5347,0.0,0.0,1.5287,27.544,308.68,302.99,302.66
130.70557,8.9488,7.5309,0.0,0.0,1.5319,27.085,308.63,302.94,302.68
130.70657,9.1324,7.5323,0.0,0.0,1.528,27.557,308.59,302.9,302.7
130.70757,8.9327,7.5295,0.0,0.0,1.5298,27.014,308.55,302.86,302.72
130.70857,9.1366,7.5309,0.0,0.0,1.5296,27.587,308.51,302.81,302.74
130.70957,8.9431,7.5331,0.0,0.0,1.5285,27.059,308.46,302.78,302.77
130.71057,9.1634,7.5277,0.0,0.0,1.5306,27.655,308.42,302.75,302.79
130.71157,8.9299,7.5336,0.0,0.0,1.5276,27.036,308.38,302.72,302.82
130.71257,9.1569,7.5341,0.0,0.0,1.5308,27.671,308.34,302.69,302.84
130.71357,8.924,7.5267,0.0,0.0,1.5304,27.007,308.29,302.66,302.87
130.71457,9.1699,7.5365,0.0,0.0,1.5276,27.705,308.25,302.63,302.89
130.71557,8.9438,7.5302,0.0,0.0,1.5317,27.053,308.21,302.6,302.92
130.71657,9.1701,7.5295,0.0,0.0,1.5294,27.711,308.16,302.57,302.94
130.71757,8.9427,7.535,0.0,0.0,1.5288,27.039,308.12,302.54,302.96
130.71857,9.1743,7.5296,0.0,0.0,1.5316,27.731,308.08,302.51,302.99
130.71957,8.9658,7.533,0.0,0.0,1.5286,27.063,308.03,302.46,303.0
130.72057,9.167,7.5317,0.0,0.0,1.5303,27.721,307.98,302.42,303.01
130.72157,8.958,7.5313,0.0,0.0,1.5303,27.067,307.92,302.38,303.02
130.72257,9.1682,7.5366,0.0,0.0,1.5294,27.754,307.87,302.34,303.03
130.72357,8.9834,7.5284,0.0,0.0,1.531,27.126,307.82,302.29,303.04
130.72457,9.1827,7.535,0.0,0.0,1.5289,27.775,307.77,302.25,303.05
130.72557,8.9917,7.5351,0.0,0.0,1.5308,27.15,307.72,302.21,303.06
130.72657,9.1624,7.5287,0.0,0.0,1.5313,27.734,307.66,302.16,303.06
130.72757,8.999,7.535,0.0,0.0,1.5273,27.183,307.61,302.12,303.07
130.72857,9.1751,7.5342,0.0,0.0,1.5331,27.778,307.56,302.08,303.08
130.72957,9.0162,7.5289,0.0,0.0,1.5294,27.226,307.52,302.02,303.09
130.73057,9.1636,7.536,0.0,0.0,1.5287,27.734,307.48,301.97,303.1
130.73157,9.0348,7.531,0.0,0.0,1.5325,27.267,307.44,301.91,303.11
130.73257,9.1597,7.5348,0.0,0.0,1.5296,27.736,307.4,301.86,303.12
130.73357,9.0477,7.5319,0.0,0.0,1.5302,27.301,307.36,301.8,303.13
130.73457,9.1464,7.5325,0.0,0.0,1.5313,27.681,307.32,301.75,303.14
130.73557,9.064,7.5358,0.0,0.0,1.5295,27.32,307.28,301.69,303.15
130.73657,9.1468,7.5293,0.0,0.0,1.531,27.694,307.24,301.64,303.16
130.73757,9.0948,7.5343,0.0,0.0,1.5284,27.43,307.2,301.58,303.17
130.73857,9.1439,7.5353,0.0,0.0,1.5311,27.695,307.16,301.53,303.18
130.73957,9.1097,7.5288,0.0,0.0,1.5319,27.476,307.12,301.48,303.17
130.74057,9.1213,7.5364,0.0,0.0,1.5276,27.621,307.07,301.43,303.17
130.74157,9.1312,7.5329,0.0,0.0,1.5319,27.523,307.02,301.39,303.16
130.74257,9.1173,7.5301,0.0,0.0,1.5303,27.614,306.98,301.34,303.15
130.74357,9.1383,7.5352,0.0,0.0,1.5281,27.556,306.93,301.29,303.15
130.74457,9.1072,7.5315,0.0,0.0,1.5328,27.588,306.89,301.25,303.14
130.74557,9.153,7.5319,0.0,0.0,1.5285,27.607,306.84,301.2,303.13
130.74657,9.1066,7.5338,0.0,0.0,1.5302,27.569,306.79,301.16,303.13
130.74757,9.1729,7.5322,0.0,0.0,1.5313,27.691,306.75,301.11,303.12
130.74857,9.0794,7.5349,0.0,0.0,1.5292,27.51,306.7,301.06,303.12
130.74957,9.185,7.5299,0.0,0.0,1.531,27.719,306.65,301.03,303.13
130.75057,9.0888,7.5339,0.0,0.0,1.5289,27.531,306.61,300.99,303.14
130.75157,9.2082,7.5359,0.0,0.0,1.5306,27.801,306.56,300.95,303.16
130.75257,9.0815,7.5265,0.0,0.0,1.5309,27.484,306.51,300.92,303.17
130.75357,9.2104,7.5366,0.0,0.0,1.5278,27.795,306.46,300.88,303.19
130.75457,9.0623,7.534,0.0,0.0,1.5319,27.426,306.41,300.84,303.21
130.75557,9.2349,7.5302,0.0,0.0,1.5306,27.872,306.36,300.81,303.22
130.75657,9.0647,7.5359,0.0,0.0,1.528,27.435,306.31,300.77,303.24
130.75757,9.2297,7.5339,0.0,0.0,1.5335,27.872,306.26,300.73,303.25
130.75857,9.0625,7.5314,0.0,0.0,1.5287,27.434,306.21,300.69,303.27
130.75957,9.2555,7.5344,0.0,0.0,1.53,27.929,306.17,300.66,303.29
130.76057,9.0649,7.5333,0.0,0.0,1.5325,27.428,306.12,300.63,303.31
130.76157,9.2545,7.5354,0.0,0.0,1.5292,27.943,306.07,300.59,303.33
130.76257,9.0564,7.5309,0.0,0.0,1.5314,27.414,306.02,300.56,303.35
130.76357,9.2744,7.535,0.0,0.0,1.5296,27.992,305.97,300.53,303.37
130.76457,9.0642,7.538,0.0,0.0,1.531,27.42,305.92,300.49,303.39
130.76557,9.27,7.5275,0.0,0.0,1.5316,27.992,305.87,300.46,303.42
130.76657,9.0613,7.5371,0.0,0.0,1.5281,27.385,305.82,300.42,303.44
130.76757,9.2724,7.5368,0.0,0.0,1.5332,28.015,305.77,300.39,303.46
130.76856,9.0642,7.5275,0.0,0.0,1.5293,27.401,305.72,300.36,303.48
130.76956,9.2822,7.5409,0.0,0.0,1.5299,28.042,305.68,300.32,303.49
130.77056,9.0631,7.533,0.0,0.0,1.5337,27.402,305.63,300.28,303.49
130.77156,9.2802,7.533,0.0,0.0,1.5299,28.067,305.59,300.25,303.49
130.77256,9.0698,7.5356,0.0,0.0,1.5305,27.399,305.54,300.21,303.5
130.77356,9.2805,7.5333,0.0,0.0,1.5327,28.068,305.49,300.17,303.5
130.77456,9.0767,7.5353,0.0,0.0,1.5295,27.419,305.45,300.14,303.5
130.77556,9.2826,7.5332,0.0,0.0,1.5323,28.057,305.4,300.1,303.5
130.77656,9.0886,7.5326,0.0,0.0,1.5297,27.444,305.36,300.06,303.51
130.77756,9.277,7.5364,0.0,0.0,1.5306,28.073,305.31,300.03,303.51
130.77856,9.1002,7.531,0.0,0.0,1.5323,27.517,305.27,299.99,303.51
130.77956,9.2705,7.538,0.0,0.0,1.5287,28.052,305.23,299.95,303.51
130.78056,9.1047,7.5345,0.0,0.0,1.5317,27.481,305.2,299.91,303.51
130.78156,9.2781,7.5303,0.0,0.0,1.5316,28.072,305.16,299.88,303.51
130.78256,9.1377,7.5374,0.0,0.0,1.5284,27.569,305.13,299.84,303.51
130.78356,9.2774,7.5341,0.0,0.0,1.5339,28.08,305.1,299.8,303.51
130.78456,9.1412,7.5312,0.0,0.0,1.5294,27.569,305.06,299.77,303.51
130.78556,9.2557,7.5363,0.0,0.0,1.5303,28.024,305.03,299.73,303.51
130.78656,9.162,7.532,0.0,0.0,1.5323,27.646,304.99,299.69,303.51
130.78756,9.2449,7.536,0.0,0.0,1.5295,27.996,304.96,299.66,303.51
130.78856,9.1644,7.5313,0.0,0.0,1.5308,27.647,304.93,299.62,303.51
130.78956,9.2343,7.5343,0.0,0.0,1.531,27.979,304.89,299.59,303.52
130.79056,9.1813,7.5364,0.0,0.0,1.53,27.693,304.84,299.56,303.53
130.79156,9.2495,7.5286,0.0,0.0,1.5315,28.013,304.8,299.54,303.54
130.79256,9.2081,7.5378,0.0,0.0,1.5291,27.768,304.76,299.51,303.55
130.79356,9.2124,7.5359,0.0,0.0,1.5322,27.903,304.71,299.48,303.56
130.79456,9.2103,7.5292,0.0,0.0,1.5311,27.766,304.67,299.45,303.57
130.79556,9.2245,7.5406,0.0,0.0,1.5297,27.931,304.63,299.43,303.58
130.79656,9.2424,7.5336,0.0,0.0,1.5334,27.888,304.59,299.4,303.59
130.79756,9.2079,7.5318,0.0,0.0,1.5299,27.88,304.54,299.37,303.6
130.79856,9.2529,7.5359,0.0,0.0,1.5293,27.91,304.5,299.34,303.61
130.79956,9.1974,7.5349,0.0,0.0,1.534,27.842,304.45,299.31,303.62
130.80056,9.2675,7.5351,0.0,0.0,1.5297,27.968,304.4,299.29,303.65
130.80156,9.1877,7.533,0.0,0.0,1.5315,27.832,304.35,299.26,303.67
130.80256,9.2787,7.5354,0.0,0.0,1.5317,27.98,304.31,299.23,303.69
130.80356,9.1886,7.5376,0.0,0.0,1.5305,27.818,304.26,299.2,303.71
130.80456,9.3081,7.5292,0.0,0.0,1.5315,28.083,304.21,299.18,303.73
130.80556,9.1883,7.5391,0.0,0.0,1.5297,27.796,304.16,299.15,303.75
130.80656,9.3143,7.5372,0.0,0.0,1.5323,28.126,304.11,299.12,303.78
130.80756,9.1661,7.53,0.0,0.0,1.5319,27.754,304.06,299.09,303.8
130.80856,9.3254,7.5401,0.0,0.0,1.5292,28.162,304.01,299.07,303.82
130.80956,9.1586,7.5334,0.0,0.0,1.5327,27.732,303.98,299.03,303.83
130.81056,9.3464,7.5343,0.0,0.0,1.5315,28.212,303.94,298.99,303.84
130.81156,9.1509,7.5364,0.0,0.0,1.5292,27.683,303.91,298.96,303.86
130.81256,9.3426,7.5335,0.0,0.0,1.5332,28.198,303.88,298.92,303.87
130.81356,9.1498,7.5374,0.0,0.0,1.5306,27.698,303.84,298.88,303.88
130.81456,9.3564,7.5331,0.0,0.0,1.5309,28.256,303.81,298.85,303.89
130.81556,9.154,7.5344,0.0,0.0,1.5318,27.703,303.77,298.81,303.91
130.81656,9.367,7.5384,0.0,0.0,1.5306,28.271,303.74,298.77,303.92
130.81756,9.1492,7.5281,0.0,0.0,1.5309,27.658,303.71,298.74,303.93
130.81856,9.3762,7.5391,0.0,0.0,1.5302,28.323,303.67,298.7,303.94
130.81956,9.1484,7.5373,0.0,0.0,1.5322,27.657,303.64,298.66,303.95
130.82056,9.375,7.5297,0.0,0.0,1.5317,28.307,303.61,298.63,303.95
130.82156,9.1546,7.5377,0.0,0.0,1.5282,27.685,303.58,298.59,303.95
130.82256,9.3713,7.5362,0.0,0.0,1.5341,28.316,303.55,298.55,303.96
130.82356,9.1662,7.5314,0.0,0.0,1.5304,27.694,303.52,298.51,303.96
130.82456,9.3677,7.5367,0.0,0.0,1.5293,28.298,303.49,298.48,303.96
130.82556,9.1565,7.5317,0.0,0.0,1.5328,27.688,303.46,298.44,303.97
130.82656,9.3751,7.5364,0.0,0.0,1.5304,28.346,303.43,298.4,303.97
130.82756,9.17,7.5342,0.0,0.0,1.5308,27.698,303.4,298.37,303.97
130.82856,9.3798,7.5333,0.0,0.0,1.5319,28.369,303.37,298.33,303.97
130.82956,9.1791,7.5383,0.0,0.0,1.5307,27.713,303.33,298.3,303.97
130.83056,9.3637,7.5304,0.0,0.0,1.5314,28.303,303.29,298.26,303.97
130.83156,9.1923,7.5375,0.0,0.0,1.5298,27.733,303.26,298.23,303.97
130.83256,9.3668,7.5373,0.0,0.0,1.5318,28.322,303.22,298.2,303.97
130.83356,9.1819,7.5306,0.0,0.0,1.5322,27.73,303.18,298.16,303.97
130.83456,9.3417,7.5385,0.0,0.0,1.5288,28.286,303.15,298.13,303.97
130.83556,9.1855,7.5349,0.0,0.0,1.5331,27.739,303.11,298.09,303.97
130.83656,9.3494,7.5338,0.0,0.0,1.5319,28.296,303.07,298.06,303.97
130.83756,9.2194,7.5367,0.0,0.0,1.5291,27.798,303.03,298.03,303.97
130.83856,9.3265,7.5354,0.0,0.0,1.5342,28.24,303.0,297.99,303.97
130.83956,9.2345,7.5359,0.0,0.0,1.5304,27.845,302.96,297.95,303.97
130.84056,9.3212,7.534,0.0,0.0,1.5305,28.232,302.92,297.9,303.97
130.84156,9.2463,7.5353,0.0,0.0,1.5333,27.889,302.88,297.86,303.97
130.84256,9.3273,7.5385,0.0,0.0,1.5304,28.264,302.84,297.81,303.97
130.84356,9.2562,7.5324,0.0,0.0,1.5324,27.938,302.8,297.76,303.97
130.84456,9.3076,7.5362,0.0,0.0,1.5299,28.176,302.76,297.72,303.97
130.84556,9.2822,7.5393,0.0,0.0,1.5323,27.978,302.72,297.67,303.97
130.84656,9.2939,7.5306,0.0,0.0,1.5326,28.169,302.68,297.63,303.97
130.84756,9.2822,7.5384,0.0,0.0,1.5284,28.016,302.64,297.58,303.97
130.84856,9.286,7.5359,0.0,0.0,1.533,28.136,302.6,297.53,303.97
130.84956,9.304,7.5318,0.0,0.0,1.5313,28.075,302.56,297.5,303.98
130.85056,9.2873,7.5409,0.0,0.0,1.5306,28.145,302.53,297.46,303.98
130.85156,9.3314,7.5341,0.0,0.0,1.5338,28.151,302.5,297.42,303.98
130.85256,9.2687,7.5339,0.0,0.0,1.5303,28.082,302.46,297.38,303.99
130.85356,9.336,7.5351,0.0,0.0,1.5305,28.173,302.43,297.35,303.99
130.85456,9.2525,7.5349,0.0,0.0,1.5332,28.019,302.4,297.31,303.99
130.85556,9.3454,7.5368,0.0,0.0,1.5298,28.187,302.36,297.27,304.0
130.85656,9.254,7.5322,0.0,0.0,1.5319,28.032,302.33,297.24,304.0
130.85756,9.3492,7.5365,0.0,0.0,1.5306,28.201,302.29,297.2,304.0
130.85856,9.2467,7.5379,0.0,0.0,1.531,27.998,302.26,297.16,304.0
130.85956,9.3685,7.5306,0.0,0.0,1.5326,28.262,302.23,297.13,304.01
130.86056,9.2301,7.5391,0.0,0.0,1.5296,27.938,302.2,297.1,304.02
130.86156,9.3727,7.5357,0.0,0.0,1.5324,28.272,302.17,297.07,304.02
130.86256,9.2223,7.5323,0.0,0.0,1.5317,27.93,302.14,297.04,304.03
130.86356,9.397,7.5394,0.0,0.0,1.5297,28.369,302.11,297.01,304.04
130.86456,9.2322,7.5346,0.0,0.0,1.5343,27.936,302.08,296.98,304.04
130.86556,9.4053,7.5332,0.0,0.0,1.5295,28.39,302.05,296.95,304.05
130.86656,9.2204,7.5362,0.0,0.0,1.5307,27.904,302.01,296.92,304.05
130.86756,9.4113,7.5346,0.0,0.0,1.5333,28.397,301.98,296.89,304.06
130.86856,9.2172,7.5376,0.0,0.0,1.5302,27.904,301.95,296.86,304.07
130.86956,9.4147,7.5334,0.0,0.0,1.5322,28.436,301.92,296.83,304.07
130.87056,9.2098,7.536,0.0,0.0,1.531,27.867,301.89,296.81,304.07
130.87156,9.4175,7.5388,0.0,0.0,1.5312,28.431,301.85,296.78,304.07
130.87256,9.2141,7.5302,0.0,0.0,1.5324,27.861,301.82,296.76,304.07
130.87356,9.4295,7.541,0.0,0.0,1.5304,28.508,301.78,296.73,304.07
130.87456,9.2031,7.5355,0.0,0.0,1.5325,27.812,301.75,296.71,304.07
130.87556,9.4191,7.5325,0.0,0.0,1.5322,28.45,301.72,296.68,304.07
130.87656,9.2187,7.5406,0.0,0.0,1.5302,27.874,301.68,296.66,304.07
130.87756,9.4189,7.5354,0.0,0.0,1.5345,28.459,301.65,296.63,304.07
130.87856,9.2131,7.5327,0.0,0.0,1.5301,27.846,301.62,296.61,304.07
130.87956,9.4087,7.5399,0.0,0.0,1.5318,28.457,301.59,296.59,304.07
130.88056,9.206,7.5337,0.0,0.0,1.533,27.811,301.57,296.57,304.07
130.88156,9.4173,7.5379,0.0,0.0,1.5306,28.459,301.54,296.54,304.08
130.88256,9.2208,7.5344,0.0,0.0,1.5323,27.835,301.52,296.52,304.08
130.88356,9.4182,7.5371,0.0,0.0,1.5317,28.477,301.49,296.5,304.08
130.88456,9.2308,7.5388,0.0,0.0,1.5309,27.885,301.47,296.48,304.08
130.88556,9.4068,7.5316,0.0,0.0,1.5327,28.429,301.44,296.46,304.09
130.88656,9.2391,7.5378,0.0,0.0,1.5293,27.907,301.42,296.44,304.09
130.88756,9.4033,7.54,0.0,0.0,1.534,28.457,301.39,296.42,304.09
130.88856,9.2411,7.5297,0.0,0.0,1.5311,27.897,301.37,296.39,304.1
130.88956,9.3865,7.5406,0.0,0.0,1.5296,28.418,301.34,296.37,304.11
130.89056,9.2584,7.5344,0.0,0.0,1.5339,27.947,301.32,296.34,304.12
130.89156,9.3826,7.535,0.0,0.0,1.5317,28.422,301.3,296.31,304.13
130.89256,9.2699,7.5365,0.0,0.0,1.5297,27.962,301.27,296.28,304.14
130.89356,9.3658,7.5356,0.0,0.0,1.534,28.377,301.25,296.26,304.16
130.89456,9.2795,7.5362,0.0,0.0,1.5298,27.977,301.22,296.23,304.17
130.89556,9.3569,7.5356,0.0,0.0,1.5327,28.334,301.2,296.2,304.18
130.89656,9.2952,7.5346,0.0,0.0,1.5313,28.041,301.17,296.17,304.19
130.89756,9.3435,7.5388,0.0,0.0,1.531,28.304,301.15,296.15,304.21
130.89856,9.3015,7.5316,0.0,0.0,1.5326,28.067,301.12,296.12,304.22
130.89956,9.3264,7.5386,0.0,0.0,1.53,28.255,301.09,296.09,304.23
130.90056,9.3159,7.5383,0.0,0.0,1.5325,28.092,301.05,296.06,304.25
130.90156,9.3063,7.5311,0.0,0.0,1.5324,28.188,301.01,296.04,304.26
130.90256,9.3214,7.5391,0.0,0.0,1.529,28.122,300.97,296.01,304.28
130.90356,9.3068,7.5357,0.0,0.0,1.5341,28.19,300.93,295.98,304.29
130.90456,9.3456,7.5337,0.0,0.0,1.531,28.178,300.89,295.95,304.31
130.90556,9.2922,7.5385,0.0,0.0,1.5308,28.155,300.85,295.93,304.32
130.90655,9.3487,7.5354,0.0,0.0,1.5341,28.202,300.81,295.9,304.34
130.90755,9.2701,7.5375,0.0,0.0,1.5305,28.072,300.77,295.87,304.35
130.90855,9.3678,7.5359,0.0,0.0,1.532,28.277,300.73,295.84,304.37
130.90955,9.2808,7.5358,0.0,0.0,1.5321,28.096,300.69,295.82,304.37
130.91055,9.37,7.5388,0.0,0.0,1.5308,28.269,300.66,295.8,304.38
130.91155,9.2736,7.5325,0.0,0.0,1.5327,28.064,300.63,295.78,304.38
130.91255,9.388,7.5386,0.0,0.0,1.5301,28.331,300.6,295.76,304.38
130.91355,9.2462,7.5386,0.0,0.0,1.5325,27.98,300.57,295.73,304.39
130.91455,9.399,7.5332,0.0,0.0,1.5333,28.386,300.54,295.71,304.39
130.91555,9.2271,7.5401,0.0,0.0,1.5285,27.932,300.51,295.69,304.39
130.91655,9.4046,7.5378,0.0,0.0,1.535,28.377,300.48,295.67,304.4
130.91755,9.2415,7.533,0.0,0.0,1.531,27.979,300.45,295.65,304.4
131.9177,9.0931,7.5392,0.0,3.5239,1.533,27.485,288.6,283.97,299.99
133.9177,8.9606,7.544,0.0,13.429,1.5351,27.083,267.35,262.93,279.44
135.9177,8.9916,7.5482,0.0,23.428,1.537,27.176,249.7,245.42,260.04
137.9177,8.9235,7.5519,0.0,33.428,1.5386,26.97,234.54,230.55,243.34
139.9177,8.9193,7.5553,0.0,43.428,1.5401,26.958,221.09,217.38,228.58
140.98171,8.9185,7.5573,0.0,48.748,1.541,26.955,214.63,211.03,221.54
142.98171,8.9132,7.5607,0.0,58.748,1.5425,26.939,203.84,200.58,209.87
144.98171,8.9011,7.5638,0.0,68.748,1.5439,26.902,194.2,191.28,199.51
146.98171,8.9035,7.5671,0.0,78.748,1.5454,26.91,185.21,182.54,190.0
148.98171,8.8976,7.5701,0.0,88.748,1.5468,26.892,177.48,175.06,181.86
150.98171,8.8951,7.5729,0.0,80.134,1.548,26.884,170.19,168.08,174.23
152.98171,8.2746,7.5763,0.0,0.15012,1.5495,25.01,154.88,154.91,151.55
154.98171,8.0109,7.5813,0.0,0.00028124,1.5517,24.214,140.02,140.72,136.03
156.98171,7.8444,7.5867,0.0,5.2688e-07,1.5542,23.709,127.25,128.35,122.99
158.98171,7.7309,7.5915,0.0,9.8706e-10,1.5563,23.366,116.76,117.99,112.68
160.98171,7.5946,7.5959,0.0,1.8492e-12,1.5583,22.954,107.31,108.57,103.47
162.98171,7.4652,7.6,0.0,3.4642e-15,1.5602,22.563,99.159,100.42,95.605
164.63051,7.3758,7.6033,0.0,1.8952e-17,1.5617,22.293,93.131,94.345,89.756
166.63051,7.2595,7.607,0.0,3.5505e-20,1.5633,21.941,86.66,87.855,83.549
168.63051,7.1563,7.6102,0.0,6.6515e-23,1.5647,21.629,80.708,81.83,77.809
170.63051,7.0867,7.6135,0.0,1.2461000000000002e-25,1.5663,21.42,75.497,76.667,72.866
171.77011,7.0611,7.6153,0.0,3.4793e-27,1.5671,21.342,72.773,73.885,70.299
173.77011,7.0043,7.6181,0.0,6.5182e-30,1.5684,21.17,68.386,69.468,66.143
175.77011,6.9503,7.6207,0.0,1.2210999999999999e-32,1.5696,21.006,64.403,65.445,62.293
177.77011,6.8817,7.6231,0.0,2.2876000000000002e-35,1.5706,20.799,60.647,61.751,58.842
179.77011,6.855,7.6253,0.0,4.2856999999999996e-38,1.5717,20.719,57.358,58.412,55.674
181.77011,6.7933,7.6271,0.0,8.028900000000001e-41,1.5725,20.533,55.414,56.161,55.123
183.77011,5.8273,7.6268,0.0,1.5134e-43,1.5724,17.613,55.786,56.064,56.416
185.77011,5.2572,7.627,0.0,2.2420999999999997e-44,1.5725,15.89,55.18,55.453,56.111
187.77011,4.737,7.6271,0.0,2.2420999999999997e-44,1.5725,14.317,54.439,54.714,55.57